Workbook

Sheet Model
B2: TFI International (TFII) — 3-Statement Financial Model | CO2: SCENARIO TOGGLE
B3: IFRS as filed in Form 40-F · $ millions (USD) | CO3: Base
B4: Drop SEC filing data into the historical columns (C–CD). Forecast columns (CE–CM) recompute from the assumption tables on the right.
CN5: FY20-FY25 | CO5: Selected scenario KPIs (FY30E)
B6: ($M) | C6: Q1/10 | D6: Q2/10 | E6: Q3/10 | F6: Q4/10 | G6: FY10 | H6: Q1/11 | I6: Q2/11 | J6: Q3/11 | K6: Q4/11 | L6: FY11 | M6: Q1/12 | N6: Q2/12 | O6: Q3/12 | P6: Q4/12 | Q6: FY12 | R6: Q1/13 | S6: Q2/13 | T6: Q3/13 | U6: Q4/13 | V6: FY13 | W6: Q1/14 | X6: Q2/14 | Y6: Q3/14 | Z6: Q4/14 | AA6: FY14 | AB6: Q1/15 | AC6: Q2/15 | AD6: Q3/15 | AE6: Q4/15 | AF6: FY15 | AG6: Q1/16 | AH6: Q2/16 | AI6: Q3/16 | AJ6: Q4/16 | AK6: FY16 | AL6: Q1/17 | AM6: Q2/17 | AN6: Q3/17 | AO6: Q4/17 | AP6: FY17 | AQ6: Q1/18 | AR6: Q2/18 | AS6: Q3/18 | AT6: Q4/18 | AU6: FY18 | AV6: Q1/19 | AW6: Q2/19 | AX6: Q3/19 | AY6: Q4/19 | AZ6: FY19 | BA6: Q1/20 | BB6: Q2/20 | BC6: Q3/20 | BD6: Q4/20 | BE6: FY20 | BF6: Q1/21 | BG6: Q2/21 | BH6: Q3/21 | BI6: Q4/21 | BJ6: FY21 | BK6: Q1/22 | BL6: Q2/22 | BM6: Q3/22 | BN6: Q4/22 | BO6: FY22 | BP6: Q1/23 | BQ6: Q2/23 | BR6: Q3/23 | BS6: Q4/23 | BT6: FY23 | BU6: Q1/24 | BV6: Q2/24 | BW6: Q3/24 | BX6: Q4/24 | BY6: FY24 | BZ6: Q1/25 | CA6: Q2/25 | CB6: Q3/25 | CC6: Q4/25 | CD6: FY25 | CE6: Q1/26 | CF6: Q2/26 | CG6: Q3/26E | CH6: Q4/26E | CI6: FY26E | CJ6: FY27E | CK6: FY28E | CL6: FY29E | CM6: FY30E | CN6: 5Y CAGR | CO6: FY30E Revenue ($M) | CP6: =CM98 | CQ6: Modeling Comments & Assumptions
CO7: FY30E GAAP EBIT ($M) | CP7: =CM102
B8: SEGMENT P&L — LEGACY STRUCTURE (FY10–FY21) | CO8: FY30E EBIT margin % | CP8: =CM102/CM98
B9: Pre-FY22 reporting — 3 reportable segments: Aircraft Controls, Space and Defense Controls, Industrial Systems. (Components and Medical Devices were separate segments in early years; combined into Industrial Systems by FY15.) | CO9: FY30E ROIC | CP9: =CM284
CO10: FY30E Adj EPS ($) | CP10: =CM156
B11: Package and Courier
B12: Net sales | AZ12: 539.61 | BC12: 122.439 | BE12: 529.155 | BG12: 145.235 | BH12: 133.315 | BI12: =BJ12-SUM(BF12:BH12) | BJ12: 641.449 | BK12: 124.58 | BL12: 125.082 | BM12: 120.236 | BN12: =BO12-SUM(BK12:BM12) | BO12: 650.844 | BP12: 112.56 | BQ12: 115.588 | BR12: 111.749 | BT12: 583.198 | BU12: 103.18
B13: Operating profit | AZ13: 82.228 | BC13: 21.392 | BE13: 78.753 | BG13: 29.543 | BH13: 23.861 | BI13: =BJ13-SUM(BF13:BH13) | BJ13: 108.44 | BK13: 26.085 | BL13: 36.8 | BM13: 33.858 | BN13: =BO13-SUM(BK13:BM13) | BO13: 134.306 | BP13: 27.323 | BQ13: 27.104 | BR13: 25.222 | BT13: 114.36 | BU13: 18.155
B14: Sales y/y % | L14: =L12/G12-1 | Q14: =Q12/L12-1 | V14: =V12/Q12-1 | AA14: =AA12/V12-1 | AF14: =AF12/AA12-1 | AK14: =AK12/AF12-1 | AP14: =AP12/AK12-1 | AU14: =AU12/AP12-1 | AZ14: =AZ12/AU12-1 | BE14: =BE12/AZ12-1 | BJ14: =BJ12/BE12-1 | BK14: =BK12/BF12-1 | BL14: =BL12/BG12-1 | BM14: =BM12/BH12-1 | BO14: =IFERROR(BO12/BJ12-1,"") | BP14: =BP12/BK12-1 | BQ14: =BQ12/BL12-1 | BR14: =BR12/BM12-1 | BT14: =IFERROR(BT12/BO12-1,"")
B15: Operating margin % | G15: =G13/G12 | L15: =L13/L12 | Q15: =Q13/Q12 | V15: =V13/V12 | AA15: =AA13/AA12 | AF15: =AF13/AF12 | AK15: =AK13/AK12 | AP15: =AP13/AP12 | AU15: =AU13/AU12 | AZ15: =AZ13/AZ12 | BE15: =BE13/BE12 | BF15: =BF13/BF12 | BG15: =BG13/BG12 | BH15: =BH13/BH12 | BI15: =BI13/BI12 | BJ15: =BJ13/BJ12 | BK15: =BK13/BK12 | BL15: =BL13/BL12 | BM15: =BM13/BM12 | BO15: =BO13/BO12 | BP15: =BP13/BP12 | BQ15: =BQ13/BQ12 | BR15: =BR13/BR12 | BT15: =BT13/BT12
B16: Backlog ($M)
B17: Book-to-bill (Bookings / Sales)
B19: Less-Than-Truckload
B20: Net sales | AZ20: 727.248 | BC20: 133.122 | BE20: 589.235 | BG20: 625.265 | BH20: 860.838 | BI20: =BJ20-SUM(BF20:BH20) | BJ20: 2815.39 | BK20: 835.399 | BL20: 870.176 | BM20: 817.199 | BN20: =BO20-SUM(BK20:BM20) | BO20: 4023.163 | BP20: 690.862 | BQ20: 672.827 | BR20: 717.69 | BT20: 3368.567 | BU20: 680.696
B21: Operating profit | AZ21: 82.23 | BC21: 26.249 | BE21: 87.95 | BG21: 351.295 | BH21: 85.144 | BI21: =BJ21-SUM(BF21:BH21) | BJ21: 482.754 | BK21: 94.77 | BL21: 187.284 | BM21: 100.513 | BN21: =BO21-SUM(BK21:BM21) | BO21: 470.807 | BP21: 57.94 | BQ21: 80.672 | BR21: 100.37 | BT21: 310.429 | BU21: 66.875
B22: Sales y/y % | L22: =L20/G20-1 | Q22: =Q20/L20-1 | V22: =V20/Q20-1 | AA22: =AA20/V20-1 | AF22: =AF20/AA20-1 | AK22: =AK20/AF20-1 | AP22: =AP20/AK20-1 | AU22: =AU20/AP20-1 | AZ22: =AZ20/AU20-1 | BE22: =BE20/AZ20-1 | BJ22: =BJ20/BE20-1 | BK22: =BK20/BF20-1 | BL22: =BL20/BG20-1 | BM22: =BM20/BH20-1 | BO22: =IFERROR(BO20/BJ20-1,"") | BP22: =BP20/BK20-1 | BQ22: =BQ20/BL20-1 | BR22: =BR20/BM20-1 | BT22: =IFERROR(BT20/BO20-1,"")
B23: Operating margin % | G23: =G21/G20 | L23: =L21/L20 | Q23: =Q21/Q20 | V23: =V21/V20 | AA23: =AA21/AA20 | AF23: =AF21/AF20 | AK23: =AK21/AK20 | AP23: =AP21/AP20 | AU23: =AU21/AU20 | AZ23: =AZ21/AZ20 | BE23: =BE21/BE20 | BF23: =BF21/BF20 | BG23: =BG21/BG20 | BH23: =BH21/BH20 | BI23: =BI21/BI20 | BJ23: =BJ21/BJ20 | BK23: =BK21/BK20 | BL23: =BL21/BL20 | BM23: =BM21/BM20 | BO23: =BO21/BO20 | BP23: =BP21/BP20 | BQ23: =BQ21/BQ20 | BR23: =BR21/BR20 | BT23: =BT21/BT20
B24: Backlog ($M)
B26: Truckload
B27: Net sales | AZ27: 1891.555 | BC27: 408.995 | BE27: 1748.359 | BG27: 481.541 | BH27: 488.617 | BI27: =BJ27-SUM(BF27:BH27) | BJ27: 2162.752 | BK27: 515.925 | BL27: 556.894 | BM27: 510.185 | BN27: =BO27-SUM(BK27:BM27) | BO27: 2451.038 | BP27: 414.125 | BQ27: 410.68 | BR27: 401.51 | BT27: 1936.038 | BU27: 397.732
B28: Operating profit | AZ28: 192.172 | BC28: 56.047 | BE28: 206.346 | BG28: 62.626 | BH28: 55.753 | BI28: =BJ28-SUM(BF28:BH28) | BJ28: 230.189 | BK28: 71.028 | BL28: 127.37 | BM28: 96.628 | BN28: =BO28-SUM(BK28:BM28) | BO28: 366.868 | BP28: 70.496 | BQ28: 66.183 | BR28: 50.057 | BT28: 237.393 | BU28: 41.464
B29: Sales y/y % | L29: =L27/G27-1 | Q29: =Q27/L27-1 | V29: =V27/Q27-1 | AA29: =AA27/V27-1 | AF29: =AF27/AA27-1 | AK29: =AK27/AF27-1 | AP29: =AP27/AK27-1 | AU29: =AU27/AP27-1 | AZ29: =AZ27/AU27-1 | BE29: =BE27/AZ27-1 | BJ29: =BJ27/BE27-1 | BK29: =BK27/BF27-1 | BL29: =BL27/BG27-1 | BM29: =BM27/BH27-1 | BO29: =IFERROR(BO27/BJ27-1,"") | BP29: =BP27/BK27-1 | BQ29: =BQ27/BL27-1 | BR29: =BR27/BM27-1 | BT29: =IFERROR(BT27/BO27-1,"")
B30: Operating margin % | G30: =G28/G27 | L30: =L28/L27 | Q30: =Q28/Q27 | V30: =V28/V27 | AA30: =AA28/AA27 | AF30: =AF28/AF27 | AK30: =AK28/AK27 | AP30: =AP28/AP27 | AU30: =AU28/AU27 | AZ30: =AZ28/AZ27 | BE30: =BE28/BE27 | BF30: =BF28/BF27 | BG30: =BG28/BG27 | BH30: =BH28/BH27 | BI30: =BI28/BI27 | BJ30: =BJ28/BJ27 | BK30: =BK28/BK27 | BL30: =BL28/BL27 | BM30: =BM28/BM27 | BO30: =BO28/BO27 | BP30: =BP28/BP27 | BQ30: =BQ28/BQ27 | BR30: =BR28/BR27 | BT30: =BT28/BT27
B31: Backlog ($M)
B33: Logistics
B34: Net sales | AZ34: 774.833 | BC34: 209.974 | BE34: 945.13 | BG34: 406.902 | BH34: 408.071 | BJ34: 1662.072 | BK34: 435.378 | BL34: 453.701 | BM34: 424.075 | BO34: 1763.28 | BP34: 355.251 | BQ34: 361.767 | BR34: 416.222 | BT34: 1697.016 | BU34: 441.905
B35: Operating profit | AZ35: 57.447 | BC35: 22.435 | BE35: 84.459 | BG35: 47.566 | BH35: 45.299 | BJ35: 142.794 | BK35: 34.882 | BL35: 42.368 | BM35: 28.992 | BO35: 140.446 | BP35: 31.71 | BQ35: 32.893 | BR35: 40.855 | BT35: 160.112 | BU35: 40.182
B36: Operating margin % | L36: =L34/G34-1 | Q36: =Q34/L34-1 | V36: =V34/Q34-1 | AA36: =AA34/V34-1 | AF36: =AF34/AA34-1 | AK36: =AK34/AF34-1 | AP36: =AP34/AK34-1 | BE36: =BE35/BE34 | BJ36: =BJ35/BJ34 | BO36: =BO35/BO34 | BT36: =BT35/BT34
G37: =G35/G34 | L37: =L35/L34 | Q37: =Q35/Q34 | V37: =V35/V34 | AA37: =AA35/AA34 | AF37: =AF35/AF34 | AK37: =AK35/AK34 | AP37: =AP35/AP34 | AU37: =AU35/AU34 | AZ37: =AZ35/AZ34 | BE37: =BE35/BE34 | BF37: =BF35/BF34 | BG37: =BG35/BG34 | BH37: =BH35/BH34 | BI37: =BI35/BI34 | BJ37: =BJ35/BJ34
B38: [Legacy Segment 5]
B39: Net sales
B40: Operating profit
B41: Operating margin % | G41: =G40/G39 | L41: =L40/L39 | Q41: =Q40/Q39 | V41: =V40/V39 | AA41: =AA40/AA39 | AF41: =AF40/AF39 | AK41: =AK40/AK39 | AP41: =AP40/AP39 | AU41: =AU40/AU39 | AZ41: =AZ40/AZ39 | BE41: =BE40/BE39 | BF41: =BF40/BF39 | BG41: =BG40/BG39 | BH41: =BH40/BH39 | BI41: =BI40/BI39 | BJ41: =BJ40/BJ39
B43: Legacy Group Total (consolidated, FY10–FY21)
B44: Net sales | G44: =G12+G20+G27+G34+G39 | L44: =L12+L20+L27+L34+L39 | Q44: =Q12+Q20+Q27+Q34+Q39 | V44: =V12+V20+V27+V34+V39 | AA44: =AA12+AA20+AA27+AA34+AA39 | AF44: =AF12+AF20+AF27+AF34+AF39 | AK44: =AK12+AK20+AK27+AK34 | AP44: =AP12+AP20+AP27+AP34 | AU44: =AU12+AU20+AU27 | AZ44: =AZ12+AZ20+AZ27 | BE44: =BE12+BE20+BE27+BE34 | BF44: =BF12+BF20+BF27 | BG44: =BG12+BG20+BG27 | BH44: =BH12+BH20+BH27 | BJ44: =BJ12+BJ20+BJ27+BJ34 | BK44: =BK12+BK20+BK27 | BL44: =BL12+BL20+BL27 | BM44: =BM12+BM20+BM27 | BO44: =BO12+BO20+BO27+BO34 | BP44: =BP12+BP20+BP27 | BQ44: =BQ12+BQ20+BQ27 | BR44: =BR12+BR20+BR27 | BT44: =BT12+BT20+BT27+BT34
B45: Operating profit | G45: =G13+G21+G28+G35+G40 | L45: =L13+L21+L28+L35+L40 | Q45: =Q13+Q21+Q28+Q35+Q40 | V45: =V13+V21+V28+V35+V40 | AA45: =AA13+AA21+AA28+AA35+AA40 | AF45: =AF13+AF21+AF28+AF35+AF40 | AK45: =AK13+AK21+AK28+AK35 | AP45: =AP13+AP21+AP28+AP35 | AU45: =AU13+AU21+AU28 | AZ45: =AZ13+AZ21+AZ28 | BE45: =BE13+BE21+BE28+BE35 | BF45: =BF13+BF21+BF28 | BG45: =BG13+BG21+BG28 | BH45: =BH13+BH21+BH28 | BJ45: =BJ13+BJ21+BJ28+BJ35 | BK45: =BK13+BK21+BK28 | BL45: =BL13+BL21+BL28 | BM45: =BM13+BM21+BM28 | BO45: =BO13+BO21+BO28+BO35 | BP45: =BP13+BP21+BP28 | BQ45: =BQ13+BQ21+BQ28 | BR45: =BR13+BR21+BR28 | BT45: =BT13+BT21+BT28+BT35
...

Sheet Bull-Base-Bear
B2: TFI International (TFII) — Bull / Base / Bear Case P&L Summary | J2: Share price ($): | K2: 150
B3: Adjusted figures · $ millions (USD) · Linked to Model — edit scenario assumptions on the Model tab. | J3: As of: | K3: =TODAY()
B5: Scenario: | C5: =Model!CO3 | N5: Scenario: | O5: Bull | Z5: Scenario: | AA5: Bear
B7: ($M, except EPS and shares) | C7: FY25A | D7: FY26E | E7: FY27E | F7: FY28E | G7: FY29E | H7: FY30E | I7: 25-'30 CAGR | J7: LT Hist Avg | K7: LT Hist Min | L7: LT Hist Max | N7: ($M, except EPS and shares) | O7: FY25A | P7: FY26E | Q7: FY27E | R7: FY28E | S7: FY29E | T7: FY30E | U7: 25-'30 CAGR | V7: LT Hist Avg | W7: LT Hist Min | X7: LT Hist Max | Z7: ($M, except EPS and shares) | AA7: FY25A | AB7: FY26E | AC7: FY27E | AD7: FY28E | AE7: FY29E | AF7: FY30E | AG7: 25-'30 CAGR | AH7: LT Hist Avg | AI7: LT Hist Min | AJ7: LT Hist Max
B9: Revenue | C9: =Model!CD114 | D9: =Model!CI114 | E9: =Model!CJ114 | F9: =Model!CK114 | G9: =Model!CL114 | H9: =Model!CM114 | I9: =IFERROR((H9/C9)^(1/5)-1,"n/m") | N9: Revenue | O9: 3860.624 | P9: 4264.9902 | Q9: 4738.1424 | R9: 5175.8989 | S9: 5605.2429 | T9: 6047.3405 | U9: 0.093909475 | Z9: Revenue | AA9: 3860.624 | AB9: 4264.9902 | AC9: 4421.3914 | AD9: 4555.9175 | AE9: 4684.1497 | AF9: 4822.1843 | AG9: 0.045483682
B10: Revenue y/y % | D10: =IFERROR(D9/C9-1,"") | E10: =IFERROR(E9/D9-1,"") | F10: =IFERROR(F9/E9-1,"") | G10: =IFERROR(G9/F9-1,"") | H10: =IFERROR(H9/G9-1,"") | N10: Revenue y/y % | P10: 0.10474115 | Q10: 0.11093863 | R10: 0.092389911 | S10: 0.082950609 | T10: 0.078872163 | Z10: Revenue y/y % | AB10: 0.10474115 | AC10: 0.036670945 | AD10: 0.030426179 | AE10: 0.028146311 | AF10: 0.029468425
B12: Gross Profit | C12: =Model!CD116 | D12: =Model!CI116 | E12: =Model!CJ116 | F12: =Model!CK116 | G12: =Model!CL116 | H12: =Model!CM116 | I12: =IFERROR((H12/C12)^(1/5)-1,"n/m") | N12: Gross Profit | O12: 1057.348 | P12: 1194.1973 | Q12: 1350.3706 | R12: 1501.0107 | S12: 1653.5467 | T12: 1814.2022 | U12: 0.11402143 | Z12: Gross Profit | AA12: 1057.348 | AB12: 1194.1973 | AC12: 1260.0966 | AD12: 1321.2161 | AE12: 1381.8242 | AF12: 1446.6553 | AG12: 0.064705313
B13: GP % | C13: =IFERROR(C12/C9,"") | D13: =IFERROR(D12/D9,"") | E13: =IFERROR(E12/E9,"") | F13: =IFERROR(F12/F9,"") | G13: =IFERROR(G12/G9,"") | H13: =IFERROR(H12/H9,"") | J13: =AVERAGE(Model!AF165,Model!AK165,Model!AP165,Model!AU165,Model!AZ165,Model!BE165,Model!BJ165,Model!BO165,Model!BT165,Model!BY165,Model!CD165) | K13: =MIN(Model!AF165,Model!AK165,Model!AP165,Model!AU165,Model!AZ165,Model!BE165,Model!BJ165,Model!BO165,Model!BT165,Model!BY165,Model!CD165) | L13: =MAX(Model!AF165,Model!AK165,Model!AP165,Model!AU165,Model!AZ165,Model!BE165,Model!BJ165,Model!BO165,Model!BT165,Model!BY165,Model!CD165) | N13: GP % | O13: 0.27388008 | P13: 0.28 | Q13: 0.285 | R13: 0.29 | S13: 0.295 | T13: 0.3 | V13: 0.2792281 | W13: 0.2578201 | X13: 0.29502553 | Z13: GP % | AA13: 0.27388008 | AB13: 0.28 | AC13: 0.285 | AD13: 0.29 | AE13: 0.295 | AF13: 0.3 | AH13: 0.2792281 | AI13: 0.2578201 | AJ13: 0.29502553
B15: EBIT (Adjusted Operating Profit) | C15: =IF(ISNUMBER(Model!CD150),IF(Model!CD150>0,Model!CD150,Model!CD126),Model!CD126) | D15: =IF(ISNUMBER(Model!CI150),IF(Model!CI150>0,Model!CI150,Model!CI126),Model!CI126) | E15: =IF(ISNUMBER(Model!CJ150),IF(Model!CJ150>0,Model!CJ150,Model!CJ126),Model!CJ126) | F15: =IF(ISNUMBER(Model!CK150),IF(Model!CK150>0,Model!CK150,Model!CK126),Model!CK126) | G15: =IF(ISNUMBER(Model!CL150),IF(Model!CL150>0,Model!CL150,Model!CL126),Model!CL126) | H15: =IF(ISNUMBER(Model!CM150),IF(Model!CM150>0,Model!CM150,Model!CM126),Model!CM126) | I15: =IFERROR((H15/C15)^(1/5)-1,"n/m") | N15: EBIT (Adjusted Operating Profit) | O15: 501.268 | P15: 511.84054 | Q15: 582.82153 | R15: 656.48366 | S15: 749.02555 | T15: 850.84825 | U15: 0.11162019 | Z15: EBIT (Adjusted Operating Profit) | AA15: 501.268 | AB15: 511.84054 | AC15: 544.81141 | AD15: 578.98598 | AE15: 626.9807 | AF15: 679.32637 | AG15: 0.062678022
B16: EBIT y/y % | D16: =IFERROR(D15/C15-1,"") | E16: =IFERROR(E15/D15-1,"") | F16: =IFERROR(F15/E15-1,"") | G16: =IFERROR(G15/F15-1,"") | H16: =IFERROR(H15/G15-1,"") | N16: EBIT y/y % | P16: 0.021091591 | Q16: 0.13867794 | R16: 0.12638883 | S16: 0.14096601 | T16: 0.13594023 | Z16: EBIT y/y % | AB16: 0.021091591 | AC16: 0.064416303 | AD16: 0.062727329 | AE16: 0.08289445 | AF16: 0.083488482
B17: EBIT % | C17: =IFERROR(C15/C9,"") | D17: =IFERROR(D15/D9,"") | E17: =IFERROR(E15/E9,"") | F17: =IFERROR(F15/F9,"") | G17: =IFERROR(G15/G9,"") | H17: =IFERROR(H15/H9,"") | J17: =AVERAGE(Model!AF151,Model!AK151,Model!AP151,Model!AU151,Model!AZ151,Model!BE151,Model!BJ151,Model!BO151,Model!BT151,Model!BY151,Model!CD151) | K17: =MIN(Model!AF151,Model!AK151,Model!AP151,Model!AU151,Model!AZ151,Model!BE151,Model!BJ151,Model!BO151,Model!BT151,Model!BY151,Model!CD151) | L17: =MAX(Model!AF151,Model!AK151,Model!AP151,Model!AU151,Model!AZ151,Model!BE151,Model!BJ151,Model!BO151,Model!BT151,Model!BY151,Model!CD151) | N17: EBIT % | O17: 0.12984119 | P17: 0.12000978 | Q17: 0.12300634 | R17: 0.12683471 | S17: 0.13362945 | T17: 0.14069792 | V17: 0.10480017 | W17: 0.084259871 | X17: 0.12984119 | Z17: EBIT % | AA17: 0.12984119 | AB17: 0.12000978 | AC17: 0.12322171 | AD17: 0.12708439 | AE17: 0.13385155 | AF17: 0.14087524 | AH17: 0.10480017 | AI17: 0.084259871 | AJ17: 0.12984119
B19: Net Income (Adjusted Earnings) | C19: =Model!CD155 | D19: =Model!CI155 | E19: =Model!CJ155 | F19: =Model!CK155 | G19: =Model!CL155 | H19: =Model!CM155 | I19: =IFERROR((H19/C19)^(1/5)-1,"n/m") | N19: Net Income (Adjusted Earnings) | O19: 278.685 | P19: 335.79881 | Q19: 396.13347 | R19: 456.31 | S19: 530.92955 | T19: 612.64891 | U19: 0.17062991 | Z19: Net Income (Adjusted Earnings) | AA19: 278.685 | AB19: 335.79881 | AC19: 367.05573 | AD19: 397.02427 | AE19: 437.56524 | AF19: 481.43467 | AG19: 0.11553899
B21: Diluted shares ('000) | C21: =Model!CD139 | D21: =Model!CI139 | E21: =Model!CJ139 | F21: =Model!CK139 | G21: =Model!CL139 | H21: =Model!CM139 | I21: =IFERROR((H21/C21)^(1/5)-1,"n/m") | N21: Diluted shares ('000) | O21: 32082.601 | P21: 31647.818 | Q21: 31241.48 | R21: 30861.724 | S21: 30506.811 | T21: 30175.118 | U21: -0.012184399 | Z21: Diluted shares ('000) | AA21: 32082.601 | AB21: 31647.818 | AC21: 31241.48 | AD21: 30861.724 | AE21: 30506.811 | AF21: 30175.118 | AG21: -0.012184399
B23: Adjusted EPS — Diluted ($) | C23: =Model!CD156 | D23: =Model!CI156 | E23: =Model!CJ156 | F23: =Model!CK156 | G23: =Model!CL156 | H23: =Model!CM156 | I23: =IFERROR((H23/C23)^(1/5)-1,"n/m") | N23: Adjusted EPS — Diluted ($) | O23: 8.686484 | P23: 10.610488 | Q23: 12.679728 | R23: 14.785629 | S23: 17.403639 | T23: 20.303116 | U23: 0.18506926 | Z23: Adjusted EPS — Diluted ($) | AA23: 8.686484 | AB23: 10.610488 | AC23: 11.748987 | AD23: 12.864618 | AE23: 14.343198 | AF23: 15.954691 | AG23: 0.12929882
B24: EPS y/y % | D24: =IFERROR(D23/C23-1,"") | E24: =IFERROR(E23/D23-1,"") | F24: =IFERROR(F23/E23-1,"") | G24: =IFERROR(G23/F23-1,"") | H24: =IFERROR(H23/G23-1,"") | N24: EPS y/y % | P24: 0.22149404 | Q24: 0.19501834 | R24: 0.16608408 | S24: 0.17706451 | T24: 0.16660173 | Z24: EPS y/y % | AB24: 0.22149404 | AC24: 0.10729935 | AD24: 0.094955491 | AE24: 0.11493388 | AF24: 0.1123524
B26: P / E (x) — assumed | E26: 20 | F26: =E26 | G26: =F26 | H26: =G26 | N26: P / E (x) — assumed | R26: 25 | S26: 22 | T26: 22 | Z26: P / E (x) — assumed | AC26: 18 | AD26: 18 | AE26: 18 | AF26: 18
B27: Price Target ($) | F27: =F26*F23 | G27: =G26*G23 | H27: =H26*H23 | N27: Price Target ($) | R27: =R26*R23 | S27: =S26*S23 | T27: =T26*T23 | Z27: Price Target ($) | AC27: 211.48176 | AD27: 231.56312 | AE27: 258.17757 | AF27: 287.18443
B28: Upside / (Downside) vs current | F28: =IFERROR(F27/$K$2-1,"") | G28: =IFERROR(G27/$K$2-1,"") | H28: =IFERROR(H27/$K$2-1,"") | N28: Upside / (Downside) vs current | R28: =IFERROR(R27/$K$2-1,"") | S28: =IFERROR(S27/$K$2-1,"") | T28: =IFERROR(T27/$K$2-1,"") | Z28: Upside / (Downside) vs current | AC28: -0.31780076 | AD28: -0.2530222 | AE28: -0.16716914 | AF28: -0.073598601
B29: IRR (to Dec-Y-1) | F29: =IFERROR((F27/$K$2)^(1/((DATE(2025+3,12,31)-$K$3)/365.25))-1,"") | G29: =IFERROR((G27/$K$2)^(1/((DATE(2025+4,12,31)-$K$3)/365.25))-1,"") | H29: =IFERROR((H27/$K$2)^(1/((DATE(2025+5,12,31)-$K$3)/365.25))-1,"") | N29: IRR (to Dec-Y-1) | R29: =IFERROR((R27/$K$2)^(1/((DATE(2025+3,12,31)-$K$3)/365.25))-1,"") | S29: =IFERROR((S27/$K$2)^(1/((DATE(2025+4,12,31)-$K$3)/365.25))-1,"") | T29: =IFERROR((T27/$K$2)^(1/((DATE(2025+5,12,31)-$K$3)/365.25))-1,"") | Z29: IRR (to Dec-Y-1) | AC29: -0.21273051 | AD29: -0.10609752 | AE29: -0.049539387 | AF29: -0.016483182
B31: Free Cash Flow | C31: =Model!CD210 | D31: =Model!CI210 | E31: =Model!CJ210 | F31: =Model!CK210 | G31: =Model!CL210 | H31: =Model!CM210 | I31: =IFERROR((H31/C31)^(1/5)-1,"n/m") | N31: Free Cash Flow | O31: 128.355 | P31: 209.97327 | Q31: 255.88546 | R31: 364.4777 | S31: 424.28432 | T31: 452.07033 | U31: 0.2863485 | Z31: Free Cash Flow | AA31: 128.355 | AB31: 209.97327 | AC31: 320.01831 | AD31: 387.72396 | AE31: 411.44649 | AF31: 410.861 | AG31: 0.26199149
B32: FCF % | C32: =IFERROR(C31/C9,"") | D32: =IFERROR(D31/D9,"") | E32: =IFERROR(E31/E9,"") | F32: =IFERROR(F31/F9,"") | G32: =IFERROR(G31/G9,"") | H32: =IFERROR(H31/H9,"") | J32: =AVERAGE(IFERROR(Model!AF210/Model!AF114,NA()),IFERROR(Model!AK210/Model!AK114,NA()),IFERROR(Model!AP210/Model!AP114,NA()),IFERROR(Model!AU210/Model!AU114,NA()),IFERROR(Model!AZ210/Model!AZ114,NA()),IFERROR(Model!BE210/Model!BE114,NA()),IFERROR(Model!BJ210/Model!BJ114,NA()),IFERROR(Model!BO210/Model!BO114,NA()),IFERROR(Model!BT210/Model!BT114,NA()),IFERROR(Model!BY210/Model!BY114,NA()),IFERROR(Model!CD210/Model!CD114,NA())) | K32: =MIN(IFERROR(Model!AF210/Model!AF114,99),IFERROR(Model!AK210/Model!AK114,99),IFERROR(Model!AP210/Model!AP114,99),IFERROR(Model!AU210/Model!AU114,99),IFERROR(Model!AZ210/Model!AZ114,99),IFERROR(Model!BE210/Model!BE114,99),IFERROR(Model!BJ210/Model!BJ114,99),IFERROR(Model!BO210/Model!BO114,99),IFERROR(Model!BT210/Model!BT114,99),IFERROR(Model!BY210/Model!BY114,99),IFERROR(Model!CD210/Model!CD114,99)) | L32: =MAX(IFERROR(Model!AF210/Model!AF114,-99),IFERROR(Model!AK210/Model!AK114,-99),IFERROR(Model!AP210/Model!AP114,-99),IFERROR(Model!AU210/Model!AU114,-99),IFERROR(Model!AZ210/Model!AZ114,-99),IFERROR(Model!BE210/Model!BE114,-99),IFERROR(Model!BJ210/Model!BJ114,-99),IFERROR(Model!BO210/Model!BO114,-99),IFERROR(Model!BT210/Model!BT114,-99),IFERROR(Model!BY210/Model!BY114,-99),IFERROR(Model!CD210/Model!CD114,-99)) | N32: FCF % | O32: 0.033247216 | P32: 0.049231828 | Q32: 0.054005439 | R32: 0.070418242 | S32: 0.075694189 | T32: 0.07475523 | V32: 0.046677948 | W32: -0.011355803 | X32: 0.10636294 | Z32: FCF % | AA32: 0.033247216 | AB32: 0.049231828 | AC32: 0.072379547 | AD32: 0.085103376 | AE32: 0.087838031 | AF32: 0.085202262 | AH32: 0.046677948 | AI32: -0.011355803 | AJ32: 0.10636294
B33: FCF / share ($) | C33: =IFERROR(C31*1000/C21,"") | D33: =IFERROR(D31*1000/D21,"") | E33: =IFERROR(E31*1000/E21,"") | F33: =IFERROR(F31*1000/F21,"") | G33: =IFERROR(G31*1000/G21,"") | H33: =IFERROR(H31*1000/H21,"") | N33: FCF / share ($) | O33: 4.0007666 | P33: 6.6346837 | Q33: 8.1905679 | R33: 11.810024 | S33: 13.907855 | T33: 14.98156 | Z33: FCF / share ($) | AA33: 4.0007666 | AB33: 6.6346837 | AC33: 10.243379 | AD33: 12.563263 | AE33: 13.487037 | AF33: 13.615887
B34: FCF Yield (on PT) | D34: =IFERROR(D33/D27,"") | E34: =IFERROR(E33/E27,"") | F34: =IFERROR(F33/F27,"") | G34: =IFERROR(G33/G27,"") | H34: =IFERROR(H33/H27,"") | N34: FCF Yield (on PT) | Q34: 0.029361713 | R34: 0.036306827 | S34: 0.036324312 | T34: 0.033540664 | Z34: FCF Yield (on PT) | AC34: 0.048436228 | AD34: 0.054254163 | AE34: 0.052239384 | AF34: 0.047411648
B35: EBITDA (before special items) | C35: =IF(ISNUMBER(Model!CD150),IF(Model!CD150>0,Model!CD150,Model!CD126),Model!CD126)+Model!CD176+Model!CD177 | D35: =IF(ISNUMBER(Model!CI150),IF(Model!CI150>0,Model!CI150,Model!CI126),Model!CI126)+Model!CI176+Model!CI177 | E35: =IF(ISNUMBER(Model!CJ150),IF(Model!CJ150>0,Model!CJ150,Model!CJ126),Model!CJ126)+Model!CJ176+Model!CJ177 | F35: =IF(ISNUMBER(Model!CK150),IF(Model!CK150>0,Model!CK150,Model!CK126),Model!CK126)+Model!CK176+Model!CK177 | G35: =IF(ISNUMBER(Model!CL150),IF(Model!CL150>0,Model!CL150,Model!CL126),Model!CL126)+Model!CL176+Model!CL177 | H35: =IF(ISNUMBER(Model!CM150),IF(Model!CM150>0,Model!CM150,Model!CM126),Model!CM126)+Model!CM176+Model!CM177 | I35: =IFERROR((H35/C35)^(1/5)-1,"n/m") | N35: EBITDA (before special items) | O35: 604.996 | P35: 626.43313 | Q35: 710.12687 | R35: 795.55073 | S35: 899.62831 | T35: 1013.3294 | U35: 0.10866318 | Z35: EBITDA (before special items) | AA35: 604.996 | AB35: 626.43313 | AC35: 663.60622 | AD35: 701.39526 | AE35: 752.83535 | AF35: 808.88976 | AG35: 0.059808423
B36: EBITDA % | C36: =IFERROR(C35/C9,"") | D36: =IFERROR(D35/D9,"") | E36: =IFERROR(E35/E9,"") | F36: =IFERROR(F35/F9,"") | G36: =IFERROR(G35/G9,"") | H36: =IFERROR(H35/H9,"") | J36: =AVERAGE(IFERROR((IF(ISNUMBER(Model!AF150),IF(Model!AF150>0,Model!AF150,Model!AF126),Model!AF126)+Model!AF176+Model!AF177)/Model!AF114,NA()),IFERROR((IF(ISNUMBER(Model!AK150),IF(Model!AK150>0,Model!AK150,Model!AK126),Model!AK126)+Model!AK176+Model!AK177)/Model!AK114,NA()),IFERROR((IF(ISNUMBER(Model!AP150),IF(Model!AP150>0,Model!AP150,Model!AP126),Model!AP126)+Model!AP176+Model!AP177)/Model!AP114,NA()),IFERROR((IF(ISNUMBER(Model!AU150),IF(Model!AU150>0,Model!AU150,Model!AU126),Model!AU126)+Model!AU176+Model!AU177)/Model!AU114,NA()),IFERROR((IF(ISNUMBER(Model!AZ150),IF(Model!AZ150>0,Model!AZ150,Model!AZ126),Model!AZ126)+Model!AZ176+Model!AZ177)/Model!AZ114,NA()),IFERROR((IF(ISNUMBER(Model!BE150),IF(Model!BE150>0,Model!BE150,Model!BE126),Model!BE126)+Model!BE176+Model!BE177)/Model!BE114,NA()),IFERROR((IF(ISNUMBER(Model!BJ150),IF(Model!BJ150>0,Model!BJ150,Model!BJ126),Model!BJ126)+Model!BJ176+Model!BJ177)/Model!BJ114,NA()),IFERROR((IF(ISNUMBER(Model!BO150),IF(Model!BO150>0,Model!BO150,Model!BO126),Model!BO126)+Model!BO176+Model!BO177)/Model!BO114,NA()),IFERROR((IF(ISNUMBER(Model!BT150),IF(Model!BT150>0,Model!BT150,Model!BT126),Model!BT126)+Model!BT176+Model!BT177)/Model!BT114,NA()),IFERROR((IF(ISNUMBER(Model!BY150),IF(Model!BY150>0,Model!BY150,Model!BY126),Model!BY126)+Model!BY176+Model!BY177)/Model!BY114,NA()),IFERROR((IF(ISNUMBER(Model!CD150),IF(Model!CD150>0,Model!CD150,Model!CD126),Model!CD126)+Model!CD176+Model!CD177)/Model!CD114,NA())) | K36: =MIN(IFERROR((IF(ISNUMBER(Model!AF150),IF(Model!AF150>0,Model!AF150,Model!AF126),Model!AF126)+Model!AF176+Model!AF177)/Model!AF114,99),IFERROR((IF(ISNUMBER(Model!AK150),IF(Model!AK150>0,Model!AK150,Model!AK126),Model!AK126)+Model!AK176+Model!AK177)/Model!AK114,99),IFERROR((IF(ISNUMBER(Model!AP150),IF(Model!AP150>0,Model!AP150,Model!AP126),Model!AP126)+Model!AP176+Model!AP177)/Model!AP114,99),IFERROR((IF(ISNUMBER(Model!AU150),IF(Model!AU150>0,Model!AU150,Model!AU126),Model!AU126)+Model!AU176+Model!AU177)/Model!AU114,99),IFERROR((IF(ISNUMBER(Model!AZ150),IF(Model!AZ150>0,Model!AZ150,Model!AZ126),Model!AZ126)+Model!AZ176+Model!AZ177)/Model!AZ114,99),IFERROR((IF(ISNUMBER(Model!BE150),IF(Model!BE150>0,Model!BE150,Model!BE126),Model!BE126)+Model!BE176+Model!BE177)/Model!BE114,99),IFERROR((IF(ISNUMBER(Model!BJ150),IF(Model!BJ150>0,Model!BJ150,Model!BJ126),Model!BJ126)+Model!BJ176+Model!BJ177)/Model!BJ114,99),IFERROR((IF(ISNUMBER(Model!BO150),IF(Model!BO150>0,Model!BO150,Model!BO126),Model!BO126)+Model!BO176+Model!BO177)/Model!BO114,99),IFERROR((IF(ISNUMBER(Model!BT150),IF(Model!BT150>0,Model!BT150,Model!BT126),Model!BT126)+Model!BT176+Model!BT177)/Model!BT114,99),IFERROR((IF(ISNUMBER(Model!BY150),IF(Model!BY150>0,Model!BY150,Model!BY126),Model!BY126)+Model!BY176+Model!BY177)/Model!BY114,99),IFERROR((IF(ISNUMBER(Model!CD150),IF(Model!CD150>0,Model!CD150,Model!CD126),Model!CD126)+Model!CD176+Model!CD177)/Model!CD114,99)) | L36: =MAX(IFERROR((IF(ISNUMBER(Model!AF150),IF(Model!AF150>0,Model!AF150,Model!AF126),Model!AF126)+Model!AF176+Model!AF177)/Model!AF114,-99),IFERROR((IF(ISNUMBER(Model!AK150),IF(Model!AK150>0,Model!AK150,Model!AK126),Model!AK126)+Model!AK176+Model!AK177)/Model!AK114,-99),IFERROR((IF(ISNUMBER(Model!AP150),IF(Model!AP150>0,Model!AP150,Model!AP126),Model!AP126)+Model!AP176+Model!AP177)/Model!AP114,-99),IFERROR((IF(ISNUMBER(Model!AU150),IF(Model!AU150>0,Model!AU150,Model!AU126),Model!AU126)+Model!AU176+Model!AU177)/Model!AU114,-99),IFERROR((IF(ISNUMBER(Model!AZ150),IF(Model!AZ150>0,Model!AZ150,Model!AZ126),Model!AZ126)+Model!AZ176+Model!AZ177)/Model!AZ114,-99),IFERROR((IF(ISNUMBER(Model!BE150),IF(Model!BE150>0,Model!BE150,Model!BE126),Model!BE126)+Model!BE176+Model!BE177)/Model!BE114,-99),IFERROR((IF(ISNUMBER(Model!BJ150),IF(Model!BJ150>0,Model!BJ150,Model!BJ126),Model!BJ126)+Model!BJ176+Model!BJ177)/Model!BJ114,-99),IFERROR((IF(ISNUMBER(Model!BO150),IF(Model!BO150>0,Model!BO150,Model!BO126),Model!BO126)+Model!BO176+Model!BO177)/Model!BO114,-99),IFERROR((IF(ISNUMBER(Model!BT150),IF(Model!BT150>0,Model!BT150,Model!BT126),Model!BT126)+Model!BT176+Model!BT177)/Model!BT114,-99),IFERROR((IF(ISNUMBER(Model!BY150),IF(Model!BY150>0,Model!BY150,Model!BY126),Model!BY126)+Model!BY176+Model!BY177)/Model!BY114,-99),IFERROR((IF(ISNUMBER(Model!CD150),IF(Model!CD150>0,Model!CD150,Model!CD126),Model!CD126)+Model!CD176+Model!CD177)/Model!CD114,-99)) | N36: EBITDA % | O36: 0.15670938 | P36: 0.14687798 | Q36: 0.14987453 | R36: 0.15370291 | S36: 0.16049765 | T36: 0.16756612 | V36: 0.13674468 | W36: 0.12528449 | X36: 0.15670938 | Z36: EBITDA % | AA36: 0.15670938 | AB36: 0.14687798 | AC36: 0.15008991 | AD36: 0.15395258 | AE36: 0.16071975 | AF36: 0.16774344 | AH36: 0.13674468 | AI36: 0.12528449 | AJ36: 0.15670938
B38: Net Debt | C38: =Model!CD331 | D38: =Model!CI331 | E38: =Model!CJ331 | F38: =Model!CK331 | G38: =Model!CL331 | H38: =Model!CM331 | N38: Net Debt | O38: 883.473 | P38: 833.49973 | Q38: 747.61427 | R38: 558.13657 | S38: 313.85226 | T38: 46.781922 | Z38: Net Debt | AA38: 883.473 | AB38: 833.49973 | AC38: 683.48142 | AD38: 470.75747 | AE38: 239.31098 | AF38: 13.449972
B39: Net Debt / EBITDA (x) | C39: =IFERROR(C38/C35,"") | D39: =IFERROR(D38/D35,"") | E39: =IFERROR(E38/E35,"") | F39: =IFERROR(F38/F35,"") | G39: =IFERROR(G38/G35,"") | H39: =IFERROR(H38/H35,"") | N39: Net Debt / EBITDA (x) | O39: 1.4602956 | P39: 1.3305486 | Q39: 1.0527897 | R39: 0.70157257 | S39: 0.34886881 | T39: 0.04616655 | Z39: Net Debt / EBITDA (x) | AA39: 1.4602956 | AB39: 1.3305486 | AC39: 1.0299503 | AD39: 0.67117287 | AE39: 0.31787957 | AF39: 0.016627695
B41: ROIC | C41: =Model!CD332 | D41: =Model!CI332 | E41: =Model!CJ332 | F41: =Model!CK332 | G41: =Model!CL332 | H41: =Model!CM332 | J41: =AVERAGE(Model!AF332,Model!AK332,Model!AP332,Model!AU332,Model!AZ332,Model!BE332,Model!BJ332,Model!BO332,Model!BT332,Model!BY332,Model!CD332) | K41: =MIN(Model!AF332,Model!AK332,Model!AP332,Model!AU332,Model!AZ332,Model!BE332,Model!BJ332,Model!BO332,Model!BT332,Model!BY332,Model!CD332) | L41: =MAX(Model!AF332,Model!AK332,Model!AP332,Model!AU332,Model!AZ332,Model!BE332,Model!BJ332,Model!BO332,Model!BT332,Model!BY332,Model!CD332) | N41: ROIC | O41: 0.13102097 | P41: 0.12994009 | Q41: 0.14220323 | R41: 0.15521947 | S41: 0.17077484 | T41: 0.18424991 | V41: 0.10649688 | W41: 0.078655447 | X41: 0.13418059 | Z41: ROIC | AA41: 0.13102097 | AB41: 0.12994009 | AC41: 0.13700201 | AD41: 0.14475876 | AE41: 0.15476995 | AF41: 0.16309349 | AH41: 0.10649688 | AI41: 0.078655447 | AJ41: 0.13418059
B42: RONTA | C42: =Model!CD346 | D42: =Model!CI346 | E42: =Model!CJ346 | F42: =Model!CK346 | G42: =Model!CL346 | H42: =Model!CM346 | J42: =AVERAGE(Model!AF346,Model!AK346,Model!AP346,Model!AU346,Model!AZ346,Model!BE346,Model!BJ346,Model!BO346,Model!BT346,Model!BY346,Model!CD346) | K42: =MIN(Model!AF346,Model!AK346,Model!AP346,Model!AU346,Model!AZ346,Model!BE346,Model!BJ346,Model!BO346,Model!BT346,Model!BY346,Model!CD346) | L42: =MAX(Model!AF346,Model!AK346,Model!AP346,Model!AU346,Model!AZ346,Model!BE346,Model!BJ346,Model!BO346,Model!BT346,Model!BY346,Model!CD346) | N42: RONTA | O42: 0.16117724 | P42: 0.15804571 | Q42: 0.17083277 | R42: 0.18476789 | S42: 0.2012659 | T42: 0.21449288 | V42: 0.14509836 | W42: 0.11691297 | X42: 0.17231893 | Z42: RONTA | AA42: 0.16117724 | AB42: 0.15804571 | AC42: 0.16565843 | AD42: 0.17438244 | AE42: 0.18547154 | AF42: 0.19387151 | AH42: 0.14509836 | AI42: 0.11691297 | AJ42: 0.17231893
B44: Implied Market Cap ($M) | E44: =E27*E21/1000 | F44: =F27*F21/1000 | G44: =G27*G21/1000 | H44: =H27*H21/1000 | N44: Implied Market Cap ($M) | Q44: 8714.9364 | R44: 10038.82 | S44: 11680.45 | T44: 13478.276 | Z44: Implied Market Cap ($M) | AC44: 6607.0032 | AD44: 7146.4369 | AE44: 7876.1743 | AF44: 8665.8241
B45: (+) Net Debt | E45: =E38 | F45: =F38 | G45: =G38 | H45: =H38 | N45: (+) Net Debt | Q45: 747.61427 | R45: 558.13657 | S45: 313.85226 | T45: 46.781922 | Z45: (+) Net Debt | AC45: 683.48142 | AD45: 470.75747 | AE45: 239.31098 | AF45: 13.449972
B46: Implied Enterprise Value ($M) | E46: =E44+E45 | F46: =F44+F45 | G46: =G44+G45 | H46: =H44+H45 | N46: Implied Enterprise Value ($M) | Q46: 9462.5506 | R46: 10596.957 | S46: 11994.302 | T46: 13525.058 | Z46: Implied Enterprise Value ($M) | AC46: 7290.4846 | AD46: 7617.1944 | AE46: 8115.4853 | AF46: 8679.2741
B47: Implied EV / EBITDA (x) | E47: =IFERROR(E46/E35,"") | F47: =IFERROR(F46/F35,"") | G47: =IFERROR(G46/G35,"") | H47: =IFERROR(H46/H35,"") | N47: Implied EV / EBITDA (x) | Q47: 13.325155 | R47: 13.320278 | S47: 13.332509 | T47: 13.347149 | Z47: Implied EV / EBITDA (x) | AC47: 10.986161 | AD47: 10.86006 | AE47: 10.779894 | AF47: 10.72986

Sheet DCF
B2: DCF VALUATION — TFI International (TFII)
B4: 1. WACC BUILD
B5: Risk-free rate (US 10Y govt) | C5: 0.043 | D5: US 10Y Treasury
B6: Equity risk premium | C6: 0.055 | D6: Damodaran global ERP estimate
B7: Levered beta | C7: 1 | D7: TFI International reported beta ~0.9-1.0; industrial A&D peer median
B8: Cost of equity | C8: =C5+C7*C6
B9: Pre-tax cost of debt | C9: 0.05 | D9: TFI International senior notes 5-7Y yield
B10: Tax rate | C10: 0.26 | D10: Long-run normalised effective tax rate
B11: After-tax cost of debt | C11: =C9*(1-C10)
B12: Target D/V | C12: 0.2 | D12: Target leverage; net debt / total capital
B13: WACC | C13: =C8*(1-C12)+C11*C12
B15: Valuation date (live) | C15: =TODAY()
B16: 2. UNLEVERED FREE CASH FLOW BUILD (explicit FY26-FY30, fade FY31-FY40 over CAP = C68 years)
D17: FY26E | E17: FY27E | F17: FY28E | G17: FY29E | H17: FY30E | I17: FY31E | J17: FY32E | K17: FY33E | L17: FY34E | M17: FY35E | N17: FY36E | O17: FY37E | P17: FY38E | Q17: FY39E | R17: FY40E | S17: Terminal | T17: FY26E-40E CAGR
B18: EBIT before special items | D18: =IF(ISNUMBER(Model!CI150),IF(Model!CI150>0,Model!CI150,Model!CI126),Model!CI126) | E18: =IF(ISNUMBER(Model!CJ150),IF(Model!CJ150>0,Model!CJ150,Model!CJ126),Model!CJ126) | F18: =IF(ISNUMBER(Model!CK150),IF(Model!CK150>0,Model!CK150,Model!CK126),Model!CK126) | G18: =IF(ISNUMBER(Model!CL150),IF(Model!CL150>0,Model!CL150,Model!CL126),Model!CL126) | H18: =IF(ISNUMBER(Model!CM150),IF(Model!CM150>0,Model!CM150,Model!CM126),Model!CM126) | I18: =H18*(1+(H18/G18-1)+(($C$27-(H18/G18-1))*1/10)) | J18: =I18*(1+(H18/G18-1)+(($C$27-(H18/G18-1))*2/10)) | K18: =J18*(1+(H18/G18-1)+(($C$27-(H18/G18-1))*3/10)) | L18: =K18*(1+(H18/G18-1)+(($C$27-(H18/G18-1))*4/10)) | M18: =L18*(1+(H18/G18-1)+(($C$27-(H18/G18-1))*5/10)) | N18: =M18*(1+(H18/G18-1)+(($C$27-(H18/G18-1))*6/10)) | O18: =N18*(1+(H18/G18-1)+(($C$27-(H18/G18-1))*7/10)) | P18: =O18*(1+(H18/G18-1)+(($C$27-(H18/G18-1))*8/10)) | Q18: =P18*(1+(H18/G18-1)+(($C$27-(H18/G18-1))*9/10)) | R18: =Q18*(1+$C$27) | T18: =IFERROR((R18/D18)^(1/14)-1,"n/m")
B19: × (1 − tax rate) | D19: =1-$C$10 | E19: =1-$C$10 | F19: =1-$C$10 | G19: =1-$C$10 | H19: =1-$C$10 | I19: =1-$C$10 | J19: =1-$C$10 | K19: =1-$C$10 | ... R19: =1-$C$10
B20: NOPAT | D20: =D18*D19 | E20: =E18*E19 | F20: =F18*F19 | G20: =G18*G19 | H20: =H18*H19 | I20: =I18*I19 | J20: =J18*J19 | K20: =K18*K19 | ... R20: =R18*R19 | T20: =IFERROR((R20/D20)^(1/14)-1,"n/m")
B21: plus D&A | D21: =Model!CI176+Model!CI177 | E21: =Model!CJ176+Model!CJ177 | F21: =Model!CK176+Model!CK177 | G21: =Model!CL176+Model!CL177 | H21: =Model!CM176+Model!CM177 | I21: =H21*(I18/H18) | J21: =I21*(J18/I18) | K21: =J21*(K18/J18) | L21: =K21*(L18/K18) | M21: =L21*(M18/L18) | N21: =M21*(N18/M18) | O21: =N21*(O18/N18) | P21: =O21*(P18/O18) | ... R21: =Q21*(R18/Q18)
B22: − Capex (PP&E + intangibles) | D22: =-ABS(Model!CI189) | E22: =-ABS(Model!CJ189) | F22: =-ABS(Model!CK189) | G22: =-ABS(Model!CL189) | H22: =-ABS(Model!CM189) | I22: =H22*(I18/H18) | J22: =I22*(J18/I18) | K22: =J22*(K18/J18) | L22: =K22*(L18/K18) | M22: =L22*(M18/L18) | N22: =M22*(N18/M18) | O22: =N22*(O18/N18) | P22: =O22*(P18/O18) | ... R22: =Q22*(R18/Q18)
B23: − Δ Working capital | D23: =Model!CI180+Model!CI181+Model!CI182+Model!CI183+Model!CI184 | E23: =Model!CJ180+Model!CJ181+Model!CJ182+Model!CJ183+Model!CJ184 | F23: =Model!CK180+Model!CK181+Model!CK182+Model!CK183+Model!CK184 | G23: =Model!CL180+Model!CL181+Model!CL182+Model!CL183+Model!CL184 | H23: =Model!CM180+Model!CM181+Model!CM182+Model!CM183+Model!CM184 | I23: =H23*(I18/H18) | J23: =I23*(J18/I18) | K23: =J23*(K18/J18) | L23: =K23*(L18/K18) | M23: =L23*(M18/L18) | N23: =M23*(N18/M18) | O23: =N23*(O18/N18) | P23: =O23*(P18/O18) | ... R23: =Q23*(R18/Q18)
B24: Unlevered FCF | D24: =D20+D21+D22+D23 | E24: =E20+E21+E22+E23 | F24: =F20+F21+F22+F23 | G24: =G20+G21+G22+G23 | H24: =H20+H21+H22+H23 | I24: =I20+I21+I22+I23 | J24: =J20+J21+J22+J23 | K24: =K20+K21+K22+K23 | ... R24: =R20+R21+R22+R23 | S24: =R24*(1+$C$27) | T24: =IFERROR((R24/D24)^(1/14)-1,"n/m")
B25: Terminal Value (Gordon Growth) | S25: =S24/($C$13-$C$27)
B27: Terminal growth rate | C27: 0.025
B29: Discount period (year #) | D29: =(DATE(2026+0,12,31)-$C$15)/365.25 | E29: =(DATE(2026+1,12,31)-$C$15)/365.25 | F29: =(DATE(2026+2,12,31)-$C$15)/365.25 | G29: =(DATE(2026+3,12,31)-$C$15)/365.25 | H29: =(DATE(2026+4,12,31)-$C$15)/365.25 | I29: =(DATE(2031,12,31)-$C$15)/365.25 | J29: =(DATE(2032,12,31)-$C$15)/365.25 | K29: =(DATE(2033,12,31)-$C$15)/365.25 | L29: =(DATE(2034,12,31)-$C$15)/365.25 | M29: =(DATE(2035,12,31)-$C$15)/365.25 | N29: =(DATE(2036,12,31)-$C$15)/365.25 | O29: =(DATE(2037,12,31)-$C$15)/365.25 | P29: =(DATE(2038,12,31)-$C$15)/365.25 | Q29: =(DATE(2039,12,31)-$C$15)/365.25 | R29: =(DATE(2040,12,31)-$C$15)/365.25 | S29: =R29
B30: Discount factor | D30: =1/(1+$C$13)^D29 | E30: =1/(1+$C$13)^E29 | F30: =1/(1+$C$13)^F29 | G30: =1/(1+$C$13)^G29 | H30: =1/(1+$C$13)^H29 | I30: =1/(1+$C$13)^I29 | J30: =1/(1+$C$13)^J29 | K30: =1/(1+$C$13)^K29 | ... S30: =1/(1+$C$13)^S29
B31: PV of UFCF | D31: =D24*D30 | E31: =E24*E30 | F31: =F24*F30 | G31: =G24*G30 | H31: =H24*H30 | I31: =I24*I30 | J31: =J24*J30 | K31: =K24*K30 | ... R31: =R24*R30 | S31: =S25*S30
B34: 3. VALUATION SUMMARY
B35: Sum of PV (explicit + fade) | C35: =SUM(D31:R31)
B36: PV of Terminal Value | C36: =S31
B37: Enterprise Value | C37: =C35+C36
B38: Less: Net debt (Model FY26E YE) | C38: =Model!CI331
B39: Equity Value | C39: =C37-C38
B40: Diluted shares ('000) | C40: =Model!CI139
B41: Implied share price ($) | C41: =C39*1000/C40
B42: Current share price ($) | C42: 150
B43: Implied upside / (downside) | C43: =C41/C42-1
B46: 4. SENSITIVITY: IMPLIED PRICE — WACC × Terminal Growth
B48: WACC (across):
B49: g (down) / WACC → | D49: 0.07 | E49: 0.075 | F49: 0.08 | G49: 0.085 | H49: 0.09
B50: 0.02 | D50: {=IFERROR((SUMPRODUCT($D$24:$M$24/(1+D$49)^$D$29:$M$29)+($M$24*(1+$B50)/(D$49-$B50))/(1+D$49)^$M$29-$C$38)*1000/$C$40,"")} | E50: {=IFERROR((SUMPRODUCT($D$24:$M$24/(1+E$49)^$D$29:$M$29)+($M$24*(1+$B50)/(E$49-$B50))/(1+E$49)^$M$29-$C$38)*1000/$C$40,"")} | F50: {=IFERROR((SUMPRODUCT($D$24:$M$24/(1+F$49)^$D$29:$M$29)+($M$24*(1+$B50)/(F$49-$B50))/(1+F$49)^$M$29-$C$38)*1000/$C$40,"")} | G50: {=IFERROR((SUMPRODUCT($D$24:$M$24/(1+G$49)^$D$29:$M$29)+($M$24*(1+$B50)/(G$49-$B50))/(1+G$49)^$M$29-$C$38)*1000/$C$40,"")} | H50: {=IFERROR((SUMPRODUCT($D$24:$M$24/(1+H$49)^$D$29:$M$29)+($M$24*(1+$B50)/(H$49-$B50))/(1+H$49)^$M$29-$C$38)*1000/$C$40,"")}
...

Sheet Charts
B2: TFI International (TFII) — Historical Operating Performance (FY15–FY25)
B3: All historicals · $ millions (USD) · Linked to Model.
C7: 2015 | D7: 2016 | E7: 2017 | F7: 2018 | G7: 2019 | H7: 2020 | I7: 2021 | J7: 2022 | K7: 2023 | L7: 2024 | M7: 2025
B8: Revenue y/y % | C8: 0 | D8: =IFERROR(Model!AK114/Model!AF114-1,"") | E8: =IFERROR(Model!AP114/Model!AK114-1,"") | F8: =IFERROR(Model!AU114/Model!AP114-1,"") | G8: =IFERROR(Model!AZ114/Model!AU114-1,"") | H8: =IFERROR(Model!BE114/Model!AZ114-1,"") | I8: =IFERROR(Model!BJ114/Model!BE114-1,"") | J8: =IFERROR(Model!BO114/Model!BJ114-1,"") | K8: =IFERROR(Model!BT114/Model!BO114-1,"") | L8: =IFERROR(Model!BY114/Model!BT114-1,"") | M8: =IFERROR(Model!CD114/Model!BY114-1,"")
B11: Year | C11: 2015 | D11: 2016 | E11: 2017 | F11: 2018 | G11: 2019 | H11: 2020 | I11: 2021 | J11: 2022 | K11: 2023 | L11: 2024 | M11: 2025
B12: Gross Profit ($M) | C12: =Model!AF116 | D12: =Model!AK116 | E12: =Model!AP116 | F12: =Model!AU116 | G12: =Model!AZ116 | H12: =Model!BE116 | I12: =Model!BJ116 | J12: =Model!BO116 | K12: =Model!BT116 | L12: =Model!BY116 | M12: =Model!CD116
B13: Adj EBIT ($M) | C13: =IF(ISNUMBER(Model!AF150),IF(Model!AF150>0,Model!AF150,Model!AF126),Model!AF126) | D13: =IF(ISNUMBER(Model!AK150),IF(Model!AK150>0,Model!AK150,Model!AK126),Model!AK126) | E13: =IF(ISNUMBER(Model!AP150),IF(Model!AP150>0,Model!AP150,Model!AP126),Model!AP126) | F13: =IF(ISNUMBER(Model!AU150),IF(Model!AU150>0,Model!AU150,Model!AU126),Model!AU126) | G13: =IF(ISNUMBER(Model!AZ150),IF(Model!AZ150>0,Model!AZ150,Model!AZ126),Model!AZ126) | H13: =IF(ISNUMBER(Model!BE150),IF(Model!BE150>0,Model!BE150,Model!BE126),Model!BE126) | I13: =IF(ISNUMBER(Model!BJ150),IF(Model!BJ150>0,Model!BJ150,Model!BJ126),Model!BJ126) | J13: =IF(ISNUMBER(Model!BO150),IF(Model!BO150>0,Model!BO150,Model!BO126),Model!BO126) | K13: =IF(ISNUMBER(Model!BT150),IF(Model!BT150>0,Model!BT150,Model!BT126),Model!BT126) | L13: =IF(ISNUMBER(Model!BY150),IF(Model!BY150>0,Model!BY150,Model!BY126),Model!BY126) | M13: =IF(ISNUMBER(Model!CD150),IF(Model!CD150>0,Model!CD150,Model!CD126),Model!CD126)
B14: Gross margin % | C14: =IFERROR(Model!AF116/Model!AF114,"") | D14: =IFERROR(Model!AK116/Model!AK114,"") | E14: =IFERROR(Model!AP116/Model!AP114,"") | F14: =IFERROR(Model!AU116/Model!AU114,"") | G14: =IFERROR(Model!AZ116/Model!AZ114,"") | H14: =IFERROR(Model!BE116/Model!BE114,"") | I14: =IFERROR(Model!BJ116/Model!BJ114,"") | J14: =IFERROR(Model!BO116/Model!BO114,"") | K14: =IFERROR(Model!BT116/Model!BT114,"") | L14: =IFERROR(Model!BY116/Model!BY114,"") | M14: =IFERROR(Model!CD116/Model!CD114,"")
B15: Adj EBIT margin % | C15: =IFERROR(IF(ISNUMBER(Model!AF150),IF(Model!AF150>0,Model!AF150,Model!AF126),Model!AF126)/Model!AF114,"") | D15: =IFERROR(IF(ISNUMBER(Model!AK150),IF(Model!AK150>0,Model!AK150,Model!AK126),Model!AK126)/Model!AK114,"") | E15: =IFERROR(IF(ISNUMBER(Model!AP150),IF(Model!AP150>0,Model!AP150,Model!AP126),Model!AP126)/Model!AP114,"") | F15: =IFERROR(IF(ISNUMBER(Model!AU150),IF(Model!AU150>0,Model!AU150,Model!AU126),Model!AU126)/Model!AU114,"") | G15: =IFERROR(IF(ISNUMBER(Model!AZ150),IF(Model!AZ150>0,Model!AZ150,Model!AZ126),Model!AZ126)/Model!AZ114,"") | H15: =IFERROR(IF(ISNUMBER(Model!BE150),IF(Model!BE150>0,Model!BE150,Model!BE126),Model!BE126)/Model!BE114,"") | I15: =IFERROR(IF(ISNUMBER(Model!BJ150),IF(Model!BJ150>0,Model!BJ150,Model!BJ126),Model!BJ126)/Model!BJ114,"") | J15: =IFERROR(IF(ISNUMBER(Model!BO150),IF(Model!BO150>0,Model!BO150,Model!BO126),Model!BO126)/Model!BO114,"") | K15: =IFERROR(IF(ISNUMBER(Model!BT150),IF(Model!BT150>0,Model!BT150,Model!BT126),Model!BT126)/Model!BT114,"") | L15: =IFERROR(IF(ISNUMBER(Model!BY150),IF(Model!BY150>0,Model!BY150,Model!BY126),Model!BY126)/Model!BY114,"") | M15: =IFERROR(IF(ISNUMBER(Model!CD150),IF(Model!CD150>0,Model!CD150,Model!CD126),Model!CD126)/Model!CD114,"")
B17: Year | C17: 2015 | D17: 2016 | E17: 2017 | F17: 2018 | G17: 2019 | H17: 2020 | I17: 2021 | J17: 2022 | K17: 2023 | L17: 2024 | M17: 2025
B18: ROIC | C18: =IFERROR(Model!AF332,NA()) | D18: =IFERROR(Model!AK332,NA()) | E18: =IFERROR(Model!AP332,NA()) | F18: =IFERROR(Model!AU332,NA()) | G18: =IFERROR(Model!AZ332,NA()) | H18: =IFERROR(Model!BE332,NA()) | I18: =IFERROR(Model!BJ332,NA()) | J18: =IFERROR(Model!BO332,NA()) | K18: =IFERROR(Model!BT332,NA()) | L18: =IFERROR(Model!BY332,NA()) | M18: =IFERROR(Model!CD332,NA())
B19: RONTA | C19: =IFERROR(Model!AF346,NA()) | D19: =IFERROR(Model!AK346,NA()) | E19: =IFERROR(Model!AP346,NA()) | F19: =IFERROR(Model!AU346,NA()) | G19: =IFERROR(Model!AZ346,NA()) | H19: =IFERROR(Model!BE346,NA()) | I19: =IFERROR(Model!BJ346,NA()) | J19: =IFERROR(Model!BO346,NA()) | K19: =IFERROR(Model!BT346,NA()) | L19: =IFERROR(Model!BY346,NA()) | M19: =IFERROR(Model!CD346,NA())
B20: EBIT / GP (conv ratio) | C20: =IFERROR(IF(ISNUMBER(Model!AF150),IF(Model!AF150>0,Model!AF150,Model!AF126),Model!AF126)/Model!AF116,NA()) | D20: =IFERROR(IF(ISNUMBER(Model!AK150),IF(Model!AK150>0,Model!AK150,Model!AK126),Model!AK126)/Model!AK116,NA()) | E20: =IFERROR(IF(ISNUMBER(Model!AP150),IF(Model!AP150>0,Model!AP150,Model!AP126),Model!AP126)/Model!AP116,NA()) | F20: =IFERROR(IF(ISNUMBER(Model!AU150),IF(Model!AU150>0,Model!AU150,Model!AU126),Model!AU126)/Model!AU116,NA()) | G20: =IFERROR(IF(ISNUMBER(Model!AZ150),IF(Model!AZ150>0,Model!AZ150,Model!AZ126),Model!AZ126)/Model!AZ116,NA()) | H20: =IFERROR(IF(ISNUMBER(Model!BE150),IF(Model!BE150>0,Model!BE150,Model!BE126),Model!BE126)/Model!BE116,NA()) | I20: =IFERROR(IF(ISNUMBER(Model!BJ150),IF(Model!BJ150>0,Model!BJ150,Model!BJ126),Model!BJ126)/Model!BJ116,NA()) | J20: =IFERROR(IF(ISNUMBER(Model!BO150),IF(Model!BO150>0,Model!BO150,Model!BO126),Model!BO126)/Model!BO116,NA()) | K20: =IFERROR(IF(ISNUMBER(Model!BT150),IF(Model!BT150>0,Model!BT150,Model!BT126),Model!BT126)/Model!BT116,NA()) | L20: =IFERROR(IF(ISNUMBER(Model!BY150),IF(Model!BY150>0,Model!BY150,Model!BY126),Model!BY126)/Model!BY116,NA()) | M20: =IFERROR(IF(ISNUMBER(Model!CD150),IF(Model!CD150>0,Model!CD150,Model!CD126),Model!CD126)/Model!CD116,NA())
B21: Incremental EBIT margin | D21: =IFERROR((IF(ISNUMBER(Model!AK150),IF(Model!AK150>0,Model!AK150,Model!AK126),Model!AK126)-IF(ISNUMBER(Model!AF150),IF(Model!AF150>0,Model!AF150,Model!AF126),Model!AF126))/(Model!AK114-Model!AF114),NA()) | E21: =IFERROR((IF(ISNUMBER(Model!AP150),IF(Model!AP150>0,Model!AP150,Model!AP126),Model!AP126)-IF(ISNUMBER(Model!AK150),IF(Model!AK150>0,Model!AK150,Model!AK126),Model!AK126))/(Model!AP114-Model!AK114),NA()) | F21: =IFERROR((IF(ISNUMBER(Model!AU150),IF(Model!AU150>0,Model!AU150,Model!AU126),Model!AU126)-IF(ISNUMBER(Model!AP150),IF(Model!AP150>0,Model!AP150,Model!AP126),Model!AP126))/(Model!AU114-Model!AP114),NA()) | G21: =IFERROR((IF(ISNUMBER(Model!AZ150),IF(Model!AZ150>0,Model!AZ150,Model!AZ126),Model!AZ126)-IF(ISNUMBER(Model!AU150),IF(Model!AU150>0,Model!AU150,Model!AU126),Model!AU126))/(Model!AZ114-Model!AU114),NA()) | H21: =IFERROR((IF(ISNUMBER(Model!BE150),IF(Model!BE150>0,Model!BE150,Model!BE126),Model!BE126)-IF(ISNUMBER(Model!AZ150),IF(Model!AZ150>0,Model!AZ150,Model!AZ126),Model!AZ126))/(Model!BE114-Model!AZ114),NA()) | I21: =IFERROR((IF(ISNUMBER(Model!BJ150),IF(Model!BJ150>0,Model!BJ150,Model!BJ126),Model!BJ126)-IF(ISNUMBER(Model!BE150),IF(Model!BE150>0,Model!BE150,Model!BE126),Model!BE126))/(Model!BJ114-Model!BE114),NA()) | J21: =IFERROR((IF(ISNUMBER(Model!BO150),IF(Model!BO150>0,Model!BO150,Model!BO126),Model!BO126)-IF(ISNUMBER(Model!BJ150),IF(Model!BJ150>0,Model!BJ150,Model!BJ126),Model!BJ126))/(Model!BO114-Model!BJ114),NA()) | K21: =IFERROR((IF(ISNUMBER(Model!BT150),IF(Model!BT150>0,Model!BT150,Model!BT126),Model!BT126)-IF(ISNUMBER(Model!BO150),IF(Model!BO150>0,Model!BO150,Model!BO126),Model!BO126))/(Model!BT114-Model!BO114),NA()) | L21: =IFERROR((IF(ISNUMBER(Model!BY150),IF(Model!BY150>0,Model!BY150,Model!BY126),Model!BY126)-IF(ISNUMBER(Model!BT150),IF(Model!BT150>0,Model!BT150,Model!BT126),Model!BT126))/(Model!BY114-Model!BT114),NA()) | M21: =IFERROR((IF(ISNUMBER(Model!CD150),IF(Model!CD150>0,Model!CD150,Model!CD126),Model!CD126)-IF(ISNUMBER(Model!BY150),IF(Model!BY150>0,Model!BY150,Model!BY126),Model!BY126))/(Model!CD114-Model!BY114),NA())
