Workbook

Sheet Model
CF1: SCENARIO SWITCH ▼ (Bull / Base / Bear) — drives all scenario-linked forecast drivers
B2: C.H. Robinson Worldwide, Inc. (Nasdaq: CHRW) — 3-Statement Financial Model | CF2: Base
B3: US GAAP as reported · USD millions (per-share data in USD; headcount in employees) · Source: C.H. Robinson Forms 10-K / 10-Q and Form 8-K earnings releases (Ex. 99.1; Ex. 99.3 segment recast Jan-2017), Q2-26 earnings presentation (Ex. 99.2), XBRL companyfacts, SEC EDGAR CIK 0001043277 (investor-relations releases are the same documents as filed on EDGAR); RXO deal 8-K 5-Oct-26
B4: Basis notes: calendar fiscal year. Each period as originally reported in its own earnings release. "Gross profits" (to 2008) → "net revenues" (2009–18) → adjusted gross profit (AGP, non-GAAP, 2019+); GAAP gross profit presented from Q1/23 (AGP − direct software amortization). ASC 606 from 2018 (contract assets). Segments (NAST / Global Forwarding / Robinson Fresh / All Other & Corporate) from Q4/16, recast to 2014; Robinson Fresh folded into All Other & Corporate from 2019. T-Chek (payment services) sold Nov-2012; Phoenix International acquired Nov-2012; Freightquote Jan-2015; Prime Distribution 2019; Europe Surface Transportation sold 1-Feb-2025. RXO acquisition (announced 5-Oct-26, close expected 1H27) excluded here — modelled on the RXO PF tab.
CH5: Forecast | CI5: Historical | CJ5: Historical | CK5: Historical
B6: (USDm) | C6: 2006 | D6: 2007 | E6: 2008 | F6: 2009 | G6: 2010 | H6: 2011 | I6: 2012 | J6: Q1/13 | K6: Q2/13 | L6: Q3/13 | M6: Q4/13 | N6: 2013 | O6: Q1/14 | P6: Q2/14 | Q6: Q3/14 | R6: Q4/14 | S6: 2014 | T6: Q1/15 | U6: Q2/15 | V6: Q3/15 | W6: Q4/15 | X6: 2015 | Y6: Q1/16 | Z6: Q2/16 | AA6: Q3/16 | AB6: Q4/16 | AC6: 2016 | AD6: Q1/17 | AE6: Q2/17 | AF6: Q3/17 | AG6: Q4/17 | AH6: 2017 | AI6: Q1/18 | AJ6: Q2/18 | AK6: Q3/18 | AL6: Q4/18 | AM6: 2018 | AN6: Q1/19 | AO6: Q2/19 | AP6: Q3/19 | AQ6: Q4/19 | AR6: 2019 | AS6: Q1/20 | AT6: Q2/20 | AU6: Q3/20 | AV6: Q4/20 | AW6: 2020 | AX6: Q1/21 | AY6: Q2/21 | AZ6: Q3/21 | BA6: Q4/21 | BB6: 2021 | BC6: Q1/22 | BD6: Q2/22 | BE6: Q3/22 | BF6: Q4/22 | BG6: 2022 | BH6: Q1/23 | BI6: Q2/23 | BJ6: Q3/23 | BK6: Q4/23 | BL6: 2023 | BM6: Q1/24 | BN6: Q2/24 | BO6: Q3/24 | BP6: Q4/24 | BQ6: 2024 | BR6: Q1/25 | BS6: Q2/25 | BT6: Q3/25 | BU6: Q4/25 | BV6: 2025 | BW6: Q1/26 | BX6: Q2/26 | BY6: Q3/26E | BZ6: Q4/26E | CA6: 2026E | CB6: 2027E | CC6: 2028E | CD6: 2029E | CE6: 2030E | CF6: Modelling Notes | CH6: 5Y CAGR | CI6: 5Y CAGR | CJ6: 10Y CAGR | CK6: 19Y CAGR
CH7: 25-'30 | CI7: 20-'25 | CJ7: 15-'25 | CK7: 06-'25
B8: SEGMENT P&L — NAST · GLOBAL FORWARDING · ALL OTHER & CORPORATE (volume × AGP-per-shipment build) | CF8: SEGMENT BUILD — modelling logic (volume × AGP per shipment → AGP → AGP margin → revenues; opex via headcount × cost per head)
CN9: SCENARIO INPUT TABLE — driver assumptions per Bull / Base / Bear | CO9: Bull | CP9: Base | CQ9: Bear | CR9: Bull / Bear = Base + Δ (Δ inputs on each block header). Outlook block = high / mid / low end of the FY26 ranges.
B10: North American Surface Transportation (NAST) — truckload, LTL & intermodal brokerage; reportable segment from Q4/16 (recast to 2014) | CF10: NAST — modelling logic
B11: NAST shipment volume y/y % (truckload + LTL) | J11: =IFERROR((J67*J22+J68*J23)/(J67+J68),"") -> 0.095364588 | K11: =IFERROR((K67*K22+K68*K23)/(K67+K68),"") -> 0.088132234 | L11: =IFERROR((L67*L22+L68*L23)/(L67+L68),"") -> 0.11496726 | M11: =IFERROR((M67*M22+M68*M23)/(M67+M68),"") -> 0.064395503 | N11: =IFERROR(AVERAGE(J11,K11,L11,M11),"") -> 0.090714896 | O11: =IFERROR((O67*O22+O68*O23)/(O67+O68),"") -> 0.032709993 | P11: =IFERROR((P67*P22+P68*P23)/(P67+P68),"") -> 0.047226529 | Q11: =IFERROR((Q67*Q22+Q68*Q23)/(Q67+Q68),"") -> 0.020864913 | R11: =IFERROR((R67*R22+R68*R23)/(R67+R68),"") -> 0.031767954 | S11: =IFERROR(AVERAGE(O11,P11,Q11,R11),"") -> 0.033142347 | T11: =IFERROR((T67*T22+T68*T23)/(T67+T68),"") -> 0.10894176 | U11: =IFERROR((U67*U22+U68*U23)/(U67+U68),"") -> 0.12585054 | V11: =IFERROR((V67*V22+V68*V23)/(V67+V68),"") -> 0.12365056 | W11: =IFERROR((W67*W22+W68*W23)/(W67+W68),"") -> 0.11483527 | X11: =IFERROR(AVERAGE(T11,U11,V11,W11),"") -> 0.11831953 | Y11: =IFERROR((Y67*Y22+Y68*Y23)/(Y67+Y68),"") -> 0.045474252 | Z11: =IFERROR((Z67*Z22+Z68*Z23)/(Z67+Z68),"") -> 0.03929209 | AA11: =IFERROR((AA67*AA22+AA68*AA23)/(AA67+AA68),"") -> 0.067864129 | AB11: =IFERROR((AB67*AB22+AB68*AB23)/(AB67+AB68),"") -> 0.087942507 | AC11: =IFERROR(AVERAGE(Y11,Z11,AA11,AB11),"") -> 0.060143245 | AD11: =IFERROR((AD67*AD22+AD68*AD23)/(AD67+AD68),"") -> 0.10392506 | AE11: =IFERROR((AE67*AE22+AE68*AE23)/(AE67+AE68),"") -> 0.076016961 | AF11: =IFERROR((AF67*AF22+AF68*AF23)/(AF67+AF68),"") -> 0.016434927 | AG11: =IFERROR((AG67*AG22+AG68*AG23)/(AG67+AG68),"") -> 0.00059578938 | AH11: =IFERROR(AVERAGE(AD11,AE11,AF11,AG11),"") -> 0.049243186 | AI11: 0.01 | AJ11: =IFERROR((AJ67*AJ22+AJ68*AJ23)/(AJ67+AJ68),"") -> -0.017831084 | AK11: =IFERROR((AK67*AK22+AK68*AK23)/(AK67+AK68),"") -> 0.0072325355 | AL11: =IFERROR((AL67*AL22+AL68*AL23)/(AL67+AL68),"") -> -0.006994319 | AM11: =IFERROR(AVERAGE(AI11,AJ11,AK11,AL11),"") -> -0.0018982168 | AN11: =IFERROR((AN67*AN22+AN68*AN23)/(AN67+AN68),"") -> 0.0061758785 | AO11: =IFERROR((AO67*AO22+AO68*AO23)/(AO67+AO68),"") -> -0.010072157 | AP11: =IFERROR((AP67*AP22+AP68*AP23)/(AP67+AP68),"") -> -0.017488029 | AQ11: =IFERROR((AQ67*AQ22+AQ68*AQ23)/(AQ67+AQ68),"") -> 0.012937462 | AR11: =IFERROR(AVERAGE(AN11,AO11,AP11,AQ11),"") -> -0.0021117113 | AS11: =IFERROR((AS67*AS22+AS68*AS23)/(AS67+AS68),"") -> 0.075 | AT11: =IFERROR((AT67*AT22+AT68*AT23)/(AT67+AT68),"") -> -0.038060609 | AU11: =IFERROR((AU67*AU22+AU68*AU23)/(AU67+AU68),"") -> 0.046697927 | AV11: =IFERROR((AV67*AV22+AV68*AV23)/(AV67+AV68),"") -> 0.035055467 | AW11: =IFERROR(AVERAGE(AS11,AT11,AU11,AV11),"") -> 0.029673196 | AX11: =IFERROR((AX67*AX22+AX68*AX23)/(AX67+AX68),"") -> -0.0030090541 | AY11: 0.16 | AZ11: 0.025 | BA11: 0 | BB11: =IFERROR(AVERAGE(AX11,AY11,AZ11,BA11),"") -> 0.045497736 | BC11: 0.01 | BD11: =IFERROR((BD67*BD22+BD68*BD23)/(BD67+BD68),"") -> 0.0011372843 | BE11: =IFERROR((BE67*BE22+BE68*BE23)/(BE67+BE68),"") -> -0.0007846964 | BF11: -0.02 | BG11: =IFERROR(AVERAGE(BC11,BD11,BE11,BF11),"") -> -0.002411853 | BH11: -0.045 | BI11: -0.025 | BJ11: -0.035 | BK11: -0.01 | BL11: =IFERROR(AVERAGE(BH11,BI11,BJ11,BK11),"") -> -0.02875 | BM11: 0.015 | BN11: 0.015 | BO11: =IFERROR((BO67*BO22+BO68*BO23)/(BO67+BO68),"") -> -0.014673977 | BP11: -0.01 | BQ11: =IFERROR(AVERAGE(BM11,BN11,BO11,BP11),"") -> 0.0013315058 | BR11: -0.01 | BS11: 0.01 | BT11: 0.03 | BU11: 0.01 | BV11: =IFERROR(AVERAGE(BR11,BS11,BT11,BU11),"") -> 0.01 | BW11: 0 | BX11: 0.015 | BY11: =$BX$11 -> 0.015 | BZ11: =$BX$11 -> 0.015 | CA11: =AVERAGE(BW11:BZ11) -> 0.01125 | CB11: =CHOOSE(MATCH($CF$2,{"Bull","Base","Bear"},0),$CO$20,$CP$20,$CQ$20) -> 0.03 | CC11: =CHOOSE(MATCH($CF$2,{"Bull","Base","Bear"},0),$CO$21,$CP$21,$CQ$21) -> 0.035 | CD11: =CHOOSE(MATCH($CF$2,{"Bull","Base","Bear"},0),$CO$22,$CP$22,$CQ$22) -> 0.03 | CE11: =CHOOSE(MATCH($CF$2,{"Bull","Base","Bear"},0),$CO$23,$CP$23,$CQ$23) -> 0.03 | CF11: History: company-stated combined NAST truckload + LTL volume growth (from 2018); earlier quarters = AGP-weighted average of stated TL and LTL volume growth; annual = average of quarters. Q3/26E–Q4/26E: Q2/26 rate (+1.5%). 2027E+: scenario lever NAST_vol. | CN11: FY26 outlook — Q2-26 release & earnings deck (29-Jul-26) | CO11: High | CP11: Mid | CQ11: Low | CR11: CHRW guides operating income (excl. restructuring), tax rate and capex only; no AGP / revenue guidance.
B12: NAST AGP per shipment y/y % (price / mix) | T12: =IFERROR((1+T14)/(1+T11)-1,"") | U12: =IFERROR((1+U14)/(1+U11)-1,"") | V12: =IFERROR((1+V14)/(1+V11)-1,"") | W12: =IFERROR((1+W14)/(1+W11)-1,"") | X12: =IFERROR((1+X14)/(1+X11)-1,"") -> 0.035529255 | Y12: =IFERROR((1+Y14)/(1+Y11)-1,"") -> 0.025404978 | Z12: =IFERROR((1+Z14)/(1+Z11)-1,"") -> -0.03526427 | AA12: =IFERROR((1+AA14)/(1+AA11)-1,"") -> -0.1374788 | ... BX12: =IFERROR((1+BX14)/(1+BX11)-1,"") -> 0.069877054 | BY12: =$BX$12+BY109 -> 0.084715672 | BZ12: =$BX$12+BY109 -> 0.084715672 | CA12: =IFERROR((1+CA14)/(1+CA11)-1,"") -> 0.067873609 | CB12: =CHOOSE(MATCH($CF$2,{"Bull","Base","Bear"},0),$CO$25,$CP$25,$CQ$25) -> 0.04 | CC12: =CHOOSE(MATCH($CF$2,{"Bull","Base","Bear"},0),$CO$26,$CP$26,$CQ$26) -> 0.03 | CD12: =CHOOSE(MATCH($CF$2,{"Bull","Base","Bear"},0),$CO$27,$CP$27,$CQ$27) -> 0.02 | CE12: =CHOOSE(MATCH($CF$2,{"Bull","Base","Bear"},0),$CO$28,$CP$28,$CQ$28) -> 0.02 | CF12: History: implied = (1 + AGP growth) / (1 + volume growth) − 1. Q3/26E–Q4/26E: Q2/26 implied rate + outlook calibration Δ (row "Outlook calibration"). 2027E+: scenario lever NAST_AGPps (contract repricing after the 2026 spot-cost spike, then normalisation). | CN12: FY26 adjusted income from operations target ($m; excl. restructuring & other charges) | CO12: 1040 | CP12: =AVERAGE(CO12,CQ12) -> 1002 | CQ12: 964 | CR12: $964m–$1.04bn "2026 Operating Income Target" (Q2-26 deck slide 17; reiterated). 1H/26 actual $459.2m. Drives the Q3/Q4-26E AGP calibration.
B13: Adjusted gross profit (AGP; "net revenues" to 2018) | S13: 1351.335 | T13: 358.009 | U13: 398.151 | V13: 410.478 | W13: 398.279 | X13: 1564.917 | Y13: 383.798 | Z13: 399.203 | AA13: 378.073 | AB13: 363.281 | AC13: 1524.355 | AD13: 372.44 | AE13: 359.906 | AF13: 377.403 | AG13: 415.315 | AH13: 1525.064 | AI13: 414.769 | AJ13: 436.813 | AK13: 465.522 | AL13: 471.394 | AM13: 1788.498 | AN13: 486.55 | AO13: 486.418 | AP13: 433.76 | AQ13: 390.641 | AR13: 1797.369 | AS13: 372.778 | AT13: 379.556 | AU13: 367.943 | AV13: 396.814 | AW13: 1517.091 | AX13: 421.108 | AY13: 436.596 | AZ13: 460.149 | BA13: 475.1 | BB13: 1792.953 | BC13: 506.1 | BD13: 624.551 | BE13: 563.787 | BF13: 502.266 | BG13: 2196.704 | BH13: 426.655 | BI13: 400.532 | BJ13: 386.51 | BK13: 380.157 | BL13: 1593.854 | BM13: 397.11 | BN13: 419.657 | BO13: 420.664 | BP13: 403.764 | BQ13: 1641.195 | BR13: 418.324 | BS13: 432.248 | BT13: 444.139 | BU13: 411.618 | BV13: 1706.329 | BW13: 431.077 | BX13: 469.389 | BY13: =BT13*(1+BY11)*(1+BY12) -> 488.991 | BZ13: =BU13*(1+BZ11)*(1+BZ12) -> 453.18582 | CA13: =SUM(BW13,BX13,BY13,BZ13) -> 1842.6428 | CB13: =CA13*(1+CB11)*(1+CB12) -> 1973.839 | CC13: =CB13*(1+CC11)*(1+CC12) -> 2104.2111 | CD13: =CC13*(1+CD11)*(1+CD12) -> 2210.6841 | CE13: =CD13*(1+CE11)*(1+CE12) -> 2322.5448 | CF13: Prior-year period × (1 + volume) × (1 + AGP per shipment). Segment AGP as reported (2014–Q3/16 from the FY2016 10-K / 8-K Ex. 99.3 recast). | CH13: =IFERROR((CE13/BV13)^(1/5)-1,"n/m") -> 0.06360474 | CI13: =IFERROR((BV13/AW13)^(1/5)-1,"n/m") -> 0.023788455 | CJ13: =IFERROR((BV13/X13)^(1/10)-1,"n/m") -> 0.0086886785 | CK13: =IFERROR((BV13/C13)^(1/19)-1,"n/m") -> n/m | CN13: FY26 effective tax rate | CO13: 0.18 | CP13: 0.19 | CQ13: 0.2 | CR13: "For 2026, we expect our full-year effective tax rate to be 18% to 20%" (Q2-26 release).
B14: AGP y/y % | D14: =IF(AND(ISNUMBER(D13),ISNUMBER(C13)),IFERROR(D13/C13-1,""),"") | E14: =IF(AND(ISNUMBER(E13),ISNUMBER(D13)),IFERROR(E13/D13-1,""),"") | F14: =IF(AND(ISNUMBER(F13),ISNUMBER(E13)),IFERROR(F13/E13-1,""),"") | G14: =IF(AND(ISNUMBER(G13),ISNUMBER(F13)),IFERROR(G13/F13-1,""),"") | H14: =IF(AND(ISNUMBER(H13),ISNUMBER(G13)),IFERROR(H13/G13-1,""),"") | I14: =IF(AND(ISNUMBER(I13),ISNUMBER(H13)),IFERROR(I13/H13-1,""),"") | N14: =IF(AND(ISNUMBER(N13),ISNUMBER(I13)),IFERROR(N13/I13-1,""),"") | O14: =IF(AND(ISNUMBER(O13),ISNUMBER(J13)),IFERROR(O13/J13-1,""),"") | P14: =IF(AND(ISNUMBER(P13),ISNUMBER(K13)),IFERROR(P13/K13-1,""),"") | Q14: =IF(AND(ISNUMBER(Q13),ISNUMBER(L13)),IFERROR(Q13/L13-1,""),"") | R14: =IF(AND(ISNUMBER(R13),ISNUMBER(M13)),IFERROR(R13/M13-1,""),"") | S14: =IF(AND(ISNUMBER(S13),ISNUMBER(N13)),IFERROR(S13/N13-1,""),"") | T14: =IF(AND(ISNUMBER(T13),ISNUMBER(O13)),IFERROR(T13/O13-1,""),"") | U14: =IF(AND(ISNUMBER(U13),ISNUMBER(P13)),IFERROR(U13/P13-1,""),"") | ... BX14: =IF(AND(ISNUMBER(BX13),ISNUMBER(BS13)),IFERROR(BX13/BS13-1,""),"") -> 0.08592521 | BY14: =IFERROR(BY13/BT13-1,"") -> 0.10098641 | BZ14: =IFERROR(BZ13/BU13-1,"") -> 0.10098641 | CA14: =IFERROR(CA13/BV13-1,"") -> 0.079887188 | CB14: =IFERROR(CB13/CA13-1,"") -> 0.0712 | CC14: =IFERROR(CC13/CB13-1,"") -> 0.06605 | CD14: =IFERROR(CD13/CC13-1,"") -> 0.0506 | CE14: =IFERROR(CE13/CD13-1,"") -> 0.0506 | CN14: FY26 capital expenditures ($m) | CO14: 75 | CP14: 70 | CQ14: 65 | CR14: "Capital expenditures for 2026 are expected to be $65 million to $75 million" (Q2-26 release; cut from $75–85m).
B15: AGP margin % of segment revenues | C15: =IF(AND(ISNUMBER(C13),ISNUMBER(C16)),IFERROR(C13/C16,""),"") | D15: =IF(AND(ISNUMBER(D13),ISNUMBER(D16)),IFERROR(D13/D16,""),"") | E15: =IF(AND(ISNUMBER(E13),ISNUMBER(E16)),IFERROR(E13/E16,""),"") | F15: =IF(AND(ISNUMBER(F13),ISNUMBER(F16)),IFERROR(F13/F16,""),"") | G15: =IF(AND(ISNUMBER(G13),ISNUMBER(G16)),IFERROR(G13/G16,""),"") | H15: =IF(AND(ISNUMBER(H13),ISNUMBER(H16)),IFERROR(H13/H16,""),"") | I15: =IF(AND(ISNUMBER(I13),ISNUMBER(I16)),IFERROR(I13/I16,""),"") | J15: =IF(AND(ISNUMBER(J13),ISNUMBER(J16)),IFERROR(J13/J16,""),"") | ... BX15: =IF(AND(ISNUMBER(BX13),ISNUMBER(BX16)),IFERROR(BX13/BX16,""),"") -> 0.13063008 | BY15: =$BX$15 -> 0.13063008 | BZ15: =$BX$15 -> 0.13063008 | CA15: =IF(AND(ISNUMBER(CA13),ISNUMBER(CA16)),IFERROR(CA13/CA16,""),"") -> 0.13397971 | CB15: 0.135 | CC15: 0.14 | CD15: 0.145 | CE15: 0.145 | CF15: Revenue is an output: AGP ÷ AGP margin. Freight-rate pass-through moves revenue far more than AGP (Q2/26 margin 13.1% vs 14.8% a year earlier as spot costs spiked). Q3/Q4-26E: Q2/26 margin; 2027E+ partial normalisation toward the 2024–25 range (14–15%). | CN15: FY26 point estimates & capital allocation
B16: Total revenues (external) | S16: 8738.747 | T16: 2194.751 | U16: 2319.936 | V16: 2282.235 | W16: 2171.427 | X16: 8968.349 | Y16: 2045.479 | Z16: 2158.615 | AA16: 2252.187 | AB16: 2281.435 | AC16: 8737.716 | AD16: 2259.252 | AE16: 2381.551 | AF16: 2469.42 | AG16: 2618.587 | AH16: 9728.81 | AI16: 2663.011 | AJ16: 2878.904 | AK16: 2931.461 | AL16: 2774.524 | AM16: 11247.9 | AN16: 2796.784 | AO16: 2872.053 | AP16: 2826.308 | AQ16: 2788.547 | AR16: 11283.692 | AS16: 2823.745 | AT16: 2475.292 | AU16: 2923.842 | AV16: 3089.674 | AW16: 11312.553 | AX16: 3211.423 | AY16: 3585.481 | AZ16: 3814.988 | BA16: 3896.025 | BB16: 14507.917 | BC16: 4114.889 | BD16: 4147.046 | BE16: 4002.461 | BF16: 3563.071 | BG16: 15827.467 | BH16: 3304.187 | BI16: 3079.268 | BJ16: 3086.97 | BK16: 3000.65 | BL16: 12471.075 | BM16: 3000.313 | BN16: 2989.909 | BO16: 2934.617 | BP16: 2802.7 | BQ16: 11727.539 | BR16: 2868.42 | BS16: 2918.227 | BT16: 2965.694 | BU16: 2810.373 | BV16: 11562.714 | BW16: 2947.323 | BX16: 3593.269 | BY16: =IF(AND(ISNUMBER(BY13),ISNUMBER(BY15)),IFERROR(BY13/BY15,""),"") -> 3743.3263 | BZ16: =IF(AND(ISNUMBER(BZ13),ISNUMBER(BZ15)),IFERROR(BZ13/BZ15,""),"") -> 3469.2304 | CA16: =SUM(BW16,BX16,BY16,BZ16) -> 13753.149 | CB16: =IF(AND(ISNUMBER(CB13),ISNUMBER(CB15)),IFERROR(CB13/CB15,""),"") -> 14621.03 | CC16: =IF(AND(ISNUMBER(CC13),ISNUMBER(CC15)),IFERROR(CC13/CC15,""),"") -> 15030.079 | CD16: =IF(AND(ISNUMBER(CD13),ISNUMBER(CD15)),IFERROR(CD13/CD15,""),"") -> 15246.098 | CE16: =IF(AND(ISNUMBER(CE13),ISNUMBER(CE15)),IFERROR(CE13/CE15,""),"") -> 16017.55 | CH16: =IFERROR((CE16/BV16)^(1/5)-1,"n/m") -> 0.067351 | CI16: =IFERROR((BV16/AW16)^(1/5)-1,"n/m") -> 0.0043841055 | CJ16: =IFERROR((BV16/X16)^(1/10)-1,"n/m") -> 0.025733946 | CK16: =IFERROR((BV16/C16)^(1/19)-1,"n/m") -> n/m | CN16: 2H/26 share repurchases ($m; ex withholding) | CO16: 350 | CP16: 250 | CQ16: 150 | CR16: 1H/26 repurchases $432m (Q2/26 $226m at $166.89 avg). Standalone case — the RXO PF tab applies the post-close buyback pause.
B17: Revenues y/y % | D17: =IF(AND(ISNUMBER(D16),ISNUMBER(C16)),IFERROR(D16/C16-1,""),"") | E17: =IF(AND(ISNUMBER(E16),ISNUMBER(D16)),IFERROR(E16/D16-1,""),"") | F17: =IF(AND(ISNUMBER(F16),ISNUMBER(E16)),IFERROR(F16/E16-1,""),"") | G17: =IF(AND(ISNUMBER(G16),ISNUMBER(F16)),IFERROR(G16/F16-1,""),"") | H17: =IF(AND(ISNUMBER(H16),ISNUMBER(G16)),IFERROR(H16/G16-1,""),"") | I17: =IF(AND(ISNUMBER(I16),ISNUMBER(H16)),IFERROR(I16/H16-1,""),"") | N17: =IF(AND(ISNUMBER(N16),ISNUMBER(I16)),IFERROR(N16/I16-1,""),"") | O17: =IF(AND(ISNUMBER(O16),ISNUMBER(J16)),IFERROR(O16/J16-1,""),"") | P17: =IF(AND(ISNUMBER(P16),ISNUMBER(K16)),IFERROR(P16/K16-1,""),"") | Q17: =IF(AND(ISNUMBER(Q16),ISNUMBER(L16)),IFERROR(Q16/L16-1,""),"") | R17: =IF(AND(ISNUMBER(R16),ISNUMBER(M16)),IFERROR(R16/M16-1,""),"") | S17: =IF(AND(ISNUMBER(S16),ISNUMBER(N16)),IFERROR(S16/N16-1,""),"") | T17: =IF(AND(ISNUMBER(T16),ISNUMBER(O16)),IFERROR(T16/O16-1,""),"") | U17: =IF(AND(ISNUMBER(U16),ISNUMBER(P16)),IFERROR(U16/P16-1,""),"") | ... BX17: =IF(AND(ISNUMBER(BX16),ISNUMBER(BS16)),IFERROR(BX16/BS16-1,""),"") -> 0.23131922 | BY17: =IFERROR(BY16/BT16-1,"") -> 0.26220923 | BZ17: =IFERROR(BZ16/BU16-1,"") -> 0.23443769 | CA17: =IFERROR(CA16/BV16-1,"") -> 0.18943949 | CB17: =IFERROR(CB16/CA16-1,"") -> 0.063104159 | CC17: =IFERROR(CC16/CB16-1,"") -> 0.027976786 | CD17: =IFERROR(CD16/CC16-1,"") -> 0.014372414 | CE17: =IFERROR(CE16/CD16-1,"") -> 0.0506 | CN17: Minimum net debt / adjusted EBITDA (x) — 2027E+ buyback plug | CO17: 1.5 | CP17: 1.25 | CQ17: 1 | CR17: Standalone: maintain leverage ~1.5x (YE25 ~1.0x; Q2/26 ~1.5x after buybacks & freight-rate working capital). Investment-grade (BBB+/Baa2).
B18: Income from operations (segment, as reported) | S18: 644.708 | T18: 150.093 | U18: 187.063 | V18: 197.209 | W18: 183.964 | X18: 718.329 | Y18: 162.351 | Z18: 182.721 | AA18: 171.733 | AB18: 157.631 | AC18: 674.436 | AD18: 155.877 | AE18: 140.284 | AF18: 151.392 | AG18: 180.557 | AH18: 628.11 | AI18: 174.078 | AJ18: 184.566 | AK18: 204.158 | AL18: 211.044 | AM18: 773.846 | AN18: 211.283 | AO18: 204.732 | AP18: 176.2 | AQ18: 130.548 | AR18: 722.763 | AS18: 98.526 | AT18: 136.846 | AU18: 122.526 | AV18: 150.577 | AW18: 508.475 | AX18: 136.784 | AY18: 151.092 | AZ18: 149.035 | BA18: 148.44 | BB18: 585.351 | BC18: 182.354 | BD18: 276.499 | BE18: 211.899 | BF18: 162.55 | BG18: 833.302 | BH18: 134.022 | BI18: 117.859 | BJ18: 112.121 | BK18: 95.958 | BL18: 459.96 | BM18: 108.895 | BN18: 141.102 | BO18: 148.767 | BP18: 132.528 | BQ18: 531.292 | BR18: 143.671 | BS18: 163.991 | BT18: 172.878 | BU18: 141.296 | BV18: 621.836 | BW18: 145.13 | BX18: 189.845
B19: Operating margin % of AGP (segment, GAAP; mid-cycle target 40%) | C19: =IF(AND(ISNUMBER(C18),ISNUMBER(C13)),IFERROR(C18/C13,""),"") | D19: =IF(AND(ISNUMBER(D18),ISNUMBER(D13)),IFERROR(D18/D13,""),"") | E19: =IF(AND(ISNUMBER(E18),ISNUMBER(E13)),IFERROR(E18/E13,""),"") | F19: =IF(AND(ISNUMBER(F18),ISNUMBER(F13)),IFERROR(F18/F13,""),"") | G19: =IF(AND(ISNUMBER(G18),ISNUMBER(G13)),IFERROR(G18/G13,""),"") | H19: =IF(AND(ISNUMBER(H18),ISNUMBER(H13)),IFERROR(H18/H13,""),"") | I19: =IF(AND(ISNUMBER(I18),ISNUMBER(I13)),IFERROR(I18/I13,""),"") | J19: =IF(AND(ISNUMBER(J18),ISNUMBER(J13)),IFERROR(J18/J13,""),"") | ... BX19: =IF(AND(ISNUMBER(BX18),ISNUMBER(BX13)),IFERROR(BX18/BX13,""),"") -> 0.40445132 | CN19: NAST_vol (NAST truckload + LTL volume y/y) | CO19: 0.02 | CP19: Δ → | CQ19: -0.02 | CR19: Outgrowing the Cass index for 13 straight quarters (Q2/26 +1.5% vs Cass −3.3%). Base assumes freight-cycle recovery from 2027 plus continued share gains.
B20: Average employee headcount | S20: 5447 | T20: 6391 | U20: 6575 | V20: 6723 | W20: 6683 | X20: 6575 | Y20: 6666 | Z20: 6800 | AA20: 6869 | AB20: 6809 | AC20: 6773 | AD20: 6844 | AE20: 7003 | AF20: 6998 | AG20: 6878 | AH20: 6907 | AI20: 6855 | AJ20: 6957 | AK20: 7007 | AL20: 6964 | AM20: 6938 | AN20: 7424 | AO20: 7533 | AP20: 7448 | AQ20: 7154 | AR20: 7354 | AS20: 7038 | AT20: 6960 | AU20: 6702 | AV20: 6555 | AW20: 6811 | AX20: 6537 | AY20: 6580 | AZ20: 6764 | BA20: 7044 | BB20: 6764 | BC20: 7348 | BD20: 7552 | BE20: 7493 | BF20: 7251 | BG20: 7365 | BH20: 6870 | BI20: 6497 | BJ20: 6278 | BK20: 6103 | BL20: 6469 | BM20: 6004 | BN20: 5868 | BO20: 5595 | BP20: 5348 | BQ20: 5696 | BR20: 5280 | BS20: 5283 | BT20: 5187 | BU20: 4970 | BV20: 5158 | BW20: 4752 | BX20: 4671 | CN20: 2027E | CO20: =CP20+$CO$19 -> 0.05 | CP20: 0.03 | CQ20: =CP20+$CQ$19 -> 0.01
B21: AGP per average employee ($000, annualised) | C21: =IFERROR(C13*1/C20*1000,"") | D21: =IFERROR(D13*1/D20*1000,"") | E21: =IFERROR(E13*1/E20*1000,"") | F21: =IFERROR(F13*1/F20*1000,"") | G21: =IFERROR(G13*1/G20*1000,"") | H21: =IFERROR(H13*1/H20*1000,"") | I21: =IFERROR(I13*1/I20*1000,"") | J21: =IFERROR(J13*4/J20*1000,"") | K21: =IFERROR(K13*4/K20*1000,"") | L21: =IFERROR(L13*4/L20*1000,"") | M21: =IFERROR(M13*4/M20*1000,"") | N21: =IFERROR(N13*1/N20*1000,"") | O21: =IFERROR(O13*4/O20*1000,"") | P21: =IFERROR(P13*4/P20*1000,"") | Q21: =IFERROR(Q13*4/Q20*1000,"") | R21: =IFERROR(R13*4/R20*1000,"") | S21: =IFERROR(S13*1/S20*1000,"") -> 248.08794 | T21: =IFERROR(T13*4/T20*1000,"") -> 224.07072 | U21: =IFERROR(U13*4/U20*1000,"") -> 242.22114 | V21: =IFERROR(V13*4/V20*1000,"") -> 244.22311 | W21: =IFERROR(W13*4/W20*1000,"") -> 238.38336 | X21: =IFERROR(X13*1/X20*1000,"") -> 238.01019 | Y21: =IFERROR(Y13*4/Y20*1000,"") -> 230.30183 | Z21: =IFERROR(Z13*4/Z20*1000,"") -> 234.82529 | AA21: =IFERROR(AA13*4/AA20*1000,"") -> 220.16189 | AB21: =IFERROR(AB13*4/AB20*1000,"") -> 213.41225 | AC21: =IFERROR(AC13*1/AC20*1000,"") -> 225.06349 | AD21: =IFERROR(AD13*4/AD20*1000,"") -> 217.67387 | AE21: =IFERROR(AE13*4/AE20*1000,"") -> 205.57247 | AF21: =IFERROR(AF13*4/AF20*1000,"") -> 215.72049 | AG21: =IFERROR(AG13*4/AG20*1000,"") -> 241.53242 | AH21: =IFERROR(AH13*1/AH20*1000,"") -> 220.79977 | AI21: =IFERROR(AI13*4/AI20*1000,"") -> 242.02422 | AJ21: =IFERROR(AJ13*4/AJ20*1000,"") -> 251.15021 | AK21: =IFERROR(AK13*4/AK20*1000,"") -> 265.74682 | AL21: =IFERROR(AL13*4/AL20*1000,"") -> 270.76048 | AM21: =IFERROR(AM13*1/AM20*1000,"") -> 257.78293 | AN21: =IFERROR(AN13*4/AN20*1000,"") -> 262.14978 | AO21: =IFERROR(AO13*4/AO20*1000,"") -> 258.28647 | AP21: =IFERROR(AP13*4/AP20*1000,"") -> 232.95381 | AQ21: =IFERROR(AQ13*4/AQ20*1000,"") -> 218.41823 | AR21: =IFERROR(AR13*1/AR20*1000,"") -> 244.40699 | AS21: =IFERROR(AS13*4/AS20*1000,"") -> 211.86587 | AT21: =IFERROR(AT13*4/AT20*1000,"") -> 218.13563 | AU21: =IFERROR(AU13*4/AU20*1000,"") -> 219.60191 | AV21: =IFERROR(AV13*4/AV20*1000,"") -> 242.14432 | AW21: =IFERROR(AW13*1/AW20*1000,"") -> 222.7413 | AX21: =IFERROR(AX13*4/AX20*1000,"") -> 257.67661 | AY21: =IFERROR(AY13*4/AY20*1000,"") -> 265.4079 | AZ21: =IFERROR(AZ13*4/AZ20*1000,"") -> 272.1165 | BA21: =IFERROR(BA13*4/BA20*1000,"") -> 269.78989 | BB21: =IFERROR(BB13*1/BB20*1000,"") -> 265.07289 | BC21: =IFERROR(BC13*4/BC20*1000,"") -> 275.50354 | BD21: =IFERROR(BD13*4/BD20*1000,"") -> 330.80032 | BE21: =IFERROR(BE13*4/BE20*1000,"") -> 300.9673 | BF21: =IFERROR(BF13*4/BF20*1000,"") -> 277.07406 | BG21: =IFERROR(BG13*1/BG20*1000,"") -> 298.26259 | BH21: =IFERROR(BH13*4/BH20*1000,"") -> 248.4163 | BI21: =IFERROR(BI13*4/BI20*1000,"") -> 246.59504 | BJ21: =IFERROR(BJ13*4/BJ20*1000,"") -> 246.26314 | BK21: =IFERROR(BK13*4/BK20*1000,"") -> 249.16074 | BL21: =IFERROR(BL13*1/BL20*1000,"") -> 246.38337 | BM21: =IFERROR(BM13*4/BM20*1000,"") -> 264.56362 | BN21: =IFERROR(BN13*4/BN20*1000,"") -> 286.06476 | BO21: =IFERROR(BO13*4/BO20*1000,"") -> 300.74281 | BP21: =IFERROR(BP13*4/BP20*1000,"") -> 301.99252 | BQ21: =IFERROR(BQ13*1/BQ20*1000,"") -> 288.13114 | BR21: =IFERROR(BR13*4/BR20*1000,"") -> 316.91212 | BS21: =IFERROR(BS13*4/BS20*1000,"") -> 327.27465 | BT21: =IFERROR(BT13*4/BT20*1000,"") -> 342.50164 | BU21: =IFERROR(BU13*4/BU20*1000,"") -> 331.28209 | BV21: =IFERROR(BV13*1/BV20*1000,"") -> 330.81214 | BW21: =IFERROR(BW13*4/BW20*1000,"") -> 362.85943 | BX21: =IFERROR(BX13*4/BX20*1000,"") -> 401.96018 | CN21: 2028E | CO21: =CP21+$CO$19 -> 0.055 | CP21: 0.035 | CQ21: =CP21+$CQ$19 -> 0.015
B22: Memo: truckload volume y/y % (NAST; company total to Q2/14) | J22: 0.09 | K22: 0.09 | L22: 0.13 | M22: 0.07 | O22: 0.04 | P22: 0.04 | Q22: 0.01 | R22: 0.03 | T22: 0.06 | U22: 0.07 | V22: 0.07 | W22: 0.05 | Y22: 0.03 | Z22: 0.03 | AA22: 0.075 | AB22: 0.1 | AD22: 0.11 | AE22: 0.08 | AF22: 0 | AG22: -0.03 | AI22: -0.07 | AJ22: -0.045 | AK22: -0.005 | AL22: -0.015 | AN22: 0.005 | AO22: -0.025 | AP22: -0.04 | AQ22: 0 | AS22: 0.075 | AT22: -0.045 | AU22: 0.005 | AV22: -0.035 | AX22: -0.065 | AY22: 0.06 | AZ22: 0.045 | BA22: 0.06 | BC22: 0.04 | BD22: 0.02 | BE22: 0.005 | BF22: -0.04 | BH22: -0.035 | BI22: -0.065 | BJ22: -0.06 | BK22: -0.015 | BM22: -0.005 | BN22: 0.015 | BO22: -0.035 | BP22: -0.065 | BR22: -0.045 | BT22: 0.03 | BU22: 0.03 | BW22: -0.035 | BX22: 0.005 | CN22: 2029E | CO22: =CP22+$CO$19 -> 0.05 | CP22: 0.03 | CQ22: =CP22+$CQ$19 -> 0.01
B23: Memo: LTL volume (shipments / orders) y/y % | J23: 0.12 | K23: 0.08 | L23: 0.05 | M23: 0.04 | P23: 0.08 | Q23: 0.07 | R23: 0.04 | T23: 0.28 | U23: 0.33 | V23: 0.32 | W23: 0.36 | Y23: 0.1 | Z23: 0.07 | AA23: 0.045 | AB23: 0.05 | AD23: 0.085 | AE23: 0.065 | AF23: 0.065 | AG23: 0.1 | AI23: 0.08 | AJ23: 0.06 | AK23: 0.045 | AL23: 0.02 | AN23: 0.01 | AO23: 0.035 | AP23: 0.04 | AQ23: 0.045 | AS23: 0.075 | AT23: -0.02 | AU23: 0.135 | AV23: 0.2 | AX23: 0.15 | AY23: 0.235 | AZ23: 0.01 | BA23: -0.04 | BC23: -0.01 | BD23: -0.05 | BE23: -0.015 | BF23: -0.01 | BH23: -0.05 | BI23: 0 | BJ23: -0.02 | BK23: -0.005 | BM23: 0.03 | BN23: 0.015 | BO23: 0.025 | BP23: 0.025 | BR23: 0.01 | BS23: 0.015 | BT23: 0.025 | BU23: 0.005 | BW23: 0.02 | BX23: 0.02 | CN23: 2030E | CO23: =CP23+$CO$19 -> 0.05 | CP23: 0.03 | CQ23: =CP23+$CQ$19 -> 0.01
B24: Memo: truckload AGP per shipment y/y % (per load Q1/21–Q1/22) | AX24: 0.23 | AY24: 0.07 | AZ24: 0.3 | BA24: 0.15 | BC24: 0.15 | BD24: 0.48 | BE24: 0.205 | BF24: 0.065 | BH24: -0.19 | BI24: -0.415 | BJ24: -0.365 | BK24: -0.295 | BM24: -0.095 | BN24: 0.065 | BO24: 0.21 | BP24: 0.17 | BR24: 0.115 | BS24: 0.025 | BU24: -0.03 | BW24: 0.015 | BX24: 0 | CN24: NAST_AGPps (NAST AGP per shipment y/y) | CO24: 0.02 | CP24: Δ → | CQ24: -0.03 | CR24: Contract repricing after the 2026 spot-cost spike (TL cost/mile +29% in Q2/26); company 2026 assumption flat to +4%.
B25: Memo: LTL AGP per order y/y % | AZ25: 0.105 | BA25: 0.235 | BC25: 0.27 | BD25: 0.37 | BE25: 0.245 | BF25: 0.08 | BH25: -0.045 | BI25: -0.19 | BJ25: -0.135 | BK25: -0.085 | BM25: -0.01 | BN25: 0.05 | BO25: 0.01 | BP25: 0.02 | BR25: 0.04 | BS25: 0.03 | BT25: 0.08 | BU25: 0.055 | BW25: 0.085 | BX25: 0.195 | CN25: 2027E | CO25: =CP25+$CO$24 -> 0.06 | CP25: 0.04 | CQ25: =CP25+$CQ$24 -> 0.01
B26: Memo: truckload linehaul price per mile y/y % (ex fuel; all segments) | J26: 0.015 | K26: 0.01 | L26: 0.02 | M26: 0.035 | O26: 0.1 | P26: 0.1 | Q26: 0.1 | R26: 0.12 | T26: 0.06 | U26: 0.03 | V26: 0 | W26: -0.03 | Y26: -0.05 | Z26: -0.075 | AA26: -0.055 | AB26: -0.035 | AD26: -0.04 | AE26: 0 | AF26: 0.065 | AG26: 0.15 | AI26: 0.21 | AJ26: 0.205 | AK26: 0.14 | AL26: 0.015 | AN26: -0.055 | AO26: -0.115 | AP26: -0.125 | AQ26: -0.11 | AS26: -0.085 | AT26: -0.055 | AU26: 0.105 | AV26: 0.29 | AX26: 0.33 | AY26: 0.42 | AZ26: 0.27 | BA26: 0.185 | BC26: 0.205 | BD26: 0.015 | BE26: -0.13 | BF26: -0.21 | BH26: -0.275 | BI26: -0.23 | BJ26: -0.165 | BK26: -0.135 | BM26: -0.075 | BN26: -0.02 | BO26: 0.025 | BP26: 0.06 | BR26: 0.04 | BS26: 0.035 | BT26: -0.015 | BU26: 0.025 | BW26: 0.11 | BX26: 0.255 | CN26: 2028E | CO26: =CP26+$CO$24 -> 0.05 | CP26: 0.03 | CQ26: =CP26+$CQ$24 -> 0
B27: Memo: truckload linehaul cost per mile y/y % (ex fuel; all segments) | J27: 0.025 | K27: 0.01 | L27: 0.04 | M27: 0.05 | O27: 0.12 | P27: 0.09 | Q27: 0.08 | R27: 0.11 | T27: 0.06 | U27: 0.025 | V27: -0.01 | W27: -0.05 | Y27: -0.07 | Z27: -0.08 | AA27: -0.035 | AB27: 0 | AD27: -0.02 | AE27: 0.04 | AF27: 0.085 | AG27: 0.145 | AI27: 0.215 | AJ27: 0.195 | AK27: 0.12 | AL27: -0.01 | AN27: -0.085 | AO27: -0.145 | AP27: -0.12 | AQ27: -0.075 | AS27: -0.025 | AT27: -0.02 | AU27: 0.165 | AV27: 0.325 | AX27: 0.335 | AY27: 0.475 | AZ27: 0.26 | BA27: 0.18 | BC27: 0.21 | BD27: -0.05 | BE27: -0.17 | BF27: -0.24 | BH27: -0.285 | BI27: -0.19 | BJ27: -0.135 | BK27: -0.105 | BM27: -0.075 | BN27: -0.035 | BO27: -0.005 | BP27: 0.04 | BR27: 0.03 | BS27: 0.035 | BT27: -0.015 | BU27: 0.025 | BW27: 0.13 | BX27: 0.29 | CN27: 2029E | CO27: =CP27+$CO$24 -> 0.04 | CP27: 0.02 | CQ27: =CP27+$CQ$24 -> -0.01
CN28: 2030E | CO28: =CP28+$CO$24 -> 0.04 | CP28: 0.02 | CQ28: =CP28+$CQ$24 -> -0.01
B29: Global Forwarding (GF) — ocean, air, customs & other; reportable segment from Q4/16 (recast to 2014) | CF29: GLOBAL FORWARDING — modelling logic | CN29: GF_vol (ocean shipments y/y) | CO29: 0.02 | CP29: Δ → | CQ29: -0.03 | CR29: Ocean +1.0% in Q2/26; trade-policy volatility.
B30: GF volume y/y % (ocean shipments) | U30: 0 | AN30: 0 | AR30: =IFERROR(AVERAGE(AN30,AO30,AP30,AQ30),"") -> 0 | AS30: -0.03 | AT30: -0.085 | AU30: 0.015 | AV30: 0.12 | AW30: =IFERROR(AVERAGE(AS30,AT30,AU30,AV30),"") -> 0.005 | AX30: 0.27 | AY30: 0.29 | AZ30: 0.12 | BA30: 0.05 | BB30: =IFERROR(AVERAGE(AX30,AY30,AZ30,BA30),"") -> 0.1825 | BC30: 0.07 | BD30: 0.025 | BE30: -0.025 | BF30: -0.095 | BG30: =IFERROR(AVERAGE(BC30,BD30,BE30,BF30),"") -> -0.00625 | BH30: -0.145 | BI30: -0.07 | BJ30: -0.005 | BK30: 0.04 | BL30: =IFERROR(AVERAGE(BH30,BI30,BJ30,BK30),"") -> -0.045 | BM30: 0.07 | BN30: 0.04 | BO30: 0.07 | BP30: 0.035 | BQ30: =IFERROR(AVERAGE(BM30,BN30,BO30,BP30),"") -> 0.05375 | BR30: 0.015 | BS30: -0.04 | BT30: -0.07 | BU30: -0.08 | BV30: =IFERROR(AVERAGE(BR30,BS30,BT30,BU30),"") -> -0.04375 | BW30: -0.105 | BX30: 0.01 | BY30: =$BX$30 -> 0.01 | BZ30: =$BX$30 -> 0.01 | CA30: =AVERAGE(BW30:BZ30) -> -0.01875 | CB30: =CHOOSE(MATCH($CF$2,{"Bull","Base","Bear"},0),$CO$30,$CP$30,$CQ$30) -> 0.02 | CC30: =CHOOSE(MATCH($CF$2,{"Bull","Base","Bear"},0),$CO$31,$CP$31,$CQ$31) -> 0.03 | CD30: =CHOOSE(MATCH($CF$2,{"Bull","Base","Bear"},0),$CO$32,$CP$32,$CQ$32) -> 0.03 | CE30: =CHOOSE(MATCH($CF$2,{"Bull","Base","Bear"},0),$CO$33,$CP$33,$CQ$33) -> 0.03 | CF30: Ocean shipment growth as the GF volume proxy (ocean ≈ 55–60% of GF AGP). Disclosed from 2019 (2015 flat). Q3/26E–Q4/26E: Q2/26 rate; 2027E+: scenario lever GF_vol. | CN30: 2027E | CO30: =CP30+$CO$29 -> 0.04 | CP30: 0.02 | CQ30: =CP30+$CQ$29 -> -0.01
B31: GF AGP per shipment y/y % (rate / mix) | AN31: =IFERROR((1+AN33)/(1+AN30)-1,"") -> 0.034127945 | AO31: =IFERROR((1+AO33)/(1+AO30)-1,"") -> -0.01454548 | AP31: =IFERROR((1+AP33)/(1+AP30)-1,"") -> 0.012781411 | AQ31: =IFERROR((1+AQ33)/(1+AQ30)-1,"") -> -0.096317003 | AR31: =IFERROR((1+AR33)/(1+AR30)-1,"") -> -0.018256831 | AS31: =IFERROR((1+AS33)/(1+AS30)-1,"") -> 0.039662314 | AT31: =IFERROR((1+AT33)/(1+AT30)-1,"") -> 0.25477934 | AU31: =IFERROR((1+AU33)/(1+AU30)-1,"") -> 0.14366671 | ... BX31: =IFERROR((1+BX33)/(1+BX30)-1,"") -> -0.0033084585 | BY31: =$BX$31+BY109 -> 0.01153016 | BZ31: =$BX$31+BY109 -> 0.01153016 | CA31: =IFERROR((1+CA33)/(1+CA30)-1,"") -> 0.001134058 | CB31: =CHOOSE(MATCH($CF$2,{"Bull","Base","Bear"},0),$CO$35,$CP$35,$CQ$35) -> 0 | CC31: =CHOOSE(MATCH($CF$2,{"Bull","Base","Bear"},0),$CO$36,$CP$36,$CQ$36) -> 0.01 | CD31: =CHOOSE(MATCH($CF$2,{"Bull","Base","Bear"},0),$CO$37,$CP$37,$CQ$37) -> 0.015 | CE31: =CHOOSE(MATCH($CF$2,{"Bull","Base","Bear"},0),$CO$38,$CP$38,$CQ$38) -> 0.015 | CF31: Implied = (1 + AGP growth) / (1 + volume) − 1 (captures ocean/air rate cycles: 2021–22 spike, 2023 reset, 2024 Red Sea). 2027E+: scenario lever GF_AGPps. | CN31: 2028E | CO31: =CP31+$CO$29 -> 0.05 | CP31: 0.03 | CQ31: =CP31+$CQ$29 -> 0
B32: Adjusted gross profit (AGP) | S32: 350.193 | T32: 86.333 | U32: 94.846 | V32: 94.797 | W32: 89.491 | X32: 365.467 | Y32: 92.866 | Z32: 97.224 | AA32: 93.368 | AB32: 114.079 | AC32: 397.537 | AD32: 106.546 | AE32: 121.023 | AF32: 129.842 | AG32: 127.869 | AH32: 485.28 | AI32: 123.037 | AJ32: 144.031 | AK32: 134.101 | AL32: 142.737 | AM32: 543.906 | AN32: 127.236 | AO32: 141.936 | AP32: 135.815 | AQ32: 128.989 | AR32: 533.976 | AS32: 128.314 | AT32: 162.96 | AU32: 157.657 | AV32: 180.057 | AW32: 628.988 | AX32: 214.3 | AY32: 238.754 | AZ32: 310.898 | BA32: 309.589 | BB32: 1073.541 | BC32: 321.848 | BD32: 324.443 | BE32: 248.433 | BF32: 188.749 | BG32: 1083.473 | BH32: 177.919 | BI32: 179.231 | BJ32: 169.893 | BK32: 162.322 | BL32: 689.365 | BM32: 180.045 | BN32: 184.067 | BO32: 234.636 | BP32: 203.801 | BQ32: 802.549 | BR32: 184.628 | BS32: 187.581 | BT32: 191.755 | BU32: 177.957 | BV32: 741.921 | BW32: 162.291 | BX32: 188.83 | BY32: =BT32*(1+BY30)*(1+BY31) -> 195.90563 | BZ32: =BU32*(1+BZ30)*(1+BZ31) -> 181.80896 | CA32: =SUM(BW32,BX32,BY32,BZ32) -> 728.83559 | CB32: =CA32*(1+CB30)*(1+CB31) -> 743.4123 | CC32: =CB32*(1+CC30)*(1+CC31) -> 773.37181 | CD32: =CC32*(1+CD30)*(1+CD31) -> 808.52156 | CE32: =CD32*(1+CE30)*(1+CE31) -> 845.26887 | CH32: =IFERROR((CE32/BV32)^(1/5)-1,"n/m") -> 0.026425522 | CI32: =IFERROR((BV32/AW32)^(1/5)-1,"n/m") -> 0.033577534 | CJ32: =IFERROR((BV32/X32)^(1/10)-1,"n/m") -> 0.073373699 | CK32: =IFERROR((BV32/C32)^(1/19)-1,"n/m") -> n/m | CN32: 2029E | CO32: =CP32+$CO$29 -> 0.05 | CP32: 0.03 | CQ32: =CP32+$CQ$29 -> 0
B33: AGP y/y % | D33: =IF(AND(ISNUMBER(D32),ISNUMBER(C32)),IFERROR(D32/C32-1,""),"") | E33: =IF(AND(ISNUMBER(E32),ISNUMBER(D32)),IFERROR(E32/D32-1,""),"") | F33: =IF(AND(ISNUMBER(F32),ISNUMBER(E32)),IFERROR(F32/E32-1,""),"") | G33: =IF(AND(ISNUMBER(G32),ISNUMBER(F32)),IFERROR(G32/F32-1,""),"") | H33: =IF(AND(ISNUMBER(H32),ISNUMBER(G32)),IFERROR(H32/G32-1,""),"") | I33: =IF(AND(ISNUMBER(I32),ISNUMBER(H32)),IFERROR(I32/H32-1,""),"") | N33: =IF(AND(ISNUMBER(N32),ISNUMBER(I32)),IFERROR(N32/I32-1,""),"") | O33: =IF(AND(ISNUMBER(O32),ISNUMBER(J32)),IFERROR(O32/J32-1,""),"") | P33: =IF(AND(ISNUMBER(P32),ISNUMBER(K32)),IFERROR(P32/K32-1,""),"") | Q33: =IF(AND(ISNUMBER(Q32),ISNUMBER(L32)),IFERROR(Q32/L32-1,""),"") | R33: =IF(AND(ISNUMBER(R32),ISNUMBER(M32)),IFERROR(R32/M32-1,""),"") | S33: =IF(AND(ISNUMBER(S32),ISNUMBER(N32)),IFERROR(S32/N32-1,""),"") | T33: =IF(AND(ISNUMBER(T32),ISNUMBER(O32)),IFERROR(T32/O32-1,""),"") | U33: =IF(AND(ISNUMBER(U32),ISNUMBER(P32)),IFERROR(U32/P32-1,""),"") | ... BX33: =IF(AND(ISNUMBER(BX32),ISNUMBER(BS32)),IFERROR(BX32/BS32-1,""),"") -> 0.0066584569 | BY33: =IFERROR(BY32/BT32-1,"") -> 0.021645461 | BZ33: =IFERROR(BZ32/BU32-1,"") -> 0.021645461 | CA33: =IFERROR(CA32/BV32-1,"") -> -0.017637206 | CB33: =IFERROR(CB32/CA32-1,"") -> 0.02 | CC33: =IFERROR(CC32/CB32-1,"") -> 0.0403 | CD33: =IFERROR(CD32/CC32-1,"") -> 0.04545 | CE33: =IFERROR(CE32/CD32-1,"") -> 0.04545 | CN33: 2030E | CO33: =CP33+$CO$29 -> 0.05 | CP33: 0.03 | CQ33: =CP33+$CQ$29 -> 0
B34: AGP margin % of segment revenues | C34: =IF(AND(ISNUMBER(C32),ISNUMBER(C35)),IFERROR(C32/C35,""),"") | D34: =IF(AND(ISNUMBER(D32),ISNUMBER(D35)),IFERROR(D32/D35,""),"") | E34: =IF(AND(ISNUMBER(E32),ISNUMBER(E35)),IFERROR(E32/E35,""),"") | F34: =IF(AND(ISNUMBER(F32),ISNUMBER(F35)),IFERROR(F32/F35,""),"") | G34: =IF(AND(ISNUMBER(G32),ISNUMBER(G35)),IFERROR(G32/G35,""),"") | H34: =IF(AND(ISNUMBER(H32),ISNUMBER(H35)),IFERROR(H32/H35,""),"") | I34: =IF(AND(ISNUMBER(I32),ISNUMBER(I35)),IFERROR(I32/I35,""),"") | J34: =IF(AND(ISNUMBER(J32),ISNUMBER(J35)),IFERROR(J32/J35,""),"") | ... BX34: =IF(AND(ISNUMBER(BX32),ISNUMBER(BX35)),IFERROR(BX32/BX35,""),"") -> 0.2106058 | BY34: =$BX$34 -> 0.2106058 | BZ34: =$BX$34 -> 0.2106058 | CA34: =IF(AND(ISNUMBER(CA32),ISNUMBER(CA35)),IFERROR(CA32/CA35,""),"") -> 0.2172515 | CB34: 0.22 | CC34: 0.225 | CD34: 0.225 | CE34: 0.225 | CF34: Q2/26 21.1% (air rates up); 2023–25 range 22–24%. | CN34: GF_AGPps (GF AGP per shipment y/y) | CO34: 0.03 | CP34: Δ → | CQ34: -0.04 | CR34: Company 2026 assumption: GF AGP/shipment reset to 2H/23 levels (−10%); air rates elevated in 2026.
B35: Total revenues (external) | S35: 1708.789 | T35: 411.451 | U35: 431.098 | V35: 420.628 | W35: 376.767 | X35: 1639.944 | Y35: 351.112 | Z35: 356.773 | AA35: 390.83 | AB35: 475.971 | AC35: 1574.686 | AD35: 468.788 | AE35: 528.82 | AF35: 552.134 | AG35: 591.245 | AH35: 2140.987 | AI35: 553.754 | AJ35: 617.597 | AK35: 639.268 | AL35: 677.125 | AM35: 2487.744 | AN35: 537.567 | AO35: 592.483 | AP35: 597.695 | AQ35: 600.168 | AR35: 2327.913 | AS35: 530.384 | AT35: 707.82 | AU35: 831.957 | AV35: 1030.364 | AW35: 3100.525 | AX35: 1156.039 | AY35: 1450.794 | AZ35: 1978.901 | BA35: 2144.056 | BB35: 6729.79 | BC35: 2194.397 | BD35: 2093.19 | BE35: 1511.115 | BF35: 1013.306 | BG35: 6812.008 | BH35: 789.978 | BI35: 779.867 | BJ35: 719.045 | BK35: 708.814 | BL35: 2997.704 | BM35: 858.637 | BN35: 921.223 | BO35: 1141.19 | BP35: 883.968 | BQ35: 3805.018 | BR35: 774.888 | BS35: 797.8 | BT35: 786.347 | BU35: 730.983 | BV35: 3090.018 | BW35: 664.73 | BX35: 896.604 | BY35: =IF(AND(ISNUMBER(BY32),ISNUMBER(BY34)),IFERROR(BY32/BY34,""),"") -> 930.20054 | BZ35: =IF(AND(ISNUMBER(BZ32),ISNUMBER(BZ34)),IFERROR(BZ32/BZ34,""),"") -> 863.26665 | CA35: =SUM(BW35,BX35,BY35,BZ35) -> 3354.8012 | CB35: =IF(AND(ISNUMBER(CB32),ISNUMBER(CB34)),IFERROR(CB32/CB34,""),"") -> 3379.1468 | CC35: =IF(AND(ISNUMBER(CC32),ISNUMBER(CC34)),IFERROR(CC32/CC34,""),"") -> 3437.2081 | CD35: =IF(AND(ISNUMBER(CD32),ISNUMBER(CD34)),IFERROR(CD32/CD34,""),"") -> 3593.4292 | CE35: =IF(AND(ISNUMBER(CE32),ISNUMBER(CE34)),IFERROR(CE32/CE34,""),"") -> 3756.7505 | CH35: =IFERROR((CE35/BV35)^(1/5)-1,"n/m") -> 0.039848978 | CI35: =IFERROR((BV35/AW35)^(1/5)-1,"n/m") -> -0.00067867677 | CJ35: =IFERROR((BV35/X35)^(1/10)-1,"n/m") -> 0.065401243 | CK35: =IFERROR((BV35/C35)^(1/19)-1,"n/m") -> n/m | CN35: 2027E | CO35: =CP35+$CO$34 -> 0.03 | CP35: 0 | CQ35: =CP35+$CQ$34 -> -0.04
B36: Revenues y/y % | D36: =IF(AND(ISNUMBER(D35),ISNUMBER(C35)),IFERROR(D35/C35-1,""),"") | E36: =IF(AND(ISNUMBER(E35),ISNUMBER(D35)),IFERROR(E35/D35-1,""),"") | F36: =IF(AND(ISNUMBER(F35),ISNUMBER(E35)),IFERROR(F35/E35-1,""),"") | G36: =IF(AND(ISNUMBER(G35),ISNUMBER(F35)),IFERROR(G35/F35-1,""),"") | H36: =IF(AND(ISNUMBER(H35),ISNUMBER(G35)),IFERROR(H35/G35-1,""),"") | I36: =IF(AND(ISNUMBER(I35),ISNUMBER(H35)),IFERROR(I35/H35-1,""),"") | N36: =IF(AND(ISNUMBER(N35),ISNUMBER(I35)),IFERROR(N35/I35-1,""),"") | O36: =IF(AND(ISNUMBER(O35),ISNUMBER(J35)),IFERROR(O35/J35-1,""),"") | P36: =IF(AND(ISNUMBER(P35),ISNUMBER(K35)),IFERROR(P35/K35-1,""),"") | Q36: =IF(AND(ISNUMBER(Q35),ISNUMBER(L35)),IFERROR(Q35/L35-1,""),"") | R36: =IF(AND(ISNUMBER(R35),ISNUMBER(M35)),IFERROR(R35/M35-1,""),"") | S36: =IF(AND(ISNUMBER(S35),ISNUMBER(N35)),IFERROR(S35/N35-1,""),"") | T36: =IF(AND(ISNUMBER(T35),ISNUMBER(O35)),IFERROR(T35/O35-1,""),"") | U36: =IF(AND(ISNUMBER(U35),ISNUMBER(P35)),IFERROR(U35/P35-1,""),"") | ... BX36: =IF(AND(ISNUMBER(BX35),ISNUMBER(BS35)),IFERROR(BX35/BS35-1,""),"") -> 0.12384558 | BY36: =IFERROR(BY35/BT35-1,"") -> 0.182939 | BZ36: =IFERROR(BZ35/BU35-1,"") -> 0.1809668 | CA36: =IFERROR(CA35/BV35-1,"") -> 0.085689853 | CB36: =IFERROR(CB35/CA35-1,"") -> 0.0072569493 | CC36: =IFERROR(CC35/CB35-1,"") -> 0.017182222 | CD36: =IFERROR(CD35/CC35-1,"") -> 0.04545 | CE36: =IFERROR(CE35/CD35-1,"") -> 0.04545 | CN36: 2028E | CO36: =CP36+$CO$34 -> 0.04 | CP36: 0.01 | CQ36: =CP36+$CQ$34 -> -0.03
B37: Income from operations (segment, as reported) | S37: 55.591 | T37: 13.973 | U37: 20.904 | V37: 22.477 | W37: 18.727 | X37: 76.081 | Y37: 16.857 | Z37: 22.396 | AA37: 17.047 | AB37: 24.631 | AC37: 80.931 | AD37: 16.206 | AE37: 27.675 | AF37: 31.125 | AG37: 16.836 | AH37: 91.842 | AI37: 8.221 | AJ37: 29.788 | AK37: 23.835 | AL37: 29.782 | AM37: 91.626 | AN37: 14.203 | AO37: 26.618 | AP37: 24.676 | AQ37: 15.03 | AR37: 80.527 | AS37: 11.959 | AT37: 58.775 | AU37: 46.299 | AV37: 58.48 | AW37: 175.513 | AX37: 90.589 | AY37: 108.212 | AZ37: 165.155 | BA37: 146.8 | BB37: 510.756 | BC37: 167.638 | BD37: 167.557 | BE37: 85.953 | BF37: 28.216 | BG37: 449.364 | BH37: 30.116 | BI37: 29.647 | BJ37: 3.491 | BK37: 22.576 | BL37: 85.83 | BM37: 31.552 | BN37: 40.982 | BO37: 88.115 | BP37: 51.827 | BQ37: 212.476 | BR37: 42.943 | BS37: 51.33 | BT37: 49.021 | BU37: 40.489 | BV37: 183.783 | BW37: 31.684 | BX37: 60.97 | CN37: 2029E | CO37: =CP37+$CO$34 -> 0.045 | CP37: 0.015 | CQ37: =CP37+$CQ$34 -> -0.025
B38: Operating margin % of AGP (segment, GAAP; mid-cycle target 30%) | C38: =IF(AND(ISNUMBER(C37),ISNUMBER(C32)),IFERROR(C37/C32,""),"") | D38: =IF(AND(ISNUMBER(D37),ISNUMBER(D32)),IFERROR(D37/D32,""),"") | E38: =IF(AND(ISNUMBER(E37),ISNUMBER(E32)),IFERROR(E37/E32,""),"") | F38: =IF(AND(ISNUMBER(F37),ISNUMBER(F32)),IFERROR(F37/F32,""),"") | G38: =IF(AND(ISNUMBER(G37),ISNUMBER(G32)),IFERROR(G37/G32,""),"") | H38: =IF(AND(ISNUMBER(H37),ISNUMBER(H32)),IFERROR(H37/H32,""),"") | I38: =IF(AND(ISNUMBER(I37),ISNUMBER(I32)),IFERROR(I37/I32,""),"") | J38: =IF(AND(ISNUMBER(J37),ISNUMBER(J32)),IFERROR(J37/J32,""),"") | ... BX38: =IF(AND(ISNUMBER(BX37),ISNUMBER(BX32)),IFERROR(BX37/BX32,""),"") -> 0.32288302 | CN38: 2030E | CO38: =CP38+$CO$34 -> 0.045 | CP38: 0.015 | CQ38: =CP38+$CQ$34 -> -0.025
B39: Average employee headcount | S39: 3202 | T39: 3294 | U39: 3350 | V39: 3422 | W39: 3455 | X39: 3381 | Y39: 3488 | Z39: 3514 | AA39: 3559 | AB39: 3934 | AC39: 3673 | AD39: 3926 | AE39: 4021 | AF39: 4301 | AG39: 4683 | AH39: 4310 | AI39: 4767 | AJ39: 4736 | AK39: 4684 | AL39: 4664 | AM39: 4711 | AN39: 4707 | AO39: 4770 | AP39: 4790 | AQ39: 4824 | AR39: 4766 | AS39: 4824 | AT39: 4726 | AU39: 4607 | AV39: 4626 | AW39: 4708 | AX39: 4735 | AY39: 4909 | AZ39: 5167 | BA39: 5430 | BB39: 5071 | BC39: 5610 | BD39: 5759 | BE39: 5861 | BF39: 5745 | BG39: 5712 | BH39: 5471 | BI39: 5225 | BJ39: 5082 | BK39: 5021 | BL39: 5222 | BM39: 4876 | BN39: 4652 | BO39: 4552 | BP39: 4542 | BQ39: 4678 | BR39: 4514 | BS39: 4436 | BT39: 4245 | BU39: 4007 | BV39: 4284 | BW39: 3848 | BX39: 3699 | CN39: AO_growth (All Other & Corporate AGP y/y) | CO39: 0.02 | CP39: Δ → | CQ39: -0.03 | CR39: Robinson Fresh foodservice wins; Managed Solutions freight under management ($2.1bn in Q2/26).
B40: AGP per average employee ($000, annualised) | C40: =IFERROR(C32*1/C39*1000,"") | D40: =IFERROR(D32*1/D39*1000,"") | E40: =IFERROR(E32*1/E39*1000,"") | F40: =IFERROR(F32*1/F39*1000,"") | G40: =IFERROR(G32*1/G39*1000,"") | H40: =IFERROR(H32*1/H39*1000,"") | I40: =IFERROR(I32*1/I39*1000,"") | J40: =IFERROR(J32*4/J39*1000,"") | K40: =IFERROR(K32*4/K39*1000,"") | L40: =IFERROR(L32*4/L39*1000,"") | M40: =IFERROR(M32*4/M39*1000,"") | N40: =IFERROR(N32*1/N39*1000,"") | O40: =IFERROR(O32*4/O39*1000,"") | P40: =IFERROR(P32*4/P39*1000,"") | Q40: =IFERROR(Q32*4/Q39*1000,"") | R40: =IFERROR(R32*4/R39*1000,"") | S40: =IFERROR(S32*1/S39*1000,"") -> 109.36696 | T40: =IFERROR(T32*4/T39*1000,"") -> 104.83667 | U40: =IFERROR(U32*4/U39*1000,"") -> 113.24896 | V40: =IFERROR(V32*4/V39*1000,"") -> 110.80888 | W40: =IFERROR(W32*4/W39*1000,"") -> 103.60753 | X40: =IFERROR(X32*1/X39*1000,"") -> 108.09435 | Y40: =IFERROR(Y32*4/Y39*1000,"") -> 106.49771 | Z40: =IFERROR(Z32*4/Z39*1000,"") -> 110.67046 | AA40: =IFERROR(AA32*4/AA39*1000,"") -> 104.93734 | AB40: =IFERROR(AB32*4/AB39*1000,"") -> 115.99288 | AC40: =IFERROR(AC32*1/AC39*1000,"") -> 108.23224 | AD40: =IFERROR(AD32*4/AD39*1000,"") -> 108.55425 | AE40: =IFERROR(AE32*4/AE39*1000,"") -> 120.39095 | AF40: =IFERROR(AF32*4/AF39*1000,"") -> 120.75517 | AG40: =IFERROR(AG32*4/AG39*1000,"") -> 109.21973 | AH40: =IFERROR(AH32*1/AH39*1000,"") -> 112.59397 | AI40: =IFERROR(AI32*4/AI39*1000,"") -> 103.24061 | AJ40: =IFERROR(AJ32*4/AJ39*1000,"") -> 121.6478 | AK40: =IFERROR(AK32*4/AK39*1000,"") -> 114.51836 | AL40: =IFERROR(AL32*4/AL39*1000,"") -> 122.41595 | AM40: =IFERROR(AM32*1/AM39*1000,"") -> 115.45447 | AN40: =IFERROR(AN32*4/AN39*1000,"") -> 108.12492 | AO40: =IFERROR(AO32*4/AO39*1000,"") -> 119.0239 | AP40: =IFERROR(AP32*4/AP39*1000,"") -> 113.41545 | AQ40: =IFERROR(AQ32*4/AQ39*1000,"") -> 106.95605 | AR40: =IFERROR(AR32*1/AR39*1000,"") -> 112.03861 | AS40: =IFERROR(AS32*4/AS39*1000,"") -> 106.39635 | AT40: =IFERROR(AT32*4/AT39*1000,"") -> 137.92636 | AU40: =IFERROR(AU32*4/AU39*1000,"") -> 136.88474 | AV40: =IFERROR(AV32*4/AV39*1000,"") -> 155.69131 | AW40: =IFERROR(AW32*1/AW39*1000,"") -> 133.59983 | AX40: =IFERROR(AX32*4/AX39*1000,"") -> 181.03485 | AY40: =IFERROR(AY32*4/AY39*1000,"") -> 194.5439 | AZ40: =IFERROR(AZ32*4/AZ39*1000,"") -> 240.6797 | BA40: =IFERROR(BA32*4/BA39*1000,"") -> 228.0582 | BB40: =IFERROR(BB32*1/BB39*1000,"") -> 211.70203 | BC40: =IFERROR(BC32*4/BC39*1000,"") -> 229.48164 | BD40: =IFERROR(BD32*4/BD39*1000,"") -> 225.34676 | BE40: =IFERROR(BE32*4/BE39*1000,"") -> 169.54991 | BF40: =IFERROR(BF32*4/BF39*1000,"") -> 131.41793 | BG40: =IFERROR(BG32*1/BG39*1000,"") -> 189.68365 | BH40: =IFERROR(BH32*4/BH39*1000,"") -> 130.08152 | BI40: =IFERROR(BI32*4/BI39*1000,"") -> 137.21033 | BJ40: =IFERROR(BJ32*4/BJ39*1000,"") -> 133.72137 | BK40: =IFERROR(BK32*4/BK39*1000,"") -> 129.31448 | BL40: =IFERROR(BL32*1/BL39*1000,"") -> 132.01168 | BM40: =IFERROR(BM32*4/BM39*1000,"") -> 147.69893 | BN40: =IFERROR(BN32*4/BN39*1000,"") -> 158.26913 | BO40: =IFERROR(BO32*4/BO39*1000,"") -> 206.18278 | BP40: =IFERROR(BP32*4/BP39*1000,"") -> 179.48129 | BQ40: =IFERROR(BQ32*1/BQ39*1000,"") -> 171.55814 | BR40: =IFERROR(BR32*4/BR39*1000,"") -> 163.60479 | BS40: =IFERROR(BS32*4/BS39*1000,"") -> 169.14427 | BT40: =IFERROR(BT32*4/BT39*1000,"") -> 180.68787 | BU40: =IFERROR(BU32*4/BU39*1000,"") -> 177.64612 | BV40: =IFERROR(BV32*1/BV39*1000,"") -> 173.18417 | BW40: =IFERROR(BW32*4/BW39*1000,"") -> 168.70166 | BX40: =IFERROR(BX32*4/BX39*1000,"") -> 204.19573 | CN40: 2027E | CO40: =CP40+$CO$39 -> 0.07 | CP40: 0.05 | CQ40: =CP40+$CQ$39 -> 0.02
...

Sheet Bull-Base-Bear
B2: C.H. Robinson Worldwide (CHRW) — Bull / Base / Bear Case P&L Summary | J2: Share price ($): | K2: =Model!$CA$394 -> 151.88
B3: Adjusted figures (company current definition: adjusted income from operations & adjusted EPS exclude restructuring, divestiture gains/losses and other company-defined items; adjusted EBITDA = model definition). CHRW standalone — RXO acquisition shown on the RXO PF tab. Margins on AGP (company KPI basis). | J3: As of: | K3: =TODAY() -> 46300
B5: Scenario: | C5: =Model!$CF$2 -> Base | N5: Scenario: | O5: Bull | P5: Snapshot (values) — Model run with switch = Bull | Z5: Scenario: | AA5: Bear | AB5: Snapshot (values) — Model run with switch = Bear
B7: (USDm, except EPS and shares) | C7: 2025A | D7: 2026E | E7: 2027E | F7: 2028E | G7: 2029E | H7: 2030E | I7: 25-'30 CAGR | J7: LT Hist Avg | K7: LT Hist Min | L7: LT Hist Max | N7: (USDm, except EPS and shares) | O7: 2025A | P7: 2026E | Q7: 2027E | R7: 2028E | S7: 2029E | T7: 2030E | U7: 25-'30 CAGR | V7: LT Hist Avg | W7: LT Hist Min | X7: LT Hist Max | Z7: (USDm, except EPS and shares) | AA7: 2025A | AB7: 2026E | AC7: 2027E | AD7: 2028E | AE7: 2029E | AF7: 2030E | AG7: 25-'30 CAGR | AH7: LT Hist Avg | AI7: LT Hist Min | AJ7: LT Hist Max
B9: Revenues | C9: =Model!BV125 -> 16232.763 | D9: =Model!CA125 -> 18797.312 | E9: =Model!CB125 -> 19741.032 | F9: =Model!CC125 -> 20378.519 | G9: =Model!CD125 -> 21048.014 | H9: =Model!CE125 -> 22335.678 | I9: =IFERROR((H9/C9)^(1/5)-1,"n/m") -> 0.065911969 | N9: Revenues | O9: 16232.763 | P9: 19050.409 | Q9: 20909.203 | R9: 22671.381 | S9: 24548.752 | T9: 27234.502 | U9: 0.10903538 | Z9: Revenues | AA9: 16232.763 | AB9: 18544.216 | AC9: 18516.551 | AD9: 18097.874 | AE9: 17626.366 | AF9: 17665.901 | AG9: 0.017064901
B10: Revenues y/y % | D10: =IFERROR(D9/C9-1,"") -> 0.15798601 | E10: =IFERROR(E9/D9-1,"") -> 0.050205035 | F10: =IFERROR(F9/E9-1,"") -> 0.032292475 | G10: =IFERROR(G9/F9-1,"") -> 0.032852979 | H10: =IFERROR(H9/G9-1,"") -> 0.061177466 | N10: Revenues y/y % | P10: 0.17357771 | Q10: 0.097572384 | R10: 0.084277624 | S10: 0.082807971 | T10: 0.10940478 | Z10: Revenues y/y % | AB10: 0.1423943 | AC10: -0.0014918316 | AD10: -0.022610951 | AE10: -0.026053217 | AF10: 0.0022429029
B11: NAST volume y/y % (truckload + LTL) | C11: =Model!BV11 -> 0.01 | D11: =Model!CA11 -> 0.01125 | E11: =Model!CB11 -> 0.03 | F11: =Model!CC11 -> 0.035 | G11: =Model!CD11 -> 0.03 | H11: =Model!CE11 -> 0.03 | N11: NAST volume y/y % (truckload + LTL) | O11: 0.01 | P11: 0.01125 | Q11: 0.05 | R11: 0.055 | S11: 0.05 | T11: 0.05 | Z11: NAST volume y/y % (truckload + LTL) | AA11: 0.01 | AB11: 0.01125 | AC11: 0.01 | AD11: 0.015 | AE11: 0.01 | AF11: 0.01
B12: Adjusted gross profit (AGP) | C12: =Model!BV133 -> 2729.41 | D12: =Model!CA133 -> 2869.9108 | E12: =Model!CB133 -> 3030.6053 | F12: =Model!CC133 -> 3219.1046 | G12: =Model!CD133 -> 3407.7834 | H12: =Model!CE133 -> 3611.9036 | I12: =IFERROR((H12/C12)^(1/5)-1,"n/m") -> 0.057629301 | N12: Adjusted gross profit (AGP) | O12: 2729.41 | P12: 2907.9108 | Q12: 3211.3639 | R12: 3582.1905 | S12: 3973.2957 | T12: 4402.9306 | U12: 0.10035954 | Z12: Adjusted gross profit (AGP) | AA12: 2729.41 | AB12: 2831.9108 | AC12: 2838.7198 | AD12: 2852.0723 | AE12: 2846.1716 | AF12: 2847.5039 | AG12: 0.008507447
B13: AGP y/y % | D13: =IFERROR(D12/C12-1,"") -> 0.051476628 | E13: =IFERROR(E12/D12-1,"") -> 0.055992855 | F13: =IFERROR(F12/E12-1,"") -> 0.062198559 | G13: =IFERROR(G12/F12-1,"") -> 0.058612201 | H13: =IFERROR(H12/G12-1,"") -> 0.059898223 | N13: AGP y/y % | P13: 0.065399051 | Q13: 0.10435433 | R13: 0.11547324 | S13: 0.10918046 | T13: 0.10813062 | Z13: AGP y/y % | AB13: 0.037554205 | AC13: 0.0024043741 | AD13: 0.0047037055 | AE13: -0.0020689195 | AF13: 0.00046810181
B15: Adjusted EBITDA (model definition) | C15: =Model!BV193 -> 936.551 | D15: =Model!CA193 -> 1094.422 | E15: =Model!CB193 -> 1204.0278 | F15: =Model!CC193 -> 1307.9428 | G15: =Model!CD193 -> 1406.6292 | H15: =Model!CE193 -> 1495.3163 | I15: =IFERROR((H15/C15)^(1/5)-1,"n/m") -> 0.098096046 | N15: Adjusted EBITDA (model definition) | O15: 936.551 | P15: 1133.5841 | Q15: 1377.039 | R15: 1614.9314 | S15: 1866.1568 | T15: 2124.8506 | U15: 0.17803825 | Z15: Adjusted EBITDA (model definition) | AA15: 936.551 | AB15: 1055.2598 | AC15: 1005.573 | AD15: 959.43274 | AE15: 896.01798 | AF15: 816.99395 | AG15: -0.026944791
B16: Adjusted EBITDA % of AGP | C16: =IFERROR(C15/Model!BV133,"") -> 0.34313313 | D16: =IFERROR(D15/Model!CA133,"") -> 0.38134355 | E16: =IFERROR(E15/Model!CB133,"") -> 0.39728955 | F16: =IFERROR(F15/Model!CC133,"") -> 0.4063064 | G16: =IFERROR(G15/Model!CD133,"") -> 0.41276955 | H16: =IFERROR(H15/Model!CE133,"") -> 0.41399674 | J16: =IFERROR(AVERAGE(Model!C194,Model!D194,Model!E194,Model!F194,Model!G194,Model!H194,Model!I194,Model!N194,Model!S194,Model!X194,Model!AC194,Model!AH194,Model!AM194,Model!AR194,Model!AW194,Model!BB194,Model!BG194,Model!BL194,Model!BQ194,Model!BV194),"") -> 0.38495897 | K16: =IFERROR(MIN(Model!C194,Model!D194,Model!E194,Model!F194,Model!G194,Model!H194,Model!I194,Model!N194,Model!S194,Model!X194,Model!AC194,Model!AH194,Model!AM194,Model!AR194,Model!AW194,Model!BB194,Model!BG194,Model!BL194,Model!BQ194,Model!BV194),"") -> 0.25018467 | L16: =IFERROR(MAX(Model!C194,Model!D194,Model!E194,Model!F194,Model!G194,Model!H194,Model!I194,Model!N194,Model!S194,Model!X194,Model!AC194,Model!AH194,Model!AM194,Model!AR194,Model!AW194,Model!BB194,Model!BG194,Model!BL194,Model!BQ194,Model!BV194),"") -> 0.44525561 | N16: Adjusted EBITDA % of AGP | O16: 0.34313313 | P16: 0.38982768 | Q16: 0.4288019 | R16: 0.45082232 | S16: 0.46967477 | T16: 0.48259915 | Z16: Adjusted EBITDA % of AGP | AA16: 0.34313313 | AB16: 0.37263173 | AC16: 0.35423468 | AD16: 0.33639846 | AE16: 0.31481517 | AF16: 0.28691583
B18: Income from Operations (GAAP) | C18: =Model!BV139 -> 794.961 | D18: =Model!CA139 -> 947.751 | E18: =Model!CB139 -> 1097.9566 | F18: =Model!CC139 -> 1194.1492 | G18: =Model!CD139 -> 1283.4543 | H18: =Model!CE139 -> 1361.7111 | I18: =IFERROR((H18/C18)^(1/5)-1,"n/m") -> 0.11364771 | N18: Income from Operations (GAAP) | O18: 794.961 | P18: 985.751 | Q18: 1262.9537 | R18: 1483.4198 | S18: 1714.911 | T18: 1952.0704 | U18: 0.19682301 | Z18: Income from Operations (GAAP) | AA18: 794.961 | AB18: 909.751 | AC18: 906.21782 | AD18: 859.61021 | AE18: 795.83948 | AF18: 715.66131 | AG18: -0.020797883
B19: Income from operations y/y % | D19: =IFERROR(D18/C18-1,"") -> 0.19219811 | E19: =IFERROR(E18/D18-1,"") -> 0.15848638 | F19: =IFERROR(F18/E18-1,"") -> 0.0876105 | G19: =IFERROR(G18/F18-1,"") -> 0.074785589 | H19: =IFERROR(H18/G18-1,"") -> 0.06097356 | N19: Income from operations y/y % | P19: 0.23999919 | Q19: 0.28120968 | R19: 0.17456383 | S19: 0.15605242 | T19: 0.13829254 | Z19: Income from operations y/y % | AB19: 0.14439702 | AC19: -0.0038836791 | AD19: -0.051430915 | AE19: -0.074185638 | AF19: -0.10074665
B20: Operating margin (GAAP) % of AGP | C20: =IFERROR(C18/Model!BV133,"") -> 0.29125745 | D20: =IFERROR(D18/Model!CA133,"") -> 0.33023709 | E20: =IFERROR(E18/Model!CB133,"") -> 0.36228955 | F20: =IFERROR(F18/Model!CC133,"") -> 0.37095693 | G20: =IFERROR(G18/Model!CD133,"") -> 0.37662438 | H20: =IFERROR(H18/Model!CE133,"") -> 0.37700649 | J20: =IFERROR(AVERAGE(Model!C231,Model!D231,Model!E231,Model!F231,Model!G231,Model!H231,Model!I231,Model!N231,Model!S231,Model!X231,Model!AC231,Model!AH231,Model!AM231,Model!AR231,Model!AW231,Model!BB231,Model!BG231,Model!BL231,Model!BQ231,Model!BV231),"") -> 0.35214122 | K20: =IFERROR(MIN(Model!C231,Model!D231,Model!E231,Model!F231,Model!G231,Model!H231,Model!I231,Model!N231,Model!S231,Model!X231,Model!AC231,Model!AH231,Model!AM231,Model!AR231,Model!AW231,Model!BB231,Model!BG231,Model!BL231,Model!BQ231,Model!BV231),"") -> 0.1975756 | L20: =IFERROR(MAX(Model!C231,Model!D231,Model!E231,Model!F231,Model!G231,Model!H231,Model!I231,Model!N231,Model!S231,Model!X231,Model!AC231,Model!AH231,Model!AM231,Model!AR231,Model!AW231,Model!BB231,Model!BG231,Model!BL231,Model!BQ231,Model!BV231),"") -> 0.42429791 | N20: Operating margin (GAAP) % of AGP | O20: 0.29125745 | P20: 0.33898942 | Q20: 0.39327643 | R20: 0.41410968 | S20: 0.4316092 | T20: 0.44335707 | Z20: Operating margin (GAAP) % of AGP | AA20: 0.29125745 | AB20: 0.32124988 | AC20: 0.31923468 | AD20: 0.30139846 | AE20: 0.27961753 | AF20: 0.25132935
B22: Adjusted Income from Operations | C22: =Model!BV181 -> 833.733 | D22: =Model!CA181 -> 1002 | E22: =Model!CB181 -> 1097.9566 | F22: =Model!CC181 -> 1194.1492 | G22: =Model!CD181 -> 1283.4543 | H22: =Model!CE181 -> 1361.7111 | I22: =IFERROR((H22/C22)^(1/5)-1,"n/m") -> 0.10309165 | N22: Adjusted Income from Operations | O22: 833.733 | P22: 1040 | Q22: 1262.9537 | R22: 1483.4198 | S22: 1714.911 | T22: 1952.0704 | U22: 0.18547854 | Z22: Adjusted Income from Operations | AA22: 833.733 | AB22: 964 | AC22: 906.21782 | AD22: 859.61021 | AE22: 795.83948 | AF22: 715.66131 | AG22: -0.030079564
B23: Adjusted operating margin % of AGP | C23: =IFERROR(C22/Model!BV133,"") -> 0.30546272 | D23: =IFERROR(D22/Model!CA133,"") -> 0.34913977 | E23: =IFERROR(E22/Model!CB133,"") -> 0.36228955 | F23: =IFERROR(F22/Model!CC133,"") -> 0.37095693 | G23: =IFERROR(G22/Model!CD133,"") -> 0.37662438 | H23: =IFERROR(H22/Model!CE133,"") -> 0.37700649 | J23: =IFERROR(AVERAGE(Model!C182,Model!D182,Model!E182,Model!F182,Model!G182,Model!H182,Model!I182,Model!N182,Model!S182,Model!X182,Model!AC182,Model!AH182,Model!AM182,Model!AR182,Model!AW182,Model!BB182,Model!BG182,Model!BL182,Model!BQ182,Model!BV182),"") -> 0.35525933 | K23: =IFERROR(MIN(Model!C182,Model!D182,Model!E182,Model!F182,Model!G182,Model!H182,Model!I182,Model!N182,Model!S182,Model!X182,Model!AC182,Model!AH182,Model!AM182,Model!AR182,Model!AW182,Model!BB182,Model!BG182,Model!BL182,Model!BQ182,Model!BV182),"") -> 0.21218087 | L23: =IFERROR(MAX(Model!C182,Model!D182,Model!E182,Model!F182,Model!G182,Model!H182,Model!I182,Model!N182,Model!S182,Model!X182,Model!AC182,Model!AH182,Model!AM182,Model!AR182,Model!AW182,Model!BB182,Model!BG182,Model!BL182,Model!BQ182,Model!BV182),"") -> 0.42429791 | N23: Adjusted operating margin % of AGP | O23: 0.30546272 | P23: 0.35764508 | Q23: 0.39327643 | R23: 0.41410968 | S23: 0.4316092 | T23: 0.44335707 | Z23: Adjusted operating margin % of AGP | AA23: 0.30546272 | AB23: 0.3404062 | AC23: 0.31923468 | AD23: 0.30139846 | AE23: 0.27961753 | AF23: 0.25132935
B25: Adjusted Net Income | C25: =Model!BV209 -> 618.196 | D25: =Model!CA209 -> 758.16348 | E25: =Model!CB209 -> 829.79979 | F25: =Model!CC209 -> 896.52203 | G25: =Model!CD209 -> 960.9141 | H25: =Model!CE209 -> 1018.9306 | I25: =IFERROR((H25/C25)^(1/5)-1,"n/m") -> 0.10510536 | N25: Adjusted Net Income | O25: 618.196 | P25: 798.17452 | Q25: 958.93283 | R25: 1107.087 | S25: 1276.7856 | T25: 1452.4948 | U25: 0.1863086 | Z25: Adjusted Net Income | AA25: 618.196 | AB25: 718.91244 | AC25: 679.30166 | AD25: 647.47085 | AE25: 595.95068 | AF25: 534.16718 | AG25: -0.028796582
B27: FDSO (m) | C27: =Model!BV156 -> 121.502 | D27: =Model!CA156 -> 119.72924 | E27: =Model!CB156 -> 114.61473 | F27: =Model!CC156 -> 110.69066 | G27: =Model!CD156 -> 107.43735 | H27: =Model!CE156 -> 104.34231 | I27: =IFERROR((H27/C27)^(1/5)-1,"n/m") -> -0.0299918 | N27: FDSO (m) | O27: 121.502 | P27: 119.56464 | Q27: 112.65618 | R27: 106.70623 | S27: 101.66574 | T27: 96.141679 | U27: -0.04574234 | Z27: FDSO (m) | AA27: 121.502 | AB27: 119.89384 | AC27: 116.89656 | AD27: 115.43471 | AE27: 114.17137 | AF27: 113.64089 | AG27: -0.013288388
B29: Adjusted EPS — Diluted ($) | C29: =Model!BV211 -> 5.0879492 | D29: =Model!CA211 -> 6.3323168 | E29: =Model!CB211 -> 7.2399051 | F29: =Model!CC211 -> 8.099347 | G29: =Model!CD211 -> 8.9439485 | H29: =Model!CE211 -> 9.7652677 | I29: =IFERROR((H29/C29)^(1/5)-1,"n/m") -> 0.13927424 | N29: Adjusted EPS — Diluted ($) | O29: 5.0879492 | P29: 6.6756738 | Q29: 8.5120302 | R29: 10.375093 | S29: 12.558662 | T29: 15.107858 | U29: 0.2431743 | Z29: Adjusted EPS — Diluted ($) | AA29: 5.0879492 | AB29: 5.9962414 | AC29: 5.8111347 | AD29: 5.6089787 | AE29: 5.2197911 | AF29: 4.700484 | AG29: -0.015717048
B30: EPS y/y % | D30: =IFERROR(D29/C29-1,"") -> 0.24457155 | E30: =IFERROR(E29/D29-1,"") -> 0.14332642 | F30: =IFERROR(F29/E29-1,"") -> 0.11870901 | G30: =IFERROR(G29/F29-1,"") -> 0.10428019 | H30: =IFERROR(H29/G29-1,"") -> 0.091829597 | N30: EPS y/y % | P30: 0.31205592 | Q30: 0.2750818 | R30: 0.21887405 | S30: 0.21046263 | T30: 0.20298305 | Z30: EPS y/y % | AB30: 0.17851835 | AC30: -0.030870461 | AD30: -0.034787696 | AE30: -0.069386534 | AF30: -0.099488105
B32: P / E (x) — assumed (adjusted EPS) | G32: 20 | H32: 20 | N32: P / E (x) — assumed (adjusted EPS) | S32: 24 | T32: 24 | Z32: P / E (x) — assumed (adjusted EPS) | AE32: 16 | AF32: 16
B33: Price Target ($) | G33: =G32*G29 -> 178.87897 | H33: =H32*H29 -> 195.30535 | N33: Price Target ($) | S33: 251.17324 | T33: 302.15715 | Z33: Price Target ($) | AE33: 104.39582 | AF33: 94.00968
B34: Upside / (Downside) vs current | G34: =IFERROR(G33/$K$2-1,"") -> 0.17776514 | H34: =IFERROR(H33/$K$2-1,"") -> 0.28591884 | N34: Upside / (Downside) vs current | S34: 0.65376112 | T34: 0.98944661 | Z34: Upside / (Downside) vs current | AE34: -0.31264273 | AF34: -0.3810266
B35: IRR (to Dec-Y-1) | G35: =IFERROR((G33/$K$2)^(1/((DATE(2029-1,12,31)-$K$3)/365.25))-1,"") -> 0.075793306 | H35: =IFERROR((H33/$K$2)^(1/((DATE(2030-1,12,31)-$K$3)/365.25))-1,"") -> 0.080735883 | N35: IRR (to Dec-Y-1) | S35: 0.25184791 | T35: 0.23661149 | Z35: IRR (to Dec-Y-1) | AE35: -0.1541382 | AF35: -0.13765918
B37: Free Cash Flow | C37: =Model!BV264 -> 843.976 | D37: =Model!CA264 -> 703.85523 | E37: =Model!CB264 -> 949.13971 | F37: =Model!CC264 -> 988.09961 | G37: =Model!CD264 -> 1061.1541 | H37: =Model!CE264 -> 1098.1817 | I37: =IFERROR((H37/C37)^(1/5)-1,"n/m") -> 0.054068474 | N37: Free Cash Flow | O37: 843.976 | P37: 726.43385 | Q37: 1036.4882 | R37: 1154.8357 | S37: 1339.689 | T37: 1496.1431 | U37: 0.12131752 | Z37: Free Cash Flow | AA37: 843.976 | AB37: 682.03661 | AC37: 844.89717 | AD37: 782.85442 | AE37: 734.93799 | AF37: 647.65299 | AG37: -0.051576175
