Workbook

Sheet Model
CT1: SCENARIO SWITCH ▼ (Bull / Base / Bear) — drives all scenario-linked forecast drivers
B2: Teledyne Technologies Incorporated (NYSE: TDY) — 3-Statement Financial Model | CT2: Base
B3: US GAAP as reported · USD millions (per-share data in USD) · Source: Teledyne Forms 10-K / 10-Q and Form 8-K earnings releases (Ex. 99.1), SEC EDGAR CIK 0001094285 (investor-relations releases are the same documents as filed on EDGAR)
B4: Basis notes: 52/53-week fiscal year (FY2009, FY2015, FY2020 = 53 weeks). FY2006–07 include Teledyne Continental Motors (piston engines, sold Apr-2011; discontinued from the FY2010 10-K). Segments on the current four-segment basis from FY2008 (FY2010 10-K recast); FY2006–07 legacy segments shown as memo. ASU 2017-07 (2018) recast 2017; ASC 606 from 2018 (2017 not restated). FLIR from 14-May-2021. Q3/26E–Q4/26E = FY26 non-GAAP EPS outlook less 1H/26 actuals.
CV5: Forecast | CW5: Historical | CX5: Historical | CY5: Historical
B6: (USDm) | C6: 2006 | D6: 2007 | E6: 2008 | F6: 2009 | G6: 2010 | H6: 2011 | I6: 2012 | J6: Q1/13 | K6: Q2/13 | L6: 1H/13 | M6: Q3/13 | N6: Q4/13 | O6: 2013 | P6: Q1/14 | Q6: Q2/14 | R6: 1H/14 | S6: Q3/14 | T6: Q4/14 | U6: 2014 | V6: Q1/15 | W6: Q2/15 | X6: 1H/15 | Y6: Q3/15 | Z6: Q4/15 | AA6: 2015 | AB6: Q1/16 | AC6: Q2/16 | AD6: 1H/16 | AE6: Q3/16 | AF6: Q4/16 | AG6: 2016 | AH6: Q1/17 | AI6: Q2/17 | AJ6: 1H/17 | AK6: Q3/17 | AL6: Q4/17 | AM6: 2017 | AN6: Q1/18 | AO6: Q2/18 | AP6: 1H/18 | AQ6: Q3/18 | AR6: Q4/18 | AS6: 2018 | AT6: Q1/19 | AU6: Q2/19 | AV6: 1H/19 | AW6: Q3/19 | AX6: Q4/19 | AY6: 2019 | AZ6: Q1/20 | BA6: Q2/20 | BB6: 1H/20 | BC6: Q3/20 | BD6: Q4/20 | BE6: 2020 | BF6: Q1/21 | BG6: Q2/21 | BH6: 1H/21 | BI6: Q3/21 | BJ6: Q4/21 | BK6: 2021 | BL6: Q1/22 | BM6: Q2/22 | BN6: 1H/22 | BO6: Q3/22 | BP6: Q4/22 | BQ6: 2022 | BR6: Q1/23 | BS6: Q2/23 | BT6: 1H/23 | BU6: Q3/23 | BV6: Q4/23 | BW6: 2023 | BX6: Q1/24 | BY6: Q2/24 | BZ6: 1H/24 | CA6: Q3/24 | CB6: Q4/24 | CC6: 2024 | CD6: Q1/25 | CE6: Q2/25 | CF6: 1H/25 | CG6: Q3/25 | CH6: Q4/25 | CI6: 2025 | CJ6: Q1/26 | CK6: Q2/26 | CL6: 1H/26 | CM6: Q3/26E | CN6: Q4/26E | CO6: 2026E | CP6: 2027E | CQ6: 2028E | CR6: 2029E | CS6: 2030E | CT6: Modelling Notes | CV6: 5Y CAGR | CW6: 5Y CAGR | CX6: 10Y CAGR | CY6: 19Y CAGR
CV7: 25-'30 | CW7: 20-'25 | CX7: 15-'25 | CY7: 06-'25
B8: SEGMENT P&L — BY SEGMENT (four reportable segments; current basis from FY2008) | CT8: SEGMENT BUILD — modelling logic (segment sales → GAAP OI → non-GAAP OI)
DB9: SCENARIO INPUT TABLE — driver assumptions per Bull / Base / Bear | DC9: Bull | DD9: Base | DE9: Bear | DF9: Bull / Bear = Base + Δ (Δ inputs on each block header). Outlook block = high / mid / low end of FY26 ranges.
B10: Digital Imaging (infrared / visible / X-ray sensors, cameras & systems; FLIR from 14-May-2021) | CT10: DIGITAL IMAGING — modelling logic
B11: Net sales | E11: 137.4 | F11: 127.3 | G11: 122.5 | H11: 349.9 | I11: 415.9 | J11: 102.4 | K11: 104.3 | L11: =J11+K11 -> 206.7 | M11: 105.2 | N11: 102.9 | O11: 414.8 | P11: 101.9 | Q11: 103.7 | R11: =P11+Q11 -> 205.6 | S11: 95.6 | T11: 102.4 | U11: 403.6 | V11: 90.4 | W11: 90.8 | X11: =V11+W11 -> 181.2 | Y11: 95.7 | Z11: 102.1 | AA11: 379 | AB11: 89.9 | AC11: 99.4 | AD11: =AB11+AC11 -> 189.3 | AE11: 98.5 | AF11: 110.9 | AG11: 398.7 | AH11: 113.8 | AI11: 200.2 | AJ11: =AH11+AI11 -> 314 | AK11: 197 | AL11: 206.7 | AM11: 710.4 | AN11: 208.3 | AO11: 223 | AP11: =AN11+AO11 -> 431.3 | AQ11: 220.7 | AR11: 223.3 | AS11: 875.3 | AT11: 232.4 | AU11: 248.4 | AV11: =AT11+AU11 -> 480.8 | AW11: 244 | AX11: 268.1 | AY11: 992.9 | AZ11: 246.7 | BA11: 237.6 | BB11: =AZ11+BA11 -> 484.3 | BC11: 239.7 | BD11: 262 | BE11: 986 | BF11: 263.3 | BG11: 579.5 | BH11: =BF11+BG11 -> 842.8 | BI11: 760.6 | BJ11: 809.5 | BK11: 2412.9 | BL11: 750.5 | BM11: 775.8 | BN11: =BL11+BM11 -> 1526.3 | BO11: 777.9 | BP11: 806.7 | BQ11: 3110.9 | BR11: 772.5 | BS11: 793.3 | BT11: =BR11+BS11 -> 1565.8 | BU11: 775.8 | BV11: 802.5 | BW11: 3144.1 | BX11: 740.8 | BY11: 739.4 | BZ11: =BX11+BY11 -> 1480.2 | CA11: 768.4 | CB11: 822.2 | CC11: 3070.8 | CD11: 757 | CE11: 771 | CF11: =CD11+CE11 -> 1528 | CG11: 785.4 | CH11: 850.5 | CI11: 3163.9 | CJ11: 816.9 | CK11: 868.7 | CL11: =CJ11+CK11 -> 1685.6 | CM11: =CG11*CK11/CE11 -> 884.92475 | CN11: =CH11*CK11/CE11 -> 958.27412 | CO11: =SUM(CJ11,CK11,CM11,CN11) -> 3528.7989 | CP11: =CO11*(1+CP12) -> 3740.5268 | CQ11: =CP11*(1+CQ12) -> 3946.2558 | CR11: =CQ11*(1+CR12) -> 4143.5686 | CS11: =CR11*(1+CS12) -> 4350.747 | CT11: Q3/26E–Q4/26E: prior-year quarter × Q2/26 y/y growth of the segment (after the Excelitas A&D anniversary). 2027E+: prior year × (1 + scenario organic growth). | CV11: =IFERROR((CS11/CI11)^(1/5)-1,"n/m") -> 0.065781595 | CW11: =IFERROR((CI11/BE11)^(1/5)-1,"n/m") -> 0.26260983 | CX11: =IFERROR((CI11/AA11)^(1/10)-1,"n/m") -> 0.23639817 | CY11: =IFERROR((CI11/C11)^(1/19)-1,"n/m") -> n/m | DB11: FY26 outlook — Q2-26 release (22-Jul-26) | DC11: High | DD11: Mid | DE11: Low
B12: Net sales y/y % | D12: =IFERROR(D11/C11-1,"") | E12: =IFERROR(E11/D11-1,"") | F12: =IFERROR(F11/E11-1,"") -> -0.073508006 | G12: =IFERROR(G11/F11-1,"") -> -0.037706206 | H12: =IFERROR(H11/G11-1,"") -> 1.8563265 | I12: =IFERROR(I11/H11-1,"") -> 0.18862532 | O12: =IFERROR(O11/I11-1,"") -> -0.0026448666 | P12: =IFERROR(P11/J11-1,"") -> -0.0048828125 | Q12: =IFERROR(Q11/K11-1,"") -> -0.0057526366 | R12: =IFERROR(R11/L11-1,"") -> -0.0053217223 | S12: =IFERROR(S11/M11-1,"") -> -0.091254753 | T12: =IFERROR(T11/N11-1,"") -> -0.0048590865 | U12: =IFERROR(U11/O11-1,"") -> -0.027000964 | V12: =IFERROR(V11/P11-1,"") -> -0.11285574 | ... CO12: =IFERROR(CO11/CI11-1,"") -> 0.11533199 | CP12: =CHOOSE(MATCH($CT$2,{"Bull","Base","Bear"},0),$DC$21,$DD$21,$DE$21) -> 0.06 | CQ12: =CHOOSE(MATCH($CT$2,{"Bull","Base","Bear"},0),$DC$22,$DD$22,$DE$22) -> 0.055 | CR12: =CHOOSE(MATCH($CT$2,{"Bull","Base","Bear"},0),$DC$23,$DD$23,$DE$23) -> 0.05 | CS12: =CHOOSE(MATCH($CT$2,{"Bull","Base","Bear"},0),$DC$24,$DD$24,$DE$24) -> 0.05 | CT12: 2027E–2030E: scenario lever (DI_organicGrowth, Bull/Base/Bear table →). | DB12: FY26 non-GAAP diluted EPS ($) | DC12: 24.65 | DD12: 24.55 | DE12: 24.45
B13: Segment operating income (GAAP) | E13: 14.6 | F13: 11.8 | G13: 5.2 | H13: 16.1 | I13: 24.8 | J13: 5.2 | K13: 7.9 | L13: =J13+K13 -> 13.1 | M13: 11.5 | N13: 3.6 | O13: 28.2 | P13: 9.7 | Q13: 11.7 | R13: =P13+Q13 -> 21.4 | S13: 7.9 | T13: 7.8 | U13: 37.1 | V13: 9.3 | W13: 8.8 | X13: =V13+W13 -> 18.1 | Y13: 10.4 | Z13: 11.5 | AA13: 40 | AB13: 8.2 | AC13: 10.7 | AD13: =AB13+AC13 -> 18.9 | AE13: 11.7 | AF13: 15.3 | AG13: 45.9 | AH13: 15.1 | AI13: 28 | AJ13: =AH13+AI13 -> 43.1 | AK13: 31.4 | AL13: 35.9 | AM13: 110.2 | AN13: 33.8 | AO13: 43.1 | AP13: =AN13+AO13 -> 76.9 | AQ13: 42.3 | AR13: 36.3 | AS13: 155.5 | AT13: 36.6 | AU13: 51.6 | AV13: =AT13+AU13 -> 88.2 | AW13: 41.2 | AX13: 47.1 | AY13: 176.5 | AZ13: 43.8 | BA13: 46.8 | BB13: =AZ13+BA13 -> 90.6 | BC13: 45.5 | BD13: 56.7 | BE13: 192.8 | BF13: 52 | BG13: 84.6 | BH13: =BF13+BG13 -> 136.6 | BI13: 94.9 | BJ13: 94.1 | BK13: 325.6 | BL13: 115.7 | BM13: 117.9 | BN13: =BL13+BM13 -> 233.6 | BO13: 133.7 | BP13: 152 | BQ13: 519.3 | BR13: 122.2 | BS13: 124.6 | BT13: =BR13+BS13 -> 246.8 | BU13: 136.3 | BV13: 134.3 | BW13: 517.4 | BX13: 113.8 | BY13: 113.5 | BZ13: =BX13+BY13 -> 227.3 | CA13: 123.9 | CB13: 90.8 | CC13: 442 | CD13: 122.3 | CE13: 119.6 | CF13: =CD13+CE13 -> 241.9 | CG13: 123.4 | CH13: 162.9 | CI13: 528.2 | CJ13: 141.7 | CK13: 170.2 | CL13: =CJ13+CK13 -> 311.9 | CM13: =CM16-CM14-CM15 -> 157.16457 | CN13: =CN16-CN14-CN15 -> 184.28463 | CO13: =SUM(CJ13,CK13,CM13,CN13) -> 653.3492 | CP13: =CP16-CP14-CP15 -> 738.56181 | CQ13: =CQ16-CQ14-CQ15 -> 811.13208 | CR13: =CR16-CR14-CR15 -> 918.04484 | CS13: =CS16-CS14-CS15 -> 1014.6315 | CT13: Forecast GAAP OI = non-GAAP OI − acquired-intangible amortization − other items. | CV13: =IFERROR((CS13/CI13)^(1/5)-1,"n/m") -> 0.13946763 | CW13: =IFERROR((CI13/BE13)^(1/5)-1,"n/m") -> 0.22331492 | CX13: =IFERROR((CI13/AA13)^(1/10)-1,"n/m") -> 0.2944159 | CY13: =IFERROR((CI13/C13)^(1/19)-1,"n/m") -> n/m | DB13: Q3/26 non-GAAP diluted EPS ($) | DC13: 6.15 | DD13: 6.1 | DE13: 6.05
B14: (+) Acquired intangible asset amortization | AZ14: 4.6 | BA14: 4.4 | BB14: =AZ14+BA14 -> 9 | BC14: 4.5 | BD14: 4.6 | BE14: 18.1 | BF14: 4.6 | BG14: 27.4 | BH14: =BF14+BG14 -> 32 | BI14: 50.1 | BJ14: 46.3 | BK14: 128.4 | BL14: 48.5 | BM14: 46.4 | BN14: =BL14+BM14 -> 94.9 | BO14: 44.7 | BP14: 44.1 | BQ14: 183.7 | BR14: 45.8 | BS14: 45.6 | BT14: =BR14+BS14 -> 91.4 | BU14: 45.4 | BV14: 44.9 | BW14: 181.7 | BX14: 45.8 | BY14: 45.4 | BZ14: =BX14+BY14 -> 91.2 | CA14: 46.1 | CB14: 46.1 | CC14: 183.3 | CD14: 45.4 | CE14: 46.3 | CF14: =CD14+CE14 -> 91.7 | CG14: 46.8 | CH14: 46.8 | CI14: 185.3 | CJ14: 48 | CK14: 47.4 | CL14: =CJ14+CK14 -> 95.4 | CM14: =CM125*$CL$14/($CL$14+$CL$31+$CL$51+$CL$70) -> 47.196127 | CN14: =CN125*$CL$14/($CL$14+$CL$31+$CL$51+$CL$70) -> 47.196127 | CO14: =SUM(CJ14,CK14,CM14,CN14) -> 189.79225 | CP14: =CP371*$CL$14/($CL$14+$CL$31+$CL$51+$CL$70) -> 177.86725 | CQ14: =CQ371*$CL$14/($CL$14+$CL$31+$CL$51+$CL$70) -> 175.43187 | CR14: =CR371*$CL$14/($CL$14+$CL$31+$CL$51+$CL$70) -> 138.56514 | CS14: =CS371*$CL$14/($CL$14+$CL$31+$CL$51+$CL$70) -> 116.56268 | CT14: Disclosed by segment from Q1/21. Forecast = amortization of existing intangibles (10-K schedule) × 1H/26 segment share. | DB14: FY26 GAAP diluted EPS ($, memo) | DC14: 20.99 | DD14: 20.86 | DE14: 20.73
B15: (+) Other segment non-GAAP items (inventory step-up, transaction costs) | BG15: 47.4 | BH15: =N(BF15)+N(BG15) -> 47.4 | BI15: 36.7 | BJ15: 48.2 | BK15: 132.3 | BP15: -4 | BQ15: -4 | BU15: 5.8 | BV15: 3 | BW15: 8.8 | BX15: 2.2 | BY15: 1 | BZ15: =BX15+BY15 -> 3.2 | CA15: 3.7 | CB15: 51 | CC15: 57.9 | CM15: 0 | CN15: 0 | CO15: =SUM(CJ15,CK15,CM15,CN15) -> 0 | CP15: 0 | CQ15: 0 | CR15: 0 | CS15: 0 | DB15: FY26 point estimates (all cases) | DF15: Not guided — analyst estimates: tax rate ≈ 1H/26 ETR before discrete items (Q2-26 21.7%); capex ≈ 2% of sales (FY25 $117m).
B16: Non-GAAP segment operating income | C16: =IF(OR(ISNUMBER(C17),ISNUMBER(C14)),C13+N(C14)+N(C15),"") | D16: =IF(OR(ISNUMBER(D17),ISNUMBER(D14)),D13+N(D14)+N(D15),"") | E16: =IF(OR(ISNUMBER(E17),ISNUMBER(E14)),E13+N(E14)+N(E15),"") | F16: =IF(OR(ISNUMBER(F17),ISNUMBER(F14)),F13+N(F14)+N(F15),"") | G16: =IF(OR(ISNUMBER(G17),ISNUMBER(G14)),G13+N(G14)+N(G15),"") | H16: =IF(OR(ISNUMBER(H17),ISNUMBER(H14)),H13+N(H14)+N(H15),"") | I16: =IF(OR(ISNUMBER(I17),ISNUMBER(I14)),I13+N(I14)+N(I15),"") | J16: =IF(OR(ISNUMBER(J17),ISNUMBER(J14)),J13+N(J14)+N(J15),"") | ... CL16: =IF(OR(ISNUMBER(CL17),ISNUMBER(CL14)),CL13+N(CL14)+N(CL15),"") -> 407.3 | CM16: =CM11*CM20 -> 204.3607 | CN16: =CN11*CN20 -> 231.48075 | CO16: =SUM(CJ16,CK16,CM16,CN16) -> 843.14146 | CP16: =CP11*CP20 -> 916.42907 | CQ16: =CQ11*CQ20 -> 986.56394 | CR16: =CR11*CR20 -> 1056.61 | CS16: =CS11*CS20 -> 1131.1942 | CT16: Company non-GAAP measure from Q1/21 (segment OI excluding acquired-intangible amortization and acquisition items). Forecast = net sales × non-GAAP margin. | CV16: =IFERROR((CS16/CI16)^(1/5)-1,"n/m") -> 0.096550507 | CW16: =IFERROR((CI16/BE16)^(1/5)-1,"n/m") -> 0.27603762 | CX16: =IFERROR((CI16/AA16)^(1/10)-1,"n/m") -> n/m | CY16: =IFERROR((CI16/C16)^(1/19)-1,"n/m") -> n/m | DB16: Tax rate (GAAP & non-GAAP) | DD16: 0.215
B17: Memo: non-GAAP segment operating income as published | AZ17: 48.4 | BA17: 51.2 | BB17: =AZ17+BA17 -> 99.6 | BC17: 50 | BD17: 61.3 | BE17: 210.9 | BF17: 56.6 | BG17: 159.4 | BH17: =BF17+BG17 -> 216 | BI17: 181.7 | BJ17: 188.6 | BK17: 586.3 | BL17: 164.2 | BM17: 164.3 | BN17: =BL17+BM17 -> 328.5 | BO17: 178.4 | BP17: 192.1 | BQ17: 699 | BR17: 168 | BS17: 170.2 | BT17: =BR17+BS17 -> 338.2 | BU17: 187.5 | BV17: 182.2 | BW17: 707.9 | BX17: 161.8 | BY17: 159.9 | BZ17: =BX17+BY17 -> 321.7 | CA17: 173.7 | CB17: 187.9 | CC17: 683.2 | CD17: 167.7 | CE17: 165.9 | CF17: =CD17+CE17 -> 333.6 | CG17: 170.2 | CH17: 209.7 | CI17: 713.5 | CJ17: 189.7 | CK17: 217.6 | CL17: =CJ17+CK17 -> 407.3 | DB17: Capital expenditures ($m) | DD17: 125
B18: Check: build vs published (should be 0) | C18: =IF(ISNUMBER(C17),ROUND(C16-C17,1),"n/p") -> n/p | D18: =IF(ISNUMBER(D17),ROUND(D16-D17,1),"n/p") -> n/p | E18: =IF(ISNUMBER(E17),ROUND(E16-E17,1),"n/p") -> n/p | F18: =IF(ISNUMBER(F17),ROUND(F16-F17,1),"n/p") -> n/p | G18: =IF(ISNUMBER(G17),ROUND(G16-G17,1),"n/p") -> n/p | H18: =IF(ISNUMBER(H17),ROUND(H16-H17,1),"n/p") -> n/p | I18: =IF(ISNUMBER(I17),ROUND(I16-I17,1),"n/p") -> n/p | J18: =IF(ISNUMBER(J17),ROUND(J16-J17,1),"n/p") -> n/p | ... CL18: =IF(ISNUMBER(CL17),ROUND(CL16-CL17,1),"n/p") -> 0
B19: Segment operating margin (GAAP) % | C19: =IFERROR(C13/C11,"") | D19: =IFERROR(D13/D11,"") | E19: =IFERROR(E13/E11,"") -> 0.1062591 | F19: =IFERROR(F13/F11,"") -> 0.092694423 | G19: =IFERROR(G13/G11,"") -> 0.04244898 | H19: =IFERROR(H13/H11,"") -> 0.046013147 | I19: =IFERROR(I13/I11,"") -> 0.059629719 | J19: =IFERROR(J13/J11,"") -> 0.05078125 | ... CS19: =IFERROR(CS13/CS11,"") -> 0.23320858 | CV19: =IFERROR(AVERAGE(CO19,CP19,CQ19,CR19,CS19),"n/m") -> 0.20858173 | CW19: =IFERROR(AVERAGE(BK19,BQ19,BW19,CC19,CI19),"n/m") -> 0.15546301 | CX19: =IFERROR(AVERAGE(AG19,AM19,AS19,AY19,BE19,BK19,BQ19,BW19,CC19,CI19),"n/m") -> 0.15985161 | CY19: =IFERROR(AVERAGE(C19,D19,E19,F19,G19,H19,I19,O19,U19,AA19,AG19,AM19,AS19,AY19,BE19,BK19,BQ19,BW19,CC19,CI19),"n/m") -> 0.12283387
B20: Non-GAAP segment operating margin % | C20: =IFERROR(C16/C11,"") | D20: =IFERROR(D16/D11,"") | E20: =IFERROR(E16/E11,"") | F20: =IFERROR(F16/F11,"") | G20: =IFERROR(G16/G11,"") | H20: =IFERROR(H16/H11,"") | I20: =IFERROR(I16/I11,"") | J20: =IFERROR(J16/J11,"") | ... CL20: =IFERROR(CL16/CL11,"") -> 0.24163503 | CM20: =CG20+$CL$20-$CF$20+CM102 -> 0.23093568 | CN20: =CH20+$CL$20-$CF$20+CN102 -> 0.24156006 | CO20: =IFERROR(CO16/CO11,"") -> 0.23893157 | CP20: =CHOOSE(MATCH($CT$2,{"Bull","Base","Bear"},0),$DC$45,$DD$45,$DE$45) -> 0.245 | CQ20: =CHOOSE(MATCH($CT$2,{"Bull","Base","Bear"},0),$DC$46,$DD$46,$DE$46) -> 0.25 | CR20: =CHOOSE(MATCH($CT$2,{"Bull","Base","Bear"},0),$DC$47,$DD$47,$DE$47) -> 0.255 | CS20: =CHOOSE(MATCH($CT$2,{"Bull","Base","Bear"},0),$DC$48,$DD$48,$DE$48) -> 0.26 | CT20: Q3/Q4-26E: prior-year quarter margin + 1H/26 vs 1H/25 change + outlook calibration Δ. 2027E+: scenario lever (DI_margin). | CV20: =IFERROR(AVERAGE(CO20,CP20,CQ20,CR20,CS20),"n/m") -> 0.24978631 | CW20: =IFERROR(AVERAGE(BK20,BQ20,BW20,CC20,CI20),"n/m") -> 0.22816537 | CX20: =IFERROR(AVERAGE(AG20,AM20,AS20,AY20,BE20,BK20,BQ20,BW20,CC20,CI20),"n/m") -> 0.2257869 | CY20: =IFERROR(AVERAGE(C20,D20,E20,F20,G20,H20,I20,O20,U20,AA20,AG20,AM20,AS20,AY20,BE20,BK20,BQ20,BW20,CC20,CI20),"n/m") -> 0.2257869 | DB20: DI_organicGrowth (Digital Imaging sales y/y) | DC20: 0.03 | DD20: Δ → | DE20: -0.04 | DF20: Digital Imaging: defense IR / unmanned systems, space sensors, industrial machine vision; commercial IR and semis capex cyclical.
B21: Segment operating income (GAAP) y/y % | D21: =IFERROR(D13/C13-1,"") | E21: =IFERROR(E13/D13-1,"") | F21: =IFERROR(F13/E13-1,"") -> -0.19178082 | G21: =IFERROR(G13/F13-1,"") -> -0.55932203 | H21: =IFERROR(H13/G13-1,"") -> 2.0961538 | I21: =IFERROR(I13/H13-1,"") -> 0.54037267 | O21: =IFERROR(O13/I13-1,"") -> 0.13709677 | P21: =IFERROR(P13/J13-1,"") -> 0.86538462 | Q21: =IFERROR(Q13/K13-1,"") -> 0.48101266 | R21: =IFERROR(R13/L13-1,"") -> 0.63358779 | S21: =IFERROR(S13/M13-1,"") -> -0.31304348 | T21: =IFERROR(T13/N13-1,"") -> 1.1666667 | U21: =IFERROR(U13/O13-1,"") -> 0.31560284 | V21: =IFERROR(V13/P13-1,"") -> -0.041237113 | ... CO21: =IFERROR(CO13/CI13-1,"") -> 0.23693526 | CP21: =IFERROR(CP13/CO13-1,"") -> 0.1304243 | CQ21: =IFERROR(CQ13/CP13-1,"") -> 0.098258891 | CR21: =IFERROR(CR13/CQ13-1,"") -> 0.13180685 | CS21: =IFERROR(CS13/CR13-1,"") -> 0.10520913 | DB21: 2027E | DC21: =DD21+$DC$20 -> 0.09 | DD21: 0.06 | DE21: =DD21+$DE$20 -> 0.02
B22: Incremental non-GAAP margin (ΔOI / ΔSales) | D22: =IFERROR((D16-C16)/(D11-C11),"") | E22: =IFERROR((E16-D16)/(E11-D11),"") | F22: =IFERROR((F16-E16)/(F11-E11),"") | G22: =IFERROR((G16-F16)/(G11-F11),"") | H22: =IFERROR((H16-G16)/(H11-G11),"") | I22: =IFERROR((I16-H16)/(I11-H11),"") | O22: =IFERROR((O16-I16)/(O11-I11),"") | P22: =IFERROR((P16-J16)/(P11-J11),"") | Q22: =IFERROR((Q16-K16)/(Q11-K11),"") | R22: =IFERROR((R16-L16)/(R11-L11),"") | S22: =IFERROR((S16-M16)/(S11-M11),"") | T22: =IFERROR((T16-N16)/(T11-N11),"") | U22: =IFERROR((U16-O16)/(U11-O11),"") | V22: =IFERROR((V16-P16)/(V11-P11),"") | ... CO22: =IFERROR((CO16-CI16)/(CO11-CI11),"") -> 0.35528051 | CP22: =IFERROR((CP16-CO16)/(CP11-CO11),"") -> 0.34614049 | CQ22: =IFERROR((CQ16-CP16)/(CQ11-CP11),"") -> 0.34090909 | CR22: =IFERROR((CR16-CQ16)/(CR11-CQ11),"") -> 0.355 | CS22: =IFERROR((CS16-CR16)/(CS11-CR11),"") -> 0.36 | DB22: 2028E | DC22: =DD22+$DC$20 -> 0.085 | DD22: 0.055 | DE22: =DD22+$DE$20 -> 0.015
B23: Segment D&A (annual, 10-K segment note) | E23: 10 | F23: 9.6 | G23: 9.3 | H23: 26.9 | I23: 30.5 | O23: 30.3 | U23: 29.6 | AA23: 26.1 | AG23: 26.2 | AM23: 49.6 | AS23: 50.8 | AY23: 48.5 | BE23: 49.2 | BK23: 309.2 | BQ23: 279 | BW23: 268.9 | CC23: 261.2 | CI23: 262.5 | DB23: 2029E | DC23: =DD23+$DC$20 -> 0.08 | DD23: 0.05 | DE23: =DD23+$DE$20 -> 0.01
B24: Segment capital expenditures (annual) | E24: 7.1 | F24: 5.7 | G24: 11.3 | H24: 13.8 | I24: 23.5 | O24: 20.2 | U24: 10.3 | AA24: 9.2 | AG24: 12.5 | AM24: 23.4 | AS24: 35.8 | AY24: 45.2 | BE24: 33.4 | BK24: 64.2 | BQ24: 63.9 | BW24: 78.2 | CC24: 54.7 | CI24: 67.7 | DB24: 2030E | DC24: =DD24+$DC$20 -> 0.08 | DD24: 0.05 | DE24: =DD24+$DE$20 -> 0.01
B25: Segment capex % of sales | C25: =IFERROR(C24/C11,"") | D25: =IFERROR(D24/D11,"") | E25: =IFERROR(E24/E11,"") -> 0.051673945 | F25: =IFERROR(F24/F11,"") -> 0.044776119 | G25: =IFERROR(G24/G11,"") -> 0.092244898 | H25: =IFERROR(H24/H11,"") -> 0.03943984 | I25: =IFERROR(I24/I11,"") -> 0.056503967 | O25: =IFERROR(O24/O11,"") -> 0.048698168 | U25: =IFERROR(U24/U11,"") -> 0.025520317 | AA25: =IFERROR(AA24/AA11,"") -> 0.024274406 | AG25: =IFERROR(AG24/AG11,"") -> 0.031351894 | AM25: =IFERROR(AM24/AM11,"") -> 0.032939189 | AS25: =IFERROR(AS24/AS11,"") -> 0.040900263 | AY25: =IFERROR(AY24/AY11,"") -> 0.045523215 | BE25: =IFERROR(BE24/BE11,"") -> 0.033874239 | BK25: =IFERROR(BK24/BK11,"") -> 0.026606987 | BQ25: =IFERROR(BQ24/BQ11,"") -> 0.02054068 | BW25: =IFERROR(BW24/BW11,"") -> 0.024871982 | CC25: =IFERROR(CC24/CC11,"") -> 0.017812948 | CI25: =IFERROR(CI24/CI11,"") -> 0.021397642
DB26: INST_organicGrowth (Instrumentation sales y/y) | DC26: 0.02 | DD26: Δ → | DE26: -0.03 | DF26: Instrumentation: marine (offshore energy, defense subsea), environmental (regulation), ETM.
B27: Instrumentation (marine, environmental, electronic test & measurement) | CT27: INSTRUMENTATION — modelling logic | DB27: 2027E | DC27: =DD27+$DC$26 -> 0.065 | DD27: 0.045 | DE27: =DD27+$DE$26 -> 0.015
B28: Net sales | E28: 549.2 | F28: 538.4 | G28: 573.2 | H28: 648.2 | I28: 804.7 | J28: 232.7 | K28: 257.7 | L28: =J28+K28 -> 490.4 | M28: 256.6 | N28: 275.8 | O28: 1022.8 | P28: 258.9 | Q28: 276.6 | R28: =P28+Q28 -> 535.5 | S28: 280.4 | T28: 299.6 | U28: 1115.5 | V28: 270.3 | W28: 271.3 | X28: =V28+W28 -> 541.6 | Y28: 243.2 | Z28: 266.3 | AA28: 1051.1 | AB28: 223.7 | AC28: 220.1 | AD28: =AB28+AC28 -> 443.8 | AE28: 208.3 | AF28: 224.6 | AG28: 876.7 | AH28: 232.8 | AI28: 233.8 | AJ28: =AH28+AI28 -> 466.6 | AK28: 232.5 | AL28: 254.8 | AM28: 953.9 | AN28: 239 | AO28: 262.6 | AP28: =AN28+AO28 -> 501.6 | AQ28: 256.2 | AR28: 263.4 | AS28: 1021.2 | AT28: 256.5 | AU28: 264.1 | AV28: =AT28+AU28 -> 520.6 | AW28: 282.9 | AX28: 301.6 | AY28: 1105.1 | AZ28: 285.1 | BA28: 263.1 | BB28: =AZ28+BA28 -> 548.2 | BC28: 263.5 | BD28: 282.8 | BE28: 1094.5 | BF28: 286.5 | BG28: 291.1 | BH28: =BF28+BG28 -> 577.6 | BI28: 287.1 | BJ28: 302.2 | BK28: 1166.9 | BL28: 308.9 | BM28: 312.5 | BN28: =BL28+BM28 -> 621.4 | BO28: 306.4 | BP28: 326.2 | BQ28: 1254 | BR28: 333.5 | BS28: 328.4 | BT28: =BR28+BS28 -> 661.9 | BU28: 329.1 | BV28: 335.2 | BW28: 1326.2 | BX28: 330.4 | BY28: 333.5 | BZ28: =BX28+BY28 -> 663.9 | CA28: 349.8 | CB28: 368.9 | CC28: 1382.6 | CD28: 343.3 | CE28: 367.6 | CF28: =CD28+CE28 -> 710.9 | CG28: 363.6 | CH28: 382.6 | CI28: 1457.1 | CJ28: 361.4 | CK28: 387.8 | CL28: =CJ28+CK28 -> 749.2 | CM28: =CG28*CK28/CE28 -> 383.5802 | CN28: =CH28*CK28/CE28 -> 403.62427 | CO28: =SUM(CJ28,CK28,CM28,CN28) -> 1536.4045 | CP28: =CO28*(1+CP29) -> 1605.5427 | CQ28: =CP28*(1+CQ29) -> 1677.7921 | CR28: =CQ28*(1+CR29) -> 1753.2927 | CS28: =CR28*(1+CS29) -> 1832.1909 | CT28: Q3/26E–Q4/26E: prior-year quarter × Q2/26 y/y growth of the segment (after the Excelitas A&D anniversary). 2027E+: prior year × (1 + scenario organic growth). | CV28: =IFERROR((CS28/CI28)^(1/5)-1,"n/m") -> 0.046878481 | CW28: =IFERROR((CI28/BE28)^(1/5)-1,"n/m") -> 0.05889944 | CX28: =IFERROR((CI28/AA28)^(1/10)-1,"n/m") -> 0.03320032 | CY28: =IFERROR((CI28/C28)^(1/19)-1,"n/m") -> n/m | DB28: 2028E | DC28: =DD28+$DC$26 -> 0.065 | DD28: 0.045 | DE28: =DD28+$DE$26 -> 0.015
B29: Net sales y/y % | D29: =IFERROR(D28/C28-1,"") | E29: =IFERROR(E28/D28-1,"") | F29: =IFERROR(F28/E28-1,"") -> -0.019664967 | G29: =IFERROR(G28/F28-1,"") -> 0.064635958 | H29: =IFERROR(H28/G28-1,"") -> 0.13084438 | I29: =IFERROR(I28/H28-1,"") -> 0.24143783 | O29: =IFERROR(O28/I28-1,"") -> 0.27103268 | P29: =IFERROR(P28/J28-1,"") -> 0.11259132 | Q29: =IFERROR(Q28/K28-1,"") -> 0.073341094 | R29: =IFERROR(R28/L28-1,"") -> 0.091965742 | S29: =IFERROR(S28/M28-1,"") -> 0.092751364 | T29: =IFERROR(T28/N28-1,"") -> 0.086294416 | U29: =IFERROR(U28/O28-1,"") -> 0.090633555 | V29: =IFERROR(V28/P28-1,"") -> 0.044032445 | ... CO29: =IFERROR(CO28/CI28-1,"") -> 0.054426231 | CP29: =CHOOSE(MATCH($CT$2,{"Bull","Base","Bear"},0),$DC$27,$DD$27,$DE$27) -> 0.045 | CQ29: =CHOOSE(MATCH($CT$2,{"Bull","Base","Bear"},0),$DC$28,$DD$28,$DE$28) -> 0.045 | CR29: =CHOOSE(MATCH($CT$2,{"Bull","Base","Bear"},0),$DC$29,$DD$29,$DE$29) -> 0.045 | CS29: =CHOOSE(MATCH($CT$2,{"Bull","Base","Bear"},0),$DC$30,$DD$30,$DE$30) -> 0.045 | CT29: 2027E–2030E: scenario lever (INST_organicGrowth, Bull/Base/Bear table →). | DB29: 2029E | DC29: =DD29+$DC$26 -> 0.065 | DD29: 0.045 | DE29: =DD29+$DE$26 -> 0.015
B30: Segment operating income (GAAP) | E30: 102.9 | F30: 95.5 | G30: 113.9 | H30: 129.3 | I30: 146 | J30: 36.6 | K30: 41.1 | L30: =J30+K30 -> 77.7 | M30: 39.9 | N30: 44.4 | O30: 162 | P30: 37.5 | Q30: 43.8 | R30: =P30+Q30 -> 81.3 | S30: 46.9 | T30: 53.4 | U30: 181.6 | V30: 42.1 | W30: 45.7 | X30: =V30+W30 -> 87.8 | Y30: 38.6 | Z30: 44.6 | AA30: 171 | AB30: 31.4 | AC30: 20.1 | AD30: =AB30+AC30 -> 51.5 | AE30: 28.1 | AF30: 30.2 | AG30: 109.8 | AH30: 30.2 | AI30: 30.5 | AJ30: =AH30+AI30 -> 60.7 | AK30: 34.6 | AL30: 30.7 | AM30: 126 | AN30: 27.8 | AO30: 40.9 | AP30: =AN30+AO30 -> 68.7 | AQ30: 35.7 | AR30: 43 | AS30: 147.4 | AT30: 39.9 | AU30: 49 | AV30: =AT30+AU30 -> 88.9 | AW30: 52 | AX30: 59.5 | AY30: 200.4 | AZ30: 50.8 | BA30: 48.5 | BB30: =AZ30+BA30 -> 99.3 | BC30: 50.7 | BD30: 63.2 | BE30: 213.2 | BF30: 59.4 | BG30: 64.6 | BH30: =BF30+BG30 -> 124 | BI30: 63 | BJ30: 66.7 | BK30: 253.7 | BL30: 71.6 | BM30: 73.6 | BN30: =BL30+BM30 -> 145.2 | BO30: 71.1 | BP30: 79 | BQ30: 295.3 | BR30: 80.7 | BS30: 81.4 | BT30: =BR30+BS30 -> 162.1 | BU30: 85.5 | BV30: 90.7 | BW30: 338.3 | BX30: 86 | BY30: 87.2 | BZ30: =BX30+BY30 -> 173.2 | CA30: 96.3 | CB30: 100.8 | CC30: 370.3 | CD30: 92.7 | CE30: 101.6 | CF30: =CD30+CE30 -> 194.3 | CG30: 98.8 | CH30: 107.3 | CI30: 400.4 | CJ30: 88.4 | CK30: 101.4 | CL30: =CJ30+CK30 -> 189.8 | CM30: =CM33-CM31-CM32 -> 93.176288 | CN30: =CN33-CN31-CN32 -> 93.588926 | CO30: =SUM(CJ30,CK30,CM30,CN30) -> 376.56521 | CP30: =CP33-CP31-CP32 -> 420.63191 | CQ30: =CQ33-CQ31-CQ32 -> 448.70435 | CR30: =CR33-CR31-CR32 -> 480.89996 | CS30: =CS33-CS31-CS32 -> 513.74377 | CT30: Forecast GAAP OI = non-GAAP OI − acquired-intangible amortization − other items. | CV30: =IFERROR((CS30/CI30)^(1/5)-1,"n/m") -> 0.051115645 | CW30: =IFERROR((CI30/BE30)^(1/5)-1,"n/m") -> 0.13433511 | CX30: =IFERROR((CI30/AA30)^(1/10)-1,"n/m") -> 0.088804221 | CY30: =IFERROR((CI30/C30)^(1/19)-1,"n/m") -> n/m | DB30: 2030E | DC30: =DD30+$DC$26 -> 0.065 | DD30: 0.045 | DE30: =DD30+$DE$26 -> 0.015
B31: (+) Acquired intangible asset amortization | AZ31: 4.8 | BA31: 5.1 | BB31: =AZ31+BA31 -> 9.9 | BC31: 5.1 | BD31: 4.8 | BE31: 19.8 | BF31: 5 | BG31: 5.2 | BH31: =BF31+BG31 -> 10.2 | BI31: 5 | BJ31: 4.9 | BK31: 20.1 | BL31: 4.9 | BM31: 4.7 | BN31: =BL31+BM31 -> 9.6 | BO31: 4 | BP31: 3.6 | BQ31: 17.2 | BR31: 3.7 | BS31: 3.5 | BT31: =BR31+BS31 -> 7.2 | BU31: 3.5 | BV31: 3.5 | BW31: 14.2 | BX31: 3.4 | BY31: 3.5 | BZ31: =BX31+BY31 -> 6.9 | CA31: 3.5 | CB31: 3.4 | CC31: 13.9 | CD31: 3.2 | CE31: 3.3 | CF31: =CD31+CE31 -> 6.5 | CG31: 3.3 | CH31: 3.1 | CI31: 12.9 | CJ31: 3.5 | CK31: 3.4 | CL31: =CJ31+CK31 -> 6.9 | CM31: =CM125*$CL$31/($CL$14+$CL$31+$CL$51+$CL$70) -> 3.4135563 | CN31: =CN125*$CL$31/($CL$14+$CL$31+$CL$51+$CL$70) -> 3.4135563 | CO31: =SUM(CJ31,CK31,CM31,CN31) -> 13.727113 | CP31: =CP371*$CL$31/($CL$14+$CL$31+$CL$51+$CL$70) -> 12.864613 | CQ31: =CQ371*$CL$31/($CL$14+$CL$31+$CL$51+$CL$70) -> 12.688468 | CR31: =CR371*$CL$31/($CL$14+$CL$31+$CL$51+$CL$70) -> 10.022007 | CS31: =CS371*$CL$31/($CL$14+$CL$31+$CL$51+$CL$70) -> 8.4306338 | CT31: Disclosed by segment from Q1/21. Forecast = amortization of existing intangibles (10-K schedule) × 1H/26 segment share.
B32: (+) Other segment non-GAAP items (inventory step-up, transaction costs) | CB32: 3 | CC32: 3 | CM32: 0 | CN32: 0 | CO32: =SUM(CJ32,CK32,CM32,CN32) -> 0 | CP32: 0 | CQ32: 0 | CR32: 0 | CS32: 0 | DB32: ADE_organicGrowth (Aerospace and Defense Electronics sales y/y) | DC32: 0.03 | DD32: Δ → | DE32: -0.04 | DF32: A&DE: defense electronics (budget growth), commercial aerospace build rates.
B33: Non-GAAP segment operating income | C33: =IF(OR(ISNUMBER(C34),ISNUMBER(C31)),C30+N(C31)+N(C32),"") | D33: =IF(OR(ISNUMBER(D34),ISNUMBER(D31)),D30+N(D31)+N(D32),"") | E33: =IF(OR(ISNUMBER(E34),ISNUMBER(E31)),E30+N(E31)+N(E32),"") | F33: =IF(OR(ISNUMBER(F34),ISNUMBER(F31)),F30+N(F31)+N(F32),"") | G33: =IF(OR(ISNUMBER(G34),ISNUMBER(G31)),G30+N(G31)+N(G32),"") | H33: =IF(OR(ISNUMBER(H34),ISNUMBER(H31)),H30+N(H31)+N(H32),"") | I33: =IF(OR(ISNUMBER(I34),ISNUMBER(I31)),I30+N(I31)+N(I32),"") | J33: =IF(OR(ISNUMBER(J34),ISNUMBER(J31)),J30+N(J31)+N(J32),"") | ... CL33: =IF(OR(ISNUMBER(CL34),ISNUMBER(CL31)),CL30+N(CL31)+N(CL32),"") -> 196.7 | CM33: =CM28*CM37 -> 96.589844 | CN33: =CN28*CN37 -> 97.002482 | CO33: =SUM(CJ33,CK33,CM33,CN33) -> 390.29233 | CP33: =CP28*CP37 -> 433.49652 | CQ33: =CQ28*CQ37 -> 461.39282 | CR33: =CR28*CR37 -> 490.92196 | CS33: =CS28*CS37 -> 522.17441 | CT33: Company non-GAAP measure from Q1/21 (segment OI excluding acquired-intangible amortization and acquisition items). Forecast = net sales × non-GAAP margin. | CV33: =IFERROR((CS33/CI33)^(1/5)-1,"n/m") -> 0.047876342 | CW33: =IFERROR((CI33/BE33)^(1/5)-1,"n/m") -> 0.12145512 | CX33: =IFERROR((CI33/AA33)^(1/10)-1,"n/m") -> n/m | CY33: =IFERROR((CI33/C33)^(1/19)-1,"n/m") -> n/m | DB33: 2027E | DC33: =DD33+$DC$32 -> 0.09 | DD33: 0.06 | DE33: =DD33+$DE$32 -> 0.02
B34: Memo: non-GAAP segment operating income as published | AZ34: 55.6 | BA34: 53.6 | BB34: =AZ34+BA34 -> 109.2 | BC34: 55.8 | BD34: 68 | BE34: 233 | BF34: 64.4 | BG34: 69.8 | BH34: =BF34+BG34 -> 134.2 | BI34: 68 | BJ34: 71.6 | BK34: 273.8 | BL34: 76.5 | BM34: 78.3 | BN34: =BL34+BM34 -> 154.8 | BO34: 75.1 | BP34: 82.6 | BQ34: 312.5 | BR34: 84.4 | BS34: 84.9 | BT34: =BR34+BS34 -> 169.3 | BU34: 89 | BV34: 94.2 | BW34: 352.5 | BX34: 89.4 | BY34: 90.7 | BZ34: =BX34+BY34 -> 180.1 | CA34: 99.8 | CB34: 107.2 | CC34: 387.2 | CD34: 95.9 | CE34: 104.9 | CF34: =CD34+CE34 -> 200.8 | CG34: 102.1 | CH34: 110.4 | CI34: 413.3 | CJ34: 91.9 | CK34: 104.8 | CL34: =CJ34+CK34 -> 196.7 | DB34: 2028E | DC34: =DD34+$DC$32 -> 0.085 | DD34: 0.055 | DE34: =DD34+$DE$32 -> 0.015
B35: Check: build vs published (should be 0) | C35: =IF(ISNUMBER(C34),ROUND(C33-C34,1),"n/p") -> n/p | D35: =IF(ISNUMBER(D34),ROUND(D33-D34,1),"n/p") -> n/p | E35: =IF(ISNUMBER(E34),ROUND(E33-E34,1),"n/p") -> n/p | F35: =IF(ISNUMBER(F34),ROUND(F33-F34,1),"n/p") -> n/p | G35: =IF(ISNUMBER(G34),ROUND(G33-G34,1),"n/p") -> n/p | H35: =IF(ISNUMBER(H34),ROUND(H33-H34,1),"n/p") -> n/p | I35: =IF(ISNUMBER(I34),ROUND(I33-I34,1),"n/p") -> n/p | J35: =IF(ISNUMBER(J34),ROUND(J33-J34,1),"n/p") -> n/p | ... CL35: =IF(ISNUMBER(CL34),ROUND(CL33-CL34,1),"n/p") -> 0 | DB35: 2029E | DC35: =DD35+$DC$32 -> 0.08 | DD35: 0.05 | DE35: =DD35+$DE$32 -> 0.01
B36: Segment operating margin (GAAP) % | C36: =IFERROR(C30/C28,"") | D36: =IFERROR(D30/D28,"") | E36: =IFERROR(E30/E28,"") -> 0.18736344 | F36: =IFERROR(F30/F28,"") -> 0.17737741 | G36: =IFERROR(G30/G28,"") -> 0.198709 | H36: =IFERROR(H30/H28,"") -> 0.19947547 | I36: =IFERROR(I30/I28,"") -> 0.18143407 | J36: =IFERROR(J30/J28,"") -> 0.15728406 | ... CS36: =IFERROR(CS30/CS28,"") -> 0.28039861 | CV36: =IFERROR(AVERAGE(CO36,CP36,CQ36,CR36,CS36),"n/m") -> 0.26584048 | CW36: =IFERROR(AVERAGE(BK36,BQ36,BW36,CC36,CI36),"n/m") -> 0.25012219 | CX36: =IFERROR(AVERAGE(AG36,AM36,AS36,AY36,BE36,BK36,BQ36,BW36,CC36,CI36),"n/m") -> 0.20284159 | CY36: =IFERROR(AVERAGE(C36,D36,E36,F36,G36,H36,I36,O36,U36,AA36,AG36,AM36,AS36,AY36,BE36,BK36,BQ36,BW36,CC36,CI36),"n/m") -> 0.19203598 | DB36: 2030E | DC36: =DD36+$DC$32 -> 0.08 | DD36: 0.05 | DE36: =DD36+$DE$32 -> 0.01
B37: Non-GAAP segment operating margin % | C37: =IFERROR(C33/C28,"") | D37: =IFERROR(D33/D28,"") | E37: =IFERROR(E33/E28,"") | F37: =IFERROR(F33/F28,"") | G37: =IFERROR(G33/G28,"") | H37: =IFERROR(H33/H28,"") | I37: =IFERROR(I33/I28,"") | J37: =IFERROR(J33/J28,"") | ... CL37: =IFERROR(CL33/CL28,"") -> 0.26254672 | CM37: =CG37+$CL$37-$CF$37+CM102 -> 0.25181134 | CN37: =CH37+$CL$37-$CF$37+CN102 -> 0.24032867 | CO37: =IFERROR(CO33/CO28,"") -> 0.25402968 | CP37: =CHOOSE(MATCH($CT$2,{"Bull","Base","Bear"},0),$DC$51,$DD$51,$DE$51) -> 0.27 | CQ37: =CHOOSE(MATCH($CT$2,{"Bull","Base","Bear"},0),$DC$52,$DD$52,$DE$52) -> 0.275 | CR37: =CHOOSE(MATCH($CT$2,{"Bull","Base","Bear"},0),$DC$53,$DD$53,$DE$53) -> 0.28 | CS37: =CHOOSE(MATCH($CT$2,{"Bull","Base","Bear"},0),$DC$54,$DD$54,$DE$54) -> 0.285 | CT37: Q3/Q4-26E: prior-year quarter margin + 1H/26 vs 1H/25 change + outlook calibration Δ. 2027E+: scenario lever (INST_margin). | CV37: =IFERROR(AVERAGE(CO37,CP37,CQ37,CR37,CS37),"n/m") -> 0.27280594 | CW37: =IFERROR(AVERAGE(BK37,BQ37,BW37,CC37,CI37),"n/m") -> 0.26266721 | CX37: =IFERROR(AVERAGE(AG37,AM37,AS37,AY37,BE37,BK37,BQ37,BW37,CC37,CI37),"n/m") -> 0.25436977 | CY37: =IFERROR(AVERAGE(C37,D37,E37,F37,G37,H37,I37,O37,U37,AA37,AG37,AM37,AS37,AY37,BE37,BK37,BQ37,BW37,CC37,CI37),"n/m") -> 0.25436977
B38: Segment operating income (GAAP) y/y % | D38: =IFERROR(D30/C30-1,"") | E38: =IFERROR(E30/D30-1,"") | F38: =IFERROR(F30/E30-1,"") -> -0.07191448 | G38: =IFERROR(G30/F30-1,"") -> 0.19267016 | H38: =IFERROR(H30/G30-1,"") -> 0.13520632 | I38: =IFERROR(I30/H30-1,"") -> 0.129157 | O38: =IFERROR(O30/I30-1,"") -> 0.10958904 | P38: =IFERROR(P30/J30-1,"") -> 0.024590164 | Q38: =IFERROR(Q30/K30-1,"") -> 0.065693431 | R38: =IFERROR(R30/L30-1,"") -> 0.046332046 | S38: =IFERROR(S30/M30-1,"") -> 0.1754386 | T38: =IFERROR(T30/N30-1,"") -> 0.2027027 | U38: =IFERROR(U30/O30-1,"") -> 0.12098765 | V38: =IFERROR(V30/P30-1,"") -> 0.12266667 | ... CO38: =IFERROR(CO30/CI30-1,"") -> -0.059527438 | CP38: =IFERROR(CP30/CO30-1,"") -> 0.11702274 | CQ38: =IFERROR(CQ30/CP30-1,"") -> 0.066738751 | CR38: =IFERROR(CR30/CQ30-1,"") -> 0.071752372 | CS38: =IFERROR(CS30/CR30-1,"") -> 0.068296567 | DB38: ES_organicGrowth (Engineered Systems sales y/y) | DC38: 0.03 | DD38: Δ → | DE38: -0.04 | DF38: Engineered Systems: US Government programs (missile defense, space), energy systems.
B39: Incremental non-GAAP margin (ΔOI / ΔSales) | D39: =IFERROR((D33-C33)/(D28-C28),"") | E39: =IFERROR((E33-D33)/(E28-D28),"") | F39: =IFERROR((F33-E33)/(F28-E28),"") | G39: =IFERROR((G33-F33)/(G28-F28),"") | H39: =IFERROR((H33-G33)/(H28-G28),"") | I39: =IFERROR((I33-H33)/(I28-H28),"") | O39: =IFERROR((O33-I33)/(O28-I28),"") | P39: =IFERROR((P33-J33)/(P28-J28),"") | Q39: =IFERROR((Q33-K33)/(Q28-K28),"") | R39: =IFERROR((R33-L33)/(R28-L28),"") | S39: =IFERROR((S33-M33)/(S28-M28),"") | T39: =IFERROR((T33-N33)/(T28-N28),"") | U39: =IFERROR((U33-O33)/(U28-O28),"") | V39: =IFERROR((V33-P33)/(V28-P28),"") | ... CO39: =IFERROR((CO33-CI33)/(CO28-CI28),"") -> -0.29011827 | CP39: =IFERROR((CP33-CO33)/(CP28-CO28),"") -> 0.6248961 | CQ39: =IFERROR((CQ33-CP33)/(CQ28-CP28),"") -> 0.38611111 | CR39: =IFERROR((CR33-CQ33)/(CR28-CQ28),"") -> 0.39111111 | CS39: =IFERROR((CS33-CR33)/(CS28-CR28),"") -> 0.39611111 | DB39: 2027E | DC39: =DD39+$DC$38 -> 0.07 | DD39: 0.04 | DE39: =DD39+$DE$38 -> 0
B40: Memo: Marine instrumentation sales | E40: 320.9 | F40: 335.1 | G40: 353.4 | H40: 404.4 | I40: 473.7 | J40: 127.1 | K40: 145.6 | L40: =J40+K40 -> 272.7 | M40: 151.6 | N40: 156.1 | O40: 580.4 | P40: 150.6 | Q40: 160.1 | R40: =P40+Q40 -> 310.7 | S40: 167.4 | T40: 176.7 | U40: 654.8 | V40: 159.5 | W40: 161.8 | X40: =V40+W40 -> 321.3 | Y40: 136.5 | Z40: 156.2 | AA40: 614 | AB40: 112.9 | AC40: 103.8 | AD40: =AB40+AC40 -> 216.7 | AE40: 97.6 | AF40: 104.4 | AG40: 418.7 | AM40: 430.7 | AS40: 433 | AY40: 450.2 | BE40: 426.3 | BF40: 102 | BG40: 104.9 | BH40: =BF40+BG40 -> 206.9 | BI40: 104.7 | BJ40: 112.5 | BK40: 424.1 | BL40: 111.9 | BM40: 115.3 | BN40: =BL40+BM40 -> 227.2 | BO40: 110 | BP40: 123.5 | BQ40: 460.7 | BR40: 128.2 | BS40: 127.4 | BT40: =BR40+BS40 -> 255.6 | BU40: 132.5 | BV40: 141.6 | BW40: 529.7 | BX40: 147.8 | BY40: 147.8 | BZ40: =BX40+BY40 -> 295.6 | CA40: 164.4 | CB40: 171.5 | CC40: 631.5 | CD40: 161.8 | CE40: 171.5 | CF40: =CD40+CE40 -> 333.3 | CG40: 169.7 | CH40: 177.1 | CI40: 680.1 | CJ40: 175.3 | CK40: 181.2 | CL40: =CJ40+CK40 -> 356.5 | DB40: 2028E | DC40: =DD40+$DC$38 -> 0.07 | DD40: 0.04 | DE40: =DD40+$DE$38 -> 0
...

Sheet Bull-Base-Bear
B2: Teledyne Technologies (TDY) — Bull / Base / Bear Case P&L Summary | J2: Share price ($): | K2: =Model!$CO$432 -> 615
B3: Non-GAAP figures (company current definition) · USD millions · Live panel linked to Model — toggle scenario via Model!CT2. Bull and Bear panels are value snapshots generated from the Model with the switch set to each case. | J3: As of: | K3: =TODAY() -> 46299
B5: Scenario: | C5: =Model!CT2 -> Base | N5: Scenario: | O5: Bull | P5: Snapshot (values) — Model run with switch = Bull | Z5: Scenario: | AA5: Bear | AB5: Snapshot (values) — Model run with switch = Bear
B7: (USDm, except EPS and shares) | C7: 2025A | D7: 2026E | E7: 2027E | F7: 2028E | G7: 2029E | H7: 2030E | I7: 25-'30 CAGR | J7: LT Hist Avg | K7: LT Hist Min | L7: LT Hist Max | N7: (USDm, except EPS and shares) | O7: 2025A | P7: 2026E | Q7: 2027E | R7: 2028E | S7: 2029E | T7: 2030E | U7: 25-'30 CAGR | V7: LT Hist Avg | W7: LT Hist Min | X7: LT Hist Max | Z7: (USDm, except EPS and shares) | AA7: 2025A | AB7: 2026E | AC7: 2027E | AD7: 2028E | AE7: 2029E | AF7: 2030E | AG7: 25-'30 CAGR | AH7: LT Hist Avg | AI7: LT Hist Min | AJ7: LT Hist Max
B9: Net Sales | C9: =Model!CI152 -> 6115.4 | D9: =Model!CO152 -> 6686.0877 | E9: =Model!CP152 -> 7179.9947 | F9: =Model!CQ152 -> 7851.4452 | G9: =Model!CR152 -> 8578.2966 | H9: =Model!CS152 -> 9344.6061 | I9: =IFERROR((H9/C9)^(1/5)-1,"n/m") -> 0.088496974 | N9: Net Sales | O9: 6115.4 | P9: 6686.0877 | Q9: 7490.2133 | R9: 8637.18 | S9: 9881.1415 | T9: 11209.549 | U9: 0.12884069 | Z9: Net Sales | AA9: 6115.4 | AB9: 6686.0877 | AC9: 6844.5819 | AD9: 7069.7166 | AE9: 7323.9719 | AF9: 7589.9868 | AG9: 0.044150812
B10: Net sales y/y % | D10: =IFERROR(D9/C9-1,"") -> 0.093319759 | E10: =IFERROR(E9/D9-1,"") -> 0.073870864 | F10: =IFERROR(F9/E9-1,"") -> 0.093516851 | G10: =IFERROR(G9/F9-1,"") -> 0.09257549 | H10: =IFERROR(H9/G9-1,"") -> 0.089331197 | N10: Net sales y/y % | P10: 0.093319759 | Q10: 0.12026849 | R10: 0.1531287 | S10: 0.14402403 | T10: 0.13443867 | Z10: Net sales y/y % | AB10: 0.093319759 | AC10: 0.023705085 | AD10: 0.032892387 | AE10: 0.035964004 | AF10: 0.036321127
B11: Organic growth % | C11: =Model!CI247 -> 0.030917108 | D11: =Model!CO247 -> 0.083263181 | E11: =Model!CP247 -> 0.055175327 | F11: =Model!CQ247 -> 0.052894722 | G11: =Model!CR247 -> 0.050120461 | H11: =Model!CS247 -> 0.050473444 | N11: Organic growth % | O11: 0.030917108 | P11: 0.083263181 | Q11: 0.082877414 | R11: 0.080812116 | S11: 0.076486557 | T11: 0.075403658 | Z11: Organic growth % | AA11: 0.030917108 | AB11: 0.083263181 | AC11: 0.017473239 | AD11: 0.014629767 | AE11: 0.012389273 | AF11: 0.013564805
B12: Non-GAAP Operating Income | C12: =Model!CI200 -> 1380 | D12: =Model!CO200 -> 1508.7264 | E12: =Model!CP200 -> 1677.4547 | F12: =Model!CQ200 -> 1856.8524 | G12: =Model!CR200 -> 2047.1616 | H12: =Model!CS200 -> 2252.5574 | I12: =IFERROR((H12/C12)^(1/5)-1,"n/m") -> 0.10295897 | N12: Non-GAAP Operating Income | O12: 1380 | P12: 1509.911 | Q12: 1816.2376 | R12: 2101.7855 | S12: 2409.556 | T12: 2745.51 | U12: 0.14748968 | Z12: Non-GAAP Operating Income | AA12: 1380 | AB12: 1502.7551 | AC12: 1467.1168 | AD12: 1546.1906 | AE12: 1628.4057 | AF12: 1716.413 | AG12: 0.044596439
B13: Non-GAAP operating margin % | C13: =IFERROR(C12/C9,"") -> 0.22565981 | D13: =IFERROR(D12/D9,"") -> 0.22565161 | E13: =IFERROR(E12/E9,"") -> 0.23362896 | F13: =IFERROR(F12/F9,"") -> 0.23649817 | G13: =IFERROR(G12/G9,"") -> 0.2386443 | H13: =IFERROR(H12/H9,"") -> 0.24105429 | J13: =IFERROR(AVERAGE(Model!C201,Model!D201,Model!E201,Model!F201,Model!G201,Model!H201,Model!I201,Model!O201,Model!U201,Model!AA201,Model!AG201,Model!AM201,Model!AS201,Model!AY201,Model!BE201,Model!BK201,Model!BQ201,Model!BW201,Model!CC201,Model!CI201),"") -> 0.15299587 | K13: =IFERROR(MIN(Model!C201,Model!D201,Model!E201,Model!F201,Model!G201,Model!H201,Model!I201,Model!O201,Model!U201,Model!AA201,Model!AG201,Model!AM201,Model!AS201,Model!AY201,Model!BE201,Model!BK201,Model!BQ201,Model!BW201,Model!CC201,Model!CI201),"") -> 0.092659782 | L13: =IFERROR(MAX(Model!C201,Model!D201,Model!E201,Model!F201,Model!G201,Model!H201,Model!I201,Model!O201,Model!U201,Model!AA201,Model!AG201,Model!AM201,Model!AS201,Model!AY201,Model!BE201,Model!BK201,Model!BQ201,Model!BW201,Model!CC201,Model!CI201),"") -> 0.22565981 | N13: Non-GAAP operating margin % | O13: 0.22565981 | P13: 0.22582878 | Q13: 0.24248142 | R13: 0.24334163 | S13: 0.24385401 | T13: 0.244926 | V13: 0.15299587 | W13: 0.092659782 | X13: 0.22565981 | Z13: Non-GAAP operating margin % | AA13: 0.22565981 | AB13: 0.22475851 | AC13: 0.21434718 | AD13: 0.21870617 | AE13: 0.22233915 | AF13: 0.22614176 | AH13: 0.15299587 | AI13: 0.092659782 | AJ13: 0.22565981
B15: Operating Income (GAAP) | C15: =Model!CI160 -> 1149.8 | D15: =Model!CO160 -> 1281.3264 | E15: =Model!CP160 -> 1449.7172 | F15: =Model!CQ160 -> 1606.4941 | G15: =Model!CR160 -> 1811.5366 | H15: =Model!CS160 -> 2013.9657 | I15: =IFERROR((H15/C15)^(1/5)-1,"n/m") -> 0.11862869 | N15: Operating Income (GAAP) | O15: 1149.8 | P15: 1282.511 | Q15: 1577.5626 | R15: 1818.6146 | S15: 2119.2435 | T15: 2430.3558 | U15: 0.16147405 | Z15: Operating Income (GAAP) | AA15: 1149.8 | AB15: 1275.3551 | AC15: 1246.671 | AD15: 1317.7073 | AE15: 1429.239 | AF15: 1528.863 | AG15: 0.058642323
B16: Operating income y/y % | D16: =IFERROR(D15/C15-1,"") -> 0.11439071 | E16: =IFERROR(E15/D15-1,"") -> 0.13141912 | F16: =IFERROR(F15/E15-1,"") -> 0.10814308 | G16: =IFERROR(G15/F15-1,"") -> 0.1276335 | H16: =IFERROR(H15/G15-1,"") -> 0.11174446 | N16: Operating income y/y % | P16: 0.11542094 | Q16: 0.23005776 | R16: 0.15280031 | S16: 0.1653065 | T16: 0.14680349 | Z16: Operating income y/y % | AB16: 0.10919733 | AC16: -0.022491077 | AD16: 0.056980808 | AE16: 0.084640745 | AF16: 0.069704192
B17: Operating margin (GAAP) % | C17: =IFERROR(C15/C9,"") -> 0.18801714 | D17: =IFERROR(D15/D9,"") -> 0.19164069 | E17: =IFERROR(E15/E9,"") -> 0.20191063 | F17: =IFERROR(F15/F9,"") -> 0.20461126 | G17: =IFERROR(G15/G9,"") -> 0.21117672 | H17: =IFERROR(H15/H9,"") -> 0.21552174 | J17: =IFERROR(AVERAGE(Model!C256,Model!D256,Model!E256,Model!F256,Model!G256,Model!H256,Model!I256,Model!O256,Model!U256,Model!AA256,Model!AG256,Model!AM256,Model!AS256,Model!AY256,Model!BE256,Model!BK256,Model!BQ256,Model!BW256,Model!CC256,Model!CI256),"") -> 0.13250642 | K17: =IFERROR(MIN(Model!C256,Model!D256,Model!E256,Model!F256,Model!G256,Model!H256,Model!I256,Model!O256,Model!U256,Model!AA256,Model!AG256,Model!AM256,Model!AS256,Model!AY256,Model!BE256,Model!BK256,Model!BQ256,Model!BW256,Model!CC256,Model!CI256),"") -> 0.08728719 | L17: =IFERROR(MAX(Model!C256,Model!D256,Model!E256,Model!F256,Model!G256,Model!H256,Model!I256,Model!O256,Model!U256,Model!AA256,Model!AG256,Model!AM256,Model!AS256,Model!AY256,Model!BE256,Model!BK256,Model!BQ256,Model!BW256,Model!CC256,Model!CI256),"") -> 0.18801714 | N17: Operating margin (GAAP) % | O17: 0.18801714 | P17: 0.19181785 | Q17: 0.21061651 | R17: 0.21055653 | S17: 0.21447355 | T17: 0.2168112 | V17: 0.13250642 | W17: 0.08728719 | X17: 0.18801714 | Z17: Operating margin (GAAP) % | AA17: 0.18801714 | AB17: 0.19074759 | AC17: 0.18213983 | AD17: 0.18638757 | AE17: 0.19514535 | AF17: 0.20143157 | AH17: 0.13250642 | AI17: 0.08728719 | AJ17: 0.18801714
B19: Non-GAAP Net Income (attributable to Teledyne) | C19: =Model!CI242 -> 1042.3 | D19: =Model!CO242 -> 1150.7812 | E19: =Model!CP242 -> 1300.7681 | F19: =Model!CQ242 -> 1420.6008 | G19: =Model!CR242 -> 1545.8904 | H19: =Model!CS242 -> 1699.0408 | I19: =IFERROR((H19/C19)^(1/5)-1,"n/m") -> 0.10266151 | N19: Non-GAAP Net Income (attributable to Teledyne) | O19: 1042.3 | P19: 1151.7111 | Q19: 1403.6283 | R19: 1567.826 | S19: 1774.3121 | T19: 2017.991 | U19: 0.14126184 | Z19: Non-GAAP Net Income (attributable to Teledyne) | AA19: 1042.3 | AB19: 1146.0938 | AC19: 1135.6883 | AD19: 1183.8803 | AE19: 1230.1973 | AF19: 1296.5845 | AG19: 0.044627887
B21: FDSO (m) | C21: =Model!CI179 -> 47.4 | D21: =Model!CO179 -> 46.875 | E21: =Model!CP179 -> 46.121231 | F21: =Model!CQ179 -> 44.756121 | G21: =Model!CR179 -> 43.934855 | H21: =Model!CS179 -> 42.989737 | I21: =IFERROR((H21/C21)^(1/5)-1,"n/m") -> -0.019342646 | N21: FDSO (m) | O21: 47.4 | P21: 46.722561 | Q21: 45.571071 | R21: 44.342901 | S21: 43.991208 | T21: 43.336178 | U21: -0.017767153 | Z21: FDSO (m) | AA21: 47.4 | AB21: 46.875 | AC21: 45.996745 | AD21: 44.355263 | AE21: 43.301528 | AF21: 42.26211 | AG21: -0.022684995
B23: Non-GAAP EPS — Diluted ($) | C23: =Model!CI243 -> 21.989451 | D23: =Model!CO243 -> 24.55 | E23: =Model!CP243 -> 28.203239 | F23: =Model!CQ243 -> 31.740928 | G23: =Model!CR243 -> 35.185967 | H23: =Model!CS243 -> 39.52201 | I23: =IFERROR((H23/C23)^(1/5)-1,"n/m") -> 0.12441059 | N23: Non-GAAP EPS — Diluted ($) | O23: 21.989451 | P23: 24.65 | Q23: 30.800863 | R23: 35.356866 | S23: 40.333334 | T23: 46.565966 | U23: 0.1619056 | Z23: Non-GAAP EPS — Diluted ($) | AA23: 21.989451 | AB23: 24.45 | AC23: 24.690623 | AD23: 26.690863 | AE23: 28.410022 | AF23: 30.679596 | AG23: 0.068875319
B24: EPS y/y % | D24: =IFERROR(D23/C23-1,"") -> 0.1164444 | E24: =IFERROR(E23/D23-1,"") -> 0.14880811 | F24: =IFERROR(F23/E23-1,"") -> 0.12543555 | G24: =IFERROR(G23/F23-1,"") -> 0.10853617 | H24: =IFERROR(H23/G23-1,"") -> 0.12323217 | N24: EPS y/y % | P24: 0.12099204 | Q24: 0.2495279 | R24: 0.14791804 | S24: 0.14074969 | T24: 0.15452806 | Z24: EPS y/y % | AB24: 0.11189677 | AC24: 0.0098414369 | AD24: 0.081012141 | AE24: 0.064409989 | AF24: 0.079886412
B26: P / E (x) — assumed (non-GAAP EPS) | G26: 23 | H26: 23 | N26: P / E (x) — assumed (non-GAAP EPS) | S26: 25 | T26: 25 | Z26: P / E (x) — assumed (non-GAAP EPS) | AD26: 18 | AE26: 18 | AF26: 18
B27: Price Target ($) | G27: =G26*G23 -> 809.27724 | H27: =H26*H23 -> 909.00623 | N27: Price Target ($) | S27: =S26*S23 -> 1008.3334 | T27: =T26*T23 -> 1164.1491 | Z27: Price Target ($) | AD27: =AD26*AD23 -> 480.43554 | AE27: =AE26*AE23 -> 511.38039 | AF27: =AF26*AF23 -> 552.23273
B28: Upside / (Downside) vs current | G28: =IFERROR(G27/$K$2-1,"") -> 0.31589795 | H28: =IFERROR(H27/$K$2-1,"") -> 0.47805891 | N28: Upside / (Downside) vs current | S28: =IFERROR(S27/$K$2-1,"") -> 0.63956643 | T28: =IFERROR(T27/$K$2-1,"") -> 0.89292544 | Z28: Upside / (Downside) vs current | AD28: =IFERROR(AD27/$K$2-1,"") -> -0.218804 | AE28: =IFERROR(AE27/$K$2-1,"") -> -0.16848717 | AF28: =IFERROR(AF27/$K$2-1,"") -> -0.1020606
B29: IRR (to Dec-Y-1) | G29: =IFERROR((G27/$K$2)^(1/((DATE(2029-1,12,31)-$K$3)/365.25))-1,"") -> 0.13023724 | H29: =IFERROR((H27/$K$2)^(1/((DATE(2030-1,12,31)-$K$3)/365.25))-1,"") -> 0.12810077 | N29: IRR (to Dec-Y-1) | S29: =IFERROR((S27/$K$2)^(1/((DATE(2029-1,12,31)-$K$3)/365.25))-1,"") -> 0.24670255 | T29: =IFERROR((T27/$K$2)^(1/((DATE(2030-1,12,31)-$K$3)/365.25))-1,"") -> 0.21756571 | Z29: IRR (to Dec-Y-1) | AD29: =IFERROR((AD27/$K$2)^(1/((DATE(2029-1,12,31)-$K$3)/365.25))-1,"") -> -0.10427621 | AE29: =IFERROR((AE27/$K$2)^(1/((DATE(2029-1,12,31)-$K$3)/365.25))-1,"") -> -0.078990942 | AF29: =IFERROR((AF27/$K$2)^(1/((DATE(2030-1,12,31)-$K$3)/365.25))-1,"") -> -0.032664198
B31: Free Cash Flow | C31: =Model!CI291 -> 1074 | D31: =Model!CO291 -> 1111.2015 | E31: =Model!CP291 -> 1299.6122 | F31: =Model!CQ291 -> 1409.7857 | G31: =Model!CR291 -> 1531.7869 | H31: =Model!CS291 -> 1674.6891 | I31: =IFERROR((H31/C31)^(1/5)-1,"n/m") -> 0.092913983 | N31: Free Cash Flow | O31: 1074 | P31: 1112.1314 | Q31: 1356.7676 | R31: 1495.263 | S31: 1703.478 | T31: 1939.2194 | U31: 0.12544566 | Z31: Free Cash Flow | AA31: 1074 | AB31: 1106.514 | AC31: 1185.0146 | AD31: 1232.7018 | AE31: 1270.5212 | AF31: 1323.946 | AG31: 0.042733193
B32: FCF % | C32: =IFERROR(C31/C9,"") -> 0.1756222 | D32: =IFERROR(D31/D9,"") -> 0.16619608 | E32: =IFERROR(E31/E9,"") -> 0.18100462 | F32: =IFERROR(F31/F9,"") -> 0.17955748 | G32: =IFERROR(G31/G9,"") -> 0.17856539 | H32: =IFERROR(H31/H9,"") -> 0.17921452 | J32: =IFERROR(AVERAGE(Model!C294,Model!D294,Model!E294,Model!F294,Model!G294,Model!H294,Model!I294,Model!O294,Model!U294,Model!AA294,Model!AG294,Model!AM294,Model!AS294,Model!AY294,Model!BE294,Model!BK294,Model!BQ294,Model!BW294,Model!CC294,Model!CI294),"") -> 0.10310692 | K32: =IFERROR(MIN(Model!C294,Model!D294,Model!E294,Model!F294,Model!G294,Model!H294,Model!I294,Model!O294,Model!U294,Model!AA294,Model!AG294,Model!AM294,Model!AS294,Model!AY294,Model!BE294,Model!BK294,Model!BQ294,Model!BW294,Model!CC294,Model!CI294),"") -> 0.036282445 | L32: =IFERROR(MAX(Model!C294,Model!D294,Model!E294,Model!F294,Model!G294,Model!H294,Model!I294,Model!O294,Model!U294,Model!AA294,Model!AG294,Model!AM294,Model!AS294,Model!AY294,Model!BE294,Model!BK294,Model!BQ294,Model!BW294,Model!CC294,Model!CI294),"") -> 0.19544974 | N32: FCF % | O32: 0.1756222 | P32: 0.16633515 | Q32: 0.18113871 | R32: 0.17311935 | S32: 0.17239688 | T32: 0.17299709 | V32: 0.10310692 | W32: 0.036282445 | X32: 0.19544974 | Z32: FCF % | AA32: 0.1756222 | AB32: 0.16549499 | AC32: 0.17313177 | AD32: 0.17436368 | AE32: 0.17347435 | AF32: 0.17443324 | AH32: 0.10310692 | AI32: 0.036282445 | AJ32: 0.19544974
B33: FCF / share ($) | C33: =IFERROR(C31/C21,"") -> 22.658228 | D33: =IFERROR(D31/D21,"") -> 23.705633 | E33: =IFERROR(E31/E21,"") -> 28.178177 | F33: =IFERROR(F31/F21,"") -> 31.499283 | G33: =IFERROR(G31/G21,"") -> 34.864957 | H33: =IFERROR(H31/H21,"") -> 38.955556 | N33: FCF / share ($) | O33: 22.658228 | P33: 23.802878 | Q33: 29.772563 | R33: 33.720459 | S33: 38.723146 | T33: 44.748278 | Z33: FCF / share ($) | AA33: 22.658228 | AB33: 23.605633 | AC33: 25.76301 | AD33: 27.791557 | AE33: 29.341256 | AF33: 31.327021
B34: FCF Yield (on PT) | E34: =IFERROR(E33/E$27,"") | F34: =IFERROR(F33/F$27,"") | G34: =IFERROR(G33/G$27,"") -> 0.043081599 | H34: =IFERROR(H33/H$27,"") -> 0.042855103 | N34: FCF Yield (on PT) | Q34: =IFERROR(Q33/Q$27,"") | R34: =IFERROR(R33/R$27,"") | S34: =IFERROR(S33/S$27,"") -> 0.038403119 | T34: =IFERROR(T33/T$27,"") -> 0.038438613 | Z34: FCF Yield (on PT) | AC34: =IFERROR(AC33/AC$27,"") | AD34: =IFERROR(AD33/AD$27,"") -> 0.057846589 | AE34: =IFERROR(AE33/AE$27,"") -> 0.057376577 | AF34: =IFERROR(AF33/AF$27,"") -> 0.056727932
B35: Adjusted EBITDA (model) | C35: =Model!CI211 -> 1504 | D35: =Model!CO211 -> 1635.4591 | E35: =Model!CP211 -> 1827.4646 | F35: =Model!CQ211 -> 2019.9556 | G35: =Model!CR211 -> 2224.4384 | H35: =Model!CS211 -> 2444.7772 | I35: =IFERROR((H35/C35)^(1/5)-1,"n/m") -> 0.10204237 | N35: Adjusted EBITDA (model) | O35: 1504 | P35: 1636.6436 | Q35: 1972.2968 | R35: 2280.2105 | S35: 2612.2382 | T35: 2974.0962 | U35: 0.14609715 | Z35: Adjusted EBITDA (model) | AA35: 1504 | AB35: 1629.4877 | AC35: 1610.5862 | AD35: 1694.0501 | AE35: 1781.2232 | AF35: 1874.4177 | AG35: 0.045017851
B36: Adjusted EBITDA margin % | C36: =IFERROR(C35/C9,"") -> 0.24593649 | D36: =IFERROR(D35/D9,"") -> 0.24460629 | E36: =IFERROR(E35/E9,"") -> 0.25452172 | F36: =IFERROR(F35/F9,"") -> 0.25727182 | G36: =IFERROR(G35/G9,"") -> 0.25931003 | H36: =IFERROR(H35/H9,"") -> 0.26162443 | J36: =IFERROR(AVERAGE(Model!C257,Model!D257,Model!E257,Model!F257,Model!G257,Model!H257,Model!I257,Model!O257,Model!U257,Model!AA257,Model!AG257,Model!AM257,Model!AS257,Model!AY257,Model!BE257,Model!BK257,Model!BQ257,Model!BW257,Model!CC257,Model!CI257),"") -> 0.17677599 | K36: =IFERROR(MIN(Model!C257,Model!D257,Model!E257,Model!F257,Model!G257,Model!H257,Model!I257,Model!O257,Model!U257,Model!AA257,Model!AG257,Model!AM257,Model!AS257,Model!AY257,Model!BE257,Model!BK257,Model!BQ257,Model!BW257,Model!CC257,Model!CI257),"") -> 0.11310354 | L36: =IFERROR(MAX(Model!C257,Model!D257,Model!E257,Model!F257,Model!G257,Model!H257,Model!I257,Model!O257,Model!U257,Model!AA257,Model!AG257,Model!AM257,Model!AS257,Model!AY257,Model!BE257,Model!BK257,Model!BQ257,Model!BW257,Model!CC257,Model!CI257),"") -> 0.24593649 | N36: Adjusted EBITDA margin % | O36: 0.24593649 | P36: 0.24478345 | Q36: 0.2633165 | R36: 0.26399942 | S36: 0.26436604 | T36: 0.26531809 | V36: 0.17677599 | W36: 0.11310354 | X36: 0.24593649 | Z36: Adjusted EBITDA margin % | AA36: 0.24593649 | AB36: 0.24371319 | AC36: 0.23530819 | AD36: 0.23962065 | AE36: 0.24320453 | AF36: 0.24695929 | AH36: 0.17677599 | AI36: 0.11310354 | AJ36: 0.24593649
B38: Net Debt | C38: =Model!CI426 -> 2123 | D38: =Model!CO426 -> 1023.2985 | E38: =Model!CP426 -> 1827.4646 | F38: =Model!CQ426 -> 2019.9556 | G38: =Model!CR426 -> 2224.4384 | H38: =Model!CS426 -> 2444.7772 | N38: Net Debt | O38: 2123 | P38: 1272.3686 | Q38: 2958.4451 | R38: 3420.3157 | S38: 3918.3573 | T38: 4461.1443 | Z38: Net Debt | AA38: 2123 | AB38: 1027.986 | AC38: 1610.5862 | AD38: 1694.0501 | AE38: 1781.2232 | AF38: 1874.4177
B39: Net Debt / Adjusted EBITDA (x) | C39: =IFERROR(C38/C35,"") -> 1.4115691 | D39: =IFERROR(D38/D35,"") -> 0.62569494 | E39: =IFERROR(E38/E35,"") -> 1 | F39: =IFERROR(F38/F35,"") -> 1 | G39: =IFERROR(G38/G35,"") -> 1 | H39: =IFERROR(H38/H35,"") -> 1 | N39: Net Debt / Adjusted EBITDA (x) | O39: 1.4115691 | P39: 0.77742556 | Q39: 1.5 | R39: 1.5 | S39: 1.5 | T39: 1.5 | Z39: Net Debt / Adjusted EBITDA (x) | AA39: 1.4115691 | AB39: 0.6308645 | AC39: 1 | AD39: 1 | AE39: 1 | AF39: 1
B41: ROIC | C41: =Model!CI406 -> 0.089368681 | D41: =Model!CO406 -> 0.094730158 | E41: =Model!CP406 -> 0.099584771 | F41: =Model!CQ406 -> 0.10342747 | G41: =Model!CR406 -> 0.10725735 | H41: =Model!CS406 -> 0.11131318 | J41: =IFERROR(AVERAGE(Model!C406,Model!D406,Model!E406,Model!F406,Model!G406,Model!H406,Model!I406,Model!O406,Model!U406,Model!AA406,Model!AG406,Model!AM406,Model!AS406,Model!AY406,Model!BE406,Model!BK406,Model!BQ406,Model!BW406,Model!CC406,Model!CI406),"") -> 0.12004492 | K41: =IFERROR(MIN(Model!C406,Model!D406,Model!E406,Model!F406,Model!G406,Model!H406,Model!I406,Model!O406,Model!U406,Model!AA406,Model!AG406,Model!AM406,Model!AS406,Model!AY406,Model!BE406,Model!BK406,Model!BQ406,Model!BW406,Model!CC406,Model!CI406),"") -> 0.072912591 | L41: =IFERROR(MAX(Model!C406,Model!D406,Model!E406,Model!F406,Model!G406,Model!H406,Model!I406,Model!O406,Model!U406,Model!AA406,Model!AG406,Model!AM406,Model!AS406,Model!AY406,Model!BE406,Model!BK406,Model!BQ406,Model!BW406,Model!CC406,Model!CI406),"") -> 0.17057143 | N41: ROIC | O41: 0.089368681 | P41: 0.094803833 | Q41: 0.10174979 | R41: 0.10526119 | S41: 0.10909992 | T41: 0.11344562 | V41: 0.12004492 | W41: 0.072912591 | X41: 0.17057143 | Z41: ROIC | AA41: 0.089368681 | AB41: 0.094358765 | AC41: 0.090856829 | AD41: 0.093379181 | AE41: 0.095730451 | AF41: 0.098122886 | AH41: 0.12004492 | AI41: 0.072912591 | AJ41: 0.17057143
B42: RONTA | C42: =Model!CI418 -> 0.36576729 | D42: =Model!CO418 -> 0.30983055 | E42: =Model!CP418 -> 0.40811295 | F42: =Model!CQ418 -> 0.43874808 | G42: =Model!CR418 -> 0.46954886 | H42: =Model!CS418 -> 0.49969959 | J42: =IFERROR(AVERAGE(Model!C418,Model!D418,Model!E418,Model!F418,Model!G418,Model!H418,Model!I418,Model!O418,Model!U418,Model!AA418,Model!AG418,Model!AM418,Model!AS418,Model!AY418,Model!BE418,Model!BK418,Model!BQ418,Model!BW418,Model!CC418,Model!CI418),"") -> 0.28276514 | K42: =IFERROR(MIN(Model!C418,Model!D418,Model!E418,Model!F418,Model!G418,Model!H418,Model!I418,Model!O418,Model!U418,Model!AA418,Model!AG418,Model!AM418,Model!AS418,Model!AY418,Model!BE418,Model!BK418,Model!BQ418,Model!BW418,Model!CC418,Model!CI418),"") -> 0.19588641 | L42: =IFERROR(MAX(Model!C418,Model!D418,Model!E418,Model!F418,Model!G418,Model!H418,Model!I418,Model!O418,Model!U418,Model!AA418,Model!AG418,Model!AM418,Model!AS418,Model!AY418,Model!BE418,Model!BK418,Model!BQ418,Model!BW418,Model!CC418,Model!CI418),"") -> 0.37213017 | N42: RONTA | O42: 0.36576729 | P42: 0.33150542 | Q42: 0.43509613 | R42: 0.47863414 | S42: 0.52173753 | T42: 0.56329799 | V42: 0.28276514 | W42: 0.19588641 | X42: 0.37213017 | Z42: RONTA | AA42: 0.36576729 | AB42: 0.30899184 | AC42: 0.35038685 | AD42: 0.3758629 | AE42: 0.39611395 | AF42: 0.41227791 | AH42: 0.28276514 | AI42: 0.19588641 | AJ42: 0.37213017
B44: Implied Market Cap (USDm) | E44: =E27*E21 -> 0 | F44: =F27*F21 -> 0 | G44: =G27*G21 -> 35555.478 | H44: =H27*H21 -> 39077.939 | N44: Implied Market Cap (USDm) | Q44: =Q27*Q21 -> 0 | R44: =R27*R21 -> 0 | S44: =S27*S21 -> 44357.802 | T44: =T27*T21 -> 50449.775 | Z44: Implied Market Cap (USDm) | AC44: =AC27*AC21 -> 0 | AD44: =AD27*AD21 -> 21309.845 | AE44: =AE27*AE21 -> 22143.552 | AF44: =AF27*AF21 -> 23338.52
B45: (+) Net Debt & NCI | E45: =E38+Model!CP436 -> 1827.4646 | F45: =F38+Model!CQ436 -> 2019.9556 | G45: =G38+Model!CR436 -> 2224.4384 | H45: =H38+Model!CS436 -> 2444.7772 | N45: (+) Net Debt & NCI | Q45: =Q38+Model!CP436 -> 2958.4451 | R45: =R38+Model!CQ436 -> 3420.3157 | S45: =S38+Model!CR436 -> 3918.3573 | T45: =T38+Model!CS436 -> 4461.1443 | Z45: (+) Net Debt & NCI | AC45: =AC38+Model!CP436 -> 1610.5862 | AD45: =AD38+Model!CQ436 -> 1694.0501 | AE45: =AE38+Model!CR436 -> 1781.2232 | AF45: =AF38+Model!CS436 -> 1874.4177
B46: Implied Enterprise Value (USDm) | E46: =E44+E45 -> 1827.4646 | F46: =F44+F45 -> 2019.9556 | G46: =G44+G45 -> 37779.917 | H46: =H44+H45 -> 41522.716 | N46: Implied Enterprise Value (USDm) | Q46: =Q44+Q45 -> 2958.4451 | R46: =R44+R45 -> 3420.3157 | S46: =S44+S45 -> 48276.159 | T46: =T44+T45 -> 54910.919 | Z46: Implied Enterprise Value (USDm) | AC46: =AC44+AC45 -> 1610.5862 | AD46: =AD44+AD45 -> 23003.895 | AE46: =AE44+AE45 -> 23924.775 | AF46: =AF44+AF45 -> 25212.938
B47: Implied EV / Adjusted EBITDA (x) | E47: =IFERROR(E46/E35,"") -> 1 | F47: =IFERROR(F46/F35,"") -> 1 | G47: =IFERROR(G46/G35,"") -> 16.984025 | H47: =IFERROR(H46/H35,"") -> 16.984253 | N47: Implied EV / Adjusted EBITDA (x) | Q47: =IFERROR(Q46/Q35,"") -> 1.5 | R47: =IFERROR(R46/R35,"") -> 1.5 | S47: =IFERROR(S46/S35,"") -> 18.480764 | T47: =IFERROR(T46/T35,"") -> 18.463061 | Z47: Implied EV / Adjusted EBITDA (x) | AC47: =IFERROR(AC46/AC35,"") -> 1 | AD47: =IFERROR(AD46/AD35,"") -> 13.579229 | AE47: =IFERROR(AE46/AE35,"") -> 13.431655 | AF47: =IFERROR(AF46/AF35,"") -> 13.451078

Sheet DCF
B2: DCF VALUATION — TELEDYNE TECHNOLOGIES (TDY)
B4: 1. WACC BUILD
B5: Risk-free rate (US 10Y govt) | C5: 0.055 | D5: Assumption (~US 10Y Treasury yield); update to market
B6: Equity risk premium | C6: 0.05 | D6: US implied ERP ~4.5–5.5% (Damodaran)
B7: Levered beta | C7: 1 | D7: Diversified instrumentation / A&D electronics peers (AME, KEYS, LHX) ~0.9–1.1; ~25% US Government sales dampen cyclicality
B8: Cost of equity | C8: =C5+C7*C6 -> 0.105
B9: Pre-tax cost of debt | C9: 0.0475 | D9: BBB-rated (investment grade); FLIR-acquisition notes 1.6%–2.75% fixed coupons; marginal cost ~4.5–5.0%
B10: Tax rate | C10: 0.215 | D10: Model 2027E+ effective tax rate (FY26 outlook rate in the scenario table)
B11: After-tax cost of debt | C11: =C9*(1-C10) -> 0.0372875
B12: Target D/V | C12: 0.2 | D12: Net debt ~$1.7bn vs ~$29bn market cap; leverage 1.1x at 30-Jun-26
B13: WACC | C13: =C8*(1-C12)+C11*C12 -> 0.0914575
B15: Valuation date (live) | C15: =TODAY() -> 46299 | D15: Periods = (Dec-31-Year − today) / 365.25; cash flows assumed at year-end
B16: 2. UNLEVERED FREE CASH FLOW BUILD (USDm)
D17: 2026E | E17: 2027E | F17: 2028E | G17: 2029E | H17: 2030E | I17: 2031E | J17: 2032E | K17: 2033E | L17: 2034E | M17: 2035E | N17: Terminal | P17: CAGR 26–30E | Q17: CAGR 26–35E
B18: Non-GAAP operating income (Model, current definition) | D18: =Model!CO200 -> 1508.7264 | E18: =Model!CP200 -> 1677.4547 | F18: =Model!CQ200 -> 1856.8524 | G18: =Model!CR200 -> 2047.1616 | H18: =Model!CS200 -> 2252.5574 | I18: =H18*(1+I$31) -> 2410.2364 | J18: =I18*(1+J$31) -> 2566.9018 | K18: =J18*(1+K$31) -> 2720.9159 | L18: =K18*(1+L$31) -> 2870.5663 | M18: =L18*(1+M$31) -> 3014.0946 | P18: =IFERROR(($H18/$D18)^(1/(VALUE(LEFT($H$17,4))-VALUE(LEFT($D$17,4))))-1,"n/m") -> 0.10539206 | Q18: =IFERROR(($M18/$D18)^(1/(VALUE(LEFT($M$17,4))-VALUE(LEFT($D$17,4))))-1,"n/m") -> 0.079926112
B19: y/y % | E19: =IFERROR(E18/D18-1,"") -> 0.11183492 | F19: =IFERROR(F18/E18-1,"") -> 0.10694638 | G19: =IFERROR(G18/F18-1,"") -> 0.10249017 | H19: =IFERROR(H18/G18-1,"") -> 0.10033201 | I19: =IFERROR(I18/H18-1,"") -> 0.07 | J19: =IFERROR(J18/I18-1,"") -> 0.065 | K19: =IFERROR(K18/J18-1,"") -> 0.06 | L19: =IFERROR(L18/K18-1,"") -> 0.055 | M19: =IFERROR(M18/L18-1,"") -> 0.05
B20: (−) Transaction & integration costs (cash, excluded from non-GAAP) | D20: =-Model!CO98 -> -1.4 | E20: =-Model!CP98 -> -5 | F20: =-Model!CQ98 -> -5 | G20: =-Model!CR98 -> -5 | H20: =-Model!CS98 -> -5 | I20: =H20*(1+I$31) -> -5.35 | J20: =I20*(1+J$31) -> -5.69775 | K20: =J20*(1+K$31) -> -6.039615 | L20: =K20*(1+L$31) -> -6.3717938 | M20: =L20*(1+M$31) -> -6.6903835
B21: × (1 − tax rate) | D21: =1-$C$10 -> 0.785 | E21: =1-$C$10 -> 0.785 | F21: =1-$C$10 -> 0.785 | G21: =1-$C$10 -> 0.785 | H21: =1-$C$10 -> 0.785 | I21: =1-$C$10 -> 0.785 | J21: =1-$C$10 -> 0.785 | K21: =1-$C$10 -> 0.785 | ... M21: =1-$C$10 -> 0.785
B22: NOPAT = (Non-GAAP OI − transaction costs) × (1 − t) | D22: =(D18+D20)*D21 -> 1183.2512 | E22: =(E18+E20)*E21 -> 1312.877 | F22: =(F18+F20)*F21 -> 1453.7042 | G22: =(G18+G20)*G21 -> 1603.0968 | H22: =(H18+H20)*H21 -> 1764.3326 | I22: =(I18+I20)*I21 -> 1887.8359 | J22: =(J18+J20)*J21 -> 2010.5452 | K22: =(K18+K20)*K21 -> 2131.1779 | ... M22: =(M18+M20)*M21 -> 2360.8123
B23: plus depreciation (D&A ex acquired-intangible amortization) | D23: =Model!CO140 -> 123.03264 | E23: =Model!CP140 -> 140.0099 | F23: =Model!CQ140 -> 153.10318 | G23: =Model!CR140 -> 167.27678 | H23: =Model!CS140 -> 182.21982 | I23: =H23*(1+I$31) -> 194.97521 | J23: =I23*(1+J$31) -> 207.6486 | K23: =J23*(1+K$31) -> 220.10751 | L23: =K23*(1+L$31) -> 232.21342 | M23: =L23*(1+M$31) -> 243.82409
B24: − Capex (PP&E) and acquisitions (M&A lever, 2027E+) | D24: =D29 -> -125 | E24: =E29+Model!CP273 -> -893.59989 | F24: =F29+Model!CQ273 -> -1157.0289 | G24: =G29+Model!CR273 -> -1171.5659 | H24: =H29+Model!CS273 -> -1186.8921 | I24: =I29 -> -199.97457 | J24: =J29 -> -212.97292 | K24: =K29 -> -225.75129 | L24: =L29 -> -238.16761 | M24: =M29 -> -250.07599
