Workbook

Sheet Model
AA1: SCENARIO SWITCH ▼ (Bull / Base / Bear) — drives all scenario-linked forecast drivers
B2: Karman Holdings Inc. (NYSE: KRMN) — 3-Statement Financial Model | AA2: Base
B3: US GAAP as reported · USD millions (per-share data in USD) · Source: Karman Forms 10-K / 10-Q, IPO prospectus (Form 424B4, 13-Feb-2025) and Form 8-K earnings releases (Ex. 99.1), SEC EDGAR CIK 0002040127 (investor-relations releases at investors.karman-sd.com are the same documents as filed on EDGAR)
B4: Basis notes: calendar fiscal year. IPO 14-Feb-2025 with Corporate Conversion (TCFIII Spaceco Holdings LLC → Karman Holdings Inc.) — pre-IPO per-unit data (159–167m units) not comparable with ~132m post-IPO shares. One reportable segment; revenue by end market (2024 quarters on the 2025 recast basis; Maritime Defense Systems disclosed from Q1-26). Quarterly data from Q1/24 (first quarters reported, as comparatives in the 2025 10-Qs); FY2022–23 annual only. Acquisitions: RMS (Feb-24), MTI (Apr-25), ISP (May-25), Five Axis (Oct-25), Seemann Composites & Materials Sciences (Q1-26), Walker Precision Engineering (28-Aug-26, after the FY26 outlook). Q3/26E–Q4/26E = FY26 revenue / Adj. EBITDA outlook less 1H/26 actuals.
AC5: Forecast | AD5: Historical
B6: (USDm) | C6: 2022 | D6: 2023 | E6: Q1/24 | F6: Q2/24 | G6: 1H/24 | H6: Q3/24 | I6: Q4/24 | J6: 2024 | K6: Q1/25 | L6: Q2/25 | M6: 1H/25 | N6: Q3/25 | O6: Q4/25 | P6: 2025 | Q6: Q1/26 | R6: Q2/26 | S6: 1H/26 | T6: Q3/26E | U6: Q4/26E | V6: 2026E | W6: 2027E | X6: 2028E | Y6: 2029E | Z6: 2030E | AA6: Modelling Notes | AC6: 5Y CAGR | AD6: 3Y CAGR
AC7: 25-'30 | AD7: 22-'25
B8: END-MARKET REVENUE BUILD — one reportable segment (revenue disaggregated by end market; no segment profit is disclosed) | AA8: END-MARKET BUILD — Karman reports a single operating / reportable segment (ASC 280; CODM = CEO). Revenue is disaggregated by end market in every release; profitability is managed and guided at the consolidated level (Adj. EBITDA), so margins are modelled at group level below.
AG9: SCENARIO INPUT TABLE — driver assumptions per Bull / Base / Bear | AH9: Bull | AI9: Base | AJ9: Bear | AK9: Bull / Bear = Base + Δ (Δ inputs on each block header). Outlook block = high / mid / low end of FY26 ranges.
B10: Hypersonics & Strategic Missile Defense (interceptors — THAAD, SM-3, GMD/NGI; hypersonic test & strategic deterrent programs) | AA10: HYPERSONICS & STRATEGIC MISSILE DEFENSE — modelling logic
B11: Revenue | C11: 72.296 | D11: 100.093 | E11: 24.822 | F11: 28.741 | G11: =E11+F11 -> 53.563 | H11: 26.927 | I11: 34.104 | J11: 114.594 | K11: 30.056 | L11: 34.96 | M11: =K11+L11 -> 65.016 | N11: 36.608 | O11: 48.363 | P11: 149.987 | Q11: 35.688 | R11: 43.417 | S11: =Q11+R11 -> 79.105 | T11: =IFERROR($S11/$S48,0)*T48 -> 45.594981 | U11: =IFERROR($S11/$S48,0)*U48 -> 50.351516 | V11: =SUM(Q11,R11,T11,U11) -> 175.0515 | W11: =V11*(1+W12) -> 206.56077 | X11: =W11*(1+X12) -> 237.54488 | Y11: =X11*(1+Y12) -> 268.42572 | Z11: =Y11*(1+Z12) -> 297.95254 | AA11: Q3/26E–Q4/26E: end-market share of 1H/26 revenue × the outlook-implied 2H/26 quarterly revenue (group block). 2027E–2030E: prior year × (1 + scenario growth lever). | AC11: =IFERROR(IF(AND(Z11>0,P11>0),(Z11/P11)^(1/5)-1,"n/m"),"n/m") -> 0.147146 | AD11: =IFERROR(IF(AND(P11>0,C11>0),(P11/C11)^(1/3)-1,"n/m"),"n/m") -> 0.27540011 | AG11: FY26 outlook — Q2-26 release (6-Aug-26) | AH11: High | AI11: Mid | AJ11: Low
B12: Revenue y/y % | D12: =IFERROR(D11/C11-1,"") -> 0.38448877 | J12: =IFERROR(J11/D11-1,"") -> 0.14487527 | K12: =IFERROR(K11/E11-1,"") -> 0.21086133 | L12: =IFERROR(L11/F11-1,"") -> 0.21638078 | M12: =IFERROR(M11/G11-1,"") -> 0.21382297 | N12: =IFERROR(N11/H11-1,"") -> 0.35952761 | O12: =IFERROR(O11/I11-1,"") -> 0.41810345 | P12: =IFERROR(P11/J11-1,"") -> 0.30885561 | Q12: =IFERROR(Q11/K11-1,"") -> 0.18738355 | ... V12: =IFERROR(V11/P11-1,"") -> 0.16711113 | W12: =CHOOSE(MATCH($AA$2,{"Bull","Base","Bear"},0),$AH$22,$AI$22,$AJ$22) -> 0.18 | X12: =CHOOSE(MATCH($AA$2,{"Bull","Base","Bear"},0),$AH$23,$AI$23,$AJ$23) -> 0.15 | Y12: =CHOOSE(MATCH($AA$2,{"Bull","Base","Bear"},0),$AH$24,$AI$24,$AJ$24) -> 0.13 | Z12: =CHOOSE(MATCH($AA$2,{"Bull","Base","Bear"},0),$AH$25,$AI$25,$AJ$25) -> 0.11 | AA12: 2027E–2030E: scenario lever (HSMD_growth, Bull / Base / Bear table →). Q1-26 onward includes acquisitions (no end-market organic split disclosed). | AC12: =IFERROR(AVERAGE(V12,W12,X12,Y12,Z12),"n/m") -> 0.14742223 | AD12: =IFERROR(AVERAGE(C12,D12,J12,P12),"n/m") -> 0.27940655 | AG12: FY26 revenue ($m) | AH12: 745 | AI12: 737.5 | AJ12: 730 | AK12: Raised from $720–735m (Q1-26) and $715–730m (FY25 release); excludes acquisitions after 6-Aug-26 (Walker).
B13: Mix — % of total revenue | C13: =IFERROR(C11/C92,"") -> 0.31945561 | D13: =IFERROR(D11/D92,"") -> 0.35657719 | E13: =IFERROR(E11/E92,"") -> 0.29903862 | F13: =IFERROR(F11/F92,"") -> 0.33797434 | G13: =IFERROR(G11/G92,"") -> 0.318742 | H13: =IFERROR(H11/H92,"") -> 0.3132212 | I13: =IFERROR(I11/I92,"") -> 0.37379162 | J13: =IFERROR(J11/J92,"") -> 0.33191504 | ... Z13: =IFERROR(Z11/Z92,"") -> 0.17605531 | AC13: =IFERROR(AVERAGE(V13,W13,X13,Y13,Z13),"n/m") -> 0.20248364 | AD13: =IFERROR(AVERAGE(C13,D13,J13,P13),"n/m") -> 0.33151347 | AG13: FY26 Adjusted EBITDA ($m) | AH13: 222.5 | AI13: 218.75 | AJ13: 215 | AK13: Raised from $208.5–219.5m (Q1-26) and $207–218m (FY25 release).
B15: Space & Launch (payload fairings / separation systems, interstage & propulsion components for legacy and new-space launch providers) | AA15: SPACE & LAUNCH — modelling logic | AG15: FY26 point estimates (all cases) | AK15: Not guided — analyst estimates.
B16: Revenue | C16: 79.664 | D16: 94.643 | E16: 30.256 | F16: 28.512 | G16: =E16+F16 -> 58.768 | H16: 27.64 | I16: 28.628 | J16: 115.036 | K16: 33.871 | L16: 39.597 | M16: =K16+L16 -> 73.468 | N16: 40.697 | O16: 35.66 | P16: 149.825 | Q16: 43.854 | R16: 42.072 | S16: =Q16+R16 -> 85.926 | T16: =IFERROR($S16/$S48,0)*T48 -> 49.526506 | U16: =IFERROR($S16/$S48,0)*U48 -> 54.693185 | V16: =SUM(Q16,R16,T16,U16) -> 190.14569 | W16: =V16*(1+W17) -> 218.66755 | X16: =W16*(1+X17) -> 247.09433 | Y16: =X16*(1+Y17) -> 274.2747 | Z16: =Y16*(1+Z17) -> 301.70217 | AA16: Q3/26E–Q4/26E: end-market share of 1H/26 revenue × the outlook-implied 2H/26 quarterly revenue (group block). 2027E–2030E: prior year × (1 + scenario growth lever). | AC16: =IFERROR(IF(AND(Z16>0,P16>0),(Z16/P16)^(1/5)-1,"n/m"),"n/m") -> 0.15026745 | AD16: =IFERROR(IF(AND(P16>0,C16>0),(P16/C16)^(1/3)-1,"n/m"),"n/m") -> 0.23435683 | AG16: Tax rate (GAAP), 2H/26E | AI16: 0.24 | AK16: 1H/26 ETR 21.8%; Q2-26 27.2% (§162(m)).
B17: Revenue y/y % | D17: =IFERROR(D16/C16-1,"") -> 0.18802721 | J17: =IFERROR(J16/D16-1,"") -> 0.21547288 | K17: =IFERROR(K16/E16-1,"") -> 0.11948043 | L17: =IFERROR(L16/F16-1,"") -> 0.38878367 | M17: =IFERROR(M16/G16-1,"") -> 0.25013613 | N17: =IFERROR(N16/H16-1,"") -> 0.47239508 | O17: =IFERROR(O16/I16-1,"") -> 0.24563365 | P17: =IFERROR(P16/J16-1,"") -> 0.30241837 | Q17: =IFERROR(Q16/K16-1,"") -> 0.29473591 | ... V17: =IFERROR(V16/P16-1,"") -> 0.26911858 | W17: =CHOOSE(MATCH($AA$2,{"Bull","Base","Bear"},0),$AH$28,$AI$28,$AJ$28) -> 0.15 | X17: =CHOOSE(MATCH($AA$2,{"Bull","Base","Bear"},0),$AH$29,$AI$29,$AJ$29) -> 0.13 | Y17: =CHOOSE(MATCH($AA$2,{"Bull","Base","Bear"},0),$AH$30,$AI$30,$AJ$30) -> 0.11 | Z17: =CHOOSE(MATCH($AA$2,{"Bull","Base","Bear"},0),$AH$31,$AI$31,$AJ$31) -> 0.1 | AA17: 2027E–2030E: scenario lever (SL_growth, Bull / Base / Bear table →). Q1-26 onward includes acquisitions (no end-market organic split disclosed). | AC17: =IFERROR(AVERAGE(V17,W17,X17,Y17,Z17),"n/m") -> 0.15182372 | AD17: =IFERROR(AVERAGE(C17,D17,J17,P17),"n/m") -> 0.23530616 | AG17: Capital expenditures ($m) | AI17: 36.5 | AK17: Investor Update 16-Sep-26: ~$35–38m 2026 capital investments.
B18: Mix — % of total revenue | C18: =IFERROR(C16/C92,"") -> 0.35201273 | D18: =IFERROR(D16/D92,"") -> 0.33716179 | E18: =IFERROR(E16/E92,"") -> 0.36450377 | F18: =IFERROR(F16/F92,"") -> 0.33528146 | G18: =IFERROR(G16/G92,"") -> 0.34971585 | H18: =IFERROR(H16/H92,"") -> 0.32151498 | I18: =IFERROR(I16/I92,"") -> 0.31377277 | J18: =IFERROR(J16/J92,"") -> 0.33319527 | ... Z18: =IFERROR(Z16/Z92,"") -> 0.17827091 | AC18: =IFERROR(AVERAGE(V18,W18,X18,Y18,Z18),"n/m") -> 0.21190562 | AD18: =IFERROR(AVERAGE(C18,D18,J18,P18),"n/m") -> 0.33503306 | AG18: Share-based compensation per quarter, 2H/26E ($m) | AI18: 1.5 | AK18: Q2-26 RSU / PSU expense $1.4m.
AG19: Transaction + integration costs, 2H/26E total ($m) | AI19: 6 | AK19: Walker deal / integration; 1H/26 $7.0m.
B20: Tactical Missiles & Integrated Defense Systems (tactical SRMs, PrSM / GMLRS content, UAS / counter-UAS launchers; “Missile & Integrated Defense Systems” in the S-1) | AA20: TACTICAL MISSILES & INTEGRATED DEFENSE SYSTEMS — modelling logic
B21: Revenue | C21: 74.351 | D21: 85.969 | E21: 27.928 | F21: 27.786 | G21: =E21+F21 -> 55.714 | H21: 31.401 | I21: 28.506 | J21: 115.621 | K21: 36.197 | L21: 40.54 | M21: =K21+L21 -> 76.737 | N21: 44.482 | O21: 50.469 | P21: 171.688 | Q21: 45.26 | R21: 63.012 | S21: =Q21+R21 -> 108.272 | T21: =IFERROR($S21/$S48,0)*T48 -> 62.406418 | U21: =IFERROR($S21/$S48,0)*U48 -> 68.916748 | V21: =SUM(Q21,R21,T21,U21) -> 239.59517 | W21: =V21*(1+W22) -> 297.09801 | X21: =W21*(1+X22) -> 350.57565 | Y21: =X21*(1+Y22) -> 403.162 | Z21: =Y21*(1+Z22) -> 451.54143 | AA21: Q3/26E–Q4/26E: end-market share of 1H/26 revenue × the outlook-implied 2H/26 quarterly revenue (group block). 2027E–2030E: prior year × (1 + scenario growth lever). | AC21: =IFERROR(IF(AND(Z21>0,P21>0),(Z21/P21)^(1/5)-1,"n/m"),"n/m") -> 0.2133652 | AD21: =IFERROR(IF(AND(P21>0,C21>0),(P21/C21)^(1/3)-1,"n/m"),"n/m") -> 0.32175525 | AG21: HSMD_growth (Hypersonics & Strategic Missile Defense revenue y/y) | AH21: 0.05 | AI21: Δ → | AJ21: -0.08 | AK21: Interceptor ramps (THAAD, SM-3, PAC-3 MSE content; $90bn+ prime awards), NGI and hypersonic test programs; FY25 +30.9%, 1H/26 +21.7%.
B22: Revenue y/y % | D22: =IFERROR(D21/C21-1,"") -> 0.15625883 | J22: =IFERROR(J21/D21-1,"") -> 0.34491503 | K22: =IFERROR(K21/E21-1,"") -> 0.29608278 | L22: =IFERROR(L21/F21-1,"") -> 0.45900813 | M22: =IFERROR(M21/G21-1,"") -> 0.37733783 | N22: =IFERROR(N21/H21-1,"") -> 0.41657909 | O22: =IFERROR(O21/I21-1,"") -> 0.77046937 | P22: =IFERROR(P21/J21-1,"") -> 0.48492056 | Q22: =IFERROR(Q21/K21-1,"") -> 0.25037987 | ... V22: =IFERROR(V21/P21-1,"") -> 0.39552658 | W22: =CHOOSE(MATCH($AA$2,{"Bull","Base","Bear"},0),$AH$34,$AI$34,$AJ$34) -> 0.24 | X22: =CHOOSE(MATCH($AA$2,{"Bull","Base","Bear"},0),$AH$35,$AI$35,$AJ$35) -> 0.18 | Y22: =CHOOSE(MATCH($AA$2,{"Bull","Base","Bear"},0),$AH$36,$AI$36,$AJ$36) -> 0.15 | Z22: =CHOOSE(MATCH($AA$2,{"Bull","Base","Bear"},0),$AH$37,$AI$37,$AJ$37) -> 0.12 | AA22: 2027E–2030E: scenario lever (TMIDS_growth, Bull / Base / Bear table →). Q1-26 onward includes acquisitions (no end-market organic split disclosed). | AC22: =IFERROR(AVERAGE(V22,W22,X22,Y22,Z22),"n/m") -> 0.21710532 | AD22: =IFERROR(AVERAGE(C22,D22,J22,P22),"n/m") -> 0.32869814 | AG22: 2027E | AH22: =AI22+$AH$21 -> 0.23 | AI22: 0.18 | AJ22: =AI22+$AJ$21 -> 0.1
B23: Mix — % of total revenue | C23: =IFERROR(C21/C92,"") -> 0.32853608 | D23: =IFERROR(D21/D92,"") -> 0.30626102 | E23: =IFERROR(E21/E92,"") -> 0.33645761 | F23: =IFERROR(F21/F92,"") -> 0.3267442 | G23: =IFERROR(G21/G92,"") -> 0.33154215 | H23: =IFERROR(H21/H92,"") -> 0.36526382 | I23: =IFERROR(I21/I92,"") -> 0.31243561 | J23: =IFERROR(J21/J92,"") -> 0.33488969 | ... Z23: =IFERROR(Z21/Z92,"") -> 0.26680849 | AC23: =IFERROR(AVERAGE(V23,W23,X23,Y23,Z23),"n/m") -> 0.29458418 | AD23: =IFERROR(AVERAGE(C23,D23,J23,P23),"n/m") -> 0.33345457 | AG23: 2028E | AH23: =AI23+$AH$21 -> 0.2 | AI23: 0.15 | AJ23: =AI23+$AJ$21 -> 0.07
B24: Memo: as originally reported in the IPO prospectus (9M/24 basis before the 2025 recast) | C24: 74.351 | D24: 85.969 | AA24: The 2025 recast moved c.$7m of 9M/24 revenue from Space & Launch into Hypersonics; FY2022–23 were not restated. | AG24: 2029E | AH24: =AI24+$AH$21 -> 0.18 | AI24: 0.13 | AJ24: =AI24+$AJ$21 -> 0.05
AG25: 2030E | AH25: =AI25+$AH$21 -> 0.16 | AI25: 0.11 | AJ25: =AI25+$AJ$21 -> 0.03
B26: Maritime Defense Systems (Columbia / Virginia-class submarine content — Seemann Composites & Materials Sciences, acquired Q1-26; separately disclosed from Q1-26) | AA26: MARITIME DEFENSE SYSTEMS — modelling logic
B27: Revenue | G27: =E27+F27 -> 0 | M27: =K27+L27 -> 0 | Q27: 26.408 | R27: 33.562 | S27: =Q27+R27 -> 59.97 | T27: =IFERROR($S27/$S48,0)*T48 -> 34.565843 | U27: =IFERROR($S27/$S48,0)*U48 -> 38.171802 | V27: =SUM(Q27,R27,T27,U27) -> 132.70765 | W27: =V27*(1+W28) -> 159.24917 | X27: =W27*(1+X28) -> 186.32153 | Y27: =X27*(1+Y28) -> 212.40655 | Z27: =Y27*(1+Z28) -> 237.89533 | AA27: Q3/26E–Q4/26E: end-market share of 1H/26 revenue × the outlook-implied 2H/26 quarterly revenue (group block). 2027E–2030E: prior year × (1 + scenario growth lever). | AC27: =IFERROR(IF(AND(Z27>0,P27>0),(Z27/P27)^(1/5)-1,"n/m"),"n/m") -> n/m | AD27: =IFERROR(IF(AND(P27>0,C27>0),(P27/C27)^(1/3)-1,"n/m"),"n/m") -> n/m | AG27: SL_growth (Space & Launch revenue y/y) | AH27: 0.05 | AI27: Δ → | AJ27: -0.08 | AK27: Legacy + emerging launch providers; new multi-year LTA (Q2-26) vs launch-schedule timing; FY25 +30.2%, 1H/26 +17.0%.
B28: Revenue y/y % | D28: =IFERROR(D27/C27-1,"") | J28: =IFERROR(J27/D27-1,"") | K28: =IFERROR(K27/E27-1,"") | L28: =IFERROR(L27/F27-1,"") | M28: =IFERROR(M27/G27-1,"") | N28: =IFERROR(N27/H27-1,"") | O28: =IFERROR(O27/I27-1,"") | P28: =IFERROR(P27/J27-1,"") | Q28: =IFERROR(Q27/K27-1,"") | ... V28: =IFERROR(V27/P27-1,"") | W28: =CHOOSE(MATCH($AA$2,{"Bull","Base","Bear"},0),$AH$40,$AI$40,$AJ$40) -> 0.2 | X28: =CHOOSE(MATCH($AA$2,{"Bull","Base","Bear"},0),$AH$41,$AI$41,$AJ$41) -> 0.17 | Y28: =CHOOSE(MATCH($AA$2,{"Bull","Base","Bear"},0),$AH$42,$AI$42,$AJ$42) -> 0.14 | Z28: =CHOOSE(MATCH($AA$2,{"Bull","Base","Bear"},0),$AH$43,$AI$43,$AJ$43) -> 0.12 | AA28: 2027E–2030E: scenario lever (MDS_growth, Bull / Base / Bear table →). Q1-26 onward includes acquisitions (no end-market organic split disclosed). | AC28: =IFERROR(AVERAGE(V28,W28,X28,Y28,Z28),"n/m") -> 0.1575 | AD28: =IFERROR(AVERAGE(C28,D28,J28,P28),"n/m") -> n/m | AG28: 2027E | AH28: =AI28+$AH$27 -> 0.2 | AI28: 0.15 | AJ28: =AI28+$AJ$27 -> 0.07
B29: Mix — % of total revenue | C29: =IFERROR(C27/C92,"") -> 0 | D29: =IFERROR(D27/D92,"") -> 0 | E29: =IFERROR(E27/E92,"") -> 0 | F29: =IFERROR(F27/F92,"") -> 0 | G29: =IFERROR(G27/G92,"") -> 0 | H29: =IFERROR(H27/H92,"") -> 0 | I29: =IFERROR(I27/I92,"") -> 0 | J29: =IFERROR(J27/J92,"") -> 0 | ... Z29: =IFERROR(Z27/Z92,"") -> 0.14056848 | AC29: =IFERROR(AVERAGE(V29,W29,X29,Y29,Z29),"n/m") -> 0.15777151 | AD29: =IFERROR(AVERAGE(C29,D29,J29,P29),"n/m") -> 0 | AG29: 2028E | AH29: =AI29+$AH$27 -> 0.18 | AI29: 0.13 | AJ29: =AI29+$AJ$27 -> 0.05
AG30: 2029E | AH30: =AI30+$AH$27 -> 0.16 | AI30: 0.11 | AJ30: =AI30+$AJ$27 -> 0.03
B31: Acquisitions after the FY26 outlook & future acquisitions (M&A lever — Walker Precision Engineering closed 28-Aug-26; scenario spend 2027E+) | AA31: M&A LEVER — Walker (closed 28-Aug-26, ~$95m / £70m cash, funded by a $100m term-loan add-on) is excluded from the FY26 outlook (“excluding the impact of any future acquisitions”). Acquired sales = spend ÷ EV/sales; mid-year convention 2027E+. | AG31: 2030E | AH31: =AI31+$AH$27 -> 0.15 | AI31: 0.1 | AJ31: =AI31+$AJ$27 -> 0.02
B32: Acquisition spend (USDm; 2026E = Walker, scenario 2027E+) | V32: 95 | W32: =CHOOSE(MATCH($AA$2,{"Bull","Base","Bear"},0),$AH$52,$AI$52,$AJ$52) -> 200 | X32: =CHOOSE(MATCH($AA$2,{"Bull","Base","Bear"},0),$AH$53,$AI$53,$AJ$53) -> 225 | Y32: =CHOOSE(MATCH($AA$2,{"Bull","Base","Bear"},0),$AH$54,$AI$54,$AJ$54) -> 250 | Z32: =CHOOSE(MATCH($AA$2,{"Bull","Base","Bear"},0),$AH$55,$AI$55,$AJ$55) -> 250 | AA32: 2026E: Walker ~$95m (8-K 28-Aug-26). 2027E+: scenario lever (M&A_spend). Since IPO Karman has closed ~2.5 deals p.a. at ~10x EBITDA (Investor Update 16-Sep-26).
B33: Purchase multiple — EV / sales (x) | V33: 2.6 | W33: 2.8 | X33: 2.8 | Y33: 2.8 | Z33: 2.8 | AA33: ~10x EBITDA × ~27% acquired EBITDA margin ≈ 2.6–2.8x sales (Investor Update 16-Sep-26: average ~10x, ~27% margin). | AG33: TMIDS_growth (Tactical Missiles & Integrated Defense Systems revenue y/y) | AH33: 0.05 | AI33: Δ → | AJ33: -0.08 | AK33: UAS / C-UAS, tactical SRMs (ISP), PrSM / GMLRS munitions replenishment, European footprint; FY25 +48.5%, 1H/26 +41.1% (incl. acquisitions).
B34: Annualised sales acquired in the year | V34: =IFERROR(V32/V33,0) -> 36.538462 | W34: =IFERROR(W32/W33,0) -> 71.428571 | X34: =IFERROR(X32/X33,0) -> 80.357143 | Y34: =IFERROR(Y32/Y33,0) -> 89.285714 | Z34: =IFERROR(Z32/Z33,0) -> 89.285714 | AG34: 2027E | AH34: =AI34+$AH$33 -> 0.29 | AI34: 0.24 | AJ34: =AI34+$AJ$33 -> 0.16
B35: Growth of acquired businesses after acquisition % | W35: 0.12 | X35: 0.12 | Y35: 0.12 | Z35: 0.12 | AA35: Acquired businesses grew ~25% under Karman ownership (Investor Update); 12% assumed post-integration. | AG35: 2028E | AH35: =AI35+$AH$33 -> 0.23 | AI35: 0.18 | AJ35: =AI35+$AJ$33 -> 0.1
B36: Run-rate sales of businesses acquired (year end) | V36: =V34 -> 36.538462 | W36: =V36*(1+W35)+W34 -> 112.35165 | X36: =W36*(1+X35)+X34 -> 206.19099 | Y36: =X36*(1+Y35)+Y34 -> 320.21962 | Z36: =Y36*(1+Z35)+Z34 -> 447.93169 | AG36: 2029E | AH36: =AI36+$AH$33 -> 0.2 | AI36: 0.15 | AJ36: =AI36+$AJ$33 -> 0.07
B37: Net sales from post-outlook / future acquisitions | T37: 3 | U37: 9 | V37: =SUM(Q37,R37,T37,U37) -> 12 | W37: =V36*(1+W35)+0.5*W34 -> 76.637363 | X37: =W36*(1+X35)+0.5*X34 -> 166.01242 | Y37: =X36*(1+Y35)+0.5*Y34 -> 275.57676 | Z37: =Y36*(1+Z35)+0.5*Z34 -> 403.28883 | AA37: Q3/26E: ~1 month of Walker (~$36m annual run-rate est. = $95m ÷ 2.6x); Q4/26E full quarter. 2027E+: opening run-rate × (1+g) + ½ of sales acquired in the year. | AG37: 2030E | AH37: =AI37+$AH$33 -> 0.17 | AI37: 0.12 | AJ37: =AI37+$AJ$33 -> 0.04
B38: Adjusted EBITDA margin of acquired businesses % | V38: 0.27 | W38: 0.27 | X38: 0.27 | Y38: 0.27 | Z38: 0.27
B39: Adjusted EBITDA from post-outlook / future acquisitions | T39: =T37*$V38 -> 0.81 | U39: =U37*$V38 -> 2.43 | V39: =SUM(Q39,R39,T39,U39) -> 3.24 | W39: =W37*W38 -> 20.692088 | X39: =X37*X38 -> 44.823353 | Y39: =Y37*Y38 -> 74.405727 | Z39: =Z37*Z38 -> 108.88799 | AG39: MDS_growth (Maritime Defense Systems revenue y/y) | AH39: 0.05 | AI39: Δ → | AJ39: -0.08 | AK39: Columbia / Virginia-class submarine build-rate ramp ($76bn+ awards); disclosed from Q1-26 (Seemann / MSC).
B40: Acquired intangibles % of spend | V40: 0.45 | W40: 0.45 | X40: 0.45 | Y40: 0.45 | Z40: 0.45 | AA40: Karman acquisitions 2024–26: identified intangibles ≈ 30–55% of consideration (customer relationships, backlog, know-how). | AG40: 2027E | AH40: =AI40+$AH$39 -> 0.25 | AI40: 0.2 | AJ40: =AI40+$AJ$39 -> 0.12
B41: Amortization life (years) | V41: 12 | W41: 12 | X41: 12 | Y41: 12 | Z41: 12 | AG41: 2028E | AH41: =AI41+$AH$39 -> 0.22 | AI41: 0.17 | AJ41: =AI41+$AJ$39 -> 0.09
...

Sheet Bull-Base-Bear
B2: Karman Holdings (KRMN) — Bull / Base / Bear Case P&L Summary | J2: Share price ($): | K2: =Model!$V$362 -> 34.14
B3: Company non-GAAP definitions (Adj. EBITDA, Adj. EPS) plus model Adj. EBITA · USD millions · Live panel linked to Model — toggle scenario via Model!AA2. Bull and Bear panels are value snapshots generated from the Model with the switch set to each case. | J3: As of: | K3: =TODAY() -> 46299
B5: Scenario: | C5: =Model!AA2 -> Base | N5: Scenario: | O5: Bull | P5: Snapshot (values) — Model run with switch = Bull | Z5: Scenario: | AA5: Bear | AB5: Snapshot (values) — Model run with switch = Bear
B7: (USDm, except EPS and shares) | C7: 2025A | D7: 2026E | E7: 2027E | F7: 2028E | G7: 2029E | H7: 2030E | I7: 25-'30 CAGR | J7: LT Hist Avg | K7: LT Hist Min | L7: LT Hist Max | N7: (USDm, except EPS and shares) | O7: 2025A | P7: 2026E | Q7: 2027E | R7: 2028E | S7: 2029E | T7: 2030E | U7: 25-'30 CAGR | V7: LT Hist Avg | W7: LT Hist Min | X7: LT Hist Max | Z7: (USDm, except EPS and shares) | AA7: 2025A | AB7: 2026E | AC7: 2027E | AD7: 2028E | AE7: 2029E | AF7: 2030E | AG7: 25-'30 CAGR | AH7: LT Hist Avg | AI7: LT Hist Min | AJ7: LT Hist Max
B9: Revenue | C9: =Model!P92 -> 471.5 | D9: =Model!V92 -> 749.5 | E9: =Model!W92 -> 958.21285 | F9: =Model!X92 -> 1187.5488 | G9: =Model!Y92 -> 1433.8457 | H9: =Model!Z92 -> 1692.3803 | I9: =IFERROR(IF(AND(H9>0,C9>0),(H9/C9)^(1/5)-1,"n/m"),"n/m") -> 0.29122895 | N9: Revenue | O9: 471.5 | P9: 757 | Q9: 1031.2137 | R9: 1374.2551 | S9: 1757.167 | T9: 2176.446 | U9: 0.35785451 | Z9: Revenue | AA9: 471.5 | AB9: 742 | AC9: 864.06197 | AD9: 957.59955 | AE9: 1047.3093 | AF9: 1130.2887 | AG9: 0.19108167
B10: Revenue y/y % | D10: =IFERROR(D9/C9-1,"") -> 0.58960764 | E10: =IFERROR(E9/D9-1,"") -> 0.27846945 | F10: =IFERROR(F9/E9-1,"") -> 0.23933717 | G10: =IFERROR(G9/F9-1,"") -> 0.20739941 | H10: =IFERROR(H9/G9-1,"") -> 0.18030851 | N10: Revenue y/y % | P10: 0.60551432 | Q10: 0.36223744 | R10: 0.33265784 | S10: 0.27863235 | T10: 0.23861076 | Z10: Revenue y/y % | AB10: 0.57370095 | AC10: 0.164504 | AD10: 0.10825332 | AE10: 0.093681929 | AF10: 0.079231061
B11: Organic growth % (where disclosed / modelled) | C11: =Model!P180 | D11: =Model!V180 -> 0.36292259 | E11: =Model!W180 -> 0.20644341 | F11: =Model!X180 -> 0.16013466 | G11: =Model!Y180 -> 0.13597377 | H11: =Model!Z180 -> 0.11803842 | N11: Organic growth % (where disclosed / modelled) | P11: 0.37882927 | Q11: 0.25554097 | R11: 0.20711231 | S11: 0.17792844 | T11: 0.15731107 | Z11: Organic growth % (where disclosed / modelled) | AB11: 0.34701591 | AC11: 0.12784928 | AD11: 0.082420191 | AE11: 0.061048246 | AF11: 0.04513007
B12: Adjusted EBITDA (company definition) | C12: =Model!P146 -> 145.302 | D12: =Model!V146 -> 221.99 | E12: =Model!W146 -> 285.16474 | F12: =Model!X146 -> 354.34888 | G12: =Model!Y146 -> 428.83603 | H12: =Model!Z146 -> 508.50635 | I12: =IFERROR(IF(AND(H12>0,C12>0),(H12/C12)^(1/5)-1,"n/m"),"n/m") -> 0.28470956 | N12: Adjusted EBITDA (company definition) | O12: 145.302 | P12: 225.74 | Q12: 315.53934 | R12: 419.27152 | S12: 535.5049 | T12: 664.83578 | U12: 0.35546578 | Z12: Adjusted EBITDA (company definition) | AA12: 145.302 | AB12: 218.24 | AC12: 241.43883 | AD12: 269.97072 | AE12: 297.58501 | AF12: 324.30295 | AG12: 0.1741832
B13: Adjusted EBITDA margin % | C13: =IFERROR(C12/C9,"") -> 0.30816967 | D13: =IFERROR(D12/D9,"") -> 0.29618412 | E13: =IFERROR(E12/E9,"") -> 0.29760062 | F13: =IFERROR(F12/F9,"") -> 0.29838679 | G13: =IFERROR(G12/G9,"") -> 0.29908101 | H13: =IFERROR(H12/H9,"") -> 0.30046813 | J13: =IFERROR(AVERAGE(Model!C188,Model!D188,Model!J188,Model!P188),"") -> 0.293412 | K13: =IFERROR(MIN(Model!C188,Model!D188,Model!J188,Model!P188),"") -> 0.26640891 | L13: =IFERROR(MAX(Model!C188,Model!D188,Model!J188,Model!P188),"") -> 0.30816967 | N13: Adjusted EBITDA margin % | O13: 0.30816967 | P13: 0.29820343 | Q13: 0.3059883 | R13: 0.30509003 | S13: 0.3047547 | T13: 0.30546854 | V13: 0.293412 | W13: 0.26640891 | X13: 0.30816967 | Z13: Adjusted EBITDA margin % | AA13: 0.30816967 | AB13: 0.29412399 | AC13: 0.27942305 | AD13: 0.28192445 | AE13: 0.28414242 | AF13: 0.28692045 | AH13: 0.293412 | AI13: 0.26640891 | AJ13: 0.30816967
B15: Operating Income (GAAP) | C15: =Model!P97 -> 72.942 | D15: =Model!V97 -> 137.37156 | E15: =Model!W97 -> 198.23987 | F15: =Model!X97 -> 255.59394 | G15: =Model!Y97 -> 312.19955 | H15: =Model!Z97 -> 371.81556 | I15: =IFERROR(IF(AND(H15>0,C15>0),(H15/C15)^(1/5)-1,"n/m"),"n/m") -> 0.38506443 | N15: Operating Income (GAAP) | O15: 72.942 | P15: 141.12156 | Q15: 218.96595 | R15: 301.23107 | S15: 388.98968 | T15: 486.53113 | U15: 0.46159347 | Z15: Operating Income (GAAP) | AA15: 72.942 | AB15: 133.62156 | AC15: 164.8393 | AD15: 191.97156 | AE15: 213.0398 | AF15: 232.03496 | AG15: 0.26041961
B16: Operating income y/y % | D16: =IFERROR(D15/C15-1,"") -> 0.88329852 | E16: =IFERROR(E15/D15-1,"") -> 0.44309254 | F16: =IFERROR(F15/E15-1,"") -> 0.2893165 | G16: =IFERROR(G15/F15-1,"") -> 0.22146694 | H16: =IFERROR(H15/G15-1,"") -> 0.19095481 | N16: Operating income y/y % | P16: 0.93470923 | Q16: 0.55161229 | R16: 0.37569825 | S16: 0.29133317 | T16: 0.25075589 | Z16: Operating income y/y % | AB16: 0.83188781 | AC16: 0.23362802 | AD16: 0.16459826 | AE16: 0.10974668 | AF16: 0.089162485
B17: Operating margin (GAAP) % | C17: =IFERROR(C15/C9,"") -> 0.15470201 | D17: =IFERROR(D15/D9,"") -> 0.18328427 | E17: =IFERROR(E15/E9,"") -> 0.20688501 | F17: =IFERROR(F15/F9,"") -> 0.21522816 | G17: =IFERROR(G15/G9,"") -> 0.2177358 | H17: =IFERROR(H15/H9,"") -> 0.21969976 | J17: =IFERROR(AVERAGE(Model!C191,Model!D191,Model!J191,Model!P191),"") -> 0.15046358 | K17: =IFERROR(MIN(Model!C191,Model!D191,Model!J191,Model!P191),"") -> 0.090296496 | L17: =IFERROR(MAX(Model!C191,Model!D191,Model!J191,Model!P191),"") -> 0.18409795 | N17: Operating margin (GAAP) % | O17: 0.15470201 | P17: 0.18642214 | Q17: 0.21233808 | R17: 0.21919589 | S17: 0.2213732 | T17: 0.22354386 | V17: 0.15046358 | W17: 0.090296496 | X17: 0.18409795 | Z17: Operating margin (GAAP) % | AA17: 0.15470201 | AB17: 0.18008297 | AC17: 0.19077255 | AD17: 0.20047165 | AE17: 0.20341632 | AF17: 0.20528822 | AH17: 0.15046358 | AI17: 0.090296496 | AJ17: 0.18409795
B19: Adjusted Net Income (company definition, not tax-effected) | C19: =Model!P167 -> 48.95914 | D19: =Model!V167 -> 81.298166 | E19: =Model!W167 -> 122.18407 | F19: =Model!X167 -> 163.38609 | G19: =Model!Y167 -> 203.81054 | H19: =Model!Z167 -> 246.67395 | I19: =IFERROR(IF(AND(H19>0,C19>0),(H19/C19)^(1/5)-1,"n/m"),"n/m") -> 0.38184045 | N19: Adjusted Net Income (company definition, not tax-effected) | O19: 48.95914 | P19: 84.148166 | Q19: 142.92601 | R19: 196.91101 | S19: 255.15002 | T19: 321.88526 | U19: 0.45738221 | Z19: Adjusted Net Income (company definition, not tax-effected) | AA19: 48.95914 | AB19: 78.448166 | AC19: 91.703684 | AD19: 114.26933 | AE19: 132.41108 | AF19: 148.08914 | AG19: 0.24777961
B21: FDSO (m) | C21: =Model!P110 -> 132.322 | D21: =Model!V110 -> 132.55225 | E21: =Model!W110 -> 133.17244 | F21: =Model!X110 -> 133.57244 | G21: =Model!Y110 -> 133.97243 | H21: =Model!Z110 -> 134.37243 | I21: =IFERROR(IF(AND(H21>0,C21>0),(H21/C21)^(1/5)-1,"n/m"),"n/m") -> 0.0030801267 | N21: FDSO (m) | O21: 132.322 | P21: 132.55225 | Q21: 133.17244 | R21: 133.57244 | S21: 133.97243 | T21: 134.37243 | U21: 0.0030801267 | Z21: FDSO (m) | AA21: 132.322 | AB21: 132.55225 | AC21: 133.17244 | AD21: 133.57244 | AE21: 133.97243 | AF21: 134.37243 | AG21: 0.0030801267
B23: Adjusted EPS — Diluted ($, company definition) | C23: =Model!P169 -> 0.37 | D23: =Model!V169 -> 0.6133292 | E23: =Model!W169 -> 0.91748771 | F23: =Model!X169 -> 1.2232022 | G23: =Model!Y169 -> 1.5212871 | H23: =Model!Z169 -> 1.8357482 | I23: =IFERROR(IF(AND(H23>0,C23>0),(H23/C23)^(1/5)-1,"n/m"),"n/m") -> 0.37759728 | N23: Adjusted EPS — Diluted ($, company definition) | O23: 0.37 | P23: 0.63483016 | Q23: 1.0732402 | R23: 1.4741889 | S23: 1.9044964 | T23: 2.3954709 | U23: 0.45290707 | Z23: Adjusted EPS — Diluted ($, company definition) | AA23: 0.37 | AB23: 0.59182825 | AC23: 0.6886086 | AD23: 0.85548585 | AE23: 0.98834566 | AF23: 1.1020797 | AG23: 0.24394809
B24: EPS y/y % | D24: =IFERROR(D23/C23-1,"") -> 0.65764649 | E24: =IFERROR(E23/D23-1,"") -> 0.49591395 | F24: =IFERROR(F23/E23-1,"") -> 0.33320825 | G24: =IFERROR(G23/F23-1,"") -> 0.24369226 | H24: =IFERROR(H23/G23-1,"") -> 0.20670724 | N24: EPS y/y % | P24: 0.71575718 | Q24: 0.69059426 | R24: 0.37358711 | S24: 0.29189435 | T24: 0.25779759 | Z24: EPS y/y % | AB24: 0.5995358 | AC24: 0.16352777 | AD24: 0.24233977 | AE24: 0.15530334 | AF24: 0.11507519
B26: P / E (x) — assumed (Adjusted EPS, company definition) | G26: 40 | H26: 40 | N26: P / E (x) — assumed (Adjusted EPS, company definition) | S26: 50 | T26: 50 | Z26: P / E (x) — assumed (Adjusted EPS, company definition) | AE26: 28 | AF26: 28
B27: Price Target ($) | G27: =G26*G23 -> 60.851484 | H27: =H26*H23 -> 73.429926 | N27: Price Target ($) | S27: =S26*S23 -> 95.224818 | T27: =T26*T23 -> 119.77355 | Z27: Price Target ($) | AE27: =AE26*AE23 -> 27.673679 | AF27: =AF26*AF23 -> 30.858232
B28: Upside / (Downside) vs current | G28: =IFERROR(G27/$K$2-1,"") -> 0.78241019 | H28: =IFERROR(H27/$K$2-1,"") -> 1.1508473 | N28: Upside / (Downside) vs current | S28: =IFERROR(S27/$K$2-1,"") -> 1.7892448 | T28: =IFERROR(T27/$K$2-1,"") -> 2.5083054 | Z28: Upside / (Downside) vs current | AE28: =IFERROR(AE27/$K$2-1,"") -> -0.18940602 | AF28: =IFERROR(AF27/$K$2-1,"") -> -0.096126764
B29: IRR (to Dec-Y-1) | G29: =IFERROR((G27/$K$2)^(1/((DATE(2029-1,12,31)-$K$3)/365.25))-1,"") -> 0.29402319 | H29: =IFERROR((H27/$K$2)^(1/((DATE(2030-1,12,31)-$K$3)/365.25))-1,"") -> 0.2665027 | N29: IRR (to Dec-Y-1) | S29: =IFERROR((S27/$K$2)^(1/((DATE(2029-1,12,31)-$K$3)/365.25))-1,"") -> 0.58006148 | T29: =IFERROR((T27/$K$2)^(1/((DATE(2030-1,12,31)-$K$3)/365.25))-1,"") -> 0.4728418 | Z29: IRR (to Dec-Y-1) | AE29: =IFERROR((AE27/$K$2)^(1/((DATE(2029-1,12,31)-$K$3)/365.25))-1,"") -> -0.089397207 | AF29: =IFERROR((AF27/$K$2)^(1/((DATE(2030-1,12,31)-$K$3)/365.25))-1,"") -> -0.0306967
B31: Free Cash Flow (CFO − capex) | C31: =Model!P222 -> -42.455 | D31: =Model!V222 -> 26.93171 | E31: =Model!W222 -> 80.815266 | F31: =Model!X222 -> 123.84979 | G31: =Model!Y222 -> 167.42287 | H31: =Model!Z222 -> 216.77556 | I31: =IFERROR(IF(AND(H31>0,C31>0),(H31/C31)^(1/5)-1,"n/m"),"n/m") -> n/m | N31: Free Cash Flow (CFO − capex) | O31: -42.455 | P31: 27.3621 | Q31: 77.520145 | R31: 123.76448 | S31: 183.91667 | T31: 255.42836 | Z31: Free Cash Flow (CFO − capex) | AA31: -42.455 | AB31: 26.50132 | AC31: 81.425899 | AD31: 115.42073 | AE31: 137.10073 | AF31: 159.31182
B32: FCF % | C32: =IFERROR(C31/C9,"") -> -0.090042418 | D32: =IFERROR(D31/D9,"") -> 0.035932902 | E32: =IFERROR(E31/E9,"") -> 0.084339576 | F32: =IFERROR(F31/F9,"") -> 0.10429028 | G32: =IFERROR(G31/G9,"") -> 0.11676492 | H32: =IFERROR(H31/H9,"") -> 0.12808915 | J32: =IFERROR(AVERAGE(Model!C224,Model!D224,Model!J224,Model!P224),"") -> -0.041102648 | K32: =IFERROR(MIN(Model!C224,Model!D224,Model!J224,Model!P224),"") -> -0.12002121 | L32: =IFERROR(MAX(Model!C224,Model!D224,Model!J224,Model!P224),"") -> 0.03299918 | N32: FCF % | O32: -0.090042418 | P32: 0.036145443 | Q32: 0.075173693 | R32: 0.090059323 | S32: 0.10466659 | T32: 0.11736031 | V32: -0.041102648 | W32: -0.12002121 | X32: 0.03299918 | Z32: FCF % | AA32: -0.090042418 | AB32: 0.035716065 | AC32: 0.09423618 | AD32: 0.12053131 | AE32: 0.13090758 | AF32: 0.1409479 | AH32: -0.041102648 | AI32: -0.12002121 | AJ32: 0.03299918
B33: FCF / share ($) | C33: =IFERROR(C31/C21,"") -> -0.32084612 | D33: =IFERROR(D31/D21,"") -> 0.20317807 | E33: =IFERROR(E31/E21,"") -> 0.6068468 | F33: =IFERROR(F31/F21,"") -> 0.92721071 | G33: =IFERROR(G31/G21,"") -> 1.2496815 | H33: =IFERROR(H31/H21,"") -> 1.6132442 | N33: FCF / share ($) | O33: -0.32084612 | P33: 0.20642502 | Q33: 0.58210354 | R33: 0.92657203 | S33: 1.3727949 | T33: 1.9008985 | Z33: FCF / share ($) | AA33: -0.32084612 | AB33: 0.19993112 | AC33: 0.61143208 | AD33: 0.8641059 | AE33: 1.0233503 | AF33: 1.185599
B34: FCF Yield (on PT) | E34: =IFERROR(E33/E$27,"") | F34: =IFERROR(F33/F$27,"") | G34: =IFERROR(G33/G$27,"") -> 0.020536582 | H34: =IFERROR(H33/H$27,"") -> 0.021969847 | N34: FCF Yield (on PT) | Q34: =IFERROR(Q33/Q$27,"") | R34: =IFERROR(R33/R$27,"") | S34: =IFERROR(S33/S$27,"") -> 0.014416356 | T34: =IFERROR(T33/T$27,"") -> 0.015870771 | Z34: FCF Yield (on PT) | AC34: =IFERROR(AC33/AC$27,"") | AD34: =IFERROR(AD33/AD$27,"") | AE34: =IFERROR(AE33/AE$27,"") -> 0.036979192 | AF34: =IFERROR(AF33/AF$27,"") -> 0.038420833
B35: Adjusted EBITA (model, ex-amortization) | C35: =Model!P124 -> 121.618 | D35: =Model!V124 -> 198.29006 | E35: =Model!W124 -> 254.21808 | F35: =Model!X124 -> 315.12558 | G35: =Model!Y124 -> 381.35782 | H35: =Model!Z124 -> 451.9171 | I35: =IFERROR(IF(AND(H35>0,C35>0),(H35/C35)^(1/5)-1,"n/m"),"n/m") -> 0.30020605 | N35: Adjusted EBITA (model, ex-amortization) | O35: 121.618 | P35: 202.04006 | Q35: 282.84066 | R35: 375.19386 | S35: 479.29701 | T35: 594.6927 | U35: 0.37359578 | Z35: Adjusted EBITA (model, ex-amortization) | AA35: 121.618 | AB35: 194.54006 | AC35: 212.7518 | AD35: 236.72611 | AE35: 260.54328 | AF35: 283.45227 | AG35: 0.1843946
B36: Adjusted EBITA margin % | C36: =IFERROR(C35/C9,"") -> 0.25793849 | D36: =IFERROR(D35/D9,"") -> 0.26456312 | E36: =IFERROR(E35/E9,"") -> 0.26530439 | F36: =IFERROR(F35/F9,"") -> 0.265358 | G36: =IFERROR(G35/G9,"") -> 0.26596851 | H36: =IFERROR(H35/H9,"") -> 0.26703046 | J36: =IFERROR(AVERAGE(Model!C189,Model!D189,Model!J189,Model!P189),"") -> 0.24530244 | K36: =IFERROR(MIN(Model!C189,Model!D189,Model!J189,Model!P189),"") -> 0.22257523 | L36: =IFERROR(MAX(Model!C189,Model!D189,Model!J189,Model!P189),"") -> 0.25793849 | N36: Adjusted EBITA margin % | O36: 0.25793849 | P36: 0.26689572 | Q36: 0.27427937 | R36: 0.27301617 | S36: 0.27276691 | T36: 0.27324028 | V36: 0.24530244 | W36: 0.22257523 | X36: 0.25793849 | Z36: Adjusted EBITA margin % | AA36: 0.25793849 | AB36: 0.26218337 | AC36: 0.24622285 | AD36: 0.24720783 | AE36: 0.24877395 | AF36: 0.25077864 | AH36: 0.24530244 | AI36: 0.22257523 | AJ36: 0.25793849
B38: Net Debt (incl. finance leases) | C38: =Model!P356 -> 546.585 | D38: =Model!V356 -> 853.07829 | E38: =Model!W356 -> 982.41257 | F38: =Model!X356 -> 1094.1098 | G38: =Model!Y356 -> 1187.6513 | H38: =Model!Z356 -> 1232.2784 | N38: Net Debt (incl. finance leases) | O38: 546.585 | P38: 852.6479 | Q38: 1135.2773 | R38: 1397.0598 | S38: 1624.1076 | T38: 1780.0818 | Z38: Net Debt (incl. finance leases) | AA38: 546.585 | AB38: 853.50868 | AC38: 832.23233 | AD38: 802.35863 | AE38: 776.22228 | AF38: 728.31306
B39: Net Debt / Adjusted EBITDA (x) | C39: =IFERROR(C38/C12,"") -> 3.761717 | D39: =IFERROR(D38/D12,"") -> 3.8428681 | E39: =IFERROR(E38/E12,"") -> 3.4450703 | F39: =IFERROR(F38/F12,"") -> 3.0876627 | G39: =IFERROR(G38/G12,"") -> 2.7694765 | H39: =IFERROR(H38/H12,"") -> 2.4233294 | N39: Net Debt / Adjusted EBITDA (x) | O39: 3.761717 | P39: 3.7771237 | Q39: 3.5978947 | R39: 3.3321124 | S39: 3.0328528 | T39: 2.6774759 | Z39: Net Debt / Adjusted EBITDA (x) | AA39: 3.761717 | AB39: 3.9108719 | AC39: 3.4469696 | AD39: 2.9720209 | AE39: 2.6084052 | AF39: 2.2457799
B41: ROIC (Adj. EBITA NOPAT / book IC) | C41: =Model!P336 -> 0.098155446 | D41: =Model!V336 -> 0.11602219 | E41: =Model!W336 -> 0.12443802 | F41: =Model!X336 -> 0.13153862 | G41: =Model!Y336 -> 0.13732976 | H41: =Model!Z336 -> 0.14345682 | J41: =IFERROR(AVERAGE(Model!C336,Model!D336,Model!J336,Model!P336),"") -> 0.089771413 | K41: =IFERROR(MIN(Model!C336,Model!D336,Model!J336,Model!P336),"") -> 0.065972883 | L41: =IFERROR(MAX(Model!C336,Model!D336,Model!J336,Model!P336),"") -> 0.10622211 | N41: ROIC (Adj. EBITA NOPAT / book IC) | O41: 0.098155446 | P41: 0.11799656 | Q41: 0.12456174 | R41: 0.13115558 | S41: 0.13769708 | T41: 0.14521734 | V41: 0.089771413 | W41: 0.065972883 | X41: 0.10622211 | Z41: ROIC (Adj. EBITA NOPAT / book IC) | AA41: 0.098155446 | AB41: 0.11404046 | AC41: 0.11781391 | AD41: 0.12381188 | AE41: 0.12733523 | AF41: 0.13049165 | AH41: 0.089771413 | AI41: 0.065972883 | AJ41: 0.10622211
B42: RONTA | C42: =Model!P348 -> 0.23564509 | D42: =Model!V348 -> 0.27158545 | E42: =Model!W348 -> 0.32966582 | F42: =Model!X348 -> 0.36123323 | G42: =Model!Y348 -> 0.39043687 | H42: =Model!Z348 -> 0.41724046 | J42: =IFERROR(AVERAGE(Model!C348,Model!D348,Model!J348,Model!P348),"") -> 0.23811586 | K42: =IFERROR(MIN(Model!C348,Model!D348,Model!J348,Model!P348),"") -> 0.19146647 | L42: =IFERROR(MAX(Model!C348,Model!D348,Model!J348,Model!P348),"") -> 0.27925921 | N42: RONTA | O42: 0.23564509 | P42: 0.27530757 | Q42: 0.35206037 | R42: 0.3938364 | S42: 0.43060615 | T42: 0.46313302 | V42: 0.23811586 | W42: 0.19146647 | X42: 0.27925921 | Z42: RONTA | AA42: 0.23564509 | AB42: 0.26782489 | AC42: 0.25947861 | AD42: 0.2631675 | AE42: 0.26837015 | AF42: 0.26567351 | AH42: 0.23811586 | AI42: 0.19146647 | AJ42: 0.27925921
B44: Implied Market Cap (USDm) | G44: =IFERROR(G27*G21,"") -> 8152.4215 | H44: =IFERROR(H27*H21,"") -> 9866.958 | N44: Implied Market Cap (USDm) | S44: =IFERROR(S27*S21,"") -> 12757.501 | T44: =IFERROR(T27*T21,"") -> 16094.263 | Z44: Implied Market Cap (USDm) | AE44: =IFERROR(AE27*AE21,"") -> 3707.5101 | AF44: =IFERROR(AF27*AF21,"") -> 4146.4958
B45: (+) Net Debt (incl. finance leases) | G45: =G38 -> 1187.6513 | H45: =H38 -> 1232.2784 | N45: (+) Net Debt (incl. finance leases) | S45: =S38 -> 1624.1076 | T45: =T38 -> 1780.0818 | Z45: (+) Net Debt (incl. finance leases) | AE45: =AE38 -> 776.22228 | AF45: =AF38 -> 728.31306
B46: Implied Enterprise Value (USDm) | G46: =IFERROR(G44+G45,"") -> 9340.0728 | H46: =IFERROR(H44+H45,"") -> 11099.236 | N46: Implied Enterprise Value (USDm) | S46: =IFERROR(S44+S45,"") -> 14381.608 | T46: =IFERROR(T44+T45,"") -> 17874.345 | Z46: Implied Enterprise Value (USDm) | AE46: =IFERROR(AE44+AE45,"") -> 4483.7324 | AF46: =IFERROR(AF44+AF45,"") -> 4874.8089
B47: Implied EV / Adjusted EBITDA (x) | G47: =IFERROR(G46/G12,"") -> 21.780056 | H47: =IFERROR(H46/H12,"") -> 21.827134 | N47: Implied EV / Adjusted EBITDA (x) | S47: =IFERROR(S46/S12,"") -> 26.856166 | T47: =IFERROR(T46/T12,"") -> 26.885353 | Z47: Implied EV / Adjusted EBITDA (x) | AE47: =IFERROR(AE46/AE12,"") -> 15.067064 | AF47: =IFERROR(AF46/AF12,"") -> 15.031651

Sheet DCF
B2: DCF VALUATION — KARMAN HOLDINGS (KRMN)
B4: 1. WACC BUILD
B5: Risk-free rate (US 10Y govt) | C5: 0.045 | D5: Assumption (~US 10Y Treasury yield); update to market
B6: Equity risk premium | C6: 0.05 | D6: US implied ERP ~4.5–5.5% (Damodaran)
B7: Levered beta | C7: 1.3 | D7: Short trading history since the Feb-2025 IPO; high-growth defense-tech peers (AVAV, KTOS, MRCY) ~1.2–1.5
B8: Cost of equity | C8: =C5+C7*C6 -> 0.11
B9: Pre-tax cost of debt | C9: 0.06 | D9: Citi Term Loan B at SOFR + 2.25% (Fifth Amendment, 3-Aug-26) ≈ 5.9–6.0%; finance leases ~8.2%
B10: Tax rate | C10: 0.245 | D10: Model 2027E+ effective tax rate
B11: After-tax cost of debt | C11: =C9*(1-C10) -> 0.0453
B12: Target D/V | C12: 0.2 | D12: Net debt incl. leases ~$0.95bn vs ~$4.5bn market cap at $34.14; ~4x Adj. EBITDA, deleveraging with growth
B13: WACC | C13: =C8*(1-C12)+C11*C12 -> 0.09706
B15: Valuation date (live) | C15: =TODAY() -> 46299 | D15: Periods = (Dec-31-Year − today) / 365.25; cash flows assumed at year-end
B16: 2. UNLEVERED FREE CASH FLOW BUILD (USDm)
D17: 2026E | E17: 2027E | F17: 2028E | G17: 2029E | H17: 2030E | I17: 2031E | J17: 2032E | K17: 2033E | L17: 2034E | M17: 2035E | N17: Terminal | P17: CAGR 26–30E | Q17: CAGR 26–35E
B18: Adjusted EBITA (Model; before acquired-intangible amortization) | D18: =Model!V124 -> 198.29006 | E18: =Model!W124 -> 254.21808 | F18: =Model!X124 -> 315.12558 | G18: =Model!Y124 -> 381.35782 | H18: =Model!Z124 -> 451.9171 | I18: =H18*(1+I$31) -> 519.70466 | J18: =I18*(1+J$31) -> 585.96701 | K18: =J18*(1+K$31) -> 647.49354 | L18: =K18*(1+L$31) -> 700.91176 | M18: =L18*(1+M$31) -> 742.96647 | P18: =IFERROR(IF(AND($H18>0,$D18>0),($H18/$D18)^(1/(VALUE(LEFT($H$17,4))-VALUE(LEFT($D$17,4))))-1,"n/m"),"n/m") -> 0.22868189 | Q18: =IFERROR(IF(AND($M18>0,$D18>0),($M18/$D18)^(1/(VALUE(LEFT($M$17,4))-VALUE(LEFT($D$17,4))))-1,"n/m"),"n/m") -> 0.15808629
B19: y/y % | E19: =IFERROR(E18/D18-1,"") -> 0.28205154 | F19: =IFERROR(F18/E18-1,"") -> 0.23958762 | G19: =IFERROR(G18/F18-1,"") -> 0.21017727 | H19: =IFERROR(H18/G18-1,"") -> 0.18502121 | I19: =IFERROR(I18/H18-1,"") -> 0.15 | J19: =IFERROR(J18/I18-1,"") -> 0.1275 | K19: =IFERROR(K18/J18-1,"") -> 0.105 | L19: =IFERROR(L18/K18-1,"") -> 0.0825 | M19: =IFERROR(M18/L18-1,"") -> 0.06
B20: (−) SBC, transaction, integration & other items excluded from Adj. EBITA | D20: =-(Model!V123-Model!V117) -> -21.231 | E20: =-(Model!W123-Model!W117) -> -15.665703 | F20: =-(Model!X123-Model!X117) -> -18.25039 | G20: =-(Model!Y123-Model!Y117) -> -20.970766 | H20: =-(Model!Z123-Model!Z117) -> -23.039043 | I20: =H20*(1+I$31) -> -26.494899 | J20: =I20*(1+J$31) -> -29.872999 | K20: =J20*(1+K$31) -> -33.009663 | L20: =K20*(1+L$31) -> -35.732961 | M20: =L20*(1+M$31) -> -37.876938
B21: × (1 − tax rate) | D21: =1-$C$10 -> 0.755 | E21: =1-$C$10 -> 0.755 | F21: =1-$C$10 -> 0.755 | G21: =1-$C$10 -> 0.755 | H21: =1-$C$10 -> 0.755 | I21: =1-$C$10 -> 0.755 | J21: =1-$C$10 -> 0.755 | K21: =1-$C$10 -> 0.755 | ... M21: =1-$C$10 -> 0.755
B22: NOPAT = (Adj. EBITA − excluded costs) × (1 − t) | D22: =(D18+D20)*D21 -> 133.67959 | E22: =(E18+E20)*E21 -> 180.10704 | F22: =(F18+F20)*F21 -> 224.14077 | G22: =(G18+G20)*G21 -> 272.09222 | H22: =(H18+H20)*H21 -> 323.80293 | I22: =(I18+I20)*I21 -> 372.37337 | J22: =(J18+J20)*J21 -> 419.85098 | K22: =(K18+K20)*K21 -> 463.93533 | ... M22: =(M18+M20)*M21 -> 532.34259
B23: plus depreciation of PP&E and finance-lease ROU amortization | D23: =Model!V64+Model!V65 -> 24.153939 | E23: =Model!W64+Model!W65 -> 30.946659 | F23: =Model!X64+Model!X65 -> 39.223296 | G23: =Model!Y64+Model!Y65 -> 47.478213 | H23: =Model!Z64+Model!Z65 -> 56.589247 | I23: =H23*(1+I$31) -> 65.077634 | J23: =I23*(1+J$31) -> 73.375032 | K23: =J23*(1+K$31) -> 81.07941 | L23: =K23*(1+L$31) -> 87.768462 | M23: =L23*(1+M$31) -> 93.03457
B24: − Capex (PP&E) and acquisitions (M&A lever, 2027E+) | D24: =D29 -> -36.5 | E24: =E29+Model!W205 -> -243.11958 | F24: =F29+Model!X205 -> -272.50195 | G24: =G29+Model!Y205 -> -300.1846 | H24: =H29+Model!Z205 -> -309.23331 | I24: =I29 -> -68.118308 | J24: =J29 -> -76.803392 | K24: =K29 -> -84.867748 | L24: =L29 -> -91.869337 | M24: =M29 -> -97.381498
B25: − Δ Working capital (CF statement) | D25: =Model!V202 -> -64.345695 | E25: =Model!W202 -> -57.661512 | F25: =Model!X202 -> -59.796709 | G25: =Model!Y202 -> -67.34065 | H25: =Model!Z202 -> -68.457452 | I25: =H25*(1+I$31) -> -78.72607 | J25: =I25*(1+J$31) -> -88.763644 | K25: =J25*(1+K$31) -> -98.083827 | L25: =K25*(1+L$31) -> -106.17574 | M25: =L25*(1+M$31) -> -112.54629
B26: Unlevered FCF | D26: =D22+D23+D24+D25 -> 56.987835 | E26: =E22+E23+E24+E25 -> -89.727389 | F26: =F22+F23+F24+F25 -> -68.934595 | G26: =G22+G23+G24+G25 -> -47.954815 | H26: =H22+H23+H24+H25 -> 2.7014158 | I26: =I22+I23+I24+I25 -> 290.60663 | J26: =J22+J23+J24+J25 -> 327.65897 | K26: =K22+K23+K24+K25 -> 362.06317 | ... M26: =M22+M23+M24+M25 -> 415.44938 | N26: =M26*(1+$C$32) -> 432.06735 | P26: =IFERROR(IF(AND($H26>0,$D26>0),($H26/$D26)^(1/(VALUE(LEFT($H$17,4))-VALUE(LEFT($D$17,4))))-1,"n/m"),"n/m") -> -0.53339185 | Q26: =IFERROR(IF(AND($M26>0,$D26>0),($M26/$D26)^(1/(VALUE(LEFT($M$17,4))-VALUE(LEFT($D$17,4))))-1,"n/m"),"n/m") -> 0.24698018
B27: y/y % | E27: =IFERROR(E26/D26-1,"") -> -2.5745007 | F27: =IFERROR(F26/E26-1,"") -> -0.23173296 | G27: =IFERROR(G26/F26-1,"") -> -0.30434327 | H27: =IFERROR(H26/G26-1,"") -> -1.0563325 | I27: =IFERROR(I26/H26-1,"") -> 106.57567 | J27: =IFERROR(J26/I26-1,"") -> 0.1275 | K27: =IFERROR(K26/J26-1,"") -> 0.105 | L27: =IFERROR(L26/K26-1,"") -> 0.0825 | M27: =IFERROR(M26/L26-1,"") -> 0.06
B28: Terminal Value (Gordon Growth) | N28: =N26/($C$13-$C$32) -> 7572.1583
B29: memo: PP&E capex only (fade years carry no new acquisitions) | D29: =Model!V204 -> -36.5 | E29: =Model!W204 -> -43.119578 | F29: =Model!X204 -> -47.501952 | G29: =Model!Y204 -> -50.1846 | H29: =Model!Z204 -> -59.233311 | I29: =H29*(1+I$31) -> -68.118308 | J29: =I29*(1+J$31) -> -76.803392 | K29: =J29*(1+K$31) -> -84.867748 | L29: =K29*(1+L$31) -> -91.869337 | M29: =L29*(1+M$31) -> -97.381498
B31: Fade-period growth (2031E–35E) | I31: 0.15 | J31: =I31+($M$31-$I$31)/(COLUMNS($I$31:$M$31)-1) -> 0.1275 | K31: =J31+($M$31-$I$31)/(COLUMNS($I$31:$M$31)-1) -> 0.105 | L31: =K31+($M$31-$I$31)/(COLUMNS($I$31:$M$31)-1) -> 0.0825 | M31: 0.06
B32: Terminal growth rate | C32: 0.04
B34: Discount period (years) | D34: =(DATE(2026,12,31)-$C$15)/365.25 -> 0.24093087 | E34: =(DATE(2027,12,31)-$C$15)/365.25 -> 1.2402464 | F34: =(DATE(2028,12,31)-$C$15)/365.25 -> 2.2422998 | G34: =(DATE(2029,12,31)-$C$15)/365.25 -> 3.2416153 | H34: =(DATE(2030,12,31)-$C$15)/365.25 -> 4.2409309 | I34: =(DATE(2031,12,31)-$C$15)/365.25 -> 5.2402464 | J34: =(DATE(2032,12,31)-$C$15)/365.25 -> 6.2422998 | K34: =(DATE(2033,12,31)-$C$15)/365.25 -> 7.2416153 | L34: =(DATE(2034,12,31)-$C$15)/365.25 -> 8.2409309 | M34: =(DATE(2035,12,31)-$C$15)/365.25 -> 9.2402464 | N34: =M34 -> 9.2402464
B35: Discount factor | D35: =1/(1+$C$13)^D34 -> 0.97792885 | E35: =1/(1+$C$13)^E34 -> 0.89146524 | F35: =1/(1+$C$13)^F34 -> 0.81244024 | G35: =1/(1+$C$13)^G34 -> 0.74060831 | H35: =1/(1+$C$13)^H34 -> 0.67512741 | I35: =1/(1+$C$13)^I34 -> 0.61543599 | J35: =1/(1+$C$13)^J34 -> 0.56087994 | K35: =1/(1+$C$13)^K34 -> 0.51128972 | ... N35: =1/(1+$C$13)^N34 -> 0.42487519
B36: PV of UFCF | D36: =D26*D35 -> 55.730048 | E36: =E26*E35 -> -79.988849 | F36: =F26*F35 -> -56.005239 | G36: =G26*G35 -> -35.515735 | H36: =H26*H35 -> 1.8237999 | I36: =I26*I35 -> 178.84978 | J36: =J26*J35 -> 183.77734 | K36: =K26*K35 -> 185.11917 | ... M36: =M26*M35 -> 176.51413 | N36: =N28*N35 -> 3217.2222
D37: Adjusted EBITA follows Karman’s Adj. EBITDA definition, which excludes SBC and transaction / integration costs; those are deducted again here (row 20) so NOPAT bears them. Acquisition spend from the M&A lever is deducted in 2027E–30E so that acquired sales / profit in the Model are paid for; the fade period and terminal value assume no new acquisitions. Finance-lease liabilities are treated as debt (net debt) and lease ROU amortization is added back with depreciation; lease interest sits below EBITA.
B39: Implied ROIC & incremental ROIC (USDm) | D39: =D17 -> 2026E | E39: =E17 -> 2027E | F39: =F17 -> 2028E | G39: =G17 -> 2029E | H39: =H17 -> 2030E | I39: =I17 -> 2031E | J39: =J17 -> 2032E | K39: =K17 -> 2033E | ... M39: =M17 -> 2035E | N39: Terminal
B40: NOPAT (row 22) | D40: =D22 -> 133.67959 | E40: =E22 -> 180.10704 | F40: =F22 -> 224.14077 | G40: =G22 -> 272.09222 | H40: =H22 -> 323.80293 | I40: =I22 -> 372.37337 | J40: =J22 -> 419.85098 | K40: =K22 -> 463.93533 | ... M40: =M22 -> 532.34259 | N40: =M40*(1+$C$32) -> 553.6363
B41: Net investment = NOPAT − UFCF | D41: =D40-D26 -> 76.691756 | E41: =E40-E26 -> 269.83443 | F41: =F40-F26 -> 293.07536 | G41: =G40-G26 -> 320.04704 | H41: =H40-H26 -> 321.10152 | I41: =I40-I26 -> 81.766744 | J41: =J40-J26 -> 92.192004 | K41: =K40-K26 -> 101.87216 | ... N41: =N40-N26 -> 121.56894
B42: Opening invested capital | D42: =Model!P333 -> 929.276 | E42: =D43 -> 1005.9678 | F42: =E43 -> 1275.8022 | G42: =F43 -> 1568.8776 | H42: =G43 -> 1888.9246 | I42: =H43 -> 2210.0261 | J42: =I43 -> 2291.7929 | K42: =J43 -> 2383.9849 | L42: =K43 -> 2485.857 | ... N42: =M43 -> 2713.0269
B43: Closing invested capital | D43: =D42+D41 -> 1005.9678 | E43: =E42+E41 -> 1275.8022 | F43: =F42+F41 -> 1568.8776 | G43: =G42+G41 -> 1888.9246 | H43: =H42+H41 -> 2210.0261 | I43: =I42+I41 -> 2291.7929 | J43: =J42+J41 -> 2383.9849 | K43: =K42+K41 -> 2485.857 | ... M43: =M42+M41 -> 2713.0269
B44: Implied ROIC = NOPAT / opening IC | D44: =IFERROR(D40/D42,"") -> 0.14385348 | E44: =IFERROR(E40/E42,"") -> 0.17903858 | F44: =IFERROR(F40/F42,"") -> 0.17568615 | G44: =IFERROR(G40/G42,"") -> 0.17343114 | H44: =IFERROR(H40/H42,"") -> 0.17142184 | I44: =IFERROR(I40/I42,"") -> 0.16849275 | J44: =IFERROR(J40/J42,"") -> 0.18319761 | K44: =IFERROR(K40/K42,"") -> 0.19460498 | ... N44: =IFERROR(N40/N42,"") -> 0.20406591
B45: Reinvestment rate = net inv. / NOPAT | D45: =IFERROR(D41/D40,"") -> 0.57369831 | E45: =IFERROR(E41/E40,"") -> 1.4981892 | F45: =IFERROR(F41/F40,"") -> 1.3075505 | G45: =IFERROR(G41/G40,"") -> 1.1762447 | H45: =IFERROR(H41/H40,"") -> 0.99165722 | I45: =IFERROR(I41/I40,"") -> 0.21958268 | J45: =IFERROR(J41/J40,"") -> 0.21958268 | K45: =IFERROR(K41/K40,"") -> 0.21958268 | ... N45: =IFERROR(N41/N40,"") -> 0.21958268
B46: Incremental ROIC = Δ NOPAT / prior-yr net inv. | E46: =IFERROR((E40-D40)/D41,"") -> 0.60537735 | F46: =IFERROR((F40-E40)/E41,"") -> 0.16318795 | G46: =IFERROR((G40-F40)/F41,"") -> 0.16361475 | H46: =IFERROR((H40-G40)/G41,"") -> 0.16157222 | I46: =IFERROR((I40-H40)/H41,"") -> 0.15126194 | J46: =IFERROR((J40-I40)/I41,"") -> 0.58064688 | K46: =IFERROR((K40-J40)/J41,"") -> 0.47817978 | L46: =IFERROR((L40-K40)/K41,"") -> 0.37571269 | M46: =IFERROR((M40-L40)/L41,"") -> 0.27324559 | N46: =IFERROR($C$32/N45,"") -> 0.18216373
...

Sheet Charts
B2: Karman Holdings — Operating Performance (2022A–2030E)
B3: USDm · Linked to Model (Base / live scenario). 2022–25 actual, 2026E–30E forecast. M&A % = disclosed / derived incremental acquisition sales (FY24 RMS) and the M&A lever; organic split not disclosed for 2022–23 and 2025. Adj. EBITDA = company definition; Adj. EBITA = model.
C7: 2022 | D7: 2023 | E7: 2024 | F7: 2025 | G7: 2026E | H7: 2027E | I7: 2028E | J7: 2029E | K7: 2030E
B8: Organic % | C8: =IFERROR(Model!C180+0,0) -> 0 | D8: =IFERROR(Model!D180+0,0) -> 0 | E8: =IFERROR(Model!J180+0,0) -> 0.1882902 | F8: =IFERROR(Model!P180+0,0) -> 0 | G8: =IFERROR(Model!V180+0,0) -> 0.36292259 | H8: =IFERROR(Model!W180+0,0) -> 0.20644341 | I8: =IFERROR(Model!X180+0,0) -> 0.16013466 | J8: =IFERROR(Model!Y180+0,0) -> 0.13597377 | K8: =IFERROR(Model!Z180+0,0) -> 0.11803842
B9: M&A % | C9: =IFERROR(Model!C181+0,0) -> 0 | D9: =IFERROR(Model!D181+0,0) -> 0 | E9: =IFERROR(Model!J181+0,0) -> 0.041652268 | F9: =IFERROR(Model!P181+0,0) -> 0 | G9: =IFERROR(Model!V181+0,0) -> 0.22668505 | H9: =IFERROR(Model!W181+0,0) -> 0.072026039 | I9: =IFERROR(Model!X181+0,0) -> 0.079202504 | J9: =IFERROR(Model!Y181+0,0) -> 0.071425636 | K9: =IFERROR(Model!Z181+0,0) -> 0.062270098
C11: 2022 | D11: 2023 | E11: 2024 | F11: 2025 | G11: 2026E | H11: 2027E | I11: 2028E | J11: 2029E | K11: 2030E
B12: Adjusted EBITDA | C12: =Model!C146 -> 60.291 | D12: =Model!D146 -> 81.861 | E12: =Model!J146 -> 106.145 | F12: =Model!P146 -> 145.302 | G12: =Model!V146 -> 221.99 | H12: =Model!W146 -> 285.16474 | I12: =Model!X146 -> 354.34888 | J12: =Model!Y146 -> 428.83603 | K12: =Model!Z146 -> 508.50635
B13: Operating Income (GAAP) | C13: =Model!C97 -> 20.435 | D13: =Model!D97 -> 48.494 | E13: =Model!J97 -> 63.56 | F13: =Model!P97 -> 72.942 | G13: =Model!V97 -> 137.37156 | H13: =Model!W97 -> 198.23987 | I13: =Model!X97 -> 255.59394 | J13: =Model!Y97 -> 312.19955 | K13: =Model!Z97 -> 371.81556
B14: Adj. EBITDA Margin % | C14: =Model!C188 -> 0.26640891 | D14: =Model!D188 -> 0.29162644 | E14: =Model!J188 -> 0.30744299 | F14: =Model!P188 -> 0.30816967 | G14: =Model!V188 -> 0.29618412 | H14: =Model!W188 -> 0.29760062 | I14: =Model!X188 -> 0.29838679 | J14: =Model!Y188 -> 0.29908101 | K14: =Model!Z188 -> 0.30046813
B15: GAAP Op. Margin % | C15: =Model!C191 -> 0.090296496 | D15: =Model!D191 -> 0.17275788 | E15: =Model!J191 -> 0.18409795 | F15: =Model!P191 -> 0.15470201 | G15: =Model!V191 -> 0.18328427 | H15: =Model!W191 -> 0.20688501 | I15: =Model!X191 -> 0.21522816 | J15: =Model!Y191 -> 0.2177358 | K15: =Model!Z191 -> 0.21969976
C17: 2022 | D17: 2023 | E17: 2024 | F17: 2025 | G17: 2026E | H17: 2027E | I17: 2028E | J17: 2029E | K17: 2030E
B18: ROIC | C18: =IFERROR(Model!C336+0,NA()) -> 0.065972883 | D18: =IFERROR(Model!D336+0,NA()) -> 0.088735214 | E18: =IFERROR(Model!J336+0,NA()) -> 0.10622211 | F18: =IFERROR(Model!P336+0,NA()) -> 0.098155446 | G18: =IFERROR(Model!V336+0,NA()) -> 0.11602219 | H18: =IFERROR(Model!W336+0,NA()) -> 0.12443802 | I18: =IFERROR(Model!X336+0,NA()) -> 0.13153862 | J18: =IFERROR(Model!Y336+0,NA()) -> 0.13732976 | K18: =IFERROR(Model!Z336+0,NA()) -> 0.14345682
B19: RONTA | C19: =IFERROR(Model!C348+0,NA()) -> 0.19146647 | D19: =IFERROR(Model!D348+0,NA()) -> 0.24609268 | E19: =IFERROR(Model!J348+0,NA()) -> 0.27925921 | F19: =IFERROR(Model!P348+0,NA()) -> 0.23564509 | G19: =IFERROR(Model!V348+0,NA()) -> 0.27158545 | H19: =IFERROR(Model!W348+0,NA()) -> 0.32966582 | I19: =IFERROR(Model!X348+0,NA()) -> 0.36123323 | J19: =IFERROR(Model!Y348+0,NA()) -> 0.39043687 | K19: =IFERROR(Model!Z348+0,NA()) -> 0.41724046
B20: Adj. EBITDA margin % | C20: =IFERROR(Model!C188+0,NA()) -> 0.26640891 | D20: =IFERROR(Model!D188+0,NA()) -> 0.29162644 | E20: =IFERROR(Model!J188+0,NA()) -> 0.30744299 | F20: =IFERROR(Model!P188+0,NA()) -> 0.30816967 | G20: =IFERROR(Model!V188+0,NA()) -> 0.29618412 | H20: =IFERROR(Model!W188+0,NA()) -> 0.29760062 | I20: =IFERROR(Model!X188+0,NA()) -> 0.29838679 | J20: =IFERROR(Model!Y188+0,NA()) -> 0.29908101 | K20: =IFERROR(Model!Z188+0,NA()) -> 0.30046813
B21: FCF margin % | C21: =IFERROR(Model!C224+0,NA()) -> -0.12002121 | D21: =IFERROR(Model!D224+0,NA()) -> 0.012653854 | E21: =IFERROR(Model!J224+0,NA()) -> 0.03299918 | F21: =IFERROR(Model!P224+0,NA()) -> -0.090042418 | G21: =IFERROR(Model!V224+0,NA()) -> 0.035932902 | H21: =IFERROR(Model!W224+0,NA()) -> 0.084339576 | I21: =IFERROR(Model!X224+0,NA()) -> 0.10429028 | J21: =IFERROR(Model!Y224+0,NA()) -> 0.11676492 | K21: =IFERROR(Model!Z224+0,NA()) -> 0.12808915
