Workbook

Sheet Model
CK1: SCENARIO SWITCH ▼ (Bull / Base / Bear) — drives all scenario-linked forecast drivers
B2: Cintas Corporation (NASDAQ: CTAS) — 3-Statement Financial Model | CK2: Base
B3: US GAAP as reported · USD millions (per-share data in USD, restated for the 4-for-1 split of Sep-2024; shares in millions) · Fiscal years end 31-May · Source: Cintas Forms 10-K / 10-Q and Form 8-K earnings releases (Ex. 99), merger 8-K (10-Mar-2026), S-4 / 424B3 (UniFirst pro forma), UniFirst 10-K / 8-K, SEC EDGAR CIK 0000723254 (investor-relations releases are the same documents as filed on EDGAR)
B4: Basis notes: fiscal year ends 31-May (Q1 = Jun–Aug). Quarters as originally reported. Segments: Rental / Uniform Direct Sales / First Aid, Safety & Fire / Document Management to FY2015; UR&FS / First Aid & Safety / All Other from FY2016 (FY2015 recast). Shred-it partnership Apr-2014 (Document Shredding deconsolidated); document storage sold FY2015–16; Shred-it stake sold FY2017 (discontinued operations FY2015–2020); G&K Services acquired 21-Mar-2017; 4-for-1 stock split 11-Sep-2024. UniFirst acquisition pending (FTC Second Request) — modelled from an assumed 31-Dec-2026 close (toggle); NOT in company FY27 guidance.
CM5: Forecast | CN5: Historical | CO5: Historical | CP5: Historical
B6: (USDm) | C6: FY2006 | D6: FY2007 | E6: FY2008 | F6: FY2009 | G6: FY2010 | H6: FY2011 | I6: FY2012 | J6: Q1/13 | K6: Q2/13 | L6: Q3/13 | M6: Q4/13 | N6: FY2013 | O6: Q1/14 | P6: Q2/14 | Q6: Q3/14 | R6: Q4/14 | S6: FY2014 | T6: Q1/15 | U6: Q2/15 | V6: Q3/15 | W6: Q4/15 | X6: FY2015 | Y6: Q1/16 | Z6: Q2/16 | AA6: Q3/16 | AB6: Q4/16 | AC6: FY2016 | AD6: Q1/17 | AE6: Q2/17 | AF6: Q3/17 | AG6: Q4/17 | AH6: FY2017 | AI6: Q1/18 | AJ6: Q2/18 | AK6: Q3/18 | AL6: Q4/18 | AM6: FY2018 | AN6: Q1/19 | AO6: Q2/19 | AP6: Q3/19 | AQ6: Q4/19 | AR6: FY2019 | AS6: Q1/20 | AT6: Q2/20 | AU6: Q3/20 | AV6: Q4/20 | AW6: FY2020 | AX6: Q1/21 | AY6: Q2/21 | AZ6: Q3/21 | BA6: Q4/21 | BB6: FY2021 | BC6: Q1/22 | BD6: Q2/22 | BE6: Q3/22 | BF6: Q4/22 | BG6: FY2022 | BH6: Q1/23 | BI6: Q2/23 | BJ6: Q3/23 | BK6: Q4/23 | BL6: FY2023 | BM6: Q1/24 | BN6: Q2/24 | BO6: Q3/24 | BP6: Q4/24 | BQ6: FY2024 | BR6: Q1/25 | BS6: Q2/25 | BT6: Q3/25 | BU6: Q4/25 | BV6: FY2025 | BW6: Q1/26 | BX6: Q2/26 | BY6: Q3/26 | BZ6: Q4/26 | CA6: FY2026 | CB6: Q1/27 | CC6: Q2/27E | CD6: Q3/27E | CE6: Q4/27E | CF6: FY2027E | CG6: FY2028E | CH6: FY2029E | CI6: FY2030E | CJ6: FY2031E | CK6: Modelling Notes | CM6: 5Y CAGR | CN6: 5Y CAGR | CO6: 10Y CAGR | CP6: 20Y CAGR
CM7: 26-'31 | CN7: 21-'26 | CO7: 16-'26 | CP7: 06-'26
B8: SEGMENT P&L — UNIFORM RENTAL & FACILITY SERVICES · FIRST AID & SAFETY · ALL OTHER · UNIFIRST (organic growth + M&A build) | CK8: SEGMENT BUILD — modelling logic (organic growth → revenues → gross margin → S&A → segment operating income)
CS9: SCENARIO INPUT TABLE — driver assumptions per Bull / Base / Bear | CT9: Bull | CU9: Base | CV9: Bear | CW9: Bull / Bear = Base + Δ (Δ inputs on each block header). Outlook block = high / mid / low end of FY27 ranges. Blue = input.
B10: Uniform Rental & Facility Services (UR&FS) — reportable segment: uniform & garment rental, mats, mops, shop towels, restroom & hygiene, water, Clean Room; legacy "Rental Uniforms & Ancillary Products" segment to FY2014 (FY2015 recast incl. storage) | CK10: UR&FS — modelling logic
B11: Revenues | C11: 2568.776 | D11: 2734.629 | E11: 2834.568 | F11: 2755.015 | G11: 2569.357 | H11: 2692.248 | I11: 2912.261 | J11: 754.843 | K11: 755.839 | L11: 748.887 | M11: 785.018 | N11: 3044.587 | O11: 792.866 | P11: 804.316 | Q11: 801.702 | R11: 825.046 | S11: 3223.93 | T11: 873.698 | U11: 891.475 | V11: 883.401 | W11: 891.269 | X11: 3539.843 | Y11: 938.408 | Z11: 937.704 | AA11: 936.565 | AB11: 965.124 | AC11: 3777.801 | AD11: 999.596 | AE11: 1005.565 | AF11: 993.398 | AG11: 1220.015 | AH11: 4202.49 | AI11: 1311.784 | AJ11: 1308.038 | AK11: 1284.516 | AL11: 1342.786 | AM11: 5247.124 | AN11: 1374.938 | AO11: 1390.778 | AP11: 1358.322 | AQ11: 1428.392 | AR11: 5552.43 | AS11: 1454.527 | AT11: 1469.977 | AU11: 1448.021 | AV11: 1270.97 | AW11: 5643.494 | AX11: 1394.411 | AY11: 1410.488 | AZ11: 1417.865 | BA11: 1466.868 | BB11: 5689.632 | BC11: 1508.176 | BD11: 1535.271 | BE11: 1553.32 | BF11: 1630.213 | BG11: 6226.98 | BH11: 1697.772 | BI11: 1709.987 | BJ11: 1716.165 | BK11: 1773.206 | BL11: 6897.13 | BM11: 1826.825 | BN11: 1850.542 | BO11: 1876.642 | BP11: 1911.19 | BQ11: 7465.199 | BR11: 1933.839 | BS11: 1990.41 | BT11: 2021.144 | BU11: 2030.68 | BV11: 7976.073 | BW11: 2091.066 | BX11: 2155.4 | BY11: 2177.453 | BZ11: 2197.705 | CA11: 8621.624 | CB11: 2294.736 | CC11: =BX11*(1+CC12) -> 2294.0821 | CD11: =BY11*(1+CD12) -> 2317.554 | CE11: =BZ11*(1+CE12) -> 2339.1091 | CF11: =SUM(CB11,CC11,CD11,CE11) -> 9245.4812 | CG11: =CF11*(1+CG12) -> 9892.6649 | CH11: =CG11*(1+CH12) -> 10535.688 | CI11: =CH11*(1+CI12) -> 11220.508 | CJ11: =CI11*(1+CJ12) -> 11893.738 | CK11: Q2–Q4/27E: prior-year quarter × (1 + Q1/27 y/y growth ex-workday effect + revenue-outlook calibration Δ). FY28E+: prior year × (1 + scenario organic growth URFS_org); bolt-on M&A modelled separately (Future acquisitions block). | CM11: =IFERROR((CJ11/CA11)^(1/5)-1,"n/m") -> 0.066463166 | CN11: =IFERROR((CA11/BB11)^(1/5)-1,"n/m") -> 0.086678264 | CO11: =IFERROR((CA11/AC11)^(1/10)-1,"n/m") -> 0.08601294 | CP11: =IFERROR((CA11/C11)^(1/20)-1,"n/m") -> 0.062412428 | CS11: FY27 outlook — Q1/27 release (23-Sep-26); legacy Cintas, excludes UniFirst | CT11: High | CU11: Mid | CV11: Low | CW11: Company guidance excludes the UniFirst acquisition — the model adds UniFirst separately.
B12: Revenues y/y % | D12: =IF(AND(ISNUMBER(D11),ISNUMBER(C11)),IFERROR(D11/C11-1,""),"") -> 0.064564991 | E12: =IF(AND(ISNUMBER(E11),ISNUMBER(D11)),IFERROR(E11/D11-1,""),"") -> 0.036545725 | F12: =IF(AND(ISNUMBER(F11),ISNUMBER(E11)),IFERROR(F11/E11-1,""),"") -> -0.0280653 | G12: =IF(AND(ISNUMBER(G11),ISNUMBER(F11)),IFERROR(G11/F11-1,""),"") -> -0.067389107 | H12: =IF(AND(ISNUMBER(H11),ISNUMBER(G11)),IFERROR(H11/G11-1,""),"") -> 0.047829476 | I12: =IF(AND(ISNUMBER(I11),ISNUMBER(H11)),IFERROR(I11/H11-1,""),"") -> 0.081720926 | N12: =IF(AND(ISNUMBER(N11),ISNUMBER(I11)),IFERROR(N11/I11-1,""),"") -> 0.045437548 | O12: =IF(AND(ISNUMBER(O11),ISNUMBER(J11)),IFERROR(O11/J11-1,""),"") -> 0.050372064 | P12: =IF(AND(ISNUMBER(P11),ISNUMBER(K11)),IFERROR(P11/K11-1,""),"") -> 0.064136675 | Q12: =IF(AND(ISNUMBER(Q11),ISNUMBER(L11)),IFERROR(Q11/L11-1,""),"") -> 0.070524659 | R12: =IF(AND(ISNUMBER(R11),ISNUMBER(M11)),IFERROR(R11/M11-1,""),"") -> 0.050989914 | S12: =IF(AND(ISNUMBER(S11),ISNUMBER(N11)),IFERROR(S11/N11-1,""),"") -> 0.058905526 | T12: =IF(AND(ISNUMBER(T11),ISNUMBER(O11)),IFERROR(T11/O11-1,""),"") -> 0.10194913 | U12: =IF(AND(ISNUMBER(U11),ISNUMBER(P11)),IFERROR(U11/P11-1,""),"") -> 0.10836413 | ... CB12: =IF(AND(ISNUMBER(CB11),ISNUMBER(BW11)),IFERROR(CB11/BW11-1,""),"") -> 0.097400082 | CC12: =$CB$12-$CB$109+CC114 -> 0.064341707 | CD12: =$CB$12-$CB$109+CD114 -> 0.064341707 | CE12: =$CB$12-$CB$109+CE114 -> 0.064341707 | CF12: =IFERROR(CF11/CA11-1,"") -> 0.072359598 | CG12: =CHOOSE(MATCH($CK$2,{"Bull","Base","Bear"},0),$CT$76,$CU$76,$CV$76) -> 0.07 | CH12: =CHOOSE(MATCH($CK$2,{"Bull","Base","Bear"},0),$CT$77,$CU$77,$CV$77) -> 0.065 | CI12: =CHOOSE(MATCH($CK$2,{"Bull","Base","Bear"},0),$CT$78,$CU$78,$CV$78) -> 0.065 | CJ12: =CHOOSE(MATCH($CK$2,{"Bull","Base","Bear"},0),$CT$79,$CU$79,$CV$79) -> 0.06 | CK12: Q2–Q4/27E: Q1/27 y/y less the Q1 extra-workday effect (row "Workday effect") + calibration Δ (Group block). FY28E+: scenario lever. | CS12: FY27 revenues ($m) | CT12: 12270 | CU12: 12210 | CV12: 12150 | CW12: Raised to $12.15–12.27bn in the Q1/27 release (from $12.10–12.25bn); excludes UniFirst & future M&A.
B13: Organic growth % (company-disclosed, segment) | AA13: 0.061 | AE13: 0.065 | AF13: 0.073 | AG13: 0.08 | AI13: 0.081 | AJ13: 0.073 | AK13: 0.065 | AL13: 0.053 | AN13: 0.049 | AO13: 0.066 | AP13: 0.062 | AQ13: 0.068 | AS13: 0.075 | AT13: 0.058 | AU13: 0.048 | AV13: -0.096 | AX13: -0.054 | AY13: -0.036 | AZ13: 0 | BA13: 0.137 | BD13: 0.083 | BE13: 0.089 | BF13: 0.105 | BH13: 0.123 | BI13: 0.113 | BJ13: 0.108 | BL13: 0.108 | BM13: 0.076 | BN13: 0.079 | BO13: 0.071 | BR13: 0.07 | BS13: 0.069 | BT13: 0.07 | BW13: 0.073 | BX13: 0.078 | BY13: 0.073 | CC13: =CC12 -> 0.064341707 | CD13: =CD12 -> 0.064341707 | CE13: =CE12 -> 0.064341707 | CF13: =CF12 -> 0.072359598 | CG13: =CG12 -> 0.07 | CH13: =CH12 -> 0.065 | CI13: =CI12 -> 0.065 | CJ13: =CJ12 -> 0.06 | CK13: Segment organic growth as disclosed in releases (FY2016–21) and 10-Q MD&A (FY2022+); blank where not disclosed. Forecast: no acquisition/FX/workday effect assumed inside segments. | CS13: FY27 adjusted diluted EPS ($) | CT13: 5.54 | CU13: 5.495 | CV13: 5.45 | CW13: Raised to $5.45–5.54 (from $5.36–5.50); excludes UniFirst transaction costs; FY26 adj. $4.94.
B14: Acquisitions, FX & workday effects % (derived = y/y − organic) | C14: =IF(AND(ISNUMBER(C12),ISNUMBER(C13)),C12-C13,"") | D14: =IF(AND(ISNUMBER(D12),ISNUMBER(D13)),D12-D13,"") | E14: =IF(AND(ISNUMBER(E12),ISNUMBER(E13)),E12-E13,"") | F14: =IF(AND(ISNUMBER(F12),ISNUMBER(F13)),F12-F13,"") | G14: =IF(AND(ISNUMBER(G12),ISNUMBER(G13)),G12-G13,"") | H14: =IF(AND(ISNUMBER(H12),ISNUMBER(H13)),H12-H13,"") | I14: =IF(AND(ISNUMBER(I12),ISNUMBER(I13)),I12-I13,"") | J14: =IF(AND(ISNUMBER(J12),ISNUMBER(J13)),J12-J13,"") | ... CB14: =IF(AND(ISNUMBER(CB12),ISNUMBER(CB13)),CB12-CB13,"")
B15: Gross margin (GAAP) | C15: 1161.947 | D15: 1219.444 | E15: 1252.951 | F15: 1192.785 | G15: 1119.781 | H15: 1161.792 | I15: 1263.71 | J15: 326.695 | K15: 316.937 | L15: 314.078 | M15: 330.58 | N15: 1288.29 | O15: 338.135 | P15: 345.204 | Q15: 351.616 | R15: 359.548 | S15: 1394.503 | T15: 383.023 | U15: 385.652 | V15: 382.128 | W15: 381.408 | X15: 1532.211 | Y15: 419.905 | Z15: 411.613 | AA15: 411.909 | AB15: 427.581 | AC15: 1671.008 | AD15: 458.664 | AE15: 449.813 | AF15: 446.86 | AG15: 543.626 | AH15: 1894.716 | AI15: 604.921 | AJ15: 584.078 | AK15: 566.378 | AL15: 604.788 | AM15: 2360.165 | AN15: 628.485 | AO15: 629.659 | AP15: 609.351 | AQ15: 657.336 | AR15: 2524.831 | AS15: 685.851 | AT15: 685.04 | AU15: 663.091 | AV15: 554.368 | AW15: 2588.349 | AX15: 678.999 | AY15: 670.677 | AZ15: 656.015 | BA15: 700.427 | BB15: 2706.118 | BC15: 728.875 | BD15: 718.01 | BE15: 719.238 | BF15: 744.424 | BG15: 2910.547 | BH15: 807.006 | BI15: 803.26 | BJ15: 808.172 | BK15: 846.517 | BL15: 3264.955 | BM15: 879.242 | BN15: 876.311 | BO15: 916.434 | BP15: 928.141 | BQ15: 3600.128 | BR15: 952.676 | BS15: 976.358 | BT15: 1011.484 | BU15: 994.667 | BV15: 3935.185 | BW15: 1038.513 | BX15: 1074.182 | BY15: 1094.434 | BZ15: 1102.398 | CA15: 4309.527 | CB15: 1165.852 | CC15: =CC11*CC17 -> 1140.795 | CD15: =CD11*CD17 -> 1162.3245 | CE15: =CE11*CE17 -> 1170.7774 | CF15: =SUM(CB15,CC15,CD15,CE15) -> 4639.7489 | CG15: =CG11*CG17 -> 5045.2591 | CH15: =CH11*CH17 -> 5404.808 | CI15: =CI11*CI17 -> 5789.7821 | CJ15: =CJ11*CJ17 -> 6172.8502 | CM15: =IFERROR((CJ15/CA15)^(1/5)-1,"n/m") -> 0.074511892 | CN15: =IFERROR((CA15/BB15)^(1/5)-1,"n/m") -> 0.097530442 | CO15: =IFERROR((CA15/AC15)^(1/10)-1,"n/m") -> 0.099373104 | CP15: =IFERROR((CA15/C15)^(1/20)-1,"n/m") -> 0.067731768 | CS15: Point estimates & structural inputs (all cases)
B16: Gross margin % before outlook calibration (Q2–Q4/27E helper) | CC16: =BX17+($CB$17-$BW$17) -> 0.50977992 | CD16: =BY17+($CB$17-$BW$17) -> 0.51403328 | CE16: =BZ17+($CB$17-$BW$17) -> 0.51302537 | CK16: Prior-year quarter margin + (Q1/27 − Q1/26 margin drift). | CS16: FY27 interest expense, net — guidance ($m) | CU16: 103 | CW16: Q1/27 release: ~$103.0m (FY26 $101.2m), incl. bridge-loan fee amortization; excludes UniFirst funding.
B17: Gross margin % | C17: =IF(AND(ISNUMBER(C15),ISNUMBER(C11)),IFERROR(C15/C11,""),"") -> 0.45233489 | D17: =IF(AND(ISNUMBER(D15),ISNUMBER(D11)),IFERROR(D15/D11,""),"") -> 0.44592667 | E17: =IF(AND(ISNUMBER(E15),ISNUMBER(E11)),IFERROR(E15/E11,""),"") -> 0.44202538 | F17: =IF(AND(ISNUMBER(F15),ISNUMBER(F11)),IFERROR(F15/F11,""),"") -> 0.43295046 | G17: =IF(AND(ISNUMBER(G15),ISNUMBER(G11)),IFERROR(G15/G11,""),"") -> 0.43582149 | H17: =IF(AND(ISNUMBER(H15),ISNUMBER(H11)),IFERROR(H15/H11,""),"") -> 0.43153231 | I17: =IF(AND(ISNUMBER(I15),ISNUMBER(I11)),IFERROR(I15/I11,""),"") -> 0.43392745 | J17: =IF(AND(ISNUMBER(J15),ISNUMBER(J11)),IFERROR(J15/J11,""),"") -> 0.43279861 | ... CB17: =IF(AND(ISNUMBER(CB15),ISNUMBER(CB11)),IFERROR(CB15/CB11,""),"") -> 0.50805496 | CC17: =CC16+CC120 -> 0.49727733 | CD17: =CD16+CD120 -> 0.50153069 | CE17: =CE16+CE120 -> 0.50052278 | CF17: =IF(AND(ISNUMBER(CF15),ISNUMBER(CF11)),IFERROR(CF15/CF11,""),"") -> 0.50183963 | CG17: =CHOOSE(MATCH($CK$2,{"Bull","Base","Bear"},0),$CT$94,$CU$94,$CV$94) -> 0.51 | CH17: =CHOOSE(MATCH($CK$2,{"Bull","Base","Bear"},0),$CT$95,$CU$95,$CV$95) -> 0.513 | CI17: =CHOOSE(MATCH($CK$2,{"Bull","Base","Bear"},0),$CT$96,$CU$96,$CV$96) -> 0.516 | CJ17: =CHOOSE(MATCH($CK$2,{"Bull","Base","Bear"},0),$CT$97,$CU$97,$CV$97) -> 0.519 | CK17: Q2–Q4/27E: helper + uniform margin calibration Δ (solved to the FY27 adjusted EPS guidance). FY28E+: scenario lever URFS_GM (level). | CS17: FY27 effective tax rate — guidance | CU17: 0.204 | CW17: Q1/27 release: 20.4% (FY26 20.2%).
B18: Selling & administrative expenses (segment) | D18: 757.058 | E18: 801.691 | F18: 769.275 | G18: 786.145 | H18: 822.23 | I18: 834.21 | J18: 209.788 | K18: 200.886 | L18: 211.531 | M18: 213.044 | N18: 835.249 | O18: 220.742 | P18: 219.134 | Q18: 223.234 | R18: 224.334 | S18: 887.444 | T18: 238.207 | U18: 226.085 | V18: 229.963 | W18: 231.921 | X18: 926.176 | Y18: 254.524 | Z18: 242.318 | AA18: 244.407 | AB18: 256.82 | AC18: 998.069 | AD18: 270.632 | AE18: 269.105 | AF18: 264.973 | AG18: 336.4 | AH18: 1138.345 | AI18: 382.04 | AJ18: 367.19 | AK18: 383.27 | AL18: 368.144 | AM18: 1500.644 | AN18: 392.101 | AO18: 378.921 | AP18: 369.414 | AQ18: 393.275 | AR18: 1533.711 | AS18: 416.84 | AT18: 398.68 | AU18: 391.462 | AV18: 376.809 | AW18: 1583.791 | AX18: 363.971 | AY18: 355.068 | AZ18: 372.612 | BA18: 388.627 | BB18: 1480.278 | BC18: 399.493 | BD18: 380.395 | BE18: 363.248 | BF18: 413.921 | BG18: 1557.057 | BH18: 442.235 | BI18: 434.165 | BJ18: 448.177 | BK18: 461.621 | BL18: 1786.198 | BM18: 472.713 | BN18: 476.7 | BO18: 496.027 | BP18: 495.187 | BQ18: 1940.627 | BR18: 506.238 | BS18: 503.999 | BT18: 522.001 | BU18: 529.558 | BV18: 2061.795 | BW18: 538.576 | BX18: 548.451 | BY18: 573.409 | BZ18: 572.93 | CA18: 2232.515 | CB18: 590.764 | CC18: =CC11*CC19 -> 583.47 | CD18: =CD11*CD19 -> 610.03109 | CE18: =CE11*CE19 -> 609.51874 | CF18: =SUM(CB18,CC18,CD18,CE18) -> 2393.7838 | CG18: =CG11*CG19 -> 2541.4994 | CH18: =CH11*CH19 -> 2685.6254 | CI18: =CI11*CI19 -> 2837.7501 | CJ18: =CJ11*CJ19 -> 2984.2276 | CS18: FY27 guidance diluted shares (m; ex-future buybacks) | CU18: 404.29 | CW18: Q1/27 weighted diluted shares 404.3m (guidance excludes future buybacks).
B19: S&A % of revenues | C19: =IF(AND(ISNUMBER(C18),ISNUMBER(C11)),IFERROR(C18/C11,""),"") | D19: =IF(AND(ISNUMBER(D18),ISNUMBER(D11)),IFERROR(D18/D11,""),"") -> 0.27684121 | E19: =IF(AND(ISNUMBER(E18),ISNUMBER(E11)),IFERROR(E18/E11,""),"") -> 0.28282652 | F19: =IF(AND(ISNUMBER(F18),ISNUMBER(F11)),IFERROR(F18/F11,""),"") -> 0.27922715 | G19: =IF(AND(ISNUMBER(G18),ISNUMBER(G11)),IFERROR(G18/G11,""),"") -> 0.30596955 | H19: =IF(AND(ISNUMBER(H18),ISNUMBER(H11)),IFERROR(H18/H11,""),"") -> 0.30540649 | I19: =IF(AND(ISNUMBER(I18),ISNUMBER(I11)),IFERROR(I18/I11,""),"") -> 0.28644754 | J19: =IF(AND(ISNUMBER(J18),ISNUMBER(J11)),IFERROR(J18/J11,""),"") -> 0.27792269 | ... CB19: =IF(AND(ISNUMBER(CB18),ISNUMBER(CB11)),IFERROR(CB18/CB11,""),"") -> 0.25744312 | CC19: =BX19+($CB$19-$BW$19) -> 0.25433702 | CD19: =BY19+($CB$19-$BW$19) -> 0.26322195 | CE19: =BZ19+($CB$19-$BW$19) -> 0.2605773 | CF19: =IF(AND(ISNUMBER(CF18),ISNUMBER(CF11)),IFERROR(CF18/CF11,""),"") -> 0.25891392 | CG19: =$CF$19+(CG124-$CF$123) -> 0.25690745 | CH19: =$CF$19+(CH124-$CF$123) -> 0.25490745 | CI19: =$CF$19+(CI124-$CF$123) -> 0.25290745 | CJ19: =$CF$19+(CJ124-$CF$123) -> 0.25090745 | CK19: Q2–Q4/27E: prior-year quarter + Q1 drift. FY28E+: FY27E segment ratio + Δ of the consolidated legacy S&A lever SA_pct vs FY27E. | CS19: Effective tax rate FY28E+ | CU19: 0.21 | CW19: Higher UniFirst mix (US-heavy, fewer stock-comp benefits).
B20: Segment operating income (before special items) | C20: =IF(AND(ISNUMBER(C15),ISNUMBER(C18)),C15-C18,"") | D20: =IF(AND(ISNUMBER(D15),ISNUMBER(D18)),D15-D18,"") -> 462.386 | E20: =IF(AND(ISNUMBER(E15),ISNUMBER(E18)),E15-E18,"") -> 451.26 | F20: =IF(AND(ISNUMBER(F15),ISNUMBER(F18)),F15-F18,"") -> 423.51 | G20: =IF(AND(ISNUMBER(G15),ISNUMBER(G18)),G15-G18,"") -> 333.636 | H20: =IF(AND(ISNUMBER(H15),ISNUMBER(H18)),H15-H18,"") -> 339.562 | I20: =IF(AND(ISNUMBER(I15),ISNUMBER(I18)),I15-I18,"") -> 429.5 | J20: =IF(AND(ISNUMBER(J15),ISNUMBER(J18)),J15-J18,"") -> 116.907 | ... CB20: =IF(AND(ISNUMBER(CB15),ISNUMBER(CB18)),CB15-CB18,"") -> 575.088 | CC20: =CC15-CC18 -> 557.32502 | CD20: =CD15-CD18 -> 552.29339 | CE20: =CE15-CE18 -> 561.25865 | CF20: =CF15-CF18 -> 2245.9651 | CG20: =CG15-CG18 -> 2503.7598 | CH20: =CH15-CH18 -> 2719.1826 | CI20: =CI15-CI18 -> 2952.032 | CJ20: =CJ15-CJ18 -> 3188.6226 | CM20: =IFERROR((CJ20/CA20)^(1/5)-1,"n/m") -> 0.08951402 | CN20: =IFERROR((CA20/BB20)^(1/5)-1,"n/m") -> 0.11122254 | CO20: =IFERROR((CA20/AC20)^(1/10)-1,"n/m") -> 0.11929955 | CP20: =IFERROR((CA20/C20)^(1/20)-1,"n/m") -> n/m | CS20: UniFirst included (1 = yes, 0 = no) | CU20: 1 | CW20: Default ON per your instruction; set 0 for standalone Cintas (matches company guidance basis).
B21: Segment operating margin % | C21: =IF(AND(ISNUMBER(C20),ISNUMBER(C11)),IFERROR(C20/C11,""),"") | D21: =IF(AND(ISNUMBER(D20),ISNUMBER(D11)),IFERROR(D20/D11,""),"") -> 0.16908546 | E21: =IF(AND(ISNUMBER(E20),ISNUMBER(E11)),IFERROR(E20/E11,""),"") -> 0.15919886 | F21: =IF(AND(ISNUMBER(F20),ISNUMBER(F11)),IFERROR(F20/F11,""),"") -> 0.1537233 | G21: =IF(AND(ISNUMBER(G20),ISNUMBER(G11)),IFERROR(G20/G11,""),"") -> 0.12985194 | H21: =IF(AND(ISNUMBER(H20),ISNUMBER(H11)),IFERROR(H20/H11,""),"") -> 0.12612582 | I21: =IF(AND(ISNUMBER(I20),ISNUMBER(I11)),IFERROR(I20/I11,""),"") -> 0.14747991 | J21: =IF(AND(ISNUMBER(J20),ISNUMBER(J11)),IFERROR(J20/J11,""),"") -> 0.15487591 | ... CJ21: =IF(AND(ISNUMBER(CJ20),ISNUMBER(CJ11)),IFERROR(CJ20/CJ11,""),"") -> 0.26809255 | CS21: UniFirst assumed closing date | CU21: 46387 | CW21: "Prior to the end of calendar 2026" (Q1/27 release); FTC Second Request 11-Jun-26.
B22: Memo: segment operating income / income before taxes as reported (incl. segment special items) | D22: 462.386 | E22: 451.26 | F22: 370.524 | G22: 336.516 | H22: 339.562 | I22: 429.5 | J22: 116.907 | K22: 116.051 | L22: 102.547 | M22: 117.536 | N22: 453.041 | O22: 117.393 | P22: 126.07 | Q22: 128.382 | R22: 135.214 | S22: 507.059 | T22: 144.816 | U22: 159.567 | V22: 152.165 | W22: 149.487 | X22: 606.035 | Y22: 165.381 | Z22: 169.295 | AA22: 167.502 | AB22: 170.761 | AC22: 672.939 | AD22: 185.245 | AE22: 177.361 | AF22: 172.543 | AG22: 143.48 | AH22: 677.147 | AI22: 218.91 | AJ22: 203.814 | AK22: 173.287 | AL22: 221.613 | AM22: 817.624 | AN22: 231.534 | AO22: 242.891 | AP22: 239.138 | AQ22: 263.147 | AR22: 976.71 | AS22: 269.011 | AT22: 286.36 | AU22: 271.629 | AV22: 177.559 | AW22: 1004.558 | AX22: 315.028 | AY22: 315.609 | AZ22: 283.403 | BA22: 311.8 | BB22: 1225.84 | BC22: 329.382 | BD22: 337.615 | BE22: 355.99 | BF22: 330.503 | BG22: 1353.49 | BH22: 364.771 | BI22: 369.095 | BJ22: 359.995 | BK22: 384.896 | BL22: 1478.757 | BM22: 406.529 | BN22: 399.611 | BO22: 420.407 | BP22: 432.954 | BQ22: 1659.501 | BR22: 446.438 | BS22: 472.359 | BT22: 489.483 | BU22: 465.109 | BV22: 1873.39 | BW22: 499.937 | BX22: 525.731 | BY22: 521.025 | BZ22: 529.468 | CA22: 2077.012 | CB22: 575.088 | CS22: CTAS shares issued to UNF holders (m) | CU22: 14.071 | CW22: 424B3 pro forma: 18.227m UNF shares × 0.7720.
CS23: UniFirst acquisition debt ($m) | CU23: 2800 | CW23: 424B3 pro forma permanent financing $2.8bn.
B24: First Aid & Safety Services (FA&S) — reportable segment from FY2016 (FY2015 recast); first aid cabinets, safety products & training, eyewash, AEDs | CK24: FIRST AID & SAFETY — modelling logic | CS24: Interest rate on acquisition debt | CU24: 0.05 | CW24: 424B3 assumption (±1/8% = $3.5m p.a.).
B25: Revenues | T25: 79.924 | U25: 82.271 | V25: 79.471 | W25: 84.927 | X25: 326.593 | Y25: 99.488 | Z25: 120.438 | AA25: 119.064 | AB25: 122.793 | AC25: 461.783 | AD25: 124.839 | AE25: 124.797 | AF25: 124.239 | AG25: 134.358 | AH25: 508.233 | AI25: 140.582 | AJ25: 139.09 | AK25: 137.327 | AL25: 147.707 | AM25: 564.706 | AN25: 153.417 | AO25: 153.348 | AP25: 149.17 | AQ25: 163.535 | AR25: 619.47 | AS25: 172.09 | AT25: 169.667 | AU25: 170.541 | AV25: 196.27 | AW25: 708.569 | AX25: 204.481 | AY25: 194.419 | AZ25: 198.474 | BA25: 186.917 | BB25: 784.291 | BC25: 199.116 | BD25: 202.16 | BE25: 212.958 | BF25: 218.224 | BG25: 832.458 | BH25: 234.161 | BI25: 235.974 | BJ25: 231.605 | BK25: 249.756 | BL25: 951.496 | BM25: 260.693 | BN25: 266.401 | BO25: 262.602 | BP25: 277.638 | BQ25: 1067.334 | BR25: 292.567 | BS25: 299.367 | BT25: 301.759 | BU25: 324.397 | BV25: 1218.09 | BW25: 334.657 | BX25: 342.24 | BY25: 346.823 | BZ25: 368.133 | CA25: 1391.853 | CB25: 388.517 | CC25: =BX25*(1+CC26) -> 386.00652 | CD25: =BY25*(1+CD26) -> 391.1756 | CE25: =BZ25*(1+CE26) -> 415.21078 | CF25: =SUM(CB25,CC25,CD25,CE25) -> 1580.9099 | CG25: =CF25*(1+CG26) -> 1770.6191 | CH25: =CG25*(1+CH26) -> 1965.3872 | CI25: =CH25*(1+CI26) -> 2161.9259 | CJ25: =CI25*(1+CJ26) -> 2356.4992 | CK25: Q2–Q4/27E: prior-year quarter × (1 + Q1/27 y/y growth ex-workday effect + revenue-outlook calibration Δ). FY28E+: prior year × (1 + scenario organic growth FAS_org); bolt-on M&A modelled separately (Future acquisitions block). | CM25: =IFERROR((CJ25/CA25)^(1/5)-1,"n/m") -> 0.11105303 | CN25: =IFERROR((CA25/BB25)^(1/5)-1,"n/m") -> 0.12156185 | CO25: =IFERROR((CA25/AC25)^(1/10)-1,"n/m") -> 0.11664607 | CP25: =IFERROR((CA25/C25)^(1/20)-1,"n/m") -> n/m | CS25: Run-rate cost synergies ($m) | CU25: 375 | CW25: Deal 8-K: ~$375m within four years.
B26: Revenues y/y % | D26: =IF(AND(ISNUMBER(D25),ISNUMBER(C25)),IFERROR(D25/C25-1,""),"") | E26: =IF(AND(ISNUMBER(E25),ISNUMBER(D25)),IFERROR(E25/D25-1,""),"") | F26: =IF(AND(ISNUMBER(F25),ISNUMBER(E25)),IFERROR(F25/E25-1,""),"") | G26: =IF(AND(ISNUMBER(G25),ISNUMBER(F25)),IFERROR(G25/F25-1,""),"") | H26: =IF(AND(ISNUMBER(H25),ISNUMBER(G25)),IFERROR(H25/G25-1,""),"") | I26: =IF(AND(ISNUMBER(I25),ISNUMBER(H25)),IFERROR(I25/H25-1,""),"") | N26: =IF(AND(ISNUMBER(N25),ISNUMBER(I25)),IFERROR(N25/I25-1,""),"") | O26: =IF(AND(ISNUMBER(O25),ISNUMBER(J25)),IFERROR(O25/J25-1,""),"") | P26: =IF(AND(ISNUMBER(P25),ISNUMBER(K25)),IFERROR(P25/K25-1,""),"") | Q26: =IF(AND(ISNUMBER(Q25),ISNUMBER(L25)),IFERROR(Q25/L25-1,""),"") | R26: =IF(AND(ISNUMBER(R25),ISNUMBER(M25)),IFERROR(R25/M25-1,""),"") | S26: =IF(AND(ISNUMBER(S25),ISNUMBER(N25)),IFERROR(S25/N25-1,""),"") | T26: =IF(AND(ISNUMBER(T25),ISNUMBER(O25)),IFERROR(T25/O25-1,""),"") | U26: =IF(AND(ISNUMBER(U25),ISNUMBER(P25)),IFERROR(U25/P25-1,""),"") | ... CB26: =IF(AND(ISNUMBER(CB25),ISNUMBER(BW25)),IFERROR(CB25/BW25-1,""),"") -> 0.1609409 | CC26: =$CB$26-$CB$109+CC114 -> 0.12788253 | CD26: =$CB$26-$CB$109+CD114 -> 0.12788253 | CE26: =$CB$26-$CB$109+CE114 -> 0.12788253 | CF26: =IFERROR(CF25/CA25-1,"") -> 0.13583108 | CG26: =CHOOSE(MATCH($CK$2,{"Bull","Base","Bear"},0),$CT$82,$CU$82,$CV$82) -> 0.12 | CH26: =CHOOSE(MATCH($CK$2,{"Bull","Base","Bear"},0),$CT$83,$CU$83,$CV$83) -> 0.11 | CI26: =CHOOSE(MATCH($CK$2,{"Bull","Base","Bear"},0),$CT$84,$CU$84,$CV$84) -> 0.1 | CJ26: =CHOOSE(MATCH($CK$2,{"Bull","Base","Bear"},0),$CT$85,$CU$85,$CV$85) -> 0.09 | CK26: Q2–Q4/27E: Q1/27 y/y less the Q1 extra-workday effect (row "Workday effect") + calibration Δ (Group block). FY28E+: scenario lever. | CS26: Share of synergies in cost of sales | CU26: 0.65 | CW26: Material, production & delivery (vs G&A).
B27: Organic growth % (company-disclosed, segment) | AG27: 0.092 | AI27: 0.119 | AJ27: 0.108 | AK27: 0.1 | AL27: 0.094 | AN27: 0.09 | AO27: 0.102 | AP27: 0.086 | AQ27: 0.107 | AS27: 0.138 | AT27: 0.106 | AU27: 0.125 | AV27: 0.219 | AX27: 0.171 | AY27: 0.145 | AZ27: 0.177 | BA27: -0.068 | BD27: 0.032 | BE27: 0.062 | BH27: 0.158 | BI27: 0.151 | BJ27: 0.078 | BL27: 0.131 | BM27: 0.11 | BN27: 0.127 | BO27: 0.115 | BQ27: 0.116 | BR27: 0.14 | BS27: 0.123 | BT27: 0.15 | BV27: 0.15 | BW27: 0.141 | BX27: 0.141 | BY27: 0.146 | CA27: 0.14 | CC27: =CC26 -> 0.12788253 | CD27: =CD26 -> 0.12788253 | CE27: =CE26 -> 0.12788253 | CF27: =CF26 -> 0.13583108 | CG27: =CG26 -> 0.12 | CH27: =CH26 -> 0.11 | CI27: =CI26 -> 0.1 | CJ27: =CJ26 -> 0.09 | CK27: Segment organic growth as disclosed in releases (FY2016–21) and 10-Q MD&A (FY2022+); blank where not disclosed. Forecast: no acquisition/FX/workday effect assumed inside segments. | CS27: Net PP&E step-up depreciation ($m p.a.) | CU27: 0.405 | CW27: $27.936m new − $27.531m eliminated (424B3).
B28: Acquisitions, FX & workday effects % (derived = y/y − organic) | C28: =IF(AND(ISNUMBER(C26),ISNUMBER(C27)),C26-C27,"") | D28: =IF(AND(ISNUMBER(D26),ISNUMBER(D27)),D26-D27,"") | E28: =IF(AND(ISNUMBER(E26),ISNUMBER(E27)),E26-E27,"") | F28: =IF(AND(ISNUMBER(F26),ISNUMBER(F27)),F26-F27,"") | G28: =IF(AND(ISNUMBER(G26),ISNUMBER(G27)),G26-G27,"") | H28: =IF(AND(ISNUMBER(H26),ISNUMBER(H27)),H26-H27,"") | I28: =IF(AND(ISNUMBER(I26),ISNUMBER(I27)),I26-I27,"") | J28: =IF(AND(ISNUMBER(J26),ISNUMBER(J27)),J26-J27,"") | ... CB28: =IF(AND(ISNUMBER(CB26),ISNUMBER(CB27)),CB26-CB27,"") | CS28: PPA intangible amortization yrs 1–3 ($m p.a.) | CU28: 98.257 | CW28: Customer relationships $1,241m/15y + trade names $50m/3y.
B29: Gross margin (GAAP) | T29: 36.655 | U29: 38.396 | V29: 37.584 | W29: 39.704 | X29: 152.339 | Y29: 42.111 | Z29: 52.027 | AA29: 50.241 | AB29: 52.631 | AC29: 197.01 | AD29: 57.126 | AE29: 57.545 | AF29: 55.681 | AG29: 59.814 | AH29: 230.166 | AI29: 66.775 | AJ29: 65.26 | AK29: 64.348 | AL29: 69.402 | AM29: 265.785 | AN29: 73.485 | AO29: 73.67 | AP29: 71.89 | AQ29: 78.029 | AR29: 297.074 | AS29: 84.287 | AT29: 82.074 | AU29: 81.91 | AV29: 90.389 | AW29: 338.661 | AX29: 82.104 | AY29: 83.597 | AZ29: 86.341 | BA29: 80.294 | BB29: 332.336 | BC29: 89.275 | BD29: 88.034 | BE29: 94.204 | BF29: 100.68 | BG29: 372.193 | BH29: 116.137 | BI29: 119.153 | BJ29: 119.408 | BK29: 127.39 | BL29: 482.088 | BM29: 145.776 | BN29: 145.316 | BO29: 147.732 | BP29: 153.832 | BQ29: 592.656 | BR29: 168.803 | BS29: 171.485 | BT29: 172.133 | BU29: 184.189 | BV29: 696.61 | BW29: 190.168 | BX29: 197.602 | BY29: 201.647 | BZ29: 213.066 | CA29: 802.483 | CB29: 223.817 | CC29: =CC25*CC31 -> 221.06929 | CD29: =CD25*CD31 -> 225.60744 | CE29: =CE25*CE31 -> 238.37449 | CF29: =SUM(CB29,CC29,CD29,CE29) -> 908.86821 | CG29: =CG25*CG31 -> 1030.5003 | CH29: =CH25*CH31 -> 1149.7515 | CI29: =CI25*CI31 -> 1271.2124 | CJ29: =CJ25*CJ31 -> 1390.3345 | CM29: =IFERROR((CJ29/CA29)^(1/5)-1,"n/m") -> 0.11618632 | CN29: =IFERROR((CA29/BB29)^(1/5)-1,"n/m") -> 0.19281115 | CO29: =IFERROR((CA29/AC29)^(1/10)-1,"n/m") -> 0.1507865 | CP29: =IFERROR((CA29/C29)^(1/20)-1,"n/m") -> n/m | CS29: PPA intangible amortization yr 4+ ($m p.a.) | CU29: 82.733333 | CW29: Customer relationships only.
B30: Gross margin % before outlook calibration (Q2–Q4/27E helper) | CC30: =BX31+($CB$31-$BW$31) -> 0.58521128 | CD30: =BY31+($CB$31-$BW$31) -> 0.58924468 | CE30: =BZ31+($CB$31-$BW$31) -> 0.58660736 | CK30: Prior-year quarter margin + (Q1/27 − Q1/26 margin drift). | CS30: UniFirst standalone gross margin (Cintas presentation) | CU30: 0.318 | CW30: LTM cost of revenues ex-D&A 63.3% + ~85% of D&A in cost of sales.
B31: Gross margin % | C31: =IF(AND(ISNUMBER(C29),ISNUMBER(C25)),IFERROR(C29/C25,""),"") | D31: =IF(AND(ISNUMBER(D29),ISNUMBER(D25)),IFERROR(D29/D25,""),"") | E31: =IF(AND(ISNUMBER(E29),ISNUMBER(E25)),IFERROR(E29/E25,""),"") | F31: =IF(AND(ISNUMBER(F29),ISNUMBER(F25)),IFERROR(F29/F25,""),"") | G31: =IF(AND(ISNUMBER(G29),ISNUMBER(G25)),IFERROR(G29/G25,""),"") | H31: =IF(AND(ISNUMBER(H29),ISNUMBER(H25)),IFERROR(H29/H25,""),"") | I31: =IF(AND(ISNUMBER(I29),ISNUMBER(I25)),IFERROR(I29/I25,""),"") | J31: =IF(AND(ISNUMBER(J29),ISNUMBER(J25)),IFERROR(J29/J25,""),"") | ... CB31: =IF(AND(ISNUMBER(CB29),ISNUMBER(CB25)),IFERROR(CB29/CB25,""),"") -> 0.57608033 | CC31: =CC30+CC120 -> 0.5727087 | CD31: =CD30+CD120 -> 0.57674209 | CE31: =CE30+CE120 -> 0.57410477 | CF31: =IF(AND(ISNUMBER(CF29),ISNUMBER(CF25)),IFERROR(CF29/CF25,""),"") -> 0.57490197 | CG31: =CHOOSE(MATCH($CK$2,{"Bull","Base","Bear"},0),$CT$100,$CU$100,$CV$100) -> 0.582 | CH31: =CHOOSE(MATCH($CK$2,{"Bull","Base","Bear"},0),$CT$101,$CU$101,$CV$101) -> 0.585 | CI31: =CHOOSE(MATCH($CK$2,{"Bull","Base","Bear"},0),$CT$102,$CU$102,$CV$102) -> 0.588 | CJ31: =CHOOSE(MATCH($CK$2,{"Bull","Base","Bear"},0),$CT$103,$CU$103,$CV$103) -> 0.59 | CK31: Q2–Q4/27E: helper + uniform margin calibration Δ (solved to the FY27 adjusted EPS guidance). FY28E+: scenario lever FAS_GM (level). | CS31: UniFirst standalone S&A % of revenue | CU31: 0.25 | CW31: LTM SG&A ex merger costs 24.3% + non-production D&A.
B32: Selling & administrative expenses (segment) | T32: 27.508 | U32: 26.619 | V32: 26.286 | W32: 26.813 | X32: 107.226 | Y32: 33.519 | Z32: 37.18 | AA32: 37.607 | AB32: 39.197 | AC32: 147.503 | AD32: 45.615 | AE32: 42.766 | AF32: 43.446 | AG32: 45.551 | AH32: 177.378 | AI32: 47.364 | AJ32: 47.285 | AK32: 47.643 | AL32: 48.275 | AM32: 190.567 | AN32: 51.502 | AO32: 52.342 | AP32: 50.268 | AQ32: 52.878 | AR32: 206.99 | AS32: 59.518 | AT32: 57.434 | AU32: 57.218 | AV32: 57.599 | AW32: 231.769 | AX32: 63.577 | AY32: 62.091 | AZ32: 60.521 | BA32: 64.964 | BB32: 251.153 | BC32: 63.547 | BD32: 65.957 | BE32: 67.9 | BF32: 68.026 | BG32: 265.43 | BH32: 75.291 | BI32: 73.658 | BJ32: 72.137 | BK32: 80.312 | BL32: 301.398 | BM32: 86.196 | BN32: 86.785 | BO32: 90.015 | BP32: 90.507 | BQ32: 353.503 | BR32: 97.515 | BS32: 96.262 | BT32: 100.6 | BU32: 107.505 | BV32: 401.882 | BW32: 109.841 | BX32: 110.598 | BY32: 114.306 | BZ32: 114.475 | CA32: 449.084 | CB32: 124.275 | CC32: =CC25*CC33 -> 121.5186 | CD32: =CD25*CD33 -> 125.65763 | CE32: =CE25*CE33 -> 125.64756 | CF32: =SUM(CB32,CC32,CD32,CE32) -> 497.0988 | CG32: =CG25*CG33 -> 553.19796 | CH32: =CH25*CH33 -> 610.11896 | CI32: =CI25*CI33 -> 666.807 | CJ32: =CJ25*CJ33 -> 722.10664 | CS32: UniFirst standalone D&A % of revenue | CU32: 0.05 | CW32: LTM D&A 5.7% less acquired-intangible amortization (~0.7%).
B33: S&A % of revenues | C33: =IF(AND(ISNUMBER(C32),ISNUMBER(C25)),IFERROR(C32/C25,""),"") | D33: =IF(AND(ISNUMBER(D32),ISNUMBER(D25)),IFERROR(D32/D25,""),"") | E33: =IF(AND(ISNUMBER(E32),ISNUMBER(E25)),IFERROR(E32/E25,""),"") | F33: =IF(AND(ISNUMBER(F32),ISNUMBER(F25)),IFERROR(F32/F25,""),"") | G33: =IF(AND(ISNUMBER(G32),ISNUMBER(G25)),IFERROR(G32/G25,""),"") | H33: =IF(AND(ISNUMBER(H32),ISNUMBER(H25)),IFERROR(H32/H25,""),"") | I33: =IF(AND(ISNUMBER(I32),ISNUMBER(I25)),IFERROR(I32/I25,""),"") | J33: =IF(AND(ISNUMBER(J32),ISNUMBER(J25)),IFERROR(J32/J25,""),"") | ... CB33: =IF(AND(ISNUMBER(CB32),ISNUMBER(CB25)),IFERROR(CB32/CB25,""),"") -> 0.31987017 | CC33: =BX33+($CB$33-$BW$33) -> 0.31480972 | CD33: =BY33+($CB$33-$BW$33) -> 0.32123075 | CE33: =BZ33+($CB$33-$BW$33) -> 0.30261152 | CF33: =IF(AND(ISNUMBER(CF32),ISNUMBER(CF25)),IFERROR(CF32/CF25,""),"") -> 0.31443841 | CG33: =$CF$33+(CG124-$CF$123) -> 0.31243194 | CH33: =$CF$33+(CH124-$CF$123) -> 0.31043194 | CI33: =$CF$33+(CI124-$CF$123) -> 0.30843194 | CJ33: =$CF$33+(CJ124-$CF$123) -> 0.30643194 | CK33: Q2–Q4/27E: prior-year quarter + Q1 drift. FY28E+: FY27E segment ratio + Δ of the consolidated legacy S&A lever SA_pct vs FY27E. | CS33: UniFirst revenue mapped to UR&FS line | CU33: 0.95 | CW33: U&F Service Solutions + Specialty Garments ~95% of UNF revenue.
B34: Segment operating income (before special items) | C34: =IF(AND(ISNUMBER(C29),ISNUMBER(C32)),C29-C32,"") | D34: =IF(AND(ISNUMBER(D29),ISNUMBER(D32)),D29-D32,"") | E34: =IF(AND(ISNUMBER(E29),ISNUMBER(E32)),E29-E32,"") | F34: =IF(AND(ISNUMBER(F29),ISNUMBER(F32)),F29-F32,"") | G34: =IF(AND(ISNUMBER(G29),ISNUMBER(G32)),G29-G32,"") | H34: =IF(AND(ISNUMBER(H29),ISNUMBER(H32)),H29-H32,"") | I34: =IF(AND(ISNUMBER(I29),ISNUMBER(I32)),I29-I32,"") | J34: =IF(AND(ISNUMBER(J29),ISNUMBER(J32)),J29-J32,"") | ... CB34: =IF(AND(ISNUMBER(CB29),ISNUMBER(CB32)),CB29-CB32,"") -> 99.542 | CC34: =CC29-CC32 -> 99.550685 | CD34: =CD29-CD32 -> 99.949803 | CE34: =CE29-CE32 -> 112.72692 | CF34: =CF29-CF32 -> 411.76941 | CG34: =CG29-CG32 -> 477.30235 | CH34: =CH29-CH32 -> 539.63254 | CI34: =CI29-CI32 -> 604.40543 | CJ34: =CJ29-CJ32 -> 668.22791 | CM34: =IFERROR((CJ34/CA34)^(1/5)-1,"n/m") -> 0.13587845 | CN34: =IFERROR((CA34/BB34)^(1/5)-1,"n/m") -> 0.34202326 | CO34: =IFERROR((CA34/AC34)^(1/10)-1,"n/m") -> 0.21719419 | CP34: =IFERROR((CA34/C34)^(1/20)-1,"n/m") -> n/m | CS34: Pre-close transaction costs per quarter ($m) | CU34: 15 | CW34: Q1/27 $14.4m; Q4/26 $14.0m.
B35: Segment operating margin % | C35: =IF(AND(ISNUMBER(C34),ISNUMBER(C25)),IFERROR(C34/C25,""),"") | D35: =IF(AND(ISNUMBER(D34),ISNUMBER(D25)),IFERROR(D34/D25,""),"") | E35: =IF(AND(ISNUMBER(E34),ISNUMBER(E25)),IFERROR(E34/E25,""),"") | F35: =IF(AND(ISNUMBER(F34),ISNUMBER(F25)),IFERROR(F34/F25,""),"") | G35: =IF(AND(ISNUMBER(G34),ISNUMBER(G25)),IFERROR(G34/G25,""),"") | H35: =IF(AND(ISNUMBER(H34),ISNUMBER(H25)),IFERROR(H34/H25,""),"") | I35: =IF(AND(ISNUMBER(I34),ISNUMBER(I25)),IFERROR(I34/I25,""),"") | J35: =IF(AND(ISNUMBER(J34),ISNUMBER(J25)),IFERROR(J34/J25,""),"") | ... CJ35: =IF(AND(ISNUMBER(CJ34),ISNUMBER(CJ25)),IFERROR(CJ34/CJ25,""),"") -> 0.28356806 | CS35: Costs at closing ($m): transaction + retention | CU35: 72.7 | CW35: Cintas transaction costs $34.0m + retention bonuses $38.7m (424B3).
B36: Memo: segment operating income / income before taxes as reported (incl. segment special items) | T36: 9.147 | U36: 11.777 | V36: 11.298 | W36: 12.891 | X36: 45.113 | Y36: 8.592 | Z36: 14.847 | AA36: 12.634 | AB36: 13.434 | AC36: 49.507 | AD36: 11.511 | AE36: 14.779 | AF36: 12.235 | AG36: 14.263 | AH36: 52.788 | AI36: 19.411 | AJ36: 17.975 | AK36: 16.705 | AL36: 21.127 | AM36: 75.218 | AN36: 21.983 | AO36: 21.328 | AP36: 21.622 | AQ36: 25.151 | AR36: 90.084 | AS36: 24.769 | AT36: 24.64 | AU36: 24.692 | AV36: 32.79 | AW36: 106.892 | AX36: 18.527 | AY36: 21.506 | AZ36: 25.82 | BA36: 15.33 | BB36: 81.183 | BC36: 25.728 | BD36: 22.077 | BE36: 26.304 | BF36: 32.654 | BG36: 106.763 | BH36: 40.846 | BI36: 45.495 | BJ36: 47.271 | BK36: 47.078 | BL36: 180.69 | BM36: 59.58 | BN36: 58.531 | BO36: 57.717 | BP36: 63.325 | BQ36: 239.153 | BR36: 71.288 | BS36: 75.223 | BT36: 71.533 | BU36: 76.684 | BV36: 294.728 | BW36: 80.327 | BX36: 87.004 | BY36: 87.341 | BZ36: 98.591 | CA36: 353.399 | CB36: 99.542 | CS36: Integration costs to achieve synergies ($m, total) | CU36: 350 | CW36: Not disclosed; "proportional to G&K" (~$138m for a $2.2bn deal) → ~$350m.
CS37: … phasing FY27E | CU37: 0.15
B38: All Other — Fire Protection Services + Uniform Direct Sale (from FY2016; FY2015 recast) | CK38: ALL OTHER (FIRE + UNIFORM DIRECT SALE) — modelling logic | CS38: … phasing FY28E | CU38: 0.45
B39: Revenues | T39: 148.455 | U39: 149.633 | V39: 145.975 | W39: 166.387 | X39: 610.45 | Y39: 160.994 | Z39: 160.938 | AA39: 160.454 | AB39: 183.488 | AC39: 665.874 | AD39: 169.695 | AE39: 166.561 | AF39: 163.498 | AG39: 175.914 | AH39: 612.658 | AI39: 159.137 | AJ39: 159.313 | AK39: 167.295 | AL39: 179.057 | AM39: 664.802 | AN39: 169.62 | AO39: 174.142 | AP39: 174.838 | AQ39: 201.803 | AR39: 720.403 | AS39: 184.522 | AT39: 204.105 | AU39: 192.086 | AV39: 152.344 | AW39: 733.057 | AX39: 147.683 | AY39: 152.141 | AZ39: 160.717 | BA39: 181.876 | BB39: 642.417 | BC39: 189.658 | BD39: 184.85 | BE39: 194.264 | BF39: 226.249 | BG39: 795.021 | BH39: 234.521 | BI39: 228.897 | BJ39: 242.216 | BK39: 261.509 | BL39: 967.143 | BM39: 254.812 | BN39: 260.234 | BO39: 266.929 | BP39: 282.107 | BQ39: 1064.082 | BR39: 275.181 | BS39: 272.006 | BT39: 286.256 | BU39: 312.575 | BV39: 1146.018 | BW39: 292.399 | BX39: 302.352 | BY39: 317.168 | BZ39: 339.365 | CA39: 1251.284 | CB39: 330.728 | CC39: =BX39*(1+CC40) -> 331.99042 | CD39: =BY39*(1+CD40) -> 348.25878 | CE39: =BZ39*(1+CE40) -> 372.63166 | CF39: =SUM(CB39,CC39,CD39,CE39) -> 1383.6089 | CG39: =CF39*(1+CG40) -> 1508.1337 | CH39: =CG39*(1+CH40) -> 1628.7843 | CI39: =CH39*(1+CI40) -> 1759.0871 | CJ39: =CI39*(1+CJ40) -> 1882.2232 | CK39: Q2–Q4/27E: prior-year quarter × (1 + Q1/27 y/y growth ex-workday effect + revenue-outlook calibration Δ). FY28E+: prior year × (1 + scenario organic growth OTH_org); bolt-on M&A modelled separately (Future acquisitions block). | CM39: =IFERROR((CJ39/CA39)^(1/5)-1,"n/m") -> 0.085083216 | CN39: =IFERROR((CA39/BB39)^(1/5)-1,"n/m") -> 0.14263566 | CO39: =IFERROR((CA39/AC39)^(1/10)-1,"n/m") -> 0.065114712 | CP39: =IFERROR((CA39/C39)^(1/20)-1,"n/m") -> n/m | CS39: … phasing FY29E | CU39: 0.3
B40: Revenues y/y % | D40: =IF(AND(ISNUMBER(D39),ISNUMBER(C39)),IFERROR(D39/C39-1,""),"") | E40: =IF(AND(ISNUMBER(E39),ISNUMBER(D39)),IFERROR(E39/D39-1,""),"") | F40: =IF(AND(ISNUMBER(F39),ISNUMBER(E39)),IFERROR(F39/E39-1,""),"") | G40: =IF(AND(ISNUMBER(G39),ISNUMBER(F39)),IFERROR(G39/F39-1,""),"") | H40: =IF(AND(ISNUMBER(H39),ISNUMBER(G39)),IFERROR(H39/G39-1,""),"") | I40: =IF(AND(ISNUMBER(I39),ISNUMBER(H39)),IFERROR(I39/H39-1,""),"") | N40: =IF(AND(ISNUMBER(N39),ISNUMBER(I39)),IFERROR(N39/I39-1,""),"") | O40: =IF(AND(ISNUMBER(O39),ISNUMBER(J39)),IFERROR(O39/J39-1,""),"") | P40: =IF(AND(ISNUMBER(P39),ISNUMBER(K39)),IFERROR(P39/K39-1,""),"") | Q40: =IF(AND(ISNUMBER(Q39),ISNUMBER(L39)),IFERROR(Q39/L39-1,""),"") | R40: =IF(AND(ISNUMBER(R39),ISNUMBER(M39)),IFERROR(R39/M39-1,""),"") | S40: =IF(AND(ISNUMBER(S39),ISNUMBER(N39)),IFERROR(S39/N39-1,""),"") | T40: =IF(AND(ISNUMBER(T39),ISNUMBER(O39)),IFERROR(T39/O39-1,""),"") | U40: =IF(AND(ISNUMBER(U39),ISNUMBER(P39)),IFERROR(U39/P39-1,""),"") | ... CB40: =IF(AND(ISNUMBER(CB39),ISNUMBER(BW39)),IFERROR(CB39/BW39-1,""),"") -> 0.13108458 | CC40: =$CB$40-$CB$109+CC114 -> 0.098026204 | CD40: =$CB$40-$CB$109+CD114 -> 0.098026204 | CE40: =$CB$40-$CB$109+CE114 -> 0.098026204 | CF40: =IFERROR(CF39/CA39-1,"") -> 0.10575126 | CG40: =CHOOSE(MATCH($CK$2,{"Bull","Base","Bear"},0),$CT$88,$CU$88,$CV$88) -> 0.09 | CH40: =CHOOSE(MATCH($CK$2,{"Bull","Base","Bear"},0),$CT$89,$CU$89,$CV$89) -> 0.08 | CI40: =CHOOSE(MATCH($CK$2,{"Bull","Base","Bear"},0),$CT$90,$CU$90,$CV$90) -> 0.08 | CJ40: =CHOOSE(MATCH($CK$2,{"Bull","Base","Bear"},0),$CT$91,$CU$91,$CV$91) -> 0.07 | CK40: Q2–Q4/27E: Q1/27 y/y less the Q1 extra-workday effect (row "Workday effect") + calibration Δ (Group block). FY28E+: scenario lever. | CS40: … phasing FY30E | CU40: 0.1
...

Sheet Bull-Base-Bear
B2: Cintas Corporation (CTAS) — Bull / Base / Bear Case P&L Summary | J2: Share price ($): | K2: =Model!$CF$380 -> 198.95
B3: Adjusted figures (company definition: adjusted diluted EPS excl. acquisition transaction & integration costs; model Adjusted EBITDA) · USD millions · Fiscal years end 31-May · Live panel linked to Model — toggle scenario via Model!CK2. Bull and Bear panels are value snapshots generated from the Model with the switch set to each case. UniFirst consolidated from an assumed 31-Dec-2026 close (toggle in the Model scenario table). | J3: As of: | K3: =TODAY() -> 46301
B5: Scenario: | C5: =Model!$CK$2 -> Base | N5: Scenario: | O5: Bull | P5: Snapshot (values) — Model run with switch = Bull | Z5: Scenario: | AA5: Bear | AB5: Snapshot (values) — Model run with switch = Bear
B7: (USDm, except EPS and shares) | C7: FY2026A | D7: FY2027E | E7: FY2028E | F7: FY2029E | G7: FY2030E | H7: FY2031E | I7: 26-'31 CAGR | J7: LT Hist Avg | K7: LT Hist Min | L7: LT Hist Max | N7: (USDm, except EPS and shares) | O7: FY2026A | P7: FY2027E | Q7: FY2028E | R7: FY2029E | S7: FY2030E | T7: FY2031E | U7: 26-'31 CAGR | V7: LT Hist Avg | W7: LT Hist Min | X7: LT Hist Max | Z7: (USDm, except EPS and shares) | AA7: FY2026A | AB7: FY2027E | AC7: FY2028E | AD7: FY2029E | AE7: FY2030E | AF7: FY2031E | AG7: 26-'31 CAGR | AH7: LT Hist Avg | AI7: LT Hist Min | AJ7: LT Hist Max
B9: Revenues | C9: =Model!CA132 -> 11264.761 | D9: =Model!CF132 -> 13279.186 | E9: =Model!CG132 -> 15890.893 | F9: =Model!CH132 -> 17114.142 | G9: =Model!CI132 -> 18430.858 | H9: =Model!CJ132 -> 19766.838 | I9: =IFERROR((H9/C9)^(1/5)-1,"n/m") -> 0.11903338 | N9: Revenues | O9: 11264.761 | P9: 13354.756 | Q9: 16298.01 | R9: 17933.15 | S9: 19718.624 | T9: 21580.14 | U9: 0.13884981 | Z9: Revenues | AA9: 11264.761 | AB9: 13193.234 | AC9: 15361.134 | AD9: 16077.674 | AE9: 16836.295 | AF9: 17566.473 | AG9: 0.092930426
B10: Revenues y/y % | D10: =IFERROR(D9/C9-1,"") -> 0.17882533 | E10: =IFERROR(E9/D9-1,"") -> 0.19667681 | F10: =IFERROR(F9/E9-1,"") -> 0.076977967 | G10: =IFERROR(G9/F9-1,"") -> 0.076937312 | H10: =IFERROR(H9/G9-1,"") -> 0.072486013 | N10: Revenues y/y % | P10: 0.18553392 | Q10: 0.22038995 | R10: 0.10032755 | S10: 0.099562786 | T10: 0.094403931 | Z10: Revenues y/y % | AB10: 0.17119524 | AC10: 0.16431907 | AD10: 0.046646265 | AE10: 0.047184728 | AF10: 0.043369283
B11: Organic revenue growth % (legacy Cintas; FY2027E ex-workday) | C11: =Model!CA214 -> 0.083 | D11: =Model!CF214 -> 0.080064896 | E11: =Model!CG214 -> 0.078740186 | F11: =Model!CH214 -> 0.072766807 | G11: =Model!CI214 -> 0.071597399 | H11: =Model!CJ214 -> 0.065445203 | N11: Aggregates shipments y/y % | O11: 0.083 | P11: 0.08539124 | Q11: 0.09624695 | R11: 0.090442418 | S11: 0.089413151 | T11: 0.083379498 | Z11: Aggregates shipments y/y % | AA11: 0.083 | AB11: 0.074738551 | AC11: 0.055018388 | AD11: 0.048883585 | AE11: 0.047598508 | AF11: 0.041368417
B12: Adjusted EBITDA (model; excl. transaction & integration costs) | C12: =Model!CA185 -> 3134.494 | D12: =Model!CF185 -> 3540.5833 | E12: =Model!CG185 -> 4235.7965 | F12: =Model!CH185 -> 4747.3834 | G12: =Model!CI185 -> 5290.6216 | H12: =Model!CJ185 -> 5787.3754 | I12: =IFERROR((H12/C12)^(1/5)-1,"n/m") -> 0.13047989 | N12: Adjusted EBITDA (continuing operations) | O12: 3134.494 | P12: 3583.4274 | Q12: 4551.225 | R12: 5185.9633 | S12: 5871.0407 | T12: 6490.211 | U12: 0.15669344 | Z12: Adjusted EBITDA (continuing operations) | AA12: 3134.494 | AB12: 3480.8979 | AC12: 3792.5525 | AD12: 4161.1723 | AE12: 4544.2724 | AF12: 4865.7725 | AG12: 0.091935213
B13: Adjusted EBITDA margin % | C13: =IFERROR(C12/C9,"") -> 0.27825659 | D13: =IFERROR(D12/D9,"") -> 0.26662654 | E13: =IFERROR(E12/E9,"") -> 0.26655496 | F13: =IFERROR(F12/F9,"") -> 0.27739535 | G13: =IFERROR(G12/G9,"") -> 0.28705238 | H13: =IFERROR(H12/H9,"") -> 0.29278206 | J13: =IFERROR(AVERAGE(Model!C186,Model!D186,Model!E186,Model!F186,Model!G186,Model!H186,Model!I186,Model!N186,Model!S186,Model!X186,Model!AC186,Model!AH186,Model!AM186,Model!AR186,Model!AW186,Model!BB186,Model!BG186,Model!BL186,Model!BQ186,Model!BV186,Model!CA186),"") -> 0.21130165 | K13: =IFERROR(MIN(Model!C186,Model!D186,Model!E186,Model!F186,Model!G186,Model!H186,Model!I186,Model!N186,Model!S186,Model!X186,Model!AC186,Model!AH186,Model!AM186,Model!AR186,Model!AW186,Model!BB186,Model!BG186,Model!BL186,Model!BQ186,Model!BV186,Model!CA186),"") -> 0.16633757 | L13: =IFERROR(MAX(Model!C186,Model!D186,Model!E186,Model!F186,Model!G186,Model!H186,Model!I186,Model!N186,Model!S186,Model!X186,Model!AC186,Model!AH186,Model!AM186,Model!AR186,Model!AW186,Model!BB186,Model!BG186,Model!BL186,Model!BQ186,Model!BV186,Model!CA186),"") -> 0.27825659 | N13: Adjusted EBITDA margin % | O13: 0.27825659 | P13: 0.26832593 | Q13: 0.27925035 | R13: 0.28918307 | S13: 0.29774089 | T13: 0.30074926 | V13: 0.21130165 | W13: 0.16633757 | X13: 0.27825659 | Z13: Adjusted EBITDA margin % | AA13: 0.27825659 | AB13: 0.26383962 | AC13: 0.24689273 | AD13: 0.25881681 | AE13: 0.26990929 | AF13: 0.27699201 | AH13: 0.21130165 | AI13: 0.16633757 | AJ13: 0.27825659
B15: Operating Income (GAAP) | C15: =Model!CA143 -> 2606.512 | D15: =Model!CF143 -> 2760.6125 | E15: =Model!CG143 -> 3275.4148 | F15: =Model!CH143 -> 3781.3271 | G15: =Model!CI143 -> 4347.4089 | H15: =Model!CJ143 -> 4815.1564 | I15: =IFERROR((H15/C15)^(1/5)-1,"n/m") -> 0.130603 | N15: Earnings from Operations (GAAP) | O15: 2606.512 | P15: 2800.1433 | Q15: 3571.1942 | R15: 4179.3287 | S15: 4864.1748 | T15: 5429.1156 | U15: 0.1580675 | Z15: Earnings from Operations (GAAP) | AA15: 2606.512 | AB15: 2704.7593 | AC15: 2857.438 | AD15: 3245.6335 | AE15: 3678.8189 | AF15: 4000.4025 | AG15: 0.089453734
B16: Operating income y/y % | D16: =IFERROR(D15/C15-1,"") -> 0.059121329 | E16: =IFERROR(E15/D15-1,"") -> 0.18648119 | F16: =IFERROR(F15/E15-1,"") -> 0.15445748 | G16: =IFERROR(G15/F15-1,"") -> 0.14970453 | H16: =IFERROR(H15/G15-1,"") -> 0.10759225 | N16: Earnings from operations y/y % | P16: 0.07428751 | Q16: 0.27536123 | R16: 0.17028885 | S16: 0.16386509 | T16: 0.11614319 | Z16: Earnings from operations y/y % | AB16: 0.037693021 | AC16: 0.056448177 | AD16: 0.13585436 | AE16: 0.13346714 | AF16: 0.087414901
B17: Operating margin (GAAP) % | C17: =IFERROR(C15/C9,"") -> 0.23138636 | D17: =IFERROR(D15/D9,"") -> 0.20789019 | E17: =IFERROR(E15/E9,"") -> 0.20611898 | F17: =IFERROR(F15/F9,"") -> 0.22094751 | G17: =IFERROR(G15/G9,"") -> 0.23587664 | H17: =IFERROR(H15/H9,"") -> 0.24359771 | J17: =IFERROR(AVERAGE(Model!C223,Model!D223,Model!E223,Model!F223,Model!G223,Model!H223,Model!I223,Model!N223,Model!S223,Model!X223,Model!AC223,Model!AH223,Model!AM223,Model!AR223,Model!AW223,Model!BB223,Model!BG223,Model!BL223,Model!BQ223,Model!BV223,Model!CA223),"") -> 0.16172099 | K17: =IFERROR(MIN(Model!C223,Model!D223,Model!E223,Model!F223,Model!G223,Model!H223,Model!I223,Model!N223,Model!S223,Model!X223,Model!AC223,Model!AH223,Model!AM223,Model!AR223,Model!AW223,Model!BB223,Model!BG223,Model!BL223,Model!BQ223,Model!BV223,Model!CA223),"") -> 0.10837063 | L17: =IFERROR(MAX(Model!C223,Model!D223,Model!E223,Model!F223,Model!G223,Model!H223,Model!I223,Model!N223,Model!S223,Model!X223,Model!AC223,Model!AH223,Model!AM223,Model!AR223,Model!AW223,Model!BB223,Model!BG223,Model!BL223,Model!BQ223,Model!BV223,Model!CA223),"") -> 0.23138636 | N17: Operating margin (GAAP) % | O17: 0.23138636 | P17: 0.20967386 | Q17: 0.21911842 | R17: 0.23305046 | S17: 0.24667922 | T17: 0.25157926 | V17: 0.16172099 | W17: 0.10837063 | X17: 0.23138636 | Z17: Operating margin (GAAP) % | AA17: 0.23138636 | AB17: 0.20501109 | AC17: 0.18601738 | AD17: 0.20187208 | AE17: 0.21850526 | AF17: 0.22772941 | AH17: 0.16172099 | AI17: 0.10837063 | AJ17: 0.23138636
B19: Adjusted Income from Continuing Operations (company definition) | C19: =Model!CA204 -> 2006.6128 | D19: =Model!CF204 -> 2198.8669 | E19: =Model!CG204 -> 2534.0651 | F19: =Model!CH204 -> 2863.4046 | G19: =Model!CI204 -> 3235.3756 | H19: =Model!CJ204 -> 3554.506 | I19: =IFERROR((H19/C19)^(1/5)-1,"n/m") -> 0.12114848 | N19: Adjusted Net Earnings (continuing ops, attributable to MLM) | O19: 2006.6128 | P19: 2230.3335 | Q19: 2768.1088 | R19: 3082.9111 | S19: 3531.9508 | T19: 3909.3837 | U19: 0.14269136 | Z19: Adjusted Net Earnings (continuing ops, attributable to MLM) | AA19: 2006.6128 | AB19: 2154.4078 | AC19: 2203.2598 | AD19: 2499.9927 | AE19: 2792.5323 | AF19: 3012.3888 | AG19: 0.084649668
B21: FDSO (m) | C21: =Model!CA161 -> 406.197 | D21: =Model!CF161 -> 408.65292 | E21: =Model!CG161 -> 412.24106 | F21: =Model!CH161 -> 404.10611 | G21: =Model!CI161 -> 396.46197 | H21: =Model!CJ161 -> 388.66912 | I21: =IFERROR((H21/C21)^(1/5)-1,"n/m") -> -0.0087831742 | N21: FDSO (m) | O21: 406.197 | P21: 408.65292 | Q21: 406.01869 | R21: 390.64137 | S21: 380.77091 | T21: 370.63671 | U21: -0.018156333 | Z21: FDSO (m) | AA21: 406.197 | AB21: 408.65292 | AC21: 417.28008 | AD21: 416.05183 | AE21: 411.48676 | AF21: 406.20651 | AG21: 4.6800254e-06
B23: Adjusted EPS — Diluted ($) | C23: =Model!CA206 -> 4.9399991 | D23: =Model!CF206 -> 5.380769 | E23: =Model!CG206 -> 6.1470469 | F23: =Model!CH206 -> 7.0857742 | G23: =Model!CI206 -> 8.1606204 | H23: =Model!CJ206 -> 9.1453264 | I23: =IFERROR((H23/C23)^(1/5)-1,"n/m") -> 0.13108298 | N23: Adjusted EPS — Diluted ($) | O23: 4.9399991 | P23: 5.4577697 | Q23: 6.8176881 | R23: 7.8919215 | S23: 9.2757895 | T23: 10.547751 | U23: 0.1638221 | Z23: Adjusted EPS — Diluted ($) | AA23: 4.9399991 | AB23: 5.2719747 | AC23: 5.2800504 | AD23: 6.0088492 | AE23: 6.7864451 | AF23: 7.4159048 | AG23: 0.084644592
B24: EPS y/y % | D24: =IFERROR(D23/C23-1,"") -> 0.089224684 | E24: =IFERROR(E23/D23-1,"") -> 0.14241047 | F24: =IFERROR(F23/E23-1,"") -> 0.15271192 | G24: =IFERROR(G23/F23-1,"") -> 0.15169073 | H24: =IFERROR(H23/G23-1,"") -> 0.12066558 | N24: EPS y/y % | P24: 0.10481186 | Q24: 0.2491711 | R24: 0.15756564 | S24: 0.17535247 | T24: 0.13712703 | Z24: EPS y/y % | AB24: 0.067201546 | AC24: 0.0015318177 | AD24: 0.13802875 | AE24: 0.12940846 | AF24: 0.092752493
B26: P / E (x) — assumed (adjusted EPS; CTAS 5-yr range ~30–50x) | F26: 35 | G26: 35 | H26: 35 | N26: P / E (x) — assumed (adjusted EPS) | R26: 35 | S26: 35 | T26: 35 | Z26: P / E (x) — assumed (adjusted EPS) | AD26: 35 | AE26: 35 | AF26: 35
B27: Price Target ($) | F27: =F26*F23 -> 248.0021 | G27: =G26*G23 -> 285.62171 | H27: =H26*H23 -> 320.08642 | N27: Price Target ($) | R27: 276.21725 | S27: 324.65263 | T27: 369.17128 | Z27: Price Target ($) | AD27: 210.30972 | AE27: 237.52558 | AF27: 259.55667
B28: Upside / (Downside) vs current | F28: =IFERROR(F27/$K$2-1,"") -> 0.24655489 | G28: =IFERROR(G27/$K$2-1,"") -> 0.43564571 | H28: =IFERROR(H27/$K$2-1,"") -> 0.60887874 | N28: Upside / (Downside) vs current | R28: 0.38837524 | S28: 0.63183026 | T28: 0.8555983 | Z28: Upside / (Downside) vs current | AD28: 0.057098375 | AE28: 0.19389585 | AF28: 0.30463267
B29: IRR (to May-Y-1) | F29: =IFERROR((F27/$K$2)^(1/((DATE(2029-1,5,31)-$K$3)/365.25))-1,"") -> 0.14281109 | G29: =IFERROR((G27/$K$2)^(1/((DATE(2030-1,5,31)-$K$3)/365.25))-1,"") -> 0.14619304 | H29: =IFERROR((H27/$K$2)^(1/((DATE(2031-1,5,31)-$K$3)/365.25))-1,"") -> 0.13917023 | N29: IRR (to Dec-Y-1) | R29: 0.21988658 | S29: 0.20294967 | T29: 0.18458497 | Z29: IRR (to Dec-Y-1) | AD29: 0.03420639 | AE29: 0.069156586 | AF29: 0.075584347
B31: Free Cash Flow | C31: =Model!CA256 -> 1881.175 | D31: =Model!CF256 -> 2009.9481 | E31: =Model!CG256 -> 2397.711 | F31: =Model!CH256 -> 2757.8852 | G31: =Model!CI256 -> 3159.1046 | H31: =Model!CJ256 -> 3506.6834 | I31: =IFERROR((H31/C31)^(1/5)-1,"n/m") -> 0.13264411 | N31: Free Cash Flow | O31: 1881.175 | P31: 2023.6158 | Q31: 2588.0985 | R31: 2927.4937 | S31: 3401.5983 | T31: 3803.2115 | U31: 0.1511827 | Z31: Free Cash Flow | AA31: 1881.175 | AB31: 1988.1156 | AC31: 2125.8818 | AD31: 2458.9521 | AE31: 2784.0009 | AF31: 3035.2445 | AG31: 0.10040587
B32: FCF % | C32: =IFERROR(C31/C9,"") -> 0.16699644 | D32: =IFERROR(D31/D9,"") -> 0.1513608 | E32: =IFERROR(E31/E9,"") -> 0.15088585 | F32: =IFERROR(F31/F9,"") -> 0.16114657 | G32: =IFERROR(G31/G9,"") -> 0.17140301 | H32: =IFERROR(H31/H9,"") -> 0.17740235 | J32: =IFERROR(AVERAGE(Model!C260,Model!D260,Model!E260,Model!F260,Model!G260,Model!H260,Model!I260,Model!N260,Model!S260,Model!X260,Model!AC260,Model!AH260,Model!AM260,Model!AR260,Model!AW260,Model!BB260,Model!BG260,Model!BL260,Model!BQ260,Model!BV260,Model!CA260),"") -> 0.11193542 | K32: =IFERROR(MIN(Model!C260,Model!D260,Model!E260,Model!F260,Model!G260,Model!H260,Model!I260,Model!N260,Model!S260,Model!X260,Model!AC260,Model!AH260,Model!AM260,Model!AR260,Model!AW260,Model!BB260,Model!BG260,Model!BL260,Model!BQ260,Model!BV260,Model!CA260),"") -> 0.03882614 | L32: =IFERROR(MAX(Model!C260,Model!D260,Model!E260,Model!F260,Model!G260,Model!H260,Model!I260,Model!N260,Model!S260,Model!X260,Model!AC260,Model!AH260,Model!AM260,Model!AR260,Model!AW260,Model!BB260,Model!BG260,Model!BL260,Model!BQ260,Model!BV260,Model!CA260),"") -> 0.1740522 | N32: FCF % | O32: 0.16699644 | P32: 0.15152773 | Q32: 0.15879843 | R32: 0.16324482 | S32: 0.17250688 | T32: 0.17623665 | V32: 0.11193542 | W32: 0.03882614 | X32: 0.1740522 | Z32: FCF % | AA32: 0.16699644 | AB32: 0.15069205 | AC32: 0.13839354 | AD32: 0.15294203 | AE32: 0.1653571 | AF32: 0.17278623 | AH32: 0.11193542 | AI32: 0.03882614 | AJ32: 0.1740522
B33: FCF / share ($) | C33: =IFERROR(C31/C21,"") -> 4.6311888 | D33: =IFERROR(D31/D21,"") -> 4.9184725 | E33: =IFERROR(E31/E21,"") -> 5.8162837 | F33: =IFERROR(F31/F21,"") -> 6.8246561 | G33: =IFERROR(G31/G21,"") -> 7.9682413 | H33: =IFERROR(H31/H21,"") -> 9.0222845 | N33: FCF / share ($) | O33: 4.6311888 | P33: 4.9519182 | Q33: 6.3743335 | R33: 7.4940699 | S33: 8.933451 | T33: 10.261292 | Z33: FCF / share ($) | AA33: 4.6311888 | AB33: 4.8650468 | AC33: 5.0946162 | AD33: 5.9102062 | AE33: 6.7657122 | AF33: 7.4721711
B34: FCF Yield (on PT) | F34: =IFERROR(F33/F$27,"") -> 0.027518542 | G34: =IFERROR(G33/G$27,"") -> 0.027897884 | H34: =IFERROR(H33/H$27,"") -> 0.028187026 | N34: FCF Yield (on PT) | R34: 0.027131071 | S34: 0.027516952 | T34: 0.027795477 | Z34: FCF Yield (on PT) | AD34: 0.028102392 | AE34: 0.028484141 | AF34: 0.028788207
B35: Adjusted EBITDA — pro forma (FY2027E incl. UniFirst full year) | C35: =Model!CA194 -> 3134.494 | D35: =Model!CF194 -> 3717.3788 | E35: =Model!CG194 -> 4235.7965 | F35: =Model!CH194 -> 4747.3834 | G35: =Model!CI194 -> 5290.6216 | H35: =Model!CJ194 -> 5787.3754 | I35: =IFERROR((H35/C35)^(1/5)-1,"n/m") -> 0.13047989 | N35: Adjusted EBITDA — pro forma (2026E incl. LNA full year) | O35: 3134.494 | P35: 3762.7976 | Q35: 4551.225 | R35: 5185.9633 | S35: 5871.0407 | T35: 6490.211 | U35: 0.15669344 | Z35: Adjusted EBITDA — pro forma (2026E incl. LNA full year) | AA35: 3134.494 | AB35: 3653.4022 | AC35: 3792.5525 | AD35: 4161.1723 | AE35: 4544.2724 | AF35: 4865.7725 | AG35: 0.091935213
B36: Adjusted EBITDA (pro forma) % of revenues | C36: =IFERROR(C35/C9,"") -> 0.27825659 | D36: =IFERROR(D35/D9,"") -> 0.27994027 | E36: =IFERROR(E35/E9,"") -> 0.26655496 | F36: =IFERROR(F35/F9,"") -> 0.27739535 | G36: =IFERROR(G35/G9,"") -> 0.28705238 | H36: =IFERROR(H35/H9,"") -> 0.29278206 | J36: =IFERROR(AVERAGE(Model!C221,Model!D221,Model!E221,Model!F221,Model!G221,Model!H221,Model!I221,Model!N221,Model!S221,Model!X221,Model!AC221,Model!AH221,Model!AM221,Model!AR221,Model!AW221,Model!BB221,Model!BG221,Model!BL221,Model!BQ221,Model!BV221,Model!CA221),"") -> 0.21130165 | K36: =IFERROR(MIN(Model!C221,Model!D221,Model!E221,Model!F221,Model!G221,Model!H221,Model!I221,Model!N221,Model!S221,Model!X221,Model!AC221,Model!AH221,Model!AM221,Model!AR221,Model!AW221,Model!BB221,Model!BG221,Model!BL221,Model!BQ221,Model!BV221,Model!CA221),"") -> 0.16633757 | L36: =IFERROR(MAX(Model!C221,Model!D221,Model!E221,Model!F221,Model!G221,Model!H221,Model!I221,Model!N221,Model!S221,Model!X221,Model!AC221,Model!AH221,Model!AM221,Model!AR221,Model!AW221,Model!BB221,Model!BG221,Model!BL221,Model!BQ221,Model!BV221,Model!CA221),"") -> 0.27825659 | N36: Adjusted EBITDA (pro forma) % of revenues | O36: 0.27825659 | P36: 0.28175711 | Q36: 0.27925035 | R36: 0.28918307 | S36: 0.29774089 | T36: 0.30074926 | V36: 0.21130165 | W36: 0.16633757 | X36: 0.27825659 | Z36: Adjusted EBITDA (pro forma) % of revenues | AA36: 0.27825659 | AB36: 0.27691483 | AC36: 0.24689273 | AD36: 0.25881681 | AE36: 0.26990929 | AF36: 0.27699201 | AH36: 0.21130165 | AI36: 0.16633757 | AJ36: 0.27825659
B38: Net Debt | C38: =Model!CA389 -> 2139.055 | D38: =Model!CF389 -> 4265.6506 | E38: =Model!CG389 -> 5294.7456 | F38: =Model!CH389 -> 5934.2292 | G38: =Model!CI389 -> 6613.2771 | H38: =Model!CJ389 -> 7234.2192 | N38: Net Debt | O38: 2139.055 | P38: 4251.9828 | Q38: 7964.6438 | R38: 9075.4358 | S38: 10274.321 | T38: 11357.869 | Z38: Net Debt | AA38: 2139.055 | AB38: 4287.4831 | AC38: 3222.9808 | AD38: 3120.8792 | AE38: 3408.2043 | AF38: 3649.3294
B39: Net Debt / Adjusted EBITDA (x) | C39: =IFERROR(C38/C35,"") -> 0.68242434 | D39: =IFERROR(D38/D35,"") -> 1.1474888 | E39: =IFERROR(E38/E35,"") -> 1.25 | F39: =IFERROR(F38/F35,"") -> 1.25 | G39: =IFERROR(G38/G35,"") -> 1.25 | H39: =IFERROR(H38/H35,"") -> 1.25 | N39: Net Debt / Adjusted EBITDA (x) | O39: 0.68242434 | P39: 1.1300057 | Q39: 1.75 | R39: 1.75 | S39: 1.75 | T39: 1.75 | Z39: Net Debt / Adjusted EBITDA (x) | AA39: 0.68242434 | AB39: 1.173559 | AC39: 0.84981838 | AD39: 0.75 | AE39: 0.75 | AF39: 0.75
B40: Share repurchases ($m) | D40: =Model!CF269 -> 544.71 | E40: =Model!CG269 -> 2165.4265 | F40: =Model!CH269 -> 1993.7879 | G40: =Model!CI269 -> 2279.7427 | H40: =Model!CJ269 -> 2406.051 | N40: Share repurchases ($m) | P40: 544.71 | Q40: 4839.38 | R40: 2467.175 | S40: 2884.4019 | T40: 3020.4887 | AB40: 544.71 | AC40: 0 | AD40: 1126.9745 | AE40: 1672.5501 | AF40: 1701.6553
B41: Implied avg buyback price ($) | D41: =Model!CF268 -> 198.95 | E41: =Model!CG268 -> 214.866 | F41: =Model!CH268 -> 232.05528 | G41: =Model!CI268 -> 250.6197 | H41: =Model!CJ268 -> 270.66928 | N41: Implied avg buyback price ($) | P41: 198.95 | Q41: 214.866 | R41: 232.05528 | S41: 250.6197 | T41: 270.66928 | AB41: 198.95 | AC41: 214.866 | AD41: 232.05528 | AE41: 250.6197 | AF41: 270.66928
B42: Shares repurchased (m) | D42: =Model!CF270 -> 2.7379241 | E42: =Model!CG270 -> 10.078032 | F42: =Model!CH270 -> 8.5918663 | G42: =Model!CI270 -> 9.0964225 | H42: =Model!CJ270 -> 8.8892653 | N42: Shares repurchased (m) | P42: 2.7379241 | Q42: 22.522781 | R42: 10.631842 | S42: 11.509079 | T42: 11.159333 | AB42: 2.7379241 | AC42: 0 | AD42: 4.8564916 | AE42: 6.6736575 | AF42: 6.2868433
B44: ROIC | C44: =Model!CA390 -> 0.287517 | D44: =Model!CF390 -> 0.18308741 | E44: =Model!CG390 -> 0.2048718 | F44: =Model!CH390 -> 0.22262944 | G44: =Model!CI390 -> 0.23991568 | H44: =Model!CJ390 -> 0.25138704 | J44: =IFERROR(AVERAGE(Model!C390,Model!D390,Model!E390,Model!F390,Model!G390,Model!H390,Model!I390,Model!N390,Model!S390,Model!X390,Model!AC390,Model!AH390,Model!AM390,Model!AR390,Model!AW390,Model!BB390,Model!BG390,Model!BL390,Model!BQ390,Model!BV390,Model!CA390),"") -> 0.16312603 | K44: =IFERROR(MIN(Model!C390,Model!D390,Model!E390,Model!F390,Model!G390,Model!H390,Model!I390,Model!N390,Model!S390,Model!X390,Model!AC390,Model!AH390,Model!AM390,Model!AR390,Model!AW390,Model!BB390,Model!BG390,Model!BL390,Model!BQ390,Model!BV390,Model!CA390),"") -> 0.090413146 | L44: =IFERROR(MAX(Model!C390,Model!D390,Model!E390,Model!F390,Model!G390,Model!H390,Model!I390,Model!N390,Model!S390,Model!X390,Model!AC390,Model!AH390,Model!AM390,Model!AR390,Model!AW390,Model!BB390,Model!BG390,Model!BL390,Model!BQ390,Model!BV390,Model!CA390),"") -> 0.287517 | N44: ROIC | O44: 0.287517 | P44: 0.18528404 | Q44: 0.21813324 | R44: 0.23643235 | S44: 0.25425001 | T44: 0.26473558 | V44: 0.16312603 | W44: 0.090413146 | X44: 0.287517 | Z44: ROIC | AA44: 0.287517 | AB44: 0.1799342 | AC44: 0.18392833 | AD44: 0.20011311 | AE44: 0.21599548 | AF44: 0.22587688 | AH44: 0.16312603 | AI44: 0.090413146 | AJ44: 0.287517
