Workbook

Sheet Model
B2: Moog Inc. — 3-Statement Financial Model | CO2: SCENARIO TOGGLE
B3: US GAAP as reported · USD millions · Fiscal year ends late September · Source: Moog 10-K and 10-Q filings (SEC EDGAR) | CO3: Base
B4: Segment structure changed in FY22: legacy 3 segments (Aircraft Controls, Space and Defense Controls, Industrial Systems) → current 4 segments (Military Aircraft, Commercial Aircraft, Space and Defense, Industrial).
CN5: FY20-FY25 | CO5: Selected scenario KPIs (FY30E)
B6: ($M) | C6: Q1/10 | D6: Q2/10 | E6: Q3/10 | F6: Q4/10 | G6: FY10 | H6: Q1/11 | I6: Q2/11 | J6: Q3/11 | K6: Q4/11 | L6: FY11 | M6: Q1/12 | N6: Q2/12 | O6: Q3/12 | P6: Q4/12 | Q6: FY12 | R6: Q1/13 | S6: Q2/13 | T6: Q3/13 | U6: Q4/13 | V6: FY13 | W6: Q1/14 | X6: Q2/14 | Y6: Q3/14 | Z6: Q4/14 | AA6: FY14 | AB6: Q1/15 | AC6: Q2/15 | AD6: Q3/15 | AE6: Q4/15 | AF6: FY15 | AG6: Q1/16 | AH6: Q2/16 | AI6: Q3/16 | AJ6: Q4/16 | AK6: FY16 | AL6: Q1/17 | AM6: Q2/17 | AN6: Q3/17 | AO6: Q4/17 | AP6: FY17 | AQ6: Q1/18 | AR6: Q2/18 | AS6: Q3/18 | AT6: Q4/18 | AU6: FY18 | AV6: Q1/19 | AW6: Q2/19 | AX6: Q3/19 | AY6: Q4/19 | AZ6: FY19 | BA6: Q1/20 | BB6: Q2/20 | BC6: Q3/20 | BD6: Q4/20 | BE6: FY20 | BF6: Q1/21 | BG6: Q2/21 | BH6: Q3/21 | BI6: Q4/21 | BJ6: FY21 | BK6: Q1/22 | BL6: Q2/22 | BM6: Q3/22 | BN6: Q4/22 | BO6: FY22 | BP6: Q1/23 | BQ6: Q2/23 | BR6: Q3/23 | BS6: Q4/23 | BT6: FY23 | BU6: Q1/24 | BV6: Q2/24 | BW6: Q3/24 | BX6: Q4/24 | BY6: FY24 | BZ6: Q1/25 | CA6: Q2/25 | CB6: Q3/25 | CC6: Q4/25 | CD6: FY25 | CE6: Q1/26 | CF6: Q2/26 | CG6: Q3/26E | CH6: Q4/26E | CI6: FY26E | CJ6: FY27E | CK6: FY28E | CL6: FY29E | CM6: FY30E | CN6: 5Y CAGR | CO6: FY30E Revenue ($M) | CP6: =CM98 -> 5581.8999 | CQ6: Modeling Comments & Assumptions
CO7: FY30E GAAP EBIT ($M) | CP7: =CM102 -> 757.94422
B8: SEGMENT P&L — LEGACY STRUCTURE (FY10–FY21) | CO8: FY30E EBIT margin % | CP8: =CM102/CM98 -> 0.13578606 | CQ8: Segment forecast assumptions
B9: Pre-FY22 reporting — 3 reportable segments: Aircraft Controls, Space and Defense Controls, Industrial Systems. (Components and Medical Devices were separate segments in early years; combined into Industrial Systems by FY15.) | CO9: FY30E ROIC | CP9: =CM284 -> 0
CO10: FY30E Adj EPS ($) | CP10: =CM156 -> 18.427098
B11: Aircraft Controls
B12: Net sales | G12: 756.55 | L12: 850.49 | Q12: 963.421 | V12: 1059.587 | AA12: 1117.656 | AF12: 1086.547 | AK12: 1063.718 | AP12: 1124.885 | AU12: 1193.505 | AZ12: 1302.972 | BE12: 1205.75 | BF12: 286.774 | BG12: 304.361 | BH12: 272.131 | BI12: =BJ12-SUM(BF12:BH12) -> 297.972 | BJ12: 1161.238 | BK12: 303.317 | BL12: 311.268 | BM12: 318.017 | BN12: =BO12-SUM(BK12:BM12) -> 323.859 | BO12: 1256.461 | BP12: 310.259 | BQ12: 347.004 | BR12: 355.025
B13: Operating profit | G13: 76.374 | L13: 83.776 | Q13: 104.582 | V13: 126.751 | AA13: 115.726 | AF13: 100.006 | AK13: 98.509 | AP13: 114.016 | AU13: 129.772 | AZ13: 122.701 | BE13: 34.67 | BF13: 27.922 | BG13: 22.018 | BH13: 20.545 | BI13: =BJ13-SUM(BF13:BH13) -> 26.193 | BJ13: 96.678 | BK13: 41.915 | BL13: 12.441 | BM13: 34.453 | BN13: =BO13-SUM(BK13:BM13) -> 34.811 | BO13: 123.62 | BP13: 29.718 | BQ13: 31.862 | BR13: 37.888
B14: Sales y/y % | L14: =L12/G12-1 -> 0.12416892 | Q14: =Q12/L12-1 -> 0.13278345 | V14: =V12/Q12-1 -> 0.099817214 | AA14: =AA12/V12-1 -> 0.054803428 | AF14: =AF12/AA12-1 -> -0.027834146 | AK14: =AK12/AF12-1 -> -0.021010596 | AP14: =AP12/AK12-1 -> 0.057503022 | AU14: =AU12/AP12-1 -> 0.061001791 | AZ14: =AZ12/AU12-1 -> 0.091718929 | BE14: =BE12/AZ12-1 -> -0.074615571 | BJ14: =BJ12/BE12-1 -> -0.036916442 | BK14: =BK12/BF12-1 -> 0.057686541 | BL14: =BL12/BG12-1 -> 0.022693446 | BM14: =BM12/BH12-1 -> 0.16861732 | BP14: =BP12/BK12-1 -> 0.022886947 | BQ14: =BQ12/BL12-1 -> 0.11480782 | BR14: =BR12/BM12-1 -> 0.11637114
B15: Operating margin % | G15: =G13/G12 -> 0.10095037 | L15: =L13/L12 -> 0.098503216 | Q15: =Q13/Q12 -> 0.10855275 | V15: =V13/V12 -> 0.11962302 | AA15: =AA13/AA12 -> 0.10354349 | AF15: =AF13/AF12 -> 0.092040197 | AK15: =AK13/AK12 -> 0.092608191 | AP15: =AP13/AP12 -> 0.10135792 | AU15: =AU13/AU12 -> 0.10873184 | AZ15: =AZ13/AZ12 -> 0.094170097 | BE15: =BE13/BE12 -> 0.028753888 | BF15: =BF13/BF12 -> 0.09736587 | BG15: =BG13/BG12 -> 0.072341726 | BH15: =BH13/BH12 -> 0.075496728 | BI15: =BI13/BI12 -> 0.087904233 | BJ15: =BJ13/BJ12 -> 0.083254251 | BK15: =BK13/BK12 -> 0.13818876 | BL15: =BL13/BL12 -> 0.039968773 | BM15: =BM13/BM12 -> 0.10833698 | BO15: =BO13/BO12 -> 0.098387455 | BP15: =BP13/BP12 -> 0.09578449 | BQ15: =BQ13/BQ12 -> 0.091820267 | BR15: =BR13/BR12 -> 0.10671925
B16: Backlog ($M) | G16: 567 | L16: 641 | Q16: 658 | V16: 671 | AA16: 715 | AF16: 678 | AK16: 632 | AP16: 571 | AU16: 755 | BO16: 5200
B17: Book-to-bill (Bookings / Sales)
B19: Space and Defense Controls
B20: Net sales | G20: 325.474 | L20: 355.762 | Q20: 358.755 | V20: 395.945 | AA20: 394.505 | AF20: 381.444 | AK20: 366.091 | AP20: 394.264 | AU20: 580.877 | AZ20: 683.468 | BE20: 770.114 | BF20: 188.162 | BG20: 206.168 | BH20: 204.887 | BI20: =BJ20-SUM(BF20:BH20) -> 200.018 | BJ20: 799.235 | BK20: 207.856 | BL20: 223.349 | BM20: 223.644 | BN20: =BO20-SUM(BK20:BM20) -> 217.494 | BO20: 872.343 | BP20: 217.785 | BQ20: 245.853 | BR20: 242.402
B21: Operating profit | G21: 35.844 | L21: 49.245 | Q21: 42.854 | V21: 25.35 | AA21: 26.119 | AF21: 33.236 | AK21: 41.419 | AP21: 37.591 | AU21: 67.615 | AZ21: 88.99 | BE21: 101.667 | BF21: 23.046 | BG21: 26.652 | BH21: 21.339 | BI21: =BJ21-SUM(BF21:BH21) -> 16.963 | BJ21: 88 | BK21: 21.299 | BL21: 24.075 | BM21: 25.368 | BN21: =BO21-SUM(BK21:BM21) -> 16.102 | BO21: 86.844 | BP21: 20.294 | BQ21: 27.507 | BR21: 18.585
B22: Sales y/y % | L22: =L20/G20-1 -> 0.093058124 | Q22: =Q20/L20-1 -> 0.0084129277 | V22: =V20/Q20-1 -> 0.10366406 | AA22: =AA20/V20-1 -> -0.0036368688 | AF22: =AF20/AA20-1 -> -0.033107312 | AK22: =AK20/AF20-1 -> -0.040249683 | AP22: =AP20/AK20-1 -> 0.076956276 | AU22: =AU20/AP20-1 -> 0.47331991 | AZ22: =AZ20/AU20-1 -> 0.17661398 | BE22: =BE20/AZ20-1 -> 0.12677404 | BJ22: =BJ20/BE20-1 -> 0.037813882 | BK22: =BK20/BF20-1 -> 0.10466513 | BL22: =BL20/BG20-1 -> 0.08333495 | BM22: =BM20/BH20-1 -> 0.091548024 | BP22: =BP20/BK20-1 -> 0.047768648 | BQ22: =BQ20/BL20-1 -> 0.10075711 | BR22: =BR20/BM20-1 -> 0.083874372
B23: Operating margin % | G23: =G21/G20 -> 0.11012861 | L23: =L21/L20 -> 0.13842119 | Q23: =Q21/Q20 -> 0.11945199 | V23: =V21/V20 -> 0.064024044 | AA23: =AA21/AA20 -> 0.066207019 | AF23: =AF21/AF20 -> 0.087132056 | AK23: =AK21/AK20 -> 0.11313854 | AP23: =AP21/AP20 -> 0.095344744 | AU23: =AU21/AU20 -> 0.11640158 | AZ23: =AZ21/AZ20 -> 0.13020361 | BE23: =BE21/BE20 -> 0.13201552 | BF23: =BF21/BF20 -> 0.12247957 | BG23: =BG21/BG20 -> 0.12927321 | BH23: =BH21/BH20 -> 0.10415009 | BI23: =BI21/BI20 -> 0.084807367 | BJ23: =BJ21/BJ20 -> 0.11010529 | BK23: =BK21/BK20 -> 0.10246998 | BL23: =BL21/BL20 -> 0.10779095 | BM23: =BM21/BM20 -> 0.11343027 | BO23: =BO21/BO20 -> 0.099552584 | BP23: =BP21/BP20 -> 0.093183644 | BQ23: =BQ21/BQ20 -> 0.11188393 | BR23: =BR21/BR20 -> 0.076670159
B24: Backlog ($M) | G24: 213 | L24: 223 | Q24: 204 | V24: 254 | AA24: 254 | AF24: 250 | AK24: 277 | AP24: 282 | AU24: 454
B26: Industrial Systems
B27: Net sales | G27: 545.672 | L27: 629.312 | Q27: 633.713 | V27: 592.112 | AA27: 590.971 | AF27: 521.505 | AK27: 514.984 | AP27: 477.325 | AU27: 935.086 | AZ27: 918.223 | BE27: 908.69 | BF27: 209.018 | BG27: 225.873 | BH27: 230.334 | BI27: =BJ27-SUM(BF27:BH27) -> 226.295 | BJ27: 891.52 | BK27: 212.913 | BL27: 236.17 | BM27: 231.25 | BN27: =BO27-SUM(BK27:BM27) -> 226.646 | BO27: 906.979 | BP27: 232.059 | BQ27: 243.935 | BR27: 252.749
B28: Operating profit | G28: 48.109 | L28: 62.805 | Q28: 63.243 | V28: 42.254 | AA28: 58.108 | AF28: 45.021 | AK28: 48.542 | AP28: 46.091 | AU28: 64.964 | AZ28: 109.451 | BE28: 80.025 | BF28: 19.898 | BG28: 23.813 | BH28: 23.004 | BI28: =BJ28-SUM(BF28:BH28) -> 19.285 | BJ28: 86 | BK28: 17.191 | BL28: 20.723 | BM28: 19.484 | BN28: =BO28-SUM(BK28:BM28) -> 14.986 | BO28: 72.384 | BP28: 36.751 | BQ28: 24.397 | BR28: 28.035
B29: Sales y/y % | L29: =L27/G27-1 -> 0.15327889 | Q29: =Q27/L27-1 -> 0.0069933515 | V29: =V27/Q27-1 -> -0.065646436 | AA29: =AA27/V27-1 -> -0.0019270003 | AF29: =AF27/AA27-1 -> -0.11754553 | AK29: =AK27/AF27-1 -> -0.012504195 | AP29: =AP27/AK27-1 -> -0.073126544 | AU29: =AU27/AP27-1 -> 0.95901325 | AZ29: =AZ27/AU27-1 -> -0.018033635 | BE29: =BE27/AZ27-1 -> -0.01038201 | BJ29: =BJ27/BE27-1 -> -0.018895333 | BK29: =BK27/BF27-1 -> 0.018634759 | BL29: =BL27/BG27-1 -> 0.045587565 | BM29: =BM27/BH27-1 -> 0.0039768336 | BP29: =BP27/BK27-1 -> 0.089924053 | BQ29: =BQ27/BL27-1 -> 0.032878858 | BR29: =BR27/BM27-1 -> 0.092968649
B30: Operating margin % | G30: =G28/G27 -> 0.088164685 | L30: =L28/L27 -> 0.099799464 | Q30: =Q28/Q27 -> 0.099797542 | V30: =V28/V27 -> 0.071361499 | AA30: =AA28/AA27 -> 0.098326314 | AF30: =AF28/AF27 -> 0.08632899 | AK30: =AK28/AK27 -> 0.094259239 | AP30: =AP28/AP27 -> 0.096561043 | AU30: =AU28/AU27 -> 0.069473824 | AZ30: =AZ28/AZ27 -> 0.11919871 | BE30: =BE28/BE27 -> 0.088066337 | BF30: =BF28/BF27 -> 0.095197543 | BG30: =BG28/BG27 -> 0.1054265 | BH30: =BH28/BH27 -> 0.099872359 | BI30: =BI28/BI27 -> 0.085220619 | BJ30: =BJ28/BJ27 -> 0.096464465 | BK30: =BK28/BK27 -> 0.080741899 | BL30: =BL28/BL27 -> 0.087746115 | BM30: =BM28/BM27 -> 0.084255135 | BO30: =BO28/BO27 -> 0.079807802 | BP30: =BP28/BP27 -> 0.15836921 | BQ30: =BQ28/BQ27 -> 0.10001435 | BR30: =BR28/BR27 -> 0.11092032
B31: Backlog ($M) | G31: 233 | L31: 284 | Q31: 234 | V31: 187 | AA31: 182 | AF31: 178 | AK31: 145 | AP31: 164 | AU31: 272
B33: Components (separate segment FY10–FY14, then merged into Industrial)
B34: Net sales | G34: 359.992 | L34: 353.142 | Q34: 374.081 | V34: 438.572 | AA34: 449.891 | AF34: 437.468 | AK34: 467.144 | AP34: 501.05 | AU34: 359.992 | AZ34: 359.992 | BE34: 359.992 | BF34: 359.992 | BG34: 359.992 | BH34: 359.992 | BI34: 359.992 | BJ34: 359.992
B35: Operating profit | G35: 60.159 | L35: 50.353 | Q35: 57.303 | V35: 74.425 | AA35: 72.768 | AF35: 58.693 | AK35: 49.772 | AP35: 52.454 | AU35: 60.159 | AZ35: 60.159 | BE35: 60.159 | BF35: 60.159 | BG35: 60.159 | BH35: 60.159 | BI35: 60.159 | BJ35: 60.159
B36: Operating margin % | L36: =L34/G34-1 -> -0.019028201 | Q36: =Q34/L34-1 -> 0.059293429 | V36: =V34/Q34-1 -> 0.17239849 | AA36: =AA34/V34-1 -> 0.025808761 | AF36: =AF34/AA34-1 -> -0.027613355 | AK36: =AK34/AF34-1 -> 0.067835819 | AP36: =AP34/AK34-1 -> 0.072581474
G37: =G35/G34 -> 0.16711205 | L37: =L35/L34 -> 0.1425857 | Q37: =Q35/Q34 -> 0.1531834 | V37: =V35/V34 -> 0.16969848 | AA37: =AA35/AA34 -> 0.16174585 | AF37: =AF35/AF34 -> 0.13416524 | AK37: =AK35/AK34 -> 0.10654531 | AP37: =AP35/AP34 -> 0.10468815 | AU37: =AU35/AU34 -> 0.16711205 | AZ37: =AZ35/AZ34 -> 0.16711205 | BE37: =BE35/BE34 -> 0.16711205 | BF37: =BF35/BF34 -> 0.16711205 | BG37: =BG35/BG34 -> 0.16711205 | BH37: =BH35/BH34 -> 0.16711205 | BI37: =BI35/BI34 -> 0.16711205 | BJ37: =BJ35/BJ34 -> 0.16711205
B38: Medical Devices (separate segment FY10–FY16, divested/merged)
B39: Net sales | G39: 126.564 | L39: 141.974 | Q39: 139.566 | V39: 124.095 | AA39: 95.362 | AF39: 98.568 | AK39: 126.564 | AP39: 126.564 | AU39: 126.564 | AZ39: 126.564 | BE39: 126.564 | BF39: 126.564 | BG39: 126.564 | BH39: 126.564 | BI39: 126.564 | BJ39: 126.564
B40: Operating profit | G40: -4.044 | L40: 0.241 | Q40: 5.443 | V40: -41.236 | AA40: 2.996 | AF40: 8.557 | AK40: -4.044 | AP40: -4.044 | AU40: -4.044 | AZ40: -4.044 | BE40: -4.044 | BF40: -4.044 | BG40: -4.044 | BH40: -4.044 | BI40: -4.044 | BJ40: -4.044
B41: Operating margin % | G41: =G40/G39 -> -0.031952214 | L41: =L40/L39 -> 0.0016974939 | Q41: =Q40/Q39 -> 0.03899947 | V41: =V40/V39 -> -0.33229381 | AA41: =AA40/AA39 -> 0.031417126 | AF41: =AF40/AF39 -> 0.086813165 | AK41: =AK40/AK39 -> -0.031952214 | AP41: =AP40/AP39 -> -0.031952214 | AU41: =AU40/AU39 -> -0.031952214 | AZ41: =AZ40/AZ39 -> -0.031952214 | BE41: =BE40/BE39 -> -0.031952214 | BF41: =BF40/BF39 -> -0.031952214 | BG41: =BG40/BG39 -> -0.031952214 | BH41: =BH40/BH39 -> -0.031952214 | BI41: =BI40/BI39 -> -0.031952214 | BJ41: =BJ40/BJ39 -> -0.031952214
B43: Legacy Group Total (consolidated, FY10–FY21)
B44: Net sales | G44: =G12+G20+G27+G34+G39 -> 2114.252 | L44: =L12+L20+L27+L34+L39 -> 2330.68 | Q44: =Q12+Q20+Q27+Q34+Q39 -> 2469.536 | V44: =V12+V20+V27+V34+V39 -> 2610.311 | AA44: =AA12+AA20+AA27+AA34+AA39 -> 2648.385 | AF44: =AF12+AF20+AF27+AF34+AF39 -> 2525.532 | AK44: =AK12+AK20+AK27+AK34 -> 2411.937 | AP44: =AP12+AP20+AP27+AP34 -> 2497.524 | AU44: =AU12+AU20+AU27 -> 2709.468 | AZ44: =AZ12+AZ20+AZ27 -> 2904.663 | BE44: =BE12+BE20+BE27 -> 2884.554 | BF44: =BF12+BF20+BF27 -> 683.954 | BG44: =BG12+BG20+BG27 -> 736.402 | BH44: =BH12+BH20+BH27 -> 707.352 | BJ44: =BJ12+BJ20+BJ27 -> 2851.993 | BK44: =BK12+BK20+BK27 -> 724.086 | BL44: =BL12+BL20+BL27 -> 770.787 | BM44: =BM12+BM20+BM27 -> 772.911 | BO44: =BO12+BO20+BO27 -> 3035.783 | BP44: =BP12+BP20+BP27 -> 760.103 | BQ44: =BQ12+BQ20+BQ27 -> 836.792 | BR44: =BR12+BR20+BR27 -> 850.176
B45: Operating profit | G45: =G13+G21+G28+G35+G40 -> 216.442 | L45: =L13+L21+L28+L35+L40 -> 246.42 | Q45: =Q13+Q21+Q28+Q35+Q40 -> 273.425 | V45: =V13+V21+V28+V35+V40 -> 227.544 | AA45: =AA13+AA21+AA28+AA35+AA40 -> 275.717 | AF45: =AF13+AF21+AF28+AF35+AF40 -> 245.513 | AK45: =AK13+AK21+AK28+AK35 -> 238.242 | AP45: =AP13+AP21+AP28+AP35 -> 250.152 | AU45: =AU13+AU21+AU28 -> 262.351 | AZ45: =AZ13+AZ21+AZ28 -> 321.142 | BE45: =BE13+BE21+BE28 -> 216.362 | BF45: =BF13+BF21+BF28 -> 70.866 | BG45: =BG13+BG21+BG28 -> 72.483 | BH45: =BH13+BH21+BH28 -> 64.888 | BJ45: =BJ13+BJ21+BJ28 -> 270.678 | BK45: =BK13+BK21+BK28 -> 80.405 | BL45: =BL13+BL21+BL28 -> 57.239 | BM45: =BM13+BM21+BM28 -> 79.305 | BO45: =BO13+BO21+BO28 -> 282.848 | BP45: =BP13+BP21+BP28 -> 86.763 | BQ45: =BQ13+BQ21+BQ28 -> 83.766 | BR45: =BR13+BR21+BR28 -> 84.508
...

Sheet Moog-Bull-Base-Bear
B2: Moog Inc. — Bull / Base / Bear Case P&L Summary | J2: Share price ($): | K2: 345
B3: Adjusted figures · $ millions · Linked to Model — toggle scenario via Model!CK3 | J3: As of: | K3: =TODAY() -> 46169
B5: Scenario: | C5: =Model!CO3 -> Base | N5: Scenario: | O5: Bull | Z5: Scenario: | AA5: Bear
B7: ($M, except EPS and shares) | C7: FY25A | D7: FY26E | E7: FY27E | F7: FY28E | G7: FY29E | H7: FY30E | I7: 25-'30 CAGR | J7: LT Hist Avg | K7: LT Hist Min | L7: LT Hist Max | N7: ($M, except EPS and shares) | O7: FY25A | P7: FY26E | Q7: FY27E | R7: FY28E | S7: FY29E | T7: FY30E | U7: 25-'30 CAGR | V7: LT Hist Avg | W7: LT Hist Min | X7: LT Hist Max | Z7: ($M, except EPS and shares) | AA7: FY25A | AB7: FY26E | AC7: FY27E | AD7: FY28E | AE7: FY29E | AF7: FY30E | AG7: 25-'30 CAGR | AH7: LT Hist Avg | AI7: LT Hist Min | AJ7: LT Hist Max
B9: Revenue | C9: =Model!CD114 -> 3860.624 | D9: =Model!CI114 -> 4264.9902 | E9: =Model!CJ114 -> 4612.542 | F9: =Model!CK114 -> 4936.561 | G9: =Model!CL114 -> 5256.574 | H9: =Model!CM114 -> 5581.8999 | I9: =IFERROR((H9/C9)^(1/5)-1,"n/m") -> 0.076526953 | N9: Revenue | O9: 3860.624 | P9: 4264.9902 | Q9: 4738.1424 | R9: 5175.8989 | S9: 5605.2429 | T9: 6047.3405 | U9: 0.093909475 | Z9: Revenue | AA9: 3860.624 | AB9: 4264.9902 | AC9: 4421.3914 | AD9: 4555.9175 | AE9: 4684.1497 | AF9: 4822.1843 | AG9: 0.045483682
B10: Revenue y/y % | D10: =IFERROR(D9/C9-1,"") -> 0.10474115 | E10: =IFERROR(E9/D9-1,"") -> 0.081489464 | F10: =IFERROR(F9/E9-1,"") -> 0.070247399 | G10: =IFERROR(G9/F9-1,"") -> 0.064825079 | H10: =IFERROR(H9/G9-1,"") -> 0.061889341 | N10: Revenue y/y % | P10: 0.10474115 | Q10: 0.11093863 | R10: 0.092389911 | S10: 0.082950609 | T10: 0.078872163 | Z10: Revenue y/y % | AB10: 0.10474115 | AC10: 0.036670945 | AD10: 0.030426179 | AE10: 0.028146311 | AF10: 0.029468425
B12: Gross Profit | C12: =Model!CD116 -> 1057.348 | D12: =Model!CI116 -> 1194.1973 | E12: =Model!CJ116 -> 1314.5745 | F12: =Model!CK116 -> 1431.6027 | G12: =Model!CL116 -> 1550.6893 | H12: =Model!CM116 -> 1674.57 | I12: =IFERROR((H12/C12)^(1/5)-1,"n/m") -> 0.096319327 | N12: Gross Profit | O12: 1057.348 | P12: 1194.1973 | Q12: 1350.3706 | R12: 1501.0107 | S12: 1653.5467 | T12: 1814.2022 | U12: 0.11402143 | Z12: Gross Profit | AA12: 1057.348 | AB12: 1194.1973 | AC12: 1260.0966 | AD12: 1321.2161 | AE12: 1381.8242 | AF12: 1446.6553 | AG12: 0.064705313
B13: GP % | C13: =IFERROR(C12/C9,"") -> 0.27388008 | D13: =IFERROR(D12/D9,"") -> 0.28 | E13: =IFERROR(E12/E9,"") -> 0.285 | F13: =IFERROR(F12/F9,"") -> 0.29 | G13: =IFERROR(G12/G9,"") -> 0.295 | H13: =IFERROR(H12/H9,"") -> 0.3 | J13: =AVERAGE(Model!AF165,Model!AK165,Model!AP165,Model!AU165,Model!AZ165,Model!BE165,Model!BJ165,Model!BO165,Model!BT165,Model!BY165,Model!CD165) -> 0.2792281 | K13: =MIN(Model!AF165,Model!AK165,Model!AP165,Model!AU165,Model!AZ165,Model!BE165,Model!BJ165,Model!BO165,Model!BT165,Model!BY165,Model!CD165) -> 0.2578201 | L13: =MAX(Model!AF165,Model!AK165,Model!AP165,Model!AU165,Model!AZ165,Model!BE165,Model!BJ165,Model!BO165,Model!BT165,Model!BY165,Model!CD165) -> 0.29502553 | N13: GP % | O13: 0.27388008 | P13: 0.28 | Q13: 0.285 | R13: 0.29 | S13: 0.295 | T13: 0.3 | V13: 0.2792281 | W13: 0.2578201 | X13: 0.29502553 | Z13: GP % | AA13: 0.27388008 | AB13: 0.28 | AC13: 0.285 | AD13: 0.29 | AE13: 0.295 | AF13: 0.3 | AH13: 0.2792281 | AI13: 0.2578201 | AJ13: 0.29502553
B15: EBIT (Adjusted Operating Profit) | C15: =IF(ISNUMBER(Model!CD150),IF(Model!CD150>0,Model!CD150,Model!CD126),Model!CD126) -> 501.268 | D15: =IF(ISNUMBER(Model!CI150),IF(Model!CI150>0,Model!CI150,Model!CI126),Model!CI126) -> 511.84054 | E15: =IF(ISNUMBER(Model!CJ150),IF(Model!CJ150>0,Model!CJ150,Model!CJ126),Model!CJ126) -> 567.74948 | F15: =IF(ISNUMBER(Model!CK150),IF(Model!CK150>0,Model!CK150,Model!CK126),Model!CK126) -> 626.56643 | G15: =IF(ISNUMBER(Model!CL150),IF(Model!CL150>0,Model!CL150,Model!CL126),Model!CL126) -> 702.82692 | H15: =IF(ISNUMBER(Model!CM150),IF(Model!CM150>0,Model!CM150,Model!CM126),Model!CM126) -> 785.68656 | I15: =IFERROR((H15/C15)^(1/5)-1,"n/m") -> 0.094046721 | N15: EBIT (Adjusted Operating Profit) | O15: 501.268 | P15: 511.84054 | Q15: 582.82153 | R15: 656.48366 | S15: 749.02555 | T15: 850.84825 | U15: 0.11162019 | Z15: EBIT (Adjusted Operating Profit) | AA15: 501.268 | AB15: 511.84054 | AC15: 544.81141 | AD15: 578.98598 | AE15: 626.9807 | AF15: 679.32637 | AG15: 0.062678022
B16: EBIT y/y % | D16: =IFERROR(D15/C15-1,"") -> 0.021091591 | E16: =IFERROR(E15/D15-1,"") -> 0.10923117 | F16: =IFERROR(F15/E15-1,"") -> 0.10359665 | G16: =IFERROR(G15/F15-1,"") -> 0.12171174 | H16: =IFERROR(H15/G15-1,"") -> 0.11789481 | N16: EBIT y/y % | P16: 0.021091591 | Q16: 0.13867794 | R16: 0.12638883 | S16: 0.14096601 | T16: 0.13594023 | Z16: EBIT y/y % | AB16: 0.021091591 | AC16: 0.064416303 | AD16: 0.062727329 | AE16: 0.08289445 | AF16: 0.083488482
B17: EBIT % | C17: =IFERROR(C15/C9,"") -> 0.12984119 | D17: =IFERROR(D15/D9,"") -> 0.12000978 | E17: =IFERROR(E15/E9,"") -> 0.1230882 | F17: =IFERROR(F15/F9,"") -> 0.12692367 | G17: =IFERROR(G15/G9,"") -> 0.13370437 | H17: =IFERROR(H15/H9,"") -> 0.14075612 | J17: =AVERAGE(Model!AF151,Model!AK151,Model!AP151,Model!AU151,Model!AZ151,Model!BE151,Model!BJ151,Model!BO151,Model!BT151,Model!BY151,Model!CD151) -> 0.10480017 | K17: =MIN(Model!AF151,Model!AK151,Model!AP151,Model!AU151,Model!AZ151,Model!BE151,Model!BJ151,Model!BO151,Model!BT151,Model!BY151,Model!CD151) -> 0.084259871 | L17: =MAX(Model!AF151,Model!AK151,Model!AP151,Model!AU151,Model!AZ151,Model!BE151,Model!BJ151,Model!BO151,Model!BT151,Model!BY151,Model!CD151) -> 0.12984119 | N17: EBIT % | O17: 0.12984119 | P17: 0.12000978 | Q17: 0.12300634 | R17: 0.12683471 | S17: 0.13362945 | T17: 0.14069792 | V17: 0.10480017 | W17: 0.084259871 | X17: 0.12984119 | Z17: EBIT % | AA17: 0.12984119 | AB17: 0.12000978 | AC17: 0.12322171 | AD17: 0.12708439 | AE17: 0.13385155 | AF17: 0.14087524 | AH17: 0.10480017 | AI17: 0.084259871 | AJ17: 0.12984119
B19: Net Income (Adjusted Earnings) | C19: =Model!CD155 -> 278.685 | D19: =Model!CI155 -> 335.35121 | E19: =Model!CJ155 -> 382.98355 | F19: =Model!CK155 -> 429.88671 | G19: =Model!CL155 -> 490.10664 | H19: =Model!CM155 -> 556.03985 | I19: =IFERROR((H19/C19)^(1/5)-1,"n/m") -> 0.14814956 | N19: Net Income (Adjusted Earnings) | O19: 278.685 | P19: 335.79881 | Q19: 396.13347 | R19: 456.31 | S19: 530.92955 | T19: 612.64891 | U19: 0.17062991 | Z19: Net Income (Adjusted Earnings) | AA19: 278.685 | AB19: 335.79881 | AC19: 367.05573 | AD19: 397.02427 | AE19: 437.56524 | AF19: 481.43467 | AG19: 0.11553899
B21: Diluted shares ('000) | C21: =Model!CD139 -> 32082.601 | D21: =Model!CI139 -> 31647.818 | E21: =Model!CJ139 -> 31241.48 | F21: =Model!CK139 -> 30861.724 | G21: =Model!CL139 -> 30506.811 | H21: =Model!CM139 -> 30175.118 | I21: =IFERROR((H21/C21)^(1/5)-1,"n/m") -> -0.012184399 | N21: Diluted shares ('000) | O21: 32082.601 | P21: 31647.818 | Q21: 31241.48 | R21: 30861.724 | S21: 30506.811 | T21: 30175.118 | U21: -0.012184399 | Z21: Diluted shares ('000) | AA21: 32082.601 | AB21: 31647.818 | AC21: 31241.48 | AD21: 30861.724 | AE21: 30506.811 | AF21: 30175.118 | AG21: -0.012184399
B23: Adjusted EPS — Diluted ($) | C23: =Model!CD156 -> 8.686484 | D23: =Model!CI156 -> 10.596345 | E23: =Model!CJ156 -> 12.258816 | F23: =Model!CK156 -> 13.929446 | G23: =Model!CL156 -> 16.065482 | H23: =Model!CM156 -> 18.427098 | I23: =IFERROR((H23/C23)^(1/5)-1,"n/m") -> 0.16231163 | N23: Adjusted EPS — Diluted ($) | O23: 8.686484 | P23: 10.610488 | Q23: 12.679728 | R23: 14.785629 | S23: 17.403639 | T23: 20.303116 | U23: 0.18506926 | Z23: Adjusted EPS — Diluted ($) | AA23: 8.686484 | AB23: 10.610488 | AC23: 11.748987 | AD23: 12.864618 | AE23: 14.343198 | AF23: 15.954691 | AG23: 0.12929882
B24: EPS y/y % | D24: =IFERROR(D23/C23-1,"") -> 0.21986585 | E24: =IFERROR(E23/D23-1,"") -> 0.15689096 | F24: =IFERROR(F23/E23-1,"") -> 0.13627987 | G24: =IFERROR(G23/F23-1,"") -> 0.15334684 | H24: =IFERROR(H23/G23-1,"") -> 0.14699935 | N24: EPS y/y % | P24: 0.22149404 | Q24: 0.19501834 | R24: 0.16608408 | S24: 0.17706451 | T24: 0.16660173 | Z24: EPS y/y % | AB24: 0.22149404 | AC24: 0.10729935 | AD24: 0.094955491 | AE24: 0.11493388 | AF24: 0.1123524
B26: P / E (x) — assumed | E26: 20 | F26: =E26 -> 20 | G26: =F26 -> 20 | H26: =G26 -> 20 | N26: P / E (x) — assumed | R26: 25 | S26: 22 | T26: 22 | Z26: P / E (x) — assumed | AC26: 18 | AD26: 18 | AE26: 18 | AF26: 18
B27: Price Target ($) | F27: =F26*F23 -> 278.58892 | G27: =G26*G23 -> 321.30965 | H27: =H26*H23 -> 368.54196 | N27: Price Target ($) | R27: =R26*R23 -> 369.64073 | S27: =S26*S23 -> 382.88007 | T27: =T26*T23 -> 446.66855 | Z27: Price Target ($) | AC27: 211.48176 | AD27: 231.56312 | AE27: 258.17757 | AF27: 287.18443
B28: Upside / (Downside) vs current | F28: =IFERROR(F27/$K$2-1,"") -> -0.19249589 | G28: =IFERROR(G27/$K$2-1,"") -> -0.068667695 | H28: =IFERROR(H27/$K$2-1,"") -> 0.068237552 | N28: Upside / (Downside) vs current | R28: =IFERROR(R27/$K$2-1,"") -> 0.071422412 | S28: =IFERROR(S27/$K$2-1,"") -> 0.1097973 | T28: =IFERROR(T27/$K$2-1,"") -> 0.29469144 | Z28: Upside / (Downside) vs current | AC28: -0.31780076 | AD28: -0.2530222 | AE28: -0.16716914 | AF28: -0.073598601
B29: IRR (to Dec-Y-1) | F29: =IFERROR((F27/$K$2)^(1/((DATE(2025+3,12,31)-$K$3)/365.25))-1,"") -> -0.078995024 | G29: =IFERROR((G27/$K$2)^(1/((DATE(2025+4,12,31)-$K$3)/365.25))-1,"") -> -0.019580174 | H29: =IFERROR((H27/$K$2)^(1/((DATE(2025+5,12,31)-$K$3)/365.25))-1,"") -> 0.014463458 | N29: IRR (to Dec-Y-1) | R29: =IFERROR((R27/$K$2)^(1/((DATE(2025+3,12,31)-$K$3)/365.25))-1,"") -> 0.026907319 | S29: =IFERROR((S27/$K$2)^(1/((DATE(2025+4,12,31)-$K$3)/365.25))-1,"") -> 0.029381342 | T29: =IFERROR((T27/$K$2)^(1/((DATE(2025+5,12,31)-$K$3)/365.25))-1,"") -> 0.057792966 | Z29: IRR (to Dec-Y-1) | AC29: -0.21273051 | AD29: -0.10609752 | AE29: -0.049539387 | AF29: -0.016483182
B31: Free Cash Flow | C31: =Model!CD210 -> 128.355 | D31: =Model!CI210 -> 209.52566 | E31: =Model!CJ210 -> 279.69608 | F31: =Model!CK210 -> 368.97287 | G31: =Model!CL210 -> 412.69993 | H31: =Model!CM210 -> 429.97726 | I31: =IFERROR((H31/C31)^(1/5)-1,"n/m") -> 0.27352226 | N31: Free Cash Flow | O31: 128.355 | P31: 209.97327 | Q31: 255.88546 | R31: 364.4777 | S31: 424.28432 | T31: 452.07033 | U31: 0.2863485 | Z31: Free Cash Flow | AA31: 128.355 | AB31: 209.97327 | AC31: 320.01831 | AD31: 387.72396 | AE31: 411.44649 | AF31: 410.861 | AG31: 0.26199149
B32: FCF % | C32: =IFERROR(C31/C9,"") -> 0.033247216 | D32: =IFERROR(D31/D9,"") -> 0.04912688 | E32: =IFERROR(E31/E9,"") -> 0.060638166 | F32: =IFERROR(F31/F9,"") -> 0.074742897 | G32: =IFERROR(G31/G9,"") -> 0.078511199 | H32: =IFERROR(H31/H9,"") -> 0.077030629 | J32: =AVERAGE(IFERROR(Model!AF210/Model!AF114,NA()),IFERROR(Model!AK210/Model!AK114,NA()),IFERROR(Model!AP210/Model!AP114,NA()),IFERROR(Model!AU210/Model!AU114,NA()),IFERROR(Model!AZ210/Model!AZ114,NA()),IFERROR(Model!BE210/Model!BE114,NA()),IFERROR(Model!BJ210/Model!BJ114,NA()),IFERROR(Model!BO210/Model!BO114,NA()),IFERROR(Model!BT210/Model!BT114,NA()),IFERROR(Model!BY210/Model!BY114,NA()),IFERROR(Model!CD210/Model!CD114,NA())) -> 0.046677948 | K32: =MIN(IFERROR(Model!AF210/Model!AF114,99),IFERROR(Model!AK210/Model!AK114,99),IFERROR(Model!AP210/Model!AP114,99),IFERROR(Model!AU210/Model!AU114,99),IFERROR(Model!AZ210/Model!AZ114,99),IFERROR(Model!BE210/Model!BE114,99),IFERROR(Model!BJ210/Model!BJ114,99),IFERROR(Model!BO210/Model!BO114,99),IFERROR(Model!BT210/Model!BT114,99),IFERROR(Model!BY210/Model!BY114,99),IFERROR(Model!CD210/Model!CD114,99)) -> -0.011355803 | L32: =MAX(IFERROR(Model!AF210/Model!AF114,-99),IFERROR(Model!AK210/Model!AK114,-99),IFERROR(Model!AP210/Model!AP114,-99),IFERROR(Model!AU210/Model!AU114,-99),IFERROR(Model!AZ210/Model!AZ114,-99),IFERROR(Model!BE210/Model!BE114,-99),IFERROR(Model!BJ210/Model!BJ114,-99),IFERROR(Model!BO210/Model!BO114,-99),IFERROR(Model!BT210/Model!BT114,-99),IFERROR(Model!BY210/Model!BY114,-99),IFERROR(Model!CD210/Model!CD114,-99)) -> 0.10636294 | N32: FCF % | O32: 0.033247216 | P32: 0.049231828 | Q32: 0.054005439 | R32: 0.070418242 | S32: 0.075694189 | T32: 0.07475523 | V32: 0.046677948 | W32: -0.011355803 | X32: 0.10636294 | Z32: FCF % | AA32: 0.033247216 | AB32: 0.049231828 | AC32: 0.072379547 | AD32: 0.085103376 | AE32: 0.087838031 | AF32: 0.085202262 | AH32: 0.046677948 | AI32: -0.011355803 | AJ32: 0.10636294
B33: FCF / share ($) | C33: =IFERROR(C31*1000/C21,"") -> 4.0007666 | D33: =IFERROR(D31*1000/D21,"") -> 6.6205405 | E33: =IFERROR(E31*1000/E21,"") -> 8.9527157 | F33: =IFERROR(F31*1000/F21,"") -> 11.955679 | G33: =IFERROR(G31*1000/G21,"") -> 13.528124 | H33: =IFERROR(H31*1000/H21,"") -> 14.249398 | N33: FCF / share ($) | O33: 4.0007666 | P33: 6.6346837 | Q33: 8.1905679 | R33: 11.810024 | S33: 13.907855 | T33: 14.98156 | Z33: FCF / share ($) | AA33: 4.0007666 | AB33: 6.6346837 | AC33: 10.243379 | AD33: 12.563263 | AE33: 13.487037 | AF33: 13.615887
B34: FCF Yield (on PT) | D34: =IFERROR(D33/D27,"") | E34: =IFERROR(E33/E27,"") | F34: =IFERROR(F33/F27,"") -> 0.042915129 | G34: =IFERROR(G33/G27,"") -> 0.042103075 | H34: =IFERROR(H33/H27,"") -> 0.038664249 | N34: FCF Yield (on PT) | Q34: 0.029361713 | R34: 0.036306827 | S34: 0.036324312 | T34: 0.033540664 | Z34: FCF Yield (on PT) | AC34: 0.048436228 | AD34: 0.054254163 | AE34: 0.052239384 | AF34: 0.047411648
B35: EBITDA (before special items) | C35: =IF(ISNUMBER(Model!CD150),IF(Model!CD150>0,Model!CD150,Model!CD126),Model!CD126)+Model!CD176+Model!CD177 -> 604.996 | D35: =IF(ISNUMBER(Model!CI150),IF(Model!CI150>0,Model!CI150,Model!CI126),Model!CI126)+Model!CI176+Model!CI177 -> 626.43313 | E35: =IF(ISNUMBER(Model!CJ150),IF(Model!CJ150>0,Model!CJ150,Model!CJ126),Model!CJ126)+Model!CJ176+Model!CJ177 -> 691.68016 | F35: =IF(ISNUMBER(Model!CK150),IF(Model!CK150>0,Model!CK150,Model!CK126),Model!CK126)+Model!CK176+Model!CK177 -> 759.20291 | G35: =IF(ISNUMBER(Model!CL150),IF(Model!CL150>0,Model!CL150,Model!CL126),Model!CL126)+Model!CL176+Model!CL177 -> 844.06158 | H35: =IF(ISNUMBER(Model!CM150),IF(Model!CM150>0,Model!CM150,Model!CM126),Model!CM126)+Model!CM176+Model!CM177 -> 935.66214 | I35: =IFERROR((H35/C35)^(1/5)-1,"n/m") -> 0.091121996 | N35: EBITDA (before special items) | O35: 604.996 | P35: 626.43313 | Q35: 710.12687 | R35: 795.55073 | S35: 899.62831 | T35: 1013.3294 | U35: 0.10866318 | Z35: EBITDA (before special items) | AA35: 604.996 | AB35: 626.43313 | AC35: 663.60622 | AD35: 701.39526 | AE35: 752.83535 | AF35: 808.88976 | AG35: 0.059808423
B36: EBITDA % | C36: =IFERROR(C35/C9,"") -> 0.15670938 | D36: =IFERROR(D35/D9,"") -> 0.14687798 | E36: =IFERROR(E35/E9,"") -> 0.14995639 | F36: =IFERROR(F35/F9,"") -> 0.15379186 | G36: =IFERROR(G35/G9,"") -> 0.16057257 | H36: =IFERROR(H35/H9,"") -> 0.16762431 | J36: =AVERAGE(IFERROR((IF(ISNUMBER(Model!AF150),IF(Model!AF150>0,Model!AF150,Model!AF126),Model!AF126)+Model!AF176+Model!AF177)/Model!AF114,NA()),IFERROR((IF(ISNUMBER(Model!AK150),IF(Model!AK150>0,Model!AK150,Model!AK126),Model!AK126)+Model!AK176+Model!AK177)/Model!AK114,NA()),IFERROR((IF(ISNUMBER(Model!AP150),IF(Model!AP150>0,Model!AP150,Model!AP126),Model!AP126)+Model!AP176+Model!AP177)/Model!AP114,NA()),IFERROR((IF(ISNUMBER(Model!AU150),IF(Model!AU150>0,Model!AU150,Model!AU126),Model!AU126)+Model!AU176+Model!AU177)/Model!AU114,NA()),IFERROR((IF(ISNUMBER(Model!AZ150),IF(Model!AZ150>0,Model!AZ150,Model!AZ126),Model!AZ126)+Model!AZ176+Model!AZ177)/Model!AZ114,NA()),IFERROR((IF(ISNUMBER(Model!BE150),IF(Model!BE150>0,Model!BE150,Model!BE126),Model!BE126)+Model!BE176+Model!BE177)/Model!BE114,NA()),IFERROR((IF(ISNUMBER(Model!BJ150),IF(Model!BJ150>0,Model!BJ150,Model!BJ126),Model!BJ126)+Model!BJ176+Model!BJ177)/Model!BJ114,NA()),IFERROR((IF(ISNUMBER(Model!BO150),IF(Model!BO150>0,Model!BO150,Model!BO126),Model!BO126)+Model!BO176+Model!BO177)/Model!BO114,NA()),IFERROR((IF(ISNUMBER(Model!BT150),IF(Model!BT150>0,Model!BT150,Model!BT126),Model!BT126)+Model!BT176+Model!BT177)/Model!BT114,NA()),IFERROR((IF(ISNUMBER(Model!BY150),IF(Model!BY150>0,Model!BY150,Model!BY126),Model!BY126)+Model!BY176+Model!BY177)/Model!BY114,NA()),IFERROR((IF(ISNUMBER(Model!CD150),IF(Model!CD150>0,Model!CD150,Model!CD126),Model!CD126)+Model!CD176+Model!CD177)/Model!CD114,NA())) -> 0.13674468 | K36: =MIN(IFERROR((IF(ISNUMBER(Model!AF150),IF(Model!AF150>0,Model!AF150,Model!AF126),Model!AF126)+Model!AF176+Model!AF177)/Model!AF114,99),IFERROR((IF(ISNUMBER(Model!AK150),IF(Model!AK150>0,Model!AK150,Model!AK126),Model!AK126)+Model!AK176+Model!AK177)/Model!AK114,99),IFERROR((IF(ISNUMBER(Model!AP150),IF(Model!AP150>0,Model!AP150,Model!AP126),Model!AP126)+Model!AP176+Model!AP177)/Model!AP114,99),IFERROR((IF(ISNUMBER(Model!AU150),IF(Model!AU150>0,Model!AU150,Model!AU126),Model!AU126)+Model!AU176+Model!AU177)/Model!AU114,99),IFERROR((IF(ISNUMBER(Model!AZ150),IF(Model!AZ150>0,Model!AZ150,Model!AZ126),Model!AZ126)+Model!AZ176+Model!AZ177)/Model!AZ114,99),IFERROR((IF(ISNUMBER(Model!BE150),IF(Model!BE150>0,Model!BE150,Model!BE126),Model!BE126)+Model!BE176+Model!BE177)/Model!BE114,99),IFERROR((IF(ISNUMBER(Model!BJ150),IF(Model!BJ150>0,Model!BJ150,Model!BJ126),Model!BJ126)+Model!BJ176+Model!BJ177)/Model!BJ114,99),IFERROR((IF(ISNUMBER(Model!BO150),IF(Model!BO150>0,Model!BO150,Model!BO126),Model!BO126)+Model!BO176+Model!BO177)/Model!BO114,99),IFERROR((IF(ISNUMBER(Model!BT150),IF(Model!BT150>0,Model!BT150,Model!BT126),Model!BT126)+Model!BT176+Model!BT177)/Model!BT114,99),IFERROR((IF(ISNUMBER(Model!BY150),IF(Model!BY150>0,Model!BY150,Model!BY126),Model!BY126)+Model!BY176+Model!BY177)/Model!BY114,99),IFERROR((IF(ISNUMBER(Model!CD150),IF(Model!CD150>0,Model!CD150,Model!CD126),Model!CD126)+Model!CD176+Model!CD177)/Model!CD114,99)) -> 0.12528449 | L36: =MAX(IFERROR((IF(ISNUMBER(Model!AF150),IF(Model!AF150>0,Model!AF150,Model!AF126),Model!AF126)+Model!AF176+Model!AF177)/Model!AF114,-99),IFERROR((IF(ISNUMBER(Model!AK150),IF(Model!AK150>0,Model!AK150,Model!AK126),Model!AK126)+Model!AK176+Model!AK177)/Model!AK114,-99),IFERROR((IF(ISNUMBER(Model!AP150),IF(Model!AP150>0,Model!AP150,Model!AP126),Model!AP126)+Model!AP176+Model!AP177)/Model!AP114,-99),IFERROR((IF(ISNUMBER(Model!AU150),IF(Model!AU150>0,Model!AU150,Model!AU126),Model!AU126)+Model!AU176+Model!AU177)/Model!AU114,-99),IFERROR((IF(ISNUMBER(Model!AZ150),IF(Model!AZ150>0,Model!AZ150,Model!AZ126),Model!AZ126)+Model!AZ176+Model!AZ177)/Model!AZ114,-99),IFERROR((IF(ISNUMBER(Model!BE150),IF(Model!BE150>0,Model!BE150,Model!BE126),Model!BE126)+Model!BE176+Model!BE177)/Model!BE114,-99),IFERROR((IF(ISNUMBER(Model!BJ150),IF(Model!BJ150>0,Model!BJ150,Model!BJ126),Model!BJ126)+Model!BJ176+Model!BJ177)/Model!BJ114,-99),IFERROR((IF(ISNUMBER(Model!BO150),IF(Model!BO150>0,Model!BO150,Model!BO126),Model!BO126)+Model!BO176+Model!BO177)/Model!BO114,-99),IFERROR((IF(ISNUMBER(Model!BT150),IF(Model!BT150>0,Model!BT150,Model!BT126),Model!BT126)+Model!BT176+Model!BT177)/Model!BT114,-99),IFERROR((IF(ISNUMBER(Model!BY150),IF(Model!BY150>0,Model!BY150,Model!BY126),Model!BY126)+Model!BY176+Model!BY177)/Model!BY114,-99),IFERROR((IF(ISNUMBER(Model!CD150),IF(Model!CD150>0,Model!CD150,Model!CD126),Model!CD126)+Model!CD176+Model!CD177)/Model!CD114,-99)) -> 0.15670938 | N36: EBITDA % | O36: 0.15670938 | P36: 0.14687798 | Q36: 0.14987453 | R36: 0.15370291 | S36: 0.16049765 | T36: 0.16756612 | V36: 0.13674468 | W36: 0.12528449 | X36: 0.15670938 | Z36: EBITDA % | AA36: 0.15670938 | AB36: 0.14687798 | AC36: 0.15008991 | AD36: 0.15395258 | AE36: 0.16071975 | AF36: 0.16774344 | AH36: 0.13674468 | AI36: 0.12528449 | AJ36: 0.15670938
B38: Net Debt | C38: =Model!CD331 -> 883.473 | D38: =Model!CI331 -> 833.94734 | E38: =Model!CJ331 -> 724.25125 | F38: =Model!CK331 -> 530.27838 | G38: =Model!CL331 -> 297.57845 | H38: =Model!CM331 -> 52.60119 | N38: Net Debt | O38: 883.473 | P38: 833.49973 | Q38: 747.61427 | R38: 558.13657 | S38: 313.85226 | T38: 46.781922 | Z38: Net Debt | AA38: 883.473 | AB38: 833.49973 | AC38: 683.48142 | AD38: 470.75747 | AE38: 239.31098 | AF38: 13.449972
B39: Net Debt / EBITDA (x) | C39: =IFERROR(C38/C35,"") -> 1.4602956 | D39: =IFERROR(D38/D35,"") -> 1.3312631 | E39: =IFERROR(E38/E35,"") -> 1.0470898 | F39: =IFERROR(F38/F35,"") -> 0.69846726 | G39: =IFERROR(G38/G35,"") -> 0.35255538 | H39: =IFERROR(H38/H35,"") -> 0.056218145 | N39: Net Debt / EBITDA (x) | O39: 1.4602956 | P39: 1.3305486 | Q39: 1.0527897 | R39: 0.70157257 | S39: 0.34886881 | T39: 0.04616655 | Z39: Net Debt / EBITDA (x) | AA39: 1.4602956 | AB39: 1.3305486 | AC39: 1.0299503 | AD39: 0.67117287 | AE39: 0.31787957 | AF39: 0.016627695
B41: ROIC | C41: =Model!CD332 -> 0.13102097 | D41: =Model!CI332 -> 0.12994009 | E41: =Model!CJ332 -> 0.14017825 | F41: =Model!CK332 -> 0.15132045 | G41: =Model!CL332 -> 0.16501807 | H41: =Model!CM332 -> 0.17672425 | J41: =AVERAGE(Model!AF332,Model!AK332,Model!AP332,Model!AU332,Model!AZ332,Model!BE332,Model!BJ332,Model!BO332,Model!BT332,Model!BY332,Model!CD332) -> 0.10649688 | K41: =MIN(Model!AF332,Model!AK332,Model!AP332,Model!AU332,Model!AZ332,Model!BE332,Model!BJ332,Model!BO332,Model!BT332,Model!BY332,Model!CD332) -> 0.078655447 | L41: =MAX(Model!AF332,Model!AK332,Model!AP332,Model!AU332,Model!AZ332,Model!BE332,Model!BJ332,Model!BO332,Model!BT332,Model!BY332,Model!CD332) -> 0.13418059 | N41: ROIC | O41: 0.13102097 | P41: 0.12994009 | Q41: 0.14220323 | R41: 0.15521947 | S41: 0.17077484 | T41: 0.18424991 | V41: 0.10649688 | W41: 0.078655447 | X41: 0.13418059 | Z41: ROIC | AA41: 0.13102097 | AB41: 0.12994009 | AC41: 0.13700201 | AD41: 0.14475876 | AE41: 0.15476995 | AF41: 0.16309349 | AH41: 0.10649688 | AI41: 0.078655447 | AJ41: 0.13418059
B42: RONTA | C42: =Model!CD346 -> 0.16117724 | D42: =Model!CI346 -> 0.15804571 | E42: =Model!CJ346 -> 0.16882625 | F42: =Model!CK346 -> 0.18092714 | G42: =Model!CL346 -> 0.1956496 | H42: =Model!CM346 -> 0.20725913 | J42: =AVERAGE(Model!AF346,Model!AK346,Model!AP346,Model!AU346,Model!AZ346,Model!BE346,Model!BJ346,Model!BO346,Model!BT346,Model!BY346,Model!CD346) -> 0.14509836 | K42: =MIN(Model!AF346,Model!AK346,Model!AP346,Model!AU346,Model!AZ346,Model!BE346,Model!BJ346,Model!BO346,Model!BT346,Model!BY346,Model!CD346) -> 0.11691297 | L42: =MAX(Model!AF346,Model!AK346,Model!AP346,Model!AU346,Model!AZ346,Model!BE346,Model!BJ346,Model!BO346,Model!BT346,Model!BY346,Model!CD346) -> 0.17231893 | N42: RONTA | O42: 0.16117724 | P42: 0.15804571 | Q42: 0.17083277 | R42: 0.18476789 | S42: 0.2012659 | T42: 0.21449288 | V42: 0.14509836 | W42: 0.11691297 | X42: 0.17231893 | Z42: RONTA | AA42: 0.16117724 | AB42: 0.15804571 | AC42: 0.16565843 | AD42: 0.17438244 | AE42: 0.18547154 | AF42: 0.19387151 | AH42: 0.14509836 | AI42: 0.11691297 | AJ42: 0.17231893
B44: Implied Market Cap ($M) | E44: =E27*E21/1000 -> 0 | F44: =F27*F21/1000 -> 8597.7341 | G44: =G27*G21/1000 -> 9802.1328 | H44: =H27*H21/1000 -> 11120.797 | N44: Implied Market Cap ($M) | Q44: 8714.9364 | R44: 10038.82 | S44: 11680.45 | T44: 13478.276 | Z44: Implied Market Cap ($M) | AC44: 6607.0032 | AD44: 7146.4369 | AE44: 7876.1743 | AF44: 8665.8241
B45: (+) Net Debt | E45: =E38 -> 724.25125 | F45: =F38 -> 530.27838 | G45: =G38 -> 297.57845 | H45: =H38 -> 52.60119 | N45: (+) Net Debt | Q45: 747.61427 | R45: 558.13657 | S45: 313.85226 | T45: 46.781922 | Z45: (+) Net Debt | AC45: 683.48142 | AD45: 470.75747 | AE45: 239.31098 | AF45: 13.449972
B46: Implied Enterprise Value ($M) | E46: =E44+E45 -> 724.25125 | F46: =F44+F45 -> 9128.0125 | G46: =G44+G45 -> 10099.711 | H46: =H44+H45 -> 11173.398 | N46: Implied Enterprise Value ($M) | Q46: 9462.5506 | R46: 10596.957 | S46: 11994.302 | T46: 13525.058 | Z46: Implied Enterprise Value ($M) | AC46: 7290.4846 | AD46: 7617.1944 | AE46: 8115.4853 | AF46: 8679.2741
B47: Implied EV / EBITDA (x) | E47: =IFERROR(E46/E35,"") -> 1.0470898 | F47: =IFERROR(F46/F35,"") -> 12.023153 | G47: =IFERROR(G46/G35,"") -> 11.965609 | H47: =IFERROR(H46/H35,"") -> 11.941702 | N47: Implied EV / EBITDA (x) | Q47: 13.325155 | R47: 13.320278 | S47: 13.332509 | T47: 13.347149 | Z47: Implied EV / EBITDA (x) | AC47: 10.986161 | AD47: 10.86006 | AE47: 10.779894 | AF47: 10.72986

Sheet Moog-DCF
B2: DCF VALUATION — Moog Inc.
B4: 1. WACC BUILD
B5: Risk-free rate (US 10Y govt) | C5: 0.043 | D5: US 10Y Treasury
B6: Equity risk premium | C6: 0.055 | D6: Damodaran global ERP estimate
B7: Levered beta | C7: 1.02 | D7: Moog reported beta ~0.9-1.0; industrial A&D peer median
B8: Cost of equity | C8: =C5+C7*C6 -> 0.0991
B9: Pre-tax cost of debt | C9: 0.05 | D9: Moog senior notes 5-7Y yield
B10: Tax rate | C10: 0.24 | D10: Long-run normalised effective tax rate
B11: After-tax cost of debt | C11: =C9*(1-C10) -> 0.038
B12: Target D/V | C12: 0.2 | D12: Target leverage; net debt / total capital
B13: WACC | C13: =C8*(1-C12)+C11*C12 -> 0.08688
B15: Valuation date (live) | C15: =TODAY() -> 46169
B16: 2. UNLEVERED FREE CASH FLOW BUILD (explicit FY26-FY30, fade FY31-FY40 over CAP = C68 years)
D17: FY26E | E17: FY27E | F17: FY28E | G17: FY29E | H17: FY30E | I17: FY31E | J17: FY32E | K17: FY33E | L17: FY34E | M17: FY35E | N17: FY36E | O17: FY37E | P17: FY38E | Q17: FY39E | R17: FY40E | S17: Terminal | T17: FY26E-40E CAGR
B18: EBIT before special items | D18: =IF(ISNUMBER(Model!CI150),IF(Model!CI150>0,Model!CI150,Model!CI126),Model!CI126) -> 511.84054 | E18: =IF(ISNUMBER(Model!CJ150),IF(Model!CJ150>0,Model!CJ150,Model!CJ126),Model!CJ126) -> 567.74948 | F18: =IF(ISNUMBER(Model!CK150),IF(Model!CK150>0,Model!CK150,Model!CK126),Model!CK126) -> 626.56643 | G18: =IF(ISNUMBER(Model!CL150),IF(Model!CL150>0,Model!CL150,Model!CL126),Model!CL126) -> 702.82692 | H18: =IF(ISNUMBER(Model!CM150),IF(Model!CM150>0,Model!CM150,Model!CM126),Model!CM126) -> 785.68656 | I18: =H18*(1+(H18/G18-1)+(($C$27-(H18/G18-1))*1/10)) -> 871.80199 | J18: =I18*(1+(H18/G18-1)+(($C$27-(H18/G18-1))*2/10)) -> 960.12935 | K18: =J18*(1+(H18/G18-1)+(($C$27-(H18/G18-1))*3/10)) -> 1049.4467 | L18: =K18*(1+(H18/G18-1)+(($C$27-(H18/G18-1))*4/10)) -> 1138.3735 | M18: =L18*(1+(H18/G18-1)+(($C$27-(H18/G18-1))*5/10)) -> 1225.3992 | N18: =M18*(1+(H18/G18-1)+(($C$27-(H18/G18-1))*6/10)) -> 1308.9199 | O18: =N18*(1+(H18/G18-1)+(($C$27-(H18/G18-1))*7/10)) -> 1387.2829 | P18: =O18*(1+(H18/G18-1)+(($C$27-(H18/G18-1))*8/10)) -> 1458.8375 | Q18: =P18*(1+(H18/G18-1)+(($C$27-(H18/G18-1))*9/10)) -> 1521.9898 | R18: =Q18*(1+$C$27) -> 1575.2595 | T18: =IFERROR((R18/D18)^(1/14)-1,"n/m") -> 0.083609173
B19: × (1 − tax rate) | D19: =1-$C$10 -> 0.76 | E19: =1-$C$10 -> 0.76 | F19: =1-$C$10 -> 0.76 | G19: =1-$C$10 -> 0.76 | H19: =1-$C$10 -> 0.76 | I19: =1-$C$10 -> 0.76 | J19: =1-$C$10 -> 0.76 | K19: =1-$C$10 -> 0.76 | ... R19: =1-$C$10 -> 0.76
B20: NOPAT | D20: =D18*D19 -> 388.99881 | E20: =E18*E19 -> 431.4896 | F20: =F18*F19 -> 476.19048 | G20: =G18*G19 -> 534.14846 | H20: =H18*H19 -> 597.12179 | I20: =I18*I19 -> 662.56952 | J20: =J18*J19 -> 729.69831 | K20: =K18*K19 -> 797.57949 | ... R20: =R18*R19 -> 1197.1972 | T20: =IFERROR((R20/D20)^(1/14)-1,"n/m") -> 0.083609173
B21: plus D&A | D21: =Model!CI176+Model!CI177 -> 114.59259 | E21: =Model!CJ176+Model!CJ177 -> 123.93068 | F21: =Model!CK176+Model!CK177 -> 132.63649 | G21: =Model!CL176+Model!CL177 -> 141.23466 | H21: =Model!CM176+Model!CM177 -> 149.97558 | I21: =H21*(I18/H18) -> 166.4137 | J21: =I21*(J18/I18) -> 183.27404 | K21: =J21*(K18/J18) -> 200.32336 | L21: =K21*(L18/K18) -> 217.29814 | M21: =L21*(M18/L18) -> 233.91002 | N21: =M21*(N18/M18) -> 249.85284 | O21: =N21*(O18/N18) -> 264.81114 | P21: =O21*(P18/O18) -> 278.46982 | ... R21: =Q21*(R18/Q18) -> 300.693
B22: − Capex (PP&E + intangibles) | D22: =-ABS(Model!CI189) -> -159.89029 | E22: =-ABS(Model!CJ189) -> -172.91967 | F22: =-ABS(Model!CK189) -> -185.06682 | G22: =-ABS(Model!CL189) -> -197.06379 | H22: =-ABS(Model!CM189) -> -209.25994 | I22: =H22*(I18/H18) -> -232.19595 | J22: =I22*(J18/I18) -> -255.72107 | K22: =J22*(K18/J18) -> -279.50988 | L22: =K22*(L18/K18) -> -303.19467 | M22: =L22*(M18/L18) -> -326.37312 | N22: =M22*(N18/M18) -> -348.61803 | O22: =N22*(O18/N18) -> -369.48925 | P22: =O22*(P18/O18) -> -388.54712 | ... R22: =Q22*(R18/Q18) -> -419.55497
B23: − Δ Working capital | D23: =Model!CI180+Model!CI181+Model!CI182+Model!CI183+Model!CI184 -> -67.35243 | E23: =Model!CJ180+Model!CJ181+Model!CJ182+Model!CJ183+Model!CJ184 -> -50.733396 | F23: =Model!CK180+Model!CK181+Model!CK182+Model!CK183+Model!CK184 -> -11.773445 | G23: =Model!CL180+Model!CL181+Model!CL182+Model!CL183+Model!CL184 -> -29.770872 | H23: =Model!CM180+Model!CM181+Model!CM182+Model!CM183+Model!CM184 -> -78.57375 | I23: =H23*(I18/H18) -> -87.185852 | J23: =I23*(J18/I18) -> -96.01916 | K23: =J23*(K18/J18) -> -104.95147 | L23: =K23*(L18/K18) -> -113.84473 | M23: =L23*(M18/L18) -> -122.54787 | N23: =M23*(N18/M18) -> -130.90048 | O23: =N23*(O18/N18) -> -138.73728 | P23: =O23*(P18/O18) -> -145.89321 | ... R23: =Q23*(R18/Q18) -> -157.53616
B24: Unlevered FCF | D24: =D20+D21+D22+D23 -> 276.34868 | E24: =E20+E21+E22+E23 -> 331.76722 | F24: =F20+F21+F22+F23 -> 411.9867 | G24: =G20+G21+G22+G23 -> 448.54845 | H24: =H20+H21+H22+H23 -> 459.26367 | I24: =I20+I21+I22+I23 -> 509.60142 | J24: =J20+J21+J22+J23 -> 561.23211 | K24: =K20+K21+K22+K23 -> 613.4415 | ... R24: =R20+R21+R22+R23 -> 920.79906 | S24: =R24*(1+$C$27) -> 953.02703 | T24: =IFERROR((R24/D24)^(1/14)-1,"n/m") -> 0.089773513
B25: Terminal Value (Gordon Growth) | S25: =S24/($C$13-$C$27) -> 18369.835
B27: Terminal growth rate | C27: 0.035
B29: Discount period (year #) | D29: =(DATE(2026+0,12,31)-$C$15)/365.25 -> 0.59685147 | E29: =(DATE(2026+1,12,31)-$C$15)/365.25 -> 1.596167 | F29: =(DATE(2026+2,12,31)-$C$15)/365.25 -> 2.5982204 | G29: =(DATE(2026+3,12,31)-$C$15)/365.25 -> 3.5975359 | H29: =(DATE(2026+4,12,31)-$C$15)/365.25 -> 4.5968515 | I29: =(DATE(2031,12,31)-$C$15)/365.25 -> 5.596167 | J29: =(DATE(2032,12,31)-$C$15)/365.25 -> 6.5982204 | K29: =(DATE(2033,12,31)-$C$15)/365.25 -> 7.5975359 | L29: =(DATE(2034,12,31)-$C$15)/365.25 -> 8.5968515 | M29: =(DATE(2035,12,31)-$C$15)/365.25 -> 9.596167 | N29: =(DATE(2036,12,31)-$C$15)/365.25 -> 10.59822 | O29: =(DATE(2037,12,31)-$C$15)/365.25 -> 11.597536 | P29: =(DATE(2038,12,31)-$C$15)/365.25 -> 12.596851 | Q29: =(DATE(2039,12,31)-$C$15)/365.25 -> 13.596167 | R29: =(DATE(2040,12,31)-$C$15)/365.25 -> 14.59822 | S29: =R29 -> 14.59822
B30: Discount factor | D30: =1/(1+$C$13)^D29 -> 0.9514916 | E30: =1/(1+$C$13)^E29 -> 0.87548383 | F30: =1/(1+$C$13)^F29 -> 0.80536404 | G30: =1/(1+$C$13)^G29 -> 0.74102934 | H30: =1/(1+$C$13)^H29 -> 0.68183387 | I30: =1/(1+$C$13)^I29 -> 0.6273671 | J30: =1/(1+$C$13)^J29 -> 0.57711963 | K30: =1/(1+$C$13)^K29 -> 0.53101772 | ... S30: =1/(1+$C$13)^S29 -> 0.29635555
B31: PV of UFCF | D31: =D24*D30 -> 262.94345 | E31: =E24*E30 -> 290.45684 | F31: =F24*F30 -> 331.79928 | G31: =G24*G30 -> 332.38756 | H31: =H24*H30 -> 313.14153 | I31: =I24*I30 -> 319.70716 | J31: =J24*J30 -> 323.89807 | K31: =K24*K30 -> 325.74831 | ... R31: =R24*R30 -> 272.88391 | S31: =S25*S30 -> 5444.0025
B34: 3. VALUATION SUMMARY
B35: Sum of PV (explicit + fade) | C35: =SUM(D31:R31) -> 4630.2895
B36: PV of Terminal Value | C36: =S31 -> 5444.0025
B37: Enterprise Value | C37: =C35+C36 -> 10074.292
B38: Less: Net debt (Model FY26E YE) | C38: =Model!CI331 -> 833.94734
B39: Equity Value | C39: =C37-C38 -> 9240.3447
B40: Diluted shares ('000) | C40: =Model!CI139 -> 31647.818
B41: Implied share price ($) | C41: =C39*1000/C40 -> 291.97414
B42: Current share price ($) | C42: 345
B43: Implied upside / (downside) | C43: =C41/C42-1 -> -0.15369813
B46: 4. SENSITIVITY: IMPLIED PRICE — WACC × Terminal Growth
B48: WACC (across):
B49: g (down) / WACC → | D49: 0.07 | E49: 0.075 | F49: 0.08 | G49: 0.085 | H49: 0.09
B50: 0.02 | D50: {=IFERROR((SUMPRODUCT($D$24:$M$24/(1+D$49)^$D$29:$M$29)+($M$24*(1+$B50)/(D$49-$B50))/(1+D$49)^$M$29-$C$38)*1000/$C$40,"")} -> 322.86878 | E50: {=IFERROR((SUMPRODUCT($D$24:$M$24/(1+E$49)^$D$29:$M$29)+($M$24*(1+$B50)/(E$49-$B50))/(1+E$49)^$M$29-$C$38)*1000/$C$40,"")} -> 288.701 | F50: {=IFERROR((SUMPRODUCT($D$24:$M$24/(1+F$49)^$D$29:$M$29)+($M$24*(1+$B50)/(F$49-$B50))/(1+F$49)^$M$29-$C$38)*1000/$C$40,"")} -> 260.30422 | G50: {=IFERROR((SUMPRODUCT($D$24:$M$24/(1+G$49)^$D$29:$M$29)+($M$24*(1+$B50)/(G$49-$B50))/(1+G$49)^$M$29-$C$38)*1000/$C$40,"")} -> 236.34392 | H50: {=IFERROR((SUMPRODUCT($D$24:$M$24/(1+H$49)^$D$29:$M$29)+($M$24*(1+$B50)/(H$49-$B50))/(1+H$49)^$M$29-$C$38)*1000/$C$40,"")} -> 215.86696
...

Sheet Moog-Charts
B2: Moog Inc. — Historical Operating Performance (FY15–FY25)
B3: All historicals · $M · Linked to Model.
C7: 2015 | D7: 2016 | E7: 2017 | F7: 2018 | G7: 2019 | H7: 2020 | I7: 2021 | J7: 2022 | K7: 2023 | L7: 2024 | M7: 2025
B8: Revenue y/y % | C8: 0 | D8: =IFERROR(Model!AK114/Model!AF114-1,"") -> -0.044978642 | E8: =IFERROR(Model!AP114/Model!AK114-1,"") -> 0.035484758 | F8: =IFERROR(Model!AU114/Model!AP114-1,"") -> 0.084861647 | G8: =IFERROR(Model!AZ114/Model!AU114-1,"") -> 0.072041818 | H8: =IFERROR(Model!BE114/Model!AZ114-1,"") -> -0.0069230062 | I8: =IFERROR(Model!BJ114/Model!BE114-1,"") -> -0.011288054 | J8: =IFERROR(Model!BO114/Model!BJ114-1,"") -> 0.064442655 | K8: =IFERROR(Model!BT114/Model!BO114-1,"") -> 0.092367274 | L8: =IFERROR(Model!BY114/Model!BT114-1,"") -> 0.08828505 | M8: =IFERROR(Model!CD114/Model!BY114-1,"") -> 0.069733109
B11: Year | C11: 2015 | D11: 2016 | E11: 2017 | F11: 2018 | G11: 2019 | H11: 2020 | I11: 2021 | J11: 2022 | K11: 2023 | L11: 2024 | M11: 2025
B12: Gross Profit ($M) | C12: =Model!AF116 -> 736.704 | D12: =Model!AK116 -> 711.583 | E12: =Model!AP116 -> 731.522 | F12: =Model!AU116 -> 774.091 | G12: =Model!AZ116 -> 815.832 | H12: =Model!BE116 -> 743.696 | I12: =Model!BJ116 -> 775.723 | J12: =Model!BO116 -> 820.801 | K12: =Model!BT116 -> 897.755 | L12: =Model!BY116 -> 1012.408 | M12: =Model!CD116 -> 1057.348
B13: Adj EBIT ($M) | C13: =IF(ISNUMBER(Model!AF150),IF(Model!AF150>0,Model!AF150,Model!AF126),Model!AF126) -> 212.801 | D13: =IF(ISNUMBER(Model!AK150),IF(Model!AK150>0,Model!AK150,Model!AK126),Model!AK126) -> 204.1 | E13: =IF(ISNUMBER(Model!AP150),IF(Model!AP150>0,Model!AP150,Model!AP126),Model!AP126) -> 250.152 | F13: =IF(ISNUMBER(Model!AU150),IF(Model!AU150>0,Model!AU150,Model!AU126),Model!AU126) -> 294.534 | G13: =IF(ISNUMBER(Model!AZ150),IF(Model!AZ150>0,Model!AZ150,Model!AZ126),Model!AZ126) -> 321.142 | H13: =IF(ISNUMBER(Model!BE150),IF(Model!BE150>0,Model!BE150,Model!BE126),Model!BE126) -> 287.609 | I13: =IF(ISNUMBER(Model!BJ150),IF(Model!BJ150>0,Model!BJ150,Model!BJ126),Model!BJ126) -> 277.863 | J13: =IF(ISNUMBER(Model!BO150),IF(Model!BO150>0,Model!BO150,Model!BO126),Model!BO126) -> 308.279 | K13: =IF(ISNUMBER(Model!BT150),IF(Model!BT150>0,Model!BT150,Model!BT126),Model!BT126) -> 361.806 | L13: =IF(ISNUMBER(Model!BY150),IF(Model!BY150>0,Model!BY150,Model!BY126),Model!BY126) -> 457.862 | M13: =IF(ISNUMBER(Model!CD150),IF(Model!CD150>0,Model!CD150,Model!CD126),Model!CD126) -> 501.268
B14: Gross margin % | C14: =IFERROR(Model!AF116/Model!AF114,"") -> 0.2917025 | D14: =IFERROR(Model!AK116/Model!AK114,"") -> 0.29502553 | E14: =IFERROR(Model!AP116/Model!AP114,"") -> 0.29289889 | F14: =IFERROR(Model!AU116/Model!AU114,"") -> 0.28569852 | G14: =IFERROR(Model!AZ116/Model!AZ114,"") -> 0.28086976 | H14: =IFERROR(Model!BE116/Model!BE114,"") -> 0.2578201 | I14: =IFERROR(Model!BJ116/Model!BJ114,"") -> 0.2719933 | J14: =IFERROR(Model!BO116/Model!BO114,"") -> 0.27037539 | K14: =IFERROR(Model!BT116/Model!BT114,"") -> 0.27071881 | L14: =IFERROR(Model!BY116/Model!BY114,"") -> 0.28052625 | M14: =IFERROR(Model!CD116/Model!CD114,"") -> 0.27388008
B15: Adj EBIT margin % | C15: =IFERROR(IF(ISNUMBER(Model!AF150),IF(Model!AF150>0,Model!AF150,Model!AF126),Model!AF126)/Model!AF114,"") -> 0.084259871 | D15: =IFERROR(IF(ISNUMBER(Model!AK150),IF(Model!AK150>0,Model!AK150,Model!AK126),Model!AK126)/Model!AK114,"") -> 0.084620784 | E15: =IFERROR(IF(ISNUMBER(Model!AP150),IF(Model!AP150>0,Model!AP150,Model!AP126),Model!AP126)/Model!AP114,"") -> 0.10016 | F15: =IFERROR(IF(ISNUMBER(Model!AU150),IF(Model!AU150>0,Model!AU150,Model!AU126),Model!AU126)/Model!AU114,"") -> 0.10870547 | G15: =IFERROR(IF(ISNUMBER(Model!AZ150),IF(Model!AZ150>0,Model!AZ150,Model!AZ126),Model!AZ126)/Model!AZ114,"") -> 0.11056085 | H15: =IFERROR(IF(ISNUMBER(Model!BE150),IF(Model!BE150>0,Model!BE150,Model!BE126),Model!BE126)/Model!BE114,"") -> 0.099706575 | I15: =IFERROR(IF(ISNUMBER(Model!BJ150),IF(Model!BJ150>0,Model!BJ150,Model!BJ126),Model!BJ126)/Model!BJ114,"") -> 0.097427658 | J15: =IFERROR(IF(ISNUMBER(Model!BO150),IF(Model!BO150>0,Model!BO150,Model!BO126),Model!BO126)/Model!BO114,"") -> 0.10154843 | K15: =IFERROR(IF(ISNUMBER(Model!BT150),IF(Model!BT150>0,Model!BT150,Model!BT126),Model!BT126)/Model!BT114,"") -> 0.10910292 | L15: =IFERROR(IF(ISNUMBER(Model!BY150),IF(Model!BY150>0,Model!BY150,Model!BY126),Model!BY126)/Model!BY114,"") -> 0.12686813 | M15: =IFERROR(IF(ISNUMBER(Model!CD150),IF(Model!CD150>0,Model!CD150,Model!CD126),Model!CD126)/Model!CD114,"") -> 0.12984119
B17: Year | C17: 2015 | D17: 2016 | E17: 2017 | F17: 2018 | G17: 2019 | H17: 2020 | I17: 2021 | J17: 2022 | K17: 2023 | L17: 2024 | M17: 2025
B18: ROIC | C18: =IFERROR(Model!AF332,NA()) -> 0.086747663 | D18: =IFERROR(Model!AK332,NA()) -> 0.08644435 | E18: =IFERROR(Model!AP332,NA()) -> 0.10728565 | F18: =IFERROR(Model!AU332,NA()) -> 0.078655447 | G18: =IFERROR(Model!AZ332,NA()) -> 0.11954878 | H18: =IFERROR(Model!BE332,NA()) -> 0.10329086 | I18: =IFERROR(Model!BJ332,NA()) -> 0.097316191 | J18: =IFERROR(Model!BO332,NA()) -> 0.1092484 | K18: =IFERROR(Model!BT332,NA()) -> 0.11772679 | L18: =IFERROR(Model!BY332,NA()) -> 0.13418059 | M18: =IFERROR(Model!CD332,NA()) -> 0.13102097
B19: RONTA | C19: =IFERROR(Model!AF346,NA()) -> 0.11831713 | D19: =IFERROR(Model!AK346,NA()) -> 0.11691297 | E19: =IFERROR(Model!AP346,NA()) -> 0.15983766 | F19: =IFERROR(Model!AU346,NA()) -> 0.121688 | G19: =IFERROR(Model!AZ346,NA()) -> 0.17231893 | H19: =IFERROR(Model!BE346,NA()) -> 0.1415721 | I19: =IFERROR(Model!BJ346,NA()) -> 0.13520954 | J19: =IFERROR(Model!BO346,NA()) -> 0.14857474 | K19: =IFERROR(Model!BT346,NA()) -> 0.15213141 | L19: =IFERROR(Model!BY346,NA()) -> 0.16834227 | M19: =IFERROR(Model!CD346,NA()) -> 0.16117724
B20: EBIT / GP (conv ratio) | C20: =IFERROR(IF(ISNUMBER(Model!AF150),IF(Model!AF150>0,Model!AF150,Model!AF126),Model!AF126)/Model!AF116,NA()) -> 0.2888555 | D20: =IFERROR(IF(ISNUMBER(Model!AK150),IF(Model!AK150>0,Model!AK150,Model!AK126),Model!AK126)/Model!AK116,NA()) -> 0.28682529 | E20: =IFERROR(IF(ISNUMBER(Model!AP150),IF(Model!AP150>0,Model!AP150,Model!AP126),Model!AP126)/Model!AP116,NA()) -> 0.34196101 | F20: =IFERROR(IF(ISNUMBER(Model!AU150),IF(Model!AU150>0,Model!AU150,Model!AU126),Model!AU126)/Model!AU116,NA()) -> 0.38049015 | G20: =IFERROR(IF(ISNUMBER(Model!AZ150),IF(Model!AZ150>0,Model!AZ150,Model!AZ126),Model!AZ126)/Model!AZ116,NA()) -> 0.39363742 | H20: =IFERROR(IF(ISNUMBER(Model!BE150),IF(Model!BE150>0,Model!BE150,Model!BE126),Model!BE126)/Model!BE116,NA()) -> 0.38672925 | I20: =IFERROR(IF(ISNUMBER(Model!BJ150),IF(Model!BJ150>0,Model!BJ150,Model!BJ126),Model!BJ126)/Model!BJ116,NA()) -> 0.35819874 | J20: =IFERROR(IF(ISNUMBER(Model!BO150),IF(Model!BO150>0,Model!BO150,Model!BO126),Model!BO126)/Model!BO116,NA()) -> 0.37558312 | K20: =IFERROR(IF(ISNUMBER(Model!BT150),IF(Model!BT150>0,Model!BT150,Model!BT126),Model!BT126)/Model!BT116,NA()) -> 0.40301196 | L20: =IFERROR(IF(ISNUMBER(Model!BY150),IF(Model!BY150>0,Model!BY150,Model!BY126),Model!BY126)/Model!BY116,NA()) -> 0.45225048 | M20: =IFERROR(IF(ISNUMBER(Model!CD150),IF(Model!CD150>0,Model!CD150,Model!CD126),Model!CD126)/Model!CD116,NA()) -> 0.47408044
B21: Incremental EBIT margin | D21: =IFERROR((IF(ISNUMBER(Model!AK150),IF(Model!AK150>0,Model!AK150,Model!AK126),Model!AK126)-IF(ISNUMBER(Model!AF150),IF(Model!AF150>0,Model!AF150,Model!AF126),Model!AF126))/(Model!AK114-Model!AF114),NA()) -> 0.076596681 | E21: =IFERROR((IF(ISNUMBER(Model!AP150),IF(Model!AP150>0,Model!AP150,Model!AP126),Model!AP126)-IF(ISNUMBER(Model!AK150),IF(Model!AK150>0,Model!AK150,Model!AK126),Model!AK126))/(Model!AP114-Model!AK114),NA()) -> 0.53807237 | F21: =IFERROR((IF(ISNUMBER(Model!AU150),IF(Model!AU150>0,Model!AU150,Model!AU126),Model!AU126)-IF(ISNUMBER(Model!AP150),IF(Model!AP150>0,Model!AP150,Model!AP126),Model!AP126))/(Model!AU114-Model!AP114),NA()) -> 0.20940437 | G21: =IFERROR((IF(ISNUMBER(Model!AZ150),IF(Model!AZ150>0,Model!AZ150,Model!AZ126),Model!AZ126)-IF(ISNUMBER(Model!AU150),IF(Model!AU150>0,Model!AU150,Model!AU126),Model!AU126))/(Model!AZ114-Model!AU114),NA()) -> 0.13631497 | H21: =IFERROR((IF(ISNUMBER(Model!BE150),IF(Model!BE150>0,Model!BE150,Model!BE126),Model!BE126)-IF(ISNUMBER(Model!AZ150),IF(Model!AZ150>0,Model!AZ150,Model!AZ126),Model!AZ126))/(Model!BE114-Model!AZ114),NA()) -> 1.6675618 | I21: =IFERROR((IF(ISNUMBER(Model!BJ150),IF(Model!BJ150>0,Model!BJ150,Model!BJ126),Model!BJ126)-IF(ISNUMBER(Model!BE150),IF(Model!BE150>0,Model!BE150,Model!BE126),Model!BE126))/(Model!BJ114-Model!BE114),NA()) -> 0.29931513 | J21: =IFERROR((IF(ISNUMBER(Model!BO150),IF(Model!BO150>0,Model!BO150,Model!BO126),Model!BO126)-IF(ISNUMBER(Model!BJ150),IF(Model!BJ150>0,Model!BJ150,Model!BJ126),Model!BJ126))/(Model!BO114-Model!BJ114),NA()) -> 0.16549323 | K21: =IFERROR((IF(ISNUMBER(Model!BT150),IF(Model!BT150>0,Model!BT150,Model!BT126),Model!BT126)-IF(ISNUMBER(Model!BO150),IF(Model!BO150>0,Model!BO150,Model!BO126),Model!BO126))/(Model!BT114-Model!BO114),NA()) -> 0.19089038 | L21: =IFERROR((IF(ISNUMBER(Model!BY150),IF(Model!BY150>0,Model!BY150,Model!BY126),Model!BY126)-IF(ISNUMBER(Model!BT150),IF(Model!BT150>0,Model!BT150,Model!BT126),Model!BT126))/(Model!BY114-Model!BT114),NA()) -> 0.32809373 | M21: =IFERROR((IF(ISNUMBER(Model!CD150),IF(Model!CD150>0,Model!CD150,Model!CD126),Model!CD126)-IF(ISNUMBER(Model!BY150),IF(Model!BY150>0,Model!BY150,Model!BY126),Model!BY126))/(Model!CD114-Model!BY114),NA()) -> 0.172476

Sheet Model_DSV_ref
B2: DSV A/S — 3-Statement Financial Model | BU2: SCENARIO → | BV2: Base
B3: IFRS as reported · DKK millions · Source: DSV Annual Reports 2018–2025 (investor.dsv.com/download-library)
B4: Schenker acquisition closed 30 April 2025 — figures from Q2 2025 onward include Schenker contribution and are not directly comparable to prior periods.
BX5: Forecast | BY5: Historical | BZ5: Historical
B6: (DKKm) | C6: Q1/15 | D6: Q2/15 | E6: 1H/15 | F6: Q3/15 | G6: Q4/15 | H6: 2015 | I6: Q1/16 | J6: Q2/16 | K6: 1H/16 | L6: Q3/16 | M6: Q4/16 | N6: 2016 | O6: Q1/17 | P6: Q2/17 | Q6: 1H/17 | R6: Q3/17 | S6: Q4/17 | T6: 2017 | U6: Q1/18 | V6: Q2/18 | W6: 1H/18 | X6: Q3/18 | Y6: Q4/18 | Z6: 2018 | AA6: Q1/19 | AB6: Q2/19 | AC6: 1H/19 | AD6: Q3/19 | AE6: Q4/19 | AF6: 2019 | AG6: Q1/20 | AH6: Q2/20 | AI6: 1H/20 | AJ6: Q3/20 | AK6: Q4/20 | AL6: 2020 | AM6: Q1/21 | AN6: Q2/21 | AO6: 1H/21 | AP6: Q3/21 | AQ6: Q4/21 | AR6: 2021 | AS6: Q1/22 | AT6: Q2/22 | AU6: 1H/22 | AV6: Q3/22 | AW6: Q4/22 | AX6: 2022 | AY6: Q1/23 | AZ6: Q2/23 | BA6: 1H/23 | BB6: Q3/23 | BC6: Q4/23 | BD6: 2023 | BE6: Q1/24 | BF6: Q2/24 | BG6: 1H/24 | BH6: Q3/24 | BI6: Q4/24 | BJ6: 2024 | BK6: Q1/25 | BL6: Q2/25 | BM6: 1H/25 | BN6: Q3/25 | BO6: Q4/25 | BP6: 2025 | BQ6: 2026E | BR6: 2027E | BS6: 2028E | BT6: 2029E | BU6: 2030E | BV6: Modelling Notes | BX6: 5Y CAGR | BY6: 5Y CAGR | BZ6: 10Y CAGR
BX7: 25-'30 | BY7: 20-'25 | BZ7: 15-'25
B8: SEGMENT P&L — BY DIVISION
CC9: SCENARIO INPUT TABLE — driver assumptions per Bull/Base/Bear | CD9: Bull | CE9: Base | CF9: Bear
B10: Air & Sea | BV10: AIR & SEA — modelling logic
B11: Revenue | H11: 21685 | N11: 32100 | T11: 34587 | Z11: 36350 | AF11: 50527 | AL11: 73032 | AR11: 130899 | AX11: 172868 | BD11: 92438 | BJ11: 103926 | BP11: 132991 | BQ11: =BQ13-BQ12 -> 151500.78 | BR11: =BR13-BR12 -> 160590.83 | BS11: =BS13-BS12 -> 168620.37 | BT11: =BT13-BT12 -> 175365.19 | BU11: =BU13-BU12 -> 182379.79 | CC11: AS_revGrowth
B12: Intersegment revenue | H12: -408 | N12: -716 | T12: 617 | Z12: 622 | AF12: 624 | AL12: 657 | AR12: 1002 | AX12: 1563 | BD12: 534 | BJ12: 570 | BP12: 4329 | BQ12: =BQ13*BQ37 -> 4685.5912 | BR12: =BR13*BR37 -> 4966.7267 | BS12: =BS13*BS37 -> 5215.063 | BT12: =BT13*BT37 -> 5423.6655 | BU12: =BU13*BU37 -> 5640.6121 | CC12: 2026E | CD12: 0.18 | CE12: 0.18 | CF12: 0.03
B13: Divisional revenue | C13: 5421 | D13: 5703 | E13: 11124 | F13: 5379 | G13: 5182 | H13: 21277 | I13: 7055 | J13: 8416 | K13: 15471 | L13: 8282 | M13: 8347 | N13: 31384 | T13: 35204 | Z13: 36972 | AF13: 51151 | AG13: 16674 | AH13: 19144 | AI13: 35818 | AJ13: 17910 | AK13: 19961 | AL13: 73689 | AM13: 22924 | AN13: 25948 | AO13: 48872 | AP13: 36861 | AQ13: 46168 | AR13: 131901 | AS13: 45887 | AT13: 47282 | AU13: 93169 | AV13: 45339 | AW13: 35923 | AX13: 174431 | AY13: 26213 | AZ13: 22993 | BA13: 49206 | BB13: 21912 | BC13: 21854 | BD13: 92972 | BE13: 22716 | BF13: 24616 | BG13: 47332 | BH13: 28416 | BI13: 28748 | BJ13: 104496 | BK13: 26108 | BL13: 34475 | BM13: 60583 | BN13: 38688 | BP13: 132361.33 | BQ13: =BP13*(1+BQ21) -> 156186.37 | BR13: =BQ13*(1+BR21) -> 165557.56 | BS13: =BR13*(1+BS21) -> 173835.43 | BT13: =BS13*(1+BT21) -> 180788.85 | BU13: =BT13*(1+BU21) -> 188020.4 | BX13: =IFERROR((BU13/BP13)^(1/5)-1,"n/m") -> 0.072725909 | BY13: =IFERROR((BP13/AL13)^(1/5)-1,"n/m") -> 0.12427278 | BZ13: =IFERROR((BP13/H13)^(1/10)-1,"n/m") -> 0.20056333 | CC13: 2027E | CD13: 0.08 | CE13: 0.06 | CF13: 0
B14: Direct costs | C14: 4195 | D14: 4351 | E14: 8546 | F14: 4012 | G14: 3836 | H14: n/a | I14: 5178 | J14: 6108 | K14: 11286 | L14: 6159 | M14: 6317 | N14: n/a | T14: 26580 | Z14: 27779 | AF14: 38634 | AG14: 12799 | AH14: 14481 | AI14: 27280 | AJ14: 13607 | AK14: 15893 | AL14: 56780 | AM14: 18136 | AN14: 20806 | AO14: 38942 | AP14: 30547 | AQ14: 38643 | AR14: 108132 | AS14: 37250 | AT14: 37707 | AU14: 74957 | AV14: 36204 | AW14: 28646 | AX14: 139807 | AY14: 19186 | AZ14: 16239 | BA14: 35425 | BB14: 15702 | BC14: 15875 | BD14: 67002 | BE14: 16953 | BF14: 18544 | BG14: 35497 | BH14: 21958 | BI14: 22320 | BJ14: 79775 | BK14: 19735 | BL14: 25989 | BM14: 45724 | BN14: 29528 | BP14: 100336 | BQ14: =BQ13*BQ38 -> 117920.71 | BR14: =BR13*BR38 -> 124168.17 | BS14: =BS13*BS38 -> 129507.4 | BT14: =BT13*BT38 -> 134687.69 | BU14: =BU13*BU38 -> 140075.2 | BV14: =BQ13-BQ14 -> 38265.661 | CC14: 2028E | CD14: 0.07 | CE14: 0.05 | CF14: 0.01
