Workbook

Sheet Model
CF1: SCENARIO SWITCH ▼ (Bull / Base / Bear) — drives all scenario-linked forecast drivers
B2: Lincoln Electric Holdings, Inc. (Nasdaq: LECO) — 3-Statement Financial Model | CF2: Base
B3: US GAAP as reported · USD millions (per-share data in USD; shares in millions) · Source: Lincoln Electric Forms 10-K / 10-Q and Form 8-K earnings releases (Ex. 99.1), SEC EDGAR CIK 0000059527 (investor-relations releases are the same documents as filed on EDGAR); FY26 outlook from public coverage of the Q2-26 call (ir.lincolnelectric.com slides not reachable from the build environment)
B4: Basis notes: calendar fiscal year. Net sales = external sales. Segments: Americas / International Welding / Harris from 2016 (2013–Q3/15 recast by LECO, 8-K 10-Feb-2016); legacy North America / Europe / Asia Pacific / South America Welding + Harris to Q4/15 (memo). Per-share data restated for the 2-for-1 split (31-May-2011). Venezuela deconsolidated Jul-2016. ASU 2017-07 (2018): pension settlements below operating income. Adjusted EBITDA is model-derived (LECO publishes Adjusted EBIT / adjusted operating income / adjusted EPS).
CH5: Forecast | CI5: Historical | CJ5: Historical | CK5: Historical
B6: (USDm) | C6: 2006 | D6: 2007 | E6: 2008 | F6: 2009 | G6: 2010 | H6: 2011 | I6: 2012 | J6: Q1/13 | K6: Q2/13 | L6: Q3/13 | M6: Q4/13 | N6: 2013 | O6: Q1/14 | P6: Q2/14 | Q6: Q3/14 | R6: Q4/14 | S6: 2014 | T6: Q1/15 | U6: Q2/15 | V6: Q3/15 | W6: Q4/15 | X6: 2015 | Y6: Q1/16 | Z6: Q2/16 | AA6: Q3/16 | AB6: Q4/16 | AC6: 2016 | AD6: Q1/17 | AE6: Q2/17 | AF6: Q3/17 | AG6: Q4/17 | AH6: 2017 | AI6: Q1/18 | AJ6: Q2/18 | AK6: Q3/18 | AL6: Q4/18 | AM6: 2018 | AN6: Q1/19 | AO6: Q2/19 | AP6: Q3/19 | AQ6: Q4/19 | AR6: 2019 | AS6: Q1/20 | AT6: Q2/20 | AU6: Q3/20 | AV6: Q4/20 | AW6: 2020 | AX6: Q1/21 | AY6: Q2/21 | AZ6: Q3/21 | BA6: Q4/21 | BB6: 2021 | BC6: Q1/22 | BD6: Q2/22 | BE6: Q3/22 | BF6: Q4/22 | BG6: 2022 | BH6: Q1/23 | BI6: Q2/23 | BJ6: Q3/23 | BK6: Q4/23 | BL6: 2023 | BM6: Q1/24 | BN6: Q2/24 | BO6: Q3/24 | BP6: Q4/24 | BQ6: 2024 | BR6: Q1/25 | BS6: Q2/25 | BT6: Q3/25 | BU6: Q4/25 | BV6: 2025 | BW6: Q1/26 | BX6: Q2/26 | BY6: Q3/26E | BZ6: Q4/26E | CA6: 2026E | CB6: 2027E | CC6: 2028E | CD6: 2029E | CE6: 2030E | CF6: Modelling Notes | CH6: 5Y CAGR | CI6: 5Y CAGR | CJ6: 10Y CAGR | CK6: 19Y CAGR
CH7: 25-'30 | CI7: 20-'25 | CJ7: 15-'25 | CK7: 06-'25
B8: SEGMENT P&L — AMERICAS WELDING · INTERNATIONAL WELDING · THE HARRIS PRODUCTS GROUP (net sales build: volume + price + acquisitions + FX → segment Adjusted EBIT) | CF8: SEGMENT BUILD — modelling logic (prior-period net sales × (1 + volume + price + acquisitions + FX) → net sales × Adjusted EBIT margin → segment Adjusted EBIT)
B9: Americas Welding (arc welding equipment & consumables, cutting, automation — U.S., Canada, Mexico, South America) | CF9: AW — modelling logic | CN9: SCENARIO INPUT TABLE — driver assumptions per Bull / Base / Bear | CO9: Bull | CP9: Base | CQ9: Bear | CR9: Bull / Bear = Base + Δ (Δ inputs on each block header). Outlook block = high / mid / low end of FY26 ranges.
B10: Net sales (external customers) | N10: 1848.663 | O10: 441.849 | P10: 465.524 | Q10: 469.39 | R10: 460.907 | S10: 1837.67 | T10: 448.837 | U10: 451.001 | V10: 454.172 | W10: 387.34 | X10: 1741.35 | Y10: 359.008 | Z10: 388.372 | AA10: 377.52 | AB10: 370.082 | AC10: 1494.982 | AD10: 383.324 | AE10: 405.147 | AF10: 398.289 | AG10: 423.019 | AH10: 1609.779 | AI10: 434.772 | AJ10: 462.515 | AK10: 454.01 | AL10: 455.217 | AM10: 1806.514 | AN10: 457.719 | AO10: 476.607 | AP10: 443.521 | AQ10: 437.899 | AR10: 1815.746 | AS10: 418.535 | AT10: 333.229 | AU10: 371.535 | AV10: 386.571 | AW10: 1509.87 | AX10: 425.242 | AY10: 457.468 | AZ10: 461.508 | BA10: 480.263 | BB10: 1824.481 | BC10: 534.055 | BD10: 595.659 | BE10: 585.628 | BF10: 573.592 | BG10: 2288.934 | BH10: 658.645 | BI10: 676.966 | BJ10: 665.228 | BK10: 654.707 | BL10: 2655.546 | BM10: 624.099 | BN10: 648.936 | BO10: 637.026 | BP10: 654.786 | BQ10: 2564.847 | BR10: 653.107 | BS10: 696.73 | BT10: 691.794 | BU10: 681.93 | BV10: 2723.561 | BW10: 706.225 | BX10: 774.438 | BY10: =BT10*(1+BY17) -> 772.94345 | BZ10: =BU10*(1+BZ17) -> 761.92238 | CA10: =SUM(BW10:BZ10) -> 3015.5288 | CB10: =CA10*(1+CB17) -> 3196.4606 | CC10: =CB10*(1+CC17) -> 3372.2659 | CD10: =CC10*(1+CD17) -> 3540.8792 | CE10: =CD10*(1+CE17) -> 3717.9231 | CF10: Q3/Q4-26E: prior-year quarter × (1 + volume + price + acquisitions + FX). 2027E+: prior year × (1 + Σ drivers). Current 3-segment structure from 2016 (2013–Q3/15 recast by LECO in the 8-K of 10-Feb-2016; Q4/15 derived = FY15 recast − 9M/15 recast). | CH10: =IFERROR((CE10/BV10)^(1/5)-1,"n/m") -> 0.064223048 | CI10: =IFERROR((BV10/AW10)^(1/5)-1,"n/m") -> 0.12522536 | CJ10: =IFERROR((BV10/X10)^(1/10)-1,"n/m") -> 0.045743331 | CK10: =IFERROR((BV10/C10)^(1/19)-1,"n/m") -> n/m
B11: Net sales y/y % | D11: =IF(AND(ISNUMBER(D10),ISNUMBER(C10)),IFERROR(D10/C10-1,""),"") | E11: =IF(AND(ISNUMBER(E10),ISNUMBER(D10)),IFERROR(E10/D10-1,""),"") | F11: =IF(AND(ISNUMBER(F10),ISNUMBER(E10)),IFERROR(F10/E10-1,""),"") | G11: =IF(AND(ISNUMBER(G10),ISNUMBER(F10)),IFERROR(G10/F10-1,""),"") | H11: =IF(AND(ISNUMBER(H10),ISNUMBER(G10)),IFERROR(H10/G10-1,""),"") | I11: =IF(AND(ISNUMBER(I10),ISNUMBER(H10)),IFERROR(I10/H10-1,""),"") | N11: =IF(AND(ISNUMBER(N10),ISNUMBER(I10)),IFERROR(N10/I10-1,""),"") | O11: =IF(AND(ISNUMBER(O10),ISNUMBER(J10)),IFERROR(O10/J10-1,""),"") | P11: =IF(AND(ISNUMBER(P10),ISNUMBER(K10)),IFERROR(P10/K10-1,""),"") | Q11: =IF(AND(ISNUMBER(Q10),ISNUMBER(L10)),IFERROR(Q10/L10-1,""),"") | R11: =IF(AND(ISNUMBER(R10),ISNUMBER(M10)),IFERROR(R10/M10-1,""),"") | S11: =IF(AND(ISNUMBER(S10),ISNUMBER(N10)),IFERROR(S10/N10-1,""),"") -> -0.0059464597 | T11: =IF(AND(ISNUMBER(T10),ISNUMBER(O10)),IFERROR(T10/O10-1,""),"") -> 0.015815358 | U11: =IF(AND(ISNUMBER(U10),ISNUMBER(P10)),IFERROR(U10/P10-1,""),"") -> -0.031197103 | ... BX11: =IF(AND(ISNUMBER(BX10),ISNUMBER(BS10)),IFERROR(BX10/BS10-1,""),"") -> 0.11153244 | BY11: =IFERROR(BY10/BT10-1,"") -> 0.11730291 | BZ11: =IFERROR(BZ10/BU10-1,"") -> 0.11730291 | CA11: =IFERROR(CA10/BV10-1,"") -> 0.10720077 | CB11: =IFERROR(CB10/CA10-1,"") -> 0.06 | CC11: =IFERROR(CC10/CB10-1,"") -> 0.055 | CD11: =IFERROR(CD10/CC10-1,"") -> 0.05 | CE11: =IFERROR(CE10/CD10-1,"") -> 0.05 | CN11: FY26 outlook — Q2-26 call (30-Jul-26); Q3 update at Jefferies conf. (10-Sep-26) | CO11: High | CP11: Mid | CQ11: Low | CR11: LECO publishes its outlook on the earnings call / slides (not in the 8-K); figures from public coverage of the call — see sources in note column.
B12: Volume % before outlook calibration (Q3/Q4-26E helper) | BY12: =$BX$13 -> 0.071339 | BZ12: =$BX$13 -> 0.071339 | CF12: Q2/26 y/y volume held for Q3/Q4-26E before the FY26 net-sales calibration (Group block). | CN12: FY26 net sales growth % (y/y) | CO12: 0.13 | CP12: 0.115 | CQ12: 0.1 | CR12: Raised on Q2-26 call to "low-double-digit" net sales growth (from high-single-digit in Q1-26). Drives the Q3/Q4-26E volume calibration.
B13: Volume % (company: change in net sales due to volume) | Y13: -0.189519 | Z13: -0.133035 | AA13: -0.179091 | AB13: -0.057611 | AC13: -0.142829 | AD13: 0.041116 | AE13: 0.017421 | AF13: 0.022253 | AG13: 0.100999 | AH13: 0.045021 | AI13: 0.074511 | AJ13: 0.076572 | AK13: 0.057958 | AL13: -0.000972 | AM13: 0.051099 | AN13: -0.028509 | AO13: -0.036228 | AP13: -0.045384 | AQ13: -0.064868 | AR13: -0.043888 | AS13: -0.082347 | AT13: -0.291718 | AU13: -0.155636 | AV13: -0.124257 | AW13: -0.165313 | AX13: -0.009055 | AY13: 0.27094 | AZ13: 0.113962 | BA13: 0.092503 | BB13: 0.109013 | BC13: 0.051745 | BD13: 0.098988 | BE13: 0.113803 | BF13: 0.076525 | BG13: 0.085811 | BH13: 0.10982 | BI13: 0.057724 | BJ13: 0.003538 | BK13: 0.025722 | BL13: 0.047996 | BM13: -0.064759 | BN13: -0.067455 | BO13: -0.086124 | BP13: -0.07155 | BQ13: -0.072472 | BR13: -0.039641 | BS13: -0.034435 | BT13: -0.023564 | BU13: -0.06931 | BV13: -0.041905 | BW13: -0.004035 | BX13: 0.071339 | BY13: =BY12+BY118 -> 0.077109914 | BZ13: =BZ12+BZ118 -> 0.077109914 | CA13: =IFERROR(SUMPRODUCT(BR10:BU10,BW13:BZ13)/SUM(BR10:BU10),"") -> 0.05617516 | CB13: =CHOOSE(MATCH($CF$2,{"Bull","Base","Bear"},0),$CO$27,$CP$27,$CQ$27) -> 0.03 | CC13: =CHOOSE(MATCH($CF$2,{"Bull","Base","Bear"},0),$CO$28,$CP$28,$CQ$28) -> 0.03 | CD13: =CHOOSE(MATCH($CF$2,{"Bull","Base","Bear"},0),$CO$29,$CP$29,$CQ$29) -> 0.025 | CE13: =CHOOSE(MATCH($CF$2,{"Bull","Base","Bear"},0),$CO$30,$CP$30,$CQ$30) -> 0.025 | CF13: Historical = LECO "Change in Net Sales by Segment" table (8-K Ex.99.1) ÷ prior-year segment net sales. Q3/Q4-26E: Q2/26 y/y + FY26 calibration Δ. 2027E–30E: scenario lever (Bull/Base/Bear table →). | CN13: 2H/26 incremental Adjusted EBIT margin % (Δ Adj. EBIT / Δ net sales, 2H y/y) | CO13: 0.27 | CP13: 0.23 | CQ13: 0.18 | CR13: Q2-26 call: "mid-20% incremental margin" for the balance of 2026; 10-Sep-26 Jefferies: Q3 incrementals tracking "low 20s" on inflation / supply-chain costs. Drives the Q3/Q4-26E margin calibration.
B14: Price % | Y14: 0.178951 | Z14: 0.429502 | AA14: -0.012429 | AB14: -0.000454 | AC14: 0.154021 | AD14: 0.015376 | AE14: 0.027057 | AF14: 0.024362 | AG14: 0.029139 | AH14: 0.024087 | AI14: 0.046128 | AJ14: 0.054198 | AK14: 0.090708 | AL14: 0.083377 | AM14: 0.068977 | AN14: 0.063086 | AO14: 0.025078 | AP14: -0.012341 | AQ14: -0.016957 | AR14: 0.014229 | AS14: -0.01178 | AT14: -0.002948 | AU14: -0.001538 | AV14: 0.011793 | AW14: -0.001275 | AX14: 0.021659 | AY14: 0.082016 | AZ14: 0.118312 | BA14: 0.146454 | BB14: 0.090714 | BC14: 0.198047 | BD14: 0.196416 | BE14: 0.151434 | BF14: 0.114454 | BG14: 0.163843 | BH14: 0.046248 | BI14: 0.010029 | BJ14: 0.005956 | BK14: 0.005167 | BL14: 0.016219 | BM14: 0.003468 | BN14: 0.009634 | BO14: 0.003766 | BP14: -0.000826 | BQ14: 0.004056 | BR14: 0.021421 | BS14: 0.06513 | BT14: 0.095577 | BU14: 0.103796 | BV14: 0.071927 | BW14: 0.075759 | BX14: 0.036859 | BY14: =$BX$14 -> 0.036859 | BZ14: =$BX$14 -> 0.036859 | CA14: =IFERROR(SUMPRODUCT(BR10:BU10,BW14:BZ14)/SUM(BR10:BU10),"") -> 0.046187178 | CB14: =CHOOSE(MATCH($CF$2,{"Bull","Base","Bear"},0),$CO$32,$CP$32,$CQ$32) -> 0.03 | CC14: =CHOOSE(MATCH($CF$2,{"Bull","Base","Bear"},0),$CO$33,$CP$33,$CQ$33) -> 0.025 | CD14: =CHOOSE(MATCH($CF$2,{"Bull","Base","Bear"},0),$CO$34,$CP$34,$CQ$34) -> 0.025 | CE14: =CHOOSE(MATCH($CF$2,{"Bull","Base","Bear"},0),$CO$35,$CP$35,$CQ$35) -> 0.025 | CF14: Q3/Q4-26E: Q2/26 y/y price held. 2027E–30E: scenario lever. | CN14: Memo: FY26 organic sales growth (company) | CO14: HSD–LDD | CP14: HSD–LDD | CQ14: HSD–LDD | CR14: High-single-digit to low-double-digit organic growth; ~1/3 volume, ~2/3 price & mix; neutral price/cost in 2H; ~$10m LIFO headwind (FY).
B15: Acquisitions % (inorganic contribution, first 12 months) | Y15: 0.015545 | Z15: 0.036193 | AA15: 0.027082 | AB15: 0.018671 | AC15: 0.024597 | AD15: 0.009298 | AE15: 0.003486 | AF15: 0.00302 | AG15: 0.007128 | AH15: 0.005666 | AI15: 0.009407 | AJ15: 0.010019 | AK15: 0.002882 | AL15: 0.006692 | AM15: 0.007233 | AN15: 0.029257 | AO15: 0.046511 | AP15: 0.038281 | AQ15: 0.042727 | AR15: 0.039337 | AS15: 0.013524 | AT15: 0 | AU15: 0 | AV15: 0 | AW15: 0.003409 | AX15: 0 | AY15: 0 | AZ15: 0 | BA15: 0 | BB15: 0 | BC15: 0.004104 | BD15: 0.011885 | BE15: 0.010236 | BF15: 0.01186 | BG15: 0.009648 | BH15: 0.084727 | BI15: 0.073779 | BJ15: 0.123216 | BK15: 0.106588 | BL15: 0.097204 | BM15: 0.006322 | BN15: 0.018347 | BO15: 0.045416 | BP15: 0.082939 | BQ15: 0.03807 | BR15: 0.075833 | BS15: 0.046525 | BT15: 0.01388 | BU15: 0 | BV15: 0.033671 | BW15: 0 | BX15: 0 | BY15: 0 | BZ15: 0 | CA15: =IFERROR(SUMPRODUCT(BR10:BU10,BW15:BZ15)/SUM(BR10:BU10),"") -> 0 | CB15: 0 | CC15: 0 | CD15: 0 | CE15: 0 | CF15: Q3/Q4-26E: input — 2025 bolt-ons anniversary during 2H/26 (International Welding +7.0% in Q2/26, fading). 2027E+: 0% here; future bolt-ons modelled in the unallocated M&A block. | CN15: FY26 point estimates (all cases)
B16: Foreign exchange % | Y16: -0.205115 | Z16: -0.471527 | AA16: -0.004335 | AB16: -0.005161 | AC16: -0.177271 | AD16: 0.001941 | AE16: -0.004771 | AF16: 0.00538 | AG16: 0.005774 | AH16: 0.002015 | AI16: 0.004169 | AJ16: 0.00081 | AK16: -0.011647 | AL16: -0.012983 | AM16: -0.005097 | AN16: -0.011054 | AO16: -0.004893 | AP16: -0.003659 | AQ16: 0.001054 | AR16: -0.004567 | AS16: -0.005003 | AT16: -0.006164 | AU16: -0.005132 | AV16: -0.00475 | AW16: -0.005278 | AX16: 0.003421 | AY16: 0.019878 | AZ16: 0.009891 | BA16: 0.003409 | BB16: 0.008642 | BC16: 0.001989 | BD16: -0.005211 | BE16: -0.006529 | BF16: -0.00851 | BG16: -0.004734 | BH16: -0.007505 | BI16: -0.005033 | BJ16: 0.003212 | BK16: 0.003938 | BL16: -0.001252 | BM16: 0.002519 | BN16: -0.001931 | BO16: -0.005452 | BP16: -0.010443 | BQ16: -0.003808 | BR16: -0.011133 | BS16: -0.00357 | BT16: 8.2e-05 | BU16: 0.006969 | BV16: -0.001813 | BW16: 0.009606 | BX16: 0.003334 | BY16: =$BX$16 -> 0.003334 | BZ16: =$BX$16 -> 0.003334 | CA16: =IFERROR(SUMPRODUCT(BR10:BU10,BW16:BZ16)/SUM(BR10:BU10),"") -> 0.0048380189 | CB16: 0 | CC16: 0 | CD16: 0 | CE16: 0 | CF16: Q3/Q4-26E: Q2/26 FX translation held; 2027E+: constant currency (0%). | CN16: Interest expense, net ($m) | CP16: 52.5 | CR16: FY26 outlook: interest expense, net $50–55m (Q1-26 call; maintained on Q2-26 call).
B17: Net sales growth % (volume + price + acquisitions + FX) | C17: =IF(ISNUMBER(C13),C13+C14+C15+C16,"") | D17: =IF(ISNUMBER(D13),D13+D14+D15+D16,"") | E17: =IF(ISNUMBER(E13),E13+E14+E15+E16,"") | F17: =IF(ISNUMBER(F13),F13+F14+F15+F16,"") | G17: =IF(ISNUMBER(G13),G13+G14+G15+G16,"") | H17: =IF(ISNUMBER(H13),H13+H14+H15+H16,"") | I17: =IF(ISNUMBER(I13),I13+I14+I15+I16,"") | J17: =IF(ISNUMBER(J13),J13+J14+J15+J16,"") | ... BX17: =IF(ISNUMBER(BX13),BX13+BX14+BX15+BX16,"") -> 0.111532 | BY17: =BY13+BY14+BY15+BY16 -> 0.11730291 | BZ17: =BZ13+BZ14+BZ15+BZ16 -> 0.11730291 | CA17: =CA13+CA14+CA15+CA16 -> 0.10720036 | CB17: =CB13+CB14+CB15+CB16 -> 0.06 | CC17: =CC13+CC14+CC15+CC16 -> 0.055 | CD17: =CD13+CD14+CD15+CD16 -> 0.05 | CE17: =CE13+CE14+CE15+CE16 -> 0.05 | CN17: Tax rate (GAAP) | CP17: 0.225 | CR17: FY26 outlook: "low-to-mid 20%" effective tax rate; 1H/26 actual 22.6%.
B18: Organic growth % (volume + price) | C18: =IF(ISNUMBER(C13),C13+C14,"") | D18: =IF(ISNUMBER(D13),D13+D14,"") | E18: =IF(ISNUMBER(E13),E13+E14,"") | F18: =IF(ISNUMBER(F13),F13+F14,"") | G18: =IF(ISNUMBER(G13),G13+G14,"") | H18: =IF(ISNUMBER(H13),H13+H14,"") | I18: =IF(ISNUMBER(I13),I13+I14,"") | J18: =IF(ISNUMBER(J13),J13+J14,"") | ... BX18: =IF(ISNUMBER(BX13),BX13+BX14,"") -> 0.108198 | BY18: =BY13+BY14 -> 0.11396891 | BZ18: =BZ13+BZ14 -> 0.11396891 | CA18: =CA13+CA14 -> 0.10236234 | CB18: =CB13+CB14 -> 0.06 | CC18: =CC13+CC14 -> 0.055 | CD18: =CD13+CD14 -> 0.05 | CE18: =CE13+CE14 -> 0.05 | CN18: Capital expenditures ($m) | CO18: 130 | CP18: 120 | CQ18: 110 | CR18: FY26 outlook: elevated capex $110–130m (1H/26: $70.6m).
B19: Check: Σ drivers vs reported y/y % (≈0; ≠0 where LECO recast the prior-year base) | C19: =IF(AND(ISNUMBER(C17),ISNUMBER(C11)),ROUND(C17-C11,3),"") | D19: =IF(AND(ISNUMBER(D17),ISNUMBER(D11)),ROUND(D17-D11,3),"") | E19: =IF(AND(ISNUMBER(E17),ISNUMBER(E11)),ROUND(E17-E11,3),"") | F19: =IF(AND(ISNUMBER(F17),ISNUMBER(F11)),ROUND(F17-F11,3),"") | G19: =IF(AND(ISNUMBER(G17),ISNUMBER(G11)),ROUND(G17-G11,3),"") | H19: =IF(AND(ISNUMBER(H17),ISNUMBER(H11)),ROUND(H17-H11,3),"") | I19: =IF(AND(ISNUMBER(I17),ISNUMBER(I11)),ROUND(I17-I11,3),"") | J19: =IF(AND(ISNUMBER(J17),ISNUMBER(J11)),ROUND(J17-J11,3),"") | ... BX19: =IF(AND(ISNUMBER(BX17),ISNUMBER(BX11)),ROUND(BX17-BX11,3),"") -> 0 | CN19: Rationalization & asset impairment charges — 2H/26 ($m) | CP19: 6 | CR19: 1H/26 $5.6m (Americas & International Welding programmes); 2H assumed at the 1H run-rate.
B20: Memo: inter-segment sales (eliminated in Corporate / Eliminations) | N20: 105.811 | O20: 28.217 | P20: 28.989 | Q20: 27.244 | R20: 26.074 | S20: 110.524 | T20: 23.023 | U20: 23.902 | V20: 25.571 | W20: 20.042 | X20: 92.538 | Y20: 23.831 | Z20: 23.456 | AA20: 22.386 | AB20: 23.939 | AC20: 93.612 | AD20: 22.46 | AE20: 27.374 | AF20: 25.546 | AG20: 22.002 | AH20: 97.382 | AI20: 26.586 | AJ20: 31.24 | AK20: 31.845 | AL20: 29.265 | AM20: 118.936 | AN20: 29.388 | AO20: 34.811 | AP20: 31.101 | AQ20: 28.042 | AR20: 123.342 | AS20: 24.783 | AT20: 27.493 | AU20: 29.368 | AV20: 27.734 | AW20: 109.378 | AX20: 32.748 | AY20: 39.765 | AZ20: 37.48 | BA20: 30.657 | BB20: 140.65 | BC20: 28.156 | BD20: 29.031 | BE20: 35.353 | BF20: 29.479 | BG20: 122.019 | BH20: 32.318 | BI20: 30.85 | BJ20: 28.875 | BK20: 35.493 | BL20: 127.536 | BM20: 29.978 | BN20: 37.8 | BO20: 30.845 | BP20: 37.134 | BQ20: 135.758 | BR20: 30.372 | BS20: 43.391 | BT20: 30.058 | BU20: 25.101 | BV20: 128.922 | BW20: 36.709 | BX20: 28.904 | CN20: Rationalization & asset impairment charges — 2027E+ ($m p.a.) | CP20: 12 | CR20: 2019–25 average ex 2023 gain ≈ $25m; RISE restructuring tapering. Treated as a special item (excluded from Adjusted EBIT).
B21: EBIT (GAAP segment result = operating income + other income) | N21: 364.186 | O21: 66.07 | P21: 92.494 | Q21: 83.444 | R21: 89.6 | S21: 331.608 | T21: 75.415 | U21: 79.421 | V21: -83.413 | W21: 72.027 | X21: 143.45 | Y21: 61.438 | Z21: 65.201 | AA21: 68.285 | AB21: 71.709 | AC21: 266.633 | AD21: 68.723 | AE21: 74.498 | AF21: 68.813 | AG21: 70.59 | AH21: 282.624 | AI21: 76.681 | AJ21: 88.158 | AK21: 85.021 | AL21: 84.198 | AM21: 334.058 | AN21: 80.416 | AO21: 83.072 | AP21: 74.11 | AQ21: 75.006 | AR21: 312.604 | AS21: 69.512 | AT21: 20.695 | AU21: 52.076 | AV21: 68.456 | AW21: 210.739 | AX21: 72.177 | AY21: 82.484 | AZ21: 10.983 | BA21: 40.258 | BB21: 205.902 | BC21: 115.303 | BD21: 117.606 | BE21: 119.157 | BF21: 113.813 | BG21: 465.879 | BH21: 129.668 | BI21: 136.913 | BJ21: 132.42 | BK21: 129.409 | BL21: 528.411 | BM21: 136.1 | BN21: 136.297 | BO21: 102.158 | BP21: 127.813 | BQ21: 502.367 | BR21: 122.063 | BS21: 137.01 | BT21: 127.24 | BU21: 137.816 | BV21: 524.129 | BW21: 126.895 | BX21: 157.083 | CN21: 2H/26 share repurchases ($m) | CO21: 200 | CP21: 150 | CQ21: 100 | CR21: 1H/26: $132.8m (Q1 $57m, Q2 $76m); 4.9m shares left under authorisation (31-Mar-26).
B22: Special items in segment EBIT (rationalization, impairments, acquisition costs) | C22: =IF(AND(ISNUMBER(C23),ISNUMBER(C21)),C23-C21,"") | D22: =IF(AND(ISNUMBER(D23),ISNUMBER(D21)),D23-D21,"") | E22: =IF(AND(ISNUMBER(E23),ISNUMBER(E21)),E23-E21,"") | F22: =IF(AND(ISNUMBER(F23),ISNUMBER(F21)),F23-F21,"") | G22: =IF(AND(ISNUMBER(G23),ISNUMBER(G21)),G23-G21,"") | H22: =IF(AND(ISNUMBER(H23),ISNUMBER(H21)),H23-H21,"") | I22: =IF(AND(ISNUMBER(I23),ISNUMBER(I21)),I23-I21,"") | J22: =IF(AND(ISNUMBER(J23),ISNUMBER(J21)),J23-J21,"") | ... BX22: =IF(AND(ISNUMBER(BX23),ISNUMBER(BX21)),BX23-BX21,"") -> 1.012 | CN22: Memo: cash conversion target (FCF / adjusted NI) | CO22: 1 | CP22: 1 | CQ22: 1 | CR22: Company target ~100% cash conversion through the cycle.
B23: Adjusted EBIT (company segment profit measure) | N23: 377.436 | O23: 83.688 | P23: 95.941 | Q23: 84.026 | R23: 89.6 | S23: 353.255 | T23: 75.415 | U23: 79.421 | V23: 82.765 | W23: 79.088 | X23: 316.689 | Y23: 61.438 | Z23: 65.201 | AA23: 68.285 | AB23: 71.709 | AC23: 266.633 | AD23: 68.723 | AE23: 74.498 | AF23: 74.096 | AG23: 74.549 | AH23: 291.866 | AI23: 77.439 | AJ23: 88.158 | AK23: 89.253 | AL23: 85.894 | AM23: 340.744 | AN23: 81.752 | AO23: 84.851 | AP23: 74.11 | AQ23: 75.006 | AR23: 315.719 | AS23: 70.702 | AT23: 46.702 | AU23: 59.12 | AV23: 69.204 | AW23: 245.728 | AX23: 76.617 | AY23: 84.134 | AZ23: 84.557 | BA23: 83.708 | BB23: 329.016 | BC23: 111.568 | BD23: 118.067 | BE23: 118.804 | BF23: 114.38 | BG23: 462.819 | BH23: 132.453 | BI23: 139.87 | BJ23: 136.476 | BK23: 129.469 | BL23: 538.269 | BM23: 136.1 | BN23: 136.651 | BO23: 125.515 | BP23: 131.923 | BQ23: 530.188 | BR23: 124.198 | BS23: 137.915 | BT23: 131.615 | BU23: 141.111 | BV23: 534.839 | BW23: 127.468 | BX23: 158.095 | BY23: =BY10*BY25 -> 156.25246 | BZ23: =BZ10*BZ25 -> 166.73121 | CA23: =SUM(BW23:BZ23) -> 608.54666 | CB23: =CB10*CB25 -> 655.27441 | CC23: =CC10*CC25 -> 701.4313 | CD23: =CD10*CD25 -> 743.58463 | CE23: =CE10*CE25 -> 780.76386 | CF23: Net sales × Adjusted EBIT margin. Forecast special items are modelled at group level (EBIT bridge), not allocated to segments. | CH23: =IFERROR((CE23/BV23)^(1/5)-1,"n/m") -> 0.078597295 | CI23: =IFERROR((BV23/AW23)^(1/5)-1,"n/m") -> 0.16829814 | CJ23: =IFERROR((BV23/X23)^(1/10)-1,"n/m") -> 0.053801977 | CK23: =IFERROR((BV23/C23)^(1/19)-1,"n/m") -> n/m
B24: Adj. EBIT margin before outlook calibration % (Q3/Q4-26E helper) | BY24: =BT25+($BX$25-$BS$25) -> 0.19644719 | BZ24: =BU25+($BX$25-$BS$25) -> 0.21312433 | CF24: Prior-year quarter margin + Q2/26 y/y margin change. | CN24: Minimum net debt / Adjusted EBITDA (x) — buyback floor 2027E+ | CO24: 1.25 | CP24: 1 | CQ24: 0.75 | CR24: LECO runs ~0.5–1.0x net leverage (YE25 net debt $985m vs model Adj. EBITDA $851m); excess cash returned via buybacks.
B25: Adjusted EBIT margin % (on external net sales) | C25: =IF(AND(ISNUMBER(C23),ISNUMBER(C10)),IFERROR(C23/C10,""),"") | D25: =IF(AND(ISNUMBER(D23),ISNUMBER(D10)),IFERROR(D23/D10,""),"") | E25: =IF(AND(ISNUMBER(E23),ISNUMBER(E10)),IFERROR(E23/E10,""),"") | F25: =IF(AND(ISNUMBER(F23),ISNUMBER(F10)),IFERROR(F23/F10,""),"") | G25: =IF(AND(ISNUMBER(G23),ISNUMBER(G10)),IFERROR(G23/G10,""),"") | H25: =IF(AND(ISNUMBER(H23),ISNUMBER(H10)),IFERROR(H23/H10,""),"") | I25: =IF(AND(ISNUMBER(I23),ISNUMBER(I10)),IFERROR(I23/I10,""),"") | J25: =IF(AND(ISNUMBER(J23),ISNUMBER(J10)),IFERROR(J23/J10,""),"") | ... BX25: =IF(AND(ISNUMBER(BX23),ISNUMBER(BX10)),IFERROR(BX23/BX10,""),"") -> 0.20414158 | BY25: =BY24+BY123 -> 0.20215251 | BZ25: =BZ24+BZ123 -> 0.21882965 | CA25: =IFERROR(CA23/CA10,"") -> 0.20180429 | CB25: =CHOOSE(MATCH($CF$2,{"Bull","Base","Bear"},0),$CO$37,$CP$37,$CQ$37) -> 0.205 | CC25: =CHOOSE(MATCH($CF$2,{"Bull","Base","Bear"},0),$CO$38,$CP$38,$CQ$38) -> 0.208 | CD25: =CHOOSE(MATCH($CF$2,{"Bull","Base","Bear"},0),$CO$39,$CP$39,$CQ$39) -> 0.21 | CE25: =CHOOSE(MATCH($CF$2,{"Bull","Base","Bear"},0),$CO$40,$CP$40,$CQ$40) -> 0.21 | CF25: LECO reports segment margins on total sales incl. inter-segment; the model uses external net sales (slightly higher). 2027E–30E: scenario lever. | CH25: =IFERROR(AVERAGE(CA25,CB25,CC25,CD25,CE25),"n/m") -> 0.20696086 | CI25: =IFERROR(AVERAGE(BB25,BG25,BL25,BQ25,BV25),"n/m") -> 0.19766338 | CJ25: =IFERROR(AVERAGE(AC25,AH25,AM25,AR25,AW25,BB25,BG25,BL25,BQ25,BV25),"n/m") -> 0.18732228 | CK25: =IFERROR(AVERAGE(C25,D25,E25,F25,G25,H25,I25,N25,S25,X25,AC25,AH25,AM25,AR25,AW25,BB25,BG25,BL25,BQ25,BV25),"n/m") -> 0.18857567
B26: Incremental Adj. EBIT margin % (Δ Adj. EBIT / Δ net sales, y/y) | D26: =IF(AND(ISNUMBER(D23),ISNUMBER(C23)),IFERROR((D23-C23)/(D10-C10),""),"") | E26: =IF(AND(ISNUMBER(E23),ISNUMBER(D23)),IFERROR((E23-D23)/(E10-D10),""),"") | F26: =IF(AND(ISNUMBER(F23),ISNUMBER(E23)),IFERROR((F23-E23)/(F10-E10),""),"") | G26: =IF(AND(ISNUMBER(G23),ISNUMBER(F23)),IFERROR((G23-F23)/(G10-F10),""),"") | H26: =IF(AND(ISNUMBER(H23),ISNUMBER(G23)),IFERROR((H23-G23)/(H10-G10),""),"") | I26: =IF(AND(ISNUMBER(I23),ISNUMBER(H23)),IFERROR((I23-H23)/(I10-H10),""),"") | N26: =IF(AND(ISNUMBER(N23),ISNUMBER(I23)),IFERROR((N23-I23)/(N10-I10),""),"") | O26: =IF(AND(ISNUMBER(O23),ISNUMBER(J23)),IFERROR((O23-J23)/(O10-J10),""),"") | P26: =IF(AND(ISNUMBER(P23),ISNUMBER(K23)),IFERROR((P23-K23)/(P10-K10),""),"") | Q26: =IF(AND(ISNUMBER(Q23),ISNUMBER(L23)),IFERROR((Q23-L23)/(Q10-L10),""),"") | R26: =IF(AND(ISNUMBER(R23),ISNUMBER(M23)),IFERROR((R23-M23)/(R10-M10),""),"") | S26: =IF(AND(ISNUMBER(S23),ISNUMBER(N23)),IFERROR((S23-N23)/(S10-N10),""),"") -> 2.1996725 | T26: =IF(AND(ISNUMBER(T23),ISNUMBER(O23)),IFERROR((T23-O23)/(T10-O10),""),"") -> -1.1838867 | U26: =IF(AND(ISNUMBER(U23),ISNUMBER(P23)),IFERROR((U23-P23)/(U10-P10),""),"") -> 1.137506 | ... CA26: =IF(AND(ISNUMBER(CA23),ISNUMBER(BV23)),IFERROR((CA23-BV23)/(CA10-BV10),""),"") -> 0.25245132 | CB26: =IF(AND(ISNUMBER(CB23),ISNUMBER(CA23)),IFERROR((CB23-CA23)/(CB10-CA10),""),"") -> 0.25826178 | CC26: =IF(AND(ISNUMBER(CC23),ISNUMBER(CB23)),IFERROR((CC23-CB23)/(CC10-CB10),""),"") -> 0.26254545 | CD26: =IF(AND(ISNUMBER(CD23),ISNUMBER(CC23)),IFERROR((CD23-CC23)/(CD10-CC10),""),"") -> 0.25 | CE26: =IF(AND(ISNUMBER(CE23),ISNUMBER(CD23)),IFERROR((CE23-CD23)/(CE10-CD10),""),"") -> 0.21 | CN26: AW_vol (Americas Welding volume y/y) | CO26: 0.02 | CP26: Δ → | CQ26: -0.02 | CR26: Americas volume inflected +7.1% in Q2/26 after 9 quarters of declines; consumables lead equipment. 2016–25 avg ≈ −0.5% (incl. 2020/2024–25 downturns).
CN27: 2027E | CO27: =CP27+$CO$26 -> 0.05 | CP27: 0.03 | CQ27: =CP27+$CQ$26 -> 0.01
B28: International Welding (Europe, Middle East, Asia Pacific — welding equipment, consumables, automation) | CF28: IW — modelling logic | CN28: 2028E | CO28: =CP28+$CO$26 -> 0.05 | CP28: 0.03 | CQ28: =CP28+$CQ$26 -> 0.01
B29: Net sales (external customers) | N29: 695.831 | O29: 170.742 | P29: 185.588 | Q29: 168.004 | R29: 157.09 | S29: 681.424 | T29: 139.247 | U29: 141.927 | V29: 128.072 | W29: 121.214 | X29: 530.46 | Y29: 124.305 | Z29: 132.815 | AA29: 119.564 | AB29: 130.605 | AC29: 507.289 | AD29: 128.888 | AE29: 141.498 | AF29: 197.617 | AG29: 256.021 | AH29: 724.024 | AI29: 247.32 | AJ29: 243.373 | AK29: 209.622 | AL29: 219.456 | AM29: 919.771 | AN29: 218.086 | AO29: 212.306 | AP29: 205.378 | AQ29: 218.606 | AR29: 854.376 | AS29: 197.923 | AT29: 177.167 | AU29: 196.937 | AV29: 214.782 | AW29: 786.809 | AX29: 223.079 | AY29: 252.352 | AZ29: 227.165 | BA29: 245.529 | BB29: 948.125 | BC29: 258.041 | BD29: 236.629 | BE29: 216.497 | BF29: 243.114 | BG29: 954.281 | BH29: 252.416 | BI29: 253.403 | BJ29: 242.01 | BK29: 292.177 | BL29: 1040.006 | BM29: 235.761 | BN29: 238.758 | BO29: 216.224 | BP29: 242.979 | BQ29: 933.722 | BR29: 219.061 | BS29: 232.824 | BT29: 219.629 | BU29: 259.351 | BV29: 930.865 | BW29: 227.035 | BX29: 243.292 | BY29: =BT29*(1+BY36) -> 223.1828 | BZ29: =BU29*(1+BZ36) -> 254.47025 | CA29: =SUM(BW29:BZ29) -> 947.98005 | CB29: =CA29*(1+CB36) -> 981.15935 | CC29: =CB29*(1+CC36) -> 1015.4999 | CD29: =CC29*(1+CD36) -> 1051.0424 | CE29: =CD29*(1+CE36) -> 1087.8289 | CF29: Q3/Q4-26E: prior-year quarter × (1 + volume + price + acquisitions + FX). 2027E+: prior year × (1 + Σ drivers). Current 3-segment structure from 2016 (2013–Q3/15 recast by LECO in the 8-K of 10-Feb-2016; Q4/15 derived = FY15 recast − 9M/15 recast). | CH29: =IFERROR((CE29/BV29)^(1/5)-1,"n/m") -> 0.031655693 | CI29: =IFERROR((BV29/AW29)^(1/5)-1,"n/m") -> 0.034197483 | CJ29: =IFERROR((BV29/X29)^(1/10)-1,"n/m") -> 0.057848333 | CK29: =IFERROR((BV29/C29)^(1/19)-1,"n/m") -> n/m | CN29: 2029E | CO29: =CP29+$CO$26 -> 0.045 | CP29: 0.025 | CQ29: =CP29+$CQ$26 -> 0.005
B30: Net sales y/y % | D30: =IF(AND(ISNUMBER(D29),ISNUMBER(C29)),IFERROR(D29/C29-1,""),"") | E30: =IF(AND(ISNUMBER(E29),ISNUMBER(D29)),IFERROR(E29/D29-1,""),"") | F30: =IF(AND(ISNUMBER(F29),ISNUMBER(E29)),IFERROR(F29/E29-1,""),"") | G30: =IF(AND(ISNUMBER(G29),ISNUMBER(F29)),IFERROR(G29/F29-1,""),"") | H30: =IF(AND(ISNUMBER(H29),ISNUMBER(G29)),IFERROR(H29/G29-1,""),"") | I30: =IF(AND(ISNUMBER(I29),ISNUMBER(H29)),IFERROR(I29/H29-1,""),"") | N30: =IF(AND(ISNUMBER(N29),ISNUMBER(I29)),IFERROR(N29/I29-1,""),"") | O30: =IF(AND(ISNUMBER(O29),ISNUMBER(J29)),IFERROR(O29/J29-1,""),"") | P30: =IF(AND(ISNUMBER(P29),ISNUMBER(K29)),IFERROR(P29/K29-1,""),"") | Q30: =IF(AND(ISNUMBER(Q29),ISNUMBER(L29)),IFERROR(Q29/L29-1,""),"") | R30: =IF(AND(ISNUMBER(R29),ISNUMBER(M29)),IFERROR(R29/M29-1,""),"") | S30: =IF(AND(ISNUMBER(S29),ISNUMBER(N29)),IFERROR(S29/N29-1,""),"") -> -0.02070474 | T30: =IF(AND(ISNUMBER(T29),ISNUMBER(O29)),IFERROR(T29/O29-1,""),"") -> -0.18445959 | U30: =IF(AND(ISNUMBER(U29),ISNUMBER(P29)),IFERROR(U29/P29-1,""),"") -> -0.23525767 | ... BX30: =IF(AND(ISNUMBER(BX29),ISNUMBER(BS29)),IFERROR(BX29/BS29-1,""),"") -> 0.044961001 | BY30: =IFERROR(BY29/BT29-1,"") -> 0.016180914 | BZ30: =IFERROR(BZ29/BU29-1,"") -> -0.018819086 | CA30: =IFERROR(CA29/BV29-1,"") -> 0.018386178 | CB30: =IFERROR(CB29/CA29-1,"") -> 0.035 | CC30: =IFERROR(CC29/CB29-1,"") -> 0.035 | CD30: =IFERROR(CD29/CC29-1,"") -> 0.035 | CE30: =IFERROR(CE29/CD29-1,"") -> 0.035 | CN30: 2030E | CO30: =CP30+$CO$26 -> 0.045 | CP30: 0.025 | CQ30: =CP30+$CQ$26 -> 0.005
B31: Volume % before outlook calibration (Q3/Q4-26E helper) | BY31: =$BX$32 -> -0.04695 | BZ31: =$BX$32 -> -0.04695 | CF31: Q2/26 y/y volume held for Q3/Q4-26E before the FY26 net-sales calibration (Group block). | CN31: AW_price (Americas Welding price y/y) | CO31: 0.01 | CP31: Δ → | CQ31: -0.01 | CR31: Price +7.2% (2025) and +5.6% (1H/26) on tariff / steel inflation; normalises to ~2–3% (2016–25 avg ≈ +5.1% incl. 2021–22 inflation).
B32: Volume % (company: change in net sales due to volume) | Y32: -0.070537 | Z32: -0.036019 | AA32: -0.049363 | AB32: 0.104171 | AC32: -0.016267 | AD32: 0.026926 | AE32: 0.032956 | AF32: 0.066809 | AG32: -0.02457 | AH32: 0.024647 | AI32: -0.036753 | AJ32: -0.045011 | AK32: -0.104541 | AL32: -0.137481 | AM32: -0.092487 | AN32: -0.072445 | AO32: -0.096765 | AP32: -0.061854 | AQ32: -0.077811 | AR32: -0.077747 | AS32: -0.139885 | AT32: -0.209377 | AU32: -0.053384 | AV32: -0.033581 | AW32: -0.10916 | AX32: 0.05684 | AY32: 0.254534 | AZ32: 0.03784 | BA32: -0.008213 | BB32: 0.078841 | BC32: -0.00459 | BD32: -0.066819 | BE32: 0.024379 | BF32: 0.013558 | BG32: -0.009512 | BH32: -0.056801 | BI32: 0.03806 | BJ32: 0.029081 | BK32: 0.048841 | BL32: 0.013119 | BM32: -0.048618 | BN32: -0.037715 | BO32: -0.119412 | BP32: -0.157199 | BQ32: -0.09294 | BR32: -0.057889 | BS32: -0.067734 | BT32: -0.042428 | BU32: -0.035538 | BV32: -0.05101 | BW32: -0.098744 | BX32: -0.04695 | BY32: =BY31+BY118 -> -0.041179086 | BZ32: =BZ31+BZ118 -> -0.041179086 | CA32: =IFERROR(SUMPRODUCT(BR29:BU29,BW32:BZ32)/SUM(BR29:BU29),"") -> -0.056169267 | CB32: =CHOOSE(MATCH($CF$2,{"Bull","Base","Bear"},0),$CO$42,$CP$42,$CQ$42) -> 0.02 | CC32: =CHOOSE(MATCH($CF$2,{"Bull","Base","Bear"},0),$CO$43,$CP$43,$CQ$43) -> 0.02 | CD32: =CHOOSE(MATCH($CF$2,{"Bull","Base","Bear"},0),$CO$44,$CP$44,$CQ$44) -> 0.02 | CE32: =CHOOSE(MATCH($CF$2,{"Bull","Base","Bear"},0),$CO$45,$CP$45,$CQ$45) -> 0.02 | CF32: Historical = LECO "Change in Net Sales by Segment" table (8-K Ex.99.1) ÷ prior-year segment net sales. Q3/Q4-26E: Q2/26 y/y + FY26 calibration Δ. 2027E–30E: scenario lever (Bull/Base/Bear table →). | CN32: 2027E | CO32: =CP32+$CO$31 -> 0.04 | CP32: 0.03 | CQ32: =CP32+$CQ$31 -> 0.02
B33: Price % | Y33: -0.022299 | Z33: -0.027359 | AA33: -0.009799 | AB33: -0.001526 | AC33: -0.015888 | AD33: 0.025735 | AE33: 0.033302 | AF33: 0.028821 | AG33: 0.05558 | AH33: 0.036127 | AI33: 0.054458 | AJ33: 0.054927 | AK33: 0.052425 | AL33: 0.037598 | AM33: 0.048033 | AN33: 0.026181 | AO33: 0.011657 | AP33: 0.002896 | AQ33: -0.003463 | AR33: 0.009958 | AS33: -0.007754 | AT33: -0.006029 | AU33: 0.000341 | AV33: 0.005036 | AW33: -0.002107 | AX33: 0.023342 | AY33: 0.08304 | AZ33: 0.107674 | BA33: 0.139304 | BB33: 0.089548 | BC33: 0.233953 | BD33: 0.185507 | BE33: 0.138358 | BF33: 0.116878 | BG33: 0.167837 | BH33: 0.057623 | BI33: 0.004222 | BJ33: 0.002203 | BK33: -0.006803 | BL33: 0.015395 | BM33: -0.015886 | BN33: -0.012427 | BO33: -0.005574 | BP33: 0.000325 | BQ33: -0.008089 | BR33: 0.003512 | BS33: 0.003568 | BT33: 0.00043 | BU33: 0.005305 | BV33: 0.003279 | BW33: 0.001356 | BX33: 0.016218 | BY33: =$BX$33 -> 0.016218 | BZ33: =$BX$33 -> 0.016218 | CA33: =IFERROR(SUMPRODUCT(BR29:BU29,BW33:BZ33)/SUM(BR29:BU29),"") -> 0.012720517 | CB33: =CHOOSE(MATCH($CF$2,{"Bull","Base","Bear"},0),$CO$47,$CP$47,$CQ$47) -> 0.015 | CC33: =CHOOSE(MATCH($CF$2,{"Bull","Base","Bear"},0),$CO$48,$CP$48,$CQ$48) -> 0.015 | CD33: =CHOOSE(MATCH($CF$2,{"Bull","Base","Bear"},0),$CO$49,$CP$49,$CQ$49) -> 0.015 | CE33: =CHOOSE(MATCH($CF$2,{"Bull","Base","Bear"},0),$CO$50,$CP$50,$CQ$50) -> 0.015 | CF33: Q3/Q4-26E: Q2/26 y/y price held. 2027E–30E: scenario lever. | CN33: 2028E | CO33: =CP33+$CO$31 -> 0.035 | CP33: 0.025 | CQ33: =CP33+$CQ$31 -> 0.015
B34: Acquisitions % (inorganic contribution, first 12 months) | Y34: 0.024884 | Z34: 0.026084 | AA34: 0.011353 | AB34: 0 | AC34: 0.016254 | AD34: 0 | AE34: 0 | AF34: 0.514536 | AG34: 0.856858 | AH34: 0.341876 | AI34: 0.798724 | AJ34: 0.680702 | AK34: 0.143378 | AL34: 0 | AM34: 0.314351 | AN34: 0 | AO34: 0 | AP34: 0.083069 | AQ34: 0.08953 | AR34: 0.040294 | AS34: 0.083921 | AT34: 0.071684 | AU34: 0 | AV34: 0 | AW34: 0.039234 | AX34: 0 | AY34: 0.020235 | AZ34: 0.017117 | BA34: 0.081557 | BB34: 0.031104 | BC34: 0.079039 | BD34: 0 | BE34: 0 | BF34: 0 | BG34: 0.018597 | BH34: 0.028507 | BI34: 0.025394 | BJ34: 0.048795 | BK34: 0.124012 | BL34: 0.056669 | BM34: 0 | BN34: 0.000225 | BO34: 0.004397 | BP34: 0.001845 | BQ34: 0.001596 | BR34: 0.003457 | BS34: 0.001319 | BT34: 0.036388 | BU34: 0.045761 | BV34: 0.021545 | BW34: 0.072099 | BX34: 0.06955 | BY34: 0.035 | BZ34: 0 | CA34: =IFERROR(SUMPRODUCT(BR29:BU29,BW34:BZ34)/SUM(BR29:BU29),"") -> 0.042620577 | CB34: 0 | CC34: 0 | CD34: 0 | CE34: 0 | CF34: Q3/Q4-26E: input — 2025 bolt-ons anniversary during 2H/26 (International Welding +7.0% in Q2/26, fading). 2027E+: 0% here; future bolt-ons modelled in the unallocated M&A block. | CN34: 2029E | CO34: =CP34+$CO$31 -> 0.035 | CP34: 0.025 | CQ34: =CP34+$CQ$31 -> 0.015
B35: Foreign exchange % | Y35: -0.039355 | Z35: -0.026908 | AA35: -0.018622 | AB35: -0.02517 | AC35: -0.02778 | AD35: -0.015792 | AE35: -0.000881 | AF35: 0.042647 | AG35: 0.072402 | AH35: 0.024592 | AI35: 0.102446 | AJ35: 0.029357 | AK35: -0.030514 | AL35: -0.042938 | AM35: 0.000463 | AN35: -0.071939 | AO35: -0.042544 | AP35: -0.044356 | AQ35: -0.01213 | AR35: -0.043604 | AS35: -0.028736 | AT35: -0.021789 | AU35: 0.011944 | AV35: 0.011052 | AW35: -0.007051 | AX35: 0.046917 | AY35: 0.066564 | AZ35: -0.00914 | BA35: -0.069494 | BB35: 0.005532 | BC35: -0.151677 | BD35: -0.180993 | BE35: -0.209698 | BF35: -0.140273 | BG35: -0.170428 | BH35: -0.051128 | BI35: 0.003212 | BJ35: 0.037765 | BK35: 0.035761 | BL35: 0.00465 | BM35: -0.001478 | BN35: -0.007877 | BO35: 0.014041 | BP35: -0.013355 | BQ35: -0.002762 | BR35: -0.019914 | BS35: 0.037992 | BT35: 0.021357 | BU35: 0.051852 | BV35: 0.023126 | BW35: 0.061691 | BX35: 0.006142 | BY35: =$BX$35 -> 0.006142 | BZ35: =$BX$35 -> 0.006142 | CA35: =IFERROR(SUMPRODUCT(BR29:BU29,BW35:BZ35)/SUM(BR29:BU29),"") -> 0.019214378 | CB35: 0 | CC35: 0 | CD35: 0 | CE35: 0 | CF35: Q3/Q4-26E: Q2/26 FX translation held; 2027E+: constant currency (0%). | CN35: 2030E | CO35: =CP35+$CO$31 -> 0.035 | CP35: 0.025 | CQ35: =CP35+$CQ$31 -> 0.015
B36: Net sales growth % (volume + price + acquisitions + FX) | C36: =IF(ISNUMBER(C32),C32+C33+C34+C35,"") | D36: =IF(ISNUMBER(D32),D32+D33+D34+D35,"") | E36: =IF(ISNUMBER(E32),E32+E33+E34+E35,"") | F36: =IF(ISNUMBER(F32),F32+F33+F34+F35,"") | G36: =IF(ISNUMBER(G32),G32+G33+G34+G35,"") | H36: =IF(ISNUMBER(H32),H32+H33+H34+H35,"") | I36: =IF(ISNUMBER(I32),I32+I33+I34+I35,"") | J36: =IF(ISNUMBER(J32),J32+J33+J34+J35,"") | ... BX36: =IF(ISNUMBER(BX32),BX32+BX33+BX34+BX35,"") -> 0.04496 | BY36: =BY32+BY33+BY34+BY35 -> 0.016180914 | BZ36: =BZ32+BZ33+BZ34+BZ35 -> -0.018819086 | CA36: =CA32+CA33+CA34+CA35 -> 0.018386205 | CB36: =CB32+CB33+CB34+CB35 -> 0.035 | CC36: =CC32+CC33+CC34+CC35 -> 0.035 | CD36: =CD32+CD33+CD34+CD35 -> 0.035 | CE36: =CE32+CE33+CE34+CE35 -> 0.035 | CN36: AW_mgn (Americas Welding Adj. EBIT margin, on external sales) | CO36: 0.015 | CP36: Δ → | CQ36: -0.015 | CR36: FY25 19.6%, 1H/26 19.3%; company guides 19–20% EBIT margin for the rest of 2026. RISE: ~19% avg / >20% peak (enterprise).
B37: Organic growth % (volume + price) | C37: =IF(ISNUMBER(C32),C32+C33,"") | D37: =IF(ISNUMBER(D32),D32+D33,"") | E37: =IF(ISNUMBER(E32),E32+E33,"") | F37: =IF(ISNUMBER(F32),F32+F33,"") | G37: =IF(ISNUMBER(G32),G32+G33,"") | H37: =IF(ISNUMBER(H32),H32+H33,"") | I37: =IF(ISNUMBER(I32),I32+I33,"") | J37: =IF(ISNUMBER(J32),J32+J33,"") | ... BX37: =IF(ISNUMBER(BX32),BX32+BX33,"") -> -0.030732 | BY37: =BY32+BY33 -> -0.024961086 | BZ37: =BZ32+BZ33 -> -0.024961086 | CA37: =CA32+CA33 -> -0.04344875 | CB37: =CB32+CB33 -> 0.035 | CC37: =CC32+CC33 -> 0.035 | CD37: =CD32+CD33 -> 0.035 | CE37: =CE32+CE33 -> 0.035 | CN37: 2027E | CO37: =CP37+$CO$36 -> 0.22 | CP37: 0.205 | CQ37: =CP37+$CQ$36 -> 0.19
B38: Check: Σ drivers vs reported y/y % (≈0; ≠0 where LECO recast the prior-year base) | C38: =IF(AND(ISNUMBER(C36),ISNUMBER(C30)),ROUND(C36-C30,3),"") | D38: =IF(AND(ISNUMBER(D36),ISNUMBER(D30)),ROUND(D36-D30,3),"") | E38: =IF(AND(ISNUMBER(E36),ISNUMBER(E30)),ROUND(E36-E30,3),"") | F38: =IF(AND(ISNUMBER(F36),ISNUMBER(F30)),ROUND(F36-F30,3),"") | G38: =IF(AND(ISNUMBER(G36),ISNUMBER(G30)),ROUND(G36-G30,3),"") | H38: =IF(AND(ISNUMBER(H36),ISNUMBER(H30)),ROUND(H36-H30,3),"") | I38: =IF(AND(ISNUMBER(I36),ISNUMBER(I30)),ROUND(I36-I30,3),"") | J38: =IF(AND(ISNUMBER(J36),ISNUMBER(J30)),ROUND(J36-J30,3),"") | ... BX38: =IF(AND(ISNUMBER(BX36),ISNUMBER(BX30)),ROUND(BX36-BX30,3),"") -> 0 | CN38: 2028E | CO38: =CP38+$CO$36 -> 0.223 | CP38: 0.208 | CQ38: =CP38+$CQ$36 -> 0.193
B39: Memo: inter-segment sales (eliminated in Corporate / Eliminations) | N39: 22.668 | O39: 5.988 | P39: 6.08 | Q39: 4.715 | R39: 4.825 | S39: 21.608 | T39: 5.027 | U39: 5.311 | V39: 5.4 | W39: 3.009 | X39: 18.747 | Y39: 4.426 | Z39: 3.841 | AA39: 3.688 | AB39: 4.02 | AC39: 15.975 | AD39: 4.285 | AE39: 5.478 | AF39: 5.451 | AG39: 3.646 | AH39: 18.86 | AI39: 4.509 | AJ39: 5.497 | AK39: 3.663 | AL39: 4.907 | AM39: 18.576 | AN39: 4.209 | AO39: 4.188 | AP39: 4.441 | AQ39: 4.853 | AR39: 17.691 | AS39: 4.483 | AT39: 4.286 | AU39: 4.898 | AV39: 4.827 | AW39: 18.494 | AX39: 4.285 | AY39: 6.897 | AZ39: 7.078 | BA39: 8.071 | BB39: 26.331 | BC39: 6.228 | BD39: 9.527 | BE39: 9.994 | BF39: 5.754 | BG39: 31.503 | BH39: 6.753 | BI39: 8.292 | BJ39: 4.896 | BK39: 11.557 | BL39: 31.498 | BM39: 8.408 | BN39: 8.849 | BO39: 7.371 | BP39: 11.233 | BQ39: 35.861 | BR39: 6.832 | BS39: 7.641 | BT39: 9.83 | BU39: 5.857 | BV39: 30.16 | BW39: 5.807 | BX39: 7.564 | CN39: 2029E | CO39: =CP39+$CO$36 -> 0.225 | CP39: 0.21 | CQ39: =CP39+$CQ$36 -> 0.195
B40: EBIT (GAAP segment result = operating income + other income) | N40: 29.921 | O40: 8.284 | P40: 14.471 | Q40: -13.757 | R40: 10.183 | S40: 19.181 | T40: 10.934 | U40: 9.778 | V40: -5.676 | W40: 2.804 | X40: 17.84 | Y40: 6.233 | Z40: 9.67 | AA40: 5.796 | AB40: 7.447 | AC40: 29.146 | AD40: 9.605 | AE40: 9.496 | AF40: 8.298 | AG40: 4.246 | AH40: 31.645 | AI40: 4.798 | AJ40: 4.734 | AK40: 8.085 | AL40: 11.371 | AM40: 28.988 | AN40: 11.138 | AO40: 17.805 | AP40: 14.681 | AQ40: 4.501 | AR40: 48.125 | AS40: 0.478 | AT40: 9.117 | AU40: 11.031 | AV40: 4.949 | AW40: 25.575 | AX40: 14.207 | AY40: 27.526 | AZ40: 22.417 | BA40: 26.824 | BB40: 90.974 | BC40: 35.74 | BD40: 34.855 | BE40: 16.861 | BF40: 21.02 | BG40: 108.476 | BH40: 29.296 | BI40: 30.519 | BJ40: 22.369 | BK40: 64.035 | BL40: 146.218 | BM40: 24.707 | BN40: -5.525 | BO40: 17.175 | BP40: 32.013 | BQ40: 68.37 | BR40: 21.6 | BS40: 28.999 | BT40: 23.059 | BU40: 25.485 | BV40: 99.143 | BW40: 20.89 | BX40: 24.313 | CN40: 2030E | CO40: =CP40+$CO$36 -> 0.225 | CP40: 0.21 | CQ40: =CP40+$CQ$36 -> 0.195
...

Sheet Bull-Base-Bear
B2: Lincoln Electric (LECO) — Bull / Base / Bear Case P&L Summary | J2: Share price ($): | K2: =Model!$CA$382 -> 275.54
B3: Adjusted figures (company current definitions: Adjusted EBIT, adjusted net income / EPS; Adjusted EBITDA model-derived) · USD millions · Live panel linked to Model — toggle scenario via Model!CF2. Bull and Bear panels are value snapshots generated from the Model with the switch set to each case. 2026E = 1H/26 actual + 2H/26E calibrated to the FY26 outlook range end-points. | J3: As of: | K3: =TODAY() -> 46302
B5: Scenario: | C5: =Model!$CF$2 -> Base | N5: Scenario: | O5: Bull | P5: Snapshot (values) — Model run with switch = Bull | Z5: Scenario: | AA5: Bear | AB5: Snapshot (values) — Model run with switch = Bear
B7: (USDm, except EPS and shares) | C7: 2025A | D7: 2026E | E7: 2027E | F7: 2028E | G7: 2029E | H7: 2030E | I7: 25-'30 CAGR | J7: LT Hist Avg | K7: LT Hist Min | L7: LT Hist Max | N7: (USDm, except EPS and shares) | O7: 2025A | P7: 2026E | Q7: 2027E | R7: 2028E | S7: 2029E | T7: 2030E | U7: 25-'30 CAGR | V7: LT Hist Avg | W7: LT Hist Min | X7: LT Hist Max | Z7: (USDm, except EPS and shares) | AA7: 2025A | AB7: 2026E | AC7: 2027E | AD7: 2028E | AE7: 2029E | AF7: 2030E | AG7: 25-'30 CAGR | AH7: LT Hist Avg | AI7: LT Hist Min | AJ7: LT Hist Max
B9: Net sales | C9: =Model!BV133 -> 4233.003 | D9: =Model!CA133 -> 4719.7983 | E9: =Model!CB133 -> 5019.0981 | F9: =Model!CC133 -> 5398.1929 | G9: =Model!CD133 -> 5778.445 | H9: =Model!CE133 -> 6175.8246 | I9: =IFERROR((H9/C9)^(1/5)-1,"n/m") -> 0.078472998 | N9: Net sales | O9: 4233.003 | P9: 4783.2934 | Q9: 5276.1656 | R9: 5918.2946 | S9: 6585.0381 | T9: 7294.5929 | U9: 0.11498878 | Z9: Net sales | AA9: 4233.003 | AB9: 4656.3033 | AC9: 4765.8402 | AD9: 4894.588 | AE9: 5011.1703 | AF9: 5130.6896 | AG9: 0.039215061
B10: Net sales y/y % | D10: =IFERROR(D9/C9-1,"") -> 0.115 | E10: =IFERROR(E9/D9-1,"") -> 0.063413666 | F10: =IFERROR(F9/E9-1,"") -> 0.075530466 | G10: =IFERROR(G9/F9-1,"") -> 0.070440637 | H10: =IFERROR(H9/G9-1,"") -> 0.068769299 | N10: Net sales y/y % | P10: 0.13 | Q10: 0.10304035 | R10: 0.12170372 | S10: 0.11265803 | T10: 0.10775258 | Z10: Net sales y/y % | AB10: 0.1 | AC10: 0.023524433 | AD10: 0.027014714 | AE10: 0.023818618 | AF10: 0.023850563
B11: Organic growth % (volume + price) | C11: =Model!BV113 -> 0.024661 | D11: =Model!CA113 -> 0.096797252 | E11: =Model!CB113 -> 0.050171575 | F11: =Model!CC113 -> 0.050255198 | G11: =Model!CD113 -> 0.047073877 | H11: =Model!CE113 -> 0.047107618 | J11: =IFERROR(AVERAGE(Model!C113,Model!D113,Model!E113,Model!F113,Model!G113,Model!H113,Model!I113,Model!N113,Model!S113,Model!X113,Model!AC113,Model!AH113,Model!AM113,Model!AR113,Model!AW113,Model!BB113,Model!BG113,Model!BL113,Model!BQ113,Model!BV113),"n/a") -> 0.043153188 | K11: =IFERROR(MIN(Model!C113,Model!D113,Model!E113,Model!F113,Model!G113,Model!H113,Model!I113,Model!N113,Model!S113,Model!X113,Model!AC113,Model!AH113,Model!AM113,Model!AR113,Model!AW113,Model!BB113,Model!BG113,Model!BL113,Model!BQ113,Model!BV113),"n/a") -> -0.122112 | L11: =IFERROR(MAX(Model!C113,Model!D113,Model!E113,Model!F113,Model!G113,Model!H113,Model!I113,Model!N113,Model!S113,Model!X113,Model!AC113,Model!AH113,Model!AM113,Model!AR113,Model!AW113,Model!BB113,Model!BG113,Model!BL113,Model!BQ113,Model!BV113),"n/a") -> 0.216856 | N11: Organic growth % (volume + price) | O11: 0.024661 | P11: 0.11179725 | Q11: 0.080174308 | R11: 0.08024885 | S11: 0.07706703 | T11: 0.07709989 | V11: 0.043153188 | W11: -0.122112 | X11: 0.216856 | Z11: Organic growth % (volume + price) | AA11: 0.024661 | AB11: 0.081797252 | AC11: 0.020168767 | AD11: 0.020261779 | AE11: 0.017080977 | AF11: 0.01711565 | AH11: 0.043153188 | AI11: -0.122112 | AJ11: 0.216856
B12: Adjusted EBIT (company definition) | C12: =Model!BV178 -> 752.632 | D12: =Model!CA178 -> 851.95165 | E12: =Model!CB178 -> 918.22028 | F12: =Model!CC178 -> 997.40069 | G12: =Model!CD178 -> 1074.135 | H12: =Model!CE178 -> 1142.0516 | I12: =IFERROR((H12/C12)^(1/5)-1,"n/m") -> 0.086977633 | N12: Adjusted EBIT (company definition) | O12: 752.632 | P12: 878.64569 | Q12: 1040.246 | R12: 1169.8671 | S12: 1302.1525 | T12: 1429.943 | U12: 0.1369653 | Z12: Adjusted EBIT (company definition) | AA12: 752.632 | AB12: 828.58457 | AC12: 803.13472 | AD12: 839.01994 | AE12: 869.75815 | AF12: 889.97456 | AG12: 0.034091534
B13: Adjusted EBIT margin % | C13: =IFERROR(C12/C9,"") -> 0.17780096 | D13: =IFERROR(D12/D9,"") -> 0.18050594 | E13: =IFERROR(E12/E9,"") -> 0.18294528 | F13: =IFERROR(F12/F9,"") -> 0.18476566 | G13: =IFERROR(G12/G9,"") -> 0.18588651 | H13: =IFERROR(H12/H9,"") -> 0.18492293 | J13: =IFERROR(AVERAGE(Model!C179,Model!D179,Model!E179,Model!F179,Model!G179,Model!H179,Model!I179,Model!N179,Model!S179,Model!X179,Model!AC179,Model!AH179,Model!AM179,Model!AR179,Model!AW179,Model!BB179,Model!BG179,Model!BL179,Model!BQ179,Model!BV179),"n/a") -> 0.1391968 | K13: =IFERROR(MIN(Model!C179,Model!D179,Model!E179,Model!F179,Model!G179,Model!H179,Model!I179,Model!N179,Model!S179,Model!X179,Model!AC179,Model!AH179,Model!AM179,Model!AR179,Model!AW179,Model!BB179,Model!BG179,Model!BL179,Model!BQ179,Model!BV179),"n/a") -> 0.070647695 | L13: =IFERROR(MAX(Model!C179,Model!D179,Model!E179,Model!F179,Model!G179,Model!H179,Model!I179,Model!N179,Model!S179,Model!X179,Model!AC179,Model!AH179,Model!AM179,Model!AR179,Model!AW179,Model!BB179,Model!BG179,Model!BL179,Model!BQ179,Model!BV179),"n/a") -> 0.1780154 | N13: Adjusted EBIT margin % | O13: 0.17780096 | P13: 0.18369053 | Q13: 0.19715946 | R13: 0.19766963 | S13: 0.19774412 | T13: 0.1960278 | V13: 0.1391968 | W13: 0.070647695 | X13: 0.1780154 | Z13: Adjusted EBIT margin % | AA13: 0.17780096 | AB13: 0.17794901 | AC13: 0.16851902 | AD13: 0.17141789 | AE13: 0.17356388 | AF13: 0.173461 | AH13: 0.1391968 | AI13: 0.070647695 | AJ13: 0.1780154
B15: Operating income (GAAP) | C15: =Model!BV140 -> 718.059 | D15: =Model!CA140 -> 838.98165 | E15: =Model!CB140 -> 901.22028 | F15: =Model!CC140 -> 980.40069 | G15: =Model!CD140 -> 1057.135 | H15: =Model!CE140 -> 1125.0516 | I15: =IFERROR((H15/C15)^(1/5)-1,"n/m") -> 0.093962564 | N15: Operating income (GAAP) | O15: 718.059 | P15: 865.67569 | Q15: 1023.246 | R15: 1152.8671 | S15: 1285.1525 | T15: 1412.943 | U15: 0.14496682 | Z15: Operating income (GAAP) | AA15: 718.059 | AB15: 815.61457 | AC15: 786.13472 | AD15: 822.01994 | AE15: 852.75815 | AF15: 872.97456 | AG15: 0.039844243
B16: Operating income y/y % | D16: =IFERROR(D15/C15-1,"") -> 0.16840211 | E16: =IFERROR(E15/D15-1,"") -> 0.074183546 | F16: =IFERROR(F15/E15-1,"") -> 0.087859101 | G16: =IFERROR(G15/F15-1,"") -> 0.078268325 | H16: =IFERROR(H15/G15-1,"") -> 0.064245878 | N16: Operating income y/y % | P16: 0.20557738 | Q16: 0.18202002 | R16: 0.12667642 | S16: 0.11474471 | T16: 0.099436029 | Z16: Operating income y/y % | AB16: 0.13586011 | AC16: -0.036144345 | AD16: 0.045647671 | AE16: 0.03739351 | AF16: 0.023707085
B17: Operating margin (GAAP) % | C17: =IFERROR(C15/C9,"") -> 0.16963347 | D17: =IFERROR(D15/D9,"") -> 0.17775794 | E17: =IFERROR(E15/E9,"") -> 0.17955821 | F17: =IFERROR(F15/F9,"") -> 0.18161646 | G17: =IFERROR(G15/G9,"") -> 0.18294455 | H17: =IFERROR(H15/H9,"") -> 0.18217026 | J17: =IFERROR(AVERAGE(Model!C224,Model!D224,Model!E224,Model!F224,Model!G224,Model!H224,Model!I224,Model!N224,Model!S224,Model!X224,Model!AC224,Model!AH224,Model!AM224,Model!AR224,Model!AW224,Model!BB224,Model!BG224,Model!BL224,Model!BQ224,Model!BV224),"n/a") -> 0.12583033 | K17: =IFERROR(MIN(Model!C224,Model!D224,Model!E224,Model!F224,Model!G224,Model!H224,Model!I224,Model!N224,Model!S224,Model!X224,Model!AC224,Model!AH224,Model!AM224,Model!AR224,Model!AW224,Model!BB224,Model!BG224,Model!BL224,Model!BQ224,Model!BV224),"n/a") -> 0.053765574 | L17: =IFERROR(MAX(Model!C224,Model!D224,Model!E224,Model!F224,Model!G224,Model!H224,Model!I224,Model!N224,Model!S224,Model!X224,Model!AC224,Model!AH224,Model!AM224,Model!AR224,Model!AW224,Model!BB224,Model!BG224,Model!BL224,Model!BQ224,Model!BV224),"n/a") -> 0.17125748 | N17: Operating margin (GAAP) % | O17: 0.16963347 | P17: 0.18097901 | Q17: 0.19393743 | R17: 0.19479718 | S17: 0.19516251 | T17: 0.19369731 | V17: 0.12583033 | W17: 0.053765574 | X17: 0.17125748 | Z17: Operating margin (GAAP) % | AA17: 0.16963347 | AB17: 0.17516354 | AC17: 0.16495197 | AD17: 0.16794466 | AE17: 0.17017146 | AF17: 0.17014761 | AH17: 0.12583033 | AI17: 0.053765574 | AJ17: 0.17125748
B19: Adjusted net income (attributable to Lincoln Electric) | C19: =Model!BV202 -> 551.331 | D19: =Model!CA202 -> 618.90333 | E19: =Model!CB202 -> 671.31629 | F19: =Model!CC202 -> 728.02672 | G19: =Model!CD202 -> 783.47776 | H19: =Model!CE202 -> 832.22228 | I19: =IFERROR((H19/C19)^(1/5)-1,"n/m") -> 0.085838872 | N19: Adjusted net income (attributable to Lincoln Electric) | O19: 551.331 | P19: 639.59121 | Q19: 763.47965 | R19: 844.57701 | S19: 938.94057 | T19: 1029.6657 | U19: 0.13307006 | Z19: Adjusted net income (attributable to Lincoln Electric) | AA19: 551.331 | AB19: 600.79384 | AC19: 584.15758 | AD19: 615.47462 | AE19: 638.55873 | AF19: 653.61848 | AG19: 0.034623602
B21: FDSO (m) | C21: =Model!BV157 -> 55.875 | D21: =Model!CA157 -> 55.019654 | E21: =Model!CB157 -> 53.999769 | F21: =Model!CC157 -> 52.983105 | G21: =Model!CD157 -> 51.942963 | H21: =Model!CE157 -> 50.871901 | I21: =IFERROR((H21/C21)^(1/5)-1,"n/m") -> -0.018586367 | N21: FDSO (m) | O21: 55.875 | P21: 54.974288 | Q21: 53.321162 | R21: 51.749417 | S21: 50.527746 | T21: 49.152485 | U21: -0.02531207 | Z21: FDSO (m) | AA21: 55.875 | AB21: 55.065019 | AC21: 54.547289 | AD21: 53.892911 | AE21: 52.900409 | AF21: 51.97857 | AG21: -0.014353105
B23: Adjusted EPS — Diluted ($) | C23: =Model!BV206 -> 9.8672215 | D23: =Model!CA206 -> 11.248768 | E23: =Model!CB206 -> 12.431836 | F23: =Model!CC206 -> 13.740733 | G23: =Model!CD206 -> 15.083424 | H23: =Model!CE206 -> 16.359174 | I23: =IFERROR((H23/C23)^(1/5)-1,"n/m") -> 0.10640288 | N23: Adjusted EPS — Diluted ($) | O23: 9.8672215 | P23: 11.63437 | Q23: 14.318511 | R23: 16.320513 | S23: 18.582673 | T23: 20.948395 | U23: 0.16249522 | Z23: Adjusted EPS — Diluted ($) | AA23: 9.8672215 | AB23: 10.910626 | AC23: 10.709195 | AD23: 11.420326 | AE23: 12.07096 | AF23: 12.574768 | AG23: 0.049689911
B24: EPS y/y % | D24: =IFERROR(D23/C23-1,"") -> 0.14001375 | E24: =IFERROR(E23/D23-1,"") -> 0.10517313 | F24: =IFERROR(F23/E23-1,"") -> 0.1052859 | G24: =IFERROR(G23/F23-1,"") -> 0.097716116 | H24: =IFERROR(H23/G23-1,"") -> 0.084579558 | N24: EPS y/y % | P24: 0.17909282 | Q24: 0.23070792 | R24: 0.1398191 | S24: 0.13860841 | T24: 0.12730797 | Z24: EPS y/y % | AB24: 0.10574454 | AC24: -0.018461908 | AD24: 0.066403751 | AE24: 0.056971592 | AF24: 0.041737201
B26: P / E (x) — assumed (adjusted EPS) | G26: 22 | H26: 22 | N26: P / E (x) — assumed (adjusted EPS) | S26: 22 | T26: 22 | Z26: P / E (x) — assumed (adjusted EPS) | AE26: 22 | AF26: 22
B27: Price Target ($) | G27: =G26*G23 -> 331.83534 | H27: =H26*H23 -> 359.90182 | N27: Price Target ($) | S27: 408.8188 | T27: 460.86469 | Z27: Price Target ($) | AE27: 265.56112 | AF27: 276.6449
B28: Upside / (Downside) vs current | G28: =IFERROR(G27/$K$2-1,"") -> 0.20430913 | H28: =IFERROR(H27/$K$2-1,"") -> 0.30616907 | N28: Upside / (Downside) vs current | S28: 0.48370038 | T28: 0.67258726 | Z28: Upside / (Downside) vs current | AE28: -0.036215706 | AF28: 0.0040099534
B29: IRR (to Dec-Y-1) | G29: =IFERROR((G27/$K$2)^(1/((DATE(2029-1,12,31)-$K$3)/365.25))-1,"") -> 0.086773777 | H29: =IFERROR((H27/$K$2)^(1/((DATE(2030-1,12,31)-$K$3)/365.25))-1,"") -> 0.086113825 | N29: IRR (to Dec-Y-1) | S29: 0.19315352 | T29: 0.17243251 | Z29: IRR (to Dec-Y-1) | AE29: -0.016375781 | AF29: 0.0012384519
B31: Free Cash Flow | C31: =Model!BV258 -> 534.199 | D31: =Model!CA258 -> 502.70628 | E31: =Model!CB258 -> 634.35813 | F31: =Model!CC258 -> 683.90773 | G31: =Model!CD258 -> 746.80176 | H31: =Model!CE258 -> 799.76997 | I31: =IFERROR((H31/C31)^(1/5)-1,"n/m") -> 0.084057714 | N31: Free Cash Flow | O31: 534.199 | P31: 505.90227 | Q31: 704.2469 | R31: 766.66549 | S31: 870.66708 | T31: 967.60723 | U31: 0.12615769 | Z31: Free Cash Flow | AA31: 534.199 | AB31: 502.42593 | AC31: 569.16104 | AD31: 603.62197 | AE31: 630.42953 | AF31: 646.00641 | AG31: 0.03873975
B32: FCF % | C32: =IFERROR(C31/C9,"") -> 0.12619859 | D32: =IFERROR(D31/D9,"") -> 0.10651012 | E32: =IFERROR(E31/E9,"") -> 0.12638887 | F32: =IFERROR(F31/F9,"") -> 0.12669198 | G32: =IFERROR(G31/G9,"") -> 0.12923923 | H32: =IFERROR(H31/H9,"") -> 0.12950011 | J32: =IFERROR(AVERAGE(Model!C260,Model!D260,Model!E260,Model!F260,Model!G260,Model!H260,Model!I260,Model!N260,Model!S260,Model!X260,Model!AC260,Model!AH260,Model!AM260,Model!AR260,Model!AW260,Model!BB260,Model!BG260,Model!BL260,Model!BQ260,Model!BV260),"n/a") -> 0.094282002 | K32: =IFERROR(MIN(Model!C260,Model!D260,Model!E260,Model!F260,Model!G260,Model!H260,Model!I260,Model!N260,Model!S260,Model!X260,Model!AC260,Model!AH260,Model!AM260,Model!AR260,Model!AW260,Model!BB260,Model!BG260,Model!BL260,Model!BQ260,Model!BV260),"n/a") -> 0.021642921 | L32: =IFERROR(MAX(Model!C260,Model!D260,Model!E260,Model!F260,Model!G260,Model!H260,Model!I260,Model!N260,Model!S260,Model!X260,Model!AC260,Model!AH260,Model!AM260,Model!AR260,Model!AW260,Model!BB260,Model!BG260,Model!BL260,Model!BQ260,Model!BV260),"n/a") -> 0.13754892 | N32: FCF % | O32: 0.12619859 | P32: 0.10576442 | Q32: 0.13347703 | R32: 0.12954162 | S32: 0.13221899 | T32: 0.13264719 | V32: 0.094282002 | W32: 0.021642921 | X32: 0.13754892 | Z32: FCF % | AA32: 0.12619859 | AB32: 0.10790232 | AC32: 0.11942512 | AD32: 0.12332437 | AE32: 0.12580485 | AF32: 0.12591025 | AH32: 0.094282002 | AI32: 0.021642921 | AJ32: 0.13754892
B33: FCF / share ($) | C33: =IFERROR(C31/C21,"") -> 9.5606085 | D33: =IFERROR(D31/D21,"") -> 9.1368492 | E33: =IFERROR(E31/E21,"") -> 11.747423 | F33: =IFERROR(F31/F21,"") -> 12.908034 | G33: =IFERROR(G31/G21,"") -> 14.377342 | H33: =IFERROR(H31/H21,"") -> 15.721252 | N33: FCF / share ($) | O33: 9.5606085 | P33: 9.2025252 | Q33: 13.207644 | R33: 14.814959 | S33: 17.231465 | T33: 19.685825 | Z33: FCF / share ($) | AA33: 9.5606085 | AB33: 9.1242306 | AC33: 10.434268 | AD33: 11.200396 | AE33: 11.91729 | AF33: 12.428322
B34: FCF Yield (on PT) | G34: =IFERROR(G33/G$27,"") -> 0.043326737 | H34: =IFERROR(H33/H$27,"") -> 0.043682056 | N34: FCF Yield (on PT) | S34: 0.042149394 | T34: 0.042714978 | Z34: FCF Yield (on PT) | AE34: 0.044875884 | AF34: 0.04492518
B35: Adjusted EBITDA (model-derived = Adjusted EBIT + D&A) | C35: =Model!BV184 -> 851.178 | D35: =Model!CA184 -> 954.57683 | E35: =Model!CB184 -> 1036.7845 | F35: =Model!CC184 -> 1131.1841 | G35: =Model!CD184 -> 1223.4242 | H35: =Model!CE184 -> 1307.5109 | I35: =IFERROR((H35/C35)^(1/5)-1,"n/m") -> 0.089644894 | N35: Adjusted EBITDA (model-derived = Adjusted EBIT + D&A) | O35: 851.178 | P35: 982.6228 | Q35: 1167.0665 | R35: 1322.8317 | S35: 1482.2822 | T35: 1638.6956 | U35: 0.13997566 | Z35: Adjusted EBITDA (model-derived = Adjusted EBIT + D&A) | AA35: 851.178 | AB35: 929.85782 | AC35: 913.53029 | AD35: 954.00171 | AE35: 989.11132 | AF35: 1013.8343 | AG35: 0.035593499
B36: Adjusted EBITDA % of net sales | C36: =IFERROR(C35/C9,"") -> 0.20108136 | D36: =IFERROR(D35/D9,"") -> 0.2022495 | E36: =IFERROR(E35/E9,"") -> 0.2065679 | F36: =IFERROR(F35/F9,"") -> 0.20954867 | G36: =IFERROR(G35/G9,"") -> 0.21172205 | H36: =IFERROR(H35/H9,"") -> 0.21171439 | J36: =IFERROR(AVERAGE(Model!C185,Model!D185,Model!E185,Model!F185,Model!G185,Model!H185,Model!I185,Model!N185,Model!S185,Model!X185,Model!AC185,Model!AH185,Model!AM185,Model!AR185,Model!AW185,Model!BB185,Model!BG185,Model!BL185,Model!BQ185,Model!BV185),"n/a") -> 0.1641208 | K36: =IFERROR(MIN(Model!C185,Model!D185,Model!E185,Model!F185,Model!G185,Model!H185,Model!I185,Model!N185,Model!S185,Model!X185,Model!AC185,Model!AH185,Model!AM185,Model!AR185,Model!AW185,Model!BB185,Model!BG185,Model!BL185,Model!BQ185,Model!BV185),"n/a") -> 0.10337683 | L36: =IFERROR(MAX(Model!C185,Model!D185,Model!E185,Model!F185,Model!G185,Model!H185,Model!I185,Model!N185,Model!S185,Model!X185,Model!AC185,Model!AH185,Model!AM185,Model!AR185,Model!AW185,Model!BB185,Model!BG185,Model!BL185,Model!BQ185,Model!BV185),"n/a") -> 0.20108136 | N36: Adjusted EBITDA % of net sales | O36: 0.20108136 | P36: 0.20542809 | Q36: 0.22119597 | R36: 0.22351568 | S36: 0.22509849 | T36: 0.22464524 | V36: 0.1641208 | W36: 0.10337683 | X36: 0.20108136 | Z36: Adjusted EBITDA % of net sales | AA36: 0.20108136 | AB36: 0.19969872 | AC36: 0.19168295 | AD36: 0.1949095 | AE36: 0.1973813 | AF36: 0.19760195 | AH36: 0.1641208 | AI36: 0.10337683 | AJ36: 0.20108136
B38: Net Debt | C38: =Model!BV377 -> 985.219 | D38: =Model!CA377 -> 926.17462 | E38: =Model!CB377 -> 1036.7845 | F38: =Model!CC377 -> 1131.1841 | G38: =Model!CD377 -> 1223.4242 | H38: =Model!CE377 -> 1307.5109 | N38: Net Debt | O38: 985.219 | P38: 972.83527 | Q38: 1458.8332 | R38: 1653.5396 | S38: 1852.8527 | T38: 2048.3695 | Z38: Net Debt | AA38: 985.219 | AB38: 876.59832 | AC38: 685.14772 | AD38: 715.50128 | AE38: 741.83349 | AF38: 760.3757
B39: Net Debt / Adjusted EBITDA (x) | C39: =IFERROR(C38/C35,"") -> 1.157477 | D39: =IFERROR(D38/D35,"") -> 0.97024628 | E39: =IFERROR(E38/E35,"") -> 1 | F39: =IFERROR(F38/F35,"") -> 1 | G39: =IFERROR(G38/G35,"") -> 1 | H39: =IFERROR(H38/H35,"") -> 1 | N39: Net Debt / Adjusted EBITDA (x) | O39: 1.157477 | P39: 0.99003938 | Q39: 1.25 | R39: 1.25 | S39: 1.25 | T39: 1.25 | Z39: Net Debt / Adjusted EBITDA (x) | AA39: 1.157477 | AB39: 0.94272296 | AC39: 0.75 | AD39: 0.75 | AE39: 0.75 | AF39: 0.75
B40: Share repurchases ($m) | D40: =Model!CA269 -> 150 | E40: =Model!CB269 -> 378.88408 | F40: =Model!CC269 -> 404.99127 | G40: =Model!CD269 -> 458.22859 | H40: =Model!CE269 -> 495.5639 | N40: Share repurchases ($m) | P40: 200 | Q40: 674.76867 | R40: 442.23043 | S40: 544.02808 | T40: 630.97022 | Z40: Share repurchases ($m) | AB40: 100 | AC40: 161.01865 | AD40: 407.41576 | AE40: 422.53848 | AF40: 422.23109
B41: Implied avg buyback price ($) | D41: =Model!CA268 -> 275.54 | E41: =Model!CB268 -> 297.5832 | F41: =Model!CC268 -> 321.38986 | G41: =Model!CD268 -> 347.10104 | H41: =Model!CE268 -> 374.86913 | N41: Implied avg buyback price ($) | P41: 275.54 | Q41: 297.5832 | R41: 321.38986 | S41: 347.10104 | T41: 374.86913 | Z41: Implied avg buyback price ($) | AB41: 275.54 | AC41: 297.5832 | AD41: 321.38986 | AE41: 347.10104 | AF41: 374.86913
B42: Shares repurchased (m) | D42: =Model!CA270 -> 0.54438557 | E42: =Model!CB270 -> 1.2732039 | F42: =Model!CC270 -> 1.2601246 | G42: =Model!CD270 -> 1.3201591 | H42: =Model!CE270 -> 1.3219651 | N42: Shares repurchased (m) | P42: 0.72584743 | Q42: 2.2674959 | R42: 1.3759937 | S42: 1.5673479 | T42: 1.6831747 | Z42: Shares repurchased (m) | AB42: 0.36292371 | AC42: 0.54108783 | AD42: 1.2676684 | AE42: 1.2173357 | AF42: 1.1263427
B44: ROIC | C44: =Model!BV360 -> 0.2362566 | D44: =Model!CA360 -> 0.25778089 | E44: =Model!CB360 -> 0.2514502 | F44: =Model!CC360 -> 0.24986307 | G44: =Model!CD360 -> 0.24837312 | H44: =Model!CE360 -> 0.24535598 | J44: =IFERROR(AVERAGE(Model!C360,Model!D360,Model!E360,Model!F360,Model!G360,Model!H360,Model!I360,Model!N360,Model!S360,Model!X360,Model!AC360,Model!AH360,Model!AM360,Model!AR360,Model!AW360,Model!BB360,Model!BG360,Model!BL360,Model!BQ360,Model!BV360),"n/a") -> 0.23179901 | K44: =IFERROR(MIN(Model!C360,Model!D360,Model!E360,Model!F360,Model!G360,Model!H360,Model!I360,Model!N360,Model!S360,Model!X360,Model!AC360,Model!AH360,Model!AM360,Model!AR360,Model!AW360,Model!BB360,Model!BG360,Model!BL360,Model!BQ360,Model!BV360),"n/a") -> 0.083557813 | L44: =IFERROR(MAX(Model!C360,Model!D360,Model!E360,Model!F360,Model!G360,Model!H360,Model!I360,Model!N360,Model!S360,Model!X360,Model!AC360,Model!AH360,Model!AM360,Model!AR360,Model!AW360,Model!BB360,Model!BG360,Model!BL360,Model!BQ360,Model!BV360),"n/a") -> 0.29017761 | N44: ROIC | O44: 0.2362566 | P44: 0.26406088 | Q44: 0.26674222 | R44: 0.26101585 | S44: 0.25754856 | T44: 0.25414622 | V44: 0.23179901 | W44: 0.083557813 | X44: 0.29017761 | Z44: ROIC | AA44: 0.2362566 | AB44: 0.25246252 | AC44: 0.23596817 | AD44: 0.23946796 | AE44: 0.24161855 | AF44: 0.24080356 | AH44: 0.23179901 | AI44: 0.083557813 | AJ44: 0.29017761
