Workbook

Sheet Model
CF1: SCENARIO SWITCH ▼ (Bull / Base / Bear) — drives all scenario-linked forecast drivers
B2: Amazon.com, Inc. (NASDAQ: AMZN) — 3-Statement Financial Model | CF2: Base
B3: US GAAP as reported · USD millions (per-share data in USD; shares in millions, split-adjusted) · Fiscal years ended 31 December · Source: Amazon.com Forms 10-K / 10-Q, Form 8-K earnings releases (Ex. 99.1, incl. the 23-Apr-2015 AWS recast Ex. 99.3) and financing 8-Ks, SEC EDGAR (CIK 0001018724); XBRL company facts; the investor-relations releases are the same documents as filed on EDGAR. Guidance: Q3-26 only (8-K 30-Jul-2026); the ~$200bn 2026 capex figure is from the call and UNVERIFIED (information row only).
B4: Basis notes: as originally reported. Segments NA / International to 2014 (AWS inside NA), AWS from 2015 (FY2013–14 recast); 2015 segment OI restated for SBC allocation (2016 releases). 20-for-1 split 6-Jun-2022. ASC 606 (2018, modified retrospective), ASC 842 (2019). Acquisitions: Whole Foods 28-Aug-17 ($13.2bn), MGM 17-Mar-22 ($6.1bn + $2.5bn debt), One Medical 22-Feb-23 ($3.5bn). Q3/26E calibrated to Q3-26 guidance (net sales, operating income); Q4/26E carries the Q3 Δs (no guidance).
CH5: Forecast | CI5: Historical | CJ5: Historical | CK5: Historical
B6: (USDm) | C6: 2006 | D6: 2007 | E6: 2008 | F6: 2009 | G6: 2010 | H6: 2011 | I6: 2012 | J6: Q1/13 | K6: Q2/13 | L6: Q3/13 | M6: Q4/13 | N6: 2013 | O6: Q1/14 | P6: Q2/14 | Q6: Q3/14 | R6: Q4/14 | S6: 2014 | T6: Q1/15 | U6: Q2/15 | V6: Q3/15 | W6: Q4/15 | X6: 2015 | Y6: Q1/16 | Z6: Q2/16 | AA6: Q3/16 | AB6: Q4/16 | AC6: 2016 | AD6: Q1/17 | AE6: Q2/17 | AF6: Q3/17 | AG6: Q4/17 | AH6: 2017 | AI6: Q1/18 | AJ6: Q2/18 | AK6: Q3/18 | AL6: Q4/18 | AM6: 2018 | AN6: Q1/19 | AO6: Q2/19 | AP6: Q3/19 | AQ6: Q4/19 | AR6: 2019 | AS6: Q1/20 | AT6: Q2/20 | AU6: Q3/20 | AV6: Q4/20 | AW6: 2020 | AX6: Q1/21 | AY6: Q2/21 | AZ6: Q3/21 | BA6: Q4/21 | BB6: 2021 | BC6: Q1/22 | BD6: Q2/22 | BE6: Q3/22 | BF6: Q4/22 | BG6: 2022 | BH6: Q1/23 | BI6: Q2/23 | BJ6: Q3/23 | BK6: Q4/23 | BL6: 2023 | BM6: Q1/24 | BN6: Q2/24 | BO6: Q3/24 | BP6: Q4/24 | BQ6: 2024 | BR6: Q1/25 | BS6: Q2/25 | BT6: Q3/25 | BU6: Q4/25 | BV6: 2025 | BW6: Q1/26 | BX6: Q2/26 | BY6: Q3/26E | BZ6: Q4/26E | CA6: 2026E | CB6: 2027E | CC6: 2028E | CD6: 2029E | CE6: 2030E | CF6: Modelling Notes | CH6: 5Y CAGR | CI6: 5Y CAGR | CJ6: 10Y CAGR | CK6: 19Y CAGR
CH7: 25-'30 | CI7: 20-'25 | CJ7: 15-'25 | CK7: 06-'25
B8: NET SALES BUILD — GROUPS OF SIMILAR PRODUCTS & SERVICES → SEGMENTS (NORTH AMERICA · INTERNATIONAL · AWS) | CF8: NET SALES BUILD — modelling logic (product-group net sales → retail groups split NA / International by the NA share; AWS group = AWS segment → segment operating income at segment margins → GAAP P&L)
CN9: SCENARIO INPUT TABLE — driver assumptions per Bull / Base / Bear | CO9: Bull | CP9: Base | CQ9: Bear | CR9: Bull / Bear = Base + Δ (Δ inputs on each block header). Outlook block = high / mid / low end of the Q3-26 guidance ranges.
B10: Net sales by groups of similar products and services (supplemental release table; from Q2-16; advertising services split out of "Other" from Q3-20) | CF10: PRODUCT GROUPS — modelling logic: Q3/Q4-26E = prior-year quarter × (1 + growth); 2027E+ = prior year × (1 + scenario lever)
B11: Online stores | Z11: 20378 | AA11: 21590 | AB11: 29548 | AD11: 22826 | AE11: 23754 | AF11: 26392 | AG11: 35383 | AH11: 108355 | AI11: 26939 | AJ11: 27165 | AK11: 29061 | AL11: 39822 | AM11: 122987 | AN11: 29498 | AO11: 31053 | AP11: 35039 | AQ11: 45657 | AR11: 141247 | AS11: 36652 | AT11: 45896 | AU11: 48350 | AV11: 66451 | AW11: 197349 | AX11: 52901 | AY11: 53157 | AZ11: 49942 | BA11: 66075 | BB11: 222075 | BC11: 51129 | BD11: 50855 | BE11: 53489 | BF11: 64531 | BG11: 220004 | BH11: 51096 | BI11: 52966 | BJ11: 57267 | BK11: 70543 | BL11: 231872 | BM11: 54670 | BN11: 55392 | BO11: 61411 | BP11: 75556 | BQ11: 247029 | BR11: 57407 | BS11: 61485 | BT11: 67407 | BU11: 82988 | BV11: 269287 | BW11: 64254 | BX11: 70432 | BY11: =BT11*(1+BY12) -> 68792.361 | BZ11: =BU11*(1+BZ12) -> 89380.837 | CA11: =SUM(BW11:BZ11) -> 292859.2 | CB11: =CA11*(1+CB12) -> 317752.23 | CC11: =CB11*(1+CC12) -> 343172.41 | CD11: =CC11*(1+CD12) -> 368910.34 | CE11: =CD11*(1+CE12) -> 394734.06 | CF11: Latest release presenting each quarter (Amazon re-presents the groups). FY = Σ quarters. Q3/Q4-26E: prior-year quarter × (1 + growth). | CH11: =IFERROR((CE11/BV11)^(1/5)-1,"n/m") -> 0.07948806 | CI11: =IFERROR((BV11/AW11)^(1/5)-1,"n/m") -> 0.064133442 | CJ11: =IFERROR((BV11/X11)^(1/10)-1,"n/m") -> n/m | CK11: =IFERROR((BV11/C11)^(1/19)-1,"n/m") -> n/m | CN11: Q3-26 guidance — Q2-26 release (8-K, 30-Jul-2026) | CO11: High | CP11: Mid | CQ11: Low | CR11: Net sales $197.0–202.0bn (+9–12% y/y; ~80 bp FX headwind; Prime Day in Q2 in 2026 vs Q3 in 2025 — ex Prime Day growth ~400 bp higher); operating income $22.5–26.5bn (assumes no energy-derivative remeasurement, acquisitions, restructurings or legal settlements). Amazon guides one quarter ahead.
B12: y/y % | D12: =IF(AND(ISNUMBER(D11),ISNUMBER(C11)),IFERROR(D11/C11-1,""),"") | E12: =IF(AND(ISNUMBER(E11),ISNUMBER(D11)),IFERROR(E11/D11-1,""),"") | F12: =IF(AND(ISNUMBER(F11),ISNUMBER(E11)),IFERROR(F11/E11-1,""),"") | G12: =IF(AND(ISNUMBER(G11),ISNUMBER(F11)),IFERROR(G11/F11-1,""),"") | H12: =IF(AND(ISNUMBER(H11),ISNUMBER(G11)),IFERROR(H11/G11-1,""),"") | I12: =IF(AND(ISNUMBER(I11),ISNUMBER(H11)),IFERROR(I11/H11-1,""),"") | N12: =IF(AND(ISNUMBER(N11),ISNUMBER(I11)),IFERROR(N11/I11-1,""),"") | O12: =IF(AND(ISNUMBER(O11),ISNUMBER(J11)),IFERROR(O11/J11-1,""),"") | P12: =IF(AND(ISNUMBER(P11),ISNUMBER(K11)),IFERROR(P11/K11-1,""),"") | Q12: =IF(AND(ISNUMBER(Q11),ISNUMBER(L11)),IFERROR(Q11/L11-1,""),"") | R12: =IF(AND(ISNUMBER(R11),ISNUMBER(M11)),IFERROR(R11/M11-1,""),"") | S12: =IF(AND(ISNUMBER(S11),ISNUMBER(N11)),IFERROR(S11/N11-1,""),"") | T12: =IF(AND(ISNUMBER(T11),ISNUMBER(O11)),IFERROR(T11/O11-1,""),"") | U12: =IF(AND(ISNUMBER(U11),ISNUMBER(P11)),IFERROR(U11/P11-1,""),"") | ... BX12: =IF(AND(ISNUMBER(BX11),ISNUMBER(BS11)),IFERROR(BX11/BS11-1,""),"") -> 0.14551517 | BY12: =BY13+BY32+BY114 -> 0.020552184 | BZ12: =BZ13+BZ32+BZ114 -> 0.077033265 | CA12: =IF(AND(ISNUMBER(CA11),ISNUMBER(BV11)),IFERROR(CA11/BV11-1,""),"") -> 0.087535595 | CB12: =CHOOSE(MATCH($CF$2,{"Bull","Base","Bear"},0),$CO$32,$CP$32,$CQ$32) -> 0.085 | CC12: =CHOOSE(MATCH($CF$2,{"Bull","Base","Bear"},0),$CO$33,$CP$33,$CQ$33) -> 0.08 | CD12: =CHOOSE(MATCH($CF$2,{"Bull","Base","Bear"},0),$CO$34,$CP$34,$CQ$34) -> 0.075 | CE12: =CHOOSE(MATCH($CF$2,{"Bull","Base","Bear"},0),$CO$35,$CP$35,$CQ$35) -> 0.07 | CF12: Q3/Q4-26E: Q1-26 y/y (before the Prime Day shift) + Prime Day timing shift (Q3 only; online stores, third-party seller services, advertising) + net-sales guidance calibration Δ (retail groups only). 2027E+: scenario lever. | CN12: Q3-26 net sales ($m) | CO12: 202000 | CP12: 199500 | CQ12: 197000 | CR12: Guided $197.0–202.0bn. Drives the Q3/26E net-sales calibration (retail product groups).
B13: Q3/Q4-26E growth before calibration (Q1-26 y/y) | BY13: =IFERROR(BW11/BR11-1,0) -> 0.11927117 | BZ13: =IFERROR(BW11/BR11-1,0) -> 0.11927117 | CN13: Q3-26 operating income ($m) | CO13: 26500 | CP13: 24500 | CQ13: 22500 | CR13: Guided $22.5–26.5bn (Q3-25 $17.4bn incl. $4.3bn special charges). Drives the segment-margin calibration.
B14: Physical stores | Z14: 0 | AA14: 0 | AB14: 0 | AD14: 0 | AE14: 0 | AF14: 1276 | AG14: 4522 | AH14: 5798 | AI14: 4263 | AJ14: 4312 | AK14: 4248 | AL14: 4401 | AM14: 17224 | AN14: 4307 | AO14: 4330 | AP14: 4192 | AQ14: 4363 | AR14: 17192 | AS14: 4640 | AT14: 3774 | AU14: 3788 | AV14: 4022 | AW14: 16224 | AX14: 3920 | AY14: 4198 | AZ14: 4269 | BA14: 4688 | BB14: 17075 | BC14: 4591 | BD14: 4721 | BE14: 4694 | BF14: 4957 | BG14: 18963 | BH14: 4895 | BI14: 5024 | BJ14: 4959 | BK14: 5152 | BL14: 20030 | BM14: 5202 | BN14: 5206 | BO14: 5228 | BP14: 5579 | BQ14: 21215 | BR14: 5533 | BS14: 5595 | BT14: 5578 | BU14: 5855 | BV14: 22561 | BW14: 5785 | BX14: 5794 | BY14: =BT14*(1+BY15) -> 5596.4465 | BZ14: =BU14*(1+BZ15) -> 5874.3625 | CA14: =SUM(BW14:BZ14) -> 23049.809 | CB14: =CA14*(1+CB15) -> 24202.299 | CC14: =CB14*(1+CC15) -> 25412.414 | CD14: =CC14*(1+CD15) -> 26555.973 | CE14: =CD14*(1+CE15) -> 27618.212 | CF14: Whole Foods Market from 28-Aug-2017 (blank before = 0). | CH14: =IFERROR((CE14/BV14)^(1/5)-1,"n/m") -> 0.041279798 | CI14: =IFERROR((BV14/AW14)^(1/5)-1,"n/m") -> 0.068169275 | CJ14: =IFERROR((BV14/X14)^(1/10)-1,"n/m") -> n/m | CK14: =IFERROR((BV14/C14)^(1/19)-1,"n/m") -> n/m
B15: y/y % | D15: =IF(AND(ISNUMBER(D14),ISNUMBER(C14)),IFERROR(D14/C14-1,""),"") | E15: =IF(AND(ISNUMBER(E14),ISNUMBER(D14)),IFERROR(E14/D14-1,""),"") | F15: =IF(AND(ISNUMBER(F14),ISNUMBER(E14)),IFERROR(F14/E14-1,""),"") | G15: =IF(AND(ISNUMBER(G14),ISNUMBER(F14)),IFERROR(G14/F14-1,""),"") | H15: =IF(AND(ISNUMBER(H14),ISNUMBER(G14)),IFERROR(H14/G14-1,""),"") | I15: =IF(AND(ISNUMBER(I14),ISNUMBER(H14)),IFERROR(I14/H14-1,""),"") | N15: =IF(AND(ISNUMBER(N14),ISNUMBER(I14)),IFERROR(N14/I14-1,""),"") | O15: =IF(AND(ISNUMBER(O14),ISNUMBER(J14)),IFERROR(O14/J14-1,""),"") | P15: =IF(AND(ISNUMBER(P14),ISNUMBER(K14)),IFERROR(P14/K14-1,""),"") | Q15: =IF(AND(ISNUMBER(Q14),ISNUMBER(L14)),IFERROR(Q14/L14-1,""),"") | R15: =IF(AND(ISNUMBER(R14),ISNUMBER(M14)),IFERROR(R14/M14-1,""),"") | S15: =IF(AND(ISNUMBER(S14),ISNUMBER(N14)),IFERROR(S14/N14-1,""),"") | T15: =IF(AND(ISNUMBER(T14),ISNUMBER(O14)),IFERROR(T14/O14-1,""),"") | U15: =IF(AND(ISNUMBER(U14),ISNUMBER(P14)),IFERROR(U14/P14-1,""),"") | ... BX15: =IF(AND(ISNUMBER(BX14),ISNUMBER(BS14)),IFERROR(BX14/BS14-1,""),"") -> 0.035567471 | BY15: =BY16+BY114 -> 0.0033070086 | BZ15: =BZ16+BZ114 -> 0.0033070086 | CA15: =IF(AND(ISNUMBER(CA14),ISNUMBER(BV14)),IFERROR(CA14/BV14-1,""),"") -> 0.021666107 | CB15: =CHOOSE(MATCH($CF$2,{"Bull","Base","Bear"},0),$CO$37,$CP$37,$CQ$37) -> 0.05 | CC15: =CHOOSE(MATCH($CF$2,{"Bull","Base","Bear"},0),$CO$38,$CP$38,$CQ$38) -> 0.05 | CD15: =CHOOSE(MATCH($CF$2,{"Bull","Base","Bear"},0),$CO$39,$CP$39,$CQ$39) -> 0.045 | CE15: =CHOOSE(MATCH($CF$2,{"Bull","Base","Bear"},0),$CO$40,$CP$40,$CQ$40) -> 0.04 | CN15: Q3/26E–Q4/26E point estimates (all cases)
B16: Q3/Q4-26E growth before calibration (Q1-26 y/y) | BY16: =IFERROR(BW14/BR14-1,0) -> 0.045544912 | BZ16: =IFERROR(BW14/BR14-1,0) -> 0.045544912 | CN16: Prime Day timing shift on Q3-26 total growth (pp) | CP16: -0.04 | CR16: Guidance: "nearly 400 basis points" (8-K 30-Jul-2026).
B17: Third-party seller services | Z17: 5083 | AA17: 5652 | AB17: 7456 | AD17: 6438 | AE17: 6991 | AF17: 7928 | AG17: 10523 | AH17: 31880 | AI17: 9265 | AJ17: 9702 | AK17: 10395 | AL17: 13383 | AM17: 42745 | AN17: 11141 | AO17: 11962 | AP17: 13212 | AQ17: 17446 | AR17: 53761 | AS17: 14479 | AT17: 18195 | AU17: 20436 | AV17: 27327 | AW17: 80437 | AX17: 23709 | AY17: 25085 | AZ17: 24252 | BA17: 30320 | BB17: 103366 | BC17: 25335 | BD17: 27376 | BE17: 28666 | BF17: 36339 | BG17: 117716 | BH17: 29820 | BI17: 32332 | BJ17: 34342 | BK17: 43559 | BL17: 140053 | BM17: 34596 | BN17: 36201 | BO17: 37864 | BP17: 47485 | BQ17: 156146 | BR17: 36512 | BS17: 40348 | BT17: 42486 | BU17: 52816 | BV17: 172162 | BW17: 41578 | BX17: 46780 | BY17: =BT17*(1+BY18) -> 44186.711 | BZ17: =BU17*(1+BZ18) -> 57913.325 | CA17: =SUM(BW17:BZ17) -> 190458.04 | CB17: =CA17*(1+CB18) -> 211408.42 | CC17: =CB17*(1+CC18) -> 232549.26 | CD17: =CC17*(1+CD18) -> 254641.44 | CE17: =CD17*(1+CE18) -> 277559.17 | CH17: =IFERROR((CE17/BV17)^(1/5)-1,"n/m") -> 0.10023044 | CI17: =IFERROR((BV17/AW17)^(1/5)-1,"n/m") -> 0.16438416 | CJ17: =IFERROR((BV17/X17)^(1/10)-1,"n/m") -> n/m | CK17: =IFERROR((BV17/C17)^(1/19)-1,"n/m") -> n/m | CN17: Gross capex per quarter, Q3/Q4-26E ($m) | CP17: 54208 | CR17: Q2-26 purchases of P&E $54.2bn (Q1 $44.2bn); held at the Q2 run-rate (assumption).
B18: y/y % | D18: =IF(AND(ISNUMBER(D17),ISNUMBER(C17)),IFERROR(D17/C17-1,""),"") | E18: =IF(AND(ISNUMBER(E17),ISNUMBER(D17)),IFERROR(E17/D17-1,""),"") | F18: =IF(AND(ISNUMBER(F17),ISNUMBER(E17)),IFERROR(F17/E17-1,""),"") | G18: =IF(AND(ISNUMBER(G17),ISNUMBER(F17)),IFERROR(G17/F17-1,""),"") | H18: =IF(AND(ISNUMBER(H17),ISNUMBER(G17)),IFERROR(H17/G17-1,""),"") | I18: =IF(AND(ISNUMBER(I17),ISNUMBER(H17)),IFERROR(I17/H17-1,""),"") | N18: =IF(AND(ISNUMBER(N17),ISNUMBER(I17)),IFERROR(N17/I17-1,""),"") | O18: =IF(AND(ISNUMBER(O17),ISNUMBER(J17)),IFERROR(O17/J17-1,""),"") | P18: =IF(AND(ISNUMBER(P17),ISNUMBER(K17)),IFERROR(P17/K17-1,""),"") | Q18: =IF(AND(ISNUMBER(Q17),ISNUMBER(L17)),IFERROR(Q17/L17-1,""),"") | R18: =IF(AND(ISNUMBER(R17),ISNUMBER(M17)),IFERROR(R17/M17-1,""),"") | S18: =IF(AND(ISNUMBER(S17),ISNUMBER(N17)),IFERROR(S17/N17-1,""),"") | T18: =IF(AND(ISNUMBER(T17),ISNUMBER(O17)),IFERROR(T17/O17-1,""),"") | U18: =IF(AND(ISNUMBER(U17),ISNUMBER(P17)),IFERROR(U17/P17-1,""),"") | ... BX18: =IF(AND(ISNUMBER(BX17),ISNUMBER(BS17)),IFERROR(BX17/BS17-1,""),"") -> 0.15941311 | BY18: =BY19+BY32+BY114 -> 0.04002992 | BZ18: =BZ19+BZ32+BZ114 -> 0.096511001 | CA18: =IF(AND(ISNUMBER(CA17),ISNUMBER(BV17)),IFERROR(CA17/BV17-1,""),"") -> 0.10627221 | CB18: =CHOOSE(MATCH($CF$2,{"Bull","Base","Bear"},0),$CO$42,$CP$42,$CQ$42) -> 0.11 | CC18: =CHOOSE(MATCH($CF$2,{"Bull","Base","Bear"},0),$CO$43,$CP$43,$CQ$43) -> 0.1 | CD18: =CHOOSE(MATCH($CF$2,{"Bull","Base","Bear"},0),$CO$44,$CP$44,$CQ$44) -> 0.095 | CE18: =CHOOSE(MATCH($CF$2,{"Bull","Base","Bear"},0),$CO$45,$CP$45,$CQ$45) -> 0.09 | CN18: Proceeds from P&E sales and incentives, % of gross capex | CP18: 0.02 | CR18: 1H-26 2.1%; FY2025 2.7%.
B19: Q3/Q4-26E growth before calibration (Q1-26 y/y) | BY19: =IFERROR(BW17/BR17-1,0) -> 0.1387489 | BZ19: =IFERROR(BW17/BR17-1,0) -> 0.1387489 | CN19: Other operating expense (income), net per quarter ($m) | CP19: 300 | CR19: 1H-26 $537m.
B20: Subscription services | Z20: 1431 | AA20: 1532 | AB20: 2130 | AD20: 1939 | AE20: 2165 | AF20: 2441 | AG20: 3177 | AH20: 9722 | AI20: 3102 | AJ20: 3408 | AK20: 3698 | AL20: 3959 | AM20: 14167 | AN20: 4342 | AO20: 4676 | AP20: 4957 | AQ20: 5235 | AR20: 19210 | AS20: 5556 | AT20: 6018 | AU20: 6572 | AV20: 7061 | AW20: 25207 | AX20: 7580 | AY20: 7917 | AZ20: 8148 | BA20: 8123 | BB20: 31768 | BC20: 8410 | BD20: 8716 | BE20: 8903 | BF20: 9189 | BG20: 35218 | BH20: 9657 | BI20: 9894 | BJ20: 10170 | BK20: 10488 | BL20: 40209 | BM20: 10722 | BN20: 10866 | BO20: 11278 | BP20: 11508 | BQ20: 44374 | BR20: 11715 | BS20: 12208 | BT20: 12574 | BU20: 13122 | BV20: 49619 | BW20: 13427 | BX20: 13730 | BY20: =BT20*(1+BY21) -> 13880.433 | BZ20: =BU20*(1+BZ21) -> 14485.37 | CA20: =SUM(BW20:BZ20) -> 55522.802 | CB20: =CA20*(1+CB21) -> 61630.31 | CC20: =CB20*(1+CC21) -> 67793.342 | CD20: =CC20*(1+CD21) -> 74233.709 | CE20: =CD20*(1+CE21) -> 80914.743 | CH20: =IFERROR((CE20/BV20)^(1/5)-1,"n/m") -> 0.10274711 | CI20: =IFERROR((BV20/AW20)^(1/5)-1,"n/m") -> 0.14505242 | CJ20: =IFERROR((BV20/X20)^(1/10)-1,"n/m") -> n/m | CK20: =IFERROR((BV20/C20)^(1/19)-1,"n/m") -> n/m | CN20: Interest income yield on cash & marketable securities (annual) | CP20: 0.036 | CR20: Q2-26 $1,295m on $143.1bn opening cash and securities (3.6%).
B21: y/y % | D21: =IF(AND(ISNUMBER(D20),ISNUMBER(C20)),IFERROR(D20/C20-1,""),"") | E21: =IF(AND(ISNUMBER(E20),ISNUMBER(D20)),IFERROR(E20/D20-1,""),"") | F21: =IF(AND(ISNUMBER(F20),ISNUMBER(E20)),IFERROR(F20/E20-1,""),"") | G21: =IF(AND(ISNUMBER(G20),ISNUMBER(F20)),IFERROR(G20/F20-1,""),"") | H21: =IF(AND(ISNUMBER(H20),ISNUMBER(G20)),IFERROR(H20/G20-1,""),"") | I21: =IF(AND(ISNUMBER(I20),ISNUMBER(H20)),IFERROR(I20/H20-1,""),"") | N21: =IF(AND(ISNUMBER(N20),ISNUMBER(I20)),IFERROR(N20/I20-1,""),"") | O21: =IF(AND(ISNUMBER(O20),ISNUMBER(J20)),IFERROR(O20/J20-1,""),"") | P21: =IF(AND(ISNUMBER(P20),ISNUMBER(K20)),IFERROR(P20/K20-1,""),"") | Q21: =IF(AND(ISNUMBER(Q20),ISNUMBER(L20)),IFERROR(Q20/L20-1,""),"") | R21: =IF(AND(ISNUMBER(R20),ISNUMBER(M20)),IFERROR(R20/M20-1,""),"") | S21: =IF(AND(ISNUMBER(S20),ISNUMBER(N20)),IFERROR(S20/N20-1,""),"") | T21: =IF(AND(ISNUMBER(T20),ISNUMBER(O20)),IFERROR(T20/O20-1,""),"") | U21: =IF(AND(ISNUMBER(U20),ISNUMBER(P20)),IFERROR(U20/P20-1,""),"") | ... BX21: =IF(AND(ISNUMBER(BX20),ISNUMBER(BS20)),IFERROR(BX20/BS20-1,""),"") -> 0.12467235 | BY21: =BY22+BY114 -> 0.10389953 | BZ21: =BZ22+BZ114 -> 0.10389953 | CA21: =IF(AND(ISNUMBER(CA20),ISNUMBER(BV20)),IFERROR(CA20/BV20-1,""),"") -> 0.11898269 | CB21: =CHOOSE(MATCH($CF$2,{"Bull","Base","Bear"},0),$CO$47,$CP$47,$CQ$47) -> 0.11 | CC21: =CHOOSE(MATCH($CF$2,{"Bull","Base","Bear"},0),$CO$48,$CP$48,$CQ$48) -> 0.1 | CD21: =CHOOSE(MATCH($CF$2,{"Bull","Base","Bear"},0),$CO$49,$CP$49,$CQ$49) -> 0.095 | CE21: =CHOOSE(MATCH($CF$2,{"Bull","Base","Bear"},0),$CO$50,$CP$50,$CQ$50) -> 0.09 | CN21: Q3/26E interest expense ($m) | CP21: 1750 | CR21: Q2-26 $1,314m on $122bn opening debt; + $25.0bn July notes (4.60–6.25%) from 9-Jul (assumption).
B22: Q3/Q4-26E growth before calibration (Q1-26 y/y) | BY22: =IFERROR(BW20/BR20-1,0) -> 0.14613743 | BZ22: =IFERROR(BW20/BR20-1,0) -> 0.14613743 | CN22: Q4/26E interest expense ($m) | CP22: 1950 | CR22: Full quarter of the July notes + £4.25bn September notes (5.20–6.65%) (assumption).
B23: Advertising services | AU23: 4982 | AV23: 7350 | AX23: 6381 | AY23: 7451 | AZ23: 7612 | BA23: 9716 | BB23: 31160 | BC23: 7877 | BD23: 8757 | BE23: 9548 | BF23: 11557 | BG23: 37739 | BH23: 9509 | BI23: 10683 | BJ23: 12060 | BK23: 14654 | BL23: 46906 | BM23: 11824 | BN23: 12771 | BO23: 14331 | BP23: 17288 | BQ23: 56214 | BR23: 13921 | BS23: 15694 | BT23: 17703 | BU23: 21317 | BV23: 68635 | BW23: 17243 | BX23: 19809 | BY23: =BT23*(1+BY24) -> 20179.885 | BZ23: =BU23*(1+BZ24) -> 25503.539 | CA23: =SUM(BW23:BZ23) -> 82735.424 | CB23: =CA23*(1+CB24) -> 98455.155 | CC23: =CB23*(1+CC24) -> 115192.53 | CD23: =CC23*(1+CD24) -> 132471.41 | CE23: =CD23*(1+CE24) -> 149692.69 | CH23: =IFERROR((CE23/BV23)^(1/5)-1,"n/m") -> 0.16877521 | CI23: =IFERROR((BV23/AW23)^(1/5)-1,"n/m") -> n/m | CJ23: =IFERROR((BV23/X23)^(1/10)-1,"n/m") -> n/m | CK23: =IFERROR((BV23/C23)^(1/19)-1,"n/m") -> n/m | CN23: Q3/Q4-26E effective tax rate | CP23: 0.19 | CR23: FY2025 19.6%; FY2024 13.5% (assumption; no investment marks forecast).
B24: y/y % | D24: =IF(AND(ISNUMBER(D23),ISNUMBER(C23)),IFERROR(D23/C23-1,""),"") | E24: =IF(AND(ISNUMBER(E23),ISNUMBER(D23)),IFERROR(E23/D23-1,""),"") | F24: =IF(AND(ISNUMBER(F23),ISNUMBER(E23)),IFERROR(F23/E23-1,""),"") | G24: =IF(AND(ISNUMBER(G23),ISNUMBER(F23)),IFERROR(G23/F23-1,""),"") | H24: =IF(AND(ISNUMBER(H23),ISNUMBER(G23)),IFERROR(H23/G23-1,""),"") | I24: =IF(AND(ISNUMBER(I23),ISNUMBER(H23)),IFERROR(I23/H23-1,""),"") | N24: =IF(AND(ISNUMBER(N23),ISNUMBER(I23)),IFERROR(N23/I23-1,""),"") | O24: =IF(AND(ISNUMBER(O23),ISNUMBER(J23)),IFERROR(O23/J23-1,""),"") | P24: =IF(AND(ISNUMBER(P23),ISNUMBER(K23)),IFERROR(P23/K23-1,""),"") | Q24: =IF(AND(ISNUMBER(Q23),ISNUMBER(L23)),IFERROR(Q23/L23-1,""),"") | R24: =IF(AND(ISNUMBER(R23),ISNUMBER(M23)),IFERROR(R23/M23-1,""),"") | S24: =IF(AND(ISNUMBER(S23),ISNUMBER(N23)),IFERROR(S23/N23-1,""),"") | T24: =IF(AND(ISNUMBER(T23),ISNUMBER(O23)),IFERROR(T23/O23-1,""),"") | U24: =IF(AND(ISNUMBER(U23),ISNUMBER(P23)),IFERROR(U23/P23-1,""),"") | ... BX24: =IF(AND(ISNUMBER(BX23),ISNUMBER(BS23)),IFERROR(BX23/BS23-1,""),"") -> 0.26220212 | BY24: =BY25+BY32+BY114 -> 0.1399133 | BZ24: =BZ25+BZ32+BZ114 -> 0.19639438 | CA24: =IF(AND(ISNUMBER(CA23),ISNUMBER(BV23)),IFERROR(CA23/BV23-1,""),"") -> 0.20544072 | CB24: =CHOOSE(MATCH($CF$2,{"Bull","Base","Bear"},0),$CO$52,$CP$52,$CQ$52) -> 0.19 | CC24: =CHOOSE(MATCH($CF$2,{"Bull","Base","Bear"},0),$CO$53,$CP$53,$CQ$53) -> 0.17 | CD24: =CHOOSE(MATCH($CF$2,{"Bull","Base","Bear"},0),$CO$54,$CP$54,$CQ$54) -> 0.15 | CE24: =CHOOSE(MATCH($CF$2,{"Bull","Base","Bear"},0),$CO$55,$CP$55,$CQ$55) -> 0.13 | CN24: Shares issued under equity plans per quarter (m) | CP24: 30 | CR24: Shares outstanding +52m in 1H-26; +138m in 2025.
B25: Q3/Q4-26E growth before calibration (Q1-26 y/y) | BY25: =IFERROR(BW23/BR23-1,0) -> 0.23863228 | BZ25: =IFERROR(BW23/BR23-1,0) -> 0.23863228 | CN25: 2H-26E deferred income taxes ($m) | CP25: 4000 | CR25: 1H-26 $30.5bn incl. deferred tax on Anthropic gains; underlying ~$2bn a quarter (assumption).
B26: AWS | Z26: 2886 | AA26: 3231 | AB26: 3536 | AD26: 3661 | AE26: 4100 | AF26: 4584 | AG26: 5113 | AH26: 17458 | AI26: 5442 | AJ26: 6105 | AK26: 6679 | AL26: 7430 | AM26: 25656 | AN26: 7696 | AO26: 8381 | AP26: 8995 | AQ26: 9954 | AR26: 35026 | AS26: 10219 | AT26: 10808 | AU26: 11601 | AV26: 12742 | AW26: 45370 | AX26: 13503 | AY26: 14809 | AZ26: 16110 | BA26: 17780 | BB26: 62202 | BC26: 18441 | BD26: 19739 | BE26: 20538 | BF26: 21378 | BG26: 80096 | BH26: 21354 | BI26: 22140 | BJ26: 23059 | BK26: 24204 | BL26: 90757 | BM26: 25037 | BN26: 26281 | BO26: 27452 | BP26: 28786 | BQ26: 107556 | BR26: 29267 | BS26: 30873 | BT26: 33006 | BU26: 35579 | BV26: 128725 | BW26: 37587 | BX26: 42232 | BY26: =BT26*(1+BY27) -> 45149.788 | BZ26: =BU26*(1+BZ27) -> 48669.463 | CA26: =SUM(BW26:BZ26) -> 173638.25 | CB26: =CA26*(1+CB27) -> 222256.96 | CC26: =CB26*(1+CC27) -> 275598.63 | CD26: =CC26*(1+CD27) -> 330718.36 | CE26: =CD26*(1+CE27) -> 386940.48 | CH26: =IFERROR((CE26/BV26)^(1/5)-1,"n/m") -> 0.24622441 | CI26: =IFERROR((BV26/AW26)^(1/5)-1,"n/m") -> 0.23190956 | CJ26: =IFERROR((BV26/X26)^(1/10)-1,"n/m") -> n/m | CK26: =IFERROR((BV26/C26)^(1/19)-1,"n/m") -> n/m | CN26: 2H-26E principal repayments of finance leases & financing obligations ($m) | CP26: -1000 | CR26: 1H-26 −$1,037m.
B27: y/y % | D27: =IF(AND(ISNUMBER(D26),ISNUMBER(C26)),IFERROR(D26/C26-1,""),"") | E27: =IF(AND(ISNUMBER(E26),ISNUMBER(D26)),IFERROR(E26/D26-1,""),"") | F27: =IF(AND(ISNUMBER(F26),ISNUMBER(E26)),IFERROR(F26/E26-1,""),"") | G27: =IF(AND(ISNUMBER(G26),ISNUMBER(F26)),IFERROR(G26/F26-1,""),"") | H27: =IF(AND(ISNUMBER(H26),ISNUMBER(G26)),IFERROR(H26/G26-1,""),"") | I27: =IF(AND(ISNUMBER(I26),ISNUMBER(H26)),IFERROR(I26/H26-1,""),"") | N27: =IF(AND(ISNUMBER(N26),ISNUMBER(I26)),IFERROR(N26/I26-1,""),"") | O27: =IF(AND(ISNUMBER(O26),ISNUMBER(J26)),IFERROR(O26/J26-1,""),"") | P27: =IF(AND(ISNUMBER(P26),ISNUMBER(K26)),IFERROR(P26/K26-1,""),"") | Q27: =IF(AND(ISNUMBER(Q26),ISNUMBER(L26)),IFERROR(Q26/L26-1,""),"") | R27: =IF(AND(ISNUMBER(R26),ISNUMBER(M26)),IFERROR(R26/M26-1,""),"") | S27: =IF(AND(ISNUMBER(S26),ISNUMBER(N26)),IFERROR(S26/N26-1,""),"") | T27: =IF(AND(ISNUMBER(T26),ISNUMBER(O26)),IFERROR(T26/O26-1,""),"") | U27: =IF(AND(ISNUMBER(U26),ISNUMBER(P26)),IFERROR(U26/P26-1,""),"") | ... BX27: =IF(AND(ISNUMBER(BX26),ISNUMBER(BS26)),IFERROR(BX26/BS26-1,""),"") -> 0.36792667 | BY27: =BY28 -> 0.36792667 | BZ27: =BZ28 -> 0.36792667 | CA27: =IF(AND(ISNUMBER(CA26),ISNUMBER(BV26)),IFERROR(CA26/BV26-1,""),"") -> 0.34890853 | CB27: =CHOOSE(MATCH($CF$2,{"Bull","Base","Bear"},0),$CO$57,$CP$57,$CQ$57) -> 0.28 | CC27: =CHOOSE(MATCH($CF$2,{"Bull","Base","Bear"},0),$CO$58,$CP$58,$CQ$58) -> 0.24 | CD27: =CHOOSE(MATCH($CF$2,{"Bull","Base","Bear"},0),$CO$59,$CP$59,$CQ$59) -> 0.2 | CE27: =CHOOSE(MATCH($CF$2,{"Bull","Base","Bear"},0),$CO$60,$CP$60,$CQ$60) -> 0.17 | CF27: Q3/Q4-26E: Q2-26 y/y (+37%, the fastest in 18 quarters; not part of the calibration Δ). 2027E+: scenario lever. | CN27: 2H-26E P&E acquired under finance leases ($m; non-cash) | CP27: 1500 | CR27: 1H-26 $2,128m; FY2025 $2,911m.
B28: Q3/Q4-26E growth (Q2-26 y/y) | BY28: =IFERROR(BX26/BS26-1,0) -> 0.36792667 | BZ28: =IFERROR(BX26/BS26-1,0) -> 0.36792667
B29: Other | Z29: 626 | AA29: 709 | AB29: 1071 | AD29: 850 | AE29: 945 | AF29: 1123 | AG29: 1735 | AH29: 4653 | AI29: 2031 | AJ29: 2194 | AK29: 2495 | AL29: 3388 | AM29: 10108 | AN29: 2716 | AO29: 3002 | AP29: 3586 | AQ29: 4782 | AR29: 14086 | AS29: 3906 | AT29: 4221 | AU29: 416 | AV29: 602 | AW29: 21477 | AX29: 524 | AY29: 463 | AZ29: 479 | BA29: 710 | BB29: 2176 | BC29: 661 | BD29: 1070 | BE29: 1263 | BF29: 1253 | BG29: 4247 | BH29: 1027 | BI29: 1344 | BJ29: 1226 | BK29: 1361 | BL29: 4958 | BM29: 1262 | BN29: 1260 | BO29: 1313 | BP29: 1590 | BQ29: 5425 | BR29: 1312 | BS29: 1499 | BT29: 1415 | BU29: 1709 | BV29: 5935 | BW29: 1645 | BX29: 1829 | BY29: =BT29*(1+BY30) -> 1714.3759 | BZ29: =BU29*(1+BZ30) -> 2070.5784 | CA29: =SUM(BW29:BZ29) -> 7258.9543 | CB29: =CA29*(1+CB30) -> 7839.6706 | CC29: =CB29*(1+CC30) -> 8388.4476 | CD29: =CC29*(1+CD30) -> 8891.7544 | CE29: =CD29*(1+CE30) -> 9425.2597 | CF29: Includes advertising services until Q2-20 (split out from Q3-20 in the Q4-21 release). | CH29: =IFERROR((CE29/BV29)^(1/5)-1,"n/m") -> 0.096918902 | CI29: =IFERROR((BV29/AW29)^(1/5)-1,"n/m") -> -0.22680432 | CJ29: =IFERROR((BV29/X29)^(1/10)-1,"n/m") -> n/m | CK29: =IFERROR((BV29/C29)^(1/19)-1,"n/m") -> n/m | CN29: Target net debt / adjusted EBITDA (x) — buyback floor 2027E+ | CO29: 0.25 | CP29: 0 | CQ29: -0.25 | CR29: Amazon has not repurchased shares since 2022 ($10bn authorization of Mar-2022, $6bn used) and has financed the AI build-out with $66bn of notes in 1H-26. Target = net debt / adjusted EBITDA up to which surplus cash is returned via buybacks (model assumption; no company target): Base 0.0x (free cash flow beyond net-debt neutrality returned), Bull 0.25x, Bear −0.25x (keeps a net-cash cushion). Net debt was −$54bn at YE2025 and +$9bn at 30-Jun-2026.
B30: y/y % | D30: =IF(AND(ISNUMBER(D29),ISNUMBER(C29)),IFERROR(D29/C29-1,""),"") | E30: =IF(AND(ISNUMBER(E29),ISNUMBER(D29)),IFERROR(E29/D29-1,""),"") | F30: =IF(AND(ISNUMBER(F29),ISNUMBER(E29)),IFERROR(F29/E29-1,""),"") | G30: =IF(AND(ISNUMBER(G29),ISNUMBER(F29)),IFERROR(G29/F29-1,""),"") | H30: =IF(AND(ISNUMBER(H29),ISNUMBER(G29)),IFERROR(H29/G29-1,""),"") | I30: =IF(AND(ISNUMBER(I29),ISNUMBER(H29)),IFERROR(I29/H29-1,""),"") | N30: =IF(AND(ISNUMBER(N29),ISNUMBER(I29)),IFERROR(N29/I29-1,""),"") | O30: =IF(AND(ISNUMBER(O29),ISNUMBER(J29)),IFERROR(O29/J29-1,""),"") | P30: =IF(AND(ISNUMBER(P29),ISNUMBER(K29)),IFERROR(P29/K29-1,""),"") | Q30: =IF(AND(ISNUMBER(Q29),ISNUMBER(L29)),IFERROR(Q29/L29-1,""),"") | R30: =IF(AND(ISNUMBER(R29),ISNUMBER(M29)),IFERROR(R29/M29-1,""),"") | S30: =IF(AND(ISNUMBER(S29),ISNUMBER(N29)),IFERROR(S29/N29-1,""),"") | T30: =IF(AND(ISNUMBER(T29),ISNUMBER(O29)),IFERROR(T29/O29-1,""),"") | U30: =IF(AND(ISNUMBER(U29),ISNUMBER(P29)),IFERROR(U29/P29-1,""),"") | ... BX30: =IF(AND(ISNUMBER(BX29),ISNUMBER(BS29)),IFERROR(BX29/BS29-1,""),"") -> 0.22014676 | BY30: =BY31+BY114 -> 0.21157307 | BZ30: =BZ31+BZ114 -> 0.21157307 | CA30: =IF(AND(ISNUMBER(CA29),ISNUMBER(BV29)),IFERROR(CA29/BV29-1,""),"") -> 0.2230757 | CB30: =CHOOSE(MATCH($CF$2,{"Bull","Base","Bear"},0),$CO$62,$CP$62,$CQ$62) -> 0.08 | CC30: =CHOOSE(MATCH($CF$2,{"Bull","Base","Bear"},0),$CO$63,$CP$63,$CQ$63) -> 0.07 | CD30: =CHOOSE(MATCH($CF$2,{"Bull","Base","Bear"},0),$CO$64,$CP$64,$CQ$64) -> 0.06 | CE30: =CHOOSE(MATCH($CF$2,{"Bull","Base","Bear"},0),$CO$65,$CP$65,$CQ$65) -> 0.06
B31: Q3/Q4-26E growth before calibration (Q1-26 y/y) | BY31: =IFERROR(BW29/BR29-1,0) -> 0.25381098 | BZ31: =IFERROR(BW29/BR29-1,0) -> 0.25381098 | CN31: ONLINE (Online stores y/y) | CO31: 0.02 | CP31: Δ → | CQ31: -0.03 | CR31: FY2025 +9.0%; 1H-26 +13.3% (Q1 +11.9%, Q2 incl. Prime Day). Faster delivery, everyday essentials; maturing category.
B32: Prime Day timing shift — pp of growth on online stores, third-party seller services and advertising (Q3/26E) | BY32: =$CP$16*$BT$144/($BT$11+$BT$17+$BT$23) -> -0.056481081 | BZ32: =0 -> 0 | CF32: Guidance (30-Jul-2026): "excluding the impact of Prime Day in both 2025 and 2026, Q3-26 y/y growth would be nearly 400 bp higher" (Prime Day in Q3 in 2025, Q2 in 2026). −4.0 pp of total Q3 net sales allocated to the Prime-Day-sensitive groups pro rata to Q3-25 revenue. | CN32: 2027E | CO32: =CP32+$CO$31 -> 0.105 | CP32: 0.085 | CQ32: =CP32+$CQ$31 -> 0.055
B33: Not split by product group (before Q2-16) | C33: =IF(ISNUMBER(C11),ROUND(C144-(C11+C14+C17+C20+N(C23)+C26+C29),0),C144) -> 10711 | D33: =IF(ISNUMBER(D11),ROUND(D144-(D11+D14+D17+D20+N(D23)+D26+D29),0),D144) -> 14835 | E33: =IF(ISNUMBER(E11),ROUND(E144-(E11+E14+E17+E20+N(E23)+E26+E29),0),E144) -> 19166 | F33: =IF(ISNUMBER(F11),ROUND(F144-(F11+F14+F17+F20+N(F23)+F26+F29),0),F144) -> 24509 | G33: =IF(ISNUMBER(G11),ROUND(G144-(G11+G14+G17+G20+N(G23)+G26+G29),0),G144) -> 34204 | H33: =IF(ISNUMBER(H11),ROUND(H144-(H11+H14+H17+H20+N(H23)+H26+H29),0),H144) -> 48077 | I33: =IF(ISNUMBER(I11),ROUND(I144-(I11+I14+I17+I20+N(I23)+I26+I29),0),I144) -> 61093 | J33: =IF(ISNUMBER(J11),ROUND(J144-(J11+J14+J17+J20+N(J23)+J26+J29),0),J144) -> 16070 | ... BX33: =IF(ISNUMBER(BX11),ROUND(BX144-(BX11+BX14+BX17+BX20+N(BX23)+BX26+BX29),0),BX144) -> 0 | BY33: =0 -> 0 | BZ33: =0 -> 0 | CA33: =SUM(BW33:BZ33) -> 0 | CB33: =0 -> 0 | CC33: =0 -> 0 | CD33: =0 -> 0 | CE33: =0 -> 0 | CN33: 2028E | CO33: =CP33+$CO$31 -> 0.1 | CP33: 0.08 | CQ33: =CP33+$CQ$31 -> 0.05
B34: Net sales (Σ product groups) | C34: =N(C11)+N(C14)+N(C17)+N(C20)+N(C23)+N(C26)+N(C29)+C33 -> 10711 | D34: =N(D11)+N(D14)+N(D17)+N(D20)+N(D23)+N(D26)+N(D29)+D33 -> 14835 | E34: =N(E11)+N(E14)+N(E17)+N(E20)+N(E23)+N(E26)+N(E29)+E33 -> 19166 | F34: =N(F11)+N(F14)+N(F17)+N(F20)+N(F23)+N(F26)+N(F29)+F33 -> 24509 | G34: =N(G11)+N(G14)+N(G17)+N(G20)+N(G23)+N(G26)+N(G29)+G33 -> 34204 | H34: =N(H11)+N(H14)+N(H17)+N(H20)+N(H23)+N(H26)+N(H29)+H33 -> 48077 | I34: =N(I11)+N(I14)+N(I17)+N(I20)+N(I23)+N(I26)+N(I29)+I33 -> 61093 | J34: =N(J11)+N(J14)+N(J17)+N(J20)+N(J23)+N(J26)+N(J29)+J33 -> 16070 | ... BX34: =N(BX11)+N(BX14)+N(BX17)+N(BX20)+N(BX23)+N(BX26)+N(BX29)+BX33 -> 200606 | BY34: =BY11+BY14+BY17+BY20+BY23+BY26+BY29+N(BY96) -> 199500 | BZ34: =BZ11+BZ14+BZ17+BZ20+BZ23+BZ26+BZ29+N(BZ96) -> 243897.47 | CA34: =CA11+CA14+CA17+CA20+CA23+CA26+CA29+N(CA96) -> 825522.47 | CB34: =CB11+CB14+CB17+CB20+CB23+CB26+CB29+N(CB96) -> 943961.71 | CC34: =CC11+CC14+CC17+CC20+CC23+CC26+CC29+N(CC96) -> 1069423.7 | CD34: =CD11+CD14+CD17+CD20+CD23+CD26+CD29+N(CD96) -> 1198711.7 | CE34: =CE11+CE14+CE17+CE20+CE23+CE26+CE29+N(CE96) -> 1330223 | CF34: Σ groups (+ future acquisitions from 2027E). | CN34: 2029E | CO34: =CP34+$CO$31 -> 0.095 | CP34: 0.075 | CQ34: =CP34+$CQ$31 -> 0.045
B35: Check: product groups vs consolidated net sales (should be 0; ±2 rounding) | C35: =IF(ISNUMBER(C11),IF(ABS(C34-C144)<=2.01,0,ROUND(C34-C144,0)),"") | D35: =IF(ISNUMBER(D11),IF(ABS(D34-D144)<=2.01,0,ROUND(D34-D144,0)),"") | E35: =IF(ISNUMBER(E11),IF(ABS(E34-E144)<=2.01,0,ROUND(E34-E144,0)),"") | F35: =IF(ISNUMBER(F11),IF(ABS(F34-F144)<=2.01,0,ROUND(F34-F144,0)),"") | G35: =IF(ISNUMBER(G11),IF(ABS(G34-G144)<=2.01,0,ROUND(G34-G144,0)),"") | H35: =IF(ISNUMBER(H11),IF(ABS(H34-H144)<=2.01,0,ROUND(H34-H144,0)),"") | I35: =IF(ISNUMBER(I11),IF(ABS(I34-I144)<=2.01,0,ROUND(I34-I144,0)),"") | J35: =IF(ISNUMBER(J11),IF(ABS(J34-J144)<=2.01,0,ROUND(J34-J144,0)),"") | ... BX35: =IF(ISNUMBER(BX11),IF(ABS(BX34-BX144)<=2.01,0,ROUND(BX34-BX144,0)),"") -> 0 | CN35: 2030E | CO35: =CP35+$CO$31 -> 0.09 | CP35: 0.07 | CQ35: =CP35+$CQ$31 -> 0.04
B36: Advertising services % of net sales | C36: =IF(AND(ISNUMBER(C23),ISNUMBER(C144)),IFERROR(C23/C144,""),"") | D36: =IF(AND(ISNUMBER(D23),ISNUMBER(D144)),IFERROR(D23/D144,""),"") | E36: =IF(AND(ISNUMBER(E23),ISNUMBER(E144)),IFERROR(E23/E144,""),"") | F36: =IF(AND(ISNUMBER(F23),ISNUMBER(F144)),IFERROR(F23/F144,""),"") | G36: =IF(AND(ISNUMBER(G23),ISNUMBER(G144)),IFERROR(G23/G144,""),"") | H36: =IF(AND(ISNUMBER(H23),ISNUMBER(H144)),IFERROR(H23/H144,""),"") | I36: =IF(AND(ISNUMBER(I23),ISNUMBER(I144)),IFERROR(I23/I144,""),"") | J36: =IF(AND(ISNUMBER(J23),ISNUMBER(J144)),IFERROR(J23/J144,""),"") | ... CE36: =IF(AND(ISNUMBER(CE23),ISNUMBER(CE144)),IFERROR(CE23/CE144,""),"") -> 0.11253203 | CH36: =IFERROR(AVERAGE(CA36,CB36,CC36,CD36,CE36),"n/m") -> 0.10705599 | CI36: =IFERROR(AVERAGE(BB36,BG36,BL36,BQ36,BV36),"n/m") -> 0.081040907 | CJ36: =IFERROR(AVERAGE(AC36,AH36,AM36,AR36,AW36,BB36,BG36,BL36,BQ36,BV36),"n/m") -> 0.081040907 | CK36: =IFERROR(AVERAGE(C36,D36,E36,F36,G36,H36,I36,N36,S36,X36,AC36,AH36,AM36,AR36,AW36,BB36,BG36,BL36,BQ36,BV36),"n/m") -> 0.081040907 | CN36: PHYS (Physical stores y/y) | CO36: 0.02 | CP36: Δ → | CQ36: -0.03 | CR36: FY2025 +6.3%; 1H-26 +4.6% (Whole Foods, Amazon Fresh).
B37: AWS % of net sales | C37: =IF(AND(ISNUMBER(C26),ISNUMBER(C144)),IFERROR(C26/C144,""),"") | D37: =IF(AND(ISNUMBER(D26),ISNUMBER(D144)),IFERROR(D26/D144,""),"") | E37: =IF(AND(ISNUMBER(E26),ISNUMBER(E144)),IFERROR(E26/E144,""),"") | F37: =IF(AND(ISNUMBER(F26),ISNUMBER(F144)),IFERROR(F26/F144,""),"") | G37: =IF(AND(ISNUMBER(G26),ISNUMBER(G144)),IFERROR(G26/G144,""),"") | H37: =IF(AND(ISNUMBER(H26),ISNUMBER(H144)),IFERROR(H26/H144,""),"") | I37: =IF(AND(ISNUMBER(I26),ISNUMBER(I144)),IFERROR(I26/I144,""),"") | J37: =IF(AND(ISNUMBER(J26),ISNUMBER(J144)),IFERROR(J26/J144,""),"") | ... CE37: =IF(AND(ISNUMBER(CE26),ISNUMBER(CE144)),IFERROR(CE26/CE144,""),"") -> 0.29088391 | CH37: =IFERROR(AVERAGE(CA37,CB37,CC37,CD37,CE37),"n/m") -> 0.254055 | CI37: =IFERROR(AVERAGE(BB37,BG37,BL37,BQ37,BV37),"n/m") -> 0.15885436 | CJ37: =IFERROR(AVERAGE(AC37,AH37,AM37,AR37,AW37,BB37,BG37,BL37,BQ37,BV37),"n/m") -> 0.13832987 | CK37: =IFERROR(AVERAGE(C37,D37,E37,F37,G37,H37,I37,N37,S37,X37,AC37,AH37,AM37,AR37,AW37,BB37,BG37,BL37,BQ37,BV37),"n/m") -> 0.13832987 | CN37: 2027E | CO37: =CP37+$CO$36 -> 0.07 | CP37: 0.05 | CQ37: =CP37+$CQ$36 -> 0.02
B38: Third-party seller services + subscriptions + advertising % of net sales | C38: =IF(AND(ISNUMBER(C23),ISNUMBER(C17)),IFERROR((C17+C20+C23)/C144,""),"") | D38: =IF(AND(ISNUMBER(D23),ISNUMBER(D17)),IFERROR((D17+D20+D23)/D144,""),"") | E38: =IF(AND(ISNUMBER(E23),ISNUMBER(E17)),IFERROR((E17+E20+E23)/E144,""),"") | F38: =IF(AND(ISNUMBER(F23),ISNUMBER(F17)),IFERROR((F17+F20+F23)/F144,""),"") | G38: =IF(AND(ISNUMBER(G23),ISNUMBER(G17)),IFERROR((G17+G20+G23)/G144,""),"") | H38: =IF(AND(ISNUMBER(H23),ISNUMBER(H17)),IFERROR((H17+H20+H23)/H144,""),"") | I38: =IF(AND(ISNUMBER(I23),ISNUMBER(I17)),IFERROR((I17+I20+I23)/I144,""),"") | J38: =IF(AND(ISNUMBER(J23),ISNUMBER(J17)),IFERROR((J17+J20+J23)/J144,""),"") | ... CE38: =IF(AND(ISNUMBER(CE23),ISNUMBER(CE17)),IFERROR((CE17+CE20+CE23)/CE144,""),"") -> 0.38201609 | CH38: =IFERROR(AVERAGE(CA38,CB38,CC38,CD38,CE38),"n/m") -> 0.38943681 | CI38: =IFERROR(AVERAGE(BB38,BG38,BL38,BQ38,BV38),"n/m") -> 0.38553229 | CJ38: =IFERROR(AVERAGE(AC38,AH38,AM38,AR38,AW38,BB38,BG38,BL38,BQ38,BV38),"n/m") -> 0.38553229 | CK38: =IFERROR(AVERAGE(C38,D38,E38,F38,G38,H38,I38,N38,S38,X38,AC38,AH38,AM38,AR38,AW38,BB38,BG38,BL38,BQ38,BV38),"n/m") -> 0.38553229 | CN38: 2028E | CO38: =CP38+$CO$36 -> 0.07 | CP38: 0.05 | CQ38: =CP38+$CQ$36 -> 0.02
B39: Memo: worldwide net sales y/y growth excluding F/X, as published | C39: 0.3 | D39: 0.37 | E39: 0.24 | F39: 0.37 | G39: 0.37 | H39: 0.34 | I39: 0.23 | J39: 0.24 | K39: 0.25 | L39: 0.26 | M39: 0.22 | N39: 0.22 | O39: 0.23 | P39: 0.22 | Q39: 0.2 | R39: 0.18 | S39: 0.18 | T39: 0.22 | U39: 0.27 | V39: 0.3 | W39: 0.26 | X39: 0.26 | Y39: 0.29 | Z39: 0.3 | AA39: 0.29 | AB39: 0.24 | AC39: 0.24 | AD39: 0.24 | AE39: 0.26 | AF39: 0.33 | AG39: 0.36 | AH39: 0.36 | AI39: 0.39 | AJ39: 0.37 | AK39: 0.3 | AL39: 0.21 | AM39: 0.21 | AN39: 0.19 | AO39: 0.21 | AP39: 0.25 | AQ39: 0.21 | AR39: 0.21 | AS39: 0.27 | AT39: 0.41 | AU39: 0.36 | AV39: 0.42 | AW39: 0.42 | AX39: 0.41 | AY39: 0.24 | AZ39: 0.15 | BA39: 0.1 | BB39: 0.1 | BC39: 0.09 | BD39: 0.1 | BE39: 0.19 | BF39: 0.12 | BG39: 0.12 | BH39: 0.11 | BI39: 0.11 | BJ39: 0.11 | BK39: 0.13 | BL39: 0.13 | BM39: 0.13 | BN39: 0.11 | BO39: 0.11 | BP39: 0.11 | BQ39: 0.11 | BR39: 0.1 | BS39: 0.12 | BT39: 0.12 | BU39: 0.12 | BV39: 0.12 | BW39: 0.15 | BX39: 0.2 | CN39: 2029E | CO39: =CP39+$CO$36 -> 0.065 | CP39: 0.045 | CQ39: =CP39+$CQ$36 -> 0.015
CN40: 2030E | CO40: =CP40+$CO$36 -> 0.06 | CP40: 0.04 | CQ40: =CP40+$CQ$36 -> 0.01
...

Sheet Bull-Base-Bear
B2: Amazon.com, Inc. (AMZN) — Bull / Base / Bear Case P&L Summary | J2: Share price ($): | K2: =Model!$CA$416 -> 260
B3: Model definitions (Amazon publishes no adjusted measures besides free cash flow): adjusted operating income / EBITDA add back only the special charges Amazon quantified and energy-contract remeasurements; adjusted EPS also excludes other income (expense) — investment marks (Anthropic, Rivian) — and equity-method activity. USD millions · Live panel linked to Model — toggle the scenario with the switch on the Model sheet (cell CF2). Bull and Bear panels are value snapshots generated from the Model with the switch set to each case. 2026E = 1H actual + Q3 calibrated to the Q3-26 guidance + Q4 carrying the Q3 Δs. | J3: As of: | K3: =TODAY() -> 2026-10-12 00:00:00
B5: Scenario: | C5: =Model!$CF$2 -> Base | N5: Scenario: | O5: Bull | P5: Snapshot (values) — Model run with switch = Bull | Z5: Scenario: | AA5: Bear | AB5: Snapshot (values) — Model run with switch = Bear
B7: (USDm, except EPS and shares) | C7: 2025A | D7: 2026E | E7: 2027E | F7: 2028E | G7: 2029E | H7: 2030E | I7: 25-'30 CAGR | J7: LT Hist Avg | K7: LT Hist Min | L7: LT Hist Max | N7: (USDm, except EPS and shares) | O7: 2025A | P7: 2026E | Q7: 2027E | R7: 2028E | S7: 2029E | T7: 2030E | U7: 25-'30 CAGR | V7: LT Hist Avg | W7: LT Hist Min | X7: LT Hist Max | Z7: (USDm, except EPS and shares) | AA7: 2025A | AB7: 2026E | AC7: 2027E | AD7: 2028E | AE7: 2029E | AF7: 2030E | AG7: 25-'30 CAGR | AH7: LT Hist Avg | AI7: LT Hist Min | AJ7: LT Hist Max
B9: Net sales | C9: =Model!BV144 -> 716924 | D9: =Model!CA144 -> 825522.47 | E9: =Model!CB144 -> 943961.71 | F9: =Model!CC144 -> 1069423.7 | G9: =Model!CD144 -> 1198711.7 | H9: =Model!CE144 -> 1330223 | I9: =IFERROR((H9/C9)^(1/5)-1,"n/m") -> 0.13159305 | N9: Net sales | O9: 716924 | P9: 831043.05 | Q9: 972979.46 | R9: 1130482.8 | S9: 1301136.4 | T9: 1484139.7 | U9: 0.15664567 | Z9: Net sales | AA9: 716924 | AB9: 820001.89 | AC9: 902684.54 | AD9: 982133.81 | AE9: 1055392.4 | AF9: 1121336.6 | AG9: 0.093585071
B10: Net sales y/y % | D10: =IFERROR(D9/C9-1,"") -> 0.15147836 | E10: =IFERROR(E9/D9-1,"") -> 0.14347185 | F10: =IFERROR(F9/E9-1,"") -> 0.13291004 | G10: =IFERROR(G9/F9-1,"") -> 0.12089497 | H10: =IFERROR(H9/G9-1,"") -> 0.10971062 | N10: Net sales y/y % | P10: 0.15917873 | Q10: 0.17079308 | R10: 0.16187733 | S10: 0.15095645 | T10: 0.14064882 | Z10: Net sales y/y % | AB10: 0.14377799 | AC10: 0.10083226 | AD10: 0.088014443 | AE10: 0.074591281 | AF10: 0.062483043
B11: AWS segment net sales y/y % | C11: =Model!BV232 -> 0.1968184 | D11: =Model!CA232 -> 0.34890853 | E11: =Model!CB232 -> 0.28 | F11: =Model!CC232 -> 0.24 | G11: =Model!CD232 -> 0.2 | H11: =Model!CE232 -> 0.17 | N11: AWS segment net sales y/y % | O11: 0.1968184 | P11: 0.34890853 | Q11: 0.33 | R11: 0.29 | S11: 0.25 | T11: 0.22 | Z11: AWS segment net sales y/y % | AA11: 0.1968184 | AB11: 0.34890853 | AC11: 0.2 | AD11: 0.16 | AE11: 0.12 | AF11: 0.09
B12: Adjusted EBITDA (model definition) | C12: =Model!BV202 -> 152471 | D12: =Model!CA202 -> 191718.14 | E12: =Model!CB202 -> 248439.41 | F12: =Model!CC202 -> 297699.81 | G12: =Model!CD202 -> 346306.16 | H12: =Model!CE202 -> 395464.06 | I12: =IFERROR((H12/C12)^(1/5)-1,"n/m") -> 0.20999605 | N12: Adjusted EBITDA (model definition) | O12: 152471 | P12: 196379.81 | Q12: 265817.55 | R12: 324590.57 | S12: 386199.23 | T12: 452333.43 | U12: 0.2429518 | Z12: Adjusted EBITDA (model definition) | AA12: 152471 | AB12: 187055.79 | AC12: 223707.88 | AD12: 260600.95 | AE12: 293137.12 | AF12: 322431.63 | AG12: 0.16158255
B13: Adjusted EBITDA margin % | C13: =IFERROR(C12/C9,"") -> 0.21267387 | D13: =IFERROR(D12/D9,"") -> 0.23223854 | E13: =IFERROR(E12/E9,"") -> 0.26318801 | F13: =IFERROR(F12/F9,"") -> 0.27837405 | G13: =IFERROR(G12/G9,"") -> 0.28889864 | H13: =IFERROR(H12/H9,"") -> 0.29729154 | J13: =IFERROR(AVERAGE(Model!C203,Model!D203,Model!E203,Model!F203,Model!G203,Model!H203,Model!I203,Model!N203,Model!S203,Model!X203,Model!AC203,Model!AH203,Model!AM203,Model!AR203,Model!AW203,Model!BB203,Model!BG203,Model!BL203,Model!BQ203,Model!BV203),"") -> 0.095523357 | K13: =IFERROR(MIN(Model!C203,Model!D203,Model!E203,Model!F203,Model!G203,Model!H203,Model!I203,Model!N203,Model!S203,Model!X203,Model!AC203,Model!AH203,Model!AM203,Model!AR203,Model!AW203,Model!BB203,Model!BG203,Model!BL203,Model!BQ203,Model!BV203),"") -> 0.040455935 | L13: =IFERROR(MAX(Model!C203,Model!D203,Model!E203,Model!F203,Model!G203,Model!H203,Model!I203,Model!N203,Model!S203,Model!X203,Model!AC203,Model!AH203,Model!AM203,Model!AR203,Model!AW203,Model!BB203,Model!BG203,Model!BL203,Model!BQ203,Model!BV203),"") -> 0.21267387 | N13: Adjusted EBITDA margin % | O13: 0.21267387 | P13: 0.23630522 | Q13: 0.27319955 | R13: 0.28712563 | S13: 0.29681686 | T13: 0.3047782 | V13: 0.095523357 | W13: 0.040455935 | X13: 0.21267387 | Z13: Adjusted EBITDA margin % | AA13: 0.21267387 | AB13: 0.22811629 | AC13: 0.24782509 | AD13: 0.26534159 | AE13: 0.27775178 | AF13: 0.28754225 | AH13: 0.095523357 | AI13: 0.040455935 | AJ13: 0.21267387
B15: Operating Income (GAAP) | C15: =Model!BV154 -> 79975 | D15: =Model!CA154 -> 106753.61 | E15: =Model!CB154 -> 133285.41 | F15: =Model!CC154 -> 160376.1 | G15: =Model!CD154 -> 188437.12 | H15: =Model!CE154 -> 219090.51 | I15: =IFERROR((H15/C15)^(1/5)-1,"n/m") -> 0.2233025 | N15: Operating Income (GAAP) | O15: 79975 | P15: 111238.59 | Q15: 149937.12 | R15: 185589.57 | S15: 224764.84 | T15: 269609.91 | U15: 0.27513545 | Z15: Operating Income (GAAP) | AA15: 79975 | AB15: 102267.95 | AC15: 109607.07 | AD15: 125809.37 | AE15: 140620.56 | AF15: 155395.75 | AG15: 0.14208119
B16: Operating income y/y % | D16: =IFERROR(D15/C15-1,"") -> 0.33483721 | E16: =IFERROR(E15/D15-1,"") -> 0.24853311 | F16: =IFERROR(F15/E15-1,"") -> 0.20325319 | G16: =IFERROR(G15/F15-1,"") -> 0.17497015 | H16: =IFERROR(H15/G15-1,"") -> 0.16267169 | N16: Operating income y/y % | P16: 0.39091708 | Q16: 0.34788759 | R16: 0.23778269 | S16: 0.2110855 | T16: 0.19951994 | Z16: Operating income y/y % | AB16: 0.27874898 | AC16: 0.071763668 | AD16: 0.14782161 | AE16: 0.11772728 | AF16: 0.10507132
B17: Operating margin (GAAP) % | C17: =IFERROR(C15/C9,"") -> 0.11155297 | D17: =IFERROR(D15/D9,"") -> 0.12931641 | E17: =IFERROR(E15/E9,"") -> 0.1411979 | F17: =IFERROR(F15/F9,"") -> 0.14996497 | G17: =IFERROR(G15/G9,"") -> 0.15719971 | H17: =IFERROR(H15/H9,"") -> 0.16470209 | J17: =IFERROR(AVERAGE(Model!C243,Model!D243,Model!E243,Model!F243,Model!G243,Model!H243,Model!I243,Model!N243,Model!S243,Model!X243,Model!AC243,Model!AH243,Model!AM243,Model!AR243,Model!AW243,Model!BB243,Model!BG243,Model!BL243,Model!BQ243,Model!BV243),"") -> 0.042588227 | K17: =IFERROR(MIN(Model!C243,Model!D243,Model!E243,Model!F243,Model!G243,Model!H243,Model!I243,Model!N243,Model!S243,Model!X243,Model!AC243,Model!AH243,Model!AM243,Model!AR243,Model!AW243,Model!BB243,Model!BG243,Model!BL243,Model!BQ243,Model!BV243),"") -> 0.0020002697 | L17: =IFERROR(MAX(Model!C243,Model!D243,Model!E243,Model!F243,Model!G243,Model!H243,Model!I243,Model!N243,Model!S243,Model!X243,Model!AC243,Model!AH243,Model!AM243,Model!AR243,Model!AW243,Model!BB243,Model!BG243,Model!BL243,Model!BQ243,Model!BV243),"") -> 0.11155297 | N17: Operating margin (GAAP) % | O17: 0.11155297 | P17: 0.13385419 | Q17: 0.15410101 | R17: 0.16416842 | S17: 0.17274502 | T17: 0.18166073 | V17: 0.042588227 | W17: 0.0020002697 | X17: 0.11155297 | Z17: Operating margin (GAAP) % | AA17: 0.11155297 | AB17: 0.12471672 | AC17: 0.12142345 | AD17: 0.12809799 | AE17: 0.13324007 | AF17: 0.13858083 | AH17: 0.042588227 | AI17: 0.0020002697 | AJ17: 0.11155297
B19: Adjusted Net Income (model definition) | C19: =Model!BV220 -> 71517.69 | D19: =Model!CA220 -> 81602.866 | E19: =Model!CB220 -> 105559.4 | F19: =Model!CC220 -> 127702.65 | G19: =Model!CD220 -> 150300.09 | H19: =Model!CE220 -> 175129.33 | I19: =IFERROR((H19/C19)^(1/5)-1,"n/m") -> 0.19615947 | N19: Adjusted Net Income (model definition) | O19: 71517.69 | P19: 85235.706 | Q19: 119143.58 | R19: 146349.24 | S19: 177430.48 | T19: 213193.57 | U19: 0.24414823 | Z19: Adjusted Net Income (model definition) | AA19: 71517.69 | AB19: 77969.484 | AC19: 86283.648 | AD19: 99041.49 | AE19: 111534.77 | AF19: 125038.23 | AG19: 0.11821642
B21: FDSO (m) | C21: =Model!BV170 -> 10827 | D21: =Model!CA170 -> 10917.75 | E21: =Model!CB170 -> 11034.771 | F21: =Model!CC170 -> 11063.533 | G21: =Model!CD170 -> 10952.724 | H21: =Model!CE170 -> 10735.617 | I21: =IFERROR((H21/C21)^(1/5)-1,"n/m") -> -0.0016937926 | N21: FDSO (m) | O21: 10827 | P21: 10917.75 | Q21: 10882.428 | R21: 10702.914 | S21: 10473.543 | T21: 10120.458 | U21: -0.013406148 | Z21: FDSO (m) | AA21: 10827 | AB21: 10917.75 | AC21: 11038 | AD21: 11158 | AE21: 11278 | AF21: 11301.795 | AG21: 0.0086206563
B23: Adjusted EPS — Diluted ($) | C23: =Model!BV222 -> 6.6054946 | D23: =Model!CA222 -> 7.47433 | E23: =Model!CB222 -> 9.5660715 | F23: =Model!CC222 -> 11.542665 | G23: =Model!CD222 -> 13.722622 | H23: =Model!CE222 -> 16.312927 | I23: =IFERROR((H23/C23)^(1/5)-1,"n/m") -> 0.19818895 | N23: Adjusted EPS — Diluted ($) | O23: 6.6054946 | P23: 7.8070761 | Q23: 10.948253 | R23: 13.673775 | S23: 16.940826 | T23: 21.065605 | U23: 0.26105411 | Z23: Adjusted EPS — Diluted ($) | AA23: 6.6054946 | AB23: 7.1415341 | AC23: 7.8169639 | AD23: 8.8762762 | AE23: 9.8895878 | AF23: 11.063572 | AG23: 0.10865905
B24: EPS y/y % | D24: =IFERROR(D23/C23-1,"") -> 0.13153222 | E24: =IFERROR(E23/D23-1,"") -> 0.27985673 | F24: =IFERROR(F23/E23-1,"") -> 0.20662541 | G24: =IFERROR(G23/F23-1,"") -> 0.18886082 | H24: =IFERROR(H23/G23-1,"") -> 0.18876165 | N24: EPS y/y % | P24: 0.18190637 | Q24: 0.40234996 | R24: 0.24894589 | S24: 0.23892823 | T24: 0.24348157 | Z24: EPS y/y % | AB24: 0.081150549 | AC24: 0.09457769 | AD24: 0.13551454 | AE24: 0.11415954 | AF24: 0.11870916
B26: P / E (x) — assumed (adjusted EPS) | G26: 28 | H26: 28 | N26: P / E (x) — assumed (adjusted EPS) | S26: 32 | T26: 32 | Z26: P / E (x) — assumed (adjusted EPS) | AE26: 22 | AF26: 22
B27: Price Target ($) | G27: =G26*G23 -> 384.23342 | H27: =H26*H23 -> 456.76195 | N27: Price Target ($) | S27: =S26*S23 -> 542.10645 | T27: =T26*T23 -> 674.09937 | Z27: Price Target ($) | AD27: =AD26*AD23 -> 0 | AE27: =AE26*AE23 -> 217.57093 | AF27: =AF26*AF23 -> 243.39859
B28: Upside / (Downside) vs current | G28: =IFERROR(G27/$K$2-1,"") -> 0.47782085 | H28: =IFERROR(H27/$K$2-1,"") -> 0.75677674 | N28: Upside / (Downside) vs current | S28: =IFERROR(S27/$K$2-1,"") -> 1.0850248 | T28: =IFERROR(T27/$K$2-1,"") -> 1.5926899 | Z28: Upside / (Downside) vs current | AD28: =IFERROR(AD27/$K$2-1,"") -> -1 | AE28: =IFERROR(AE27/$K$2-1,"") -> -0.16318872 | AF28: =IFERROR(AF27/$K$2-1,"") -> -0.063851564
B29: IRR (to Dec-Y-1) | G29: =IFERROR((G27/$K$2)^(1/((DATE(2029-1,12,31)-$K$3)/365.25))-1,"") -> 0.19231923 | H29: =IFERROR((H27/$K$2)^(1/((DATE(2030-1,12,31)-$K$3)/365.25))-1,"") -> 0.1912577 | N29: IRR (to Dec-Y-1) | S29: =IFERROR((S27/$K$2)^(1/((DATE(2029-1,12,31)-$K$3)/365.25))-1,"") -> 0.39225278 | T29: =IFERROR((T27/$K$2)^(1/((DATE(2030-1,12,31)-$K$3)/365.25))-1,"") -> 0.34432861 | Z29: IRR (to Dec-Y-1) | AD29: =IFERROR((AD27/$K$2)^(1/((DATE(2028-1,12,31)-$K$3)/365.25))-1,"") -> -1 | AE29: =IFERROR((AE27/$K$2)^(1/((DATE(2029-1,12,31)-$K$3)/365.25))-1,"") -> -0.077101873 | AF29: =IFERROR((AF27/$K$2)^(1/((DATE(2030-1,12,31)-$K$3)/365.25))-1,"") -> -0.020284342
B31: Free Cash Flow | C31: =Model!BV277 -> 11194 | D31: =Model!CA277 -> -26742.759 | E31: =Model!CB277 -> 21226.413 | F31: =Model!CC277 -> 60379.489 | G31: =Model!CD277 -> 100541.79 | H31: =Model!CE277 -> 144462.64 | I31: =IFERROR((H31/C31)^(1/5)-1,"n/m") -> 0.66783871 | N31: Free Cash Flow | O31: 11194 | P31: -23140.363 | Q31: 39724.941 | R31: 82612.248 | S31: 129163.3 | T31: 182821.92 | U31: 0.74827035 | Z31: Free Cash Flow | AA31: 11194 | AB31: -30345.54 | AC31: -4754.8732 | AD31: 27502.165 | AE31: 61446.84 | AF31: 96489.918 | AG31: 0.53850647
B32: FCF % | C32: =IFERROR(C31/C9,"") -> 0.015613928 | D32: =IFERROR(D31/D9,"") -> -0.03239495 | E32: =IFERROR(E31/E9,"") -> 0.022486519 | F32: =IFERROR(F31/F9,"") -> 0.056459838 | G32: =IFERROR(G31/G9,"") -> 0.083874872 | H32: =IFERROR(H31/H9,"") -> 0.10860031 | J32: =IFERROR(AVERAGE(Model!C290,Model!D290,Model!E290,Model!F290,Model!G290,Model!H290,Model!I290,Model!N290,Model!S290,Model!X290,Model!AC290,Model!AH290,Model!AM290,Model!AR290,Model!AW290,Model!BB290,Model!BG290,Model!BL290,Model!BQ290,Model!BV290),"") -> 0.051422747 | K32: =IFERROR(MIN(Model!C290,Model!D290,Model!E290,Model!F290,Model!G290,Model!H290,Model!I290,Model!N290,Model!S290,Model!X290,Model!AC290,Model!AH290,Model!AM290,Model!AR290,Model!AW290,Model!BB290,Model!BG290,Model!BL290,Model!BQ290,Model!BV290),"") -> -0.022508527 | L32: =IFERROR(MAX(Model!C290,Model!D290,Model!E290,Model!F290,Model!G290,Model!H290,Model!I290,Model!N290,Model!S290,Model!X290,Model!AC290,Model!AH290,Model!AM290,Model!AR290,Model!AW290,Model!BB290,Model!BG290,Model!BL290,Model!BQ290,Model!BV290),"") -> 0.11913991 | N32: FCF % | O32: 0.015613928 | P32: -0.027844963 | Q32: 0.040828139 | R32: 0.073076963 | S32: 0.099269602 | T32: 0.12318376 | V32: 0.051422747 | W32: -0.022508527 | X32: 0.11913991 | Z32: FCF % | AA32: 0.015613928 | AB32: -0.03700667 | AC32: -0.0052674805 | AD32: 0.028002462 | AE32: 0.058221793 | AF32: 0.086049025 | AH32: 0.051422747 | AI32: -0.022508527 | AJ32: 0.11913991
B33: FCF / share ($) | C33: =IFERROR(C31/C21,"") -> 1.0338967 | D33: =IFERROR(D31/D21,"") -> -2.4494753 | E33: =IFERROR(E31/E21,"") -> 1.9235935 | F33: =IFERROR(F31/F21,"") -> 5.4575233 | G33: =IFERROR(G31/G21,"") -> 9.1796151 | H33: =IFERROR(H31/H21,"") -> 13.45639 | N33: FCF / share ($) | O33: 1.0338967 | P33: -2.1195176 | Q33: 3.6503746 | R33: 7.7186688 | S33: 12.33234 | T33: 18.06459 | Z33: FCF / share ($) | AA33: 1.0338967 | AB33: -2.7794683 | AC33: -0.43077308 | AD33: 2.4647934 | AE33: 5.4483809 | AF33: 8.5375745
B34: FCF Yield (on PT) | F34: =IFERROR(F33/F$27,"") | G34: =IFERROR(G33/G$27,"") -> 0.023890725 | H34: =IFERROR(H33/H$27,"") -> 0.0294604 | N34: FCF Yield (on PT) | R34: =IFERROR(R33/R$27,"") | S34: =IFERROR(S33/S$27,"") -> 0.022748927 | T34: =IFERROR(T33/T$27,"") -> 0.026798111 | Z34: FCF Yield (on PT) | AD34: =IFERROR(AD33/AD$27,"") | AE34: =IFERROR(AE33/AE$27,"") -> 0.02504186 | AF34: =IFERROR(AF33/AF$27,"") -> 0.035076515
B35: Adjusted EBITDA (leverage basis) | C35: =Model!BV202 -> 152471 | D35: =Model!CA202 -> 191718.14 | E35: =Model!CB202 -> 248439.41 | F35: =Model!CC202 -> 297699.81 | G35: =Model!CD202 -> 346306.16 | H35: =Model!CE202 -> 395464.06 | I35: =IFERROR((H35/C35)^(1/5)-1,"n/m") -> 0.20999605 | N35: Adjusted EBITDA (leverage basis) | O35: 152471 | P35: 196379.81 | Q35: 265817.55 | R35: 324590.57 | S35: 386199.23 | T35: 452333.43 | U35: 0.2429518 | Z35: Adjusted EBITDA (leverage basis) | AA35: 152471 | AB35: 187055.79 | AC35: 223707.88 | AD35: 260600.95 | AE35: 293137.12 | AF35: 322431.63 | AG35: 0.16158255
B36: Adjusted EBITDA % of net sales | C36: =IFERROR(C35/C9,"") -> 0.21267387 | D36: =IFERROR(D35/D9,"") -> 0.23223854 | E36: =IFERROR(E35/E9,"") -> 0.26318801 | F36: =IFERROR(F35/F9,"") -> 0.27837405 | G36: =IFERROR(G35/G9,"") -> 0.28889864 | H36: =IFERROR(H35/H9,"") -> 0.29729154 | J36: =IFERROR(AVERAGE(Model!C242,Model!D242,Model!E242,Model!F242,Model!G242,Model!H242,Model!I242,Model!N242,Model!S242,Model!X242,Model!AC242,Model!AH242,Model!AM242,Model!AR242,Model!AW242,Model!BB242,Model!BG242,Model!BL242,Model!BQ242,Model!BV242),"") -> 0.095523357 | K36: =IFERROR(MIN(Model!C242,Model!D242,Model!E242,Model!F242,Model!G242,Model!H242,Model!I242,Model!N242,Model!S242,Model!X242,Model!AC242,Model!AH242,Model!AM242,Model!AR242,Model!AW242,Model!BB242,Model!BG242,Model!BL242,Model!BQ242,Model!BV242),"") -> 0.040455935 | L36: =IFERROR(MAX(Model!C242,Model!D242,Model!E242,Model!F242,Model!G242,Model!H242,Model!I242,Model!N242,Model!S242,Model!X242,Model!AC242,Model!AH242,Model!AM242,Model!AR242,Model!AW242,Model!BB242,Model!BG242,Model!BL242,Model!BQ242,Model!BV242),"") -> 0.21267387 | N36: Adjusted EBITDA % of net sales | O36: 0.21267387 | P36: 0.23630522 | Q36: 0.27319955 | R36: 0.28712563 | S36: 0.29681686 | T36: 0.3047782 | V36: 0.095523357 | W36: 0.040455935 | X36: 0.21267387 | Z36: Adjusted EBITDA % of net sales | AA36: 0.21267387 | AB36: 0.22811629 | AC36: 0.24782509 | AD36: 0.26534159 | AE36: 0.27775178 | AF36: 0.28754225 | AH36: 0.095523357 | AI36: 0.040455935 | AJ36: 0.21267387
B38: Net Debt | C38: =Model!BV410 -> -54178 | D38: =Model!CA410 -> 12412.759 | E38: =Model!CB410 -> 0 | F38: =Model!CC410 -> 0 | G38: =Model!CD410 -> 0 | H38: =Model!CE410 -> 0 | N38: Net Debt | O38: -54178 | P38: 8810.3634 | Q38: 66454.387 | R38: 81147.644 | S38: 96549.807 | T38: 113083.36 | Z38: Net Debt | AA38: -54178 | AB38: 16015.54 | AC38: 24770.413 | AD38: 1268.2483 | AE38: -56178.592 | AF38: -80607.908
B39: Net Debt / Adjusted EBITDA (x) | C39: =IFERROR(C38/C35,"") -> -0.35533315 | D39: =IFERROR(D38/D35,"") -> 0.064744836 | E39: =IFERROR(E38/E35,"") -> 0 | F39: =IFERROR(F38/F35,"") -> 0 | G39: =IFERROR(G38/G35,"") -> 0 | H39: =IFERROR(H38/H35,"") -> 0 | N39: Net Debt / Adjusted EBITDA (x) | O39: -0.35533315 | P39: 0.044863896 | Q39: 0.25 | R39: 0.25 | S39: 0.25 | T39: 0.25 | Z39: Net Debt / Adjusted EBITDA (x) | AA39: -0.35533315 | AB39: 0.085619053 | AC39: 0.1107266 | AD39: 0.0048666294 | AE39: -0.19164612 | AF39: -0.25
B40: Share repurchases ($m; 2026E = 2H) | D40: =Model!CA301 -> 0 | E40: =Model!CB301 -> 1813.6534 | F40: =Model!CC301 -> 53379.489 | G40: =Model!CD301 -> 93541.787 | H40: =Model!CE301 -> 137462.64 | N40: Share repurchases ($m; 2026E = 2H) | P40: 0 | Q40: 87368.964 | R40: 87305.505 | S40: 134565.46 | T40: 189355.47 | AB40: 0 | AC40: 0 | AD40: 0 | AE40: 0 | AF40: 68060.601
B41: Implied avg buyback price ($) | D41: =Model!CA300 -> 260 | E41: =Model!CB300 -> 280.8 | F41: =Model!CC300 -> 303.264 | G41: =Model!CD300 -> 327.52512 | H41: =Model!CE300 -> 353.72713 | N41: Implied avg buyback price ($) | P41: 260 | Q41: 280.8 | R41: 303.264 | S41: 327.52512 | T41: 353.72713 | AB41: 260 | AC41: 280.8 | AD41: 303.264 | AE41: 327.52512 | AF41: 353.72713
B42: Shares repurchased (m) | D42: =Model!CA302 -> 0 | E42: =Model!CB302 -> 6.4588796 | F42: =Model!CC302 -> 176.01657 | G42: =Model!CD302 -> 285.60187 | H42: =Model!CE302 -> 388.6121 | N42: Shares repurchased (m) | P42: 0 | Q42: 311.14304 | R42: 287.88615 | S42: 410.85539 | T42: 535.31509 | AB42: 0 | AC42: 0 | AD42: 0 | AE42: 0 | AF42: 192.4099
B44: ROIC | C44: =Model!BV392 -> 0.19563945 | D44: =Model!CA392 -> 0.13376607 | E44: =Model!CB392 -> 0.14734354 | F44: =Model!CC392 -> 0.15560318 | G44: =Model!CD392 -> 0.1654085 | H44: =Model!CE392 -> 0.17835098 | J44: =IFERROR(AVERAGE(Model!C392,Model!D392,Model!E392,Model!F392,Model!G392,Model!H392,Model!I392,Model!N392,Model!S392,Model!X392,Model!AC392,Model!AH392,Model!AM392,Model!AR392,Model!AW392,Model!BB392,Model!BG392,Model!BL392,Model!BQ392,Model!BV392),"") -> 0.41136477 | K44: =IFERROR(MIN(Model!C392,Model!D392,Model!E392,Model!F392,Model!G392,Model!H392,Model!I392,Model!N392,Model!S392,Model!X392,Model!AC392,Model!AH392,Model!AM392,Model!AR392,Model!AW392,Model!BB392,Model!BG392,Model!BL392,Model!BQ392,Model!BV392),"") -> 0.034340836 | L44: =IFERROR(MAX(Model!C392,Model!D392,Model!E392,Model!F392,Model!G392,Model!H392,Model!I392,Model!N392,Model!S392,Model!X392,Model!AC392,Model!AH392,Model!AM392,Model!AR392,Model!AW392,Model!BB392,Model!BG392,Model!BL392,Model!BQ392,Model!BV392),"") -> 1.291021 | N44: ROIC | O44: 0.19563945 | P44: 0.13965114 | Q44: 0.16600746 | R44: 0.18009391 | S44: 0.19643581 | T44: 0.2171304 | V44: 0.41136477 | W44: 0.034340836 | X44: 1.291021 | Z44: ROIC | AA44: 0.19563945 | AB44: 0.12787934 | AC44: 0.12073904 | AD44: 0.12183922 | AE44: 0.12408749 | AF44: 0.12848849 | AH44: 0.41136477 | AI44: 0.034340836 | AJ44: 1.291021
B45: RONTA | C45: =Model!BV404 -> 0.1528023 | D45: =Model!CA404 -> 0.10691764 | E45: =Model!CB404 -> 0.12091553 | F45: =Model!CC404 -> 0.12987312 | G45: =Model!CD404 -> 0.13959359 | H45: =Model!CE404 -> 0.15155888 | J45: =IFERROR(AVERAGE(Model!C404,Model!D404,Model!E404,Model!F404,Model!G404,Model!H404,Model!I404,Model!N404,Model!S404,Model!X404,Model!AC404,Model!AH404,Model!AM404,Model!AR404,Model!AW404,Model!BB404,Model!BG404,Model!BL404,Model!BQ404,Model!BV404),"") -> 0.36434569 | K45: =IFERROR(MIN(Model!C404,Model!D404,Model!E404,Model!F404,Model!G404,Model!H404,Model!I404,Model!N404,Model!S404,Model!X404,Model!AC404,Model!AH404,Model!AM404,Model!AR404,Model!AW404,Model!BB404,Model!BG404,Model!BL404,Model!BQ404,Model!BV404),"") -> 0.014831273 | L45: =IFERROR(MAX(Model!C404,Model!D404,Model!E404,Model!F404,Model!G404,Model!H404,Model!I404,Model!N404,Model!S404,Model!X404,Model!AC404,Model!AH404,Model!AM404,Model!AR404,Model!AW404,Model!BB404,Model!BG404,Model!BL404,Model!BQ404,Model!BV404),"") -> 3.0727273 | N45: RONTA | O45: 0.1528023 | P45: 0.11162262 | Q45: 0.13635468 | R45: 0.15062661 | S45: 0.16636904 | T45: 0.18546877 | V45: 0.36434569 | W45: 0.014831273 | X45: 3.0727273 | Z45: RONTA | AA45: 0.1528023 | AB45: 0.10221143 | AC45: 0.0990297 | AD45: 0.10151061 | AE45: 0.1043333 | AF45: 0.1085351 | AH45: 0.36434569 | AI45: 0.014831273 | AJ45: 3.0727273
B47: Implied Market Cap (USDm) | F47: =F27*F21 -> 0 | G47: =G27*G21 -> 4208402.5 | H47: =H27*H21 -> 4903621.2 | N47: Implied Market Cap (USDm) | R47: =R27*R21 -> 0 | S47: =S27*S21 -> 5677775.2 | T47: =T27*T21 -> 6822194.3 | Z47: Implied Market Cap (USDm) | AD47: =AD27*AD21 -> 0 | AE47: =AE27*AE21 -> 2453765 | AF47: =AF27*AF21 -> 2750841
B48: (+) Net Debt & NCI | F48: =F38+Model!CC333 -> 0 | G48: =G38+Model!CD333 -> 0 | H48: =H38+Model!CE333 -> 0 | N48: (+) Net Debt & NCI | R48: =R38+Model!CC333 -> 81147.644 | S48: =S38+Model!CD333 -> 96549.807 | T48: =T38+Model!CE333 -> 113083.36 | Z48: (+) Net Debt & NCI | AD48: =AD38+Model!CC333 -> 1268.2483 | AE48: =AE38+Model!CD333 -> -56178.592 | AF48: =AF38+Model!CE333 -> -80607.908
B49: Implied Enterprise Value (USDm) | F49: =F47+F48 -> 0 | G49: =G47+G48 -> 4208402.5 | H49: =H47+H48 -> 4903621.2 | N49: Implied Enterprise Value (USDm) | R49: =R47+R48 -> 81147.644 | S49: =S47+S48 -> 5774325 | T49: =T47+T48 -> 6935277.7 | Z49: Implied Enterprise Value (USDm) | AD49: =AD47+AD48 -> 1268.2483 | AE49: =AE47+AE48 -> 2397586.4 | AF49: =AF47+AF48 -> 2670233.1
B50: Implied EV / Adjusted EBITDA (x) | F50: =IFERROR(F49/F35,"") -> 0 | G50: =IFERROR(G49/G35,"") -> 12.15226 | H50: =IFERROR(H49/H35,"") -> 12.399663 | N50: Implied EV / Adjusted EBITDA (x) | R50: =IFERROR(R49/R35,"") -> 0.25 | S50: =IFERROR(S49/S35,"") -> 14.951674 | T50: =IFERROR(T49/T35,"") -> 15.332224 | Z50: Implied EV / Adjusted EBITDA (x) | AD50: =IFERROR(AD49/AD35,"") -> 0.0048666294 | AE50: =IFERROR(AE49/AE35,"") -> 8.1790609 | AF50: =IFERROR(AF49/AF35,"") -> 8.2815482

Sheet DCF
B2: DCF VALUATION — AMAZON.COM, INC. (AMZN)
B4: 1. WACC BUILD
B5: Risk-free rate (US 10Y govt) | C5: 0.0425 | D5: Assumption (~US 10Y Treasury yield, Oct-2026; government rate sources not reachable from the build environment); update to market
B6: Equity risk premium | C6: 0.05 | D6: Assumption: US implied ERP ~4.5–5.5%
B7: Levered beta | C7: 1.1 | D7: Assumption: mega-cap internet / cloud peers (MSFT, GOOGL, META, ORCL) ~1.0–1.3; Amazon's retail cyclicality offset by AWS / advertising contract revenue; heavy AI capex raises operating leverage
B8: Cost of equity | C8: =C5+C7*C6 -> 0.0975
B9: Pre-tax cost of debt | C9: 0.053 | D9: AA / A1 issuer; 2026 issues priced at 3.85–6.25% (USD, 8-Ks 13-Mar and 9-Jul-2026); marginal long-dated cost ~5.3%
B10: Tax rate | C10: 0.19 | D10: Model 2027E+ effective tax rate (FY2025 19.6%)
B11: After-tax cost of debt | C11: =C9*(1-C10) -> 0.04293
B12: Target D/V | C12: 0.05 | D12: Gross debt ~$165bn after the Jul/Sep-2026 notes vs ~$2.8tn market cap ($260 × ~10.9bn shares) → ~5% D/V; net debt near zero
B13: WACC | C13: =C8*(1-C12)+C11*C12 -> 0.0947715
B15: Valuation date (live) | C15: =TODAY() -> 2026-10-12 00:00:00 | D15: Periods = (Dec-31-Year − today) / 365.25; cash flows assumed at year-end. 2026E UFCF is excluded (row 24) because valuation net debt is taken at YE2026E
B16: 2. UNLEVERED FREE CASH FLOW BUILD (USDm)
