Workbook

Sheet Model
AU1: SCENARIO SWITCH ▼ (Bull / Base / Bear) — drives all scenario-linked forecast drivers
B2: Booz Allen Hamilton Holding Corporation (NYSE: BAH) — 3-Statement Financial Model | AU2: Base
B3: US GAAP as reported · USD millions (per-share data in USD; shares in millions) · Fiscal years ended 31 March (2027 = Apr-2026 – Mar-2027) · Source: Booz Allen Forms 10-K / 10-Q, Form 8-K earnings releases (Ex. 99.1), deal and financing 8-Ks and the Jul-2026 424B2, SEC EDGAR (CIK 1443646); XBRL company facts; investor-relations releases are the same documents as filed on EDGAR
B4: Basis notes: as originally reported in each period's release; one reportable segment (revenue by customer type: Defense / Intelligence / Civil / Global Commercial to FY2026, National Security / Civil & Commercial from Q1 FY2027); USD thousands to Q3 FY2025, millions from Q4 FY2025. Acquisitions: Liberty Jun-21, EverWatch Oct-22, PGSC FY25, Defy Apr-26, Ultra Mission Solutions 24-Aug-26 ($720m). Q2–Q4/27E calibrated to FY27 revenue and adjusted EBITDA guidance (22-May-2026, reiterated 24-Jul-2026; assumed to exclude Ultra).
AW5: Forecast | AX5: Historical | AY5: Historical | AZ5: Historical
B6: (USDm) | C6: 2012 | D6: 2013 | E6: 2014 | F6: 2015 | G6: 2016 | H6: 2017 | I6: 2018 | J6: 2019 | K6: 2020 | L6: 2021 | M6: Q1/22 | N6: Q2/22 | O6: Q3/22 | P6: Q4/22 | Q6: 2022 | R6: Q1/23 | S6: Q2/23 | T6: Q3/23 | U6: Q4/23 | V6: 2023 | W6: Q1/24 | X6: Q2/24 | Y6: Q3/24 | Z6: Q4/24 | AA6: 2024 | AB6: Q1/25 | AC6: Q2/25 | AD6: Q3/25 | AE6: Q4/25 | AF6: 2025 | AG6: Q1/26 | AH6: Q2/26 | AI6: Q3/26 | AJ6: Q4/26 | AK6: 2026 | AL6: Q1/27 | AM6: Q2/27E | AN6: Q3/27E | AO6: Q4/27E | AP6: 2027E | AQ6: 2028E | AR6: 2029E | AS6: 2030E | AT6: 2031E | AU6: Modelling Notes | AW6: 5Y CAGR | AX6: 5Y CAGR | AY6: 10Y CAGR | AZ6: 14Y CAGR
AW7: 26-'31 | AX7: 21-'26 | AY7: 16-'26 | AZ7: 12-'26
B8: REVENUE BUILD — CUSTOMER TYPE (NATIONAL SECURITY · CIVIL & COMMERCIAL) · ULTRA MISSION SOLUTIONS · BACKLOG | AU8: REVENUE BUILD — modelling logic (one reportable segment: revenue by customer type → + Ultra Mission Solutions (closed 24-Aug-2026) + future M&A = revenue; adjusted EBITDA = revenue × margin → GAAP P&L)
BC9: SCENARIO INPUT TABLE — driver assumptions per Bull / Base / Bear | BD9: Bull | BE9: Base | BF9: Bear | BG9: Bull / Bear = Base + Δ (Δ inputs on each block header). Outlook block = high / mid / low end of the FY27 guidance ranges.
B10: National Security (Defense + Intelligence customers; one customer type from Q1 FY2027) | AU10: NATIONAL SECURITY — modelling logic
B11: National Security revenue (Defense + Intelligence) | H11: 4044.19 | I11: 4324.591 | J11: 4681.441 | K11: 5182.974 | L11: 5470.213 | M11: 1352.682 | N11: 1392.743 | O11: 1315.148 | P11: 1467.936 | Q11: 5528.51 | R11: 1428.874 | S11: 1451.651 | T11: 1462.762 | U11: 1561.085 | V11: 5904.372 | W11: 1700.814 | X11: 1715.117 | Y11: 1633.019 | Z11: 1781.234 | AA11: 6830.184 | AB11: 1877.909 | AC11: 2040.528 | AD11: 1905.873 | AE11: 1985.69 | AF11: 7810 | AG11: 2001 | AH11: 2063 | AI11: 1888 | AJ11: 2017 | AK11: 7969 | AL11: 2028 | AM11: =AH11*(1+AM12) -> 2254.2335 | AN11: =AI11*(1+AN12) -> 2063.0116 | AO11: =AJ11*(1+AO12) -> 2203.9695 | AP11: =SUM(AL11,AM11,AN11,AO11) -> 8549.2146 | AQ11: =AP11*(1+AQ12) -> 8891.1832 | AR11: =AQ11*(1+AR12) -> 9335.7424 | AS11: =AR11*(1+AS12) -> 9802.5295 | AT11: =AS11*(1+AT12) -> 10292.656 | AU11: Revenue by customer type (10-Q / 10-K revenue note; FY2017–18 from the FY2019 10-K comparatives; Q4 = fiscal year − nine months). Q2–Q4/27E: prior-year quarter × (1 + growth). 2028E+: prior year × (1 + scenario lever). Excludes Ultra (own block below). | AW11: =IFERROR((AT11/AK11)^(1/5)-1,"n/m") -> 0.052506353 | AX11: =IFERROR((AK11/L11)^(1/5)-1,"n/m") -> 0.078151814 | AY11: =IFERROR((AK11/G11)^(1/10)-1,"n/m") -> n/m | AZ11: =IFERROR((AK11/C11)^(1/14)-1,"n/m") -> n/m | BC11: FY27 guidance — Q4 FY26 release (22-May-2026), reiterated in the Q1 FY27 release (24-Jul-2026) | BD11: High | BE11: Mid | BF11: Low | BG11: Revenue $11.2–11.7bn (0–4% growth), adjusted EBITDA $1,240–1,290m (~11% margin), adjusted diluted EPS $6.00–6.35, free cash flow $825–925m; effective tax rate 20–23%, average diluted shares 118–120m, capex ~$220m ($105m new headquarters). Assumed to exclude Ultra (see the Ultra block).
B12: y/y % | D12: =IF(AND(ISNUMBER(D11),ISNUMBER(C11)),IFERROR(D11/C11-1,""),"") | E12: =IF(AND(ISNUMBER(E11),ISNUMBER(D11)),IFERROR(E11/D11-1,""),"") | F12: =IF(AND(ISNUMBER(F11),ISNUMBER(E11)),IFERROR(F11/E11-1,""),"") | G12: =IF(AND(ISNUMBER(G11),ISNUMBER(F11)),IFERROR(G11/F11-1,""),"") | H12: =IF(AND(ISNUMBER(H11),ISNUMBER(G11)),IFERROR(H11/G11-1,""),"") | I12: =IF(AND(ISNUMBER(I11),ISNUMBER(H11)),IFERROR(I11/H11-1,""),"") -> 0.06933428 | J12: =IF(AND(ISNUMBER(J11),ISNUMBER(I11)),IFERROR(J11/I11-1,""),"") -> 0.082516474 | K12: =IF(AND(ISNUMBER(K11),ISNUMBER(J11)),IFERROR(K11/J11-1,""),"") -> 0.10713218 | L12: =IF(AND(ISNUMBER(L11),ISNUMBER(K11)),IFERROR(L11/K11-1,""),"") -> 0.055419726 | Q12: =IF(AND(ISNUMBER(Q11),ISNUMBER(L11)),IFERROR(Q11/L11-1,""),"") -> 0.010657172 | R12: =IF(AND(ISNUMBER(R11),ISNUMBER(M11)),IFERROR(R11/M11-1,""),"") -> 0.056326616 | S12: =IF(AND(ISNUMBER(S11),ISNUMBER(N11)),IFERROR(S11/N11-1,""),"") -> 0.042296389 | T12: =IF(AND(ISNUMBER(T11),ISNUMBER(O11)),IFERROR(T11/O11-1,""),"") -> 0.11224136 | U12: =IF(AND(ISNUMBER(U11),ISNUMBER(P11)),IFERROR(U11/P11-1,""),"") -> 0.063455764 | V12: =IF(AND(ISNUMBER(V11),ISNUMBER(Q11)),IFERROR(V11/Q11-1,""),"") -> 0.06798613 | W12: =IF(AND(ISNUMBER(W11),ISNUMBER(R11)),IFERROR(W11/R11-1,""),"") -> 0.19031769 | X12: =IF(AND(ISNUMBER(X11),ISNUMBER(S11)),IFERROR(X11/S11-1,""),"") -> 0.18149404 | ... AL12: =IF(AND(ISNUMBER(AL11),ISNUMBER(AG11)),IFERROR(AL11/AG11-1,""),"") -> 0.013493253 | AM12: =AM13+$AM$87 -> 0.092696824 | AN12: =AN13+$AM$87 -> 0.092696824 | AO12: =AO13+$AM$87 -> 0.092696824 | AP12: =IF(AND(ISNUMBER(AP11),ISNUMBER(AK11)),IFERROR(AP11/AK11-1,""),"") -> 0.072808965 | AQ12: =CHOOSE(MATCH($AU$2,{"Bull","Base","Bear"},0),$BD$35,$BE$35,$BF$35) -> 0.04 | AR12: =CHOOSE(MATCH($AU$2,{"Bull","Base","Bear"},0),$BD$36,$BE$36,$BF$36) -> 0.05 | AS12: =CHOOSE(MATCH($AU$2,{"Bull","Base","Bear"},0),$BD$37,$BE$37,$BF$37) -> 0.05 | AT12: =CHOOSE(MATCH($AU$2,{"Bull","Base","Bear"},0),$BD$38,$BE$38,$BF$38) -> 0.05 | AU12: Q2–Q4/27E: Q1/27 y/y growth + guidance-calibration Δ (Group block). 2028E–2031E: scenario lever (Bull/Base/Bear table →). | BC12: FY27 revenue ($m; legacy basis, excl. Ultra) | BD12: 11700 | BE12: 11450 | BF12: 11200 | BG12: Guided $11.2–11.7bn. Drives the Q2–Q4/27E revenue calibration.
B13: Q2–Q4/27E growth before calibration (Q1/27 y/y) | AM13: =IFERROR(AL11/AG11-1,0) -> 0.013493253 | AN13: =IFERROR(AL11/AG11-1,0) -> 0.013493253 | AO13: =IFERROR(AL11/AG11-1,0) -> 0.013493253 | BC13: FY27 adjusted EBITDA ($m; legacy basis) | BD13: 1290 | BE13: 1265 | BF13: 1240 | BG13: Guided $1,240–1,290m. Drives the Q2–Q4/27E adjusted EBITDA margin calibration.
B14: National Security % of revenue | C14: =IF(AND(ISNUMBER(C11),ISNUMBER(C120)),IFERROR(C11/C120,""),"") | D14: =IF(AND(ISNUMBER(D11),ISNUMBER(D120)),IFERROR(D11/D120,""),"") | E14: =IF(AND(ISNUMBER(E11),ISNUMBER(E120)),IFERROR(E11/E120,""),"") | F14: =IF(AND(ISNUMBER(F11),ISNUMBER(F120)),IFERROR(F11/F120,""),"") | G14: =IF(AND(ISNUMBER(G11),ISNUMBER(G120)),IFERROR(G11/G120,""),"") | H14: =IF(AND(ISNUMBER(H11),ISNUMBER(H120)),IFERROR(H11/H120,""),"") -> 0.6967595 | I14: =IF(AND(ISNUMBER(I11),ISNUMBER(I120)),IFERROR(I11/I120,""),"") -> 0.70069572 | J14: =IF(AND(ISNUMBER(J11),ISNUMBER(J120)),IFERROR(J11/J120,""),"") -> 0.69830178 | ... AT14: =IF(AND(ISNUMBER(AT11),ISNUMBER(AT120)),IFERROR(AT11/AT120,""),"") -> 0.74598759 | AW14: =IFERROR(AVERAGE(AP14,AQ14,AR14,AS14,AT14),"n/m") -> 0.74553193 | AX14: =IFERROR(AVERAGE(Q14,V14,AA14,AF14,AK14),"n/m") -> 0.66033686 | AY14: =IFERROR(AVERAGE(H14,I14,J14,K14,L14,Q14,V14,AA14,AF14,AK14),"n/m") -> 0.67879023 | AZ14: =IFERROR(AVERAGE(C14,D14,E14,F14,G14,H14,I14,J14,K14,L14,Q14,V14,AA14,AF14,AK14),"n/m") -> 0.67879023 | BC14: FY27 adjusted diluted EPS ($) — memo | BD14: 6.35 | BE14: 6.175 | BF14: 6 | BG14: Guided $6.00–6.35 (information row; not forced).
B15: Civil & Commercial (Civil customers + Global Commercial) | AU15: CIVIL & COMMERCIAL — modelling logic | BC15: FY27 free cash flow ($m) | BD15: 925 | BE15: 875 | BF15: 825 | BG15: Guided $825–925m. Drives the FY2027E payables & accrued calibration (working-capital block).
B16: Civil & Commercial revenue | H16: 1765.301 | I16: 1843.009 | J16: 2022.596 | K16: 2280.867 | L16: 2388.725 | M16: 636.384 | N16: 713.295 | O16: 715.372 | P16: 770.14 | Q16: 2835.19 | R16: 820.726 | S16: 847.325 | T16: 814.312 | U16: 872.176 | V16: 3354.539 | W16: 953.672 | X16: 951.165 | Y16: 936.782 | Z16: 990.093 | AA16: 3831.712 | AB16: 1063.888 | AC16: 1105.858 | AD16: 1011.317 | AE16: 988.937 | AF16: 4170 | AG16: 923 | AH16: 827 | AI16: 732 | AJ16: 766 | AK16: 3248 | AL16: 772 | AM16: =AH16*(1+AM17) -> 757.20666 | AN16: =AI16*(1+AN17) -> 670.22403 | AO16: =AJ16*(1+AO17) -> 701.35466 | AP16: =SUM(AL16,AM16,AN16,AO16) -> 2900.7854 | AQ16: =AP16*(1+AQ17) -> 2784.7539 | AR16: =AQ16*(1+AR17) -> 2784.7539 | AS16: =AR16*(1+AS17) -> 2840.449 | AT16: =AS16*(1+AT17) -> 2925.6625 | AU16: Civil customers + Global Commercial (reported separately to FY2024, inside Civil from FY2025). Same forecast logic as National Security. | AW16: =IFERROR((AT16/AK16)^(1/5)-1,"n/m") -> -0.020686727 | AX16: =IFERROR((AK16/L16)^(1/5)-1,"n/m") -> 0.063383637 | AY16: =IFERROR((AK16/G16)^(1/10)-1,"n/m") -> n/m | AZ16: =IFERROR((AK16/C16)^(1/14)-1,"n/m") -> n/m | BC16: Q2–Q4/27E share repurchases ($m) | BD16: 300 | BE16: 150 | BF16: 50 | BG16: Assumption. Q1/27 $72m (incl. shares withheld for taxes); $634m left on the $4,085m program at 30-Jun-2026; Ultra ($720m) funded in Q2.
B17: y/y % | D17: =IF(AND(ISNUMBER(D16),ISNUMBER(C16)),IFERROR(D16/C16-1,""),"") | E17: =IF(AND(ISNUMBER(E16),ISNUMBER(D16)),IFERROR(E16/D16-1,""),"") | F17: =IF(AND(ISNUMBER(F16),ISNUMBER(E16)),IFERROR(F16/E16-1,""),"") | G17: =IF(AND(ISNUMBER(G16),ISNUMBER(F16)),IFERROR(G16/F16-1,""),"") | H17: =IF(AND(ISNUMBER(H16),ISNUMBER(G16)),IFERROR(H16/G16-1,""),"") | I17: =IF(AND(ISNUMBER(I16),ISNUMBER(H16)),IFERROR(I16/H16-1,""),"") -> 0.044019688 | J17: =IF(AND(ISNUMBER(J16),ISNUMBER(I16)),IFERROR(J16/I16-1,""),"") -> 0.097442281 | K17: =IF(AND(ISNUMBER(K16),ISNUMBER(J16)),IFERROR(K16/J16-1,""),"") -> 0.12769283 | L17: =IF(AND(ISNUMBER(L16),ISNUMBER(K16)),IFERROR(L16/K16-1,""),"") -> 0.047288158 | Q17: =IF(AND(ISNUMBER(Q16),ISNUMBER(L16)),IFERROR(Q16/L16-1,""),"") -> 0.18690515 | R17: =IF(AND(ISNUMBER(R16),ISNUMBER(M16)),IFERROR(R16/M16-1,""),"") -> 0.28967102 | S17: =IF(AND(ISNUMBER(S16),ISNUMBER(N16)),IFERROR(S16/N16-1,""),"") -> 0.18790262 | T17: =IF(AND(ISNUMBER(T16),ISNUMBER(O16)),IFERROR(T16/O16-1,""),"") -> 0.13830566 | U17: =IF(AND(ISNUMBER(U16),ISNUMBER(P16)),IFERROR(U16/P16-1,""),"") -> 0.1324902 | V17: =IF(AND(ISNUMBER(V16),ISNUMBER(Q16)),IFERROR(V16/Q16-1,""),"") -> 0.18317961 | W17: =IF(AND(ISNUMBER(W16),ISNUMBER(R16)),IFERROR(W16/R16-1,""),"") -> 0.16198585 | X17: =IF(AND(ISNUMBER(X16),ISNUMBER(S16)),IFERROR(X16/S16-1,""),"") -> 0.12255038 | ... AL17: =IF(AND(ISNUMBER(AL16),ISNUMBER(AG16)),IFERROR(AL16/AG16-1,""),"") -> -0.16359697 | AM17: =AM18+$AM$87 -> -0.084393396 | AN17: =AN18+$AM$87 -> -0.084393396 | AO17: =AO18+$AM$87 -> -0.084393396 | AP17: =IF(AND(ISNUMBER(AP16),ISNUMBER(AK16)),IFERROR(AP16/AK16-1,""),"") -> -0.10690106 | AQ17: =CHOOSE(MATCH($AU$2,{"Bull","Base","Bear"},0),$BD$40,$BE$40,$BF$40) -> -0.04 | AR17: =CHOOSE(MATCH($AU$2,{"Bull","Base","Bear"},0),$BD$41,$BE$41,$BF$41) -> 0 | AS17: =CHOOSE(MATCH($AU$2,{"Bull","Base","Bear"},0),$BD$42,$BE$42,$BF$42) -> 0.02 | AT17: =CHOOSE(MATCH($AU$2,{"Bull","Base","Bear"},0),$BD$43,$BE$43,$BF$43) -> 0.03
B18: Q2–Q4/27E growth before calibration (Q1/27 y/y) | AM18: =IFERROR(AL16/AG16-1,0) -> -0.16359697 | AN18: =IFERROR(AL16/AG16-1,0) -> -0.16359697 | AO18: =IFERROR(AL16/AG16-1,0) -> -0.16359697 | BC18: FY27 point estimates (all cases)
B19: Civil & Commercial % of revenue | C19: =IF(AND(ISNUMBER(C16),ISNUMBER(C120)),IFERROR(C16/C120,""),"") | D19: =IF(AND(ISNUMBER(D16),ISNUMBER(D120)),IFERROR(D16/D120,""),"") | E19: =IF(AND(ISNUMBER(E16),ISNUMBER(E120)),IFERROR(E16/E120,""),"") | F19: =IF(AND(ISNUMBER(F16),ISNUMBER(F120)),IFERROR(F16/F120,""),"") | G19: =IF(AND(ISNUMBER(G16),ISNUMBER(G120)),IFERROR(G16/G120,""),"") | H19: =IF(AND(ISNUMBER(H16),ISNUMBER(H120)),IFERROR(H16/H120,""),"") -> 0.3041376 | I19: =IF(AND(ISNUMBER(I16),ISNUMBER(I120)),IFERROR(I16/I120,""),"") -> 0.29861518 | J19: =IF(AND(ISNUMBER(J16),ISNUMBER(J120)),IFERROR(J16/J120,""),"") -> 0.30169822 | ... AT19: =IF(AND(ISNUMBER(AT16),ISNUMBER(AT120)),IFERROR(AT16/AT120,""),"") -> 0.21204516 | AW19: =IFERROR(AVERAGE(AP19,AQ19,AR19,AS19,AT19),"n/m") -> 0.22730672 | AX19: =IFERROR(AVERAGE(Q19,V19,AA19,AF19,AK19),"n/m") -> 0.33966314 | AY19: =IFERROR(AVERAGE(H19,I19,J19,K19,L19,Q19,V19,AA19,AF19,AK19),"n/m") -> 0.32123057 | AZ19: =IFERROR(AVERAGE(C19,D19,E19,F19,G19,H19,I19,J19,K19,L19,Q19,V19,AA19,AF19,AK19),"n/m") -> 0.32123057 | BC19: FY27 interest expense, net ($m) | BE19: 216 | BG19: Not guided (assumption): Q1 $48m; $1.2bn notes at 5.375% / 5.900% from 4-Aug-2026, Term Loan A-1 ($714m, ~5.0%) repaid, lower interest income after the Ultra payment.
B20: Revenue outside the customer split (FY2012–16 not split; FY2017–18 ASC 606 recast basis difference; rounding) — derived | C20: =IF(ISNUMBER(C11),C120-C11-C16,C120) -> 5859.218 | D20: =IF(ISNUMBER(D11),D120-D11-D16,D120) -> 5758.059 | E20: =IF(ISNUMBER(E11),E120-E11-E16,E120) -> 5478.693 | F20: =IF(ISNUMBER(F11),F120-F11-F16,F120) -> 5274.77 | G20: =IF(ISNUMBER(G11),G120-G11-G16,G120) -> 5405.738 | H20: =IF(ISNUMBER(H11),H120-H11-H16,H120) -> -5.207 | I20: =IF(ISNUMBER(I11),I120-I11-I16,I120) -> 4.253 | J20: =IF(ISNUMBER(J11),J120-J11-J16,J120) -> 0 | ... AL20: =IF(ISNUMBER(AL11),AL120-AL11-AL16,AL120) -> 0 | AM20: =0 -> 0 | AN20: =0 -> 0 | AO20: =0 -> 0 | AP20: =SUM(AL20,AM20,AN20,AO20) -> 0 | AQ20: =0 -> 0 | AR20: =0 -> 0 | AS20: =0 -> 0 | AT20: =0 -> 0 | AU20: Derived = revenue − Σ customer types, so the build ties in every period. FY2012–16: no customer split published (whole revenue). FY2017–18: the split comes from the FY2019 10-K (ASC 606 full-retrospective recast: $5,809.5m / $6,167.6m vs $5,804.3m / $6,171.9m as originally reported). From FY2025 the 10-Q tables are in whole $m (±1 rounding). | BC20: FY27 other income (expense) ($m) | BE20: 26 | BG20: Q1 $20m (incl. $18m net gains on investments and dispositions); ~$2m a quarter after (assumption).
B21: Legacy customer types (as reported; replaced by National Security / Civil & Commercial): | BC21: FY27 acquisition amortization excl. Ultra ($m) | BE21: 60 | BG21: Q1 $15m (incl. Defy, $86m over 8 years) × 4.
B22: Defense | H22: 2699.284 | I22: 2830.102 | J22: 3114.571 | K22: 3568.659 | L22: 3898.802 | M22: 975.926 | N22: 999.174 | O22: 946.161 | P22: 1034.211 | Q22: 3955.473 | R22: 1019.991 | S22: 1019.108 | T22: 1043.535 | U22: 1127.796 | V22: 4210.43 | W22: 1224.317 | X22: 1270.135 | Y22: 1224.561 | Z22: 1336.766 | AA22: 5055.779 | AB22: 1416.87 | AC22: 1544.108 | AD22: 1454.686 | AE22: 1527.336 | AF22: 5943 | AG22: 1517 | AH22: 1580 | AI22: 1454 | AJ22: 1518 | AK22: 6069 | BC22: FY27 depreciation & other amortization ($m) | BE22: 120 | BG22: Q1 $30m (D&A $45m − acquisition amortization $15m) × 4.
B23: Intelligence | H23: 1344.906 | I23: 1494.489 | J23: 1566.87 | K23: 1614.315 | L23: 1571.411 | M23: 376.756 | N23: 393.569 | O23: 368.987 | P23: 433.725 | Q23: 1573.037 | R23: 408.883 | S23: 432.543 | T23: 419.227 | U23: 433.289 | V23: 1693.942 | W23: 476.497 | X23: 444.982 | Y23: 408.458 | Z23: 444.468 | AA23: 1774.405 | AB23: 461.039 | AC23: 496.42 | AD23: 451.187 | AE23: 458.354 | AF23: 1867 | AG23: 484 | AH23: 483 | AI23: 434 | AJ23: 499 | AK23: 1900 | BC23: FY27 stock-based compensation ($m) | BE23: 84 | BG23: Q1 $21m × 4 (FY26 $69m).
B24: Civil (incl. Global Commercial from FY2025) | H24: 1611.309 | I24: 1644.86 | J24: 1760.996 | K24: 2019.245 | L24: 2185.03 | M24: 592.896 | N24: 662.261 | O24: 651.372 | P24: 712.386 | Q24: 2618.914 | R24: 757.714 | S24: 783.782 | T24: 758.473 | U24: 824.92 | V24: 3124.889 | W24: 904.96 | X24: 916.069 | Y24: 893.202 | Z24: 944.234 | AA24: 3658.465 | AB24: 1063.888 | AC24: 1105.858 | AD24: 1011.317 | AE24: 988.937 | AF24: 4170 | AG24: 923 | AH24: 827 | AI24: 732 | AJ24: 766 | AK24: 3248 | BC24: Q2–Q4/27E effective tax rate | BE24: 0.215 | BG24: FY27 guidance 20–23% (Q1/27 21.1%).
B25: Global Commercial (to FY2024) | H25: 153.992 | I25: 198.149 | J25: 261.6 | K25: 261.622 | L25: 203.695 | M25: 43.488 | N25: 51.034 | O25: 64 | P25: 57.754 | Q25: 216.276 | R25: 63.012 | S25: 63.543 | T25: 55.839 | U25: 47.256 | V25: 229.65 | W25: 48.712 | X25: 35.096 | Y25: 43.58 | Z25: 45.859 | AA25: 173.247 | BC25: FY27 capital expenditures ($m) | BE25: 220 | BG25: Guided ~$220m, of which ~$105m for the new headquarters (Q1 $20m).
B26: Check: legacy customer types vs National Security + Civil & Commercial (should be 0; ±0.15, ±0.6 from Q4 FY25) | C26: =IF(ISNUMBER(C22),IF(ABS(C22+C23+C24+N(C25)-C11-C16)<=1,0,ROUND(C22+C23+C24+N(C25)-C11-C16,1)),"") | D26: =IF(ISNUMBER(D22),IF(ABS(D22+D23+D24+N(D25)-D11-D16)<=1,0,ROUND(D22+D23+D24+N(D25)-D11-D16,1)),"") | E26: =IF(ISNUMBER(E22),IF(ABS(E22+E23+E24+N(E25)-E11-E16)<=1,0,ROUND(E22+E23+E24+N(E25)-E11-E16,1)),"") | F26: =IF(ISNUMBER(F22),IF(ABS(F22+F23+F24+N(F25)-F11-F16)<=1,0,ROUND(F22+F23+F24+N(F25)-F11-F16,1)),"") | G26: =IF(ISNUMBER(G22),IF(ABS(G22+G23+G24+N(G25)-G11-G16)<=1,0,ROUND(G22+G23+G24+N(G25)-G11-G16,1)),"") | H26: =IF(ISNUMBER(H22),IF(ABS(H22+H23+H24+N(H25)-H11-H16)<=1,0,ROUND(H22+H23+H24+N(H25)-H11-H16,1)),"") -> 0 | I26: =IF(ISNUMBER(I22),IF(ABS(I22+I23+I24+N(I25)-I11-I16)<=1,0,ROUND(I22+I23+I24+N(I25)-I11-I16,1)),"") -> 0 | J26: =IF(ISNUMBER(J22),IF(ABS(J22+J23+J24+N(J25)-J11-J16)<=1,0,ROUND(J22+J23+J24+N(J25)-J11-J16,1)),"") -> 0 | ... AL26: =IF(ISNUMBER(AL22),IF(ABS(AL22+AL23+AL24+N(AL25)-AL11-AL16)<=1,0,ROUND(AL22+AL23+AL24+N(AL25)-AL11-AL16,1)),"") | BC26: FY27 other corporate (acquisition) expenses, adjusted out ($m) | BE26: 25 | BG26: Q1 $10m (Defy; Ultra agreement). Ultra closing and integration costs (assumption).
BC27: FY27 non-operating adjusting items ($m) | BE27: 0 | BG27: None in Q1/27 (debt-cost amortization no longer adjusted out since FY2026).
B28: Ultra I&C Mission Solutions — acquired 24-Aug-2026 for $720m (National Security defense technology; revenue not disclosed) | AU28: ULTRA MISSION SOLUTIONS — modelling logic (closed after the FY27 guidance; added on top of the calibrated legacy business) | BC28: Two-class allocation to participating securities (% of net income) | BE28: 0.008 | BG28: FY2026 0.7%, Q1/27 1.0%, FY2025 0.5%.
B29: Annualised revenue run-rate (USDm; FY2027E = assumption, then × (1 + growth)) | AP29: 180 | AQ29: =AP29*(1+AQ30) -> 207 | AR29: =AQ29*(1+AR30) -> 238.05 | AS29: =AR29*(1+AS30) -> 266.616 | AT29: =AS29*(1+AT30) -> 293.2776 | AU29: Ultra I&C Mission Solutions (Ultra Electronics Advanced Tactical Systems, Inc.): stock purchase agreement 19-Jun-2026 for $720m subject to adjustments (8-K Item 1.01, 22-Jun-2026); closed 24-Aug-2026 (8-K 24-Aug-2026, Ex. 99.1). Revenue and EBITDA not disclosed; the announcement (Ex. 99.1, 22-Jun-2026) says BAH 'expects revenue from this acquisition to grow at a strong double-digit rate for the next several years with EBITDA margins well above 20%'. Run-rate $180m is an ASSUMPTION (~4x EV / sales); replace with the Q2 FY27 10-Q disclosure. | BC29: Tax rate on adjusting items (company assumed rate) | BE29: 0.26 | BG29: Release footnote: "assumed effective tax rate of 26%, which approximates the blended federal and state tax rates".
B30: Growth % (scenario lever from 2028E; company: "strong double-digit rate for the next several years") | AQ30: =CHOOSE(MATCH($AU$2,{"Bull","Base","Bear"},0),$BD$45,$BE$45,$BF$45) -> 0.15 | AR30: =CHOOSE(MATCH($AU$2,{"Bull","Base","Bear"},0),$BD$46,$BE$46,$BF$46) -> 0.15 | AS30: =CHOOSE(MATCH($AU$2,{"Bull","Base","Bear"},0),$BD$47,$BE$47,$BF$47) -> 0.12 | AT30: =CHOOSE(MATCH($AU$2,{"Bull","Base","Bear"},0),$BD$48,$BE$48,$BF$48) -> 0.1 | BC30: FY27 Ultra adjusted EBITDA margin | BE30: 0.25 | BG30: Company: "EBITDA margins well above 20%" (8-K Ex. 99.1, 22-Jun-2026). 25% is an assumption.
B31: Share of the quarter consolidated (closed 24-Aug-2026: 38 of 91 days in Q2/27) | AM31: 0.41758242 | AN31: 1 | AO31: 1
B32: Ultra revenue | AM32: =$AP$29/4*AM31 -> 18.791209 | AN32: =$AP$29/4*AN31 -> 45 | AO32: =$AP$29/4*AO31 -> 45 | AP32: =SUM(AL32,AM32,AN32,AO32) -> 108.79121 | AQ32: =AQ29 -> 207 | AR32: =AR29 -> 238.05 | AS32: =AS29 -> 266.616 | AT32: =AT29 -> 293.2776 | BC32: Maximum net debt / adjusted EBITDA before buybacks (x) — buyback floor 2028E+ | BD32: 3.25 | BE32: 3 | BF32: 2.5 | BG32: Assumption (no leverage target in the SEC filings). Net leverage ratio (net debt / LTM adjusted EBITDA, company definition) 2.6x at 31-Mar-2026, 2.7x at 30-Jun-2026; ~3.2x pro forma for Ultra. Target = leverage up to which surplus cash is returned via buybacks; below it free cash flow repays debt / builds cash.
B33: Adjusted EBITDA margin % (company: "EBITDA margins well above 20%") | AM33: =$BE$30 -> 0.25 | AN33: =$BE$30 -> 0.25 | AO33: =$BE$30 -> 0.25 | AP33: =$BE$30 -> 0.25 | AQ33: =CHOOSE(MATCH($AU$2,{"Bull","Base","Bear"},0),$BD$55,$BE$55,$BF$55) -> 0.25 | AR33: =CHOOSE(MATCH($AU$2,{"Bull","Base","Bear"},0),$BD$56,$BE$56,$BF$56) -> 0.25 | AS33: =CHOOSE(MATCH($AU$2,{"Bull","Base","Bear"},0),$BD$57,$BE$57,$BF$57) -> 0.25 | AT33: =CHOOSE(MATCH($AU$2,{"Bull","Base","Bear"},0),$BD$58,$BE$58,$BF$58) -> 0.25
B34: Ultra adjusted EBITDA | AM34: =AM32*AM33 -> 4.6978022 | AN34: =AN32*AN33 -> 11.25 | AO34: =AO32*AO33 -> 11.25 | AP34: =SUM(AL34,AM34,AN34,AO34) -> 27.197802 | AQ34: =AQ32*AQ33 -> 51.75 | AR34: =AR32*AR33 -> 59.5125 | AS34: =AS32*AS33 -> 66.654 | AT34: =AT32*AT33 -> 73.3194 | BC34: NS_G (National Security revenue y/y, ex-Ultra) | BD34: 0.02 | BE34: Δ → | BF34: -0.03 | BG34: FY26 +2.0%, Q1/27 +1.3% (incl. Defy); FY2022–25 CAGR +9%. Record $39.5bn backlog, Q1/27 book-to-bill 1.5x; defense / intelligence budget growth (FY26 NDAA). Assumption.
B35: Consideration (USDm; 8-K 22-Jun-2026, subject to adjustments) | AP35: 720 | BC35: 2028E | BD35: =BE35+$BD$34 -> 0.06 | BE35: 0.04 | BF35: =BE35+$BF$34 -> 0.01
B36: Acquired intangibles % of consideration (assumption; Defy 37%) | AP36: 0.4 | BC36: 2029E | BD36: =BE36+$BD$34 -> 0.07 | BE36: 0.05 | BF36: =BE36+$BF$34 -> 0.02
B37: Intangible amortization life (years; assumption) | AP37: 10 | BC37: 2030E | BD37: =BE37+$BD$34 -> 0.07 | BE37: 0.05 | BF37: =BE37+$BF$34 -> 0.02
B38: Ultra acquisition amortization (adjusted out by the company) | AM38: =$AP$35*$AP$36/$AP$37/4*AM31 -> 3.0065934 | AN38: =$AP$35*$AP$36/$AP$37/4*AN31 -> 7.2 | AO38: =$AP$35*$AP$36/$AP$37/4*AO31 -> 7.2 | AP38: =SUM(AL38,AM38,AN38,AO38) -> 17.406593 | AQ38: =AP35*AP36/AP37 -> 28.8 | AR38: =AP35*AP36/AP37 -> 28.8 | AS38: =AP35*AP36/AP37 -> 28.8 | AT38: =AP35*AP36/AP37 -> 28.8 | BC38: 2031E | BD38: =BE38+$BD$34 -> 0.07 | BE38: 0.05 | BF38: =BE38+$BF$34 -> 0.02
BC39: CC_G (Civil & Commercial revenue y/y) | BD39: 0.04 | BE39: Δ → | BF39: -0.04 | BG39: FY26 −22% (civil agency contract cuts and cancellations, contract sale Nov-2025), Q1/27 −16%. Assumed to trough in FY28. Assumption.
B40: Backlog, book-to-bill & headcount (operating data, release Exhibit 5) | AU40: BACKLOG — roll-forward: closing = opening + net bookings − revenue; net bookings = revenue × book-to-bill (company definition) | BC40: 2028E | BD40: =BE40+$BD$39 -> 0 | BE40: -0.04 | BF40: =BE40+$BF$39 -> -0.08
...

Sheet Bull-Base-Bear
B2: Booz Allen Hamilton Holding Corporation (BAH) — Bull / Base / Bear Case P&L Summary | J2: Share price ($): | K2: =Model!$AP$385 -> 75
B3: Adjusted figures (company definitions: adjusted EBITDA, adjusted net income, adjusted diluted EPS) · USD millions · fiscal years ended 31 March · Live panel linked to Model — toggle scenario via Model!AU2. Bull and Bear panels are value snapshots generated from the Model with the switch set to each case. FY2027E = Q1 actual + Q2–Q4 calibrated to FY27 guidance (revenue $11.2–11.7bn, adjusted EBITDA $1,240–1,290m), plus Ultra Mission Solutions from 24-Aug-2026. | J3: As of: | K3: =TODAY() -> 2026-10-12 00:00:00
B5: Scenario: | C5: =Model!$AU$2 -> Base | N5: Scenario: | O5: Bull | P5: Snapshot (values) — Model run with switch = Bull | Z5: Scenario: | AA5: Bear | AB5: Snapshot (values) — Model run with switch = Bear
B7: (USDm, except EPS and shares) | C7: 2026A | D7: 2027E | E7: 2028E | F7: 2029E | G7: 2030E | H7: 2031E | I7: 26-'31 CAGR | J7: LT Hist Avg | K7: LT Hist Min | L7: LT Hist Max | N7: (USDm, except EPS and shares) | O7: 2026A | P7: 2027E | Q7: 2028E | R7: 2029E | S7: 2030E | T7: 2031E | U7: 26-'31 CAGR | V7: LT Hist Avg | W7: LT Hist Min | X7: LT Hist Max | Z7: (USDm, except EPS and shares) | AA7: 2026A | AB7: 2027E | AC7: 2028E | AD7: 2029E | AE7: 2030E | AF7: 2031E | AG7: 26-'31 CAGR | AH7: LT Hist Avg | AI7: LT Hist Min | AJ7: LT Hist Max
B9: Revenue | C9: =Model!AK120 -> 11217 | D9: =Model!AP120 -> 11558.791 | E9: =Model!AQ120 -> 11920.437 | F9: =Model!AR120 -> 12474.796 | G9: =Model!AS120 -> 13108.532 | H9: =Model!AT120 -> 13797.355 | I9: =IFERROR((H9/C9)^(1/5)-1,"n/m") -> 0.042278614 | N9: Revenue | O9: 11217 | P9: 11808.791 | Q9: 12514.748 | R9: 13481.984 | S9: 14569.845 | T9: 15759.788 | U9: 0.070371979 | Z9: Revenue | AA9: 11217 | AB9: 11308.791 | AC9: 11249.837 | AD9: 11328.21 | AE9: 11458.893 | AF9: 11614.568 | AG9: 0.0069902638
B10: Revenue y/y % | D10: =IFERROR(D9/C9-1,"") -> 0.030470822 | E10: =IFERROR(E9/D9-1,"") -> 0.031287524 | F10: =IFERROR(F9/E9-1,"") -> 0.046504935 | G10: =IFERROR(G9/F9-1,"") -> 0.050801286 | H10: =IFERROR(H9/G9-1,"") -> 0.052547716 | N10: Revenue y/y % | P10: 0.052758421 | Q10: 0.059782268 | R10: 0.077287703 | S10: 0.080690037 | T10: 0.081671615 | Z10: Revenue y/y % | AB10: 0.0081832227 | AC10: -0.0052131 | AD10: 0.0069665293 | AE10: 0.011536068 | AF10: 0.013585586
B11: National Security revenue y/y % | C11: =Model!AK214 -> 0.020358515 | D11: =Model!AP214 -> 0.072808965 | E11: =Model!AQ214 -> 0.04 | F11: =Model!AR214 -> 0.05 | G11: =Model!AS214 -> 0.05 | H11: =Model!AT214 -> 0.05 | N11: National Security revenue y/y % | O11: 0.020358515 | P11: 0.095385295 | Q11: 0.06 | R11: 0.07 | S11: 0.07 | T11: 0.07 | Z11: National Security revenue y/y % | AA11: 0.020358515 | AB11: 0.050232636 | AC11: 0.01 | AD11: 0.02 | AE11: 0.02 | AF11: 0.02
B12: Adjusted EBITDA | C12: =Model!AK174 -> 1229 | D12: =Model!AP174 -> 1292.1978 | E12: =Model!AQ174 -> 1363.955 | F12: =Model!AR174 -> 1443.0786 | G12: =Model!AS174 -> 1531.8261 | H12: =Model!AT174 -> 1627.7171 | I12: =IFERROR((H12/C12)^(1/5)-1,"n/m") -> 0.057804503 | N12: Adjusted EBITDA | O12: 1229 | P12: 1317.1978 | Q12: 1499.6585 | R12: 1633.3295 | S12: 1783.035 | T12: 1946.9752 | U12: 0.096381517 | Z12: Adjusted EBITDA | AA12: 1229 | AB12: 1267.1978 | AC12: 1170.2102 | AD12: 1190.9172 | AE12: 1216.5866 | AF12: 1244.67 | AG12: 0.0025371406
B13: Adjusted EBITDA margin % | C13: =IFERROR(C12/C9,"") -> 0.10956584 | D13: =IFERROR(D12/D9,"") -> 0.11179351 | E13: =IFERROR(E12/E9,"") -> 0.11442156 | F13: =IFERROR(F12/F9,"") -> 0.11567953 | G13: =IFERROR(G12/G9,"") -> 0.11685718 | H13: =IFERROR(H12/H9,"") -> 0.11797313 | J13: =IFERROR(AVERAGE(Model!C175,Model!D175,Model!E175,Model!F175,Model!G175,Model!H175,Model!I175,Model!J175,Model!K175,Model!L175,Model!Q175,Model!V175,Model!AA175,Model!AF175,Model!AK175),"") -> 0.10092471 | K13: =IFERROR(MIN(Model!C175,Model!D175,Model!E175,Model!F175,Model!G175,Model!H175,Model!I175,Model!J175,Model!K175,Model!L175,Model!Q175,Model!V175,Model!AA175,Model!AF175,Model!AK175),"") -> 0.083297805 | L13: =IFERROR(MAX(Model!C175,Model!D175,Model!E175,Model!F175,Model!G175,Model!H175,Model!I175,Model!J175,Model!K175,Model!L175,Model!Q175,Model!V175,Model!AA175,Model!AF175,Model!AK175),"") -> 0.11178366 | N13: Adjusted EBITDA margin % | O13: 0.10956584 | P13: 0.11154383 | Q13: 0.1198313 | R13: 0.12114905 | S13: 0.12237844 | T13: 0.12354069 | V13: 0.10092471 | W13: 0.083297805 | X13: 0.11178366 | Z13: Adjusted EBITDA margin % | AA13: 0.10956584 | AB13: 0.11205422 | AC13: 0.10402019 | AD13: 0.10512846 | AE13: 0.10616965 | AF13: 0.10716455 | AH13: 0.10092471 | AI13: 0.083297805 | AJ13: 0.11178366
B15: Operating Income (GAAP) | C15: =Model!AK127 -> 1033 | D15: =Model!AP127 -> 1069.7912 | E15: =Model!AQ127 -> 1157.8693 | F15: =Model!AR127 -> 1232.1869 | G15: =Model!AS127 -> 1314.7345 | H15: =Model!AT127 -> 1401.4748 | I15: =IFERROR((H15/C15)^(1/5)-1,"n/m") -> 0.062911234 | N15: Operating Income (GAAP) | O15: 1033 | P15: 1094.7912 | Q15: 1279.8485 | R15: 1398.0221 | S15: 1530.424 | T15: 1673.6398 | U15: 0.10131698 | Z15: Operating Income (GAAP) | AA15: 1033 | AB15: 1044.7912 | AC15: 978.61184 | AD15: 1005.8351 | AE15: 1036.8976 | AF15: 1067.7244 | AG15: 0.0066343957
B16: Operating income y/y % | D16: =IFERROR(D15/C15-1,"") -> 0.035615885 | E16: =IFERROR(E15/D15-1,"") -> 0.082332078 | F16: =IFERROR(F15/E15-1,"") -> 0.06418473 | G16: =IFERROR(G15/F15-1,"") -> 0.066992769 | H16: =IFERROR(H15/G15-1,"") -> 0.065975575 | N16: Operating income y/y % | P16: 0.05981724 | Q16: 0.16903431 | R16: 0.09233409 | S16: 0.09470658 | T16: 0.093579131 | Z16: Operating income y/y % | AB16: 0.011414529 | AC16: -0.063342199 | AD16: 0.027818238 | AE16: 0.030882349 | AF16: 0.029729756
B17: Operating margin (GAAP) % | C17: =IFERROR(C15/C9,"") -> 0.09209236 | D17: =IFERROR(D15/D9,"") -> 0.09255217 | E17: =IFERROR(E15/E9,"") -> 0.097133127 | F17: =IFERROR(F15/F9,"") -> 0.098774107 | G17: =IFERROR(G15/G9,"") -> 0.10029609 | H17: =IFERROR(H15/H9,"") -> 0.10157561 | J17: =IFERROR(AVERAGE(Model!C223,Model!D223,Model!E223,Model!F223,Model!G223,Model!H223,Model!I223,Model!J223,Model!K223,Model!L223,Model!Q223,Model!V223,Model!AA223,Model!AF223,Model!AK223),"") -> 0.084786964 | K17: =IFERROR(MIN(Model!C223,Model!D223,Model!E223,Model!F223,Model!G223,Model!H223,Model!I223,Model!J223,Model!K223,Model!L223,Model!Q223,Model!V223,Model!AA223,Model!AF223,Model!AK223),"") -> 0.048261399 | L17: =IFERROR(MAX(Model!C223,Model!D223,Model!E223,Model!F223,Model!G223,Model!H223,Model!I223,Model!J223,Model!K223,Model!L223,Model!Q223,Model!V223,Model!AA223,Model!AF223,Model!AK223),"") -> 0.11435726 | N17: Operating margin (GAAP) % | O17: 0.09209236 | P17: 0.092709846 | Q17: 0.10226722 | R17: 0.10369558 | S17: 0.10504051 | T17: 0.10619684 | V17: 0.084786964 | W17: 0.048261399 | X17: 0.11435726 | Z17: Operating margin (GAAP) % | AA17: 0.09209236 | AB17: 0.092387523 | AC17: 0.086988976 | AD17: 0.088790296 | AE17: 0.090488468 | AF17: 0.091929749 | AH17: 0.084786964 | AI17: 0.048261399 | AJ17: 0.11435726
B19: Adjusted Net Income | C19: =Model!AK199 -> 797 | D19: =Model!AP199 -> 767.88198 | E19: =Model!AQ199 -> 800.61154 | F19: =Model!AR199 -> 846.57043 | G19: =Model!AS199 -> 893.51464 | H19: =Model!AT199 -> 946.03976 | I19: =IFERROR((H19/C19)^(1/5)-1,"n/m") -> 0.034880524 | N19: Adjusted Net Income | O19: 797 | P19: 787.50698 | Q19: 898.61965 | R19: 952.37331 | S19: 1034.4112 | T19: 1126.1706 | U19: 0.071591294 | Z19: Adjusted Net Income | AA19: 797 | AB19: 748.25698 | AC19: 657.06391 | AD19: 681.82032 | AE19: 701.55895 | AF19: 716.47786 | AG19: -0.021076193
B21: FDSO (m) | C21: =Model!AK146 -> 122.37515 | D21: =Model!AP146 -> 119.8994 | E21: =Model!AQ146 -> 115.01146 | F21: =Model!AR146 -> 106.93131 | G21: =Model!AS146 -> 98.87022 | H21: =Model!AT146 -> 90.541097 | I21: =IFERROR((H21/C21)^(1/5)-1,"n/m") -> -0.058477935 | N21: FDSO (m) | O21: 122.37515 | P21: 119.1494 | Q21: 109.11035 | R21: 96.134078 | S21: 85.771397 | T21: 74.519962 | U21: -0.094442824 | Z21: FDSO (m) | AA21: 122.37515 | AB21: 120.3994 | AC21: 121.06759 | AD21: 120.94998 | AE21: 117.67531 | AF21: 112.69234 | AG21: -0.016350823
B23: Adjusted EPS — Diluted ($) | C23: =Model!AK203 -> 6.5127601 | D23: =Model!AP203 -> 6.4043857 | E23: =Model!AQ203 -> 6.961146 | F23: =Model!AR203 -> 7.9169555 | G23: =Model!AS203 -> 9.0372474 | H23: =Model!AT203 -> 10.448733 | I23: =IFERROR((H23/C23)^(1/5)-1,"n/m") -> 0.099156953 | N23: Adjusted EPS — Diluted ($) | O23: 6.5127601 | P23: 6.6094081 | Q23: 8.235879 | R23: 9.9067191 | S23: 12.060095 | T23: 15.112335 | U23: 0.18335023 | Z23: Adjusted EPS — Diluted ($) | AA23: 6.5127601 | AB23: 6.2147902 | AC23: 5.4272486 | AD23: 5.6372089 | AE23: 5.9618197 | AF23: 6.357822 | AG23: -0.0048039188
B24: EPS y/y % | D24: =IFERROR(D23/C23-1,"") -> -0.016640312 | E24: =IFERROR(E23/D23-1,"") -> 0.086934221 | F24: =IFERROR(F23/E23-1,"") -> 0.13730634 | G24: =IFERROR(G23/F23-1,"") -> 0.14150539 | H24: =IFERROR(H23/G23-1,"") -> 0.15618536 | N24: EPS y/y % | P24: 0.01483979 | Q24: 0.2460842 | R24: 0.20287332 | S24: 0.21736514 | T24: 0.25308597 | Z24: EPS y/y % | AB24: -0.045751714 | AC24: -0.12672053 | AD24: 0.038686314 | AE24: 0.057583601 | AF24: 0.066423072
B26: P / E (x) — assumed (adjusted EPS) | G26: 13 | H26: 13 | N26: P / E (x) — assumed (adjusted EPS) | S26: 15 | T26: 15 | Z26: P / E (x) — assumed (adjusted EPS) | AD26: 10 | AE26: 10 | AF26: 10
B27: Price Target ($) | G27: =G26*G23 -> 117.48422 | H27: =H26*H23 -> 135.83353 | N27: Price Target ($) | S27: =S26*S23 -> 180.90142 | T27: =T26*T23 -> 226.68503 | Z27: Price Target ($) | AD27: =AD26*AD23 -> 56.372089 | AE27: =AE26*AE23 -> 59.618197 | AF27: =AF26*AF23 -> 63.57822
B28: Upside / (Downside) vs current | G28: =IFERROR(G27/$K$2-1,"") -> 0.56645621 | H28: =IFERROR(H27/$K$2-1,"") -> 0.81111374 | N28: Upside / (Downside) vs current | S28: =IFERROR(S27/$K$2-1,"") -> 1.4120189 | T28: =IFERROR(T27/$K$2-1,"") -> 2.0224671 | Z28: Upside / (Downside) vs current | AD28: =IFERROR(AD27/$K$2-1,"") -> -0.24837215 | AE28: =IFERROR(AE27/$K$2-1,"") -> -0.20509071 | AF28: =IFERROR(AF27/$K$2-1,"") -> -0.1522904
B29: IRR (to 31-Mar of Y-1) | G29: =IFERROR((G27/$K$2)^(1/((DATE(2030-1,3,31)-$K$3)/365.25))-1,"") -> 0.19954496 | H29: =IFERROR((H27/$K$2)^(1/((DATE(2031-1,3,31)-$K$3)/365.25))-1,"") -> 0.18691379 | N29: IRR (to 31-Mar of Y-1) | S29: =IFERROR((S27/$K$2)^(1/((DATE(2030-1,3,31)-$K$3)/365.25))-1,"") -> 0.42892884 | T29: =IFERROR((T27/$K$2)^(1/((DATE(2031-1,3,31)-$K$3)/365.25))-1,"") -> 0.37590272 | Z29: IRR (to 31-Mar of Y-1) | AD29: =IFERROR((AD27/$K$2)^(1/((DATE(2029-1,3,31)-$K$3)/365.25))-1,"") -> -0.17680293 | AE29: =IFERROR((AE27/$K$2)^(1/((DATE(2030-1,3,31)-$K$3)/365.25))-1,"") -> -0.088848809 | AF29: =IFERROR((AF27/$K$2)^(1/((DATE(2031-1,3,31)-$K$3)/365.25))-1,"") -> -0.04654812
B31: Free Cash Flow | C31: =Model!AK252 -> 951 | D31: =Model!AP252 -> 875 | E31: =Model!AQ252 -> 902.20964 | F31: =Model!AR252 -> 943.66475 | G31: =Model!AS252 -> 991.83763 | H31: =Model!AT252 -> 1047.6961 | I31: =IFERROR((H31/C31)^(1/5)-1,"n/m") -> 0.019555709 | N31: Free Cash Flow | O31: 951 | P31: 925 | Q31: 989.53854 | R31: 1041.4929 | S31: 1128.4813 | T31: 1227.3309 | U31: 0.052340375 | Z31: Free Cash Flow | AA31: 951 | AB31: 825 | AC31: 774.81034 | AD31: 791.71879 | AE31: 808.20516 | AF31: 821.98379 | AG31: -0.028737664
B32: FCF % | C32: =IFERROR(C31/C9,"") -> 0.084782027 | D32: =IFERROR(D31/D9,"") -> 0.075699957 | E32: =IFERROR(E31/E9,"") -> 0.075685952 | F32: =IFERROR(F31/F9,"") -> 0.075645704 | G32: =IFERROR(G31/G9,"") -> 0.075663517 | H32: =IFERROR(H31/H9,"") -> 0.075934558 | J32: =IFERROR(AVERAGE(Model!C256,Model!D256,Model!E256,Model!F256,Model!G256,Model!H256,Model!I256,Model!J256,Model!K256,Model!L256,Model!Q256,Model!V256,Model!AA256,Model!AF256,Model!AK256),"") -> 0.0587511 | K32: =IFERROR(MIN(Model!C256,Model!D256,Model!E256,Model!F256,Model!G256,Model!H256,Model!I256,Model!J256,Model!K256,Model!L256,Model!Q256,Model!V256,Model!AA256,Model!AF256,Model!AK256),"") -> 0.018021091 | L32: =IFERROR(MAX(Model!C256,Model!D256,Model!E256,Model!F256,Model!G256,Model!H256,Model!I256,Model!J256,Model!K256,Model!L256,Model!Q256,Model!V256,Model!AA256,Model!AF256,Model!AK256),"") -> 0.084782027 | N32: FCF % | O32: 0.084782027 | P32: 0.078331472 | Q32: 0.079069797 | R32: 0.077250719 | S32: 0.077453209 | T32: 0.077877375 | V32: 0.0587511 | W32: 0.018021091 | X32: 0.084782027 | Z32: FCF % | AA32: 0.084782027 | AB32: 0.072952094 | AC32: 0.068873026 | AD32: 0.069889136 | AE32: 0.070530826 | AF32: 0.07077179 | AH32: 0.0587511 | AI32: 0.018021091 | AJ32: 0.084782027
B33: FCF / share ($) | C33: =IFERROR(C31/C21,"") -> 7.7711855 | D33: =IFERROR(D31/D21,"") -> 7.2977849 | E33: =IFERROR(E31/E21,"") -> 7.8445198 | F33: =IFERROR(F31/F21,"") -> 8.8249619 | G33: =IFERROR(G31/G21,"") -> 10.031713 | H33: =IFERROR(H31/H21,"") -> 11.571498 | N33: FCF / share ($) | O33: 7.7711855 | P33: 7.7633629 | Q33: 9.0691536 | R33: 10.833754 | S33: 13.156848 | T33: 16.469828 | Z33: FCF / share ($) | AA33: 7.7711855 | AB33: 6.8521939 | AC33: 6.3998163 | AD33: 6.5458362 | AE33: 6.8680949 | AF33: 7.2940519
B34: FCF Yield (on PT) | F34: =IFERROR(F33/F$27,"") | G34: =IFERROR(G33/G$27,"") -> 0.085387748 | H34: =IFERROR(H33/H$27,"") -> 0.085188815 | N34: FCF Yield (on PT) | R34: =IFERROR(R33/R$27,"") | S34: =IFERROR(S33/S$27,"") -> 0.072729383 | T34: =IFERROR(T33/T$27,"") -> 0.072655119 | Z34: FCF Yield (on PT) | AD34: =IFERROR(AD33/AD$27,"") -> 0.11611839 | AE34: =IFERROR(AE33/AE$27,"") -> 0.11520132 | AF34: =IFERROR(AF33/AF$27,"") -> 0.11472564
B35: Adjusted EBITDA (leverage basis) | C35: =Model!AK174 -> 1229 | D35: =Model!AP174 -> 1292.1978 | E35: =Model!AQ174 -> 1363.955 | F35: =Model!AR174 -> 1443.0786 | G35: =Model!AS174 -> 1531.8261 | H35: =Model!AT174 -> 1627.7171 | I35: =IFERROR((H35/C35)^(1/5)-1,"n/m") -> 0.057804503 | N35: Adjusted EBITDA (leverage basis) | O35: 1229 | P35: 1317.1978 | Q35: 1499.6585 | R35: 1633.3295 | S35: 1783.035 | T35: 1946.9752 | U35: 0.096381517 | Z35: Adjusted EBITDA (leverage basis) | AA35: 1229 | AB35: 1267.1978 | AC35: 1170.2102 | AD35: 1190.9172 | AE35: 1216.5866 | AF35: 1244.67 | AG35: 0.0025371406
B36: Adjusted EBITDA % of revenue | C36: =IFERROR(C35/C9,"") -> 0.10956584 | D36: =IFERROR(D35/D9,"") -> 0.11179351 | E36: =IFERROR(E35/E9,"") -> 0.11442156 | F36: =IFERROR(F35/F9,"") -> 0.11567953 | G36: =IFERROR(G35/G9,"") -> 0.11685718 | H36: =IFERROR(H35/H9,"") -> 0.11797313 | J36: =IFERROR(AVERAGE(Model!C221,Model!D221,Model!E221,Model!F221,Model!G221,Model!H221,Model!I221,Model!J221,Model!K221,Model!L221,Model!Q221,Model!V221,Model!AA221,Model!AF221,Model!AK221),"") -> 0.10092471 | K36: =IFERROR(MIN(Model!C221,Model!D221,Model!E221,Model!F221,Model!G221,Model!H221,Model!I221,Model!J221,Model!K221,Model!L221,Model!Q221,Model!V221,Model!AA221,Model!AF221,Model!AK221),"") -> 0.083297805 | L36: =IFERROR(MAX(Model!C221,Model!D221,Model!E221,Model!F221,Model!G221,Model!H221,Model!I221,Model!J221,Model!K221,Model!L221,Model!Q221,Model!V221,Model!AA221,Model!AF221,Model!AK221),"") -> 0.11178366 | N36: Adjusted EBITDA % of revenue | O36: 0.10956584 | P36: 0.11154383 | Q36: 0.1198313 | R36: 0.12114905 | S36: 0.12237844 | T36: 0.12354069 | V36: 0.10092471 | W36: 0.083297805 | X36: 0.11178366 | Z36: Adjusted EBITDA % of revenue | AA36: 0.10956584 | AB36: 0.11205422 | AC36: 0.10402019 | AD36: 0.10512846 | AE36: 0.10616965 | AF36: 0.10716455 | AH36: 0.10092471 | AI36: 0.083297805 | AJ36: 0.11178366
B38: Net Debt | C38: =Model!AK380 -> 3212 | D38: =Model!AP380 -> 3833.6641 | E38: =Model!AQ380 -> 4091.8649 | F38: =Model!AR380 -> 4329.2358 | G38: =Model!AS380 -> 4595.4782 | H38: =Model!AT380 -> 4883.1514 | N38: Net Debt | O38: 3212 | P38: 3931.8941 | Q38: 4873.89 | R38: 5308.3208 | S38: 5794.8637 | T38: 6327.6693 | Z38: Net Debt | AA38: 3212 | AB38: 3784.8441 | AC38: 3265.7701 | AD38: 2977.293 | AE38: 3041.4664 | AF38: 3111.6751
B39: Net Debt / Adjusted EBITDA (x) | C39: =IFERROR(C38/C35,"") -> 2.6135069 | D39: =IFERROR(D38/D35,"") -> 2.9667781 | E39: =IFERROR(E38/E35,"") -> 3 | F39: =IFERROR(F38/F35,"") -> 3 | G39: =IFERROR(G38/G35,"") -> 3 | H39: =IFERROR(H38/H35,"") -> 3 | N39: Net Debt / Adjusted EBITDA (x) | O39: 2.6135069 | P39: 2.9850446 | Q39: 3.25 | R39: 3.25 | S39: 3.25 | T39: 3.25 | Z39: Net Debt / Adjusted EBITDA (x) | AA39: 2.6135069 | AB39: 2.9867824 | AC39: 2.7907551 | AD39: 2.5 | AE39: 2.5 | AF39: 2.5
B40: Share repurchases ($m; FY2027E = Q2–Q4) | D40: =Model!AP266 -> 150 | E40: =Model!AQ266 -> 758.00954 | F40: =Model!AR266 -> 782.65554 | G40: =Model!AS266 -> 864.34374 | H40: =Model!AT266 -> 948.76268 | N40: Share repurchases ($m; FY2027E = Q2–Q4) | P40: 300 | Q40: 1384.1367 | R40: 953.5361 | S40: 1104.4335 | T40: 1266.4499 | AB40: 50 | AC40: 0 | AD40: 226.2791 | AE40: 580.13241 | AF40: 594.94882
B41: Implied avg buyback price ($) | D41: =Model!AP265 -> 75 | E41: =Model!AQ265 -> 80.25 | F41: =Model!AR265 -> 85.8675 | G41: =Model!AS265 -> 91.878225 | H41: =Model!AT265 -> 98.309701 | N41: Implied avg buyback price ($) | P41: 75 | Q41: 80.25 | R41: 85.8675 | S41: 91.878225 | T41: 98.309701 | AB41: 75 | AC41: 80.25 | AD41: 85.8675 | AE41: 91.878225 | AF41: 98.309701
B42: Shares repurchased (m) | D42: =Model!AP267 -> 2 | E42: =Model!AQ267 -> 9.4456017 | F42: =Model!AR267 -> 9.1146887 | G42: =Model!AS267 -> 9.4074928 | H42: =Model!AT267 -> 9.6507534 | N42: Shares repurchased (m) | P42: 4 | Q42: 17.24781 | R42: 11.104738 | S42: 12.020623 | T42: 12.882247 | AB42: 0.66666667 | AC42: 0 | AD42: 2.6352124 | AE42: 6.3141447 | AF42: 6.0517814
B44: ROIC | C44: =Model!AK363 -> 0.21026047 | D44: =Model!AP363 -> 0.16270146 | E44: =Model!AQ363 -> 0.16861988 | F44: =Model!AR363 -> 0.17710557 | G44: =Model!AS363 -> 0.1864314 | H44: =Model!AT363 -> 0.19610118 | J44: =IFERROR(AVERAGE(Model!C363,Model!D363,Model!E363,Model!F363,Model!G363,Model!H363,Model!I363,Model!J363,Model!K363,Model!L363,Model!Q363,Model!V363,Model!AA363,Model!AF363,Model!AK363),"") -> 0.18929918 | K44: =IFERROR(MIN(Model!C363,Model!D363,Model!E363,Model!F363,Model!G363,Model!H363,Model!I363,Model!J363,Model!K363,Model!L363,Model!Q363,Model!V363,Model!AA363,Model!AF363,Model!AK363),"") -> 0.1463063 | L44: =IFERROR(MAX(Model!C363,Model!D363,Model!E363,Model!F363,Model!G363,Model!H363,Model!I363,Model!J363,Model!K363,Model!L363,Model!Q363,Model!V363,Model!AA363,Model!AF363,Model!AK363),"") -> 0.24719915 | N44: ROIC | O44: 0.21026047 | P44: 0.1674003 | Q44: 0.18258317 | R44: 0.19144967 | S44: 0.20161094 | T44: 0.21259684 | V44: 0.18929918 | W44: 0.1463063 | X44: 0.24719915 | Z44: ROIC | AA44: 0.21026047 | AB44: 0.15805648 | AC44: 0.14557985 | AD44: 0.15233332 | AE44: 0.15962149 | AF44: 0.1669072 | AH44: 0.18929918 | AI44: 0.1463063 | AJ44: 0.24719915
B45: RONTA | C45: =Model!AK374 -> 0.35373907 | D45: =Model!AP374 -> 0.32454624 | E45: =Model!AQ374 -> 0.36333375 | F45: =Model!AR374 -> 0.3843383 | G45: =Model!AS374 -> 0.40716366 | H45: =Model!AT374 -> 0.43062826 | J45: =IFERROR(AVERAGE(Model!C374,Model!D374,Model!E374,Model!F374,Model!G374,Model!H374,Model!I374,Model!J374,Model!K374,Model!L374,Model!Q374,Model!V374,Model!AA374,Model!AF374,Model!AK374),"") -> 0.39003852 | K45: =IFERROR(MIN(Model!C374,Model!D374,Model!E374,Model!F374,Model!G374,Model!H374,Model!I374,Model!J374,Model!K374,Model!L374,Model!Q374,Model!V374,Model!AA374,Model!AF374,Model!AK374),"") -> 0.23645009 | L45: =IFERROR(MAX(Model!C374,Model!D374,Model!E374,Model!F374,Model!G374,Model!H374,Model!I374,Model!J374,Model!K374,Model!L374,Model!Q374,Model!V374,Model!AA374,Model!AF374,Model!AK374),"") -> 0.54451307 | N45: RONTA | O45: 0.35373907 | P45: 0.34901059 | Q45: 0.40542622 | R45: 0.43696449 | S45: 0.47140146 | T45: 0.50754476 | V45: 0.39003852 | W45: 0.23645009 | X45: 0.54451307 | Z45: RONTA | AA45: 0.35373907 | AB45: 0.30785642 | AC45: 0.23615659 | AD45: 0.22567894 | AE45: 0.24021237 | AF45: 0.25526997 | AH45: 0.39003852 | AI45: 0.23645009 | AJ45: 0.54451307
B47: Implied Market Cap (USDm) | F47: =F27*F21 -> 0 | G47: =G27*G21 -> 11615.69 | H47: =H27*H21 -> 12298.517 | N47: Implied Market Cap (USDm) | R47: =R27*R21 -> 0 | S47: =S27*S21 -> 15516.167 | T47: =T27*T21 -> 16892.56 | Z47: Implied Market Cap (USDm) | AD47: =AD27*AD21 -> 6818.2032 | AE47: =AE27*AE21 -> 7015.5895 | AF47: =AF27*AF21 -> 7164.7786
B48: (+) Net Debt & NCI | F48: =F38+Model!AR297 -> 4329.2358 | G48: =G38+Model!AS297 -> 4595.4782 | H48: =H38+Model!AT297 -> 4883.1514 | N48: (+) Net Debt & NCI | R48: =R38+Model!AR297 -> 5308.3208 | S48: =S38+Model!AS297 -> 5794.8637 | T48: =T38+Model!AT297 -> 6327.6693 | Z48: (+) Net Debt & NCI | AD48: =AD38+Model!AR297 -> 2977.293 | AE48: =AE38+Model!AS297 -> 3041.4664 | AF48: =AF38+Model!AT297 -> 3111.6751
B49: Implied Enterprise Value (USDm) | F49: =F47+F48 -> 4329.2358 | G49: =G47+G48 -> 16211.168 | H49: =H47+H48 -> 17181.668 | N49: Implied Enterprise Value (USDm) | R49: =R47+R48 -> 5308.3208 | S49: =S47+S48 -> 21311.031 | T49: =T47+T48 -> 23220.229 | Z49: Implied Enterprise Value (USDm) | AD49: =AD47+AD48 -> 9795.4962 | AE49: =AE47+AE48 -> 10057.056 | AF49: =AF47+AF48 -> 10276.454
B50: Implied EV / Adjusted EBITDA (x) | F50: =IFERROR(F49/F35,"") -> 3 | G50: =IFERROR(G49/G35,"") -> 10.582904 | H50: =IFERROR(H49/H35,"") -> 10.555684 | N50: Implied EV / Adjusted EBITDA (x) | R50: =IFERROR(R49/R35,"") -> 3.25 | S50: =IFERROR(S49/S35,"") -> 11.95211 | T50: =IFERROR(T49/T35,"") -> 11.92631 | Z50: Implied EV / Adjusted EBITDA (x) | AD50: =IFERROR(AD49/AD35,"") -> 8.2251699 | AE50: =IFERROR(AE49/AE35,"") -> 8.2666176 | AF50: =IFERROR(AF49/AF35,"") -> 8.2563678

Sheet DCF
B2: DCF VALUATION — BOOZ ALLEN HAMILTON HOLDING CORPORATION (BAH)
B4: 1. WACC BUILD
B5: Risk-free rate (US 10Y govt) | C5: 0.0425 | D5: Assumption (~US 10Y Treasury yield, Oct-2026; government rate sources not reachable from the build environment); update to market
B6: Equity risk premium | C6: 0.05 | D6: Assumption: US implied ERP ~4.5–5.5%
B7: Levered beta | C7: 1 | D7: Assumption: government IT / consulting services peers (CACI, SAIC, Leidos, Parsons) ~0.6–1.0; ~98% U.S. government revenue on cost-reimbursable contracts, but Civil budget and procurement-policy risk (FY26 Civil −22%) and the 2025–26 de-rating argue for the top of the range
B8: Cost of equity | C8: =C5+C7*C6 -> 0.0925
B9: Pre-tax cost of debt | C9: 0.0575 | D9: Aug-2026 notes at 5.375% (2030) and 5.900% (2034) (8-K 4-Aug-2026); 2033 / 2035 notes 5.950%; marginal cost ~5.75%
B10: Tax rate | C10: 0.225 | D10: Model FY2028E+ effective tax rate (FY27 guidance 20–23%)
B11: After-tax cost of debt | C11: =C9*(1-C10) -> 0.0445625
B12: Target D/V | C12: 0.3 | D12: Net debt ~$3.9bn at FY2027E YE (post-Ultra) vs ~$9.0bn market cap ($75.00 × ~120m diluted shares); net leverage ~3.0x
B13: WACC | C13: =C8*(1-C12)+C11*C12 -> 0.07811875
B15: Valuation date (live) | C15: =TODAY() -> 2026-10-12 00:00:00 | D15: Periods = (31-Mar of fiscal year − today) / 365.25; cash flows assumed at fiscal year-end (31 March). FY2027E UFCF is excluded from the PV (its cash flows, incl. the $720m Ultra payment, are in the FY2027E year-end net debt deducted below); explicit years FY2028E–31E.
B16: 2. UNLEVERED FREE CASH FLOW BUILD (USDm)
D17: 2027E | E17: 2028E | F17: 2029E | G17: 2030E | H17: 2031E | I17: 2032E | J17: 2033E | K17: 2034E | L17: 2035E | M17: 2036E | N17: Terminal | P17: CAGR 28–31E | Q17: CAGR 28–36E
B18: Adj. EBITA (before acquisition amortization) less acquisition, restructuring, legal & financing costs | D18: =Model!AP181-Model!AP184 -> 1147.1978 | E18: =Model!AQ181-Model!AQ184 -> 1240.2506 | F18: =Model!AR181-Model!AR184 -> 1313.8306 | G18: =Model!AS181-Model!AS184 -> 1396.2407 | H18: =Model!AT181-Model!AT184 -> 1485.2436 | I18: =H18*(1+I$26) -> 1552.0796 | J18: =I18*(1+J$26) -> 1616.1028 | K18: =J18*(1+K$26) -> 1676.7067 | L18: =K18*(1+L$26) -> 1733.2955 | M18: =L18*(1+M$26) -> 1785.2944 | P18: =(H18/D18)^(1/(COLUMNS(D18:H18)-1))-1 -> 0.066693983 | Q18: =(M18/D18)^(1/(COLUMNS(D18:M18)-1))-1 -> 0.050367516
B19: × (1 − tax rate) | D19: =1-$C$10 -> 0.775 | E19: =1-$C$10 -> 0.775 | F19: =1-$C$10 -> 0.775 | G19: =1-$C$10 -> 0.775 | H19: =1-$C$10 -> 0.775 | I19: =1-$C$10 -> 0.775 | J19: =1-$C$10 -> 0.775 | K19: =1-$C$10 -> 0.775 | ... M19: =1-$C$10 -> 0.775
B20: NOPAT | D20: =D18*D19 -> 889.0783 | E20: =E18*E19 -> 961.19421 | F20: =F18*F19 -> 1018.2187 | G20: =G18*G19 -> 1082.0866 | H20: =H18*H19 -> 1151.0638 | I20: =I18*I19 -> 1202.8617 | J20: =J18*J19 -> 1252.4797 | K20: =K18*K19 -> 1299.4477 | ... M20: =M18*M19 -> 1383.6032
B21: plus depreciation & other amortization (acquisition amortization is outside the NOPAT basis) | D21: =Model!AP104 -> 120 | E21: =Model!AQ104 -> 119.20437 | F21: =Model!AR104 -> 124.74796 | G21: =Model!AS104 -> 131.08532 | H21: =Model!AT104 -> 137.97355 | I21: =H21*(1+I$26) -> 144.18236 | J21: =I21*(1+J$26) -> 150.12989 | K21: =J21*(1+K$26) -> 155.75976 | L21: =K21*(1+L$26) -> 161.01665 | M21: =L21*(1+M$26) -> 165.84715
B22: − Capex and acquisitions (Ultra in FY2027E; M&A lever 2028E–31E) | D22: =Model!AP236+Model!AP237 -> -1160 | E22: =Model!AQ236+Model!AQ237 -> -257.28393 | F22: =Model!AR236+Model!AR237 -> -262.27317 | G22: =Model!AS236+Model!AS237 -> -267.97679 | H22: =Model!AT236+Model!AT237 -> -274.1762 | I22: =Model!AT236*(1+I$26) -> -129.76413 | J22: =I22*(1+J$26) -> -135.1169 | K22: =J22*(1+K$26) -> -140.18378 | L22: =K22*(1+L$26) -> -144.91498 | M22: =L22*(1+M$26) -> -149.26243
B23: − Δ Working capital (CF statement) | D23: =Model!AP234 -> 121.99231 | E23: =Model!AQ234 -> -15.894303 | F23: =Model!AR234 -> -24.364028 | G23: =Model!AS234 -> -27.852619 | H23: =Model!AT234 -> -30.273719 | I23: =H23*(1+I$26) -> -31.636036 | J23: =I23*(1+J$26) -> -32.941023 | K23: =J23*(1+K$26) -> -34.176311 | L23: =K23*(1+L$26) -> -35.329762 | M23: =L23*(1+M$26) -> -36.389655
B24: Unlevered FCF | D24: =D20+D21+D22+D23 -> -28.929396 | E24: =E20+E21+E22+E23 -> 807.22034 | F24: =F20+F21+F22+F23 -> 856.3295 | G24: =G20+G21+G22+G23 -> 917.34248 | H24: =H20+H21+H22+H23 -> 984.58742 | I24: =I20+I21+I22+I23 -> 1185.6439 | J24: =J20+J21+J22+J23 -> 1234.5517 | K24: =K20+K21+K22+K23 -> 1280.8474 | ... M24: =M20+M21+M22+M23 -> 1363.7982 | N24: =M24*(1+$C$27) -> 1397.8932 | P24: =IFERROR((H24/E24)^(1/(COLUMNS(E24:H24)-1))-1,"n/m") -> 0.068449652 | Q24: =IFERROR((M24/E24)^(1/(COLUMNS(E24:M24)-1))-1,"n/m") -> 0.067750425
B25: Terminal Value (Gordon Growth) | N25: =N24/($C$13-$C$27) -> 26316.38
B26: Fade-period growth (2032E–36E; 4.5% → 3.0% linear) | I26: 0.045 | J26: =I26+($M$26-$I$26)/4 -> 0.04125 | K26: =J26+($M$26-$I$26)/4 -> 0.0375 | L26: =K26+($M$26-$I$26)/4 -> 0.03375 | M26: 0.03
B27: Terminal growth rate | C27: 0.025
B29: Discount period (years) | D29: =(DATE(2027,3,31)-$C$15)/365.25 -> 0.46543463 | E29: =(DATE(2028,3,31)-$C$15)/365.25 -> 1.467488 | F29: =(DATE(2029,3,31)-$C$15)/365.25 -> 2.4668036 | G29: =(DATE(2030,3,31)-$C$15)/365.25 -> 3.4661191 | H29: =(DATE(2031,3,31)-$C$15)/365.25 -> 4.4654346 | I29: =(DATE(2032,3,31)-$C$15)/365.25 -> 5.467488 | J29: =(DATE(2033,3,31)-$C$15)/365.25 -> 6.4668036 | K29: =(DATE(2034,3,31)-$C$15)/365.25 -> 7.4661191 | L29: =(DATE(2035,3,31)-$C$15)/365.25 -> 8.4654346 | M29: =(DATE(2036,3,31)-$C$15)/365.25 -> 9.467488 | N29: =M29 -> 9.467488
B30: Discount factor | D30: =1/(1+$C$13)^D29 -> 0.96559683 | E30: =1/(1+$C$13)^E29 -> 0.89549292 | F30: =1/(1+$C$13)^F29 -> 0.83064971 | G30: =1/(1+$C$13)^G29 -> 0.77050183 | H30: =1/(1+$C$13)^H29 -> 0.71470931 | I30: =1/(1+$C$13)^I29 -> 0.66282024 | J30: =1/(1+$C$13)^J29 -> 0.614825 | K30: =1/(1+$C$13)^K29 -> 0.57030513 | ... N30: =1/(1+$C$13)^N29 -> 0.49060206
B31: PV of UFCF | D31: =0*D24*D30 -> 0 | E31: =E24*E30 -> 722.8601 | F31: =F24*F30 -> 711.30985 | G31: =G24*G30 -> 706.81406 | H31: =H24*H30 -> 703.69379 | I31: =I24*I30 -> 785.86874 | J31: =J24*J30 -> 759.03323 | K31: =K24*K30 -> 730.47382 | L31: =L24*L30 -> 700.44806 | M31: =M24*M30 -> 669.08222 | N31: =N25*N30 -> 12910.87
D32: Booz Allen's adjusted EBITDA expenses stock-based compensation (not adjusted out since FY2016). NOPAT is taxed on adjusted EBITA (before acquisition amortization, which is non-cash and excluded) less the cash items the company adjusts out (other corporate / acquisition costs, restructuring, legal matters, financing costs); row 21 adds back depreciation & other amortization only. FY2027E (column D) is shown but not discounted: its cash flows, including the $720m Ultra acquisition, are already in the FY2027E year-end net debt. Row 22 includes bolt-on acquisitions in FY2028E–31E; the fade period and terminal value assume no new acquisitions. Operating leases are treated as operating costs (not in net debt).
B33: IMPLIED ROIC — invested capital roll-forward (USDm)
B34: Opening invested capital | D34: =Model!AK360 -> 4317 | E34: =D38 -> 5235.0077 | F34: =E38 -> 5388.9816 | G34: =F38 -> 5550.8708 | H34: =G38 -> 5715.6149 | I34: =H38 -> 5882.0912 | J34: =I38 -> 5899.309 | K34: =J38 -> 5917.2371 | L34: =K38 -> 5935.8374 | M34: =L38 -> 5955.0655
B35: plus Capex and acquisitions | D35: =-D22 -> 1160 | E35: =-E22 -> 257.28393 | F35: =-F22 -> 262.27317 | G35: =-G22 -> 267.97679 | H35: =-H22 -> 274.1762 | I35: =-I22 -> 129.76413 | J35: =-J22 -> 135.1169 | K35: =-K22 -> 140.18378 | ... M35: =-M22 -> 149.26243
B36: less DD&A | D36: =-D21 -> -120 | E36: =-E21 -> -119.20437 | F36: =-F21 -> -124.74796 | G36: =-G21 -> -131.08532 | H36: =-H21 -> -137.97355 | I36: =-I21 -> -144.18236 | J36: =-J21 -> -150.12989 | K36: =-K21 -> -155.75976 | ... M36: =-M21 -> -165.84715
B37: plus Δ Working capital investment | D37: =-D23 -> -121.99231 | E37: =-E23 -> 15.894303 | F37: =-F23 -> 24.364028 | G37: =-G23 -> 27.852619 | H37: =-H23 -> 30.273719 | I37: =-I23 -> 31.636036 | J37: =-J23 -> 32.941023 | K37: =-K23 -> 34.176311 | ... M37: =-M23 -> 36.389655
B38: Closing invested capital | D38: =SUM(D34:D37) -> 5235.0077 | E38: =SUM(E34:E37) -> 5388.9816 | F38: =SUM(F34:F37) -> 5550.8708 | G38: =SUM(G34:G37) -> 5715.6149 | H38: =SUM(H34:H37) -> 5882.0912 | I38: =SUM(I34:I37) -> 5899.309 | J38: =SUM(J34:J37) -> 5917.2371 | K38: =SUM(K34:K37) -> 5935.8374 | ... M38: =SUM(M34:M37) -> 5974.8704
B39: NOPAT (row 20) | D39: =D20 -> 889.0783 | E39: =E20 -> 961.19421 | F39: =F20 -> 1018.2187 | G39: =G20 -> 1082.0866 | H39: =H20 -> 1151.0638 | I39: =I20 -> 1202.8617 | J39: =J20 -> 1252.4797 | K39: =K20 -> 1299.4477 | ... M39: =M20 -> 1383.6032
B40: Implied ROIC (NOPAT / avg. invested capital) | D40: =IFERROR(D39/AVERAGE(D34,D38),"") -> 0.18615527 | E40: =IFERROR(E39/AVERAGE(E34,E38),"") -> 0.18094789 | F40: =IFERROR(F39/AVERAGE(F34,F38),"") -> 0.18614853 | G40: =IFERROR(G39/AVERAGE(G34,G38),"") -> 0.19208946 | H40: =IFERROR(H39/AVERAGE(H34,H38),"") -> 0.19849853 | I40: =IFERROR(I39/AVERAGE(I34,I38),"") -> 0.20419672 | J40: =IFERROR(J39/AVERAGE(J34,J38),"") -> 0.21198744 | K40: =IFERROR(K39/AVERAGE(K34,K38),"") -> 0.21925918 | ... M40: =IFERROR(M39/AVERAGE(M34,M38),"") -> 0.23195484
B41: Reinvestment rate (net investment / NOPAT) | D41: =IFERROR(SUM(D35:D37)/D39,"") -> 1.0325386 | E41: =IFERROR(SUM(E35:E37)/E39,"") -> 0.16019017 | F41: =IFERROR(SUM(F35:F37)/F39,"") -> 0.15899259 | G41: =IFERROR(SUM(G35:G37)/G39,"") -> 0.15224668 | H41: =IFERROR(SUM(H35:H37)/H39,"") -> 0.14462827 | I41: =IFERROR(SUM(I35:I37)/I39,"") -> 0.014314032 | J41: =IFERROR(SUM(J35:J37)/J39,"") -> 0.014314032 | K41: =IFERROR(SUM(K35:K37)/K39,"") -> 0.014314032 | ... M41: =IFERROR(SUM(M35:M37)/M39,"") -> 0.014314032
B42: Implied terminal RONIC (g / reinvestment rate) | N42: =IFERROR($C$27/M41,"") -> 1.746538
D43: Opening IC = Model FY2026A book IC (equity + net debt), rolled forward with capex + acquisitions (incl. Ultra in FY2027E) − depreciation + ΔWC.
B44: 3. VALUATION SUMMARY
...

Sheet Charts
B2: Booz Allen Hamilton — Operating Performance (FY2012–FY2026) and Model Forecast (FY2027E–FY2031E)
B3: USDm · fiscal years ended 31 March · Linked to Model. Bars = contribution to revenue growth (pp): National Security (Defense + Intelligence) vs Civil & Commercial, Ultra and other (customer split published from FY2017; earlier years shown as other). Adjusted EBITDA = company definition. ROIC / RONTA on adjusted EBIT (full-cost).
C7: 2012 | D7: 2013 | E7: 2014 | F7: 2015 | G7: 2016 | H7: 2017 | I7: 2018 | J7: 2019 | K7: 2020 | L7: 2021 | M7: 2022 | N7: 2023 | O7: 2024 | P7: 2025 | Q7: 2026 | R7: 2027E | S7: 2028E | T7: 2029E | U7: 2030E | V7: 2031E
B8: National Security contribution (pp) | C8: 0 | D8: =IF(AND(ISNUMBER(Model!D11),ISNUMBER(Model!C11)),IFERROR((Model!D11-Model!C11)/Model!C120,0),0) -> 0 | E8: =IF(AND(ISNUMBER(Model!E11),ISNUMBER(Model!D11)),IFERROR((Model!E11-Model!D11)/Model!D120,0),0) -> 0 | F8: =IF(AND(ISNUMBER(Model!F11),ISNUMBER(Model!E11)),IFERROR((Model!F11-Model!E11)/Model!E120,0),0) -> 0 | G8: =IF(AND(ISNUMBER(Model!G11),ISNUMBER(Model!F11)),IFERROR((Model!G11-Model!F11)/Model!F120,0),0) -> 0 | H8: =IF(AND(ISNUMBER(Model!H11),ISNUMBER(Model!G11)),IFERROR((Model!H11-Model!G11)/Model!G120,0),0) -> 0 | I8: =IF(AND(ISNUMBER(Model!I11),ISNUMBER(Model!H11)),IFERROR((Model!I11-Model!H11)/Model!H120,0),0) -> 0.048309318 | J8: =IF(AND(ISNUMBER(Model!J11),ISNUMBER(Model!I11)),IFERROR((Model!J11-Model!I11)/Model!I120,0),0) -> 0.05781894 | K8: =IF(AND(ISNUMBER(Model!K11),ISNUMBER(Model!J11)),IFERROR((Model!K11-Model!J11)/Model!J120,0),0) -> 0.074810595 | L8: =IF(AND(ISNUMBER(Model!L11),ISNUMBER(Model!K11)),IFERROR((Model!L11-Model!K11)/Model!K120,0),0) -> 0.038484073 | M8: =IF(AND(ISNUMBER(Model!Q11),ISNUMBER(Model!L11)),IFERROR((Model!Q11-Model!L11)/Model!L120,0),0) -> 0.0074179234 | N8: =IF(AND(ISNUMBER(Model!V11),ISNUMBER(Model!Q11)),IFERROR((Model!V11-Model!Q11)/Model!Q120,0),0) -> 0.04493968 | O8: =IF(AND(ISNUMBER(Model!AA11),ISNUMBER(Model!V11)),IFERROR((Model!AA11-Model!V11)/Model!V120,0),0) -> 0.099991457 | P8: =IF(AND(ISNUMBER(Model!AF11),ISNUMBER(Model!AA11)),IFERROR((Model!AF11-Model!AA11)/Model!AA120,0),0) -> 0.091898852 | Q8: =IF(AND(ISNUMBER(Model!AK11),ISNUMBER(Model!AF11)),IFERROR((Model!AK11-Model!AF11)/Model!AF120,0),0) -> 0.01327212 | R8: =IF(AND(ISNUMBER(Model!AP11),ISNUMBER(Model!AK11)),IFERROR((Model!AP11-Model!AK11)/Model!AK120,0),0) -> 0.051726366 | S8: =IF(AND(ISNUMBER(Model!AQ11),ISNUMBER(Model!AP11)),IFERROR((Model!AQ11-Model!AP11)/Model!AP120,0),0) -> 0.029585151 | T8: =IF(AND(ISNUMBER(Model!AR11),ISNUMBER(Model!AQ11)),IFERROR((Model!AR11-Model!AQ11)/Model!AQ120,0),0) -> 0.037293864 | U8: =IF(AND(ISNUMBER(Model!AS11),ISNUMBER(Model!AR11)),IFERROR((Model!AS11-Model!AR11)/Model!AR120,0),0) -> 0.037418416 | V8: =IF(AND(ISNUMBER(Model!AT11),ISNUMBER(Model!AS11)),IFERROR((Model!AT11-Model!AS11)/Model!AS120,0),0) -> 0.037389883
B9: Civil & Commercial, Ultra & other (pp) | C9: 0 | D9: =IFERROR(Model!D213-D8,0) -> -0.017264932 | E9: =IFERROR(Model!E213-E8,0) -> -0.048517391 | F9: =IFERROR(Model!F213-F8,0) -> -0.037221104 | G9: =IFERROR(Model!G213-G8,0) -> 0.024829139 | H9: =IFERROR(Model!H213-H8,0) -> 0.073726474 | I9: =IFERROR(Model!I213-I8,0) -> 0.015017873 | J9: =IFERROR(Model!J213-J8,0) -> 0.028408648 | K9: =IFERROR(Model!K213-K8,0) -> 0.038524698 | L9: =IFERROR(Model!L213-L8,0) -> 0.014450737 | M9: =IFERROR(Model!Q213-M8,0) -> 0.056809839 | N9: =IFERROR(Model!V213-N8,0) -> 0.062095604 | O9: =IFERROR(Model!AA213-O8,0) -> 0.051536622 | P9: =IFERROR(Model!AF213-P8,0) -> 0.031728691 | Q9: =IFERROR(Model!AK213-Q8,0) -> -0.076961603 | R9: =IFERROR(Model!AP213-R8,0) -> -0.021255544 | S9: =IFERROR(Model!AQ213-S8,0) -> 0.0017023733 | T9: =IFERROR(Model!AR213-T8,0) -> 0.0092110716 | U9: =IFERROR(Model!AS213-U8,0) -> 0.01338287 | V9: =IFERROR(Model!AT213-V8,0) -> 0.015157833
C11: =C7 -> 2012 | D11: =D7 -> 2013 | E11: =E7 -> 2014 | F11: =F7 -> 2015 | G11: =G7 -> 2016 | H11: =H7 -> 2017 | I11: =I7 -> 2018 | J11: =J7 -> 2019 | ... V11: =V7 -> 2031E
