Workbook

Sheet Model
BC1: SCENARIO SWITCH ▼ (Bull / Base / Bear) — drives all scenario-linked forecast drivers
B2: Brunello Cucinelli S.p.A. (Euronext Milan: BC) — 3-Statement Financial Model | BC2: Base
B3: IFRS as reported · EUR millions (per-share data in EUR; store counts in units) · Source: Brunello Cucinelli annual financial reports (consolidated financial statements) and half-year financial reports 2011–H1/26, Q1 / nine-month interim reports (2012–15) and revenue press releases (2016–26), investor.brunellocucinelli.com (regulated information also filed via eMarket Storage / Borsa Italiana; BC is not an SEC registrant — no EDGAR filings)
B4: Basis notes: calendar fiscal year; full statements published for H1 and FY only (H2 = FY − H1; Q1/Q3 revenue memo). Revenues = net revenues (other operating income shown separately; "revenues from sales and services" to 2016 included it). IPO Apr-2012 (60.0m → 68.0m shares). IFRS 15 from 2018 (2017 as originally reported); IFRS 16 from 1-Jan-2019 (modified retrospective, 2018 not restated) — pre-IFRS 16 bridge provided. Channels: retail / mono-brand wholesale / multi-brand wholesale to 2020, retail / wholesale from 2021. Regions: Italy, Europe, North America, Greater China, RoW to 2020; Italy, Europe, Americas, Asia 2021–24; Europe (incl. Italy), Americas, Asia from 2025.
BE5: Forecast | BF5: Historical | BG5: Historical | BH5: Historical
B6: (EURm) | C6: H1/11 | D6: H2/11 | E6: 2011 | F6: H1/12 | G6: H2/12 | H6: 2012 | I6: H1/13 | J6: H2/13 | K6: 2013 | L6: H1/14 | M6: H2/14 | N6: 2014 | O6: H1/15 | P6: H2/15 | Q6: 2015 | R6: H1/16 | S6: H2/16 | T6: 2016 | U6: H1/17 | V6: H2/17 | W6: 2017 | X6: H1/18 | Y6: H2/18 | Z6: 2018 | AA6: H1/19 | AB6: H2/19 | AC6: 2019 | AD6: H1/20 | AE6: H2/20 | AF6: 2020 | AG6: H1/21 | AH6: H2/21 | AI6: 2021 | AJ6: H1/22 | AK6: H2/22 | AL6: 2022 | AM6: H1/23 | AN6: H2/23 | AO6: 2023 | AP6: H1/24 | AQ6: H2/24 | AR6: 2024 | AS6: H1/25 | AT6: H2/25 | AU6: 2025 | AV6: H1/26 | AW6: H2/26E | AX6: 2026E | AY6: 2027E | AZ6: 2028E | BA6: 2029E | BB6: 2030E | BC6: Modelling Notes | BE6: 5Y CAGR | BF6: 5Y CAGR | BG6: 10Y CAGR | BH6: 14Y CAGR
BE7: 25-'30 | BF7: 20-'25 | BG7: 15-'25 | BH7: 11-'25
B8: REVENUE BUILD — DISTRIBUTION CHANNEL (RETAIL · WHOLESALE) × GEOGRAPHY (EUROPE · AMERICAS · ASIA) | BC8: REVENUE BUILD — modelling logic
BK9: SCENARIO INPUT TABLE — driver assumptions per Bull / Base / Bear | BL9: Bull | BM9: Base | BN9: Bear | BO9: Bull / Bear = Base + Δ (Δ inputs on each block header). Outlook block = company guidance end-points.
B10: Retail channel (directly operated boutiques, concessions / hard shops in luxury department stores, e-commerce) | BC10: RETAIL — modelling logic
B11: Directly operated boutiques (DOS), period end (#) | C11: 21 | D11: =E11 -> 20 | E11: 20 | F11: 30 | G11: =H11 -> 46 | H11: 46 | I11: 54 | J11: =K11 -> 61 | K11: 61 | L11: 65 | M11: =N11 -> 71 | N11: 71 | O11: 79 | P11: =Q11 -> 81 | Q11: 81 | R11: 86 | S11: =T11 -> 86 | T11: 86 | U11: 91 | V11: =W11 -> 94 | W11: 94 | X11: 97 | Y11: =Z11 -> 100 | Z11: 100 | AA11: 102 | AB11: =AC11 -> 106 | AC11: 106 | AD11: 107 | AE11: =AF11 -> 107 | AF11: 107 | AG11: 112 | AH11: =AI11 -> 114 | AI11: 114 | AJ11: 117 | AK11: =AL11 -> 119 | AL11: 119 | AM11: 124 | AN11: =AO11 -> 125 | AO11: 125 | AP11: 126 | AQ11: =AR11 -> 130 | AR11: 130 | AS11: 130 | AT11: =AU11 -> 136 | AU11: 136 | AV11: 141 | AW11: =AX11 -> 143 | AX11: =AU11+AX12 -> 143 | AY11: =AX11+AY12 -> 148 | AZ11: =AY11+AZ12 -> 153 | BA11: =AZ11+BA12 -> 158 | BB11: =BA11+BB12 -> 163 | BC11: 2026E+: prior year-end + net openings (row below). H2/26E column = 31-Dec-26 count. | BK11: FY26 outlook — H1-26 release (30-Jul-26) | BL11: High | BM11: Mid | BN11: Low | BO11: Revenue growth guidance is at constant exchange rates.
B12: Net DOS openings in period (#) | D12: =D11-C11 -> -1 | F12: =F11-E11 -> 10 | G12: =G11-F11 -> 16 | H12: =H11-E11 -> 26 | I12: =I11-H11 -> 8 | J12: =J11-I11 -> 7 | K12: =K11-H11 -> 15 | L12: =L11-K11 -> 4 | M12: =M11-L11 -> 6 | N12: =N11-K11 -> 10 | O12: =O11-N11 -> 8 | P12: =P11-O11 -> 2 | Q12: =Q11-N11 -> 10 | R12: =R11-Q11 -> 5 | S12: =S11-R11 -> 0 | T12: =T11-Q11 -> 5 | U12: =U11-T11 -> 5 | V12: =V11-U11 -> 3 | W12: =W11-T11 -> 8 | X12: =X11-W11 -> 3 | Y12: =Y11-X11 -> 3 | Z12: =Z11-W11 -> 6 | AA12: =AA11-Z11 -> 2 | AB12: =AB11-AA11 -> 4 | AC12: =AC11-Z11 -> 6 | AD12: =AD11-AC11 -> 1 | AE12: =AE11-AD11 -> 0 | AF12: =AF11-AC11 -> 1 | AG12: =AG11-AF11 -> 5 | AH12: =AH11-AG11 -> 2 | AI12: =AI11-AF11 -> 7 | AJ12: =AJ11-AI11 -> 3 | AK12: =AK11-AJ11 -> 2 | AL12: =AL11-AI11 -> 5 | AM12: =AM11-AL11 -> 5 | AN12: =AN11-AM11 -> 1 | AO12: =AO11-AL11 -> 6 | AP12: =AP11-AO11 -> 1 | AQ12: =AQ11-AP11 -> 4 | AR12: =AR11-AO11 -> 5 | AS12: =AS11-AR11 -> 0 | AT12: =AT11-AS11 -> 6 | AU12: =AU11-AR11 -> 6 | AV12: =AV11-AU11 -> 5 | AW12: =AW11-AV11 -> 2 | AX12: 7 | AY12: 5 | AZ12: 5 | BA12: 5 | BB12: 5 | BC12: Net DOS openings: 2025 +6 (130→136), H1/26 +5 (141). 2026E +7 for the year; 2027E–30E +5 p.a. (selective openings and enlargements; Base, scenario-neutral input). | BK12: FY26 revenue growth at constant FX | BL12: 0.11 | BM12: 0.105 | BN12: 0.1 | BO12: Raised to +10% to +11% (from ~+10%) on 30-Jul-26.
B13: Average DOS in period (#) | D13: =IFERROR(AVERAGE(C11,D11),"") -> 20.5 | F13: =IFERROR(AVERAGE(E11,F11),"") -> 25 | G13: =IFERROR(AVERAGE(F11,G11),"") -> 38 | H13: =IFERROR(AVERAGE(E11,H11),"") -> 33 | I13: =IFERROR(AVERAGE(H11,I11),"") -> 50 | J13: =IFERROR(AVERAGE(I11,J11),"") -> 57.5 | K13: =IFERROR(AVERAGE(H11,K11),"") -> 53.5 | L13: =IFERROR(AVERAGE(K11,L11),"") -> 63 | M13: =IFERROR(AVERAGE(L11,M11),"") -> 68 | N13: =IFERROR(AVERAGE(K11,N11),"") -> 66 | O13: =IFERROR(AVERAGE(N11,O11),"") -> 75 | P13: =IFERROR(AVERAGE(O11,P11),"") -> 80 | Q13: =IFERROR(AVERAGE(N11,Q11),"") -> 76 | R13: =IFERROR(AVERAGE(Q11,R11),"") -> 83.5 | S13: =IFERROR(AVERAGE(R11,S11),"") -> 86 | T13: =IFERROR(AVERAGE(Q11,T11),"") -> 83.5 | U13: =IFERROR(AVERAGE(T11,U11),"") -> 88.5 | V13: =IFERROR(AVERAGE(U11,V11),"") -> 92.5 | W13: =IFERROR(AVERAGE(T11,W11),"") -> 90 | X13: =IFERROR(AVERAGE(W11,X11),"") -> 95.5 | Y13: =IFERROR(AVERAGE(X11,Y11),"") -> 98.5 | Z13: =IFERROR(AVERAGE(W11,Z11),"") -> 97 | AA13: =IFERROR(AVERAGE(Z11,AA11),"") -> 101 | AB13: =IFERROR(AVERAGE(AA11,AB11),"") -> 104 | AC13: =IFERROR(AVERAGE(Z11,AC11),"") -> 103 | AD13: =IFERROR(AVERAGE(AC11,AD11),"") -> 106.5 | AE13: =IFERROR(AVERAGE(AD11,AE11),"") -> 107 | AF13: =IFERROR(AVERAGE(AC11,AF11),"") -> 106.5 | AG13: =IFERROR(AVERAGE(AF11,AG11),"") -> 109.5 | AH13: =IFERROR(AVERAGE(AG11,AH11),"") -> 113 | AI13: =IFERROR(AVERAGE(AF11,AI11),"") -> 110.5 | AJ13: =IFERROR(AVERAGE(AI11,AJ11),"") -> 115.5 | AK13: =IFERROR(AVERAGE(AJ11,AK11),"") -> 118 | AL13: =IFERROR(AVERAGE(AI11,AL11),"") -> 116.5 | AM13: =IFERROR(AVERAGE(AL11,AM11),"") -> 121.5 | AN13: =IFERROR(AVERAGE(AM11,AN11),"") -> 124.5 | AO13: =IFERROR(AVERAGE(AL11,AO11),"") -> 122 | AP13: =IFERROR(AVERAGE(AO11,AP11),"") -> 125.5 | AQ13: =IFERROR(AVERAGE(AP11,AQ11),"") -> 128 | AR13: =IFERROR(AVERAGE(AO11,AR11),"") -> 127.5 | AS13: =IFERROR(AVERAGE(AR11,AS11),"") -> 130 | AT13: =IFERROR(AVERAGE(AS11,AT11),"") -> 133 | AU13: =IFERROR(AVERAGE(AR11,AU11),"") -> 133 | AV13: =IFERROR(AVERAGE(AU11,AV11),"") -> 138.5 | AW13: =IFERROR(AVERAGE(AV11,AW11),"") -> 142 | AX13: =IFERROR(AVERAGE(AU11,AX11),"") -> 139.5 | AY13: =IFERROR(AVERAGE(AX11,AY11),"") -> 145.5 | AZ13: =IFERROR(AVERAGE(AY11,AZ11),"") -> 150.5 | BA13: =IFERROR(AVERAGE(AZ11,BA11),"") -> 155.5 | BB13: =IFERROR(AVERAGE(BA11,BB11),"") -> 160.5 | BK13: 2028 revenue target (EURm; 2024–28 plan, Jan-26) — memo | BL13: 1800 | BM13: 1800 | BN13: 1800 | BO13: "Turnover of approximately €1.8 billion in 2028" (12-Jan-26 / 18-Feb-26 releases).
B14: Retail revenues per average DOS (EURm; half-years not annualised) | C14: =IFERROR(C16/C13,"") | D14: =IFERROR(D16/D13,"") -> 1.6346829 | E14: =IFERROR(E16/E13,"") | F14: =IFERROR(F16/F13,"") -> 1.21576 | G14: =IFERROR(G16/G13,"") -> 1.2251316 | H14: =IFERROR(H16/H13,"") -> 2.3317879 | I14: =IFERROR(I16/I13,"") -> 1.01494 | J14: =IFERROR(J16/J13,"") -> 1.1250957 | ... AX14: =IFERROR(AX16/AX13,"") -> 7.6131936 | AY14: =AX14*(1+AY15) -> 8.1841832 | AZ14: =AY14*(1+AZ15) -> 8.6752341 | BA14: =AZ14*(1+BA15) -> 9.152372 | BB14: =BA14*(1+BB15) -> 9.6099906 | BC14: Sales density incl. e-commerce and hard shops (not separately disclosed). 2027E+: prior year × (1 + scenario lever RET_density: like-for-like + pricing).
B15: Sales density y/y % (like-for-like + price/mix + non-DOS formats) | F15: =IF(AND(ISNUMBER(F14),ISNUMBER(C14)),IFERROR(F14/C14-1,""),"") | G15: =IF(AND(ISNUMBER(G14),ISNUMBER(D14)),IFERROR(G14/D14-1,""),"") -> -0.25053871 | H15: =IF(AND(ISNUMBER(H14),ISNUMBER(E14)),IFERROR(H14/E14-1,""),"") | I15: =IF(AND(ISNUMBER(I14),ISNUMBER(F14)),IFERROR(I14/F14-1,""),"") -> -0.16518063 | J15: =IF(AND(ISNUMBER(J14),ISNUMBER(G14)),IFERROR(J14/G14-1,""),"") -> -0.081653211 | K15: =IF(AND(ISNUMBER(K14),ISNUMBER(H14)),IFERROR(K14/H14-1,""),"") -> -0.074634091 | L15: =IF(AND(ISNUMBER(L14),ISNUMBER(I14)),IFERROR(L14/I14-1,""),"") -> -0.024885668 | M15: =IF(AND(ISNUMBER(M14),ISNUMBER(J14)),IFERROR(M14/J14-1,""),"") -> 0.12586506 | ... AX15: =IF(AND(ISNUMBER(AX14),ISNUMBER(AU14)),IFERROR(AX14/AU14-1,""),"") -> 0.069213443 | AY15: =CHOOSE(MATCH($BC$2,{"Bull","Base","Bear"},0),$BL$16,$BM$16,$BN$16) -> 0.075 | AZ15: =CHOOSE(MATCH($BC$2,{"Bull","Base","Bear"},0),$BL$17,$BM$17,$BN$17) -> 0.06 | BA15: =CHOOSE(MATCH($BC$2,{"Bull","Base","Bear"},0),$BL$18,$BM$18,$BN$18) -> 0.055 | BB15: =CHOOSE(MATCH($BC$2,{"Bull","Base","Bear"},0),$BL$19,$BM$19,$BN$19) -> 0.05 | BC15: 2027E–2030E: scenario lever RET_density (Bull / Base / Bear table →). | BK15: RET_density (retail sales per average DOS y/y) | BL15: 0.02 | BM15: Δ → | BN15: -0.03 | BO15: LFL + pricing + enlargements/e-commerce: 2023 +17%, 2024 +11%, 2025 +6% (per avg DOS); H1/26 retail +19.3% cFX.
B16: Retail revenues | C16: 20.35 | D16: =E16-C16 -> 33.511 | E16: 53.861 | F16: 30.394 | G16: =H16-F16 -> 46.555 | H16: 76.949 | I16: 50.747 | J16: =K16-I16 -> 64.693 | K16: 115.44 | L16: 62.35 | M16: =N16-L16 -> 86.136 | N16: 148.486 | O16: 84.768 | P16: =Q16-O16 -> 108.406 | Q16: 193.174 | R16: 99.555 | S16: =T16-R16 -> 126.665 | T16: 226.22 | U16: 121.121 | V16: =W16-U16 -> 149.433 | W16: 270.554 | X16: 133.92 | Y16: =Z16-X16 -> 162.345 | Z16: 296.265 | AA16: 149.946 | AB16: =AC16-AA16 -> 189.489 | AC16: 339.435 | AD16: 102.517 | AE16: =AF16-AD16 -> 166.256 | AF16: 268.773 | AG16: 165.468 | AH16: =AI16-AG16 -> 254.349 | AI16: 419.817 | AJ16: 243.325 | AK16: =AL16-AJ16 -> 329.995 | AL16: 573.32 | AM16: 344.648 | AN16: =AO16-AM16 -> 402.168 | AO16: 746.816 | AP16: 395.184 | AQ16: =AR16-AP16 -> 456.059 | AR16: 851.243 | AS16: 435.837 | AT16: =AU16-AS16 -> 511.172 | AU16: 947.009 | AV16: 499.765 | AW16: =AT16*(1+AW18+AW66) -> 562.27551 | AX16: =AV16+AW16 -> 1062.0405 | AY16: =AY13*AY14 -> 1190.7986 | AZ16: =AZ13*AZ14 -> 1305.6227 | BA16: =BA13*BA14 -> 1423.1938 | BB16: =BB13*BB14 -> 1542.4035 | BC16: H2/26E: H2/25 × (1 + calibrated constant-FX growth + FX effect). 2027E+: average DOS × sales density. | BE16: =IFERROR(IF(AND(BB16>0,AU16>0),(BB16/AU16)^(1/5)-1,"n/m"),"n/m") -> 0.10247507 | BF16: =IFERROR(IF(AND(AU16>0,AF16>0),(AU16/AF16)^(1/5)-1,"n/m"),"n/m") -> 0.28645232 | BG16: =IFERROR(IF(AND(AU16>0,Q16>0),(AU16/Q16)^(1/10)-1,"n/m"),"n/m") -> 0.1723048 | BH16: =IFERROR(IF(AND(AU16>0,E16>0),(AU16/E16)^(1/14)-1,"n/m"),"n/m") -> 0.22725346 | BK16: 2027E | BL16: =BM16+$BL$15 -> 0.095 | BM16: 0.075 | BN16: =BM16+$BN$15 -> 0.045
B17: Retail revenues y/y % | F17: =IF(AND(ISNUMBER(F16),ISNUMBER(C16)),IFERROR(F16/C16-1,""),"") -> 0.49356265 | G17: =IF(AND(ISNUMBER(G16),ISNUMBER(D16)),IFERROR(G16/D16-1,""),"") -> 0.38924532 | H17: =IF(AND(ISNUMBER(H16),ISNUMBER(E16)),IFERROR(H16/E16-1,""),"") -> 0.42865896 | I17: =IF(AND(ISNUMBER(I16),ISNUMBER(F16)),IFERROR(I16/F16-1,""),"") -> 0.66963874 | J17: =IF(AND(ISNUMBER(J16),ISNUMBER(G16)),IFERROR(J16/G16-1,""),"") -> 0.38960369 | K17: =IF(AND(ISNUMBER(K16),ISNUMBER(H16)),IFERROR(K16/H16-1,""),"") -> 0.50021443 | L17: =IF(AND(ISNUMBER(L16),ISNUMBER(I16)),IFERROR(L16/I16-1,""),"") -> 0.22864406 | M17: =IF(AND(ISNUMBER(M16),ISNUMBER(J16)),IFERROR(M16/J16-1,""),"") -> 0.33145781 | ... AX17: =IF(AND(ISNUMBER(AX16),ISNUMBER(AU16)),IFERROR(AX16/AU16-1,""),"") -> 0.12146824 | AY17: =IF(AND(ISNUMBER(AY16),ISNUMBER(AX16)),IFERROR(AY16/AX16-1,""),"") -> 0.12123656 | AZ17: =IF(AND(ISNUMBER(AZ16),ISNUMBER(AY16)),IFERROR(AZ16/AY16-1,""),"") -> 0.096426117 | BA17: =IF(AND(ISNUMBER(BA16),ISNUMBER(AZ16)),IFERROR(BA16/AZ16-1,""),"") -> 0.090049834 | BB17: =IF(AND(ISNUMBER(BB16),ISNUMBER(BA16)),IFERROR(BB16/BA16-1,""),"") -> 0.083762058 | BK17: 2028E | BL17: =BM17+$BL$15 -> 0.08 | BM17: 0.06 | BN17: =BM17+$BN$15 -> 0.03
B18: Retail growth at constant FX (company) % | AU18: 0.129 | AV18: 0.193 | AW18: =AW69+AW71 -> 0.099973222 | AX18: =IFERROR((AS16*(1+AV18)+AT16*(1+AW18))/AU16-1,"") -> 0.14278645 | BC18: Company-reported constant-currency growth (H1 and FY). H2/26E retail: H1/26 trend + outlook calibration Δ; wholesale: H1/26 trend. | BK18: 2029E | BL18: =BM18+$BL$15 -> 0.075 | BM18: 0.055 | BN18: =BM18+$BN$15 -> 0.025
B19: Memo: retail like-for-like growth (company, where disclosed) % | F19: 0.197 | H19: 0.093 | I19: 0.106 | K19: 0.073 | L19: 0.056 | N19: 0.055 | O19: 0.051 | Q19: 0.054 | R19: 0.037 | T19: 0.039 | U19: 0.04 | W19: 0.044 | X19: 0.038 | Z19: 0.035 | AA19: 0.037 | AC19: 0.042 | BK19: 2030E | BL19: =BM19+$BL$15 -> 0.07 | BM19: 0.05 | BN19: =BM19+$BN$15 -> 0.02
B20: Retail % of revenues | C20: =IF(AND(ISNUMBER(C16),ISNUMBER(C111)),IFERROR(C16/C111,""),"") -> 0.17474261 | D20: =IF(AND(ISNUMBER(D16),ISNUMBER(D111)),IFERROR(D16/D111,""),"") -> 0.26558513 | E20: =IF(AND(ISNUMBER(E16),ISNUMBER(E111)),IFERROR(E16/E111,""),"") -> 0.22198364 | F20: =IF(AND(ISNUMBER(F16),ISNUMBER(F111)),IFERROR(F16/F111,""),"") -> 0.2248027 | G20: =IF(AND(ISNUMBER(G16),ISNUMBER(G111)),IFERROR(G16/G111,""),"") -> 0.3230339 | H20: =IF(AND(ISNUMBER(H16),ISNUMBER(H111)),IFERROR(H16/H111,""),"") -> 0.27548591 | I20: =IF(AND(ISNUMBER(I16),ISNUMBER(I111)),IFERROR(I16/I111,""),"") -> 0.32205186 | J20: =IF(AND(ISNUMBER(J16),ISNUMBER(J111)),IFERROR(J16/J111,""),"") -> 0.39230228 | ... BB20: =IF(AND(ISNUMBER(BB16),ISNUMBER(BB111)),IFERROR(BB16/BB111,""),"") -> 0.7315037
B21: Memo: hard shops in luxury department stores, period end (#) | AE21: =AF21 -> 31 | AF21: 31 | AG21: 41 | AH21: =AI21 -> 43 | AI21: 43 | AJ21: 42 | AK21: =AL21 -> 42 | AL21: 42 | AM21: 42 | AN21: =AO21 -> 49 | AO21: 49 | AP21: 49 | AQ21: =AR21 -> 50 | AR21: 50 | AS21: 51 | AT21: =AU21 -> 57 | AU21: 57 | AV21: 59 | BK21: WHS_growth (wholesale revenues y/y) | BL21: 0.02 | BM21: Δ → | BN21: -0.03 | BO21: Selective multi-brand & department stores: FY25 +7.9%, H1/26 +2.7% cFX; SS27 order intake "extremely positive".
BK22: 2027E | BL22: =BM22+$BL$21 -> 0.08 | BM22: 0.06 | BN22: =BM22+$BN$21 -> 0.03
B23: Wholesale channel (mono-brand franchised boutiques, multi-brand specialty stores & department stores, e-tailers) | BC23: WHOLESALE — modelling logic | BK23: 2028E | BL23: =BM23+$BL$21 -> 0.07 | BM23: 0.05 | BN23: =BM23+$BN$21 -> 0.02
B24: Mono-brand wholesale boutiques, period end (#) | C24: 34 | D24: =E24 -> 39 | E24: 39 | F24: 40 | G24: =H24 -> 35 | H24: 35 | I24: 38 | J24: =K24 -> 37 | K24: 37 | L24: 37 | M24: =N24 -> 34 | N24: 34 | O24: 36 | P24: =Q24 -> 36 | Q24: 36 | R24: 36 | S24: =T24 -> 36 | T24: 36 | U24: 32 | V24: =W24 -> 30 | W24: 30 | X24: 29 | Y24: =Z24 -> 27 | Z24: 27 | AA24: 28 | AB24: =AC24 -> 30 | AC24: 30 | AD24: 30 | AE24: =AF24 -> 31 | AF24: 31 | AG24: 31 | AH24: =AI24 -> 30 | AI24: 30 | AJ24: 30 | AK24: =AL24 -> 30 | AL24: 30 | AM24: 27 | AN24: =AO24 -> 27 | AO24: 27 | AP24: 27 | AQ24: =AR24 -> 27 | AR24: 27 | AS24: 27 | AT24: =AU24 -> 28 | AU24: 28 | AV24: 28 | BK24: 2029E | BL24: =BM24+$BL$21 -> 0.065 | BM24: 0.045 | BN24: =BM24+$BN$21 -> 0.015
B25: Wholesale revenues | C25: 96.107 | D25: =E25-C25 -> 92.667 | E25: 188.774 | F25: 104.809 | G25: =H25-F25 -> 97.563 | H25: 202.372 | I25: 106.827 | J25: =K25-I25 -> 100.213 | K25: 207.04 | L25: 113.461 | M25: =N25-L25 -> 93.962 | N25: 207.423 | O25: 115.564 | P25: =Q25-O25 -> 105.413 | Q25: 220.977 | R25: 120.285 | S25: =T25-R25 -> 109.466 | T25: 229.751 | U25: 122.206 | V25: =W25-U25 -> 110.811 | W25: 233.017 | X25: 135.566 | Y25: =Z25-X25 -> 121.165 | Z25: 256.731 | AA25: 141.467 | AB25: =AC25-AA25 -> 126.859 | AC25: 268.326 | AD25: 102.626 | AE25: =AF25-AD25 -> 172.614 | AF25: 275.24 | AG25: 148.296 | AH25: =AI25-AG25 -> 144.066 | AI25: 292.362 | AJ25: 172.032 | AK25: =AL25-AJ25 -> 174.356 | AL25: 346.388 | AM25: 199.294 | AN25: =AO25-AM25 -> 193.31 | AO25: 392.604 | AP25: 225.478 | AQ25: =AR25-AP25 -> 201.819 | AR25: 427.297 | AS25: 248.298 | AT25: =AU25-AS25 -> 212.644 | AU25: 460.942 | AV25: 249.646 | AW25: =AT25*(1+AW27+AW66) -> 218.38539 | AX25: =AV25+AW25 -> 468.03139 | AY25: =AX25*(1+AY26) -> 496.11327 | AZ25: =AY25*(1+AZ26) -> 520.91893 | BA25: =AZ25*(1+BA26) -> 544.36029 | BB25: =BA25*(1+BB26) -> 566.1347 | BC25: H2/26E: H2/25 × (1 + calibrated constant-FX growth + FX effect). 2027E+: prior year × (1 + scenario lever WHS_growth). | BE25: =IFERROR(IF(AND(BB25>0,AU25>0),(BB25/AU25)^(1/5)-1,"n/m"),"n/m") -> 0.04196876 | BF25: =IFERROR(IF(AND(AU25>0,AF25>0),(AU25/AF25)^(1/5)-1,"n/m"),"n/m") -> 0.10863082 | BG25: =IFERROR(IF(AND(AU25>0,Q25>0),(AU25/Q25)^(1/10)-1,"n/m"),"n/m") -> 0.076291526 | BH25: =IFERROR(IF(AND(AU25>0,E25>0),(AU25/E25)^(1/14)-1,"n/m"),"n/m") -> 0.065842786 | BK25: 2030E | BL25: =BM25+$BL$21 -> 0.06 | BM25: 0.04 | BN25: =BM25+$BN$21 -> 0.01
B26: Wholesale revenues y/y % | F26: =IF(AND(ISNUMBER(F25),ISNUMBER(C25)),IFERROR(F25/C25-1,""),"") -> 0.090544913 | G26: =IF(AND(ISNUMBER(G25),ISNUMBER(D25)),IFERROR(G25/D25-1,""),"") -> 0.052834342 | H26: =IF(AND(ISNUMBER(H25),ISNUMBER(E25)),IFERROR(H25/E25-1,""),"") -> 0.072033225 | I26: =IF(AND(ISNUMBER(I25),ISNUMBER(F25)),IFERROR(I25/F25-1,""),"") -> 0.019254072 | J26: =IF(AND(ISNUMBER(J25),ISNUMBER(G25)),IFERROR(J25/G25-1,""),"") -> 0.027161936 | K26: =IF(AND(ISNUMBER(K25),ISNUMBER(H25)),IFERROR(K25/H25-1,""),"") -> 0.023066432 | L26: =IF(AND(ISNUMBER(L25),ISNUMBER(I25)),IFERROR(L25/I25-1,""),"") -> 0.062100405 | M26: =IF(AND(ISNUMBER(M25),ISNUMBER(J25)),IFERROR(M25/J25-1,""),"") -> -0.062377137 | ... AX26: =IF(AND(ISNUMBER(AX25),ISNUMBER(AU25)),IFERROR(AX25/AU25-1,""),"") -> 0.015380217 | AY26: =CHOOSE(MATCH($BC$2,{"Bull","Base","Bear"},0),$BL$22,$BM$22,$BN$22) -> 0.06 | AZ26: =CHOOSE(MATCH($BC$2,{"Bull","Base","Bear"},0),$BL$23,$BM$23,$BN$23) -> 0.05 | BA26: =CHOOSE(MATCH($BC$2,{"Bull","Base","Bear"},0),$BL$24,$BM$24,$BN$24) -> 0.045 | BB26: =CHOOSE(MATCH($BC$2,{"Bull","Base","Bear"},0),$BL$25,$BM$25,$BN$25) -> 0.04 | BC26: 2027E–2030E: scenario lever WHS_growth (selective distribution: SS/FW order books, department-store exposure).
B27: Wholesale growth at constant FX (company) % | AU27: 0.087 | AV27: 0.027 | AW27: =AW70 -> 0.027 | AX27: =IFERROR((AS25*(1+AV27)+AT25*(1+AW27))/AU25-1,"") -> 0.027 | BK27: FM_margin (first margin %) | BL27: 0.007 | BM27: Δ → | BN27: -0.01 | BO27: FY23 72.5%, FY24 74.5%, FY25 75.2%, H1/26 75.0%: retail mix and pricing.
B28: Memo: mono-brand wholesale revenues (reported separately to 2016) | C28: 14.864 | D28: =E28-C28 -> 12.292 | E28: 27.156 | F28: 21.809 | G28: =H28-F28 -> 10.873 | H28: 32.682 | I28: 20.6 | J28: =K28-I28 -> 12.48 | K28: 33.08 | L28: 21.833 | M28: =N28-L28 -> 9.04 | N28: 30.873 | O28: 21.96 | P28: =Q28-O28 -> 11.428 | Q28: 33.388 | R28: 22.221 | S28: =T28-R28 -> 11.955 | T28: 34.176 | U28: 17.6 | V28: =W28-U28 -> 7.705 | W28: 25.305 | X28: 19.778 | Y28: =Z28-X28 -> 10.427 | Z28: 30.205 | AA28: 18.209 | AB28: =AC28-AA28 -> 14.408 | AC28: 32.617 | AD28: 13.604 | AE28: =AF28-AD28 -> 21.972 | AF28: 35.576 | BK28: 2027E | BL28: =BM28+$BL$27 -> 0.765 | BM28: 0.758 | BN28: =BM28+$BN$27 -> 0.748
B29: Memo: multi-brand wholesale revenues (reported separately to 2016) | C29: 81.243 | D29: =E29-C29 -> 80.375 | E29: 161.618 | F29: 83 | G29: =H29-F29 -> 86.69 | H29: 169.69 | I29: 86.227 | J29: =K29-I29 -> 87.733 | K29: 173.96 | L29: 91.628 | M29: =N29-L29 -> 84.922 | N29: 176.55 | O29: 93.604 | P29: =Q29-O29 -> 93.985 | Q29: 187.589 | R29: 98.064 | S29: =T29-R29 -> 97.511 | T29: 195.575 | U29: 104.606 | V29: =W29-U29 -> 103.106 | W29: 207.712 | X29: 115.788 | Y29: =Z29-X29 -> 110.738 | Z29: 226.526 | AA29: 123.258 | AB29: =AC29-AA29 -> 112.451 | AC29: 235.709 | AD29: 89.022 | AE29: =AF29-AD29 -> 150.642 | AF29: 239.664 | BK29: 2028E | BL29: =BM29+$BL$27 -> 0.766 | BM29: 0.759 | BN29: =BM29+$BN$27 -> 0.749
B30: Wholesale % of revenues | C30: =IF(AND(ISNUMBER(C25),ISNUMBER(C111)),IFERROR(C25/C111,""),"") -> 0.82525739 | D30: =IF(AND(ISNUMBER(D25),ISNUMBER(D111)),IFERROR(D25/D111,""),"") -> 0.73441487 | E30: =IF(AND(ISNUMBER(E25),ISNUMBER(E111)),IFERROR(E25/E111,""),"") -> 0.77801636 | F30: =IF(AND(ISNUMBER(F25),ISNUMBER(F111)),IFERROR(F25/F111,""),"") -> 0.7751973 | G30: =IF(AND(ISNUMBER(G25),ISNUMBER(G111)),IFERROR(G25/G111,""),"") -> 0.6769661 | H30: =IF(AND(ISNUMBER(H25),ISNUMBER(H111)),IFERROR(H25/H111,""),"") -> 0.72451409 | I30: =IF(AND(ISNUMBER(I25),ISNUMBER(I111)),IFERROR(I25/I111,""),"") -> 0.67794814 | J30: =IF(AND(ISNUMBER(J25),ISNUMBER(J111)),IFERROR(J25/J111,""),"") -> 0.60769772 | ... BB30: =IF(AND(ISNUMBER(BB25),ISNUMBER(BB111)),IFERROR(BB25/BB111,""),"") -> 0.2684963 | BK30: 2029E | BL30: =BM30+$BL$27 -> 0.767 | BM30: 0.76 | BN30: =BM30+$BN$27 -> 0.75
BK31: 2030E | BL31: =BM31+$BL$27 -> 0.767 | BM31: 0.76 | BN31: =BM31+$BN$27 -> 0.75
B32: Geography (Europe incl. Italy · Americas · Asia incl. Middle East & rest of world) — reconciled to the channel build | BC32: GEOGRAPHY — modelling logic
B33: Europe (incl. Italy) | C33: 75.172 | D33: =E33-C33 -> 74.348 | E33: 149.52 | F33: 80.638 | G33: =H33-F33 -> 77.948 | H33: 158.586 | I33: 91.017 | J33: =K33-I33 -> 83.544 | K33: 174.561 | L33: 96.308 | M33: =N33-L33 -> 88.885 | N33: 185.193 | O33: 100.119 | P33: =Q33-O33 -> 99.853 | Q33: 199.972 | R33: 107.908 | S33: =T33-R33 -> 104.692 | T33: 212.6 | U33: 117.048 | V33: =W33-U33 -> 118.507 | W33: 235.555 | X33: 128.077 | Y33: =Z33-X33 -> 123.85 | Z33: 251.927 | AA33: 136.705 | AB33: =AC33-AA33 -> 137.766 | AC33: 274.471 | AD33: 99.031 | AE33: =AF33-AD33 -> 150.764 | AF33: 249.795 | AG33: 136.932 | AH33: =AI33-AG33 -> 166.441 | AI33: 303.373 | AJ33: 164.955 | AK33: =AL33-AJ33 -> 201.612 | AL33: 366.567 | AM33: 202.769 | AN33: =AO33-AM33 -> 225.463 | AO33: 428.232 | AP33: 221.052 | AQ33: =AR33-AP33 -> 235.535 | AR33: 456.587 | AS33: 243.213 | AT33: =AU33-AS33 -> 251.707 | AU33: 494.92 | AV33: 255.582 | AW33: =AW47*AW52 -> 265.61866 | AX33: =AV33+AW33 -> 521.20066 | AY33: =AY47*AY52 -> 560.80307 | AZ33: =AZ47*AZ52 -> 595.23614 | BA33: =BA47*BA52 -> 628.34989 | BB33: =BB47*BB52 -> 661.8416 | BE33: =IFERROR(IF(AND(BB33>0,AU33>0),(BB33/AU33)^(1/5)-1,"n/m"),"n/m") -> 0.059848552 | BF33: =IFERROR(IF(AND(AU33>0,AF33>0),(AU33/AF33)^(1/5)-1,"n/m"),"n/m") -> 0.14654275 | BG33: =IFERROR(IF(AND(AU33>0,Q33>0),(AU33/Q33)^(1/10)-1,"n/m"),"n/m") -> 0.094854938 | BH33: =IFERROR(IF(AND(AU33>0,E33>0),(AU33/E33)^(1/14)-1,"n/m"),"n/m") -> 0.089258914 | BK33: SVC_ratio (services ex-outsourced % revenues) | BL33: -0.005 | BM33: Δ → | BN33: 0.008 | BO33: Variable rents, communication, transport & duties (US tariffs from FW25), cards: FY24 26.3%, FY25 26.1%.
B34: Europe y/y % | F34: =IF(AND(ISNUMBER(F33),ISNUMBER(C33)),IFERROR(F33/C33-1,""),"") -> 0.072713244 | G34: =IF(AND(ISNUMBER(G33),ISNUMBER(D33)),IFERROR(G33/D33-1,""),"") -> 0.048420939 | H34: =IF(AND(ISNUMBER(H33),ISNUMBER(E33)),IFERROR(H33/E33-1,""),"") -> 0.060634029 | I34: =IF(AND(ISNUMBER(I33),ISNUMBER(F33)),IFERROR(I33/F33-1,""),"") -> 0.12871103 | J34: =IF(AND(ISNUMBER(J33),ISNUMBER(G33)),IFERROR(J33/G33-1,""),"") -> 0.071791451 | K34: =IF(AND(ISNUMBER(K33),ISNUMBER(H33)),IFERROR(K33/H33-1,""),"") -> 0.10073399 | L34: =IF(AND(ISNUMBER(L33),ISNUMBER(I33)),IFERROR(L33/I33-1,""),"") -> 0.058131997 | M34: =IF(AND(ISNUMBER(M33),ISNUMBER(J33)),IFERROR(M33/J33-1,""),"") -> 0.063930384 | ... AX34: =IF(AND(ISNUMBER(AX33),ISNUMBER(AU33)),IFERROR(AX33/AU33-1,""),"") -> 0.053100823 | AY34: =IF(AND(ISNUMBER(AY33),ISNUMBER(AX33)),IFERROR(AY33/AX33-1,""),"") -> 0.075983045 | AZ34: =IF(AND(ISNUMBER(AZ33),ISNUMBER(AY33)),IFERROR(AZ33/AY33-1,""),"") -> 0.061399578 | BA34: =IF(AND(ISNUMBER(BA33),ISNUMBER(AZ33)),IFERROR(BA33/AZ33-1,""),"") -> 0.05563127 | BB34: =IF(AND(ISNUMBER(BB33),ISNUMBER(BA33)),IFERROR(BB33/BA33-1,""),"") -> 0.053301051 | BK34: 2027E | BL34: =BM34+$BL$33 -> 0.253 | BM34: 0.258 | BN34: =BM34+$BN$33 -> 0.266
B35: Europe growth at constant FX (company) % | AS35: 0.097 | AU35: 0.081 | AV35: 0.053 | BK35: 2028E | BL35: =BM35+$BL$33 -> 0.252 | BM35: 0.257 | BN35: =BM35+$BN$33 -> 0.265
B36: Americas (North America to 2023) | C36: 28.744 | D36: =E36-C36 -> 40.217 | E36: 68.961 | F36: 35.445 | G36: =H36-F36 -> 53.109 | H36: 88.554 | I36: 46.892 | J36: =K36-I36 -> 62.176 | K36: 109.068 | L36: 55.416 | M36: =N36-L36 -> 67.467 | N36: 122.883 | O36: 69.692 | P36: =Q36-O36 -> 86.903 | Q36: 156.595 | R36: 76.445 | S36: =T36-R36 -> 91.212 | T36: 167.657 | U36: 83.584 | V36: =W36-U36 -> 95.072 | W36: 178.656 | X36: 86.323 | Y36: =Z36-X36 -> 100.913 | Z36: 187.236 | AA36: 94.077 | AB36: =AC36-AA36 -> 110.032 | AC36: 204.109 | AD36: 57.484 | AE36: =AF36-AD36 -> 115.294 | AF36: 172.778 | AG36: 99.983 | AH36: =AI36-AG36 -> 138.255 | AI36: 238.238 | AJ36: 152.613 | AK36: =AL36-AJ36 -> 182.08 | AL36: 334.693 | AM36: 189.007 | AN36: =AO36-AM36 -> 215.446 | AO36: 404.453 | AP36: 225.616 | AQ36: =AR36-AP36 -> 250.943 | AR36: 476.559 | AS36: 245.253 | AT36: =AU36-AS36 -> 275.235 | AU36: 520.488 | AV36: 278.671 | AW36: =AW49*AW52 -> 301.4073 | AX36: =AV36+AW36 -> 580.0783 | AY36: =AY49*AY52 -> 647.48729 | AZ36: =AZ49*AZ52 -> 706.60169 | BA36: =BA49*BA52 -> 767.02152 | BB36: =BB49*BB52 -> 826.95893 | BE36: =IFERROR(IF(AND(BB36>0,AU36>0),(BB36/AU36)^(1/5)-1,"n/m"),"n/m") -> 0.097020249 | BF36: =IFERROR(IF(AND(AU36>0,AF36>0),(AU36/AF36)^(1/5)-1,"n/m"),"n/m") -> 0.24676458 | BG36: =IFERROR(IF(AND(AU36>0,Q36>0),(AU36/Q36)^(1/10)-1,"n/m"),"n/m") -> 0.12762133 | BH36: =IFERROR(IF(AND(AU36>0,E36>0),(AU36/E36)^(1/14)-1,"n/m"),"n/m") -> 0.15531527 | BK36: 2029E | BL36: =BM36+$BL$33 -> 0.251 | BM36: 0.256 | BN36: =BM36+$BN$33 -> 0.264
B37: Americas y/y % | F37: =IF(AND(ISNUMBER(F36),ISNUMBER(C36)),IFERROR(F36/C36-1,""),"") -> 0.23312691 | G37: =IF(AND(ISNUMBER(G36),ISNUMBER(D36)),IFERROR(G36/D36-1,""),"") -> 0.32056096 | H37: =IF(AND(ISNUMBER(H36),ISNUMBER(E36)),IFERROR(H36/E36-1,""),"") -> 0.28411711 | I37: =IF(AND(ISNUMBER(I36),ISNUMBER(F36)),IFERROR(I36/F36-1,""),"") -> 0.32295105 | J37: =IF(AND(ISNUMBER(J36),ISNUMBER(G36)),IFERROR(J36/G36-1,""),"") -> 0.17072436 | K37: =IF(AND(ISNUMBER(K36),ISNUMBER(H36)),IFERROR(K36/H36-1,""),"") -> 0.23165526 | L37: =IF(AND(ISNUMBER(L36),ISNUMBER(I36)),IFERROR(L36/I36-1,""),"") -> 0.18177941 | M37: =IF(AND(ISNUMBER(M36),ISNUMBER(J36)),IFERROR(M36/J36-1,""),"") -> 0.085097144 | ... AX37: =IF(AND(ISNUMBER(AX36),ISNUMBER(AU36)),IFERROR(AX36/AU36-1,""),"") -> 0.11448929 | AY37: =IF(AND(ISNUMBER(AY36),ISNUMBER(AX36)),IFERROR(AY36/AX36-1,""),"") -> 0.11620671 | AZ37: =IF(AND(ISNUMBER(AZ36),ISNUMBER(AY36)),IFERROR(AZ36/AY36-1,""),"") -> 0.091298158 | BA37: =IF(AND(ISNUMBER(BA36),ISNUMBER(AZ36)),IFERROR(BA36/AZ36-1,""),"") -> 0.085507627 | BB37: =IF(AND(ISNUMBER(BB36),ISNUMBER(BA36)),IFERROR(BB36/BA36-1,""),"") -> 0.078143057 | BK37: 2030E | BL37: =BM37+$BL$33 -> 0.25 | BM37: 0.255 | BN37: =BM37+$BN$33 -> 0.263
B38: Americas growth at constant FX (company) % | AS38: 0.1 | AU38: 0.119 | AV38: 0.206
B39: Asia (Greater China + rest of world / rest of Asia) | C39: 12.541 | D39: =E39-C39 -> 11.613 | E39: 24.154 | F39: 19.12 | G39: =H39-F39 -> 13.061 | H39: 32.181 | I39: 19.665 | J39: =K39-I39 -> 19.186 | K39: 38.851 | L39: 24.087 | M39: =N39-L39 -> 23.746 | N39: 47.833 | O39: 30.521 | P39: =Q39-O39 -> 27.063 | Q39: 57.584 | R39: 35.487 | S39: =T39-R39 -> 40.227 | T39: 75.714 | U39: 42.695 | V39: =W39-U39 -> 46.665 | W39: 89.36 | X39: 55.086 | Y39: =Z39-X39 -> 58.747 | Z39: 113.833 | AA39: 60.631 | AB39: =AC39-AA39 -> 68.55 | AC39: 129.181 | AD39: 48.628 | AE39: =AF39-AD39 -> 72.812 | AF39: 121.44 | AG39: 76.849 | AH39: =AI39-AG39 -> 93.719 | AI39: 170.568 | AJ39: 97.789 | AK39: =AL39-AJ39 -> 120.659 | AL39: 218.448 | AM39: 152.166 | AN39: =AO39-AM39 -> 154.569 | AO39: 306.735 | AP39: 173.994 | AQ39: =AR39-AP39 -> 171.4 | AR39: 345.394 | AS39: 195.669 | AT39: =AU39-AS39 -> 196.874 | AU39: 392.543 | AV39: 215.158 | AW39: =AW51*AW52 -> 213.63494 | AX39: =AV39+AW39 -> 428.79294 | AY39: =AY51*AY52 -> 478.62156 | AZ39: =AZ51*AZ52 -> 524.70384 | BA39: =BA51*BA52 -> 572.18273 | BB39: =BB51*BB52 -> 619.73767 | BE39: =IFERROR(IF(AND(BB39>0,AU39>0),(BB39/AU39)^(1/5)-1,"n/m"),"n/m") -> 0.095630545 | BF39: =IFERROR(IF(AND(AU39>0,AF39>0),(AU39/AF39)^(1/5)-1,"n/m"),"n/m") -> 0.26446 | BG39: =IFERROR(IF(AND(AU39>0,Q39>0),(AU39/Q39)^(1/10)-1,"n/m"),"n/m") -> 0.21159798 | BH39: =IFERROR(IF(AND(AU39>0,E39>0),(AU39/E39)^(1/14)-1,"n/m"),"n/m") -> 0.22037338 | BK39: PAY_ratio (payroll % revenues) | BL39: -0.003 | BM39: Δ → | BN39: 0.005 | BO39: FY24 18.3%, FY25 18.1%, H1/26 18.5% (artisans in boutiques, stock-grant plan).
B40: Asia y/y % | F40: =IF(AND(ISNUMBER(F39),ISNUMBER(C39)),IFERROR(F39/C39-1,""),"") -> 0.52459931 | G40: =IF(AND(ISNUMBER(G39),ISNUMBER(D39)),IFERROR(G39/D39-1,""),"") -> 0.12468785 | H40: =IF(AND(ISNUMBER(H39),ISNUMBER(E39)),IFERROR(H39/E39-1,""),"") -> 0.33232591 | I40: =IF(AND(ISNUMBER(I39),ISNUMBER(F39)),IFERROR(I39/F39-1,""),"") -> 0.028504184 | J40: =IF(AND(ISNUMBER(J39),ISNUMBER(G39)),IFERROR(J39/G39-1,""),"") -> 0.46895337 | K40: =IF(AND(ISNUMBER(K39),ISNUMBER(H39)),IFERROR(K39/H39-1,""),"") -> 0.20726516 | L40: =IF(AND(ISNUMBER(L39),ISNUMBER(I39)),IFERROR(L39/I39-1,""),"") -> 0.22486651 | M40: =IF(AND(ISNUMBER(M39),ISNUMBER(J39)),IFERROR(M39/J39-1,""),"") -> 0.2376733 | ... AX40: =IF(AND(ISNUMBER(AX39),ISNUMBER(AU39)),IFERROR(AX39/AU39-1,""),"") -> 0.09234642 | AY40: =IF(AND(ISNUMBER(AY39),ISNUMBER(AX39)),IFERROR(AY39/AX39-1,""),"") -> 0.11620671 | AZ40: =IF(AND(ISNUMBER(AZ39),ISNUMBER(AY39)),IFERROR(AZ39/AY39-1,""),"") -> 0.096281255 | BA40: =IF(AND(ISNUMBER(BA39),ISNUMBER(AZ39)),IFERROR(BA39/AZ39-1,""),"") -> 0.09048702 | BB40: =IF(AND(ISNUMBER(BB39),ISNUMBER(BA39)),IFERROR(BB39/BA39-1,""),"") -> 0.083111458 | BK40: 2027E | BL40: =BM40+$BL$39 -> 0.178 | BM40: 0.181 | BN40: =BM40+$BN$39 -> 0.186
...

Sheet Bull-Base-Bear
B2: Brunello Cucinelli (BC) — Bull / Base / Bear Case P&L Summary | J2: Share price (EUR): | K2: =Model!$AX$384 -> 80.18
B3: Adjusted figures (company-normalised; IFRS 16 basis unless stated) · EUR millions · Live panel linked to Model — toggle scenario on Model!BC2. Bull / Bear panels are value snapshots of the Model run with the switch set to Bull / Bear. | J3: As of: | K3: =TODAY() -> 46301
B5: Scenario: | C5: =Model!$BC$2 -> Base | N5: Scenario: | O5: Bull | P5: Snapshot (values) — Model run with switch = Bull | Z5: Scenario: | AA5: Bear | AB5: Snapshot (values) — Model run with switch = Bear
B7: (EURm, except EPS and shares) | C7: 2025A | D7: 2026E | E7: 2027E | F7: 2028E | G7: 2029E | H7: 2030E | I7: 25-'30 CAGR | J7: LT Hist Avg | K7: LT Hist Min | L7: LT Hist Max | N7: (EURm, except EPS and shares) | O7: 2025A | P7: 2026E | Q7: 2027E | R7: 2028E | S7: 2029E | T7: 2030E | U7: 25-'30 CAGR | V7: LT Hist Avg | W7: LT Hist Min | X7: LT Hist Max | Z7: (EURm, except EPS and shares) | AA7: 2025A | AB7: 2026E | AC7: 2027E | AD7: 2028E | AE7: 2029E | AF7: 2030E | AG7: 25-'30 CAGR | AH7: LT Hist Avg | AI7: LT Hist Min | AJ7: LT Hist Max
B9: Revenues | C9: =Model!AU111 -> 1407.951 | D9: =Model!AX111 -> 1530.0719 | E9: =Model!AY111 -> 1686.9119 | F9: =Model!AZ111 -> 1826.5417 | G9: =Model!BA111 -> 1967.5541 | H9: =Model!BB111 -> 2108.5382 | I9: =IFERROR(IF(AND(H9>0,C9>0),(H9/C9)^(1/5)-1,"n/m"),"n/m") -> 0.084123569 | N9: Revenues | O9: 1407.951 | P9: 1537.1117 | Q9: 1726.467 | R9: 1904.8449 | S9: 2091.0135 | T9: 2283.7481 | U9: 0.10157008 | Z9: Revenues | AA9: 1407.951 | AB9: 1523.0321 | AC9: 1631.9664 | AD9: 1716.8054 | AE9: 1796.5267 | AF9: 1870.0189 | AG9: 0.058404532
B10: Revenues y/y % | D10: =IFERROR(D9/C9-1,"") -> 0.086736612 | E10: =IFERROR(E9/D9-1,"") -> 0.102505 | F10: =IFERROR(F9/E9-1,"") -> 0.082772403 | G10: =IFERROR(G9/F9-1,"") -> 0.077201886 | H10: =IFERROR(H9/G9-1,"") -> 0.071654474 | N10: Revenues y/y % | P10: 0.091736612 | Q10: 0.12318908 | R10: 0.10331957 | S10: 0.097734281 | T10: 0.092172832 | Z10: Revenues y/y % | AB10: 0.081736612 | AC10: 0.071524616 | AD10: 0.051985744 | AE10: 0.046435801 | AF10: 0.04090796
B11: Retail revenues y/y % | C11: =Model!AU17 -> 0.11250137 | D11: =Model!AX17 -> 0.12146824 | E11: =Model!AY17 -> 0.12123656 | F11: =Model!AZ17 -> 0.096426117 | G11: =Model!BA17 -> 0.090049834 | H11: =Model!BB17 -> 0.083762058 | N11: Retail revenues y/y % | O11: 0.11250137 | P11: 0.12890191 | Q11: 0.14209677 | R11: 0.1171134 | S11: 0.11071429 | T11: 0.10440514 | Z11: Retail revenues y/y % | AA11: 0.11250137 | AB11: 0.11403456 | AC11: 0.089946237 | AD11: 0.065395189 | AE11: 0.059053156 | AF11: 0.052797428
B12: Adjusted EBITDA (normalised, IFRS 16) | C12: =Model!AU158 -> 416.463 | D12: =Model!AX158 -> 463.01556 | E12: =Model!AY158 -> 512.82122 | F12: =Model!AZ158 -> 560.74829 | G12: =Model!BA158 -> 607.97423 | H12: =Model!BB158 -> 655.75538 | I12: =IFERROR(IF(AND(H12>0,C12>0),(H12/C12)^(1/5)-1,"n/m"),"n/m") -> 0.095047827 | N12: Adjusted EBITDA (normalised, IFRS 16) | O12: 416.463 | P12: 465.148 | Q12: 550.74298 | R12: 613.36004 | S12: 677.48837 | T12: 744.50189 | U12: 0.12320202 | Z12: Adjusted EBITDA (normalised, IFRS 16) | AA12: 416.463 | AB12: 460.88311 | AC12: 458.58257 | AD12: 487.57274 | AE12: 513.80662 | AF12: 538.56544 | AG12: 0.052767361
B13: Adjusted EBITDA margin % | C13: =IFERROR(C12/C9,"") -> 0.29579367 | D13: =IFERROR(D12/D9,"") -> 0.30261033 | E13: =IFERROR(E12/E9,"") -> 0.304 | F13: =IFERROR(F12/F9,"") -> 0.307 | G13: =IFERROR(G12/G9,"") -> 0.309 | H13: =IFERROR(H12/H9,"") -> 0.311 | J13: =IFERROR(AVERAGE(Model!E159,Model!H159,Model!K159,Model!N159,Model!Q159,Model!T159,Model!W159,Model!Z159,Model!AC159,Model!AF159,Model!AI159,Model!AL159,Model!AO159,Model!AR159,Model!AU159),"") -> 0.22089036 | K13: =IFERROR(MIN(Model!E159,Model!H159,Model!K159,Model!N159,Model!Q159,Model!T159,Model!W159,Model!Z159,Model!AC159,Model!AF159,Model!AI159,Model!AL159,Model!AO159,Model!AR159,Model!AU159),"") -> 0.1655161 | L13: =IFERROR(MAX(Model!E159,Model!H159,Model!K159,Model!N159,Model!Q159,Model!T159,Model!W159,Model!Z159,Model!AC159,Model!AF159,Model!AI159,Model!AL159,Model!AO159,Model!AR159,Model!AU159),"") -> 0.29579367 | N13: Adjusted EBITDA margin % | O13: 0.29579367 | P13: 0.30261172 | Q13: 0.319 | R13: 0.322 | S13: 0.324 | T13: 0.326 | V13: 0.22089036 | W13: 0.1655161 | X13: 0.29579367 | Z13: Adjusted EBITDA margin % | AA13: 0.29579367 | AB13: 0.30260892 | AC13: 0.281 | AD13: 0.284 | AE13: 0.286 | AF13: 0.288 | AH13: 0.22089036 | AI13: 0.1655161 | AJ13: 0.29579367
B15: Operating Income — EBIT (IFRS) | C15: =Model!AU120 -> 227.784 | D15: =Model!AX120 -> 262.61966 | E15: =Model!AY120 -> 288.2668 | F15: =Model!AZ120 -> 322.55526 | G15: =Model!BA120 -> 358.25621 | H15: =Model!BB120 -> 391.0879 | I15: =IFERROR(IF(AND(H15>0,C15>0),(H15/C15)^(1/5)-1,"n/m"),"n/m") -> 0.11416685 | N15: Operating Income — EBIT (IFRS) | O15: 227.784 | P15: 264.4619 | Q15: 324.40805 | R15: 370.89787 | S15: 420.22457 | T15: 467.96912 | U15: 0.15488515 | Z15: Operating Income — EBIT (IFRS) | AA15: 227.784 | AB15: 260.77743 | AC15: 236.43965 | AD15: 255.30044 | AE15: 274.53439 | AF15: 290.16113 | AG15: 0.049598506
B16: EBIT y/y % | D16: =IFERROR(D15/C15-1,"") -> 0.15293287 | E16: =IFERROR(E15/D15-1,"") -> 0.097658862 | F16: =IFERROR(F15/E15-1,"") -> 0.11894698 | G16: =IFERROR(G15/F15-1,"") -> 0.11068166 | H16: =IFERROR(H15/G15-1,"") -> 0.091643047 | N16: EBIT y/y % | P16: 0.16102051 | Q16: 0.22667218 | R16: 0.14330661 | S16: 0.13299268 | T16: 0.11361674 | Z16: EBIT y/y % | AB16: 0.14484523 | AC16: -0.093327758 | AD16: 0.079769972 | AE16: 0.075338493 | AF16: 0.056920893
B17: Operating margin (IFRS) % | C17: =IFERROR(C15/C9,"") -> 0.16178404 | D17: =IFERROR(D15/D9,"") -> 0.17163877 | E17: =IFERROR(E15/E9,"") -> 0.17088432 | F17: =IFERROR(F15/F9,"") -> 0.17659343 | G17: =IFERROR(G15/G9,"") -> 0.18208201 | H17: =IFERROR(H15/H9,"") -> 0.18547822 | J17: =IFERROR(AVERAGE(Model!E121,Model!H121,Model!K121,Model!N121,Model!Q121,Model!T121,Model!W121,Model!Z121,Model!AC121,Model!AF121,Model!AI121,Model!AL121,Model!AO121,Model!AR121,Model!AU121),"") -> 0.1275804 | K17: =IFERROR(MIN(Model!E121,Model!H121,Model!K121,Model!N121,Model!Q121,Model!T121,Model!W121,Model!Z121,Model!AC121,Model!AF121,Model!AI121,Model!AL121,Model!AO121,Model!AR121,Model!AU121),"") -> -0.02723832 | L17: =IFERROR(MAX(Model!E121,Model!H121,Model!K121,Model!N121,Model!Q121,Model!T121,Model!W121,Model!Z121,Model!AC121,Model!AF121,Model!AI121,Model!AL121,Model!AO121,Model!AR121,Model!AU121),"") -> 0.16555681 | N17: Operating margin (IFRS) % | O17: 0.16178404 | P17: 0.17205119 | Q17: 0.18790284 | R17: 0.1947129 | S17: 0.20096693 | T17: 0.20491275 | V17: 0.1275804 | W17: -0.02723832 | X17: 0.16555681 | Z17: Operating margin (IFRS) % | AA17: 0.16178404 | AB17: 0.17122254 | AC17: 0.14488022 | AD17: 0.14870668 | AE17: 0.15281398 | AF17: 0.15516481 | AH17: 0.1275804 | AI17: -0.02723832 | AJ17: 0.16555681
B19: Adjusted Net Profit (attributable to BC shareholders) | C19: =Model!AU184 -> 140.79871 | D19: =Model!AX184 -> 155.41683 | E19: =Model!AY184 -> 169.57534 | F19: =Model!AZ184 -> 192.34758 | G19: =Model!BA184 -> 216.48774 | H19: =Model!BB184 -> 238.64752 | I19: =IFERROR(IF(AND(H19>0,C19>0),(H19/C19)^(1/5)-1,"n/m"),"n/m") -> 0.11130085 | N19: Adjusted Net Profit (attributable to BC shareholders) | O19: 140.79871 | P19: 156.67602 | Q19: 194.36404 | R19: 225.6711 | S19: 259.22548 | T19: 291.6446 | U19: 0.15678075 | Z19: Adjusted Net Profit (attributable to BC shareholders) | AA19: 140.79871 | AB19: 154.15764 | AC19: 134.01986 | AD19: 145.96631 | AE19: 158.73363 | AF19: 169.06124 | AG19: 0.037263442
B21: Shares outstanding (m, weighted average) | C21: =Model!AU138 -> 67.975949 | D21: =Model!AX138 -> 68 | E21: =Model!AY138 -> 68 | F21: =Model!AZ138 -> 68 | G21: =Model!BA138 -> 68 | H21: =Model!BB138 -> 68 | I21: =IFERROR(IF(AND(H21>0,C21>0),(H21/C21)^(1/5)-1,"n/m"),"n/m") -> 7.0753251e-05 | N21: Shares outstanding (m, weighted average) | O21: 67.975949 | P21: 68 | Q21: 68 | R21: 68 | S21: 68 | T21: 68 | U21: 7.0753251e-05 | Z21: Shares outstanding (m, weighted average) | AA21: 67.975949 | AB21: 68 | AC21: 68 | AD21: 68 | AE21: 68 | AF21: 68 | AG21: 7.0753251e-05
B23: Adjusted EPS — basic & diluted (EUR) | C23: =Model!AU188 -> 2.0713019 | D23: =Model!AX188 -> 2.2855416 | E23: =Model!AY188 -> 2.4937551 | F23: =Model!AZ188 -> 2.8286409 | G23: =Model!BA188 -> 3.1836433 | H23: =Model!BB188 -> 3.5095223 | I23: =IFERROR(IF(AND(H23>0,C23>0),(H23/C23)^(1/5)-1,"n/m"),"n/m") -> 0.11122223 | N23: Adjusted EPS — basic & diluted (EUR) | O23: 2.0713019 | P23: 2.3040591 | Q23: 2.8582946 | R23: 3.3186927 | S23: 3.8121394 | T23: 4.2888912 | U23: 0.15669891 | Z23: Adjusted EPS — basic & diluted (EUR) | AA23: 2.0713019 | AB23: 2.2670241 | AC23: 1.9708803 | AD23: 2.1465634 | AE23: 2.334318 | AF23: 2.4861947 | AG23: 0.037190057
B24: EPS y/y % | D24: =IFERROR(D23/C23-1,"") -> 0.10343238 | E24: =IFERROR(E23/D23-1,"") -> 0.091100284 | F24: =IFERROR(F23/E23-1,"") -> 0.13428978 | G24: =IFERROR(G23/F23-1,"") -> 0.12550281 | H24: =IFERROR(H23/G23-1,"") -> 0.10236042 | N24: EPS y/y % | P24: 0.11237242 | Q24: 0.24054744 | R24: 0.16107437 | S24: 0.14868709 | T24: 0.12506148 | Z24: EPS y/y % | AB24: 0.094492337 | AC24: -0.13063108 | AD24: 0.08913942 | AE24: 0.08746756 | AF24: 0.065062521
B26: P / E (x) — assumed (adjusted EPS) | G26: 35 | H26: 35 | N26: P / E (x) — assumed (adjusted EPS) | S26: 40 | T26: 40 | Z26: P / E (x) — assumed (adjusted EPS) | AE26: 28 | AF26: 28
B27: Price Target (EUR) | G27: =G26*G23 -> 111.42752 | H27: =H26*H23 -> 122.83328 | N27: Price Target (EUR) | S27: =S26*S23 -> 152.48558 | T27: =T26*T23 -> 171.55565 | Z27: Price Target (EUR) | AE27: =AE26*AE23 -> 65.360905 | AF27: =AF26*AF23 -> 69.61345
B28: Upside / (Downside) vs current | G28: =IFERROR(G27/$K$2-1,"") -> 0.38971707 | H28: =IFERROR(H27/$K$2-1,"") -> 0.5319691 | N28: Upside / (Downside) vs current | S28: =IFERROR(S27/$K$2-1,"") -> 0.90179068 | T28: =IFERROR(T27/$K$2-1,"") -> 1.1396314 | Z28: Upside / (Downside) vs current | AE28: =IFERROR(AE27/$K$2-1,"") -> -0.18482284 | AF28: =IFERROR(AF27/$K$2-1,"") -> -0.13178536
B29: IRR (to Dec-Y-1) | G29: =IFERROR((G27/$K$2)^(1/((DATE(2029-1,12,31)-$K$3)/365.25))-1,"") -> 0.15850262 | H29: =IFERROR((H27/$K$2)^(1/((DATE(2030-1,12,31)-$K$3)/365.25))-1,"") -> 0.14089094 | N29: IRR (to Dec-Y-1) | S29: =IFERROR((S27/$K$2)^(1/((DATE(2029-1,12,31)-$K$3)/365.25))-1,"") -> 0.33291716 | T29: =IFERROR((T27/$K$2)^(1/((DATE(2030-1,12,31)-$K$3)/365.25))-1,"") -> 0.2649638 | Z29: IRR (to Dec-Y-1) | AE29: =IFERROR((AE27/$K$2)^(1/((DATE(2029-1,12,31)-$K$3)/365.25))-1,"") -> -0.087308289 | AF29: =IFERROR((AF27/$K$2)^(1/((DATE(2030-1,12,31)-$K$3)/365.25))-1,"") -> -0.042728448
B31: Free Cash Flow after lease payments | C31: =Model!AU240 -> -12.982 | D31: =Model!AX240 -> 120.86336 | E31: =Model!AY240 -> 100.86355 | F31: =Model!AZ240 -> 123.79637 | G31: =Model!BA240 -> 143.13626 | H31: =Model!BB240 -> 163.08211 | I31: =IFERROR(IF(AND(H31>0,C31>0),(H31/C31)^(1/5)-1,"n/m"),"n/m") -> n/m | N31: Free Cash Flow after lease payments | O31: -12.982 | P31: 120.10256 | Q31: 113.21331 | R31: 147.23024 | S31: 173.64111 | T31: 201.44633 | U31: n/m | Z31: Free Cash Flow after lease payments | AA31: -12.982 | AB31: 121.62417 | AC31: 83.310703 | AD31: 91.03617 | AE31: 101.69085 | AF31: 112.39538 | AG31: n/m
B32: FCF % | C32: =IFERROR(C31/C9,"") -> -0.0092204913 | D32: =IFERROR(D31/D9,"") -> 0.078991951 | E32: =IFERROR(E31/E9,"") -> 0.059791828 | F32: =IFERROR(F31/F9,"") -> 0.067776373 | G32: =IFERROR(G31/G9,"") -> 0.072748319 | H32: =IFERROR(H31/H9,"") -> 0.077343681 | J32: =IFERROR(AVERAGE(Model!E242,Model!H242,Model!K242,Model!N242,Model!Q242,Model!T242,Model!W242,Model!Z242,Model!AC242,Model!AF242,Model!AI242,Model!AL242,Model!AO242,Model!AR242,Model!AU242),"") -> 0.01037891 | K32: =IFERROR(MIN(Model!E242,Model!H242,Model!K242,Model!N242,Model!Q242,Model!T242,Model!W242,Model!Z242,Model!AC242,Model!AF242,Model!AI242,Model!AL242,Model!AO242,Model!AR242,Model!AU242),"") -> -0.11541636 | L32: =IFERROR(MAX(Model!E242,Model!H242,Model!K242,Model!N242,Model!Q242,Model!T242,Model!W242,Model!Z242,Model!AC242,Model!AF242,Model!AI242,Model!AL242,Model!AO242,Model!AR242,Model!AU242),"") -> 0.11571357 | N32: FCF % | O32: -0.0092204913 | P32: 0.078135222 | Q32: 0.065575136 | R32: 0.077292508 | S32: 0.0830416 | T32: 0.088208645 | V32: 0.01037891 | W32: -0.11541636 | X32: 0.11571357 | Z32: FCF % | AA32: -0.0092204913 | AB32: 0.0798566 | AC32: 0.051049275 | AD32: 0.053026493 | AE32: 0.05660414 | AF32: 0.060103872 | AH32: 0.01037891 | AI32: -0.11541636 | AJ32: 0.11571357
B33: FCF / share (EUR) | C33: =IFERROR(C31/C21,"") -> -0.19097931 | D33: =IFERROR(D31/D21,"") -> 1.7774024 | E33: =IFERROR(E31/E21,"") -> 1.4832875 | F33: =IFERROR(F31/F21,"") -> 1.8205349 | G33: =IFERROR(G31/G21,"") -> 2.104945 | H33: =IFERROR(H31/H21,"") -> 2.3982663 | N33: FCF / share (EUR) | O33: -0.19097931 | P33: 1.7662141 | Q33: 1.6649016 | R33: 2.1651505 | S33: 2.5535457 | T33: 2.962446 | Z33: FCF / share (EUR) | AA33: -0.19097931 | AB33: 1.7885907 | AC33: 1.2251574 | AD33: 1.3387672 | AE33: 1.4954536 | AF33: 1.6528732
B34: FCF Yield (on PT) | G34: =IFERROR(G33/G$27,"") -> 0.018890711 | H34: =IFERROR(H33/H$27,"") -> 0.019524564 | N34: FCF Yield (on PT) | S34: =IFERROR(S33/S$27,"") -> 0.016746146 | T34: =IFERROR(T33/T$27,"") -> 0.017268134 | Z34: FCF Yield (on PT) | AE34: =IFERROR(AE33/AE$27,"") -> 0.022879941 | AF34: =IFERROR(AF33/AF$27,"") -> 0.02374359
B35: Adjusted EBITDA pre-IFRS 16 (comparable with 2011–18) | C35: =Model!AU162 -> 265.797 | D35: =Model!AX162 -> 297.75718 | E35: =Model!AY162 -> 323.93009 | F35: =Model!AZ162 -> 362.39922 | G35: =Model!BA162 -> 400.40954 | H35: =Model!BB162 -> 437.06399 | I35: =IFERROR(IF(AND(H35>0,C35>0),(H35/C35)^(1/5)-1,"n/m"),"n/m") -> 0.10458462 | N35: Adjusted EBITDA pre-IFRS 16 (comparable with 2011–18) | O35: 265.797 | P35: 299.12933 | Q35: 361.69254 | R35: 413.77609 | S35: 466.83792 | T35: 520.03632 | U35: 0.14365945 | Z35: Adjusted EBITDA pre-IFRS 16 (comparable with 2011–18) | AA35: 265.797 | AB35: 296.38503 | AC35: 269.85075 | AD35: 290.89218 | AE35: 310.51956 | AF35: 327.87772 | AG35: 0.042875263
B36: Adjusted EBITDA pre-IFRS 16 % of revenues | C36: =IFERROR(C35/C9,"") -> 0.18878285 | D36: =IFERROR(D35/D9,"") -> 0.19460339 | E36: =IFERROR(E35/E9,"") -> 0.19202549 | F36: =IFERROR(F35/F9,"") -> 0.19840731 | G36: =IFERROR(G35/G9,"") -> 0.20350624 | H36: =IFERROR(H35/H9,"") -> 0.20728294 | J36: =IFERROR(AVERAGE(Model!E163,Model!H163,Model!K163,Model!N163,Model!Q163,Model!T163,Model!W163,Model!Z163,Model!AC163,Model!AF163,Model!AI163,Model!AL163,Model!AO163,Model!AR163,Model!AU163),"") -> 0.17048322 | K36: =IFERROR(MIN(Model!E163,Model!H163,Model!K163,Model!N163,Model!Q163,Model!T163,Model!W163,Model!Z163,Model!AC163,Model!AF163,Model!AI163,Model!AL163,Model!AO163,Model!AR163,Model!AU163),"") -> 0.076761033 | L36: =IFERROR(MAX(Model!E163,Model!H163,Model!K163,Model!N163,Model!Q163,Model!T163,Model!W163,Model!Z163,Model!AC163,Model!AF163,Model!AI163,Model!AL163,Model!AO163,Model!AR163,Model!AU163),"") -> 0.20210195 | N36: Adjusted EBITDA pre-IFRS 16 % of revenues | O36: 0.18878285 | P36: 0.19460482 | Q36: 0.20949867 | R36: 0.21722299 | S36: 0.22325916 | T36: 0.22771177 | V36: 0.17048322 | W36: 0.076761033 | X36: 0.20210195 | Z36: Adjusted EBITDA pre-IFRS 16 % of revenues | AA36: 0.18878285 | AB36: 0.19460195 | AC36: 0.16535312 | AD36: 0.16943806 | AE36: 0.17284439 | AF36: 0.17533391 | AH36: 0.17048322 | AI36: 0.076761033 | AJ36: 0.20210195
B38: Net Financial Debt (core, excl. leases) | C38: =Model!AU300 -> 198.365 | D38: =Model!AX300 -> 139.85164 | E38: =Model!AY300 -> 127.50809 | F38: =Model!AZ300 -> 99.711718 | G38: =Model!BA300 -> 63.455461 | H38: =Model!BB300 -> 19.493356 | I38: =IFERROR(IF(AND(H38>0,C38>0),(H38/C38)^(1/5)-1,"n/m"),"n/m") -> -0.37124086 | N38: Net Financial Debt (core, excl. leases) | O38: 198.365 | P38: 140.61244 | Q38: 116.59913 | R38: 77.608893 | S38: 27.847788 | T38: -32.718541 | U38: n/m | Z38: Net Financial Debt (core, excl. leases) | AA38: 198.365 | AB38: 139.09083 | AC38: 143.62013 | AD38: 130.90396 | AE38: 112.97311 | AF38: 91.137736 | AG38: -0.14405347
B39: Net financial debt / Adjusted EBITDA pre-IFRS 16 (x) | C39: =IFERROR(C38/C35,"") -> 0.74630263 | D39: =IFERROR(D38/D35,"") -> 0.4696835 | E39: =IFERROR(E38/E35,"") -> 0.39362841 | F39: =IFERROR(F38/F35,"") -> 0.2751433 | G39: =IFERROR(G38/G35,"") -> 0.15847639 | H39: =IFERROR(H38/H35,"") -> 0.04460069 | N39: Net financial debt / Adjusted EBITDA pre-IFRS 16 (x) | O39: 0.74630263 | P39: 0.47007239 | Q39: 0.32237085 | R39: 0.18756254 | S39: 0.059651941 | T39: -0.062915876 | Z39: Net financial debt / Adjusted EBITDA pre-IFRS 16 (x) | AA39: 0.74630263 | AB39: 0.46929102 | AC39: 0.53222061 | AD39: 0.45000852 | AE39: 0.36381964 | AF39: 0.27796258
B41: ROIC | C41: =Model!AU361 -> 0.10876679 | D41: =Model!AX361 -> 0.11504936 | E41: =Model!AY361 -> 0.11847993 | F41: =Model!AZ361 -> 0.12440728 | G41: =Model!BA361 -> 0.12926627 | H41: =Model!BB361 -> 0.1326399 | J41: =IFERROR(AVERAGE(Model!E361,Model!H361,Model!K361,Model!N361,Model!Q361,Model!T361,Model!W361,Model!Z361,Model!AC361,Model!AF361,Model!AI361,Model!AL361,Model!AO361,Model!AR361,Model!AU361),"") -> 0.14327853 | K41: =IFERROR(MIN(Model!E361,Model!H361,Model!K361,Model!N361,Model!Q361,Model!T361,Model!W361,Model!Z361,Model!AC361,Model!AF361,Model!AI361,Model!AL361,Model!AO361,Model!AR361,Model!AU361),"") -> 0.018513493 | L41: =IFERROR(MAX(Model!E361,Model!H361,Model!K361,Model!N361,Model!Q361,Model!T361,Model!W361,Model!Z361,Model!AC361,Model!AF361,Model!AI361,Model!AL361,Model!AO361,Model!AR361,Model!AU361),"") -> 0.26386811 | N41: ROIC | O41: 0.10876679 | P41: 0.11570786 | Q41: 0.13182264 | R41: 0.14012137 | S41: 0.14689853 | T41: 0.1519296 | V41: 0.14327853 | W41: 0.018513493 | X41: 0.26386811 | Z41: ROIC | AA41: 0.10876679 | AB41: 0.11438916 | AC41: 0.098752737 | AD41: 0.10141818 | AE41: 0.10365334 | AF41: 0.10477011 | AH41: 0.14327853 | AI41: 0.018513493 | AJ41: 0.26386811
B42: RONTA | C42: =Model!AU372 -> 0.096346132 | D42: =Model!AX372 -> 0.10523115 | E42: =Model!AY372 -> 0.10901119 | F42: =Model!AZ372 -> 0.1150642 | G42: =Model!BA372 -> 0.12019182 | H42: =Model!BB372 -> 0.12390457 | J42: =IFERROR(AVERAGE(Model!E372,Model!H372,Model!K372,Model!N372,Model!Q372,Model!T372,Model!W372,Model!Z372,Model!AC372,Model!AF372,Model!AI372,Model!AL372,Model!AO372,Model!AR372,Model!AU372),"") -> 0.12564941 | K42: =IFERROR(MIN(Model!E372,Model!H372,Model!K372,Model!N372,Model!Q372,Model!T372,Model!W372,Model!Z372,Model!AC372,Model!AF372,Model!AI372,Model!AL372,Model!AO372,Model!AR372,Model!AU372),"") -> 0.017232995 | L42: =IFERROR(MAX(Model!E372,Model!H372,Model!K372,Model!N372,Model!Q372,Model!T372,Model!W372,Model!Z372,Model!AC372,Model!AF372,Model!AI372,Model!AL372,Model!AO372,Model!AR372,Model!AU372),"") -> 0.25139736 | N42: RONTA | O42: 0.096346132 | P42: 0.10584244 | Q42: 0.1213956 | R42: 0.1297975 | S42: 0.13688908 | T42: 0.14233265 | V42: 0.12564941 | W42: 0.017232995 | X42: 0.25139736 | Z42: RONTA | AA42: 0.096346132 | AB42: 0.10461838 | AC42: 0.090744366 | AD42: 0.093590568 | AE42: 0.096059896 | AF42: 0.097446286 | AH42: 0.12564941 | AI42: 0.017232995 | AJ42: 0.25139736
B44: Implied Market Cap (EURm) | G44: =G27*G21 -> 7577.071 | H44: =H27*H21 -> 8352.6632 | N44: Implied Market Cap (EURm) | S44: =S27*S21 -> 10369.019 | T44: =T27*T21 -> 11665.784 | Z44: Implied Market Cap (EURm) | AE44: =AE27*AE21 -> 4444.5415 | AF44: =AF27*AF21 -> 4733.7146
B45: (+) Net financial debt, lease liabilities & NCI | G45: =G38+Model!BA304+Model!BA278 -> 1058.3339 | H45: =H38+Model!BB304+Model!BB278 -> 1062.386 | N45: (+) Net financial debt, lease liabilities & NCI | S45: 1049.9127 | T45: 1053.1089 | Z45: (+) Net financial debt, lease liabilities & NCI | AE45: 1069.9468 | AF45: 1074.904
B46: Implied Enterprise Value (EURm; IFRS 16 basis) | G46: =G44+G45 -> 8635.4049 | H46: =H44+H45 -> 9415.0492 | N46: Implied Enterprise Value (EURm; IFRS 16 basis) | S46: =S44+S45 -> 11418.932 | T46: =T44+T45 -> 12718.893 | Z46: Implied Enterprise Value (EURm; IFRS 16 basis) | AE46: =AE44+AE45 -> 5514.4883 | AF46: =AF44+AF45 -> 5808.6186
B47: Implied EV / Adjusted EBITDA (x) | G47: =IFERROR(G46/G12,"") -> 14.203571 | H47: =IFERROR(H46/H12,"") -> 14.357563 | N47: Implied EV / Adjusted EBITDA (x) | S47: =IFERROR(S46/S12,"") -> 16.854801 | T47: =IFERROR(T46/T12,"") -> 17.083762 | Z47: Implied EV / Adjusted EBITDA (x) | AE47: =IFERROR(AE46/AE12,"") -> 10.732614 | AF47: =IFERROR(AF46/AF12,"") -> 10.785353

Sheet DCF
B2: DCF VALUATION — BRUNELLO CUCINELLI (BC)
B4: 1. WACC BUILD (EUR)
B5: Risk-free rate (EUR 10Y) | C5: 0.0325 | D5: EUR 10Y swap / Bund-BTP blend ~3.0–3.5%; update to market
B6: Equity risk premium | C6: 0.055 | D6: Mature-market ERP ~4.5% + Italy country premium ~1.0% (Damodaran)
B7: Levered beta | C7: 1.05 | D7: European luxury peers (Hermès, Moncler, Prada, Zegna, Kering) ~0.9–1.2; high-end positioning and low leverage
B8: Cost of equity | C8: =C5+C7*C6 -> 0.09025
B9: Pre-tax cost of debt | C9: 0.04 | D9: Unrated; bank loans at Euribor + spread (FY25 loan interest ~3.1% of average bank debt)
B10: Tax rate | C10: 0.285 | D10: Model 2027E+ effective tax rate (IRES 24% + IRAP 3.9%)
B11: After-tax cost of debt | C11: =C9*(1-C10) -> 0.0286
B12: Target D/V | C12: 0.03 | D12: Core net financial debt ~€140m at YE2026E vs ~€5.5bn market cap; leases treated as operating costs (pre-IFRS 16 DCF)
B13: WACC | C13: =C8*(1-C12)+C11*C12 -> 0.0884005
B15: Valuation date (live) | C15: =TODAY() -> 46301 | D15: Periods = (Dec-31-Year − today) / 365.25; cash flows assumed at period end. Valuation from the 30-Jun-26 balance sheet: H2/26E is the first explicit period.
B16: 2. UNLEVERED FREE CASH FLOW BUILD — pre-IFRS 16 basis (rents as operating costs; EURm)
D17: H2/26E | E17: 2027E | F17: 2028E | G17: 2029E | H17: 2030E | I17: 2031E | J17: 2032E | K17: 2033E | L17: 2034E | M17: 2035E | N17: Terminal
B18: Adjusted EBIT pre-IFRS 16 | D18: =Model!AW173 -> 119.97992 | E18: =Model!AY173 -> 254.7667 | F18: =Model!AZ173 -> 287.51102 | G18: =Model!BA173 -> 321.70738 | H18: =Model!BB173 -> 352.72246 | I18: =H18*(1+I$26) -> 377.41304 | J18: =I18*(1+J$26) -> 401.47312 | K18: =J18*(1+K$26) -> 424.55782 | L18: =K18*(1+L$26) -> 446.31641 | M18: =L18*(1+M$26) -> 466.40065
B19: × (1 − tax rate) | D19: =1-$C$10 -> 0.715 | E19: =1-$C$10 -> 0.715 | F19: =1-$C$10 -> 0.715 | G19: =1-$C$10 -> 0.715 | H19: =1-$C$10 -> 0.715 | I19: =1-$C$10 -> 0.715 | J19: =1-$C$10 -> 0.715 | K19: =1-$C$10 -> 0.715 | ... M19: =1-$C$10 -> 0.715
B20: NOPAT | D20: =D18*D19 -> 85.785644 | E20: =E18*E19 -> 182.15819 | F20: =F18*F19 -> 205.57038 | G20: =G18*G19 -> 230.02077 | H20: =H18*H19 -> 252.19656 | I20: =I18*I19 -> 269.85032 | J20: =J18*J19 -> 287.05328 | K20: =K18*K19 -> 303.55884 | ... M20: =M18*M19 -> 333.47646
B21: plus D&A excl. right-of-use | D21: =-Model!AW106 -> 32.182258 | E21: =-Model!AY106 -> 69.163389 | F21: =-Model!AZ106 -> 74.888209 | G21: =-Model!BA106 -> 78.702165 | H21: =-Model!BB106 -> 84.341528 | I21: =H21*(1+I$26) -> 90.245435 | J21: =I21*(1+J$26) -> 95.998581 | K21: =J21*(1+K$26) -> 101.5185 | L21: =K21*(1+L$26) -> 106.72132 | M21: =L21*(1+M$26) -> 111.52378
B22: − Capex (PP&E + intangibles) | D22: =Model!AW221+Model!AW222 -> -39.946 | E22: =Model!AY221+Model!AY222 -> -109.64927 | F22: =Model!AZ221+Model!AZ222 -> -118.72521 | G22: =Model!BA221+Model!BA222 -> -127.89102 | H22: =Model!BB221+Model!BB222 -> -137.05498 | I22: =H22*(1+I$26) -> -146.64883 | J22: =I22*(1+J$26) -> -155.99769 | K22: =J22*(1+K$26) -> -164.96756 | L22: =K22*(1+L$26) -> -173.42215 | M22: =L22*(1+M$26) -> -181.22615
B23: − Δ Working capital (CF statement) | D23: =Model!AW216+Model!AW217+Model!AW218 -> 10.826066 | E23: =Model!AY216+Model!AY217+Model!AY218 -> -35.291551 | F23: =Model!AZ216+Model!AZ217+Model!AZ218 -> -32.728693 | G23: =Model!BA216+Model!BA217+Model!BA218 -> -33.182956 | H23: =Model!BB216+Model!BB217+Model!BB218 -> -32.795606 | I23: =H23*(1+I$26) -> -35.091299 | J23: =I23*(1+J$26) -> -37.328369 | K23: =J23*(1+K$26) -> -39.47475 | L23: =K23*(1+L$26) -> -41.497831 | M23: =L23*(1+M$26) -> -43.365233
B24: Unlevered FCF | D24: =D20+D21+D22+D23 -> 88.847968 | E24: =E20+E21+E22+E23 -> 106.38076 | F24: =F20+F21+F22+F23 -> 129.00468 | G24: =G20+G21+G22+G23 -> 147.64897 | H24: =H20+H21+H22+H23 -> 166.6875 | I24: =I20+I21+I22+I23 -> 178.35563 | J24: =J20+J21+J22+J23 -> 189.7258 | K24: =K20+K21+K22+K23 -> 200.63503 | ... M24: =M20+M21+M22+M23 -> 220.40887 | N24: =M24*(1+$C$27) -> 227.02113
B25: Terminal Value (Gordon Growth) | N25: =N24/($C$13-$C$27) -> 3887.3149
B26: Fade-period growth (2031E–35E; 7% → 4.5% linear) | I26: 0.07 | J26: =I26+($M$26-$I$26)/4 -> 0.06375 | K26: =J26+($M$26-$I$26)/4 -> 0.0575 | L26: =K26+($M$26-$I$26)/4 -> 0.05125 | M26: 0.045
B27: Terminal growth rate | C27: 0.03
B29: Discount period (years) | D29: =MAX(0,(DATE(2026,12,31)-$C$15)/365.25) -> 0.23545517 | E29: =MAX(0,(DATE(2027,12,31)-$C$15)/365.25) -> 1.2347707 | F29: =MAX(0,(DATE(2028,12,31)-$C$15)/365.25) -> 2.2368241 | G29: =MAX(0,(DATE(2029,12,31)-$C$15)/365.25) -> 3.2361396 | H29: =MAX(0,(DATE(2030,12,31)-$C$15)/365.25) -> 4.2354552 | I29: =MAX(0,(DATE(2031,12,31)-$C$15)/365.25) -> 5.2347707 | J29: =MAX(0,(DATE(2032,12,31)-$C$15)/365.25) -> 6.2368241 | K29: =MAX(0,(DATE(2033,12,31)-$C$15)/365.25) -> 7.2361396 | L29: =MAX(0,(DATE(2034,12,31)-$C$15)/365.25) -> 8.2354552 | M29: =MAX(0,(DATE(2035,12,31)-$C$15)/365.25) -> 9.2347707 | N29: =M29 -> 9.2347707
B30: Discount factor | D30: =1/(1+$C$13)^D29 -> 0.98025237 | E30: =1/(1+$C$13)^E29 -> 0.90068795 | F30: =1/(1+$C$13)^F29 -> 0.82738964 | G30: =1/(1+$C$13)^G29 -> 0.76023266 | H30: =1/(1+$C$13)^H29 -> 0.69852664 | I30: =1/(1+$C$13)^I29 -> 0.64182912 | J30: =1/(1+$C$13)^J29 -> 0.58959684 | K30: =1/(1+$C$13)^K29 -> 0.54174086 | ... N30: =1/(1+$C$13)^N29 -> 0.45736665
B31: PV of UFCF | D31: =D24*D30 -> 87.093432 | E31: =E24*E30 -> 95.815866 | F31: =F24*F30 -> 106.73714 | G31: =G24*G30 -> 112.24757 | H31: =H24*H30 -> 116.43566 | I31: =I24*I30 -> 114.47384 | J31: =J24*J30 -> 111.86173 | K31: =K24*K30 -> 108.69219 | ... M31: =M24*M30 -> 100.80766 | N31: =N25*N30 -> 1777.9282
D32: DCF on a pre-IFRS 16 basis: Adjusted EBIT pre-IFRS 16 deducts all rents (fixed & variable) as operating costs, so lease liabilities are NOT deducted from EV (consistent treatment). H2/26E UFCF is valued against the 30-Jun-26 net financial debt.
B33: IMPLIED ROIC — invested capital roll-forward (EURm; pre-IFRS 16, excl. right-of-use / lease liabilities)
B34: Opening invested capital | D34: =Model!AV279+Model!AV300-Model!AV262+Model!AV304 -> 870.302 | E34: =D38 -> 867.23968 | F34: =E38 -> 943.01711 | G34: =F38 -> 1019.5828 | H34: =G38 -> 1101.9546 | I34: =H38 -> 1187.4637 | J34: =I38 -> 1278.9584 | K34: =J38 -> 1376.2859 | L34: =K38 -> 1479.2097 | M34: =L38 -> 1587.4083
B35: plus Capex | D35: =-D22 -> 39.946 | E35: =-E22 -> 109.64927 | F35: =-F22 -> 118.72521 | G35: =-G22 -> 127.89102 | H35: =-H22 -> 137.05498 | I35: =-I22 -> 146.64883 | J35: =-J22 -> 155.99769 | K35: =-K22 -> 164.96756 | ... M35: =-M22 -> 181.22615
B36: less D&A excl. right-of-use | D36: =-D21 -> -32.182258 | E36: =-E21 -> -69.163389 | F36: =-F21 -> -74.888209 | G36: =-G21 -> -78.702165 | H36: =-H21 -> -84.341528 | I36: =-I21 -> -90.245435 | J36: =-J21 -> -95.998581 | K36: =-K21 -> -101.5185 | ... M36: =-M21 -> -111.52378
B37: plus Δ Working capital investment | D37: =-D23 -> -10.826066 | E37: =-E23 -> 35.291551 | F37: =-F23 -> 32.728693 | G37: =-G23 -> 33.182956 | H37: =-H23 -> 32.795606 | I37: =-I23 -> 35.091299 | J37: =-J23 -> 37.328369 | K37: =-K23 -> 39.47475 | ... M37: =-M23 -> 43.365233
B38: Closing invested capital | D38: =SUM(D34:D37) -> 867.23968 | E38: =SUM(E34:E37) -> 943.01711 | F38: =SUM(F34:F37) -> 1019.5828 | G38: =SUM(G34:G37) -> 1101.9546 | H38: =SUM(H34:H37) -> 1187.4637 | I38: =SUM(I34:I37) -> 1278.9584 | J38: =SUM(J34:J37) -> 1376.2859 | K38: =SUM(K34:K37) -> 1479.2097 | ... M38: =SUM(M34:M37) -> 1700.4759
B39: NOPAT (row 20) | D39: =D20 -> 85.785644 | E39: =E20 -> 182.15819 | F39: =F20 -> 205.57038 | G39: =G20 -> 230.02077 | H39: =H20 -> 252.19656 | I39: =I20 -> 269.85032 | J39: =J20 -> 287.05328 | K39: =K20 -> 303.55884 | ... M39: =M20 -> 333.47646
B40: Implied ROIC (NOPAT / avg. invested capital; H2/26E annualised) | D40: =IFERROR(D39/AVERAGE(D34,D38)*2,"") -> 0.19748739 | E40: =IFERROR(E39/AVERAGE(E34,E38)*1,"") -> 0.20125122 | F40: =IFERROR(F39/AVERAGE(F34,F38)*1,"") -> 0.20948781 | G40: =IFERROR(G39/AVERAGE(G34,G38)*1,"") -> 0.21684348 | H40: =IFERROR(H39/AVERAGE(H34,H38)*1,"") -> 0.22031497 | I40: =IFERROR(I39/AVERAGE(I34,I38)*1,"") -> 0.21881926 | J40: =IFERROR(J39/AVERAGE(J34,J38)*1,"") -> 0.2162161 | K40: =IFERROR(K39/AVERAGE(K34,K38)*1,"") -> 0.21261378 | L40: =IFERROR(L39/AVERAGE(L34,L38)*1,"") -> 0.20812259 | M40: =IFERROR(M39/AVERAGE(M34,M38)*1,"") -> 0.20285171
