Workbook

Sheet Model
BV1: SCENARIO SWITCH ▼ (Bull / Base / Bear) — drives all scenario-linked forecast drivers
B2: BWX Technologies, Inc. (NYSE: BWXT) — 3-Statement Financial Model | BV2: Base
B3: US GAAP as reported · USD millions (per-share data in USD; shares in millions) · Source: BWXT Forms 10-K / 10-Q and Form 8-K earnings releases (Ex. 99.1), convertible-note 8-Ks (Nov-2025), SEC EDGAR CIK 0001486957 (investor-relations releases at investors.bwxt.com are the same documents as filed on EDGAR); Form 4 for the share price
B4: Basis notes: calendar fiscal year. Power Generation (Babcock & Wilcox Enterprises) spun off 30-Jun-2015 → discontinued operations; 2012–13 annual and Q1/14–Q1/15 on the recast continuing-operations basis (Q1/14 = 6M/14 − Q2/14; balance sheets from Dec-14 recast). Later periods as originally reported (2017 and earlier: pension MTM within operating income; ASU 2017-07 from 2018). Segments: Government / Commercial Operations from 2022 (2020 annual and 2021 quarters recast); legacy NOG/NSG/NPG memo. Kinectrics from 20-May-2025; A.O.T. 2025; PCG from 1-Jul-2026; medical business (BWXT Medical + Kinectrics isotopes) sale to Nordic Capital agreed 31-Jul-2026 — modelled to close 31-Mar-2027.
BX5: Forecast | BY5: Historical | BZ5: Historical | CA5: Historical
B6: (USDm) | C6: 2012 | D6: 2013 | E6: Q1/14 | F6: Q2/14 | G6: Q3/14 | H6: Q4/14 | I6: 2014 | J6: Q1/15 | K6: Q2/15 | L6: Q3/15 | M6: Q4/15 | N6: 2015 | O6: Q1/16 | P6: Q2/16 | Q6: Q3/16 | R6: Q4/16 | S6: 2016 | T6: Q1/17 | U6: Q2/17 | V6: Q3/17 | W6: Q4/17 | X6: 2017 | Y6: Q1/18 | Z6: Q2/18 | AA6: Q3/18 | AB6: Q4/18 | AC6: 2018 | AD6: Q1/19 | AE6: Q2/19 | AF6: Q3/19 | AG6: Q4/19 | AH6: 2019 | AI6: Q1/20 | AJ6: Q2/20 | AK6: Q3/20 | AL6: Q4/20 | AM6: 2020 | AN6: Q1/21 | AO6: Q2/21 | AP6: Q3/21 | AQ6: Q4/21 | AR6: 2021 | AS6: Q1/22 | AT6: Q2/22 | AU6: Q3/22 | AV6: Q4/22 | AW6: 2022 | AX6: Q1/23 | AY6: Q2/23 | AZ6: Q3/23 | BA6: Q4/23 | BB6: 2023 | BC6: Q1/24 | BD6: Q2/24 | BE6: Q3/24 | BF6: Q4/24 | BG6: 2024 | BH6: Q1/25 | BI6: Q2/25 | BJ6: Q3/25 | BK6: Q4/25 | BL6: 2025 | BM6: Q1/26 | BN6: Q2/26 | BO6: Q3/26E | BP6: Q4/26E | BQ6: 2026E | BR6: 2027E | BS6: 2028E | BT6: 2029E | BU6: 2030E | BV6: Modelling Notes | BX6: 5Y CAGR | BY6: 5Y CAGR | BZ6: 10Y CAGR | CA6: 12Y CAGR
BX7: 25-'30 | BY7: 20-'25 | BZ7: 15-'25 | CA7: 13-'25
B9: SEGMENT BUILD — GOVERNMENT OPERATIONS · COMMERCIAL OPERATIONS (backlog × book-to-bill → revenues → non-GAAP operating income → Adjusted EBITDA) | BV9: SEGMENT BUILD — modelling logic (bookings = revenues × book-to-bill; backlog roll-forward; non-GAAP margin → segment Adjusted EBITDA) | CD9: SCENARIO INPUT TABLE — driver assumptions per Bull / Base / Bear | CE9: Bull | CF9: Base | CG9: Bear | CH9: Bull / Bear = Base + Δ (Δ inputs on each block header). Outlook block: High / Mid / Low guidance end-points.
B11: Government Operations (naval nuclear reactors & fuel, special materials / HEU down-blending, advanced reactors, technical-services JVs) — reported from 2022 (2020–21 recast) | BV11: GOVERNMENT OPERATIONS — modelling logic | CD11: FY26 outlook — Q2-26 release (3-Aug-26); includes PCG from 1-Jul-26 | CE11: High | CF11: Mid | CG11: Low | CH11: Company does not give GAAP guidance. Medical business still consolidated in 2026.
B12: Opening backlog | AN12: =AM19 -> 3680.126 | AO12: =AN19 -> 4495.617 | AP12: =AO19 -> 4174.767 | AQ12: =AP19 -> 3813.289 | AR12: =AM19 -> 3680.126 | AS12: =AR19 -> 4532.17 | AT12: =AS19 -> 4158.335 | AU12: =AT19 -> 3989.3 | AV12: =AU19 -> 3686.469 | AW12: =AR19 -> 4532.17 | AX12: =AW19 -> 3515.377 | AY12: =AX19 -> 3108.628 | AZ12: =AY19 -> 3405.716 | BA12: =AZ19 -> 3258.877 | BB12: =AW19 -> 3515.377 | BC12: =BB19 -> 3216.673 | BD12: =BC19 -> 2908.986 | BE12: =BD19 -> 2865.193 | BF12: =BE19 -> 2745.333 | BG12: =BB19 -> 3216.673 | BH12: =BG19 -> 3912.58 | BI12: =BH19 -> 3583.69 | BJ12: =BI19 -> 4435.593 | BK12: =BJ19 -> 5905.02 | BL12: =BG19 -> 3912.58 | BM12: =BL19 -> 5541.291 | BN12: =BM19 -> 6931.111 | BO12: =BN19 -> 6797.627 | BP12: =BO19 -> 6797.627 | BQ12: =BL19 -> 5541.291 | BR12: =BQ19 -> 6797.627 | BS12: =BR19 -> 6928.9501 | BT12: =BS19 -> 7070.7791 | BU12: =BT19 -> 7222.5361 | BV12: Prior period-end backlog (Q1 = prior year-end). | CD12: FY26 revenues ($m) | CE12: 3850 | CF12: 3800 | CG12: 3750 | CH12: ~$3,800m (raised from >$3,750m in Q1, ~$3,750m in Feb-26).
B13: Bookings | AM13: 889.844 | AN13: 1236.546 | AO13: 82.751 | AP13: 53.989 | AQ13: 1196.527 | AR13: 2569.813 | AS13: 57.019 | AT13: 222.127 | AU13: 119.086 | AV13: 345.22 | AW13: 743.452 | AX13: 52.737 | AY13: 788.668 | AZ13: 330.801 | BA13: 559.412 | BB13: 1731.618 | BC13: 179.413 | BD13: 497.021 | BE13: 440.146 | BF13: 1762.228 | BG13: 2878.808 | BH13: 226.397 | BI13: 1412.286 | BJ13: 2086.092 | BK13: 225.397 | BL13: 3950.171 | BM13: 1967.644 | BN13: 467.619 | BO13: =BO15*BO14 -> 640.6692 | BP13: =BP15*BP14 -> 612.04828 | BQ13: =SUM(BM13:BP13) -> 3687.9805 | BR13: =BR15*BR14 -> 2757.7853 | BS13: =BS15*BS14 -> 2978.4082 | BT13: =BT15*BT14 -> 3186.8967 | BU13: =BU15*BU14 -> 3409.9795 | BV13: Forecast = revenues × book-to-bill. Naval awards are lumpy (multi-year Navy contract options), so quarterly book-to-bill is set at 1.0x. | BX13: =IFERROR((BU13/BL13)^(1/5)-1,"n/m") -> -0.028982237 | BY13: =IFERROR((BL13/AM13)^(1/5)-1,"n/m") -> 0.34728788 | BZ13: =IFERROR((BL13/N13)^(1/10)-1,"n/m") -> n/m | CA13: =IFERROR((BL13/D13)^(1/12)-1,"n/m") -> n/m | CD13: FY26 Adjusted EBITDA ($m) | CE13: 672 | CF13: 667 | CG13: 662 | CH13: $662–672m (raised from $650–665m). Drives the Q3/Q4-26E margin calibration.
B14: Book-to-bill (x) | C14: =IF(AND(ISNUMBER(C13),ISNUMBER(C15)),IFERROR(C13/C15,""),"") | D14: =IF(AND(ISNUMBER(D13),ISNUMBER(D15)),IFERROR(D13/D15,""),"") | E14: =IF(AND(ISNUMBER(E13),ISNUMBER(E15)),IFERROR(E13/E15,""),"") | F14: =IF(AND(ISNUMBER(F13),ISNUMBER(F15)),IFERROR(F13/F15,""),"") | G14: =IF(AND(ISNUMBER(G13),ISNUMBER(G15)),IFERROR(G13/G15,""),"") | H14: =IF(AND(ISNUMBER(H13),ISNUMBER(H15)),IFERROR(H13/H15,""),"") | I14: =IF(AND(ISNUMBER(I13),ISNUMBER(I15)),IFERROR(I13/I15,""),"") | J14: =IF(AND(ISNUMBER(J13),ISNUMBER(J15)),IFERROR(J13/J15,""),"") | ... BN14: =IF(AND(ISNUMBER(BN13),ISNUMBER(BN15)),IFERROR(BN13/BN15,""),"") -> 0.77769167 | BO14: 1 | BP14: 1 | BQ14: =IF(AND(ISNUMBER(BQ13),ISNUMBER(BQ15)),IFERROR(BQ13/BQ15,""),"") -> 1.5164958 | BR14: =CHOOSE(MATCH($BV$2,{"Bull","Base","Bear"},0),$CE$33,$CF$33,$CG$33) -> 1.05 | BS14: =CHOOSE(MATCH($BV$2,{"Bull","Base","Bear"},0),$CE$34,$CF$34,$CG$34) -> 1.05 | BT14: =CHOOSE(MATCH($BV$2,{"Bull","Base","Bear"},0),$CE$35,$CF$35,$CG$35) -> 1.05 | BU14: =CHOOSE(MATCH($BV$2,{"Bull","Base","Bear"},0),$CE$36,$CF$36,$CG$36) -> 1.05 | BV14: 2027E+: scenario lever GOV_btb (Bull / Base / Bear table →). 2021–25 average ~1.4x incl. the 2023/2025 naval awards. | CD14: FY26 non-GAAP EPS ($) | CE14: 4.8 | CF14: 4.75 | CG14: 4.7 | CH14: $4.70–4.80 (memo; compared with the model, not forced).
B15: Revenues | AM15: 1763.127 | AN15: 423.275 | AO15: 405.497 | AP15: 417.139 | AQ15: 479.186 | AR15: 1725.097 | AS15: 431.777 | AT15: 436.537 | AU15: 422.521 | AV15: 517.648 | AW15: 1808.483 | AX15: 459.886 | AY15: 491.967 | AZ15: 477.855 | BA15: 601.629 | BB15: 2031.337 | BC15: 487.121 | BD15: 540.846 | BE15: 560.073 | BF15: 595 | BG15: 2183.04 | BH15: 555.286 | BI15: 588.959 | BJ15: 616.697 | BK15: 589.147 | BL15: 2350.09 | BM15: 577.901 | BN15: 601.291 | BO15: =BJ15*(1+BO17) -> 640.6692 | BP15: =BK15*(1+BP17) -> 612.04828 | BQ15: =SUM(BM15:BP15) -> 2431.9095 | BR15: =BQ15*(1+BR17) -> 2626.4622 | BS15: =BR15*(1+BS17) -> 2836.5792 | BT15: =BS15*(1+BT17) -> 3035.1398 | BU15: =BT15*(1+BU17) -> 3247.5995 | BV15: Q3/26E–Q4/26E: prior-year quarter × (1 + 1H/26 y/y growth + revenue-outlook calibration Δ). 2027E+: prior year × (1 + GOV_growth). | BX15: =IFERROR((BU15/BL15)^(1/5)-1,"n/m") -> 0.066830922 | BY15: =IFERROR((BL15/AM15)^(1/5)-1,"n/m") -> 0.059156607 | BZ15: =IFERROR((BL15/N15)^(1/10)-1,"n/m") -> n/m | CA15: =IFERROR((BL15/D15)^(1/12)-1,"n/m") -> n/m | CD15: FY26 free cash flow ($m) | CE15: 360 | CF15: 352.5 | CG15: 345 | CH15: $345–360m (memo).
B16: Q3/Q4-26E growth input — 1H/26 y/y (before revenue calibration) | BO16: =SUM(BM15,BN15)/SUM(BH15,BI15)-1 -> 0.030541536 | BP16: =SUM(BM15,BN15)/SUM(BH15,BI15)-1 -> 0.030541536 | BV16: 1H/26 Government Operations revenue growth (+3.1% y/y; naval propulsion & special materials up, microreactor volumes down).
B17: Revenues y/y % | D17: =IF(AND(ISNUMBER(D15),ISNUMBER(C15)),IFERROR(D15/C15-1,""),"") | I17: =IF(AND(ISNUMBER(I15),ISNUMBER(D15)),IFERROR(I15/D15-1,""),"") | J17: =IF(AND(ISNUMBER(J15),ISNUMBER(E15)),IFERROR(J15/E15-1,""),"") | K17: =IF(AND(ISNUMBER(K15),ISNUMBER(F15)),IFERROR(K15/F15-1,""),"") | L17: =IF(AND(ISNUMBER(L15),ISNUMBER(G15)),IFERROR(L15/G15-1,""),"") | M17: =IF(AND(ISNUMBER(M15),ISNUMBER(H15)),IFERROR(M15/H15-1,""),"") | N17: =IF(AND(ISNUMBER(N15),ISNUMBER(I15)),IFERROR(N15/I15-1,""),"") | O17: =IF(AND(ISNUMBER(O15),ISNUMBER(J15)),IFERROR(O15/J15-1,""),"") | P17: =IF(AND(ISNUMBER(P15),ISNUMBER(K15)),IFERROR(P15/K15-1,""),"") | ... BN17: =IF(AND(ISNUMBER(BN15),ISNUMBER(BI15)),IFERROR(BN15/BI15-1,""),"") -> 0.020938639 | BO17: =BO16+BO118 -> 0.038871923 | BP17: =BP16+BP118 -> 0.038871923 | BQ17: =IF(AND(ISNUMBER(BQ15),ISNUMBER(BL15)),IFERROR(BQ15/BL15-1,""),"") -> 0.034815464 | BR17: =CHOOSE(MATCH($BV$2,{"Bull","Base","Bear"},0),$CE$23,$CF$23,$CG$23) -> 0.08 | BS17: =CHOOSE(MATCH($BV$2,{"Bull","Base","Bear"},0),$CE$24,$CF$24,$CG$24) -> 0.08 | BT17: =CHOOSE(MATCH($BV$2,{"Bull","Base","Bear"},0),$CE$25,$CF$25,$CG$25) -> 0.07 | BU17: =CHOOSE(MATCH($BV$2,{"Bull","Base","Bear"},0),$CE$26,$CF$26,$CG$26) -> 0.07 | BV17: 2027E–2030E: scenario lever GOV_growth (Columbia/Virginia-class build rates, naval fuel, special materials / DUECE, TRISO). | BX17: =IFERROR(AVERAGE(BQ17,BR17,BS17,BT17,BU17),"n/m") -> 0.066963093 | BY17: =IFERROR(AVERAGE(AR17,AW17,BB17,BG17,BL17),"n/m") -> 0.060239497 | BZ17: =IFERROR(AVERAGE(S17,X17,AC17,AH17,AM17,AR17,AW17,BB17,BG17,BL17),"n/m") -> 0.060239497 | CA17: =IFERROR(AVERAGE(D17,I17,N17,S17,X17,AC17,AH17,AM17,AR17,AW17,BB17,BG17,BL17),"n/m") -> 0.060239497 | CD17: Capital allocation & transactions | CE17: Bull | CF17: Base | CG17: Bear
B18: Backlog adjustments, FX & de-bookings (derived) | AN18: =AN19-AN12-AN13+AN15 -> 2.22 | AO18: =AO19-AO12-AO13+AO15 -> 1.896 | AP18: =AP19-AP12-AP13+AP15 -> 1.672 | AQ18: =AQ19-AQ12-AQ13+AQ15 -> 1.54 | AR18: =AR19-AR12-AR13+AR15 -> 7.328 | AS18: =AS19-AS12-AS13+AS15 -> 0.923 | AT18: =AT19-AT12-AT13+AT15 -> 45.375 | AU18: =AU19-AU12-AU13+AU15 -> 0.604 | ... BN18: =BN19-BN12-BN13+BN15 -> 0.188 | BO18: 0 | BP18: 0 | BQ18: =SUM(BM18:BP18) -> 0.265 | BR18: 0 | BS18: 0 | BT18: 0 | BU18: 0 | BV18: Historical = closing − opening − bookings + revenues (unfunded options, FX, scope changes). Forecast: nil. | CD18: 2H/26 share repurchases ($m) | CE18: 0 | CF18: 0 | CG18: 0 | CH18: No buybacks in 1H/26; PCG funded from cash.
B19: Closing backlog | AM19: 3680.126 | AN19: 4495.617 | AO19: 4174.767 | AP19: 3813.289 | AQ19: 4532.17 | AR19: 4532.17 | AS19: 4158.335 | AT19: 3989.3 | AU19: 3686.469 | AV19: 3515.377 | AW19: 3515.377 | AX19: 3108.628 | AY19: 3405.716 | AZ19: 3258.877 | BA19: 3216.673 | BB19: 3216.673 | BC19: 2908.986 | BD19: 2865.193 | BE19: 2745.333 | BF19: 3912.58 | BG19: 3912.58 | BH19: 3583.69 | BI19: 4435.593 | BJ19: 5905.02 | BK19: 5541.291 | BL19: 5541.291 | BM19: 6931.111 | BN19: 6797.627 | BO19: =BO12+BO13-BO15+BO18 -> 6797.627 | BP19: =BP12+BP13-BP15+BP18 -> 6797.627 | BQ19: =BP19 -> 6797.627 | BR19: =BR12+BR13-BR15+BR18 -> 6928.9501 | BS19: =BS12+BS13-BS15+BS18 -> 7070.7791 | BT19: =BT12+BT13-BT15+BT18 -> 7222.5361 | BU19: =BU12+BU13-BU15+BU18 -> 7384.916 | BV19: Backlog at 30-Jun-26: $6.80bn (Government) — c.2.9x LTM segment revenues. | BX19: =IFERROR((BU19/BL19)^(1/5)-1,"n/m") -> 0.059124272 | BY19: =IFERROR((BL19/AM19)^(1/5)-1,"n/m") -> 0.085299627 | BZ19: =IFERROR((BL19/N19)^(1/10)-1,"n/m") -> n/m | CA19: =IFERROR((BL19/D19)^(1/12)-1,"n/m") -> n/m | CD19: Medical sale cash consideration ($m) | CE19: 800 | CF19: 750 | CG19: 750 | CH19: $750m base; up to $800m with shared economics (Q2-26 call).
B20: Closing backlog ÷ annual revenues (years of coverage) | C20: =IF(AND(ISNUMBER(C19),ISNUMBER(C15)),IFERROR(C19/C15,""),"") | D20: =IF(AND(ISNUMBER(D19),ISNUMBER(D15)),IFERROR(D19/D15,""),"") | I20: =IF(AND(ISNUMBER(I19),ISNUMBER(I15)),IFERROR(I19/I15,""),"") | N20: =IF(AND(ISNUMBER(N19),ISNUMBER(N15)),IFERROR(N19/N15,""),"") | S20: =IF(AND(ISNUMBER(S19),ISNUMBER(S15)),IFERROR(S19/S15,""),"") | X20: =IF(AND(ISNUMBER(X19),ISNUMBER(X15)),IFERROR(X19/X15,""),"") | AC20: =IF(AND(ISNUMBER(AC19),ISNUMBER(AC15)),IFERROR(AC19/AC15,""),"") | AH20: =IF(AND(ISNUMBER(AH19),ISNUMBER(AH15)),IFERROR(AH19/AH15,""),"") | AM20: =IF(AND(ISNUMBER(AM19),ISNUMBER(AM15)),IFERROR(AM19/AM15,""),"") -> 2.0872722 | AR20: =IF(AND(ISNUMBER(AR19),ISNUMBER(AR15)),IFERROR(AR19/AR15,""),"") -> 2.6271972 | AW20: =IF(AND(ISNUMBER(AW19),ISNUMBER(AW15)),IFERROR(AW19/AW15,""),"") -> 1.9438264 | BB20: =IF(AND(ISNUMBER(BB19),ISNUMBER(BB15)),IFERROR(BB19/BB15,""),"") -> 1.583525 | BG20: =IF(AND(ISNUMBER(BG19),ISNUMBER(BG15)),IFERROR(BG19/BG15,""),"") -> 1.7922622 | BL20: =IF(AND(ISNUMBER(BL19),ISNUMBER(BL15)),IFERROR(BL19/BL15,""),"") -> 2.3579059 | BQ20: =IF(AND(ISNUMBER(BQ19),ISNUMBER(BQ15)),IFERROR(BQ19/BQ15,""),"") -> 2.7951809 | BR20: =IF(AND(ISNUMBER(BR19),ISNUMBER(BR15)),IFERROR(BR19/BR15,""),"") -> 2.6381305 | BS20: =IF(AND(ISNUMBER(BS19),ISNUMBER(BS15)),IFERROR(BS19/BS15,""),"") -> 2.4927134 | BT20: =IF(AND(ISNUMBER(BT19),ISNUMBER(BT15)),IFERROR(BT19/BT15,""),"") -> 2.3796387 | BU20: =IF(AND(ISNUMBER(BU19),ISNUMBER(BU15)),IFERROR(BU19/BU15,""),"") -> 2.2739614 | CD20: Minimum net debt / Adjusted EBITDA (x) — buyback floor 2027E+ | CE20: 2 | CF20: 1.5 | CG20: 1 | CH20: Buybacks resume once leverage falls to the floor.
B21: Operating income (GAAP; incl. equity income of technical-services JVs) | AM21: 345.25 | AN21: 78.245 | AO21: 72.871 | AP21: 87.542 | AQ21: 90.891 | AR21: 329.549 | AS21: 72.231 | AT21: 83.783 | AU21: 77.735 | AV21: 102.752 | AW21: 336.501 | AX21: 90.56 | AY21: 82.208 | AZ21: 85.632 | BA21: 116.282 | BB21: 374.682 | BC21: 85.686 | BD21: 92.52 | BE21: 101.609 | BF21: 98.059 | BG21: 377.875 | BH21: 97.746 | BI21: 109.417 | BJ21: 97.371 | BK21: 90.314 | BL21: 394.85 | BM21: 99.141 | BN21: 105.678 | BO21: =BO24-BO23 -> 107.21967 | BP21: =BP24-BP23 -> 98.818983 | BQ21: =SUM(BM21:BP21) -> 410.85766 | BR21: =BR24-BR23 -> 455.13089 | BS21: =BS24-BS23 -> 498.99281 | BT21: =BT24-BT23 -> 541.82516 | BU21: =BU24-BU23 -> 580.06792 | BV21: Forecast = non-GAAP operating income − non-GAAP adjustments allocated to the segment. | BX21: =IFERROR((BU21/BL21)^(1/5)-1,"n/m") -> 0.079964154 | BY21: =IFERROR((BL21/AM21)^(1/5)-1,"n/m") -> 0.02721107 | BZ21: =IFERROR((BL21/N21)^(1/10)-1,"n/m") -> n/m | CA21: =IFERROR((BL21/D21)^(1/12)-1,"n/m") -> n/m
B22: Operating margin (GAAP) % | C22: =IF(AND(ISNUMBER(C21),ISNUMBER(C15)),IFERROR(C21/C15,""),"") | D22: =IF(AND(ISNUMBER(D21),ISNUMBER(D15)),IFERROR(D21/D15,""),"") | E22: =IF(AND(ISNUMBER(E21),ISNUMBER(E15)),IFERROR(E21/E15,""),"") | F22: =IF(AND(ISNUMBER(F21),ISNUMBER(F15)),IFERROR(F21/F15,""),"") | G22: =IF(AND(ISNUMBER(G21),ISNUMBER(G15)),IFERROR(G21/G15,""),"") | H22: =IF(AND(ISNUMBER(H21),ISNUMBER(H15)),IFERROR(H21/H15,""),"") | I22: =IF(AND(ISNUMBER(I21),ISNUMBER(I15)),IFERROR(I21/I15,""),"") | J22: =IF(AND(ISNUMBER(J21),ISNUMBER(J15)),IFERROR(J21/J15,""),"") | ... BU22: =IF(AND(ISNUMBER(BU21),ISNUMBER(BU15)),IFERROR(BU21/BU15,""),"") -> 0.17861436 | BX22: =IFERROR(AVERAGE(BQ22,BR22,BS22,BT22,BU22),"n/m") -> 0.17505529 | BY22: =IFERROR(AVERAGE(AR22,AW22,BB22,BG22,BL22),"n/m") -> 0.18053236 | BZ22: =IFERROR(AVERAGE(S22,X22,AC22,AH22,AM22,AR22,AW22,BB22,BG22,BL22),"n/m") -> 0.18307978 | CA22: =IFERROR(AVERAGE(D22,I22,N22,S22,X22,AC22,AH22,AM22,AR22,AW22,BB22,BG22,BL22),"n/m") -> 0.18307978 | CD22: GOV_growth (Government Operations revenues y/y) | CE22: 0.02 | CF22: Δ → | CG22: -0.025 | CH22: Naval propulsion (Columbia 1+1 / Virginia 2/yr build rates), naval fuel, special materials & DUECE enrichment, TRISO / microreactors; FY21–25 CAGR 7.5%.
B23: Non-GAAP adjustments (restructuring, acquisition costs & amortization) | AM23: =AM24-AM21 -> 0.956 | AN23: =AN24-AN21 -> 0 | AO23: =AO24-AO21 -> 0 | AP23: =AP24-AP21 -> 0.165 | AQ23: =AQ24-AQ21 -> 0 | AR23: =AR24-AR21 -> 0.165 | AS23: =AS24-AS21 -> 1.3 | AT23: =AT24-AT21 -> 0 | ... BN23: =BN24-BN21 -> 1.1 | BO23: =BN23 -> 1.1 | BP23: =BN23 -> 1.1 | BQ23: =SUM(BM23:BP23) -> 4.3 | BR23: =BR147*BR148 -> 4.5 | BS23: =BS147*BS148 -> 4.5 | BT23: =BT147*BT148 -> 4.5 | BU23: =BU147*BU148 -> 4.5 | BV23: Q3/Q4-26E: Q2/26 run-rate. 2027E+: Government share of legacy acquisition amortization (A.O.T., Kinectrics). | CD23: 2027E | CE23: =CF23+$CE$22 -> 0.1 | CF23: 0.08 | CG23: =CF23+$CG$22 -> 0.055
B24: Non-GAAP operating income | AM24: 346.206 | AN24: 78.245 | AO24: 72.871 | AP24: 87.707 | AQ24: 90.891 | AR24: 329.714 | AS24: 73.531 | AT24: 83.783 | AU24: 78.235 | AV24: 103.052 | AW24: 338.601 | AX24: 90.76 | AY24: 82.408 | AZ24: 85.632 | BA24: 117.182 | BB24: 376.082 | BC24: 85.686 | BD24: 92.82 | BE24: 101.709 | BF24: 100.559 | BG24: 380.875 | BH24: 100.646 | BI24: 115.617 | BJ24: 101.371 | BK24: 93.414 | BL24: 410.95 | BM24: 100.141 | BN24: 106.778 | BO24: =BO15*BO26 -> 108.31967 | BP24: =BP15*BP26 -> 99.918983 | BQ24: =SUM(BM24:BP24) -> 415.15766 | BR24: =BR15*BR26 -> 459.63089 | BS24: =BS15*BS26 -> 503.49281 | BT24: =BT15*BT26 -> 546.32516 | BU24: =BU15*BU26 -> 584.56792 | BV24: Company non-GAAP segment operating income (reconciliation tables, Ex. 99.1). | BX24: =IFERROR((BU24/BL24)^(1/5)-1,"n/m") -> 0.073023413 | BY24: =IFERROR((BL24/AM24)^(1/5)-1,"n/m") -> 0.034882109 | BZ24: =IFERROR((BL24/N24)^(1/10)-1,"n/m") -> n/m | CA24: =IFERROR((BL24/D24)^(1/12)-1,"n/m") -> n/m | CD24: 2028E | CE24: =CF24+$CE$22 -> 0.1 | CF24: 0.08 | CG24: =CF24+$CG$22 -> 0.055
B25: Non-GAAP margin before outlook calibration % (Q3/Q4-26E helper) | BO25: =BJ26+(SUM(BM24,BN24)/SUM(BM15,BN15)-SUM(BH24,BI24)/SUM(BH15,BI15)) -> 0.15085195 | BP25: =BK26+(SUM(BM24,BN24)/SUM(BM15,BN15)-SUM(BH24,BI24)/SUM(BH15,BI15)) -> 0.14503268 | BV25: Prior-year quarter margin + (1H/26 − 1H/25 margin drift). | CD25: 2029E | CE25: =CF25+$CE$22 -> 0.09 | CF25: 0.07 | CG25: =CF25+$CG$22 -> 0.045
B26: Non-GAAP operating margin % | C26: =IF(AND(ISNUMBER(C24),ISNUMBER(C15)),IFERROR(C24/C15,""),"") | D26: =IF(AND(ISNUMBER(D24),ISNUMBER(D15)),IFERROR(D24/D15,""),"") | E26: =IF(AND(ISNUMBER(E24),ISNUMBER(E15)),IFERROR(E24/E15,""),"") | F26: =IF(AND(ISNUMBER(F24),ISNUMBER(F15)),IFERROR(F24/F15,""),"") | G26: =IF(AND(ISNUMBER(G24),ISNUMBER(G15)),IFERROR(G24/G15,""),"") | H26: =IF(AND(ISNUMBER(H24),ISNUMBER(H15)),IFERROR(H24/H15,""),"") | I26: =IF(AND(ISNUMBER(I24),ISNUMBER(I15)),IFERROR(I24/I15,""),"") | J26: =IF(AND(ISNUMBER(J24),ISNUMBER(J15)),IFERROR(J24/J15,""),"") | ... BN26: =IF(AND(ISNUMBER(BN24),ISNUMBER(BN15)),IFERROR(BN24/BN15,""),"") -> 0.17758124 | BO26: =BO25+BO121 -> 0.1690727 | BP26: =BP25+BP121 -> 0.16325343 | BQ26: =IF(AND(ISNUMBER(BQ24),ISNUMBER(BQ15)),IFERROR(BQ24/BQ15,""),"") -> 0.17071263 | BR26: =CHOOSE(MATCH($BV$2,{"Bull","Base","Bear"},0),$CE$28,$CF$28,$CG$28) -> 0.175 | BS26: =CHOOSE(MATCH($BV$2,{"Bull","Base","Bear"},0),$CE$29,$CF$29,$CG$29) -> 0.1775 | BT26: =CHOOSE(MATCH($BV$2,{"Bull","Base","Bear"},0),$CE$30,$CF$30,$CG$30) -> 0.18 | BU26: =CHOOSE(MATCH($BV$2,{"Bull","Base","Bear"},0),$CE$31,$CF$31,$CG$31) -> 0.18 | BV26: Q3/Q4-26E: margin before calibration + Adjusted EBITDA outlook calibration Δ. 2027E+: scenario lever GOV_margin. | BX26: =IFERROR(AVERAGE(BQ26,BR26,BS26,BT26,BU26),"n/m") -> 0.17664253 | BY26: =IFERROR(AVERAGE(AR26,AW26,BB26,BG26,BL26),"n/m") -> 0.18256658 | BZ26: =IFERROR(AVERAGE(S26,X26,AC26,AH26,AM26,AR26,AW26,BB26,BG26,BL26),"n/m") -> 0.18486533 | CA26: =IFERROR(AVERAGE(D26,I26,N26,S26,X26,AC26,AH26,AM26,AR26,AW26,BB26,BG26,BL26),"n/m") -> 0.18486533 | CD26: 2030E | CE26: =CF26+$CE$22 -> 0.09 | CF26: 0.07 | CG26: =CF26+$CG$22 -> 0.045
B27: D&A (excl. acquisition amortization) % of revenues | C27: =IF(AND(ISNUMBER(C28),ISNUMBER(C15)),IFERROR(C28/C15,""),"") | D27: =IF(AND(ISNUMBER(D28),ISNUMBER(D15)),IFERROR(D28/D15,""),"") | E27: =IF(AND(ISNUMBER(E28),ISNUMBER(E15)),IFERROR(E28/E15,""),"") | F27: =IF(AND(ISNUMBER(F28),ISNUMBER(F15)),IFERROR(F28/F15,""),"") | G27: =IF(AND(ISNUMBER(G28),ISNUMBER(G15)),IFERROR(G28/G15,""),"") | H27: =IF(AND(ISNUMBER(H28),ISNUMBER(H15)),IFERROR(H28/H15,""),"") | I27: =IF(AND(ISNUMBER(I28),ISNUMBER(I15)),IFERROR(I28/I15,""),"") | J27: =IF(AND(ISNUMBER(J28),ISNUMBER(J15)),IFERROR(J28/J15,""),"") | ... BN27: =IF(AND(ISNUMBER(BN28),ISNUMBER(BN15)),IFERROR(BN28/BN15,""),"") -> 0.032692989 | BO27: =SUM(BM28,BN28)/SUM(BM15,BN15) -> 0.031538545 | BP27: =SUM(BM28,BN28)/SUM(BM15,BN15) -> 0.031538545 | BQ27: =IF(AND(ISNUMBER(BQ28),ISNUMBER(BQ15)),IFERROR(BQ28/BQ15,""),"") -> 0.031538545 | BR27: 0.036 | BS27: 0.037 | BT27: 0.038 | BU27: 0.038 | BV27: 1H/26 3.4%. Rising with the 2021–26 capacity build-out (naval, special materials, Erwin/NFS, Lynchburg). | CD27: GOV_margin (Government non-GAAP operating margin) | CE27: 0.01 | CF27: Δ → | CG27: -0.01 | CH27: FY25 17.5%; 1H/26 17.6%. Includes technical-services JV equity income.
B28: D&A excl. acquisition-related amortization | AM28: 35.398 | AN28: 9.171 | AO28: 10.334 | AP28: 10.928 | AQ28: 12.052 | AR28: 42.485 | AS28: 11.208 | AT28: 11.913 | AU28: 12.137 | AV28: 12.724 | AW28: 47.982 | AX28: 12.795 | AY28: 13.141 | AZ28: 13.417 | BA28: 14.035 | BB28: 53.388 | BC28: 14.234 | BD28: 15.431 | BE28: 15.284 | BF28: 16.079 | BG28: 61.027 | BH28: 16.296 | BI28: 17.422 | BJ28: 16.962 | BK28: 17.522 | BL28: 68.202 | BM28: 17.532 | BN28: 19.658 | BO28: =BO15*BO27 -> 20.205774 | BP28: =BP15*BP27 -> 19.303112 | BQ28: =SUM(BM28:BP28) -> 76.698887 | BR28: =BR15*BR27 -> 94.55264 | BS28: =BS15*BS27 -> 104.95343 | BT28: =BT15*BT27 -> 115.33531 | BU28: =BU15*BU27 -> 123.40878 | CD28: 2027E | CE28: =CF28+$CE$27 -> 0.185 | CF28: 0.175 | CG28: =CF28+$CG$27 -> 0.165
B29: Segment Adjusted EBITDA (non-GAAP OI + D&A ex amortization) | C29: =IF(AND(ISNUMBER(C24),ISNUMBER(C28)),C24+C28,"") | D29: =IF(AND(ISNUMBER(D24),ISNUMBER(D28)),D24+D28,"") | E29: =IF(AND(ISNUMBER(E24),ISNUMBER(E28)),E24+E28,"") | F29: =IF(AND(ISNUMBER(F24),ISNUMBER(F28)),F24+F28,"") | G29: =IF(AND(ISNUMBER(G24),ISNUMBER(G28)),G24+G28,"") | H29: =IF(AND(ISNUMBER(H24),ISNUMBER(H28)),H24+H28,"") | I29: =IF(AND(ISNUMBER(I24),ISNUMBER(I28)),I24+I28,"") | J29: =IF(AND(ISNUMBER(J24),ISNUMBER(J28)),J24+J28,"") | ... BN29: =IF(AND(ISNUMBER(BN24),ISNUMBER(BN28)),BN24+BN28,"") -> 126.436 | BO29: =BO24+BO28 -> 128.52545 | BP29: =BP24+BP28 -> 119.22209 | BQ29: =BQ24+BQ28 -> 491.85654 | BR29: =BR24+BR28 -> 554.18353 | BS29: =BS24+BS28 -> 608.44624 | BT29: =BT24+BT28 -> 661.66047 | BU29: =BU24+BU28 -> 707.9767 | BX29: =IFERROR((BU29/BL29)^(1/5)-1,"n/m") -> 0.081207705 | BY29: =IFERROR((BL29/AM29)^(1/5)-1,"n/m") -> 0.046579147 | BZ29: =IFERROR((BL29/N29)^(1/10)-1,"n/m") -> n/m | CA29: =IFERROR((BL29/D29)^(1/12)-1,"n/m") -> n/m | CD29: 2028E | CE29: =CF29+$CE$27 -> 0.1875 | CF29: 0.1775 | CG29: =CF29+$CG$27 -> 0.1675
B30: Segment Adjusted EBITDA margin % | C30: =IF(AND(ISNUMBER(C29),ISNUMBER(C15)),IFERROR(C29/C15,""),"") | D30: =IF(AND(ISNUMBER(D29),ISNUMBER(D15)),IFERROR(D29/D15,""),"") | E30: =IF(AND(ISNUMBER(E29),ISNUMBER(E15)),IFERROR(E29/E15,""),"") | F30: =IF(AND(ISNUMBER(F29),ISNUMBER(F15)),IFERROR(F29/F15,""),"") | G30: =IF(AND(ISNUMBER(G29),ISNUMBER(G15)),IFERROR(G29/G15,""),"") | H30: =IF(AND(ISNUMBER(H29),ISNUMBER(H15)),IFERROR(H29/H15,""),"") | I30: =IF(AND(ISNUMBER(I29),ISNUMBER(I15)),IFERROR(I29/I15,""),"") | J30: =IF(AND(ISNUMBER(J29),ISNUMBER(J15)),IFERROR(J29/J15,""),"") | ... BU30: =IF(AND(ISNUMBER(BU29),ISNUMBER(BU15)),IFERROR(BU29/BU15,""),"") -> 0.218 | BX30: =IFERROR(AVERAGE(BQ30,BR30,BS30,BT30,BU30),"n/m") -> 0.21275023 | BY30: =IFERROR(AVERAGE(AR30,AW30,BB30,BG30,BL30),"n/m") -> 0.20945008 | BZ30: =IFERROR(AVERAGE(S30,X30,AC30,AH30,AM30,AR30,AW30,BB30,BG30,BL30),"n/m") -> 0.21061438 | CA30: =IFERROR(AVERAGE(D30,I30,N30,S30,X30,AC30,AH30,AM30,AR30,AW30,BB30,BG30,BL30),"n/m") -> 0.21061438 | CD30: 2029E | CE30: =CF30+$CE$27 -> 0.19 | CF30: 0.18 | CG30: =CF30+$CG$27 -> 0.17
B31: Memo: segment Adjusted EBITDA as published (2022+) | AU31: 90.4 | AV31: 115.8 | AW31: 386.5 | AX31: 103.6 | AY31: 95.5 | AZ31: 99 | BA31: 131.3 | BB31: 429.4 | BC31: 99.9 | BD31: 108.2 | BE31: 117 | BF31: 116.7 | BG31: 441.9 | BH31: 116.9 | BI31: 133 | BJ31: 118.3 | BK31: 110.9 | BL31: 479.1 | BM31: 117.7 | BN31: 126.5 | CD31: 2030E | CE31: =CF31+$CE$27 -> 0.19 | CF31: 0.18 | CG31: =CF31+$CG$27 -> 0.17
B32: Check: model vs published segment Adjusted EBITDA (should be 0) | C32: =IF(AND(ISNUMBER(C29),ISNUMBER(C31)),ROUND(C29-C31,1),"") | D32: =IF(AND(ISNUMBER(D29),ISNUMBER(D31)),ROUND(D29-D31,1),"") | E32: =IF(AND(ISNUMBER(E29),ISNUMBER(E31)),ROUND(E29-E31,1),"") | F32: =IF(AND(ISNUMBER(F29),ISNUMBER(F31)),ROUND(F29-F31,1),"") | G32: =IF(AND(ISNUMBER(G29),ISNUMBER(G31)),ROUND(G29-G31,1),"") | H32: =IF(AND(ISNUMBER(H29),ISNUMBER(H31)),ROUND(H29-H31,1),"") | I32: =IF(AND(ISNUMBER(I29),ISNUMBER(I31)),ROUND(I29-I31,1),"") | J32: =IF(AND(ISNUMBER(J29),ISNUMBER(J31)),ROUND(J29-J31,1),"") | ... BN32: =IF(AND(ISNUMBER(BN29),ISNUMBER(BN31)),ROUND(BN29-BN31,1),"") -> -0.1 | CD32: GOV_btb (Government book-to-bill, x) | CE32: 0.15 | CF32: Δ → | CG32: -0.15 | CH32: FY21–25 average ~1.4x (multi-year naval awards in 2023 and 2025).
B33: Memo: segment capital expenditures | AM33: 137.197 | AN33: 45.945 | AO33: 30.073 | AP33: 34.155 | AQ33: 36.878 | AR33: 147.051 | AS33: 27.581 | AT33: 19.488 | AU33: 19.126 | AV33: 36.898 | AW33: 103.093 | AX33: 15.268 | AY33: 23.223 | AZ33: 19.624 | BA33: 33.584 | BB33: 91.699 | BC33: 16.383 | BD33: 14.201 | BE33: 22.429 | BF33: 28.05 | BG33: 81.063 | BH33: 18.5 | BI33: 15.77 | BJ33: 25.703 | BK33: 38.472 | BL33: 98.445 | BM33: 27.096 | BN33: 15.546 | CD33: 2027E | CE33: =CF33+$CE$32 -> 1.2 | CF33: 1.05 | CG33: =CF33+$CG$32 -> 0.9
CD34: 2028E | CE34: =CF34+$CE$32 -> 1.2 | CF34: 1.05 | CG34: =CF34+$CG$32 -> 0.9
B35: Commercial Operations (CANDU & U.S. components, fuel & fuel handling, field services, Kinectrics from 20-May-2025, medical isotopes (sale pending), PCG from 1-Jul-2026) | BV35: COMMERCIAL OPERATIONS — modelling logic | CD35: 2029E | CE35: =CF35+$CE$32 -> 1.2 | CF35: 1.05 | CG35: =CF35+$CG$32 -> 0.9
B36: Opening backlog | AN36: =AM67 -> 725.702 | AO36: =AN67 -> 697.169 | AP36: =AO67 -> 674.287 | AQ36: =AP67 -> 687.806 | AR36: =AM67 -> 725.702 | AS36: =AR67 -> 643.866 | AT36: =AS67 -> 748.101 | AU36: =AT67 -> 731.42 | AV36: =AU67 -> 632.416 | AW36: =AR67 -> 643.866 | AX36: =AW67 -> 628.933 | AY36: =AX67 -> 665.745 | AZ36: =AY67 -> 709.254 | BA36: =AZ67 -> 721.967 | BB36: =AW67 -> 628.933 | BC36: =BB67 -> 780.974 | BD36: =BC67 -> 726.523 | BE36: =BD67 -> 669.054 | BF36: =BE67 -> 635.356 | BG36: =BB67 -> 780.974 | BH36: =BG67 -> 929.88 | BI36: =BH67 -> 1294.99 | BJ36: =BI67 -> 1579.598 | BK36: =BJ67 -> 1484.111 | BL36: =BG67 -> 929.88 | BM36: =BL67 -> 1719.401 | BN36: =BM67 -> 1719.725 | BO36: =BN67 -> 1600.454 | BP36: =BO67 -> 1600.454 | BQ36: =BL67 -> 1719.401 | BR36: =BQ67 -> 1600.454 | BS36: =BR67 -> 1600.454 | BT36: =BS67 -> 1600.454 | BU36: =BT67 -> 1600.454 | CD36: 2030E | CE36: =CF36+$CE$32 -> 1.2 | CF36: 1.05 | CG36: =CF36+$CG$32 -> 0.9
B37: Bookings | AM37: 239.104 | AN37: 78.685 | AO37: 78.616 | AP37: 96.78 | AQ37: 70.387 | AR37: 324.468 | AS37: 204.119 | AT37: 101.84 | AU37: 2.79 | AV37: 103.609 | AW37: 412.359 | AX37: 145.686 | AY37: 164.375 | AZ37: 125.061 | BA37: 182.907 | BB37: 618.029 | BC37: 62.414 | BD37: 83.183 | BE37: 78.252 | BF37: 446.438 | BG37: 670.288 | BH37: 493.42 | BI37: 228.195 | BJ37: 159.342 | BK37: 528.774 | BL37: 1409.732 | BM37: 282.716 | BN37: 181.251 | BO37: =BO39*BO38 -> 363.35299 | BP37: =BP39*BP38 -> 424.42454 | BQ37: =SUM(BM37:BP37) -> 1251.7445 | BR37: =BR39*BR38 -> 1542.5747 | BS37: =BS39*BS38 -> 1714.6442 | BT37: =BT39*BT38 -> 1935.7917 | BU37: =BU39*BU38 -> 2168.0868 | BX37: =IFERROR((BU37/BL37)^(1/5)-1,"n/m") -> 0.089903431 | BY37: =IFERROR((BL37/AM37)^(1/5)-1,"n/m") -> 0.42596854 | BZ37: =IFERROR((BL37/N37)^(1/10)-1,"n/m") -> n/m | CA37: =IFERROR((BL37/D37)^(1/12)-1,"n/m") -> n/m | CD37: COM_growth (core Commercial revenues y/y, ex PCG / medical) | CE37: 0.05 | CF37: Δ → | CG37: -0.05 | CH37: CANDU refurbishments (Bruce MCR, Darlington, Pickering), U.S. large components, SMR components (BWRX-300 Darlington), fuel & fuel handling, Kinectrics services.
B38: Book-to-bill (x) | C38: =IF(AND(ISNUMBER(C37),ISNUMBER(C39)),IFERROR(C37/C39,""),"") | D38: =IF(AND(ISNUMBER(D37),ISNUMBER(D39)),IFERROR(D37/D39,""),"") | E38: =IF(AND(ISNUMBER(E37),ISNUMBER(E39)),IFERROR(E37/E39,""),"") | F38: =IF(AND(ISNUMBER(F37),ISNUMBER(F39)),IFERROR(F37/F39,""),"") | G38: =IF(AND(ISNUMBER(G37),ISNUMBER(G39)),IFERROR(G37/G39,""),"") | H38: =IF(AND(ISNUMBER(H37),ISNUMBER(H39)),IFERROR(H37/H39,""),"") | I38: =IF(AND(ISNUMBER(I37),ISNUMBER(I39)),IFERROR(I37/I39,""),"") | J38: =IF(AND(ISNUMBER(J37),ISNUMBER(J39)),IFERROR(J37/J39,""),"") | ... BN38: =IF(AND(ISNUMBER(BN37),ISNUMBER(BN39)),IFERROR(BN37/BN39,""),"") -> 0.59915309 | BO38: 1 | BP38: 1 | BQ38: =IF(AND(ISNUMBER(BQ37),ISNUMBER(BQ39)),IFERROR(BQ37/BQ39,""),"") -> 0.91106563 | BR38: =CHOOSE(MATCH($BV$2,{"Bull","Base","Bear"},0),$CE$48,$CF$48,$CG$48) -> 1 | BS38: =CHOOSE(MATCH($BV$2,{"Bull","Base","Bear"},0),$CE$49,$CF$49,$CG$49) -> 1 | BT38: =CHOOSE(MATCH($BV$2,{"Bull","Base","Bear"},0),$CE$50,$CF$50,$CG$50) -> 1 | BU38: =CHOOSE(MATCH($BV$2,{"Bull","Base","Bear"},0),$CE$51,$CF$51,$CG$51) -> 1 | BV38: 2027E+: scenario lever COM_btb (CANDU refurbishments, U.S. large-component & SMR orders, fuel). | CD38: 2027E | CE38: =CF38+$CE$37 -> 0.2 | CF38: 0.15 | CG38: =CF38+$CG$37 -> 0.1
B39: Revenues | AM39: 371.269 | AN39: 107.398 | AO39: 101.842 | AP39: 83.382 | AQ39: 114.46 | AR39: 407.082 | AS39: 99.95 | AT39: 118.522 | AU39: 101.794 | AV39: 107.092 | AW39: 427.358 | AX39: 108.924 | AY39: 120.92 | AZ39: 112.359 | BA39: 124.141 | BB39: 466.344 | BC39: 117.038 | BD39: 141.491 | BE39: 113.112 | BF39: 152.331 | BG39: 523.972 | BH39: 128.31 | BI39: 176.139 | BJ39: 250.971 | BK39: 297.65 | BL39: 853.07 | BM39: 283.645 | BN39: 302.512 | BO39: =BJ39*(1+BO41)+BO47 -> 363.35299 | BP39: =BK39*(1+BP41)+BP47 -> 424.42454 | BQ39: =SUM(BM39:BP39) -> 1373.9345 | BR39: =BR42+BR47+BR48 -> 1542.5747 | BS39: =BS42+BS47+BS48 -> 1714.6442 | BT39: =BT42+BT47+BT48 -> 1935.7917 | BU39: =BU42+BU47+BU48 -> 2168.0868 | BV39: Q3/Q4-26E: prior-year quarter × (1 + organic growth + calibration Δ) + PCG. 2027E+: core (ex PCG, ex medical) + PCG + medical until closing. | BX39: =IFERROR((BU39/BL39)^(1/5)-1,"n/m") -> 0.20508699 | BY39: =IFERROR((BL39/AM39)^(1/5)-1,"n/m") -> 0.18102529 | BZ39: =IFERROR((BL39/N39)^(1/10)-1,"n/m") -> n/m | CA39: =IFERROR((BL39/D39)^(1/12)-1,"n/m") -> n/m | CD39: 2028E | CE39: =CF39+$CE$37 -> 0.19 | CF39: 0.14 | CG39: =CF39+$CG$37 -> 0.09
B40: Q3/Q4-26E organic growth input (before revenue calibration) | BO40: 0.3 | BP40: 0.3 | BV40: Input: 1H/26 Commercial +93% y/y is inflated by Kinectrics (closed 20-May-2025, in the base from Q3/25); Q1/26 organic ex-Kinectrics ~+39%. | CD40: 2029E | CE40: =CF40+$CE$37 -> 0.18 | CF40: 0.13 | CG40: =CF40+$CG$37 -> 0.08
B41: Revenues y/y % (Q3/Q4-26E: organic, incl. calibration) | D41: =IF(AND(ISNUMBER(D39),ISNUMBER(C39)),IFERROR(D39/C39-1,""),"") | I41: =IF(AND(ISNUMBER(I39),ISNUMBER(D39)),IFERROR(I39/D39-1,""),"") | J41: =IF(AND(ISNUMBER(J39),ISNUMBER(E39)),IFERROR(J39/E39-1,""),"") | K41: =IF(AND(ISNUMBER(K39),ISNUMBER(F39)),IFERROR(K39/F39-1,""),"") | L41: =IF(AND(ISNUMBER(L39),ISNUMBER(G39)),IFERROR(L39/G39-1,""),"") | M41: =IF(AND(ISNUMBER(M39),ISNUMBER(H39)),IFERROR(M39/H39-1,""),"") | N41: =IF(AND(ISNUMBER(N39),ISNUMBER(I39)),IFERROR(N39/I39-1,""),"") | O41: =IF(AND(ISNUMBER(O39),ISNUMBER(J39)),IFERROR(O39/J39-1,""),"") | P41: =IF(AND(ISNUMBER(P39),ISNUMBER(K39)),IFERROR(P39/K39-1,""),"") | ... BN41: =IF(AND(ISNUMBER(BN39),ISNUMBER(BI39)),IFERROR(BN39/BI39-1,""),"") -> 0.71746178 | BO41: =BO40+BO118 -> 0.30833039 | BP41: =BP40+BP118 -> 0.30833039 | BQ41: =IF(AND(ISNUMBER(BQ39),ISNUMBER(BL39)),IFERROR(BQ39/BL39-1,""),"") -> 0.61057654 | BR41: =IF(AND(ISNUMBER(BR39),ISNUMBER(BQ39)),IFERROR(BR39/BQ39-1,""),"") -> 0.12274251 | BS41: =IF(AND(ISNUMBER(BS39),ISNUMBER(BR39)),IFERROR(BS39/BR39-1,""),"") -> 0.11154692 | BT41: =IF(AND(ISNUMBER(BT39),ISNUMBER(BS39)),IFERROR(BT39/BS39-1,""),"") -> 0.12897579 | BU41: =IF(AND(ISNUMBER(BU39),ISNUMBER(BT39)),IFERROR(BU39/BT39-1,""),"") -> 0.12 | BX41: =IFERROR(AVERAGE(BQ41,BR41,BS41,BT41,BU41),"n/m") -> 0.21876835 | BY41: =IFERROR(AVERAGE(AR41,AW41,BB41,BG41,BL41),"n/m") -> 0.1978304 | BZ41: =IFERROR(AVERAGE(S41,X41,AC41,AH41,AM41,AR41,AW41,BB41,BG41,BL41),"n/m") -> 0.1978304 | CA41: =IFERROR(AVERAGE(D41,I41,N41,S41,X41,AC41,AH41,AM41,AR41,AW41,BB41,BG41,BL41),"n/m") -> 0.1978304 | CD41: 2030E | CE41: =CF41+$CE$37 -> 0.17 | CF41: 0.12 | CG41: =CF41+$CG$37 -> 0.07
B42: Core Commercial revenues (ex PCG, ex medical) | BQ42: =BQ39-BQ47-BQ48 -> 1173.9345 | BR42: =BQ42*(1+BR43) -> 1350.0247 | BS42: =BR42*(1+BS43) -> 1539.0282 | BT42: =BS42*(1+BT43) -> 1739.1018 | BU42: =BT42*(1+BU43) -> 1947.794 | BV42: 2026E = segment revenues − PCG − medical (2026E medical ~$130m per Q2-26 call). 2027E+: × (1 + COM_growth). | CD42: COM_margin (core + PCG non-GAAP operating margin) | CE42: 0.015 | CF42: Δ → | CG42: -0.015 | CH42: FY25 10.2%; 1H/26 9.9%. Operating leverage on Cambridge capacity.
...

Sheet Bull-Base-Bear
B2: BWX Technologies (BWXT) — Bull / Base / Bear Case P&L Summary | J2: Share price ($): | K2: =Model!$BQ$448 -> 152.29
B3: Adjusted figures (company definition: Adjusted EBITDA / non-GAAP EPS from continuing operations); GAAP operating income shown for reference. 2027E GAAP includes the medical-sale gain. | J3: As of: | K3: =TODAY() -> 46302
B5: Scenario: | C5: =Model!$BV$2 -> Base | N5: Scenario: | O5: Bull | P5: Snapshot (values) — Model run with switch = Bull; refresh by re-running the switch | Z5: Scenario: | AA5: Bear | AB5: Snapshot (values) — Model run with switch = Bear; refresh by re-running the switch
B7: (USDm, except EPS and shares) | C7: 2025A | D7: 2026E | E7: 2027E | F7: 2028E | G7: 2029E | H7: 2030E | I7: 25-'30 CAGR | J7: Hist. avg 16–25 | N7: (USDm, except EPS and shares) | O7: 2025A | P7: 2026E | Q7: 2027E | R7: 2028E | S7: 2029E | T7: 2030E | Z7: (USDm, except EPS and shares) | AA7: 2025A | AB7: 2026E | AC7: 2027E | AD7: 2028E | AE7: 2029E | AF7: 2030E
B9: Revenues | C9: =Model!BL157 -> 3198.425 | D9: =Model!BQ157 -> 3800 | E9: =Model!BR157 -> 4163.1929 | F9: =Model!BS157 -> 4582.8794 | G9: =Model!BT157 -> 5083.5875 | H9: =Model!BU157 -> 5615.8223 | I9: =IFERROR((H9/C9)^(1/5)-1,"n/m") -> 0.11916839 | N9: Revenues | O9: 3198.425 | P9: 3850 | Q9: 4364.5914 | R9: 5008.6694 | S9: 5772.5676 | T9: 6611.6383 | U9: =IFERROR((T9/O9)^(1/5)-1,"n/m") -> 0.1563108 | Z9: Revenues | AA9: 3198.425 | AB9: 3750 | AC9: 3990.2449 | AD9: 4227.1001 | AE9: 4479.3618 | AF9: 4733.4454 | AG9: =IFERROR((AF9/AA9)^(1/5)-1,"n/m") -> 0.081554082
B10: Revenues y/y % | D10: =IFERROR(D9/C9-1,"") -> 0.18808476 | E10: =IFERROR(E9/D9-1,"") -> 0.095577089 | F10: =IFERROR(F9/E9-1,"") -> 0.10080879 | G10: =IFERROR(G9/F9-1,"") -> 0.10925623 | H10: =IFERROR(H9/G9-1,"") -> 0.10469669 | N10: Revenues y/y % | P10: =IFERROR(P9/O9-1,"") -> 0.20371745 | Q10: =IFERROR(Q9/P9-1,"") -> 0.13366009 | R10: =IFERROR(R9/Q9-1,"") -> 0.14756892 | S10: =IFERROR(S9/R9-1,"") -> 0.15251519 | T10: =IFERROR(T9/S9-1,"") -> 0.14535485 | Z10: Revenues y/y % | AB10: =IFERROR(AB9/AA9-1,"") -> 0.17245207 | AC10: =IFERROR(AC9/AB9-1,"") -> 0.064065306 | AD10: =IFERROR(AD9/AC9-1,"") -> 0.059358555 | AE10: =IFERROR(AE9/AD9-1,"") -> 0.059677254 | AF10: =IFERROR(AF9/AE9-1,"") -> 0.056723178
B11: Government Operations revenues y/y % | C11: =Model!BL17 -> 0.076521731 | D11: =Model!BQ17 -> 0.034815464 | E11: =Model!BR17 -> 0.08 | F11: =Model!BS17 -> 0.08 | G11: =Model!BT17 -> 0.07 | H11: =Model!BU17 -> 0.07 | N11: Government Operations revenues y/y % | O11: 0.076521731 | P11: 0.049438311 | Q11: 0.1 | R11: 0.1 | S11: 0.09 | T11: 0.09 | Z11: Government Operations revenues y/y % | AA11: 0.076521731 | AB11: 0.020192618 | AC11: 0.055 | AD11: 0.055 | AE11: 0.045 | AF11: 0.045
B12: Adjusted EBITDA | C12: =Model!BL208 -> 574.245 | D12: =Model!BQ208 -> 667 | E12: =Model!BR208 -> 754.33929 | F12: =Model!BS208 -> 848.22208 | G12: =Model!BT208 -> 957.41076 | H12: =Model!BU208 -> 1062.9173 | I12: =IFERROR((H12/C12)^(1/5)-1,"n/m") -> 0.13104647 | N12: Adjusted EBITDA | O12: 574.245 | P12: 672 | Q12: 840.56022 | R12: 980.20706 | S12: 1143.7554 | T12: 1312.4478 | U12: =IFERROR((T12/O12)^(1/5)-1,"n/m") -> 0.17976895 | Z12: Adjusted EBITDA | AA12: 574.245 | AB12: 662 | AC12: 675.87061 | AD12: 733.26337 | AE12: 794.28593 | AF12: 846.22035 | AG12: =IFERROR((AF12/AA12)^(1/5)-1,"n/m") -> 0.080630569
B13: Adjusted EBITDA margin % | C13: =IFERROR(C12/C9,"") -> 0.17953993 | D13: =IFERROR(D12/D9,"") -> 0.17552632 | E13: =IFERROR(E12/E9,"") -> 0.18119249 | F13: =IFERROR(F12/F9,"") -> 0.18508497 | G13: =IFERROR(G12/G9,"") -> 0.18833368 | H13: =IFERROR(H12/H9,"") -> 0.18927188 | J13: =IFERROR(AVERAGE(Model!S209,Model!X209,Model!AC209,Model!AH209,Model!AM209,Model!AR209,Model!AW209,Model!BB209,Model!BG209,Model!BL209),"") -> 0.19920187 | N13: Adjusted EBITDA margin % | O13: =IFERROR(O12/O9,"") -> 0.17953993 | P13: =IFERROR(P12/P9,"") -> 0.17454545 | Q13: =IFERROR(Q12/Q9,"") -> 0.19258624 | R13: =IFERROR(R12/R9,"") -> 0.19570209 | S13: =IFERROR(S12/S9,"") -> 0.19813634 | T13: =IFERROR(T12/T9,"") -> 0.19850569 | Z13: Adjusted EBITDA margin % | AA13: =IFERROR(AA12/AA9,"") -> 0.17953993 | AB13: =IFERROR(AB12/AB9,"") -> 0.17653333 | AC13: =IFERROR(AC12/AC9,"") -> 0.16938073 | AD13: =IFERROR(AD12/AD9,"") -> 0.17346724 | AE13: =IFERROR(AE12/AE9,"") -> 0.17732123 | AF13: =IFERROR(AF12/AF9,"") -> 0.17877471
B15: Operating Income (GAAP) | C15: =Model!BL164 -> 404.459 | D15: =Model!BQ164 -> 490.7205 | E15: =Model!BR164 -> 1153.0586 | F15: =Model!BS164 -> 649.19547 | G15: =Model!BT164 -> 737.8482 | H15: =Model!BU164 -> 821.31298 | I15: =IFERROR((H15/C15)^(1/5)-1,"n/m") -> 0.15219725 | N15: Operating Income (GAAP) | O15: 404.459 | P15: 494.24812 | Q15: 1293.1863 | R15: 760.97064 | S15: 890.84492 | T15: 1023.2732 | U15: =IFERROR((T15/O15)^(1/5)-1,"n/m") -> 0.20399149 | Z15: Operating Income (GAAP) | AA15: 404.459 | AB15: 487.19288 | AC15: 1080.2088 | AD15: 548.12378 | AE15: 601.38487 | AF15: 644.69289 | AG15: =IFERROR((AF15/AA15)^(1/5)-1,"n/m") -> 0.097730358
B16: Operating income y/y % | D16: =IFERROR(D15/C15-1,"") -> 0.21327625 | E16: =IFERROR(E15/D15-1,"") -> 1.3497257 | F16: =IFERROR(F15/E15-1,"") -> -0.43697962 | G16: =IFERROR(G15/F15-1,"") -> 0.13655785 | H16: =IFERROR(H15/G15-1,"") -> 0.11311917 | N16: Operating income y/y % | P16: =IFERROR(P15/O15-1,"") -> 0.22199808 | Q16: =IFERROR(Q15/P15-1,"") -> 1.6164719 | R16: =IFERROR(R15/Q15-1,"") -> -0.41155375 | S16: =IFERROR(S15/R15-1,"") -> 0.17066924 | T16: =IFERROR(T15/S15-1,"") -> 0.14865468 | Z16: Operating income y/y % | AB16: =IFERROR(AB15/AA15-1,"") -> 0.20455443 | AC16: =IFERROR(AC15/AB15-1,"") -> 1.2172099 | AD16: =IFERROR(AD15/AC15-1,"") -> -0.49257611 | AE16: =IFERROR(AE15/AD15-1,"") -> 0.097169816 | AF16: =IFERROR(AF15/AE15-1,"") -> 0.072013812
B17: Operating margin (GAAP) % | C17: =IFERROR(C15/C9,"") -> 0.12645568 | D17: =IFERROR(D15/D9,"") -> 0.12913697 | E17: =IFERROR(E15/E9,"") -> 0.27696496 | F17: =IFERROR(F15/F9,"") -> 0.14165668 | G17: =IFERROR(G15/G9,"") -> 0.14514321 | H17: =IFERROR(H15/H9,"") -> 0.14624982 | J17: =IFERROR(AVERAGE(Model!S254,Model!X254,Model!AC254,Model!AH254,Model!AM254,Model!AR254,Model!AW254,Model!BB254,Model!BG254,Model!BL254),"") -> 0.15870152 | N17: Operating margin (GAAP) % | O17: =IFERROR(O15/O9,"") -> 0.12645568 | P17: =IFERROR(P15/P9,"") -> 0.12837614 | Q17: =IFERROR(Q15/Q9,"") -> 0.29629035 | R17: =IFERROR(R15/R9,"") -> 0.1519307 | S17: =IFERROR(S15/S9,"") -> 0.15432386 | T17: =IFERROR(T15/T9,"") -> 0.15476848 | Z17: Operating margin (GAAP) % | AA17: =IFERROR(AA15/AA9,"") -> 0.12645568 | AB17: =IFERROR(AB15/AB9,"") -> 0.1299181 | AC17: =IFERROR(AC15/AC9,"") -> 0.27071242 | AD17: =IFERROR(AD15/AD9,"") -> 0.12966899 | AE17: =IFERROR(AE15/AE9,"") -> 0.13425682 | AF17: =IFERROR(AF15/AF9,"") -> 0.1361995
B19: Non-GAAP Net Income (continuing ops, attributable to BWXT) | C19: =Model!BL234 -> 368.34256 | D19: =Model!BQ234 -> 436.00785 | E19: =Model!BR234 -> 481.21415 | F19: =Model!BS234 -> 540.78871 | G19: =Model!BT234 -> 600.71214 | H19: =Model!BU234 -> 659.76219 | I19: =IFERROR((H19/C19)^(1/5)-1,"n/m") -> 0.12363977 | N19: Non-GAAP Net Income (continuing ops, attributable to BWXT) | O19: 368.34256 | P19: 438.77703 | Q19: 544.61134 | R19: 617.95644 | S19: 708.38514 | T19: 799.48414 | U19: =IFERROR((T19/O19)^(1/5)-1,"n/m") -> 0.16764706 | Z19: Non-GAAP Net Income (continuing ops, attributable to BWXT) | AA19: 368.34256 | AB19: 433.23866 | AC19: 424.45634 | AD19: 468.41312 | AE19: 503.99984 | AF19: 531.20798 | AG19: =IFERROR((AF19/AA19)^(1/5)-1,"n/m") -> 0.075975885
B21: FDSO (m) | C21: =Model!BL185 -> 91.856 | D21: =Model!BQ185 -> 91.995125 | E21: =Model!BR185 -> 91.177622 | F21: =Model!BS185 -> 89.656385 | G21: =Model!BT185 -> 88.114487 | H21: =Model!BU185 -> 86.364543 | I21: =IFERROR((H21/C21)^(1/5)-1,"n/m") -> -0.012253293 | N21: FDSO (m) | O21: 91.856 | P21: 91.995125 | Q21: 89.730857 | R21: 86.643856 | S21: 84.733592 | T21: 82.399413 | U21: =IFERROR((T21/O21)^(1/5)-1,"n/m") -> -0.021494395 | Z21: FDSO (m) | AA21: 91.856 | AB21: 91.995125 | AC21: 92.1966 | AD21: 92.09913 | AE21: 91.027751 | AF21: 89.481149 | AG21: =IFERROR((AF21/AA21)^(1/5)-1,"n/m") -> -0.0052251334
B23: Non-GAAP EPS — Diluted ($) | C23: =Model!BL236 -> 4.01 | D23: =Model!BQ236 -> 4.7394669 | E23: =Model!BR236 -> 5.277766 | F23: =Model!BS236 -> 6.0317924 | G23: =Model!BT236 -> 6.8174049 | H23: =Model!BU236 -> 7.6392714 | I23: =IFERROR((H23/C23)^(1/5)-1,"n/m") -> 0.13757886 | N23: Non-GAAP EPS — Diluted ($) | O23: 4.01 | P23: 4.7695683 | Q23: 6.0693875 | R23: 7.1321439 | S23: 8.3601453 | T23: 9.7025465 | U23: =IFERROR((T23/O23)^(1/5)-1,"n/m") -> 0.19329624 | Z23: Non-GAAP EPS — Diluted ($) | AA23: 4.01 | AB23: 4.7093654 | AC23: 4.6038177 | AD23: 5.0859668 | AE23: 5.5367714 | AF23: 5.9365351 | AG23: =IFERROR((AF23/AA23)^(1/5)-1,"n/m") -> 0.081627533
B24: EPS y/y % | D24: =IFERROR(D23/C23-1,"") -> 0.18191193 | E24: =IFERROR(E23/D23-1,"") -> 0.11357799 | F24: =IFERROR(F23/E23-1,"") -> 0.14286849 | G24: =IFERROR(G23/F23-1,"") -> 0.13024528 | H24: =IFERROR(H23/G23-1,"") -> 0.12055416 | N24: EPS y/y % | P24: =IFERROR(P23/O23-1,"") -> 0.18941852 | Q24: =IFERROR(Q23/P23-1,"") -> 0.27252346 | R24: =IFERROR(R23/Q23-1,"") -> 0.17510109 | S24: =IFERROR(S23/R23-1,"") -> 0.17217844 | T24: =IFERROR(T23/S23-1,"") -> 0.16057152 | Z24: EPS y/y % | AB24: =IFERROR(AB23/AA23-1,"") -> 0.17440535 | AC24: =IFERROR(AC23/AB23-1,"") -> -0.022412307 | AD24: =IFERROR(AD23/AC23-1,"") -> 0.10472811 | AE24: =IFERROR(AE23/AD23-1,"") -> 0.088636938 | AF24: =IFERROR(AF23/AE23-1,"") -> 0.072201601
B26: P / E (x) — assumed (non-GAAP EPS) | F26: 30 | G26: 30 | H26: 30 | N26: P / E (x) — assumed (non-GAAP EPS) | R26: 35 | S26: 35 | T26: 35 | Z26: P / E (x) — assumed (non-GAAP EPS) | AD26: 22 | AE26: 22 | AF26: 22
B27: Price Target ($) | F27: =F26*F23 -> 180.95377 | G27: =G26*G23 -> 204.52215 | H27: =H26*H23 -> 229.17814 | N27: Price Target ($) | R27: =R26*R23 -> 249.62504 | S27: =S26*S23 -> 292.60509 | T27: =T26*T23 -> 339.58913 | Z27: Price Target ($) | AD27: =AD26*AD23 -> 111.89127 | AE27: =AE26*AE23 -> 121.80897 | AF27: =AF26*AF23 -> 130.60377
B28: Upside / (Downside) vs current | F28: =IFERROR(F27/$K$2-1,"") -> 0.18821835 | G28: =IFERROR(G27/$K$2-1,"") -> 0.34297818 | H28: =IFERROR(H27/$K$2-1,"") -> 0.50487978 | N28: Upside / (Downside) vs current | R28: =IFERROR(R27/$K$2-1,"") -> 0.63914266 | S28: =IFERROR(S27/$K$2-1,"") -> 0.92136769 | T28: =IFERROR(T27/$K$2-1,"") -> 1.2298846 | Z28: Upside / (Downside) vs current | AD28: =IFERROR(AD27/$K$2-1,"") -> -0.265275 | AE28: =IFERROR(AE27/$K$2-1,"") -> -0.20015123 | AF28: =IFERROR(AF27/$K$2-1,"") -> -0.14240086
B29: IRR (to Dec-Y-1) | F29: =IFERROR((F27/$K$2)^(1/((DATE(2028-1,12,31)-$K$3)/365.25))-1,"") -> 0.15024616 | G29: =IFERROR((G27/$K$2)^(1/((DATE(2029-1,12,31)-$K$3)/365.25))-1,"") -> 0.14110336 | H29: =IFERROR((H27/$K$2)^(1/((DATE(2030-1,12,31)-$K$3)/365.25))-1,"") -> 0.13473984 | N29: IRR (to Dec-Y-1) | R29: =IFERROR((R27/$K$2)^(1/((DATE(2028-1,12,31)-$K$3)/365.25))-1,"") -> 0.49347262 | S29: =IFERROR((S27/$K$2)^(1/((DATE(2029-1,12,31)-$K$3)/365.25))-1,"") -> 0.33951312 | T29: =IFERROR((T27/$K$2)^(1/((DATE(2030-1,12,31)-$K$3)/365.25))-1,"") -> 0.28148617 | Z29: IRR (to Dec-Y-1) | AD29: =IFERROR((AD27/$K$2)^(1/((DATE(2028-1,12,31)-$K$3)/365.25))-1,"") -> -0.22135773 | AE29: =IFERROR((AE27/$K$2)^(1/((DATE(2029-1,12,31)-$K$3)/365.25))-1,"") -> -0.095131791 | AF29: =IFERROR((AF27/$K$2)^(1/((DATE(2030-1,12,31)-$K$3)/365.25))-1,"") -> -0.046398938
B31: Free Cash Flow | C31: =Model!BL288 -> 295.291 | D31: =Model!BQ288 -> 368.23576 | E31: =Model!BR288 -> 152.65928 | F31: =Model!BS288 -> 451.36732 | G31: =Model!BT288 -> 531.75615 | H31: =Model!BU288 -> 584.86449 | I31: =IFERROR((H31/C31)^(1/5)-1,"n/m") -> 0.14646555 | N31: Free Cash Flow | O31: 295.291 | P31: 365.85621 | Q31: 181.33535 | R31: 501.52912 | S31: 609.8594 | T31: 689.16781 | U31: =IFERROR((T31/O31)^(1/5)-1,"n/m") -> 0.18471791 | Z31: Free Cash Flow | AA31: 295.291 | AB31: 370.6153 | AC31: 112.63 | AD31: 401.6589 | AE31: 463.17092 | AF31: 488.54399 | AG31: =IFERROR((AF31/AA31)^(1/5)-1,"n/m") -> 0.10593778
B32: FCF % | C32: =IFERROR(C31/C9,"") -> 0.092323878 | D32: =IFERROR(D31/D9,"") -> 0.096904146 | E32: =IFERROR(E31/E9,"") -> 0.036668797 | F32: =IFERROR(F31/F9,"") -> 0.098489898 | G32: =IFERROR(G31/G9,"") -> 0.10460254 | H32: =IFERROR(H31/H9,"") -> 0.10414583 | J32: =IFERROR(AVERAGE(Model!S290,Model!X290,Model!AC290,Model!AH290,Model!AM290,Model!AR290,Model!AW290,Model!BB290,Model!BG290,Model!BL290),"") -> 0.057972992 | N32: FCF % | O32: =IFERROR(O31/O9,"") -> 0.092323878 | P32: =IFERROR(P31/P9,"") -> 0.095027586 | Q32: =IFERROR(Q31/Q9,"") -> 0.041546925 | R32: =IFERROR(R31/R9,"") -> 0.10013221 | S32: =IFERROR(S31/S9,"") -> 0.10564786 | T32: =IFERROR(T31/T9,"") -> 0.10423556 | Z32: FCF % | AA32: =IFERROR(AA31/AA9,"") -> 0.092323878 | AB32: =IFERROR(AB31/AB9,"") -> 0.098830748 | AC32: =IFERROR(AC31/AC9,"") -> 0.028226338 | AD32: =IFERROR(AD31/AD9,"") -> 0.095019966 | AE32: =IFERROR(AE31/AE9,"") -> 0.1034011 | AF32: =IFERROR(AF31/AF9,"") -> 0.10321108
B33: FCF / share ($) | C33: =IFERROR(C31/C21,"") -> 3.2147165 | D33: =IFERROR(D31/D21,"") -> 4.0027747 | E33: =IFERROR(E31/E21,"") -> 1.6743064 | F33: =IFERROR(F31/F21,"") -> 5.0344136 | G33: =IFERROR(G31/G21,"") -> 6.0348322 | H33: =IFERROR(H31/H21,"") -> 6.772044 | N33: FCF / share ($) | O33: =IFERROR(O31/O21,"") -> 3.2147165 | P33: =IFERROR(P31/P21,"") -> 3.9769086 | Q33: =IFERROR(Q31/Q21,"") -> 2.0208806 | R33: =IFERROR(R31/R21,"") -> 5.788398 | S33: =IFERROR(S31/S21,"") -> 7.1973746 | T33: =IFERROR(T31/T21,"") -> 8.3637466 | Z33: FCF / share ($) | AA33: =IFERROR(AA31/AA21,"") -> 3.2147165 | AB33: =IFERROR(AB31/AB21,"") -> 4.0286407 | AC33: =IFERROR(AC31/AC21,"") -> 1.2216286 | AD33: =IFERROR(AD31/AD21,"") -> 4.3611585 | AE33: =IFERROR(AE31/AE21,"") -> 5.0882387 | AF33: =IFERROR(AF31/AF21,"") -> 5.4597421
B34: FCF Yield (on PT) | F34: =IFERROR(F33/F$27,"") -> 0.027821545 | G34: =IFERROR(G33/G$27,"") -> 0.029506986 | H34: =IFERROR(H33/H$27,"") -> 0.029549258 | N34: FCF Yield (on PT) | R34: =IFERROR(R33/R$27,"") -> 0.023188371 | S34: =IFERROR(S33/S$27,"") -> 0.024597572 | T34: =IFERROR(T33/T$27,"") -> 0.024629018 | Z34: FCF Yield (on PT) | AD34: =IFERROR(AD33/AD$27,"") -> 0.038976754 | AE34: =IFERROR(AE33/AE$27,"") -> 0.041772283 | AF34: =IFERROR(AF33/AF$27,"") -> 0.041803862
B35: Total backlog (year end) | C35: =Model!BL110 -> 7260.692 | D35: =Model!BQ110 -> 8398.081 | E35: =Model!BR110 -> 8529.4041 | F35: =Model!BS110 -> 8671.2331 | G35: =Model!BT110 -> 8822.9901 | H35: =Model!BU110 -> 8985.37 | I35: =IFERROR((H35/C35)^(1/5)-1,"n/m") -> 0.043545983 | N35: Total backlog (year end) | O35: 7260.692 | P35: 8398.081 | Q35: 9102.6647 | R35: 9886.9353 | S35: 10757.605 | T35: 11723.262 | U35: =IFERROR((T35/O35)^(1/5)-1,"n/m") -> 0.10056092 | Z35: Total backlog (year end) | AA35: 7260.692 | AB35: 8398.081 | AC35: 7998.4721 | AD35: 7575.1777 | AE35: 7126.6571 | AF35: 6652.7282 | AG35: =IFERROR((AF35/AA35)^(1/5)-1,"n/m") -> -0.017337568
B36: Book-to-bill (x) | C36: =Model!BL112 -> 1.6757945 | D36: =Model!BQ112 -> 1.2999276 | E36: =Model!BR112 -> 1.0329476 | F36: =Model!BS112 -> 1.0240401 | G36: =Model!BT112 -> 1.0076916 | H36: =Model!BU112 -> 0.99327685 | N36: Book-to-bill (x) | O36: 1.6757945 | P36: 1.2960325 | Q36: 1.1541789 | R36: 1.1266034 | S36: 1.0956306 | T36: 1.0703399 | Z36: Book-to-bill (x) | AA36: 1.6757945 | AB36: 1.3039267 | AC36: 0.90131811 | AD36: 0.90124426 | AE36: 0.90117419 | AF36: 0.90111116
B38: Net Debt | C38: =Model!BL443 -> 1508.779 | D38: =Model!BQ443 -> 1565.9949 | E38: =Model!BR443 -> 1131.5089 | F38: =Model!BS443 -> 1272.3331 | G38: =Model!BT443 -> 1436.1161 | H38: =Model!BU443 -> 1594.3759 | N38: Net Debt | O38: 1508.779 | P38: 1568.3745 | Q38: 1681.1204 | R38: 1960.4141 | S38: 2287.5108 | T38: 2624.8956 | Z38: Net Debt | AA38: 1508.779 | AB38: 1563.6154 | AC38: 833.96943 | AD38: 733.26337 | AE38: 794.28593 | AF38: 846.22035
B39: Net Debt / Adjusted EBITDA (x) | C39: =IFERROR(C38/C12,"") -> 2.6274134 | D39: =IFERROR(D38/D12,"") -> 2.3478185 | E39: =IFERROR(E38/E12,"") -> 1.5 | F39: =IFERROR(F38/F12,"") -> 1.5 | G39: =IFERROR(G38/G12,"") -> 1.5 | H39: =IFERROR(H38/H12,"") -> 1.5 | N39: Net Debt / Adjusted EBITDA (x) | O39: =IFERROR(O38/O12,"") -> 2.6274134 | P39: =IFERROR(P38/P12,"") -> 2.3338906 | Q39: =IFERROR(Q38/Q12,"") -> 2 | R39: =IFERROR(R38/R12,"") -> 2 | S39: =IFERROR(S38/S12,"") -> 2 | T39: =IFERROR(T38/T12,"") -> 2 | Z39: Net Debt / Adjusted EBITDA (x) | AA39: =IFERROR(AA38/AA12,"") -> 2.6274134 | AB39: =IFERROR(AB38/AB12,"") -> 2.3619567 | AC39: =IFERROR(AC38/AC12,"") -> 1.2339188 | AD39: =IFERROR(AD38/AD12,"") -> 1 | AE39: =IFERROR(AE38/AE12,"") -> 1 | AF39: =IFERROR(AF38/AF12,"") -> 1
B40: Share repurchases ($m) | D40: =Model!BQ299 -> 0 | E40: =Model!BR299 -> 335.18922 | F40: =Model!BS299 -> 302.77505 | G40: =Model!BT299 -> 398.8922 | H40: =Model!BU299 -> 439.36638 | N40: Share repurchases ($m) | P40: 0 | Q40: 811.09726 | R40: 345.05134 | S40: 494.56955 | T40: 578.12877 | Z40: Share repurchases ($m) | AB40: 0 | AC40: 0 | AD40: 158.96915 | AE40: 373.67247 | AF40: 382.34345
B41: Implied avg buyback price ($) | D41: =Model!BQ298 -> 152.29 | E41: =Model!BR298 -> 164.4732 | F41: =Model!BS298 -> 177.63106 | G41: =Model!BT298 -> 191.84154 | H41: =Model!BU298 -> 207.18886 | N41: Implied avg buyback price ($) | P41: 152.29 | Q41: 164.4732 | R41: 177.63106 | S41: 191.84154 | T41: 207.18886 | Z41: Implied avg buyback price ($) | AB41: 152.29 | AC41: 164.4732 | AD41: 177.63106 | AE41: 191.84154 | AF41: 207.18886
B42: Shares repurchased (m) | D42: =Model!BQ300 -> 0 | E42: =Model!BR300 -> 2.0379565 | F42: =Model!BS300 -> 1.7045164 | G42: =Model!BT300 -> 2.0792796 | H42: =Model!BU300 -> 2.1206081 | N42: Shares repurchased (m) | P42: 0 | Q42: 4.9314859 | R42: 1.942517 | S42: 2.5780107 | T42: 2.7903467 | Z42: Shares repurchased (m) | AB42: 0 | AC42: 0 | AD42: 0.89494005 | AE42: 1.9478183 | AF42: 1.8453861
B44: ROIC | C44: =Model!BL426 -> 0.14374023 | D44: =Model!BQ426 -> 0.14085705 | E44: =Model!BR426 -> 0.15064591 | F44: =Model!BS426 -> 0.1561988 | G44: =Model!BT426 -> 0.16418556 | H44: =Model!BU426 -> 0.170754 | J44: =IFERROR(AVERAGE(Model!S426,Model!X426,Model!AC426,Model!AH426,Model!AM426,Model!AR426,Model!AW426,Model!BB426,Model!BG426,Model!BL426),"") -> 0.2051783 | N44: ROIC | O44: 0.14374023 | P44: 0.14148447 | Q44: 0.16077454 | R44: 0.16552153 | S44: 0.17335056 | T44: 0.18045635 | Z44: ROIC | AA44: 0.14374023 | AB44: 0.14022735 | AC44: 0.13366953 | AD44: 0.14085612 | AE44: 0.14919125 | AF44: 0.15581351
B45: RONTA | C45: =Model!BL437 -> 0.14234019 | D45: =Model!BQ437 -> 0.1531374 | E45: =Model!BR437 -> 0.13561772 | F45: =Model!BS437 -> 0.15075449 | G45: =Model!BT437 -> 0.16978231 | H45: =Model!BU437 -> 0.18773961 | J45: =IFERROR(AVERAGE(Model!S437,Model!X437,Model!AC437,Model!AH437,Model!AM437,Model!AR437,Model!AW437,Model!BB437,Model!BG437,Model!BL437),"") -> 0.19833665 | N45: RONTA | O45: 0.14234019 | P45: 0.15392254 | Q45: 0.17720985 | R45: 0.20333255 | S45: 0.21989937 | T45: 0.23438101 | Z45: RONTA | AA45: 0.14234019 | AB45: 0.15235046 | AC45: 0.11077501 | AD45: 0.11361263 | AE45: 0.12192732 | AF45: 0.12871464
B47: Implied Market Cap (USDm) | F47: =F27*F21 -> 16223.661 | G47: =G27*G21 -> 18021.364 | H47: =H27*H21 -> 19792.866 | N47: Implied Market Cap (USDm) | R47: =R27*R21 -> 21628.476 | S47: =S27*S21 -> 24793.48 | T47: =T27*T21 -> 27981.945 | Z47: Implied Market Cap (USDm) | AD47: =AD27*AD21 -> 10305.089 | AE47: =AE27*AE21 -> 11087.997 | AF47: =AF27*AF21 -> 11686.576
B48: (+) Net Debt & NCI | F48: =F38+Model!BS354 -> 1274.0311 | G48: =G38+Model!BT354 -> 1438.2141 | H48: =H38+Model!BU354 -> 1596.8739 | N48: (+) Net Debt & NCI | R48: =R38+1.698 -> 1962.1121 | S48: =S38+2.098 -> 2289.6088 | T48: =T38+2.498 -> 2627.3936 | Z48: (+) Net Debt & NCI | AD48: =AD38+1.698 -> 734.96137 | AE48: =AE38+2.098 -> 796.38393 | AF48: =AF38+2.498 -> 848.71835
B49: Implied Enterprise Value (USDm) | F49: =F47+F48 -> 17497.692 | G49: =G47+G48 -> 19459.578 | H49: =H47+H48 -> 21389.739 | N49: Implied Enterprise Value (USDm) | R49: =R47+R48 -> 23590.588 | S49: =S47+S48 -> 27083.089 | T49: =T47+T48 -> 30609.338 | Z49: Implied Enterprise Value (USDm) | AD49: =AD47+AD48 -> 11040.05 | AE49: =AE47+AE48 -> 11884.38 | AF49: =AF47+AF48 -> 12535.294
B50: Implied EV / Adjusted EBITDA (x) | F50: =IFERROR(F49/F12,"") -> 20.628669 | G50: =IFERROR(G49/G12,"") -> 20.325214 | H50: =IFERROR(H49/H12,"") -> 20.123617 | N50: Implied EV / Adjusted EBITDA (x) | R50: =IFERROR(R49/R12,"") -> 24.066943 | S50: =IFERROR(S49/S12,"") -> 23.679091 | T50: =IFERROR(T49/T12,"") -> 23.322328 | Z50: Implied EV / Adjusted EBITDA (x) | AD50: =IFERROR(AD49/AD12,"") -> 15.05605 | AE50: =IFERROR(AE49/AE12,"") -> 14.962346 | AF50: =IFERROR(AF49/AF12,"") -> 14.813274

Sheet DCF
B2: DCF VALUATION — BWX TECHNOLOGIES (BWXT)
B4: 1. WACC BUILD
B5: Risk-free rate (US 10Y govt) | C5: 0.055 | D5: Assumption (kept consistent with the MLM model); update to the current US 10Y Treasury yield
B6: Equity risk premium | C6: 0.05 | D6: US implied ERP ~4.5–5.5% (Damodaran)
B7: Levered beta | C7: 0.85 | D7: Defense / nuclear peers (HII, GD, LHX, CW, CCJ) ~0.6–1.1; cost-plus naval reactor contracts (sole source) dampen cyclicality
B8: Cost of equity | C8: =C5+C7*C6 -> 0.0975
B9: Pre-tax cost of debt | C9: 0.06 | D9: BB-rated; 4.125% 2028/2029 notes trade ~5.5–6%; 0% 2030 converts carry an embedded equity option
B10: Tax rate | C10: 0.22 | D10: Model 2027E+ effective tax rate
B11: After-tax cost of debt | C11: =C9*(1-C10) -> 0.0468
B12: Target D/V | C12: 0.1 | D12: Net debt ~$1.7bn at YE2026E vs ~$14bn market cap ($152.29 × ~92m shares); 2.5x Adjusted EBITDA
B13: WACC | C13: =C8*(1-C12)+C11*C12 -> 0.09243
B15: Valuation date (live) | C15: =TODAY() -> 46302 | D15: Periods = (Dec-31-Year − today) / 365.25; cash flows assumed at year-end
B16: 2. UNLEVERED FREE CASH FLOW BUILD (USDm)
D17: 2026E | E17: 2027E | F17: 2028E | G17: 2029E | H17: 2030E | I17: 2031E | J17: 2032E | K17: 2033E | L17: 2034E | M17: 2035E | N17: Terminal
B18: Adj. EBITDA − total D&A − restructuring & acquisition costs | D18: =Model!BQ208-Model!BQ181-Model!BQ204 -> 499.4205 | E18: =Model!BR208-Model!BR181-Model!BR204 -> 565.55856 | F18: =Model!BS208-Model!BS181-Model!BS204 -> 649.19547 | G18: =Model!BT208-Model!BT181-Model!BT204 -> 737.8482 | H18: =Model!BU208-Model!BU181-Model!BU204 -> 821.31298 | I18: =H18*(1+I$26) -> 887.01801 | J18: =I18*(1+J$26) -> 951.32682 | K18: =J18*(1+K$26) -> 1013.1631 | L18: =K18*(1+L$26) -> 1071.4199 | M18: =L18*(1+M$26) -> 1124.9909
B19: × (1 − tax rate) | D19: =1-$C$10 -> 0.78 | E19: =1-$C$10 -> 0.78 | F19: =1-$C$10 -> 0.78 | G19: =1-$C$10 -> 0.78 | H19: =1-$C$10 -> 0.78 | I19: =1-$C$10 -> 0.78 | J19: =1-$C$10 -> 0.78 | K19: =1-$C$10 -> 0.78 | ... M19: =1-$C$10 -> 0.78
B20: NOPAT | D20: =D18*D19 -> 389.54799 | E20: =E18*E19 -> 441.13567 | F20: =F18*F19 -> 506.37246 | G20: =G18*G19 -> 575.5216 | H20: =H18*H19 -> 640.62412 | I20: =I18*I19 -> 691.87405 | J20: =J18*J19 -> 742.03492 | K20: =K18*K19 -> 790.26719 | ... M20: =M18*M19 -> 877.49293
B21: plus D&A (incl. acquisition amortization) | D21: =Model!BQ181 -> 132.4795 | E21: =Model!BR181 -> 163.78073 | F21: =Model!BS181 -> 184.02661 | G21: =Model!BT181 -> 209.56256 | H21: =Model!BU181 -> 231.60429 | I21: =H21*(1+I$26) -> 250.13263 | J21: =I21*(1+J$26) -> 268.26724 | K21: =J21*(1+K$26) -> 285.70461 | L21: =K21*(1+L$26) -> 302.13263 | M21: =L21*(1+M$26) -> 317.23926
B22: − Capex & acquisitions; + medical-sale proceeds after tax on gain (2027E) | D22: =Model!BQ269+Model!BQ270+Model!BQ271-Model!BQ83*$C$10 -> -506.22648 | E22: =Model!BR269+Model!BR270+Model!BR271-Model!BR83*$C$10 -> 370.95842 | F22: =Model!BS269+Model!BS270+Model!BS271-Model!BS83*$C$10 -> -402.05837 | G22: =Model!BT269+Model!BT270+Model!BT271-Model!BT83*$C$10 -> -404.17937 | H22: =Model!BU269+Model!BU270+Model!BU271-Model!BU83*$C$10 -> -430.79111 | I22: =(Model!BU269+Model!BU270)*(1+I$26) -> -465.2544 | J22: =I22*(1+J$26) -> -498.98535 | K22: =J22*(1+K$26) -> -531.4194 | L22: =K22*(1+L$26) -> -561.97601 | M22: =L22*(1+M$26) -> -590.07481
B23: − Δ Working capital (CF statement) | D23: =Model!BQ267 -> 5.895 | E23: =Model!BR267 -> -113.22728 | F23: =Model!BS267 -> -43.01786 | G23: =Model!BT267 -> -51.322583 | H23: =Model!BU267 -> -54.554066 | I23: =H23*(1+I$26) -> -58.918391 | J23: =I23*(1+J$26) -> -63.189975 | K23: =J23*(1+K$26) -> -67.297323 | L23: =K23*(1+L$26) -> -71.166919 | M23: =L23*(1+M$26) -> -74.725265
B24: Unlevered FCF | D24: =D20+D21+D22+D23 -> 21.69601 | E24: =E20+E21+E22+E23 -> 862.64755 | F24: =F20+F21+F22+F23 -> 245.32285 | G24: =G20+G21+G22+G23 -> 329.5822 | H24: =H20+H21+H22+H23 -> 386.88323 | I24: =I20+I21+I22+I23 -> 417.83388 | J24: =J20+J21+J22+J23 -> 448.12684 | K24: =K20+K21+K22+K23 -> 477.25509 | ... M24: =M20+M21+M22+M23 -> 529.93212 | N24: =M24*(1+$C$27) -> 551.1294
B25: Terminal Value (Gordon Growth) | N25: =N24/($C$13-$C$27) -> 10511.718
B26: Fade-period growth (2031E–35E; 8% → 5% linear) | I26: 0.08 | J26: =I26+($M$26-$I$26)/4 -> 0.0725 | K26: =J26+($M$26-$I$26)/4 -> 0.065 | L26: =K26+($M$26-$I$26)/4 -> 0.0575 | M26: 0.05
B27: Terminal growth rate | C27: 0.04
B28: Included in valuation (1 = yes) | D28: 0 | E28: 1 | F28: 1 | G28: 1 | H28: 1 | I28: 1 | J28: 1 | K28: 1 | L28: 1 | M28: 1
B29: Discount period (years) | D29: =(DATE(2026,12,31)-$C$15)/365.25 -> 0.23271732 | E29: =(DATE(2027,12,31)-$C$15)/365.25 -> 1.2320329 | F29: =(DATE(2028,12,31)-$C$15)/365.25 -> 2.2340862 | G29: =(DATE(2029,12,31)-$C$15)/365.25 -> 3.2334018 | H29: =(DATE(2030,12,31)-$C$15)/365.25 -> 4.2327173 | I29: =(DATE(2031,12,31)-$C$15)/365.25 -> 5.2320329 | J29: =(DATE(2032,12,31)-$C$15)/365.25 -> 6.2340862 | K29: =(DATE(2033,12,31)-$C$15)/365.25 -> 7.2334018 | L29: =(DATE(2034,12,31)-$C$15)/365.25 -> 8.2327173 | M29: =(DATE(2035,12,31)-$C$15)/365.25 -> 9.2320329 | N29: =M29 -> 9.2320329
