Workbook

Sheet Model
CF1: SCENARIO SWITCH ▼ (Bull / Base / Bear) — drives all scenario-linked forecast drivers
B2: Clean Harbors, Inc. (NYSE: CLH) — 3-Statement Financial Model | CF2: Base
B3: US GAAP as reported · USD millions (per-share data in USD; shares in millions) · Source: Clean Harbors Forms 10-K / 10-Q and Form 8-K earnings releases (Ex. 99.1), deal & financing 8-Ks (Terra Nova May-26, ES&H Jul-26, EnviroServe Aug-26, $600m 6.25% notes Sep-26), Form 4 (share price), SEC EDGAR CIK 0000822818 (investor-relations releases are the same documents as filed on EDGAR)
B4: Basis notes: calendar fiscal year; each period as originally reported (quarters from 10-Qs, Q4 = FY − 9M; cash flows de-cumulated from YTD). Segments: Technical Services / Site Services 2006–08; Technical, Field, Industrial, Exploration (Eveready, Jul-09) / Oil & Gas Field Services 2009–12; Safety-Kleen acquired 28-Dec-2012 → 5–6 segments 2013–17; Environmental Services + Safety-Kleen from Q1/18 (2017 recast); Safety-Kleen renamed SKSS Q1/21. Adjusted EBITDA as published by period (SBC added back from Q1/21). Acquisitions: HydroChemPSC Oct-21, Thompson Industrial Mar-23, Noble Oil Mar-24, Depot Connect Mar-26, Terra Nova May-26, Western Oil Jul-26; ES&H ($305m) & EnviroServe ($470m) pending — excluded from FY26 guidance, modelled separately from Q3/26E.
CH5: Forecast | CI5: Historical | CJ5: Historical | CK5: Historical
B6: (USDm) | C6: 2006 | D6: 2007 | E6: 2008 | F6: 2009 | G6: 2010 | H6: 2011 | I6: 2012 | J6: Q1/13 | K6: Q2/13 | L6: Q3/13 | M6: Q4/13 | N6: 2013 | O6: Q1/14 | P6: Q2/14 | Q6: Q3/14 | R6: Q4/14 | S6: 2014 | T6: Q1/15 | U6: Q2/15 | V6: Q3/15 | W6: Q4/15 | X6: 2015 | Y6: Q1/16 | Z6: Q2/16 | AA6: Q3/16 | AB6: Q4/16 | AC6: 2016 | AD6: Q1/17 | AE6: Q2/17 | AF6: Q3/17 | AG6: Q4/17 | AH6: 2017 | AI6: Q1/18 | AJ6: Q2/18 | AK6: Q3/18 | AL6: Q4/18 | AM6: 2018 | AN6: Q1/19 | AO6: Q2/19 | AP6: Q3/19 | AQ6: Q4/19 | AR6: 2019 | AS6: Q1/20 | AT6: Q2/20 | AU6: Q3/20 | AV6: Q4/20 | AW6: 2020 | AX6: Q1/21 | AY6: Q2/21 | AZ6: Q3/21 | BA6: Q4/21 | BB6: 2021 | BC6: Q1/22 | BD6: Q2/22 | BE6: Q3/22 | BF6: Q4/22 | BG6: 2022 | BH6: Q1/23 | BI6: Q2/23 | BJ6: Q3/23 | BK6: Q4/23 | BL6: 2023 | BM6: Q1/24 | BN6: Q2/24 | BO6: Q3/24 | BP6: Q4/24 | BQ6: 2024 | BR6: Q1/25 | BS6: Q2/25 | BT6: Q3/25 | BU6: Q4/25 | BV6: 2025 | BW6: Q1/26 | BX6: Q2/26 | BY6: Q3/26E | BZ6: Q4/26E | CA6: 2026E | CB6: 2027E | CC6: 2028E | CD6: 2029E | CE6: 2030E | CF6: Modelling Notes | CH6: 5Y CAGR | CI6: 5Y CAGR | CJ6: 10Y CAGR | CK6: 19Y CAGR
CH7: 25-'30 | CI7: 20-'25 | CJ7: 15-'25 | CK7: 06-'25
B8: SEGMENT & SERVICE-LINE P&L — ENVIRONMENTAL SERVICES · SAFETY-KLEEN SUSTAINABILITY SOLUTIONS (service-line revenue × segment Adjusted EBITDA margin build) | CF8: SEGMENT BUILD — CLH reports segment profit as Adjusted EBITDA (no segment gross profit); revenues built by service line (third-party, ASC 606 disaggregation from 2018) + intersegment = segment direct revenues
CN9: SCENARIO INPUT TABLE — driver assumptions per Bull / Base / Bear | CO9: Bull | CP9: Base | CQ9: Bear | CR9: Bull / Bear = Base + Δ (Δ inputs on each block header). Outlook block = high / mid / low end of FY26 ranges.
B10: Environmental Services (ES) — Technical Services (incineration, landfill, TSDF network) · Field & Emergency Response · Industrial Services & Other · Safety-Kleen Environmental Services (ES portion from 2021) | CF10: ES — modelling logic: service lines = prior-year quarter × (1 + growth input) for Q3/Q4-26E; 2027E+ scenario levers. ES Adj. EBITDA = direct revenues × margin.
B11: Technical Services — third-party revenues | AI11: 236.306 | AJ11: 257.006 | AK11: 264.769 | AL11: 279.307 | AM11: 1037.388 | AN11: 251.919 | AO11: 275.908 | AP11: 292.506 | AQ11: 299.71 | AR11: 1120.043 | AS11: 275.273 | AT11: 241.929 | AU11: 257.612 | AV11: 287.9 | AW11: 1062.714 | AX11: 272.04 | AY11: 306.865 | AZ11: 308.158 | BA11: 322.561 | BB11: 1209.624 | BC11: 323.656 | BD11: 387.019 | BE11: 398.664 | BF11: 385.925 | BG11: 1495.264 | BH11: 366.509 | BI11: 389.908 | BJ11: 403.889 | BK11: 403.541 | BL11: 1563.847 | BM11: 407.491 | BN11: 443.668 | BO11: 437.18 | BP11: 445.211 | BQ11: 1733.55 | BR11: 426.205 | BS11: 463.421 | BT11: 490.768 | BU11: 479.311 | BV11: 1859.705 | BW11: 448.313 | BX11: 544.91 | BY11: =BT11*(1+BY12) -> 549.66016 | BZ11: =BU11*(1+BZ12) -> 527.2421 | CA11: =SUM(BW11,BX11,BY11,BZ11) -> 2070.1253 | CB11: =CA11*(1+CB12) -> 2235.7353 | CC11: =CB11*(1+CC12) -> 2403.4154 | CD11: =CC11*(1+CD12) -> 2571.6545 | CE11: =CD11*(1+CE12) -> 2738.812 | CF11: Incineration, landfill, wastewater, TSDF/transfer network (Kimball, NE incinerator online 2025; Terra Nova from 13-May-26). Historical: 10-Q/10-K revenue disaggregation (third-party), Q4 = FY − 9M. | CH11: =IFERROR((CE11/BV11)^(1/5)-1,"n/m") -> 0.080497171 | CI11: =IFERROR((BV11/AW11)^(1/5)-1,"n/m") -> 0.11842156 | CJ11: =IFERROR((BV11/X11)^(1/10)-1,"n/m") -> n/m | CK11: =IFERROR((BV11/C11)^(1/19)-1,"n/m") -> n/m | CN11: FY26 outlook — Q2-26 release (29-Jul-26); excludes pending ES&H / EnviroServe | CO11: High | CP11: Mid | CQ11: Low | CR11: Company guidance excludes ES&H (signed 17-Jul-26) and EnviroServe (signed 12-Aug-26) — the model adds them separately.
B12: Technical Services y/y % | D12: =IF(AND(ISNUMBER(D11),ISNUMBER(C11)),IFERROR(D11/C11-1,""),"") | E12: =IF(AND(ISNUMBER(E11),ISNUMBER(D11)),IFERROR(E11/D11-1,""),"") | F12: =IF(AND(ISNUMBER(F11),ISNUMBER(E11)),IFERROR(F11/E11-1,""),"") | G12: =IF(AND(ISNUMBER(G11),ISNUMBER(F11)),IFERROR(G11/F11-1,""),"") | H12: =IF(AND(ISNUMBER(H11),ISNUMBER(G11)),IFERROR(H11/G11-1,""),"") | I12: =IF(AND(ISNUMBER(I11),ISNUMBER(H11)),IFERROR(I11/H11-1,""),"") | N12: =IF(AND(ISNUMBER(N11),ISNUMBER(I11)),IFERROR(N11/I11-1,""),"") | O12: =IF(AND(ISNUMBER(O11),ISNUMBER(J11)),IFERROR(O11/J11-1,""),"") | P12: =IF(AND(ISNUMBER(P11),ISNUMBER(K11)),IFERROR(P11/K11-1,""),"") | Q12: =IF(AND(ISNUMBER(Q11),ISNUMBER(L11)),IFERROR(Q11/L11-1,""),"") | R12: =IF(AND(ISNUMBER(R11),ISNUMBER(M11)),IFERROR(R11/M11-1,""),"") | S12: =IF(AND(ISNUMBER(S11),ISNUMBER(N11)),IFERROR(S11/N11-1,""),"") | T12: =IF(AND(ISNUMBER(T11),ISNUMBER(O11)),IFERROR(T11/O11-1,""),"") | U12: =IF(AND(ISNUMBER(U11),ISNUMBER(P11)),IFERROR(U11/P11-1,""),"") | ... BX12: =IF(AND(ISNUMBER(BX11),ISNUMBER(BS11)),IFERROR(BX11/BS11-1,""),"") -> 0.17584227 | BY12: =BY13 -> 0.12 | BZ12: =BZ13 -> 0.1 | CA12: =IFERROR(CA11/BV11-1,"") -> 0.11314712 | CB12: =CHOOSE(MATCH($CF$2,{"Bull","Base","Bear"},0),$CO$31,$CP$31,$CQ$31) -> 0.08 | CC12: =CHOOSE(MATCH($CF$2,{"Bull","Base","Bear"},0),$CO$32,$CP$32,$CQ$32) -> 0.075 | CD12: =CHOOSE(MATCH($CF$2,{"Bull","Base","Bear"},0),$CO$33,$CP$33,$CQ$33) -> 0.07 | CE12: =CHOOSE(MATCH($CF$2,{"Bull","Base","Bear"},0),$CO$34,$CP$34,$CQ$34) -> 0.065 | CF12: Q3/Q4-26E: growth input below. 2027E+: scenario lever TS_growth (pricing + volumes into the disposal network, PFAS, reshoring). | CN12: FY26 Adjusted EBITDA ($m) | CO12: 1410 | CP12: 1380 | CQ12: 1350 | CR12: Raised by $110m at the mid-point in the Q2-26 release (from $1,240–1,300m). Drives the Q3/Q4-26E margin calibration.
B13: Q3/Q4-26E growth input (incl. Terra Nova from May-26) | BY13: 0.12 | BZ13: 0.1 | CF13: Q2/26 +17.6% y/y (incl. Terra Nova ~$12m/qtr, Kimball ramp, large PFAS filtration project). H2 input +12% / +10% as Kimball and the PFAS project anniversary. | CN13: FY26 GAAP net income ($m) | CO13: 531 | CP13: 506 | CQ13: 481 | CR13: Q2-26 release guidance reconciliation (memo).
B14: Field & Emergency Response Services — third-party revenues | AI14: 69.935 | AJ14: 76.092 | AK14: 77.025 | AL14: 81.675 | AM14: 304.727 | AN14: 71.626 | AO14: 86.722 | AP14: 95.546 | AQ14: 87.012 | AR14: 340.906 | AS14: 105.912 | AT14: 127.353 | AU14: 115.989 | AV14: 111.782 | AW14: 461.036 | AX14: 105.168 | AY14: 106.986 | AZ14: 116.677 | BA14: 137.549 | BB14: 466.38 | BC14: 132.359 | BD14: 144.86 | BE14: 150.031 | BF14: 148.05 | BG14: 575.3 | BH14: 148.086 | BI14: 154.359 | BJ14: 155.046 | BK14: 152.422 | BL14: 609.913 | BM14: 163.469 | BN14: 252.893 | BO14: 260.2 | BP14: 218.558 | BQ14: 895.12 | BR14: 215.702 | BS14: 242.791 | BT14: 232.262 | BU14: 246.607 | BV14: 937.362 | BW14: 231.358 | BX14: 249.02 | BY14: =BT14*(1+BY15) -> 248.52034 | BZ14: =BU14*(1+BZ15) -> 258.93735 | CA14: =SUM(BW14,BX14,BY14,BZ14) -> 987.83569 | CB14: =CA14*(1+CB15) -> 1037.2275 | CC14: =CB14*(1+CC15) -> 1089.0888 | CD14: =CC14*(1+CD15) -> 1138.0978 | CE14: =CD14*(1+CE15) -> 1189.3122 | CH14: =IFERROR((CE14/BV14)^(1/5)-1,"n/m") -> 0.048763851 | CI14: =IFERROR((BV14/AW14)^(1/5)-1,"n/m") -> 0.15248293 | CJ14: =IFERROR((BV14/X14)^(1/10)-1,"n/m") -> n/m | CK14: =IFERROR((BV14/C14)^(1/19)-1,"n/m") -> n/m | CN14: FY26 net cash from operating activities ($m) | CO14: 1010 | CP14: 950 | CQ14: 890 | CR14: Q2-26 release (memo vs model CFO).
B15: Field & Emergency Response y/y % | D15: =IF(AND(ISNUMBER(D14),ISNUMBER(C14)),IFERROR(D14/C14-1,""),"") | E15: =IF(AND(ISNUMBER(E14),ISNUMBER(D14)),IFERROR(E14/D14-1,""),"") | F15: =IF(AND(ISNUMBER(F14),ISNUMBER(E14)),IFERROR(F14/E14-1,""),"") | G15: =IF(AND(ISNUMBER(G14),ISNUMBER(F14)),IFERROR(G14/F14-1,""),"") | H15: =IF(AND(ISNUMBER(H14),ISNUMBER(G14)),IFERROR(H14/G14-1,""),"") | I15: =IF(AND(ISNUMBER(I14),ISNUMBER(H14)),IFERROR(I14/H14-1,""),"") | N15: =IF(AND(ISNUMBER(N14),ISNUMBER(I14)),IFERROR(N14/I14-1,""),"") | O15: =IF(AND(ISNUMBER(O14),ISNUMBER(J14)),IFERROR(O14/J14-1,""),"") | P15: =IF(AND(ISNUMBER(P14),ISNUMBER(K14)),IFERROR(P14/K14-1,""),"") | Q15: =IF(AND(ISNUMBER(Q14),ISNUMBER(L14)),IFERROR(Q14/L14-1,""),"") | R15: =IF(AND(ISNUMBER(R14),ISNUMBER(M14)),IFERROR(R14/M14-1,""),"") | S15: =IF(AND(ISNUMBER(S14),ISNUMBER(N14)),IFERROR(S14/N14-1,""),"") | T15: =IF(AND(ISNUMBER(T14),ISNUMBER(O14)),IFERROR(T14/O14-1,""),"") | U15: =IF(AND(ISNUMBER(U14),ISNUMBER(P14)),IFERROR(U14/P14-1,""),"") | ... BX15: =IF(AND(ISNUMBER(BX14),ISNUMBER(BS14)),IFERROR(BX14/BS14-1,""),"") -> 0.025655811 | BY15: =BY16 -> 0.07 | BZ15: =BZ16 -> 0.05 | CA15: =IFERROR(CA14/BV14-1,"") -> 0.053846529 | CB15: =CHOOSE(MATCH($CF$2,{"Bull","Base","Bear"},0),$CO$36,$CP$36,$CQ$36) -> 0.05 | CC15: =CHOOSE(MATCH($CF$2,{"Bull","Base","Bear"},0),$CO$37,$CP$37,$CQ$37) -> 0.05 | CD15: =CHOOSE(MATCH($CF$2,{"Bull","Base","Bear"},0),$CO$38,$CP$38,$CQ$38) -> 0.045 | CE15: =CHOOSE(MATCH($CF$2,{"Bull","Base","Bear"},0),$CO$39,$CP$39,$CQ$39) -> 0.045 | CN15: FY26 additions to PP&E ($m) | CO15: 565 | CP15: 535 | CQ15: 505 | CR15: Q2-26 release adjusted-FCF reconciliation: ($505)–($565)m.
B16: Q3/Q4-26E growth input | BY16: 0.07 | BZ16: 0.05 | CF16: Q2/26 +2.6% y/y against large prior-year ER comps; company: "multiple large emergency response events that should support Q3 growth". ES&H (Gulf ER) modelled separately in the deal block. | CN16: FY26 adjusted free cash flow ($m) | CO16: 580 | CP16: 550 | CQ16: 520 | CR16: Raised by $30m at the mid-point.
B17: Industrial Services & Other — third-party revenues (incl. Oil, Gas & Lodging and other to 2019) | AI17: 133.447 | AJ17: 186.818 | AK17: 167.019 | AL17: 174.444 | AM17: 661.728 | AN17: 150.153 | AO17: 163.664 | AP17: 162.07 | AQ17: 155.527 | AR17: 631.414 | AS17: 146.919 | AT17: 95.072 | AU17: 124.582 | AV17: 113.758 | AW17: 480.331 | AX17: 119.81 | AY17: 150.367 | AZ17: 154.977 | BA17: 280.845 | BB17: 705.999 | BC17: 308.838 | BD17: 360.87 | BE17: 332.025 | BF17: 309.339 | BG17: 1311.072 | BH17: 336.379 | BI17: 399.545 | BJ17: 350.251 | BK17: 332.763 | BL17: 1418.938 | BM17: 359.397 | BN17: 359.471 | BO17: 345.573 | BP17: 313.061 | BQ17: 1377.502 | BR17: 322.358 | BS17: 361.58 | BT17: 332.102 | BU17: 311.843 | BV17: 1327.883 | BW17: 302.561 | BX17: 358.929 | BY17: =BT17*(1+BY18) -> 342.06506 | BZ17: =BU17*(1+BZ18) -> 324.31672 | CA17: =SUM(BW17,BX17,BY17,BZ17) -> 1327.8718 | CB17: =CA17*(1+CB18) -> 1367.7079 | CC17: =CB17*(1+CC18) -> 1415.5777 | CD17: =CC17*(1+CD18) -> 1465.1229 | CE17: =CD17*(1+CE18) -> 1516.4022 | CH17: =IFERROR((CE17/BV17)^(1/5)-1,"n/m") -> 0.026906543 | CI17: =IFERROR((BV17/AW17)^(1/5)-1,"n/m") -> 0.2255297 | CJ17: =IFERROR((BV17/X17)^(1/10)-1,"n/m") -> n/m | CK17: =IFERROR((BV17/C17)^(1/19)-1,"n/m") -> n/m | CN17: FY26 point estimates (guidance mid-points; all cases)
B18: Industrial Services & Other y/y % | D18: =IF(AND(ISNUMBER(D17),ISNUMBER(C17)),IFERROR(D17/C17-1,""),"") | E18: =IF(AND(ISNUMBER(E17),ISNUMBER(D17)),IFERROR(E17/D17-1,""),"") | F18: =IF(AND(ISNUMBER(F17),ISNUMBER(E17)),IFERROR(F17/E17-1,""),"") | G18: =IF(AND(ISNUMBER(G17),ISNUMBER(F17)),IFERROR(G17/F17-1,""),"") | H18: =IF(AND(ISNUMBER(H17),ISNUMBER(G17)),IFERROR(H17/G17-1,""),"") | I18: =IF(AND(ISNUMBER(I17),ISNUMBER(H17)),IFERROR(I17/H17-1,""),"") | N18: =IF(AND(ISNUMBER(N17),ISNUMBER(I17)),IFERROR(N17/I17-1,""),"") | O18: =IF(AND(ISNUMBER(O17),ISNUMBER(J17)),IFERROR(O17/J17-1,""),"") | P18: =IF(AND(ISNUMBER(P17),ISNUMBER(K17)),IFERROR(P17/K17-1,""),"") | Q18: =IF(AND(ISNUMBER(Q17),ISNUMBER(L17)),IFERROR(Q17/L17-1,""),"") | R18: =IF(AND(ISNUMBER(R17),ISNUMBER(M17)),IFERROR(R17/M17-1,""),"") | S18: =IF(AND(ISNUMBER(S17),ISNUMBER(N17)),IFERROR(S17/N17-1,""),"") | T18: =IF(AND(ISNUMBER(T17),ISNUMBER(O17)),IFERROR(T17/O17-1,""),"") | U18: =IF(AND(ISNUMBER(U17),ISNUMBER(P17)),IFERROR(U17/P17-1,""),"") | ... BX18: =IF(AND(ISNUMBER(BX17),ISNUMBER(BS17)),IFERROR(BX17/BS17-1,""),"") -> -0.0073317108 | BY18: =BY19 -> 0.03 | BZ18: =BZ19 -> 0.04 | CA18: =IFERROR(CA17/BV17-1,"") -> -8.4495396e-06 | CB18: =CHOOSE(MATCH($CF$2,{"Bull","Base","Bear"},0),$CO$41,$CP$41,$CQ$41) -> 0.03 | CC18: =CHOOSE(MATCH($CF$2,{"Bull","Base","Bear"},0),$CO$42,$CP$42,$CQ$42) -> 0.035 | CD18: =CHOOSE(MATCH($CF$2,{"Bull","Base","Bear"},0),$CO$43,$CP$43,$CQ$43) -> 0.035 | CE18: =CHOOSE(MATCH($CF$2,{"Bull","Base","Bear"},0),$CO$44,$CP$44,$CQ$44) -> 0.035 | CN18: Stock-based compensation ($m) | CP18: 49.5 | CR18: Guidance reconciliation $48–51m.
B19: Q3/Q4-26E growth input (incl. Depot Connect from 20-Mar-26) | BY19: 0.03 | BZ19: 0.04 | CF19: Q2/26 −0.7% y/y (refinery turnaround timing) despite Depot Connect International ($131m, Mar-26). New data-center offering expected to support growth. | CN19: Depreciation & amortization ($m) | CP19: 480 | CR19: Guidance reconciliation $475–485m.
B20: Safety-Kleen Environmental Services — ES portion (containerized waste, vacuum, branch services; from 2021) | AI20: 0 | AJ20: 0 | AK20: 0 | AL20: 0 | AM20: 0 | AN20: 0 | AO20: 0 | AP20: 0 | AQ20: 0 | AR20: 0 | AS20: 0 | AT20: 0 | AU20: 0 | AV20: 0 | AW20: 0 | AX20: 155.86 | AY20: 158.929 | AZ20: 164.019 | BA20: 165.096 | BB20: 643.904 | BC20: 175.945 | BD20: 191.757 | BE20: 199.312 | BF20: 196.323 | BG20: 763.337 | BH20: 210.008 | BI20: 217.67 | BJ20: 226.093 | BK20: 223.44 | BL20: 877.211 | BM20: 230.922 | BN20: 241.266 | BO20: 244.697 | BP20: 237.268 | BQ20: 954.153 | BR20: 242.773 | BS20: 262.267 | BT20: 263.448 | BU20: 252.916 | BV20: 1021.404 | BW20: 260.216 | BX20: 291.673 | BY20: =BT20*(1+BY21) -> 289.7928 | BZ20: =BU20*(1+BZ21) -> 275.67844 | CA20: =SUM(BW20,BX20,BY20,BZ20) -> 1117.3602 | CB20: =CA20*(1+CB21) -> 1195.5755 | CC20: =CB20*(1+CC21) -> 1273.2879 | CD20: =CC20*(1+CD21) -> 1349.6851 | CE20: =CD20*(1+CE21) -> 1430.6662 | CH20: =IFERROR((CE20/BV20)^(1/5)-1,"n/m") -> 0.069715171 | CI20: =IFERROR((BV20/AW20)^(1/5)-1,"n/m") -> n/m | CJ20: =IFERROR((BV20/X20)^(1/10)-1,"n/m") -> n/m | CK20: =IFERROR((BV20/C20)^(1/19)-1,"n/m") -> n/m | CN20: Accretion of environmental liabilities ($m) | CP20: 15.5 | CR20: Guidance reconciliation $15–16m.
B21: Safety-Kleen Environmental Services (ES) y/y % | D21: =IF(AND(ISNUMBER(D20),ISNUMBER(C20)),IFERROR(D20/C20-1,""),"") | E21: =IF(AND(ISNUMBER(E20),ISNUMBER(D20)),IFERROR(E20/D20-1,""),"") | F21: =IF(AND(ISNUMBER(F20),ISNUMBER(E20)),IFERROR(F20/E20-1,""),"") | G21: =IF(AND(ISNUMBER(G20),ISNUMBER(F20)),IFERROR(G20/F20-1,""),"") | H21: =IF(AND(ISNUMBER(H20),ISNUMBER(G20)),IFERROR(H20/G20-1,""),"") | I21: =IF(AND(ISNUMBER(I20),ISNUMBER(H20)),IFERROR(I20/H20-1,""),"") | N21: =IF(AND(ISNUMBER(N20),ISNUMBER(I20)),IFERROR(N20/I20-1,""),"") | O21: =IF(AND(ISNUMBER(O20),ISNUMBER(J20)),IFERROR(O20/J20-1,""),"") | P21: =IF(AND(ISNUMBER(P20),ISNUMBER(K20)),IFERROR(P20/K20-1,""),"") | Q21: =IF(AND(ISNUMBER(Q20),ISNUMBER(L20)),IFERROR(Q20/L20-1,""),"") | R21: =IF(AND(ISNUMBER(R20),ISNUMBER(M20)),IFERROR(R20/M20-1,""),"") | S21: =IF(AND(ISNUMBER(S20),ISNUMBER(N20)),IFERROR(S20/N20-1,""),"") | T21: =IF(AND(ISNUMBER(T20),ISNUMBER(O20)),IFERROR(T20/O20-1,""),"") | U21: =IF(AND(ISNUMBER(U20),ISNUMBER(P20)),IFERROR(U20/P20-1,""),"") | ... BX21: =IF(AND(ISNUMBER(BX20),ISNUMBER(BS20)),IFERROR(BX20/BS20-1,""),"") -> 0.11212238 | BY21: =BY22 -> 0.1 | BZ21: =BZ22 -> 0.09 | CA21: =IFERROR(CA20/BV20-1,"") -> 0.093945432 | CB21: =CHOOSE(MATCH($CF$2,{"Bull","Base","Bear"},0),$CO$46,$CP$46,$CQ$46) -> 0.07 | CC21: =CHOOSE(MATCH($CF$2,{"Bull","Base","Bear"},0),$CO$47,$CP$47,$CQ$47) -> 0.065 | CD21: =CHOOSE(MATCH($CF$2,{"Bull","Base","Bear"},0),$CO$48,$CP$48,$CQ$48) -> 0.06 | CE21: =CHOOSE(MATCH($CF$2,{"Bull","Base","Bear"},0),$CO$49,$CP$49,$CQ$49) -> 0.06 | CN21: Interest expense, net ($m) | CP21: 148.5 | CR21: Guidance reconciliation $146–151m (before the Oct-26 notes).
B22: Q3/Q4-26E growth input (SK Environmental Services, ES & SKSS portions) | BY22: 0.1 | BZ22: 0.09 | CF22: Q2/26 +11.2% (ES) / +21.1% (SKSS) y/y on pricing, containerized waste and vacuum services (Noble Oil / Western Oil branches). | CN22: Tax rate (GAAP) | CP22: =180.5/(506+180.5) -> 0.2629279 | CR22: Implied by the mid-point reconciliation: tax $180.5m / pre-tax $686.5m.
B23: ES third-party revenues (Σ service lines from 2018; as reported 2017) | AD23: 395.907 | AE23: 449.631 | AF23: 440.163 | AG23: 442.999 | AH23: 1728.7 | AI23: 439.688 | AJ23: 519.916 | AK23: 508.813 | AL23: 535.426 | AM23: 2003.843 | AN23: 473.698 | AO23: 526.294 | AP23: 550.122 | AQ23: 542.249 | AR23: 2092.363 | AS23: 528.104 | AT23: 464.354 | AU23: 498.183 | AV23: 513.44 | AW23: 2004.081 | AX23: 652.878 | AY23: 723.147 | AZ23: 743.831 | BA23: 906.051 | BB23: 3025.907 | BC23: 940.798 | BD23: 1084.506 | BE23: 1080.032 | BF23: 1039.637 | BG23: 4144.973 | BH23: 1060.982 | BI23: 1161.482 | BJ23: 1135.279 | BK23: 1112.166 | BL23: 4469.909 | BM23: 1161.279 | BN23: 1297.298 | BO23: 1287.65 | BP23: 1214.098 | BQ23: 4960.325 | BR23: 1207.038 | BS23: 1330.059 | BT23: 1318.58 | BU23: 1290.677 | BV23: 5146.354 | BW23: 1242.448 | BX23: 1444.532 | BY23: =BY11+BY14+BY17+BY20 -> 1430.0384 | BZ23: =BZ11+BZ14+BZ17+BZ20 -> 1386.1746 | CA23: =SUM(BW23,BX23,BY23,BZ23) -> 5503.193 | CB23: =CB11+CB14+CB17+CB20 -> 5836.2461 | CC23: =CC11+CC14+CC17+CC20 -> 6181.3698 | CD23: =CD11+CD14+CD17+CD20 -> 6524.5604 | CE23: =CE11+CE14+CE17+CE20 -> 6875.1928 | CN23: Strategic growth investments excluded from adjusted FCF ($m) | CP23: 120 | CR23: Guidance reconciliation.
B24: Check: Σ service lines vs ES third-party revenues (should be 0) | AI24: =IF(ISNUMBER(AI11),ROUND(AI11+AI14+AI17+N(AI20)-AI23,1),"") -> 0 | AJ24: =IF(ISNUMBER(AJ11),ROUND(AJ11+AJ14+AJ17+N(AJ20)-AJ23,1),"") -> 0 | AK24: =IF(ISNUMBER(AK11),ROUND(AK11+AK14+AK17+N(AK20)-AK23,1),"") -> 0 | AL24: =IF(ISNUMBER(AL11),ROUND(AL11+AL14+AL17+N(AL20)-AL23,1),"") -> 0 | AM24: =IF(ISNUMBER(AM11),ROUND(AM11+AM14+AM17+N(AM20)-AM23,1),"") -> 0 | AN24: =IF(ISNUMBER(AN11),ROUND(AN11+AN14+AN17+N(AN20)-AN23,1),"") -> 0 | AO24: =IF(ISNUMBER(AO11),ROUND(AO11+AO14+AO17+N(AO20)-AO23,1),"") -> 0 | AP24: =IF(ISNUMBER(AP11),ROUND(AP11+AP14+AP17+N(AP20)-AP23,1),"") -> 0 | ... BX24: =IF(ISNUMBER(BX11),ROUND(BX11+BX14+BX17+N(BX20)-BX23,1),"") -> 0 | CN24: Proceeds from sale & disposal of fixed assets ($m) | CP24: 15 | CR24: Guidance reconciliation.
B25: Intersegment revenues (expenses), net | AD25: 32.989 | AE25: 31.959 | AF25: 32.518 | AG25: 31.308 | AH25: 128.774 | AI25: 32.759 | AJ25: 34.898 | AK25: 34.167 | AL25: 35.527 | AM25: 137.351 | AN25: 35.324 | AO25: 36.782 | AP25: 36.75 | AQ25: 35.849 | AR25: 144.705 | AS25: 38.258 | AT25: 32.56 | AU25: 29.787 | AV25: 32.62 | AW25: 133.225 | AX25: 1.724 | AY25: 0.95 | AZ25: 1.802 | BA25: 2.071 | BB25: 6.547 | BC25: 6.647 | BD25: 6.237 | BE25: 6.452 | BF25: 7.397 | BG25: 26.733 | BH25: 9.759 | BI25: 10.554 | BJ25: 11.084 | BK25: 10.136 | BL25: 41.533 | BM25: 11.231 | BN25: 12.085 | BO25: 9.537 | BP25: 11.569 | BQ25: 44.422 | BR25: 2.075 | BS25: 21.976 | BT25: 12.72 | BU25: 10.165 | BV25: 46.936 | BW25: 10.078 | BX25: 12.031 | BY25: =AVERAGE(BW25,BX25) -> 11.0545 | BZ25: =AVERAGE(BW25,BX25) -> 11.0545 | CA25: =SUM(BW25,BX25,BY25,BZ25) -> 44.218 | CB25: =CB23*CB26 -> 46.894073 | CC25: =CC23*CC26 -> 49.667132 | CD25: =CD23*CD26 -> 52.424659 | CE25: =CE23*CE26 -> 55.24198 | CF25: Net revenue for disposal/recycling of SKSS-collected waste. Q3/Q4-26E: 1H/26 quarterly average; 2027E+: 2026E % of ES third-party revenues. | CN25: 2H/26 share repurchases ($m) | CO25: 100 | CP25: 50 | CQ25: 0 | CR25: Q2/26 $25m; 1H/26 $52m. Base: Q2 pace maintained alongside ~$0.8bn of deal funding.
B26: Intersegment % of ES third-party revenues | AD26: =IF(AND(ISNUMBER(AD25),ISNUMBER(AD23)),IFERROR(AD25/AD23,""),"") -> 0.083325124 | AE26: =IF(AND(ISNUMBER(AE25),ISNUMBER(AE23)),IFERROR(AE25/AE23,""),"") -> 0.071078284 | AF26: =IF(AND(ISNUMBER(AF25),ISNUMBER(AF23)),IFERROR(AF25/AF23,""),"") -> 0.073877177 | AG26: =IF(AND(ISNUMBER(AG25),ISNUMBER(AG23)),IFERROR(AG25/AG23,""),"") -> 0.070672846 | AH26: =IF(AND(ISNUMBER(AH25),ISNUMBER(AH23)),IFERROR(AH25/AH23,""),"") -> 0.074491815 | AI26: =IF(AND(ISNUMBER(AI25),ISNUMBER(AI23)),IFERROR(AI25/AI23,""),"") -> 0.074505104 | AJ26: =IF(AND(ISNUMBER(AJ25),ISNUMBER(AJ23)),IFERROR(AJ25/AJ23,""),"") -> 0.067122381 | AK26: =IF(AND(ISNUMBER(AK25),ISNUMBER(AK23)),IFERROR(AK25/AK23,""),"") -> 0.067150407 | ... CA26: =IF(AND(ISNUMBER(CA25),ISNUMBER(CA23)),IFERROR(CA25/CA23,""),"") -> 0.0080349717 | CB26: =$CA$26 -> 0.0080349717 | CC26: =$CA$26 -> 0.0080349717 | CD26: =$CA$26 -> 0.0080349717 | CE26: =$CA$26 -> 0.0080349717 | CN26: Pending-deal run-rate cost synergies ($m) | CP26: 30 | CR26: EnviroServe ~$25m (within two years) + ES&H ~$5m (after first full year).
B27: ES direct revenues (segment revenues) | AD27: 428.896 | AE27: 481.59 | AF27: 472.681 | AG27: 474.307 | AH27: 1857.474 | AI27: 472.447 | AJ27: 554.814 | AK27: 542.98 | AL27: 570.953 | AM27: 2141.194 | AN27: 509.022 | AO27: 563.076 | AP27: 586.872 | AQ27: 578.098 | AR27: 2237.068 | AS27: 566.362 | AT27: 496.914 | AU27: 527.97 | AV27: 546.06 | AW27: 2137.306 | AX27: 654.602 | AY27: 724.097 | AZ27: 745.633 | BA27: 908.122 | BB27: 3032.454 | BC27: 947.445 | BD27: 1090.743 | BE27: 1086.484 | BF27: 1047.034 | BG27: 4171.706 | BH27: 1070.741 | BI27: 1172.036 | BJ27: 1146.363 | BK27: 1122.302 | BL27: 4511.442 | BM27: 1172.51 | BN27: 1309.383 | BO27: 1297.187 | BP27: 1225.667 | BQ27: 5004.747 | BR27: 1209.113 | BS27: 1352.035 | BT27: 1331.3 | BU27: 1300.842 | BV27: 5193.29 | BW27: 1252.526 | BX27: 1456.563 | BY27: =BY23+BY25 -> 1441.0929 | BZ27: =BZ23+BZ25 -> 1397.2291 | CA27: =SUM(BW27,BX27,BY27,BZ27) -> 5547.411 | CB27: =CB23+CB25 -> 5883.1402 | CC27: =CC23+CC25 -> 6231.037 | CD27: =CD23+CD25 -> 6576.9851 | CE27: =CE23+CE25 -> 6930.4348 | CH27: =IFERROR((CE27/BV27)^(1/5)-1,"n/m") -> 0.059408812 | CI27: =IFERROR((BV27/AW27)^(1/5)-1,"n/m") -> 0.19430479 | CJ27: =IFERROR((BV27/X27)^(1/10)-1,"n/m") -> n/m | CK27: =IFERROR((BV27/C27)^(1/19)-1,"n/m") -> n/m | CN27: Minimum annual buyback programme 2027E+ ($m) | CP27: 150 | CR27: CLH repurchased $50–200m p.a. 2022–25; $549m authorisation remaining.
B28: ES direct revenues y/y % | AI28: =IF(AND(ISNUMBER(AI27),ISNUMBER(AD27)),IFERROR(AI27/AD27-1,""),"") -> 0.1015421 | AJ28: =IF(AND(ISNUMBER(AJ27),ISNUMBER(AE27)),IFERROR(AJ27/AE27-1,""),"") -> 0.15204635 | AK28: =IF(AND(ISNUMBER(AK27),ISNUMBER(AF27)),IFERROR(AK27/AF27-1,""),"") -> 0.14872398 | AL28: =IF(AND(ISNUMBER(AL27),ISNUMBER(AG27)),IFERROR(AL27/AG27-1,""),"") -> 0.20376254 | AM28: =IF(AND(ISNUMBER(AM27),ISNUMBER(AH27)),IFERROR(AM27/AH27-1,""),"") -> 0.15274507 | AN28: =IF(AND(ISNUMBER(AN27),ISNUMBER(AI27)),IFERROR(AN27/AI27-1,""),"") -> 0.077416091 | AO28: =IF(AND(ISNUMBER(AO27),ISNUMBER(AJ27)),IFERROR(AO27/AJ27-1,""),"") -> 0.014891477 | AP28: =IF(AND(ISNUMBER(AP27),ISNUMBER(AK27)),IFERROR(AP27/AK27-1,""),"") -> 0.08083539 | ... BX28: =IF(AND(ISNUMBER(BX27),ISNUMBER(BS27)),IFERROR(BX27/BS27-1,""),"") -> 0.077311608 | BY28: =IFERROR(BY27/BT27-1,"") -> 0.082470412 | BZ28: =IFERROR(BZ27/BU27-1,"") -> 0.074095939 | CA28: =IFERROR(CA27/BV27-1,"") -> 0.068188176 | CB28: =IFERROR(CB27/CA27-1,"") -> 0.060519989 | CC28: =IFERROR(CC27/CB27-1,"") -> 0.059134535 | CD28: =IFERROR(CD27/CC27-1,"") -> 0.055520148 | CE28: =IFERROR(CE27/CD27-1,"") -> 0.05374038 | CN28: Minimum net debt / Adjusted EBITDA (x) — buyback floor 2027E+ | CO28: 2 | CP28: 1.75 | CQ28: 1.5 | CR28: Surplus cash above the floor returned via buybacks.
B29: ES Adjusted EBITDA (segment profit measure) | AD29: 60.19 | AE29: 94.832 | AF29: 86.505 | AG29: 79.783 | AH29: 321.31 | AI29: 61.417 | AJ29: 109.199 | AK29: 102.419 | AL29: 107.821 | AM29: 380.856 | AN29: 89.51 | AO29: 117.868 | AP29: 121.658 | AQ29: 117.248 | AR29: 446.284 | AS29: 108.914 | AT29: 138.083 | AU29: 140.854 | AV29: 132.109 | AW29: 519.96 | AX29: 140.254 | AY29: 176.041 | AZ29: 166.471 | BA29: 176.952 | BB29: 659.718 | BC29: 183.602 | BD29: 269.341 | BE29: 260.687 | BF29: 239.423 | BG29: 953.053 | BH29: 228.345 | BI29: 305.622 | BJ29: 288.982 | BK29: 278.659 | BL29: 1101.608 | BM29: 264.475 | BN29: 359.915 | BO29: 332.502 | BP29: 310.57 | BQ29: 1267.462 | BR29: 274.591 | BS29: 376.194 | BT29: 357.229 | BU29: 335.762 | BV29: 1343.776 | BW29: 290.401 | BX29: 406.104 | BY29: =BY27*BY31 -> 404.90967 | BZ29: =BZ27*BZ31 -> 378.30588 | CA29: =SUM(BW29,BX29,BY29,BZ29) -> 1479.7206 | CB29: =CB27*CB31 -> 1623.7467 | CC29: =CC27*CC31 -> 1744.6904 | CD29: =CD27*CD31 -> 1867.8638 | CE29: =CE27*CE31 -> 1989.0348 | CH29: =IFERROR((CE29/BV29)^(1/5)-1,"n/m") -> 0.081591085 | CI29: =IFERROR((BV29/AW29)^(1/5)-1,"n/m") -> 0.20912552 | CJ29: =IFERROR((BV29/X29)^(1/10)-1,"n/m") -> n/m | CK29: =IFERROR((BV29/C29)^(1/19)-1,"n/m") -> n/m
B30: Adj. EBITDA margin before outlook calibration % (Q3/Q4-26E helper) | BY30: =BT31+(BW29+BX29)/(BW27+BX27)-(BR29+BS29)/(BR27+BS27) -> 0.27133135 | BZ30: =BU31+(BW29+BX29)/(BW27+BX27)-(BR29+BS29)/(BR27+BS27) -> 0.26111168 | CF30: Prior-year quarter margin + 1H/26 y/y margin drift (1H/26 25.7% vs 1H/25 25.4%). | CN30: TS_growth (Technical Services revenues y/y) | CO30: 0.02 | CP30: Δ → | CQ30: -0.02 | CR30: Incineration / landfill pricing + volumes (reshoring, PFAS, Kimball ramp); FY23–25 +11% / +11% / +7%.
B31: ES Adjusted EBITDA margin % (on direct revenues) | AD31: =IF(AND(ISNUMBER(AD29),ISNUMBER(AD27)),IFERROR(AD29/AD27,""),"") -> 0.14033705 | AE31: =IF(AND(ISNUMBER(AE29),ISNUMBER(AE27)),IFERROR(AE29/AE27,""),"") -> 0.19691439 | AF31: =IF(AND(ISNUMBER(AF29),ISNUMBER(AF27)),IFERROR(AF29/AF27,""),"") -> 0.18300926 | AG31: =IF(AND(ISNUMBER(AG29),ISNUMBER(AG27)),IFERROR(AG29/AG27,""),"") -> 0.16820962 | AH31: =IF(AND(ISNUMBER(AH29),ISNUMBER(AH27)),IFERROR(AH29/AH27,""),"") -> 0.17298223 | AI31: =IF(AND(ISNUMBER(AI29),ISNUMBER(AI27)),IFERROR(AI29/AI27,""),"") -> 0.12999765 | AJ31: =IF(AND(ISNUMBER(AJ29),ISNUMBER(AJ27)),IFERROR(AJ29/AJ27,""),"") -> 0.19682092 | AK31: =IF(AND(ISNUMBER(AK29),ISNUMBER(AK27)),IFERROR(AK29/AK27,""),"") -> 0.18862389 | ... BX31: =IF(AND(ISNUMBER(BX29),ISNUMBER(BX27)),IFERROR(BX29/BX27,""),"") -> 0.27880977 | BY31: =BY30+BY101 -> 0.28097403 | BZ31: =BZ30+BZ101 -> 0.27075436 | CA31: =IF(AND(ISNUMBER(CA29),ISNUMBER(CA27)),IFERROR(CA29/CA27,""),"") -> 0.26674075 | CB31: =CHOOSE(MATCH($CF$2,{"Bull","Base","Bear"},0),$CO$56,$CP$56,$CQ$56) -> 0.276 | CC31: =CHOOSE(MATCH($CF$2,{"Bull","Base","Bear"},0),$CO$57,$CP$57,$CQ$57) -> 0.28 | CD31: =CHOOSE(MATCH($CF$2,{"Bull","Base","Bear"},0),$CO$58,$CP$58,$CQ$58) -> 0.284 | CE31: =CHOOSE(MATCH($CF$2,{"Bull","Base","Bear"},0),$CO$59,$CP$59,$CQ$59) -> 0.287 | CF31: Q3/Q4-26E: pre-calibration margin + outlook calibration Δ (solves FY26 Adjusted EBITDA = guidance end-point). 2027E+: scenario lever ES_margin (17 consecutive quarters of y/y margin expansion to Q2/26). | CH31: =IFERROR(AVERAGE(CA31,CB31,CC31,CD31,CE31),"n/m") -> 0.27874815 | CI31: =IFERROR(AVERAGE(BB31,BG31,BL31,BQ31,BV31),"n/m") -> 0.24043883 | CJ31: =IFERROR(AVERAGE(AC31,AH31,AM31,AR31,AW31,BB31,BG31,BL31,BQ31,BV31),"n/m") -> 0.22175783 | CK31: =IFERROR(AVERAGE(C31,D31,E31,F31,G31,H31,I31,N31,S31,X31,AC31,AH31,AM31,AR31,AW31,BB31,BG31,BL31,BQ31,BV31),"n/m") -> 0.22175783 | CN31: 2027E | CO31: =CP31+$CO$30 -> 0.1 | CP31: 0.08 | CQ31: =CP31+$CQ$30 -> 0.06
B32: ES incremental margin (Δ Adj. EBITDA / Δ direct revenues, y/y) | AI32: =IFERROR((AI29-AD29)/(AI27-AD27),"") -> 0.028173865 | AJ32: =IFERROR((AJ29-AE29)/(AJ27-AE27),"") -> 0.19620616 | AK32: =IFERROR((AK29-AF29)/(AK27-AF27),"") -> 0.22637591 | AL32: =IFERROR((AL29-AG29)/(AL27-AG27),"") -> 0.2901103 | AM32: =IFERROR((AM29-AH29)/(AM27-AH27),"") -> 0.20987593 | AN32: =IFERROR((AN29-AI29)/(AN27-AI27),"") -> 0.76809296 | AO32: =IFERROR((AO29-AJ29)/(AO27-AJ27),"") -> 1.0492617 | AP32: =IFERROR((AP29-AK29)/(AP27-AK27),"") -> 0.43832589 | ... CA32: =IFERROR((CA29-BV29)/(CA27-BV27),"") -> 0.38389297 | CB32: =IFERROR((CB29-CA29)/(CB27-CA27),"") -> 0.42899494 | CC32: =IFERROR((CC29-CB29)/(CC27-CB27),"") -> 0.34764237 | CD32: =IFERROR((CD29-CC29)/(CD27-CC27),"") -> 0.35604592 | CE32: =IFERROR((CE29-CD29)/(CE27-CD27),"") -> 0.34282394 | CN32: 2028E | CO32: =CP32+$CO$30 -> 0.095 | CP32: 0.075 | CQ32: =CP32+$CQ$30 -> 0.055
B33: Memo: incineration utilization % (company; ex-Kimball Q1–Q4/25, incl. Kimball from Q1/26) | J33: 0.88 | K33: 0.923 | L33: 0.93 | M33: 0.91 | O33: 0.91 | P33: 0.95 | Q33: 0.9 | R33: 0.96 | T33: 0.91 | U33: 0.91 | V33: 0.92 | W33: 0.89 | Y33: 0.88 | Z33: 0.88 | AA33: 0.9 | AB33: 0.9 | AD33: 0.79 | AE33: 0.87 | AF33: 0.92 | AG33: 0.92 | AI33: 0.87 | AJ33: 0.9 | AK33: 0.84 | AL33: 0.86 | AN33: 0.77 | AO33: 0.82 | AP33: 0.92 | AQ33: 0.89 | AS33: 0.86 | AT33: 0.87 | AU33: 0.8 | AV33: 0.84 | AX33: 0.8 | AY33: 0.87 | AZ33: 0.82 | BA33: 0.92 | BC33: 0.85 | BF33: 0.84 | BH33: 0.8 | BI33: 0.84 | BJ33: 0.86 | BK33: 0.85 | BM33: 0.79 | BN33: 0.88 | BO33: 0.89 | BP33: 0.94 | BR33: 0.88 | BS33: 0.89 | BT33: 0.92 | BU33: 0.87 | BW33: 0.8 | BX33: 0.91 | CF33: Quoted in each earnings release (CEO commentary); quarterly only. | CN33: 2029E | CO33: =CP33+$CO$30 -> 0.09 | CP33: 0.07 | CQ33: =CP33+$CQ$30 -> 0.05
B34: Memo: landfill volumes y/y % (company, where disclosed) | K34: 0.17 | O34: 0.25 | R34: 0.37 | T34: 0.21 | U34: -0.29 | V34: -0.28 | W34: -0.5 | Y34: -0.33 | Z34: -0.21 | AA34: -0.49 | AB34: -0.28 | AD34: -0.25 | AE34: 0.23 | AF34: 0.4 | AG34: 0.18 | AI34: 0.58 | AP34: 0.06 | AQ34: 0.4 | AT34: -0.24 | AV34: -0.37 | AZ34: -0.05 | BA34: 0.15 | BC34: 0.14 | BD34: 0.36 | BE34: 0.38 | BF34: 0.28 | BH34: -0.08 | BN34: 0.04 | BT34: 0.4 | BU34: 0.56 | BW34: 0.34 | BX34: 0.07 | CN34: 2030E | CO34: =CP34+$CO$30 -> 0.085 | CP34: 0.065 | CQ34: =CP34+$CQ$30 -> 0.045
CN35: FER_growth (Field & Emergency Response y/y) | CO35: 0.03 | CP35: Δ → | CQ35: -0.03 | CR35: ER is event-driven (lumpy); base business + branch growth.
B36: Safety-Kleen Sustainability Solutions (SKSS; "Safety-Kleen" segment Q1/18–Q4/20) — Safety-Kleen Oil (re-refined base oil, blended lubricants, used-oil collection) · SK Environmental Services (SKSS portion) | CF36: SKSS — modelling logic: re-refining spread business (base-oil price vs. charge-for-oil on collection); Q2/26 margin spike on global refined-product supply disruption. | CN36: 2027E | CO36: =CP36+$CO$35 -> 0.08 | CP36: 0.05 | CQ36: =CP36+$CQ$35 -> 0.02
B37: Safety-Kleen Environmental Services — SKSS portion (all SK Environmental Services 2018–20) | AI37: 194.161 | AJ37: 200.034 | AK37: 200.681 | AL37: 200.201 | AM37: 795.077 | AN37: 207.083 | AO37: 216.434 | AP37: 217.439 | AQ37: 210.564 | AR37: 851.52 | AS37: 214.481 | AT37: 194.872 | AU37: 203.455 | AV37: 196.428 | AW37: 809.236 | AX37: 38.978 | AY37: 40.453 | AZ37: 39.551 | BA37: 42.605 | BB37: 161.587 | BC37: 44.388 | BD37: 49.381 | BE37: 52.072 | BF37: 53.519 | BG37: 199.36 | BH37: 49.559 | BI37: 62.452 | BJ37: 59.458 | BK37: 53.361 | BL37: 224.83 | BM37: 53.021 | BN37: 58.421 | BO37: 59.675 | BP37: 58.613 | BQ37: 229.73 | BR37: 64.901 | BS37: 72.463 | BT37: 76.601 | BU37: 76.458 | BV37: 290.423 | BW37: 77.973 | BX37: 87.738 | BY37: =BT37*(1+BY38) -> 84.2611 | BZ37: =BU37*(1+BZ38) -> 83.33922 | CA37: =SUM(BW37,BX37,BY37,BZ37) -> 333.31132 | CB37: =CA37*(1+CB38) -> 356.64311 | CC37: =CB37*(1+CC38) -> 379.82491 | CD37: =CC37*(1+CD38) -> 402.61441 | CE37: =CD37*(1+CE38) -> 426.77127 | CH37: =IFERROR((CE37/BV37)^(1/5)-1,"n/m") -> 0.080022578 | CI37: =IFERROR((BV37/AW37)^(1/5)-1,"n/m") -> -0.18531229 | CJ37: =IFERROR((BV37/X37)^(1/10)-1,"n/m") -> n/m | CK37: =IFERROR((BV37/C37)^(1/19)-1,"n/m") -> n/m | CN37: 2028E | CO37: =CP37+$CO$35 -> 0.08 | CP37: 0.05 | CQ37: =CP37+$CQ$35 -> 0.02
B38: SK Environmental Services (SKSS) y/y % | D38: =IF(AND(ISNUMBER(D37),ISNUMBER(C37)),IFERROR(D37/C37-1,""),"") | E38: =IF(AND(ISNUMBER(E37),ISNUMBER(D37)),IFERROR(E37/D37-1,""),"") | F38: =IF(AND(ISNUMBER(F37),ISNUMBER(E37)),IFERROR(F37/E37-1,""),"") | G38: =IF(AND(ISNUMBER(G37),ISNUMBER(F37)),IFERROR(G37/F37-1,""),"") | H38: =IF(AND(ISNUMBER(H37),ISNUMBER(G37)),IFERROR(H37/G37-1,""),"") | I38: =IF(AND(ISNUMBER(I37),ISNUMBER(H37)),IFERROR(I37/H37-1,""),"") | N38: =IF(AND(ISNUMBER(N37),ISNUMBER(I37)),IFERROR(N37/I37-1,""),"") | O38: =IF(AND(ISNUMBER(O37),ISNUMBER(J37)),IFERROR(O37/J37-1,""),"") | P38: =IF(AND(ISNUMBER(P37),ISNUMBER(K37)),IFERROR(P37/K37-1,""),"") | Q38: =IF(AND(ISNUMBER(Q37),ISNUMBER(L37)),IFERROR(Q37/L37-1,""),"") | R38: =IF(AND(ISNUMBER(R37),ISNUMBER(M37)),IFERROR(R37/M37-1,""),"") | S38: =IF(AND(ISNUMBER(S37),ISNUMBER(N37)),IFERROR(S37/N37-1,""),"") | T38: =IF(AND(ISNUMBER(T37),ISNUMBER(O37)),IFERROR(T37/O37-1,""),"") | U38: =IF(AND(ISNUMBER(U37),ISNUMBER(P37)),IFERROR(U37/P37-1,""),"") | ... BX38: =IF(AND(ISNUMBER(BX37),ISNUMBER(BS37)),IFERROR(BX37/BS37-1,""),"") -> 0.21079723 | BY38: =BY22 -> 0.1 | BZ38: =BZ22 -> 0.09 | CA38: =IFERROR(CA37/BV37-1,"") -> 0.14767536 | CB38: =CHOOSE(MATCH($CF$2,{"Bull","Base","Bear"},0),$CO$46,$CP$46,$CQ$46) -> 0.07 | CC38: =CHOOSE(MATCH($CF$2,{"Bull","Base","Bear"},0),$CO$47,$CP$47,$CQ$47) -> 0.065 | CD38: =CHOOSE(MATCH($CF$2,{"Bull","Base","Bear"},0),$CO$48,$CP$48,$CQ$48) -> 0.06 | CE38: =CHOOSE(MATCH($CF$2,{"Bull","Base","Bear"},0),$CO$49,$CP$49,$CQ$49) -> 0.06 | CN38: 2029E | CO38: =CP38+$CO$35 -> 0.075 | CP38: 0.045 | CQ38: =CP38+$CQ$35 -> 0.015
B39: Safety-Kleen Oil — base oil, blended lubricants & collection services (Kleen Performance Products 2018) | AI39: 115.757 | AJ39: 128.681 | AK39: 133.22 | AL39: 122.62 | AM39: 500.278 | AN39: 99.464 | AO39: 125.748 | AP39: 123.978 | AQ39: 117.981 | AR39: 467.171 | AS39: 115.888 | AT39: 50.718 | AU39: 77.634 | AV39: 86.25 | AW39: 330.49 | AX39: 116.213 | AY39: 162.779 | AZ39: 168.038 | BA39: 170.743 | BB39: 617.773 | BC39: 183.851 | BD39: 222.346 | BE39: 230.699 | BF39: 184.869 | BG39: 821.765 | BH39: 196.739 | BI39: 173.85 | BJ39: 170.847 | BK39: 172.53 | BL39: 713.966 | BM39: 162.293 | BN39: 196.901 | BO39: 182.001 | BP39: 158.295 | BQ39: 699.49 | BR39: 159.914 | BS39: 147.243 | BT39: 154.156 | BU39: 132.561 | BV39: 593.874 | BW39: 139.116 | BX39: 202.735 | BY39: =BT39*(1+BY40) -> 197.31968 | BZ39: =BU39*(1+BZ40) -> 145.8171 | CA39: =SUM(BW39,BX39,BY39,BZ39) -> 684.98778 | CB39: =CA39*(1+CB40) -> 630.18876 | CC39: =CB39*(1+CC40) -> 642.79253 | CD39: =CC39*(1+CD40) -> 655.64838 | CE39: =CD39*(1+CE40) -> 668.76135 | CH39: =IFERROR((CE39/BV39)^(1/5)-1,"n/m") -> 0.024036345 | CI39: =IFERROR((BV39/AW39)^(1/5)-1,"n/m") -> 0.12436469 | CJ39: =IFERROR((BV39/X39)^(1/10)-1,"n/m") -> n/m | CK39: =IFERROR((BV39/C39)^(1/19)-1,"n/m") -> n/m | CN39: 2030E | CO39: =CP39+$CO$35 -> 0.075 | CP39: 0.045 | CQ39: =CP39+$CQ$35 -> 0.015
B40: Safety-Kleen Oil y/y % | D40: =IF(AND(ISNUMBER(D39),ISNUMBER(C39)),IFERROR(D39/C39-1,""),"") | E40: =IF(AND(ISNUMBER(E39),ISNUMBER(D39)),IFERROR(E39/D39-1,""),"") | F40: =IF(AND(ISNUMBER(F39),ISNUMBER(E39)),IFERROR(F39/E39-1,""),"") | G40: =IF(AND(ISNUMBER(G39),ISNUMBER(F39)),IFERROR(G39/F39-1,""),"") | H40: =IF(AND(ISNUMBER(H39),ISNUMBER(G39)),IFERROR(H39/G39-1,""),"") | I40: =IF(AND(ISNUMBER(I39),ISNUMBER(H39)),IFERROR(I39/H39-1,""),"") | N40: =IF(AND(ISNUMBER(N39),ISNUMBER(I39)),IFERROR(N39/I39-1,""),"") | O40: =IF(AND(ISNUMBER(O39),ISNUMBER(J39)),IFERROR(O39/J39-1,""),"") | P40: =IF(AND(ISNUMBER(P39),ISNUMBER(K39)),IFERROR(P39/K39-1,""),"") | Q40: =IF(AND(ISNUMBER(Q39),ISNUMBER(L39)),IFERROR(Q39/L39-1,""),"") | R40: =IF(AND(ISNUMBER(R39),ISNUMBER(M39)),IFERROR(R39/M39-1,""),"") | S40: =IF(AND(ISNUMBER(S39),ISNUMBER(N39)),IFERROR(S39/N39-1,""),"") | T40: =IF(AND(ISNUMBER(T39),ISNUMBER(O39)),IFERROR(T39/O39-1,""),"") | U40: =IF(AND(ISNUMBER(U39),ISNUMBER(P39)),IFERROR(U39/P39-1,""),"") | ... BX40: =IF(AND(ISNUMBER(BX39),ISNUMBER(BS39)),IFERROR(BX39/BS39-1,""),"") -> 0.3768736 | BY40: =BY41 -> 0.28 | BZ40: =BZ41 -> 0.1 | CA40: =IFERROR(CA39/BV39-1,"") -> 0.15342275 | CB40: =CHOOSE(MATCH($CF$2,{"Bull","Base","Bear"},0),$CO$51,$CP$51,$CQ$51) -> -0.08 | CC40: =CHOOSE(MATCH($CF$2,{"Bull","Base","Bear"},0),$CO$52,$CP$52,$CQ$52) -> 0.02 | CD40: =CHOOSE(MATCH($CF$2,{"Bull","Base","Bear"},0),$CO$53,$CP$53,$CQ$53) -> 0.02 | CE40: =CHOOSE(MATCH($CF$2,{"Bull","Base","Bear"},0),$CO$54,$CP$54,$CQ$54) -> 0.02 | CF40: 2027E+: scenario lever SKOIL_growth (base-oil pricing normalisation after the 2026 supply-disruption spike, then volume/blended mix growth). | CN40: IS_growth (Industrial Services & Other y/y) | CO40: 0.02 | CP40: Δ → | CQ40: -0.02 | CR40: Refinery / chemical turnarounds; data-center offering; FY24–25 −3% / −4%.
...

Sheet Bull-Base-Bear
B2: Clean Harbors (CLH) — Bull / Base / Bear Case P&L Summary | J2: Share price ($): | K2: =Model!$CA$424 -> 321.34
B3: Adjusted figures (company definitions: Adjusted EBITDA as published — SBC added back from Q1/21; adjusted EPS = GAAP excl. debt extinguishment, impairments, business-sale gains / losses, tax items) · USD millions · Live panel linked to Model — toggle scenario via Model!CF2. Bull and Bear panels are value snapshots generated from the Model with the switch set to each case. 2026E includes ES&H (from 1-Sep-26) and EnviroServe (from 1-Nov-26) — assumed closing dates. | J3: As of: | K3: =TODAY() -> 46299
B5: Scenario: | C5: =Model!$CF$2 -> Base | N5: Scenario: | O5: Bull | P5: Snapshot (values) — Model run with switch = Bull | Z5: Scenario: | AA5: Bear | AB5: Snapshot (values) — Model run with switch = Bear
B7: (USDm, except EPS and shares) | C7: 2025A | D7: 2026E | E7: 2027E | F7: 2028E | G7: 2029E | H7: 2030E | I7: 25-'30 CAGR | J7: LT Hist Avg | K7: LT Hist Min | L7: LT Hist Max | N7: (USDm, except EPS and shares) | O7: 2025A | P7: 2026E | Q7: 2027E | R7: 2028E | S7: 2029E | T7: 2030E | U7: 25-'30 CAGR | V7: LT Hist Avg | W7: LT Hist Min | X7: LT Hist Max | Z7: (USDm, except EPS and shares) | AA7: 2025A | AB7: 2026E | AC7: 2027E | AD7: 2028E | AE7: 2029E | AF7: 2030E | AG7: 25-'30 CAGR | AH7: LT Hist Avg | AI7: LT Hist Min | AJ7: LT Hist Max
B9: Revenues | C9: =Model!BV138 -> 6030.837 | D9: =Model!CA138 -> 6593.3551 | E9: =Model!CB138 -> 7277.4048 | F9: =Model!CC138 -> 7876.5116 | G9: =Model!CD138 -> 8483.2694 | H9: =Model!CE138 -> 9109.8892 | I9: =IFERROR((H9/C9)^(1/5)-1,"n/m") -> 0.085993186 | N9: Revenues | O9: 6030.837 | P9: 6593.3551 | Q9: 7523.798 | R9: 8473.7845 | S9: 9462.2496 | T9: 10503.272 | U9: 0.11735045 | Z9: Revenues | AA9: 6030.837 | AB9: 6593.3551 | AC9: 7031.0117 | AD9: 7288.6538 | AE9: 7533.4165 | AF9: 7776.9012 | AG9: 0.052169717
B10: Revenues y/y % | D10: =IFERROR(D9/C9-1,"") -> 0.093273634 | E10: =IFERROR(E9/D9-1,"") -> 0.10374835 | F10: =IFERROR(F9/E9-1,"") -> 0.08232424 | G10: =IFERROR(G9/F9-1,"") -> 0.077033819 | H10: =IFERROR(H9/G9-1,"") -> 0.073865361 | N10: Revenues y/y % | P10: 0.093273634 | Q10: 0.14111827 | R10: 0.12626423 | S10: 0.11664978 | T10: 0.11001851 | Z10: Revenues y/y % | AB10: 0.093273634 | AC10: 0.066378434 | AD10: 0.036643673 | AE10: 0.033581333 | AF10: 0.032320624
B11: ES direct revenues y/y % | C11: =Model!BV226 -> 0.037672833 | D11: =Model!CA226 -> 0.068188176 | E11: =Model!CB226 -> 0.060519989 | F11: =Model!CC226 -> 0.059134535 | G11: =Model!CD226 -> 0.055520148 | H11: =Model!CE226 -> 0.05374038 | N11: ES direct revenues y/y % | O11: 0.037672833 | P11: 0.068188176 | Q11: 0.082315011 | R11: 0.080904949 | S11: 0.07726624 | T11: 0.075472574 | Z11: ES direct revenues y/y % | AA11: 0.037672833 | AB11: 0.068188176 | AC11: 0.038724966 | AD11: 0.037393512 | AE11: 0.033832253 | AF11: 0.032094305
B12: Adjusted EBITDA | C12: =Model!BV187 -> 1169.939 | D12: =Model!CA187 -> 1394.5397 | E12: =Model!CB187 -> 1550.1963 | F12: =Model!CC187 -> 1718.7809 | G12: =Model!CD187 -> 1876.8572 | H12: =Model!CE187 -> 2029.9644 | I12: =IFERROR((H12/C12)^(1/5)-1,"n/m") -> 0.11651624 | N12: Adjusted EBITDA | O12: 1169.939 | P12: 1424.5397 | Q12: 1696.2154 | R12: 1942.7647 | S12: 2187.0327 | T12: 2433.9323 | U12: 0.15778803 | Z12: Adjusted EBITDA | AA12: 1169.939 | AB12: 1364.5397 | AC12: 1408.9925 | AD12: 1506.4891 | AE12: 1587.8483 | AF12: 1659.5181 | AG12: 0.072417157
B13: Adjusted EBITDA margin % | C13: =IFERROR(C12/C9,"") -> 0.19399281 | D13: =IFERROR(D12/D9,"") -> 0.21150684 | E13: =IFERROR(E12/E9,"") -> 0.21301499 | F13: =IFERROR(F12/F9,"") -> 0.218216 | G13: =IFERROR(G12/G9,"") -> 0.2212422 | H13: =IFERROR(H12/H9,"") -> 0.22283086 | J13: =IFERROR(AVERAGE(Model!C188,Model!D188,Model!E188,Model!F188,Model!G188,Model!H188,Model!I188,Model!N188,Model!S188,Model!X188,Model!AC188,Model!AH188,Model!AM188,Model!AR188,Model!AW188,Model!BB188,Model!BG188,Model!BL188,Model!BQ188,Model!BV188),"") -> 0.16460537 | K13: =IFERROR(MIN(Model!C188,Model!D188,Model!E188,Model!F188,Model!G188,Model!H188,Model!I188,Model!N188,Model!S188,Model!X188,Model!AC188,Model!AH188,Model!AM188,Model!AR188,Model!AW188,Model!BB188,Model!BG188,Model!BL188,Model!BQ188,Model!BV188),"") -> 0.14076947 | L13: =IFERROR(MAX(Model!C188,Model!D188,Model!E188,Model!F188,Model!G188,Model!H188,Model!I188,Model!N188,Model!S188,Model!X188,Model!AC188,Model!AH188,Model!AM188,Model!AR188,Model!AW188,Model!BB188,Model!BG188,Model!BL188,Model!BQ188,Model!BV188),"") -> 0.19783359 | N13: Adjusted EBITDA margin % | O13: 0.19399281 | P13: 0.21605688 | Q13: 0.22544669 | R13: 0.22926765 | S13: 0.23113243 | T13: 0.23173086 | V13: 0.16460537 | W13: 0.14076947 | X13: 0.19783359 | Z13: Adjusted EBITDA margin % | AA13: 0.19399281 | AB13: 0.20695681 | AC13: 0.20039684 | AD13: 0.20668962 | AE13: 0.21077399 | AF13: 0.21339066 | AH13: 0.16460537 | AI13: 0.14076947 | AJ13: 0.19783359
B15: Income from Operations (GAAP) | C15: =Model!BV147 -> 673.372 | D15: =Model!CA147 -> 830.46493 | E15: =Model!CB147 -> 930.59597 | F15: =Model!CC147 -> 1046.5048 | G15: =Model!CD147 -> 1151.103 | H15: =Model!CE147 -> 1248.9178 | I15: =IFERROR((H15/C15)^(1/5)-1,"n/m") -> 0.13150313 | N15: Income from Operations (GAAP) | O15: 673.372 | P15: 860.46493 | Q15: 1054.9819 | R15: 1217.1234 | S15: 1373.5033 | T15: 1527.8617 | U15: 0.17805563 | Z15: Income from Operations (GAAP) | AA15: 673.372 | AB15: 800.46493 | AC15: 811.02532 | AD15: 886.80298 | AE15: 947.47122 | AF15: 998.52354 | AG15: 0.081983532
B16: Income from operations y/y % | D16: =IFERROR(D15/C15-1,"") -> 0.23329294 | E16: =IFERROR(E15/D15-1,"") -> 0.12057227 | F16: =IFERROR(F15/E15-1,"") -> 0.12455331 | G16: =IFERROR(G15/F15-1,"") -> 0.099950057 | H16: =IFERROR(H15/G15-1,"") -> 0.084974852 | N16: Income from operations y/y % | P16: 0.27784483 | Q16: 0.22606026 | R16: 0.15369127 | S16: 0.12848324 | T16: 0.112383 | Z16: Income from operations y/y % | AB16: 0.18874104 | AC16: 0.013192815 | AD16: 0.093434402 | AE16: 0.068412305 | AF16: 0.053882713
B17: Operating margin (GAAP) % | C17: =IFERROR(C15/C9,"") -> 0.11165482 | D17: =IFERROR(D15/D9,"") -> 0.12595483 | E17: =IFERROR(E15/E9,"") -> 0.1278747 | F17: =IFERROR(F15/F9,"") -> 0.13286399 | G17: =IFERROR(G15/G9,"") -> 0.13569096 | H17: =IFERROR(H15/H9,"") -> 0.13709473 | J17: =IFERROR(AVERAGE(Model!C235,Model!D235,Model!E235,Model!F235,Model!G235,Model!H235,Model!I235,Model!N235,Model!S235,Model!X235,Model!AC235,Model!AH235,Model!AM235,Model!AR235,Model!AW235,Model!BB235,Model!BG235,Model!BL235,Model!BQ235,Model!BV235),"") -> 0.083113356 | K17: =IFERROR(MIN(Model!C235,Model!D235,Model!E235,Model!F235,Model!G235,Model!H235,Model!I235,Model!N235,Model!S235,Model!X235,Model!AC235,Model!AH235,Model!AM235,Model!AR235,Model!AW235,Model!BB235,Model!BG235,Model!BL235,Model!BQ235,Model!BV235),"") -> 0.025102115 | L17: =IFERROR(MAX(Model!C235,Model!D235,Model!E235,Model!F235,Model!G235,Model!H235,Model!I235,Model!N235,Model!S235,Model!X235,Model!AC235,Model!AH235,Model!AM235,Model!AR235,Model!AW235,Model!BB235,Model!BG235,Model!BL235,Model!BQ235,Model!BV235),"") -> 0.12285572 | N17: Operating margin (GAAP) % | O17: 0.11165482 | P17: 0.13050487 | Q17: 0.14021932 | R17: 0.14363398 | S17: 0.14515611 | T17: 0.14546531 | V17: 0.083113356 | W17: 0.025102115 | X17: 0.12285572 | Z17: Operating margin (GAAP) % | AA17: 0.11165482 | AB17: 0.1214048 | AC17: 0.11534973 | AD17: 0.12166897 | AE17: 0.12576913 | AF17: 0.12839607 | AH17: 0.083113356 | AI17: 0.025102115 | AJ17: 0.12285572
B19: Adjusted Net Income | C19: =Model!BV204 -> 396.5287 | D19: =Model!CA204 -> 495.87315 | E19: =Model!CB204 -> 560.42977 | F19: =Model!CC204 -> 643.58192 | G19: =Model!CD204 -> 713.11883 | H19: =Model!CE204 -> 773.62868 | I19: =IFERROR((H19/C19)^(1/5)-1,"n/m") -> 0.1430141 | N19: Adjusted Net Income | O19: 396.5287 | P19: 517.98531 | Q19: 650.95166 | R19: 745.4684 | S19: 840.02578 | T19: 933.28304 | U19: 0.1867186 | Z19: Adjusted Net Income | AA19: 396.5287 | AB19: 473.76099 | AC19: 473.47115 | AD19: 535.43905 | AE19: 582.24709 | AF19: 617.07945 | AG19: 0.092479491
B21: FDSO (m) | C21: =Model!BV165 -> 53.716 | D21: =Model!CA165 -> 52.92985 | E21: =Model!CB165 -> 52.507983 | F21: =Model!CC165 -> 51.399485 | G21: =Model!CD165 -> 49.817265 | H21: =Model!CE165 -> 48.202127 | I21: =IFERROR((H21/C21)^(1/5)-1,"n/m") -> -0.021428625 | N21: FDSO (m) | O21: 53.716 | P21: 52.890951 | Q21: 51.738292 | R21: 50.013207 | S21: 48.3746 | T21: 46.597446 | U21: -0.028032622 | Z21: FDSO (m) | AA21: 53.716 | AB21: 52.96875 | AC21: 52.847965 | AD21: 52.157958 | AE21: 50.799969 | AF21: 49.20737 | AG21: -0.017380684
B23: Adjusted EPS — Diluted ($) | C23: =Model!BV207 -> 7.3819476 | D23: =Model!CA207 -> 9.3684971 | E23: =Model!CB207 -> 10.67323 | F23: =Model!CC207 -> 12.521174 | G23: =Model!CD207 -> 14.314693 | H23: =Model!CE207 -> 16.049679 | I23: =IFERROR((H23/C23)^(1/5)-1,"n/m") -> 0.16804367 | N23: Adjusted EPS — Diluted ($) | O23: 7.3819476 | P23: 9.7934582 | Q23: 12.581623 | R23: 14.905431 | S23: 17.365017 | T23: 20.028631 | U23: 0.22094489 | Z23: Adjusted EPS — Diluted ($) | AA23: 7.3819476 | AB23: 8.9441602 | AC23: 8.9591178 | AD23: 10.265721 | AE23: 11.461564 | AF23: 12.540387 | AG23: 0.11180339
B24: EPS y/y % | D24: =IFERROR(D23/C23-1,"") -> 0.26910914 | E24: =IFERROR(E23/D23-1,"") -> 0.13926808 | F24: =IFERROR(F23/E23-1,"") -> 0.17313829 | G24: =IFERROR(G23/F23-1,"") -> 0.14323881 | H24: =IFERROR(H23/G23-1,"") -> 0.1212032 | N24: EPS y/y % | P24: 0.32667674 | Q24: 0.28469662 | R24: 0.18469863 | S24: 0.16501276 | T24: 0.15338962 | Z24: EPS y/y % | AB24: 0.21162609 | AC24: 0.0016723239 | AD24: 0.14584062 | AE24: 0.1164889 | AF24: 0.094125302
B26: P / E (x) — assumed (adjusted EPS) | G26: 28 | H26: 28 | N26: P / E (x) — assumed (adjusted EPS) | S26: 32 | T26: 32 | Z26: P / E (x) — assumed (adjusted EPS) | AD26: 22 | AE26: 22 | AF26: 22
B27: Price Target ($) | G27: =G26*G23 -> 400.81139 | H27: =H26*H23 -> 449.39102 | N27: Price Target ($) | S27: =S26*S23 -> 555.68056 | T27: =T26*T23 -> 640.91619 | Z27: Price Target ($) | AD27: =AD26*AD23 -> 225.84586 | AE27: =AE26*AE23 -> 252.1544 | AF27: =AF26*AF23 -> 275.88851
B28: Upside / (Downside) vs current | G28: =IFERROR(G27/$K$2-1,"") -> 0.24731249 | H28: =IFERROR(H27/$K$2-1,"") -> 0.39849075 | N28: Upside / (Downside) vs current | S28: =IFERROR(S27/$K$2-1,"") -> 0.72926047 | T28: =IFERROR(T27/$K$2-1,"") -> 0.99451108 | Z28: Upside / (Downside) vs current | AD28: =IFERROR(AD27/$K$2-1,"") -> -0.29717476 | AE28: =IFERROR(AE27/$K$2-1,"") -> -0.21530341 | AF28: =IFERROR(AF27/$K$2-1,"") -> -0.14144361
B29: IRR (to Dec-Y-1) | G29: =IFERROR((G27/$K$2)^(1/((DATE(2029-1,12,31)-$K$3)/365.25))-1,"") -> 0.10357577 | H29: =IFERROR((H27/$K$2)^(1/((DATE(2030-1,12,31)-$K$3)/365.25))-1,"") -> 0.10900694 | N29: IRR (to Dec-Y-1) | S29: =IFERROR((S27/$K$2)^(1/((DATE(2029-1,12,31)-$K$3)/365.25))-1,"") -> 0.27667036 | T29: =IFERROR((T27/$K$2)^(1/((DATE(2030-1,12,31)-$K$3)/365.25))-1,"") -> 0.23735979 | Z29: IRR (to Dec-Y-1) | AD29: =IFERROR((AD27/$K$2)^(1/((DATE(2028-1,12,31)-$K$3)/365.25))-1,"") -> -0.24748642 | AE29: =IFERROR((AE27/$K$2)^(1/((DATE(2029-1,12,31)-$K$3)/365.25))-1,"") -> -0.1024884 | AF29: =IFERROR((AF27/$K$2)^(1/((DATE(2030-1,12,31)-$K$3)/365.25))-1,"") -> -0.045955866
B31: Free Cash Flow | C31: =Model!BV271 -> 441.807 | D31: =Model!CA271 -> 406.42372 | E31: =Model!CB271 -> 569.26249 | F31: =Model!CC271 -> 629.81474 | G31: =Model!CD271 -> 708.23579 | H31: =Model!CE271 -> 775.89339 | I31: =IFERROR((H31/C31)^(1/5)-1,"n/m") -> 0.11921595 | N31: Free Cash Flow | O31: 441.807 | P31: 397.595 | Q31: 620.79597 | R31: 683.57433 | S31: 788.76271 | T31: 891.11926 | U31: 0.15064313 | Z31: Free Cash Flow | AA31: 441.807 | AB31: 415.25243 | AC31: 521.14716 | AD31: 568.18253 | AE31: 620.60553 | AF31: 659.02097 | AG31: 0.083261549
B32: FCF % | C32: =IFERROR(C31/C9,"") -> 0.073257991 | D32: =IFERROR(D31/D9,"") -> 0.061641412 | E32: =IFERROR(E31/E9,"") -> 0.078223282 | F32: =IFERROR(F31/F9,"") -> 0.079961127 | G32: =IFERROR(G31/G9,"") -> 0.083486184 | H32: =IFERROR(H31/H9,"") -> 0.085170453 | J32: =IFERROR(AVERAGE(Model!C273,Model!D273,Model!E273,Model!F273,Model!G273,Model!H273,Model!I273,Model!N273,Model!S273,Model!X273,Model!AC273,Model!AH273,Model!AM273,Model!AR273,Model!AW273,Model!BB273,Model!BG273,Model!BL273,Model!BQ273,Model!BV273),"") -> 0.047231357 | K32: =IFERROR(MIN(Model!C273,Model!D273,Model!E273,Model!F273,Model!G273,Model!H273,Model!I273,Model!N273,Model!S273,Model!X273,Model!AC273,Model!AH273,Model!AM273,Model!AR273,Model!AW273,Model!BB273,Model!BG273,Model!BL273,Model!BQ273,Model!BV273),"") -> 0.011686436 | L32: =IFERROR(MAX(Model!C273,Model!D273,Model!E273,Model!F273,Model!G273,Model!H273,Model!I273,Model!N273,Model!S273,Model!X273,Model!AC273,Model!AH273,Model!AM273,Model!AR273,Model!AW273,Model!BB273,Model!BG273,Model!BL273,Model!BQ273,Model!BV273),"") -> 0.079920043 | N32: FCF % | O32: 0.073257991 | P32: 0.06030238 | Q32: 0.082510984 | R32: 0.080669307 | S32: 0.083358899 | T32: 0.08484206 | V32: 0.047231357 | W32: 0.011686436 | X32: 0.079920043 | Z32: FCF % | AA32: 0.073257991 | AB32: 0.062980444 | AC32: 0.07412122 | AD32: 0.077954386 | AE32: 0.082380356 | AF32: 0.084740818 | AH32: 0.047231357 | AI32: 0.011686436 | AJ32: 0.079920043
B33: FCF / share ($) | C33: =IFERROR(C31/C21,"") -> 8.2248678 | D33: =IFERROR(D31/D21,"") -> 7.6785352 | E33: =IFERROR(E31/E21,"") -> 10.841446 | F33: =IFERROR(F31/F21,"") -> 12.253328 | G33: =IFERROR(G31/G21,"") -> 14.216674 | H33: =IFERROR(H31/H21,"") -> 16.096663 | N33: FCF / share ($) | O33: 8.2248678 | P33: 7.5172595 | Q33: 11.998772 | R33: 13.667876 | S33: 16.305307 | T33: 19.123779 | Z33: FCF / share ($) | AA33: 8.2248678 | AB33: 7.8395739 | AC33: 9.8612531 | AD33: 10.893496 | AE33: 12.216652 | AF33: 13.392729
B34: FCF Yield (on PT) | F34: =IFERROR(F33/F$27,"") | G34: =IFERROR(G33/G$27,"") -> 0.035469734 | H34: =IFERROR(H33/H$27,"") -> 0.035818835 | N34: FCF Yield (on PT) | R34: =IFERROR(R33/R$27,"") | S34: =IFERROR(S33/S$27,"") -> 0.02934295 | T34: =IFERROR(T33/T$27,"") -> 0.02983819 | Z34: FCF Yield (on PT) | AD34: =IFERROR(AD33/AD$27,"") -> 0.048234208 | AE34: =IFERROR(AE33/AE$27,"") -> 0.048449091 | AF34: =IFERROR(AF33/AF$27,"") -> 0.04854399
B35: Adjusted EBITDA — pro forma (2026E incl. ES&H / EnviroServe full year) | C35: =Model!BV196 -> 1169.939 | D35: =Model!CA196 -> 1437 | E35: =Model!CB196 -> 1550.1963 | F35: =Model!CC196 -> 1718.7809 | G35: =Model!CD196 -> 1876.8572 | H35: =Model!CE196 -> 2029.9644 | I35: =IFERROR((H35/C35)^(1/5)-1,"n/m") -> 0.11651624 | N35: Adjusted EBITDA — pro forma (2026E incl. ES&H / EnviroServe full year) | O35: 1169.939 | P35: 1467 | Q35: 1696.2154 | R35: 1942.7647 | S35: 2187.0327 | T35: 2433.9323 | U35: 0.15778803 | Z35: Adjusted EBITDA — pro forma (2026E incl. ES&H / EnviroServe full year) | AA35: 1169.939 | AB35: 1407 | AC35: 1408.9925 | AD35: 1506.4891 | AE35: 1587.8483 | AF35: 1659.5181 | AG35: 0.072417157
B36: Adjusted EBITDA (pro forma) % of revenues | C36: =IFERROR(C35/C9,"") -> 0.19399281 | D36: =IFERROR(D35/D9,"") -> 0.2179467 | E36: =IFERROR(E35/E9,"") -> 0.21301499 | F36: =IFERROR(F35/F9,"") -> 0.218216 | G36: =IFERROR(G35/G9,"") -> 0.2212422 | H36: =IFERROR(H35/H9,"") -> 0.22283086 | J36: =IFERROR(AVERAGE(Model!C233,Model!D233,Model!E233,Model!F233,Model!G233,Model!H233,Model!I233,Model!N233,Model!S233,Model!X233,Model!AC233,Model!AH233,Model!AM233,Model!AR233,Model!AW233,Model!BB233,Model!BG233,Model!BL233,Model!BQ233,Model!BV233),"") -> 0.16460537 | K36: =IFERROR(MIN(Model!C233,Model!D233,Model!E233,Model!F233,Model!G233,Model!H233,Model!I233,Model!N233,Model!S233,Model!X233,Model!AC233,Model!AH233,Model!AM233,Model!AR233,Model!AW233,Model!BB233,Model!BG233,Model!BL233,Model!BQ233,Model!BV233),"") -> 0.14076947 | L36: =IFERROR(MAX(Model!C233,Model!D233,Model!E233,Model!F233,Model!G233,Model!H233,Model!I233,Model!N233,Model!S233,Model!X233,Model!AC233,Model!AH233,Model!AM233,Model!AR233,Model!AW233,Model!BB233,Model!BG233,Model!BL233,Model!BQ233,Model!BV233),"") -> 0.19783359 | N36: Adjusted EBITDA (pro forma) % of revenues | O36: 0.19399281 | P36: 0.22249674 | Q36: 0.22544669 | R36: 0.22926765 | S36: 0.23113243 | T36: 0.23173086 | V36: 0.16460537 | W36: 0.14076947 | X36: 0.19783359 | Z36: Adjusted EBITDA (pro forma) % of revenues | AA36: 0.19399281 | AB36: 0.21339667 | AC36: 0.20039684 | AD36: 0.20668962 | AE36: 0.21077399 | AF36: 0.21339066 | AH36: 0.16460537 | AI36: 0.14076947 | AJ36: 0.19783359
B38: Net Debt | C38: =Model!BV419 -> 1822.485 | D38: =Model!CA419 -> 2710.3113 | E38: =Model!CB419 -> 2712.8436 | F38: =Model!CC419 -> 3007.8665 | G38: =Model!CD419 -> 3284.5001 | H38: =Model!CE419 -> 3552.4378 | N38: Net Debt | O38: 1822.485 | P38: 2769.14 | Q38: 3392.4307 | R38: 3885.5293 | S38: 4374.0654 | T38: 4867.8646 | Z38: Net Debt | AA38: 1822.485 | AB38: 2651.4826 | AC38: 2325.3354 | AD38: 2259.7337 | AE38: 2381.7724 | AF38: 2489.2771
B39: Net Debt / Adjusted EBITDA (x) | C39: =IFERROR(C38/C35,"") -> 1.5577607 | D39: =IFERROR(D38/D35,"") -> 1.88609 | E39: =IFERROR(E38/E35,"") -> 1.75 | F39: =IFERROR(F38/F35,"") -> 1.75 | G39: =IFERROR(G38/G35,"") -> 1.75 | H39: =IFERROR(H38/H35,"") -> 1.75 | N39: Net Debt / Adjusted EBITDA (x) | O39: 1.5577607 | P39: 1.887621 | Q39: 2 | R39: 2 | S39: 2 | T39: 2 | Z39: Net Debt / Adjusted EBITDA (x) | AA39: 1.5577607 | AB39: 1.8844937 | AC39: 1.6503532 | AD39: 1.5 | AE39: 1.5 | AF39: 1.5
B41: ROIC | C41: =Model!BV402 -> 0.11735446 | D41: =Model!CA402 -> 0.11361331 | E41: =Model!CB402 -> 0.11939476 | F41: =Model!CC402 -> 0.12661089 | G41: =Model!CD402 -> 0.13196332 | H41: =Model!CE402 -> 0.13617116 | J41: =IFERROR(AVERAGE(Model!C402,Model!D402,Model!E402,Model!F402,Model!G402,Model!H402,Model!I402,Model!N402,Model!S402,Model!X402,Model!AC402,Model!AH402,Model!AM402,Model!AR402,Model!AW402,Model!BB402,Model!BG402,Model!BL402,Model!BQ402,Model!BV402),"") -> 0.12472586 | K41: =IFERROR(MIN(Model!C402,Model!D402,Model!E402,Model!F402,Model!G402,Model!H402,Model!I402,Model!N402,Model!S402,Model!X402,Model!AC402,Model!AH402,Model!AM402,Model!AR402,Model!AW402,Model!BB402,Model!BG402,Model!BL402,Model!BQ402,Model!BV402),"") -> 0.028214374 | L41: =IFERROR(MAX(Model!C402,Model!D402,Model!E402,Model!F402,Model!G402,Model!H402,Model!I402,Model!N402,Model!S402,Model!X402,Model!AC402,Model!AH402,Model!AM402,Model!AR402,Model!AW402,Model!BB402,Model!BG402,Model!BL402,Model!BQ402,Model!BV402),"") -> 0.348056 | N41: ROIC | O41: 0.11735446 | P41: 0.11675899 | Q41: 0.12787876 | R41: 0.13377652 | S41: 0.13823142 | T41: 0.14188842 | V41: 0.12472586 | W41: 0.028214374 | X41: 0.348056 | Z41: ROIC | AA41: 0.11735446 | AB41: 0.11043445 | AC41: 0.11058591 | AD41: 0.11927362 | AE41: 0.12599745 | AF41: 0.13146393 | AH41: 0.12472586 | AI41: 0.028214374 | AJ41: 0.348056
B42: RONTA | C42: =Model!BV413 -> 0.12273926 | D42: =Model!CA413 -> 0.14381298 | E42: =Model!CB413 -> 0.1531507 | F42: =Model!CC413 -> 0.17302979 | G42: =Model!CD413 -> 0.18066215 | H42: =Model!CE413 -> 0.18647255 | J42: =IFERROR(AVERAGE(Model!C413,Model!D413,Model!E413,Model!F413,Model!G413,Model!H413,Model!I413,Model!N413,Model!S413,Model!X413,Model!AC413,Model!AH413,Model!AM413,Model!AR413,Model!AW413,Model!BB413,Model!BG413,Model!BL413,Model!BQ413,Model!BV413),"") -> 0.099873354 | K42: =IFERROR(MIN(Model!C413,Model!D413,Model!E413,Model!F413,Model!G413,Model!H413,Model!I413,Model!N413,Model!S413,Model!X413,Model!AC413,Model!AH413,Model!AM413,Model!AR413,Model!AW413,Model!BB413,Model!BG413,Model!BL413,Model!BQ413,Model!BV413),"") -> 0.030727346 | L42: =IFERROR(MAX(Model!C413,Model!D413,Model!E413,Model!F413,Model!G413,Model!H413,Model!I413,Model!N413,Model!S413,Model!X413,Model!AC413,Model!AH413,Model!AM413,Model!AR413,Model!AW413,Model!BB413,Model!BG413,Model!BL413,Model!BQ413,Model!BV413),"") -> 0.19140262 | N42: RONTA | O42: 0.12273926 | P42: 0.14947012 | Q42: 0.17689516 | R42: 0.18800765 | S42: 0.19642746 | T42: 0.20307544 | V42: 0.099873354 | W42: 0.030727346 | X42: 0.19140262 | Z42: RONTA | AA42: 0.12273926 | AB42: 0.13822348 | AC42: 0.12852533 | AD42: 0.13588886 | AE42: 0.14589328 | AF42: 0.15422849 | AH42: 0.099873354 | AI42: 0.030727346 | AJ42: 0.19140262
B44: Implied Market Cap (USDm) | F44: =F27*F21 -> 0 | G44: =G27*G21 -> 19967.327 | H44: =H27*H21 -> 21661.603 | N44: Implied Market Cap (USDm) | R44: =R27*R21 -> 0 | S44: =S27*S21 -> 26880.825 | T44: =T27*T21 -> 29865.057 | Z44: Implied Market Cap (USDm) | AD44: =AD27*AD21 -> 11779.659 | AE44: =AE27*AE21 -> 12809.436 | AF44: =AF27*AF21 -> 13575.748
B45: (+) Net Debt & NCI | F45: =F38+Model!CC325 -> 3007.8665 | G45: =G38+Model!CD325 -> 3284.5001 | H45: =H38+Model!CE325 -> 3552.4378 | N45: (+) Net Debt & NCI | R45: =R38+Model!CC325 -> 3885.5293 | S45: =S38+Model!CD325 -> 4374.0654 | T45: =T38+Model!CE325 -> 4867.8646 | Z45: (+) Net Debt & NCI | AD45: =AD38+Model!CC325 -> 2259.7337 | AE45: =AE38+Model!CD325 -> 2381.7724 | AF45: =AF38+Model!CE325 -> 2489.2771
B46: Implied Enterprise Value (USDm) | F46: =F44+F45 -> 3007.8665 | G46: =G44+G45 -> 23251.827 | H46: =H44+H45 -> 25214.041 | N46: Implied Enterprise Value (USDm) | R46: =R44+R45 -> 3885.5293 | S46: =S44+S45 -> 31254.89 | T46: =T44+T45 -> 34732.922 | Z46: Implied Enterprise Value (USDm) | AD46: =AD44+AD45 -> 14039.393 | AE46: =AE44+AE45 -> 15191.208 | AF46: =AF44+AF45 -> 16065.025
B47: Implied EV / Adjusted EBITDA (x) | F47: =IFERROR(F46/F35,"") -> 1.75 | G47: =IFERROR(G46/G35,"") -> 12.388703 | H47: =IFERROR(H46/H35,"") -> 12.420927 | N47: Implied EV / Adjusted EBITDA (x) | R47: =IFERROR(R46/R35,"") -> 2 | S47: =IFERROR(S46/S35,"") -> 14.291003 | T47: =IFERROR(T46/T35,"") -> 14.270291 | Z47: Implied EV / Adjusted EBITDA (x) | AD47: =IFERROR(AD46/AD35,"") -> 9.3192794 | AE47: =IFERROR(AE46/AE35,"") -> 9.5671662 | AF47: =IFERROR(AF46/AF35,"") -> 9.6805364

Sheet DCF
B2: DCF VALUATION — CLEAN HARBORS (CLH)
B4: 1. WACC BUILD
B5: Risk-free rate (US 10Y govt) | C5: 0.055 | D5: Assumption (~US 10Y Treasury yield), as in prior models; update to market
B6: Equity risk premium | C6: 0.05 | D6: US implied ERP ~4.5–5.5% (Damodaran)
