Workbook

Sheet Model
CU1: SCENARIO SWITCH ▼ (Bull / Base / Bear) — drives all scenario-linked forecast drivers
B2: Copart, Inc. (NASDAQ: CPRT) — 3-Statement Financial Model | CU2: Base
B3: US GAAP as reported · fiscal year ends 31-July (FY2026 = Aug-2025 to Jul-2026) · USD millions (per-share data in USD; shares and per-share data restated for the 2-for-1 splits of Mar-2012, Apr-2017, Nov-2022 and Aug-2023) · Source: Copart Forms 10-K / 10-Q and Form 8-K earnings releases (Ex. 99.1), SEC EDGAR CIK 0000900075
B4: Basis notes: FY2006–12 annual; quarterly from FY2013 (Q4 = 10-K fiscal year less 10-Q nine-month YTD). ASC 606 adopted FY2019 (modified retrospective, no recast); ASC 842 leases from FY2020. Segments: US / International from the FY2016 10-K (FY2014+ recast). Copart issues no financial guidance: FY2027E–31E are model estimates. STANDALONE — the pending ACV Auctions acquisition (merger agreement 10-Sep-2026, $10.50/share cash tender) is excluded.
CW5: Forecast | CX5: Historical | CY5: Historical | CZ5: Historical
B6: (USDm; FY = Aug–Jul) | C6: 2006 | D6: 2007 | E6: 2008 | F6: 2009 | G6: 2010 | H6: 2011 | I6: 2012 | J6: Q1/13 | K6: Q2/13 | L6: 1H/13 | M6: Q3/13 | N6: Q4/13 | O6: 2013 | P6: Q1/14 | Q6: Q2/14 | R6: 1H/14 | S6: Q3/14 | T6: Q4/14 | U6: 2014 | V6: Q1/15 | W6: Q2/15 | X6: 1H/15 | Y6: Q3/15 | Z6: Q4/15 | AA6: 2015 | AB6: Q1/16 | AC6: Q2/16 | AD6: 1H/16 | AE6: Q3/16 | AF6: Q4/16 | AG6: 2016 | AH6: Q1/17 | AI6: Q2/17 | AJ6: 1H/17 | AK6: Q3/17 | AL6: Q4/17 | AM6: 2017 | AN6: Q1/18 | AO6: Q2/18 | AP6: 1H/18 | AQ6: Q3/18 | AR6: Q4/18 | AS6: 2018 | AT6: Q1/19 | AU6: Q2/19 | AV6: 1H/19 | AW6: Q3/19 | AX6: Q4/19 | AY6: 2019 | AZ6: Q1/20 | BA6: Q2/20 | BB6: 1H/20 | BC6: Q3/20 | BD6: Q4/20 | BE6: 2020 | BF6: Q1/21 | BG6: Q2/21 | BH6: 1H/21 | BI6: Q3/21 | BJ6: Q4/21 | BK6: 2021 | BL6: Q1/22 | BM6: Q2/22 | BN6: 1H/22 | BO6: Q3/22 | BP6: Q4/22 | BQ6: 2022 | BR6: Q1/23 | BS6: Q2/23 | BT6: 1H/23 | BU6: Q3/23 | BV6: Q4/23 | BW6: 2023 | BX6: Q1/24 | BY6: Q2/24 | BZ6: 1H/24 | CA6: Q3/24 | CB6: Q4/24 | CC6: 2024 | CD6: Q1/25 | CE6: Q2/25 | CF6: 1H/25 | CG6: Q3/25 | CH6: Q4/25 | CI6: 2025 | CJ6: Q1/26 | CK6: Q2/26 | CL6: 1H/26 | CM6: Q3/26 | CN6: Q4/26 | CO6: 2026 | CP6: 2027E | CQ6: 2028E | CR6: 2029E | CS6: 2030E | CT6: 2031E | CU6: Modelling Notes | CW6: 5Y CAGR | CX6: 5Y CAGR | CY6: 10Y CAGR | CZ6: 20Y CAGR
CW7: 26-'31 | CX7: 21-'26 | CY7: 16-'26 | CZ7: 06-'26
B9: REVENUE BUILD — US / INTERNATIONAL SEGMENTS × UNITS (service revenues + vehicle sales) | CU9: REVENUE BUILD — modelling logic (Copart reports two operating segments: United States and International; the build replaces RBA's GTV × take-rate build) | DC9: SCENARIO INPUT TABLE — driver assumptions per Bull / Base / Bear | DD9: Bull | DE9: Base | DF9: Bear | DG9: Bull / Bear = Base + Δ (Δ inputs on each block header). Copart issues no guidance — all cases are model assumptions.
B11: United States segment | CU11: UNITED STATES — modelling logic | DC11: US_unitGrowth (US units sold y/y) | DD11: 0.02 | DE11: Δ → | DF11: -0.03 | DG11: US: insurance total-loss frequency (vehicle age, repair cost inflation), insurer share gains, non-insurance (dealer, fleet, Blue Car) volumes.
B12: Service revenues (USDm) | AM12: 1128.99 | AN12: 331.391 | AO12: 355.542 | AP12: =AN12+AO12 -> 686.933 | AQ12: 356.252 | AR12: 342.053 | AS12: 1385.238 | AT12: 343.573 | AU12: 362.023 | AV12: =AT12+AU12 -> 705.596 | AW12: 416.874 | AX12: 414.961 | AY12: 1537.431 | AZ12: 430.803 | BA12: 447.345 | BB12: =AZ12+BA12 -> 878.148 | BC12: 431.875 | BD12: 404.701 | BE12: 1714.724 | BF12: 450.235 | BG12: 465.423 | BH12: =BF12+BG12 -> 915.658 | BI12: 550.338 | BJ12: 551.508 | BK12: 2017.504 | BL12: 590.758 | BM12: 630.707 | BN12: =BL12+BM12 -> 1221.465 | BO12: 678.865 | BP12: 632.835 | BQ12: 2533.165 | BR12: 651.657 | BS12: 705.733 | BT12: =BR12+BS12 -> 1357.39 | BU12: 752.077 | BV12: 732.174 | BW12: 2841.641 | BX12: 762.524 | BY12: 756.036 | BZ12: =BX12+BY12 -> 1518.56 | CA12: 830.68 | CB12: 776.861 | CC12: 3126.102 | CD12: 859.99 | CE12: 868.13 | CF12: =CD12+CE12 -> 1728.12 | CG12: 898.625 | CH12: 824.813 | CI12: 3451.558 | CJ12: 855.534 | CK12: 819.467 | CL12: =CJ12+CK12 -> 1675.001 | CM12: 895.464 | CN12: 817.822 | CO12: 3388.287 | CP12: =CO12*(1+CP13)*(1+CP14) -> 3524.835 | CQ12: =CP12*(1+CQ13)*(1+CQ14) -> 3721.3445 | CR12: =CQ12*(1+CR13)*(1+CR14) -> 3947.9744 | CS12: =CR12*(1+CS13)*(1+CS14) -> 4188.406 | CT12: =CS12*(1+CT13)*(1+CT14) -> 4443.48 | CU12: FY2027E+: prior year × (1 + units sold growth, scenario lever) × (1 + service revenue per unit growth). | CW12: =IFERROR((CT12/CO12)^(1/5)-1,"n/m") -> 0.055719655 | CX12: =IFERROR((CO12/BK12)^(1/5)-1,"n/m") -> 0.1092595 | CY12: =IFERROR((CO12/AG12)^(1/10)-1,"n/m") -> n/m | CZ12: =IFERROR((CO12/C12)^(1/20)-1,"n/m") -> n/m | DC12: 2027E | DD12: =DE12+$DD$11 -> 0.03 | DE12: 0.01 | DF12: =DE12+$DF$11 -> -0.02
B13: Units sold y/y % (disclosed in MD&A; forecast = scenario lever) | CP13: =CHOOSE(MATCH($CU$2,{"Bull","Base","Bear"},0),$DD$12,$DE$12,$DF$12) -> 0.01 | CQ13: =CHOOSE(MATCH($CU$2,{"Bull","Base","Bear"},0),$DD$13,$DE$13,$DF$13) -> 0.025 | CR13: =CHOOSE(MATCH($CU$2,{"Bull","Base","Bear"},0),$DD$14,$DE$14,$DF$14) -> 0.03 | CS13: =CHOOSE(MATCH($CU$2,{"Bull","Base","Bear"},0),$DD$15,$DE$15,$DF$15) -> 0.03 | CT13: =CHOOSE(MATCH($CU$2,{"Bull","Base","Bear"},0),$DD$16,$DE$16,$DF$16) -> 0.03 | CU13: 2027E–2031E: scenario lever (US_unitGrowth, Bull/Base/Bear table →). | DC13: 2028E | DD13: =DE13+$DD$11 -> 0.045 | DE13: 0.025 | DF13: =DE13+$DF$11 -> -0.005
B14: Service revenue per unit y/y % (implied price / mix; forecast input) | C14: =IF(ISNUMBER(C13),IFERROR((1+C15)/(1+C13)-1,""),"") | D14: =IF(ISNUMBER(D13),IFERROR((1+D15)/(1+D13)-1,""),"") | E14: =IF(ISNUMBER(E13),IFERROR((1+E15)/(1+E13)-1,""),"") | F14: =IF(ISNUMBER(F13),IFERROR((1+F15)/(1+F13)-1,""),"") | G14: =IF(ISNUMBER(G13),IFERROR((1+G15)/(1+G13)-1,""),"") | H14: =IF(ISNUMBER(H13),IFERROR((1+H15)/(1+H13)-1,""),"") | I14: =IF(ISNUMBER(I13),IFERROR((1+I15)/(1+I13)-1,""),"") | J14: =IF(ISNUMBER(J13),IFERROR((1+J15)/(1+J13)-1,""),"") | ... CO14: =IF(ISNUMBER(CO13),IFERROR((1+CO15)/(1+CO13)-1,""),"") | CP14: =CHOOSE(MATCH($CU$2,{"Bull","Base","Bear"},0),$DD$26,$DE$26,$DF$26) -> 0.03 | CQ14: =CHOOSE(MATCH($CU$2,{"Bull","Base","Bear"},0),$DD$27,$DE$27,$DF$27) -> 0.03 | CR14: =CHOOSE(MATCH($CU$2,{"Bull","Base","Bear"},0),$DD$28,$DE$28,$DF$28) -> 0.03 | CS14: =CHOOSE(MATCH($CU$2,{"Bull","Base","Bear"},0),$DD$29,$DE$29,$DF$29) -> 0.03 | CT14: =CHOOSE(MATCH($CU$2,{"Bull","Base","Bear"},0),$DD$30,$DE$30,$DF$30) -> 0.03 | CU14: 2027E–2031E: scenario lever (US_RPU) — buyer / seller fee pricing, ASP-linked fees, mix of purchase vs fee units. | DC14: 2029E | DD14: =DE14+$DD$11 -> 0.05 | DE14: 0.03 | DF14: =DE14+$DF$11 -> 0
B15: Service revenues y/y % | D15: =IFERROR(D12/C12-1,"") | E15: =IFERROR(E12/D12-1,"") | F15: =IFERROR(F12/E12-1,"") | G15: =IFERROR(G12/F12-1,"") | H15: =IFERROR(H12/G12-1,"") | I15: =IFERROR(I12/H12-1,"") | O15: =IFERROR(O12/I12-1,"") | P15: =IFERROR(P12/J12-1,"") | Q15: =IFERROR(Q12/K12-1,"") | R15: =IFERROR(R12/L12-1,"") | S15: =IFERROR(S12/M12-1,"") | T15: =IFERROR(T12/N12-1,"") | U15: =IFERROR(U12/O12-1,"") | V15: =IFERROR(V12/P12-1,"") | ... CO15: =IFERROR(CO12/CI12-1,"") -> -0.018331142 | CP15: =IFERROR(CP12/CO12-1,"") -> 0.0403 | CQ15: =IFERROR(CQ12/CP12-1,"") -> 0.05575 | CR15: =IFERROR(CR12/CQ12-1,"") -> 0.0609 | CS15: =IFERROR(CS12/CR12-1,"") -> 0.0609 | CT15: =IFERROR(CT12/CS12-1,"") -> 0.0609 | DC15: 2030E | DD15: =DE15+$DD$11 -> 0.05 | DE15: 0.03 | DF15: =DE15+$DF$11 -> 0
B16: Vehicle sales (USDm; purchase-model units) | AM16: 64.198 | AN16: 19.714 | AO16: 29.593 | AP16: =AN16+AO16 -> 49.307 | AQ16: 29.029 | AR16: 27.448 | AS16: 105.784 | AT16: 27.636 | AU16: 28.049 | AV16: =AT16+AU16 -> 55.685 | AW16: 31.325 | AX16: 32.128 | AY16: 119.138 | AZ16: 33.361 | BA16: 35.392 | BB16: =AZ16+BA16 -> 68.753 | BC16: 35.323 | BD16: 41.886 | BE16: 145.962 | BF16: 47.02 | BG16: 52.5 | BH16: =BF16+BG16 -> 99.52 | BI16: 71.615 | BJ16: 83.433 | BK16: 254.568 | BL16: 87.703 | BM16: 96.679 | BN16: =BL16+BM16 -> 184.382 | BO16: 111.385 | BP16: 116.218 | BQ16: 411.985 | BR16: 97.192 | BS16: 82.196 | BT16: =BR16+BS16 -> 179.388 | BU16: 81.681 | BV16: 86.938 | BW16: 348.007 | BX16: 78.382 | BY16: 74.69 | BZ16: =BX16+BY16 -> 153.072 | CA16: 88.236 | CB16: 97.326 | CC16: 338.633 | CD16: 87.549 | CE16: 106.715 | CF16: =CD16+CE16 -> 194.264 | CG16: 107.832 | CH16: 101.449 | CI16: 403.546 | CJ16: 97.08 | CK16: 102.153 | CL16: =CJ16+CK16 -> 199.233 | CM16: 107.398 | CN16: 112.512 | CO16: 419.143 | CP16: =CO16*(1+CP17) -> 435.90872 | CQ16: =CP16*(1+CQ17) -> 453.34507 | CR16: =CQ16*(1+CR17) -> 471.47887 | CS16: =CR16*(1+CS17) -> 490.33803 | CT16: =CS16*(1+CT17) -> 509.95155 | CU16: Vehicle sales = units sold under the purchase model (gross revenue); forecast grows with the input below. | DC16: 2031E | DD16: =DE16+$DD$11 -> 0.05 | DE16: 0.03 | DF16: =DE16+$DF$11 -> 0
B17: Vehicle sales y/y % (forecast input) | D17: =IFERROR(D16/C16-1,"") | E17: =IFERROR(E16/D16-1,"") | F17: =IFERROR(F16/E16-1,"") | G17: =IFERROR(G16/F16-1,"") | H17: =IFERROR(H16/G16-1,"") | I17: =IFERROR(I16/H16-1,"") | O17: =IFERROR(O16/I16-1,"") | P17: =IFERROR(P16/J16-1,"") | Q17: =IFERROR(Q16/K16-1,"") | R17: =IFERROR(R16/L16-1,"") | S17: =IFERROR(S16/M16-1,"") | T17: =IFERROR(T16/N16-1,"") | U17: =IFERROR(U16/O16-1,"") | V17: =IFERROR(V16/P16-1,"") | ... CO17: =IFERROR(CO16/CI16-1,"") -> 0.038649869 | CP17: 0.04 | CQ17: 0.04 | CR17: 0.04 | CS17: 0.04 | CT17: 0.04
B18: Total US revenue | C18: 526.456 | D18: 541.801 | E18: 591.6 | F18: 591.284 | G18: 602.794 | H18: 674.742 | I18: 724.869 | U18: 893.659 | AA18: 902.88 | AB18: 230.465 | AC18: 238.261 | AD18: =AB18+AC18 -> 468.726 | AE18: 279.21 | AF18: 268.1 | AG18: 1016.036 | AH18: 285.062 | AI18: 286.911 | AJ18: =AH18+AI18 -> 571.973 | AK18: 307.12 | AL18: 314.095 | AM18: =AM12+AM16 -> 1193.188 | AN18: =AN12+AN16 -> 351.105 | AO18: =AO12+AO16 -> 385.135 | AP18: =AP12+AP16 -> 736.24 | AQ18: =AQ12+AQ16 -> 385.281 | AR18: =AR12+AR16 -> 369.501 | AS18: =AS12+AS16 -> 1491.022 | AT18: =AT12+AT16 -> 371.209 | ... CT18: =CT12+CT16 -> 4953.4315 | CW18: =IFERROR((CT18/CO18)^(1/5)-1,"n/m") -> 0.054034551 | CX18: =IFERROR((CO18/BK18)^(1/5)-1,"n/m") -> 0.10877128 | CY18: =IFERROR((CO18/AG18)^(1/10)-1,"n/m") -> 0.14122764 | CZ18: =IFERROR((CO18/C18)^(1/20)-1,"n/m") -> 0.10398581 | DC18: INTL_unitGrowth (International units sold y/y) | DD18: 0.02 | DE18: Δ → | DF18: -0.03 | DG18: International: UK / Germany / Brazil market-share gains, total-loss adoption in continental Europe, new country entries.
B19: Total revenue y/y % | D19: =IFERROR(D18/C18-1,"") -> 0.029147735 | E19: =IFERROR(E18/D18-1,"") -> 0.091913821 | F19: =IFERROR(F18/E18-1,"") -> -0.00053414469 | G19: =IFERROR(G18/F18-1,"") -> 0.019466111 | H19: =IFERROR(H18/G18-1,"") -> 0.11935753 | I19: =IFERROR(I18/H18-1,"") -> 0.074290618 | O19: =IFERROR(O18/I18-1,"") -> -1 | P19: =IFERROR(P18/J18-1,"") | Q19: =IFERROR(Q18/K18-1,"") | R19: =IFERROR(R18/L18-1,"") | S19: =IFERROR(S18/M18-1,"") | T19: =IFERROR(T18/N18-1,"") | U19: =IFERROR(U18/O18-1,"") | V19: =IFERROR(V18/P18-1,"") | ... CO19: =IFERROR(CO18/CI18-1,"") -> -0.012366463 | CP19: =IFERROR(CP18/CO18-1,"") -> 0.040266974 | CQ19: =IFERROR(CQ18/CP18-1,"") -> 0.054016598 | CR19: =IFERROR(CR18/CQ18-1,"") -> 0.058630391 | CS19: =IFERROR(CS18/CR18-1,"") -> 0.058670333 | CT19: =IFERROR(CT18/CS18-1,"") -> 0.058709655 | DC19: 2027E | DD19: =DE19+$DD$18 -> 0.08 | DE19: 0.06 | DF19: =DE19+$DF$18 -> 0.03
B20: Segment operating income (historical disclosure) | U20: 223.384 | AA20: 289.991 | AB20: 72.939 | AC20: 79.053 | AD20: =AB20+AC20 -> 151.992 | AE20: 104.914 | AF20: 90.803 | AG20: 347.709 | AH20: 88.982 | AI20: 93.592 | AJ20: =AH20+AI20 -> 182.574 | AK20: 119.117 | AL20: 94.669 | AM20: 396.36 | AN20: 106.019 | AO20: 133.01 | AP20: =AN20+AO20 -> 239.029 | AQ20: 150.888 | AR20: 124.97 | AS20: 514.887 | AT20: 130.292 | AU20: 145.402 | AV20: =AT20+AU20 -> 275.694 | AW20: 188.258 | AX20: 173.516 | AY20: 637.468 | AZ20: 189.05 | BA20: 188.989 | BB20: =AZ20+BA20 -> 378.039 | BC20: 178.82 | BD20: 187.696 | BE20: 743.179 | BF20: 221.591 | BG20: 229.452 | BH20: =BF20+BG20 -> 451.043 | BI20: 296.726 | BJ20: 275.785 | BK20: 1023.555 | BL20: 294.949 | BM20: 312.646 | BN20: =BL20+BM20 -> 607.595 | BO20: 340.437 | BP20: 299.537 | BQ20: 1247.569 | BR20: 282.628 | BS20: 336.164 | BT20: =BR20+BS20 -> 618.792 | BU20: 384.791 | BV20: 364.515 | BW20: 1368.097 | BX20: 362.291 | BY20: 347.338 | BZ20: =BX20+BY20 -> 709.629 | CA20: 392.931 | CB20: 325.474 | CC20: 1428.034 | CD20: 355.059 | CE20: 375.893 | CF20: =CD20+CE20 -> 730.952 | CG20: 392.465 | CH20: 357.468 | CI20: 1480.886 | CJ20: 374.972 | CK20: 341.472 | CL20: =CJ20+CK20 -> 716.444 | CM20: 390.445 | CN20: 312.15 | CO20: 1419.04 | CU20: Segment profit is disclosed but not forecast (consolidated cost drivers below). | DC20: 2028E | DD20: =DE20+$DD$18 -> 0.08 | DE20: 0.06 | DF20: =DE20+$DF$18 -> 0.03
B21: Segment operating margin % | C21: =IF(ISNUMBER(C20),IFERROR(C20/C18,""),"") | D21: =IF(ISNUMBER(D20),IFERROR(D20/D18,""),"") | E21: =IF(ISNUMBER(E20),IFERROR(E20/E18,""),"") | F21: =IF(ISNUMBER(F20),IFERROR(F20/F18,""),"") | G21: =IF(ISNUMBER(G20),IFERROR(G20/G18,""),"") | H21: =IF(ISNUMBER(H20),IFERROR(H20/H18,""),"") | I21: =IF(ISNUMBER(I20),IFERROR(I20/I18,""),"") | J21: =IF(ISNUMBER(J20),IFERROR(J20/J18,""),"") | ... CO21: =IF(ISNUMBER(CO20),IFERROR(CO20/CO18,""),"") -> 0.37270285 | DC21: 2029E | DD21: =DE21+$DD$18 -> 0.075 | DE21: 0.055 | DF21: =DE21+$DF$18 -> 0.025
B22: Segment depreciation & amortization | U22: 44.516 | AA22: 36.238 | AB22: 9.049 | AC22: 9.286 | AD22: =AB22+AC22 -> 18.335 | AE22: 10.048 | AF22: 10.7 | AG22: 39.083 | AH22: 12.386 | AI22: 12.667 | AJ22: =AH22+AI22 -> 25.053 | AK22: 10.904 | AL22: 11.55 | AM22: 47.507 | AN22: 13.529 | AO22: 14.054 | AP22: =AN22+AO22 -> 27.583 | AQ22: 14.189 | AR22: 26.007 | AS22: 67.779 | AT22: 19.392 | AU22: 17.877 | AV22: =AT22+AU22 -> 37.269 | AW22: 18.636 | AX22: 19.36 | AY22: 75.265 | AZ22: 20.567 | BA22: 21.728 | BB22: =AZ22+BA22 -> 42.295 | BC22: 23.764 | BD22: 24.717 | BE22: 90.818 | BF22: 26.162 | BG22: 27.745 | BH22: =BF22+BG22 -> 53.907 | BI22: 28.161 | BJ22: 25.697 | BK22: 107.765 | BL22: 27.725 | BM22: 29.316 | BN22: =BL22+BM22 -> 57.041 | BO22: 31.609 | BP22: 31.98 | BQ22: 120.635 | BR22: 34.935 | BS22: 34.121 | BT22: =BR22+BS22 -> 69.056 | BU22: 32.918 | BV22: 33.83 | BW22: 135.804 | BX22: 36.936 | BY22: 38.344 | BZ22: =BX22+BY22 -> 75.28 | CA22: 43.477 | CB22: 42.929 | CC22: 161.685 | CD22: 45.915 | CE22: 46.455 | CF22: =CD22+CE22 -> 92.37 | CG22: 46.461 | CH22: 45.195 | CI22: 184.026 | CJ22: 45.409 | CK22: 46.829 | CL22: =CJ22+CK22 -> 92.238 | CM22: 50.259 | CN22: 52.252 | CO22: 194.749 | DC22: 2030E | DD22: =DE22+$DD$18 -> 0.07 | DE22: 0.05 | DF22: =DE22+$DF$18 -> 0.02
B23: Segment capital expenditures (incl. acquired productive assets) | U23: 59.724 | AA23: 64.769 | AB23: 19.321 | AC23: 56.997 | AD23: =AB23+AC23 -> 76.318 | AE23: 49.866 | AF23: 27.267 | AG23: 153.451 | AH23: 36.521 | AI23: 51.541 | AJ23: =AH23+AI23 -> 88.062 | AK23: 40.872 | AL23: 188.712 | AM23: 317.646 | AN23: 38.905 | AO23: 56.804 | AP23: =AN23+AO23 -> 95.709 | AQ23: 57.028 | AR23: 103.131 | AS23: 255.868 | AT23: 35.253 | AU23: 66.901 | AV23: =AT23+AU23 -> 102.154 | AW23: 107.569 | AX23: 102.104 | AY23: 311.827 | AZ23: 113.266 | BA23: 261.258 | BB23: =AZ23+BA23 -> 374.524 | BC23: 86.441 | BD23: 107.701 | BE23: 568.773 | BF23: 122.459 | BG23: 121.595 | BH23: =BF23+BG23 -> 244.054 | BI23: 59.006 | BJ23: 87.646 | BK23: 390.706 | BL23: 54.272 | BM23: 86.788 | BN23: =BL23+BM23 -> 141.06 | BO23: 64.397 | BP23: 92.175 | BQ23: 297.632 | BR23: 136.283 | BS23: 89.428 | BT23: =BR23+BS23 -> 225.711 | BU23: 79.633 | BV23: 67.846 | BW23: 373.19 | BX23: 216.131 | BY23: 83.861 | BZ23: =BX23+BY23 -> 299.992 | CA23: 72.186 | CB23: 119.319 | CC23: 491.497 | CD23: 211.917 | CE23: 153.212 | CF23: =CD23+CE23 -> 365.129 | CG23: 62.906 | CH23: 62.93 | CI23: 490.965 | CJ23: 71.458 | CK23: 58.875 | CL23: =CJ23+CK23 -> 130.333 | CM23: 75.213 | CN23: 51.419 | CO23: 256.965 | DC23: 2031E | DD23: =DE23+$DD$18 -> 0.07 | DE23: 0.05 | DF23: =DE23+$DF$18 -> 0.02
B25: International segment (UK, Canada, Germany, Brazil, Spain, Ireland, Finland, UAE, Oman, Bahrain) | CU25: INTERNATIONAL — modelling logic | DC25: US_RPU (US service revenue per unit y/y) | DD25: 0.01 | DE25: Δ → | DF25: -0.015 | DG25: Per-unit fees track used-vehicle / salvage ASPs (buyer fees are ASP-linked) plus pricing actions and purchase-vs-fee mix.
B26: Service revenues (USDm) | AM26: 157.262 | AN26: 42.734 | AO26: 46.412 | AP26: =AN26+AO26 -> 89.146 | AQ26: 54.51 | AR26: 49.608 | AS26: 193.264 | AT26: 51.233 | AU26: 54.784 | AV26: =AT26+AU26 -> 106.017 | AW26: 56.808 | AX26: 55.438 | AY26: 218.263 | AZ26: 57.053 | BA26: 62.689 | BB26: =AZ26+BA26 -> 119.742 | BC26: 59.707 | BD26: 52.967 | BE26: 232.416 | BF26: 65.137 | BG26: 67.178 | BH26: =BF26+BG26 -> 132.315 | BI26: 73.508 | BJ26: 68.54 | BK26: 274.363 | BL26: 77.06 | BM26: 80.383 | BN26: =BL26+BM26 -> 157.443 | BO26: 87.451 | BP26: 74.981 | BQ26: 319.875 | BR26: 75.183 | BS26: 84.064 | BT26: =BR26+BS26 -> 159.247 | BU26: 95.172 | BV26: 102.068 | BW26: 356.487 | BX26: 97.012 | BY26: 105.709 | BZ26: =BX26+BY26 -> 202.721 | CA26: 115.95 | CB26: 116.23 | CC26: 434.9 | CD26: 126.346 | CE26: 123.151 | CF26: =CD26+CE26 -> 249.497 | CG26: 136.211 | CH26: 131.396 | CI26: 517.104 | CJ26: 136.311 | CK26: 132.584 | CL26: =CJ26+CK26 -> 268.895 | CM26: 160.616 | CN26: 151.722 | CO26: 581.233 | CP26: =CO26*(1+CP27)*(1+CP28) -> 634.59019 | CQ26: =CP26*(1+CQ27)*(1+CQ28) -> 692.84557 | CR26: =CQ26*(1+CR27)*(1+CR28) -> 752.88064 | CS26: =CR26*(1+CS27)*(1+CS28) -> 814.24041 | CT26: =CS26*(1+CT27)*(1+CT28) -> 880.601 | CU26: FY2027E+: prior year × (1 + units sold growth, scenario lever) × (1 + service revenue per unit growth). | CW26: =IFERROR((CT26/CO26)^(1/5)-1,"n/m") -> 0.086640237 | CX26: =IFERROR((CO26/BK26)^(1/5)-1,"n/m") -> 0.16199683 | CY26: =IFERROR((CO26/AG26)^(1/10)-1,"n/m") -> n/m | CZ26: =IFERROR((CO26/C26)^(1/20)-1,"n/m") -> n/m | DC26: 2027E | DD26: =DE26+$DD$25 -> 0.04 | DE26: 0.03 | DF26: =DE26+$DF$25 -> 0.015
B27: Units sold y/y % (disclosed in MD&A; forecast = scenario lever) | CP27: =CHOOSE(MATCH($CU$2,{"Bull","Base","Bear"},0),$DD$19,$DE$19,$DF$19) -> 0.06 | CQ27: =CHOOSE(MATCH($CU$2,{"Bull","Base","Bear"},0),$DD$20,$DE$20,$DF$20) -> 0.06 | CR27: =CHOOSE(MATCH($CU$2,{"Bull","Base","Bear"},0),$DD$21,$DE$21,$DF$21) -> 0.055 | CS27: =CHOOSE(MATCH($CU$2,{"Bull","Base","Bear"},0),$DD$22,$DE$22,$DF$22) -> 0.05 | CT27: =CHOOSE(MATCH($CU$2,{"Bull","Base","Bear"},0),$DD$23,$DE$23,$DF$23) -> 0.05 | CU27: 2027E–2031E: scenario lever (INTL_unitGrowth, Bull/Base/Bear table →). | DC27: 2028E | DD27: =DE27+$DD$25 -> 0.04 | DE27: 0.03 | DF27: =DE27+$DF$25 -> 0.015
B28: Service revenue per unit y/y % (implied price / mix; forecast input) | C28: =IF(ISNUMBER(C27),IFERROR((1+C29)/(1+C27)-1,""),"") | D28: =IF(ISNUMBER(D27),IFERROR((1+D29)/(1+D27)-1,""),"") | E28: =IF(ISNUMBER(E27),IFERROR((1+E29)/(1+E27)-1,""),"") | F28: =IF(ISNUMBER(F27),IFERROR((1+F29)/(1+F27)-1,""),"") | G28: =IF(ISNUMBER(G27),IFERROR((1+G29)/(1+G27)-1,""),"") | H28: =IF(ISNUMBER(H27),IFERROR((1+H29)/(1+H27)-1,""),"") | I28: =IF(ISNUMBER(I27),IFERROR((1+I29)/(1+I27)-1,""),"") | J28: =IF(ISNUMBER(J27),IFERROR((1+J29)/(1+J27)-1,""),"") | ... CO28: =IF(ISNUMBER(CO27),IFERROR((1+CO29)/(1+CO27)-1,""),"") | CP28: 0.03 | CQ28: 0.03 | CR28: 0.03 | CS28: 0.03 | CT28: 0.03 | CU28: Input: fee pricing and mix (International units carry lower fees per unit than the US). | DC28: 2029E | DD28: =DE28+$DD$25 -> 0.04 | DE28: 0.03 | DF28: =DE28+$DF$25 -> 0.015
B29: Service revenues y/y % | D29: =IFERROR(D26/C26-1,"") | E29: =IFERROR(E26/D26-1,"") | F29: =IFERROR(F26/E26-1,"") | G29: =IFERROR(G26/F26-1,"") | H29: =IFERROR(H26/G26-1,"") | I29: =IFERROR(I26/H26-1,"") | O29: =IFERROR(O26/I26-1,"") | P29: =IFERROR(P26/J26-1,"") | Q29: =IFERROR(Q26/K26-1,"") | R29: =IFERROR(R26/L26-1,"") | S29: =IFERROR(S26/M26-1,"") | T29: =IFERROR(T26/N26-1,"") | U29: =IFERROR(U26/O26-1,"") | V29: =IFERROR(V26/P26-1,"") | ... CO29: =IFERROR(CO26/CI26-1,"") -> 0.12401567 | CP29: =IFERROR(CP26/CO26-1,"") -> 0.0918 | CQ29: =IFERROR(CQ26/CP26-1,"") -> 0.0918 | CR29: =IFERROR(CR26/CQ26-1,"") -> 0.08665 | CS29: =IFERROR(CS26/CR26-1,"") -> 0.0815 | CT29: =IFERROR(CT26/CS26-1,"") -> 0.0815 | DC29: 2030E | DD29: =DE29+$DD$25 -> 0.04 | DE29: 0.03 | DF29: =DE29+$DF$25 -> 0.015
B30: Vehicle sales (USDm; purchase-model units) | AM30: 97.531 | AN30: 25.329 | AO30: 27.559 | AP30: =AN30+AO30 -> 52.888 | AQ30: 38.407 | AR30: 30.114 | AS30: 121.409 | AT30: 38.926 | AU30: 40.042 | AV30: =AT30+AU30 -> 78.968 | AW30: 48.109 | AX30: 40.048 | AY30: 167.125 | AZ30: 33.207 | BA30: 29.714 | BB30: =AZ30+BA30 -> 62.921 | BC30: 23.455 | BD30: 26.105 | BE30: 112.481 | BF30: 30.548 | BG30: 31.93 | BH30: =BF30+BG30 -> 62.478 | BI30: 38.449 | BJ30: 45.149 | BK30: 146.076 | BL30: 54.611 | BM30: 59.691 | BN30: =BL30+BM30 -> 114.302 | BO30: 62.24 | BP30: 59.354 | BQ30: 235.896 | BR30: 69.34 | BS30: 84.731 | BT30: =BR30+BS30 -> 154.071 | BU30: 92.901 | BV30: 76.411 | BW30: 323.383 | BX30: 82.498 | BY30: 83.714 | BZ30: =BX30+BY30 -> 166.212 | CA30: 92.393 | CB30: 78.582 | CC30: 337.188 | CD30: 72.944 | CE30: 65.32 | CF30: =CD30+CE30 -> 138.264 | CG30: 69.048 | CH30: 67.439 | CI30: 274.75 | CJ30: 66.105 | CK30: 67.47 | CL30: =CJ30+CK30 -> 133.575 | CM30: 73.588 | CN30: 70.383 | CO30: 277.546 | CP30: =CO30*(1+CP31) -> 291.4233 | CQ30: =CP30*(1+CQ31) -> 305.99446 | CR30: =CQ30*(1+CR31) -> 321.29419 | CS30: =CR30*(1+CS31) -> 337.3589 | CT30: =CS30*(1+CT31) -> 354.22684 | CU30: Vehicle sales = units sold under the purchase model (gross revenue); forecast grows with the input below. | DC30: 2031E | DD30: =DE30+$DD$25 -> 0.04 | DE30: 0.03 | DF30: =DE30+$DF$25 -> 0.015
B31: Vehicle sales y/y % (forecast input) | D31: =IFERROR(D30/C30-1,"") | E31: =IFERROR(E30/D30-1,"") | F31: =IFERROR(F30/E30-1,"") | G31: =IFERROR(G30/F30-1,"") | H31: =IFERROR(H30/G30-1,"") | I31: =IFERROR(I30/H30-1,"") | O31: =IFERROR(O30/I30-1,"") | P31: =IFERROR(P30/J30-1,"") | Q31: =IFERROR(Q30/K30-1,"") | R31: =IFERROR(R30/L30-1,"") | S31: =IFERROR(S30/M30-1,"") | T31: =IFERROR(T30/N30-1,"") | U31: =IFERROR(U30/O30-1,"") | V31: =IFERROR(V30/P30-1,"") | ... CO31: =IFERROR(CO30/CI30-1,"") -> 0.010176524 | CP31: 0.05 | CQ31: 0.05 | CR31: 0.05 | CS31: 0.05 | CT31: 0.05
B32: Total International revenue | C32: 2.115 | D32: 18.879 | E32: 193.248 | F32: 151.798 | G32: 170.085 | H32: 197.504 | I32: 199.322 | O32: 228.945 | U32: 269.83 | AA32: 243.199 | AB32: 58.373 | AC32: 61.445 | AD32: =AB32+AC32 -> 119.818 | AE32: 68.036 | AF32: 64.559 | AG32: 252.413 | AH32: 60.929 | AI32: 62.621 | AJ32: =AH32+AI32 -> 123.55 | AK32: 66.742 | AL32: 64.501 | AM32: =AM26+AM30 -> 254.793 | AN32: =AN26+AN30 -> 68.063 | AO32: =AO26+AO30 -> 73.971 | AP32: =AP26+AP30 -> 142.034 | AQ32: =AQ26+AQ30 -> 92.917 | AR32: =AR26+AR30 -> 79.722 | AS32: =AS26+AS30 -> 314.673 | AT32: =AT26+AT30 -> 90.159 | ... CT32: =CT26+CT30 -> 1234.8278 | CW32: =IFERROR((CT32/CO32)^(1/5)-1,"n/m") -> 0.075338016 | CX32: =IFERROR((CO32/BK32)^(1/5)-1,"n/m") -> 0.15354804 | CY32: =IFERROR((CO32/AG32)^(1/10)-1,"n/m") -> 0.13025639 | CZ32: =IFERROR((CO32/C32)^(1/20)-1,"n/m") -> 0.35029467 | DC32: ADJ_EBITDA_margin (% of total revenues) | DD32: 0.015 | DE32: Δ → | DF32: -0.02 | DG32: FY2026 40.3%, FY2025 41.2%, FY2021 peak ~45%. Yard capacity absorption and fee pricing vs labour / towing inflation.
B33: Total revenue y/y % | D33: =IFERROR(D32/C32-1,"") -> 7.9262411 | E33: =IFERROR(E32/D32-1,"") -> 9.2361354 | F33: =IFERROR(F32/E32-1,"") -> -0.21449122 | G33: =IFERROR(G32/F32-1,"") -> 0.12046931 | H33: =IFERROR(H32/G32-1,"") -> 0.16120763 | I33: =IFERROR(I32/H32-1,"") -> 0.0092048769 | O33: =IFERROR(O32/I32-1,"") -> 0.14861882 | P33: =IFERROR(P32/J32-1,"") | Q33: =IFERROR(Q32/K32-1,"") | R33: =IFERROR(R32/L32-1,"") | S33: =IFERROR(S32/M32-1,"") | T33: =IFERROR(T32/N32-1,"") | U33: =IFERROR(U32/O32-1,"") -> 0.17858001 | V33: =IFERROR(V32/P32-1,"") | ... CO33: =IFERROR(CO32/CI32-1,"") -> 0.084516843 | CP33: =IFERROR(CP32/CO32-1,"") -> 0.078290794 | CQ33: =IFERROR(CQ32/CP32-1,"") -> 0.078645231 | CR33: =IFERROR(CR32/CQ32-1,"") -> 0.075422279 | CS33: =IFERROR(CS32/CR32-1,"") -> 0.072078101 | CT33: =IFERROR(CT32/CS32-1,"") -> 0.072272133 | DC33: 2027E | DD33: =DE33+$DD$32 -> 0.415 | DE33: 0.4 | DF33: =DE33+$DF$32 -> 0.38
B34: Segment operating income (historical disclosure) | U34: 51.55 | AA34: 54.41 | AB34: 13.307 | AC34: 13.032 | AD34: =AB34+AC34 -> 26.339 | AE34: 17.034 | AF34: 15.388 | AG34: 58.761 | AH34: 15.842 | AI34: 15.288 | AJ34: =AH34+AI34 -> 31.13 | AK34: 17.671 | AL34: 16.138 | AM34: 64.939 | AN34: 17.923 | AO34: 17.937 | AP34: =AN34+AO34 -> 35.86 | AQ34: 23.731 | AR34: 9.867 | AS34: 69.458 | AT34: 21.148 | AU34: 19.337 | AV34: =AT34+AU34 -> 40.485 | AW34: 19.236 | AX34: 19.286 | AY34: 79.007 | AZ34: 16.341 | BA34: 20.903 | BB34: =AZ34+BA34 -> 37.244 | BC34: 16.281 | BD34: 18.019 | BE34: 72.92 | BF34: 27.003 | BG34: 28.769 | BH34: =BF34+BG34 -> 55.772 | BI34: 31.385 | BJ34: 25.715 | BK34: 112.871 | BL34: 35.172 | BM34: 34.682 | BN34: =BL34+BM34 -> 69.854 | BO34: 32.318 | BP34: 25.256 | BQ34: 127.428 | BR34: 28.875 | BS34: 29.361 | BT34: =BR34+BS34 -> 58.236 | BU34: 34.133 | BV34: 26.102 | BW34: 118.472 | BX34: 33.085 | BY34: 32.562 | BZ34: =BX34+BY34 -> 65.647 | CA34: 44.272 | CB34: 34.07 | CC34: 143.989 | CD34: 51.308 | CE34: 50.318 | CF34: =CD34+CE34 -> 101.626 | CG34: 59.08 | CH34: 55.123 | CI34: 215.828 | CJ34: 55.722 | CK34: 47.238 | CL34: =CJ34+CK34 -> 102.96 | CM34: 73.837 | CN34: 56.754 | CO34: 233.55 | CU34: Segment profit is disclosed but not forecast (consolidated cost drivers below). | DC34: 2028E | DD34: =DE34+$DD$32 -> 0.42 | DE34: 0.405 | DF34: =DE34+$DF$32 -> 0.385
B35: Segment operating margin % | C35: =IF(ISNUMBER(C34),IFERROR(C34/C32,""),"") | D35: =IF(ISNUMBER(D34),IFERROR(D34/D32,""),"") | E35: =IF(ISNUMBER(E34),IFERROR(E34/E32,""),"") | F35: =IF(ISNUMBER(F34),IFERROR(F34/F32,""),"") | G35: =IF(ISNUMBER(G34),IFERROR(G34/G32,""),"") | H35: =IF(ISNUMBER(H34),IFERROR(H34/H32,""),"") | I35: =IF(ISNUMBER(I34),IFERROR(I34/I32,""),"") | J35: =IF(ISNUMBER(J34),IFERROR(J34/J32,""),"") | ... CO35: =IF(ISNUMBER(CO34),IFERROR(CO34/CO32,""),"") -> 0.27195588 | DC35: 2029E | DD35: =DE35+$DD$32 -> 0.425 | DE35: 0.41 | DF35: =DE35+$DF$32 -> 0.39
B36: Segment depreciation & amortization | U36: 9.21 | AA36: 10.335 | AB36: 2.472 | AC36: 2.405 | AD36: =AB36+AC36 -> 4.877 | AE36: 2.31 | AF36: 2.305 | AG36: 9.492 | AH36: 2.323 | AI36: 2.548 | AJ36: =AH36+AI36 -> 4.871 | AK36: 2.304 | AL36: 2.318 | AM36: 9.493 | AN36: 2.373 | AO36: 3.817 | AP36: =AN36+AO36 -> 6.19 | AQ36: 2.384 | AR36: 2.245 | AS36: 10.819 | AT36: 2.477 | AU36: 2.522 | AV36: =AT36+AU36 -> 4.999 | AW36: 2.476 | AX36: 2.155 | AY36: 9.63 | AZ36: 2.447 | BA36: 2.554 | BB36: =AZ36+BA36 -> 5.001 | BC36: 2.951 | BD36: 2.662 | BE36: 10.572 | BF36: 2.787 | BG36: 3.647 | BH36: =BF36+BG36 -> 6.434 | BI36: 3.805 | BJ36: 3.967 | BK36: 14.206 | BL36: 4.035 | BM36: 3.987 | BN36: =BL36+BM36 -> 8.022 | BO36: 4.97 | BP36: 4.353 | BQ36: 17.35 | BR36: 4.123 | BS36: 4.293 | BT36: =BR36+BS36 -> 8.416 | BU36: 4.453 | BV36: 10.805 | BW36: 23.674 | BX36: 6.228 | BY36: 6.918 | BZ36: =BX36+BY36 -> 13.146 | CA36: 7.256 | CB36: 7.674 | CC36: 28.076 | CD36: 7.712 | CE36: 7.744 | CF36: =CD36+CE36 -> 15.456 | CG36: 7.955 | CH36: 8.412 | CI36: 31.823 | CJ36: 8.633 | CK36: 8.558 | CL36: =CJ36+CK36 -> 17.191 | CM36: 8.724 | CN36: 8.709 | CO36: 34.624 | DC36: 2030E | DD36: =DE36+$DD$32 -> 0.43 | DE36: 0.415 | DF36: =DE36+$DF$32 -> 0.395
B37: Segment capital expenditures (incl. acquired productive assets) | U37: 36.086 | AA37: 14.384 | AB37: 0.846 | AC37: 0.599 | AD37: =AB37+AC37 -> 1.445 | AE37: 16.204 | AF37: 2.817 | AG37: 20.466 | AH37: 1.688 | AI37: 2.662 | AJ37: =AH37+AI37 -> 4.35 | AK37: 1.426 | AL37: 9.568 | AM37: 15.344 | AN37: 2.456 | AO37: 12.617 | AP37: =AN37+AO37 -> 15.073 | AQ37: 20.672 | AR37: 5.084 | AS37: 40.829 | AT37: 27.083 | AU37: 7.49 | AV37: =AT37+AU37 -> 34.573 | AW37: 15.785 | AX37: 12.443 | AY37: 62.801 | AZ37: 18.527 | BA37: 7.301 | BB37: =AZ37+BA37 -> 25.828 | BC37: 4.205 | BD37: 4.975 | BE37: 34.901 | BF37: 24.634 | BG37: 14.526 | BH37: =BF37+BG37 -> 39.16 | BI37: 22.175 | BJ37: 15.955 | BK37: 77.29 | BL37: 10.424 | BM37: 5.185 | BN37: =BL37+BM37 -> 15.609 | BO37: 14.237 | BP37: 116.574 | BQ37: 146.42 | BR37: 16.372 | BS37: 14.636 | BT37: =BR37+BS37 -> 31.008 | BU37: 10.172 | BV37: 102.266 | BW37: 143.446 | BX37: 40.542 | BY37: 39.168 | BZ37: =BX37+BY37 -> 79.71 | CA37: 15.629 | CB37: 18.567 | CC37: 113.906 | CD37: 26.098 | CE37: 20.868 | CF37: =CD37+CE37 -> 46.966 | CG37: 7.561 | CH37: 24.721 | CI37: 79.248 | CJ37: 41.283 | CK37: 10.738 | CL37: =CJ37+CK37 -> 52.021 | CM37: 5.733 | CN37: 27.648 | CO37: 85.402 | DC37: 2031E | DD37: =DE37+$DD$32 -> 0.435 | DE37: 0.42 | DF37: =DE37+$DF$32 -> 0.4
B39: Total — segment build, units & mix | CU39: TOTAL — modelling logic | DC39: Buybacks ($m) | DD39: 500 | DE39: Δ → | DF39: -700 | DG39: FY2026 repurchases $1,633m (first material buyback since FY2019). ACV deal funding (~$2bn cash) would displace buybacks (not modelled).
B40: Service revenues — segment build | C40: =IF(ISNUMBER(C12),C12+C26,"n/d") -> n/d | D40: =IF(ISNUMBER(D12),D12+D26,"n/d") -> n/d | E40: =IF(ISNUMBER(E12),E12+E26,"n/d") -> n/d | F40: =IF(ISNUMBER(F12),F12+F26,"n/d") -> n/d | G40: =IF(ISNUMBER(G12),G12+G26,"n/d") -> n/d | H40: =IF(ISNUMBER(H12),H12+H26,"n/d") -> n/d | I40: =IF(ISNUMBER(I12),I12+I26,"n/d") -> n/d | J40: =IF(ISNUMBER(J12),J12+J26,"n/d") -> n/d | ... CO40: =IF(ISNUMBER(CO12),CO12+CO26,"n/d") -> 3969.52 | CP40: =CP12+CP26 -> 4159.4252 | CQ40: =CQ12+CQ26 -> 4414.1901 | CR40: =CR12+CR26 -> 4700.855 | CS40: =CS12+CS26 -> 5002.6464 | CT40: =CT12+CT26 -> 5324.081 | CU40: Forecast service revenues = US + International build (links to the income statement). | DC40: 2027E | DD40: =MAX(0,DE40+$DD$39) -> 1500 | DE40: 1000 | DF40: =MAX(0,DE40+$DF$39) -> 300
B41: Vehicle sales — segment build | C41: =IF(ISNUMBER(C16),C16+C30,"n/d") -> n/d | D41: =IF(ISNUMBER(D16),D16+D30,"n/d") -> n/d | E41: =IF(ISNUMBER(E16),E16+E30,"n/d") -> n/d | F41: =IF(ISNUMBER(F16),F16+F30,"n/d") -> n/d | G41: =IF(ISNUMBER(G16),G16+G30,"n/d") -> n/d | H41: =IF(ISNUMBER(H16),H16+H30,"n/d") -> n/d | I41: =IF(ISNUMBER(I16),I16+I30,"n/d") -> n/d | J41: =IF(ISNUMBER(J16),J16+J30,"n/d") -> n/d | ... CO41: =IF(ISNUMBER(CO16),CO16+CO30,"n/d") -> 696.689 | CP41: =CP16+CP30 -> 727.33202 | CQ41: =CQ16+CQ30 -> 759.33953 | CR41: =CR16+CR30 -> 792.77306 | CS41: =CS16+CS30 -> 827.69692 | CT41: =CT16+CT30 -> 864.17839 | DC41: 2028E | DD41: =MAX(0,DE41+$DD$39) -> 1250 | DE41: 750 | DF41: =MAX(0,DE41+$DF$39) -> 50
B42: Total service revenues and vehicle sales (build) | C42: =IF(ISNUMBER(C40),C40+C41,C73) -> 528.571 | D42: =IF(ISNUMBER(D40),D40+D41,D73) -> 560.68 | E42: =IF(ISNUMBER(E40),E40+E41,E73) -> 784.848 | F42: =IF(ISNUMBER(F40),F40+F41,F73) -> 743.082 | G42: =IF(ISNUMBER(G40),G40+G41,G73) -> 772.879 | H42: =IF(ISNUMBER(H40),H40+H41,H73) -> 872.246 | I42: =IF(ISNUMBER(I40),I40+I41,I73) -> 924.191 | J42: =IF(ISNUMBER(J40),J40+J41,J73) -> 238.866 | ... CO42: =IF(ISNUMBER(CO40),CO40+CO41,CO73) -> 4666.209 | CP42: =CP40+CP41 -> 4886.7572 | CQ42: =CQ40+CQ41 -> 5173.5296 | CR42: =CR40+CR41 -> 5493.6281 | CS42: =CS40+CS41 -> 5830.3434 | CT42: =CT40+CT41 -> 6188.2594 | CU42: Group revenue = service revenues + vehicle sales (ties to the GAAP income statement). | CW42: =IFERROR((CT42/CO42)^(1/5)-1,"n/m") -> 0.058085747 | CX42: =IFERROR((CO42/BK42)^(1/5)-1,"n/m") -> 0.11624966 | CY42: =IFERROR((CO42/AG42)^(1/10)-1,"n/m") -> 0.13911906 | CZ42: =IFERROR((CO42/C42)^(1/20)-1,"n/m") -> 0.11504666 | DC42: 2029E | DD42: =MAX(0,DE42+$DD$39) -> 1250 | DE42: 750 | DF42: =MAX(0,DE42+$DF$39) -> 50
B43: Check: service / vehicle segment build vs income statement (should be 0) | C43: =IF(ISNUMBER(C40),ROUND(C42-C73,1),"n/d") -> n/d | D43: =IF(ISNUMBER(D40),ROUND(D42-D73,1),"n/d") -> n/d | E43: =IF(ISNUMBER(E40),ROUND(E42-E73,1),"n/d") -> n/d | F43: =IF(ISNUMBER(F40),ROUND(F42-F73,1),"n/d") -> n/d | G43: =IF(ISNUMBER(G40),ROUND(G42-G73,1),"n/d") -> n/d | H43: =IF(ISNUMBER(H40),ROUND(H42-H73,1),"n/d") -> n/d | I43: =IF(ISNUMBER(I40),ROUND(I42-I73,1),"n/d") -> n/d | J43: =IF(ISNUMBER(J40),ROUND(J42-J73,1),"n/d") -> n/d | ... CO43: =IF(ISNUMBER(CO40),ROUND(CO42-CO73,1),"n/d") -> 0 | CP43: =ROUND(CP42-CP73,1) -> 0 | CQ43: =ROUND(CQ42-CQ73,1) -> 0 | CR43: =ROUND(CR42-CR73,1) -> 0 | CS43: =ROUND(CS42-CS73,1) -> 0 | CT43: =ROUND(CT42-CT73,1) -> 0 | DC43: 2030E | DD43: =MAX(0,DE43+$DD$39) -> 1250 | DE43: 750 | DF43: =MAX(0,DE43+$DF$39) -> 50
B44: Check: US + International revenue vs income statement (should be 0) | C44: =IF(AND(ISNUMBER(C18),ISNUMBER(C32)),ROUND(C18+C32-C73,1),"n/d") -> 0 | D44: =IF(AND(ISNUMBER(D18),ISNUMBER(D32)),ROUND(D18+D32-D73,1),"n/d") -> 0 | E44: =IF(AND(ISNUMBER(E18),ISNUMBER(E32)),ROUND(E18+E32-E73,1),"n/d") -> 0 | F44: =IF(AND(ISNUMBER(F18),ISNUMBER(F32)),ROUND(F18+F32-F73,1),"n/d") -> 0 | G44: =IF(AND(ISNUMBER(G18),ISNUMBER(G32)),ROUND(G18+G32-G73,1),"n/d") -> 0 | H44: =IF(AND(ISNUMBER(H18),ISNUMBER(H32)),ROUND(H18+H32-H73,1),"n/d") -> 0 | I44: =IF(AND(ISNUMBER(I18),ISNUMBER(I32)),ROUND(I18+I32-I73,1),"n/d") -> 0 | J44: =IF(AND(ISNUMBER(J18),ISNUMBER(J32)),ROUND(J18+J32-J73,1),"n/d") -> n/d | ... CO44: =IF(AND(ISNUMBER(CO18),ISNUMBER(CO32)),ROUND(CO18+CO32-CO73,1),"n/d") -> 0 | CP44: =ROUND(CP18+CP32-CP73,1) -> 0 | CQ44: =ROUND(CQ18+CQ32-CQ73,1) -> 0 | CR44: =ROUND(CR18+CR32-CR73,1) -> 0 | CS44: =ROUND(CS18+CS32-CS73,1) -> 0 | CT44: =ROUND(CT18+CT32-CT73,1) -> 0 | DC44: 2031E | DD44: =MAX(0,DE44+$DD$39) -> 1250 | DE44: 750 | DF44: =MAX(0,DE44+$DF$39) -> 50
...

Sheet Bull-Base-Bear
B2: Copart, Inc. (CPRT) — Bull / Base / Bear Case P&L Summary | J2: Share price ($): | K2: =Model!$CO$344 -> 27
B3: Adjusted figures (Copart non-GAAP definition; adjusted = GAAP since Q1/24) · USD millions · fiscal years ending 31-July · Live panel linked to Model — toggle scenario via Model!CU2. Bull and Bear panels are value snapshots of the Model run with the switch set to Bull / Bear. Standalone (pending ACV Auctions acquisition excluded). | J3: As of: | K3: =TODAY() -> 46298
B5: Scenario: | C5: =Model!CU2 -> Base | N5: Scenario: | O5: Bull | P5: Snapshot (values) — Model run with switch = Bull | Z5: Scenario: | AA5: Bear | AB5: Snapshot (values) — Model run with switch = Bear
B7: (USDm, except EPS and shares) | C7: 2026A | D7: 2027E | E7: 2028E | F7: 2029E | G7: 2030E | H7: 2031E | I7: 26-'31 CAGR | J7: LT Hist Avg | K7: LT Hist Min | L7: LT Hist Max | N7: (USDm, except EPS and shares) | O7: 2026A | P7: 2027E | Q7: 2028E | R7: 2029E | S7: 2030E | T7: 2031E | U7: 26-'31 CAGR | V7: LT Hist Avg | W7: LT Hist Min | X7: LT Hist Max | Z7: (USDm, except EPS and shares) | AA7: 2026A | AB7: 2027E | AC7: 2028E | AD7: 2029E | AE7: 2030E | AF7: 2031E | AG7: 26-'31 CAGR | AH7: LT Hist Avg | AI7: LT Hist Min | AJ7: LT Hist Max
B9: Revenue | C9: =Model!CO73 -> 4666.209 | D9: =Model!CP73 -> 4886.7572 | E9: =Model!CQ73 -> 5173.5296 | F9: =Model!CR73 -> 5493.6281 | G9: =Model!CS73 -> 5830.3434 | H9: =Model!CT73 -> 6188.2594 | I9: =IFERROR((H9/C9)^(1/5)-1,"n/m") -> 0.058085747 | N9: Revenue | O9: 4666.209 | P9: 5003.4286 | Q9: 5423.1534 | R9: 5896.6261 | S9: 6409.1479 | T9: 6967.9875 | U9: 0.083499299 | Z9: Revenue | AA9: 4666.209 | AB9: 4714.2912 | AC9: 4817.302 | AD9: 4938.2629 | AE9: 5059.9564 | AF9: 5185.7531 | AG9: 0.021338093
B10: Revenue y/y % | D10: =IFERROR(D9/C9-1,"") -> 0.047264959 | E10: =IFERROR(E9/D9-1,"") -> 0.058683588 | F10: =IFERROR(F9/E9-1,"") -> 0.061872358 | G10: =IFERROR(G9/F9-1,"") -> 0.061291968 | H10: =IFERROR(H9/G9-1,"") -> 0.061388492 | N10: Revenue y/y % | P10: 0.07226844 | Q10: 0.083887422 | R10: 0.087305805 | S10: 0.086917795 | T10: 0.087194053 | Z10: Revenue y/y % | AB10: 0.010304337 | AC10: 0.021850751 | AD10: 0.025109681 | AE10: 0.024642973 | AF10: 0.02486123
B11: Service revenues | C11: =Model!CO71 -> 3969.52 | D11: =Model!CP71 -> 4159.4252 | E11: =Model!CQ71 -> 4414.1901 | F11: =Model!CR71 -> 4700.855 | G11: =Model!CS71 -> 5002.6464 | H11: =Model!CT71 -> 5324.081 | I11: =IFERROR((H11/C11)^(1/5)-1,"n/m") -> 0.060477189 | N11: Service revenues | O11: 3969.52 | P11: 4276.0966 | Q11: 4663.8138 | R11: 5103.8531 | S11: 5581.451 | T11: 6103.8091 | U11: 0.089864707 | Z11: Service revenues | AA11: 3969.52 | AB11: 3986.9592 | AC11: 4057.9625 | AD11: 4145.4898 | AE11: 4232.2595 | AF11: 4321.5747 | AG11: 0.017140171
B12: Adjusted EBIT (model) | C12: =Model!CO63 -> 1653.054 | D12: =Model!CP63 -> 1710.365 | E12: =Model!CQ63 -> 1836.603 | F12: =Model!CR63 -> 1977.7061 | G12: =Model!CS63 -> 2128.0753 | H12: =Model!CT63 -> 2289.656 | I12: =IFERROR((H12/C12)^(1/5)-1,"n/m") -> 0.067324892 | N12: Adjusted EBIT (model) | O12: 1653.054 | P12: 1826.2515 | Q12: 2006.5667 | R12: 2211.2348 | S12: 2435.4762 | T12: 2682.6752 | U12: 0.10168189 | Z12: Adjusted EBIT (model) | AA12: 1653.054 | AB12: 1555.7161 | AC12: 1613.7962 | AD12: 1679.0094 | AE12: 1745.685 | AF12: 1815.0136 | AG12: 0.018869515
B13: Adjusted EBIT margin % | C13: =IFERROR(C12/C9,"") -> 0.3542606 | D13: =IFERROR(D12/D9,"") -> 0.35 | E13: =IFERROR(E12/E9,"") -> 0.355 | F13: =IFERROR(F12/F9,"") -> 0.36 | G13: =IFERROR(G12/G9,"") -> 0.365 | H13: =IFERROR(H12/H9,"") -> 0.37 | J13: =IFERROR(AVERAGE(Model!C64,Model!D64,Model!E64,Model!F64,Model!G64,Model!H64,Model!I64,Model!O64,Model!U64,Model!AA64,Model!AG64,Model!AM64,Model!AS64,Model!AY64,Model!BE64,Model!BK64,Model!BQ64,Model!BW64,Model!CC64,Model!CI64,Model!CO64),"") -> 0.33690307 | K13: =IFERROR(MIN(Model!C64,Model!D64,Model!E64,Model!F64,Model!G64,Model!H64,Model!I64,Model!O64,Model!U64,Model!AA64,Model!AG64,Model!AM64,Model!AS64,Model!AY64,Model!BE64,Model!BK64,Model!BQ64,Model!BW64,Model!CC64,Model!CI64,Model!CO64),"") -> 0.26421909 | L13: =IFERROR(MAX(Model!C64,Model!D64,Model!E64,Model!F64,Model!G64,Model!H64,Model!I64,Model!O64,Model!U64,Model!AA64,Model!AG64,Model!AM64,Model!AS64,Model!AY64,Model!BE64,Model!BK64,Model!BQ64,Model!BW64,Model!CC64,Model!CI64,Model!CO64),"") -> 0.42551742 | N13: Adjusted EBIT margin % | O13: 0.3542606 | P13: 0.365 | Q13: 0.37 | R13: 0.375 | S13: 0.38 | T13: 0.385 | V13: 0.33690307 | W13: 0.26421909 | X13: 0.42551742 | Z13: Adjusted EBIT margin % | AA13: 0.3542606 | AB13: 0.33 | AC13: 0.335 | AD13: 0.34 | AE13: 0.345 | AF13: 0.35 | AH13: 0.33690307 | AI13: 0.26421909 | AJ13: 0.42551742
B15: Operating Income (GAAP) | C15: =Model!CO81 -> 1652.59 | D15: =Model!CP81 -> 1710.365 | E15: =Model!CQ81 -> 1836.603 | F15: =Model!CR81 -> 1977.7061 | G15: =Model!CS81 -> 2128.0753 | H15: =Model!CT81 -> 2289.656 | I15: =IFERROR((H15/C15)^(1/5)-1,"n/m") -> 0.06738482 | N15: Operating Income (GAAP) | O15: 1652.59 | P15: 1826.2515 | Q15: 2006.5667 | R15: 2211.2348 | S15: 2435.4762 | T15: 2682.6752 | U15: 0.10174375 | Z15: Operating Income (GAAP) | AA15: 1652.59 | AB15: 1555.7161 | AC15: 1613.7962 | AD15: 1679.0094 | AE15: 1745.685 | AF15: 1815.0136 | AG15: 0.018926723
B16: Operating income y/y % | D16: =IFERROR(D15/C15-1,"") -> 0.034960281 | E16: =IFERROR(E15/D15-1,"") -> 0.073807639 | F16: =IFERROR(F15/E15-1,"") -> 0.076828306 | G16: =IFERROR(G15/F15-1,"") -> 0.076032134 | H16: =IFERROR(H15/G15-1,"") -> 0.07592806 | N16: Operating income y/y % | P16: 0.10508442 | Q16: 0.098735195 | R16: 0.10199913 | S16: 0.10141003 | T16: 0.10149924 | Z16: Operating income y/y % | AB16: -0.058619444 | AC16: 0.037333338 | AD16: 0.040409825 | AE16: 0.039711252 | AF16: 0.039714291
B17: Operating margin (GAAP) % | C17: =IFERROR(C15/C9,"") -> 0.35416116 | D17: =IFERROR(D15/D9,"") -> 0.35 | E17: =IFERROR(E15/E9,"") -> 0.355 | F17: =IFERROR(F15/F9,"") -> 0.36 | G17: =IFERROR(G15/G9,"") -> 0.365 | H17: =IFERROR(H15/H9,"") -> 0.37 | J17: =IFERROR(AVERAGE(Model!C171,Model!D171,Model!E171,Model!F171,Model!G171,Model!H171,Model!I171,Model!O171,Model!U171,Model!AA171,Model!AG171,Model!AM171,Model!AS171,Model!AY171,Model!BE171,Model!BK171,Model!BQ171,Model!BW171,Model!CC171,Model!CI171,Model!CO171),"") -> 0.33317515 | K17: =IFERROR(MIN(Model!C171,Model!D171,Model!E171,Model!F171,Model!G171,Model!H171,Model!I171,Model!O171,Model!U171,Model!AA171,Model!AG171,Model!AM171,Model!AS171,Model!AY171,Model!BE171,Model!BK171,Model!BQ171,Model!BW171,Model!CC171,Model!CI171,Model!CO171),"") -> 0.23630133 | L17: =IFERROR(MAX(Model!C171,Model!D171,Model!E171,Model!F171,Model!G171,Model!H171,Model!I171,Model!O171,Model!U171,Model!AA171,Model!AG171,Model!AM171,Model!AS171,Model!AY171,Model!BE171,Model!BK171,Model!BQ171,Model!BW171,Model!CC171,Model!CI171,Model!CO171),"") -> 0.42206921 | N17: Operating margin (GAAP) % | O17: 0.35416116 | P17: 0.365 | Q17: 0.37 | R17: 0.375 | S17: 0.38 | T17: 0.385 | V17: 0.33317515 | W17: 0.23630133 | X17: 0.42206921 | Z17: Operating margin (GAAP) % | AA17: 0.35416116 | AB17: 0.33 | AC17: 0.335 | AD17: 0.34 | AE17: 0.345 | AF17: 0.35 | AH17: 0.33317515 | AI17: 0.23630133 | AJ17: 0.42206921
B19: Net Income (Adjusted, available to common) | C19: =Model!CO148 -> 1484.27 | D19: =Model!CP148 -> 1484.6689 | E19: =Model!CQ148 -> 1561.1087 | F19: =Model!CR148 -> 1680.5499 | G19: =Model!CS148 -> 1808.212 | H19: =Model!CT148 -> 1945.3089 | I19: =IFERROR((H19/C19)^(1/5)-1,"n/m") -> 0.055589677 | N19: Net Income (Adjusted, available to common) | O19: 1484.27 | P19: 1576.7986 | Q19: 1675.6949 | R19: 1844.4514 | S19: 2032.593 | T19: 2239.5364 | U19: 0.085748014 | Z19: Net Income (Adjusted, available to common) | AA19: 1484.27 | AB19: 1361.723 | AC19: 1423.0195 | AD19: 1506.4472 | AE19: 1593.0484 | AF19: 1683.8774 | AG19: 0.02555631
B21: FDSO (m) | C21: =Model!CO98 -> 956.86 | D21: =Model!CP98 -> 901.11248 | E21: =Model!CQ98 -> 853.04856 | F21: =Model!CR98 -> 820.36581 | G21: =Model!CS98 -> 787.59375 | H21: =Model!CT98 -> 754.54046 | I21: =IFERROR((H21/C21)^(1/5)-1,"n/m") -> -0.046398718 | N21: FDSO (m) | O21: 956.86 | P21: 885.95651 | Q21: 820.39624 | R21: 784.28197 | S21: 748.67086 | T21: 711.23182 | U21: -0.057605905 | Z21: FDSO (m) | AA21: 956.86 | AB21: 929.10619 | AC21: 926.10534 | AD21: 927.54077 | AE21: 929.07855 | AF21: 930.71199 | AG21: -0.005526117
B23: Adjusted EPS — Diluted ($) | C23: =Model!CO152 -> 1.5511883 | D23: =Model!CP152 -> 1.6475956 | E23: =Model!CQ152 -> 1.8300349 | F23: =Model!CR152 -> 2.0485373 | G23: =Model!CS152 -> 2.2958689 | H23: =Model!CT152 -> 2.5781373 | I23: =IFERROR((H23/C23)^(1/5)-1,"n/m") -> 0.10695077 | N23: Adjusted EPS — Diluted ($) | O23: 1.5511883 | P23: 1.7797698 | Q23: 2.0425434 | R23: 2.3517708 | S23: 2.7149354 | T23: 3.1488136 | U23: 0.15211674 | Z23: Adjusted EPS — Diluted ($) | AA23: 1.5511883 | AB23: 1.4656269 | AC23: 1.5365634 | AD23: 1.6241304 | AE23: 1.7146542 | AF23: 1.8092357 | AG23: 0.031255147
B24: EPS y/y % | D24: =IFERROR(D23/C23-1,"") -> 0.062150618 | E24: =IFERROR(E23/D23-1,"") -> 0.11073067 | F24: =IFERROR(F23/E23-1,"") -> 0.11939789 | G24: =IFERROR(G23/F23-1,"") -> 0.12073574 | H24: =IFERROR(H23/G23-1,"") -> 0.12294623 | N24: EPS y/y % | P24: 0.147359 | Q24: 0.14764471 | R24: 0.15139332 | S24: 0.15442177 | T24: 0.15981158 | Z24: EPS y/y % | AB24: -0.055158581 | AC24: 0.048400062 | AD24: 0.056988897 | AE24: 0.05573677 | AF24: 0.055160709
B26: P / E (x) — assumed (adjusted EPS) | G26: 20 | H26: 20 | N26: P / E (x) — assumed (adjusted EPS) | S26: 20 | T26: 20 | Z26: P / E (x) — assumed (adjusted EPS) | AE26: 20 | AF26: 20
B27: Price Target ($) | G27: =G26*G23 -> 45.917378 | H27: =H26*H23 -> 51.562747 | N27: Price Target ($) | S27: 54.298709 | T27: 62.976271 | Z27: Price Target ($) | AE27: 34.293084 | AF27: 36.184714
B28: Upside / (Downside) vs current | G28: =IFERROR(G27/$K$2-1,"") -> 0.70064364 | H28: =IFERROR(H27/$K$2-1,"") -> 0.90973137 | N28: Upside / (Downside) vs current | S28: 1.0110633 | T28: 1.3324545 | Z28: Upside / (Downside) vs current | AE28: 0.27011421 | AF28: 0.34017461
B29: IRR (to Jul of FY−1) | G29: =IFERROR((G27/$K$2)^(1/((DATE(2029,7,31)-$K$3)/365.25))-1,"") -> 0.20675661 | H29: =IFERROR((H27/$K$2)^(1/((DATE(2030,7,31)-$K$3)/365.25))-1,"") -> 0.18429822 | N29: IRR (to Jul of FY−1) | S29: 0.28053006 | T29: 0.24786011 | Z29: IRR (to Jul of FY−1) | AE29: 0.088309685 | AF29: 0.07955989
B31: Free Cash Flow | C31: =Model!CO213 -> 1279.704 | D31: =Model!CP213 -> 1312.0802 | E31: =Model!CQ213 -> 1361.4597 | F31: =Model!CR213 -> 1467.0347 | G31: =Model!CS213 -> 1581.1973 | H31: =Model!CT213 -> 1703.7374 | I31: =IFERROR((H31/C31)^(1/5)-1,"n/m") -> 0.058908973 | N31: Free Cash Flow | O31: 1279.704 | P31: 1393.0205 | Q31: 1458.9782 | R31: 1606.9907 | S31: 1773.8066 | T31: 1957.2795 | U31: 0.088701108 | Z31: Free Cash Flow | AA31: 1279.704 | AB31: 1205.6747 | AC31: 1247.3755 | AD31: 1325.2107 | AE31: 1407.2039 | AF31: 1493.0717 | AG31: 0.031321869
B32: FCF % | C32: =IFERROR(C31/C9,"") -> 0.27424918 | D32: =IFERROR(D31/D9,"") -> 0.26849712 | E32: =IFERROR(E31/E9,"") -> 0.26315876 | F32: =IFERROR(F31/F9,"") -> 0.26704295 | G32: =IFERROR(G31/G9,"") -> 0.2712014 | H32: =IFERROR(H31/H9,"") -> 0.27531772 | J32: =IFERROR(AVERAGE(Model!C215,Model!D215,Model!E215,Model!F215,Model!G215,Model!H215,Model!I215,Model!O215,Model!U215,Model!AA215,Model!AG215,Model!AM215,Model!AS215,Model!AY215,Model!BE215,Model!BK215,Model!BQ215,Model!BW215,Model!CC215,Model!CI215,Model!CO215),"") -> 0.18143094 | K32: =IFERROR(MIN(Model!C215,Model!D215,Model!E215,Model!F215,Model!G215,Model!H215,Model!I215,Model!O215,Model!U215,Model!AA215,Model!AG215,Model!AM215,Model!AS215,Model!AY215,Model!BE215,Model!BK215,Model!BQ215,Model!BW215,Model!CC215,Model!CI215,Model!CO215),"") -> 0.068940143 | L32: =IFERROR(MAX(Model!C215,Model!D215,Model!E215,Model!F215,Model!G215,Model!H215,Model!I215,Model!O215,Model!U215,Model!AA215,Model!AG215,Model!AM215,Model!AS215,Model!AY215,Model!BE215,Model!BK215,Model!BQ215,Model!BW215,Model!CC215,Model!CI215,Model!CO215),"") -> 0.27424918 | N32: FCF % | O32: 0.27424918 | P32: 0.27841319 | Q32: 0.26902766 | R32: 0.27252715 | S32: 0.27676169 | T32: 0.28089596 | V32: 0.18143094 | W32: 0.068940143 | X32: 0.27424918 | Z32: FCF % | AA32: 0.27424918 | AB32: 0.25574889 | AC32: 0.25893653 | AD32: 0.26835564 | AE32: 0.27810594 | AF32: 0.28791801 | AH32: 0.18143094 | AI32: 0.068940143 | AJ32: 0.27424918
B33: FCF / share ($) | C33: =IFERROR(C31/C21,"") -> 1.3373994 | D33: =IFERROR(D31/D21,"") -> 1.4560671 | E33: =IFERROR(E31/E21,"") -> 1.5959932 | F33: =IFERROR(F31/F21,"") -> 1.7882689 | G33: =IFERROR(G31/G21,"") -> 2.0076305 | H33: =IFERROR(H31/H21,"") -> 2.2579802 | N33: FCF / share ($) | O33: 1.3373994 | P33: 1.5723351 | Q33: 1.7783824 | R33: 2.0489961 | S33: 2.3692743 | T33: 2.7519572 | Z33: FCF / share ($) | AA33: 1.3373994 | AB33: 1.2976716 | AC33: 1.3469045 | AD33: 1.4287358 | AE33: 1.5146232 | AF33: 1.6042253
B34: FCF Yield (on PT) | E34: =IFERROR(E33/E$27,"") | F34: =IFERROR(F33/F$27,"") | G34: =IFERROR(G33/G$27,"") -> 0.043722674 | H34: =IFERROR(H33/H$27,"") -> 0.043790922 | N34: FCF Yield (on PT) | Q34: =IFERROR(Q33/Q$27,"") | R34: =IFERROR(R33/R$27,"") | S34: 0.043634081 | T34: 0.043698319 | Z34: FCF Yield (on PT) | AC34: =IFERROR(AC33/AC$27,"") | AD34: =IFERROR(AD33/AD$27,"") | AE34: 0.044167017 | AF34: 0.044334335
B35: Adjusted EBITDA | C35: =Model!CO58 -> 1882.427 | D35: =Model!CP58 -> 1954.7029 | E35: =Model!CQ58 -> 2095.2795 | F35: =Model!CR58 -> 2252.3875 | G35: =Model!CS58 -> 2419.5925 | H35: =Model!CT58 -> 2599.0689 | I35: =IFERROR((H35/C35)^(1/5)-1,"n/m") -> 0.066645071 | N35: Adjusted EBITDA | O35: 1882.427 | P35: 2076.4229 | Q35: 2277.7244 | R35: 2506.0661 | S35: 2755.9336 | T35: 3031.0745 | U35: 0.099956967 | Z35: Adjusted EBITDA | AA35: 1882.427 | AB35: 1791.4307 | AC35: 1854.6613 | AD35: 1925.9225 | AE35: 1998.6828 | AF35: 2074.3012 | AG35: 0.019602137
B36: Adjusted EBITDA margin % | C36: =IFERROR(C35/C9,"") -> 0.40341678 | D36: =IFERROR(D35/D9,"") -> 0.4 | E36: =IFERROR(E35/E9,"") -> 0.405 | F36: =IFERROR(F35/F9,"") -> 0.41 | G36: =IFERROR(G35/G9,"") -> 0.415 | H36: =IFERROR(H35/H9,"") -> 0.42 | J36: =IFERROR(AVERAGE(Model!C170,Model!D170,Model!E170,Model!F170,Model!G170,Model!H170,Model!I170,Model!O170,Model!U170,Model!AA170,Model!AG170,Model!AM170,Model!AS170,Model!AY170,Model!BE170,Model!BK170,Model!BQ170,Model!BW170,Model!CC170,Model!CI170,Model!CO170),"") -> 0.38511197 | K36: =IFERROR(MIN(Model!C170,Model!D170,Model!E170,Model!F170,Model!G170,Model!H170,Model!I170,Model!O170,Model!U170,Model!AA170,Model!AG170,Model!AM170,Model!AS170,Model!AY170,Model!BE170,Model!BK170,Model!BQ170,Model!BW170,Model!CC170,Model!CI170,Model!CO170),"") -> 0.31039571 | L36: =IFERROR(MAX(Model!C170,Model!D170,Model!E170,Model!F170,Model!G170,Model!H170,Model!I170,Model!O170,Model!U170,Model!AA170,Model!AG170,Model!AM170,Model!AS170,Model!AY170,Model!BE170,Model!BK170,Model!BQ170,Model!BW170,Model!CC170,Model!CI170,Model!CO170),"") -> 0.47081751 | N36: Adjusted EBITDA margin % | O36: 0.40341678 | P36: 0.415 | Q36: 0.42 | R36: 0.425 | S36: 0.43 | T36: 0.435 | V36: 0.38511197 | W36: 0.31039571 | X36: 0.47081751 | Z36: Adjusted EBITDA margin % | AA36: 0.40341678 | AB36: 0.38 | AC36: 0.385 | AD36: 0.39 | AE36: 0.395 | AF36: 0.4 | AH36: 0.38511197 | AI36: 0.31039571 | AJ36: 0.47081751
B38: Net Debt (negative = net cash) | C38: =Model!CO318 -> -4489.802 | D38: =Model!CP318 -> -3909.4057 | E38: =Model!CQ318 -> -4190.559 | F38: =Model!CR318 -> -4504.775 | G38: =Model!CS318 -> -4839.185 | H38: =Model!CT318 -> -5198.1379 | N38: Net Debt (negative = net cash) | O38: -4489.802 | P38: -3114.6343 | Q38: -3348.6126 | R38: -3730.6033 | S38: -4133.9004 | T38: -4546.6118 | Z38: Net Debt (negative = net cash) | AA38: -4489.802 | AB38: -5420.4767 | AC38: -6642.8522 | AD38: -7943.0629 | AE38: -9325.2668 | AF38: -10793.339
B39: Net Debt / Adjusted EBITDA (x) | C39: =IFERROR(C38/C35,"") -> -2.3851135 | D39: =IFERROR(D38/D35,"") -> -2 | E39: =IFERROR(E38/E35,"") -> -2 | F39: =IFERROR(F38/F35,"") -> -2 | G39: =IFERROR(G38/G35,"") -> -2 | H39: =IFERROR(H38/H35,"") -> -2 | N39: Net Debt / Adjusted EBITDA (x) | O39: -2.3851135 | P39: -1.5 | Q39: -1.470157 | R39: -1.4886292 | S39: -1.5 | T39: -1.5 | Z39: Net Debt / Adjusted EBITDA (x) | AA39: -2.3851135 | AB39: -3.0257809 | AC39: -3.5817064 | AD39: -4.1242899 | AE39: -4.6657063 | AF39: -5.2033611
B41: ROIC | C41: =Model!CO319 -> 0.28840943 | D41: =Model!CP319 -> 0.28118434 | E41: =Model!CQ319 -> 0.28760242 | F41: =Model!CR319 -> 0.29475048 | G41: =Model!CS319 -> 0.30168404 | H41: =Model!CT319 -> 0.30857388 | J41: =IFERROR(AVERAGE(Model!C319,Model!D319,Model!E319,Model!F319,Model!G319,Model!H319,Model!I319,Model!O319,Model!U319,Model!AA319,Model!AG319,Model!AM319,Model!AS319,Model!AY319,Model!BE319,Model!BK319,Model!BQ319,Model!BW319,Model!CC319,Model!CI319,Model!CO319),"") -> 0.24810352 | K41: =IFERROR(MIN(Model!C319,Model!D319,Model!E319,Model!F319,Model!G319,Model!H319,Model!I319,Model!O319,Model!U319,Model!AA319,Model!AG319,Model!AM319,Model!AS319,Model!AY319,Model!BE319,Model!BK319,Model!BQ319,Model!BW319,Model!CC319,Model!CI319,Model!CO319),"") -> 0.17040746 | L41: =IFERROR(MAX(Model!C319,Model!D319,Model!E319,Model!F319,Model!G319,Model!H319,Model!I319,Model!O319,Model!U319,Model!AA319,Model!AG319,Model!AM319,Model!AS319,Model!AY319,Model!BE319,Model!BK319,Model!BQ319,Model!BW319,Model!CC319,Model!CI319,Model!CO319),"") -> 0.3461967 | N41: ROIC | O41: 0.28840943 | P41: 0.29948531 | Q41: 0.31229935 | R41: 0.32598847 | S41: 0.33952527 | T41: 0.35306073 | V41: 0.24810352 | W41: 0.17040746 | X41: 0.3461967 | Z41: ROIC | AA41: 0.28840943 | AB41: 0.25671133 | AC41: 0.25496067 | AD41: 0.25411613 | AE41: 0.25329381 | AF41: 0.25264217 | AH41: 0.24810352 | AI41: 0.17040746 | AJ41: 0.3461967
B42: RONTA | C42: =Model!CO331 -> 0.15220073 | D42: =Model!CP331 -> 0.16157412 | E42: =Model!CQ331 -> 0.16297986 | F42: =Model!CR331 -> 0.16464571 | G42: =Model!CS331 -> 0.16628007 | H42: =Model!CT331 -> 0.16792915 | J42: =IFERROR(AVERAGE(Model!C331,Model!D331,Model!E331,Model!F331,Model!G331,Model!H331,Model!I331,Model!O331,Model!U331,Model!AA331,Model!AG331,Model!AM331,Model!AS331,Model!AY331,Model!BE331,Model!BK331,Model!BQ331,Model!BW331,Model!CC331,Model!CI331,Model!CO331),"") -> 0.21732716 | K42: =IFERROR(MIN(Model!C331,Model!D331,Model!E331,Model!F331,Model!G331,Model!H331,Model!I331,Model!O331,Model!U331,Model!AA331,Model!AG331,Model!AM331,Model!AS331,Model!AY331,Model!BE331,Model!BK331,Model!BQ331,Model!BW331,Model!CC331,Model!CI331,Model!CO331),"") -> 0.15220073 | L42: =IFERROR(MAX(Model!C331,Model!D331,Model!E331,Model!F331,Model!G331,Model!H331,Model!I331,Model!O331,Model!U331,Model!AA331,Model!AG331,Model!AM331,Model!AS331,Model!AY331,Model!BE331,Model!BK331,Model!BQ331,Model!BW331,Model!CC331,Model!CI331,Model!CO331),"") -> 0.32455213 | N42: RONTA | O42: 0.15220073 | P42: 0.19021128 | Q42: 0.19578032 | R42: 0.19900428 | S42: 0.20244717 | T42: 0.20646538 | V42: 0.21732716 | W42: 0.15220073 | X42: 0.32455213 | Z42: RONTA | AA42: 0.15220073 | AB42: 0.12481862 | AC42: 0.11287482 | AD42: 0.10342378 | AE42: 0.095502432 | AF42: 0.088811708 | AH42: 0.21732716 | AI42: 0.15220073 | AJ42: 0.32455213
B44: Implied Market Cap (USDm) | H44: =H27*H21 -> 38906.179 | N44: Implied Market Cap (USDm) | T44: 44790.728 | Z44: Implied Market Cap (USDm) | AF44: 33677.548
B45: (+) Net debt (net cash) & NCI | H45: =H38+Model!CT348 -> -5181.5529 | N45: (+) Net debt (net cash) & NCI | T45: -4530.0268 | Z45: (+) Net debt (net cash) & NCI | AF45: -10776.754
B46: Implied Enterprise Value (USDm) | H46: =H44+H45 -> 33724.626 | N46: Implied Enterprise Value (USDm) | T46: 40260.701 | Z46: Implied Enterprise Value (USDm) | AF46: 22900.794
B47: Implied EV / Adjusted EBITDA (x) | H47: =IFERROR(H46/H35,"") -> 12.975657 | N47: Implied EV / Adjusted EBITDA (x) | T47: 13.28265 | Z47: Implied EV / Adjusted EBITDA (x) | AF47: 11.040245
B49: 2031E Price Target — P/E Sensitivity | N49: 2031E Price Target — P/E Sensitivity | Z49: 2031E Price Target — P/E Sensitivity
B50: P/E step (x) | C50: 2 | N50: P/E step (x) | O50: 2 | Z50: P/E step (x) | AA50: 2
B51: P / E (x) | D51: =E51-$C$50 -> 16 | E51: =F51-$C$50 -> 18 | F51: =$H$26 -> 20 | G51: =F51+$C$50 -> 22 | H51: =G51+$C$50 -> 24 | N51: P / E (x) | P51: 16 | Q51: 18 | R51: 20 | S51: 22 | T51: 24 | Z51: P / E (x) | AB51: 16 | AC51: 18 | AD51: 20 | AE51: 22 | AF51: 24
B52: 2031E Price Target ($) | D52: =D51*$H$23 -> 41.250198 | E52: =E51*$H$23 -> 46.406472 | F52: =F51*$H$23 -> 51.562747 | G52: =G51*$H$23 -> 56.719022 | H52: =H51*$H$23 -> 61.875296 | N52: 2031E Price Target ($) | P52: 50.381017 | Q52: 56.678644 | R52: 62.976271 | S52: 69.273898 | T52: 75.571526 | Z52: 2031E Price Target ($) | AB52: 28.947772 | AC52: 32.566243 | AD52: 36.184714 | AE52: 39.803186 | AF52: 43.421657
B53: Upside / (Downside) vs current | D53: =IFERROR(D52/$K$2-1,"") -> 0.52778509 | E53: =IFERROR(E52/$K$2-1,"") -> 0.71875823 | F53: =IFERROR(F52/$K$2-1,"") -> 0.90973137 | G53: =IFERROR(G52/$K$2-1,"") -> 1.1007045 | H53: =IFERROR(H52/$K$2-1,"") -> 1.2916776 | N53: Upside / (Downside) vs current | P53: 0.86596359 | Q53: 1.099209 | R53: 1.3324545 | S53: 1.5656999 | T53: 1.7989454 | Z53: Upside / (Downside) vs current | AB53: 0.072139689 | AC53: 0.20615715 | AD53: 0.34017461 | AE53: 0.47419207 | AF53: 0.60820953
B54: IRR (to Jul-2030) | D54: =IFERROR((D52/$K$2)^(1/((DATE(2030,7,31)-$K$3)/365.25))-1,"") -> 0.11718129 | E54: =IFERROR((E52/$K$2)^(1/((DATE(2030,7,31)-$K$3)/365.25))-1,"") -> 0.1521198 | F54: =IFERROR((F52/$K$2)^(1/((DATE(2030,7,31)-$K$3)/365.25))-1,"") -> 0.18429822 | G54: =IFERROR((G52/$K$2)^(1/((DATE(2030,7,31)-$K$3)/365.25))-1,"") -> 0.2141807 | H54: =IFERROR((H52/$K$2)^(1/((DATE(2030,7,31)-$K$3)/365.25))-1,"") -> 0.24211916 | N54: IRR (to Jul-2030) | P54: 0.17714097 | Q54: 0.21395465 | R54: 0.24786011 | S54: 0.27934639 | T54: 0.30878432 | Z54: IRR (to Jul-2030) | AB54: 0.01837872 | AC54: 0.050227297 | AD54: 0.07955989 | AE54: 0.10679958 | AF54: 0.13226719

Sheet DCF
B2: DCF VALUATION — COPART, INC. (CPRT)
B4: 1. WACC BUILD
B5: Risk-free rate (US 10Y govt) | C5: 0.055 | D5: Assumption (~US 10Y Treasury yield); update to market
B6: Equity risk premium | C6: 0.055 | D6: Damodaran-style US ERP estimate
B7: Levered beta | C7: 1 | D7: Online salvage-auction duopoly (with RB Global / IAA); defensive insurance-driven volumes, net-cash balance sheet
B8: Cost of equity | C8: =C5+C7*C6 -> 0.11
B9: Pre-tax cost of debt | C9: 0.055 | D9: No funded debt since May-2022 (senior notes redeemed); undrawn revolver — notional cost if levered
B10: Tax rate | C10: 0.205 | D10: Model effective tax rate (FY2026 19.3%; FY2025 18.3%)
B11: After-tax cost of debt | C11: =C9*(1-C10) -> 0.043725
B12: Target D/V | C12: 0 | D12: Debt-free capital structure (net cash $4.5bn incl. HTM Treasuries at FY2026)
B13: WACC | C13: =C8*(1-C12)+C11*C12 -> 0.11
B15: Valuation date (live) | C15: =TODAY() -> 46298 | D15: Periods = (31-Jul-FY − today) / 365.25; cash flows assumed at fiscal year-end
B16: 2. UNLEVERED FREE CASH FLOW BUILD (USDm)
D17: 2027E | E17: 2028E | F17: 2029E | G17: 2030E | H17: 2031E | I17: 2032E | J17: 2033E | K17: 2034E | L17: 2035E | M17: 2036E | N17: Terminal
B18: Adjusted EBIT (Model) | D18: =Model!CP63 -> 1710.365 | E18: =Model!CQ63 -> 1836.603 | F18: =Model!CR63 -> 1977.7061 | G18: =Model!CS63 -> 2128.0753 | H18: =Model!CT63 -> 2289.656 | I18: =H18*(1+I$29) -> 2427.0353 | J18: =I18*(1+J$29) -> 2560.5223 | K18: =J18*(1+K$29) -> 2688.5484 | L18: =K18*(1+L$29) -> 2809.5331 | M18: =L18*(1+M$29) -> 2921.9144
B19: (−) Stock-based compensation (economic cost) | D19: =-Model!CP103 -> -39.094057 | E19: =-Model!CQ103 -> -41.388237 | F19: =-Model!CR103 -> -43.949025 | G19: =-Model!CS103 -> -46.642747 | H19: =-Model!CT103 -> -49.506075 | I19: =H19*(1+I$29) -> -52.476439 | J19: =I19*(1+J$29) -> -55.362644 | K19: =J19*(1+K$29) -> -58.130776 | L19: =K19*(1+L$29) -> -60.746661 | M19: =L19*(1+M$29) -> -63.176527
B20: × (1 − tax rate) | D20: =1-$C$10 -> 0.795 | E20: =1-$C$10 -> 0.795 | F20: =1-$C$10 -> 0.795 | G20: =1-$C$10 -> 0.795 | H20: =1-$C$10 -> 0.795 | I20: =1-$C$10 -> 0.795 | J20: =1-$C$10 -> 0.795 | K20: =1-$C$10 -> 0.795 | ... M20: =1-$C$10 -> 0.795
B21: NOPAT = (Adj. EBIT − SBC) × (1 − t) | D21: =(D18+D19)*D20 -> 1328.6604 | E21: =(E18+E19)*E20 -> 1427.1957 | F21: =(F18+F19)*F20 -> 1537.3369 | G21: =(G18+G19)*G20 -> 1654.7389 | H21: =(H18+H19)*H20 -> 1780.9192 | I21: =(I18+I19)*I20 -> 1887.7743 | J21: =(J18+J19)*J20 -> 1991.6019 | K21: =(K18+K19)*K20 -> 2091.182 | ... M21: =(M18+M19)*M20 -> 2272.6966
B22: plus D&A (owned-yard depreciation; minimal acquired-intangible amortization) | D22: =Model!CP102 -> 244.33786 | E22: =Model!CQ102 -> 258.67648 | F22: =Model!CR102 -> 274.6814 | G22: =Model!CS102 -> 291.51717 | H22: =Model!CT102 -> 309.41297 | I22: =H22*(1+I$29) -> 327.97775 | J22: =I22*(1+J$29) -> 346.01652 | K22: =J22*(1+K$29) -> 363.31735 | L22: =K22*(1+L$29) -> 379.66663 | M22: =L22*(1+M$29) -> 394.85329
B23: − Capex (purchases of property & equipment, net of disposal proceeds) | D23: =Model!CP190+0+Model!CP191 -> -464.24193 | E23: =Model!CQ190+0+Model!CQ191 -> -491.48531 | F23: =Model!CR190+0+Model!CR191 -> -521.89467 | G23: =Model!CS190+0+Model!CS191 -> -553.88262 | H23: =Model!CT190+0+Model!CT191 -> -587.88464 | I23: =H23*(1+I$29) -> -623.15772 | J23: =I23*(1+J$29) -> -657.43139 | K23: =J23*(1+K$29) -> -690.30296 | L23: =K23*(1+L$29) -> -721.36659 | M23: =L23*(1+M$29) -> -750.22126
B24: − Δ Working capital (CF statement) | D24: =Model!CP188 -> -1.7786899 | E24: =Model!CQ188 -> -18.228411 | F24: =Model!CR188 -> -20.251013 | G24: =Model!CS188 -> -21.292037 | H24: =Model!CT188 -> -22.605886 | I24: =H24*(1+I$29) -> -23.962239 | J24: =I24*(1+J$29) -> -25.280163 | K24: =J24*(1+K$29) -> -26.544171 | L24: =K24*(1+L$29) -> -27.738658 | M24: =L24*(1+M$29) -> -28.848205
