Workbook

Sheet Cover
B2: COPART, INC.
B3: SEC-Filings 3-Statement Financial Model — 15-Year History + 5-Year Forecast
B5: Ticker / Exchange | C5: CPRT · Nasdaq
B6: SEC CIK | C6: 0000900075
B7: Fiscal year end | C7: July 31
B8: Currency / units | C8: US$ millions (except per-share and share counts)
B9: Data source | C9: SEC EDGAR — Forms 10-K & 10-Q, XBRL (data.sec.gov). No non-SEC inputs except the manual valuation share price.
B10: Reported segments | C10: United States · International
B11: Historical coverage | C11: FY2011–FY2025 (fiscal-year ends + Q1–Q4)
B12: Forecast | C12: FY2026E–FY2030E (driver-based, scenario toggle)
B14: Worksheets
B15: Model | C15: Full model — segment P&L, income statement, cash flow, balance sheet, ratios, non-GAAP reconciliation (8-K), valuation; historicals (formulas) + FY26E–30E estimates.
B16: Bull / Base / Bear | C16: Scenario P&L summary linked to the Model scenario toggle.
B17: DCF | C17: Unlevered DCF built off the model's forecast free cash flow.
B19: Colour key: blue = as-reported figure taken directly from Copart's SEC filings; black = live Excel formula; pale-yellow columns = forecast years driven by the Assumptions / scenario table on the Model tab. Segment operating income is reported by Copart from ~FY2016 (two reportable segments); earlier years reflect geographic revenue disclosure as filed. For research/education only — not investment advice.

Sheet Model
B2: COPART, INC. (CPRT) — SEC-Filings 3-Statement Model | CE2: Scenario: | CF2: Base
B3: US GAAP as reported · US$ millions · FYE July 31 · Source: SEC EDGAR Forms 10-K & 10-Q (data.sec.gov XBRL), CIK 0000900075
B4: Blue = as-reported input from SEC filings · Black = formula · Yellow columns = forecast (driven by Assumptions / scenario toggle).
CK5: SCENARIO / ASSUMPTIONS TABLE
B6: (US$ in millions) | C6: Q1 11 | D6: Q2 11 | E6: Q3 11 | F6: Q4 11 | G6: FY2011 | H6: Q1 12 | I6: Q2 12 | J6: Q3 12 | K6: Q4 12 | L6: FY2012 | M6: Q1 13 | N6: Q2 13 | O6: Q3 13 | P6: Q4 13 | Q6: FY2013 | R6: Q1 14 | S6: Q2 14 | T6: Q3 14 | U6: Q4 14 | V6: FY2014 | W6: Q1 15 | X6: Q2 15 | Y6: Q3 15 | Z6: Q4 15 | AA6: FY2015 | AB6: Q1 16 | AC6: Q2 16 | AD6: Q3 16 | AE6: Q4 16 | AF6: FY2016 | AG6: Q1 17 | AH6: Q2 17 | AI6: Q3 17 | AJ6: Q4 17 | AK6: FY2017 | AL6: Q1 18 | AM6: Q2 18 | AN6: Q3 18 | AO6: Q4 18 | AP6: FY2018 | AQ6: Q1 19 | AR6: Q2 19 | AS6: Q3 19 | AT6: Q4 19 | AU6: FY2019 | AV6: Q1 20 | AW6: Q2 20 | AX6: Q3 20 | AY6: Q4 20 | AZ6: FY2020 | BA6: Q1 21 | BB6: Q2 21 | BC6: Q3 21 | BD6: Q4 21 | BE6: FY2021 | BF6: Q1 22 | BG6: Q2 22 | BH6: Q3 22 | BI6: Q4 22 | BJ6: FY2022 | BK6: Q1 23 | BL6: Q2 23 | BM6: Q3 23 | BN6: Q4 23 | BO6: FY2023 | BP6: Q1 24 | BQ6: Q2 24 | BR6: Q3 24 | BS6: Q4 24 | BT6: FY2024 | BU6: Q1 25 | BV6: Q2 25 | BW6: Q3 25 | BX6: Q4 25 | BY6: FY2025 | BZ6: FY2026E | CA6: FY2027E | CB6: FY2028E | CC6: FY2029E | CD6: FY2030E | CE6: Modelling Notes | CF6: 5Y CAGR (fwd) | CG6: 5Y CAGR (hist) | CH6: 10Y CAGR | CK6: Driver | CL6: Bull | CM6: Base | CN6: Bear
CK7: Revenue growth — US | CL7: 0.14 | CM7: 0.1 | CN7: 0.04
B8: SEGMENT P&L — BY REPORTABLE SEGMENT (US & INTERNATIONAL) | CK8: Revenue growth — International | CL8: 0.16 | CM8: 0.11 | CN8: 0.04
B9: United States | CK9: Operating margin — US | CL9: 0.4 | CM9: 0.385 | CN9: 0.35
B10: Revenue | L10: 724.869 | Q10: 826.03 | V10: 904 | AA10: 914.443 | AF10: 1016.036 | AG10: 285.062 | AH10: 286.911 | AI10: 307.12 | AJ10: 314.095 | AK10: 1193.188 | AL10: 351.105 | AM10: 385.135 | AN10: 385.281 | AO10: 369.501 | AP10: 1491.022 | AQ10: 371.209 | AR10: 390.072 | AS10: 448.199 | AT10: 447.089 | AU10: 1656.569 | AV10: 464.164 | AW10: 482.737 | AX10: 467.198 | AY10: 446.587 | AZ10: 1860.686 | BA10: 497.255 | BB10: 517.923 | BC10: 621.953 | BD10: 634.941 | BE10: 2272.072 | BF10: 678.461 | BG10: 727.386 | BH10: 790.25 | BI10: 749.053 | BJ10: 2945.15 | BK10: 748.849 | BL10: 787.929 | BM10: 833.758 | BN10: 819.112 | BO10: 3189.648 | BP10: 840.906 | BQ10: 830.726 | BR10: 918.916 | BS10: 874.187 | BT10: 3464.735 | BU10: 947.539 | BV10: 974.845 | BW10: 1006.457 | BX10: 926.263 | BY10: 3855.104 | BZ10: =BY10*(1+CHOOSE(MATCH($CF$2,{"Bull","Base","Bear"},0),$CL$7,$CM$7,$CN$7)) | CA10: =BZ10*(1+CHOOSE(MATCH($CF$2,{"Bull","Base","Bear"},0),$CL$7,$CM$7,$CN$7)) | CB10: =CA10*(1+CHOOSE(MATCH($CF$2,{"Bull","Base","Bear"},0),$CL$7,$CM$7,$CN$7)) | CC10: =CB10*(1+CHOOSE(MATCH($CF$2,{"Bull","Base","Bear"},0),$CL$7,$CM$7,$CN$7)) | CD10: =CC10*(1+CHOOSE(MATCH($CF$2,{"Bull","Base","Bear"},0),$CL$7,$CM$7,$CN$7)) | CF10: =IFERROR((CD10/BY10)^(1/5)-1,"n/m") | CG10: =IFERROR((BY10/AZ10)^(1/5)-1,"n/m") | CH10: =IFERROR((BY10/G10)^(1/14)-1,"n/m") | CK10: Operating margin — International | CL10: 0.3 | CM10: 0.27 | CN10: 0.22
B11: Operating income | AF11: 347.709 | AG11: 88.982 | AH11: 93.592 | AI11: 119.117 | AJ11: 94.669 | AK11: 396.36 | AL11: 106.019 | AM11: 133.01 | AN11: 150.888 | AO11: 124.97 | AP11: 514.887 | AQ11: 130.292 | AR11: 145.402 | AS11: 188.258 | AT11: 176.842 | AU11: 640.794 | AV11: 189.05 | AW11: 190.085 | AX11: 180.687 | AY11: 188.955 | AZ11: 748.777 | BA11: 223.239 | BB11: 229.452 | BC11: 296.726 | BD11: 274.138 | BE11: 1023.555 | BF11: 294.949 | BG11: 312.646 | BH11: 340.437 | BI11: 299.537 | BJ11: 1247.569 | BK11: 282.628 | BL11: 336.164 | BM11: 384.791 | BN11: 364.514 | BO11: 1368.097 | BP11: 362.291 | BQ11: 347.338 | BR11: 392.931 | BS11: 325.474 | BT11: 1428.034 | BU11: 355.059 | BV11: 375.893 | BW11: 392.465 | BX11: 357.469 | BY11: 1480.886 | BZ11: =BZ10*CHOOSE(MATCH($CF$2,{"Bull","Base","Bear"},0),$CL$9,$CM$9,$CN$9) | CA11: =CA10*CHOOSE(MATCH($CF$2,{"Bull","Base","Bear"},0),$CL$9,$CM$9,$CN$9) | CB11: =CB10*CHOOSE(MATCH($CF$2,{"Bull","Base","Bear"},0),$CL$9,$CM$9,$CN$9) | CC11: =CC10*CHOOSE(MATCH($CF$2,{"Bull","Base","Bear"},0),$CL$9,$CM$9,$CN$9) | CD11: =CD10*CHOOSE(MATCH($CF$2,{"Bull","Base","Bear"},0),$CL$9,$CM$9,$CN$9) | CF11: =IFERROR((CD11/BY11)^(1/5)-1,"n/m") | CG11: =IFERROR((BY11/AZ11)^(1/5)-1,"n/m") | CH11: =IFERROR((BY11/G11)^(1/14)-1,"n/m") | CK11: Other income % of revenue | CL11: 0.02 | CM11: 0.015 | CN11: 0.01
B12: Operating margin % | C12: =IFERROR(C11/C10,"") | D12: =IFERROR(D11/D10,"") | E12: =IFERROR(E11/E10,"") | F12: =IFERROR(F11/F10,"") | G12: =IFERROR(G11/G10,"") | H12: =IFERROR(H11/H10,"") | I12: =IFERROR(I11/I10,"") | J12: =IFERROR(J11/J10,"") | ... CD12: =IFERROR(CD11/CD10,"") | CK12: Effective tax rate | CL12: 0.22 | CM12: 0.23 | CN12: 0.25
B13: Revenue y/y % | L13: =IFERROR(L10/G10-1,"") | Q13: =IFERROR(Q10/L10-1,"") | V13: =IFERROR(V10/Q10-1,"") | AA13: =IFERROR(AA10/V10-1,"") | AF13: =IFERROR(AF10/AA10-1,"") | AK13: =IFERROR(AK10/AF10-1,"") | AP13: =IFERROR(AP10/AK10-1,"") | AU13: =IFERROR(AU10/AP10-1,"") | AZ13: =IFERROR(AZ10/AU10-1,"") | BE13: =IFERROR(BE10/AZ10-1,"") | BJ13: =IFERROR(BJ10/BE10-1,"") | BO13: =IFERROR(BO10/BJ10-1,"") | BT13: =IFERROR(BT10/BO10-1,"") | BY13: =IFERROR(BY10/BT10-1,"") | BZ13: =IFERROR(BZ10/BY10-1,"") | CA13: =IFERROR(CA10/BZ10-1,"") | CB13: =IFERROR(CB10/CA10-1,"") | CC13: =IFERROR(CC10/CB10-1,"") | CD13: =IFERROR(CD10/CC10-1,"") | CK13: D&A % of revenue | CL13: 0.045 | CM13: 0.05 | CN13: 0.055
B14: Depreciation & amortisation | AF14: 39.083 | AG14: 12.386 | AH14: 12.667 | AI14: 10.904 | AJ14: 11.55 | AK14: 47.507 | AL14: 13.529 | AM14: 14.054 | AN14: 14.189 | AO14: 26.007 | AP14: 67.779 | AQ14: 19.392 | AR14: 17.877 | AS14: 18.636 | AT14: 19.23 | AU14: 75.135 | AV14: 20.567 | AW14: 21.698 | AX14: 23.703 | AY14: 24.667 | AZ14: 90.635 | BA14: 26.105 | BB14: 27.745 | BC14: 28.161 | BD14: 25.754 | BE14: 107.765 | BF14: 27.725 | BG14: 29.316 | BH14: 31.609 | BI14: 31.985 | BJ14: 120.635 | BK14: 34.935 | BL14: 34.121 | BM14: 32.918 | BN14: 33.83 | BO14: 135.804 | BP14: 36.936 | BQ14: 38.344 | BR14: 43.477 | BS14: 42.928 | BT14: 161.685 | BU14: 45.915 | BV14: 46.455 | BW14: 46.461 | BX14: 45.195 | BY14: 184.026 | CK14: Stock-based comp % of revenue | CL14: 0.006 | CM14: 0.007 | CN14: 0.008
B15: Capital expenditures | AF15: 153.451 | AG15: 36.521 | AH15: 51.541 | AI15: 40.872 | AJ15: 188.712 | AK15: 317.646 | AL15: 38.905 | AM15: 56.804 | AN15: 57.028 | AO15: 103.131 | AP15: 255.868 | AQ15: 35.253 | AR15: 66.901 | AS15: 107.569 | AT15: 101.749 | AU15: 311.472 | AV15: 113.266 | AW15: 261.157 | AX15: 86.423 | AY15: 107.626 | AZ15: 568.472 | BA15: 122.459 | BB15: 121.595 | BC15: 59.006 | BD15: 87.646 | BE15: 390.706 | BF15: 54.272 | BG15: 86.788 | BH15: 64.397 | BI15: 92.175 | BJ15: 297.632 | BK15: 136.283 | BL15: 89.428 | BM15: 79.633 | BN15: 67.846 | BO15: 373.19 | BP15: 216.131 | BQ15: 83.861 | BR15: 72.186 | BS15: 119.319 | BT15: 491.497 | BU15: 211.917 | BV15: 153.212 | BW15: 62.906 | BX15: 62.93 | BY15: 490.965 | CK15: ΔNWC % of Δrevenue | CL15: 0.05 | CM15: 0.08 | CN15: 0.1
B16: Total assets | AE16: 1249.755 | AF16: 1249.755 | AG16: 1375.198 | AH16: 1422.145 | AI16: 1372.425 | AJ16: 1514.018 | AK16: 1514.018 | AL16: 1577.659 | AM16: 1659.901 | AN16: 1702.637 | AO16: 1856.058 | AP16: 1856.058 | AQ16: 1934.693 | AR16: 1848.216 | AS16: 1935.621 | AT16: 2094.592 | AU16: 2094.592 | AV16: 2322.493 | AW16: 2526.943 | AX16: 2666.911 | AY16: 2901.158 | AZ16: 2901.158 | BA16: 3161.943 | BB16: 3287.453 | BC16: 3604.803 | BD16: 3900.712 | BE16: 3900.712 | BF16: 4223.448 | BG16: 4447.523 | BH16: 4751.379 | BI16: 4615.788 | BJ16: 4615.788 | BK16: 4870.941 | BL16: 5136.744 | BM16: 5510.093 | BN16: 5825.064 | BO16: 5825.064 | BP16: 6410.493 | BQ16: 6626.492 | BR16: 7034.96 | BS16: 7386.103 | BT16: 7386.103 | BU16: 7756.673 | BV16: 8047.72 | BW16: 8413.365 | BX16: 8834.063 | BY16: 8834.063 | CK16: CapEx % of revenue | CL16: 0.1 | CM16: 0.12 | CN16: 0.14
B17: Goodwill | AE17: 179.906 | AF17: 179.906 | AG17: 179.906 | AH17: 179.906 | AI17: 180.063 | AJ17: 259.162 | AK17: 259.162 | AL17: 257.896 | AM17: 257.896 | AN17: 257.896 | AO17: 256.434 | AP17: 256.434 | AQ17: 256.434 | AR17: 256.434 | AS17: 256.997 | AT17: 256.998 | AU17: 256.998 | AV17: 256.998 | AW17: 256.998 | AX17: 260.67 | AY17: 262.423 | AZ17: 262.423 | BA17: 262.423 | BB17: 262.423 | BC17: 262.423 | BD17: 270.305 | BE17: 270.305 | BF17: 270.269 | BG17: 270.357 | BH17: 270.358 | BI17: 270.269 | BJ17: 270.269 | BK17: 270.269 | BL17: 270.269 | BM17: 270.269 | BN17: 270.269 | BO17: 270.269 | BP17: 383.329 | BQ17: 388.207 | BR17: 390.903 | BS17: 390.421 | BT17: 390.421 | BU17: 390.422 | BV17: 390.421 | BW17: 390.421 | BX17: 390.422 | BY17: 390.422 | CK17: Buyback (% shares retired / yr) | CL17: 0.01 | CM17: 0.005 | CN17: 0
B19: International
B20: Revenue | Q20: 228.945 | V20: 269.915 | AA20: 243.199 | AF20: 252.413 | AG20: 60.929 | AH20: 62.621 | AI20: 66.742 | AJ20: 64.501 | AK20: 254.793 | AL20: 68.063 | AM20: 73.971 | AN20: 92.917 | AO20: 79.722 | AP20: 314.673 | AQ20: 90.159 | AR20: 94.826 | AS20: 104.917 | AT20: 95.486 | AU20: 385.388 | AV20: 90.26 | AW20: 92.403 | AX20: 83.162 | AY20: 79.072 | AZ20: 344.897 | BA20: 95.685 | BB20: 99.108 | BC20: 111.957 | BD20: 113.689 | BE20: 420.439 | BF20: 131.671 | BG20: 140.074 | BH20: 149.691 | BI20: 134.335 | BJ20: 555.771 | BK20: 144.523 | BL20: 168.795 | BM20: 188.073 | BN20: 178.479 | BO20: 679.87 | BP20: 179.51 | BQ20: 189.423 | BR20: 208.343 | BS20: 194.812 | BT20: 772.088 | BU20: 199.29 | BV20: 188.471 | BW20: 205.259 | BX20: 198.834 | BY20: 791.854 | BZ20: =BY20*(1+CHOOSE(MATCH($CF$2,{"Bull","Base","Bear"},0),$CL$8,$CM$8,$CN$8)) | CA20: =BZ20*(1+CHOOSE(MATCH($CF$2,{"Bull","Base","Bear"},0),$CL$8,$CM$8,$CN$8)) | CB20: =CA20*(1+CHOOSE(MATCH($CF$2,{"Bull","Base","Bear"},0),$CL$8,$CM$8,$CN$8)) | CC20: =CB20*(1+CHOOSE(MATCH($CF$2,{"Bull","Base","Bear"},0),$CL$8,$CM$8,$CN$8)) | CD20: =CC20*(1+CHOOSE(MATCH($CF$2,{"Bull","Base","Bear"},0),$CL$8,$CM$8,$CN$8)) | CF20: =IFERROR((CD20/BY20)^(1/5)-1,"n/m") | CG20: =IFERROR((BY20/AZ20)^(1/5)-1,"n/m") | CH20: =IFERROR((BY20/G20)^(1/14)-1,"n/m")
B21: Operating income | AF21: 58.761 | AG21: 15.842 | AH21: 15.288 | AI21: 17.671 | AJ21: 16.138 | AK21: 64.939 | AL21: 17.923 | AM21: 17.937 | AN21: 23.731 | AO21: 9.867 | AP21: 69.458 | AQ21: 21.148 | AR21: 19.337 | AS21: 19.236 | AT21: 15.96 | AU21: 75.681 | AV21: 16.341 | AW21: 19.807 | AX21: 14.414 | AY21: 16.76 | AZ21: 67.322 | BA21: 25.355 | BB21: 28.769 | BC21: 31.385 | BD21: 27.362 | BE21: 112.871 | BF21: 35.172 | BG21: 34.682 | BH21: 32.318 | BI21: 25.256 | BJ21: 127.428 | BK21: 28.875 | BL21: 29.361 | BM21: 34.133 | BN21: 26.103 | BO21: 118.472 | BP21: 33.085 | BQ21: 32.562 | BR21: 44.272 | BS21: 34.07 | BT21: 143.989 | BU21: 51.308 | BV21: 50.318 | BW21: 59.08 | BX21: 55.122 | BY21: 215.828 | BZ21: =BZ20*CHOOSE(MATCH($CF$2,{"Bull","Base","Bear"},0),$CL$10,$CM$10,$CN$10) | CA21: =CA20*CHOOSE(MATCH($CF$2,{"Bull","Base","Bear"},0),$CL$10,$CM$10,$CN$10) | CB21: =CB20*CHOOSE(MATCH($CF$2,{"Bull","Base","Bear"},0),$CL$10,$CM$10,$CN$10) | CC21: =CC20*CHOOSE(MATCH($CF$2,{"Bull","Base","Bear"},0),$CL$10,$CM$10,$CN$10) | CD21: =CD20*CHOOSE(MATCH($CF$2,{"Bull","Base","Bear"},0),$CL$10,$CM$10,$CN$10) | CF21: =IFERROR((CD21/BY21)^(1/5)-1,"n/m") | CG21: =IFERROR((BY21/AZ21)^(1/5)-1,"n/m") | CH21: =IFERROR((BY21/G21)^(1/14)-1,"n/m")
B22: Operating margin % | C22: =IFERROR(C21/C20,"") | D22: =IFERROR(D21/D20,"") | E22: =IFERROR(E21/E20,"") | F22: =IFERROR(F21/F20,"") | G22: =IFERROR(G21/G20,"") | H22: =IFERROR(H21/H20,"") | I22: =IFERROR(I21/I20,"") | J22: =IFERROR(J21/J20,"") | ... CD22: =IFERROR(CD21/CD20,"")
B23: Revenue y/y % | L23: =IFERROR(L20/G20-1,"") | Q23: =IFERROR(Q20/L20-1,"") | V23: =IFERROR(V20/Q20-1,"") | AA23: =IFERROR(AA20/V20-1,"") | AF23: =IFERROR(AF20/AA20-1,"") | AK23: =IFERROR(AK20/AF20-1,"") | AP23: =IFERROR(AP20/AK20-1,"") | AU23: =IFERROR(AU20/AP20-1,"") | AZ23: =IFERROR(AZ20/AU20-1,"") | BE23: =IFERROR(BE20/AZ20-1,"") | BJ23: =IFERROR(BJ20/BE20-1,"") | BO23: =IFERROR(BO20/BJ20-1,"") | BT23: =IFERROR(BT20/BO20-1,"") | BY23: =IFERROR(BY20/BT20-1,"") | BZ23: =IFERROR(BZ20/BY20-1,"") | CA23: =IFERROR(CA20/BZ20-1,"") | CB23: =IFERROR(CB20/CA20-1,"") | CC23: =IFERROR(CC20/CB20-1,"") | CD23: =IFERROR(CD20/CC20-1,"")
B24: Depreciation & amortisation | AF24: 9.492 | AG24: 2.323 | AH24: 2.548 | AI24: 2.304 | AJ24: 2.318 | AK24: 9.493 | AL24: 2.373 | AM24: 3.817 | AN24: 2.384 | AO24: 2.245 | AP24: 10.819 | AQ24: 2.477 | AR24: 2.522 | AS24: 2.476 | AT24: 2.285 | AU24: 9.76 | AV24: 2.447 | AW24: 2.584 | AX24: 3.012 | AY24: 2.712 | AZ24: 10.755 | BA24: 2.844 | BB24: 3.647 | BC24: 3.805 | BD24: 3.91 | BE24: 14.206 | BF24: 4.035 | BG24: 3.987 | BH24: 4.97 | BI24: 4.358 | BJ24: 17.35 | BK24: 4.123 | BL24: 4.293 | BM24: 4.453 | BN24: 10.805 | BO24: 23.674 | BP24: 6.228 | BQ24: 6.918 | BR24: 7.256 | BS24: 7.674 | BT24: 28.076 | BU24: 7.712 | BV24: 7.744 | BW24: 7.955 | BX24: 8.412 | BY24: 31.823
B25: Capital expenditures | AF25: 20.466 | AG25: 1.688 | AH25: 2.662 | AI25: 1.426 | AJ25: 9.568 | AK25: 15.344 | AL25: 2.456 | AM25: 12.617 | AN25: 20.672 | AO25: 5.084 | AP25: 40.829 | AQ25: 27.083 | AR25: 7.49 | AS25: 15.785 | AT25: 12.798 | AU25: 63.156 | AV25: 18.527 | AW25: 7.402 | AX25: 4.223 | AY25: 5.05 | AZ25: 35.202 | BA25: 24.634 | BB25: 14.526 | BC25: 22.175 | BD25: 15.955 | BE25: 77.29 | BF25: 10.424 | BG25: 5.185 | BH25: 14.237 | BI25: 116.574 | BJ25: 146.42 | BK25: 16.372 | BL25: 14.636 | BM25: 10.172 | BN25: 102.266 | BO25: 143.446 | BP25: 40.542 | BQ25: 39.168 | BR25: 15.629 | BS25: 18.567 | BT25: 113.906 | BU25: 26.098 | BV25: 20.868 | BW25: 7.561 | BX25: 24.721 | BY25: 79.248
B26: Total assets | AE26: 400.065 | AF26: 400.065 | AG26: 395.198 | AH26: 419.096 | AI26: 439.261 | AJ26: 468.483 | AK26: 468.483 | AL26: 485.011 | AM26: 483.64 | AN26: 462.556 | AO26: 451.64 | AP26: 451.64 | AQ26: 447.095 | AR26: 448.689 | AS26: 456.142 | AT26: 453.025 | AU26: 453.025 | AV26: 533.446 | AW26: 521.662 | AX26: 494.672 | AY26: 554.103 | AZ26: 554.103 | BA26: 579.245 | BB26: 646.985 | BC26: 677.143 | BD26: 661.431 | BE26: 661.431 | BF26: 695.404 | BG26: 689.433 | BH26: 692.495 | BI26: 693.076 | BJ26: 693.076 | BK26: 722.736 | BL26: 795.664 | BM26: 839.712 | BN26: 912.815 | BO26: 912.815 | BP26: 923.293 | BQ26: 972.028 | BR26: 975.672 | BS26: 1041.661 | BT26: 1041.661 | BU26: 1112.814 | BV26: 1139.627 | BW26: 1258.857 | BX26: 1256.839 | BY26: 1256.839
B27: Goodwill | AE27: 80.292 | AF27: 80.292 | AG27: 75.187 | AH27: 76.961 | AI27: 78.571 | AJ27: 81.081 | AK27: 81.081 | AL27: 81.128 | AM27: 86.603 | AN27: 84.563 | AO27: 80.801 | AP27: 80.801 | AQ27: 78.686 | AR27: 81.611 | AS27: 80.728 | AT27: 76.323 | AU27: 76.323 | AV27: 80.181 | AW27: 81.264 | AX27: 77.369 | AY27: 81.199 | AZ27: 81.199 | BA27: 80.153 | BB27: 84.543 | BC27: 85.092 | BD27: 85.412 | BE27: 85.412 | BF27: 83.793 | BG27: 82.551 | BH27: 77.642 | BI27: 131.685 | BJ27: 131.685 | BK27: 124.575 | BL27: 133.777 | BM27: 136.371 | BN27: 124.02 | BO27: 124.02 | BP27: 117.597 | BQ27: 122.356 | BR27: 120.469 | BS27: 123.488 | BT27: 123.488 | BU27: 124.061 | BV27: 119.249 | BW27: 128.179 | BX27: 127.357 | BY27: 127.357
B29: Group total (consolidated segments)
B30: Revenue | C30: =C10+C20 | D30: =D10+D20 | E30: =E10+E20 | F30: =F10+F20 | G30: =G10+G20 | H30: =H10+H20 | I30: =I10+I20 | J30: =J10+J20 | ... CD30: =CD10+CD20 | CF30: =IFERROR((CD30/BY30)^(1/5)-1,"n/m") | CG30: =IFERROR((BY30/AZ30)^(1/5)-1,"n/m") | CH30: =IFERROR((BY30/G30)^(1/14)-1,"n/m")
B31: Operating income | C31: =C11+C21 | D31: =D11+D21 | E31: =E11+E21 | F31: =F11+F21 | G31: =G11+G21 | H31: =H11+H21 | I31: =I11+I21 | J31: =J11+J21 | ... CD31: =CD11+CD21 | CF31: =IFERROR((CD31/BY31)^(1/5)-1,"n/m") | CG31: =IFERROR((BY31/AZ31)^(1/5)-1,"n/m") | CH31: =IFERROR((BY31/G31)^(1/14)-1,"n/m")
B32: Operating margin % | C32: =IFERROR(C31/C30,"") | D32: =IFERROR(D31/D30,"") | E32: =IFERROR(E31/E30,"") | F32: =IFERROR(F31/F30,"") | G32: =IFERROR(G31/G30,"") | H32: =IFERROR(H31/H30,"") | I32: =IFERROR(I31/I30,"") | J32: =IFERROR(J31/J30,"") | ... CD32: =IFERROR(CD31/CD30,"")
B33: Revenue mix %
B34: United States | C34: =IFERROR(C10/C30,"") | D34: =IFERROR(D10/D30,"") | E34: =IFERROR(E10/E30,"") | F34: =IFERROR(F10/F30,"") | G34: =IFERROR(G10/G30,"") | H34: =IFERROR(H10/H30,"") | I34: =IFERROR(I10/I30,"") | J34: =IFERROR(J10/J30,"") | ... CD34: =IFERROR(CD10/CD30,"")
B35: International | C35: =IFERROR(C20/C30,"") | D35: =IFERROR(D20/D30,"") | E35: =IFERROR(E20/E30,"") | F35: =IFERROR(F20/F30,"") | G35: =IFERROR(G20/G30,"") | H35: =IFERROR(H20/H30,"") | I35: =IFERROR(I20/I30,"") | J35: =IFERROR(J20/J30,"") | ... CD35: =IFERROR(CD20/CD30,"")
B37: CONSOLIDATED INCOME STATEMENT
B38: Total revenues (service + vehicle sales) | C38: 212.667 | D38: 207.38 | E38: 236.755 | F38: 215.443 | G38: 872.246 | H38: 225.626 | I38: 227.904 | J38: 244.105 | K38: 226.556 | L38: 924.191 | M38: 238.866 | N38: 266.185 | O38: 277.638 | P38: 263.697 | Q38: 1046.386 | R38: 279.883 | S38: 286.434 | T38: 309.722 | U38: 287.45 | V38: 1163.489 | W38: 290.386 | X38: 276.258 | Y38: 297.142 | Z38: 282.293 | AA38: 1146.079 | AB38: 288.838 | AC38: 299.706 | AD38: 347.246 | AE38: 332.659 | AF38: 1268.449 | AG38: 345.991 | AH38: 349.532 | AI38: 373.862 | AJ38: 378.596 | AK38: 1447.981 | AL38: 419.168 | AM38: 459.106 | AN38: 478.198 | AO38: 449.223 | AP38: 1805.695 | AQ38: 461.368 | AR38: 484.898 | AS38: 553.116 | AT38: 542.575 | AU38: 2041.957 | AV38: 554.424 | AW38: 575.14 | AX38: 550.36 | AY38: 525.659 | AZ38: 2205.583 | BA38: 592.94 | BB38: 617.031 | BC38: 733.91 | BD38: 748.63 | BE38: 2692.511 | BF38: 810.132 | BG38: 867.46 | BH38: 939.941 | BI38: 883.388 | BJ38: 3500.921 | BK38: 893.372 | BL38: 956.724 | BM38: 1021.831 | BN38: 997.591 | BO38: 3869.518 | BP38: 1020.416 | BQ38: 1020.149 | BR38: 1127.259 | BS38: 1068.999 | BT38: 4236.823 | BU38: 1146.829 | BV38: 1163.316 | BW38: 1211.716 | BX38: 1125.097 | BY38: 4646.958 | BZ38: =BZ30 | CA38: =CA30 | CB38: =CB30 | CC38: =CC30 | CD38: =CD30 | CF38: =IFERROR((CD38/BY38)^(1/5)-1,"n/m") | CG38: =IFERROR((BY38/AZ38)^(1/5)-1,"n/m") | CH38: =IFERROR((BY38/G38)^(1/14)-1,"n/m")
B39: Yard operations expense | D39: 94.473 | E39: 92.996 | G39: 374.149 | H39: 96.207 | I39: 94.603 | J39: 92.578 | L39: 377.604 | M39: 97.119 | N39: 127.164 | O39: 116.41 | P39: 117.535 | Q39: 458.228 | R39: 125.956 | S39: 131.246 | T39: 131.207 | U39: 132.014 | V39: 520.423 | W39: 131.005 | X39: 129.273 | Y39: 135.222 | Z39: 130.791 | AA39: 526.291 | AB39: 135.909 | AC39: 140.965 | AD39: 151.855 | AE39: 154.175 | AF39: 582.904 | AG39: 167.611 | AH39: 169.081 | AI39: 166.572 | AJ39: 175.137 | AK39: 678.401 | AL39: 217.607 | AM39: 217.184 | AN39: 201.592 | AO39: 210.485 | AP39: 846.868 | AQ39: 207.694 | AR39: 215.46 | AS39: 230.553 | AT39: 234.404 | AU39: 888.111 | AV39: 240.791 | AW39: 257.351 | AX39: 253.76 | AY39: 220.585 | AZ39: 972.487 | BA39: 231.811 | BB39: 235.904 | BC39: 258.071 | BD39: 277.506 | BE39: 1003.292 | BF39: 298.694 | BG39: 323.814 | BH39: 346.428 | BI39: 340.561 | BJ39: 1309.497 | BK39: 372.777 | BL39: 375.497 | BM39: 378.958 | BN39: 390.797 | BO39: 1518.029 | BP39: 408.501 | BQ39: 409.178 | BR39: 438.873 | BS39: 453.532 | BT39: 1710.084 | BU39: 496.546 | BV39: 490.056 | BW39: 489.735 | BX39: 467.981 | BY39: 1944.318
B40: Cost of vehicle sales | D40: 27.002 | E40: 34.852 | G40: 125.202 | H40: 34.194 | I40: 33.605 | J40: 36.258 | L40: 136.971 | M40: 36.311 | N40: 42.204 | O40: 45.631 | P40: 43.09 | Q40: 167.236 | R40: 46.091 | S40: 43.642 | T40: 46.263 | U40: 38.497 | V40: 174.493 | W40: 37.073 | X40: 32.118 | Y40: 34.503 | Z40: 32.718 | AA40: 136.412 | AB40: 32.068 | AC40: 34.127 | AD40: 37.744 | AE40: 37.02 | AF40: 140.959 | AG40: 33.087 | AH40: 33.686 | AI40: 34.785 | AJ40: 35.994 | AK40: 137.552 | AL40: 38.297 | AM40: 50.313 | AN40: 57.538 | AO40: 50.313 | AP40: 196.461 | AS40: 70.984 | AU40: 255.504 | AV40: 58.764 | AW40: 57.9 | AX40: 53.987 | AY40: 54.643 | AZ40: 225.294 | BA40: 64.36 | BB40: 73.629 | BC40: 94.498 | BD40: 113.641 | BE40: 346.128 | BF40: 126.408 | BG40: 140.304 | BH40: 157.236 | BI40: 161.255 | BJ40: 585.203 | BK40: 151.112 | BL40: 154.727 | BM40: 159.443 | BN40: 149.216 | BO40: 614.498 | BP40: 147.896 | BQ40: 146.819 | BR40: 162.881 | BS40: 161.891 | BT40: 619.487 | BU40: 138.178 | BV40: 147.707 | BW40: 169.714 | BX40: 147.398 | BY40: 602.997
B41: Gross profit | D41: =D38-D39-D40 | E41: =E38-E39-E40 | G41: =G38-G39-G40 | H41: =H38-H39-H40 | I41: =I38-I39-I40 | J41: =J38-J39-J40 | L41: =L38-L39-L40 | M41: =M38-M39-M40 | N41: =N38-N39-N40 | O41: =O38-O39-O40 | P41: =P38-P39-P40 | Q41: =Q38-Q39-Q40 | R41: =R38-R39-R40 | S41: =S38-S39-S40 | ... AP41: =AP38-AP39-AP40 | AS41: =AS38-AS39-AS40 | AU41: =AU38-AU39-AU40 | AV41: =AV38-AV39-AV40 | AW41: =AW38-AW39-AW40 | AX41: =AX38-AX39-AX40 | AY41: =AY38-AY39-AY40 | AZ41: =AZ38-AZ39-AZ40 | BA41: =BA38-BA39-BA40 | BB41: =BB38-BB39-BB40 | ... BY41: =BY38-BY39-BY40
B42: General & administrative | D42: 25.71 | E42: 26.863 | G42: 107.605 | H42: 29.849 | I42: 27.386 | J42: 27.325 | L42: 114.492 | M42: 31.079 | N42: 34.047 | O42: 32.784 | P42: 40.02 | Q42: 137.93 | R42: 42.877 | S42: 40.062 | T42: 40.515 | U42: 41.081 | V42: 164.535 | W42: 39.907 | X42: 34.399 | Y42: 32.65 | Z42: 32.019 | AA42: 138.975 | AB42: 34.615 | AC42: 32.529 | AD42: 35.699 | AE42: 35.273 | AF42: 138.116 | AG42: 40.469 | AH42: 37.885 | AI42: 35.717 | AJ42: 37.293 | AK42: 151.364 | AL42: 39.322 | AM42: 40.662 | AN42: 44.449 | AO42: 52.457 | AP42: 176.89 | AQ42: 44.478 | AR42: 43.487 | AS42: 44.085 | AT42: 49.817 | AU42: 181.867 | AV42: 49.478 | AW42: 49.997 | AX42: 47.512 | AY42: 44.716 | AZ42: 191.703 | BA42: 48.175 | BB42: 49.277 | BC42: 53.23 | BD42: 55.983 | BE42: 206.665 | BF42: 54.909 | BG42: 56.014 | BH42: 63.522 | BI42: 56.779 | BJ42: 231.224 | BK42: 57.98 | BL42: 60.975 | BM42: 64.506 | BN42: 66.961 | BO42: 250.422 | BP42: 68.643 | BQ42: 84.252 | BR42: 88.302 | BS42: 94.032 | BT42: 335.229 | BU42: 105.738 | BV42: 99.342 | BW42: 100.722 | BX42: 97.127 | BY42: 402.929
B43: Operating income | D43: =D41-D42 | E43: =E41-E42 | G43: =G41-G42 | H43: =H41-H42 | I43: =I41-I42 | J43: =J41-J42 | L43: =L41-L42 | M43: =M41-M42 | N43: =N41-N42 | O43: =O41-O42 | P43: =P41-P42 | Q43: =Q41-Q42 | R43: =R41-R42 | S43: =S41-S42 | ... AP43: =AP41-AP42 | AS43: =AS41-AS42 | AU43: =AU41-AU42 | AV43: =AV41-AV42 | AW43: =AW41-AW42 | AX43: =AX41-AX42 | AY43: =AY41-AY42 | AZ43: =AZ41-AZ42 | BA43: =BA41-BA42 | BB43: =BB41-BB42 | ... BY43: =BY41-BY42 | BZ43: =BZ31 | CA43: =CA31 | CB43: =CB31 | CC43: =CC31 | CD43: =CD31 | CF43: =IFERROR((CD43/BY43)^(1/5)-1,"n/m") | CG43: =IFERROR((BY43/AZ43)^(1/5)-1,"n/m") | CH43: =IFERROR((BY43/G43)^(1/14)-1,"n/m")
B44: Interest & other income / (expense), net | C44: 0.569 | D44: 0.522 | E44: -1.694 | F44: -0.811 | G44: -1.413 | H44: -1.561 | I44: -1.323 | J44: -3.397 | L44: -8.297 | M44: -2.769 | N44: -1.653 | O44: -0.808 | P44: -0.89 | Q44: -6.12 | R44: -0.714 | S44: -0.896 | T44: -1.315 | U44: -1.974 | V44: -4.899 | W44: -0.178 | X44: -0.364 | Y44: -6.471 | Z44: -5.319 | AA44: -12.332 | AB44: -4.486 | AC44: -0.533 | AD44: -5.38 | AE44: -0.206 | AF44: -10.605 | AG44: -2.29 | AH44: -8.781 | AI44: -5.7 | AJ44: -4.428 | AK44: -21.199 | AL44: -9.814 | AM44: -6.509 | AN44: -3.403 | AO44: -2.108 | AP44: -21.834 | AQ44: -2.654 | AR44: 0.227 | AS44: -3.365 | AT44: -5.732 | AU44: -11.524 | AV44: -3.309 | AW44: -4.818 | AX44: -3.301 | AY44: -3.832 | AZ44: -15.26 | BA44: -1.779 | BB44: -5.769 | BC44: -4.576 | BD44: -2.456 | BE44: -14.58 | BF44: -4.295 | BG44: -5.273 | BH44: -3.15 | BI44: -21.325 | BJ44: -34.043 | BK44: 1.6 | BL44: 11.578 | BM44: 21.506 | BN44: 33.075 | BO44: 67.759 | BP44: 27.933 | BQ44: 30.853 | BR44: 34.909 | BS44: 48.883 | BT44: 142.578 | BU44: 44.951 | BV44: 36.84 | BW44: 51.259 | BX44: 65.817 | BY44: 198.867 | BZ44: =BZ38*CHOOSE(MATCH($CF$2,{"Bull","Base","Bear"},0),$CL$11,$CM$11,$CN$11) | CA44: =CA38*CHOOSE(MATCH($CF$2,{"Bull","Base","Bear"},0),$CL$11,$CM$11,$CN$11) | CB44: =CB38*CHOOSE(MATCH($CF$2,{"Bull","Base","Bear"},0),$CL$11,$CM$11,$CN$11) | CC44: =CC38*CHOOSE(MATCH($CF$2,{"Bull","Base","Bear"},0),$CL$11,$CM$11,$CN$11) | CD44: =CD38*CHOOSE(MATCH($CF$2,{"Bull","Base","Bear"},0),$CL$11,$CM$11,$CN$11)
...

Sheet Bull-Base-Bear
B2: COPART — Bull / Base / Bear P&L Summary
B3: Linked to Model — toggle scenario via the Model tab.
C5: FY2025A | D5: FY2026E | E5: FY2027E | F5: FY2028E | G5: FY2029E | H5: FY2030E
B6: Revenue | C6: =Model!BY38 | D6: =Model!BZ38 | E6: =Model!CA38 | F6: =Model!CB38 | G6: =Model!CC38 | H6: =Model!CD38
B7: Operating income | C7: =Model!BY43 | D7: =Model!BZ43 | E7: =Model!CA43 | F7: =Model!CB43 | G7: =Model!CC43 | H7: =Model!CD43
B8: Net income attrib. to Copart | C8: =Model!BY49 | D8: =Model!BZ49 | E8: =Model!CA49 | F8: =Model!CB49 | G8: =Model!CC49 | H8: =Model!CD49
B9: EPS — diluted ($) | C9: =Model!BY54 | D9: =Model!BZ54 | E9: =Model!CA54 | F9: =Model!CB54 | G9: =Model!CC54 | H9: =Model!CD54
B10: Free cash flow | C10: =Model!BY74 | D10: =Model!BZ74 | E10: =Model!CA74 | F10: =Model!CB74 | G10: =Model!CC74 | H10: =Model!CD74
B12: Active scenario: | C12: =Model!$CF$2

Sheet DCF
B2: COPART — Unlevered DCF (off model forecast FCF)
B3: Free cash flow linked from the Model forecast columns. Assumptions in blue are editable.
B5: WACC | C5: 0.09
B6: Terminal growth (g) | C6: 0.03
C8: FY2026E | D8: FY2027E | E8: FY2028E | F8: FY2029E | G8: FY2030E
B9: Free cash flow (US$m) | C9: =Model!BZ74 | D9: =Model!CA74 | E9: =Model!CB74 | F9: =Model!CC74 | G9: =Model!CD74
B10: Discount factor | C10: =1/(1+$C$5)^1 | D10: =1/(1+$C$5)^2 | E10: =1/(1+$C$5)^3 | F10: =1/(1+$C$5)^4 | G10: =1/(1+$C$5)^5
B11: PV of FCF | C11: =C9*C10 | D11: =D9*D10 | E11: =E9*E10 | F11: =F9*F10 | G11: =G9*G10
B13: Terminal value (Gordon) | C13: =G9*(1+$C$6)/($C$5-$C$6)
B14: PV of terminal value | C14: =C13*G10
B15: Enterprise value | C15: =SUM(C11:G11)+C14
B16: − Net debt (FY latest, Model) | C16: =Model!BY96
B17: Equity value | C17: =C15-C16
B18: ÷ Diluted shares (m, FY latest) | C18: =Model!BY51
B19: Implied value per share ($) | C19: =C17/C18
