Workbook

Sheet Model
CF1: SCENARIO SWITCH ▼ (Bull / Base / Bear) — drives all scenario-linked forecast drivers
B2: CoStar Group, Inc. (NASDAQ: CSGP) — 3-Statement Financial Model | CF2: Base
B3: US GAAP as reported · USD millions (per-share data in USD; shares in millions, split-adjusted for the 10-for-1 split of June 2021) · Source: CoStar Group Forms 10-K / 10-Q (XBRL statements; 2006–2010 from 10-K HTML) and Form 8-K earnings releases (Ex. 99.1), deal 8-Ks (Zonda, May/Aug-2026), Form 4 (share price), SEC EDGAR CIK 0001057352 (investor-relations releases are the same documents as filed on EDGAR)
B4: Basis notes: calendar fiscal year. Q4 = FY (10-K) − 9M (Q3 10-Q); quarterly cash flows = YTD − prior YTD. Revenue lines: current basis (CoStar · LoopNet · Other CRE · Residential) recast from Q1/23 in the Q4-25 release; legacy product lines 2015–Q3/25 and North America / International segments 2007–Q3/25 kept as memo. Adjusted EBITDA / Adjusted Net Income per company definitions in force (EBITDA only to 2008; non-GAAP net income from FY2009). Acquisitions: LoopNet Apr-2012, Apartments.com Apr-2014, ForRent Feb-2018, STR Oct-2019, Ten-X Jun-2020, Homesnap Dec-2020, Homes.com May-2021, OnTheMarket Dec-2023, Matterport Feb-2025, Domain Aug-2025; Zonda closed 21-Aug-2026 — excluded from company FY26 guidance, modelled separately from Q3/26E.
CH5: Forecast | CI5: Historical | CJ5: Historical | CK5: Historical
B6: (USDm) | C6: 2006 | D6: 2007 | E6: 2008 | F6: 2009 | G6: 2010 | H6: 2011 | I6: 2012 | J6: Q1/13 | K6: Q2/13 | L6: Q3/13 | M6: Q4/13 | N6: 2013 | O6: Q1/14 | P6: Q2/14 | Q6: Q3/14 | R6: Q4/14 | S6: 2014 | T6: Q1/15 | U6: Q2/15 | V6: Q3/15 | W6: Q4/15 | X6: 2015 | Y6: Q1/16 | Z6: Q2/16 | AA6: Q3/16 | AB6: Q4/16 | AC6: 2016 | AD6: Q1/17 | AE6: Q2/17 | AF6: Q3/17 | AG6: Q4/17 | AH6: 2017 | AI6: Q1/18 | AJ6: Q2/18 | AK6: Q3/18 | AL6: Q4/18 | AM6: 2018 | AN6: Q1/19 | AO6: Q2/19 | AP6: Q3/19 | AQ6: Q4/19 | AR6: 2019 | AS6: Q1/20 | AT6: Q2/20 | AU6: Q3/20 | AV6: Q4/20 | AW6: 2020 | AX6: Q1/21 | AY6: Q2/21 | AZ6: Q3/21 | BA6: Q4/21 | BB6: 2021 | BC6: Q1/22 | BD6: Q2/22 | BE6: Q3/22 | BF6: Q4/22 | BG6: 2022 | BH6: Q1/23 | BI6: Q2/23 | BJ6: Q3/23 | BK6: Q4/23 | BL6: 2023 | BM6: Q1/24 | BN6: Q2/24 | BO6: Q3/24 | BP6: Q4/24 | BQ6: 2024 | BR6: Q1/25 | BS6: Q2/25 | BT6: Q3/25 | BU6: Q4/25 | BV6: 2025 | BW6: Q1/26 | BX6: Q2/26 | BY6: Q3/26E | BZ6: Q4/26E | CA6: 2026E | CB6: 2027E | CC6: 2028E | CD6: 2029E | CE6: 2030E | CF6: Modelling Notes | CH6: 5Y CAGR / avg | CI6: 5Y CAGR / avg | CJ6: 10Y CAGR / avg | CK6: 19Y CAGR / avg
CH7: 25-'30 | CI7: 20-'25 | CJ7: 15-'25 | CK7: 06-'25
B8: SEGMENT REVENUE BUILD — COMMERCIAL REAL ESTATE · RESIDENTIAL REAL ESTATE · ZONDA → SEGMENT ADJUSTED EBITDA | CF8: SEGMENT BUILD — modelling logic (product-line revenues → segment Adjusted EBITDA margin → consolidated Adjusted EBITDA → GAAP P&L)
CN9: SCENARIO INPUT TABLE — driver assumptions per Bull / Base / Bear | CO9: Bull | CP9: Base | CQ9: Bear | CR9: Bull / Bear = Base + Δ (Δ inputs on each lever header). Outlook block = high / mid / low end of the FY26 ranges.
B10: Commercial Real Estate (CoStar · LoopNet · Other CRE) — current reporting basis (Q4-25 recast, history from Q1/23) | CF10: COMMERCIAL REAL ESTATE — modelling logic
B11: CoStar (subscription data & analytics, incl. Information Services) | T11: =IF(ISNUMBER(T37),N(T37)+N(T38),"") -> 105.347 | U11: =IF(ISNUMBER(U37),N(U37)+N(U38),"") -> 107.523 | V11: =IF(ISNUMBER(V37),N(V37)+N(V38),"") -> 110.476 | W11: =IF(ISNUMBER(W37),N(W37)+N(W38),"") -> 112.884 | X11: =IF(ISNUMBER(X37),N(X37)+N(X38),"") -> 436.23 | Y11: =IF(ISNUMBER(Y37),N(Y37)+N(Y38),"") -> 117.059 | Z11: =IF(ISNUMBER(Z37),N(Z37)+N(Z38),"") -> 120.499 | AA11: =IF(ISNUMBER(AA37),N(AA37)+N(AA38),"") -> 122.747 | ... BG11: =IF(ISNUMBER(BG37),N(BG37)+N(BG38),"") -> 994.362 | BH11: 267 | BI11: 271 | BJ11: 278 | BK11: 280 | BL11: =IF(ISNUMBER(BL37),N(BL37)+N(BL38),"") -> 1096.1 | BM11: 283 | BN11: 286 | BO11: 290 | BP11: 297 | BQ11: 1156 | BR11: 305 | BS11: 310 | BT11: 318 | BU11: 325 | BV11: 1259 | BW11: 331 | BX11: 337 | BY11: =BX11*(1+BY13+BY92) -> 345.92134 | BZ11: =BX11*((1+BZ13)^2+2*BZ92) -> 354.95548 | CA11: =SUM(BW11,BX11,BY11,BZ11) -> 1368.8768 | CB11: =CA11*(1+CB12) -> 1492.0757 | CC11: =CB11*(1+CC12) -> 1626.3626 | CD11: =CC11*(1+CD12) -> 1764.6034 | CE11: =CD11*(1+CE12) -> 1905.7716 | CF11: Q3/26E = Q2/26 × (1 + 1H/26 average q/q + outlook calibration Δ); Q4/26E = Q2/26 × ((1+g)² + 2Δ). 2027E+: prior year × (1 + scenario lever COSTAR_growth). | CH11: =IFERROR((CE11/BV11)^(1/5)-1,"n/m") -> 0.086448203 | CI11: =IFERROR((BV11/AW11)^(1/5)-1,"n/m") -> 0.096359611 | CJ11: =IFERROR((BV11/X11)^(1/10)-1,"n/m") -> 0.11181114 | CK11: =IFERROR((BV11/C11)^(1/19)-1,"n/m") -> n/m | CN11: FY26 outlook — Q2-26 release (28-Jul-26); legacy CoStar, excludes Zonda | CO11: High | CP11: Mid | CQ11: Low | CR11: Company guidance pre-dates the Zonda closing (21-Aug-26) — the model adds Zonda separately.
B12: y/y % | D12: =IF(AND(ISNUMBER(D11),ISNUMBER(C11)),IFERROR(D11/C11-1,""),"") | E12: =IF(AND(ISNUMBER(E11),ISNUMBER(D11)),IFERROR(E11/D11-1,""),"") | F12: =IF(AND(ISNUMBER(F11),ISNUMBER(E11)),IFERROR(F11/E11-1,""),"") | G12: =IF(AND(ISNUMBER(G11),ISNUMBER(F11)),IFERROR(G11/F11-1,""),"") | H12: =IF(AND(ISNUMBER(H11),ISNUMBER(G11)),IFERROR(H11/G11-1,""),"") | I12: =IF(AND(ISNUMBER(I11),ISNUMBER(H11)),IFERROR(I11/H11-1,""),"") | N12: =IF(AND(ISNUMBER(N11),ISNUMBER(I11)),IFERROR(N11/I11-1,""),"") | O12: =IF(AND(ISNUMBER(O11),ISNUMBER(J11)),IFERROR(O11/J11-1,""),"") | P12: =IF(AND(ISNUMBER(P11),ISNUMBER(K11)),IFERROR(P11/K11-1,""),"") | Q12: =IF(AND(ISNUMBER(Q11),ISNUMBER(L11)),IFERROR(Q11/L11-1,""),"") | R12: =IF(AND(ISNUMBER(R11),ISNUMBER(M11)),IFERROR(R11/M11-1,""),"") | S12: =IF(AND(ISNUMBER(S11),ISNUMBER(N11)),IFERROR(S11/N11-1,""),"") | T12: =IF(AND(ISNUMBER(T11),ISNUMBER(O11)),IFERROR(T11/O11-1,""),"") | U12: =IF(AND(ISNUMBER(U11),ISNUMBER(P11)),IFERROR(U11/P11-1,""),"") | ... BZ12: =IF(AND(ISNUMBER(BZ11),ISNUMBER(BU11)),IFERROR(BZ11/BU11-1,""),"") -> 0.092170695 | CA12: =IFERROR(CA11/BV11-1,"") -> 0.08727309 | CB12: =CHOOSE(MATCH($CF$2,{"Bull","Base","Bear"},0),$CO$46,$CP$46,$CQ$46) -> 0.09 | CC12: =CHOOSE(MATCH($CF$2,{"Bull","Base","Bear"},0),$CO$47,$CP$47,$CQ$47) -> 0.09 | CD12: =CHOOSE(MATCH($CF$2,{"Bull","Base","Bear"},0),$CO$48,$CP$48,$CQ$48) -> 0.085 | CE12: =CHOOSE(MATCH($CF$2,{"Bull","Base","Bear"},0),$CO$49,$CP$49,$CQ$49) -> 0.08 | CF12: 2015–22 mapped from legacy lines (CoStar Suite + Information Services). | CN12: FY26 revenues ($m) | CO12: 3755 | CP12: 3735 | CQ12: 3715 | CR12: Revised to $3.715–3.755bn in the Q2-26 release (from $3.78–3.82bn on 7-Jan-26 / 24-Feb-26).
B13: Sequential q/q % (Q3/Q4-26E: 1H/26 average q/q before outlook calibration) | K13: =IF(AND(ISNUMBER(K11),ISNUMBER(J11)),IFERROR(K11/J11-1,""),"") | L13: =IF(AND(ISNUMBER(L11),ISNUMBER(K11)),IFERROR(L11/K11-1,""),"") | M13: =IF(AND(ISNUMBER(M11),ISNUMBER(L11)),IFERROR(M11/L11-1,""),"") | O13: =IF(AND(ISNUMBER(O11),ISNUMBER(M11)),IFERROR(O11/M11-1,""),"") | P13: =IF(AND(ISNUMBER(P11),ISNUMBER(O11)),IFERROR(P11/O11-1,""),"") | Q13: =IF(AND(ISNUMBER(Q11),ISNUMBER(P11)),IFERROR(Q11/P11-1,""),"") | R13: =IF(AND(ISNUMBER(R11),ISNUMBER(Q11)),IFERROR(R11/Q11-1,""),"") | T13: =IF(AND(ISNUMBER(T11),ISNUMBER(R11)),IFERROR(T11/R11-1,""),"") | U13: =IF(AND(ISNUMBER(U11),ISNUMBER(T11)),IFERROR(U11/T11-1,""),"") -> 0.020655548 | V13: =IF(AND(ISNUMBER(V11),ISNUMBER(U11)),IFERROR(V11/U11-1,""),"") -> 0.027463891 | W13: =IF(AND(ISNUMBER(W11),ISNUMBER(V11)),IFERROR(W11/V11-1,""),"") -> 0.021796589 | Y13: =IF(AND(ISNUMBER(Y11),ISNUMBER(W11)),IFERROR(Y11/W11-1,""),"") -> 0.036984869 | Z13: =IF(AND(ISNUMBER(Z11),ISNUMBER(Y11)),IFERROR(Z11/Y11-1,""),"") -> 0.02938689 | AA13: =IF(AND(ISNUMBER(AA11),ISNUMBER(Z11)),IFERROR(AA11/Z11-1,""),"") -> 0.018655756 | AB13: =IF(AND(ISNUMBER(AB11),ISNUMBER(AA11)),IFERROR(AB11/AA11-1,""),"") -> 0.021035137 | AD13: =IF(AND(ISNUMBER(AD11),ISNUMBER(AB11)),IFERROR(AD11/AB11-1,""),"") -> 0.023825292 | AE13: =IF(AND(ISNUMBER(AE11),ISNUMBER(AD11)),IFERROR(AE11/AD11-1,""),"") -> 0.02954448 | AF13: =IF(AND(ISNUMBER(AF11),ISNUMBER(AE11)),IFERROR(AF11/AE11-1,""),"") -> 0.02970342 | AG13: =IF(AND(ISNUMBER(AG11),ISNUMBER(AF11)),IFERROR(AG11/AF11-1,""),"") -> 0.024421084 | AI13: =IF(AND(ISNUMBER(AI11),ISNUMBER(AG11)),IFERROR(AI11/AG11-1,""),"") -> 0.043551582 | AJ13: =IF(AND(ISNUMBER(AJ11),ISNUMBER(AI11)),IFERROR(AJ11/AI11-1,""),"") -> 0.028001458 | AK13: =IF(AND(ISNUMBER(AK11),ISNUMBER(AJ11)),IFERROR(AK11/AJ11-1,""),"") -> 0.047667784 | AL13: =IF(AND(ISNUMBER(AL11),ISNUMBER(AK11)),IFERROR(AL11/AK11-1,""),"") -> 0.028847075 | AN13: =IF(AND(ISNUMBER(AN11),ISNUMBER(AL11)),IFERROR(AN11/AL11-1,""),"") -> 0.033598739 | AO13: =IF(AND(ISNUMBER(AO11),ISNUMBER(AN11)),IFERROR(AO11/AN11-1,""),"") -> 0.042335381 | AP13: =IF(AND(ISNUMBER(AP11),ISNUMBER(AO11)),IFERROR(AP11/AO11-1,""),"") -> 0.010840889 | AQ13: =IF(AND(ISNUMBER(AQ11),ISNUMBER(AP11)),IFERROR(AQ11/AP11-1,""),"") -> 0.086178797 | AS13: =IF(AND(ISNUMBER(AS11),ISNUMBER(AQ11)),IFERROR(AS11/AQ11-1,""),"") -> 0.035313498 | AT13: =IF(AND(ISNUMBER(AT11),ISNUMBER(AS11)),IFERROR(AT11/AS11-1,""),"") -> -0.0088629661 | AU13: =IF(AND(ISNUMBER(AU11),ISNUMBER(AT11)),IFERROR(AU11/AT11-1,""),"") -> 0.018267899 | AV13: =IF(AND(ISNUMBER(AV11),ISNUMBER(AU11)),IFERROR(AV11/AU11-1,""),"") -> 0.01784477 | AX13: =IF(AND(ISNUMBER(AX11),ISNUMBER(AV11)),IFERROR(AX11/AV11-1,""),"") -> 0.020541053 | AY13: =IF(AND(ISNUMBER(AY11),ISNUMBER(AX11)),IFERROR(AY11/AX11-1,""),"") -> 0.025406032 | AZ13: =IF(AND(ISNUMBER(AZ11),ISNUMBER(AY11)),IFERROR(AZ11/AY11-1,""),"") -> 0.033256967 | BA13: =IF(AND(ISNUMBER(BA11),ISNUMBER(AZ11)),IFERROR(BA11/AZ11-1,""),"") -> 0.032291472 | BC13: =IF(AND(ISNUMBER(BC11),ISNUMBER(BA11)),IFERROR(BC11/BA11-1,""),"") -> 0.042405279 | BD13: =IF(AND(ISNUMBER(BD11),ISNUMBER(BC11)),IFERROR(BD11/BC11-1,""),"") -> 0.039022488 | BE13: =IF(AND(ISNUMBER(BE11),ISNUMBER(BD11)),IFERROR(BE11/BD11-1,""),"") -> 0.035235118 | BF13: =IF(AND(ISNUMBER(BF11),ISNUMBER(BE11)),IFERROR(BF11/BE11-1,""),"") -> 0.023744299 | BH13: =IF(AND(ISNUMBER(BH11),ISNUMBER(BF11)),IFERROR(BH11/BF11-1,""),"") -> 0.02800248 | BI13: =IF(AND(ISNUMBER(BI11),ISNUMBER(BH11)),IFERROR(BI11/BH11-1,""),"") -> 0.014981273 | BJ13: =IF(AND(ISNUMBER(BJ11),ISNUMBER(BI11)),IFERROR(BJ11/BI11-1,""),"") -> 0.025830258 | BK13: =IF(AND(ISNUMBER(BK11),ISNUMBER(BJ11)),IFERROR(BK11/BJ11-1,""),"") -> 0.0071942446 | BM13: =IF(AND(ISNUMBER(BM11),ISNUMBER(BK11)),IFERROR(BM11/BK11-1,""),"") -> 0.010714286 | BN13: =IF(AND(ISNUMBER(BN11),ISNUMBER(BM11)),IFERROR(BN11/BM11-1,""),"") -> 0.010600707 | BO13: =IF(AND(ISNUMBER(BO11),ISNUMBER(BN11)),IFERROR(BO11/BN11-1,""),"") -> 0.013986014 | BP13: =IF(AND(ISNUMBER(BP11),ISNUMBER(BO11)),IFERROR(BP11/BO11-1,""),"") -> 0.024137931 | BR13: =IF(AND(ISNUMBER(BR11),ISNUMBER(BP11)),IFERROR(BR11/BP11-1,""),"") -> 0.026936027 | BS13: =IF(AND(ISNUMBER(BS11),ISNUMBER(BR11)),IFERROR(BS11/BR11-1,""),"") -> 0.016393443 | BT13: =IF(AND(ISNUMBER(BT11),ISNUMBER(BS11)),IFERROR(BT11/BS11-1,""),"") -> 0.025806452 | BU13: =IF(AND(ISNUMBER(BU11),ISNUMBER(BT11)),IFERROR(BU11/BT11-1,""),"") -> 0.022012579 | BW13: =IF(AND(ISNUMBER(BW11),ISNUMBER(BU11)),IFERROR(BW11/BU11-1,""),"") -> 0.018461538 | BX13: =IF(AND(ISNUMBER(BX11),ISNUMBER(BW11)),IFERROR(BX11/BW11-1,""),"") -> 0.018126888 | BY13: =((BW11/BU11-1)+(BX11/BW11-1))/2 -> 0.018294213 | BZ13: =BY13 -> 0.018294213 | CN13: FY26 Adjusted EBITDA ($m) | CO13: 820 | CP13: 800 | CQ13: 780 | CR13: Affirmed $780–820m (raised +$30m at the mid-point vs Feb-26). Check vs model (segment calibration below sums to this).
B14: LoopNet (commercial property marketplace) | AS14: =IF(ISNUMBER(AS42),AS42,"") -> 43.2 | AT14: =IF(ISNUMBER(AT42),AT42,"") -> 43.32 | AU14: =IF(ISNUMBER(AU42),AU42,"") -> 45.084 | AV14: =IF(ISNUMBER(AV42),AV42,"") -> 48.201 | AW14: =IF(ISNUMBER(AW42),AW42,"") -> 179.805 | AX14: =IF(ISNUMBER(AX42),AX42,"") -> 49.23 | AY14: =IF(ISNUMBER(AY42),AY42,"") -> 51.095 | AZ14: =IF(ISNUMBER(AZ42),AZ42,"") -> 52.527 | ... BG14: =IF(ISNUMBER(BG42),BG42,"") -> 230.941 | BH14: 63 | BI14: 66 | BJ14: 68 | BK14: 69 | BL14: =IF(ISNUMBER(BL42),BL42,"") -> 264.8 | BM14: 69 | BN14: 70 | BO14: 71 | BP14: 72 | BQ14: 282 | BR14: 73 | BS14: 76 | BT14: 79 | BU14: 84 | BV14: 312 | BW14: 85 | BX14: 87 | BY14: =BX14*(1+BY16+BY92) -> 89.252926 | BZ14: =BX14*((1+BZ16)^2+2*BZ92) -> 91.533162 | CA14: =SUM(BW14,BX14,BY14,BZ14) -> 352.78609 | CB14: =CA14*(1+CB15) -> 395.12042 | CC14: =CB14*(1+CC15) -> 438.58366 | CD14: =CC14*(1+CD15) -> 482.44203 | CE14: =CD14*(1+CE15) -> 525.86181 | CF14: As CoStar. 2027E+: scenario lever LOOPNET_growth. | CH14: =IFERROR((CE14/BV14)^(1/5)-1,"n/m") -> 0.11005222 | CI14: =IFERROR((BV14/AW14)^(1/5)-1,"n/m") -> 0.11653044 | CJ14: =IFERROR((BV14/X14)^(1/10)-1,"n/m") -> n/m | CK14: =IFERROR((BV14/C14)^(1/19)-1,"n/m") -> n/m | CN14: FY26 net income ($m, guidance reconciliation) | CO14: 247 | CP14: 232.5 | CQ14: 218 | CR14: Q2-26 release forward-looking reconciliation (memo only).
B15: y/y % | D15: =IF(AND(ISNUMBER(D14),ISNUMBER(C14)),IFERROR(D14/C14-1,""),"") | E15: =IF(AND(ISNUMBER(E14),ISNUMBER(D14)),IFERROR(E14/D14-1,""),"") | F15: =IF(AND(ISNUMBER(F14),ISNUMBER(E14)),IFERROR(F14/E14-1,""),"") | G15: =IF(AND(ISNUMBER(G14),ISNUMBER(F14)),IFERROR(G14/F14-1,""),"") | H15: =IF(AND(ISNUMBER(H14),ISNUMBER(G14)),IFERROR(H14/G14-1,""),"") | I15: =IF(AND(ISNUMBER(I14),ISNUMBER(H14)),IFERROR(I14/H14-1,""),"") | N15: =IF(AND(ISNUMBER(N14),ISNUMBER(I14)),IFERROR(N14/I14-1,""),"") | O15: =IF(AND(ISNUMBER(O14),ISNUMBER(J14)),IFERROR(O14/J14-1,""),"") | P15: =IF(AND(ISNUMBER(P14),ISNUMBER(K14)),IFERROR(P14/K14-1,""),"") | Q15: =IF(AND(ISNUMBER(Q14),ISNUMBER(L14)),IFERROR(Q14/L14-1,""),"") | R15: =IF(AND(ISNUMBER(R14),ISNUMBER(M14)),IFERROR(R14/M14-1,""),"") | S15: =IF(AND(ISNUMBER(S14),ISNUMBER(N14)),IFERROR(S14/N14-1,""),"") | T15: =IF(AND(ISNUMBER(T14),ISNUMBER(O14)),IFERROR(T14/O14-1,""),"") | U15: =IF(AND(ISNUMBER(U14),ISNUMBER(P14)),IFERROR(U14/P14-1,""),"") | ... BZ15: =IF(AND(ISNUMBER(BZ14),ISNUMBER(BU14)),IFERROR(BZ14/BU14-1,""),"") -> 0.089680498 | CA15: =IFERROR(CA14/BV14-1,"") -> 0.13072464 | CB15: =CHOOSE(MATCH($CF$2,{"Bull","Base","Bear"},0),$CO$51,$CP$51,$CQ$51) -> 0.12 | CC15: =CHOOSE(MATCH($CF$2,{"Bull","Base","Bear"},0),$CO$52,$CP$52,$CQ$52) -> 0.11 | CD15: =CHOOSE(MATCH($CF$2,{"Bull","Base","Bear"},0),$CO$53,$CP$53,$CQ$53) -> 0.1 | CE15: =CHOOSE(MATCH($CF$2,{"Bull","Base","Bear"},0),$CO$54,$CP$54,$CQ$54) -> 0.09 | CN15: FY26 Adjusted EPS ($) | CO15: 1.39 | CP15: 1.355 | CQ15: 1.32 | CR15: On 405m shares; 26% non-GAAP tax rate (memo; model Adjusted EPS shown in the bridge).
B16: Sequential q/q % (Q3/Q4-26E: 1H/26 average q/q before outlook calibration) | K16: =IF(AND(ISNUMBER(K14),ISNUMBER(J14)),IFERROR(K14/J14-1,""),"") | L16: =IF(AND(ISNUMBER(L14),ISNUMBER(K14)),IFERROR(L14/K14-1,""),"") | M16: =IF(AND(ISNUMBER(M14),ISNUMBER(L14)),IFERROR(M14/L14-1,""),"") | O16: =IF(AND(ISNUMBER(O14),ISNUMBER(M14)),IFERROR(O14/M14-1,""),"") | P16: =IF(AND(ISNUMBER(P14),ISNUMBER(O14)),IFERROR(P14/O14-1,""),"") | Q16: =IF(AND(ISNUMBER(Q14),ISNUMBER(P14)),IFERROR(Q14/P14-1,""),"") | R16: =IF(AND(ISNUMBER(R14),ISNUMBER(Q14)),IFERROR(R14/Q14-1,""),"") | T16: =IF(AND(ISNUMBER(T14),ISNUMBER(R14)),IFERROR(T14/R14-1,""),"") | U16: =IF(AND(ISNUMBER(U14),ISNUMBER(T14)),IFERROR(U14/T14-1,""),"") | V16: =IF(AND(ISNUMBER(V14),ISNUMBER(U14)),IFERROR(V14/U14-1,""),"") | W16: =IF(AND(ISNUMBER(W14),ISNUMBER(V14)),IFERROR(W14/V14-1,""),"") | Y16: =IF(AND(ISNUMBER(Y14),ISNUMBER(W14)),IFERROR(Y14/W14-1,""),"") | Z16: =IF(AND(ISNUMBER(Z14),ISNUMBER(Y14)),IFERROR(Z14/Y14-1,""),"") | AA16: =IF(AND(ISNUMBER(AA14),ISNUMBER(Z14)),IFERROR(AA14/Z14-1,""),"") | AB16: =IF(AND(ISNUMBER(AB14),ISNUMBER(AA14)),IFERROR(AB14/AA14-1,""),"") | AD16: =IF(AND(ISNUMBER(AD14),ISNUMBER(AB14)),IFERROR(AD14/AB14-1,""),"") | AE16: =IF(AND(ISNUMBER(AE14),ISNUMBER(AD14)),IFERROR(AE14/AD14-1,""),"") | AF16: =IF(AND(ISNUMBER(AF14),ISNUMBER(AE14)),IFERROR(AF14/AE14-1,""),"") | AG16: =IF(AND(ISNUMBER(AG14),ISNUMBER(AF14)),IFERROR(AG14/AF14-1,""),"") | AI16: =IF(AND(ISNUMBER(AI14),ISNUMBER(AG14)),IFERROR(AI14/AG14-1,""),"") | AJ16: =IF(AND(ISNUMBER(AJ14),ISNUMBER(AI14)),IFERROR(AJ14/AI14-1,""),"") | AK16: =IF(AND(ISNUMBER(AK14),ISNUMBER(AJ14)),IFERROR(AK14/AJ14-1,""),"") | AL16: =IF(AND(ISNUMBER(AL14),ISNUMBER(AK14)),IFERROR(AL14/AK14-1,""),"") | AN16: =IF(AND(ISNUMBER(AN14),ISNUMBER(AL14)),IFERROR(AN14/AL14-1,""),"") | AO16: =IF(AND(ISNUMBER(AO14),ISNUMBER(AN14)),IFERROR(AO14/AN14-1,""),"") | AP16: =IF(AND(ISNUMBER(AP14),ISNUMBER(AO14)),IFERROR(AP14/AO14-1,""),"") | AQ16: =IF(AND(ISNUMBER(AQ14),ISNUMBER(AP14)),IFERROR(AQ14/AP14-1,""),"") | AS16: =IF(AND(ISNUMBER(AS14),ISNUMBER(AQ14)),IFERROR(AS14/AQ14-1,""),"") | AT16: =IF(AND(ISNUMBER(AT14),ISNUMBER(AS14)),IFERROR(AT14/AS14-1,""),"") -> 0.0027777778 | AU16: =IF(AND(ISNUMBER(AU14),ISNUMBER(AT14)),IFERROR(AU14/AT14-1,""),"") -> 0.040720222 | AV16: =IF(AND(ISNUMBER(AV14),ISNUMBER(AU14)),IFERROR(AV14/AU14-1,""),"") -> 0.06913761 | AX16: =IF(AND(ISNUMBER(AX14),ISNUMBER(AV14)),IFERROR(AX14/AV14-1,""),"") -> 0.021348105 | AY16: =IF(AND(ISNUMBER(AY14),ISNUMBER(AX14)),IFERROR(AY14/AX14-1,""),"") -> 0.037883404 | AZ16: =IF(AND(ISNUMBER(AZ14),ISNUMBER(AY14)),IFERROR(AZ14/AY14-1,""),"") -> 0.028026226 | BA16: =IF(AND(ISNUMBER(BA14),ISNUMBER(AZ14)),IFERROR(BA14/AZ14-1,""),"") -> 0.04058865 | BC16: =IF(AND(ISNUMBER(BC14),ISNUMBER(BA14)),IFERROR(BC14/BA14-1,""),"") -> -0.0038785927 | BD16: =IF(AND(ISNUMBER(BD14),ISNUMBER(BC14)),IFERROR(BD14/BC14-1,""),"") -> 0.033977997 | BE16: =IF(AND(ISNUMBER(BE14),ISNUMBER(BD14)),IFERROR(BE14/BD14-1,""),"") -> 0.046254685 | BF16: =IF(AND(ISNUMBER(BF14),ISNUMBER(BE14)),IFERROR(BF14/BE14-1,""),"") -> 0.040661449 | BH16: =IF(AND(ISNUMBER(BH14),ISNUMBER(BF14)),IFERROR(BH14/BF14-1,""),"") -> 0.02779953 | BI16: =IF(AND(ISNUMBER(BI14),ISNUMBER(BH14)),IFERROR(BI14/BH14-1,""),"") -> 0.047619048 | BJ16: =IF(AND(ISNUMBER(BJ14),ISNUMBER(BI14)),IFERROR(BJ14/BI14-1,""),"") -> 0.03030303 | BK16: =IF(AND(ISNUMBER(BK14),ISNUMBER(BJ14)),IFERROR(BK14/BJ14-1,""),"") -> 0.014705882 | BM16: =IF(AND(ISNUMBER(BM14),ISNUMBER(BK14)),IFERROR(BM14/BK14-1,""),"") -> 0 | BN16: =IF(AND(ISNUMBER(BN14),ISNUMBER(BM14)),IFERROR(BN14/BM14-1,""),"") -> 0.014492754 | BO16: =IF(AND(ISNUMBER(BO14),ISNUMBER(BN14)),IFERROR(BO14/BN14-1,""),"") -> 0.014285714 | BP16: =IF(AND(ISNUMBER(BP14),ISNUMBER(BO14)),IFERROR(BP14/BO14-1,""),"") -> 0.014084507 | BR16: =IF(AND(ISNUMBER(BR14),ISNUMBER(BP14)),IFERROR(BR14/BP14-1,""),"") -> 0.013888889 | BS16: =IF(AND(ISNUMBER(BS14),ISNUMBER(BR14)),IFERROR(BS14/BR14-1,""),"") -> 0.04109589 | BT16: =IF(AND(ISNUMBER(BT14),ISNUMBER(BS14)),IFERROR(BT14/BS14-1,""),"") -> 0.039473684 | BU16: =IF(AND(ISNUMBER(BU14),ISNUMBER(BT14)),IFERROR(BU14/BT14-1,""),"") -> 0.063291139 | BW16: =IF(AND(ISNUMBER(BW14),ISNUMBER(BU14)),IFERROR(BW14/BU14-1,""),"") -> 0.011904762 | BX16: =IF(AND(ISNUMBER(BX14),ISNUMBER(BW14)),IFERROR(BX14/BW14-1,""),"") -> 0.023529412 | BY16: =((BW14/BU14-1)+(BX14/BW14-1))/2 -> 0.017717087 | BZ16: =BY16 -> 0.017717087 | CN16: FY26 Commercial Real Estate Adjusted EBITDA ($m) | CO16: 690 | CP16: 680 | CQ16: 670 | CR16: Segment guidance (Q2-26 release) — drives the CRE margin calibration.
B17: Other Commercial Real Estate (Matterport from Feb-25, STR, Ten-X, BizBuySell, Realla) | BH17: 18 | BI17: 19 | BJ17: 20 | BK17: 24 | BL17: =SUM(BH17,BI17,BJ17,BK17) -> 81 | BM17: 17 | BN17: 18 | BO17: 19 | BP17: 22 | BQ17: 77 | BR17: 31 | BS17: 60 | BT17: 64 | BU17: 62 | BV17: 216 | BW17: 56 | BX17: 57 | BY17: =BX17*(1+BY19+BY92) -> 55.217045 | BZ17: =BX17*((1+BZ19)^2+2*BZ92) -> 53.522838 | CA17: =SUM(BW17,BX17,BY17,BZ17) -> 221.73988 | CB17: =CA17*(1+CB18) -> 232.82688 | CC17: =CB17*(1+CC18) -> 244.46822 | CD17: =CC17*(1+CD18) -> 256.69163 | CE17: =CD17*(1+CE18) -> 269.52621 | CF17: As CoStar. 2027E+: scenario lever OCRE_growth. Q1/25 → Q2/25 step-up = Matterport (closed 28-Feb-2025). | CH17: =IFERROR((CE17/BV17)^(1/5)-1,"n/m") -> 0.045272325 | CI17: =IFERROR((BV17/AW17)^(1/5)-1,"n/m") -> n/m | CJ17: =IFERROR((BV17/X17)^(1/10)-1,"n/m") -> n/m | CK17: =IFERROR((BV17/C17)^(1/19)-1,"n/m") -> n/m | CN17: FY26 Residential Real Estate Adjusted EBITDA ($m) | CO17: 130 | CP17: 120 | CQ17: 110 | CR17: Segment guidance — drives the Residential margin calibration. CRE + Residential = consolidated guide.
B18: y/y % | D18: =IF(AND(ISNUMBER(D17),ISNUMBER(C17)),IFERROR(D17/C17-1,""),"") | E18: =IF(AND(ISNUMBER(E17),ISNUMBER(D17)),IFERROR(E17/D17-1,""),"") | F18: =IF(AND(ISNUMBER(F17),ISNUMBER(E17)),IFERROR(F17/E17-1,""),"") | G18: =IF(AND(ISNUMBER(G17),ISNUMBER(F17)),IFERROR(G17/F17-1,""),"") | H18: =IF(AND(ISNUMBER(H17),ISNUMBER(G17)),IFERROR(H17/G17-1,""),"") | I18: =IF(AND(ISNUMBER(I17),ISNUMBER(H17)),IFERROR(I17/H17-1,""),"") | N18: =IF(AND(ISNUMBER(N17),ISNUMBER(I17)),IFERROR(N17/I17-1,""),"") | O18: =IF(AND(ISNUMBER(O17),ISNUMBER(J17)),IFERROR(O17/J17-1,""),"") | P18: =IF(AND(ISNUMBER(P17),ISNUMBER(K17)),IFERROR(P17/K17-1,""),"") | Q18: =IF(AND(ISNUMBER(Q17),ISNUMBER(L17)),IFERROR(Q17/L17-1,""),"") | R18: =IF(AND(ISNUMBER(R17),ISNUMBER(M17)),IFERROR(R17/M17-1,""),"") | S18: =IF(AND(ISNUMBER(S17),ISNUMBER(N17)),IFERROR(S17/N17-1,""),"") | T18: =IF(AND(ISNUMBER(T17),ISNUMBER(O17)),IFERROR(T17/O17-1,""),"") | U18: =IF(AND(ISNUMBER(U17),ISNUMBER(P17)),IFERROR(U17/P17-1,""),"") | ... BZ18: =IF(AND(ISNUMBER(BZ17),ISNUMBER(BU17)),IFERROR(BZ17/BU17-1,""),"") -> -0.13672841 | CA18: =IFERROR(CA17/BV17-1,"") -> 0.026573536 | CB18: =CHOOSE(MATCH($CF$2,{"Bull","Base","Bear"},0),$CO$56,$CP$56,$CQ$56) -> 0.05 | CC18: =CHOOSE(MATCH($CF$2,{"Bull","Base","Bear"},0),$CO$57,$CP$57,$CQ$57) -> 0.05 | CD18: =CHOOSE(MATCH($CF$2,{"Bull","Base","Bear"},0),$CO$58,$CP$58,$CQ$58) -> 0.05 | CE18: =CHOOSE(MATCH($CF$2,{"Bull","Base","Bear"},0),$CO$59,$CP$59,$CQ$59) -> 0.05 | CN18: FY26 point estimates (all cases; Q2-26 guidance reconciliation)
B19: Sequential q/q % (Q3/Q4-26E: 1H/26 average q/q before outlook calibration) | K19: =IF(AND(ISNUMBER(K17),ISNUMBER(J17)),IFERROR(K17/J17-1,""),"") | L19: =IF(AND(ISNUMBER(L17),ISNUMBER(K17)),IFERROR(L17/K17-1,""),"") | M19: =IF(AND(ISNUMBER(M17),ISNUMBER(L17)),IFERROR(M17/L17-1,""),"") | O19: =IF(AND(ISNUMBER(O17),ISNUMBER(M17)),IFERROR(O17/M17-1,""),"") | P19: =IF(AND(ISNUMBER(P17),ISNUMBER(O17)),IFERROR(P17/O17-1,""),"") | Q19: =IF(AND(ISNUMBER(Q17),ISNUMBER(P17)),IFERROR(Q17/P17-1,""),"") | R19: =IF(AND(ISNUMBER(R17),ISNUMBER(Q17)),IFERROR(R17/Q17-1,""),"") | T19: =IF(AND(ISNUMBER(T17),ISNUMBER(R17)),IFERROR(T17/R17-1,""),"") | U19: =IF(AND(ISNUMBER(U17),ISNUMBER(T17)),IFERROR(U17/T17-1,""),"") | V19: =IF(AND(ISNUMBER(V17),ISNUMBER(U17)),IFERROR(V17/U17-1,""),"") | W19: =IF(AND(ISNUMBER(W17),ISNUMBER(V17)),IFERROR(W17/V17-1,""),"") | Y19: =IF(AND(ISNUMBER(Y17),ISNUMBER(W17)),IFERROR(Y17/W17-1,""),"") | Z19: =IF(AND(ISNUMBER(Z17),ISNUMBER(Y17)),IFERROR(Z17/Y17-1,""),"") | AA19: =IF(AND(ISNUMBER(AA17),ISNUMBER(Z17)),IFERROR(AA17/Z17-1,""),"") | AB19: =IF(AND(ISNUMBER(AB17),ISNUMBER(AA17)),IFERROR(AB17/AA17-1,""),"") | AD19: =IF(AND(ISNUMBER(AD17),ISNUMBER(AB17)),IFERROR(AD17/AB17-1,""),"") | AE19: =IF(AND(ISNUMBER(AE17),ISNUMBER(AD17)),IFERROR(AE17/AD17-1,""),"") | AF19: =IF(AND(ISNUMBER(AF17),ISNUMBER(AE17)),IFERROR(AF17/AE17-1,""),"") | AG19: =IF(AND(ISNUMBER(AG17),ISNUMBER(AF17)),IFERROR(AG17/AF17-1,""),"") | AI19: =IF(AND(ISNUMBER(AI17),ISNUMBER(AG17)),IFERROR(AI17/AG17-1,""),"") | AJ19: =IF(AND(ISNUMBER(AJ17),ISNUMBER(AI17)),IFERROR(AJ17/AI17-1,""),"") | AK19: =IF(AND(ISNUMBER(AK17),ISNUMBER(AJ17)),IFERROR(AK17/AJ17-1,""),"") | AL19: =IF(AND(ISNUMBER(AL17),ISNUMBER(AK17)),IFERROR(AL17/AK17-1,""),"") | AN19: =IF(AND(ISNUMBER(AN17),ISNUMBER(AL17)),IFERROR(AN17/AL17-1,""),"") | AO19: =IF(AND(ISNUMBER(AO17),ISNUMBER(AN17)),IFERROR(AO17/AN17-1,""),"") | AP19: =IF(AND(ISNUMBER(AP17),ISNUMBER(AO17)),IFERROR(AP17/AO17-1,""),"") | AQ19: =IF(AND(ISNUMBER(AQ17),ISNUMBER(AP17)),IFERROR(AQ17/AP17-1,""),"") | AS19: =IF(AND(ISNUMBER(AS17),ISNUMBER(AQ17)),IFERROR(AS17/AQ17-1,""),"") | AT19: =IF(AND(ISNUMBER(AT17),ISNUMBER(AS17)),IFERROR(AT17/AS17-1,""),"") | AU19: =IF(AND(ISNUMBER(AU17),ISNUMBER(AT17)),IFERROR(AU17/AT17-1,""),"") | AV19: =IF(AND(ISNUMBER(AV17),ISNUMBER(AU17)),IFERROR(AV17/AU17-1,""),"") | AX19: =IF(AND(ISNUMBER(AX17),ISNUMBER(AV17)),IFERROR(AX17/AV17-1,""),"") | AY19: =IF(AND(ISNUMBER(AY17),ISNUMBER(AX17)),IFERROR(AY17/AX17-1,""),"") | AZ19: =IF(AND(ISNUMBER(AZ17),ISNUMBER(AY17)),IFERROR(AZ17/AY17-1,""),"") | BA19: =IF(AND(ISNUMBER(BA17),ISNUMBER(AZ17)),IFERROR(BA17/AZ17-1,""),"") | BC19: =IF(AND(ISNUMBER(BC17),ISNUMBER(BA17)),IFERROR(BC17/BA17-1,""),"") | BD19: =IF(AND(ISNUMBER(BD17),ISNUMBER(BC17)),IFERROR(BD17/BC17-1,""),"") | BE19: =IF(AND(ISNUMBER(BE17),ISNUMBER(BD17)),IFERROR(BE17/BD17-1,""),"") | BF19: =IF(AND(ISNUMBER(BF17),ISNUMBER(BE17)),IFERROR(BF17/BE17-1,""),"") | BH19: =IF(AND(ISNUMBER(BH17),ISNUMBER(BF17)),IFERROR(BH17/BF17-1,""),"") | BI19: =IF(AND(ISNUMBER(BI17),ISNUMBER(BH17)),IFERROR(BI17/BH17-1,""),"") -> 0.055555556 | BJ19: =IF(AND(ISNUMBER(BJ17),ISNUMBER(BI17)),IFERROR(BJ17/BI17-1,""),"") -> 0.052631579 | BK19: =IF(AND(ISNUMBER(BK17),ISNUMBER(BJ17)),IFERROR(BK17/BJ17-1,""),"") -> 0.2 | BM19: =IF(AND(ISNUMBER(BM17),ISNUMBER(BK17)),IFERROR(BM17/BK17-1,""),"") -> -0.29166667 | BN19: =IF(AND(ISNUMBER(BN17),ISNUMBER(BM17)),IFERROR(BN17/BM17-1,""),"") -> 0.058823529 | BO19: =IF(AND(ISNUMBER(BO17),ISNUMBER(BN17)),IFERROR(BO17/BN17-1,""),"") -> 0.055555556 | BP19: =IF(AND(ISNUMBER(BP17),ISNUMBER(BO17)),IFERROR(BP17/BO17-1,""),"") -> 0.15789474 | BR19: =IF(AND(ISNUMBER(BR17),ISNUMBER(BP17)),IFERROR(BR17/BP17-1,""),"") -> 0.40909091 | BS19: =IF(AND(ISNUMBER(BS17),ISNUMBER(BR17)),IFERROR(BS17/BR17-1,""),"") -> 0.93548387 | BT19: =IF(AND(ISNUMBER(BT17),ISNUMBER(BS17)),IFERROR(BT17/BS17-1,""),"") -> 0.066666667 | BU19: =IF(AND(ISNUMBER(BU17),ISNUMBER(BT17)),IFERROR(BU17/BT17-1,""),"") -> -0.03125 | BW19: =IF(AND(ISNUMBER(BW17),ISNUMBER(BU17)),IFERROR(BW17/BU17-1,""),"") -> -0.096774194 | BX19: =IF(AND(ISNUMBER(BX17),ISNUMBER(BW17)),IFERROR(BX17/BW17-1,""),"") -> 0.017857143 | BY19: =((BW17/BU17-1)+(BX17/BW17-1))/2 -> -0.039458525 | BZ19: =BY19 -> -0.039458525 | CN19: Stock-based compensation ($m) | CP19: 156 | CR19: Guidance reconciliation (FY).
B20: Commercial Real Estate — revenues | C20: =IF(ISNUMBER(C17),C11+C14+C17,"") | D20: =IF(ISNUMBER(D17),D11+D14+D17,"") | E20: =IF(ISNUMBER(E17),E11+E14+E17,"") | F20: =IF(ISNUMBER(F17),F11+F14+F17,"") | G20: =IF(ISNUMBER(G17),G11+G14+G17,"") | H20: =IF(ISNUMBER(H17),H11+H14+H17,"") | I20: =IF(ISNUMBER(I17),I11+I14+I17,"") | J20: =IF(ISNUMBER(J17),J11+J14+J17,"") | ... BX20: =IF(ISNUMBER(BX17),BX11+BX14+BX17,"") -> 481 | BY20: =BY11+BY14+BY17 -> 490.39132 | BZ20: =BZ11+BZ14+BZ17 -> 500.01148 | CA20: =CA11+CA14+CA17 -> 1943.4028 | CB20: =CB11+CB14+CB17 -> 2120.023 | CC20: =CC11+CC14+CC17 -> 2309.4144 | CD20: =CD11+CD14+CD17 -> 2503.737 | CE20: =CE11+CE14+CE17 -> 2701.1597 | CH20: =IFERROR((CE20/BV20)^(1/5)-1,"n/m") -> 0.086138331 | CI20: =IFERROR((BV20/AW20)^(1/5)-1,"n/m") -> n/m | CJ20: =IFERROR((BV20/X20)^(1/10)-1,"n/m") -> n/m | CK20: =IFERROR((BV20/C20)^(1/19)-1,"n/m") -> n/m | CN20: Amortization of acquired intangible assets ($m) | CP20: 251 | CR20: $108m in cost of revenues + $143m in operating expenses.
B21: y/y % | D21: =IF(AND(ISNUMBER(D20),ISNUMBER(C20)),IFERROR(D20/C20-1,""),"") | E21: =IF(AND(ISNUMBER(E20),ISNUMBER(D20)),IFERROR(E20/D20-1,""),"") | F21: =IF(AND(ISNUMBER(F20),ISNUMBER(E20)),IFERROR(F20/E20-1,""),"") | G21: =IF(AND(ISNUMBER(G20),ISNUMBER(F20)),IFERROR(G20/F20-1,""),"") | H21: =IF(AND(ISNUMBER(H20),ISNUMBER(G20)),IFERROR(H20/G20-1,""),"") | I21: =IF(AND(ISNUMBER(I20),ISNUMBER(H20)),IFERROR(I20/H20-1,""),"") | N21: =IF(AND(ISNUMBER(N20),ISNUMBER(I20)),IFERROR(N20/I20-1,""),"") | O21: =IF(AND(ISNUMBER(O20),ISNUMBER(J20)),IFERROR(O20/J20-1,""),"") | P21: =IF(AND(ISNUMBER(P20),ISNUMBER(K20)),IFERROR(P20/K20-1,""),"") | Q21: =IF(AND(ISNUMBER(Q20),ISNUMBER(L20)),IFERROR(Q20/L20-1,""),"") | R21: =IF(AND(ISNUMBER(R20),ISNUMBER(M20)),IFERROR(R20/M20-1,""),"") | S21: =IF(AND(ISNUMBER(S20),ISNUMBER(N20)),IFERROR(S20/N20-1,""),"") | T21: =IF(AND(ISNUMBER(T20),ISNUMBER(O20)),IFERROR(T20/O20-1,""),"") | U21: =IF(AND(ISNUMBER(U20),ISNUMBER(P20)),IFERROR(U20/P20-1,""),"") | ... CA21: =IF(AND(ISNUMBER(CA20),ISNUMBER(BV20)),IFERROR(CA20/BV20-1,""),"") -> 0.087522548 | CB21: =IF(AND(ISNUMBER(CB20),ISNUMBER(CA20)),IFERROR(CB20/CA20-1,""),"") -> 0.090881952 | CC21: =IF(AND(ISNUMBER(CC20),ISNUMBER(CB20)),IFERROR(CC20/CB20-1,""),"") -> 0.089334598 | CD21: =IF(AND(ISNUMBER(CD20),ISNUMBER(CC20)),IFERROR(CD20/CC20-1,""),"") -> 0.084143665 | CE21: =IF(AND(ISNUMBER(CE20),ISNUMBER(CD20)),IFERROR(CE20/CD20-1,""),"") -> 0.078851186 | CN21: Depreciation & other amortization ($m) | CP21: 77
B22: Commercial Real Estate — Adjusted EBITDA (segment) | BM22: 143 | BN22: 144 | BO22: 153 | BP22: 162 | BQ22: 602 | BR22: 151 | BS22: 161 | BT22: 183 | BU22: 177 | BV22: 672 | BW22: 161 | BX22: 172 | BY22: =BY20*BY24 -> 177.05518 | BZ22: =BZ20*BZ24 -> 169.94482 | CA22: =SUM(BW22,BX22,BY22,BZ22) -> 680 | CB22: =CB20*CB24 -> 773.80841 | CC22: =CC20*CC24 -> 866.03041 | CD22: =CD20*CD24 -> 963.93876 | CE22: =CE20*CE24 -> 1066.9581 | CH22: =IFERROR((CE22/BV22)^(1/5)-1,"n/m") -> 0.096871155 | CI22: =IFERROR((BV22/AW22)^(1/5)-1,"n/m") -> n/m | CJ22: =IFERROR((BV22/X22)^(1/10)-1,"n/m") -> n/m | CK22: =IFERROR((BV22/C22)^(1/19)-1,"n/m") -> n/m | CN22: Interest income, net ($m) | CP22: 13 | CR22: Pre-Zonda cash balance (deal closed after guidance).
B23: Adjusted EBITDA margin before outlook calibration % (Q3/Q4-26E helper) | BY23: =BT24+(BW22+BX22)/(BW20+BX20)-(BR22+BS22)/(BR20+BS20) -> 0.38147372 | BZ23: =BU24+(BW22+BX22)/(BW20+BX20)-(BR22+BS22)/(BR20+BS20) -> 0.36030677 | CF23: Prior-year quarter margin + (1H/26 − 1H/25 margin drift). | CN23: Other expense, net ($m) | CP23: 3
B24: Adjusted EBITDA margin % | C24: =IF(AND(ISNUMBER(C22),ISNUMBER(C20)),IFERROR(C22/C20,""),"") | D24: =IF(AND(ISNUMBER(D22),ISNUMBER(D20)),IFERROR(D22/D20,""),"") | E24: =IF(AND(ISNUMBER(E22),ISNUMBER(E20)),IFERROR(E22/E20,""),"") | F24: =IF(AND(ISNUMBER(F22),ISNUMBER(F20)),IFERROR(F22/F20,""),"") | G24: =IF(AND(ISNUMBER(G22),ISNUMBER(G20)),IFERROR(G22/G20,""),"") | H24: =IF(AND(ISNUMBER(H22),ISNUMBER(H20)),IFERROR(H22/H20,""),"") | I24: =IF(AND(ISNUMBER(I22),ISNUMBER(I20)),IFERROR(I22/I20,""),"") | J24: =IF(AND(ISNUMBER(J22),ISNUMBER(J20)),IFERROR(J22/J20,""),"") | ... BX24: =IF(AND(ISNUMBER(BX22),ISNUMBER(BX20)),IFERROR(BX22/BX20,""),"") -> 0.35758836 | BY24: =BY23+$BY97 -> 0.36104878 | BZ24: =BZ23+$BY97 -> 0.33988183 | CA24: =IF(AND(ISNUMBER(CA22),ISNUMBER(CA20)),IFERROR(CA22/CA20,""),"") -> 0.34990173 | CB24: =CHOOSE(MATCH($CF$2,{"Bull","Base","Bear"},0),$CO$66,$CP$66,$CQ$66) -> 0.365 | CC24: =CHOOSE(MATCH($CF$2,{"Bull","Base","Bear"},0),$CO$67,$CP$67,$CQ$67) -> 0.375 | CD24: =CHOOSE(MATCH($CF$2,{"Bull","Base","Bear"},0),$CO$68,$CP$68,$CQ$68) -> 0.385 | CE24: =CHOOSE(MATCH($CF$2,{"Bull","Base","Bear"},0),$CO$69,$CP$69,$CQ$69) -> 0.395 | CF24: Q3/Q4-26E: margin before calibration + CRE outlook calibration Δ (Group block; to segment guidance). 2027E+: scenario lever CRE_margin. | CH24: =IFERROR(AVERAGE(CA24,CB24,CC24,CD24,CE24),"n/m") -> 0.37398035 | CI24: =IFERROR(AVERAGE(BB24,BG24,BL24,BQ24,BV24),"n/m") -> 0.38670449 | CJ24: =IFERROR(AVERAGE(AC24,AH24,AM24,AR24,AW24,BB24,BG24,BL24,BQ24,BV24),"n/m") -> 0.38670449 | CK24: =IFERROR(AVERAGE(C24,D24,E24,F24,G24,H24,I24,N24,S24,X24,AC24,AH24,AM24,AR24,AW24,BB24,BG24,BL24,BQ24,BV24),"n/m") -> 0.38670449 | CN24: Income tax expense ($m, mid-point) | CP24: 92.5 | CR24: $87–98m.
B25: Memo: Commercial Real Estate — EBITDA (segment, as reported) | BM25: 126 | BN25: 125 | BO25: 136 | BP25: 132 | BQ25: 519 | BR25: 103 | BS25: 118 | BT25: 114 | BU25: 145 | BV25: 480 | BW25: 127 | BX25: 162 | CN25: GAAP tax rate (implied) | CP25: =CP24/(CP14+CP24) -> 0.28461538 | CR25: Tax $92.5m / pre-tax $325m = 28.5%.
CN26: Acquisition & integration related costs ($m) | CP26: 15 | CR26: Excludes Zonda closing costs (estimated separately in the Zonda block).
B27: Residential Real Estate (Apartments.com network · Homes.com · Domain from Aug-25 · OnTheMarket · Land.com) — excludes Zonda | CF27: RESIDENTIAL REAL ESTATE — modelling logic | CN27: Restructuring & related costs ($m) | CP27: 4
B28: Residential Real Estate — revenues (legacy, ex-Zonda) | BH28: 236 | BI28: 250 | BJ28: 259 | BK28: 267 | BL28: =SUM(BH28,BI28,BJ28,BK28) -> 1012 | BM28: 287 | BN28: 304 | BO28: 313 | BP28: 318 | BQ28: 1221 | BR28: 323 | BS28: 335 | BT28: 373 | BU28: 429 | BV28: 1460 | BW28: 425 | BX28: 444 | BY28: =BX28*(1+BY30+BY92) -> 455.48608 | BZ28: =BX28*((1+BZ30)^2+2*BZ92) -> 467.11112 | CA28: =SUM(BW28,BX28,BY28,BZ28) -> 1791.5972 | CB28: =CA28*(1+CB29) -> 2006.5889 | CC28: =CB28*(1+CC29) -> 2227.3136 | CD28: =CC28*(1+CD29) -> 2450.045 | CE28: =CD28*(1+CE29) -> 2670.5491 | CF28: Q3/Q4-26E as CoStar (sequential). 2027E+: scenario lever RESI_growth. Q3/26 y/y growth flatters as Domain (Aug-25) anniversaries. | CH28: =IFERROR((CE28/BV28)^(1/5)-1,"n/m") -> 0.12836483 | CI28: =IFERROR((BV28/AW28)^(1/5)-1,"n/m") -> n/m | CJ28: =IFERROR((BV28/X28)^(1/10)-1,"n/m") -> n/m | CK28: =IFERROR((BV28/C28)^(1/19)-1,"n/m") -> n/m | CN28: Settlements & impairments ($m) | CP28: -18 | CR28: Q2-26 credit (litigation accrual release).
B29: y/y % | D29: =IF(AND(ISNUMBER(D28),ISNUMBER(C28)),IFERROR(D28/C28-1,""),"") | E29: =IF(AND(ISNUMBER(E28),ISNUMBER(D28)),IFERROR(E28/D28-1,""),"") | F29: =IF(AND(ISNUMBER(F28),ISNUMBER(E28)),IFERROR(F28/E28-1,""),"") | G29: =IF(AND(ISNUMBER(G28),ISNUMBER(F28)),IFERROR(G28/F28-1,""),"") | H29: =IF(AND(ISNUMBER(H28),ISNUMBER(G28)),IFERROR(H28/G28-1,""),"") | I29: =IF(AND(ISNUMBER(I28),ISNUMBER(H28)),IFERROR(I28/H28-1,""),"") | N29: =IF(AND(ISNUMBER(N28),ISNUMBER(I28)),IFERROR(N28/I28-1,""),"") | O29: =IF(AND(ISNUMBER(O28),ISNUMBER(J28)),IFERROR(O28/J28-1,""),"") | P29: =IF(AND(ISNUMBER(P28),ISNUMBER(K28)),IFERROR(P28/K28-1,""),"") | Q29: =IF(AND(ISNUMBER(Q28),ISNUMBER(L28)),IFERROR(Q28/L28-1,""),"") | R29: =IF(AND(ISNUMBER(R28),ISNUMBER(M28)),IFERROR(R28/M28-1,""),"") | S29: =IF(AND(ISNUMBER(S28),ISNUMBER(N28)),IFERROR(S28/N28-1,""),"") | T29: =IF(AND(ISNUMBER(T28),ISNUMBER(O28)),IFERROR(T28/O28-1,""),"") | U29: =IF(AND(ISNUMBER(U28),ISNUMBER(P28)),IFERROR(U28/P28-1,""),"") | ... BZ29: =IF(AND(ISNUMBER(BZ28),ISNUMBER(BU28)),IFERROR(BZ28/BU28-1,""),"") -> 0.088837119 | CA29: =IFERROR(CA28/BV28-1,"") -> 0.22712137 | CB29: =CHOOSE(MATCH($CF$2,{"Bull","Base","Bear"},0),$CO$61,$CP$61,$CQ$61) -> 0.12 | CC29: =CHOOSE(MATCH($CF$2,{"Bull","Base","Bear"},0),$CO$62,$CP$62,$CQ$62) -> 0.11 | CD29: =CHOOSE(MATCH($CF$2,{"Bull","Base","Bear"},0),$CO$63,$CP$63,$CQ$63) -> 0.1 | CE29: =CHOOSE(MATCH($CF$2,{"Bull","Base","Bear"},0),$CO$64,$CP$64,$CQ$64) -> 0.09 | CN29: Adjusted diluted shares (m) | CP29: 405
B30: Sequential q/q % (Q3/Q4-26E: 1H/26 average q/q before outlook calibration) | K30: =IF(AND(ISNUMBER(K28),ISNUMBER(J28)),IFERROR(K28/J28-1,""),"") | L30: =IF(AND(ISNUMBER(L28),ISNUMBER(K28)),IFERROR(L28/K28-1,""),"") | M30: =IF(AND(ISNUMBER(M28),ISNUMBER(L28)),IFERROR(M28/L28-1,""),"") | O30: =IF(AND(ISNUMBER(O28),ISNUMBER(M28)),IFERROR(O28/M28-1,""),"") | P30: =IF(AND(ISNUMBER(P28),ISNUMBER(O28)),IFERROR(P28/O28-1,""),"") | Q30: =IF(AND(ISNUMBER(Q28),ISNUMBER(P28)),IFERROR(Q28/P28-1,""),"") | R30: =IF(AND(ISNUMBER(R28),ISNUMBER(Q28)),IFERROR(R28/Q28-1,""),"") | T30: =IF(AND(ISNUMBER(T28),ISNUMBER(R28)),IFERROR(T28/R28-1,""),"") | U30: =IF(AND(ISNUMBER(U28),ISNUMBER(T28)),IFERROR(U28/T28-1,""),"") | V30: =IF(AND(ISNUMBER(V28),ISNUMBER(U28)),IFERROR(V28/U28-1,""),"") | W30: =IF(AND(ISNUMBER(W28),ISNUMBER(V28)),IFERROR(W28/V28-1,""),"") | Y30: =IF(AND(ISNUMBER(Y28),ISNUMBER(W28)),IFERROR(Y28/W28-1,""),"") | Z30: =IF(AND(ISNUMBER(Z28),ISNUMBER(Y28)),IFERROR(Z28/Y28-1,""),"") | AA30: =IF(AND(ISNUMBER(AA28),ISNUMBER(Z28)),IFERROR(AA28/Z28-1,""),"") | AB30: =IF(AND(ISNUMBER(AB28),ISNUMBER(AA28)),IFERROR(AB28/AA28-1,""),"") | AD30: =IF(AND(ISNUMBER(AD28),ISNUMBER(AB28)),IFERROR(AD28/AB28-1,""),"") | AE30: =IF(AND(ISNUMBER(AE28),ISNUMBER(AD28)),IFERROR(AE28/AD28-1,""),"") | AF30: =IF(AND(ISNUMBER(AF28),ISNUMBER(AE28)),IFERROR(AF28/AE28-1,""),"") | AG30: =IF(AND(ISNUMBER(AG28),ISNUMBER(AF28)),IFERROR(AG28/AF28-1,""),"") | AI30: =IF(AND(ISNUMBER(AI28),ISNUMBER(AG28)),IFERROR(AI28/AG28-1,""),"") | AJ30: =IF(AND(ISNUMBER(AJ28),ISNUMBER(AI28)),IFERROR(AJ28/AI28-1,""),"") | AK30: =IF(AND(ISNUMBER(AK28),ISNUMBER(AJ28)),IFERROR(AK28/AJ28-1,""),"") | AL30: =IF(AND(ISNUMBER(AL28),ISNUMBER(AK28)),IFERROR(AL28/AK28-1,""),"") | AN30: =IF(AND(ISNUMBER(AN28),ISNUMBER(AL28)),IFERROR(AN28/AL28-1,""),"") | AO30: =IF(AND(ISNUMBER(AO28),ISNUMBER(AN28)),IFERROR(AO28/AN28-1,""),"") | AP30: =IF(AND(ISNUMBER(AP28),ISNUMBER(AO28)),IFERROR(AP28/AO28-1,""),"") | AQ30: =IF(AND(ISNUMBER(AQ28),ISNUMBER(AP28)),IFERROR(AQ28/AP28-1,""),"") | AS30: =IF(AND(ISNUMBER(AS28),ISNUMBER(AQ28)),IFERROR(AS28/AQ28-1,""),"") | AT30: =IF(AND(ISNUMBER(AT28),ISNUMBER(AS28)),IFERROR(AT28/AS28-1,""),"") | AU30: =IF(AND(ISNUMBER(AU28),ISNUMBER(AT28)),IFERROR(AU28/AT28-1,""),"") | AV30: =IF(AND(ISNUMBER(AV28),ISNUMBER(AU28)),IFERROR(AV28/AU28-1,""),"") | AX30: =IF(AND(ISNUMBER(AX28),ISNUMBER(AV28)),IFERROR(AX28/AV28-1,""),"") | AY30: =IF(AND(ISNUMBER(AY28),ISNUMBER(AX28)),IFERROR(AY28/AX28-1,""),"") | AZ30: =IF(AND(ISNUMBER(AZ28),ISNUMBER(AY28)),IFERROR(AZ28/AY28-1,""),"") | BA30: =IF(AND(ISNUMBER(BA28),ISNUMBER(AZ28)),IFERROR(BA28/AZ28-1,""),"") | BC30: =IF(AND(ISNUMBER(BC28),ISNUMBER(BA28)),IFERROR(BC28/BA28-1,""),"") | BD30: =IF(AND(ISNUMBER(BD28),ISNUMBER(BC28)),IFERROR(BD28/BC28-1,""),"") | BE30: =IF(AND(ISNUMBER(BE28),ISNUMBER(BD28)),IFERROR(BE28/BD28-1,""),"") | BF30: =IF(AND(ISNUMBER(BF28),ISNUMBER(BE28)),IFERROR(BF28/BE28-1,""),"") | BH30: =IF(AND(ISNUMBER(BH28),ISNUMBER(BF28)),IFERROR(BH28/BF28-1,""),"") | BI30: =IF(AND(ISNUMBER(BI28),ISNUMBER(BH28)),IFERROR(BI28/BH28-1,""),"") -> 0.059322034 | BJ30: =IF(AND(ISNUMBER(BJ28),ISNUMBER(BI28)),IFERROR(BJ28/BI28-1,""),"") -> 0.036 | BK30: =IF(AND(ISNUMBER(BK28),ISNUMBER(BJ28)),IFERROR(BK28/BJ28-1,""),"") -> 0.030888031 | BM30: =IF(AND(ISNUMBER(BM28),ISNUMBER(BK28)),IFERROR(BM28/BK28-1,""),"") -> 0.074906367 | BN30: =IF(AND(ISNUMBER(BN28),ISNUMBER(BM28)),IFERROR(BN28/BM28-1,""),"") -> 0.059233449 | BO30: =IF(AND(ISNUMBER(BO28),ISNUMBER(BN28)),IFERROR(BO28/BN28-1,""),"") -> 0.029605263 | BP30: =IF(AND(ISNUMBER(BP28),ISNUMBER(BO28)),IFERROR(BP28/BO28-1,""),"") -> 0.015974441 | BR30: =IF(AND(ISNUMBER(BR28),ISNUMBER(BP28)),IFERROR(BR28/BP28-1,""),"") -> 0.01572327 | BS30: =IF(AND(ISNUMBER(BS28),ISNUMBER(BR28)),IFERROR(BS28/BR28-1,""),"") -> 0.037151703 | BT30: =IF(AND(ISNUMBER(BT28),ISNUMBER(BS28)),IFERROR(BT28/BS28-1,""),"") -> 0.11343284 | BU30: =IF(AND(ISNUMBER(BU28),ISNUMBER(BT28)),IFERROR(BU28/BT28-1,""),"") -> 0.15013405 | BW30: =IF(AND(ISNUMBER(BW28),ISNUMBER(BU28)),IFERROR(BW28/BU28-1,""),"") -> -0.0093240093 | BX30: =IF(AND(ISNUMBER(BX28),ISNUMBER(BW28)),IFERROR(BX28/BW28-1,""),"") -> 0.044705882 | BY30: =((BW28/BU28-1)+(BX28/BW28-1))/2 -> 0.017690937 | BZ30: =BY30 -> 0.017690937 | CN30: Q3/26 guidance (memo; mid-point used for SBC, D&A, amortization, interest, other, acquisition costs) | CO30: High | CP30: Mid | CQ30: Low
B31: Residential Real Estate — Adjusted EBITDA (segment, ex-Zonda) | BM31: -131 | BN31: -103 | BO31: -77 | BP31: -50 | BQ31: -361 | BR31: -85 | BS31: -76 | BT31: -69 | BU31: 0 | BV31: -230 | BW31: -29 | BX31: 12 | BY31: =BY28*BY33 -> 24.976622 | BZ31: =BZ28*BZ33 -> 112.02338 | CA31: =SUM(BW31,BX31,BY31,BZ31) -> 120 | CB31: =CB28*CB33 -> 180.593 | CC31: =CC28*CC33 -> 311.82391 | CD31: =CD28*CD33 -> 465.50855 | CE31: =CE28*CE33 -> 640.93178 | CH31: =IFERROR((CE31/BV31)^(1/5)-1,"n/m") -> -2.2274867 | CI31: =IFERROR((BV31/AW31)^(1/5)-1,"n/m") -> n/m | CJ31: =IFERROR((BV31/X31)^(1/10)-1,"n/m") -> n/m | CK31: =IFERROR((BV31/C31)^(1/19)-1,"n/m") -> n/m | CN31: Q3/26 revenues ($m) | CO31: 945 | CP31: 940 | CQ31: 935 | CR31: Memo check only — FY calibration drives the Q3/Q4 split.
B32: Adjusted EBITDA margin before outlook calibration % (Q3/Q4-26E helper) | BY32: =BT33+(BW31+BX31)/(BW28+BX28)-(BR31+BS31)/(BR28+BS28) -> 0.04013154 | BZ32: =BU33+(BW31+BX31)/(BW28+BX28)-(BR31+BS31)/(BR28+BS28) -> 0.22511814 | CF32: Prior-year quarter margin + 1H margin drift (+22pp: Homes.com marketing cut). Q4 seasonally strongest (lower marketing). | CN32: Q3/26 Adjusted EBITDA ($m) | CO32: 210 | CP32: 200 | CQ32: 190 | CR32: Memo check only.
B33: Adjusted EBITDA margin % | C33: =IF(AND(ISNUMBER(C31),ISNUMBER(C28)),IFERROR(C31/C28,""),"") | D33: =IF(AND(ISNUMBER(D31),ISNUMBER(D28)),IFERROR(D31/D28,""),"") | E33: =IF(AND(ISNUMBER(E31),ISNUMBER(E28)),IFERROR(E31/E28,""),"") | F33: =IF(AND(ISNUMBER(F31),ISNUMBER(F28)),IFERROR(F31/F28,""),"") | G33: =IF(AND(ISNUMBER(G31),ISNUMBER(G28)),IFERROR(G31/G28,""),"") | H33: =IF(AND(ISNUMBER(H31),ISNUMBER(H28)),IFERROR(H31/H28,""),"") | I33: =IF(AND(ISNUMBER(I31),ISNUMBER(I28)),IFERROR(I31/I28,""),"") | J33: =IF(AND(ISNUMBER(J31),ISNUMBER(J28)),IFERROR(J31/J28,""),"") | ... BX33: =IF(AND(ISNUMBER(BX31),ISNUMBER(BX28)),IFERROR(BX31/BX28,""),"") -> 0.027027027 | BY33: =BY32+$BZ97 -> 0.054835093 | BZ33: =BZ32+$BZ97 -> 0.23982169 | CA33: =IF(AND(ISNUMBER(CA31),ISNUMBER(CA28)),IFERROR(CA31/CA28,""),"") -> 0.066979341 | CB33: =CHOOSE(MATCH($CF$2,{"Bull","Base","Bear"},0),$CO$71,$CP$71,$CQ$71) -> 0.09 | CC33: =CHOOSE(MATCH($CF$2,{"Bull","Base","Bear"},0),$CO$72,$CP$72,$CQ$72) -> 0.14 | CD33: =CHOOSE(MATCH($CF$2,{"Bull","Base","Bear"},0),$CO$73,$CP$73,$CQ$73) -> 0.19 | CE33: =CHOOSE(MATCH($CF$2,{"Bull","Base","Bear"},0),$CO$74,$CP$74,$CQ$74) -> 0.24 | CF33: 2027E+: scenario lever RESI_margin (Homes.com net investment −$100m+ p.a.; Adjusted EBITDA positive 2030 per company). | CH33: =IFERROR(AVERAGE(CA33,CB33,CC33,CD33,CE33),"n/m") -> 0.14539587 | CI33: =IFERROR(AVERAGE(BB33,BG33,BL33,BQ33,BV33),"n/m") -> -0.22659677 | CJ33: =IFERROR(AVERAGE(AC33,AH33,AM33,AR33,AW33,BB33,BG33,BL33,BQ33,BV33),"n/m") -> -0.22659677 | CK33: =IFERROR(AVERAGE(C33,D33,E33,F33,G33,H33,I33,N33,S33,X33,AC33,AH33,AM33,AR33,AW33,BB33,BG33,BL33,BQ33,BV33),"n/m") -> -0.22659677 | CN33: Q3/26 stock-based compensation ($m) | CP33: 34
B34: Memo: Residential Real Estate — EBITDA (segment, as reported) | BM34: -139 | BN34: -113 | BO34: -85 | BP34: -59 | BQ34: -396 | BR34: -104 | BS34: -89 | BT34: -101 | BU34: -16 | BV34: -310 | BW34: -46 | BX34: -5 | CN34: Q3/26 amortization of acquired intangibles ($m) | CP34: 62
CN35: Q3/26 depreciation & other amortization ($m) | CP35: 23
B36: Legacy product lines & geographic segments (as originally reported; memo — not forecast) | CF36: LEGACY DISCLOSURE — product lines 2015–Q3/25 (first disclosed Q1/15 comparatives); North America / International segments 2007–Q3/25 | CN36: Q3/26 interest income, net ($m) | CP36: 2
B37: Memo: CoStar Suite / CoStar (Q1/15–Q3/25) | T37: 86.81 | U37: 88.771 | V37: 91.35 | W37: 93.509 | X37: 360.44 | Y37: 97.634 | Z37: 101.074 | AA37: 103.261 | AB37: 106.487 | AC37: 408.456 | AD37: 109.979 | AE37: 113.794 | AF37: 117.314 | AG37: 122.098 | AH37: 463.185 | AI37: 130.361 | AJ37: 133.812 | AK37: 139.084 | AL37: 141.938 | AM37: 545.195 | AN37: 147.701 | AO37: 152.825 | AP37: 156.013 | AQ37: 161.259 | AR37: 617.798 | AS37: 164.956 | AT37: 165.053 | AU37: 165.988 | AV37: 168.738 | AW37: 664.735 | AX37: 172.184 | AY37: 176.979 | AZ37: 183.265 | BA37: 190.393 | BB37: 722.821 | BC37: 198.649 | BD37: 206.566 | BE37: 212.69 | BF37: 219.075 | BG37: 836.98 | BH37: 225.013 | BI37: 229.169 | BJ37: 233.36 | BK37: 237.7 | BL37: 925.2 | BM37: 250.3 | BN37: 253 | BO37: 256.9 | BP37: 260.3 | BQ37: 1020.5 | BR37: 265.1 | BS37: 270.9 | BT37: 277 | CN37: Q3/26 other expense, net ($m) | CP37: 1
B38: Memo: Information Services (Q1/15–Q3/25) | T38: 18.537 | U38: 18.752 | V38: 19.126 | W38: 19.375 | X38: 75.79 | Y38: 19.425 | Z38: 19.425 | AA38: 19.486 | AB38: 18.842 | AC38: 77.178 | AD38: 18.336 | AE38: 18.312 | AF38: 18.716 | AG38: 17.254 | AH38: 72.618 | AI38: 15.06 | AJ38: 15.681 | AK38: 17.535 | AL38: 19.199 | AM38: 67.624 | AN38: 18.85 | AO38: 20.777 | AP38: 19.471 | AQ38: 29.348 | AR38: 88.446 | AS38: 32.382 | AT38: 30.536 | AU38: 33.174 | AV38: 33.978 | AW38: 130.07 | AX38: 34.696 | AY38: 35.157 | AZ38: 35.926 | BA38: 35.876 | BB38: 141.655 | BC38: 37.215 | BD38: 38.502 | BE38: 41.013 | BF38: 40.652 | BG38: 157.382 | BH38: 41.629 | BI38: 41.921 | BJ38: 44.636 | BK38: 42.7 | BL38: 170.9 | BM38: 33 | BN38: 33.4 | BO38: 33 | BP38: 36.5 | BQ38: 135.9 | BR38: 39.8 | BS38: 39.3 | BT38: 41.3 | CN38: Q3/26 acquisition & integration costs ($m) | CP38: 2
B39: Memo: Multifamily — Apartments.com network (Q1/15–Q3/25) | T39: 26.133 | U39: 34.742 | V39: 49.312 | W39: 50.443 | X39: 160.63 | Y39: 52.238 | Z39: 54.86 | AA39: 57.654 | AB39: 60.083 | AC39: 224.835 | AD39: 63.991 | AE39: 68.076 | AF39: 72.257 | AG39: 75.531 | AH39: 279.855 | AI39: 87.683 | AJ39: 104.793 | AK39: 104.778 | AL39: 108.541 | AM39: 405.795 | AN39: 114.268 | AO39: 120.488 | AP39: 125.707 | AQ39: 130.168 | AR39: 490.631 | AS39: 137.46 | AT39: 145.541 | AU39: 155.184 | AV39: 160.37 | AW39: 598.555 | AX39: 166.147 | AY39: 171.357 | AZ39: 171.125 | BA39: 170.051 | BB39: 678.68 | BC39: 175.477 | BD39: 182.359 | BE39: 189.536 | BF39: 198.016 | BG39: 745.388 | BH39: 210.697 | BI39: 224.291 | BJ39: 235.343 | BK39: 243.8 | BL39: 914.2 | BM39: 254.8 | BN39: 264.2 | BO39: 271.8 | BP39: 276.5 | BQ39: 1067.3 | BR39: 282.5 | BS39: 292.3 | BT39: 303 | CH39: =IFERROR((CE39/BV39)^(1/5)-1,"n/m") -> n/m | CI39: =IFERROR((BV39/AW39)^(1/5)-1,"n/m") -> -1 | CJ39: =IFERROR((BV39/X39)^(1/10)-1,"n/m") -> -1 | CK39: =IFERROR((BV39/C39)^(1/19)-1,"n/m") -> n/m | CN39: 2H/26 share repurchases ($m) | CO39: 413 | CP39: 113 | CQ39: 0 | CR39: 2026 plan $700m under the $1.5bn authorization (1H/26: $587m). Bull = $1.0bn for the year.
B40: Multifamily y/y % | D40: =IF(AND(ISNUMBER(D39),ISNUMBER(C39)),IFERROR(D39/C39-1,""),"") | E40: =IF(AND(ISNUMBER(E39),ISNUMBER(D39)),IFERROR(E39/D39-1,""),"") | F40: =IF(AND(ISNUMBER(F39),ISNUMBER(E39)),IFERROR(F39/E39-1,""),"") | G40: =IF(AND(ISNUMBER(G39),ISNUMBER(F39)),IFERROR(G39/F39-1,""),"") | H40: =IF(AND(ISNUMBER(H39),ISNUMBER(G39)),IFERROR(H39/G39-1,""),"") | I40: =IF(AND(ISNUMBER(I39),ISNUMBER(H39)),IFERROR(I39/H39-1,""),"") | N40: =IF(AND(ISNUMBER(N39),ISNUMBER(I39)),IFERROR(N39/I39-1,""),"") | O40: =IF(AND(ISNUMBER(O39),ISNUMBER(J39)),IFERROR(O39/J39-1,""),"") | P40: =IF(AND(ISNUMBER(P39),ISNUMBER(K39)),IFERROR(P39/K39-1,""),"") | Q40: =IF(AND(ISNUMBER(Q39),ISNUMBER(L39)),IFERROR(Q39/L39-1,""),"") | R40: =IF(AND(ISNUMBER(R39),ISNUMBER(M39)),IFERROR(R39/M39-1,""),"") | S40: =IF(AND(ISNUMBER(S39),ISNUMBER(N39)),IFERROR(S39/N39-1,""),"") | T40: =IF(AND(ISNUMBER(T39),ISNUMBER(O39)),IFERROR(T39/O39-1,""),"") | U40: =IF(AND(ISNUMBER(U39),ISNUMBER(P39)),IFERROR(U39/P39-1,""),"") | ... BX40: =IF(AND(ISNUMBER(BX39),ISNUMBER(BS39)),IFERROR(BX39/BS39-1,""),"") | CN40: Minimum net debt / Adjusted EBITDA (x) — buyback floor 2027E+ | CO40: 1 | CP40: 0.5 | CQ40: 0 | CR40: CoStar has historically run net cash; Base lets net debt drift to 0.5x via buybacks.
...

Sheet Bull-Base-Bear
B2: CoStar Group (CSGP) — Bull / Base / Bear Case P&L Summary | J2: Share price ($): | K2: =Model!$CA$388 -> 30.78
B3: Adjusted figures (company current definition: Adjusted EBITDA adds back SBC; Adjusted EPS at a 26% assumed tax rate) · USD | J3: As of: | K3: =TODAY() -> 46301
B5: Scenario: | C5: =Model!$CF$2 -> Base | N5: Scenario: | O5: Bull | P5: Snapshot (values) — Model run with switch = Bull, captured 06-Oct-2026; re-run to refresh | Z5: Scenario: | AA5: Bear | AB5: Snapshot (values) — Model run with switch = Bear, captured 06-Oct-2026; re-run to refresh
B7: (USDm, except EPS and shares) | C7: 2025A | D7: 2026E | E7: 2027E | F7: 2028E | G7: 2029E | H7: 2030E | I7: 25-'30 CAGR | J7: LT Hist Avg | K7: LT Hist Min | L7: LT Hist Max | N7: (USDm, except EPS and shares) | O7: 2025A | P7: 2026E | Q7: 2027E | R7: 2028E | S7: 2029E | T7: 2030E | U7: 25-'30 CAGR | V7: LT Hist Avg | W7: LT Hist Min | X7: LT Hist Max | Z7: (USDm, except EPS and shares) | AA7: 2025A | AB7: 2026E | AC7: 2027E | AD7: 2028E | AE7: 2029E | AF7: 2030E | AG7: 25-'30 CAGR | AH7: LT Hist Avg | AI7: LT Hist Min | AJ7: LT Hist Max
B9: Revenues | C9: =Model!BV121 -> 3247 | D9: =Model!CA121 -> 3801.9008 | E9: =Model!CB121 -> 4324.8999 | F9: =Model!CC121 -> 4750.8791 | G9: =Model!CD121 -> 5185.0652 | H9: =Model!CE121 -> 5621.4945 | I9: =IFERROR((H9/C9)^(1/5)-1,"n/m") -> 0.11602494 | N9: Revenues | O9: 3247 | P9: 3821.9008 | Q9: 4493.0581 | R9: 5139.8641 | S9: 5828.2125 | T9: 6553.8917 | U9: 0.15080938 | Z9: Revenues | AA9: 3247 | AB9: 3781.9008 | AC9: 4199.4627 | AD9: 4501.5722 | AE9: 4793.3687 | AF9: 5069.4852 | AG9: 0.093191672
B10: Revenues y/y % | D10: =IFERROR(D9/C9-1,"") -> 0.17089647 | E10: =IFERROR(E9/D9-1,"") -> 0.13756253 | F10: =IFERROR(F9/E9-1,"") -> 0.098494585 | G10: =IFERROR(G9/F9-1,"") -> 0.091390673 | H10: =IFERROR(H9/G9-1,"") -> 0.084170463 | N10: Revenues y/y % | P10: 0.177056 | Q10: 0.17560823 | R10: 0.14395676 | S10: 0.13392346 | T10: 0.12451145 | Z10: Revenues y/y % | AB10: 0.16473693 | AC10: 0.11041058 | AD10: 0.071940047 | AE10: 0.064821009 | AF10: 0.057603863
B11: Commercial Real Estate revenues y/y % | C11: =Model!BV204 -> 0.17953795 | D11: =Model!CA204 -> 0.087522548 | E11: =Model!CB204 -> 0.090881952 | F11: =Model!CC204 -> 0.089334598 | G11: =Model!CD204 -> 0.084143665 | H11: =Model!CE204 -> 0.078851186 | N11: Commercial Real Estate revenues y/y % | O11: 0.17953795 | P11: 0.093342357 | Q11: 0.1138374 | R11: 0.11230295 | S11: 0.10711613 | T11: 0.10182495 | Z11: Commercial Real Estate revenues y/y % | AA11: 0.17953795 | AB11: 0.081702738 | AC11: 0.067926918 | AD11: 0.066405079 | AE11: 0.061248595 | AF11: 0.055993451
B12: Residential Real Estate revenues y/y % (ex-Zonda) | C12: =Model!BV205 -> 0.1957412 | D12: =Model!CA205 -> 0.22712137 | E12: =Model!CB205 -> 0.12 | F12: =Model!CC205 -> 0.11 | G12: =Model!CD205 -> 0.1 | H12: =Model!CE205 -> 0.09 | N12: Residential Real Estate revenues y/y % (ex-Zonda) | O12: 0.1957412 | P12: 0.23369672 | Q12: 0.15 | R12: 0.14 | S12: 0.13 | T12: 0.12 | Z12: Residential Real Estate revenues y/y % (ex-Zonda) | AA12: 0.1957412 | AB12: 0.22054603 | AC12: 0.09 | AD12: 0.08 | AE12: 0.07 | AF12: 0.06
B13: Adjusted EBITDA (company definition; adds back SBC) | C13: =Model!BV168 -> 442 | D13: =Model!CA168 -> 815.38719 | E13: =Model!CB168 -> 1003.9734 | F13: =Model!CC168 -> 1235.6751 | G13: =Model!CD168 -> 1496.5194 | H13: =Model!CE168 -> 1782.8256 | I13: =IFERROR((H13/C13)^(1/5)-1,"n/m") -> 0.32171347 | N13: Adjusted EBITDA (company definition; adds back SBC) | O13: 442 | P13: 835.38719 | Q13: 1172.5647 | R13: 1479.7078 | S13: 1834.1367 | T13: 2234.8487 | U13: 0.38281847 | Z13: Adjusted EBITDA (company definition; adds back SBC) | AA13: 442 | AB13: 795.38719 | AC13: 853.64372 | AD13: 1041.8735 | AE13: 1246.7969 | AF13: 1463.4808 | AG13: 0.27055348
B14: Adjusted EBITDA margin % | C14: =IFERROR(C13/C9,"") -> 0.13612565 | D14: =IFERROR(D13/D9,"") -> 0.2144683 | E14: =IFERROR(E13/E9,"") -> 0.23213795 | F14: =IFERROR(F13/F9,"") -> 0.26009399 | G14: =IFERROR(G13/G9,"") -> 0.28862114 | H14: =IFERROR(H13/H9,"") -> 0.31714441 | J14: =IFERROR(AVERAGE(Model!C169,Model!D169,Model!E169,Model!F169,Model!G169,Model!H169,Model!I169,Model!N169,Model!S169,Model!X169,Model!AC169,Model!AH169,Model!AM169,Model!AR169,Model!AW169,Model!BB169,Model!BG169,Model!BL169,Model!BQ169,Model!BV169),"n/m") -> 0.25494591 | K14: =IFERROR(MIN(Model!C169,Model!D169,Model!E169,Model!F169,Model!G169,Model!H169,Model!I169,Model!N169,Model!S169,Model!X169,Model!AC169,Model!AH169,Model!AM169,Model!AR169,Model!AW169,Model!BB169,Model!BG169,Model!BL169,Model!BQ169,Model!BV169),"n/m") -> 0.088005263 | L14: =IFERROR(MAX(Model!C169,Model!D169,Model!E169,Model!F169,Model!G169,Model!H169,Model!I169,Model!N169,Model!S169,Model!X169,Model!AC169,Model!AH169,Model!AM169,Model!AR169,Model!AW169,Model!BB169,Model!BG169,Model!BL169,Model!BQ169,Model!BV169),"n/m") -> 0.36200123 | N14: Adjusted EBITDA margin % | O14: 0.13612565 | P14: 0.21857898 | Q14: 0.26097253 | R14: 0.2878885 | S14: 0.31469969 | T14: 0.34099567 | V14: 0.25494591 | W14: 0.088005263 | X14: 0.36200123 | Z14: Adjusted EBITDA margin % | AA14: 0.13612565 | AB14: 0.21031413 | AC14: 0.20327451 | AD14: 0.23144659 | AE14: 0.26010871 | AF14: 0.2886843 | AH14: 0.25494591 | AI14: 0.088005263 | AJ14: 0.36200123
B16: Income from Operations (GAAP) | C16: =Model!BV131 -> -72 | D16: =Model!CA131 -> 307.3889 | E16: =Model!CB131 -> 469.82961 | F16: =Model!CC131 -> 706.1206 | G16: =Model!CD131 -> 954.04538 | H16: =Model!CE131 -> 1245.2929 | I16: =IFERROR((H16/C16)^(1/5)-1,"n/m") -> -2.7684297 | N16: Income from Operations (GAAP) | O16: -72 | P16: 327.3889 | Q16: 607.99514 | R16: 886.03622 | S16: 1191.7875 | T16: 1559.5074 | U16: -2.8498265 | Z16: Income from Operations (GAAP) | AA16: -72 | AB16: 287.3889 | AC16: 327.27703 | AD16: 527.77605 | AE16: 728.60809 | AF16: 960.17271 | AG16: -2.6788171
B17: Income from operations y/y % | D17: =IFERROR(D16/C16-1,"") -> -5.2692903 | E17: =IFERROR(E16/D16-1,"") -> 0.52845341 | F17: =IFERROR(F16/E16-1,"") -> 0.50292911 | G17: =IFERROR(G16/F16-1,"") -> 0.35110826 | H17: =IFERROR(H16/G16-1,"") -> 0.3052764 | N17: Income from operations y/y % | P17: -5.547068 | Q17: 0.8571037 | R17: 0.45730807 | S17: 0.34507765 | T17: 0.30854483 | Z17: Income from operations y/y % | AB17: -4.9915125 | AC17: 0.13879498 | AD17: 0.61262782 | AE17: 0.3805251 | AF17: 0.3178178
B18: Operating margin (GAAP) % | C18: =IFERROR(C16/C9,"") -> -0.022174315 | D18: =IFERROR(D16/D9,"") -> 0.080851372 | E18: =IFERROR(E16/E9,"") -> 0.10863364 | F18: =IFERROR(F16/F9,"") -> 0.14862946 | G18: =IFERROR(G16/G9,"") -> 0.18399872 | H18: =IFERROR(H16/H9,"") -> 0.22152346 | J18: =IFERROR(AVERAGE(Model!C213,Model!D213,Model!E213,Model!F213,Model!G213,Model!H213,Model!I213,Model!N213,Model!S213,Model!X213,Model!AC213,Model!AH213,Model!AM213,Model!AR213,Model!AW213,Model!BB213,Model!BG213,Model!BL213,Model!BQ213,Model!BV213),"n/m") -> 0.13027222 | K18: =IFERROR(MIN(Model!C213,Model!D213,Model!E213,Model!F213,Model!G213,Model!H213,Model!I213,Model!N213,Model!S213,Model!X213,Model!AC213,Model!AH213,Model!AM213,Model!AR213,Model!AW213,Model!BB213,Model!BG213,Model!BL213,Model!BQ213,Model!BV213),"n/m") -> -0.022174315 | L18: =IFERROR(MAX(Model!C213,Model!D213,Model!E213,Model!F213,Model!G213,Model!H213,Model!I213,Model!N213,Model!S213,Model!X213,Model!AC213,Model!AH213,Model!AM213,Model!AR213,Model!AW213,Model!BB213,Model!BG213,Model!BL213,Model!BQ213,Model!BV213),"n/m") -> 0.25972856 | N18: Operating margin (GAAP) % | O18: -0.022174315 | P18: 0.085661275 | Q18: 0.13531878 | R18: 0.17238514 | S18: 0.20448594 | T18: 0.23795135 | V18: 0.13027222 | W18: -0.022174315 | X18: 0.25972856 | Z18: Operating margin (GAAP) % | AA18: -0.022174315 | AB18: 0.075990596 | AC18: 0.077933074 | AD18: 0.1172426 | AE18: 0.15200335 | AF18: 0.18940241 | AH18: 0.13027222 | AI18: -0.022174315 | AJ18: 0.25972856
B20: Adjusted Net Income (company definition, 26% assumed tax) | C20: =Model!BV192 -> 364.08 | D20: =Model!CA192 -> 550.47639 | E20: =Model!CB192 -> 661.08108 | F20: =Model!CC192 -> 820.73116 | G20: =Model!CD192 -> 1003.6745 | H20: =Model!CE192 -> 1194.3011 | I20: =IFERROR((H20/C20)^(1/5)-1,"n/m") -> 0.26818731 | N20: Adjusted Net Income (company definition, 26% assumed tax) | O20: 364.08 | P20: 565.27639 | Q20: 775.72924 | R20: 969.3924 | S20: 1207.9627 | T20: 1469.4236 | U20: 0.32187393 | Z20: Adjusted Net Income (company definition, 26% assumed tax) | AA20: 364.08 | AB20: 535.67639 | AC20: 554.26488 | AD20: 692.52081 | AE20: 839.4137 | AF20: 986.43785 | AG20: 0.22060342
B22: FDSO (m) | C22: =Model!BV145 -> 420.7 | D22: =Model!CA145 -> 405.7072 | E22: =Model!CB145 -> 390.55054 | F22: =Model!CC145 -> 365.85034 | G22: =Model!CD145 -> 338.23807 | H22: =Model!CE145 -> 307.6637 | I22: =IFERROR((H22/C22)^(1/5)-1,"n/m") -> -0.060664473 | N22: FDSO (m) | O22: 420.7 | P22: 403.27055 | Q22: 380.89922 | R22: 358.49913 | S22: 333.8961 | T22: 303.53119 | U22: -0.063201551 | Z22: FDSO (m) | AA22: 420.7 | AB22: 406.625 | AC22: 401.87457 | AD22: 388.23059 | AE22: 367.84081 | AF22: 345.30983 | AG22: -0.038725799
B24: Adjusted EPS — Diluted ($) | C24: =Model!BV196 -> 0.86541478 | D24: =Model!CA196 -> 1.3568317 | E24: =Model!CB196 -> 1.6926902 | F24: =Model!CC196 -> 2.2433522 | G24: =Model!CD196 -> 2.9673612 | H24: =Model!CE196 -> 3.8818396 | I24: =IFERROR((H24/C24)^(1/5)-1,"n/m") -> 0.35008979 | N24: Adjusted EPS — Diluted ($) | O24: 0.86541478 | P24: 1.4017299 | Q24: 2.0365735 | R24: 2.70403 | S24: 3.6177803 | T24: 4.8410958 | U24: 0.41105478 | Z24: Adjusted EPS — Diluted ($) | AA24: 0.86541478 | AB24: 1.317372 | AC24: 1.3791987 | AD24: 1.7837873 | AE24: 2.2820026 | AF24: 2.8566746 | AG24: 0.26977653
B25: EPS y/y % | D25: =IFERROR(D24/C24-1,"") -> 0.56783976 | E25: =IFERROR(E24/D24-1,"") -> 0.24753146 | F25: =IFERROR(F24/E24-1,"") -> 0.32531762 | G25: =IFERROR(G24/F24-1,"") -> 0.32273532 | H25: =IFERROR(H24/G24-1,"") -> 0.30817899 | N25: EPS y/y % | P25: 0.61972031 | Q25: 0.45290007 | R25: 0.32773506 | S25: 0.33792165 | T25: 0.3381398 | Z25: EPS y/y % | AB25: 0.52224346 | AC25: 0.046931832 | AD25: 0.29335053 | AE25: 0.27930196 | AF25: 0.25182794
B27: P / E (x) — assumed (Adjusted EPS) | G27: 22 | H27: 22 | N27: P / E (x) — assumed (Adjusted EPS) | S27: 28 | T27: 28 | Z27: P / E (x) — assumed (Adjusted EPS) | AD27: 16 | AE27: 16 | AF27: 16
B28: Price Target ($) | G28: =G27*G24 -> 65.281946 | H28: =H27*H24 -> 85.40047 | N28: Price Target ($) | S28: =S27*S24 -> 101.29785 | T28: =T27*T24 -> 135.55068 | Z28: Price Target ($) | AD28: =AD27*AD24 -> 28.540597 | AE28: =AE27*AE24 -> 36.512042 | AF28: =AF27*AF24 -> 45.706794
B29: Upside / (Downside) vs current | G29: =IFERROR(G28/$K$2-1,"") -> 1.1209209 | H29: =IFERROR(H28/$K$2-1,"") -> 1.7745442 | N29: Upside / (Downside) vs current | S29: =IFERROR(S28/$K$2-1,"") -> 2.2910282 | T29: =IFERROR(T28/$K$2-1,"") -> 3.4038559 | Z29: Upside / (Downside) vs current | AD29: =IFERROR(AD28/$K$2-1,"") -> -0.07275512 | AE29: =IFERROR(AE28/$K$2-1,"") -> 0.18622619 | AF29: =IFERROR(AF28/$K$2-1,"") -> 0.48495109
B30: IRR (to Dec-Y-1) | G30: =IFERROR((G28/$K$2)^(1/((DATE(2029-1,12,31)-$K$3)/365.25))-1,"") -> 0.39951263 | H30: =IFERROR((H28/$K$2)^(1/((DATE(2030-1,12,31)-$K$3)/365.25))-1,"") -> 0.37072621 | N30: IRR (to Dec-Y-1) | S30: =IFERROR((S28/$K$2)^(1/((DATE(2029-1,12,31)-$K$3)/365.25))-1,"") -> 0.70325441 | T30: =IFERROR((T28/$K$2)^(1/((DATE(2030-1,12,31)-$K$3)/365.25))-1,"") -> 0.58106951 | Z30: IRR (to Dec-Y-1) | AD30: =IFERROR((AD28/$K$2)^(1/((DATE(2028-1,12,31)-$K$3)/365.25))-1,"") -> -0.05934176 | AE30: =IFERROR((AE28/$K$2)^(1/((DATE(2029-1,12,31)-$K$3)/365.25))-1,"") -> 0.079338096 | AF30: =IFERROR((AF28/$K$2)^(1/((DATE(2030-1,12,31)-$K$3)/365.25))-1,"") -> 0.12995409
B32: Free Cash Flow (CFO − capex incl. campuses) | C32: =Model!BV248 -> 41 | D32: =Model!CA248 -> 453.83716 | E32: =Model!CB248 -> 694.57496 | F32: =Model!CC248 -> 893.96844 | G32: =Model!CD248 -> 1096.1414 | H32: =Model!CE248 -> 1281.1175 | I32: =IFERROR((H32/C32)^(1/5)-1,"n/m") -> 0.99049469 | N32: Free Cash Flow (CFO − capex incl. campuses) | O32: 41 | P32: 467.64186 | Q32: 803.85832 | R32: 1044.3609 | S32: 1309.7546 | T32: 1573.3862 | U32: 1.0740074 | Z32: Free Cash Flow (CFO − capex incl. campuses) | AA32: 41 | AB32: 440.03245 | AC32: 588.57011 | AD32: 765.44321 | AE32: 930.40127 | AF32: 1070.4777 | AG32: 0.92025432
