Workbook

Sheet Model
CF1: SCENARIO SWITCH ▼ (Bull / Base / Bear) — drives all scenario-linked forecast drivers
B2: Curtiss-Wright Corporation (NYSE: CW) — 3-Statement Financial Model | CF2: Base
B3: US GAAP as reported · USD millions (per-share data in USD; shares in millions) · Source: Curtiss-Wright Forms 10-K / 10-Q and Form 8-K earnings releases (Ex. 99.1), 10b5-1 / credit-agreement 8-Ks (2026), SEC EDGAR CIK 0000026324 (investor-relations releases are the same documents as filed on EDGAR)
B4: Basis notes: calendar fiscal year. Segments: Flow Control / Motion Control / Metal Treatment (to 2012) → Flow Control / Controls / Surface Technologies (2013) → Commercial/Industrial, Defense, Energy→Power (2014–2020) → Aerospace & Industrial, Defense Electronics, Naval & Power (current; 2020 restated in the 2021 releases). Adjusted (non-GAAP) framework from Q2/18 (first-year purchase accounting; later restructuring, exited businesses, activism, legal, FY26 Restructuring Program and 2026 equity-securities gain). Income statement as originally reported in each period (discontinued operations 2012–17; ASU 2017-07 pension reclass from 2018). FY26 guidance raised 5-Aug-2026; $300m of 10b5-1 buybacks Aug–Oct 2026; $200m 4.24% notes mature Dec-2026.
CH5: Forecast | CI5: Historical | CJ5: Historical | CK5: Historical
B6: (USDm) | C6: 2006 | D6: 2007 | E6: 2008 | F6: 2009 | G6: 2010 | H6: 2011 | I6: 2012 | J6: Q1/13 | K6: Q2/13 | L6: Q3/13 | M6: Q4/13 | N6: 2013 | O6: Q1/14 | P6: Q2/14 | Q6: Q3/14 | R6: Q4/14 | S6: 2014 | T6: Q1/15 | U6: Q2/15 | V6: Q3/15 | W6: Q4/15 | X6: 2015 | Y6: Q1/16 | Z6: Q2/16 | AA6: Q3/16 | AB6: Q4/16 | AC6: 2016 | AD6: Q1/17 | AE6: Q2/17 | AF6: Q3/17 | AG6: Q4/17 | AH6: 2017 | AI6: Q1/18 | AJ6: Q2/18 | AK6: Q3/18 | AL6: Q4/18 | AM6: 2018 | AN6: Q1/19 | AO6: Q2/19 | AP6: Q3/19 | AQ6: Q4/19 | AR6: 2019 | AS6: Q1/20 | AT6: Q2/20 | AU6: Q3/20 | AV6: Q4/20 | AW6: 2020 | AX6: Q1/21 | AY6: Q2/21 | AZ6: Q3/21 | BA6: Q4/21 | BB6: 2021 | BC6: Q1/22 | BD6: Q2/22 | BE6: Q3/22 | BF6: Q4/22 | BG6: 2022 | BH6: Q1/23 | BI6: Q2/23 | BJ6: Q3/23 | BK6: Q4/23 | BL6: 2023 | BM6: Q1/24 | BN6: Q2/24 | BO6: Q3/24 | BP6: Q4/24 | BQ6: 2024 | BR6: Q1/25 | BS6: Q2/25 | BT6: Q3/25 | BU6: Q4/25 | BV6: 2025 | BW6: Q1/26 | BX6: Q2/26 | BY6: Q3/26E | BZ6: Q4/26E | CA6: 2026E | CB6: 2027E | CC6: 2028E | CD6: 2029E | CE6: 2030E | CF6: Modelling Notes | CH6: 5Y CAGR | CI6: 5Y CAGR | CJ6: 10Y CAGR | CK6: 19Y CAGR
CH7: 25-'30 | CI7: 20-'25 | CJ7: 15-'25 | CK7: 06-'25
B8: SEGMENT P&L — AEROSPACE & INDUSTRIAL · DEFENSE ELECTRONICS · NAVAL & POWER (growth × incremental-margin build) | CF8: SEGMENT BUILD — modelling logic (sales growth → sales → Adjusted OI via incremental margins)
CM9: SCENARIO INPUT TABLE — driver assumptions per Bull / Base / Bear | CN9: Bull | CO9: Base | CP9: Bear | CQ9: Bull / Bear = Base + Δ (Δ inputs on each lever header). Outlook block = high / mid / low end of the FY26 guidance ranges.
B10: Aerospace & Industrial (actuation, sensors & controls, surface treatment, industrial vehicles & valves) — current segment basis from Q1/20 | CF10: AEROSPACE & INDUSTRIAL — modelling logic
B11: Sales | AS11: 226.728 | AT11: 177.411 | AU11: 188.768 | AV11: 212.766 | AW11: 805.673 | AX11: 180.331 | AY11: 199.713 | AZ11: 196.296 | BA11: 209.994 | BB11: 786.334 | BC11: 191.112 | BD11: 208.572 | BE11: 213.093 | BF11: 223.258 | BG11: 836.035 | BH11: 202.447 | BI11: 226.26 | BJ11: 220.297 | BK11: 238.224 | BL11: 887.228 | BM11: 219.325 | BN11: 233.232 | BO11: 228.659 | BP11: 250.917 | BQ11: 932.133 | BR11: 227.246 | BS11: 239.138 | BT11: 247.985 | BU11: 262.391 | BV11: 976.76 | BW11: 254.919 | BX11: 267.765 | BY11: =BT11*(1+BY13) -> 263.01834 | BZ11: =BU11*(1+BZ13) -> 278.29766 | CA11: =SUM(BW11,BX11,BY11,BZ11) -> 1064 | CB11: =CA11*(1+CB13) -> 1138.48 | CC11: =CB11*(1+CC13) -> 1212.4812 | CD11: =CC11*(1+CD13) -> 1285.2301 | CE11: =CD11*(1+CE13) -> 1362.3439 | CF11: Q3/Q4-26E: prior-year quarter × (1 + guidance-implied 2H/26 y/y growth + revenue calibration Δ). 2027E+: prior year × (1 + scenario lever). | CH11: =IFERROR((CE11/BV11)^(1/5)-1,"n/m") -> 0.068808196 | CI11: =IFERROR((BV11/AW11)^(1/5)-1,"n/m") -> 0.039263827 | CJ11: =IFERROR((BV11/X11)^(1/10)-1,"n/m") -> n/m | CK11: =IFERROR((BV11/C11)^(1/19)-1,"n/m") -> n/m | CM11: FY26 outlook — Q2-26 release (5-Aug-26), Adjusted (non-GAAP) | CN11: High | CO11: Mid | CP11: Low | CQ11: Raised on 5-Aug-26 (Form 8-K Ex. 99.1, guidance tables). Segment ranges drive the Q3/Q4-26E build; total ranges drive the calibration.
B12: Sales y/y % | D12: =IF(AND(ISNUMBER(D11),ISNUMBER(C11)),IFERROR(D11/C11-1,""),"") | E12: =IF(AND(ISNUMBER(E11),ISNUMBER(D11)),IFERROR(E11/D11-1,""),"") | F12: =IF(AND(ISNUMBER(F11),ISNUMBER(E11)),IFERROR(F11/E11-1,""),"") | G12: =IF(AND(ISNUMBER(G11),ISNUMBER(F11)),IFERROR(G11/F11-1,""),"") | H12: =IF(AND(ISNUMBER(H11),ISNUMBER(G11)),IFERROR(H11/G11-1,""),"") | I12: =IF(AND(ISNUMBER(I11),ISNUMBER(H11)),IFERROR(I11/H11-1,""),"") | N12: =IF(AND(ISNUMBER(N11),ISNUMBER(I11)),IFERROR(N11/I11-1,""),"") | O12: =IF(AND(ISNUMBER(O11),ISNUMBER(J11)),IFERROR(O11/J11-1,""),"") | P12: =IF(AND(ISNUMBER(P11),ISNUMBER(K11)),IFERROR(P11/K11-1,""),"") | Q12: =IF(AND(ISNUMBER(Q11),ISNUMBER(L11)),IFERROR(Q11/L11-1,""),"") | R12: =IF(AND(ISNUMBER(R11),ISNUMBER(M11)),IFERROR(R11/M11-1,""),"") | S12: =IF(AND(ISNUMBER(S11),ISNUMBER(N11)),IFERROR(S11/N11-1,""),"") | T12: =IF(AND(ISNUMBER(T11),ISNUMBER(O11)),IFERROR(T11/O11-1,""),"") | U12: =IF(AND(ISNUMBER(U11),ISNUMBER(P11)),IFERROR(U11/P11-1,""),"") | ... BX12: =IF(AND(ISNUMBER(BX11),ISNUMBER(BS11)),IFERROR(BX11/BS11-1,""),"") -> 0.11970912 | BY12: =IFERROR(BY11/BT11-1,"") -> 0.060621973 | BZ12: =IFERROR(BZ11/BU11-1,"") -> 0.060621973 | CA12: =IFERROR(CA11/BV11-1,"") -> 0.089315697 | CB12: =IFERROR(CB11/CA11-1,"") -> 0.07 | CC12: =IFERROR(CC11/CB11-1,"") -> 0.065 | CD12: =IFERROR(CD11/CC11-1,"") -> 0.06 | CE12: =IFERROR(CE11/CD11-1,"") -> 0.06 | CM12: FY26 total sales ($m) | CN12: 3813 | CO12: 3790.5 | CP12: 3768 | CQ12: Raised to $3,768–3,813m (from $3,740–3,795m); +8–9% vs 2025.
B13: Forecast sales growth driver % (Q3/Q4-26E: guidance-implied 2H y/y + calibration; 2027E+: lever) | BY13: =($CA$21-$BW$11-$BX$11)/($BT$11+$BU$11)-1+BY89 -> 0.060621973 | BZ13: =($CA$21-$BW$11-$BX$11)/($BT$11+$BU$11)-1+BZ89 -> 0.060621973 | CA13: =IFERROR(CA11/BV11-1,"") -> 0.089315697 | CB13: =CHOOSE(MATCH($CF$2,{"Bull","Base","Bear"},0),$CN$40,$CO$40,$CP$40) -> 0.07 | CC13: =CHOOSE(MATCH($CF$2,{"Bull","Base","Bear"},0),$CN$41,$CO$41,$CP$41) -> 0.065 | CD13: =CHOOSE(MATCH($CF$2,{"Bull","Base","Bear"},0),$CN$42,$CO$42,$CP$42) -> 0.06 | CE13: =CHOOSE(MATCH($CF$2,{"Bull","Base","Bear"},0),$CN$43,$CO$43,$CP$43) -> 0.06 | CF13: FY26: (segment guidance end-point − 1H/26) ÷ 2H/25 − 1, by scenario (high / mid / low). 2027E–30E: scenario lever (table →). | CM13: FY26 Adjusted operating income ($m) | CN13: 736 | CO13: 728 | CP13: 720 | CQ13: Raised to $720–736m (from $712–729m); margin 19.1–19.3%.
B14: Operating income (GAAP, as reported) | AS14: 32.14 | AT14: 9.615 | AU14: 23.88 | AV14: 34.079 | AW14: 99.714 | AX14: 19.025 | AY14: 31.977 | AZ14: 30.872 | BA14: 39.943 | BB14: 121.817 | BC14: 24.853 | BD14: 32.464 | BE14: 39.08 | BF14: 40.599 | BG14: 136.996 | BH14: 26.545 | BI14: 35.665 | BJ14: 39.014 | BK14: 44.054 | BL14: 145.278 | BM14: 27.466 | BN14: 35.246 | BO14: 37.435 | BP14: 47.876 | BQ14: 148.023 | BR14: 29.922 | BS14: 39.006 | BT14: 45.439 | BU14: 51.799 | BV14: 166.166 | BW14: 38.498 | BX14: 49.004 | BY14: =BY17-BY16 -> 48.237616 | BZ14: =BZ17-BZ16 -> 55.483185 | CA14: =SUM(BW14,BX14,BY14,BZ14) -> 191.2228 | CB14: =CB17-CB16 -> 219.5668 | CC14: =CC17-CC16 -> 241.76716 | CD14: =CD17-CD16 -> 263.59182 | CE14: =CE17-CE16 -> 286.72596 | CM14: FY26 Adjusted diluted EPS ($) | CN14: 15.4 | CO14: 15.25 | CP14: 15.1 | CQ14: Raised to $15.10–15.40 (memo; model output compared below).
B15: Operating margin (GAAP) % | C15: =IF(AND(ISNUMBER(C14),ISNUMBER(C11)),IFERROR(C14/C11,""),"") | D15: =IF(AND(ISNUMBER(D14),ISNUMBER(D11)),IFERROR(D14/D11,""),"") | E15: =IF(AND(ISNUMBER(E14),ISNUMBER(E11)),IFERROR(E14/E11,""),"") | F15: =IF(AND(ISNUMBER(F14),ISNUMBER(F11)),IFERROR(F14/F11,""),"") | G15: =IF(AND(ISNUMBER(G14),ISNUMBER(G11)),IFERROR(G14/G11,""),"") | H15: =IF(AND(ISNUMBER(H14),ISNUMBER(H11)),IFERROR(H14/H11,""),"") | I15: =IF(AND(ISNUMBER(I14),ISNUMBER(I11)),IFERROR(I14/I11,""),"") | J15: =IF(AND(ISNUMBER(J14),ISNUMBER(J11)),IFERROR(J14/J11,""),"") | ... BX15: =IF(AND(ISNUMBER(BX14),ISNUMBER(BX11)),IFERROR(BX14/BX11,""),"") -> 0.18301122 | BY15: =IFERROR(BY14/BY11,"") -> 0.1834002 | BZ15: =IFERROR(BZ14/BZ11,"") -> 0.19936634 | CA15: =IFERROR(CA14/CA11,"") -> 0.17972068 | CB15: =IFERROR(CB14/CB11,"") -> 0.1928596 | CC15: =IFERROR(CC14/CC11,"") -> 0.19939869 | CD15: =IFERROR(CD14/CD11,"") -> 0.2050931 | CE15: =IFERROR(CE14/CE11,"") -> 0.21046519 | CM15: FY26 free cash flow ($m) | CN15: 605 | CO15: 595 | CP15: 585 | CQ15: Raised to $585–605m; capex up ~$25m y/y (memo; model output compared below).
B16: (+) Adjustments (first-year purchase accounting, restructuring, exited businesses) | AS16: -3.74 | AT16: 3.185 | AU16: -0.98 | AV16: -0.362 | AW16: -1.879 | AX16: -0.525 | AY16: -1.477 | AZ16: -0.072 | BA16: 0.493 | BB16: -1.586 | BC16: 0 | BD16: 0 | BE16: 0 | BF16: 0.703 | BG16: 0.703 | BH16: 0 | BI16: 0 | BJ16: 0 | BK16: 0 | BL16: 0 | BM16: 0 | BN16: 2.619 | BO16: 1.926 | BP16: 5.694 | BQ16: 10.239 | BR16: 1.764 | BS16: 0.582 | BT16: 0.57 | BU16: 0.938 | BV16: 3.855 | BW16: 0.703 | BX16: 0.399 | BY16: =MAX(0,($CO$30-$BW$16-$BX$16)/2) -> 2.449 | BZ16: =MAX(0,($CO$30-$BW$16-$BX$16)/2) -> 2.449 | CA16: =SUM(BW16,BX16,BY16,BZ16) -> 6 | CB16: 0 | CC16: 0 | CD16: 0 | CE16: 0 | CF16: Q3/Q4-26E: remaining FY26 Restructuring Program cost per the guidance adjustment column, spread evenly. 2027E+: none assumed. | CM16: A&I sales ($m) | CN16: 1070 | CO16: 1064 | CP16: 1058 | CQ16: +8–10% vs 2025.
B17: Adjusted operating income | AS17: =AS14+AS16 -> 28.4 | AT17: =AT14+AT16 -> 12.8 | AU17: =AU14+AU16 -> 22.9 | AV17: =AV14+AV16 -> 33.717 | AW17: =AW14+AW16 -> 97.835 | AX17: =AX14+AX16 -> 18.5 | AY17: =AY14+AY16 -> 30.5 | AZ17: =AZ14+AZ16 -> 30.8 | ... BX17: =BX14+BX16 -> 49.403 | BY17: =BY11*BY18 -> 50.686616 | BZ17: =BZ11*BZ18 -> 57.932185 | CA17: =SUM(BW17,BX17,BY17,BZ17) -> 197.2228 | CB17: =CA17+(CB11-CA11)*CB20 -> 219.5668 | CC17: =CB17+(CC11-CB11)*CC20 -> 241.76716 | CD17: =CC17+(CD11-CC11)*CD20 -> 263.59182 | CE17: =CD17+(CE11-CD11)*CE20 -> 286.72596 | CF17: 2027E+: prior-year Adjusted OI + Δ sales × incremental margin (scenario lever) — margin is an output, not an input. | CH17: =IFERROR((CE17/BV17)^(1/5)-1,"n/m") -> 0.1101787 | CI17: =IFERROR((BV17/AW17)^(1/5)-1,"n/m") -> 0.11686753 | CJ17: =IFERROR((BV17/X17)^(1/10)-1,"n/m") -> n/m | CK17: =IFERROR((BV17/C17)^(1/19)-1,"n/m") -> n/m | CM17: A&I Adjusted OI ($m) | CN17: 200 | CO17: 197.5 | CP17: 195 | CQ17: Adj. margin 18.5–18.7%.
B18: Adjusted operating margin % | C18: =IF(AND(ISNUMBER(C17),ISNUMBER(C11)),IFERROR(C17/C11,""),"") | D18: =IF(AND(ISNUMBER(D17),ISNUMBER(D11)),IFERROR(D17/D11,""),"") | E18: =IF(AND(ISNUMBER(E17),ISNUMBER(E11)),IFERROR(E17/E11,""),"") | F18: =IF(AND(ISNUMBER(F17),ISNUMBER(F11)),IFERROR(F17/F11,""),"") | G18: =IF(AND(ISNUMBER(G17),ISNUMBER(G11)),IFERROR(G17/G11,""),"") | H18: =IF(AND(ISNUMBER(H17),ISNUMBER(H11)),IFERROR(H17/H11,""),"") | I18: =IF(AND(ISNUMBER(I17),ISNUMBER(I11)),IFERROR(I17/I11,""),"") | J18: =IF(AND(ISNUMBER(J17),ISNUMBER(J11)),IFERROR(J17/J11,""),"") | ... BX18: =IF(AND(ISNUMBER(BX17),ISNUMBER(BX11)),IFERROR(BX17/BX11,""),"") -> 0.18450134 | BY18: =BY19+BY93 -> 0.19271134 | BZ18: =BZ19+BZ93 -> 0.20816627 | CA18: =IFERROR(CA17/CA11,"") -> 0.18535978 | CB18: =IFERROR(CB17/CB11,"") -> 0.1928596 | CC18: =IFERROR(CC17/CC11,"") -> 0.19939869 | CD18: =IFERROR(CD17/CD11,"") -> 0.2050931 | CE18: =IFERROR(CE17/CE11,"") -> 0.21046519 | CH18: =IFERROR(AVERAGE(CA18,CB18,CC18,CD18,CE18),"n/m") -> 0.19863527 | CI18: =IFERROR(AVERAGE(BB18,BG18,BL18,BQ18,BV18),"n/m") -> 0.16504006 | CJ18: =IFERROR(AVERAGE(AC18,AH18,AM18,AR18,AW18,BB18,BG18,BL18,BQ18,BV18),"n/m") -> 0.15777216 | CK18: =IFERROR(AVERAGE(C18,D18,E18,F18,G18,H18,I18,N18,S18,X18,AC18,AH18,AM18,AR18,AW18,BB18,BG18,BL18,BQ18,BV18),"n/m") -> 0.15777216 | CM18: Defense Electronics sales ($m) | CN18: 1075 | CO18: 1065 | CP18: 1055 | CQ18: +4–6%.
B19: Adjusted margin before outlook calibration % (Q3/Q4-26E helper) | BY19: =BT18+(($CA$22-$BW$17-$BX$17)-($BT$18*$BY$11+$BU$18*$BZ$11))/($BY$11+$BZ$11) -> 0.19322342 | BZ19: =BU18+(($CA$22-$BW$17-$BX$17)-($BT$18*$BY$11+$BU$18*$BZ$11))/($BY$11+$BZ$11) -> 0.20867835 | CF19: Prior-year quarter margin + uniform shift so that the segment hits its FY26 Adjusted OI guidance end-point (scenario). | CM19: Defense Electronics Adjusted OI ($m) | CN19: 298 | CO19: 294.5 | CP19: 291 | CQ19: Adj. margin 27.5–27.7%.
B20: Incremental Adjusted OI margin on Δ sales % (2027E+: lever) | BB20: =IFERROR((BB17-AW17)/(BB11-AW11),"") -> -1.1580744 | BG20: =IFERROR((BG17-BB17)/(BG11-BB11),"") -> 0.35146174 | BL20: =IFERROR((BL17-BG17)/(BL11-BG11),"") -> 0.14804758 | BQ20: =IFERROR((BQ17-BL17)/(BQ11-BL11),"") -> 0.28914375 | BV20: =IFERROR((BV17-BQ17)/(BV11-BQ11),"") -> 0.26349519 | CA20: =IFERROR((CA17-BV17)/(CA11-BV11),"") -> 0.31180423 | CB20: =CHOOSE(MATCH($CF$2,{"Bull","Base","Bear"},0),$CN$46,$CO$46,$CP$46) -> 0.3 | CC20: =CHOOSE(MATCH($CF$2,{"Bull","Base","Bear"},0),$CN$47,$CO$47,$CP$47) -> 0.3 | CD20: =CHOOSE(MATCH($CF$2,{"Bull","Base","Bear"},0),$CN$48,$CO$48,$CP$48) -> 0.3 | CE20: =CHOOSE(MATCH($CF$2,{"Bull","Base","Bear"},0),$CN$49,$CO$49,$CP$49) -> 0.3 | CM20: Naval & Power sales ($m) | CN20: 1668 | CO20: 1661.5 | CP20: 1655 | CQ20: +10–11%.
B21: Memo: FY26 sales guidance (scenario end-point) | CA21: =CHOOSE(MATCH($CF$2,{"Bull","Base","Bear"},0),$CN$16,$CO$16,$CP$16) -> 1064 | CM21: Naval & Power Adjusted OI ($m) | CN21: 283 | CO21: 280.5 | CP21: 278 | CQ21: Adj. margin 16.8–17.0%.
B22: Memo: FY26 Adjusted OI guidance (scenario end-point) | CA22: =CHOOSE(MATCH($CF$2,{"Bull","Base","Bear"},0),$CN$17,$CO$17,$CP$17) -> 197.5 | CM22: Corporate & other ($m) | CN22: -44 | CO22: -43.5 | CP22: -43 | CQ22: High OI end pairs with -$44m (764-43 = 721 ≈ 720 low; 780-44 = 736 high).
B24: Defense Electronics (embedded computing, tactical communications, turret aiming & stabilization) — current segment basis from Q1/20 | CF24: DEFENSE ELECTRONICS — modelling logic | CM24: FY26 point estimates (all cases)
B25: Sales | AS25: 139.581 | AT25: 139.613 | AU25: 148.324 | AV25: 181.239 | AW25: 608.757 | AX25: 181.212 | AY25: 162.351 | AZ25: 181.504 | BA25: 199.259 | BB25: 724.326 | BC25: 143.069 | BD25: 149.549 | BE25: 161.188 | BF25: 236.456 | BG25: 690.262 | BH25: 162.154 | BI25: 197.722 | BJ25: 216.285 | BK25: 239.751 | BL25: 815.912 | BM25: 211.741 | BN25: 228.461 | BO25: 243.029 | BP25: 227.475 | BQ25: 910.706 | BR25: 245.164 | BS25: 253.011 | BT25: 253.159 | BU25: 267.276 | BV25: 1018.61 | BW25: 256.288 | BX25: 245.987 | BY25: =BT25*(1+BY27) -> 273.73043 | BZ25: =BU25*(1+BZ27) -> 288.99457 | CA25: =SUM(BW25,BX25,BY25,BZ25) -> 1065 | CB25: =CA25*(1+CB27) -> 1128.9 | CC25: =CB25*(1+CC27) -> 1196.634 | CD25: =CC25*(1+CD27) -> 1262.4489 | CE25: =CD25*(1+CE27) -> 1331.8836 | CF25: Q3/Q4-26E: prior-year quarter × (1 + guidance-implied 2H/26 y/y growth + revenue calibration Δ). 2027E+: prior year × (1 + scenario lever). | CH25: =IFERROR((CE25/BV25)^(1/5)-1,"n/m") -> 0.055095242 | CI25: =IFERROR((BV25/AW25)^(1/5)-1,"n/m") -> 0.10844154 | CJ25: =IFERROR((BV25/X25)^(1/10)-1,"n/m") -> n/m | CK25: =IFERROR((BV25/C25)^(1/19)-1,"n/m") -> n/m | CM25: Interest expense ($m) | CO25: 41 | CQ25: ~$41m; $200m 4.24% notes due Dec-2026.
B26: Sales y/y % | D26: =IF(AND(ISNUMBER(D25),ISNUMBER(C25)),IFERROR(D25/C25-1,""),"") | E26: =IF(AND(ISNUMBER(E25),ISNUMBER(D25)),IFERROR(E25/D25-1,""),"") | F26: =IF(AND(ISNUMBER(F25),ISNUMBER(E25)),IFERROR(F25/E25-1,""),"") | G26: =IF(AND(ISNUMBER(G25),ISNUMBER(F25)),IFERROR(G25/F25-1,""),"") | H26: =IF(AND(ISNUMBER(H25),ISNUMBER(G25)),IFERROR(H25/G25-1,""),"") | I26: =IF(AND(ISNUMBER(I25),ISNUMBER(H25)),IFERROR(I25/H25-1,""),"") | N26: =IF(AND(ISNUMBER(N25),ISNUMBER(I25)),IFERROR(N25/I25-1,""),"") | O26: =IF(AND(ISNUMBER(O25),ISNUMBER(J25)),IFERROR(O25/J25-1,""),"") | P26: =IF(AND(ISNUMBER(P25),ISNUMBER(K25)),IFERROR(P25/K25-1,""),"") | Q26: =IF(AND(ISNUMBER(Q25),ISNUMBER(L25)),IFERROR(Q25/L25-1,""),"") | R26: =IF(AND(ISNUMBER(R25),ISNUMBER(M25)),IFERROR(R25/M25-1,""),"") | S26: =IF(AND(ISNUMBER(S25),ISNUMBER(N25)),IFERROR(S25/N25-1,""),"") | T26: =IF(AND(ISNUMBER(T25),ISNUMBER(O25)),IFERROR(T25/O25-1,""),"") | U26: =IF(AND(ISNUMBER(U25),ISNUMBER(P25)),IFERROR(U25/P25-1,""),"") | ... BX26: =IF(AND(ISNUMBER(BX25),ISNUMBER(BS25)),IFERROR(BX25/BS25-1,""),"") -> -0.027761639 | BY26: =IFERROR(BY25/BT25-1,"") -> 0.081258947 | BZ26: =IFERROR(BZ25/BU25-1,"") -> 0.081258947 | CA26: =IFERROR(CA25/BV25-1,"") -> 0.045542455 | CB26: =IFERROR(CB25/CA25-1,"") -> 0.06 | CC26: =IFERROR(CC25/CB25-1,"") -> 0.06 | CD26: =IFERROR(CD25/CC25-1,"") -> 0.055 | CE26: =IFERROR(CE25/CD25-1,"") -> 0.055 | CM26: Other income, net — GAAP ($m) | CO26: 51 | CQ26: Reported guidance $51m incl. $17m gain on equity securities (Q2/26); adjusted ~$34m.
B27: Forecast sales growth driver % (Q3/Q4-26E: guidance-implied 2H y/y + calibration; 2027E+: lever) | BY27: =($CA$35-$BW$25-$BX$25)/($BT$25+$BU$25)-1+BY89 -> 0.081258947 | BZ27: =($CA$35-$BW$25-$BX$25)/($BT$25+$BU$25)-1+BZ89 -> 0.081258947 | CA27: =IFERROR(CA25/BV25-1,"") -> 0.045542455 | CB27: =CHOOSE(MATCH($CF$2,{"Bull","Base","Bear"},0),$CN$52,$CO$52,$CP$52) -> 0.06 | CC27: =CHOOSE(MATCH($CF$2,{"Bull","Base","Bear"},0),$CN$53,$CO$53,$CP$53) -> 0.06 | CD27: =CHOOSE(MATCH($CF$2,{"Bull","Base","Bear"},0),$CN$54,$CO$54,$CP$54) -> 0.055 | CE27: =CHOOSE(MATCH($CF$2,{"Bull","Base","Bear"},0),$CN$55,$CO$55,$CP$55) -> 0.055 | CF27: FY26: (segment guidance end-point − 1H/26) ÷ 2H/25 − 1, by scenario (high / mid / low). 2027E–30E: scenario lever (table →). | CM27: Gain on equity securities — excluded from adjusted ($m) | CO27: 17 | CQ27: Guidance adjustment column (-$17m other income).
B28: Operating income (GAAP, as reported) | AS28: 24.063 | AT28: 24.736 | AU28: 35.103 | AV28: 34.846 | AW28: 118.748 | AX28: 36.623 | AY28: 29.271 | AZ28: 40.762 | BA28: 52.433 | BB28: 159.089 | BC28: 23.29 | BD28: 24.46 | BE28: 36.588 | BF28: 70.23 | BG28: 154.568 | BH28: 23.368 | BI28: 43.18 | BJ28: 56.212 | BK28: 69.015 | BL28: 191.775 | BM28: 48.081 | BN28: 58.244 | BO28: 63.639 | BP28: 54.775 | BQ28: 224.739 | BR28: 67.449 | BS28: 67.833 | BT28: 73.957 | BU28: 68.777 | BV28: 278.016 | BW28: 71.927 | BX28: 68.768 | BY28: =BY31-BY30 -> 79.338763 | BZ28: =BZ31-BZ30 -> 74.052074 | CA28: =SUM(BW28,BX28,BY28,BZ28) -> 294.08584 | CB28: =CB31-CB30 -> 314.65984 | CC28: =CC31-CC30 -> 336.33472 | CD28: =CD31-CD30 -> 356.07918 | CE28: =CE31-CE30 -> 376.90958 | CM28: Tax rate | CO28: 0.215 | CQ28: 21.5% (reported and adjusted).
B29: Operating margin (GAAP) % | C29: =IF(AND(ISNUMBER(C28),ISNUMBER(C25)),IFERROR(C28/C25,""),"") | D29: =IF(AND(ISNUMBER(D28),ISNUMBER(D25)),IFERROR(D28/D25,""),"") | E29: =IF(AND(ISNUMBER(E28),ISNUMBER(E25)),IFERROR(E28/E25,""),"") | F29: =IF(AND(ISNUMBER(F28),ISNUMBER(F25)),IFERROR(F28/F25,""),"") | G29: =IF(AND(ISNUMBER(G28),ISNUMBER(G25)),IFERROR(G28/G25,""),"") | H29: =IF(AND(ISNUMBER(H28),ISNUMBER(H25)),IFERROR(H28/H25,""),"") | I29: =IF(AND(ISNUMBER(I28),ISNUMBER(I25)),IFERROR(I28/I25,""),"") | J29: =IF(AND(ISNUMBER(J28),ISNUMBER(J25)),IFERROR(J28/J25,""),"") | ... BX29: =IF(AND(ISNUMBER(BX28),ISNUMBER(BX25)),IFERROR(BX28/BX25,""),"") -> 0.27955949 | BY29: =IFERROR(BY28/BY25,"") -> 0.28984268 | BZ29: =IFERROR(BZ28/BZ25,"") -> 0.25624037 | CA29: =IFERROR(CA28/CA25,"") -> 0.27613694 | CB29: =IFERROR(CB28/CB25,"") -> 0.27873136 | CC29: =IFERROR(CC28/CC25,"") -> 0.28106733 | CD29: =IFERROR(CD28/CD25,"") -> 0.28205434 | CE29: =IFERROR(CE28/CE25,"") -> 0.28298989 | CM29: Diluted shares (m) | CO29: 37.1 | CQ29: Memo — guidance predates the Aug–Oct 10b5-1 plans ($300m); model shares are built from the buyback schedule.
B30: (+) Adjustments (first-year purchase accounting, restructuring, exited businesses) | AS30: 2.737 | AT30: 8.764 | AU30: 3.597 | AV30: 10.492 | AW30: 25.625 | AX30: 1.577 | AY30: 1.529 | AZ30: 1.538 | BA30: 0.442 | BB30: 5.134 | BC30: 0 | BD30: 0 | BE30: 0 | BF30: 0 | BG30: 0 | BH30: 0 | BI30: 0 | BJ30: 0 | BK30: 0 | BL30: 0 | BM30: 0 | BN30: 0.523 | BO30: 0.819 | BP30: 0.587 | BQ30: 1.929 | BR30: 0 | BS30: 0.019 | BT30: 0 | BU30: 0.323 | BV30: 0.342 | BW30: 0.096 | BX30: 0.03 | BY30: =MAX(0,($CO$31-$BW$30-$BX$30)/2) -> 0 | BZ30: =MAX(0,($CO$31-$BW$30-$BX$30)/2) -> 0 | CA30: =SUM(BW30,BX30,BY30,BZ30) -> 0.126 | CB30: 0 | CC30: 0 | CD30: 0 | CE30: 0 | CF30: Q3/Q4-26E: remaining FY26 Restructuring Program cost per the guidance adjustment column, spread evenly. 2027E+: none assumed. | CM30: FY26 restructuring adjustment — A&I ($m) | CO30: 6 | CQ30: FY26 Restructuring Program, guidance adjustment column.
B31: Adjusted operating income | AS31: =AS28+AS30 -> 26.8 | AT31: =AT28+AT30 -> 33.5 | AU31: =AU28+AU30 -> 38.7 | AV31: =AV28+AV30 -> 45.338 | AW31: =AW28+AW30 -> 144.373 | AX31: =AX28+AX30 -> 38.2 | AY31: =AY28+AY30 -> 30.8 | AZ31: =AZ28+AZ30 -> 42.3 | ... BX31: =BX28+BX30 -> 68.798 | BY31: =BY25*BY32 -> 79.338763 | BZ31: =BZ25*BZ32 -> 74.052074 | CA31: =SUM(BW31,BX31,BY31,BZ31) -> 294.21184 | CB31: =CA31+(CB25-CA25)*CB34 -> 314.65984 | CC31: =CB31+(CC25-CB25)*CC34 -> 336.33472 | CD31: =CC31+(CD25-CC25)*CD34 -> 356.07918 | CE31: =CD31+(CE25-CD25)*CE34 -> 376.90958 | CF31: 2027E+: prior-year Adjusted OI + Δ sales × incremental margin (scenario lever) — margin is an output, not an input. | CH31: =IFERROR((CE31/BV31)^(1/5)-1,"n/m") -> 0.06249451 | CI31: =IFERROR((BV31/AW31)^(1/5)-1,"n/m") -> 0.14031161 | CJ31: =IFERROR((BV31/X31)^(1/10)-1,"n/m") -> n/m | CK31: =IFERROR((BV31/C31)^(1/19)-1,"n/m") -> n/m | CM31: FY26 restructuring adjustment — Defense Electronics ($m) | CO31: 0
B32: Adjusted operating margin % | C32: =IF(AND(ISNUMBER(C31),ISNUMBER(C25)),IFERROR(C31/C25,""),"") | D32: =IF(AND(ISNUMBER(D31),ISNUMBER(D25)),IFERROR(D31/D25,""),"") | E32: =IF(AND(ISNUMBER(E31),ISNUMBER(E25)),IFERROR(E31/E25,""),"") | F32: =IF(AND(ISNUMBER(F31),ISNUMBER(F25)),IFERROR(F31/F25,""),"") | G32: =IF(AND(ISNUMBER(G31),ISNUMBER(G25)),IFERROR(G31/G25,""),"") | H32: =IF(AND(ISNUMBER(H31),ISNUMBER(H25)),IFERROR(H31/H25,""),"") | I32: =IF(AND(ISNUMBER(I31),ISNUMBER(I25)),IFERROR(I31/I25,""),"") | J32: =IF(AND(ISNUMBER(J31),ISNUMBER(J25)),IFERROR(J31/J25,""),"") | ... BX32: =IF(AND(ISNUMBER(BX31),ISNUMBER(BX25)),IFERROR(BX31/BX25,""),"") -> 0.27968145 | BY32: =BY33+BY93 -> 0.28984268 | BZ32: =BZ33+BZ93 -> 0.25624037 | CA32: =IFERROR(CA31/CA25,"") -> 0.27625525 | CB32: =IFERROR(CB31/CB25,"") -> 0.27873136 | CC32: =IFERROR(CC31/CC25,"") -> 0.28106733 | CD32: =IFERROR(CD31/CD25,"") -> 0.28205434 | CE32: =IFERROR(CE31/CE25,"") -> 0.28298989 | CH32: =IFERROR(AVERAGE(CA32,CB32,CC32,CD32,CE32),"n/m") -> 0.28021963 | CI32: =IFERROR(AVERAGE(BB32,BG32,BL32,BQ32,BV32),"n/m") -> 0.24157211 | CJ32: =IFERROR(AVERAGE(AC32,AH32,AM32,AR32,AW32,BB32,BG32,BL32,BQ32,BV32),"n/m") -> 0.24083681 | CK32: =IFERROR(AVERAGE(C32,D32,E32,F32,G32,H32,I32,N32,S32,X32,AC32,AH32,AM32,AR32,AW32,BB32,BG32,BL32,BQ32,BV32),"n/m") -> 0.24083681 | CM32: FY26 restructuring adjustment — Naval & Power ($m) | CO32: 1
B33: Adjusted margin before outlook calibration % (Q3/Q4-26E helper) | BY33: =BT32+(($CA$36-$BW$31-$BX$31)-($BT$32*$BY$25+$BU$32*$BZ$25))/($BY$25+$BZ$25) -> 0.29035477 | BZ33: =BU32+(($CA$36-$BW$31-$BX$31)-($BT$32*$BY$25+$BU$32*$BZ$25))/($BY$25+$BZ$25) -> 0.25675245 | CF33: Prior-year quarter margin + uniform shift so that the segment hits its FY26 Adjusted OI guidance end-point (scenario). | CM33: Capex increase vs 2025 ($m) | CO33: 25 | CQ33: "Year-over-year increase of approximately $25 million compared with 2025".
B34: Incremental Adjusted OI margin on Δ sales % (2027E+: lever) | BB34: =IFERROR((BB31-AW31)/(BB25-AW25),"") -> 0.17175886 | BG34: =IFERROR((BG31-BB31)/(BG25-BB25),"") -> 0.28343706 | BL34: =IFERROR((BL31-BG31)/(BL25-BG25),"") -> 0.2961162 | BQ34: =IFERROR((BQ31-BL31)/(BQ25-BL25),"") -> 0.36809292 | BV34: =IFERROR((BV31-BQ31)/(BV25-BQ25),"") -> 0.47903692 | CA34: =IFERROR((CA31-BV31)/(CA25-BV25),"") -> 0.34175119 | CB34: =CHOOSE(MATCH($CF$2,{"Bull","Base","Bear"},0),$CN$58,$CO$58,$CP$58) -> 0.32 | CC34: =CHOOSE(MATCH($CF$2,{"Bull","Base","Bear"},0),$CN$59,$CO$59,$CP$59) -> 0.32 | CD34: =CHOOSE(MATCH($CF$2,{"Bull","Base","Bear"},0),$CN$60,$CO$60,$CP$60) -> 0.3 | CE34: =CHOOSE(MATCH($CF$2,{"Bull","Base","Bear"},0),$CN$61,$CO$61,$CP$61) -> 0.3 | CM34: Amortization of acquired intangibles FY26 ($m) | CO34: 60 | CQ34: FY2025 10-K expected amortization: 2026 $60m, 2027 $57m, 2028 $51m, 2029 $51m, 2030 $50m.
B35: Memo: FY26 sales guidance (scenario end-point) | CA35: =CHOOSE(MATCH($CF$2,{"Bull","Base","Bear"},0),$CN$18,$CO$18,$CP$18) -> 1065 | CM35: 2H/26 share repurchases ($m) | CN35: 400 | CO35: 300 | CP35: 300 | CQ35: 10b5-1 plans: $100m (10-Aug), $100m (18-Aug), $100m (10-Sep→30-Oct); $600m authorization left.
B36: Memo: FY26 Adjusted OI guidance (scenario end-point) | CA36: =CHOOSE(MATCH($CF$2,{"Bull","Base","Bear"},0),$CN$19,$CO$19,$CP$19) -> 294.5 | CM36: Minimum net debt / Adjusted EBITDA (x) — buyback floor 2027E+ | CN36: 1 | CO36: 0.5 | CP36: 0.25 | CQ36: CW ran 0.3–0.9x net leverage 2021–25; surplus FCF returned via buybacks once leverage is at the floor.
CM37: Minimum annual repurchases 2027E+ ($m) | CN37: 60 | CO37: 60 | CP37: 60 | CQ37: "Min. $60M share repurchase ... to offset dilution" (2025/2026 guidance).
B38: Naval & Power (naval pumps/valves/generators, arresting systems, commercial & government nuclear, process) — current segment basis from Q1/20 | CF38: NAVAL & POWER — modelling logic
B39: Sales | AS39: 234.922 | AT39: 233.023 | AU39: 234.522 | AV39: 274.439 | AW39: 976.906 | AX39: 235.516 | AY39: 259.431 | AZ39: 242.819 | BA39: 257.505 | BB39: 995.271 | BC39: 225.28 | BD39: 251.236 | BE39: 256.261 | BF39: 297.951 | BG39: 1030.728 | BH39: 266.259 | BI39: 280.414 | BJ39: 287.744 | BK39: 307.816 | BL39: 1142.233 | BM39: 282.101 | BN39: 323.098 | BO39: 327.23 | BP39: 345.921 | BQ39: 1278.35 | BR39: 333.235 | BS39: 384.427 | BT39: 368.026 | BU39: 417.314 | BV39: 1503.002 | BW39: 402.48 | BX39: 410.256 | BY39: =BT39*(1+BY41) -> 397.74775 | BZ39: =BU39*(1+BZ41) -> 451.01625 | CA39: =SUM(BW39,BX39,BY39,BZ39) -> 1661.5 | CB39: =CA39*(1+CB41) -> 1794.42 | CC39: =CB39*(1+CC41) -> 1929.0015 | CD39: =CC39*(1+CD41) -> 2064.0316 | CE39: =CD39*(1+CE41) -> 2208.5138 | CF39: Q3/Q4-26E: prior-year quarter × (1 + guidance-implied 2H/26 y/y growth + revenue calibration Δ). 2027E+: prior year × (1 + scenario lever). | CH39: =IFERROR((CE39/BV39)^(1/5)-1,"n/m") -> 0.080010835 | CI39: =IFERROR((BV39/AW39)^(1/5)-1,"n/m") -> 0.089987096 | CJ39: =IFERROR((BV39/X39)^(1/10)-1,"n/m") -> n/m | CK39: =IFERROR((BV39/C39)^(1/19)-1,"n/m") -> n/m | CM39: AI_g (Aerospace & Industrial sales growth y/y) | CN39: 0.03 | CO39: Δ → | CP39: -0.03 | CQ39: Commercial aero OEM ramp (narrow/widebody actuation, sensors, surface treatment), defense actuation; FY26 +8–10%.
B40: Sales y/y % | D40: =IF(AND(ISNUMBER(D39),ISNUMBER(C39)),IFERROR(D39/C39-1,""),"") | E40: =IF(AND(ISNUMBER(E39),ISNUMBER(D39)),IFERROR(E39/D39-1,""),"") | F40: =IF(AND(ISNUMBER(F39),ISNUMBER(E39)),IFERROR(F39/E39-1,""),"") | G40: =IF(AND(ISNUMBER(G39),ISNUMBER(F39)),IFERROR(G39/F39-1,""),"") | H40: =IF(AND(ISNUMBER(H39),ISNUMBER(G39)),IFERROR(H39/G39-1,""),"") | I40: =IF(AND(ISNUMBER(I39),ISNUMBER(H39)),IFERROR(I39/H39-1,""),"") | N40: =IF(AND(ISNUMBER(N39),ISNUMBER(I39)),IFERROR(N39/I39-1,""),"") | O40: =IF(AND(ISNUMBER(O39),ISNUMBER(J39)),IFERROR(O39/J39-1,""),"") | P40: =IF(AND(ISNUMBER(P39),ISNUMBER(K39)),IFERROR(P39/K39-1,""),"") | Q40: =IF(AND(ISNUMBER(Q39),ISNUMBER(L39)),IFERROR(Q39/L39-1,""),"") | R40: =IF(AND(ISNUMBER(R39),ISNUMBER(M39)),IFERROR(R39/M39-1,""),"") | S40: =IF(AND(ISNUMBER(S39),ISNUMBER(N39)),IFERROR(S39/N39-1,""),"") | T40: =IF(AND(ISNUMBER(T39),ISNUMBER(O39)),IFERROR(T39/O39-1,""),"") | U40: =IF(AND(ISNUMBER(U39),ISNUMBER(P39)),IFERROR(U39/P39-1,""),"") | ... BX40: =IF(AND(ISNUMBER(BX39),ISNUMBER(BS39)),IFERROR(BX39/BS39-1,""),"") -> 0.067188309 | BY40: =IFERROR(BY39/BT39-1,"") -> 0.080759926 | BZ40: =IFERROR(BZ39/BU39-1,"") -> 0.080759926 | CA40: =IFERROR(CA39/BV39-1,"") -> 0.10545428 | CB40: =IFERROR(CB39/CA39-1,"") -> 0.08 | CC40: =IFERROR(CC39/CB39-1,"") -> 0.075 | CD40: =IFERROR(CD39/CC39-1,"") -> 0.07 | CE40: =IFERROR(CE39/CD39-1,"") -> 0.07 | CM40: 2027E | CN40: =CO40+$CN$39 -> 0.1 | CO40: 0.07 | CP40: =CO40+$CP$39 -> 0.04
B41: Forecast sales growth driver % (Q3/Q4-26E: guidance-implied 2H y/y + calibration; 2027E+: lever) | BY41: =($CA$49-$BW$39-$BX$39)/($BT$39+$BU$39)-1+BY89 -> 0.080759926 | BZ41: =($CA$49-$BW$39-$BX$39)/($BT$39+$BU$39)-1+BZ89 -> 0.080759926 | CA41: =IFERROR(CA39/BV39-1,"") -> 0.10545428 | CB41: =CHOOSE(MATCH($CF$2,{"Bull","Base","Bear"},0),$CN$64,$CO$64,$CP$64) -> 0.08 | CC41: =CHOOSE(MATCH($CF$2,{"Bull","Base","Bear"},0),$CN$65,$CO$65,$CP$65) -> 0.075 | CD41: =CHOOSE(MATCH($CF$2,{"Bull","Base","Bear"},0),$CN$66,$CO$66,$CP$66) -> 0.07 | CE41: =CHOOSE(MATCH($CF$2,{"Bull","Base","Bear"},0),$CN$67,$CO$67,$CP$67) -> 0.07 | CF41: FY26: (segment guidance end-point − 1H/26) ÷ 2H/25 − 1, by scenario (high / mid / low). 2027E–30E: scenario lever (table →). | CM41: 2028E | CN41: =CO41+$CN$39 -> 0.095 | CO41: 0.065 | CP41: =CO41+$CP$39 -> 0.035
...

Sheet Bull-Base-Bear
B2: Curtiss-Wright (CW) — Bull / Base / Bear Case P&L Summary | J2: Share price ($): | K2: =Model!CA381 -> 544.21
B3: Adjusted figures (company definition: Adjusted operating income / Adjusted diluted EPS; Adjusted EBITDA = model definition) · USD millions · Live panel linked to Model — toggle scenario via Model!CF2. Bull and Bear panels are value snapshots generated from the Model with the switch set to each case. 2026E calibrated to the FY26 guidance end-points (high / mid / low). | J3: As of: | K3: =TODAY() -> 46302
B5: Scenario: | C5: =Model!$CF$2 -> Base | N5: Scenario: | O5: Bull | P5: Snapshot (values) — Model run with switch = Bull | Z5: Scenario: | AA5: Bear | AB5: Snapshot (values) — Model run with switch = Bear
B7: (USDm, except EPS and shares) | C7: 2025A | D7: 2026E | E7: 2027E | F7: 2028E | G7: 2029E | H7: 2030E | I7: 25-'30 CAGR | J7: LT Hist Avg | K7: LT Hist Min | L7: LT Hist Max | N7: (USDm, except EPS and shares) | O7: 2025A | P7: 2026E | Q7: 2027E | R7: 2028E | S7: 2029E | T7: 2030E | U7: 25-'30 CAGR | V7: LT Hist Avg | W7: LT Hist Min | X7: LT Hist Max | Z7: (USDm, except EPS and shares) | AA7: 2025A | AB7: 2026E | AC7: 2027E | AD7: 2028E | AE7: 2029E | AF7: 2030E | AG7: 25-'30 CAGR | AH7: LT Hist Avg | AI7: LT Hist Min | AJ7: LT Hist Max
B9: Sales | C9: =Model!BV114 -> 3498.372 | D9: =Model!CA114 -> 3790.5 | E9: =Model!CB114 -> 4111.8 | F9: =Model!CC114 -> 4493.1167 | G9: =Model!CD114 -> 4876.9605 | H9: =Model!CE114 -> 5283.7538 | I9: =IFERROR((H9/C9)^(1/5)-1,"n/m") -> 0.085963719 | N9: Sales | O9: 3498.372 | P9: 3813 | Q9: 4300.23 | R9: 4921.9079 | S9: 5571.5524 | T9: 6272.348 | U9: =IFERROR((T9/O9)^(1/5)-1,"n/m") -> 0.1238616 | Z9: Sales | AA9: 3498.372 | AB9: 3768 | AC9: 3924.72 | AD9: 4074.0294 | AE9: 4208.8136 | AF9: 4348.2277 | AG9: =IFERROR((AF9/AA9)^(1/5)-1,"n/m") -> 0.044453857
B10: Sales y/y % | D10: =IFERROR(D9/C9-1,"") -> 0.083503984 | E10: =IFERROR(E9/D9-1,"") -> 0.084764543 | F10: =IFERROR(F9/E9-1,"") -> 0.092737171 | G10: =IFERROR(G9/F9-1,"") -> 0.085429307 | H10: =IFERROR(H9/G9-1,"") -> 0.083411215 | N10: Sales y/y % | P10: 0.089935547 | Q10: 0.12778127 | R10: 0.14456852 | S10: 0.13199039 | T10: 0.12578103 | Z10: Sales y/y % | AB10: 0.077072421 | AC10: 0.041592357 | AD10: 0.038043338 | AE10: 0.033083738 | AF10: 0.033124328
B11: Naval & Power sales y/y % (largest segment; growth driver) | C11: =Model!BV212 -> 0.17573591 | D11: =Model!CA212 -> 0.10545428 | E11: =Model!CB212 -> 0.08 | F11: =Model!CC212 -> 0.075 | G11: =Model!CD212 -> 0.07 | H11: =Model!CE212 -> 0.07 | N11: Naval & Power sales y/y % (largest segment; growth driver) | O11: 0.17573591 | P11: 0.10977896 | Q11: 0.11 | R11: 0.105 | S11: 0.1 | T11: 0.1 | Z11: Naval & Power sales y/y % (largest segment; growth driver) | AA11: 0.17573591 | AB11: 0.10112961 | AC11: 0.05 | AD11: 0.045 | AE11: 0.04 | AF11: 0.04
B12: Adjusted operating income (company KPI) | C12: =Model!BV159 -> 650.994 | D12: =Model!CA159 -> 728 | E12: =Model!CB159 -> 809.7922 | F12: =Model!CC159 -> 898.86833 | G12: =Model!CD159 -> 986.5102 | H12: =Model!CE159 -> 1079.4849 | I12: =IFERROR((H12/C12)^(1/5)-1,"n/m") -> 0.10644014 | N12: Adjusted operating income (company KPI) | O12: 650.994 | P12: 736 | Q12: 885.66972 | R12: 1057.0994 | S12: 1233.728 | T12: 1425.4721 | U12: =IFERROR((T12/O12)^(1/5)-1,"n/m") -> 0.16970501 | Z12: Adjusted operating income (company KPI) | AA12: 650.994 | AB12: 720 | AC12: 751.58558 | AD12: 780.27985 | AE12: 805.49176 | AF12: 831.54921 | AG12: =IFERROR((AF12/AA12)^(1/5)-1,"n/m") -> 0.050176253
B13: Adjusted operating margin % | C13: =IFERROR(C12/C9,"") -> 0.18608484 | D13: =IFERROR(D12/D9,"") -> 0.1920591 | E13: =IFERROR(E12/E9,"") -> 0.19694348 | F13: =IFERROR(F12/F9,"") -> 0.20005453 | G13: =IFERROR(G12/G9,"") -> 0.20227972 | H13: =IFERROR(H12/H9,"") -> 0.20430266 | J13: =IFERROR(AVERAGE(Model!C160,Model!D160,Model!E160,Model!F160,Model!G160,Model!H160,Model!I160,Model!N160,Model!S160,Model!X160,Model!AC160,Model!AH160,Model!AM160,Model!AR160,Model!AW160,Model!BB160,Model!BG160,Model!BL160,Model!BQ160,Model!BV160),"") -> 0.13623148 | K13: =IFERROR(MIN(Model!C160,Model!D160,Model!E160,Model!F160,Model!G160,Model!H160,Model!I160,Model!N160,Model!S160,Model!X160,Model!AC160,Model!AH160,Model!AM160,Model!AR160,Model!AW160,Model!BB160,Model!BG160,Model!BL160,Model!BQ160,Model!BV160),"") -> 0.093046718 | L13: =IFERROR(MAX(Model!C160,Model!D160,Model!E160,Model!F160,Model!G160,Model!H160,Model!I160,Model!N160,Model!S160,Model!X160,Model!AC160,Model!AH160,Model!AM160,Model!AR160,Model!AW160,Model!BB160,Model!BG160,Model!BL160,Model!BQ160,Model!BV160),"") -> 0.18608484 | N13: Adjusted operating margin % | O13: 0.18608484 | P13: 0.19302387 | Q13: 0.20595869 | R13: 0.21477431 | S13: 0.22143344 | T13: 0.22726292 | V13: 0.13623148 | W13: 0.093046718 | X13: 0.18608484 | Z13: Adjusted operating margin % | AA13: 0.18608484 | AB13: 0.1910828 | AC13: 0.19150043 | AD13: 0.19152533 | AE13: 0.19138214 | AF13: 0.19123865 | AH13: 0.13623148 | AI13: 0.093046718 | AJ13: 0.18608484
B15: Operating income (GAAP) | C15: =Model!BV123 -> 633.521 | D15: =Model!CA123 -> 720.874 | E15: =Model!CB123 -> 809.7922 | F15: =Model!CC123 -> 898.86833 | G15: =Model!CD123 -> 986.5102 | H15: =Model!CE123 -> 1079.4849 | I15: =IFERROR((H15/C15)^(1/5)-1,"n/m") -> 0.11247719 | N15: Operating income (GAAP) | O15: 633.521 | P15: 728.874 | Q15: 885.66972 | R15: 1057.0994 | S15: 1233.728 | T15: 1425.4721 | U15: =IFERROR((T15/O15)^(1/5)-1,"n/m") -> 0.17608726 | Z15: Operating income (GAAP) | AA15: 633.521 | AB15: 712.874 | AC15: 751.58558 | AD15: 780.27985 | AE15: 805.49176 | AF15: 831.54921 | AG15: =IFERROR((AF15/AA15)^(1/5)-1,"n/m") -> 0.055906316
B16: Operating income y/y % | D16: =IFERROR(D15/C15-1,"") -> 0.13788493 | E16: =IFERROR(E15/D15-1,"") -> 0.12334777 | F16: =IFERROR(F15/E15-1,"") -> 0.10999875 | G16: =IFERROR(G15/F15-1,"") -> 0.097502452 | H16: =IFERROR(H15/G15-1,"") -> 0.094246112 | N16: Operating income y/y % | P16: 0.15051277 | Q16: 0.21512047 | R16: 0.19355933 | S16: 0.16708806 | T16: 0.15541846 | Z16: Operating income y/y % | AB16: 0.12525709 | AC16: 0.054303538 | AD16: 0.03817832 | AE16: 0.032311362 | AF16: 0.032349739
B17: Operating margin (GAAP) % | C17: =IFERROR(C15/C9,"") -> 0.18109023 | D17: =IFERROR(D15/D9,"") -> 0.19017913 | E17: =IFERROR(E15/E9,"") -> 0.19694348 | F17: =IFERROR(F15/F9,"") -> 0.20005453 | G17: =IFERROR(G15/G9,"") -> 0.20227972 | H17: =IFERROR(H15/H9,"") -> 0.20430266 | J17: =IFERROR(AVERAGE(Model!C124,Model!D124,Model!E124,Model!F124,Model!G124,Model!H124,Model!I124,Model!N124,Model!S124,Model!X124,Model!AC124,Model!AH124,Model!AM124,Model!AR124,Model!AW124,Model!BB124,Model!BG124,Model!BL124,Model!BQ124,Model!BV124),"") -> 0.13144665 | K17: =IFERROR(MIN(Model!C124,Model!D124,Model!E124,Model!F124,Model!G124,Model!H124,Model!I124,Model!N124,Model!S124,Model!X124,Model!AC124,Model!AH124,Model!AM124,Model!AR124,Model!AW124,Model!BB124,Model!BG124,Model!BL124,Model!BQ124,Model!BV124),"") -> 0.076962754 | L17: =IFERROR(MAX(Model!C124,Model!D124,Model!E124,Model!F124,Model!G124,Model!H124,Model!I124,Model!N124,Model!S124,Model!X124,Model!AC124,Model!AH124,Model!AM124,Model!AR124,Model!AW124,Model!BB124,Model!BG124,Model!BL124,Model!BQ124,Model!BV124),"") -> 0.18109023 | N17: Operating margin (GAAP) % | O17: 0.18109023 | P17: 0.191155 | Q17: 0.20595869 | R17: 0.21477431 | S17: 0.22143344 | T17: 0.22726292 | V17: 0.13144665 | W17: 0.076962754 | X17: 0.18109023 | Z17: Operating margin (GAAP) % | AA17: 0.18109023 | AB17: 0.18919161 | AC17: 0.19150043 | AD17: 0.19152533 | AE17: 0.19138214 | AF17: 0.19123865 | AH17: 0.13144665 | AI17: 0.076962754 | AJ17: 0.18109023
B19: Adjusted net earnings | C19: =Model!BV189 -> 497.85842 | D19: =Model!CA189 -> 568.89077 | E19: =Model!CB189 -> 637.70049 | F19: =Model!CC189 -> 703.73998 | G19: =Model!CD189 -> 768.95149 | H19: =Model!CE189 -> 838.05972 | I19: =IFERROR((H19/C19)^(1/5)-1,"n/m") -> 0.10977215 | N19: Adjusted net earnings | O19: 497.85842 | P19: 575.17077 | Q19: 694.77951 | R19: 804.20272 | S19: 931.81057 | T19: 1071.2906 | U19: =IFERROR((T19/O19)^(1/5)-1,"n/m") -> 0.16562884 | Z19: Adjusted net earnings | AA19: 497.85842 | AB19: 562.61077 | AC19: 592.06532 | AD19: 617.11309 | AE19: 634.85935 | AF19: 653.84253 | AG19: =IFERROR((AF19/AA19)^(1/5)-1,"n/m") -> 0.056023208
B21: FDSO (m) | C21: =Model!BV143 -> 37.631 | D21: =Model!CA143 -> 36.925341 | E21: =Model!CB143 -> 36.423811 | F21: =Model!CC143 -> 35.94746 | G21: =Model!CD143 -> 35.473648 | H21: =Model!CE143 -> 34.938293 | I21: =IFERROR((H21/C21)^(1/5)-1,"n/m") -> -0.014739243 | N21: FDSO (m) | O21: 37.631 | P21: 36.902372 | Q21: 36.057861 | R21: 35.447148 | S21: 35.007245 | T21: 34.382138 | U21: =IFERROR((T21/O21)^(1/5)-1,"n/m") -> -0.017896126 | Z21: FDSO (m) | AA21: 37.631 | AB21: 36.925341 | AC21: 36.420443 | AD21: 35.796924 | AE21: 35.086715 | AF21: 34.41381 | AG21: =IFERROR((AF21/AA21)^(1/5)-1,"n/m") -> -0.017715255
B23: Adjusted EPS — Diluted ($) | C23: =Model!BV191 -> 13.230008 | D23: =Model!CA191 -> 15.406513 | E23: =Model!CB191 -> 17.507792 | F23: =Model!CC191 -> 19.576904 | G23: =Model!CD191 -> 21.676696 | H23: =Model!CE191 -> 23.986853 | I23: =IFERROR((H23/C23)^(1/5)-1,"n/m") -> 0.12637405 | N23: Adjusted EPS — Diluted ($) | O23: 13.230008 | P23: 15.586282 | Q23: 19.268462 | R23: 22.687374 | S23: 26.617649 | T23: 31.158347 | U23: =IFERROR((T23/O23)^(1/5)-1,"n/m") -> 0.18686921 | Z23: Adjusted EPS — Diluted ($) | AA23: 13.230008 | AB23: 15.236441 | AC23: 16.256401 | AD23: 17.239277 | AE23: 18.094009 | AF23: 18.999423 | AG23: =IFERROR((AF23/AA23)^(1/5)-1,"n/m") -> 0.075068317
B24: EPS y/y % | D24: =IFERROR(D23/C23-1,"") -> 0.16451281 | E24: =IFERROR(E23/D23-1,"") -> 0.13638895 | F24: =IFERROR(F23/E23-1,"") -> 0.11818238 | G24: =IFERROR(G23/F23-1,"") -> 0.10725864 | H24: =IFERROR(H23/G23-1,"") -> 0.1065733 | N24: EPS y/y % | P24: 0.17810073 | Q24: 0.23624494 | R24: 0.17743567 | S24: 0.17323621 | T24: 0.17058973 | Z24: EPS y/y % | AB24: 0.15165773 | AC24: 0.066942161 | AD24: 0.060460882 | AE24: 0.04958052 | AF24: 0.050039405
B26: P / E (x) — assumed (adjusted EPS) | G26: 28 | H26: 28 | N26: P / E (x) — assumed (adjusted EPS) | S26: 32 | T26: 32 | Z26: P / E (x) — assumed (adjusted EPS) | AE26: 24 | AF26: 24
B27: Price Target ($) | G27: =G26*G23 -> 606.9475 | H27: =H26*H23 -> 671.6319 | N27: Price Target ($) | S27: =S26*S23 -> 851.76477 | T27: =T26*T23 -> 997.06709 | Z27: Price Target ($) | AE27: =AE26*AE23 -> 434.25623 | AF27: =AF26*AF23 -> 455.98615
B28: Upside / (Downside) vs current | G28: =IFERROR(G27/$K$2-1,"") -> 0.11528178 | H28: =IFERROR(H27/$K$2-1,"") -> 0.23414104 | N28: Upside / (Downside) vs current | S28: =IFERROR(S27/$K$2-1,"") -> 0.56513987 | T28: =IFERROR(T27/$K$2-1,"") -> 0.83213666 | Z28: Upside / (Downside) vs current | AE28: =IFERROR(AE27/$K$2-1,"") -> -0.20204291 | AF28: =IFERROR(AF27/$K$2-1,"") -> -0.16211361
B29: IRR (to Dec-Y-1) | G29: =IFERROR((G27/$K$2)^(1/((DATE(2029-1,12,31)-$K$3)/365.25))-1,"") -> 0.050049659 | H29: =IFERROR((H27/$K$2)^(1/((DATE(2030-1,12,31)-$K$3)/365.25))-1,"") -> 0.067226388 | N29: IRR (to Dec-Y-1) | S29: =IFERROR((S27/$K$2)^(1/((DATE(2029-1,12,31)-$K$3)/365.25))-1,"") -> 0.22203598 | T29: =IFERROR((T27/$K$2)^(1/((DATE(2030-1,12,31)-$K$3)/365.25))-1,"") -> 0.20593931 | Z29: IRR (to Dec-Y-1) | AE29: =IFERROR((AE27/$K$2)^(1/((DATE(2029-1,12,31)-$K$3)/365.25))-1,"") -> -0.096090331 | AF29: =IFERROR((AF27/$K$2)^(1/((DATE(2030-1,12,31)-$K$3)/365.25))-1,"") -> -0.053232529
B31: Free Cash Flow (CFO − net capex) | C31: =Model!BV257 -> 553.71 | D31: =Model!CA257 -> 595 | E31: =Model!CB257 -> 623.11068 | F31: =Model!CC257 -> 682.26568 | G31: =Model!CD257 -> 755.04 | H31: =Model!CE257 -> 828.94351 | I31: =IFERROR((H31/C31)^(1/5)-1,"n/m") -> 0.084048004 | N31: Free Cash Flow (CFO − net capex) | O31: 553.71 | P31: 605 | Q31: 672.39007 | R31: 776.06662 | S31: 917.58763 | T31: 1068.2718 | U31: =IFERROR((T31/O31)^(1/5)-1,"n/m") -> 0.14045953 | Z31: Free Cash Flow (CFO − net capex) | AA31: 553.71 | AB31: 585 | AC31: 587.9775 | AD31: 604.82136 | AE31: 623.27602 | AF31: 639.99373 | AG31: =IFERROR((AF31/AA31)^(1/5)-1,"n/m") -> 0.029386981
B32: FCF % | C32: =IFERROR(C31/C9,"") -> 0.15827648 | D32: =IFERROR(D31/D9,"") -> 0.15697138 | E32: =IFERROR(E31/E9,"") -> 0.15154207 | F32: =IFERROR(F31/F9,"") -> 0.15184686 | G32: =IFERROR(G31/G9,"") -> 0.15481774 | H32: =IFERROR(H31/H9,"") -> 0.15688534 | J32: =IFERROR(AVERAGE(Model!C259,Model!D259,Model!E259,Model!F259,Model!G259,Model!H259,Model!I259,Model!N259,Model!S259,Model!X259,Model!AC259,Model!AH259,Model!AM259,Model!AR259,Model!AW259,Model!BB259,Model!BG259,Model!BL259,Model!BQ259,Model!BV259),"") -> 0.10025119 | K32: =IFERROR(MIN(Model!C259,Model!D259,Model!E259,Model!F259,Model!G259,Model!H259,Model!I259,Model!N259,Model!S259,Model!X259,Model!AC259,Model!AH259,Model!AM259,Model!AR259,Model!AW259,Model!BB259,Model!BG259,Model!BL259,Model!BQ259,Model!BV259),"") -> 0.033140806 | L32: =IFERROR(MAX(Model!C259,Model!D259,Model!E259,Model!F259,Model!G259,Model!H259,Model!I259,Model!N259,Model!S259,Model!X259,Model!AC259,Model!AH259,Model!AM259,Model!AR259,Model!AW259,Model!BB259,Model!BG259,Model!BL259,Model!BQ259,Model!BV259),"") -> 0.17848901 | N32: FCF % | O32: 0.15827648 | P32: 0.15866772 | Q32: 0.15636142 | R32: 0.15767597 | S32: 0.16469155 | T32: 0.17031449 | V32: 0.10025119 | W32: 0.033140806 | X32: 0.17848901 | Z32: FCF % | AA32: 0.15827648 | AB32: 0.15525478 | AC32: 0.14981387 | AD32: 0.14845778 | AE32: 0.14808829 | AF32: 0.14718496 | AH32: 0.10025119 | AI32: 0.033140806 | AJ32: 0.17848901
B33: FCF / share ($) | C33: =IFERROR(C31/C21,"") -> 14.714198 | D33: =IFERROR(D31/D21,"") -> 16.113595 | E33: =IFERROR(E31/E21,"") -> 17.107235 | F33: =IFERROR(F31/F21,"") -> 18.979524 | G33: =IFERROR(G31/G21,"") -> 21.284532 | H33: =IFERROR(H31/H21,"") -> 23.72593 | N33: FCF / share ($) | O33: 14.714198 | P33: 16.39461 | Q33: 18.647531 | R33: 21.893626 | S33: 26.211363 | T33: 31.070545 | Z33: FCF / share ($) | AA33: 14.714198 | AB33: 15.842778 | AC33: 16.144161 | AD33: 16.895903 | AE33: 17.763875 | AF33: 18.597003
B34: FCF Yield (on PT) | G34: =IFERROR(G33/G27,"") -> 0.035068161 | H34: =IFERROR(H33/H27,"") -> 0.035325795 | N34: FCF Yield (on PT) | S34: =IFERROR(S33/S27,"") -> 0.030773007 | T34: =IFERROR(T33/T27,"") -> 0.031161941 | Z34: FCF Yield (on PT) | AE34: =IFERROR(AE33/AE27,"") -> 0.040906437 | AF34: =IFERROR(AF33/AF27,"") -> 0.04078414
B35: Adjusted EBITDA (model: Adjusted OI + D&A) | C35: =Model!BV174 -> 775.811 | D35: =Model!CA174 -> 843.43211 | E35: =Model!CB174 -> 937.581 | F35: =Model!CC174 -> 1036.8582 | G35: =Model!CD174 -> 1140.8466 | H35: =Model!CE174 -> 1249.6453 | I35: =IFERROR((H35/C35)^(1/5)-1,"n/m") -> 0.10003414 | N35: Adjusted EBITDA (model: Adjusted OI + D&A) | O35: 775.811 | P35: 851.76281 | Q35: 1021.4734 | R35: 1217.0499 | S35: 1424.4829 | T35: 1647.0702 | U35: =IFERROR((T35/O35)^(1/5)-1,"n/m") -> 0.16249538 | Z35: Adjusted EBITDA (model: Adjusted OI + D&A) | AA35: 775.811 | AB35: 835.10141 | AC35: 871.3811 | AD35: 896.46433 | AE35: 923.83278 | AF35: 951.12085 | AG35: =IFERROR((AF35/AA35)^(1/5)-1,"n/m") -> 0.041587967
B36: Adjusted EBITDA % of sales | C36: =IFERROR(C35/C9,"") -> 0.22176344 | D36: =IFERROR(D35/D9,"") -> 0.2225121 | E36: =IFERROR(E35/E9,"") -> 0.22802203 | F36: =IFERROR(F35/F9,"") -> 0.23076592 | G36: =IFERROR(G35/G9,"") -> 0.23392573 | H36: =IFERROR(H35/H9,"") -> 0.2365071 | J36: =IFERROR(AVERAGE(Model!C175,Model!D175,Model!E175,Model!F175,Model!G175,Model!H175,Model!I175,Model!N175,Model!S175,Model!X175,Model!AC175,Model!AH175,Model!AM175,Model!AR175,Model!AW175,Model!BB175,Model!BG175,Model!BL175,Model!BQ175,Model!BV175),"") -> 0.17929397 | K36: =IFERROR(MIN(Model!C175,Model!D175,Model!E175,Model!F175,Model!G175,Model!H175,Model!I175,Model!N175,Model!S175,Model!X175,Model!AC175,Model!AH175,Model!AM175,Model!AR175,Model!AW175,Model!BB175,Model!BG175,Model!BL175,Model!BQ175,Model!BV175),"") -> 0.13582382 | L36: =IFERROR(MAX(Model!C175,Model!D175,Model!E175,Model!F175,Model!G175,Model!H175,Model!I175,Model!N175,Model!S175,Model!X175,Model!AC175,Model!AH175,Model!AM175,Model!AR175,Model!AW175,Model!BB175,Model!BG175,Model!BL175,Model!BQ175,Model!BV175),"") -> 0.22176344 | N36: Adjusted EBITDA % of sales | O36: 0.22176344 | P36: 0.2233839 | Q36: 0.23753925 | R36: 0.24727197 | S36: 0.25567073 | T36: 0.26259229 | V36: 0.17929397 | W36: 0.13582382 | X36: 0.22176344 | Z36: Adjusted EBITDA % of sales | AA36: 0.22176344 | AB36: 0.22162989 | AC36: 0.22202376 | AD36: 0.22004365 | AE36: 0.21949957 | AF36: 0.21873759 | AH36: 0.17929397 | AI36: 0.13582382 | AJ36: 0.22176344
B38: Net Debt | C38: =Model!BV376 -> 586.539 | D38: =Model!CA376 -> 347.03295 | E38: =Model!CB376 -> 468.7905 | F38: =Model!CC376 -> 518.4291 | G38: =Model!CD376 -> 570.42328 | H38: =Model!CE376 -> 624.82263 | N38: Net Debt | O38: 586.539 | P38: 437.00907 | Q38: 1021.4734 | R38: 1217.0499 | S38: 1424.4829 | T38: 1647.0702 | Z38: Net Debt | AA38: 586.539 | AB38: 357.03295 | AC38: 217.84527 | AD38: 224.11608 | AE38: 230.95819 | AF38: 237.78021
B39: Net Debt / Adjusted EBITDA (x) | C39: =IFERROR(C38/C35,"") -> 0.75603336 | D39: =IFERROR(D38/D35,"") -> 0.41145333 | E39: =IFERROR(E38/E35,"") -> 0.5 | F39: =IFERROR(F38/F35,"") -> 0.5 | G39: =IFERROR(G38/G35,"") -> 0.5 | H39: =IFERROR(H38/H35,"") -> 0.5 | N39: Net Debt / Adjusted EBITDA (x) | O39: 0.75603336 | P39: 0.51306427 | Q39: 1 | R39: 1 | S39: 1 | T39: 1 | Z39: Net Debt / Adjusted EBITDA (x) | AA39: 0.75603336 | AB39: 0.42753245 | AC39: 0.25 | AD39: 0.25 | AE39: 0.25 | AF39: 0.25
B40: Share repurchases ($m) | D40: =Model!CA266 -> 300 | E40: =Model!CB266 -> 414.68199 | F40: =Model!CC266 -> 399.11245 | G40: =Model!CD266 -> 471.38509 | H40: =Model!CE266 -> 544.74549 | N40: Share repurchases ($m) | P40: 400 | Q40: 626.87059 | R40: 339.50342 | S40: 489.95292 | T40: 652.9283 | Z40: Share repurchases ($m) | AB40: 300 | AC40: 418.60358 | AD40: 578.30835 | AE40: 594.84724 | AF40: 608.88382
B41: Implied avg buyback price ($) | D41: =Model!CA265 -> 544.21 | E41: =Model!CB265 -> 582.3047 | F41: =Model!CC265 -> 623.06603 | G41: =Model!CD265 -> 666.68065 | H41: =Model!CE265 -> 713.3483 | N41: Implied avg buyback price ($) | P41: 544.21 | Q41: 582.3047 | R41: 623.06603 | S41: 666.68065 | T41: 713.3483 | Z41: Implied avg buyback price ($) | AB41: 544.21 | AC41: 582.3047 | AD41: 623.06603 | AE41: 666.68065 | AF41: 713.3483
B42: Shares repurchased (m) | D42: =Model!CA267 -> 0.55125779 | E42: =Model!CB267 -> 0.71213918 | F42: =Model!CC267 -> 0.64056205 | G42: =Model!CD267 -> 0.70706281 | H42: =Model!CE267 -> 0.76364588 | N42: Shares repurchased (m) | P42: 0.73501038 | Q42: 1.0765336 | R42: 0.54489156 | S42: 0.73491396 | T42: 0.91530084 | Z42: Shares repurchased (m) | AB42: 0.55125779 | AC42: 0.71887378 | AD42: 0.92816543 | AE42: 0.89225214 | AF42: 0.85355755
B44: ROIC | C44: =Model!BV359 -> 0.16295131 | D44: =Model!CA359 -> 0.1848843 | E44: =Model!CB359 -> 0.18294905 | F44: =Model!CC359 -> 0.18413109 | G44: =Model!CD359 -> 0.18505091 | H44: =Model!CE359 -> 0.18682259 | J44: =IFERROR(AVERAGE(Model!C359,Model!D359,Model!E359,Model!F359,Model!G359,Model!H359,Model!I359,Model!N359,Model!S359,Model!X359,Model!AC359,Model!AH359,Model!AM359,Model!AR359,Model!AW359,Model!BB359,Model!BG359,Model!BL359,Model!BQ359,Model!BV359),"") -> 0.10962339 | K44: =IFERROR(MIN(Model!C359,Model!D359,Model!E359,Model!F359,Model!G359,Model!H359,Model!I359,Model!N359,Model!S359,Model!X359,Model!AC359,Model!AH359,Model!AM359,Model!AR359,Model!AW359,Model!BB359,Model!BG359,Model!BL359,Model!BQ359,Model!BV359),"") -> 0.06600687 | L44: =IFERROR(MAX(Model!C359,Model!D359,Model!E359,Model!F359,Model!G359,Model!H359,Model!I359,Model!N359,Model!S359,Model!X359,Model!AC359,Model!AH359,Model!AM359,Model!AR359,Model!AW359,Model!BB359,Model!BG359,Model!BL359,Model!BQ359,Model!BV359),"") -> 0.16295131 | N44: ROIC | O44: 0.16295131 | P44: 0.1871213 | Q44: 0.1838191 | R44: 0.18641137 | S44: 0.18945961 | T44: 0.19406752 | V44: 0.10962339 | W44: 0.06600687 | X44: 0.16295131 | Z44: ROIC | AA44: 0.16295131 | AB44: 0.18265244 | AC44: 0.18644946 | AD44: 0.19096546 | AE44: 0.19450245 | AF44: 0.19794745 | AH44: 0.10962339 | AI44: 0.06600687 | AJ44: 0.16295131
B45: RONTA | C45: =Model!BV370 -> 0.28390171 | D45: =Model!CA370 -> 0.30370136 | E45: =Model!CB370 -> 0.3313625 | F45: =Model!CC370 -> 0.34781781 | G45: =Model!CD370 -> 0.35504826 | H45: =Model!CE370 -> 0.36230667 | J45: =IFERROR(AVERAGE(Model!C370,Model!D370,Model!E370,Model!F370,Model!G370,Model!H370,Model!I370,Model!N370,Model!S370,Model!X370,Model!AC370,Model!AH370,Model!AM370,Model!AR370,Model!AW370,Model!BB370,Model!BG370,Model!BL370,Model!BQ370,Model!BV370),"") -> 0.18635808 | K45: =IFERROR(MIN(Model!C370,Model!D370,Model!E370,Model!F370,Model!G370,Model!H370,Model!I370,Model!N370,Model!S370,Model!X370,Model!AC370,Model!AH370,Model!AM370,Model!AR370,Model!AW370,Model!BB370,Model!BG370,Model!BL370,Model!BQ370,Model!BV370),"") -> 0.11731518 | L45: =IFERROR(MAX(Model!C370,Model!D370,Model!E370,Model!F370,Model!G370,Model!H370,Model!I370,Model!N370,Model!S370,Model!X370,Model!AC370,Model!AH370,Model!AM370,Model!AR370,Model!AW370,Model!BB370,Model!BG370,Model!BL370,Model!BQ370,Model!BV370),"") -> 0.28390171 | N45: RONTA | O45: 0.28390171 | P45: 0.32299785 | Q45: 0.36221484 | R45: 0.39128276 | S45: 0.41581356 | T45: 0.43941481 | V45: 0.18635808 | W45: 0.11731518 | X45: 0.28390171 | Z45: RONTA | AA45: 0.28390171 | AB45: 0.30140369 | AC45: 0.27720575 | AD45: 0.27634528 | AE45: 0.27439669 | AF45: 0.27260135 | AH45: 0.18635808 | AI45: 0.11731518 | AJ45: 0.28390171
B47: Implied Market Cap (USDm) | G47: =G27*G21 -> 21530.642 | H47: =H27*H21 -> 23465.672 | N47: Implied Market Cap (USDm) | S47: =S27*S21 -> 29817.938 | T47: =T27*T21 -> 34281.298 | Z47: Implied Market Cap (USDm) | AE47: =AE27*AE21 -> 15236.624 | AF47: =AF27*AF21 -> 15692.221
B48: (+) Net Debt | G48: =G38 -> 570.42328 | H48: =H38 -> 624.82263 | N48: (+) Net Debt | S48: =S38 -> 1424.4829 | T48: =T38 -> 1647.0702 | Z48: (+) Net Debt | AE48: =AE38 -> 230.95819 | AF48: =AF38 -> 237.78021
B49: Implied Enterprise Value (USDm) | G49: =G47+G48 -> 22101.065 | H49: =H47+H48 -> 24090.495 | N49: Implied Enterprise Value (USDm) | S49: =S47+S48 -> 31242.421 | T49: =T47+T48 -> 35928.369 | Z49: Implied Enterprise Value (USDm) | AE49: =AE47+AE48 -> 15467.583 | AF49: =AF47+AF48 -> 15930.001
B50: Implied EV / Adjusted EBITDA (x) | G50: =IFERROR(G49/G35,"") -> 19.372513 | H50: =IFERROR(H49/H35,"") -> 19.277867 | N50: Implied EV / Adjusted EBITDA (x) | S50: =IFERROR(S49/S35,"") -> 21.932465 | T50: =IFERROR(T49/T35,"") -> 21.813502 | Z50: Implied EV / Adjusted EBITDA (x) | AE50: =IFERROR(AE49/AE35,"") -> 16.742838 | AF50: =IFERROR(AF49/AF35,"") -> 16.748661

Sheet DCF
B2: DCF VALUATION — CURTISS-WRIGHT (CW)
B4: 1. WACC BUILD
B5: Risk-free rate (US 10Y govt) | C5: 0.055 | D5: Assumption (kept consistent with the other models in the coverage set); update to market
B6: Equity risk premium | C6: 0.05 | D6: US implied ERP ~4.5–5.5% (Damodaran)
B7: Levered beta | C7: 0.95 | D7: A&D / defense-electronics peers (HEI, TDG, MOG, PH aerospace, BWXT) ~0.85–1.1; ~70% A&D mix, long-cycle naval & nuclear backlog
B8: Cost of equity | C8: =C5+C7*C6 -> 0.1025
B9: Pre-tax cost of debt | C9: 0.055 | D9: BBB-rated private-placement notes 3.1–4.6%; marginal cost ~5.5%
B10: Tax rate | C10: 0.22 | D10: Model 2027E+ effective tax rate
B11: After-tax cost of debt | C11: =C9*(1-C10) -> 0.0429
B12: Target D/V | C12: 0.05 | D12: Net debt ~$0.4bn vs ~$20bn market cap; net leverage ~0.5x Adjusted EBITDA
B13: WACC | C13: =C8*(1-C12)+C11*C12 -> 0.09952
B15: Valuation date (live) | C15: =TODAY() -> 46302 | D15: Periods = (Dec-31-Year − today) / 365.25; cash flows assumed at year-end
B16: 2. UNLEVERED FREE CASH FLOW BUILD (USDm)
D17: 2026E | E17: 2027E | F17: 2028E | G17: 2029E | H17: 2030E | I17: 2031E | J17: 2032E | K17: 2033E | L17: 2034E | M17: 2035E | N17: Terminal | P17: CAGR 27–30E | Q17: CAGR 27–35E
B18: Operating income (GAAP) = Adjusted OI less restructuring & other adjustments | D18: =Model!CA123 -> 720.874 | E18: =Model!CB123 -> 809.7922 | F18: =Model!CC123 -> 898.86833 | G18: =Model!CD123 -> 986.5102 | H18: =Model!CE123 -> 1079.4849 | I18: =H18*(1+I$26) -> 1155.0489 | J18: =I18*(1+J$26) -> 1230.1271 | K18: =J18*(1+K$26) -> 1303.9347 | L18: =K18*(1+L$26) -> 1375.6511 | M18: =L18*(1+M$26) -> 1444.4337
B19: × (1 − tax rate) | D19: =1-$C$10 -> 0.78 | E19: =1-$C$10 -> 0.78 | F19: =1-$C$10 -> 0.78 | G19: =1-$C$10 -> 0.78 | H19: =1-$C$10 -> 0.78 | I19: =1-$C$10 -> 0.78 | J19: =1-$C$10 -> 0.78 | K19: =1-$C$10 -> 0.78 | ... M19: =1-$C$10 -> 0.78
B20: NOPAT | D20: =D18*D19 -> 562.28172 | E20: =E18*E19 -> 631.63792 | F20: =F18*F19 -> 701.1173 | G20: =G18*G19 -> 769.47795 | H20: =H18*H19 -> 841.99826 | I20: =I18*I19 -> 900.93814 | J20: =J18*J19 -> 959.49912 | K20: =K18*K19 -> 1017.0691 | ... M20: =M18*M19 -> 1126.6583
B21: plus D&A | D21: =Model!CA100 -> 115.43211 | E21: =Model!CB100 -> 127.7888 | F21: =Model!CC100 -> 137.98987 | G21: =Model!CD100 -> 154.33637 | H21: =Model!CE100 -> 170.16031 | I21: =H21*(1+I$26) -> 182.07153 | J21: =I21*(1+J$26) -> 193.90618 | K21: =J21*(1+K$26) -> 205.54055 | L21: =K21*(1+L$26) -> 216.84528 | M21: =L21*(1+M$26) -> 227.68755
B22: − Capex (PP&E, net of grants) and acquisitions (M&A 2027E–30E) | D22: =Model!CA237+Model!CA238+Model!CA239 -> -106.164 | E22: =Model!CB237+Model!CB238+Model!CB239 -> -419.2422 | F22: =Model!CC237+Model!CC238+Model!CC239 -> -430.30038 | G22: =Model!CD237+Model!CD238+Model!CD239 -> -441.43186 | H22: =Model!CE237+Model!CE238+Model!CE239 -> -453.22886 | I22: =Model!CE237*(1+I$26) -> -163.95488 | J22: =I22*(1+J$26) -> -174.61195 | K22: =J22*(1+K$26) -> -185.08866 | L22: =K22*(1+L$26) -> -195.26854 | M22: =L22*(1+M$26) -> -205.03197
B23: − Δ Working capital (CF statement, excl. non-cash pension) | D23: =Model!CA234-Model!CA235 -> 4.4466434 | E23: =Model!CB234-Model!CB235 -> -28.974907 | F23: =Model!CC234-Model!CC235 -> -37.862158 | G23: =Model!CD234-Model!CD235 -> -38.393204 | H23: =Model!CE234-Model!CE235 -> -40.67581 | I23: =H23*(1+I$26) -> -43.523116 | J23: =I23*(1+J$26) -> -46.352119 | K23: =J23*(1+K$26) -> -49.133246 | L23: =K23*(1+L$26) -> -51.835575 | M23: =L23*(1+M$26) -> -54.427353
B24: Unlevered FCF | D24: =D20+D21+D22+D23 -> 575.99648 | E24: =E20+E21+E22+E23 -> 311.20961 | F24: =F20+F21+F22+F23 -> 370.94462 | G24: =G20+G21+G22+G23 -> 443.98926 | H24: =H20+H21+H22+H23 -> 518.2539 | I24: =I20+I21+I22+I23 -> 875.53167 | J24: =J20+J21+J22+J23 -> 932.44123 | K24: =K20+K21+K22+K23 -> 988.38771 | ... M24: =M20+M21+M22+M23 -> 1094.8865 | N24: =M24*(1+$C$27) -> 1138.6819 | P24: =IFERROR((H24/E24)^(1/3)-1,"n/m") -> 0.1853043 | Q24: =IFERROR((M24/E24)^(1/8)-1,"n/m") -> 0.17027927
B25: Terminal Value (Gordon Growth) | N25: =N24/($C$13-$C$27) -> 19131.081
B26: Fade-period growth (2031E–35E; 7% → 5% linear) | I26: 0.07 | J26: =I26+($M$26-$I$26)/4 -> 0.065 | K26: =J26+($M$26-$I$26)/4 -> 0.06 | L26: =K26+($M$26-$I$26)/4 -> 0.055 | M26: 0.05
B27: Terminal growth rate | C27: 0.04
B29: Discount period (years) | D29: =(DATE(2026,12,31)-$C$15)/365.25 -> 0.23271732 | E29: =(DATE(2027,12,31)-$C$15)/365.25 -> 1.2320329 | F29: =(DATE(2028,12,31)-$C$15)/365.25 -> 2.2340862 | G29: =(DATE(2029,12,31)-$C$15)/365.25 -> 3.2334018 | H29: =(DATE(2030,12,31)-$C$15)/365.25 -> 4.2327173 | I29: =(DATE(2031,12,31)-$C$15)/365.25 -> 5.2320329 | J29: =(DATE(2032,12,31)-$C$15)/365.25 -> 6.2340862 | K29: =(DATE(2033,12,31)-$C$15)/365.25 -> 7.2334018 | L29: =(DATE(2034,12,31)-$C$15)/365.25 -> 8.2327173 | M29: =(DATE(2035,12,31)-$C$15)/365.25 -> 9.2320329 | N29: =M29 -> 9.2320329
B30: Discount factor | D30: =1/(1+$C$13)^D29 -> 0.97816319 | E30: =1/(1+$C$13)^E29 -> 0.88968524 | F30: =1/(1+$C$13)^F29 -> 0.80900023 | G30: =1/(1+$C$13)^G29 -> 0.7358236 | H30: =1/(1+$C$13)^H29 -> 0.66926603 | I30: =1/(1+$C$13)^I29 -> 0.6087288 | J30: =1/(1+$C$13)^J29 -> 0.55352356 | K30: =1/(1+$C$13)^K29 -> 0.50345561 | ... N30: =1/(1+$C$13)^N29 -> 0.41649646
B31: PV of UFCF | D31: =D24*D30*0 -> 0 | E31: =E24*E30 -> 276.8786 | F31: =F24*F30 -> 300.09429 | G31: =G24*G30 -> 326.69778 | H31: =H24*H30 -> 346.84973 | I31: =I24*I30 -> 532.96135 | J31: =J24*J30 -> 516.12819 | K31: =K24*K30 -> 497.60933 | L31: =L24*L30 -> 477.49194 | M31: =M24*M30 -> 456.01635 | N31: =N25*N30 -> 7968.0276
D32: 2026E is shown for reference but excluded from the PV (×0): its cash flow (incl. the 2H/26 $300m buybacks) is already reflected in YE2026E net debt, which is deducted below. Adjusted OI expenses stock-based compensation; acquisition spend from the M&A lever is deducted in 2027E–30E; fade and terminal value assume no new acquisitions. Non-service pension income sits below operating income and is excluded from UFCF (CW plans are overfunded).
B33: IMPLIED ROIC — invested capital roll-forward (USDm)
B34: Opening invested capital | E34: =Model!CA356 -> 3107.1062 | F34: =E38 -> 3427.5346 | G34: =F38 -> 3757.7072 | H34: =G38 -> 4083.1959 | I34: =H38 -> 4406.9403 | J34: =I38 -> 4432.3467 | K34: =J38 -> 4459.4046 | L34: =K38 -> 4488.086 | M34: =L38 -> 4518.3448
B35: plus Capex and acquisitions | E35: =-E22 -> 419.2422 | F35: =-F22 -> 430.30038 | G35: =-G22 -> 441.43186 | H35: =-H22 -> 453.22886 | I35: =-I22 -> 163.95488 | J35: =-J22 -> 174.61195 | K35: =-K22 -> 185.08866 | L35: =-L22 -> 195.26854 | M35: =-M22 -> 205.03197
B36: less D&A | E36: =-E21 -> -127.7888 | F36: =-F21 -> -137.98987 | G36: =-G21 -> -154.33637 | H36: =-H21 -> -170.16031 | I36: =-I21 -> -182.07153 | J36: =-J21 -> -193.90618 | K36: =-K21 -> -205.54055 | L36: =-L21 -> -216.84528 | M36: =-M21 -> -227.68755
B37: plus Δ Working capital investment | E37: =-E23 -> 28.974907 | F37: =-F23 -> 37.862158 | G37: =-G23 -> 38.393204 | H37: =-H23 -> 40.67581 | I37: =-I23 -> 43.523116 | J37: =-J23 -> 46.352119 | K37: =-K23 -> 49.133246 | L37: =-L23 -> 51.835575 | M37: =-M23 -> 54.427353
B38: Closing invested capital | E38: =SUM(E34:E37) -> 3427.5346 | F38: =SUM(F34:F37) -> 3757.7072 | G38: =SUM(G34:G37) -> 4083.1959 | H38: =SUM(H34:H37) -> 4406.9403 | I38: =SUM(I34:I37) -> 4432.3467 | J38: =SUM(J34:J37) -> 4459.4046 | K38: =SUM(K34:K37) -> 4488.086 | L38: =SUM(L34:L37) -> 4518.3448 | M38: =SUM(M34:M37) -> 4550.1166
