Workbook

Sheet Model
CF1: SCENARIO SWITCH ▼ (Bull / Base / Bear) — drives all scenario-linked forecast drivers
B2: Danaher Corporation (NYSE: DHR) — 3-Statement Financial Model | CF2: Base
B3: US GAAP as reported · USD millions (per-share data in USD; shares in millions, split-adjusted) · Source: Danaher Forms 10-K / 10-Q and Form 8-K earnings releases (Ex. 99.1), deal 8-Ks (Masimo Feb-2026; financing Apr–Jun 2026), SEC EDGAR CIK 0000313616; Masimo standalone history from Masimo Corp. filings (CIK 0000937556) (investor-relations releases are the same documents as filed on EDGAR)
B4: Basis notes: calendar fiscal year (quarters end on the Friday nearest the calendar quarter end). Hybrid recast: income statement, segments and adjusted EPS of the periods before each separation use the restated continuing-operations comparatives of the following year's filings (Apex JV 2010, Communications 2015, Fortive 2-Jul-2016, ASU 2017-07 pension recast, Envista Dec-2019, Veralto 30-Sep-2023); balance sheet and cash flow as originally reported. 2-for-1 split Jun-2010. Segments: Biotechnology / Life Sciences / Diagnostics from Q4-22 (legacy segments in memo rows). Cytiva 31-Mar-2020; Aldevron Aug-2021; Abcam Dec-2023; Masimo 10-Jun-2026 (in Diagnostics; modelled separately); StatLab pending (assumed closed end-2026). Q3/26E–Q4/26E calibrated to FY26 core-growth and adjusted-EPS guidance.
CH5: Forecast | CI5: Historical | CJ5: Historical | CK5: Historical
B6: (USDm) | C6: 2006 | D6: 2007 | E6: 2008 | F6: 2009 | G6: 2010 | H6: 2011 | I6: 2012 | J6: Q1/13 | K6: Q2/13 | L6: Q3/13 | M6: Q4/13 | N6: 2013 | O6: Q1/14 | P6: Q2/14 | Q6: Q3/14 | R6: Q4/14 | S6: 2014 | T6: Q1/15 | U6: Q2/15 | V6: Q3/15 | W6: Q4/15 | X6: 2015 | Y6: Q1/16 | Z6: Q2/16 | AA6: Q3/16 | AB6: Q4/16 | AC6: 2016 | AD6: Q1/17 | AE6: Q2/17 | AF6: Q3/17 | AG6: Q4/17 | AH6: 2017 | AI6: Q1/18 | AJ6: Q2/18 | AK6: Q3/18 | AL6: Q4/18 | AM6: 2018 | AN6: Q1/19 | AO6: Q2/19 | AP6: Q3/19 | AQ6: Q4/19 | AR6: 2019 | AS6: Q1/20 | AT6: Q2/20 | AU6: Q3/20 | AV6: Q4/20 | AW6: 2020 | AX6: Q1/21 | AY6: Q2/21 | AZ6: Q3/21 | BA6: Q4/21 | BB6: 2021 | BC6: Q1/22 | BD6: Q2/22 | BE6: Q3/22 | BF6: Q4/22 | BG6: 2022 | BH6: Q1/23 | BI6: Q2/23 | BJ6: Q3/23 | BK6: Q4/23 | BL6: 2023 | BM6: Q1/24 | BN6: Q2/24 | BO6: Q3/24 | BP6: Q4/24 | BQ6: 2024 | BR6: Q1/25 | BS6: Q2/25 | BT6: Q3/25 | BU6: Q4/25 | BV6: 2025 | BW6: Q1/26 | BX6: Q2/26 | BY6: Q3/26E | BZ6: Q4/26E | CA6: 2026E | CB6: 2027E | CC6: 2028E | CD6: 2029E | CE6: 2030E | CF6: Modelling Notes | CH6: 5Y CAGR | CI6: 5Y CAGR | CJ6: 10Y CAGR | CK6: 19Y CAGR
CH7: 25-'30 | CI7: 20-'25 | CJ7: 15-'25 | CK7: 06-'25
B8: SEGMENT P&L — BIOTECHNOLOGY · LIFE SCIENCES · DIAGNOSTICS (+ MASIMO · STATLAB) · CORE GROWTH BRIDGE | CF8: SEGMENT BUILD — modelling logic (prior-year sales × (1 + core growth + FX) → segment sales × adjusted operating margin → adjusted operating profit → adjusted EPS)
CN9: SCENARIO INPUT TABLE — driver assumptions per Bull / Base / Bear | CO9: Bull | CP9: Base | CQ9: Bear | CR9: Bull / Bear = Base + Δ (Δ inputs on each block header). Outlook block = high / mid / low end of FY26 guidance ranges.
B10: Biotechnology (bioprocessing — Cytiva, Pall Biotech; discovery & medical — Aldevron, Abcam reagents to 2024 in Life Sciences) | CF10: BIOTECHNOLOGY — modelling logic
B11: Biotechnology sales | BB11: 8570 | BF11: 2223 | BG11: 8758 | BH11: 1864 | BI11: 1885 | BJ11: 1664 | BK11: 1759 | BL11: 7172 | BM11: 1524 | BN11: 1713 | BO11: 1653 | BP11: 1869 | BQ11: 6759 | BR11: 1612 | BS11: 1850 | BT11: 1798 | BU11: 2033 | BV11: 7293 | BW11: 1797 | BX11: 1920 | BY11: =BT11*(1+BY13+BY16) -> 1891.1714 | BZ11: =BU11*(1+BZ13+BZ16) -> 2185.108 | CA11: =SUM(BW11,BX11,BY11,BZ11) -> 7793.2795 | CB11: =CA11*(1+CB13) -> 8338.809 | CC11: =CB11*(1+CC13) -> 8964.2197 | CD11: =CC11*(1+CD13) -> 9636.5362 | CE11: =CD11*(1+CE13) -> 10359.276 | CF11: Segment sales as reported (hybrid recast basis: periods before a segment recast / spin-off on the restated comparatives). Q3/Q4-26E: prior-year quarter × (1 + core growth + FX). 2027E+: prior year × (1 + scenario core growth); FX nil. | CH11: =IFERROR((CE11/BV11)^(1/5)-1,"n/m") -> 0.072715711 | CI11: =IFERROR((BV11/AW11)^(1/5)-1,"n/m") -> n/m | CJ11: =IFERROR((BV11/X11)^(1/10)-1,"n/m") -> n/m | CK11: =IFERROR((BV11/C11)^(1/19)-1,"n/m") -> n/m | CN11: FY26 outlook — Q2-26 release (21-Jul-26) | CO11: High | CP11: Mid | CQ11: Low | CR11: Raised adjusted EPS in the Q2-26 release ($8.45–8.60 vs $8.35–8.55 in Q1-26; $8.35–8.50 in Jan-26). Includes Masimo (closed 10-Jun-2026); excludes pending StatLab.
B12: Sales y/y % | D12: =IF(AND(ISNUMBER(D11),ISNUMBER(C11)),IFERROR(D11/C11-1,""),"") | E12: =IF(AND(ISNUMBER(E11),ISNUMBER(D11)),IFERROR(E11/D11-1,""),"") | F12: =IF(AND(ISNUMBER(F11),ISNUMBER(E11)),IFERROR(F11/E11-1,""),"") | G12: =IF(AND(ISNUMBER(G11),ISNUMBER(F11)),IFERROR(G11/F11-1,""),"") | H12: =IF(AND(ISNUMBER(H11),ISNUMBER(G11)),IFERROR(H11/G11-1,""),"") | I12: =IF(AND(ISNUMBER(I11),ISNUMBER(H11)),IFERROR(I11/H11-1,""),"") | N12: =IF(AND(ISNUMBER(N11),ISNUMBER(I11)),IFERROR(N11/I11-1,""),"") | O12: =IF(AND(ISNUMBER(O11),ISNUMBER(J11)),IFERROR(O11/J11-1,""),"") | P12: =IF(AND(ISNUMBER(P11),ISNUMBER(K11)),IFERROR(P11/K11-1,""),"") | Q12: =IF(AND(ISNUMBER(Q11),ISNUMBER(L11)),IFERROR(Q11/L11-1,""),"") | R12: =IF(AND(ISNUMBER(R11),ISNUMBER(M11)),IFERROR(R11/M11-1,""),"") | S12: =IF(AND(ISNUMBER(S11),ISNUMBER(N11)),IFERROR(S11/N11-1,""),"") | T12: =IF(AND(ISNUMBER(T11),ISNUMBER(O11)),IFERROR(T11/O11-1,""),"") | U12: =IF(AND(ISNUMBER(U11),ISNUMBER(P11)),IFERROR(U11/P11-1,""),"") | ... CA12: =IF(AND(ISNUMBER(CA11),ISNUMBER(BV11)),IFERROR(CA11/BV11-1,""),"") -> 0.06859721 | CB12: =IF(AND(ISNUMBER(CB11),ISNUMBER(CA11)),IFERROR(CB11/CA11-1,""),"") -> 0.07 | CC12: =IF(AND(ISNUMBER(CC11),ISNUMBER(CB11)),IFERROR(CC11/CB11-1,""),"") -> 0.075 | CD12: =IF(AND(ISNUMBER(CD11),ISNUMBER(CC11)),IFERROR(CD11/CC11-1,""),"") -> 0.075 | CE12: =IF(AND(ISNUMBER(CE11),ISNUMBER(CD11)),IFERROR(CE11/CD11-1,""),"") -> 0.075 | CN12: FY26 core sales growth (non-GAAP) | CO12: 0.04 | CP12: 0.035 | CQ12: 0.03 | CR12: Guided +3.0% to +4.0% (Q2-26 release). Drives the Q3/Q4-26E core-growth calibration.
B13: Core sales growth % (non-GAAP, as published) | BF13: 0.04 | BG13: 0.06 | BH13: -0.13 | BI13: -0.165 | BJ13: -0.21 | BK13: -0.225 | BL13: -0.18 | BM13: -0.17 | BN13: -0.07 | BO13: 0 | BP13: 0.08 | BQ13: -0.045 | BR13: 0.07 | BS13: 0.06 | BT13: 0.065 | BU13: 0.06 | BV13: 0.065 | BW13: 0.07 | BX13: 0.025 | BY13: =BY14+$BY$128 -> 0.061819486 | BZ13: =BZ14+$BY$128 -> 0.081819486 | CB13: =CHOOSE(MATCH($CF$2,{"Bull","Base","Bear"},0),$CO$33,$CP$33,$CQ$33) -> 0.07 | CC13: =CHOOSE(MATCH($CF$2,{"Bull","Base","Bear"},0),$CO$34,$CP$34,$CQ$34) -> 0.075 | CD13: =CHOOSE(MATCH($CF$2,{"Bull","Base","Bear"},0),$CO$35,$CP$35,$CQ$35) -> 0.075 | CE13: =CHOOSE(MATCH($CF$2,{"Bull","Base","Bear"},0),$CO$36,$CP$36,$CQ$36) -> 0.075 | CF13: Q3/Q4-26E: segment input (row below) + core-growth outlook calibration Δ (Group block). 2027E–2030E: scenario lever (Bull/Base/Bear table →). | CH13: =IFERROR(AVERAGE(CA13,CB13,CC13,CD13,CE13),"n/m") -> 0.07375 | CI13: =IFERROR(AVERAGE(BB13,BG13,BL13,BQ13,BV13),"n/m") -> -0.025 | CJ13: =IFERROR(AVERAGE(AC13,AH13,AM13,AR13,AW13,BB13,BG13,BL13,BQ13,BV13),"n/m") -> -0.025 | CK13: =IFERROR(AVERAGE(C13,D13,E13,F13,G13,H13,I13,N13,S13,X13,AC13,AH13,AM13,AR13,AW13,BB13,BG13,BL13,BQ13,BV13),"n/m") -> -0.025 | CN13: FY26 adjusted diluted EPS ($) | CO13: 8.6 | CP13: 8.525 | CQ13: 8.45 | CR13: Guided $8.45–8.60 (raised in Q2-26). Drives the Q3/Q4-26E adjusted-margin calibration.
B14: Q3/Q4-26E core growth input before outlook calibration | BY14: 0.05 | BZ14: 0.07 | CF14: Q2-26 release segment guidance: Q3 +MSD; FY +MSD. Q4 input +7% (bioprocessing; Q4-25 comparison +6%). | CN14: 2H/26 share repurchases ($m) | CO14: 1000 | CP14: 500 | CQ14: 0 | CR14: Q2/26: 5.0m shares for $903m; ~32m shares of authorization left. Net debt ~2.6x Adjusted EBITDA after Masimo — Base assumes modest repurchases.
B15: Acquisitions / divestitures contribution % (as published) | BF15: 0 | BG15: 0.005 | BH15: 0 | BI15: 0 | BJ15: 0.005 | BK15: 0 | BL15: 0 | BM15: 0 | BN15: 0 | BO15: 0 | BP15: 0 | BQ15: 0 | BR15: 0 | BS15: 0 | BT15: 0 | BU15: 0 | BV15: 0 | BW15: 0 | BX15: 0
B16: Currency contribution % (as published) | BF16: -0.05 | BG16: -0.045 | BH16: -0.03 | BI16: -0.005 | BJ16: 0.015 | BK16: 0.015 | BL16: 0 | BM16: -0.01 | BN16: -0.02 | BO16: -0.005 | BP16: -0.015 | BQ16: -0.015 | BR16: -0.01 | BS16: 0.02 | BT16: 0.025 | BU16: 0.03 | BV16: 0.015 | BW16: 0.045 | BX16: 0.015 | BY16: -0.01 | BZ16: -0.007 | CB16: 0 | CC16: 0 | CD16: 0 | CE16: 0 | CF16: Q3/Q4-26E: company FX guidance (Q3 ~−1.0%; FY ~+0.5% → Q4 implied). 2027E+: nil. | CN16: FY26 point estimates (all cases)
B17: Biotechnology operating profit (GAAP) | BB17: 3074 | BF17: 693 | BG17: 3008 | BH17: 596 | BI17: 480 | BJ17: 417 | BK17: 416 | BL17: 1909 | BM17: 325 | BN17: 462 | BO17: 390 | BP17: 508 | BQ17: 1685 | BR17: 441 | BS17: 531 | BT17: 352 | BU17: 540 | BV17: 1864 | BW17: 534 | BX17: 556 | BY17: =BY22-BY19-BY21 -> 460.10026 | BZ17: =BZ22-BZ19-BZ21 -> 656.6742 | CA17: =SUM(BW17,BX17,BY17,BZ17) -> 2206.7745 | CB17: =CB22-CB19-CB21 -> 2454.4794 | CC17: =CC22-CC19-CC21 -> 2746.3377 | CD17: =CD22-CD19-CD21 -> 3063.447 | CE17: =CE22-CE19-CE21 -> 3512.8719 | CN17: Interest expense, net ($m) | CP17: 310 | CR17: Q2-26 release: FY26 interest expense, net ~$(310)m (Q3 ~$(115)m) after the Masimo financing.
B18: Operating margin (GAAP) % | C18: =IF(AND(ISNUMBER(C17),ISNUMBER(C11)),IFERROR(C17/C11,""),"") | D18: =IF(AND(ISNUMBER(D17),ISNUMBER(D11)),IFERROR(D17/D11,""),"") | E18: =IF(AND(ISNUMBER(E17),ISNUMBER(E11)),IFERROR(E17/E11,""),"") | F18: =IF(AND(ISNUMBER(F17),ISNUMBER(F11)),IFERROR(F17/F11,""),"") | G18: =IF(AND(ISNUMBER(G17),ISNUMBER(G11)),IFERROR(G17/G11,""),"") | H18: =IF(AND(ISNUMBER(H17),ISNUMBER(H11)),IFERROR(H17/H11,""),"") | I18: =IF(AND(ISNUMBER(I17),ISNUMBER(I11)),IFERROR(I17/I11,""),"") | J18: =IF(AND(ISNUMBER(J17),ISNUMBER(J11)),IFERROR(J17/J11,""),"") | ... CE18: =IF(AND(ISNUMBER(CE17),ISNUMBER(CE11)),IFERROR(CE17/CE11,""),"") -> 0.33910399 | CN18: Adjusted effective tax rate | CP18: 0.17 | CR18: Q2-26 release: effective tax rate ~17.0% (non-GAAP supplemental).
B19: Amortization of acquired intangibles in segment | BG19: 812 | BH19: 217 | BI19: 218 | BJ19: 214 | BK19: 215 | BL19: 864 | BM19: 218 | BN19: 214 | BO19: 218 | BP19: 213 | BQ19: 863 | BR19: 213 | BS19: 228 | BT19: 231 | BU19: 230 | BV19: 902 | BW19: 234 | BX19: 231 | BY19: =BY172*BY20 -> 230.6198 | BZ19: =BZ172*BZ20 -> 229.75688 | CA19: =SUM(BW19,BX19,BY19,BZ19) -> 925.37668 | CB19: =CB172*CB20 -> 839.35018 | CC19: =CC172*CC20 -> 839.35018 | CD19: =CD172*CD20 -> 839.35018 | CE19: =CE172*CE20 -> 734.43141 | CF19: Segment amortization as published (segment note; 2024+). Forecast = existing-intangibles schedule × segment share (1H/26). | CN19: Capital expenditures ($m) | CP19: 1150 | CR19: 1H/26 $506m; FY25 $1,156m (not guided).
B20: Segment share of amortization (existing intangibles) % | C20: =IF(ISNUMBER(C19),IFERROR(C19/(C19+C37+C55),""),"") | D20: =IF(ISNUMBER(D19),IFERROR(D19/(D19+D37+D55),""),"") | E20: =IF(ISNUMBER(E19),IFERROR(E19/(E19+E37+E55),""),"") | F20: =IF(ISNUMBER(F19),IFERROR(F19/(F19+F37+F55),""),"") | G20: =IF(ISNUMBER(G19),IFERROR(G19/(G19+G37+G55),""),"") | H20: =IF(ISNUMBER(H19),IFERROR(H19/(H19+H37+H55),""),"") | I20: =IF(ISNUMBER(I19),IFERROR(I19/(I19+I37+I55),""),"") | J20: =IF(ISNUMBER(J19),IFERROR(J19/(J19+J37+J55),""),"") | ... BX20: =IF(ISNUMBER(BX19),IFERROR(BX19/(BX19+BX37+BX55),""),"") -> 0.51061008 | BY20: =IFERROR((BW19+BX19)/((BW19+BX19)+(BW37+BX37)+(BW55+BX55)),"") -> 0.52459386 | BZ20: =IFERROR((BW19+BX19)/((BW19+BX19)+(BW37+BX37)+(BW55+BX55)),"") -> 0.52459386 | CA20: =$BY$20 -> 0.52459386 | CB20: =$BY$20 -> 0.52459386 | CC20: =$BY$20 -> 0.52459386 | CD20: =$BY$20 -> 0.52459386 | CE20: =$BY$20 -> 0.52459386 | CN20: Q3/26 adjusted operating profit margin | CP20: 0.265 | CR20: Q2-26 release: Q3/26 adjusted operating profit margin ~26.5% (Q1/26 guide was ~28.5%; actual 30.2%). Drives the Q3 margin calibration.
B21: Other operating profit adjustments in segment (impairments, step-up, contingencies; company definition) | BM21: 0 | BN21: 0 | BO21: 0 | BP21: 0 | BQ21: 0 | BR21: 15 | BS21: 0 | BT21: 86 | BU21: 0 | BV21: 101 | BW21: 0 | BX21: 0 | BY21: 0 | BZ21: 0 | CA21: =SUM(BW21,BX21,BY21,BZ21) -> 0 | CB21: 0 | CC21: 0 | CD21: 0 | CE21: 0 | CF21: Published by segment from the Q4-25 release (FY24, Q4-24, FY25, Q4-25); 2025–26 quarters allocated from the release footnotes (see comments). Blank = not disclosed by segment. | CN21: Q3/26 amortization of acquired intangibles ($m) | CP21: 500 | CR21: Q2-26 release: Q3 ~$(500)m incl. Masimo.
B22: Biotechnology adjusted operating profit (non-GAAP) | C22: =IF(AND(ISNUMBER(C17),ISNUMBER(C19)),C17+C19+N(C21),"") | D22: =IF(AND(ISNUMBER(D17),ISNUMBER(D19)),D17+D19+N(D21),"") | E22: =IF(AND(ISNUMBER(E17),ISNUMBER(E19)),E17+E19+N(E21),"") | F22: =IF(AND(ISNUMBER(F17),ISNUMBER(F19)),F17+F19+N(F21),"") | G22: =IF(AND(ISNUMBER(G17),ISNUMBER(G19)),G17+G19+N(G21),"") | H22: =IF(AND(ISNUMBER(H17),ISNUMBER(H19)),H17+H19+N(H21),"") | I22: =IF(AND(ISNUMBER(I17),ISNUMBER(I19)),I17+I19+N(I21),"") | J22: =IF(AND(ISNUMBER(J17),ISNUMBER(J19)),J17+J19+N(J21),"") | ... BX22: =IF(AND(ISNUMBER(BX17),ISNUMBER(BX19)),BX17+BX19+N(BX21),"") -> 787 | BY22: =BY11*BY23 -> 690.72006 | BZ22: =BZ11*BZ23 -> 886.43107 | CA22: =SUM(BW22,BX22,BY22,BZ22) -> 3132.1511 | CB22: =CB11*CB23 -> 3293.8296 | CC22: =CC11*CC23 -> 3585.6879 | CD22: =CD11*CD23 -> 3902.7971 | CE22: =CE11*CE23 -> 4247.3033 | CF22: Company definition (Q4-25 release): operating profit + amortization of intangibles + other operating profit adjustments. Historical where segment amortization is disclosed (2024+). Forecast = sales × adjusted margin. | CH22: =IFERROR((CE22/BV22)^(1/5)-1,"n/m") -> 0.081775439 | CI22: =IFERROR((BV22/AW22)^(1/5)-1,"n/m") -> n/m | CJ22: =IFERROR((BV22/X22)^(1/10)-1,"n/m") -> n/m | CK22: =IFERROR((BV22/C22)^(1/19)-1,"n/m") -> n/m | CN22: FY26 amortization of acquired intangibles ($m) | CP22: 1900 | CR22: Q2-26 release: FY26 ~$(1,900)m incl. Masimo (10-K schedule pre-Masimo ~$1.7bn).
B23: Adjusted operating margin % | C23: =IF(AND(ISNUMBER(C22),ISNUMBER(C11)),IFERROR(C22/C11,""),"") | D23: =IF(AND(ISNUMBER(D22),ISNUMBER(D11)),IFERROR(D22/D11,""),"") | E23: =IF(AND(ISNUMBER(E22),ISNUMBER(E11)),IFERROR(E22/E11,""),"") | F23: =IF(AND(ISNUMBER(F22),ISNUMBER(F11)),IFERROR(F22/F11,""),"") | G23: =IF(AND(ISNUMBER(G22),ISNUMBER(G11)),IFERROR(G22/G11,""),"") | H23: =IF(AND(ISNUMBER(H22),ISNUMBER(H11)),IFERROR(H22/H11,""),"") | I23: =IF(AND(ISNUMBER(I22),ISNUMBER(I11)),IFERROR(I22/I11,""),"") | J23: =IF(AND(ISNUMBER(J22),ISNUMBER(J11)),IFERROR(J22/J11,""),"") | ... BX23: =IF(AND(ISNUMBER(BX22),ISNUMBER(BX11)),IFERROR(BX22/BX11,""),"") -> 0.40989583 | BY23: =BY24+BY134 -> 0.36523397 | BZ23: =BZ24+BZ134 -> 0.40566922 | CA23: =IF(AND(ISNUMBER(CA22),ISNUMBER(CA11)),IFERROR(CA22/CA11,""),"") -> 0.40190412 | CB23: =CHOOSE(MATCH($CF$2,{"Bull","Base","Bear"},0),$CO$48,$CP$48,$CQ$48) -> 0.395 | CC23: =CHOOSE(MATCH($CF$2,{"Bull","Base","Bear"},0),$CO$49,$CP$49,$CQ$49) -> 0.4 | CD23: =CHOOSE(MATCH($CF$2,{"Bull","Base","Bear"},0),$CO$50,$CP$50,$CQ$50) -> 0.405 | CE23: =CHOOSE(MATCH($CF$2,{"Bull","Base","Bear"},0),$CO$51,$CP$51,$CQ$51) -> 0.41 | CF23: Q3/Q4-26E: margin before calibration + outlook calibration Δ of the quarter (Group block: Q3 margin guidance, Q4 FY26 EPS guidance). 2027E–2030E: scenario lever. | CH23: =IFERROR(AVERAGE(CA23,CB23,CC23,CD23,CE23),"n/m") -> 0.40238082 | CI23: =IFERROR(AVERAGE(BB23,BG23,BL23,BQ23,BV23),"n/m") -> 0.39822767 | CJ23: =IFERROR(AVERAGE(AC23,AH23,AM23,AR23,AW23,BB23,BG23,BL23,BQ23,BV23),"n/m") -> 0.39822767 | CK23: =IFERROR(AVERAGE(C23,D23,E23,F23,G23,H23,I23,N23,S23,X23,AC23,AH23,AM23,AR23,AW23,BB23,BG23,BL23,BQ23,BV23),"n/m") -> 0.39822767
B24: Adjusted operating margin before outlook calibration % (Q3/Q4-26E helper) | BY24: =BT23+((BW22+BX22)/(BW11+BX11)-(BR22+BS22)/(BR11+BS11)) -> 0.37794988 | BZ24: =BU23+((BW22+BX22)/(BW11+BX11)-(BR22+BS22)/(BR11+BS11)) -> 0.38462041 | CF24: Prior-year quarter adjusted margin + (1H/26 − 1H/25 adjusted margin drift).
B25: Incremental adjusted operating margin (Δ adj. op. profit / Δ sales) | D25: =IFERROR((D22-C22)/(D11-C11),"") | E25: =IFERROR((E22-D22)/(E11-D11),"") | F25: =IFERROR((F22-E22)/(F11-E11),"") | G25: =IFERROR((G22-F22)/(G11-F11),"") | H25: =IFERROR((H22-G22)/(H11-G11),"") | I25: =IFERROR((I22-H22)/(I11-H11),"") | N25: =IFERROR((N22-I22)/(N11-I11),"") | O25: =IFERROR((O22-J22)/(O11-J11),"") | P25: =IFERROR((P22-K22)/(P11-K11),"") | Q25: =IFERROR((Q22-L22)/(Q11-L11),"") | R25: =IFERROR((R22-M22)/(R11-M11),"") | S25: =IFERROR((S22-N22)/(S11-N11),"") | T25: =IFERROR((T22-O22)/(T11-O11),"") | U25: =IFERROR((U22-P22)/(U11-P11),"") | ... CA25: =IFERROR((CA22-BV22)/(CA11-BV11),"") -> 0.53000604 | CB25: =IFERROR((CB22-CA22)/(CB11-CA11),"") -> 0.2963697 | CC25: =IFERROR((CC22-CB22)/(CC11-CB11),"") -> 0.46666667 | CD25: =IFERROR((CD22-CC22)/(CD11-CC11),"") -> 0.47166667 | CE25: =IFERROR((CE22-CD22)/(CE11-CD11),"") -> 0.47666667
B26: Depreciation in segment | BG26: 190 | BH26: 40 | BI26: 39 | BJ26: 40 | BK26: 43 | BL26: 162 | BM26: 42 | BN26: 35 | BO26: 36 | BP26: 38 | BQ26: 151 | BR26: 34 | BS26: 38 | BT26: 38 | BU26: 39 | BV26: 149 | BW26: 40 | BX26: 40
B28: Life Sciences (Beckman Coulter Life Sciences, Leica Microsystems, SCIEX, Molecular Devices, IDT, Abcam, Aldevron, Pall Industrial) | CF28: LIFE SCIENCES — modelling logic
B29: Life Sciences sales | V29: 804.5 | W29: 1374.1 | X29: 3314.6 | Y29: 1258.1 | Z29: 1328.3 | AA29: 1325.4 | AB29: 1454.1 | AC29: 5365.9 | AD29: 1308.1 | AE29: 1384.3 | AF29: 1392.6 | AG29: 1625.1 | AH29: 5710.1 | AI29: 1476 | AJ29: 1605.2 | AK29: 1596.7 | AL29: 1793.5 | AM29: 6471.4 | AN29: 1626.9 | AO29: 1712.6 | AP29: 1695.6 | AQ29: 1916 | AR29: 6951.1 | AS29: 1650.4 | AT29: 2642.4 | AU29: 2922.5 | AV29: 3361 | AW29: 10576 | AX29: 3546 | AY29: 3734 | AZ29: 3632 | BA29: 4046 | BB29: 6388 | BC29: 3882 | BD29: 3967 | BE29: 3776 | BF29: 1946 | BG29: 7036 | BH29: 1709 | BI29: 1796 | BJ29: 1706 | BK29: 1930 | BL29: 7141 | BM29: 1745 | BN29: 1770 | BO29: 1782 | BP29: 2032 | BQ29: 7329 | BR29: 1680 | BS29: 1777 | BT29: 1792 | BU29: 2085 | BV29: 7334 | BW29: 1737 | BX29: 1879 | BY29: =BT29*(1+BY31+BY34) -> 1857.9805 | BZ29: =BU29*(1+BZ31+BZ34) -> 2178.4486 | CA29: =SUM(BW29,BX29,BY29,BZ29) -> 7652.4291 | CB29: =CA29*(1+CB31) -> 7958.5263 | CC29: =CB29*(1+CC31) -> 8316.66 | CD29: =CC29*(1+CD31) -> 8690.9097 | CE29: =CD29*(1+CE31) -> 9082.0006 | CF29: Segment sales as reported (hybrid recast basis: periods before a segment recast / spin-off on the restated comparatives). Q3/Q4-26E: prior-year quarter × (1 + core growth + FX). 2027E+: prior year × (1 + scenario core growth); FX nil. | CH29: =IFERROR((CE29/BV29)^(1/5)-1,"n/m") -> 0.043681834 | CI29: =IFERROR((BV29/AW29)^(1/5)-1,"n/m") -> -0.070597379 | CJ29: =IFERROR((BV29/X29)^(1/10)-1,"n/m") -> 0.082657224 | CK29: =IFERROR((BV29/C29)^(1/19)-1,"n/m") -> n/m
B30: Sales y/y % | D30: =IF(AND(ISNUMBER(D29),ISNUMBER(C29)),IFERROR(D29/C29-1,""),"") | E30: =IF(AND(ISNUMBER(E29),ISNUMBER(D29)),IFERROR(E29/D29-1,""),"") | F30: =IF(AND(ISNUMBER(F29),ISNUMBER(E29)),IFERROR(F29/E29-1,""),"") | G30: =IF(AND(ISNUMBER(G29),ISNUMBER(F29)),IFERROR(G29/F29-1,""),"") | H30: =IF(AND(ISNUMBER(H29),ISNUMBER(G29)),IFERROR(H29/G29-1,""),"") | I30: =IF(AND(ISNUMBER(I29),ISNUMBER(H29)),IFERROR(I29/H29-1,""),"") | N30: =IF(AND(ISNUMBER(N29),ISNUMBER(I29)),IFERROR(N29/I29-1,""),"") | O30: =IF(AND(ISNUMBER(O29),ISNUMBER(J29)),IFERROR(O29/J29-1,""),"") | P30: =IF(AND(ISNUMBER(P29),ISNUMBER(K29)),IFERROR(P29/K29-1,""),"") | Q30: =IF(AND(ISNUMBER(Q29),ISNUMBER(L29)),IFERROR(Q29/L29-1,""),"") | R30: =IF(AND(ISNUMBER(R29),ISNUMBER(M29)),IFERROR(R29/M29-1,""),"") | S30: =IF(AND(ISNUMBER(S29),ISNUMBER(N29)),IFERROR(S29/N29-1,""),"") | T30: =IF(AND(ISNUMBER(T29),ISNUMBER(O29)),IFERROR(T29/O29-1,""),"") | U30: =IF(AND(ISNUMBER(U29),ISNUMBER(P29)),IFERROR(U29/P29-1,""),"") | ... CA30: =IF(AND(ISNUMBER(CA29),ISNUMBER(BV29)),IFERROR(CA29/BV29-1,""),"") -> 0.04341821 | CB30: =IF(AND(ISNUMBER(CB29),ISNUMBER(CA29)),IFERROR(CB29/CA29-1,""),"") -> 0.04 | CC30: =IF(AND(ISNUMBER(CC29),ISNUMBER(CB29)),IFERROR(CC29/CB29-1,""),"") -> 0.045 | CD30: =IF(AND(ISNUMBER(CD29),ISNUMBER(CC29)),IFERROR(CD29/CC29-1,""),"") -> 0.045 | CE30: =IF(AND(ISNUMBER(CE29),ISNUMBER(CD29)),IFERROR(CE29/CD29-1,""),"") -> 0.045 | CN30: Minimum net debt / Adjusted EBITDA (x) — buyback floor 2027E+ | CO30: 2.25 | CP30: 2 | CQ30: 1.75 | CR30: Danaher de-levers to ~2x after large deals (Cytiva 2020, Aldevron 2021) before resuming buybacks / M&A. Net debt ~2.6x at 26-Jun-26 (model Adjusted EBITDA). Buybacks absorb surplus cash once leverage reaches the scenario floor.
B31: Core sales growth % (non-GAAP, as published) | AA31: 0.03 | AC31: 0.035 | AD31: 0.03 | AE31: 0.035 | AF31: 0.03 | AH31: 0.04 | AI31: 0.055 | AJ31: 0.075 | AK31: 0.095 | AM31: 0.075 | AN31: 0.07 | AO31: 0.075 | AP31: 0.065 | AR31: 0.07 | AS31: 0.025 | AT31: 0 | AU31: 0.085 | AW31: 0.055 | AX31: 0.205 | AY31: 0.35 | AZ31: 0.2 | BB31: 0.23 | BC31: 0.075 | BD31: 0.07 | BE31: 0.08 | BF31: 0.13 | BG31: 0.095 | BH31: 0.05 | BI31: 0.055 | BJ31: -0.025 | BK31: -0.04 | BL31: 0.01 | BM31: -0.03 | BN31: -0.055 | BO31: -0.02 | BP31: 0.01 | BQ31: -0.02 | BR31: -0.04 | BS31: -0.025 | BT31: -0.01 | BU31: 0.005 | BV31: -0.015 | BW31: 0.005 | BX31: 0.055 | BY31: =BY32+$BY$128 -> 0.046819486 | BZ31: =BZ32+$BY$128 -> 0.051819486 | CB31: =CHOOSE(MATCH($CF$2,{"Bull","Base","Bear"},0),$CO$38,$CP$38,$CQ$38) -> 0.04 | CC31: =CHOOSE(MATCH($CF$2,{"Bull","Base","Bear"},0),$CO$39,$CP$39,$CQ$39) -> 0.045 | CD31: =CHOOSE(MATCH($CF$2,{"Bull","Base","Bear"},0),$CO$40,$CP$40,$CQ$40) -> 0.045 | CE31: =CHOOSE(MATCH($CF$2,{"Bull","Base","Bear"},0),$CO$41,$CP$41,$CQ$41) -> 0.045 | CF31: Q3/Q4-26E: segment input (row below) + core-growth outlook calibration Δ (Group block). 2027E–2030E: scenario lever (Bull/Base/Bear table →). | CH31: =IFERROR(AVERAGE(CA31,CB31,CC31,CD31,CE31),"n/m") -> 0.04375 | CI31: =IFERROR(AVERAGE(BB31,BG31,BL31,BQ31,BV31),"n/m") -> 0.06 | CJ31: =IFERROR(AVERAGE(AC31,AH31,AM31,AR31,AW31,BB31,BG31,BL31,BQ31,BV31),"n/m") -> 0.0575 | CK31: =IFERROR(AVERAGE(C31,D31,E31,F31,G31,H31,I31,N31,S31,X31,AC31,AH31,AM31,AR31,AW31,BB31,BG31,BL31,BQ31,BV31),"n/m") -> 0.0575
B32: Q3/Q4-26E core growth input before outlook calibration | BY32: 0.035 | BZ32: 0.04 | CF32: Q2-26 release: Q3 +3.0–4.0%; FY +3.0–4.0%. Q4 input +4%. | CN32: BIO_CORE (Biotechnology core growth) | CO32: 0.02 | CP32: Δ → | CQ32: -0.025 | CR32: Bioprocessing (Cytiva / Pall): consumables recovery after the 2023–24 destock; FY25 +6.5%, 1H/26 +4.7%; long-term HSD.
B33: Acquisitions / divestitures contribution % (as published) | AA33: 0.61 | AC33: 0.59 | AD33: 0.025 | AE33: 0.025 | AF33: 0.01 | AH33: 0.02 | AI33: 0.015 | AJ33: 0.06 | AK33: 0.065 | AM33: 0.05 | AN33: 0.07 | AO33: 0.02 | AP33: 0.01 | AR33: 0.025 | AS33: 0 | AT33: 0.555 | AU33: 0.63 | AW33: 0.465 | AX33: 0.905 | AY33: 0.02 | AZ33: 0.025 | BB33: 0.165 | BC33: 0.04 | BD33: 0.04 | BE33: 0.025 | BF33: 0 | BG33: 0.055 | BH33: 0.01 | BI33: -0.01 | BJ33: 0.01 | BK33: 0.025 | BL33: 0.015 | BM33: 0.06 | BN33: 0.06 | BO33: 0.07 | BP33: 0.05 | BQ33: 0.06 | BR33: 0.02 | BS33: 0.015 | BT33: 0 | BU33: 0 | BV33: 0.005 | BW33: 0 | BX33: 0 | CN33: 2027E | CO33: =CP33+$CO$32 -> 0.09 | CP33: 0.07 | CQ33: =CP33+$CQ$32 -> 0.045
B34: Currency contribution % (as published) | AA34: 0.005 | AC34: -0.005 | AD34: -0.015 | AE34: -0.02 | AF34: 0.01 | AH34: 0.005 | AI34: 0.06 | AJ34: 0.025 | AK34: -0.015 | AM34: 0.01 | AN34: -0.04 | AO34: -0.03 | AP34: -0.015 | AR34: -0.02 | AS34: -0.01 | AT34: -0.01 | AU34: 0.01 | AW34: 0 | AX34: 0.04 | AY34: 0.045 | AZ34: 0.02 | BB34: 0.02 | BC34: -0.02 | BD34: -0.05 | BE34: -0.065 | BF34: -0.05 | BG34: -0.05 | BH34: -0.035 | BI34: 0.01 | BJ34: 0.005 | BK34: 0.005 | BL34: -0.01 | BM34: -0.01 | BN34: -0.02 | BO34: -0.005 | BP34: -0.005 | BQ34: -0.015 | BR34: -0.015 | BS34: 0.015 | BT34: 0.015 | BU34: 0.02 | BV34: 0.01 | BW34: 0.03 | BX34: 0 | BY34: -0.01 | BZ34: -0.007 | CB34: 0 | CC34: 0 | CD34: 0 | CE34: 0 | CF34: Q3/Q4-26E: company FX guidance (Q3 ~−1.0%; FY ~+0.5% → Q4 implied). 2027E+: nil. | CN34: 2028E | CO34: =CP34+$CO$32 -> 0.095 | CP34: 0.075 | CQ34: =CP34+$CQ$32 -> 0.05
B35: Life Sciences operating profit (GAAP) | V35: 51.5 | W35: 132.6 | X35: 329.2 | Y35: 177.2 | Z35: 192.2 | AA35: 204.7 | AB35: 244.8 | AC35: 818.9 | AD35: 211.6 | AE35: 221.6 | AF35: 246.8 | AG35: 324.3 | AH35: 1004.3 | AI35: 271.3 | AJ35: 291.5 | AK35: 312.8 | AL35: 353.7 | AM35: 1229.3 | AN35: 309 | AO35: 344 | AP35: 342.5 | AQ35: 405.9 | AR35: 1401.4 | AS35: 325.6 | AT35: 412.4 | AU35: 504.9 | AV35: 811 | AW35: 2054 | AX35: 1151 | AY35: 1144 | AZ35: 975 | BA35: 1097 | BB35: 1293 | BC35: 1118 | BD35: 1174 | BE35: 1045 | BF35: 392 | BG35: 1414 | BH35: 321 | BI35: 340 | BJ35: 313 | BK35: 235 | BL35: 1209 | BM35: 235 | BN35: 233 | BO35: 35 | BP35: 376 | BQ35: 879 | BR35: 201 | BS35: -239 | BT35: 222 | BU35: 336 | BV35: 520 | BW35: 225 | BX35: 244 | BY35: =BY40-BY37-BY39 -> 240.15797 | BZ35: =BZ40-BZ37-BZ39 -> 447.98695 | CA35: =SUM(BW35,BX35,BY35,BZ35) -> 1157.1449 | CB35: =CB40-CB37-CB39 -> 1243.737 | CC35: =CC40-CC37-CC39 -> 1365.9004 | CD35: =CD40-CD37-CD39 -> 1495.4324 | CE35: =CE40-CE37-CE39 -> 1701.1152 | CN35: 2029E | CO35: =CP35+$CO$32 -> 0.095 | CP35: 0.075 | CQ35: =CP35+$CQ$32 -> 0.05
B36: Operating margin (GAAP) % | C36: =IF(AND(ISNUMBER(C35),ISNUMBER(C29)),IFERROR(C35/C29,""),"") | D36: =IF(AND(ISNUMBER(D35),ISNUMBER(D29)),IFERROR(D35/D29,""),"") | E36: =IF(AND(ISNUMBER(E35),ISNUMBER(E29)),IFERROR(E35/E29,""),"") | F36: =IF(AND(ISNUMBER(F35),ISNUMBER(F29)),IFERROR(F35/F29,""),"") | G36: =IF(AND(ISNUMBER(G35),ISNUMBER(G29)),IFERROR(G35/G29,""),"") | H36: =IF(AND(ISNUMBER(H35),ISNUMBER(H29)),IFERROR(H35/H29,""),"") | I36: =IF(AND(ISNUMBER(I35),ISNUMBER(I29)),IFERROR(I35/I29,""),"") | J36: =IF(AND(ISNUMBER(J35),ISNUMBER(J29)),IFERROR(J35/J29,""),"") | ... CE36: =IF(AND(ISNUMBER(CE35),ISNUMBER(CE29)),IFERROR(CE35/CE29,""),"") -> 0.18730622 | CN36: 2030E | CO36: =CP36+$CO$32 -> 0.095 | CP36: 0.075 | CQ36: =CP36+$CQ$32 -> 0.05
B37: Amortization of acquired intangibles in segment | AA37: 76.1 | AB37: 76.1 | AC37: 299.4 | AD37: 76.6 | AE37: 76.4 | AF37: 76.9 | AG37: 79 | AH37: 308.9 | AI37: 80.7 | AJ37: 90.5 | AK37: 84.2 | AL37: 88.4 | AM37: 343.8 | AN37: 89.6 | AO37: 89.1 | AP37: 89 | AQ37: 88.9 | AR37: 356.6 | AS37: 89.6 | AT37: 247.9 | AU37: 263.7 | AV37: 268.8 | AW37: 870 | AX37: 277 | AY37: 280 | AZ37: 298 | BA37: 328 | BB37: 1183 | BC37: 321 | BD37: 310 | BE37: 300 | BG37: 419 | BH37: 105 | BI37: 104 | BJ37: 104 | BK37: 116 | BL37: 429 | BM37: 141 | BN37: 140 | BO37: 147 | BP37: 148 | BQ37: 576 | BR37: 149 | BS37: 150 | BT37: 154 | BU37: 151 | BV37: 604 | BW37: 152 | BX37: 151 | BY37: =BY172*BY38 -> 150.27484 | BZ37: =BZ172*BZ38 -> 149.71255 | CA37: =SUM(BW37,BX37,BY37,BZ37) -> 602.98738 | CB37: =CB172*CB38 -> 546.93141 | CC37: =CC172*CC38 -> 546.93141 | CD37: =CD172*CD38 -> 546.93141 | CE37: =CE172*CE38 -> 478.56498 | CF37: Segment amortization as published (segment note; 2024+). Forecast = existing-intangibles schedule × segment share (1H/26). | CN37: LS_CORE (Life Sciences core growth) | CO37: 0.015 | CP37: Δ → | CQ37: -0.02 | CR37: Instruments (pharma / academic capex), reagents (Abcam, IDT), genomic medicines (Aldevron); FY25 −1.5%, 1H/26 +3.0%; guided +3–4% FY26.
B38: Segment share of amortization (existing intangibles) % | C38: =IF(ISNUMBER(C37),IFERROR(C37/(C19+C37+C55),""),"") | D38: =IF(ISNUMBER(D37),IFERROR(D37/(D19+D37+D55),""),"") | E38: =IF(ISNUMBER(E37),IFERROR(E37/(E19+E37+E55),""),"") | F38: =IF(ISNUMBER(F37),IFERROR(F37/(F19+F37+F55),""),"") | G38: =IF(ISNUMBER(G37),IFERROR(G37/(G19+G37+G55),""),"") | H38: =IF(ISNUMBER(H37),IFERROR(H37/(H19+H37+H55),""),"") | I38: =IF(ISNUMBER(I37),IFERROR(I37/(I19+I37+I55),""),"") | J38: =IF(ISNUMBER(J37),IFERROR(J37/(J19+J37+J55),""),"") | ... BX38: =IF(ISNUMBER(BX37),IFERROR(BX37/(BX19+BX37+BX55),""),"") -> 0.33377542 | BY38: =IFERROR((BW37+BX37)/((BW19+BX19)+(BW37+BX37)+(BW55+BX55)),"") -> 0.34183213 | BZ38: =IFERROR((BW37+BX37)/((BW19+BX19)+(BW37+BX37)+(BW55+BX55)),"") -> 0.34183213 | CA38: =$BY$38 -> 0.34183213 | CB38: =$BY$38 -> 0.34183213 | CC38: =$BY$38 -> 0.34183213 | CD38: =$BY$38 -> 0.34183213 | CE38: =$BY$38 -> 0.34183213 | CN38: 2027E | CO38: =CP38+$CO$37 -> 0.055 | CP38: 0.04 | CQ38: =CP38+$CQ$37 -> 0.02
B39: Other operating profit adjustments in segment (impairments, step-up, contingencies; company definition) | BM39: 25 | BN39: 0 | BO39: 222 | BP39: 0 | BQ39: 247 | BR39: 0 | BS39: 432 | BT39: 0 | BU39: 14 | BV39: 446 | BW39: 0 | BX39: 0 | BY39: 0 | BZ39: 0 | CA39: =SUM(BW39,BX39,BY39,BZ39) -> 0 | CB39: 0 | CC39: 0 | CD39: 0 | CE39: 0 | CF39: Published by segment from the Q4-25 release (FY24, Q4-24, FY25, Q4-25); 2025–26 quarters allocated from the release footnotes (see comments). Blank = not disclosed by segment. | CN39: 2028E | CO39: =CP39+$CO$37 -> 0.06 | CP39: 0.045 | CQ39: =CP39+$CQ$37 -> 0.025
B40: Life Sciences adjusted operating profit (non-GAAP) | C40: =IF(AND(ISNUMBER(C35),ISNUMBER(C37)),C35+C37+N(C39),"") | D40: =IF(AND(ISNUMBER(D35),ISNUMBER(D37)),D35+D37+N(D39),"") | E40: =IF(AND(ISNUMBER(E35),ISNUMBER(E37)),E35+E37+N(E39),"") | F40: =IF(AND(ISNUMBER(F35),ISNUMBER(F37)),F35+F37+N(F39),"") | G40: =IF(AND(ISNUMBER(G35),ISNUMBER(G37)),G35+G37+N(G39),"") | H40: =IF(AND(ISNUMBER(H35),ISNUMBER(H37)),H35+H37+N(H39),"") | I40: =IF(AND(ISNUMBER(I35),ISNUMBER(I37)),I35+I37+N(I39),"") | J40: =IF(AND(ISNUMBER(J35),ISNUMBER(J37)),J35+J37+N(J39),"") | ... BX40: =IF(AND(ISNUMBER(BX35),ISNUMBER(BX37)),BX35+BX37+N(BX39),"") -> 395 | BY40: =BY29*BY41 -> 390.4328 | BZ40: =BZ29*BZ41 -> 597.69949 | CA40: =SUM(BW40,BX40,BY40,BZ40) -> 1760.1323 | CB40: =CB29*CB41 -> 1790.6684 | CC40: =CC29*CC41 -> 1912.8318 | CD40: =CD29*CD41 -> 2042.3638 | CE40: =CE29*CE41 -> 2179.6802 | CF40: Company definition (Q4-25 release): operating profit + amortization of intangibles + other operating profit adjustments. Historical where segment amortization is disclosed (2024+). Forecast = sales × adjusted margin. | CH40: =IFERROR((CE40/BV40)^(1/5)-1,"n/m") -> 0.067821408 | CI40: =IFERROR((BV40/AW40)^(1/5)-1,"n/m") -> -0.1169517 | CJ40: =IFERROR((BV40/X40)^(1/10)-1,"n/m") -> n/m | CK40: =IFERROR((BV40/C40)^(1/19)-1,"n/m") -> n/m | CN40: 2029E | CO40: =CP40+$CO$37 -> 0.06 | CP40: 0.045 | CQ40: =CP40+$CQ$37 -> 0.025
B41: Adjusted operating margin % | C41: =IF(AND(ISNUMBER(C40),ISNUMBER(C29)),IFERROR(C40/C29,""),"") | D41: =IF(AND(ISNUMBER(D40),ISNUMBER(D29)),IFERROR(D40/D29,""),"") | E41: =IF(AND(ISNUMBER(E40),ISNUMBER(E29)),IFERROR(E40/E29,""),"") | F41: =IF(AND(ISNUMBER(F40),ISNUMBER(F29)),IFERROR(F40/F29,""),"") | G41: =IF(AND(ISNUMBER(G40),ISNUMBER(G29)),IFERROR(G40/G29,""),"") | H41: =IF(AND(ISNUMBER(H40),ISNUMBER(H29)),IFERROR(H40/H29,""),"") | I41: =IF(AND(ISNUMBER(I40),ISNUMBER(I29)),IFERROR(I40/I29,""),"") | J41: =IF(AND(ISNUMBER(J40),ISNUMBER(J29)),IFERROR(J40/J29,""),"") | ... BX41: =IF(AND(ISNUMBER(BX40),ISNUMBER(BX29)),IFERROR(BX40/BX29,""),"") -> 0.2102182 | BY41: =BY42+BY134 -> 0.21013826 | BZ41: =BZ42+BZ134 -> 0.27436933 | CA41: =IF(AND(ISNUMBER(CA40),ISNUMBER(CA29)),IFERROR(CA40/CA29,""),"") -> 0.23000962 | CB41: =CHOOSE(MATCH($CF$2,{"Bull","Base","Bear"},0),$CO$53,$CP$53,$CQ$53) -> 0.225 | CC41: =CHOOSE(MATCH($CF$2,{"Bull","Base","Bear"},0),$CO$54,$CP$54,$CQ$54) -> 0.23 | CD41: =CHOOSE(MATCH($CF$2,{"Bull","Base","Bear"},0),$CO$55,$CP$55,$CQ$55) -> 0.235 | CE41: =CHOOSE(MATCH($CF$2,{"Bull","Base","Bear"},0),$CO$56,$CP$56,$CQ$56) -> 0.24 | CF41: Q3/Q4-26E: margin before calibration + outlook calibration Δ of the quarter (Group block: Q3 margin guidance, Q4 FY26 EPS guidance). 2027E–2030E: scenario lever. | CH41: =IFERROR(AVERAGE(CA41,CB41,CC41,CD41,CE41),"n/m") -> 0.23200192 | CI41: =IFERROR(AVERAGE(BB41,BG41,BL41,BQ41,BV41),"n/m") -> 0.26475966 | CJ41: =IFERROR(AVERAGE(AC41,AH41,AM41,AR41,AW41,BB41,BG41,BL41,BQ41,BV41),"n/m") -> 0.2534655 | CK41: =IFERROR(AVERAGE(C41,D41,E41,F41,G41,H41,I41,N41,S41,X41,AC41,AH41,AM41,AR41,AW41,BB41,BG41,BL41,BQ41,BV41),"n/m") -> 0.2534655 | CN41: 2030E | CO41: =CP41+$CO$37 -> 0.06 | CP41: 0.045 | CQ41: =CP41+$CQ$37 -> 0.025
...

Sheet Bull-Base-Bear
B2: Danaher Corporation (DHR) — Bull / Base / Bear Case P&L Summary | J2: Share price ($): | K2: =Model!$CA$464 -> 221.21
B3: Adjusted figures (company definitions: core sales growth, adjusted operating profit, adjusted diluted EPS incl. add-back of acquired-intangible amortization; Adjusted EBITDA = model definition) · USD millions · Live panel linked to Model — toggle scenario via Model!CF2. Bull and Bear panels are value snapshots generated from the Model with the switch set to each case. 2026E includes Masimo from 10-Jun-2026; StatLab assumed closed end-2026. | J3: As of: | K3: =TODAY() -> 46301
B5: Scenario: | C5: =Model!$CF$2 -> Base | N5: Scenario: | O5: Bull | P5: Snapshot (values) — Model run with switch = Bull | Z5: Scenario: | AA5: Bear | AB5: Snapshot (values) — Model run with switch = Bear
B7: (USDm, except EPS and shares) | C7: 2025A | D7: 2026E | E7: 2027E | F7: 2028E | G7: 2029E | H7: 2030E | I7: 25-'30 CAGR | J7: LT Hist Avg | K7: LT Hist Min | L7: LT Hist Max | N7: (USDm, except EPS and shares) | O7: 2025A | P7: 2026E | Q7: 2027E | R7: 2028E | S7: 2029E | T7: 2030E | U7: 25-'30 CAGR | V7: LT Hist Avg | W7: LT Hist Min | X7: LT Hist Max | Z7: (USDm, except EPS and shares) | AA7: 2025A | AB7: 2026E | AC7: 2027E | AD7: 2028E | AE7: 2029E | AF7: 2030E | AG7: 25-'30 CAGR | AH7: LT Hist Avg | AI7: LT Hist Min | AJ7: LT Hist Max
B9: Sales | C9: =Model!BV178 -> 24568 | D9: =Model!CA178 -> 26498.419 | E9: =Model!CB178 -> 28985.763 | F9: =Model!CC178 -> 30884.566 | G9: =Model!CD178 -> 33073.036 | H9: =Model!CE178 -> 35433.883 | I9: =IFERROR((H9/C9)^(1/5)-1,"n/m") -> 0.075993849 | N9: Sales | O9: 24568 | P9: 26621.259 | Q9: 29702.454 | R9: 32395.807 | S9: 35464.939 | T9: 38800.719 | U9: 0.095705883 | Z9: Sales | AA9: 24568 | AB9: 26375.579 | AC9: 28168.378 | AD9: 29224.288 | AE9: 30495.931 | AF9: 31860.725 | AG9: 0.053360842
B10: Sales y/y % | D10: =IFERROR(D9/C9-1,"") -> 0.078574528 | E10: =IFERROR(E9/D9-1,"") -> 0.093867652 | F10: =IFERROR(F9/E9-1,"") -> 0.065508114 | G10: =IFERROR(G9/F9-1,"") -> 0.070859671 | H10: =IFERROR(H9/G9-1,"") -> 0.071382824 | N10: Sales y/y % | P10: 0.083574528 | Q10: 0.11574188 | R10: 0.090677812 | S10: 0.094738536 | T10: 0.094058538 | Z10: Sales y/y % | AB10: 0.073574528 | AC10: 0.067971945 | AD10: 0.037485653 | AE10: 0.043513203 | AF10: 0.044753316
B11: Core sales growth % (non-GAAP) | C11: =Model!BV275 -> 0.02 | D11: =Model!CA275 -> 0.035 | E11: =Model!CB275 -> 0.047406087 | F11: =Model!CC275 -> 0.056020698 | G11: =Model!CD275 -> 0.057241218 | H11: =Model!CE275 -> 0.056745442 | N11: Core sales growth % (non-GAAP) | O11: 0.02 | P11: 0.04 | Q11: 0.06335471 | R11: 0.072497496 | S11: 0.0730845 | T11: 0.072012633 | Z11: Core sales growth % (non-GAAP) | AA11: 0.02 | AB11: 0.03 | AC11: 0.02664042 | AD11: 0.033994741 | AE11: 0.035528977 | AF11: 0.035388132
B12: Adjusted EBITDA (model definition) | C12: =Model!BV227 -> 7689 | D12: =Model!CA227 -> 8416.5095 | E12: =Model!CB227 -> 9261.6202 | F12: =Model!CC227 -> 10055.048 | G12: =Model!CD227 -> 10953.254 | H12: =Model!CE227 -> 11919.924 | I12: =IFERROR((H12/C12)^(1/5)-1,"n/m") -> 0.091643228 | N12: Adjusted EBITDA (model definition) | O12: 7689 | P12: 8478.5362 | Q12: 9760.6638 | R12: 10823.16 | S12: 12026.382 | T12: 13337.556 | U12: 0.11645514 | Z12: Adjusted EBITDA (model definition) | AA12: 7689 | AB12: 8354.3807 | AC12: 8610.4472 | AD12: 9120.7153 | AE12: 9703.0939 | AF12: 10319.184 | AG12: 0.060608484
B13: Adjusted EBITDA margin % | C13: =IFERROR(C12/C9,"") -> 0.31296809 | D13: =IFERROR(D12/D9,"") -> 0.31762308 | E13: =IFERROR(E12/E9,"") -> 0.31952307 | F13: =IFERROR(F12/F9,"") -> 0.32556869 | G13: =IFERROR(G12/G9,"") -> 0.33118382 | H13: =IFERROR(H12/H9,"") -> 0.33639903 | J13: =IFERROR(AVERAGE(Model!C228,Model!D228,Model!E228,Model!F228,Model!G228,Model!H228,Model!I228,Model!N228,Model!S228,Model!X228,Model!AC228,Model!AH228,Model!AM228,Model!AR228,Model!AW228,Model!BB228,Model!BG228,Model!BL228,Model!BQ228,Model!BV228),"") -> 0.24791445 | K13: =IFERROR(MIN(Model!C228,Model!D228,Model!E228,Model!F228,Model!G228,Model!H228,Model!I228,Model!N228,Model!S228,Model!X228,Model!AC228,Model!AH228,Model!AM228,Model!AR228,Model!AW228,Model!BB228,Model!BG228,Model!BL228,Model!BQ228,Model!BV228),"") -> 0.17942047 | L13: =IFERROR(MAX(Model!C228,Model!D228,Model!E228,Model!F228,Model!G228,Model!H228,Model!I228,Model!N228,Model!S228,Model!X228,Model!AC228,Model!AH228,Model!AM228,Model!AR228,Model!AW228,Model!BB228,Model!BG228,Model!BL228,Model!BQ228,Model!BV228),"") -> 0.36666291 | N13: Adjusted EBITDA margin % | O13: 0.31296809 | P13: 0.31848742 | Q13: 0.32861473 | R13: 0.3340914 | S13: 0.33910625 | T13: 0.34374507 | V13: 0.24791445 | W13: 0.17942047 | X13: 0.36666291 | Z13: Adjusted EBITDA margin % | AA13: 0.31296809 | AB13: 0.31674682 | AC13: 0.30567778 | AD13: 0.31209366 | AE13: 0.31817667 | AF13: 0.32388415 | AH13: 0.24791445 | AI13: 0.17942047 | AJ13: 0.36666291
B15: Operating Profit (GAAP) | C15: =Model!BV185 -> 4690 | D15: =Model!CA185 -> 5517.7075 | E15: =Model!CB185 -> 6453.5282 | F15: =Model!CC185 -> 7148.0929 | G15: =Model!CD185 -> 7918.4569 | H15: =Model!CE185 -> 8945.2736 | I15: =IFERROR((H15/C15)^(1/5)-1,"n/m") -> 0.13784776 | N15: Operating Profit (GAAP) | O15: 4690 | P15: 5575.8226 | Q15: 6910.3544 | R15: 7809.3571 | S15: 8817.4358 | T15: 10118.534 | U15: 0.16624272 | Z15: Operating Profit (GAAP) | AA15: 4690 | AB15: 5459.4904 | AC15: 5841.0275 | AD15: 6305.229 | AE15: 6814.8534 | AF15: 7548.6346 | AG15: 0.099864315
B16: Operating profit y/y % | D16: =IFERROR(D15/C15-1,"") -> 0.17648348 | E16: =IFERROR(E15/D15-1,"") -> 0.16960316 | F16: =IFERROR(F15/E15-1,"") -> 0.10762558 | G16: =IFERROR(G15/F15-1,"") -> 0.10777196 | H16: =IFERROR(H15/G15-1,"") -> 0.12967384 | N16: Operating profit y/y % | P16: 0.18887475 | Q16: 0.23934259 | R16: 0.13009502 | S16: 0.12908601 | T16: 0.14755965 | Z16: Operating profit y/y % | AB16: 0.16407044 | AC16: 0.069885123 | AD16: 0.079472568 | AE16: 0.080825674 | AF16: 0.10767381
B17: Operating margin (GAAP) % | C17: =IFERROR(C15/C9,"") -> 0.19089873 | D17: =IFERROR(D15/D9,"") -> 0.2082278 | E17: =IFERROR(E15/E9,"") -> 0.22264475 | F17: =IFERROR(F15/F9,"") -> 0.23144547 | G17: =IFERROR(G15/G9,"") -> 0.23942334 | H17: =IFERROR(H15/H9,"") -> 0.25244971 | J17: =IFERROR(AVERAGE(Model!C288,Model!D288,Model!E288,Model!F288,Model!G288,Model!H288,Model!I288,Model!N288,Model!S288,Model!X288,Model!AC288,Model!AH288,Model!AM288,Model!AR288,Model!AW288,Model!BB288,Model!BG288,Model!BL288,Model!BQ288,Model!BV288),"") -> 0.18114768 | K17: =IFERROR(MIN(Model!C288,Model!D288,Model!E288,Model!F288,Model!G288,Model!H288,Model!I288,Model!N288,Model!S288,Model!X288,Model!AC288,Model!AH288,Model!AM288,Model!AR288,Model!AW288,Model!BB288,Model!BG288,Model!BL288,Model!BQ288,Model!BV288),"") -> 0.1379002 | L17: =IFERROR(MAX(Model!C288,Model!D288,Model!E288,Model!F288,Model!G288,Model!H288,Model!I288,Model!N288,Model!S288,Model!X288,Model!AC288,Model!AH288,Model!AM288,Model!AR288,Model!AW288,Model!BB288,Model!BG288,Model!BL288,Model!BQ288,Model!BV288),"") -> 0.28285103 | N17: Operating margin (GAAP) % | O17: 0.19089873 | P17: 0.20945 | Q17: 0.23265264 | R17: 0.24106074 | S17: 0.24862403 | T17: 0.26078212 | V17: 0.18114768 | W17: 0.1379002 | X17: 0.28285103 | Z17: Operating margin (GAAP) % | AA17: 0.19089873 | AB17: 0.20699035 | AC17: 0.20736116 | AD17: 0.21575304 | AE17: 0.22346763 | AF17: 0.23692601 | AH17: 0.18114768 | AI17: 0.1379002 | AJ17: 0.28285103
B19: Adjusted Net Earnings (continuing operations, attributable to common) | C19: =Model!BV262 -> 5582.678 | D19: =Model!CA262 -> 6035.1452 | E19: =Model!CB262 -> 6579.9381 | F19: =Model!CC262 -> 7228.8626 | G19: =Model!CD262 -> 7848.6301 | H19: =Model!CE262 -> 8535.563 | I19: =IFERROR((H19/C19)^(1/5)-1,"n/m") -> 0.088624036 | N19: Adjusted Net Earnings (continuing operations, attributable to common) | O19: 5582.678 | P19: 6083.3807 | Q19: 6966.547 | R19: 7754.4261 | S19: 8589.7608 | T19: 9518.6471 | U19: 0.11261915 | Z19: Adjusted Net Earnings (continuing operations, attributable to common) | AA19: 5582.678 | AB19: 5986.825 | AC19: 6069.6509 | AD19: 6555.9391 | AE19: 6975.7686 | AF19: 7409.2472 | AG19: 0.058245184
B21: FDSO (m) | C21: =Model!BV209 -> 716.1 | D21: =Model!CA209 -> 707.93493 | E21: =Model!CB209 -> 701.43901 | F21: =Model!CC209 -> 689.62062 | G21: =Model!CD209 -> 670.81054 | H21: =Model!CE209 -> 651.66626 | I21: =IFERROR((H21/C21)^(1/5)-1,"n/m") -> -0.018680762 | N21: FDSO (m) | O21: 716.1 | P21: 707.36985 | Q21: 695.12896 | R21: 679.51135 | S21: 660.57442 | T21: 640.07981 | U21: -0.022195368 | Z21: FDSO (m) | AA21: 716.1 | AB21: 708.5 | AC21: 706.9 | AD21: 701.1576 | AE21: 686.52837 | AF21: 670.50598 | AG21: -0.013071258
B23: Adjusted EPS — Diluted ($) | C23: =Model!BV266 -> 7.7959475 | D23: =Model!CA266 -> 8.525 | E23: =Model!CB266 -> 9.3806276 | F23: =Model!CC266 -> 10.482376 | G23: =Model!CD266 -> 11.700219 | H23: =Model!CE266 -> 13.098059 | I23: =IFERROR((H23/C23)^(1/5)-1,"n/m") -> 0.10934749 | N23: Adjusted EPS — Diluted ($) | O23: 7.7959475 | P23: 8.6 | Q23: 10.021949 | R23: 11.411768 | S23: 13.003472 | T23: 14.871032 | U23: 0.13787469 | Z23: Adjusted EPS — Diluted ($) | AA23: 7.7959475 | AB23: 8.45 | AC23: 8.5862936 | AD23: 9.3501648 | AE23: 10.160933 | AF23: 11.050233 | AG23: 0.072260984
B24: EPS y/y % | D24: =IFERROR(D23/C23-1,"") -> 0.093516857 | E24: =IFERROR(E23/D23-1,"") -> 0.10036687 | F24: =IFERROR(F23/E23-1,"") -> 0.11744932 | G24: =IFERROR(G23/F23-1,"") -> 0.11618005 | H24: =IFERROR(H23/G23-1,"") -> 0.11947127 | N24: EPS y/y % | P24: 0.10313724 | Q24: 0.16534292 | R24: 0.13867754 | S24: 0.13947911 | T24: 0.14362012 | Z24: EPS y/y % | AB24: 0.083896474 | AC24: 0.016129419 | AD24: 0.088964019 | AE24: 0.086711616 | AF24: 0.087521498
B26: P / E (x) — assumed (adjusted EPS) | G26: 23 | H26: 25 | N26: P / E (x) — assumed (adjusted EPS) | S26: 27 | T26: 28 | Z26: P / E (x) — assumed (adjusted EPS) | AD26: 18 | AE26: 18 | AF26: 20
B27: Price Target ($) | G27: =G26*G23 -> 269.10503 | H27: =H26*H23 -> 327.45147 | N27: Price Target ($) | S27: =S26*S23 -> 351.09373 | T27: =T26*T23 -> 416.38889 | Z27: Price Target ($) | AD27: =AD26*AD23 -> 168.30297 | AE27: =AE26*AE23 -> 182.89679 | AF27: =AF26*AF23 -> 221.00465
B28: Upside / (Downside) vs current | G28: =IFERROR(G27/$K$2-1,"") -> 0.21651387 | H28: =IFERROR(H27/$K$2-1,"") -> 0.48027426 | N28: Upside / (Downside) vs current | S28: =IFERROR(S27/$K$2-1,"") -> 0.58715128 | T28: =IFERROR(T27/$K$2-1,"") -> 0.88232399 | Z28: Upside / (Downside) vs current | AD28: =IFERROR(AD27/$K$2-1,"") -> -0.23917108 | AE28: =IFERROR(AE27/$K$2-1,"") -> -0.17319837 | AF28: =IFERROR(AF27/$K$2-1,"") -> -0.00092828288
B29: IRR (to Dec-Y-1) | G29: =IFERROR((G27/$K$2)^(1/((DATE(2029-1,12,31)-$K$3)/365.25))-1,"") -> 0.09157264 | H29: =IFERROR((H27/$K$2)^(1/((DATE(2030-1,12,31)-$K$3)/365.25))-1,"") -> 0.12885319 | N29: IRR (to Dec-Y-1) | S29: =IFERROR((S27/$K$2)^(1/((DATE(2029-1,12,31)-$K$3)/365.25))-1,"") -> 0.22938784 | T29: =IFERROR((T27/$K$2)^(1/((DATE(2030-1,12,31)-$K$3)/365.25))-1,"") -> 0.21585939 | Z29: IRR (to Dec-Y-1) | AD29: =IFERROR((AD27/$K$2)^(1/((DATE(2028-1,12,31)-$K$3)/365.25))-1,"") -> -0.19858351 | AE29: =IFERROR((AE27/$K$2)^(1/((DATE(2029-1,12,31)-$K$3)/365.25))-1,"") -> -0.081512531 | AF29: =IFERROR((AF27/$K$2)^(1/((DATE(2030-1,12,31)-$K$3)/365.25))-1,"") -> -0.00028694088
B31: Free Cash Flow | C31: =Model!BV325 -> 5293 | D31: =Model!CA325 -> 6480.4482 | E31: =Model!CB325 -> 6524.3547 | F31: =Model!CC325 -> 7169.0648 | G31: =Model!CD325 -> 7801.1436 | H31: =Model!CE325 -> 8476.1766 | I31: =IFERROR((H31/C31)^(1/5)-1,"n/m") -> 0.098751852 | N31: Free Cash Flow | O31: 5293 | P31: 6538.2476 | Q31: 6940.5335 | R31: 7718.3381 | S31: 8573.8501 | T31: 9498.7526 | U31: 0.12406891 | Z31: Free Cash Flow | AA31: 5293 | AB31: 6422.5575 | AC31: 5975.7093 | AD31: 6474.5105 | AE31: 6901.4871 | AF31: 7317.9185 | AG31: 0.066932969
B32: FCF % | C32: =IFERROR(C31/C9,"") -> 0.21544285 | D32: =IFERROR(D31/D9,"") -> 0.24455981 | E32: =IFERROR(E31/E9,"") -> 0.22508825 | F32: =IFERROR(F31/F9,"") -> 0.23212451 | G32: =IFERROR(G31/G9,"") -> 0.23587625 | H32: =IFERROR(H31/H9,"") -> 0.23921106 | J32: =IFERROR(AVERAGE(Model!C329,Model!D329,Model!E329,Model!F329,Model!G329,Model!H329,Model!I329,Model!N329,Model!S329,Model!X329,Model!AC329,Model!AH329,Model!AM329,Model!AR329,Model!AW329,Model!BB329,Model!BG329,Model!BL329,Model!BQ329,Model!BV329),"") -> 0.18309383 | K32: =IFERROR(MIN(Model!C329,Model!D329,Model!E329,Model!F329,Model!G329,Model!H329,Model!I329,Model!N329,Model!S329,Model!X329,Model!AC329,Model!AH329,Model!AM329,Model!AR329,Model!AW329,Model!BB329,Model!BG329,Model!BL329,Model!BQ329,Model!BV329),"") -> 0.13123056 | L32: =IFERROR(MAX(Model!C329,Model!D329,Model!E329,Model!F329,Model!G329,Model!H329,Model!I329,Model!N329,Model!S329,Model!X329,Model!AC329,Model!AH329,Model!AM329,Model!AR329,Model!AW329,Model!BB329,Model!BG329,Model!BL329,Model!BQ329,Model!BV329),"") -> 0.2768457 | N32: FCF % | O32: 0.21544285 | P32: 0.2456025 | Q32: 0.23366869 | R32: 0.23825114 | S32: 0.24175567 | T32: 0.24480868 | V32: 0.18309383 | W32: 0.13123056 | X32: 0.2768457 | Z32: FCF % | AA32: 0.21544285 | AB32: 0.24350395 | AC32: 0.21214247 | AD32: 0.22154553 | AE32: 0.22630846 | AF32: 0.22968462 | AH32: 0.18309383 | AI32: 0.13123056 | AJ32: 0.2768457
B33: FCF / share ($) | C33: =IFERROR(C31/C21,"") -> 7.3914258 | D33: =IFERROR(D31/D21,"") -> 9.1540168 | E33: =IFERROR(E31/E21,"") -> 9.3013855 | F33: =IFERROR(F31/F21,"") -> 10.395665 | G33: =IFERROR(G31/G21,"") -> 11.629429 | H33: =IFERROR(H31/H21,"") -> 13.006929 | N33: FCF / share ($) | O33: 7.3914258 | P33: 9.2430397 | Q33: 9.9845265 | R33: 11.358659 | S33: 12.979385 | T33: 14.83995 | Z33: FCF / share ($) | AA33: 7.3914258 | AB33: 9.0650071 | AC33: 8.4534011 | AD33: 9.2340303 | AE33: 10.052734 | AF33: 10.914024
B34: FCF Yield (on PT) | F34: =IFERROR(F33/F$27,"") | G34: =IFERROR(G33/G$27,"") -> 0.043215205 | H34: =IFERROR(H33/H$27,"") -> 0.039721699 | N34: FCF Yield (on PT) | R34: =IFERROR(R33/R$27,"") | S34: =IFERROR(S33/S$27,"") -> 0.036968434 | T34: =IFERROR(T33/T$27,"") -> 0.035639641 | Z34: FCF Yield (on PT) | AD34: =IFERROR(AD33/AD$27,"") -> 0.054865523 | AE34: =IFERROR(AE33/AE$27,"") -> 0.054963972 | AF34: =IFERROR(AF33/AF$27,"") -> 0.049383685
B35: Adjusted EBITDA — pro forma (2026E incl. Masimo full year) | C35: =Model!BV231 -> 7689 | D35: =Model!CA231 -> 8604.8611 | E35: =Model!CB231 -> 9261.6202 | F35: =Model!CC231 -> 10055.048 | G35: =Model!CD231 -> 10953.254 | H35: =Model!CE231 -> 11919.924 | I35: =IFERROR((H35/C35)^(1/5)-1,"n/m") -> 0.091643228 | N35: Adjusted EBITDA — pro forma (2026E incl. Masimo full year) | O35: 7689 | P35: 8666.8878 | Q35: 9760.6638 | R35: 10823.16 | S35: 12026.382 | T35: 13337.556 | U35: 0.11645514 | Z35: Adjusted EBITDA — pro forma (2026E incl. Masimo full year) | AA35: 7689 | AB35: 8542.7323 | AC35: 8610.4472 | AD35: 9120.7153 | AE35: 9703.0939 | AF35: 10319.184 | AG35: 0.060608484
B36: Adjusted EBITDA (pro forma) % of sales | C36: =IFERROR(C35/C9,"") -> 0.31296809 | D36: =IFERROR(D35/D9,"") -> 0.32473111 | E36: =IFERROR(E35/E9,"") -> 0.31952307 | F36: =IFERROR(F35/F9,"") -> 0.32556869 | G36: =IFERROR(G35/G9,"") -> 0.33118382 | H36: =IFERROR(H35/H9,"") -> 0.33639903 | J36: =IFERROR(AVERAGE(Model!C286,Model!D286,Model!E286,Model!F286,Model!G286,Model!H286,Model!I286,Model!N286,Model!S286,Model!X286,Model!AC286,Model!AH286,Model!AM286,Model!AR286,Model!AW286,Model!BB286,Model!BG286,Model!BL286,Model!BQ286,Model!BV286),"") -> 0.24791445 | K36: =IFERROR(MIN(Model!C286,Model!D286,Model!E286,Model!F286,Model!G286,Model!H286,Model!I286,Model!N286,Model!S286,Model!X286,Model!AC286,Model!AH286,Model!AM286,Model!AR286,Model!AW286,Model!BB286,Model!BG286,Model!BL286,Model!BQ286,Model!BV286),"") -> 0.17942047 | L36: =IFERROR(MAX(Model!C286,Model!D286,Model!E286,Model!F286,Model!G286,Model!H286,Model!I286,Model!N286,Model!S286,Model!X286,Model!AC286,Model!AH286,Model!AM286,Model!AR286,Model!AW286,Model!BB286,Model!BG286,Model!BL286,Model!BQ286,Model!BV286),"") -> 0.36666291 | N36: Adjusted EBITDA (pro forma) % of sales | O36: 0.31296809 | P36: 0.32556266 | Q36: 0.32861473 | R36: 0.3340914 | S36: 0.33910625 | T36: 0.34374507 | V36: 0.24791445 | W36: 0.17942047 | X36: 0.36666291 | Z36: Adjusted EBITDA (pro forma) % of sales | AA36: 0.31296809 | AB36: 0.32388795 | AC36: 0.30567778 | AD36: 0.31209366 | AE36: 0.31817667 | AF36: 0.32388415 | AH36: 0.24791445 | AI36: 0.17942047 | AJ36: 0.36666291
B38: Net Debt | C38: =Model!BV459 -> 13803 | D38: =Model!CA459 -> 21167.888 | E38: =Model!CB459 -> 18523.24 | F38: =Model!CC459 -> 20110.096 | G38: =Model!CD459 -> 21906.509 | H38: =Model!CE459 -> 23839.848 | N38: Net Debt | O38: 13803 | P38: 21609.184 | Q38: 21961.494 | R38: 24352.111 | S38: 27059.36 | T38: 30009.501 | Z38: Net Debt | AA38: 13803 | AB38: 20726.682 | AC38: 16119.485 | AD38: 15961.252 | AE38: 16980.414 | AF38: 18058.571
B39: Net Debt / Adjusted EBITDA (x) | C39: =IFERROR(C38/C35,"") -> 1.7951619 | D39: =IFERROR(D38/D35,"") -> 2.4599918 | E39: =IFERROR(E38/E35,"") -> 2 | F39: =IFERROR(F38/F35,"") -> 2 | G39: =IFERROR(G38/G35,"") -> 2 | H39: =IFERROR(H38/H35,"") -> 2 | N39: Net Debt / Adjusted EBITDA (x) | O39: 1.7951619 | P39: 2.4933038 | Q39: 2.25 | R39: 2.25 | S39: 2.25 | T39: 2.25 | Z39: Net Debt / Adjusted EBITDA (x) | AA39: 1.7951619 | AB39: 2.4262357 | AC39: 1.8720845 | AD39: 1.75 | AE39: 1.75 | AF39: 1.75
B40: Share repurchases ($m) | D40: =Model!CA338 -> 500 | E40: =Model!CB338 -> 1515.1735 | F40: =Model!CC338 -> 5276.841 | G40: =Model!CD338 -> 5524.1077 | H40: =Model!CE338 -> 6235.2578 | N40: Share repurchases ($m) | P40: 1000 | Q40: 3432.2872 | R40: 5149.9332 | S40: 5728.6451 | T40: 6799.4979 | AB40: 0 | AC40: 0 | AD40: 3820.429 | AE40: 4816.5082 | AF40: 5181.9393
B41: Implied avg buyback price ($) | D41: =Model!CA337 -> 221.21 | E41: =Model!CB337 -> 236.6947 | F41: =Model!CC337 -> 253.26333 | G41: =Model!CD337 -> 270.99176 | H41: =Model!CE337 -> 289.96119 | N41: Implied avg buyback price ($) | P41: 221.21 | Q41: 236.6947 | R41: 253.26333 | S41: 270.99176 | T41: 289.96119 | AB41: 221.21 | AC41: 236.6947 | AD41: 253.26333 | AE41: 270.99176 | AF41: 289.96119
B42: Shares repurchased (m) | D42: =Model!CA339 -> 2.2602956 | E42: =Model!CB339 -> 6.4013832 | F42: =Model!CC339 -> 20.835393 | G42: =Model!CD339 -> 20.384781 | H42: =Model!CE339 -> 21.503767 | N42: Shares repurchased (m) | P42: 4.5205913 | Q42: 14.500904 | R42: 20.334303 | S42: 21.139555 | T42: 23.449683 | AB42: 0 | AC42: 0 | AD42: 15.084809 | AE42: 17.773633 | AF42: 17.871148
B44: ROIC | C44: =Model!BV442 -> 0.067196955 | D44: =Model!CA442 -> 0.062438184 | E44: =Model!CB442 -> 0.071538933 | F44: =Model!CC442 -> 0.07824088 | G44: =Model!CD442 -> 0.085092043 | H44: =Model!CE442 -> 0.094192943 | J44: =IFERROR(AVERAGE(Model!C442,Model!D442,Model!E442,Model!F442,Model!G442,Model!H442,Model!I442,Model!N442,Model!S442,Model!X442,Model!AC442,Model!AH442,Model!AM442,Model!AR442,Model!AW442,Model!BB442,Model!BG442,Model!BL442,Model!BQ442,Model!BV442),"") -> 0.090953744 | K44: =IFERROR(MIN(Model!C442,Model!D442,Model!E442,Model!F442,Model!G442,Model!H442,Model!I442,Model!N442,Model!S442,Model!X442,Model!AC442,Model!AH442,Model!AM442,Model!AR442,Model!AW442,Model!BB442,Model!BG442,Model!BL442,Model!BQ442,Model!BV442),"") -> 0.054413349 | L44: =IFERROR(MAX(Model!C442,Model!D442,Model!E442,Model!F442,Model!G442,Model!H442,Model!I442,Model!N442,Model!S442,Model!X442,Model!AC442,Model!AH442,Model!AM442,Model!AR442,Model!AW442,Model!BB442,Model!BG442,Model!BL442,Model!BQ442,Model!BV442),"") -> 0.13199238 | N44: ROIC | O44: 0.067196955 | P44: 0.063086329 | Q44: 0.075131662 | R44: 0.082326744 | S44: 0.089739649 | T44: 0.099367 | V44: 0.090953744 | W44: 0.054413349 | X44: 0.13199238 | Z44: ROIC | AA44: 0.067196955 | AB44: 0.061789042 | AC44: 0.065606069 | AD44: 0.070825569 | AE44: 0.076074877 | AF44: 0.083529713 | AH44: 0.090953744 | AI44: 0.054413349 | AJ44: 0.13199238
B45: RONTA | C45: =Model!BV453 -> 0.28411923 | D45: =Model!CA453 -> 0.33903964 | E45: =Model!CB453 -> 0.36404012 | F45: =Model!CC453 -> 0.39871872 | G45: =Model!CD453 -> 0.42368431 | H45: =Model!CE453 -> 0.45925462 | J45: =IFERROR(AVERAGE(Model!C453,Model!D453,Model!E453,Model!F453,Model!G453,Model!H453,Model!I453,Model!N453,Model!S453,Model!X453,Model!AC453,Model!AH453,Model!AM453,Model!AR453,Model!AW453,Model!BB453,Model!BG453,Model!BL453,Model!BQ453,Model!BV453),"") -> 0.3775129 | K45: =IFERROR(MIN(Model!C453,Model!D453,Model!E453,Model!F453,Model!G453,Model!H453,Model!I453,Model!N453,Model!S453,Model!X453,Model!AC453,Model!AH453,Model!AM453,Model!AR453,Model!AW453,Model!BB453,Model!BG453,Model!BL453,Model!BQ453,Model!BV453),"") -> 0.099371425 | L45: =IFERROR(MAX(Model!C453,Model!D453,Model!E453,Model!F453,Model!G453,Model!H453,Model!I453,Model!N453,Model!S453,Model!X453,Model!AC453,Model!AH453,Model!AM453,Model!AR453,Model!AW453,Model!BB453,Model!BG453,Model!BL453,Model!BQ453,Model!BV453),"") -> 0.61569755 | N45: RONTA | O45: 0.28411923 | P45: 0.34272148 | Q45: 0.39974001 | R45: 0.43177506 | S45: 0.46513323 | T45: 0.50934116 | V45: 0.3775129 | W45: 0.099371425 | X45: 0.61569755 | Z45: RONTA | AA45: 0.28411923 | AB45: 0.33535578 | AC45: 0.28374445 | AD45: 0.29444058 | AE45: 0.32648095 | AF45: 0.37230208 | AH45: 0.3775129 | AI45: 0.099371425 | AJ45: 0.61569755
B47: Implied Market Cap (USDm) | F47: =F27*F21 -> 0 | G47: =G27*G21 -> 180518.49 | H47: =H27*H21 -> 213389.08 | N47: Implied Market Cap (USDm) | R47: =R27*R21 -> 0 | S47: =S27*S21 -> 231923.54 | T47: =T27*T21 -> 266522.12 | Z47: Implied Market Cap (USDm) | AD47: =AD27*AD21 -> 118006.9 | AE47: =AE27*AE21 -> 125563.83 | AF47: =AF27*AF21 -> 148184.94
B48: (+) Net Debt & NCI | F48: =F38+Model!CC374 -> 20121.096 | G48: =G38+Model!CD374 -> 21917.509 | H48: =H38+Model!CE374 -> 23850.848 | N48: (+) Net Debt & NCI | R48: =R38+Model!CC374 -> 24363.111 | S48: =S38+Model!CD374 -> 27070.36 | T48: =T38+Model!CE374 -> 30020.501 | Z48: (+) Net Debt & NCI | AD48: =AD38+Model!CC374 -> 15972.252 | AE48: =AE38+Model!CD374 -> 16991.414 | AF48: =AF38+Model!CE374 -> 18069.571
B49: Implied Enterprise Value (USDm) | F49: =F47+F48 -> 20121.096 | G49: =G47+G48 -> 202436 | H49: =H47+H48 -> 237239.92 | N49: Implied Enterprise Value (USDm) | R49: =R47+R48 -> 24363.111 | S49: =S47+S48 -> 258993.9 | T49: =T47+T48 -> 296542.62 | Z49: Implied Enterprise Value (USDm) | AD49: =AD47+AD48 -> 133979.15 | AE49: =AE47+AE48 -> 142555.25 | AF49: =AF47+AF48 -> 166254.51
B50: Implied EV / Adjusted EBITDA (x) | F50: =IFERROR(F49/F35,"") -> 2.001094 | G50: =IFERROR(G49/G35,"") -> 18.481813 | H50: =IFERROR(H49/H35,"") -> 19.902805 | N50: Implied EV / Adjusted EBITDA (x) | R50: =IFERROR(R49/R35,"") -> 2.2510163 | S50: =IFERROR(S49/S35,"") -> 21.535479 | T50: =IFERROR(T49/T35,"") -> 22.233655 | Z50: Implied EV / Adjusted EBITDA (x) | AD50: =IFERROR(AD49/AD35,"") -> 14.689545 | AE50: =IFERROR(AE49/AE35,"") -> 14.691731 | AF50: =IFERROR(AF49/AF35,"") -> 16.111208

Sheet DCF
B2: DCF VALUATION — DANAHER CORPORATION (DHR)
B4: 1. WACC BUILD
B5: Risk-free rate (US 10Y govt) | C5: 0.0425 | D5: Assumption (~US 10Y Treasury yield); update to market
B6: Equity risk premium | C6: 0.05 | D6: US implied ERP ~4.5–5.5% (Damodaran)
B7: Levered beta | C7: 0.95 | D7: Life-science tools & diagnostics peers (TMO, A, RVTY, WAT, ABT diagnostics) ~0.8–1.1; ~80% recurring revenue (consumables, service) dampens cyclicality
B8: Cost of equity | C8: =C5+C7*C6 -> 0.09
B9: Pre-tax cost of debt | C9: 0.045 | D9: Investment grade (A- / A3); 2026 Masimo financing: €3.0bn notes 3.25–4.0% (floating 2028), CHF 1.65–2.51% private placement; USD marginal cost ~4.5–5.0%
B10: Tax rate | C10: 0.17 | D10: Model 2027E+ adjusted effective tax rate (FY26 guidance ~17%)
B11: After-tax cost of debt | C11: =C9*(1-C10) -> 0.03735
B12: Target D/V | C12: 0.15 | D12: Net debt ~$22bn at 26-Jun-26 (post Masimo) vs ~$156bn market cap ($221 × ~705m shares) → ~12–15% D/V
B13: WACC | C13: =C8*(1-C12)+C11*C12 -> 0.0821025
B15: Valuation date (live) | C15: =TODAY() -> 46301 | D15: Periods = (Dec-31-Year − today) / 365.25; cash flows assumed at year-end
B16: 2. UNLEVERED FREE CASH FLOW BUILD (USDm)
D17: 2026E | E17: 2027E | F17: 2028E | G17: 2029E | H17: 2030E | I17: 2031E | J17: 2032E | K17: 2033E | L17: 2034E | M17: 2035E | N17: Terminal | P17: CAGR 26–30E | Q17: CAGR 26–35E
B18: Adjusted operating profit (before acquired-intangible amortization) less other operating profit adjustments | D18: =Model!CA243-Model!CA241 -> 7417.7075 | E18: =Model!CB243-Model!CB241 -> 8363.0615 | F18: =Model!CC243-Model!CC241 -> 9097.6262 | G18: =Model!CD243-Model!CD241 -> 9927.9902 | H18: =Model!CE243-Model!CE241 -> 10821.474 | I18: =H18*(1+I$26) -> 11470.762 | J18: =I18*(1+J$26) -> 12115.992 | K18: =J18*(1+K$26) -> 12752.082 | L18: =K18*(1+L$26) -> 13373.746 | M18: =L18*(1+M$26) -> 13975.565 | P18: =(H18/D18)^(1/(COLUMNS(D18:H18)-1))-1 -> 0.099016404 | Q18: =(M18/D18)^(1/(COLUMNS(D18:M18)-1))-1 -> 0.07291824
B19: × (1 − tax rate) | D19: =1-$C$10 -> 0.83 | E19: =1-$C$10 -> 0.83 | F19: =1-$C$10 -> 0.83 | G19: =1-$C$10 -> 0.83 | H19: =1-$C$10 -> 0.83 | I19: =1-$C$10 -> 0.83 | J19: =1-$C$10 -> 0.83 | K19: =1-$C$10 -> 0.83 | ... M19: =1-$C$10 -> 0.83
B20: NOPAT | D20: =D18*D19 -> 6156.6972 | E20: =E18*E19 -> 6941.3411 | F20: =F18*F19 -> 7551.0298 | G20: =G18*G19 -> 8240.2319 | H20: =H18*H19 -> 8981.8231 | I20: =I18*I19 -> 9520.7325 | J20: =J18*J19 -> 10056.274 | K20: =K18*K19 -> 10584.228 | ... M20: =M18*M19 -> 11599.719
B21: plus depreciation (acquired-intangible amortization is excluded from EBIT above, as in adjusted EPS) | D21: =Model!CA170 -> 843.80198 | E21: =Model!CB170 -> 898.55866 | F21: =Model!CC170 -> 957.42155 | G21: =Model!CD170 -> 1025.2641 | H21: =Model!CE170 -> 1098.4504 | I21: =H21*(1+I$26) -> 1164.3574 | J21: =I21*(1+J$26) -> 1229.8525 | K21: =J21*(1+K$26) -> 1294.4198 | L21: =K21*(1+L$26) -> 1357.5227 | M21: =L21*(1+M$26) -> 1418.6112
B22: − Capex (PP&E) and acquisitions (M&A lever 2027E–30E; Masimo / StatLab in opening invested capital) | D22: =Model!CA303 -> -1150 | E22: =Model!CB303+Model!CB305 -> -2304.3594 | F22: =Model!CC303+Model!CC305 -> -3389.8055 | G22: =Model!CD303+Model!CD305 -> -3988.2866 | H22: =Model!CE303+Model!CE305 -> -4094.5247 | I22: =Model!CE303*(1+I$26) -> -1690.1962 | J22: =I22*(1+J$26) -> -1785.2698 | K22: =J22*(1+K$26) -> -1878.9964 | L22: =K22*(1+L$26) -> -1970.5975 | M22: =L22*(1+M$26) -> -2059.2744
B23: − Δ Working capital (CF statement) | D23: =Model!CA301 -> 380.24629 | E23: =Model!CB301 -> 58.672073 | F23: =Model!CC301 -> 51.055372 | G23: =Model!CD301 -> 56.943613 | H23: =Model!CE301 -> 73.76529 | I23: =H23*(1+I$26) -> 78.191207 | J23: =I23*(1+J$26) -> 82.589463 | K23: =J23*(1+K$26) -> 86.92541 | L23: =K23*(1+L$26) -> 91.163023 | M23: =L23*(1+M$26) -> 95.265359
B24: Unlevered FCF | D24: =D20+D21+D22+D23 -> 6230.7455 | E24: =E20+E21+E22+E23 -> 5594.2124 | F24: =F20+F21+F22+F23 -> 5169.7012 | G24: =G20+G21+G22+G23 -> 5334.153 | H24: =H20+H21+H22+H23 -> 6059.514 | I24: =I20+I21+I22+I23 -> 9073.0849 | J24: =J20+J21+J22+J23 -> 9583.4459 | K24: =K20+K21+K22+K23 -> 10086.577 | ... M24: =M20+M21+M22+M23 -> 11054.321 | N24: =M24*(1+$C$27) -> 11441.222 | P24: =(H24/D24)^(1/(COLUMNS(D24:H24)-1))-1 -> -0.0069423865 | Q24: =(M24/D24)^(1/(COLUMNS(D24:M24)-1))-1 -> 0.065775625
B25: Terminal Value (Gordon Growth) | N25: =N24/($C$13-$C$27) -> 242900.53
