Workbook

Sheet Model
AT1: SCENARIO SWITCH ▼ (Bull / Base / Bear) — drives all scenario-linked forecast drivers
B2: ESAB Corporation (NYSE: ESAB) — 3-Statement Financial Model | AT2: Base
B3: US GAAP as reported · USD millions (per-share data in USD; shares in millions) · Source: ESAB Forms 10-K / 10-Q, Form 10 information statement (10-12B/A, 17-Mar-2022; carve-out combined financial statements 2019–2021), Form 8-K earnings releases (Ex. 99.1) and Eddyfi deal 8-Ks / 8-K/A (Ex. 99.1–99.3), SEC EDGAR CIK 0001877322; pre-spin Colfax 10-K "Fabrication Technology" segment data 2012–2021 (CIK 0001420800) as memo
B4: Basis notes: calendar fiscal year (fiscal quarters end on the Friday nearest quarter end). Spun off from Colfax on 4-Apr-2022: 2019–Q1/22 carve-out (combined) basis, 2012–2018 Colfax segment memo only. Two reportable segments (Americas; EMEA & APAC). "Core" = excluding Russia (from Q2/22). Adjusted EBITDA / adjusted EPS = company definitions (restructuring, acquisition-amortization & other, separation costs 2022–23, pension settlements, performance option awards; MCPS if-converted). Eddyfi Technologies acquired 1-Jun-2026 ($1.45bn) — inside the segments in Q2/26 actuals, modelled separately from Q3/26E; FY26 outlook (6-Aug-2026) includes Eddyfi. Asbestos activity of divested Colfax businesses reported in discontinued operations.
AV5: Forecast | AW5: Historical | AX5: Historical | AY5: Historical
B6: (USDm) | C6: 2012 | D6: 2013 | E6: 2014 | F6: 2015 | G6: 2016 | H6: 2017 | I6: 2018 | J6: 2019 | K6: 2020 | L6: Q1/21 | M6: Q2/21 | N6: Q3/21 | O6: Q4/21 | P6: 2021 | Q6: Q1/22 | R6: Q2/22 | S6: Q3/22 | T6: Q4/22 | U6: 2022 | V6: Q1/23 | W6: Q2/23 | X6: Q3/23 | Y6: Q4/23 | Z6: 2023 | AA6: Q1/24 | AB6: Q2/24 | AC6: Q3/24 | AD6: Q4/24 | AE6: 2024 | AF6: Q1/25 | AG6: Q2/25 | AH6: Q3/25 | AI6: Q4/25 | AJ6: 2025 | AK6: Q1/26 | AL6: Q2/26 | AM6: Q3/26E | AN6: Q4/26E | AO6: 2026E | AP6: 2027E | AQ6: 2028E | AR6: 2029E | AS6: 2030E | AT6: Modelling Notes | AV6: 5Y CAGR | AW6: 5Y CAGR | AX6: 10Y CAGR | AY6: 13Y CAGR
AV7: 25-'30 | AW7: 20-'25 | AX7: 15-'25 | AY7: 12-'25
B8: SEGMENT P&L — AMERICAS · EMEA & APAC (organic × acquisitions × FX build) · EDDYFI (acquired 1-Jun-2026) | AT8: SEGMENT BUILD — modelling logic (prior-year net sales × (1 + organic + acquisitions + FX) → segment adjusted EBITDA; Eddyfi modelled separately from Q3/26E)
BB9: SCENARIO INPUT TABLE — driver assumptions per Bull / Base / Bear | BC9: Bull | BD9: Base | BE9: Bear | BF9: Bull / Bear = Base + Δ (Δ inputs on each lever header). Outlook block = high / mid / low end of the FY26 ranges.
B10: Americas (welding & cutting equipment, consumables, gas control, automation — North & South America) | AT10: AMERICAS — modelling logic
B11: Net sales | J11: 939.673 | K11: 767.414 | L11: 226.2 | M11: 253.6 | N11: 260 | O11: 264.4 | P11: 1004.2 | Q11: 272.3 | R11: 291.1 | S11: 281.4 | T11: 283.6 | U11: 1128.4 | V11: 291.6 | W11: 310.3 | X11: 305.8 | Y11: 307.3 | Z11: 1215 | AA11: 296 | AB11: 309.8 | AC11: 288.8 | AD11: 282.1 | AE11: 1176.7 | AF11: 280.7 | AG11: 282.7 | AH11: 292.7 | AI11: 274.2 | AJ11: 1130.3 | AK11: 288.4 | AL11: 315.9 | AM11: =AH11*(1+AM12) -> 305.6147 | AN11: =AI11*(1+AN12) -> 286.29843 | AO11: =SUM(AK11,AL11,AM11,AN11) -> 1196.2131 | AP11: =(AO11-N(AO19))*(1+AP12) -> 1234.0777 | AQ11: =(AP11-N(AP19))*(1+AQ12) -> 1283.4408 | AR11: =(AQ11-N(AQ19))*(1+AR12) -> 1328.3612 | AS11: =(AR11-N(AR19))*(1+AS12) -> 1374.8538 | AT11: Historical: as reported (Q2/26 includes one month of Eddyfi). Q3/Q4-26E: legacy business only = prior-year quarter × (1 + organic + acquisitions + FX); Eddyfi in its own block. 2027E+: legacy 2026E (ex-Eddyfi June) × (1 + organic lever + FX). | AV11: =IFERROR((AS11/AJ11)^(1/5)-1,"n/m") -> 0.039950241 | AW11: =IFERROR((AJ11/K11)^(1/5)-1,"n/m") -> 0.08051998 | AX11: =IFERROR((AJ11/F11)^(1/10)-1,"n/m") -> n/m | AY11: =IFERROR((AJ11/C11)^(1/13)-1,"n/m") -> n/m | BB11: FY26 outlook — Q2-26 release (6-Aug-26); includes Eddyfi from 1-Jun-26 | BC11: High | BD11: Mid | BE11: Low | BF11: Updated outlook: total core sales growth 11.0–14.0% (core organic 2–4%, M&A ~9%, FX 0–1%); core adjusted EBITDA $615–625m; core adjusted EPS $5.40–5.50.
B12: Net sales y/y % | K12: =IF(AND(ISNUMBER(K11),ISNUMBER(J11)),IFERROR(K11/J11-1,""),"") -> -0.18331803 | P12: =IF(AND(ISNUMBER(P11),ISNUMBER(K11)),IFERROR(P11/K11-1,""),"") -> 0.30855053 | Q12: =IF(AND(ISNUMBER(Q11),ISNUMBER(L11)),IFERROR(Q11/L11-1,""),"") -> 0.20380195 | R12: =IF(AND(ISNUMBER(R11),ISNUMBER(M11)),IFERROR(R11/M11-1,""),"") -> 0.14787066 | S12: =IF(AND(ISNUMBER(S11),ISNUMBER(N11)),IFERROR(S11/N11-1,""),"") -> 0.082307692 | T12: =IF(AND(ISNUMBER(T11),ISNUMBER(O11)),IFERROR(T11/O11-1,""),"") -> 0.072617247 | U12: =IF(AND(ISNUMBER(U11),ISNUMBER(P11)),IFERROR(U11/P11-1,""),"") -> 0.12368054 | V12: =IF(AND(ISNUMBER(V11),ISNUMBER(Q11)),IFERROR(V11/Q11-1,""),"") -> 0.070877708 | W12: =IF(AND(ISNUMBER(W11),ISNUMBER(R11)),IFERROR(W11/R11-1,""),"") -> 0.065956716 | ... AL12: =IF(AND(ISNUMBER(AL11),ISNUMBER(AG11)),IFERROR(AL11/AG11-1,""),"") -> 0.11743898 | AM12: =AM13+AM14+AM15 -> 0.044122646 | AN12: =AN13+AN14+AN15 -> 0.044122646 | AO12: =IFERROR(AO11/AJ11-1,"") -> 0.05831472 | AP12: =AP13+AP14+AP15 -> 0.04 | AQ12: =AQ13+AQ14+AQ15 -> 0.04 | AR12: =AR13+AR14+AR15 -> 0.035 | AS12: =AS13+AS14+AS15 -> 0.035 | BB12: FY26 core sales growth (ex-Russia) | BC12: 0.14 | BD12: 0.125 | BE12: 0.11 | BF12: Raised from 6–9% (M&A contribution ~9% from ~4% after the Eddyfi close). Drives the Q3/Q4-26E organic calibration.
B13: Organic growth % (company; price, mix & volume) | Q13: 0.211 | R13: 0.15 | S13: 0.104 | T13: 0.052 | U13: 0.127 | V13: 0.045 | W13: 0.041 | X13: 0.04 | Y13: 0.088 | Z13: 0.054 | AA13: 0.031 | AB13: 0.04 | AC13: 0.02 | AD13: -0.015 | AE13: 0.019 | AF13: -0.024 | AG13: -0.072 | AH13: 0.001 | AI13: -0.049 | AJ13: -0.037 | AK13: -0.007 | AL13: 0.049 | AM13: =$AL$13+AM118 -> 0.044122646 | AN13: =$AL$13+AN118 -> 0.044122646 | AO13: =IFERROR(AO16/AJ11,"") -> 0.032569343 | AP13: =CHOOSE(MATCH($AT$2,{"Bull","Base","Bear"},0),$BC$21,$BD$21,$BE$21) -> 0.04 | AQ13: =CHOOSE(MATCH($AT$2,{"Bull","Base","Bear"},0),$BC$22,$BD$22,$BE$22) -> 0.04 | AR13: =CHOOSE(MATCH($AT$2,{"Bull","Base","Bear"},0),$BC$23,$BD$23,$BE$23) -> 0.035 | AS13: =CHOOSE(MATCH($AT$2,{"Bull","Base","Bear"},0),$BC$24,$BD$24,$BE$24) -> 0.035 | AT13: Q3/Q4-26E: Q2/26 y/y organic + outlook calibration Δ. 2027E+: scenario lever. ESAB does not split organic growth into price and volume. | BB13: FY26 core adjusted EBITDA ($m) | BC13: 625 | BD13: 620 | BE13: 615 | BF13: Raised to $615–625m (from $575–595m). Drives the Q3/Q4-26E margin calibration.
B14: Acquisitions % (excl. Eddyfi in forecast) | Q14: 0 | R14: 0 | S14: 0 | T14: 0.04 | U14: 0.011 | V14: 0.048 | W14: 0.047 | X14: 0.052 | Y14: 0.008 | Z14: 0.039 | AA14: 0.003 | AB14: 0.009 | AC14: 0.009 | AD14: 0.026 | AE14: 0.012 | AF14: 0.032 | AG14: 0.026 | AH14: 0.026 | AI14: 0.009 | AJ14: 0.024 | AK14: 0 | AL14: 0.034 | AM14: 0 | AN14: 0 | AO14: =IFERROR(AO17/AJ11,"") -> 0.0084933204 | AP14: 0 | AQ14: 0 | AR14: 0 | AS14: 0 | AT14: Eddyfi (Americas share) modelled in the Eddyfi block from Q3/26E; no other Americas deals to anniversary. | BB14: FY26 core adjusted EPS ($; memo) | BC14: 5.5 | BD14: 5.45 | BE14: 5.4 | BF14: $5.40–5.50 (memo; compare with model core adjusted EPS).
B15: Foreign currency translation % | Q15: -0.007 | R15: -0.002 | S15: -0.022 | T15: -0.02 | U15: -0.014 | V15: -0.022 | W15: -0.022 | X15: -0.005 | Y15: -0.012 | Z15: -0.015 | AA15: -0.018 | AB15: -0.051 | AC15: -0.085 | AD15: -0.093 | AE15: -0.062 | AF15: -0.061 | AG15: -0.042 | AH15: -0.014 | AI15: 0.012 | AJ15: -0.027 | AK15: 0.035 | AL15: 0.034 | AM15: 0 | AN15: 0 | AO15: =IFERROR(AO18/AJ11,"") -> 0.017252057 | AP15: 0 | AQ15: 0 | AR15: 0 | AS15: 0 | AT15: Q3/Q4-26E: FX input (spot vs prior-year rates). 2027E+: EMEA & APAC FX lever; Americas 0%. | BB15: FY26 point estimates / capital returns | BC15: Bull | BD15: Base | BE15: Bear
B16: Δ Net sales — organic ($) | Q16: 47.7 | R16: 38.1 | S16: 27.1 | T16: 13.8 | U16: 127.3 | V16: 12.2 | W16: 11.9 | X16: 11.3 | Y16: 25.1 | Z16: 60.5 | AA16: 8.9 | AB16: 12.5 | AC16: 6.2 | AD16: -4.6 | AE16: 23 | AF16: -7 | AG16: -22.4 | AH16: 0.4 | AI16: -13.9 | AJ16: -43 | AK16: -2.1 | AL16: 13.9 | AM16: =AH11*AM13 -> 12.914698 | AN16: =AI11*AN13 -> 12.098429 | AO16: =SUM(AK16,AL16,AM16,AN16) -> 36.813128 | AP16: =(AO11-N(AO19))*AP13 -> 47.464525 | AQ16: =(AP11-N(AP19))*AQ13 -> 49.363106 | AR16: =(AQ11-N(AQ19))*AR13 -> 44.920427 | AS16: =(AR11-N(AR19))*AS13 -> 46.492641 | BB16: FY26 capital expenditures ($m) | BC16: 75 | BD16: 70 | BE16: 65 | BF16: No explicit FY26 capex guidance; 1H/26 $31.4m, FY25 $47.3m. Eddyfi adds capitalized development / equipment.
B17: Δ Net sales — acquisitions ($) | Q17: 0 | R17: 0 | S17: 0 | T17: 10.7 | U17: 10.7 | V17: 13 | W17: 13.8 | X17: 14.6 | Y17: 2.2 | Z17: 43.7 | AA17: 0.9 | AB17: 2.7 | AC17: 2.8 | AD17: 7.9 | AE17: 14.3 | AF17: 9.6 | AG17: 8.2 | AH17: 7.4 | AI17: 2.7 | AJ17: 27.9 | AK17: 0 | AL17: 9.6 | AM17: =AH11*AM14 -> 0 | AN17: =AI11*AN14 -> 0 | AO17: =SUM(AK17,AL17,AM17,AN17) -> 9.6 | AP17: 0 | AQ17: 0 | AR17: 0 | AS17: 0 | BB17: 2H/26 effective tax rate | BC17: 0.22 | BD17: 0.23 | BE17: 0.24 | BF17: ESAB adjusted tax rate ~22–23%.
B18: Δ Net sales — FX ($) | Q18: -1.6 | R18: -0.6 | S18: -5.7 | T18: -5.3 | U18: -13.8 | V18: -5.9 | W18: -6.5 | X18: -1.5 | Y18: -3.5 | Z18: -17.5 | AA18: -5.3 | AB18: -15.7 | AC18: -26 | AD18: -28.5 | AE18: -75.5 | AF18: -17.9 | AG18: -12.9 | AH18: -3.9 | AI18: 3.4 | AJ18: -31.3 | AK18: 9.8 | AL18: 9.7 | AM18: =AH11*AM15 -> 0 | AN18: =AI11*AN15 -> 0 | AO18: =SUM(AK18,AL18,AM18,AN18) -> 19.5 | AP18: =(AO11-N(AO19))*AP15 -> 0 | AQ18: =(AP11-N(AP19))*AQ15 -> 0 | AR18: =(AQ11-N(AQ19))*AR15 -> 0 | AS18: =(AR11-N(AR19))*AS15 -> 0 | BB18: 2H/26 share repurchases ($m) | BC18: 0 | BD18: 0 | BE18: 0 | BF18: Post-Eddyfi deleveraging: no 2H buybacks in Base.
B19: Memo: Eddyfi net sales included in the segment (from 1-Jun-2026) | AL19: 9.6 | AM19: 0 | AN19: 0 | AO19: =SUM(AK19,AL19,AM19,AN19) -> 9.6 | AP19: 0 | AQ19: 0 | AR19: 0 | AS19: 0 | AT19: Q2/26: Eddyfi sales since closing $21.4m (10-Q Note 3) — Americas $9.6m (MD&A), EMEA & APAC $11.8m (derived). Removed from the 2026E base when growing the legacy segments in 2027E. | BB19: Minimum net debt / Adjusted EBITDA (x) — buyback floor 2027E+ | BC19: 2.5 | BD19: 2 | BE19: 1.75 | BF19: ESAB targets net leverage < 3.0x by YE2026 after Eddyfi and ~2x over time; buybacks resume once leverage reaches the floor.
B20: Adjusted EBITDA (segment, company definition) | K20: 111.588 | L20: 33.3 | M20: 38 | N20: 42.6 | O20: 45.7 | P20: 159.6 | Q20: 44 | R20: 48.6 | S20: 46.4 | T20: 49.6 | U20: 188.6 | V20: 49.4 | W20: 58.3 | X20: 57.2 | Y20: 59.8 | Z20: 224.7 | AA20: 54.1 | AB20: 64.7 | AC20: 59.4 | AD20: 61 | AE20: 239.2 | AF20: 54.5 | AG20: 56.8 | AH20: 57.3 | AI20: 56.8 | AJ20: 225.4 | AK20: 56 | AL20: 64 | AM20: =AM11*AM23 -> 65.481983 | AN20: =AN11*AN23 -> 64.602579 | AO20: =SUM(AK20,AL20,AM20,AN20) -> 250.08456 | AP20: =AO20-N(AO21)+AP26 -> 261.47944 | AQ20: =AP20-N(AP21)+AQ26 -> 276.28837 | AR20: =AQ20-N(AQ21)+AR26 -> 289.7645 | AS20: =AR20-N(AR21)+AS26 -> 303.71229 | AT20: 2027E+: legacy prior-year adjusted EBITDA + Δ bridge (organic $ × incremental margin + FX $ × prior margin). | AV20: =IFERROR((AS20/AJ20)^(1/5)-1,"n/m") -> 0.061455255 | AW20: =IFERROR((AJ20/K20)^(1/5)-1,"n/m") -> 0.15097869 | AX20: =IFERROR((AJ20/F20)^(1/10)-1,"n/m") -> n/m | AY20: =IFERROR((AJ20/C20)^(1/13)-1,"n/m") -> n/m | BB20: AM_org (Americas organic growth y/y) | BC20: 0.02 | BD20: Δ → | BE20: -0.02 | BF20: US equipment & automation demand, tariff-driven pricing, Latin America; 2025 −4%, Q2/26 +4.9%. Company organic outlook 2–4% (2026).
B21: Memo: Eddyfi adjusted EBITDA included in the segment (estimate) | AL21: 2.84448 | AM21: 0 | AN21: 0 | AO21: =SUM(AK21,AL21,AM21,AN21) -> 2.84448 | AP21: 0 | AQ21: 0 | AR21: 0 | AS21: 0 | AT21: June 2026 Eddyfi sales × 2026E standalone margin (not separately disclosed). | BB21: 2027E | BC21: =BD21+$BC$20 -> 0.06 | BD21: 0.04 | BE21: =BD21+$BE$20 -> 0.02
B22: Adjusted EBITDA margin before outlook calibration % (Q3/Q4-26E helper) | AM22: =AH23+($AK$20+$AL$20-$AL$21)/($AK$11+$AL$11-$AL$19)-($AF$20+$AG$20)/($AF$11+$AG$11) -> 0.19521236 | AN22: =AI23+($AK$20+$AL$20-$AL$21)/($AK$11+$AL$11-$AL$19)-($AF$20+$AG$20)/($AF$11+$AG$11) -> 0.20659684 | AT22: Prior-year quarter margin + (1H/26 legacy − 1H/25 margin drift). | BB22: 2028E | BC22: =BD22+$BC$20 -> 0.06 | BD22: 0.04 | BE22: =BD22+$BE$20 -> 0.02
B23: Adjusted EBITDA margin % | J23: =IF(AND(ISNUMBER(J20),ISNUMBER(J11)),IFERROR(J20/J11,""),"") | K23: =IF(AND(ISNUMBER(K20),ISNUMBER(K11)),IFERROR(K20/K11,""),"") -> 0.14540782 | L23: =IF(AND(ISNUMBER(L20),ISNUMBER(L11)),IFERROR(L20/L11,""),"") -> 0.14721485 | M23: =IF(AND(ISNUMBER(M20),ISNUMBER(M11)),IFERROR(M20/M11,""),"") -> 0.14984227 | N23: =IF(AND(ISNUMBER(N20),ISNUMBER(N11)),IFERROR(N20/N11,""),"") -> 0.16384615 | O23: =IF(AND(ISNUMBER(O20),ISNUMBER(O11)),IFERROR(O20/O11,""),"") -> 0.17284418 | P23: =IF(AND(ISNUMBER(P20),ISNUMBER(P11)),IFERROR(P20/P11,""),"") -> 0.15893248 | Q23: =IF(AND(ISNUMBER(Q20),ISNUMBER(Q11)),IFERROR(Q20/Q11,""),"") -> 0.16158649 | ... AL23: =IF(AND(ISNUMBER(AL20),ISNUMBER(AL11)),IFERROR(AL20/AL11,""),"") -> 0.20259576 | AM23: =AM22+AM122 -> 0.2142632 | AN23: =AN22+AN122 -> 0.22564769 | AO23: =IFERROR(AO20/AO11,"") -> 0.20906355 | AP23: =IFERROR(AP20/AP11,"") -> 0.21188248 | AQ23: =IFERROR(AQ20/AQ11,"") -> 0.21527162 | AR23: =IFERROR(AR20/AR11,"") -> 0.21813683 | AS23: =IFERROR(AS20/AS11,"") -> 0.22090515 | AV23: =IFERROR(AVERAGE(AO23,AP23,AQ23,AR23,AS23),"n/m") -> 0.21505193 | AW23: =IFERROR(AVERAGE(K23,P23,U23,Z23,AE23,AJ23),"n/m") -> 0.17651906 | AX23: =IFERROR(AVERAGE(F23,G23,H23,I23,J23,K23,P23,U23,Z23,AE23,AJ23),"n/m") -> 0.17651906 | AY23: =IFERROR(AVERAGE(C23,D23,E23,F23,G23,H23,I23,J23,K23,P23,U23,Z23,AE23,AJ23),"n/m") -> 0.17651906 | BB23: 2029E | BC23: =BD23+$BC$20 -> 0.055 | BD23: 0.035 | BE23: =BD23+$BE$20 -> 0.015
B24: Incremental adjusted EBITDA margin (Δ adj. EBITDA / Δ net sales) | K24: =IFERROR((K20-J20)/(K11-J11),"") -> -0.64779199 | P24: =IFERROR((P20-K20)/(P11-K11),"") -> 0.20276537 | Q24: =IFERROR((Q20-L20)/(Q11-L11),"") -> 0.23210412 | R24: =IFERROR((R20-M20)/(R11-M11),"") -> 0.28266667 | S24: =IFERROR((S20-N20)/(S11-N11),"") -> 0.17757009 | T24: =IFERROR((T20-O20)/(T11-O11),"") -> 0.203125 | U24: =IFERROR((U20-P20)/(U11-P11),"") -> 0.23349436 | V24: =IFERROR((V20-Q20)/(V11-Q11),"") -> 0.27979275 | W24: =IFERROR((W20-R20)/(W11-R11),"") -> 0.50520833 | ... AO24: =IFERROR((AO20-AJ20)/(AO11-AJ11),"") -> 0.37450145 | AP24: =IFERROR((AP20-AO20)/(AP11-AO11),"") -> 0.30093808 | AQ24: =IFERROR((AQ20-AP20)/(AQ11-AP11),"") -> 0.3 | AR24: =IFERROR((AR20-AQ20)/(AR11-AQ11),"") -> 0.3 | AS24: =IFERROR((AS20-AR20)/(AS11-AR11),"") -> 0.3 | BB24: 2030E | BC24: =BD24+$BC$20 -> 0.055 | BD24: 0.035 | BE24: =BD24+$BE$20 -> 0.015
B25: Organic incremental adjusted EBITDA margin % (input) | AP25: 0.3 | AQ25: 0.3 | AR25: 0.3 | AS25: 0.3 | AT25: Input: incremental margin on organic sales growth (EBXai productivity; ESAB delivered ~30–35% organic incrementals in 2023–25). | BB25: EA_org (EMEA & APAC organic growth y/y) | BC25: 0.02 | BD25: Δ → | BE25: -0.02 | BF25: Europe resilient, India/Asia growth, Middle East disruption in 2026; 2025 ~0%, 1H/26 −0.8%.
B26: Δ Adjusted EBITDA (organic × incremental + FX × prior margin) | AP26: =AP16*AP25+AP18*AO23 -> 14.239358 | AQ26: =AQ16*AQ25+AQ18*AP23 -> 14.808932 | AR26: =AR16*AR25+AR18*AQ23 -> 13.476128 | AS26: =AS16*AS25+AS18*AR23 -> 13.947792 | BB26: 2027E | BC26: =BD26+$BC$25 -> 0.05 | BD26: 0.03 | BE26: =BD26+$BE$25 -> 0.01
B27: Operating income (GAAP, segment) | J27: 95.2 | K27: 61.5 | L27: 22.4 | M27: 27.1 | N27: 31.6 | O27: 30.1 | P27: 111.2 | Q27: 30.2 | R27: 35.8 | S27: 36.6 | T27: 33.7 | U27: 136.2 | V27: 39.9 | W27: 46.1 | X27: 46.5 | Y27: 50.1 | Z27: 182.5 | AA27: 46 | AB27: 55.9 | AC27: 49.9 | AD27: 51.5 | AE27: 203.2 | AF27: 43.2 | AG27: 42.4 | AH27: 45.3 | AI27: 36.8 | AJ27: 167.8 | AK27: 35.2 | AL27: 22.5 | AT27: Historical disclosure only. | BB27: 2028E | BC27: =BD27+$BC$25 -> 0.05 | BD27: 0.03 | BE27: =BD27+$BE$25 -> 0.01
B28: Restructuring & other related charges (segment) | J28: 13.8 | K28: 12.4 | L28: 2.4 | M28: 2.1 | N28: 1.8 | O28: 5.3 | P28: 11.6 | Q28: 3.6 | R28: 3.6 | S28: 1.9 | T28: 2.3 | U28: 11.4 | V28: 0.9 | W28: 3 | X28: 1.6 | Y28: 1.1 | Z28: 6.5 | AA28: 0.2 | AB28: 0.8 | AC28: 0.9 | AD28: 1 | AE28: 3 | AF28: 1.7 | AG28: 0.5 | AH28: 2.2 | AI28: 7.2 | AJ28: 11.6 | AK28: 9 | AL28: 18.3 | BB28: 2029E | BC28: =BD28+$BC$25 -> 0.05 | BD28: 0.03 | BE28: =BD28+$BE$25 -> 0.01
B29: Acquisition-amortization & other related charges (segment) | J29: 20.1 | K29: 19.4 | L29: 4.7 | M29: 4.7 | N29: 4.6 | O29: 4.5 | P29: 18.5 | Q29: 4.1 | R29: 4.2 | S29: 4 | T29: 7.8 | U29: 20.1 | V29: 5.3 | W29: 5.4 | X29: 5.2 | Y29: 5 | Z29: 20.9 | AA29: 4.4 | AB29: 4.3 | AC29: 4.8 | AD29: 5 | AE29: 18.6 | AF29: 5.6 | AG29: 10 | AH29: 5.8 | AI29: 7.7 | AJ29: 29.2 | AK29: 7.7 | AL29: 18.2 | BB29: 2030E | BC29: =BD29+$BC$25 -> 0.05 | BD29: 0.03 | BE29: =BD29+$BE$25 -> 0.01
B30: Depreciation & other amortization (segment) | L30: 3.5 | M30: 3.7 | N30: 3.9 | O30: 3.8 | P30: 15 | Q30: 3.5 | R30: 3.4 | S30: 3.2 | T30: 3.3 | U30: 13.4 | V30: 3.3 | W30: 3.8 | X30: 3.9 | Y30: 3.7 | Z30: 14.8 | AA30: 3.5 | AB30: 3.7 | AC30: 3.8 | AD30: 3.5 | AE30: 14.5 | AF30: 3.9 | AG30: 3.8 | AH30: 3.9 | AI30: 5 | AJ30: 16.7 | AK30: 4.2 | AL30: 4.7 | BB30: EA_fx (EMEA & APAC FX translation y/y) | BC30: 0.01 | BD30: Δ → | BE30: -0.01 | BF30: Base 0% (constant currency); Bull weaker USD, Bear stronger USD.
BB31: 2027E | BC31: =BD31+$BC$30 -> 0.01 | BD31: 0 | BE31: =BD31+$BE$30 -> -0.01
B32: EMEA & APAC (Europe, Middle East, Africa, Asia Pacific; includes Russia) | AT32: EMEA & APAC — modelling logic | BB32: 2028E | BC32: =BD32+$BC$30 -> 0.01 | BD32: 0 | BE32: =BD32+$BE$30 -> -0.01
B33: Net sales | J33: 1307.353 | K33: 1182.655 | L33: 342 | M33: 376.2 | N33: 346 | O33: 359.8 | P33: 1423.9 | Q33: 375.6 | R33: 370.1 | S33: 338.9 | T33: 380.5 | U33: 1465.1 | V33: 392.4 | W33: 410.1 | X33: 375.2 | Y33: 382 | Z33: 1559.8 | AA33: 393.7 | AB33: 397.3 | AC33: 384.4 | AD33: 388.6 | AE33: 1564.1 | AF33: 397.5 | AG33: 432.9 | AH33: 435.1 | AI33: 446.8 | AJ33: 1712.2 | AK33: 457.2 | AL33: 491.7 | AM33: =AH33*(1+AM34) -> 455.16796 | AN33: =AI33*(1+AN34) -> 448.642 | AO33: =SUM(AK33,AL33,AM33,AN33) -> 1852.71 | AP33: =(AO33-N(AO41))*(1+AP34) -> 1896.1373 | AQ33: =(AP33-N(AP41))*(1+AQ34) -> 1953.0214 | AR33: =(AQ33-N(AQ41))*(1+AR34) -> 2011.612 | AS33: =(AR33-N(AR41))*(1+AS34) -> 2071.9604 | AT33: Historical: as reported (Q2/26 includes one month of Eddyfi). Q3/Q4-26E: legacy business only = prior-year quarter × (1 + organic + acquisitions + FX); Eddyfi in its own block. 2027E+: legacy 2026E (ex-Eddyfi June) × (1 + organic lever + FX). | AV33: =IFERROR((AS33/AJ33)^(1/5)-1,"n/m") -> 0.038880013 | AW33: =IFERROR((AJ33/K33)^(1/5)-1,"n/m") -> 0.076810506 | AX33: =IFERROR((AJ33/F33)^(1/10)-1,"n/m") -> n/m | AY33: =IFERROR((AJ33/C33)^(1/13)-1,"n/m") -> n/m | BB33: 2029E | BC33: =BD33+$BC$30 -> 0.01 | BD33: 0 | BE33: =BD33+$BE$30 -> -0.01
B34: Net sales y/y % | K34: =IF(AND(ISNUMBER(K33),ISNUMBER(J33)),IFERROR(K33/J33-1,""),"") -> -0.095382043 | P34: =IF(AND(ISNUMBER(P33),ISNUMBER(K33)),IFERROR(P33/K33-1,""),"") -> 0.20398595 | Q34: =IF(AND(ISNUMBER(Q33),ISNUMBER(L33)),IFERROR(Q33/L33-1,""),"") -> 0.098245614 | R34: =IF(AND(ISNUMBER(R33),ISNUMBER(M33)),IFERROR(R33/M33-1,""),"") -> -0.016214779 | S34: =IF(AND(ISNUMBER(S33),ISNUMBER(N33)),IFERROR(S33/N33-1,""),"") -> -0.020520231 | T34: =IF(AND(ISNUMBER(T33),ISNUMBER(O33)),IFERROR(T33/O33-1,""),"") -> 0.057531962 | U34: =IF(AND(ISNUMBER(U33),ISNUMBER(P33)),IFERROR(U33/P33-1,""),"") -> 0.028934616 | V34: =IF(AND(ISNUMBER(V33),ISNUMBER(Q33)),IFERROR(V33/Q33-1,""),"") -> 0.044728435 | W34: =IF(AND(ISNUMBER(W33),ISNUMBER(R33)),IFERROR(W33/R33-1,""),"") -> 0.1080789 | ... AL34: =IF(AND(ISNUMBER(AL33),ISNUMBER(AG33)),IFERROR(AL33/AG33-1,""),"") -> 0.13582814 | AM34: =AM35+AM36+AM37 -> 0.046122646 | AN34: =AN35+AN36+AN37 -> 0.0041226457 | AO34: =IFERROR(AO33/AJ33-1,"") -> 0.082063989 | AP34: =AP35+AP36+AP37 -> 0.03 | AQ34: =AQ35+AQ36+AQ37 -> 0.03 | AR34: =AR35+AR36+AR37 -> 0.03 | AS34: =AS35+AS36+AS37 -> 0.03 | BB34: 2030E | BC34: =BD34+$BC$30 -> 0.01 | BD34: 0 | BE34: =BD34+$BE$30 -> -0.01
B35: Organic growth % (company; price, mix & volume) | Q35: 0.156 | R35: 0.044 | S35: 0.048 | T35: 0.113 | U35: 0.089 | V35: 0.049 | W35: 0.111 | X35: 0.106 | Y35: 0.015 | Z35: 0.069 | AA35: 0.02 | AB35: -0.01 | AC35: 0.001 | AD35: 0.014 | AE35: 0.006 | AF35: 0.015 | AG35: 0.017 | AH35: 0.028 | AI35: -0.03 | AJ35: 0.007 | AK35: -0.027 | AL35: 0.009 | AM35: =$AL$35+AM118 -> 0.0041226457 | AN35: =$AL$35+AN118 -> 0.0041226457 | AO35: =IFERROR(AO38/AJ33,"") -> -0.0016728412 | AP35: =CHOOSE(MATCH($AT$2,{"Bull","Base","Bear"},0),$BC$26,$BD$26,$BE$26) -> 0.03 | AQ35: =CHOOSE(MATCH($AT$2,{"Bull","Base","Bear"},0),$BC$27,$BD$27,$BE$27) -> 0.03 | AR35: =CHOOSE(MATCH($AT$2,{"Bull","Base","Bear"},0),$BC$28,$BD$28,$BE$28) -> 0.03 | AS35: =CHOOSE(MATCH($AT$2,{"Bull","Base","Bear"},0),$BC$29,$BD$29,$BE$29) -> 0.03 | AT35: Q3/Q4-26E: Q2/26 y/y organic + outlook calibration Δ. 2027E+: scenario lever. ESAB does not split organic growth into price and volume. | BB35: EDD_g (Eddyfi sales growth y/y) | BC35: 0.03 | BD35: Δ → | BE35: -0.03 | BF35: Company: high-single-digit organic growth (aerospace & defense, nuclear, energy, civil infrastructure inspection).
B36: Acquisitions % (excl. Eddyfi in forecast) | Q36: 0 | R36: 0 | S36: 0 | T36: 0.008 | U36: 0.002 | V36: 0.017 | W36: 0.014 | X36: 0.02 | Y36: 0.006 | Z36: 0.014 | AA36: 0 | AB36: 0 | AC36: 0.01 | AD36: 0.014 | AE36: 0.006 | AF36: 0.013 | AG36: 0.032 | AH36: 0.069 | AI36: 0.112 | AJ36: 0.056 | AK36: 0.108 | AL36: 0.106 | AM36: 0.042 | AN36: 0 | AO36: =IFERROR(AO39/AJ33,"") -> 0.062536036 | AP36: 0 | AQ36: 0 | AR36: 0 | AS36: 0 | AT36: EWM GmbH (acquired 22-Aug-2025) anniversaries in Q3/26: Q3/26E = 49 of 91 days of the Q2/26 non-Eddyfi acquisition contribution ($46.0m − $11.8m Eddyfi = $34.2m) ÷ Q3/25 EMEA & APAC sales = 4.2%; Q4/26E 0%. | BB36: 2027E | BC36: =BD36+$BC$35 -> 0.11 | BD36: 0.08 | BE36: =BD36+$BE$35 -> 0.05
B37: Foreign currency translation % | Q37: -0.058 | R37: -0.06 | S37: -0.069 | T37: -0.063 | U37: -0.062 | V37: -0.021 | W37: -0.017 | X37: -0.019 | Y37: -0.016 | Z37: -0.018 | AA37: -0.017 | AB37: -0.021 | AC37: 0.014 | AD37: -0.01 | AE37: -0.009 | AF37: -0.019 | AG37: 0.041 | AH37: 0.036 | AI37: 0.067 | AJ37: 0.031 | AK37: 0.069 | AL37: 0.021 | AM37: 0 | AN37: 0 | AO37: =IFERROR(AO40/AJ33,"") -> 0.021259199 | AP37: =CHOOSE(MATCH($AT$2,{"Bull","Base","Bear"},0),$BC$31,$BD$31,$BE$31) -> 0 | AQ37: =CHOOSE(MATCH($AT$2,{"Bull","Base","Bear"},0),$BC$32,$BD$32,$BE$32) -> 0 | AR37: =CHOOSE(MATCH($AT$2,{"Bull","Base","Bear"},0),$BC$33,$BD$33,$BE$33) -> 0 | AS37: =CHOOSE(MATCH($AT$2,{"Bull","Base","Bear"},0),$BC$34,$BD$34,$BE$34) -> 0 | AT37: Q3/Q4-26E: FX input (spot vs prior-year rates). 2027E+: EMEA & APAC FX lever; Americas 0%. | BB37: 2028E | BC37: =BD37+$BC$35 -> 0.11 | BD37: 0.08 | BE37: =BD37+$BE$35 -> 0.05
B38: Δ Net sales — organic ($) | Q38: 53.5 | R38: 16.5 | S38: 16.7 | T38: 40.6 | U38: 126.9 | V38: 18.3 | W38: 41.2 | X38: 36 | Y38: 5.6 | Z38: 101.1 | AA38: 7.7 | AB38: -4.1 | AC38: 0.4 | AD38: 5.3 | AE38: 9.3 | AF38: 5.9 | AG38: 6.8 | AH38: 10.6 | AI38: -11.7 | AJ38: 11.6 | AK38: -10.5 | AL38: 4 | AM38: =AH33*AM35 -> 1.7937631 | AN38: =AI33*AN35 -> 1.8419981 | AO38: =SUM(AK38,AL38,AM38,AN38) -> -2.8642388 | AP38: =(AO33-N(AO41))*AP35 -> 55.227299 | AQ38: =(AP33-N(AP41))*AQ35 -> 56.884118 | AR38: =(AQ33-N(AQ41))*AR35 -> 58.590641 | AS38: =(AR33-N(AR41))*AS35 -> 60.348361 | BB38: 2029E | BC38: =BD38+$BC$35 -> 0.11 | BD38: 0.08 | BE38: =BD38+$BE$35 -> 0.05
B39: Δ Net sales — acquisitions ($) | Q39: 0 | R39: 0 | S39: 0 | T39: 2.8 | U39: 2.8 | V39: 6.3 | W39: 5.2 | X39: 6.7 | Y39: 2.1 | Z39: 20.2 | AA39: 0.1 | AB39: 0 | AC39: 3.8 | AD39: 5.3 | AE39: 9.2 | AF39: 5.2 | AG39: 12.7 | AH39: 26.4 | AI39: 43.7 | AJ39: 88 | AK39: 42.8 | AL39: 46 | AM39: =AH33*AM36 -> 18.2742 | AN39: =AI33*AN36 -> 0 | AO39: =SUM(AK39,AL39,AM39,AN39) -> 107.0742 | AP39: 0 | AQ39: 0 | AR39: 0 | AS39: 0 | BB39: 2030E | BC39: =BD39+$BC$35 -> 0.11 | BD39: 0.08 | BE39: =BD39+$BE$35 -> 0.05
B40: Δ Net sales — FX ($) | Q40: -19.9 | R40: -22.6 | S40: -23.8 | T40: -22.7 | U40: -88.5 | V40: -7.8 | W40: -6.4 | X40: -6.4 | Y40: -6.2 | Z40: -26.7 | AA40: -6.6 | AB40: -8.8 | AC40: 5.1 | AD40: -4 | AE40: -14.2 | AF40: -7.4 | AG40: 16.1 | AH40: 13.7 | AI40: 26.2 | AJ40: 48.5 | AK40: 27.5 | AL40: 8.9 | AM40: =AH33*AM37 -> 0 | AN40: =AI33*AN37 -> 0 | AO40: =SUM(AK40,AL40,AM40,AN40) -> 36.4 | AP40: =(AO33-N(AO41))*AP37 -> 0 | AQ40: =(AP33-N(AP41))*AQ37 -> 0 | AR40: =(AQ33-N(AQ41))*AR37 -> 0 | AS40: =(AR33-N(AR41))*AS37 -> 0 | BB40: EDD_m (Eddyfi adjusted EBITDA margin before synergies) | BC40: 0.02 | BD40: Δ → | BE40: -0.02 | BF40: Deal metrics: ~$80m adj. EBITDA on ~$270m 2026E revenue (29.6%); gross margin > 65%.
...

Sheet Bull-Base-Bear
B2: ESAB Corporation (ESAB) — Bull / Base / Bear Case P&L Summary | J2: Share price ($): | K2: =Model!$AO$419 -> 69.94
B3: Adjusted figures (company definitions: adjusted EBITDA; core adjusted net income / EPS excluding Russia, MCPS if-converted) · USD millions · Live panel linked to Model — toggle scenario via Model!AT2. Bull and Bear panels are value snapshots generated from the Model with the switch set to each case. 2026E includes Eddyfi from 1-Jun-2026; adjusted EBITDA for leverage / EV is pro forma for Eddyfi full year in 2026E. | J3: As of: | K3: =TODAY() -> 2026-10-07 00:00:00
B5: Scenario: | C5: =Model!$AT$2 -> Base | N5: Scenario: | O5: Bull | P5: Snapshot (values) — Model run with switch = Bull | Z5: Scenario: | AA5: Bear | AB5: Snapshot (values) — Model run with switch = Bear
B7: (USDm, except EPS and shares) | C7: 2025A | D7: 2026E | E7: 2027E | F7: 2028E | G7: 2029E | H7: 2030E | I7: 25-'30 CAGR | J7: LT Hist Avg | K7: LT Hist Min | L7: LT Hist Max | N7: (USDm, except EPS and shares) | O7: 2025A | P7: 2026E | Q7: 2027E | R7: 2028E | S7: 2029E | T7: 2030E | U7: 25-'30 CAGR | V7: LT Hist Avg | W7: LT Hist Min | X7: LT Hist Max | Z7: (USDm, except EPS and shares) | AA7: 2025A | AB7: 2026E | AC7: 2027E | AD7: 2028E | AE7: 2029E | AF7: 2030E | AG7: 25-'30 CAGR | AH7: LT Hist Avg | AI7: LT Hist Min | AJ7: LT Hist Max
B9: Net sales | C9: =Model!AJ136 -> 2842.555 | D9: =Model!AO136 -> 3182.8135 | E9: =Model!AP136 -> 3421.8149 | F9: =Model!AQ136 -> 3588.8901 | G9: =Model!AR136 -> 3808.0954 | H9: =Model!AS136 -> 4049.2662 | I9: =IFERROR((H9/C9)^(1/5)-1,"n/m") -> 0.07333055 | N9: Net sales | O9: 2842.555 | P9: 3223.318 | Q9: 3576.8092 | R9: 3894.4028 | S9: 4275.6549 | T9: 4691.3486 | U9: 0.10539569 | Z9: Net sales | AA9: 2842.555 | AB9: 3142.309 | AC9: 3293.9339 | AD9: 3344.4925 | AE9: 3416.1472 | AF9: 3503.3601 | AG9: 0.042689933
B10: Net sales y/y % | D10: =IFERROR(D9/C9-1,"") -> 0.11970164 | E10: =IFERROR(E9/D9-1,"") -> 0.07509124 | F10: =IFERROR(F9/E9-1,"") -> 0.048826494 | G10: =IFERROR(G9/F9-1,"") -> 0.061078857 | H10: =IFERROR(H9/G9-1,"") -> 0.063331076 | N10: Net sales y/y % | P10: 0.13395097 | Q10: 0.10966688 | R10: 0.088792422 | S10: 0.097897446 | T10: 0.097223406 | Z10: Net sales y/y % | AB10: 0.10545231 | AC10: 0.048252693 | AD10: 0.015348999 | AE10: 0.021424684 | AF10: 0.025529622
B11: Core organic growth % (ex-Russia) | C11: =Model!AJ235 -> -0.002 | D11: =Model!AO235 -> 0.012572266 | E11: =Model!AP235 -> 0.033804519 | F11: =Model!AQ235 -> 0.032423932 | G11: =Model!AR235 -> 0.030056437 | H11: =Model!AS235 -> 0.029166863 | N11: Core organic growth % (ex-Russia) | O11: -0.002 | P11: 0.027572266 | Q11: 0.053739088 | R11: 0.05111755 | S11: 0.047809364 | T11: 0.045923584 | Z11: Core organic growth % (ex-Russia) | AA11: -0.002 | AB11: -0.0024277343 | AC11: 0.013871719 | AD11: 0.013346352 | AE11: 0.011377011 | AF11: 0.011206861
B12: Adjusted EBITDA (company definition) | C12: =Model!AJ189 -> 559.726 | D12: =Model!AO189 -> 624.982 | E12: =Model!AP189 -> 707.275 | F12: =Model!AQ189 -> 766.04685 | G12: =Model!AR189 -> 824.6016 | H12: =Model!AS189 -> 884.64263 | I12: =IFERROR((H12/C12)^(1/5)-1,"n/m") -> 0.095868584 | N12: Adjusted EBITDA (company definition) | O12: 559.726 | P12: 629.982 | Q12: 752.37768 | R12: 848.62738 | S12: 948.14669 | T12: 1052.5559 | U12: 0.13462915 | Z12: Adjusted EBITDA (company definition) | AA12: 559.726 | AB12: 619.982 | AC12: 667.53707 | AD12: 696.03497 | AE12: 718.00384 | AF12: 739.89747 | AG12: 0.057399772
B13: Adjusted EBITDA margin % | C13: =Model!AJ190 -> 0.19690947 | D13: =Model!AO190 -> 0.19636149 | E13: =Model!AP190 -> 0.20669587 | F13: =Model!AQ190 -> 0.21344951 | G13: =Model!AR190 -> 0.21653911 | H13: =Model!AS190 -> 0.21846986 | J13: =IFERROR(AVERAGE(Model!J190,Model!K190,Model!P190,Model!U190,Model!Z190,Model!AE190,Model!AJ190),"") -> 0.17387673 | K13: =IFERROR(MIN(Model!J190,Model!K190,Model!P190,Model!U190,Model!Z190,Model!AE190,Model!AJ190),"") -> 0.15442838 | L13: =IFERROR(MAX(Model!J190,Model!K190,Model!P190,Model!U190,Model!Z190,Model!AE190,Model!AJ190),"") -> 0.19690947 | N13: Adjusted EBITDA margin % | O13: 0.19690947 | P13: 0.19544519 | Q13: 0.21034884 | R13: 0.2179095 | S13: 0.22175473 | T13: 0.22436105 | V13: 0.17387673 | W13: 0.15442838 | X13: 0.19690947 | Z13: Adjusted EBITDA margin % | AA13: 0.19690947 | AB13: 0.19730141 | AC13: 0.20265649 | AD13: 0.20811378 | AE13: 0.21017942 | AF13: 0.21119652 | AH13: 0.17387673 | AI13: 0.15442838 | AJ13: 0.19690947
B15: Operating income (GAAP) | C15: =Model!AJ144 -> 412.17 | D15: =Model!AO144 -> 380.08277 | E15: =Model!AP144 -> 501.98734 | F15: =Model!AQ144 -> 578.60307 | G15: =Model!AR144 -> 637.66022 | H15: =Model!AS144 -> 693.23441 | I15: =IFERROR((H15/C15)^(1/5)-1,"n/m") -> 0.10958543 | N15: Operating income (GAAP) | O15: 412.17 | P15: 385.08277 | Q15: 542.89632 | R15: 651.29437 | S15: 745.42184 | T15: 839.25539 | U15: 0.15282544 | Z15: Operating income (GAAP) | AA15: 412.17 | AB15: 375.08277 | AC15: 464.40719 | AD15: 514.28645 | AE15: 542.40145 | AF15: 565.5846 | AG15: 0.065330203
B16: Operating income y/y % | D16: =IFERROR(D15/C15-1,"") -> -0.077849511 | E16: =IFERROR(E15/D15-1,"") -> 0.32073166 | F16: =IFERROR(F15/E15-1,"") -> 0.15262481 | G16: =IFERROR(G15/F15-1,"") -> 0.10206851 | H16: =IFERROR(H15/G15-1,"") -> 0.08715329 | N16: Operating income y/y % | P16: -0.065718594 | Q16: 0.40981723 | R16: 0.1996662 | S16: 0.1445237 | T16: 0.12587979 | Z16: Operating income y/y % | AB16: -0.089980428 | AC16: 0.2381459 | AD16: 0.10740415 | AE16: 0.054667985 | AF16: 0.042741682
B17: Operating margin (GAAP) % | C17: =Model!AJ246 -> 0.14499983 | D17: =Model!AO246 -> 0.11941723 | E17: =Model!AP246 -> 0.14670207 | F17: =Model!AQ246 -> 0.16122061 | G17: =Model!AR246 -> 0.16744859 | H17: =Model!AS246 -> 0.17120001 | J17: =IFERROR(AVERAGE(Model!J246,Model!K246,Model!P246,Model!U246,Model!Z246,Model!AE246,Model!AJ246),"") -> 0.13207439 | K17: =IFERROR(MIN(Model!J246,Model!K246,Model!P246,Model!U246,Model!Z246,Model!AE246,Model!AJ246),"") -> 0.10365069 | L17: =IFERROR(MAX(Model!J246,Model!K246,Model!P246,Model!U246,Model!Z246,Model!AE246,Model!AJ246),"") -> 0.16325508 | N17: Operating margin (GAAP) % | O17: 0.14499983 | P17: 0.11946782 | Q17: 0.1517823 | R17: 0.16723857 | S17: 0.17434097 | T17: 0.17889427 | V17: 0.13207439 | W17: 0.10365069 | X17: 0.16325508 | Z17: Operating margin (GAAP) % | AA17: 0.14499983 | AB17: 0.11936534 | AC17: 0.14098862 | AD17: 0.15377115 | AE17: 0.15877579 | AF17: 0.16144061 | AH17: 0.13207439 | AI17: 0.10365069 | AJ17: 0.16325508
B19: Core adjusted net income (continuing ops, ex-Russia) | C19: =Model!AJ220 -> 324.493 | D19: =Model!AO220 -> 334.79372 | E19: =Model!AP220 -> 389.82392 | F19: =Model!AQ220 -> 441.41024 | G19: =Model!AR220 -> 484.88186 | H19: =Model!AS220 -> 525.1913 | I19: =IFERROR((H19/C19)^(1/5)-1,"n/m") -> 0.10108904 | N19: Core adjusted net income (continuing ops, ex-Russia) | O19: 324.493 | P19: 340.0975 | Q19: 421.87793 | R19: 495.87438 | S19: 556.23746 | T19: 619.43308 | U19: 0.13804075 | Z19: Core adjusted net income (continuing ops, ex-Russia) | AA19: 324.493 | AB19: 329.58993 | AC19: 361.41058 | AD19: 391.24324 | AE19: 411.62064 | AF19: 428.95151 | AG19: 0.057403088
B21: FDSO (m; incl. MCPS if-converted) | C21: =Model!AJ223 -> 61.266294 | D21: =Model!AO223 -> 63.307258 | E21: =Model!AP223 -> 64.065302 | F21: =Model!AQ223 -> 63.712067 | G21: =Model!AR223 -> 62.031076 | H21: =Model!AS223 -> 57.559192 | I21: =IFERROR((H21/C21)^(1/5)-1,"n/m") -> -0.012405609 | N21: FDSO (m; incl. MCPS if-converted) | O21: 61.266294 | P21: 63.307258 | Q21: 63.204293 | R21: 60.010702 | S21: 55.80935 | T21: 50.119013 | U21: -0.039369925 | Z21: FDSO (m; incl. MCPS if-converted) | AA21: 61.266294 | AB21: 63.307258 | AC21: 64.065302 | AD21: 64.365302 | AE21: 64.518148 | AF21: 61.596079 | AG21: 0.0010742534
B23: Core adjusted EPS — Diluted ($) | C23: =Model!AJ227 -> 5.2964359 | D23: =Model!AO227 -> 5.5179078 | E23: =Model!AP227 -> 6.0847902 | F23: =Model!AQ227 -> 6.9282046 | G23: =Model!AR227 -> 7.8167573 | H23: =Model!AS227 -> 9.124369 | I23: =IFERROR((H23/C23)^(1/5)-1,"n/m") -> 0.1149203 | N23: Core adjusted EPS — Diluted ($) | O23: 5.2964359 | P23: 5.6028169 | Q23: 6.6748303 | R23: 8.2630991 | S23: 9.9667432 | T23: 12.359243 | U23: 0.18468157 | Z23: Core adjusted EPS — Diluted ($) | AA23: 5.2964359 | AB23: 5.4345997 | AC23: 5.6412843 | AD23: 6.0784806 | AE23: 6.3799203 | AF23: 6.9639418 | AG23: 0.056268388
B24: EPS y/y % | D24: =IFERROR(D23/C23-1,"") -> 0.041815275 | E24: =IFERROR(E23/D23-1,"") -> 0.10273501 | F24: =IFERROR(F23/E23-1,"") -> 0.13861028 | G24: =IFERROR(G23/F23-1,"") -> 0.1282515 | H24: =IFERROR(H23/G23-1,"") -> 0.16728315 | N24: EPS y/y % | P24: 0.05784664 | Q24: 0.19133471 | R24: 0.23794895 | S24: 0.20617495 | T24: 0.24004835 | Z24: EPS y/y % | AB24: 0.026086172 | AC24: 0.038031248 | AD24: 0.07749944 | AE24: 0.049591285 | AF24: 0.091540566
B26: P / E (x) — assumed (adjusted EPS) | G26: 16 | H26: 16 | N26: P / E (x) — assumed (adjusted EPS) | S26: 19 | T26: 19 | Z26: P / E (x) — assumed (adjusted EPS) | AD26: 13 | AE26: 13 | AF26: 13
B27: Price Target ($) | G27: =G26*G23 -> 125.06812 | H27: =H26*H23 -> 145.9899 | N27: Price Target ($) | S27: =S26*S23 -> 189.36812 | T27: =T26*T23 -> 234.82563 | Z27: Price Target ($) | AD27: =AD26*AD23 -> 79.020248 | AE27: =AE26*AE23 -> 82.938964 | AF27: =AF26*AF23 -> 90.531244
B28: Upside / (Downside) vs current | G28: =IFERROR(G27/$K$2-1,"") -> 0.78822013 | H28: =IFERROR(H27/$K$2-1,"") -> 1.0873592 | N28: Upside / (Downside) vs current | S28: =IFERROR(S27/$K$2-1,"") -> 1.7075796 | T28: =IFERROR(T27/$K$2-1,"") -> 2.3575297 | Z28: Upside / (Downside) vs current | AD28: =IFERROR(AD27/$K$2-1,"") -> 0.12982911 | AE28: =IFERROR(AE27/$K$2-1,"") -> 0.18585879 | AF28: =IFERROR(AF27/$K$2-1,"") -> 0.29441298
B29: IRR (to Dec-Y-1) | G29: =IFERROR((G27/$K$2)^(1/((DATE(2029-1,12,31)-$K$3)/365.25))-1,"") -> 0.29713814 | H29: =IFERROR((H27/$K$2)^(1/((DATE(2030-1,12,31)-$K$3)/365.25))-1,"") -> 0.25557425 | N29: IRR (to Dec-Y-1) | S29: =IFERROR((S27/$K$2)^(1/((DATE(2029-1,12,31)-$K$3)/365.25))-1,"") -> 0.56180862 | T29: =IFERROR((T27/$K$2)^(1/((DATE(2030-1,12,31)-$K$3)/365.25))-1,"") -> 0.45439747 | Z29: IRR (to Dec-Y-1) | AD29: =IFERROR((AD27/$K$2)^(1/((DATE(2028-1,12,31)-$K$3)/365.25))-1,"") -> 0.10415156 | AE29: =IFERROR((AE27/$K$2)^(1/((DATE(2029-1,12,31)-$K$3)/365.25))-1,"") -> 0.079289427 | AF29: =IFERROR((AF27/$K$2)^(1/((DATE(2030-1,12,31)-$K$3)/365.25))-1,"") -> 0.083081094
B31: Free Cash Flow | C31: =Model!AJ281 -> 213.28 | D31: =Model!AO281 -> 255.64936 | E31: =Model!AP281 -> 378.62344 | F31: =Model!AQ281 -> 441.30207 | G31: =Model!AR281 -> 479.26273 | H31: =Model!AS281 -> 518.12534 | I31: =IFERROR((H31/C31)^(1/5)-1,"n/m") -> 0.19425465 | N31: Free Cash Flow | O31: 213.28 | P31: 252.30229 | Q31: 401.71571 | R31: 484.13898 | S31: 539.42725 | T31: 601.54987 | U31: 0.23045093 | Z31: Free Cash Flow | AA31: 213.28 | AB31: 259.09646 | AC31: 357.02467 | AD31: 400.54947 | AE31: 417.05197 | AF31: 432.1005 | AG31: 0.15166701
B32: FCF % | C32: =Model!AJ284 -> 0.07503109 | D32: =Model!AO284 -> 0.080321817 | E32: =Model!AP284 -> 0.11064989 | F32: =Model!AQ284 -> 0.12296338 | G32: =Model!AR284 -> 0.12585366 | H32: =Model!AS284 -> 0.12795537 | J32: =IFERROR(AVERAGE(Model!J284,Model!K284,Model!P284,Model!U284,Model!Z284,Model!AE284,Model!AJ284),"") -> 0.096094779 | K32: =IFERROR(MIN(Model!J284,Model!K284,Model!P284,Model!U284,Model!Z284,Model!AE284,Model!AJ284),"") -> 0.067135663 | L32: =IFERROR(MAX(Model!J284,Model!K284,Model!P284,Model!U284,Model!Z284,Model!AE284,Model!AJ284),"") -> 0.13796589 | N32: FCF % | O32: 0.07503109 | P32: 0.078274091 | Q32: 0.11231119 | R32: 0.12431662 | S32: 0.12616249 | T32: 0.12822536 | V32: 0.096094779 | W32: 0.067135663 | X32: 0.13796589 | Z32: FCF % | AA32: 0.07503109 | AB32: 0.082454165 | AC32: 0.10838854 | AD32: 0.1197639 | AE32: 0.12208255 | AF32: 0.12333888 | AH32: 0.096094779 | AI32: 0.067135663 | AJ32: 0.13796589
B33: FCF / share ($) | C33: =IFERROR(C31/C21,"") -> 3.4811964 | D33: =IFERROR(D31/D21,"") -> 4.0382315 | E33: =IFERROR(E31/E21,"") -> 5.909961 | F33: =IFERROR(F31/F21,"") -> 6.9265069 | G33: =IFERROR(G31/G21,"") -> 7.7261715 | H33: =IFERROR(H31/H21,"") -> 9.0016091 | N33: FCF / share ($) | O33: 3.4811964 | P33: 3.9853611 | Q33: 6.3558295 | R33: 8.0675439 | S33: 9.6655355 | T33: 12.002429 | Z33: FCF / share ($) | AA33: 3.4811964 | AB33: 4.0926818 | AC33: 5.5728243 | AD33: 6.2230651 | AE33: 6.4641032 | AF33: 7.015065
B34: FCF Yield (on PT) | F34: =IFERROR(F33/F$27,"") | G34: =IFERROR(G33/G$27,"") -> 0.061775709 | H34: =IFERROR(H33/H$27,"") -> 0.061659121 | N34: FCF Yield (on PT) | R34: =IFERROR(R33/R$27,"") | S34: =IFERROR(S33/S$27,"") -> 0.051040985 | T34: =IFERROR(T33/T$27,"") -> 0.05111209 | Z34: FCF Yield (on PT) | AD34: =IFERROR(AD33/AD$27,"") -> 0.078752791 | AE34: =IFERROR(AE33/AE$27,"") -> 0.077938076 | AF34: =IFERROR(AF33/AF$27,"") -> 0.077487779
B35: Adjusted EBITDA — pro forma (2026E incl. Eddyfi full year) | C35: =Model!AJ415 -> 559.726 | D35: =Model!AO415 -> 658.0783 | E35: =Model!AP415 -> 707.275 | F35: =Model!AQ415 -> 766.04685 | G35: =Model!AR415 -> 824.6016 | H35: =Model!AS415 -> 884.64263 | I35: =IFERROR((H35/C35)^(1/5)-1,"n/m") -> 0.095868584 | N35: Adjusted EBITDA — pro forma (2026E incl. Eddyfi full year) | O35: 559.726 | P35: 663.0783 | Q35: 752.37768 | R35: 848.62738 | S35: 948.14669 | T35: 1052.5559 | U35: 0.13462915 | Z35: Adjusted EBITDA — pro forma (2026E incl. Eddyfi full year) | AA35: 559.726 | AB35: 653.0783 | AC35: 667.53707 | AD35: 696.03497 | AE35: 718.00384 | AF35: 739.89747 | AG35: 0.057399772
B36: Adjusted EBITDA (pro forma) % of net sales | C36: =IFERROR(C35/C9,"") -> 0.19690947 | D36: =IFERROR(D35/D9,"") -> 0.20675993 | E36: =IFERROR(E35/E9,"") -> 0.20669587 | F36: =IFERROR(F35/F9,"") -> 0.21344951 | G36: =IFERROR(G35/G9,"") -> 0.21653911 | H36: =IFERROR(H35/H9,"") -> 0.21846986 | J36: =IFERROR(AVERAGE(Model!J190,Model!K190,Model!P190,Model!U190,Model!Z190,Model!AE190,Model!AJ190),"") -> 0.17387673 | K36: =IFERROR(MIN(Model!J190,Model!K190,Model!P190,Model!U190,Model!Z190,Model!AE190,Model!AJ190),"") -> 0.15442838 | L36: =IFERROR(MAX(Model!J190,Model!K190,Model!P190,Model!U190,Model!Z190,Model!AE190,Model!AJ190),"") -> 0.19690947 | N36: Adjusted EBITDA (pro forma) % of net sales | O36: 0.19690947 | P36: 0.20571297 | Q36: 0.21034884 | R36: 0.2179095 | S36: 0.22175473 | T36: 0.22436105 | V36: 0.17387673 | W36: 0.15442838 | X36: 0.19690947 | Z36: Adjusted EBITDA (pro forma) % of net sales | AA36: 0.19690947 | AB36: 0.20783389 | AC36: 0.20265649 | AD36: 0.20811378 | AE36: 0.21017942 | AF36: 0.21119652 | AH36: 0.17387673 | AI36: 0.15442838 | AJ36: 0.19690947
B38: Net Debt | C38: =Model!AJ414 -> 1049.089 | D38: =Model!AO414 -> 1993.6474 | E38: =Model!AP414 -> 1657.9064 | F38: =Model!AQ414 -> 1519.3837 | G38: =Model!AR414 -> 1636.4932 | H38: =Model!AS414 -> 1756.5753 | N38: Net Debt | O38: 1049.089 | P38: 1996.9945 | Q38: 1868.2342 | R38: 2108.8584 | S38: 2357.6567 | T38: 2618.6797 | Z38: Net Debt | AA38: 1049.089 | AB38: 1990.2003 | AC38: 1676.058 | AD38: 1371.7087 | AE38: 1243.7967 | AF38: 1282.1106
B39: Net Debt / Adjusted EBITDA (x) | C39: =IFERROR(C38/C35,"") -> 1.8742903 | D39: =IFERROR(D38/D35,"") -> 3.0294987 | E39: =IFERROR(E38/E35,"") -> 2.344076 | F39: =IFERROR(F38/F35,"") -> 1.9834083 | G39: =IFERROR(G38/G35,"") -> 1.9845865 | H39: =IFERROR(H38/H35,"") -> 1.9856326 | N39: Net Debt / Adjusted EBITDA (x) | O39: 1.8742903 | P39: 3.0117023 | Q39: 2.4831069 | R39: 2.4850229 | S39: 2.4865949 | T39: 2.4879246 | Z39: Net Debt / Adjusted EBITDA (x) | AA39: 1.8742903 | AB39: 3.0474145 | AC39: 2.510809 | AD39: 1.9707469 | AE39: 1.7322981 | AF39: 1.7328219
B40: Share repurchases ($m) | D40: =Model!AO293 -> 0 | E40: =Model!AP293 -> 0 | F40: =Model!AQ293 -> 106.57922 | G40: =Model!AR293 -> 352.99079 | H40: =Model!AS293 -> 398.3332 | N40: Share repurchases ($m) | P40: 0 | Q40: 130.073 | R40: 429.52154 | S40: 448.32215 | T40: 527.25326
B41: Implied avg buyback price ($) | D41: =Model!AO292 -> 69.94 | E41: =Model!AP292 -> 75.5352 | F41: =Model!AQ292 -> 81.578016 | G41: =Model!AR292 -> 88.104257 | H41: =Model!AS292 -> 95.152598 | N41: Implied avg buyback price ($) | P41: 69.94 | Q41: 75.5352 | R41: 81.578016 | S41: 88.104257 | T41: 95.152598
B42: Shares repurchased (m) | D42: =Model!AO294 -> 0 | E42: =Model!AP294 -> 0 | F42: =Model!AQ294 -> 1.3064699 | G42: =Model!AR294 -> 4.0065123 | H42: =Model!AS294 -> 4.1862567 | N42: Shares repurchased (m) | P42: 0 | Q42: 1.7220184 | R42: 5.2651629 | S42: 5.0885413 | T42: 5.5411336
B44: ROIC | C44: =Model!AJ397 -> 0.12395001 | D44: =Model!AO397 -> 0.094723216 | E44: =Model!AP397 -> 0.1077261 | F44: =Model!AQ397 -> 0.11473909 | G44: =Model!AR397 -> 0.11986751 | H44: =Model!AS397 -> 0.12487139 | J44: =IFERROR(AVERAGE(Model!J397,Model!K397,Model!P397,Model!U397,Model!Z397,Model!AE397,Model!AJ397),"") -> 0.11895184 | K44: =IFERROR(MIN(Model!J397,Model!K397,Model!P397,Model!U397,Model!Z397,Model!AE397,Model!AJ397),"") -> 0.081782149 | L44: =IFERROR(MAX(Model!J397,Model!K397,Model!P397,Model!U397,Model!Z397,Model!AE397,Model!AJ397),"") -> 0.14780085 | N44: ROIC | O44: 0.12395001 | P44: 0.096050737 | Q44: 0.11189622 | R44: 0.12138919 | S44: 0.12904685 | T44: 0.1366238 | V44: 0.11895184 | W44: 0.081782149 | X44: 0.14780085 | Z44: ROIC | AA44: 0.12395001 | AB44: 0.093424302 | AC44: 0.10186496 | AD44: 0.10692429 | AE44: 0.10950985 | AF44: 0.11196308 | AH44: 0.11895184 | AI44: 0.081782149 | AJ44: 0.14780085
B45: RONTA | C45: =Model!AJ408 -> 0.27289074 | D45: =Model!AO408 -> 0.27373304 | E45: =Model!AP408 -> 0.27163673 | F45: =Model!AQ408 -> 0.26791248 | G45: =Model!AR408 -> 0.29725975 | H45: =Model!AS408 -> 0.32874601 | J45: =IFERROR(AVERAGE(Model!J408,Model!K408,Model!P408,Model!U408,Model!Z408,Model!AE408,Model!AJ408),"") -> 0.29044232 | K45: =IFERROR(MIN(Model!J408,Model!K408,Model!P408,Model!U408,Model!Z408,Model!AE408,Model!AJ408),"") -> 0.2569119 | L45: =IFERROR(MAX(Model!J408,Model!K408,Model!P408,Model!U408,Model!Z408,Model!AE408,Model!AJ408),"") -> 0.33757774 | N45: RONTA | O45: 0.27289074 | P45: 0.27657469 | Q45: 0.31518812 | R45: 0.34187961 | S45: 0.36452615 | T45: 0.38576945 | V45: 0.29044232 | W45: 0.2569119 | X45: 0.33757774 | Z45: RONTA | AA45: 0.27289074 | AB45: 0.27095759 | AC45: 0.26090297 | AD45: 0.23044184 | AE45: 0.22110257 | AF45: 0.22816399 | AH45: 0.29044232 | AI45: 0.2569119 | AJ45: 0.33757774
B47: Implied Market Cap (USDm) | F47: =F27*F21 -> 0 | G47: =G27*G21 -> 7758.1098 | H47: =H27*H21 -> 8403.0608 | N47: Implied Market Cap (USDm) | R47: =R27*R21 -> 0 | S47: =S27*S21 -> 10568.512 | T47: =T27*T21 -> 11769.228 | Z47: Implied Market Cap (USDm) | AD47: =AD27*AD21 -> 5086.1621 | AE47: =AE27*AE21 -> 5351.0684 | AF47: =AF27*AF21 -> 5576.3697
B48: (+) Net Debt & NCI | F48: =F38+Model!AQ328+Model!AQ424 -> 1636.9628 | G48: =G38+Model!AR328+Model!AR424 -> 1761.7942 | H48: =H38+Model!AS328+Model!AS424 -> 1890.0872 | N48: (+) Net Debt & NCI | R48: =R38+Model!AQ328+Model!AQ424 -> 2226.4375 | S48: =S38+Model!AR328+Model!AR424 -> 2482.9577 | T48: =T38+Model!AS328+Model!AS424 -> 2752.1917 | Z48: (+) Net Debt & NCI | AD48: =AD38+Model!AQ328+Model!AQ424 -> 1489.2878 | AE48: =AE38+Model!AR328+Model!AR424 -> 1369.0977 | AF48: =AF38+Model!AS328+Model!AS424 -> 1415.6225
B49: Implied Enterprise Value (USDm) | F49: =F47+F48 -> 1636.9628 | G49: =G47+G48 -> 9519.904 | H49: =H47+H48 -> 10293.148 | N49: Implied Enterprise Value (USDm) | R49: =R47+R48 -> 2226.4375 | S49: =S47+S48 -> 13051.469 | T49: =T47+T48 -> 14521.42 | Z49: Implied Enterprise Value (USDm) | AD49: =AD47+AD48 -> 6575.45 | AE49: =AE47+AE48 -> 6720.1661 | AF49: =AF47+AF48 -> 6991.9922
B50: Implied EV / Adjusted EBITDA (x) | F50: =IFERROR(F49/F35,"") -> 2.1368964 | G50: =IFERROR(G49/G35,"") -> 11.544853 | H50: =IFERROR(H49/H35,"") -> 11.635374 | N50: Implied EV / Adjusted EBITDA (x) | R50: =IFERROR(R49/R35,"") -> 2.6235749 | S50: =IFERROR(S49/S35,"") -> 13.765243 | T50: =IFERROR(T49/T35,"") -> 13.796341 | Z50: Implied EV / Adjusted EBITDA (x) | AD50: =IFERROR(AD49/AD35,"") -> 9.4470109 | AE50: =IFERROR(AE49/AE35,"") -> 9.3595128 | AF50: =IFERROR(AF49/AF35,"") -> 9.4499474

Sheet DCF
B2: DCF VALUATION — ESAB CORPORATION (ESAB)
B4: 1. WACC BUILD
B5: Risk-free rate (US 10Y govt) | C5: 0.055 | D5: Assumption (~US 10Y Treasury yield); update to market
B6: Equity risk premium | C6: 0.05 | D6: US implied ERP ~4.5–5.5% (Damodaran)
B7: Levered beta | C7: 1.2 | D7: Welding / fabrication peers (Lincoln Electric, ITW, Kennametal) ~1.0–1.2; higher financial leverage post-Eddyfi (~3x) and Europe / emerging-market exposure → 1.2
B8: Cost of equity | C8: =C5+C7*C6 -> 0.115
B9: Pre-tax cost of debt | C9: 0.058 | D9: BB-rated senior unsecured notes: 6.25% 2029, 5.625% 2031 (Mar-2026); TLA / revolver SOFR + 1.125–1.75%; marginal cost ~5.75–6.0%
B10: Tax rate | C10: 0.235 | D10: Model 2027E+ effective tax rate
B11: After-tax cost of debt | C11: =C9*(1-C10) -> 0.04437
B12: Target D/V | C12: 0.35 | D12: Net debt ~$2.1bn at YE2026E vs ~$4.3bn market cap ($69.94 × ~62m shares); target leverage < 3.0x YE26, ~2x medium term
B13: WACC | C13: =C8*(1-C12)+C11*C12 -> 0.0902795
B15: Valuation date (live) | C15: =TODAY() -> 2026-10-07 00:00:00 | D15: Periods = (Dec-31-Year − today) / 365.25; cash flows assumed at year-end
B16: 2. UNLEVERED FREE CASH FLOW BUILD (USDm)
D17: 2026E | E17: 2027E | F17: 2028E | G17: 2029E | H17: 2030E | I17: 2031E | J17: 2032E | K17: 2033E | L17: 2034E | M17: 2035E | N17: Terminal | P17: CAGR 26–30E | Q17: CAGR 26–35E
B18: Adj. EBITA less restructuring, transaction & integration costs (cash items) | D18: =Model!AO200-Model!AO142-Model!AO130 -> 472.59564 | E18: =Model!AP200-Model!AP142-Model!AP130 -> 614.68734 | F18: =Model!AQ200-Model!AQ142-Model!AQ130 -> 685.55307 | G18: =Model!AR200-Model!AR142-Model!AR130 -> 741.16022 | H18: =Model!AS200-Model!AS142-Model!AS130 -> 796.83441 | I18: =H18*(1+I$26) -> 844.64448 | J18: =I18*(1+J$26) -> 892.15573 | K18: =J18*(1+K$26) -> 938.9939 | L18: =K18*(1+L$26) -> 984.76986 | M18: =L18*(1+M$26) -> 1029.0845 | P18: =(H18/D18)^(1/(COLUMNS(D18:H18)-1))-1 -> 0.13951381 | Q18: =(M18/D18)^(1/(COLUMNS(D18:M18)-1))-1 -> 0.09031317
B19: × (1 − tax rate) | D19: =1-$C$10 -> 0.765 | E19: =1-$C$10 -> 0.765 | F19: =1-$C$10 -> 0.765 | G19: =1-$C$10 -> 0.765 | H19: =1-$C$10 -> 0.765 | I19: =1-$C$10 -> 0.765 | J19: =1-$C$10 -> 0.765 | K19: =1-$C$10 -> 0.765 | ... M19: =1-$C$10 -> 0.765
B20: NOPAT | D20: =D18*D19 -> 361.53567 | E20: =E18*E19 -> 470.23582 | F20: =F18*F19 -> 524.4481 | G20: =G18*G19 -> 566.98757 | H20: =H18*H19 -> 609.57832 | I20: =I18*I19 -> 646.15302 | J20: =J18*J19 -> 682.49913 | K20: =K18*K19 -> 718.33034 | ... M20: =M18*M19 -> 787.24964
B21: plus depreciation & other amortization | D21: =Model!AO127 -> 52.808356 | E21: =Model!AP127 -> 57.587654 | F21: =Model!AQ127 -> 60.493776 | G21: =Model!AR127 -> 64.441378 | H21: =Model!AS127 -> 68.808222 | I21: =H21*(1+I$26) -> 72.936715 | J21: =I21*(1+J$26) -> 77.039405 | K21: =J21*(1+K$26) -> 81.083974 | L21: =K21*(1+L$26) -> 85.036818 | M21: =L21*(1+M$26) -> 88.863475
B22: − Capex and acquisitions (M&A 2027E–30E) | D22: =Model!AO260 -> -70 | E22: =Model!AP260+Model!AP261 -> -75.279928 | F22: =Model!AQ260+Model!AQ261 -> -228.95558 | G22: =Model!AR260+Model!AR261 -> -283.7781 | H22: =Model!AS260+Model!AS261 -> -289.08386 | I22: =Model!AS260*(1+I$26) -> -94.428888 | J22: =I22*(1+J$26) -> -99.740513 | K22: =J22*(1+K$26) -> -104.97689 | L22: =K22*(1+L$26) -> -110.09451 | M22: =L22*(1+M$26) -> -115.04877
B23: − Δ Working capital (CF statement) | D23: =Model!AO258 -> -11.393119 | E23: =Model!AP258 -> -13.386644 | F23: =Model!AQ258 -> -12.969574 | G23: =Model!AR258 -> -19.406954 | H23: =Model!AS258 -> -21.995519 | I23: =H23*(1+I$26) -> -23.31525 | J23: =I23*(1+J$26) -> -24.626733 | K23: =J23*(1+K$26) -> -25.919636 | L23: =K23*(1+L$26) -> -27.183218 | M23: =L23*(1+M$26) -> -28.406463
B24: Unlevered FCF | D24: =D20+D21+D22+D23 -> 332.9509 | E24: =E20+E21+E22+E23 -> 439.1569 | F24: =F20+F21+F22+F23 -> 343.01672 | G24: =G20+G21+G22+G23 -> 328.2439 | H24: =H20+H21+H22+H23 -> 367.30717 | I24: =I20+I21+I22+I23 -> 601.3456 | J24: =J20+J21+J22+J23 -> 635.17129 | K24: =K20+K21+K22+K23 -> 668.51778 | ... M24: =M20+M21+M22+M23 -> 732.65789 | N24: =M24*(1+$C$27) -> 758.30091 | P24: =(H24/D24)^(1/(COLUMNS(D24:H24)-1))-1 -> 0.024854711 | Q24: =(M24/D24)^(1/(COLUMNS(D24:M24)-1))-1 -> 0.091585837
B25: Terminal Value (Gordon Growth) | N25: =N24/($C$13-$C$27) -> 13717.579
B26: Fade-period growth (2031E–35E; 6% → 4.5% linear) | I26: 0.06 | J26: =I26+($M$26-$I$26)/4 -> 0.05625 | K26: =J26+($M$26-$I$26)/4 -> 0.0525 | L26: =K26+($M$26-$I$26)/4 -> 0.04875 | M26: 0.045
B27: Terminal growth rate | C27: 0.035
B29: Discount period (years) | D29: =(DATE(2026,12,31)-$C$15)/365.25 -> 0.23271732 | E29: =(DATE(2027,12,31)-$C$15)/365.25 -> 1.2320329 | F29: =(DATE(2028,12,31)-$C$15)/365.25 -> 2.2340862 | G29: =(DATE(2029,12,31)-$C$15)/365.25 -> 3.2334018 | H29: =(DATE(2030,12,31)-$C$15)/365.25 -> 4.2327173 | I29: =(DATE(2031,12,31)-$C$15)/365.25 -> 5.2320329 | J29: =(DATE(2032,12,31)-$C$15)/365.25 -> 6.2340862 | K29: =(DATE(2033,12,31)-$C$15)/365.25 -> 7.2334018 | L29: =(DATE(2034,12,31)-$C$15)/365.25 -> 8.2327173 | M29: =(DATE(2035,12,31)-$C$15)/365.25 -> 9.2320329 | N29: =M29 -> 9.2320329
B30: Discount factor | D30: =1/(1+$C$13)^D29 -> 0.98008624 | E30: =1/(1+$C$13)^E29 -> 0.89898437 | F30: =1/(1+$C$13)^F29 -> 0.82439854 | G30: =1/(1+$C$13)^G29 -> 0.75617978 | H30: =1/(1+$C$13)^H29 -> 0.69360611 | I30: =1/(1+$C$13)^I29 -> 0.63621039 | J30: =1/(1+$C$13)^J29 -> 0.58342607 | K30: =1/(1+$C$13)^K29 -> 0.53514772 | ... N30: =1/(1+$C$13)^N29 -> 0.45024549
B31: PV of UFCF | D31: =D24*D30 -> 326.3206 | E31: =E24*E30 -> 394.79519 | F31: =F24*F30 -> 282.78248 | G31: =G24*G30 -> 248.2114 | H31: =H24*H30 -> 254.7665 | I31: =I24*I30 -> 382.58232 | J31: =J24*J30 -> 370.57549 | K31: =K24*K30 -> 357.75576 | ... M31: =M24*M30 -> 329.87591 | N31: =N25*N30 -> 6176.2781
D32: ESAB-specific: adjusted EBITA excludes amortization of acquired intangibles (Eddyfi PPA ~$58m p.a.) and the performance option awards; NOPAT is struck on adjusted EBITA less cash restructuring and integration costs (row 18). Eddyfi cash consideration (closed 1-Jun-2026) sits in YE2026E net debt, not in UFCF. Acquisition spend from the M&A lever is deducted in 2027E–30E. Asbestos liabilities of divested Colfax businesses (net of insurance, ~$55m) are deducted as a debt-like item; MCPS conversion shares are included in the diluted share count.
B33: IMPLIED ROIC — invested capital roll-forward (USDm)
B34: Opening invested capital | D34: =Model!AJ394+Model!AO352 -> 4754.618 | E34: =D38 -> 4783.2028 | F34: =E38 -> 4814.2817 | G34: =F38 -> 4995.7131 | H34: =G38 -> 5234.4567 | I34: =H38 -> 5476.7279 | J34: =I38 -> 5521.5353 | K34: =J38 -> 5568.8632 | L34: =K38 -> 5618.6757 | M34: =L38 -> 5670.9166
B35: plus Capex and acquisitions | D35: =-D22 -> 70 | E35: =-E22 -> 75.279928 | F35: =-F22 -> 228.95558 | G35: =-G22 -> 283.7781 | H35: =-H22 -> 289.08386 | I35: =-I22 -> 94.428888 | J35: =-J22 -> 99.740513 | K35: =-K22 -> 104.97689 | ... M35: =-M22 -> 115.04877
B36: less DD&A | D36: =-D21 -> -52.808356 | E36: =-E21 -> -57.587654 | F36: =-F21 -> -60.493776 | G36: =-G21 -> -64.441378 | H36: =-H21 -> -68.808222 | I36: =-I21 -> -72.936715 | J36: =-J21 -> -77.039405 | K36: =-K21 -> -81.083974 | ... M36: =-M21 -> -88.863475
B37: plus Δ Working capital investment | D37: =-D23 -> 11.393119 | E37: =-E23 -> 13.386644 | F37: =-F23 -> 12.969574 | G37: =-G23 -> 19.406954 | H37: =-H23 -> 21.995519 | I37: =-I23 -> 23.31525 | J37: =-J23 -> 24.626733 | K37: =-K23 -> 25.919636 | ... M37: =-M23 -> 28.406463
B38: Closing invested capital | D38: =SUM(D34:D37) -> 4783.2028 | E38: =SUM(E34:E37) -> 4814.2817 | F38: =SUM(F34:F37) -> 4995.7131 | G38: =SUM(G34:G37) -> 5234.4567 | H38: =SUM(H34:H37) -> 5476.7279 | I38: =SUM(I34:I37) -> 5521.5353 | J38: =SUM(J34:J37) -> 5568.8632 | K38: =SUM(K34:K37) -> 5618.6757 | ... M38: =SUM(M34:M37) -> 5725.5084
B39: NOPAT (row 20) | D39: =D20 -> 361.53567 | E39: =E20 -> 470.23582 | F39: =F20 -> 524.4481 | G39: =G20 -> 566.98757 | H39: =H20 -> 609.57832 | I39: =I20 -> 646.15302 | J39: =J20 -> 682.49913 | K39: =K20 -> 718.33034 | ... M39: =M20 -> 787.24964
B40: Implied ROIC (NOPAT / avg. invested capital) | D40: =IFERROR(D39/AVERAGE(D34,D38),"") -> 0.075810959 | E40: =IFERROR(E39/AVERAGE(E34,E38),"") -> 0.097991473 | F40: =IFERROR(F39/AVERAGE(F34,F38),"") -> 0.10692118 | G40: =IFERROR(G39/AVERAGE(G34,G38),"") -> 0.11084617 | H40: =IFERROR(H39/AVERAGE(H34,H38),"") -> 0.1138209 | I40: =IFERROR(I39/AVERAGE(I34,I38),"") -> 0.11750092 | J40: =IFERROR(J39/AVERAGE(J34,J38),"") -> 0.12307928 | K40: =IFERROR(K39/AVERAGE(K34,K38),"") -> 0.12841615 | ... M40: =IFERROR(M39/AVERAGE(M34,M38),"") -> 0.1381573
B41: Reinvestment rate (net investment / NOPAT) | D41: =IFERROR(SUM(D35:D37)/D39,"") -> 0.079064849 | E41: =IFERROR(SUM(E35:E37)/E39,"") -> 0.066092198 | F41: =IFERROR(SUM(F35:F37)/F39,"") -> 0.34594726 | G41: =IFERROR(SUM(G35:G37)/G39,"") -> 0.42107391 | H41: =IFERROR(SUM(H35:H37)/H39,"") -> 0.39744057 | I41: =IFERROR(SUM(I35:I37)/I39,"") -> 0.06934491 | J41: =IFERROR(SUM(J35:J37)/J39,"") -> 0.06934491 | K41: =IFERROR(SUM(K35:K37)/K39,"") -> 0.06934491 | ... M41: =IFERROR(SUM(M35:M37)/M39,"") -> 0.06934491
B42: Implied terminal RONIC (g / reinvestment rate) | N42: =IFERROR($C$27/M41,"") -> 0.50472342
D43: Opening IC = Model 2025A book invested capital (equity + net debt) + Eddyfi consideration ($1.49bn), rolled forward with capex + M&A − D&A + ΔWC.
B44: 3. VALUATION SUMMARY
...

Sheet Charts
B2: ESAB — Historical Operating Performance (2012–2025; 2012–2018 = Colfax "Fabrication Technology" segment)
B3: USDm · Linked to Model. 2012–2018: pre-spin Colfax segment data (organic / acquisitions / FX and segment operating income); 2019–2025: ESAB carve-out / stand-alone reporting (adjusted EBITDA per company reconciliations). Not strictly comparable across the two bases.
C7: 2012 | D7: 2013 | E7: 2014 | F7: 2015 | G7: 2016 | H7: 2017 | I7: 2018 | J7: 2019 | K7: 2020 | L7: 2021 | M7: 2022 | N7: 2023 | O7: 2024 | P7: 2025
B8: Organic growth % | C8: =IFERROR(Model!C234+0,IFERROR(Model!C65+0,0)) -> 0 | D8: =IFERROR(Model!D234+0,IFERROR(Model!D65+0,0)) -> 0 | E8: =IFERROR(Model!E234+0,IFERROR(Model!E65+0,0)) -> 0 | F8: =IFERROR(Model!F234+0,IFERROR(Model!F65+0,0)) -> 0 | G8: =IFERROR(Model!G234+0,IFERROR(Model!G65+0,0)) -> 0 | H8: =IFERROR(Model!H234+0,IFERROR(Model!H65+0,0)) -> 0 | I8: =IFERROR(Model!I234+0,IFERROR(Model!I65+0,0)) -> 0 | J8: =IFERROR(Model!J234+0,IFERROR(Model!J65+0,0)) -> 0 | K8: =IFERROR(Model!K234+0,IFERROR(Model!K65+0,0)) -> -0.097 | L8: =IFERROR(Model!P234+0,IFERROR(Model!P65+0,0)) -> 0.234 | M8: =IFERROR(Model!U234+0,IFERROR(Model!U65+0,0)) -> 0.105 | N8: =IFERROR(Model!Z234+0,IFERROR(Model!Z65+0,0)) -> 0.062 | O8: =IFERROR(Model!AE234+0,IFERROR(Model!AE65+0,0)) -> 0.012 | P8: =IFERROR(Model!AJ234+0,IFERROR(Model!AJ65+0,0)) -> -0.011
B9: Acquisitions % | C9: =IFERROR(Model!C236+0,IFERROR(Model!C66+0,0)) -> 0 | D9: =IFERROR(Model!D236+0,IFERROR(Model!D66+0,0)) -> 0 | E9: =IFERROR(Model!E236+0,IFERROR(Model!E66+0,0)) -> 0 | F9: =IFERROR(Model!F236+0,IFERROR(Model!F66+0,0)) -> 0 | G9: =IFERROR(Model!G236+0,IFERROR(Model!G66+0,0)) -> 0 | H9: =IFERROR(Model!H236+0,IFERROR(Model!H66+0,0)) -> 0 | I9: =IFERROR(Model!I236+0,IFERROR(Model!I66+0,0)) -> 0 | J9: =IFERROR(Model!J236+0,IFERROR(Model!J66+0,0)) -> 0 | K9: =IFERROR(Model!K236+0,IFERROR(Model!K66+0,0)) -> 0 | L9: =IFERROR(Model!P236+0,IFERROR(Model!P66+0,0)) -> 0.001 | M9: =IFERROR(Model!U236+0,IFERROR(Model!U66+0,0)) -> 0.006 | N9: =IFERROR(Model!Z236+0,IFERROR(Model!Z66+0,0)) -> 0.025 | O9: =IFERROR(Model!AE236+0,IFERROR(Model!AE66+0,0)) -> 0.008 | P9: =IFERROR(Model!AJ236+0,IFERROR(Model!AJ66+0,0)) -> 0.042
B10: Foreign currency % | C10: =IFERROR(Model!C237+0,IFERROR(Model!C67+0,0)) -> 0 | D10: =IFERROR(Model!D237+0,IFERROR(Model!D67+0,0)) -> 0 | E10: =IFERROR(Model!E237+0,IFERROR(Model!E67+0,0)) -> 0 | F10: =IFERROR(Model!F237+0,IFERROR(Model!F67+0,0)) -> 0 | G10: =IFERROR(Model!G237+0,IFERROR(Model!G67+0,0)) -> 0 | H10: =IFERROR(Model!H237+0,IFERROR(Model!H67+0,0)) -> 0 | I10: =IFERROR(Model!I237+0,IFERROR(Model!I67+0,0)) -> 0 | J10: =IFERROR(Model!J237+0,IFERROR(Model!J67+0,0)) -> 0 | K10: =IFERROR(Model!K237+0,IFERROR(Model!K67+0,0)) -> -0.035 | L10: =IFERROR(Model!P237+0,IFERROR(Model!P67+0,0)) -> 0.01 | M10: =IFERROR(Model!U237+0,IFERROR(Model!U67+0,0)) -> -0.042 | N10: =IFERROR(Model!Z237+0,IFERROR(Model!Z67+0,0)) -> -0.017 | O10: =IFERROR(Model!AE237+0,IFERROR(Model!AE67+0,0)) -> -0.032 | P10: =IFERROR(Model!AJ237+0,IFERROR(Model!AJ67+0,0)) -> 0.006
C11: =C7 -> 2012 | D11: =D7 -> 2013 | E11: =E7 -> 2014 | F11: =F7 -> 2015 | G11: =G7 -> 2016 | H11: =H7 -> 2017 | I11: =I7 -> 2018 | J11: =J7 -> 2019 | ... P11: =P7 -> 2025
B12: Adjusted EBITDA (ESAB, 2019+) | C12: =IFERROR(Model!C189+0,NA()) -> 0 | D12: =IFERROR(Model!D189+0,NA()) -> 0 | E12: =IFERROR(Model!E189+0,NA()) -> 0 | F12: =IFERROR(Model!F189+0,NA()) -> 0 | G12: =IFERROR(Model!G189+0,NA()) -> 0 | H12: =IFERROR(Model!H189+0,NA()) -> 0 | I12: =IFERROR(Model!I189+0,NA()) -> 0 | J12: =IFERROR(Model!J189+0,NA()) -> 353.663 | K12: =IFERROR(Model!K189+0,NA()) -> 301.146 | L12: =IFERROR(Model!P189+0,NA()) -> 404.168 | M12: =IFERROR(Model!U189+0,NA()) -> 436.761 | N12: =IFERROR(Model!Z189+0,NA()) -> 501.176 | O12: =IFERROR(Model!AE189+0,NA()) -> 528.777 | P12: =IFERROR(Model!AJ189+0,NA()) -> 559.726
B13: Operating income (GAAP, 2019+) | C13: =IFERROR(Model!C144+0,NA()) -> 0 | D13: =IFERROR(Model!D144+0,NA()) -> 0 | E13: =IFERROR(Model!E144+0,NA()) -> 0 | F13: =IFERROR(Model!F144+0,NA()) -> 0 | G13: =IFERROR(Model!G144+0,NA()) -> 0 | H13: =IFERROR(Model!H144+0,NA()) -> 0 | I13: =IFERROR(Model!I144+0,NA()) -> 0 | J13: =IFERROR(Model!J144+0,NA()) -> 256.08 | K13: =IFERROR(Model!K144+0,NA()) -> 202.126 | L13: =IFERROR(Model!P144+0,NA()) -> 306.214 | M13: =IFERROR(Model!U144+0,NA()) -> 329.065 | N13: =IFERROR(Model!Z144+0,NA()) -> 404.166 | O13: =IFERROR(Model!AE144+0,NA()) -> 447.45 | P13: =IFERROR(Model!AJ144+0,NA()) -> 412.17
