Workbook

Sheet Model
CG1: SCENARIO SWITCH ▼ (Bull / Base / Bear) — drives all scenario-linked forecast drivers
B2: Fair Isaac Corporation (NYSE: FICO) — 3-Statement Financial Model | CG2: Base
B3: US GAAP as reported · USD millions (per-share data in USD; shares in millions) · Fiscal years ended 30 September (2026 = Oct-2025 – Sep-2026) · Source: Fair Isaac Forms 10-K / 10-Q, Form 8-K earnings releases (Ex. 99.1) and financing / restructuring 8-Ks, SEC EDGAR (CIK 814547); XBRL company facts; investor-relations releases at fico.com are the same documents as filed on EDGAR
B4: Basis notes: as originally reported. Segments: Strategy Machine Solutions / Scoring Solutions / Professional Services / Analytic Software Tools (FY2006–09), Applications / Scores / Tools (FY2010–15), Applications / Scores / DMS (FY2016–Q3/21), Scores / Software (FY2021 10-K on). Disc ops FY2007–09. Non-GAAP published from Q1 FY13. Q4/26E calibrated to FY26 revenue and non-GAAP EPS guidance (29-Jul-2026) plus the Oct-2026 restructuring; $1.5bn ASR (Jun-2026) settles in Q4 FY26.
CI5: Forecast | CJ5: Historical | CK5: Historical | CL5: Historical
B6: (USDm) | C6: 2006 | D6: 2007 | E6: 2008 | F6: 2009 | G6: 2010 | H6: 2011 | I6: 2012 | J6: Q1/13 | K6: Q2/13 | L6: Q3/13 | M6: Q4/13 | N6: 2013 | O6: Q1/14 | P6: Q2/14 | Q6: Q3/14 | R6: Q4/14 | S6: 2014 | T6: Q1/15 | U6: Q2/15 | V6: Q3/15 | W6: Q4/15 | X6: 2015 | Y6: Q1/16 | Z6: Q2/16 | AA6: Q3/16 | AB6: Q4/16 | AC6: 2016 | AD6: Q1/17 | AE6: Q2/17 | AF6: Q3/17 | AG6: Q4/17 | AH6: 2017 | AI6: Q1/18 | AJ6: Q2/18 | AK6: Q3/18 | AL6: Q4/18 | AM6: 2018 | AN6: Q1/19 | AO6: Q2/19 | AP6: Q3/19 | AQ6: Q4/19 | AR6: 2019 | AS6: Q1/20 | AT6: Q2/20 | AU6: Q3/20 | AV6: Q4/20 | AW6: 2020 | AX6: Q1/21 | AY6: Q2/21 | AZ6: Q3/21 | BA6: Q4/21 | BB6: 2021 | BC6: Q1/22 | BD6: Q2/22 | BE6: Q3/22 | BF6: Q4/22 | BG6: 2022 | BH6: Q1/23 | BI6: Q2/23 | BJ6: Q3/23 | BK6: Q4/23 | BL6: 2023 | BM6: Q1/24 | BN6: Q2/24 | BO6: Q3/24 | BP6: Q4/24 | BQ6: 2024 | BR6: Q1/25 | BS6: Q2/25 | BT6: Q3/25 | BU6: Q4/25 | BV6: 2025 | BW6: Q1/26 | BX6: Q2/26 | BY6: Q3/26 | BZ6: Q4/26E | CA6: 2026E | CB6: 2027E | CC6: 2028E | CD6: 2029E | CE6: 2030E | CF6: 2031E | CG6: Modelling Notes | CI6: 5Y CAGR | CJ6: 5Y CAGR | CK6: 10Y CAGR | CL6: 19Y CAGR
CI7: 26-'31 | CJ7: 20-'25 | CK7: 15-'25 | CL7: 06-'25
B8: SEGMENT P&L — SCORES · SOFTWARE (revenue streams × segment operating margin) | CG8: SEGMENT BUILD — modelling logic (revenue streams → segment revenue → segment operating income at the segment margin → + unallocated corporate expenses = non-GAAP operating income → GAAP P&L)
CO9: SCENARIO INPUT TABLE — driver assumptions per Bull / Base / Bear | CP9: Bull | CQ9: Base | CR9: Bear | CS9: Bull / Bear = Base + Δ (Δ inputs on each block header). Outlook block = FY26 guidance (point guidance: high = mid = low).
B10: Scores (B2B and B2C scoring; "Scoring Solutions" product-line segment in FY2006–09) | CG10: SCORES — modelling logic
B11: B2B scores (FICO Scores sold to lenders through the credit bureaus; mortgage, auto, card, personal loans) | AR11: 302.103 | AW11: 381.929 | AX11: 100.144 | AY11: 119.319 | AZ11: 115.862 | BA11: 111.213 | BB11: 446.538 | BC11: 112.968 | BD11: 125.243 | BE11: 119.01 | BF11: 118.221 | BG11: 475.442 | BH11: 124.905 | BI11: 144.874 | BJ11: 148.128 | BK11: 143.088 | BL11: 560.995 | BM11: 140.442 | BN11: 185.508 | BO11: 188.754 | BP11: 197.139 | BQ11: 711.843 | BR11: 182.391 | BS11: 242.494 | BT11: 268.479 | BU11: 255.231 | BV11: 948.595 | BW11: 248.613 | BX11: 417.629 | BY11: 400.043 | BZ11: =BU11*(1+BZ12) -> 384.14405 | CA11: =SUM(BW11:BZ11) -> 1450.4291 | CB11: =CA11*(1+CB12) -> 1667.9934 | CC11: =CB11*(1+CC12) -> 1868.1526 | CD11: =CC11*(1+CD12) -> 2054.9679 | CE11: =CD11*(1+CE12) -> 2239.915 | CF11: =CE11*(1+CF12) -> 2419.1082 | CG11: Revenue streams from the 10-Q / 10-K MD&A tables (first published in the FY2021 10-K: FY2019–21 annual; FY2021 quarters from the FY2022 10-Q comparatives; Q4 = fiscal year − nine months). Q4/26E: prior-year quarter × (1 + growth). 2027E+: prior year × (1 + scenario lever). | CI11: =IFERROR((CF11/CA11)^(1/5)-1,"n/m") -> 0.1077245 | CJ11: =IFERROR((BV11/AW11)^(1/5)-1,"n/m") -> 0.19955355 | CK11: =IFERROR((BV11/X11)^(1/10)-1,"n/m") -> n/m | CL11: =IFERROR((BV11/C11)^(1/19)-1,"n/m") -> n/m | CO11: FY26 guidance — Q3 FY26 release (29-Jul-2026; point guidance) | CP11: High | CQ11: Mid | CR11: Low | CS11: Revenue $2.53bn (raised from $2.45bn), GAAP net income $850m / EPS $36.86, non-GAAP net income $979m / EPS $42.43 (raised from $40.45); reconciliation: SBC $188m, income tax adjustments −$46m, excess tax benefit −$13m. No segment, margin, tax, interest or cash-flow guidance. Point guidance, so high = mid = low.
B12: y/y % | D12: =IF(AND(ISNUMBER(D11),ISNUMBER(C11)),IFERROR(D11/C11-1,""),"") | E12: =IF(AND(ISNUMBER(E11),ISNUMBER(D11)),IFERROR(E11/D11-1,""),"") | F12: =IF(AND(ISNUMBER(F11),ISNUMBER(E11)),IFERROR(F11/E11-1,""),"") | G12: =IF(AND(ISNUMBER(G11),ISNUMBER(F11)),IFERROR(G11/F11-1,""),"") | H12: =IF(AND(ISNUMBER(H11),ISNUMBER(G11)),IFERROR(H11/G11-1,""),"") | I12: =IF(AND(ISNUMBER(I11),ISNUMBER(H11)),IFERROR(I11/H11-1,""),"") | N12: =IF(AND(ISNUMBER(N11),ISNUMBER(I11)),IFERROR(N11/I11-1,""),"") | O12: =IF(AND(ISNUMBER(O11),ISNUMBER(J11)),IFERROR(O11/J11-1,""),"") | P12: =IF(AND(ISNUMBER(P11),ISNUMBER(K11)),IFERROR(P11/K11-1,""),"") | Q12: =IF(AND(ISNUMBER(Q11),ISNUMBER(L11)),IFERROR(Q11/L11-1,""),"") | R12: =IF(AND(ISNUMBER(R11),ISNUMBER(M11)),IFERROR(R11/M11-1,""),"") | S12: =IF(AND(ISNUMBER(S11),ISNUMBER(N11)),IFERROR(S11/N11-1,""),"") | T12: =IF(AND(ISNUMBER(T11),ISNUMBER(O11)),IFERROR(T11/O11-1,""),"") | U12: =IF(AND(ISNUMBER(U11),ISNUMBER(P11)),IFERROR(U11/P11-1,""),"") | ... BY12: =IF(AND(ISNUMBER(BY11),ISNUMBER(BT11)),IFERROR(BY11/BT11-1,""),"") -> 0.4900346 | BZ12: =BZ13+$BZ$97 -> 0.50508383 | CA12: =IF(AND(ISNUMBER(CA11),ISNUMBER(BV11)),IFERROR(CA11/BV11-1,""),"") -> 0.52902878 | CB12: =CHOOSE(MATCH($CG$2,{"Bull","Base","Bear"},0),$CP$33,$CQ$33,$CR$33) -> 0.15 | CC12: =CHOOSE(MATCH($CG$2,{"Bull","Base","Bear"},0),$CP$34,$CQ$34,$CR$34) -> 0.12 | CD12: =CHOOSE(MATCH($CG$2,{"Bull","Base","Bear"},0),$CP$35,$CQ$35,$CR$35) -> 0.1 | CE12: =CHOOSE(MATCH($CG$2,{"Bull","Base","Bear"},0),$CP$36,$CQ$36,$CR$36) -> 0.09 | CF12: =CHOOSE(MATCH($CG$2,{"Bull","Base","Bear"},0),$CP$37,$CQ$37,$CR$37) -> 0.08 | CG12: Q4/26E: 9M FY26 y/y growth of the stream + revenue-guidance calibration Δ (Group block). 2027E–2031E: scenario lever (Bull/Base/Bear table →). | CO12: FY26 revenue ($m) | CP12: 2530 | CQ12: 2530 | CR12: 2530 | CS12: Guided $2.53bn. Drives the Q4/26E revenue calibration.
B13: Q4/26E growth before revenue calibration (9M FY26 y/y) | BZ13: =IFERROR(SUM(BW11:BY11)/SUM(BR11:BT11)-1,0) -> 0.53784304 | CO13: FY26 non-GAAP EPS ($) | CP13: 42.43 | CQ13: 42.43 | CR13: 42.43 | CS13: Guided $42.43. Drives the Q4/26E segment-margin calibration.
B14: B2C scores (myFICO.com subscriptions; royalties on scores sold to consumers through the bureaus) | AR14: 119.074 | AW14: 146.618 | AX14: 44.507 | AY14: 49.4 | AZ14: 56.34 | BA14: 57.362 | BB14: 207.609 | BC14: 56.519 | BD14: 58.499 | BE14: 60.345 | BF14: 55.838 | BG14: 231.201 | BH14: 53.083 | BI14: 53.633 | BJ14: 53.65 | BK14: 52.467 | BL14: 212.833 | BM14: 51.67 | BN14: 51.377 | BO14: 52.696 | BP14: 52.064 | BQ14: 207.807 | BR14: 53.284 | BS14: 54.545 | BT14: 55.83 | BU14: 56.321 | BV14: 219.98 | BW14: 55.921 | BX14: 57.344 | BY14: 58.854 | BZ14: =BU14*(1+BZ15) -> 57.387362 | CA14: =SUM(BW14:BZ14) -> 229.50636 | CB14: =CA14*(1+CB15) -> 238.68662 | CC14: =CB14*(1+CC15) -> 248.23408 | CD14: =CC14*(1+CD15) -> 258.16344 | CE14: =CD14*(1+CE15) -> 265.90835 | CF14: =CE14*(1+CF15) -> 273.8856 | CI14: =IFERROR((CF14/CA14)^(1/5)-1,"n/m") -> 0.035988402 | CJ14: =IFERROR((BV14/AW14)^(1/5)-1,"n/m") -> 0.084524035 | CK14: =IFERROR((BV14/X14)^(1/10)-1,"n/m") -> n/m | CL14: =IFERROR((BV14/C14)^(1/19)-1,"n/m") -> n/m | CO14: FY26 GAAP net income ($m) — memo | CP14: 850 | CQ14: 850 | CR14: 850 | CS14: Guided $850m (information row; excludes the $27m Q4 restructuring announced 6-Oct-2026).
B15: y/y % | D15: =IF(AND(ISNUMBER(D14),ISNUMBER(C14)),IFERROR(D14/C14-1,""),"") | E15: =IF(AND(ISNUMBER(E14),ISNUMBER(D14)),IFERROR(E14/D14-1,""),"") | F15: =IF(AND(ISNUMBER(F14),ISNUMBER(E14)),IFERROR(F14/E14-1,""),"") | G15: =IF(AND(ISNUMBER(G14),ISNUMBER(F14)),IFERROR(G14/F14-1,""),"") | H15: =IF(AND(ISNUMBER(H14),ISNUMBER(G14)),IFERROR(H14/G14-1,""),"") | I15: =IF(AND(ISNUMBER(I14),ISNUMBER(H14)),IFERROR(I14/H14-1,""),"") | N15: =IF(AND(ISNUMBER(N14),ISNUMBER(I14)),IFERROR(N14/I14-1,""),"") | O15: =IF(AND(ISNUMBER(O14),ISNUMBER(J14)),IFERROR(O14/J14-1,""),"") | P15: =IF(AND(ISNUMBER(P14),ISNUMBER(K14)),IFERROR(P14/K14-1,""),"") | Q15: =IF(AND(ISNUMBER(Q14),ISNUMBER(L14)),IFERROR(Q14/L14-1,""),"") | R15: =IF(AND(ISNUMBER(R14),ISNUMBER(M14)),IFERROR(R14/M14-1,""),"") | S15: =IF(AND(ISNUMBER(S14),ISNUMBER(N14)),IFERROR(S14/N14-1,""),"") | T15: =IF(AND(ISNUMBER(T14),ISNUMBER(O14)),IFERROR(T14/O14-1,""),"") | U15: =IF(AND(ISNUMBER(U14),ISNUMBER(P14)),IFERROR(U14/P14-1,""),"") | ... BY15: =IF(AND(ISNUMBER(BY14),ISNUMBER(BT14)),IFERROR(BY14/BT14-1,""),"") -> 0.054164428 | BZ15: =BZ16+$BZ$97 -> 0.018933643 | CA15: =IF(AND(ISNUMBER(CA14),ISNUMBER(BV14)),IFERROR(CA14/BV14-1,""),"") -> 0.043305581 | CB15: =CHOOSE(MATCH($CG$2,{"Bull","Base","Bear"},0),$CP$39,$CQ$39,$CR$39) -> 0.04 | CC15: =CHOOSE(MATCH($CG$2,{"Bull","Base","Bear"},0),$CP$40,$CQ$40,$CR$40) -> 0.04 | CD15: =CHOOSE(MATCH($CG$2,{"Bull","Base","Bear"},0),$CP$41,$CQ$41,$CR$41) -> 0.04 | CE15: =CHOOSE(MATCH($CG$2,{"Bull","Base","Bear"},0),$CP$42,$CQ$42,$CR$42) -> 0.03 | CF15: =CHOOSE(MATCH($CG$2,{"Bull","Base","Bear"},0),$CP$43,$CQ$43,$CR$43) -> 0.03 | CO15: FY26 GAAP EPS ($) — memo | CP15: 36.86 | CQ15: 36.86 | CR15: 36.86 | CS15: Guided $36.86 (information row).
B16: Q4/26E growth before revenue calibration (9M FY26 y/y) | BZ16: =IFERROR(SUM(BW14:BY14)/SUM(BR14:BT14)-1,0) -> 0.051692849 | CO16: Q4/26E share repurchases ($m; cash) | CP16: 500 | CQ16: 300 | CR16: 100 | CS16: Assumption. $800m left on the June 2026 program at 30-Jun-2026, of which $300m is the ASR prepayment (settles in Q4 with no further cash) → $500m available; 9M FY26 $3,046m.
B17: Scores — segment revenue | C17: =IF(AND(ISNUMBER(C11),ISNUMBER(C14)),C11+C14,C21) -> 177.152 | D17: =IF(AND(ISNUMBER(D11),ISNUMBER(D14)),D11+D14,D21) -> 180.444 | E17: =IF(AND(ISNUMBER(E11),ISNUMBER(E14)),E11+E14,E21) -> 156.816 | F17: =IF(AND(ISNUMBER(F11),ISNUMBER(F14)),F11+F14,F21) -> 131.621 | G17: =IF(AND(ISNUMBER(G11),ISNUMBER(G14)),G11+G14,G21) -> 172.339 | H17: =IF(AND(ISNUMBER(H11),ISNUMBER(H14)),H11+H14,H21) -> 168.567 | I17: =IF(AND(ISNUMBER(I11),ISNUMBER(I14)),I11+I14,I21) -> 175.623 | J17: =IF(AND(ISNUMBER(J11),ISNUMBER(J14)),J11+J14,J21) -> 43.447 | ... BY17: =IF(AND(ISNUMBER(BY11),ISNUMBER(BY14)),BY11+BY14,BY21) -> 458.897 | BZ17: =BZ11+BZ14 -> 441.53141 | CA17: =CA11+CA14 -> 1679.9354 | CB17: =CB11+CB14 -> 1906.68 | CC17: =CC11+CC14 -> 2116.3867 | CD17: =CD11+CD14 -> 2313.1313 | CE17: =CE11+CE14 -> 2505.8233 | CF17: =CF11+CF14 -> 2692.9938 | CG17: History: Σ revenue streams where all are published, otherwise segment revenue as reported. | CI17: =IFERROR((CF17/CA17)^(1/5)-1,"n/m") -> 0.098976873 | CJ17: =IFERROR((BV17/AW17)^(1/5)-1,"n/m") -> 0.17196488 | CK17: =IFERROR((BV17/X17)^(1/10)-1,"n/m") -> 0.18895976 | CL17: =IFERROR((BV17/C17)^(1/19)-1,"n/m") -> 0.10438782
B18: Segment revenue y/y % | D18: =IF(AND(ISNUMBER(D17),ISNUMBER(C17)),IFERROR(D17/C17-1,""),"") -> 0.018582912 | E18: =IF(AND(ISNUMBER(E17),ISNUMBER(D17)),IFERROR(E17/D17-1,""),"") -> -0.13094367 | F18: =IF(AND(ISNUMBER(F17),ISNUMBER(E17)),IFERROR(F17/E17-1,""),"") -> -0.160666 | G18: =IF(AND(ISNUMBER(G17),ISNUMBER(F17)),IFERROR(G17/F17-1,""),"") -> 0.30935793 | H18: =IF(AND(ISNUMBER(H17),ISNUMBER(G17)),IFERROR(H17/G17-1,""),"") -> -0.021887095 | I18: =IF(AND(ISNUMBER(I17),ISNUMBER(H17)),IFERROR(I17/H17-1,""),"") -> 0.041858727 | N18: =IF(AND(ISNUMBER(N17),ISNUMBER(I17)),IFERROR(N17/I17-1,""),"") -> 0.029551938 | O18: =IF(AND(ISNUMBER(O17),ISNUMBER(J17)),IFERROR(O17/J17-1,""),"") -> 0.085920777 | P18: =IF(AND(ISNUMBER(P17),ISNUMBER(K17)),IFERROR(P17/K17-1,""),"") -> 0.086151332 | Q18: =IF(AND(ISNUMBER(Q17),ISNUMBER(L17)),IFERROR(Q17/L17-1,""),"") -> -0.038640991 | R18: =IF(AND(ISNUMBER(R17),ISNUMBER(M17)),IFERROR(R17/M17-1,""),"") -> -0.0011050442 | S18: =IF(AND(ISNUMBER(S17),ISNUMBER(N17)),IFERROR(S17/N17-1,""),"") -> 0.031280937 | T18: =IF(AND(ISNUMBER(T17),ISNUMBER(O17)),IFERROR(T17/O17-1,""),"") -> -0.068651971 | U18: =IF(AND(ISNUMBER(U17),ISNUMBER(P17)),IFERROR(U17/P17-1,""),"") -> 0.043441013 | ... CA18: =IF(AND(ISNUMBER(CA17),ISNUMBER(BV17)),IFERROR(CA17/BV17-1,""),"") -> 0.43759315 | CB18: =IF(AND(ISNUMBER(CB17),ISNUMBER(CA17)),IFERROR(CB17/CA17-1,""),"") -> 0.13497222 | CC18: =IF(AND(ISNUMBER(CC17),ISNUMBER(CB17)),IFERROR(CC17/CB17-1,""),"") -> 0.10998525 | CD18: =IF(AND(ISNUMBER(CD17),ISNUMBER(CC17)),IFERROR(CD17/CC17-1,""),"") -> 0.092962513 | CE18: =IF(AND(ISNUMBER(CE17),ISNUMBER(CD17)),IFERROR(CE17/CD17-1,""),"") -> 0.083303533 | CF18: =IF(AND(ISNUMBER(CF17),ISNUMBER(CE17)),IFERROR(CF17/CE17-1,""),"") -> 0.074694192 | CO18: Q4/26E and FY26 point estimates (all cases)
B19: % of total revenue | C19: =IF(AND(ISNUMBER(C17),ISNUMBER(C87)),IFERROR(C17/C87,""),"") -> 0.21463474 | D19: =IF(AND(ISNUMBER(D17),ISNUMBER(D87)),IFERROR(D17/D87,""),"") -> 0.21945524 | E19: =IF(AND(ISNUMBER(E17),ISNUMBER(E87)),IFERROR(E17/E87,""),"") -> 0.21053593 | F19: =IF(AND(ISNUMBER(F17),ISNUMBER(F87)),IFERROR(F17/F87,""),"") -> 0.20867876 | G19: =IF(AND(ISNUMBER(G17),ISNUMBER(G87)),IFERROR(G17/G87,""),"") -> 0.28455542 | H19: =IF(AND(ISNUMBER(H17),ISNUMBER(H87)),IFERROR(H17/H87,""),"") -> 0.27202134 | I19: =IF(AND(ISNUMBER(I17),ISNUMBER(I87)),IFERROR(I17/I87,""),"") -> 0.25963487 | J19: =IF(AND(ISNUMBER(J17),ISNUMBER(J87)),IFERROR(J17/J87,""),"") -> 0.22864435 | ... CF19: =IF(AND(ISNUMBER(CF17),ISNUMBER(CF87)),IFERROR(CF17/CF87,""),"") -> 0.67723396 | CI19: =IFERROR(AVERAGE(CB19,CC19,CD19,CE19,CF19),"n/m") -> 0.68192686 | CJ19: =IFERROR(AVERAGE(BB19,BG19,BL19,BQ19,BV19),"n/m") -> 0.52872544 | CK19: =IFERROR(AVERAGE(AC19,AH19,AM19,AR19,AW19,BB19,BG19,BL19,BQ19,BV19),"n/m") -> 0.43060828 | CL19: =IFERROR(AVERAGE(C19,D19,E19,F19,G19,H19,I19,N19,S19,X19,AC19,AH19,AM19,AR19,AW19,BB19,BG19,BL19,BQ19,BV19),"n/m") -> 0.33509722 | CO19: Q4/26E interest expense, net ($m) | CQ19: 78 | CS19: Not guided. Full quarter on ~$5.6bn debt: notes $3.4bn at ~5.5%, term loan $1.5bn at 5.86%, revolver ~$0.7bn at 5.64% (Q3 $59.9m incl. 25 days of the term loan).
B20: B2B % of Scores revenue | C20: =IF(ISNUMBER(C11),IFERROR(C11/C17,""),"") | D20: =IF(ISNUMBER(D11),IFERROR(D11/D17,""),"") | E20: =IF(ISNUMBER(E11),IFERROR(E11/E17,""),"") | F20: =IF(ISNUMBER(F11),IFERROR(F11/F17,""),"") | G20: =IF(ISNUMBER(G11),IFERROR(G11/G17,""),"") | H20: =IF(ISNUMBER(H11),IFERROR(H11/H17,""),"") | I20: =IF(ISNUMBER(I11),IFERROR(I11/I17,""),"") | J20: =IF(ISNUMBER(J11),IFERROR(J11/J17,""),"") | ... CF20: =IF(ISNUMBER(CF11),IFERROR(CF11/CF17,""),"") -> 0.89829698 | CI20: =IFERROR(AVERAGE(CB20,CC20,CD20,CE20,CF20),"n/m") -> 0.88761944 | CJ20: =IFERROR(AVERAGE(BB20,BG20,BL20,BQ20,BV20),"n/m") -> 0.73323911 | CK20: =IFERROR(AVERAGE(AC20,AH20,AM20,AR20,AW20,BB20,BG20,BL20,BQ20,BV20),"n/m") -> 0.72944001 | CL20: =IFERROR(AVERAGE(C20,D20,E20,F20,G20,H20,I20,N20,S20,X20,AC20,AH20,AM20,AR20,AW20,BB20,BG20,BL20,BQ20,BV20),"n/m") -> 0.72944001 | CO20: Q4/26E other income (expense), net ($m) | CQ20: 3 | CS20: 9M FY26 $9.9m (Q3 $11.9m incl. investment gains).
B21: Memo: Scores segment revenue as reported (segment note) | C21: 177.152 | D21: 180.444 | E21: 156.816 | F21: 131.621 | G21: 172.339 | H21: 168.567 | I21: 175.623 | J21: 43.447 | K21: 44.062 | L21: 47.152 | M21: 46.152 | N21: 180.813 | O21: 47.18 | P21: 47.858 | Q21: 45.33 | R21: 46.101 | S21: 186.469 | T21: 43.941 | U21: 49.937 | V21: 55.754 | W21: 57.375 | X21: 207.007 | Y21: 56.002 | Z21: 61.116 | AA21: 61.13 | AB21: 62.811 | AC21: 241.059 | AD21: 59.382 | AE21: 65.433 | AF21: 69.514 | AG21: 72.025 | AH21: 266.354 | AI21: 69.915 | AJ21: 87.91 | AK21: 92.105 | AL21: 92.718 | AM21: 342.648 | AN21: 85.683 | AO21: 104.403 | AP21: 115.146 | AQ21: 115.945 | AR21: 421.177 | AS21: 115.138 | AT21: 129.148 | AU21: 131.55 | AV21: 152.711 | AW21: 528.547 | AX21: 144.651 | AY21: 168.719 | AZ21: 172.202 | BA21: 168.575 | BB21: 654.147 | BC21: 169.487 | BD21: 183.742 | BE21: 179.355 | BF21: 174.059 | BG21: 706.643 | BH21: 177.988 | BI21: 198.507 | BJ21: 201.778 | BK21: 195.555 | BL21: 773.828 | BM21: 192.112 | BN21: 236.885 | BO21: 241.45 | BP21: 249.203 | BQ21: 919.65 | BR21: 235.675 | BS21: 297.039 | BT21: 324.309 | BU21: 311.552 | BV21: 1168.575 | BW21: 304.534 | BX21: 474.973 | BY21: 458.897 | CO21: Q4/26E depreciation & amortization ($m) | CQ21: 4.3 | CS21: Q3 $4.2m; rising with capitalized software.
B22: Check: revenue streams vs segment revenue (should be 0) | C22: =IF(AND(ISNUMBER(C11),ISNUMBER(C14),ISNUMBER(C21)),IF(ABS(C17-C21)<=0.15,0,ROUND(C17-C21,1)),"") | D22: =IF(AND(ISNUMBER(D11),ISNUMBER(D14),ISNUMBER(D21)),IF(ABS(D17-D21)<=0.15,0,ROUND(D17-D21,1)),"") | E22: =IF(AND(ISNUMBER(E11),ISNUMBER(E14),ISNUMBER(E21)),IF(ABS(E17-E21)<=0.15,0,ROUND(E17-E21,1)),"") | F22: =IF(AND(ISNUMBER(F11),ISNUMBER(F14),ISNUMBER(F21)),IF(ABS(F17-F21)<=0.15,0,ROUND(F17-F21,1)),"") | G22: =IF(AND(ISNUMBER(G11),ISNUMBER(G14),ISNUMBER(G21)),IF(ABS(G17-G21)<=0.15,0,ROUND(G17-G21,1)),"") | H22: =IF(AND(ISNUMBER(H11),ISNUMBER(H14),ISNUMBER(H21)),IF(ABS(H17-H21)<=0.15,0,ROUND(H17-H21,1)),"") | I22: =IF(AND(ISNUMBER(I11),ISNUMBER(I14),ISNUMBER(I21)),IF(ABS(I17-I21)<=0.15,0,ROUND(I17-I21,1)),"") | J22: =IF(AND(ISNUMBER(J11),ISNUMBER(J14),ISNUMBER(J21)),IF(ABS(J17-J21)<=0.15,0,ROUND(J17-J21,1)),"") | ... BY22: =IF(AND(ISNUMBER(BY11),ISNUMBER(BY14),ISNUMBER(BY21)),IF(ABS(BY17-BY21)<=0.15,0,ROUND(BY17-BY21,1)),"") -> 0 | CO22: Q4/26E share-based compensation ($m) | CQ22: 46.1 | CS22: FY26 guidance $188m − 9M actual $141.9m.
B23: Scores segment operating income | C23: 112.413 | D23: 115.317 | E23: 90.458 | F23: 75.888 | G23: 110.651 | H23: 113.398 | I23: 122.936 | J23: 29.666 | K23: 31.128 | L23: 34.175 | M23: 34.063 | N23: 129.032 | O23: 36.805 | P23: 36.919 | Q23: 33.886 | R23: 34.672 | S23: 142.282 | T23: 31.049 | U23: 35.319 | V23: 41.018 | W23: 43.828 | X23: 151.214 | Y23: 41.833 | Z23: 47.026 | AA23: 46.809 | AB23: 49.416 | AC23: 185.084 | AD23: 46.063 | AE23: 50.949 | AF23: 55.501 | AG23: 59.405 | AH23: 211.918 | AI23: 54.028 | AJ23: 71.499 | AK23: 75.731 | AL23: 77.914 | AM23: 279.171 | AN23: 72.201 | AO23: 88.236 | AP23: 99.296 | AQ23: 101.623 | AR23: 361.356 | AS23: 97.426 | AT23: 113.488 | AU23: 110.217 | AV23: 133.179 | AW23: 454.31 | AX23: 123.025 | AY23: 146.542 | AZ23: 146.784 | BA23: 144.333 | BB23: 560.684 | BC23: 147.503 | BD23: 162.716 | BE23: 160.148 | BF23: 152.439 | BG23: 622.806 | BH23: 156.692 | BI23: 175.405 | BJ23: 176.999 | BK23: 171.975 | BL23: 681.071 | BM23: 168.654 | BN23: 212.208 | BO23: 212.989 | BP23: 219.503 | BQ23: 813.354 | BR23: 203.771 | BS23: 264.97 | BT23: 284.711 | BU23: 272.791 | BV23: 1026.243 | BW23: 267.853 | BX23: 432.476 | BY23: 416.886 | BZ23: =BZ17*BZ24 -> 385.55731 | CA23: =SUM(BW23:BZ23) -> 1502.7723 | CB23: =CB17*CB24 -> 1725.5454 | CC23: =CC17*CC24 -> 1915.33 | CD23: =CD17*CD24 -> 2093.3838 | CE23: =CE17*CE24 -> 2267.7701 | CF23: =CF17*CF24 -> 2437.1594 | CG23: Segment operating income as reported (company measure: excludes share-based compensation, amortization, restructuring & acquisition costs and unallocated corporate expenses; FY2006–09 segment results were after amortization and corporate costs). Forecast = segment revenue × segment margin. | CI23: =IFERROR((CF23/CA23)^(1/5)-1,"n/m") -> 0.10153462 | CJ23: =IFERROR((BV23/AW23)^(1/5)-1,"n/m") -> 0.17700845 | CK23: =IFERROR((BV23/X23)^(1/10)-1,"n/m") -> 0.21106045 | CL23: =IFERROR((BV23/C23)^(1/19)-1,"n/m") -> 0.12343808 | CO23: Q4/26E restructuring charges ($m) | CQ23: 27 | CS23: 8-K Item 2.05 (1-Oct-2026): ~$27.0m pre-tax in Q4 FY26 (15% workforce reduction).
B24: Segment operating margin % | C24: =IF(AND(ISNUMBER(C23),ISNUMBER(C17)),IFERROR(C23/C17,""),"") -> 0.63455676 | D24: =IF(AND(ISNUMBER(D23),ISNUMBER(D17)),IFERROR(D23/D17,""),"") -> 0.63907362 | E24: =IF(AND(ISNUMBER(E23),ISNUMBER(E17)),IFERROR(E23/E17,""),"") -> 0.57684165 | F24: =IF(AND(ISNUMBER(F23),ISNUMBER(F17)),IFERROR(F23/F17,""),"") -> 0.57656453 | G24: =IF(AND(ISNUMBER(G23),ISNUMBER(G17)),IFERROR(G23/G17,""),"") -> 0.64205432 | H24: =IF(AND(ISNUMBER(H23),ISNUMBER(H17)),IFERROR(H23/H17,""),"") -> 0.67271767 | I24: =IF(AND(ISNUMBER(I23),ISNUMBER(I17)),IFERROR(I23/I17,""),"") -> 0.69999943 | J24: =IF(AND(ISNUMBER(J23),ISNUMBER(J17)),IFERROR(J23/J17,""),"") -> 0.68280894 | ... BY24: =IF(AND(ISNUMBER(BY23),ISNUMBER(BY17)),IFERROR(BY23/BY17,""),"") -> 0.90845222 | BZ24: =BZ25+$BZ$104 -> 0.87322736 | CA24: =IF(AND(ISNUMBER(CA23),ISNUMBER(CA17)),IFERROR(CA23/CA17,""),"") -> 0.89454172 | CB24: =CHOOSE(MATCH($CG$2,{"Bull","Base","Bear"},0),$CP$63,$CQ$63,$CR$63) -> 0.905 | CC24: =CHOOSE(MATCH($CG$2,{"Bull","Base","Bear"},0),$CP$64,$CQ$64,$CR$64) -> 0.905 | CD24: =CHOOSE(MATCH($CG$2,{"Bull","Base","Bear"},0),$CP$65,$CQ$65,$CR$65) -> 0.905 | CE24: =CHOOSE(MATCH($CG$2,{"Bull","Base","Bear"},0),$CP$66,$CQ$66,$CR$66) -> 0.905 | CF24: =CHOOSE(MATCH($CG$2,{"Bull","Base","Bear"},0),$CP$67,$CQ$67,$CR$67) -> 0.905 | CG24: Q4/26E: margin before calibration + non-GAAP-EPS-guidance calibration Δ (Group block). 2027E+: scenario lever. | CI24: =IFERROR(AVERAGE(CB24,CC24,CD24,CE24,CF24),"n/m") -> 0.905 | CJ24: =IFERROR(AVERAGE(BB24,BG24,BL24,BQ24,BV24),"n/m") -> 0.87624613 | CK24: =IFERROR(AVERAGE(AC24,AH24,AM24,AR24,AW24,BB24,BG24,BL24,BQ24,BV24),"n/m") -> 0.84769094 | CL24: =IFERROR(AVERAGE(C24,D24,E24,F24,G24,H24,I24,N24,S24,X24,AC24,AH24,AM24,AR24,AW24,BB24,BG24,BL24,BQ24,BV24),"n/m") -> 0.75629247 | CO24: Q4/26E purchases of property and equipment ($m) | CQ24: 0.6 | CS24: 9M FY26 $1.4m.
B25: Q4/26E margin before EPS calibration (prior-year quarter + 9M FY26 y/y drift) | BZ25: =BU24+IFERROR(SUM(BW23:BY23)/SUM(BW17:BY17)-SUM(BR23:BT23)/SUM(BR17:BT17),0) -> 0.8985781 | CO25: Q4/26E capitalized internal-use software ($m) | CQ25: 9.5 | CS25: 9M FY26 $26.5m (Q3 $9.2m).
B26: Incremental segment margin (Δ operating income / Δ revenue) | D26: =IFERROR((D23-C23)/(D17-C17),"") -> 0.88213852 | E26: =IFERROR((E23-D23)/(E17-D17),"") -> 1.0520992 | F26: =IFERROR((F23-E23)/(F17-E17),"") -> 0.57828934 | G26: =IFERROR((G23-F23)/(G17-F17),"") -> 0.85375018 | H26: =IFERROR((H23-G23)/(H17-G17),"") -> -0.72826087 | I26: =IFERROR((I23-H23)/(I17-H17),"") -> 1.3517574 | N26: =IFERROR((N23-I23)/(N17-I17),"") -> 1.1745665 | O26: =IFERROR((O23-J23)/(O17-J17),"") -> 1.9124029 | P26: =IFERROR((P23-K23)/(P17-K17),"") -> 1.5255532 | Q26: =IFERROR((Q23-L23)/(Q17-L17),"") -> 0.1586169 | R26: =IFERROR((R23-M23)/(R17-M17),"") -> -11.941176 | S26: =IFERROR((S23-N23)/(S17-N17),"") -> 2.342645 | T26: =IFERROR((T23-O23)/(T17-O17),"") -> 1.7770917 | U26: =IFERROR((U23-P23)/(U17-P17),"") -> -0.76960077 | ... CA26: =IFERROR((CA23-BV23)/(CA17-BV17),"") -> 0.93188541 | CB26: =IFERROR((CB23-CA23)/(CB17-CA17),"") -> 0.98248471 | CC26: =IFERROR((CC23-CB23)/(CC17-CB17),"") -> 0.905 | CD26: =IFERROR((CD23-CC23)/(CD17-CC17),"") -> 0.905 | CE26: =IFERROR((CE23-CD23)/(CE17-CD17),"") -> 0.905 | CF26: =IFERROR((CF23-CE23)/(CF17-CE17),"") -> 0.905 | CO26: Q4/26E non-GAAP effective tax rate | CQ26: 0.255 | CS26: 9M FY26 25.4% (non-GAAP tax = GAAP tax − income tax adjustments − excess tax benefit).
CO27: Q4/26E tax rate on adjusting items | CQ27: 0.245 | CS27: FY26 guidance: income tax adjustments −$46m on SBC $188m = 24.5%.
B28: Software (= consolidated revenue − Scores: Strategy Machine Solutions + Professional Services + Analytic Software Tools to FY2009; Applications + Tools / Decision Management Software FY2010–Q3/21; Software from FY2021) | CG28: SOFTWARE — modelling logic | CO28: Q4/26E excess tax benefit line ($m; + = shortfall added back) | CQ28: 3.37 | CS28: FY26 guidance −$13m − 9M actual $-16.4m.
B29: Platform software (FICO Platform: SaaS / cloud decisioning) | AR29: 39.175 | AW29: 65.665 | AX29: 14.125 | AY29: 15.312 | AZ29: 14.178 | BA29: 23.269 | BB29: 66.884 | BC29: 22.072 | BD29: 39.802 | BE29: 27.806 | BF29: 26.572 | BG29: 116.252 | BH29: 30.828 | BI29: 38.682 | BJ29: 40.317 | BK29: 44.923 | BL29: 154.75 | BM29: 45.173 | BN29: 47.325 | BO29: 51.78 | BP29: 55.726 | BQ29: 200.004 | BR29: 53.822 | BS29: 56.464 | BT29: 61.479 | BU29: 65.291 | BV29: 237.056 | BW29: 73.857 | BX29: 86.963 | BY29: 101.845 | BZ29: =BU29*(1+BZ30) -> 97.704862 | CA29: =SUM(BW29:BZ29) -> 360.36986 | CB29: =CA29*(1+CB30) -> 468.48082 | CC29: =CB29*(1+CC30) -> 585.60103 | CD29: =CC29*(1+CD30) -> 702.72123 | CE29: =CD29*(1+CE30) -> 822.18384 | CF29: =CE29*(1+CF30) -> 945.51142 | CG29: Revenue streams from the 10-Q / 10-K MD&A tables (first published in the FY2021 10-K: FY2019–21 annual; FY2021 quarters from the FY2022 10-Q comparatives; Q4 = fiscal year − nine months). Q4/26E: prior-year quarter × (1 + growth). 2027E+: prior year × (1 + scenario lever). | CI29: =IFERROR((CF29/CA29)^(1/5)-1,"n/m") -> 0.21278457 | CJ29: =IFERROR((BV29/AW29)^(1/5)-1,"n/m") -> 0.29271682 | CK29: =IFERROR((BV29/X29)^(1/10)-1,"n/m") -> n/m | CL29: =IFERROR((BV29/C29)^(1/19)-1,"n/m") -> n/m
B30: y/y % | D30: =IF(AND(ISNUMBER(D29),ISNUMBER(C29)),IFERROR(D29/C29-1,""),"") | E30: =IF(AND(ISNUMBER(E29),ISNUMBER(D29)),IFERROR(E29/D29-1,""),"") | F30: =IF(AND(ISNUMBER(F29),ISNUMBER(E29)),IFERROR(F29/E29-1,""),"") | G30: =IF(AND(ISNUMBER(G29),ISNUMBER(F29)),IFERROR(G29/F29-1,""),"") | H30: =IF(AND(ISNUMBER(H29),ISNUMBER(G29)),IFERROR(H29/G29-1,""),"") | I30: =IF(AND(ISNUMBER(I29),ISNUMBER(H29)),IFERROR(I29/H29-1,""),"") | N30: =IF(AND(ISNUMBER(N29),ISNUMBER(I29)),IFERROR(N29/I29-1,""),"") | O30: =IF(AND(ISNUMBER(O29),ISNUMBER(J29)),IFERROR(O29/J29-1,""),"") | P30: =IF(AND(ISNUMBER(P29),ISNUMBER(K29)),IFERROR(P29/K29-1,""),"") | Q30: =IF(AND(ISNUMBER(Q29),ISNUMBER(L29)),IFERROR(Q29/L29-1,""),"") | R30: =IF(AND(ISNUMBER(R29),ISNUMBER(M29)),IFERROR(R29/M29-1,""),"") | S30: =IF(AND(ISNUMBER(S29),ISNUMBER(N29)),IFERROR(S29/N29-1,""),"") | T30: =IF(AND(ISNUMBER(T29),ISNUMBER(O29)),IFERROR(T29/O29-1,""),"") | U30: =IF(AND(ISNUMBER(U29),ISNUMBER(P29)),IFERROR(U29/P29-1,""),"") | ... BY30: =IF(AND(ISNUMBER(BY29),ISNUMBER(BT29)),IFERROR(BY29/BT29-1,""),"") -> 0.65658192 | BZ30: =BZ31+$BZ$97 -> 0.49645222 | CA30: =IF(AND(ISNUMBER(CA29),ISNUMBER(BV29)),IFERROR(CA29/BV29-1,""),"") -> 0.52018874 | CB30: =CHOOSE(MATCH($CG$2,{"Bull","Base","Bear"},0),$CP$45,$CQ$45,$CR$45) -> 0.3 | CC30: =CHOOSE(MATCH($CG$2,{"Bull","Base","Bear"},0),$CP$46,$CQ$46,$CR$46) -> 0.25 | CD30: =CHOOSE(MATCH($CG$2,{"Bull","Base","Bear"},0),$CP$47,$CQ$47,$CR$47) -> 0.2 | CE30: =CHOOSE(MATCH($CG$2,{"Bull","Base","Bear"},0),$CP$48,$CQ$48,$CR$48) -> 0.17 | CF30: =CHOOSE(MATCH($CG$2,{"Bull","Base","Bear"},0),$CP$49,$CQ$49,$CR$49) -> 0.15 | CG30: Q4/26E: 9M FY26 y/y growth of the stream + revenue-guidance calibration Δ (Group block). 2027E–2031E: scenario lever (Bull/Base/Bear table →). | CO30: Maximum net debt / adjusted EBITDA before buybacks (x) — buyback floor 2027E+ | CP30: 3.25 | CQ30: 3 | CR30: 2.5 | CS30: Net debt $5.28bn at 30-Jun-2026 ≈ 3.5x LTM adjusted EBITDA (model); credit-agreement covenant 4.5x to Dec-2026, 4.0x to Dec-2027, 3.5x thereafter. Target (assumption) = leverage up to which free cash flow and debt capacity are returned via buybacks; FICO has bought back stock every year since FY2013. Bull = more buybacks (higher target).
B31: Q4/26E growth before revenue calibration (9M FY26 y/y) | BZ31: =IFERROR(SUM(BW29:BY29)/SUM(BR29:BT29)-1,0) -> 0.52921142
B32: Non-platform software (on-premises & SaaS point solutions: fraud, originations, customer management) | AR32: 517.793 | AW32: 518.911 | AX32: 112.33 | AY32: 110.239 | AZ32: 116.052 | BA32: 112.383 | BB32: 451.004 | BC32: 104.266 | BD32: 109.286 | BE32: 114.731 | BF32: 120.216 | BG32: 448.499 | BH32: 113.732 | BI32: 115.902 | BJ32: 131.742 | BK32: 124.056 | BL32: 485.432 | BM32: 123.495 | BN32: 129.855 | BO32: 132.005 | BP32: 125.981 | BQ32: 511.336 | BR32: 132.189 | BS32: 127.362 | BT32: 126.436 | BU32: 117.102 | BV32: 503.089 | BW32: 114.364 | BX32: 112.268 | BY32: 95.124 | BZ32: =BU32*(1+BZ33) -> 93.77922 | CA32: =SUM(BW32:BZ32) -> 415.53522 | CB32: =CA32*(1+CB33) -> 353.20494 | CC32: =CB32*(1+CC33) -> 317.88444 | CD32: =CC32*(1+CD33) -> 295.63253 | CE32: =CD32*(1+CE33) -> 280.85091 | CF32: =CE32*(1+CF33) -> 269.61687 | CI32: =IFERROR((CF32/CA32)^(1/5)-1,"n/m") -> -0.082876452 | CJ32: =IFERROR((BV32/AW32)^(1/5)-1,"n/m") -> -0.0061739209 | CK32: =IFERROR((BV32/X32)^(1/10)-1,"n/m") -> n/m | CL32: =IFERROR((BV32/C32)^(1/19)-1,"n/m") -> n/m | CO32: SC_B2B (B2B scores revenue y/y) | CP32: 0.05 | CQ32: Δ → | CR32: -0.12 | CS32: 9M FY26 +54%, FY25 +33%, FY24 +27% — mortgage origination score unit price (10-Q MD&A). Base assumes pricing gains moderate. Bear: FHFA approval of other score models / VantageScore competition (10-K risk factors).
B33: y/y % | D33: =IF(AND(ISNUMBER(D32),ISNUMBER(C32)),IFERROR(D32/C32-1,""),"") | E33: =IF(AND(ISNUMBER(E32),ISNUMBER(D32)),IFERROR(E32/D32-1,""),"") | F33: =IF(AND(ISNUMBER(F32),ISNUMBER(E32)),IFERROR(F32/E32-1,""),"") | G33: =IF(AND(ISNUMBER(G32),ISNUMBER(F32)),IFERROR(G32/F32-1,""),"") | H33: =IF(AND(ISNUMBER(H32),ISNUMBER(G32)),IFERROR(H32/G32-1,""),"") | I33: =IF(AND(ISNUMBER(I32),ISNUMBER(H32)),IFERROR(I32/H32-1,""),"") | N33: =IF(AND(ISNUMBER(N32),ISNUMBER(I32)),IFERROR(N32/I32-1,""),"") | O33: =IF(AND(ISNUMBER(O32),ISNUMBER(J32)),IFERROR(O32/J32-1,""),"") | P33: =IF(AND(ISNUMBER(P32),ISNUMBER(K32)),IFERROR(P32/K32-1,""),"") | Q33: =IF(AND(ISNUMBER(Q32),ISNUMBER(L32)),IFERROR(Q32/L32-1,""),"") | R33: =IF(AND(ISNUMBER(R32),ISNUMBER(M32)),IFERROR(R32/M32-1,""),"") | S33: =IF(AND(ISNUMBER(S32),ISNUMBER(N32)),IFERROR(S32/N32-1,""),"") | T33: =IF(AND(ISNUMBER(T32),ISNUMBER(O32)),IFERROR(T32/O32-1,""),"") | U33: =IF(AND(ISNUMBER(U32),ISNUMBER(P32)),IFERROR(U32/P32-1,""),"") | ... BY33: =IF(AND(ISNUMBER(BY32),ISNUMBER(BT32)),IFERROR(BY32/BT32-1,""),"") -> -0.24765099 | BZ33: =BZ34+$BZ$97 -> -0.19916636 | CA33: =IF(AND(ISNUMBER(CA32),ISNUMBER(BV32)),IFERROR(CA32/BV32-1,""),"") -> -0.17403239 | CB33: =CHOOSE(MATCH($CG$2,{"Bull","Base","Bear"},0),$CP$51,$CQ$51,$CR$51) -> -0.15 | CC33: =CHOOSE(MATCH($CG$2,{"Bull","Base","Bear"},0),$CP$52,$CQ$52,$CR$52) -> -0.1 | CD33: =CHOOSE(MATCH($CG$2,{"Bull","Base","Bear"},0),$CP$53,$CQ$53,$CR$53) -> -0.07 | CE33: =CHOOSE(MATCH($CG$2,{"Bull","Base","Bear"},0),$CP$54,$CQ$54,$CR$54) -> -0.05 | CF33: =CHOOSE(MATCH($CG$2,{"Bull","Base","Bear"},0),$CP$55,$CQ$55,$CR$55) -> -0.04 | CO33: 2027E | CP33: =CQ33+$CP$32 -> 0.2 | CQ33: 0.15 | CR33: =CQ33+$CR$32 -> 0.03
B34: Q4/26E growth before revenue calibration (9M FY26 y/y) | BZ34: =IFERROR(SUM(BW32:BY32)/SUM(BR32:BT32)-1,0) -> -0.16640716 | CO34: 2028E | CP34: =CQ34+$CP$32 -> 0.17 | CQ34: 0.12 | CR34: =CQ34+$CR$32 -> 0
B35: Professional services | BA35: 30.35 | BB35: 144.501 | BC35: 26.536 | BD35: 24.365 | BE35: 27.074 | BF35: 27.901 | BG35: 105.876 | BH35: 22.322 | BI35: 27.175 | BJ35: 24.851 | BK35: 25.199 | BL35: 99.547 | BM35: 21.279 | BN35: 19.744 | BO35: 22.614 | BP35: 22.899 | BQ35: 86.536 | BR35: 18.282 | BS35: 17.87 | BT35: 24.191 | BU35: 21.806 | BV35: 82.149 | BW35: 19.204 | BX35: 17.473 | BY35: 18.322 | BZ35: =BU35*(1+BZ36) -> 19.160505 | CA35: =SUM(BW35:BZ35) -> 74.159505 | CB35: =CA35*(1+CB36) -> 70.45153 | CC35: =CB35*(1+CC36) -> 68.337984 | CD35: =CC35*(1+CD36) -> 68.337984 | CE35: =CD35*(1+CE36) -> 68.337984 | CF35: =CE35*(1+CF36) -> 68.337984 | CI35: =IFERROR((CF35/CA35)^(1/5)-1,"n/m") -> -0.016217556 | CJ35: =IFERROR((BV35/AW35)^(1/5)-1,"n/m") -> n/m | CK35: =IFERROR((BV35/X35)^(1/10)-1,"n/m") -> n/m | CL35: =IFERROR((BV35/C35)^(1/19)-1,"n/m") -> n/m | CO35: 2029E | CP35: =CQ35+$CP$32 -> 0.15 | CQ35: 0.1 | CR35: =CQ35+$CR$32 -> -0.02
B36: y/y % | D36: =IF(AND(ISNUMBER(D35),ISNUMBER(C35)),IFERROR(D35/C35-1,""),"") | E36: =IF(AND(ISNUMBER(E35),ISNUMBER(D35)),IFERROR(E35/D35-1,""),"") | F36: =IF(AND(ISNUMBER(F35),ISNUMBER(E35)),IFERROR(F35/E35-1,""),"") | G36: =IF(AND(ISNUMBER(G35),ISNUMBER(F35)),IFERROR(G35/F35-1,""),"") | H36: =IF(AND(ISNUMBER(H35),ISNUMBER(G35)),IFERROR(H35/G35-1,""),"") | I36: =IF(AND(ISNUMBER(I35),ISNUMBER(H35)),IFERROR(I35/H35-1,""),"") | N36: =IF(AND(ISNUMBER(N35),ISNUMBER(I35)),IFERROR(N35/I35-1,""),"") | O36: =IF(AND(ISNUMBER(O35),ISNUMBER(J35)),IFERROR(O35/J35-1,""),"") | P36: =IF(AND(ISNUMBER(P35),ISNUMBER(K35)),IFERROR(P35/K35-1,""),"") | Q36: =IF(AND(ISNUMBER(Q35),ISNUMBER(L35)),IFERROR(Q35/L35-1,""),"") | R36: =IF(AND(ISNUMBER(R35),ISNUMBER(M35)),IFERROR(R35/M35-1,""),"") | S36: =IF(AND(ISNUMBER(S35),ISNUMBER(N35)),IFERROR(S35/N35-1,""),"") | T36: =IF(AND(ISNUMBER(T35),ISNUMBER(O35)),IFERROR(T35/O35-1,""),"") | U36: =IF(AND(ISNUMBER(U35),ISNUMBER(P35)),IFERROR(U35/P35-1,""),"") | ... BY36: =IF(AND(ISNUMBER(BY35),ISNUMBER(BT35)),IFERROR(BY35/BT35-1,""),"") -> -0.24261089 | BZ36: =BZ37+$BZ$97 -> -0.1213196 | CA36: =IF(AND(ISNUMBER(CA35),ISNUMBER(BV35)),IFERROR(CA35/BV35-1,""),"") -> -0.097256147 | CB36: =CHOOSE(MATCH($CG$2,{"Bull","Base","Bear"},0),$CP$57,$CQ$57,$CR$57) -> -0.05 | CC36: =CHOOSE(MATCH($CG$2,{"Bull","Base","Bear"},0),$CP$58,$CQ$58,$CR$58) -> -0.03 | CD36: =CHOOSE(MATCH($CG$2,{"Bull","Base","Bear"},0),$CP$59,$CQ$59,$CR$59) -> 0 | CE36: =CHOOSE(MATCH($CG$2,{"Bull","Base","Bear"},0),$CP$60,$CQ$60,$CR$60) -> 0 | CF36: =CHOOSE(MATCH($CG$2,{"Bull","Base","Bear"},0),$CP$61,$CQ$61,$CR$61) -> 0 | CO36: 2030E | CP36: =CQ36+$CP$32 -> 0.14 | CQ36: 0.09 | CR36: =CQ36+$CR$32 -> -0.03
B37: Q4/26E growth before revenue calibration (9M FY26 y/y) | BZ37: =IFERROR(SUM(BW35:BY35)/SUM(BR35:BT35)-1,0) -> -0.088560396 | CO37: 2031E | CP37: =CQ37+$CP$32 -> 0.13 | CQ37: 0.08 | CR37: =CQ37+$CR$32 -> -0.04
B38: Software — segment revenue | C38: =IF(AND(ISNUMBER(C29),ISNUMBER(C32),ISNUMBER(C35)),C29+C32+C35,C42) -> 648.213 | D38: =IF(AND(ISNUMBER(D29),ISNUMBER(D32),ISNUMBER(D35)),D29+D32+D35,D42) -> 641.792 | E38: =IF(AND(ISNUMBER(E29),ISNUMBER(E32),ISNUMBER(E35)),E29+E32+E35,E42) -> 588.026 | F38: =IF(AND(ISNUMBER(F29),ISNUMBER(F32),ISNUMBER(F35)),F29+F32+F35,F42) -> 499.114 | G38: =IF(AND(ISNUMBER(G29),ISNUMBER(G32),ISNUMBER(G35)),G29+G32+G35,G42) -> 433.304 | H38: =IF(AND(ISNUMBER(H29),ISNUMBER(H32),ISNUMBER(H35)),H29+H32+H35,H42) -> 451.116 | I38: =IF(AND(ISNUMBER(I29),ISNUMBER(I32),ISNUMBER(I35)),I29+I32+I35,I42) -> 500.8 | J38: =IF(AND(ISNUMBER(J29),ISNUMBER(J32),ISNUMBER(J35)),J29+J32+J35,J42) -> 146.573 | ... BY38: =IF(AND(ISNUMBER(BY29),ISNUMBER(BY32),ISNUMBER(BY35)),BY29+BY32+BY35,BY42) -> 215.291 | BZ38: =BZ29+BZ32+BZ35 -> 210.64459 | CA38: =CA29+CA32+CA35 -> 850.06459 | CB38: =CB29+CB32+CB35 -> 892.13729 | CC38: =CC29+CC32+CC35 -> 971.82345 | CD38: =CD29+CD32+CD35 -> 1066.6917 | CE38: =CE29+CE32+CE35 -> 1171.3727 | CF38: =CF29+CF32+CF35 -> 1283.4663 | CI38: =IFERROR((CF38/CA38)^(1/5)-1,"n/m") -> 0.085891684 | CJ38: =IFERROR((BV38/AW38)^(1/5)-1,"n/m") -> 0.014280251 | CK38: =IFERROR((BV38/X38)^(1/10)-1,"n/m") -> 0.026707034 | CL38: =IFERROR((BV38/C38)^(1/19)-1,"n/m") -> 0.012598631 | CO38: SC_B2C (B2C scores revenue y/y) | CP38: 0.02 | CQ38: Δ → | CR38: -0.04 | CS38: 9M FY26 +5%, FY25 +6%, FY24 −2% (myFICO subscriptions; royalties on scores sold through the bureaus).
B39: Segment revenue y/y % | D39: =IF(AND(ISNUMBER(D38),ISNUMBER(C38)),IFERROR(D38/C38-1,""),"") -> -0.0099056946 | E39: =IF(AND(ISNUMBER(E38),ISNUMBER(D38)),IFERROR(E38/D38-1,""),"") -> -0.083774806 | F39: =IF(AND(ISNUMBER(F38),ISNUMBER(E38)),IFERROR(F38/E38-1,""),"") -> -0.1512042 | G39: =IF(AND(ISNUMBER(G38),ISNUMBER(F38)),IFERROR(G38/F38-1,""),"") -> -0.13185364 | H39: =IF(AND(ISNUMBER(H38),ISNUMBER(G38)),IFERROR(H38/G38-1,""),"") -> 0.041107398 | I39: =IF(AND(ISNUMBER(I38),ISNUMBER(H38)),IFERROR(I38/H38-1,""),"") -> 0.11013575 | N39: =IF(AND(ISNUMBER(N38),ISNUMBER(I38)),IFERROR(N38/I38-1,""),"") -> 0.12346446 | O39: =IF(AND(ISNUMBER(O38),ISNUMBER(J38)),IFERROR(O38/J38-1,""),"") -> -0.064200091 | P39: =IF(AND(ISNUMBER(P38),ISNUMBER(K38)),IFERROR(P38/K38-1,""),"") -> 0.017307024 | Q39: =IF(AND(ISNUMBER(Q38),ISNUMBER(L38)),IFERROR(Q38/L38-1,""),"") -> 0.11462451 | R39: =IF(AND(ISNUMBER(R38),ISNUMBER(M38)),IFERROR(R38/M38-1,""),"") -> 0.21705566 | S39: =IF(AND(ISNUMBER(S38),ISNUMBER(N38)),IFERROR(S38/N38-1,""),"") -> 0.070890157 | T39: =IF(AND(ISNUMBER(T38),ISNUMBER(O38)),IFERROR(T38/O38-1,""),"") -> 0.061576373 | U39: =IF(AND(ISNUMBER(U38),ISNUMBER(P38)),IFERROR(U38/P38-1,""),"") -> 0.14220517 | ... CA39: =IF(AND(ISNUMBER(CA38),ISNUMBER(BV38)),IFERROR(CA38/BV38-1,""),"") -> 0.03377209 | CB39: =IF(AND(ISNUMBER(CB38),ISNUMBER(CA38)),IFERROR(CB38/CA38-1,""),"") -> 0.049493534 | CC39: =IF(AND(ISNUMBER(CC38),ISNUMBER(CB38)),IFERROR(CC38/CB38-1,""),"") -> 0.089320519 | CD39: =IF(AND(ISNUMBER(CD38),ISNUMBER(CC38)),IFERROR(CD38/CC38-1,""),"") -> 0.097618856 | CE39: =IF(AND(ISNUMBER(CE38),ISNUMBER(CD38)),IFERROR(CE38/CD38-1,""),"") -> 0.098136114 | CF39: =IF(AND(ISNUMBER(CF38),ISNUMBER(CE38)),IFERROR(CF38/CE38-1,""),"") -> 0.095694169 | CO39: 2027E | CP39: =CQ39+$CP$38 -> 0.06 | CQ39: 0.04 | CR39: =CQ39+$CR$38 -> 0
B40: % of total revenue | C40: =IF(AND(ISNUMBER(C38),ISNUMBER(C87)),IFERROR(C38/C87,""),"") -> 0.78536526 | D40: =IF(AND(ISNUMBER(D38),ISNUMBER(D87)),IFERROR(D38/D87,""),"") -> 0.78054476 | E40: =IF(AND(ISNUMBER(E38),ISNUMBER(E87)),IFERROR(E38/E87,""),"") -> 0.78946407 | F40: =IF(AND(ISNUMBER(F38),ISNUMBER(F87)),IFERROR(F38/F87,""),"") -> 0.79132124 | G40: =IF(AND(ISNUMBER(G38),ISNUMBER(G87)),IFERROR(G38/G87,""),"") -> 0.71544458 | H40: =IF(AND(ISNUMBER(H38),ISNUMBER(H87)),IFERROR(H38/H87,""),"") -> 0.72797866 | I40: =IF(AND(ISNUMBER(I38),ISNUMBER(I87)),IFERROR(I38/I87,""),"") -> 0.74036513 | J40: =IF(AND(ISNUMBER(J38),ISNUMBER(J87)),IFERROR(J38/J87,""),"") -> 0.77135565 | ... CF40: =IF(AND(ISNUMBER(CF38),ISNUMBER(CF87)),IFERROR(CF38/CF87,""),"") -> 0.32276604 | CO40: 2028E | CP40: =CQ40+$CP$38 -> 0.06 | CQ40: 0.04 | CR40: =CQ40+$CR$38 -> 0
...

Sheet Bull-Base-Bear
B2: Fair Isaac Corporation (FICO) — Bull / Base / Bear Case P&L Summary | J2: Share price ($): | K2: =Model!$CB$389 -> 740
B3: Non-GAAP figures (company definition: non-GAAP net income / EPS; model non-GAAP operating income and adjusted EBITDA) · USD millions · fiscal years ended 30 September · Live panel linked to Model — toggle scenario via Model!CG2. Bull and Bear panels are value snapshots generated from the Model with the switch set to each case. FY2026E = Q1–Q3 actual + Q4 calibrated to the FY26 guidance (revenue $2.53bn, non-GAAP EPS $42.43). | J3: As of: | K3: =TODAY() -> 2026-10-13 00:00:00
B5: Scenario: | C5: =Model!$CG$2 -> Base | N5: Scenario: | O5: Bull | P5: Snapshot (values) — Model run with switch = Bull | Z5: Scenario: | AA5: Bear | AB5: Snapshot (values) — Model run with switch = Bear
B7: (USDm, except EPS and shares) | C7: 2026E | D7: 2027E | E7: 2028E | F7: 2029E | G7: 2030E | H7: 2031E | I7: 26-'31 CAGR | J7: LT Hist Avg | K7: LT Hist Min | L7: LT Hist Max | N7: (USDm, except EPS and shares) | O7: 2026E | P7: 2027E | Q7: 2028E | R7: 2029E | S7: 2030E | T7: 2031E | U7: 26-'31 CAGR | V7: LT Hist Avg | W7: LT Hist Min | X7: LT Hist Max | Z7: (USDm, except EPS and shares) | AA7: 2026E | AB7: 2027E | AC7: 2028E | AD7: 2029E | AE7: 2030E | AF7: 2031E | AG7: 26-'31 CAGR | AH7: LT Hist Avg | AI7: LT Hist Min | AJ7: LT Hist Max
B9: Revenue | C9: =Model!CA127 -> 2530 | D9: =Model!CB127 -> 2798.8173 | E9: =Model!CC127 -> 3088.2102 | F9: =Model!CD127 -> 3379.8231 | G9: =Model!CE127 -> 3677.1961 | H9: =Model!CF127 -> 3976.4601 | I9: =IFERROR((H9/C9)^(1/5)-1,"n/m") -> 0.094649847 | N9: Revenue | O9: 2530 | P9: 2927.76 | Q9: 3383.6575 | R9: 3884.8633 | S9: 4440.2924 | T9: 5050.9055 | U9: 0.14828514 | Z9: Revenue | AA9: 2530 | AB9: 2549.3396 | AC9: 2550.6625 | AD9: 2523.3934 | AE9: 2476.3925 | AF9: 2411.7105 | AG9: -0.0095309037
B10: Revenue y/y % | D10: =IFERROR(D9/C9-1,"") -> 0.1062519 | E10: =IFERROR(E9/D9-1,"") -> 0.10339826 | F10: =IFERROR(F9/E9-1,"") -> 0.094427809 | G10: =IFERROR(G9/F9-1,"") -> 0.087984782 | H10: =IFERROR(H9/G9-1,"") -> 0.081383746 | N10: Revenue y/y % | P10: 0.1572174 | Q10: 0.15571545 | R10: 0.14812545 | S10: 0.14297262 | T10: 0.13751643 | Z10: Revenue y/y % | AB10: 0.0076441273 | AC10: 0.00051892092 | AD10: -0.010691 | AE10: -0.018626081 | AF10: -0.02611945
B11: Scores segment revenue y/y % | C11: =Model!CA216 -> 0.43759315 | D11: =Model!CB216 -> 0.13497222 | E11: =Model!CC216 -> 0.10998525 | F11: =Model!CD216 -> 0.092962513 | G11: =Model!CE216 -> 0.083303533 | H11: =Model!CF216 -> 0.074694192 | N11: Scores segment revenue y/y % | O11: 0.43759315 | P11: 0.18087373 | Q11: 0.15651046 | R11: 0.13988413 | S11: 0.13059306 | T11: 0.12223433 | Z11: Scores segment revenue y/y % | AA11: 0.43759315 | AB11: 0.025901515 | AC11: 0 | AD11: -0.017336661 | AE11: -0.027289673 | AF11: -0.035862246
B12: Adjusted EBITDA (model) | C12: =Model!CA183 -> 1545.8696 | D12: =Model!CB183 -> 1790.9017 | E12: =Model!CC183 -> 2002.2487 | F12: =Model!CD183 -> 2209.6101 | G12: =Model!CE183 -> 2408.2373 | H12: =Model!CF183 -> 2606.2804 | I12: =IFERROR((H12/C12)^(1/5)-1,"n/m") -> 0.11011931 | N12: Adjusted EBITDA (model) | O12: 1543.9455 | P12: 1914.1999 | Q12: 2233.1594 | R12: 2576.3126 | S12: 2939.1589 | T12: 3333.4893 | U12: 0.16641587 | Z12: Adjusted EBITDA (model) | AA12: 1547.7937 | AB12: 1521.932 | AC12: 1538.6919 | AD12: 1531.9227 | AE12: 1503.1728 | AF12: 1463.0694 | AG12: -0.011195641
B13: Adjusted EBITDA margin % | C13: =IFERROR(C12/C9,"") -> 0.61101565 | D13: =IFERROR(D12/D9,"") -> 0.63987804 | E13: =IFERROR(E12/E9,"") -> 0.64835247 | F13: =IFERROR(F12/F9,"") -> 0.65376503 | G13: =IFERROR(G12/G9,"") -> 0.6549113 | H13: =IFERROR(H12/H9,"") -> 0.65542729 | J13: =IFERROR(AVERAGE(Model!C184,Model!D184,Model!E184,Model!F184,Model!G184,Model!H184,Model!I184,Model!N184,Model!S184,Model!X184,Model!AC184,Model!AH184,Model!AM184,Model!AR184,Model!AW184,Model!BB184,Model!BG184,Model!BL184,Model!BQ184,Model!BV184),"") -> 0.35212441 | K13: =IFERROR(MIN(Model!C184,Model!D184,Model!E184,Model!F184,Model!G184,Model!H184,Model!I184,Model!N184,Model!S184,Model!X184,Model!AC184,Model!AH184,Model!AM184,Model!AR184,Model!AW184,Model!BB184,Model!BG184,Model!BL184,Model!BQ184,Model!BV184),"") -> 0.27108031 | L13: =IFERROR(MAX(Model!C184,Model!D184,Model!E184,Model!F184,Model!G184,Model!H184,Model!I184,Model!N184,Model!S184,Model!X184,Model!AC184,Model!AH184,Model!AM184,Model!AR184,Model!AW184,Model!BB184,Model!BG184,Model!BL184,Model!BQ184,Model!BV184),"") -> 0.56195712 | N13: Adjusted EBITDA margin % | O13: 0.61025514 | P13: 0.65381039 | Q13: 0.65998388 | R13: 0.66316685 | S13: 0.66192914 | T13: 0.65997854 | V13: 0.35212441 | W13: 0.27108031 | X13: 0.56195712 | Z13: Adjusted EBITDA margin % | AA13: 0.61177615 | AB13: 0.59699069 | AC13: 0.60325187 | AD13: 0.60708833 | AE13: 0.60700104 | AF13: 0.60665218 | AH13: 0.35212441 | AI13: 0.27108031 | AJ13: 0.56195712
B15: Operating income (GAAP) | C15: =Model!CA135 -> 1301.4976 | D15: =Model!CB135 -> 1549.9963 | E15: =Model!CC135 -> 1743.1919 | F15: =Model!CD135 -> 1927.2243 | G15: =Model!CE135 -> 2102.0616 | H15: =Model!CF135 -> 2276.1636 | I15: =IFERROR((H15/C15)^(1/5)-1,"n/m") -> 0.11828377 | N15: Operating income (GAAP) | O15: 1299.5735 | P15: 1662.9791 | Q15: 1950.4668 | R15: 2253.5235 | S15: 2571.9355 | T15: 2917.4168 | U15: 0.17554573 | Z15: Operating income (GAAP) | AA15: 1303.4217 | AB15: 1300.9849 | AC15: 1322.6389 | AD15: 1318.0512 | AE15: 1293.0614 | AF15: 1258.1326 | AG15: -0.0070479119
B16: Operating income y/y % | D16: =IFERROR(D15/C15-1,"") -> 0.19093294 | E16: =IFERROR(E15/D15-1,"") -> 0.12464257 | F16: =IFERROR(F15/E15-1,"") -> 0.1055721 | G16: =IFERROR(G15/F15-1,"") -> 0.090719733 | H16: =IFERROR(H15/G15-1,"") -> 0.082824427 | N16: Operating income y/y % | P16: 0.27963453 | Q16: 0.17287511 | R16: 0.15537649 | S16: 0.14129518 | T16: 0.13432737 | Z16: Operating income y/y % | AB16: -0.0018695557 | AC16: 0.01664438 | AD16: -0.0034686163 | AE16: -0.01895966 | AF16: -0.027012514
B17: Operating margin (GAAP) % | C17: =IFERROR(C15/C9,"") -> 0.51442592 | D17: =IFERROR(D15/D9,"") -> 0.55380404 | E17: =IFERROR(E15/E9,"") -> 0.56446673 | F17: =IFERROR(F15/F9,"") -> 0.57021455 | G17: =IFERROR(G15/G9,"") -> 0.57164794 | H17: =IFERROR(H15/H9,"") -> 0.57240953 | J17: =IFERROR(AVERAGE(Model!C226,Model!D226,Model!E226,Model!F226,Model!G226,Model!H226,Model!I226,Model!N226,Model!S226,Model!X226,Model!AC226,Model!AH226,Model!AM226,Model!AR226,Model!AW226,Model!BB226,Model!BG226,Model!BL226,Model!BQ226,Model!BV226),"") -> 0.25333516 | K17: =IFERROR(MIN(Model!C226,Model!D226,Model!E226,Model!F226,Model!G226,Model!H226,Model!I226,Model!N226,Model!S226,Model!X226,Model!AC226,Model!AH226,Model!AM226,Model!AR226,Model!AW226,Model!BB226,Model!BG226,Model!BL226,Model!BQ226,Model!BV226),"") -> 0.16393433 | L17: =IFERROR(MAX(Model!C226,Model!D226,Model!E226,Model!F226,Model!G226,Model!H226,Model!I226,Model!N226,Model!S226,Model!X226,Model!AC226,Model!AH226,Model!AM226,Model!AR226,Model!AW226,Model!BB226,Model!BG226,Model!BL226,Model!BQ226,Model!BV226),"") -> 0.46454588 | N17: Operating margin (GAAP) % | O17: 0.51366541 | P17: 0.5680039 | Q17: 0.57643742 | R17: 0.58007794 | S17: 0.57922661 | T17: 0.57760273 | V17: 0.25333516 | W17: 0.16393433 | X17: 0.46454588 | Z17: Operating margin (GAAP) % | AA17: 0.51518643 | AB17: 0.51032229 | AC17: 0.51854721 | AD17: 0.52233282 | AE17: 0.52215528 | AF17: 0.52167645 | AH17: 0.25333516 | AI17: 0.16393433 | AJ17: 0.46454588
B19: Non-GAAP Net Income | C19: =Model!CA201 -> 972.85941 | D19: =Model!CB201 -> 1094.4293 | E19: =Model!CC201 -> 1251.8589 | F19: =Model!CD201 -> 1355.855 | G19: =Model!CE201 -> 1474.3475 | H19: =Model!CF201 -> 1593.5992 | I19: =IFERROR((H19/C19)^(1/5)-1,"n/m") -> 0.10373752 | N19: Non-GAAP Net Income | O19: 971.42596 | P19: 1177.8202 | Q19: 1388.0163 | R19: 1570.1482 | S19: 1787.5096 | T19: 2025.2007 | U19: 0.15827498 | Z19: Non-GAAP Net Income | AA19: 974.29285 | AB19: 902.50801 | AC19: 951.28901 | AD19: 941.28978 | AE19: 920.26323 | AF19: 891.65189 | AG19: -0.017571023
B21: FDSO (m) | C21: =Model!CA153 -> 22.928574 | D21: =Model!CB153 -> 20.474889 | E21: =Model!CC153 -> 18.918259 | F21: =Model!CD153 -> 16.983654 | G21: =Model!CE153 -> 15.116438 | H21: =Model!CF153 -> 13.306447 | I21: =IFERROR((H21/C21)^(1/5)-1,"n/m") -> -0.10311448 | N21: FDSO (m) | O21: 22.894791 | P21: 19.752994 | Q21: 17.441005 | R21: 14.834814 | S21: 12.169578 | T21: 9.4335358 | U21: -0.1624947 | Z21: FDSO (m) | AA21: 22.962358 | AB21: 21.392865 | AC21: 21.279682 | AD21: 20.687018 | AE21: 19.950299 | AF21: 19.341095 | AG21: -0.033742416
B23: Non-GAAP EPS — Diluted ($) | C23: =Model!CA205 -> 42.43 | D23: =Model!CB205 -> 53.452271 | E23: =Model!CC205 -> 66.171989 | F23: =Model!CD205 -> 79.83294 | G23: =Model!CE205 -> 97.532729 | H23: =Model!CF205 -> 119.76143 | I23: =IFERROR((H23/C23)^(1/5)-1,"n/m") -> 0.23063367 | N23: Non-GAAP EPS — Diluted ($) | O23: 42.43 | P23: 59.627425 | Q23: 79.583506 | R23: 105.84212 | S23: 146.88345 | T23: 214.68098 | U23: 0.38300614 | Z23: Non-GAAP EPS — Diluted ($) | AA23: 42.43 | AB23: 42.187337 | AC23: 44.704098 | AD23: 45.501473 | AE23: 46.12779 | AF23: 46.101417 | AG23: 0.016736109
B24: EPS y/y % | D24: =IFERROR(D23/C23-1,"") -> 0.25977541 | E24: =IFERROR(E23/D23-1,"") -> 0.23796405 | F24: =IFERROR(F23/E23-1,"") -> 0.20644613 | G24: =IFERROR(G23/F23-1,"") -> 0.22171035 | H24: =IFERROR(H23/G23-1,"") -> 0.22791022 | N24: EPS y/y % | P24: 0.40531287 | Q24: 0.33467957 | R24: 0.32995044 | S24: 0.38775991 | T24: 0.46157369 | Z24: EPS y/y % | AB24: -0.0057191284 | AC24: 0.05965678 | AD24: 0.017836739 | AE24: 0.013764758 | AF24: -0.00057175161
B26: P / E (x) — assumed (non-GAAP EPS) | G26: 30 | H26: 30 | N26: P / E (x) — assumed (non-GAAP EPS) | S26: 38 | T26: 38 | Z26: P / E (x) — assumed (non-GAAP EPS) | AD26: 20 | AE26: 20 | AF26: 20
B27: Price Target ($) | G27: =G26*G23 -> 2925.9819 | H27: =H26*H23 -> 3592.843 | N27: Price Target ($) | S27: =S26*S23 -> 5581.571 | T27: =T26*T23 -> 8157.8774 | Z27: Price Target ($) | AD27: =AD26*AD23 -> 910.02947 | AE27: =AE26*AE23 -> 922.5558 | AF27: =AF26*AF23 -> 922.02833
B28: Upside / (Downside) vs current | G28: =IFERROR(G27/$K$2-1,"") -> 2.9540295 | H28: =IFERROR(H27/$K$2-1,"") -> 3.8551933 | N28: Upside / (Downside) vs current | S28: =IFERROR(S27/$K$2-1,"") -> 6.5426636 | T28: =IFERROR(T27/$K$2-1,"") -> 10.024159 | Z28: Upside / (Downside) vs current | AD28: =IFERROR(AD27/$K$2-1,"") -> 0.22976955 | AE28: =IFERROR(AE27/$K$2-1,"") -> 0.24669703 | AF28: =IFERROR(AF27/$K$2-1,"") -> 0.24598423
B29: IRR (to 30-Sep of Y-1) | G29: =IFERROR((G27/$K$2)^(1/((DATE(2030-1,9,30)-$K$3)/365.25))-1,"") -> 0.58985039 | H29: =IFERROR((H27/$K$2)^(1/((DATE(2031-1,9,30)-$K$3)/365.25))-1,"") -> 0.48967594 | N29: IRR (to 30-Sep of Y-1) | S29: =IFERROR((S27/$K$2)^(1/((DATE(2030-1,9,30)-$K$3)/365.25))-1,"") -> 0.97675071 | T29: =IFERROR((T27/$K$2)^(1/((DATE(2031-1,9,30)-$K$3)/365.25))-1,"") -> 0.83200174 | Z29: IRR (to 30-Sep of Y-1) | AD29: =IFERROR((AD27/$K$2)^(1/((DATE(2029-1,9,30)-$K$3)/365.25))-1,"") -> 0.11094807 | AE29: =IFERROR((AE27/$K$2)^(1/((DATE(2030-1,9,30)-$K$3)/365.25))-1,"") -> 0.077199397 | AF29: =IFERROR((AF27/$K$2)^(1/((DATE(2031-1,9,30)-$K$3)/365.25))-1,"") -> 0.057042653
B31: Free Cash Flow | C31: =Model!CA258 -> 1002.3757 | D31: =Model!CB258 -> 1116.9485 | E31: =Model!CC258 -> 1280.1248 | F31: =Model!CD258 -> 1386.8439 | G31: =Model!CE258 -> 1507.974 | H31: =Model!CF258 -> 1630.0355 | I31: =IFERROR((H31/C31)^(1/5)-1,"n/m") -> 0.10213122 | N31: Free Cash Flow | O31: 1000.9423 | P31: 1196.4564 | Q31: 1412.5113 | R31: 1597.6736 | S31: 1818.2338 | T31: 2059.6175 | U31: 0.15524875 | Z31: Free Cash Flow | AA31: 1003.8092 | AB31: 932.53982 | AC31: 985.8248 | AD31: 976.69934 | AE31: 956.0041 | AF31: 927.47211 | AG31: -0.01569444
B32: FCF % | C32: =IFERROR(C31/C9,"") -> 0.39619595 | D32: =IFERROR(D31/D9,"") -> 0.39907874 | E32: =IFERROR(E31/E9,"") -> 0.41451999 | F32: =IFERROR(F31/F9,"") -> 0.41033032 | G32: =IFERROR(G31/G9,"") -> 0.41008802 | H32: =IFERROR(H31/H9,"") -> 0.40992126 | J32: =IFERROR(AVERAGE(Model!C263,Model!D263,Model!E263,Model!F263,Model!G263,Model!H263,Model!I263,Model!N263,Model!S263,Model!X263,Model!AC263,Model!AH263,Model!AM263,Model!AR263,Model!AW263,Model!BB263,Model!BG263,Model!BL263,Model!BQ263,Model!BV263),"") -> 0.22755881 | K32: =IFERROR(MIN(Model!C263,Model!D263,Model!E263,Model!F263,Model!G263,Model!H263,Model!I263,Model!N263,Model!S263,Model!X263,Model!AC263,Model!AH263,Model!AM263,Model!AR263,Model!AW263,Model!BB263,Model!BG263,Model!BL263,Model!BQ263,Model!BV263),"") -> 0.12873205 | L32: =IFERROR(MAX(Model!C263,Model!D263,Model!E263,Model!F263,Model!G263,Model!H263,Model!I263,Model!N263,Model!S263,Model!X263,Model!AC263,Model!AH263,Model!AM263,Model!AR263,Model!AW263,Model!BB263,Model!BG263,Model!BL263,Model!BQ263,Model!BV263),"") -> 0.37139561 | N32: FCF % | O32: 0.39562937 | P32: 0.40865932 | Q32: 0.41745103 | R32: 0.41125607 | S32: 0.40948515 | T32: 0.40777193 | V32: 0.22755881 | W32: 0.12873205 | X32: 0.37139561 | Z32: FCF % | AA32: 0.39676253 | AB32: 0.36579662 | AC32: 0.38649754 | AD32: 0.38705789 | AE32: 0.38604709 | AF32: 0.38457025 | AH32: 0.22755881 | AI32: 0.12873205 | AJ32: 0.37139561
B33: FCF / share ($) | C33: =IFERROR(C31/C21,"") -> 43.717317 | D33: =IFERROR(D31/D21,"") -> 54.552115 | E33: =IFERROR(E31/E21,"") -> 67.666101 | F33: =IFERROR(F31/F21,"") -> 81.65757 | G33: =IFERROR(G31/G21,"") -> 99.757233 | H33: =IFERROR(H31/H21,"") -> 122.49968 | N33: FCF / share ($) | O33: 43.719216 | P33: 60.570891 | Q33: 80.987953 | R33: 107.69758 | S33: 149.40812 | T33: 218.32933 | Z33: FCF / share ($) | AA33: 43.715423 | AB33: 43.591161 | AC33: 46.327045 | AD33: 47.213153 | AE33: 47.919286 | AF33: 47.953443
B34: FCF Yield (on PT) | F34: =IFERROR(F33/F$27,"") | G34: =IFERROR(G33/G$27,"") -> 0.034093592 | H34: =IFERROR(H33/H$27,"") -> 0.034095472 | N34: FCF Yield (on PT) | R34: =IFERROR(R33/R$27,"") | S34: =IFERROR(S33/S$27,"") -> 0.026768113 | T34: =IFERROR(T33/T$27,"") -> 0.026763007 | Z34: FCF Yield (on PT) | AD34: =IFERROR(AD33/AD$27,"") -> 0.051880906 | AE34: =IFERROR(AE33/AE$27,"") -> 0.051941883 | AF34: =IFERROR(AF33/AF$27,"") -> 0.052008644
B35: Adjusted EBITDA (leverage basis) | C35: =Model!CA183 -> 1545.8696 | D35: =Model!CB183 -> 1790.9017 | E35: =Model!CC183 -> 2002.2487 | F35: =Model!CD183 -> 2209.6101 | G35: =Model!CE183 -> 2408.2373 | H35: =Model!CF183 -> 2606.2804 | I35: =IFERROR((H35/C35)^(1/5)-1,"n/m") -> 0.11011931 | N35: Adjusted EBITDA (leverage basis) | O35: 1543.9455 | P35: 1914.1999 | Q35: 2233.1594 | R35: 2576.3126 | S35: 2939.1589 | T35: 3333.4893 | U35: 0.16641587 | Z35: Adjusted EBITDA (leverage basis) | AA35: 1547.7937 | AB35: 1521.932 | AC35: 1538.6919 | AD35: 1531.9227 | AE35: 1503.1728 | AF35: 1463.0694 | AG35: -0.011195641
B36: Adjusted EBITDA % of revenue | C36: =IFERROR(C35/C9,"") -> 0.61101565 | D36: =IFERROR(D35/D9,"") -> 0.63987804 | E36: =IFERROR(E35/E9,"") -> 0.64835247 | F36: =IFERROR(F35/F9,"") -> 0.65376503 | G36: =IFERROR(G35/G9,"") -> 0.6549113 | H36: =IFERROR(H35/H9,"") -> 0.65542729 | J36: =IFERROR(AVERAGE(Model!C225,Model!D225,Model!E225,Model!F225,Model!G225,Model!H225,Model!I225,Model!N225,Model!S225,Model!X225,Model!AC225,Model!AH225,Model!AM225,Model!AR225,Model!AW225,Model!BB225,Model!BG225,Model!BL225,Model!BQ225,Model!BV225),"") -> 0.35212441 | K36: =IFERROR(MIN(Model!C225,Model!D225,Model!E225,Model!F225,Model!G225,Model!H225,Model!I225,Model!N225,Model!S225,Model!X225,Model!AC225,Model!AH225,Model!AM225,Model!AR225,Model!AW225,Model!BB225,Model!BG225,Model!BL225,Model!BQ225,Model!BV225),"") -> 0.27108031 | L36: =IFERROR(MAX(Model!C225,Model!D225,Model!E225,Model!F225,Model!G225,Model!H225,Model!I225,Model!N225,Model!S225,Model!X225,Model!AC225,Model!AH225,Model!AM225,Model!AR225,Model!AW225,Model!BB225,Model!BG225,Model!BL225,Model!BQ225,Model!BV225),"") -> 0.56195712 | N36: Adjusted EBITDA % of revenue | O36: 0.61025514 | P36: 0.65381039 | Q36: 0.65998388 | R36: 0.66316685 | S36: 0.66192914 | T36: 0.65997854 | V36: 0.35212441 | W36: 0.27108031 | X36: 0.56195712 | Z36: Adjusted EBITDA % of revenue | AA36: 0.61177615 | AB36: 0.59699069 | AC36: 0.60325187 | AD36: 0.60708833 | AE36: 0.60700104 | AF36: 0.60665218 | AH36: 0.35212441 | AI36: 0.27108031 | AJ36: 0.56195712
B38: Net Debt | C38: =Model!CA383 -> 5322.5103 | D38: =Model!CB383 -> 5316.6122 | E38: =Model!CC383 -> 5950.6531 | F38: =Model!CD383 -> 6572.7374 | G38: =Model!CE383 -> 7168.6188 | H38: =Model!CF383 -> 7762.7483 | N38: Net Debt | O38: 5523.9437 | P38: 6165.0568 | Q38: 7201.6751 | R38: 8316.9228 | S38: 9496.1734 | T38: 10777.747 | Z38: Net Debt | AA38: 5121.0768 | AB38: 4255.3132 | AC38: 3790.6369 | AD38: 3773.7137 | AE38: 3701.839 | AF38: 3601.5805
B39: Net Debt / Adjusted EBITDA (x) | C39: =IFERROR(C38/C35,"") -> 3.4430526 | D39: =IFERROR(D38/D35,"") -> 2.9686789 | E39: =IFERROR(E38/E35,"") -> 2.971985 | F39: =IFERROR(F38/F35,"") -> 2.9746141 | G39: =IFERROR(G38/G35,"") -> 2.9767079 | H39: =IFERROR(H38/H35,"") -> 2.9784778 | N39: Net Debt / Adjusted EBITDA (x) | O39: 3.57781 | P39: 3.2206964 | Q39: 3.2248818 | R39: 3.2282274 | S39: 3.2309153 | T39: 3.2331729 | Z39: Net Debt / Adjusted EBITDA (x) | AA39: 3.3086302 | AB39: 2.7959943 | AC39: 2.463545 | AD39: 2.4633839 | AE39: 2.4626836 | AF39: 2.4616607
B40: Share repurchases ($m; FY2026E = Q4) | D40: =Model!CB276 -> 1035.293 | E40: =Model!CC276 -> 1827.9901 | F40: =Model!CD276 -> 1912.2546 | G40: =Model!CE276 -> 1996.4763 | H40: =Model!CF276 -> 2106.0125 | N40: Share repurchases ($m; FY2026E = Q4) | P40: 1757.1701 | Q40: 2352.318 | R40: 2598.0663 | S40: 2862.6339 | T40: 3184.3586 | AB40: 0 | AC40: 454.32459 | AD40: 893.93403 | AE40: 819.97928 | AF40: 765.39203
B41: Implied avg buyback price ($) | D41: =Model!CB275 -> 799.2 | E41: =Model!CC275 -> 863.136 | F41: =Model!CD275 -> 932.18688 | G41: =Model!CE275 -> 1006.7618 | H41: =Model!CF275 -> 1087.3028 | N41: Implied avg buyback price ($) | P41: 799.2 | Q41: 863.136 | R41: 932.18688 | S41: 1006.7618 | T41: 1087.3028 | AB41: 799.2 | AC41: 863.136 | AD41: 932.18688 | AE41: 1006.7618 | AF41: 1087.3028
B42: Shares repurchased (m) | D42: =Model!CB277 -> 1.2954117 | E42: =Model!CC277 -> 2.1178472 | F42: =Model!CD277 -> 2.051364 | G42: =Model!CE277 -> 1.9830672 | H42: =Model!CF277 -> 1.9369145 | N42: Shares repurchased (m) | P42: 2.1986613 | Q42: 2.7253156 | R42: 2.7870659 | S42: 2.8434072 | T42: 2.928677 | AB42: 0 | AC42: 0.52636502 | AD42: 0.9589644 | AE42: 0.81447195 | AF42: 0.70393643
B44: ROIC | C44: =Model!CA366 -> 0.87741218 | D44: =Model!CB366 -> 1.0020601 | E44: =Model!CC366 -> 1.0887916 | F44: =Model!CD366 -> 1.1657053 | G44: =Model!CE366 -> 1.2301435 | H44: =Model!CF366 -> 1.287781 | J44: =IFERROR(AVERAGE(Model!C366,Model!D366,Model!E366,Model!F366,Model!G366,Model!H366,Model!I366,Model!N366,Model!S366,Model!X366,Model!AC366,Model!AH366,Model!AM366,Model!AR366,Model!AW366,Model!BB366,Model!BG366,Model!BL366,Model!BQ366,Model!BV366),"") -> 0.23057775 | K44: =IFERROR(MIN(Model!C366,Model!D366,Model!E366,Model!F366,Model!G366,Model!H366,Model!I366,Model!N366,Model!S366,Model!X366,Model!AC366,Model!AH366,Model!AM366,Model!AR366,Model!AW366,Model!BB366,Model!BG366,Model!BL366,Model!BQ366,Model!BV366),"") -> 0.089689362 | L44: =IFERROR(MAX(Model!C366,Model!D366,Model!E366,Model!F366,Model!G366,Model!H366,Model!I366,Model!N366,Model!S366,Model!X366,Model!AC366,Model!AH366,Model!AM366,Model!AR366,Model!AW366,Model!BB366,Model!BG366,Model!BL366,Model!BQ366,Model!BV366),"") -> 0.63913839 | N44: ROIC | O44: 0.87615453 | P44: 1.0686994 | Q44: 1.2023138 | R44: 1.3324677 | S44: 1.4540591 | T44: 1.5721731 | V44: 0.23057775 | W44: 0.089689362 | X44: 0.63913839 | Z44: ROIC | AA44: 0.87866984 | AB44: 0.85147176 | AC44: 0.84729972 | AD44: 0.83095053 | AE44: 0.80333132 | AF44: 0.7712458 | AH44: 0.23057775 | AI44: 0.089689362 | AJ44: 0.63913839
B45: RONTA | C45: =Model!CA377 -> 1.5130022 | D45: =Model!CB377 -> 1.6933493 | E45: =Model!CC377 -> 1.802669 | F45: =Model!CD377 -> 1.8916103 | G45: =Model!CE377 -> 1.9571805 | H45: =Model!CF377 -> 2.009921 | J45: =IFERROR(AVERAGE(Model!C377,Model!D377,Model!E377,Model!F377,Model!G377,Model!H377,Model!I377,Model!N377,Model!S377,Model!X377,Model!AC377,Model!AH377,Model!AM377,Model!AR377,Model!AW377,Model!BB377,Model!BG377,Model!BL377,Model!BQ377,Model!BV377),"") -> 0.58673449 | K45: =IFERROR(MIN(Model!C377,Model!D377,Model!E377,Model!F377,Model!G377,Model!H377,Model!I377,Model!N377,Model!S377,Model!X377,Model!AC377,Model!AH377,Model!AM377,Model!AR377,Model!AW377,Model!BB377,Model!BG377,Model!BL377,Model!BQ377,Model!BV377),"") -> 0.15634971 | L45: =IFERROR(MAX(Model!C377,Model!D377,Model!E377,Model!F377,Model!G377,Model!H377,Model!I377,Model!N377,Model!S377,Model!X377,Model!AC377,Model!AH377,Model!AM377,Model!AR377,Model!AW377,Model!BB377,Model!BG377,Model!BL377,Model!BQ377,Model!BV377),"") -> 1.1282412 | N45: RONTA | O45: 1.5108335 | P45: 1.7994775 | Q45: 1.9746112 | R45: 2.1335536 | S45: 2.2692817 | T45: 2.3915569 | V45: 0.58673449 | W45: 0.15634971 | X45: 1.1282412 | Z45: RONTA | AA45: 1.5151709 | AB45: 1.449134 | AC45: 1.064033 | AD45: 1.0212655 | AE45: 0.9176921 | AF45: 0.80485587 | AH45: 0.58673449 | AI45: 0.15634971 | AJ45: 1.1282412
B47: Implied Market Cap (USDm) | F47: =F27*F21 -> 0 | G47: =G27*G21 -> 44230.424 | H47: =H27*H21 -> 47807.977 | N47: Implied Market Cap (USDm) | R47: =R27*R21 -> 0 | S47: =S27*S21 -> 67925.364 | T47: =T27*T21 -> 76957.628 | Z47: Implied Market Cap (USDm) | AD47: =AD27*AD21 -> 18825.796 | AE47: =AE27*AE21 -> 18405.265 | AF47: =AF27*AF21 -> 17833.038
