Workbook

Sheet Model
AC1: SCENARIO SWITCH ▼ (Bull / Base / Bear) — drives all scenario-linked forecast drivers
B2: General Electric Company, operating as GE Aerospace (NYSE: GE) — 3-Statement Financial Model | AC2: Base
B3: US GAAP · USD millions (per-share data in USD; shares in millions) · Calendar fiscal years · Source: General Electric Company Forms 10-K / 10-Q, Form 8-K earnings releases (Ex. 99.1), the 11-Apr-2024 supplemental GE Aerospace financial information (8-K Ex. 99.1) and the CPP deal 8-K (8-Sep-2026), SEC EDGAR (CIK 40545); XBRL company facts (cross-check, dividends per share); investor-relations releases are the same documents as filed on EDGAR
B4: Basis notes: GE Aerospace continuing operations — GE HealthCare spun 3-Jan-2023 and GE Vernova spun 2-Apr-2024 (both discontinued operations). FY2022–23 and the 2023 quarters are the recast comparatives first presented on that basis (2024 10-Qs / 10-K / releases; Q1-23 = H1-23 − Q2-23, Q4 = FY − 9M); Q1-24 from the Q1-25 10-Q; Q2-24+ as originally reported. Balance sheet from 31-Dec-2023; cash flow from Q3-23. Segments CES / DPT (Jan-2026 recast: Aeroderivative to DPT; recast 2025 in memo rows). Run-off insurance and U.S. tax equity outside operating profit. Pending: CPP ($11.75bn, close 2H-27, toggle). Q3/Q4-26E calibrated to the 16-Jul-2026 FY26 guidance.
AE5: Forecast | AF5: Historical | AG5: Historical | AH5: Historical
B6: (USDm) | C6: 2022 | D6: Q1/23 | E6: Q2/23 | F6: Q3/23 | G6: Q4/23 | H6: 2023 | I6: Q1/24 | J6: Q2/24 | K6: Q3/24 | L6: Q4/24 | M6: 2024 | N6: Q1/25 | O6: Q2/25 | P6: Q3/25 | Q6: Q4/25 | R6: 2025 | S6: Q1/26 | T6: Q2/26 | U6: Q3/26E | V6: Q4/26E | W6: 2026E | X6: 2027E | Y6: 2028E | Z6: 2029E | AA6: 2030E | AB6: 2031E | AC6: Modelling Notes | AE6: 5Y CAGR | AF6: 3Y CAGR | AG6: 2Y CAGR | AH6: 1Y / level
AE7: 26-'31 | AF7: 22-'25 | AG7: 23-'25 | AH7: '25-'26E
B8: SEGMENT BUILD — COMMERCIAL ENGINES & SERVICES · DEFENSE & PROPULSION TECHNOLOGIES (revenue × segment operating profit margin) | AC8: SEGMENT BUILD — modelling logic (CES services + equipment, DPT → segment revenue × margin → + adjusted Corporate & Other operating costs = operating profit → GAAP P&L)
AK9: SCENARIO INPUT TABLE — driver assumptions per Bull / Base / Bear | AL9: Bull | AM9: Base | AN9: Bear | AO9: Bull / Bear = Base + Δ (Δ inputs on each block header). Outlook block = high / mid / low end of the FY26 guidance ranges.
B10: Commercial Engines & Services (CES) — commercial and business-jet engines (CFM LEAP / CFM56, GE9X, GEnx, GE90, Passport), services (MRO, spare parts); Aeroderivative moved to DPT from Q1-26 | AC10: CES — modelling logic
B11: CES services revenue (internal shop visits, spare parts, long-term service agreements) | C11: 13688 | D11: 3933 | E11: 4130 | F11: 4853 | G11: 4770 | H11: 17686 | I11: 4390 | J11: 4705 | K11: 5317 | L11: 5363 | M11: 19775 | N11: 5118 | O11: 6059 | P11: 6820 | Q11: 7012 | R11: 25010 | S11: 6817 | T11: 7434 | U11: =($W$14-SUM(S11:T11))*P11/(P11+Q11) -> 7480.45 | V11: =($W$14-SUM(S11:T11))*Q11/(P11+Q11) -> 7691.0434 | W11: =SUM(S11:V11) -> 29422.493 | X11: =W11*(1+X12) -> 33541.642 | Y11: =X11*(1+Y12) -> 37231.223 | Z11: =Y11*(1+Z12) -> 40582.033 | AA11: =Z11*(1+AA12) -> 43828.596 | AB11: =AA11*(1+AB12) -> 46896.598 | AC11: History as reported in each period (Jan-2026 structure from Q1-26). Q3/Q4-26E = (FY26E target − H1-26) × Q3/Q4-25 share of 2H-25. 2027E+: prior year × (1 + scenario growth). | AE11: =IFERROR((AB11/W11)^(1/5)-1,"n/m") -> 0.09772201 | AF11: =IFERROR((R11/C11)^(1/3)-1,"n/m") -> 0.22252542 | AG11: =IFERROR((R11/H11)^(1/2)-1,"n/m") -> 0.18916477 | AH11: =IFERROR(W11/R11-1,"n/m") -> 0.17642916 | AK11: FY26 guidance — Q2-26 release (16-Jul-2026) | AL11: High | AM11: Mid | AN11: Low | AO11: Adjusted revenue growth high-teens (prior LDD); operating profit $10.55–10.75B; adjusted EPS $7.65–7.85; FCF $8.9–9.2B. CES revenue ~+20% (services low 20s, equipment ~20%), CES operating profit $10.25–10.35B; DPT revenue LDD, operating profit $1.6–1.7B; Corporate cost & eliminations $(1.2)–(1.3)B (22-Jan-2026). Numeric mapping of qualitative growth guides (high-teens, ~20%, low 20s, LDD) = assumption.
B12: y/y % (2026: vs the recast prior year) | H12: =IF(AND(ISNUMBER(H11),ISNUMBER(C11)),IFERROR(H11/C11-1,""),"") -> 0.29208065 | I12: =IF(AND(ISNUMBER(I11),ISNUMBER(D11)),IFERROR(I11/D11-1,""),"") -> 0.11619629 | J12: =IF(AND(ISNUMBER(J11),ISNUMBER(E11)),IFERROR(J11/E11-1,""),"") -> 0.13922518 | K12: =IF(AND(ISNUMBER(K11),ISNUMBER(F11)),IFERROR(K11/F11-1,""),"") -> 0.095610962 | L12: =IF(AND(ISNUMBER(L11),ISNUMBER(G11)),IFERROR(L11/G11-1,""),"") -> 0.12431866 | M12: =IF(AND(ISNUMBER(M11),ISNUMBER(H11)),IFERROR(M11/H11-1,""),"") -> 0.11811602 | N12: =IF(AND(ISNUMBER(N11),ISNUMBER(I11)),IFERROR(N11/I11-1,""),"") -> 0.16583144 | O12: =IF(AND(ISNUMBER(O11),ISNUMBER(J11)),IFERROR(O11/J11-1,""),"") -> 0.28777896 | ... R12: =IF(AND(ISNUMBER(R11),ISNUMBER(M11)),IFERROR(R11/M11-1,""),"") -> 0.26472819 | S12: =IF(AND(ISNUMBER(S11),ISNUMBER(N11)),IFERROR(S11/IF(ISNUMBER(N13),N13,N11)-1,""),"") -> 0.38697864 | T12: =IF(AND(ISNUMBER(T11),ISNUMBER(O11)),IFERROR(T11/IF(ISNUMBER(O13),O13,O11)-1,""),"") -> 0.26407074 | U12: =IF(AND(ISNUMBER(U11),ISNUMBER(P11)),IFERROR(U11/P11-1,""),"") -> 0.096840182 | V12: =IF(AND(ISNUMBER(V11),ISNUMBER(Q11)),IFERROR(V11/Q11-1,""),"") -> 0.096840182 | W12: =$W$11/$R$13-1 -> 0.21580551 | X12: =CHOOSE(MATCH($AC$2,{"Bull","Base","Bear"},0),$AL$35,$AM$35,$AN$35) -> 0.14 | Y12: =CHOOSE(MATCH($AC$2,{"Bull","Base","Bear"},0),$AL$36,$AM$36,$AN$36) -> 0.11 | Z12: =CHOOSE(MATCH($AC$2,{"Bull","Base","Bear"},0),$AL$37,$AM$37,$AN$37) -> 0.09 | AA12: =CHOOSE(MATCH($AC$2,{"Bull","Base","Bear"},0),$AL$38,$AM$38,$AN$38) -> 0.08 | AB12: =CHOOSE(MATCH($AC$2,{"Bull","Base","Bear"},0),$AL$39,$AM$39,$AN$39) -> 0.07 | AC12: 2026 quarters and FY2026E vs the Jan-2026 recast comparatives (memo row). 2027E+: scenario lever. | AK12: FY26 adjusted revenue growth (high-teens → 19 / 18 / 17%) | AL12: 0.19 | AM12: 0.18 | AN12: 0.17 | AO12: Guided "high-teens" (raised from LDD, 16-Jul-2026); numeric mapping is an assumption. Drives the revenue calibration.
B13: Memo: on the Jan-2026 segment structure (Q1–Q2/25 recast in the 2026 10-Qs; FY2025 revised, $bn estimate) | N13: 4915 | O13: 5881 | R13: 24200 | AK13: FY26 operating profit ($m) | AL13: 10750 | AM13: 10650 | AN13: 10550 | AO13: Guided $10.55–10.75B. Drives the 2H segment-margin calibration.
B14: FY26E target = FY2025 revised × (1 + guided growth + calibration Δ) | W14: =$R$13*(1+W15+W119) -> 29422.493 | AK14: FY26 adjusted EPS ($) — memo | AL14: 7.85 | AM14: 7.75 | AN14: 7.65 | AO14: Guided $7.65–7.85 (information row; compare the model).
B15: FY26 guided growth (scenario end-point; before calibration) | W15: =CHOOSE(MATCH($AC$2,{"Bull","Base","Bear"},0),$AL$16,$AM$16,$AN$16) -> 0.22 | AK15: FY26 free cash flow ($m) | AL15: 9200 | AM15: 9050 | AN15: 8900 | AO15: Guided $8.9–9.2B. Drives the 2026E customer-advances calibration (FCF bridge section).
B16: CES equipment revenue (install and spare engines) | C16: 5125 | D16: 1299 | E16: 1607 | F16: 1604 | G16: 1659 | H16: 6169 | I16: 1706 | J16: 1427 | K16: 1686 | L16: 2287 | M16: 7106 | N16: 1858 | O16: 1931 | P16: 2059 | Q16: 2455 | R16: 8304 | S16: 2102 | T16: 2297 | U16: =($W$19-SUM(S16:T16))*P16/(P16+Q16) -> 2193.4245 | V16: =($W$19-SUM(S16:T16))*Q16/(P16+Q16) -> 2615.2779 | W16: =SUM(S16:V16) -> 9207.7024 | X16: =W16*(1+X17) -> 10312.627 | Y16: =X16*(1+Y17) -> 11343.889 | Z16: =Y16*(1+Z17) -> 12251.401 | AA16: =Z16*(1+AA17) -> 12986.485 | AB16: =AA16*(1+AB17) -> 13635.809 | AE16: =IFERROR((AB16/W16)^(1/5)-1,"n/m") -> 0.081697748 | AF16: =IFERROR((R16/C16)^(1/3)-1,"n/m") -> 0.17453102 | AG16: =IFERROR((R16/H16)^(1/2)-1,"n/m") -> 0.16020915 | AH16: =IFERROR(W16/R16-1,"n/m") -> 0.10882737 | AK16: FY26 CES services revenue growth (low 20s → 23 / 22 / 21%) | AL16: 0.23 | AM16: 0.22 | AN16: 0.21 | AO16: Guided "low 20s" on the FY2025 revised base $24.2B (assumption mapping).
B17: y/y % (2026: vs the recast prior year) | H17: =IF(AND(ISNUMBER(H16),ISNUMBER(C16)),IFERROR(H16/C16-1,""),"") -> 0.20370732 | I17: =IF(AND(ISNUMBER(I16),ISNUMBER(D16)),IFERROR(I16/D16-1,""),"") -> 0.31331794 | J17: =IF(AND(ISNUMBER(J16),ISNUMBER(E16)),IFERROR(J16/E16-1,""),"") -> -0.11200996 | K17: =IF(AND(ISNUMBER(K16),ISNUMBER(F16)),IFERROR(K16/F16-1,""),"") -> 0.051122195 | L17: =IF(AND(ISNUMBER(L16),ISNUMBER(G16)),IFERROR(L16/G16-1,""),"") -> 0.37854129 | M17: =IF(AND(ISNUMBER(M16),ISNUMBER(H16)),IFERROR(M16/H16-1,""),"") -> 0.15188847 | N17: =IF(AND(ISNUMBER(N16),ISNUMBER(I16)),IFERROR(N16/I16-1,""),"") -> 0.089097304 | O17: =IF(AND(ISNUMBER(O16),ISNUMBER(J16)),IFERROR(O16/J16-1,""),"") -> 0.35318851 | ... R17: =IF(AND(ISNUMBER(R16),ISNUMBER(M16)),IFERROR(R16/M16-1,""),"") -> 0.16858992 | S17: =IF(AND(ISNUMBER(S16),ISNUMBER(N16)),IFERROR(S16/IF(ISNUMBER(N18),N18,N16)-1,""),"") -> 0.20182962 | T17: =IF(AND(ISNUMBER(T16),ISNUMBER(O16)),IFERROR(T16/IF(ISNUMBER(O18),O18,O16)-1,""),"") -> 0.30141643 | U17: =IF(AND(ISNUMBER(U16),ISNUMBER(P16)),IFERROR(U16/P16-1,""),"") -> 0.065286319 | V17: =IF(AND(ISNUMBER(V16),ISNUMBER(Q16)),IFERROR(V16/Q16-1,""),"") -> 0.065286319 | W17: =$W$16/$R$18-1 -> 0.19580551 | X17: =CHOOSE(MATCH($AC$2,{"Bull","Base","Bear"},0),$AL$41,$AM$41,$AN$41) -> 0.12 | Y17: =CHOOSE(MATCH($AC$2,{"Bull","Base","Bear"},0),$AL$42,$AM$42,$AN$42) -> 0.1 | Z17: =CHOOSE(MATCH($AC$2,{"Bull","Base","Bear"},0),$AL$43,$AM$43,$AN$43) -> 0.08 | AA17: =CHOOSE(MATCH($AC$2,{"Bull","Base","Bear"},0),$AL$44,$AM$44,$AN$44) -> 0.06 | AB17: =CHOOSE(MATCH($AC$2,{"Bull","Base","Bear"},0),$AL$45,$AM$45,$AN$45) -> 0.05 | AK17: FY26 CES equipment revenue growth (~20% → 21 / 20 / 19%) | AL17: 0.21 | AM17: 0.2 | AN17: 0.19 | AO17: Guided "~20%" on the FY2025 revised base $7.7B (assumption mapping).
B18: Memo: on the Jan-2026 segment structure (Q1–Q2/25 recast in the 2026 10-Qs; FY2025 revised, $bn estimate) | N18: 1749 | O18: 1765 | R18: 7700 | AK18: FY26 DPT revenue growth (LDD → 12 / 11 / 10%) | AL18: 0.12 | AM18: 0.11 | AN18: 0.1 | AO18: Guided "low double digits" on the FY2025 revised base $12.2B (assumption mapping).
B19: FY26E target = FY2025 revised × (1 + guided growth + calibration Δ) | W19: =$R$18*(1+W20+W119) -> 9207.7024 | AK19: FY26 CES operating profit ($m) | AL19: 10350 | AM19: 10300 | AN19: 10250 | AO19: Guided $10.25–10.35B.
B20: FY26 guided growth (scenario end-point; before calibration) | W20: =CHOOSE(MATCH($AC$2,{"Bull","Base","Bear"},0),$AL$17,$AM$17,$AN$17) -> 0.2 | AK20: FY26 DPT operating profit ($m) | AL20: 1700 | AM20: 1650 | AN20: 1600 | AO20: Guided $1.6–1.7B.
B21: CES — segment revenue | C21: =C11+C16 -> 18813 | D21: =D11+D16 -> 5232 | E21: =E11+E16 -> 5737 | F21: =F11+F16 -> 6457 | G21: =G11+G16 -> 6429 | H21: =H11+H16 -> 23855 | I21: =I11+I16 -> 6096 | J21: =J11+J16 -> 6132 | ... AB21: =AB11+AB16 -> 60532.406 | AE21: =IFERROR((AB21/W21)^(1/5)-1,"n/m") -> 0.093987112 | AF21: =IFERROR((R21/C21)^(1/3)-1,"n/m") -> 0.20982599 | AG21: =IFERROR((R21/H21)^(1/2)-1,"n/m") -> 0.18174475 | AH21: =IFERROR(W21/R21-1,"n/m") -> 0.15957843 | AK21: FY26 Corporate cost & eliminations ($m) | AL21: -1200 | AM21: -1250 | AN21: -1300 | AO21: Corporate cost & eliminations (adjusted Corporate & Other operating costs): $(1.2)-(1.3)B per the Q4-25 release (22-Jan-2026); not restated in the Q1-26 / Q2-26 releases. The 16-Jul-2026 total and segment ranges imply about $(1.3)B at the mid-points.
B22: CES revenue y/y % (2026: vs recast prior year) | H22: =IF(AND(ISNUMBER(H21),ISNUMBER(C21)),IFERROR(H21/C21-1,""),"") -> 0.26800617 | I22: =IF(AND(ISNUMBER(I21),ISNUMBER(D21)),IFERROR(I21/D21-1,""),"") -> 0.16513761 | J22: =IF(AND(ISNUMBER(J21),ISNUMBER(E21)),IFERROR(J21/E21-1,""),"") -> 0.068851316 | K22: =IF(AND(ISNUMBER(K21),ISNUMBER(F21)),IFERROR(K21/F21-1,""),"") -> 0.084559393 | L22: =IF(AND(ISNUMBER(L21),ISNUMBER(G21)),IFERROR(L21/G21-1,""),"") -> 0.18992067 | M22: =IF(AND(ISNUMBER(M21),ISNUMBER(H21)),IFERROR(M21/H21-1,""),"") -> 0.12684972 | N22: =IF(AND(ISNUMBER(N21),ISNUMBER(I21)),IFERROR(N21/I21-1,""),"") -> 0.14435696 | O22: =IF(AND(ISNUMBER(O21),ISNUMBER(J21)),IFERROR(O21/J21-1,""),"") -> 0.30300065 | ... R22: =IF(AND(ISNUMBER(R21),ISNUMBER(M21)),IFERROR(R21/M21-1,""),"") -> 0.23931401 | S22: =IF(AND(ISNUMBER(S21),ISNUMBER(N21)),IFERROR(S21/IF(ISNUMBER(N23),N23,N21)-1,""),"") -> 0.33858622 | T22: =IF(AND(ISNUMBER(T21),ISNUMBER(O21)),IFERROR(T21/IF(ISNUMBER(O23),O23,O21)-1,""),"") -> 0.2726916 | U22: =IF(AND(ISNUMBER(U21),ISNUMBER(P21)),IFERROR(U21/P21-1,""),"") -> 0.089522983 | V22: =IF(AND(ISNUMBER(V21),ISNUMBER(Q21)),IFERROR(V21/Q21-1,""),"") -> 0.088657575 | W22: =$W$21/$R$23-1 -> 0.21097793 | X22: =IF(AND(ISNUMBER(X21),ISNUMBER(W21)),IFERROR(X21/W21-1,""),"") -> 0.1352329 | Y22: =IF(AND(ISNUMBER(Y21),ISNUMBER(X21)),IFERROR(Y21/X21-1,""),"") -> 0.10764843 | Z22: =IF(AND(ISNUMBER(Z21),ISNUMBER(Y21)),IFERROR(Z21/Y21-1,""),"") -> 0.08766467 | AA22: =IF(AND(ISNUMBER(AA21),ISNUMBER(Z21)),IFERROR(AA21/Z21-1,""),"") -> 0.075362255 | AB22: =IF(AND(ISNUMBER(AB21),ISNUMBER(AA21)),IFERROR(AB21/AA21-1,""),"") -> 0.065428508 | AK22: 2H-26E share repurchases ($m) | AL22: 5000 | AM22: 4000 | AN22: 3000 | AO22: H1-26 $4,527m (Q2 $2,012m at $292.17); ~$18.0bn left on the $20bn authorization (Dec-2025) at 30-Jun-2026. Scenario input (assumption).
B23: Memo: CES revenue on the Jan-2026 structure (recast) | N23: 6663 | O23: 7646 | R23: 31900
B24: Memo: CES segment revenue as reported | C24: 18813 | D24: 5232 | E24: 5737 | F24: 6457 | G24: 6429 | H24: 23855 | I24: 6095 | J24: 6132 | K24: 7003 | L24: 7650 | M24: 26881 | N24: 6977 | O24: 7990 | P24: 8880 | Q24: 9468 | R24: 33314 | S24: 8920 | T24: 9731 | AK24: Q3/Q4-26E and FY26 point estimates (all cases)
B25: Check: services + equipment vs CES segment revenue (should be 0) | C25: =IF(ISNUMBER(C24),IF(ABS(C21-C24)<=1.01,0,ROUND(C21-C24,0)),"") -> 0 | D25: =IF(ISNUMBER(D24),IF(ABS(D21-D24)<=1.01,0,ROUND(D21-D24,0)),"") -> 0 | E25: =IF(ISNUMBER(E24),IF(ABS(E21-E24)<=1.01,0,ROUND(E21-E24,0)),"") -> 0 | F25: =IF(ISNUMBER(F24),IF(ABS(F21-F24)<=1.01,0,ROUND(F21-F24,0)),"") -> 0 | G25: =IF(ISNUMBER(G24),IF(ABS(G21-G24)<=1.01,0,ROUND(G21-G24,0)),"") -> 0 | H25: =IF(ISNUMBER(H24),IF(ABS(H21-H24)<=1.01,0,ROUND(H21-H24,0)),"") -> 0 | I25: =IF(ISNUMBER(I24),IF(ABS(I21-I24)<=1.01,0,ROUND(I21-I24,0)),"") -> 0 | J25: =IF(ISNUMBER(J24),IF(ABS(J21-J24)<=1.01,0,ROUND(J21-J24,0)),"") -> 0 | ... T25: =IF(ISNUMBER(T24),IF(ABS(T21-T24)<=1.01,0,ROUND(T21-T24,0)),"") -> 0 | AK25: Q3/Q4-26E interest and other financial charges ($m per quarter) | AM25: 222 | AO25: H1-26 $444m (run-rate).
B26: CES segment operating profit | C26: 4164 | D26: 1214 | E26: 1389 | F26: 1545 | G26: 1495 | H26: 5643 | I26: 1419 | J26: 1679 | K26: 1799 | L26: 2158 | M26: 7055 | N26: 1920 | O26: 2232 | P26: 2436 | Q26: 2273 | R26: 8861 | S26: 2356 | T26: 2657 | U26: =U21*U27 -> 2541.7847 | V26: =V21*V27 -> 2707.9583 | W26: =SUM(S26:V26) -> 10262.743 | X26: =X21*X27 -> 11752.944 | Y26: =Y21*Y27 -> 13212.431 | Z26: =Z21*Z27 -> 14582.028 | AA26: =AA21*AA27 -> 15908.223 | AB26: =AB21*AB27 -> 17070.139 | AC26: Segment profit as reported (company measure; after amortization and stock-based compensation). Forecast = segment revenue × margin. | AE26: =IFERROR((AB26/W26)^(1/5)-1,"n/m") -> 0.10712006 | AF26: =IFERROR((R26/C26)^(1/3)-1,"n/m") -> 0.28624591 | AG26: =IFERROR((R26/H26)^(1/2)-1,"n/m") -> 0.25310177 | AH26: =IFERROR(W26/R26-1,"n/m") -> 0.15819242 | AK26: Q3/Q4-26E adjusted effective tax rate | AM26: 0.165 | AO26: H1-26 15.7% (Q2 16.7%); FY2025 17.3%. Not guided in the releases — assumption.
B27: CES operating profit margin % | C27: =IF(AND(ISNUMBER(C26),ISNUMBER(C21)),IFERROR(C26/C21,""),"") -> 0.22133631 | D27: =IF(AND(ISNUMBER(D26),ISNUMBER(D21)),IFERROR(D26/D21,""),"") -> 0.23203364 | E27: =IF(AND(ISNUMBER(E26),ISNUMBER(E21)),IFERROR(E26/E21,""),"") -> 0.2421126 | F27: =IF(AND(ISNUMBER(F26),ISNUMBER(F21)),IFERROR(F26/F21,""),"") -> 0.23927521 | G27: =IF(AND(ISNUMBER(G26),ISNUMBER(G21)),IFERROR(G26/G21,""),"") -> 0.23254005 | H27: =IF(AND(ISNUMBER(H26),ISNUMBER(H21)),IFERROR(H26/H21,""),"") -> 0.23655418 | I27: =IF(AND(ISNUMBER(I26),ISNUMBER(I21)),IFERROR(I26/I21,""),"") -> 0.23277559 | J27: =IF(AND(ISNUMBER(J26),ISNUMBER(J21)),IFERROR(J26/J21,""),"") -> 0.27380952 | ... T27: =IF(AND(ISNUMBER(T26),ISNUMBER(T21)),IFERROR(T26/T21,""),"") -> 0.27304491 | U27: =$W$28+$W$123 -> 0.26274733 | V27: =$W$28+$W$123 -> 0.26274733 | W27: =IF(AND(ISNUMBER(W26),ISNUMBER(W21)),IFERROR(W26/W21,""),"") -> 0.26566635 | X27: =CHOOSE(MATCH($AC$2,{"Bull","Base","Bear"},0),$AL$53,$AM$53,$AN$53) -> 0.268 | Y27: =CHOOSE(MATCH($AC$2,{"Bull","Base","Bear"},0),$AL$54,$AM$54,$AN$54) -> 0.272 | Z27: =CHOOSE(MATCH($AC$2,{"Bull","Base","Bear"},0),$AL$55,$AM$55,$AN$55) -> 0.276 | AA27: =CHOOSE(MATCH($AC$2,{"Bull","Base","Bear"},0),$AL$56,$AM$56,$AN$56) -> 0.28 | AB27: =CHOOSE(MATCH($AC$2,{"Bull","Base","Bear"},0),$AL$57,$AM$57,$AN$57) -> 0.282 | AC27: Q3/Q4-26E: 2H margin implied by the CES operating-profit guide end-point + operating-profit calibration Δ (Group block). 2027E+: scenario lever. | AE27: =IFERROR(AVERAGE(X27,Y27,Z27,AA27,AB27),"n/m") -> 0.2756 | AF27: =IFERROR(AVERAGE(H27,M27,R27),"n/m") -> 0.25499716 | AG27: =IFERROR(AVERAGE(M27,R27),"n/m") -> 0.26421865 | AH27: =IFERROR(W27+0,"n/m") -> 0.26566635 | AK27: Tax rate on adjusting items | AM27: 0.21 | AO27: H1-26 company tax effects ~21% (non-operating benefit, separation, restructuring).
B28: 2H-26E margin before calibration = (CES operating-profit guide − H1-26) ÷ 2H-26E revenue | W28: =(CHOOSE(MATCH($AC$2,{"Bull","Base","Bear"},0),$AL$19,$AM$19,$AN$19)-SUM(S26:T26))/SUM(U21:V21) -> 0.26461202 | AK28: 2H-26E capex % of adjusted revenue | AM28: 0.028 | AO28: H1-26 2.7%; FY2025 3.0% (not guided).
B29: Memo: CES operating profit on the Jan-2026 structure (recast) | N29: 1910 | O29: 2208 | R29: 8600 | AK29: 2H-26E provision less cash taxes paid ($m) | AM29: 400 | AO29: H1-26 $517m; FY2025 $666m.
B30: Incremental margin (Δ profit / Δ revenue) | H30: =IFERROR((H26-C26)/(H21-C21),"") -> 0.29333598 | I30: =IFERROR((I26-D26)/(I21-D21),"") -> 0.23726852 | J30: =IFERROR((J26-E26)/(J21-E21),"") -> 0.73417722 | K30: =IFERROR((K26-F26)/(K21-F21),"") -> 0.46520147 | L30: =IFERROR((L26-G26)/(L21-G21),"") -> 0.54299754 | M30: =IFERROR((M26-H26)/(M21-H21),"") -> 0.4666226 | N30: =IFERROR((N26-I26)/(N21-I21),"") -> 0.56931818 | O30: =IFERROR((O26-J26)/(O21-J21),"") -> 0.29763186 | ... W30: =IFERROR((W26-R26)/(W21-R21),"") -> 0.26367407 | X30: =IFERROR((X26-W26)/(X21-W21),"") -> 0.28525655 | Y30: =IFERROR((Y26-X26)/(Y21-X21),"") -> 0.309158 | Z30: =IFERROR((Z26-Y26)/(Z21-Y21),"") -> 0.32162842 | AA30: =IFERROR((AA26-Z26)/(AA21-Z21),"") -> 0.33307697 | AB30: =IFERROR((AB26-AA26)/(AB21-AA21),"") -> 0.31256772 | AK30: FY26 pension / OPEB cash contributions & payments ($m) | AM30: 350 | AO30: H1-26: pension line −$526m incl. −$354m non-cash benefit income → ~$170m cash per half.
B31: Operating statistics (memo):
B32: Commercial engine deliveries (units; incl. LEAP) | C32: 1663 | D32: 481 | E32: 543 | F32: 520 | G32: 531 | H32: 2075 | I32: 489 | J32: 402 | K32: 501 | L32: 519 | M32: 1911 | N32: 444 | O32: 551 | P32: 664 | Q32: 727 | R32: 2386 | S32: 640 | T32: 659 | AK32: Maximum net debt / adjusted EBITDA before buybacks (x) — buyback floor 2027E+ | AL32: 1.5 | AM32: 1 | AN32: 0.5 | AO32: Net debt ~$9.8bn at 30-Jun-2026 (borrowings $19.2bn − cash $9.3bn) ≈ 0.8x adjusted EBITDA (model definition); ~1.4x pro forma for CPP ($11.75bn, 2H-27). Target = leverage up to which surplus cash is returned via buybacks (assumption; GE publishes no leverage target in its filings).
B33: of which LEAP engines (units) | C33: 1136 | D33: 366 | E33: 419 | F33: 389 | G33: 396 | H33: 1570 | I33: 367 | J33: 297 | K33: 365 | L33: 378 | M33: 1407 | N33: 319 | O33: 410 | P33: 511 | Q33: 562 | R33: 1802 | S33: 520 | T33: 510
B34: Implied CES equipment revenue per commercial engine ($m; incl. spare engines, other equipment) | C34: =IF(ISNUMBER(C32),IFERROR(C16/C32,""),"") -> 3.0817799 | D34: =IF(ISNUMBER(D32),IFERROR(D16/D32,""),"") -> 2.7006237 | E34: =IF(ISNUMBER(E32),IFERROR(E16/E32,""),"") -> 2.9594843 | F34: =IF(ISNUMBER(F32),IFERROR(F16/F32,""),"") -> 3.0846154 | G34: =IF(ISNUMBER(G32),IFERROR(G16/G32,""),"") -> 3.1242938 | H34: =IF(ISNUMBER(H32),IFERROR(H16/H32,""),"") -> 2.973012 | I34: =IF(ISNUMBER(I32),IFERROR(I16/I32,""),"") -> 3.4887526 | J34: =IF(ISNUMBER(J32),IFERROR(J16/J32,""),"") -> 3.5497512 | ... T34: =IF(ISNUMBER(T32),IFERROR(T16/T32,""),"") -> 3.4855842 | AK34: CES_SV (CES services revenue y/y) | AL34: 0.03 | AM34: Δ → | AN34: -0.05 | AO34: FY26 guided low 20s; H1-26 +32% (shop-visit output, spare parts, price). LEAP shop-visit ramp and a young fleet sustain double-digit growth into 2027–28, normalising to high-single digits (assumption).
B35: Internal shop visit revenue growth % (as reported; n/d for derived Q4s) | C35: 0.22 | E35: 0.12 | F35: 0.02 | H35: 0.1 | I35: 0.21 | J35: 0.14 | K35: -0.01 | M35: 0.03 | N35: 0.11 | O35: 0.22 | P35: 0.33 | R35: 0.24 | S35: 0.35 | T35: 0.25 | AK35: 2027E | AL35: =AM35+$AL$34 -> 0.17 | AM35: 0.14 | AN35: =AM35+$AN$34 -> 0.09
B36: CES orders | D36: 6194 | E36: 6653 | F36: 7603 | G36: 8642 | H36: 29092 | I36: 8315 | J36: 9152 | K36: 9799 | L36: 12947 | M36: 40213 | N36: 9583 | O36: 11690 | P36: 10301 | Q36: 22842 | R36: 54415 | S36: 17331 | T36: 12932 | AK36: 2028E | AL36: =AM36+$AL$34 -> 0.14 | AM36: 0.11 | AN36: =AM36+$AN$34 -> 0.06
B37: CES book-to-bill (orders / revenue) | C37: =IF(ISNUMBER(C36),IFERROR(C36/C21,""),"") | D37: =IF(ISNUMBER(D36),IFERROR(D36/D21,""),"") -> 1.1838685 | E37: =IF(ISNUMBER(E36),IFERROR(E36/E21,""),"") -> 1.1596653 | F37: =IF(ISNUMBER(F36),IFERROR(F36/F21,""),"") -> 1.1774818 | G37: =IF(ISNUMBER(G36),IFERROR(G36/G21,""),"") -> 1.3442215 | H37: =IF(ISNUMBER(H36),IFERROR(H36/H21,""),"") -> 1.2195347 | I37: =IF(ISNUMBER(I36),IFERROR(I36/I21,""),"") -> 1.3640092 | J37: =IF(ISNUMBER(J36),IFERROR(J36/J21,""),"") -> 1.4924984 | ... T37: =IF(ISNUMBER(T36),IFERROR(T36/T21,""),"") -> 1.3289487 | AK37: 2029E | AL37: =AM37+$AL$34 -> 0.12 | AM37: 0.09 | AN37: =AM37+$AN$34 -> 0.04
B38: CES remaining performance obligation (period end) | E38: 137535 | F38: 137535 | H38: 137535 | I38: 153644 | J38: 143004 | K38: 148513 | M38: 153644 | N38: 153752 | O38: 155232 | P38: 157196 | R38: 169822 | S38: 181055 | T38: 179900 | AK38: 2030E | AL38: =AM38+$AL$34 -> 0.11 | AM38: 0.08 | AN38: =AM38+$AN$34 -> 0.03
AK39: 2031E | AL39: =AM39+$AL$34 -> 0.1 | AM39: 0.07 | AN39: =AM39+$AN$34 -> 0.02
B40: Defense & Propulsion Technologies (DPT) — Defense & Systems (military engines, Aeroderivative from Q1-26) · Propulsion & Additive Technologies (Avio Aero, Unison, Dowty, Colibrium Additive) | AC40: DPT — modelling logic | AK40: CES_EQ (CES equipment revenue y/y) | AL40: 0.04 | AM40: Δ → | AN40: -0.08 | AO40: FY26 guided ~20% (LEAP deliveries +41% in H1-26); airframer rate increases (A320neo / 737 MAX), GE9X entry into service (assumption).
...

Sheet Bull-Base-Bear
B2: General Electric Company, operating as GE Aerospace (GE) — Bull / Base / Bear Case P&L Summary | J2: Share price ($): | K2: =Model!$X$471 -> 308
B3: Company non-GAAP definitions (adjusted revenue, operating profit, adjusted EPS, FCF); adjusted EBITDA = operating profit + D&A (model) · USD millions · Live panel linked to Model — toggle scenario via Model!AC2. Bull and Bear panels are value snapshots generated from the Model with the switch set to each case. FY2026E = H1 actual + 2H calibrated to the FY26 guidance (adjusted revenue high-teens, operating profit $10.55–10.75B). CPP ($11.75bn) from 2H-27. | J3: As of: | K3: =TODAY() -> 2026-10-13 00:00:00
B5: Scenario: | C5: =Model!$AC$2 -> Base | N5: Scenario: | O5: Bull | P5: Snapshot (values) — Model run with switch = Bull | Z5: Scenario: | AA5: Bear | AB5: Snapshot (values) — Model run with switch = Bear
B7: (USDm, except EPS and shares) | C7: 2026E | D7: 2027E | E7: 2028E | F7: 2029E | G7: 2030E | H7: 2031E | I7: 26-'31 CAGR | J7: LT Hist Avg | K7: LT Hist Min | L7: LT Hist Max | N7: (USDm, except EPS and shares) | O7: 2026E | P7: 2027E | Q7: 2028E | R7: 2029E | S7: 2030E | T7: 2031E | U7: 26-'31 CAGR | V7: LT Hist Avg | W7: LT Hist Min | X7: LT Hist Max | Z7: (USDm, except EPS and shares) | AA7: 2026E | AB7: 2027E | AC7: 2028E | AD7: 2029E | AE7: 2030E | AF7: 2031E | AG7: 26-'31 CAGR | AH7: LT Hist Avg | AI7: LT Hist Min | AJ7: LT Hist Max
B9: Adjusted revenue | C9: =Model!W105 -> 49939.96 | D9: =Model!X105 -> 56345.539 | E9: =Model!Y105 -> 63090.178 | F9: =Model!Z105 -> 68257.863 | G9: =Model!AA105 -> 73294.628 | H9: =Model!AB105 -> 77986.503 | I9: =IFERROR((H9/C9)^(1/5)-1,"n/m") -> 0.093236822 | N9: Adjusted revenue | O9: 50363.18 | P9: 58481.533 | Q9: 67406.165 | R9: 75131.953 | S9: 83102.711 | T9: 91082.231 | U9: 0.12580741 | Z9: Adjusted revenue | AA9: 49516.74 | AB9: 53261.867 | AC9: 56916.617 | AD9: 58612.544 | AE9: 59854.52 | AF9: 60567.585 | AG9: 0.041112457
B10: Adjusted revenue y/y % | D10: =IFERROR(D9/C9-1,"") -> 0.12826561 | E10: =IFERROR(E9/D9-1,"") -> 0.11970137 | F10: =IFERROR(F9/E9-1,"") -> 0.0819095 | G10: =IFERROR(G9/F9-1,"") -> 0.073790261 | H10: =IFERROR(H9/G9-1,"") -> 0.064013891 | N10: Adjusted revenue y/y % | P10: 0.16119619 | Q10: 0.15260599 | R10: 0.11461545 | S10: 0.10609013 | T10: 0.096019973 | Z10: Adjusted revenue y/y % | AB10: 0.075633548 | AC10: 0.068618507 | AD10: 0.029796703 | AE10: 0.021189601 | AF10: 0.011913299
B11: CES revenue y/y % | C11: =Model!W259 -> 0.21097793 | D11: =Model!X259 -> 0.1352329 | E11: =Model!Y259 -> 0.10764843 | F11: =Model!Z259 -> 0.08766467 | G11: =Model!AA259 -> 0.075362255 | H11: =Model!AB259 -> 0.065428508 | N11: CES revenue y/y % | O11: 0.22099388 | P11: 0.1676162 | Q11: 0.14 | R11: 0.12 | S11: 0.10763175 | T11: 0.097648068 | Z11: CES revenue y/y % | AA11: 0.20096197 | AB11: 0.078083508 | AC11: 0.050803569 | AD11: 0.031073156 | AE11: 0.019177727 | AF11: 0.0095937405
B12: Adjusted EBITDA (operating profit + D&A) | C12: =Model!W224 -> 11907 | D12: =Model!X224 -> 13777.983 | E12: =Model!Y224 -> 15833.7 | F12: =Model!Z224 -> 17525.083 | G12: =Model!AA224 -> 19197.499 | H12: =Model!AB224 -> 20658.915 | I12: =IFERROR((H12/C12)^(1/5)-1,"n/m") -> 0.11650592 | N12: Adjusted EBITDA (operating profit + D&A) | O12: 12007 | P12: 14892.377 | Q12: 17582.406 | R12: 20025.785 | S12: 22571.531 | T12: 24993.28 | U12: 0.15791785 | Z12: Adjusted EBITDA (operating profit + D&A) | AA12: 11807 | AB12: 11991.243 | AC12: 13184.022 | AD12: 13893.143 | AE12: 14476.005 | AF12: 14826.737 | AG12: 0.046601143
B13: Adjusted EBITDA margin % | C13: =IFERROR(C12/C9,"") -> 0.2384263 | D13: =IFERROR(D12/D9,"") -> 0.2445266 | E13: =IFERROR(E12/E9,"") -> 0.25096933 | F13: =IFERROR(F12/F9,"") -> 0.25674819 | G13: =IFERROR(G12/G9,"") -> 0.26192231 | H13: =IFERROR(H12/H9,"") -> 0.26490372 | J13: =IFERROR(AVERAGE(Model!C225,Model!H225,Model!M225,Model!R225),"") -> 0.23129992 | K13: =IFERROR(MIN(Model!C225,Model!H225,Model!M225,Model!R225),"") -> 0.21083263 | L13: =IFERROR(MAX(Model!C225,Model!H225,Model!M225,Model!R225),"") -> 0.24280516 | N13: Adjusted EBITDA margin % | O13: 0.2384083 | P13: 0.25465093 | Q13: 0.26084271 | R13: 0.26654152 | S13: 0.27161005 | T13: 0.27440347 | V13: 0.23129992 | W13: 0.21083263 | X13: 0.24280516 | Z13: Adjusted EBITDA margin % | AA13: 0.23844461 | AB13: 0.22513749 | AC13: 0.23163749 | AD13: 0.23703362 | AE13: 0.24185316 | AF13: 0.24479657 | AH13: 0.23129992 | AI13: 0.21083263 | AJ13: 0.24280516
B15: Profit before tax (GAAP) | C15: =Model!W172 -> 10301 | D15: =Model!X172 -> 12265.538 | E15: =Model!Y172 -> 13543.22 | F15: =Model!Z172 -> 15189.124 | G15: =Model!AA172 -> 16612.473 | H15: =Model!AB172 -> 17861.293 | I15: =IFERROR((H15/C15)^(1/5)-1,"n/m") -> 0.11636626 | N15: Profit before tax (GAAP) | O15: 10401 | P15: 13295.333 | Q15: 14851.545 | R15: 17055.756 | S15: 19196.207 | T15: 21234.648 | U15: 0.15343731 | Z15: Profit before tax (GAAP) | AA15: 10201 | AB15: 10539.014 | AC15: 11010.84 | AD15: 11771.555 | AE15: 12265.23 | AF15: 12565.889 | AG15: 0.042581692
B16: Profit before tax y/y % | D16: =IFERROR(D15/C15-1,"") -> 0.19071333 | E16: =IFERROR(E15/D15-1,"") -> 0.1041684 | F16: =IFERROR(F15/E15-1,"") -> 0.12152978 | G16: =IFERROR(G15/F15-1,"") -> 0.093708409 | H16: =IFERROR(H15/G15-1,"") -> 0.075173671 | N16: Profit before tax y/y % | P16: 0.27827452 | Q16: 0.11704944 | R16: 0.14841629 | S16: 0.12549727 | T16: 0.10618983 | Z16: Profit before tax y/y % | AB16: 0.0331354 | AC16: 0.044769441 | AD16: 0.069087869 | AE16: 0.041937878 | AF16: 0.024513154
B17: Profit margin (GAAP) % | C17: =IFERROR(C15/C9,"") -> 0.20626769 | D17: =IFERROR(D15/D9,"") -> 0.21768428 | E17: =IFERROR(E15/E9,"") -> 0.21466447 | F17: =IFERROR(F15/F9,"") -> 0.22252563 | G17: =IFERROR(G15/G9,"") -> 0.22665334 | H17: =IFERROR(H15/H9,"") -> 0.22903057 | J17: =IFERROR(AVERAGE(Model!C268,Model!H268,Model!M268,Model!R268),"") -> 0.19064439 | K17: =IFERROR(MIN(Model!C268,Model!H268,Model!M268,Model!R268),"") -> 0.052232403 | L17: =IFERROR(MAX(Model!C268,Model!H268,Model!M268,Model!R268),"") -> 0.29537739 | N17: Profit margin (GAAP) % | O17: 0.20651992 | P17: 0.22734242 | Q17: 0.22032918 | R17: 0.22701068 | S17: 0.23099375 | T17: 0.23313711 | V17: 0.19064439 | W17: 0.052232403 | X17: 0.29537739 | Z17: Profit margin (GAAP) % | AA17: 0.20601114 | AB17: 0.19787166 | AC17: 0.19345563 | AD17: 0.20083679 | AE17: 0.20491735 | AF17: 0.20746888 | AH17: 0.19064439 | AI17: 0.052232403 | AJ17: 0.29537739
B19: Adjusted Net Income | C19: =Model!W243 -> 8194.385 | D19: =Model!X243 -> 9444.0103 | E19: =Model!Y243 -> 10619.953 | F19: =Model!Z243 -> 11893.544 | G19: =Model!AA243 -> 13106.452 | H19: =Model!AB243 -> 14174.054 | I19: =IFERROR((H19/C19)^(1/5)-1,"n/m") -> 0.1158236 | N19: Adjusted Net Income | O19: 8277.885 | P19: 10298.74 | Q19: 11705.862 | R19: 13442.848 | S19: 15250.951 | T19: 16973.939 | U19: 0.15444341 | Z19: Adjusted Net Income | AA19: 8110.885 | AB19: 8010.9955 | AC19: 8518.0775 | AD19: 9056.9619 | AE19: 9498.2403 | AF19: 9778.8686 | AG19: 0.038111671
B21: FDSO (m) | C21: =Model!W190 -> 1044.7845 | D21: =Model!X190 -> 1034.8266 | E21: =Model!Y190 -> 1022.3489 | F21: =Model!Z190 -> 995.66575 | G21: =Model!AA190 -> 969.86928 | H21: =Model!AB190 -> 944.90357 | I21: =IFERROR((H21/C21)^(1/5)-1,"n/m") -> -0.019896018 | N21: FDSO (m) | O21: 1043.9728 | P21: 1018.643 | Q21: 989.22747 | R21: 953.90532 | S21: 918.12814 | T21: 881.99946 | U21: -0.033157292 | Z21: FDSO (m) | AA21: 1045.5962 | AB21: 1038.8223 | AC21: 1042.8223 | AD21: 1039.1397 | AE21: 1026.942 | AF21: 1015.0109 | AG21: -0.0059199843
B23: Adjusted EPS — Diluted ($) | C23: =Model!W248 -> 7.8431341 | D23: =Model!X248 -> 9.1261762 | E23: =Model!Y248 -> 10.387796 | F23: =Model!Z248 -> 11.945318 | G23: =Model!AA248 -> 13.513627 | H23: =Model!AB248 -> 15.00053 | I23: =IFERROR((H23/C23)^(1/5)-1,"n/m") -> 0.13847472 | N23: Adjusted EPS — Diluted ($) | O23: 7.9292151 | P23: 10.110255 | Q23: 11.833337 | R23: 14.092435 | S23: 16.610918 | T23: 19.24484 | U23: 0.19403436 | Z23: Adjusted EPS — Diluted ($) | AA23: 7.7571868 | AB23: 7.7116133 | AC23: 8.1682928 | AD23: 8.7158268 | AE23: 9.2490519 | AF23: 9.6342498 | AG23: 0.044293874
B24: EPS y/y % | D24: =IFERROR(D23/C23-1,"") -> 0.16358792 | E24: =IFERROR(E23/D23-1,"") -> 0.13824194 | F24: =IFERROR(F23/E23-1,"") -> 0.1499376 | G24: =IFERROR(G23/F23-1,"") -> 0.13129074 | H24: =IFERROR(H23/G23-1,"") -> 0.11002984 | N24: EPS y/y % | P24: 0.27506382 | Q24: 0.17042913 | R24: 0.19090956 | S24: 0.17871173 | T24: 0.15856574 | Z24: EPS y/y % | AB24: -0.005875006 | AC24: 0.059219707 | AD24: 0.067031638 | AE24: 0.061178947 | AF24: 0.041647283
B26: P / E (x) — assumed (adjusted EPS) | G26: 36 | H26: 36 | N26: P / E (x) — assumed (adjusted EPS) | S26: 42 | T26: 42 | Z26: P / E (x) — assumed (adjusted EPS) | AD26: 28 | AE26: 28 | AF26: 28
B27: Price Target ($) | G27: =G26*G23 -> 486.49058 | H27: =H26*H23 -> 540.01907 | N27: Price Target ($) | S27: =S26*S23 -> 697.65856 | T27: =T26*T23 -> 808.2833 | Z27: Price Target ($) | AD27: =AD26*AD23 -> 244.04315 | AE27: =AE26*AE23 -> 258.97345 | AF27: =AF26*AF23 -> 269.75899
B28: Upside / (Downside) vs current | G28: =IFERROR(G27/$K$2-1,"") -> 0.57951488 | H28: =IFERROR(H27/$K$2-1,"") -> 0.75330866 | N28: Upside / (Downside) vs current | S28: =IFERROR(S27/$K$2-1,"") -> 1.2651252 | T28: =IFERROR(T27/$K$2-1,"") -> 1.6242964 | Z28: Upside / (Downside) vs current | AD28: =IFERROR(AD27/$K$2-1,"") -> -0.20765211 | AE28: =IFERROR(AE27/$K$2-1,"") -> -0.1591771 | AF28: =IFERROR(AF27/$K$2-1,"") -> -0.12415911
B29: IRR (to 31-Dec of Y-1) | G29: =IFERROR((G27/$K$2)^(1/((DATE(2030-1,12,31)-$K$3)/365.25))-1,"") -> 0.15268677 | H29: =IFERROR((H27/$K$2)^(1/((DATE(2031-1,12,31)-$K$3)/365.25))-1,"") -> 0.14244997 | N29: IRR (to 31-Dec of Y-1) | S29: =IFERROR((S27/$K$2)^(1/((DATE(2030-1,12,31)-$K$3)/365.25))-1,"") -> 0.28937959 | T29: =IFERROR((T27/$K$2)^(1/((DATE(2031-1,12,31)-$K$3)/365.25))-1,"") -> 0.25712805 | Z29: IRR (to 31-Dec of Y-1) | AD29: =IFERROR((AD27/$K$2)^(1/((DATE(2029-1,12,31)-$K$3)/365.25))-1,"") -> -0.099635088 | AE29: =IFERROR((AE27/$K$2)^(1/((DATE(2030-1,12,31)-$K$3)/365.25))-1,"") -> -0.052467044 | AF29: =IFERROR((AF27/$K$2)^(1/((DATE(2031-1,12,31)-$K$3)/365.25))-1,"") -> -0.030953355
B31: Free Cash Flow | C31: =Model!W281 -> 9050 | D31: =Model!X281 -> 11058.815 | E31: =Model!Y281 -> 12393.114 | F31: =Model!Z281 -> 13376.764 | G31: =Model!AA281 -> 14574.508 | H31: =Model!AB281 -> 15514.258 | I31: =IFERROR((H31/C31)^(1/5)-1,"n/m") -> 0.11382378 | N31: Free Cash Flow | O31: 9200 | P31: 12276.871 | Q31: 13885.486 | R31: 15396.073 | S31: 17253.113 | T31: 18895.307 | U31: 0.15481715 | Z31: Free Cash Flow | AA31: 8900 | AB31: 9058.2312 | AC31: 9740.4284 | AD31: 9940.2015 | AE31: 10319.923 | AF31: 10468.999 | AG31: 0.033006439
B32: FCF % | C32: =IFERROR(C31/C9,"") -> 0.18121761 | D32: =IFERROR(D31/D9,"") -> 0.1962678 | E32: =IFERROR(E31/E9,"") -> 0.19643491 | F32: =IFERROR(F31/F9,"") -> 0.19597397 | G32: =IFERROR(G31/G9,"") -> 0.19884824 | H32: =IFERROR(H31/H9,"") -> 0.19893517 | J32: =IFERROR(AVERAGE(Model!C293,Model!H293,Model!M293,Model!R293),"") -> 0.16787129 | K32: =IFERROR(MIN(Model!C293,Model!H293,Model!M293,Model!R293),"") -> 0.14844019 | L32: =IFERROR(MAX(Model!C293,Model!H293,Model!M293,Model!R293),"") -> 0.1817967 | N32: FCF % | O32: 0.18267314 | P32: 0.20992731 | Q32: 0.20599727 | R32: 0.20492044 | S32: 0.20761192 | T32: 0.20745328 | V32: 0.16787129 | W32: 0.14844019 | X32: 0.1817967 | Z32: FCF % | AA32: 0.1797372 | AB32: 0.17006973 | AC32: 0.17113506 | AD32: 0.16959171 | AE32: 0.17241677 | AF32: 0.17284821 | AH32: 0.16787129 | AI32: 0.14844019 | AJ32: 0.1817967
B33: FCF / share ($) | C33: =IFERROR(C31/C21,"") -> 8.6620733 | D33: =IFERROR(D31/D21,"") -> 10.686635 | E33: =IFERROR(E31/E21,"") -> 12.122196 | F33: =IFERROR(F31/F21,"") -> 13.434995 | G33: =IFERROR(G31/G21,"") -> 15.027291 | H33: =IFERROR(H31/H21,"") -> 16.41888 | N33: FCF / share ($) | O33: 8.81249 | P33: 12.052182 | Q33: 14.036697 | R33: 16.140043 | S33: 18.791618 | T33: 21.423264 | Z33: FCF / share ($) | AA33: 8.5118902 | AB33: 8.7197123 | AC33: 9.3404493 | AD33: 9.5657987 | AE33: 10.049178 | AF33: 10.314174
B34: FCF Yield (on PT) | F34: =IFERROR(F33/F$27,"") | G34: =IFERROR(G33/G$27,"") -> 0.030889172 | H34: =IFERROR(H33/H$27,"") -> 0.030404259 | N34: FCF Yield (on PT) | R34: =IFERROR(R33/R$27,"") | S34: =IFERROR(S33/S$27,"") -> 0.026935265 | T34: =IFERROR(T33/T$27,"") -> 0.026504648 | Z34: FCF Yield (on PT) | AD34: =IFERROR(AD33/AD$27,"") -> 0.039197161 | AE34: =IFERROR(AE33/AE$27,"") -> 0.038803892 | AF34: =IFERROR(AF33/AF$27,"") -> 0.038234772
B35: Adjusted EBITDA (pro forma CPP full year in 2027E) | C35: =Model!W227 -> 11907 | D35: =Model!X227 -> 14116.983 | E35: =Model!Y227 -> 15833.7 | F35: =Model!Z227 -> 17525.083 | G35: =Model!AA227 -> 19197.499 | H35: =Model!AB227 -> 20658.915 | I35: =IFERROR((H35/C35)^(1/5)-1,"n/m") -> 0.11650592 | N35: Adjusted EBITDA (pro forma CPP full year in 2027E) | O35: 12007 | P35: 15231.377 | Q35: 17582.406 | R35: 20025.785 | S35: 22571.531 | T35: 24993.28 | U35: 0.15791785 | Z35: Adjusted EBITDA (pro forma CPP full year in 2027E) | AA35: 11807 | AB35: 12330.243 | AC35: 13184.022 | AD35: 13893.143 | AE35: 14476.005 | AF35: 14826.737 | AG35: 0.046601143
B36: Adjusted EBITDA (pro forma) % of adjusted revenue | C36: =IFERROR(C35/C9,"") -> 0.2384263 | D36: =IFERROR(D35/D9,"") -> 0.25054305 | E36: =IFERROR(E35/E9,"") -> 0.25096933 | F36: =IFERROR(F35/F9,"") -> 0.25674819 | G36: =IFERROR(G35/G9,"") -> 0.26192231 | H36: =IFERROR(H35/H9,"") -> 0.26490372 | J36: =IFERROR(AVERAGE(Model!C267,Model!H267,Model!M267,Model!R267),"") -> 0.23129992 | K36: =IFERROR(MIN(Model!C267,Model!H267,Model!M267,Model!R267),"") -> 0.21083263 | L36: =IFERROR(MAX(Model!C267,Model!H267,Model!M267,Model!R267),"") -> 0.24280516 | N36: Adjusted EBITDA (pro forma) % of adjusted revenue | O36: 0.2384083 | P36: 0.26044764 | Q36: 0.26084271 | R36: 0.26654152 | S36: 0.27161005 | T36: 0.27440347 | V36: 0.23129992 | W36: 0.21083263 | X36: 0.24280516 | Z36: Adjusted EBITDA (pro forma) % of adjusted revenue | AA36: 0.23844461 | AB36: 0.23150227 | AC36: 0.23163749 | AD36: 0.23703362 | AE36: 0.24185316 | AF36: 0.24479657 | AH36: 0.23129992 | AI36: 0.21083263 | AJ36: 0.24280516
B38: Net Debt | C38: =Model!W465 -> 10558.145 | D38: =Model!X465 -> 14116.983 | E38: =Model!Y465 -> 15833.7 | F38: =Model!Z465 -> 17525.083 | G38: =Model!AA465 -> 19197.499 | H38: =Model!AB465 -> 20658.915 | N38: Net Debt | O38: 11406.619 | P38: 22847.065 | Q38: 26373.61 | R38: 30038.677 | S38: 33857.297 | T38: 37489.92 | Z38: Net Debt | AA38: 9709.6708 | AB38: 14777.915 | AC38: 7857.8792 | AD38: 6946.5717 | AE38: 7238.0024 | AF38: 7413.3686
B39: Net Debt / Adjusted EBITDA (x) | C39: =IFERROR(C38/C35,"") -> 0.88671747 | D39: =IFERROR(D38/D35,"") -> 1 | E39: =IFERROR(E38/E35,"") -> 1 | F39: =IFERROR(F38/F35,"") -> 1 | G39: =IFERROR(G38/G35,"") -> 1 | H39: =IFERROR(H38/H35,"") -> 1 | N39: Net Debt / Adjusted EBITDA (x) | O39: 0.94999741 | P39: 1.5 | Q39: 1.5 | R39: 1.5 | S39: 1.5 | T39: 1.5 | Z39: Net Debt / Adjusted EBITDA (x) | AA39: 0.82236562 | AB39: 1.1985097 | AC39: 0.59601532 | AD39: 0.5 | AE39: 0.5 | AF39: 0.5
B40: Share repurchases ($m; FY2026E = 2H) | D40: =Model!X338 -> 498.19707 | E40: =Model!Y338 -> 11301.234 | F40: =Model!Z338 -> 11604.27 | G40: =Model!AA338 -> 12438.656 | H40: =Model!AB338 -> 12783.288 | N40: Share repurchases ($m; FY2026E = 2H) | P40: 9104.8805 | Q40: 14175.837 | R40: 15203.405 | S40: 16916.03 | T40: 18051.397 | AB40: 0 | AC40: 0 | AD40: 5961.5058 | AE40: 7136.2275 | AF40: 6712.2417
B41: Implied avg buyback price ($) | D41: =Model!X337 -> 332.64 | E41: =Model!Y337 -> 359.2512 | F41: =Model!Z337 -> 387.9913 | G41: =Model!AA337 -> 419.0306 | H41: =Model!AB337 -> 452.55305 | N41: Implied avg buyback price ($) | P41: 332.64 | Q41: 359.2512 | R41: 387.9913 | S41: 419.0306 | T41: 452.55305 | AB41: 332.64 | AC41: 359.2512 | AD41: 387.9913 | AE41: 419.0306 | AF41: 452.55305
B42: Shares repurchased (m) | D42: =Model!X339 -> 1.4977065 | E42: =Model!Y339 -> 31.457749 | F42: =Model!Z339 -> 29.908584 | G42: =Model!AA339 -> 29.684362 | H42: =Model!AB339 -> 28.247049 | N42: Shares repurchased (m) | P42: 27.371575 | Q42: 39.4594 | R42: 39.184914 | S42: 40.369438 | T42: 39.887915 | AB42: 0 | AC42: 0 | AD42: 15.36505 | AE42: 17.030325 | AF42: 14.831945
B44: ROIC | C44: =Model!W447 -> 0.31935731 | D44: =Model!X447 -> 0.25925911 | E44: =Model!Y447 -> 0.29901478 | F44: =Model!Z447 -> 0.33208645 | G44: =Model!AA447 -> 0.36522213 | H44: =Model!AB447 -> 0.39301733 | J44: =IFERROR(AVERAGE(Model!C447,Model!H447,Model!M447,Model!R447),"") -> 0.20880481 | K44: =IFERROR(MIN(Model!C447,Model!H447,Model!M447,Model!R447),"") -> 0.1171593 | L44: =IFERROR(MAX(Model!C447,Model!H447,Model!M447,Model!R447),"") -> 0.27815169 | N44: ROIC | O44: 0.32310604 | P44: 0.28134415 | Q44: 0.33308913 | R44: 0.380477 | S44: 0.43098453 | T44: 0.47829921 | V44: 0.20880481 | W44: 0.1171593 | X44: 0.27815169 | Z44: ROIC | AA44: 0.31562637 | AB44: 0.21916681 | AC44: 0.23723464 | AD44: 0.24980269 | AE44: 0.26011366 | AF44: 0.26519029 | AH44: 0.20880481 | AI44: 0.1171593 | AJ44: 0.27815169
B45: RONTA | C45: =Model!W459 -> 0.32632787 | D45: =Model!X459 -> 0.35524766 | E45: =Model!Y459 -> 0.41804085 | F45: =Model!Z459 -> 0.47710265 | G45: =Model!AA459 -> 0.53911923 | H45: =Model!AB459 -> 0.5952346 | J45: =IFERROR(AVERAGE(Model!C459,Model!H459,Model!M459,Model!R459),"") -> 0.22066741 | K45: =IFERROR(MIN(Model!C459,Model!H459,Model!M459,Model!R459),"") -> 0.14409608 | L45: =IFERROR(MAX(Model!C459,Model!H459,Model!M459,Model!R459),"") -> 0.28281287 | N45: RONTA | O45: 0.33017559 | P45: 0.39096308 | Q45: 0.47916945 | R45: 0.57122216 | S45: 0.67616904 | T45: 0.78401146 | V45: 0.22066741 | W45: 0.14409608 | X45: 0.28281287 | Z45: RONTA | AA45: 0.32249882 | AB45: 0.2985539 | AC45: 0.32777984 | AD45: 0.34872349 | AE45: 0.36658021 | AF45: 0.37677742 | AH45: 0.22066741 | AI45: 0.14409608 | AJ45: 0.28281287
B47: Implied Market Cap (USDm) | F47: =IF(ISNUMBER(F27),F27*F21,"") | G47: =IF(ISNUMBER(G27),G27*G21,"") -> 471832.27 | H47: =IF(ISNUMBER(H27),H27*H21,"") -> 510265.95 | N47: Implied Market Cap (USDm) | R47: =IF(ISNUMBER(R27),R27*R21,"") | S47: =IF(ISNUMBER(S27),S27*S21,"") -> 640539.95 | T47: =IF(ISNUMBER(T27),T27*T21,"") -> 712905.44 | Z47: Implied Market Cap (USDm) | AD47: =IF(ISNUMBER(AD27),AD27*AD21,"") -> 253594.93 | AE47: =IF(ISNUMBER(AE27),AE27*AE21,"") -> 265950.73 | AF47: =IF(ISNUMBER(AF27),AF27*AF21,"") -> 273808.32
B48: (+) Net Debt & NCI | F48: =IF(ISNUMBER(F27),F38+Model!Z377,"") | G48: =IF(ISNUMBER(G27),G38+Model!AA377,"") -> 19424.499 | H48: =IF(ISNUMBER(H27),H38+Model!AB377,"") -> 20885.915 | N48: (+) Net Debt & NCI | R48: =IF(ISNUMBER(R27),R38+Model!Z377,"") | S48: =IF(ISNUMBER(S27),S38+Model!AA377,"") -> 34084.297 | T48: =IF(ISNUMBER(T27),T38+Model!AB377,"") -> 37716.92 | Z48: (+) Net Debt & NCI | AD48: =IF(ISNUMBER(AD27),AD38+Model!Z377,"") -> 7173.5717 | AE48: =IF(ISNUMBER(AE27),AE38+Model!AA377,"") -> 7465.0024 | AF48: =IF(ISNUMBER(AF27),AF38+Model!AB377,"") -> 7640.3686
B49: Implied Enterprise Value (USDm) | F49: =IF(ISNUMBER(F27),F47+F48,"") | G49: =IF(ISNUMBER(G27),G47+G48,"") -> 491256.77 | H49: =IF(ISNUMBER(H27),H47+H48,"") -> 531151.86 | N49: Implied Enterprise Value (USDm) | R49: =IF(ISNUMBER(R27),R47+R48,"") | S49: =IF(ISNUMBER(S27),S47+S48,"") -> 674624.25 | T49: =IF(ISNUMBER(T27),T47+T48,"") -> 750622.36 | Z49: Implied Enterprise Value (USDm) | AD49: =IF(ISNUMBER(AD27),AD47+AD48,"") -> 260768.51 | AE49: =IF(ISNUMBER(AE27),AE47+AE48,"") -> 273415.73 | AF49: =IF(ISNUMBER(AF27),AF47+AF48,"") -> 281448.69
B50: Implied EV / Adjusted EBITDA (x) | F50: =IFERROR(F49/F35,"") | G50: =IFERROR(G49/G35,"") -> 25.589624 | H50: =IFERROR(H49/H35,"") -> 25.71054 | N50: Implied EV / Adjusted EBITDA (x) | R50: =IFERROR(R49/R35,"") | S50: =IFERROR(S49/S35,"") -> 29.88828 | T50: =IFERROR(T49/T35,"") -> 30.032967 | Z50: Implied EV / Adjusted EBITDA (x) | AD50: =IFERROR(AD49/AD35,"") -> 18.769583 | AE50: =IFERROR(AE49/AE35,"") -> 18.887513 | AF50: =IFERROR(AF49/AF35,"") -> 18.98251

Sheet DCF
B2: DCF VALUATION — GENERAL ELECTRIC COMPANY, OPERATING AS GE AEROSPACE (GE)
B4: 1. WACC BUILD
B5: Risk-free rate (US 10Y govt) | C5: 0.0425 | D5: Assumption (~US 10Y Treasury yield, Oct-2026; government rate sources not reachable from the build environment); update to market
B6: Equity risk premium | C6: 0.05 | D6: Assumption: US implied ERP ~4.5–5.5%
B7: Levered beta | C7: 1.1 | D7: Assumption: aero-engine and aerospace peers (RTX, Safran, Rolls-Royce, MTU, HEI, TDG) ~1.0–1.3; long-cycle services annuity vs airline-traffic and production-rate cyclicality
B8: Cost of equity | C8: =C5+C7*C6 -> 0.0975
B9: Pre-tax cost of debt | C9: 0.05 | D9: A2 / A- ratings (Q2-26 10-Q); 2025 senior notes at 4.3% (2030) and 4.9% (2036); CPP acquisition debt (2027E) assumed ~5%
B10: Tax rate | C10: 0.17 | D10: Model 2027E+ adjusted effective tax rate (FY2025 adjusted 17.3%; H1-26 15.7%)
B11: After-tax cost of debt | C11: =C9*(1-C10) -> 0.0415
B12: Target D/V | C12: 0.05 | D12: Net debt ~$10bn at 30-Jun-2026 (~$15bn pro forma for CPP) vs ~$320bn market cap ($308.00 × ~1,043m diluted shares)
B13: WACC | C13: =C8*(1-C12)+C11*C12 -> 0.0947
B15: Valuation date (live) | C15: =TODAY() -> 2026-10-13 00:00:00 | D15: Periods = (31-Dec of the fiscal year − today) / 365.25; cash flows assumed at year end; FY2026E (ends 31-Dec-2026, ~3 months after the valuation date) is the base year
B16: 2. UNLEVERED FREE CASH FLOW BUILD (USDm)
D17: 2027E | E17: 2028E | F17: 2029E | G17: 2030E | H17: 2031E | I17: 2032E | J17: 2033E | K17: 2034E | L17: 2035E | M17: 2036E | N17: Terminal | P17: CAGR 27–31E | Q17: CAGR 27–36E
B18: Operating profit (full-cost) less restructuring & separation costs | D18: =Model!X229-Model!X231 -> 12107.876 | E18: =Model!Y229-Model!Y231 -> 13645.819 | F18: =Model!Z229-Model!Z231 -> 15355.543 | G18: =Model!AA229-Model!AA231 -> 16916.263 | H18: =Model!AB229-Model!AB231 -> 18277.789 | I18: =H18*(1+I$26) -> 19922.79 | J18: =I18*(1+J$26) -> 21516.613 | K18: =J18*(1+K$26) -> 23022.776 | L18: =K18*(1+L$26) -> 24404.143 | M18: =L18*(1+M$26) -> 25624.35 | P18: =IFERROR((H18/D18)^(1/(COLUMNS(D18:H18)-1))-1,"n/m") -> 0.10844442 | Q18: =IFERROR((M18/D18)^(1/(COLUMNS(D18:M18)-1))-1,"n/m") -> 0.086866239
B19: × (1 − tax rate) | D19: =1-$C$10 -> 0.83 | E19: =1-$C$10 -> 0.83 | F19: =1-$C$10 -> 0.83 | G19: =1-$C$10 -> 0.83 | H19: =1-$C$10 -> 0.83 | I19: =1-$C$10 -> 0.83 | J19: =1-$C$10 -> 0.83 | K19: =1-$C$10 -> 0.83 | ... M19: =1-$C$10 -> 0.83
B20: NOPAT | D20: =D18*D19 -> 10049.537 | E20: =E18*E19 -> 11326.03 | F20: =F18*F19 -> 12745.101 | G20: =G18*G19 -> 14040.498 | H20: =H18*H19 -> 15170.565 | I20: =I18*I19 -> 16535.916 | J20: =J18*J19 -> 17858.789 | K20: =K18*K19 -> 19108.904 | ... M20: =M18*M19 -> 21268.21
B21: plus D&A (PP&E depreciation + amortization of intangibles, incl. CPP PPA) | D21: =Model!X132 -> 1520.1069 | E21: =Model!Y132 -> 1937.88 | F21: =Model!Z132 -> 2069.5394 | G21: =Model!AA132 -> 2181.2358 | H21: =Model!AB132 -> 2281.1258 | I21: =H21*(1+I$26) -> 2486.4271 | J21: =I21*(1+J$26) -> 2685.3413 | K21: =J21*(1+K$26) -> 2873.3152 | L21: =K21*(1+L$26) -> 3045.7141 | M21: =L21*(1+M$26) -> 3197.9998
B22: − Capex (PP&E) and acquisitions (CPP $11.75bn in 2027E; M&A lever) | D22: =Model!X309+Model!X311 -> -13440.366 | E22: =Model!Y309+Model!Y311 -> -2018.8857 | F22: =Model!Z309+Model!Z311 -> -2615.9937 | G22: =Model!AA309+Model!AA311 -> -2698.8388 | H22: =Model!AB309+Model!AB311 -> -2839.5951 | I22: =Model!AB309*(1+I$26) -> -2550.1586 | J22: =I22*(1+J$26) -> -2754.1713 | K22: =J22*(1+K$26) -> -2946.9633 | L22: =K22*(1+L$26) -> -3123.7811 | M22: =L22*(1+M$26) -> -3279.9702
B23: − Δ Working capital (CF statement) | D23: =Model!X306 -> 1302.9663 | E23: =Model!Y306 -> 1361.9709 | F23: =Model!Z306 -> 1079.4279 | G23: =Model!AA306 -> 1045.4215 | H23: =Model!AB306 -> 968.0189 | I23: =H23*(1+I$26) -> 1055.1406 | J23: =I23*(1+J$26) -> 1139.5519 | K23: =J23*(1+K$26) -> 1219.3205 | L23: =K23*(1+L$26) -> 1292.4797 | M23: =L23*(1+M$26) -> 1357.1037
B24: Unlevered FCF | D24: =D20+D21+D22+D23 -> -567.75575 | E24: =E20+E21+E22+E23 -> 12606.995 | F24: =F20+F21+F22+F23 -> 13278.074 | G24: =G20+G21+G22+G23 -> 14568.317 | H24: =H20+H21+H22+H23 -> 15580.114 | I24: =I20+I21+I22+I23 -> 17527.325 | J24: =J20+J21+J22+J23 -> 18929.511 | K24: =K20+K21+K22+K23 -> 20254.577 | ... M24: =M20+M21+M22+M23 -> 22543.344 | N24: =M24*(1+$C$27) -> 23332.361 | P24: =IFERROR((H24/D24)^(1/(COLUMNS(D24:H24)-1))-1,"n/m") -> n/m | Q24: =IFERROR((M24/D24)^(1/(COLUMNS(D24:M24)-1))-1,"n/m") -> -2.505396
B25: Terminal Value (Gordon Growth) | N25: =N24/($C$13-$C$27) -> 390826.81
B26: Fade-period growth (2032E–36E; 9.0% → 5.0% linear) | I26: 0.09 | J26: =I26+($M$26-$I$26)/4 -> 0.08 | K26: =J26+($M$26-$I$26)/4 -> 0.07 | L26: =K26+($M$26-$I$26)/4 -> 0.06 | M26: 0.05
B27: Terminal growth rate | C27: 0.035
B29: Discount period (years) | D29: =(DATE(2027,12,31)-$C$15)/365.25 -> 1.2156057 | E29: =(DATE(2028,12,31)-$C$15)/365.25 -> 2.2176591 | F29: =(DATE(2029,12,31)-$C$15)/365.25 -> 3.2169747 | G29: =(DATE(2030,12,31)-$C$15)/365.25 -> 4.2162902 | H29: =(DATE(2031,12,31)-$C$15)/365.25 -> 5.2156057 | I29: =(DATE(2032,12,31)-$C$15)/365.25 -> 6.2176591 | J29: =(DATE(2033,12,31)-$C$15)/365.25 -> 7.2169747 | K29: =(DATE(2034,12,31)-$C$15)/365.25 -> 8.2162902 | L29: =(DATE(2035,12,31)-$C$15)/365.25 -> 9.2156057 | M29: =(DATE(2036,12,31)-$C$15)/365.25 -> 10.217659 | N29: =M29 -> 10.217659
B30: Discount factor | D30: =1/(1+$C$13)^D29 -> 0.89584449 | E30: =1/(1+$C$13)^E29 -> 0.818195 | F30: =1/(1+$C$13)^F29 -> 0.74746111 | G30: =1/(1+$C$13)^G29 -> 0.68284224 | H30: =1/(1+$C$13)^H29 -> 0.62380975 | I30: =1/(1+$C$13)^I29 -> 0.56973953 | J30: =1/(1+$C$13)^J29 -> 0.52048489 | K30: =1/(1+$C$13)^K29 -> 0.47548838 | ... N30: =1/(1+$C$13)^N29 -> 0.39673076
B31: PV of UFCF | D31: =D24*D30 -> -508.62086 | E31: =E24*E30 -> 10314.981 | F31: =F24*F30 -> 9924.8443 | G31: =G24*G30 -> 9947.8619 | H31: =H24*H30 -> 9719.0273 | I31: =I24*I30 -> 9986.0097 | J31: =J24*J30 -> 9852.5244 | K31: =K24*K30 -> 9630.8157 | ... M31: =M24*M30 -> 8943.6379 | N31: =N25*N30 -> 155053.02
D32: GE Aerospace operating profit already deducts amortization of intangibles and stock-based compensation (neither is adjusted out); D&A is added back in row 21. Restructuring and separation costs (cash; excluded from operating profit) are deducted in row 18. Run-off insurance, U.S. tax equity and non-operating pension income are excluded from NOPAT, and the insurance balance sheet from net debt. Row 22 includes the $11.75bn CPP consideration in FY2027E (its operating profit is in NOPAT from closing) and bolt-ons from the M&A lever; the fade period and terminal value assume no further acquisitions.
B33: IMPLIED ROIC — invested capital roll-forward (USDm)
B34: Opening invested capital | D34: =Model!W444 -> 27995.445 | E34: =D38 -> 38612.738 | F34: =E38 -> 37331.773 | G34: =F38 -> 36798.799 | H34: =G38 -> 36270.981 | I34: =H38 -> 35861.431 | J34: =I38 -> 34870.022 | K34: =J38 -> 33799.3 | L34: =K38 -> 32653.628 | M34: =L38 -> 31439.215
B35: plus Capex and acquisitions | D35: =-D22 -> 13440.366 | E35: =-E22 -> 2018.8857 | F35: =-F22 -> 2615.9937 | G35: =-G22 -> 2698.8388 | H35: =-H22 -> 2839.5951 | I35: =-I22 -> 2550.1586 | J35: =-J22 -> 2754.1713 | K35: =-K22 -> 2946.9633 | ... M35: =-M22 -> 3279.9702
B36: less DD&A | D36: =-D21 -> -1520.1069 | E36: =-E21 -> -1937.88 | F36: =-F21 -> -2069.5394 | G36: =-G21 -> -2181.2358 | H36: =-H21 -> -2281.1258 | I36: =-I21 -> -2486.4271 | J36: =-J21 -> -2685.3413 | K36: =-K21 -> -2873.3152 | ... M36: =-M21 -> -3197.9998
B37: plus Δ Working capital investment | D37: =-D23 -> -1302.9663 | E37: =-E23 -> -1361.9709 | F37: =-F23 -> -1079.4279 | G37: =-G23 -> -1045.4215 | H37: =-H23 -> -968.0189 | I37: =-I23 -> -1055.1406 | J37: =-J23 -> -1139.5519 | K37: =-K23 -> -1219.3205 | ... M37: =-M23 -> -1357.1037
B38: Closing invested capital | D38: =SUM(D34:D37) -> 38612.738 | E38: =SUM(E34:E37) -> 37331.773 | F38: =SUM(F34:F37) -> 36798.799 | G38: =SUM(G34:G37) -> 36270.981 | H38: =SUM(H34:H37) -> 35861.431 | I38: =SUM(I34:I37) -> 34870.022 | J38: =SUM(J34:J37) -> 33799.3 | K38: =SUM(K34:K37) -> 32653.628 | ... M38: =SUM(M34:M37) -> 30164.082
B39: NOPAT (row 20) | D39: =D20 -> 10049.537 | E39: =E20 -> 11326.03 | F39: =F20 -> 12745.101 | G39: =G20 -> 14040.498 | H39: =H20 -> 15170.565 | I39: =I20 -> 16535.916 | J39: =J20 -> 17858.789 | K39: =K20 -> 19108.904 | ... M39: =M20 -> 21268.21
B40: Implied ROIC (NOPAT / avg. invested capital) | D40: =IFERROR(D39/AVERAGE(D34,D38),"") -> 0.30175083 | E40: =IFERROR(E39/AVERAGE(E34,E38),"") -> 0.2982712 | F40: =IFERROR(F39/AVERAGE(F34,F38),"") -> 0.34385546 | G40: =IFERROR(G39/AVERAGE(G34,G38),"") -> 0.38430383 | H40: =IFERROR(H39/AVERAGE(H34,H38),"") -> 0.42063102 | I40: =IFERROR(I39/AVERAGE(I34,I38),"") -> 0.46756895 | J40: =IFERROR(J39/AVERAGE(J34,J38),"") -> 0.52013879 | K40: =IFERROR(K39/AVERAGE(K34,K38),"") -> 0.57511098 | ... M40: =IFERROR(M39/AVERAGE(M34,M38),"") -> 0.69048935
B41: Reinvestment rate (net investment / NOPAT) | D41: =IFERROR(SUM(D35:D37)/D39,"") -> 1.0564957 | E41: =IFERROR(SUM(E35:E37)/E39,"") -> -0.11309923 | F41: =IFERROR(SUM(F35:F37)/F39,"") -> -0.041817915 | G41: =IFERROR(SUM(G35:G37)/G39,"") -> -0.037592573 | H41: =IFERROR(SUM(H35:H37)/H39,"") -> -0.026996332 | I41: =IFERROR(SUM(I35:I37)/I39,"") -> -0.059954894 | J41: =IFERROR(SUM(J35:J37)/J39,"") -> -0.059954894 | K41: =IFERROR(SUM(K35:K37)/K39,"") -> -0.059954894 | ... M41: =IFERROR(SUM(M35:M37)/M39,"") -> -0.059954894
B42: Implied terminal RONIC (g / reinvestment rate) | N42: =IFERROR($C$27/M41,"") -> -0.5837722
D43: Opening IC = Model FY2026E book IC (equity + net debt at 31-Dec-2026E), rolled forward with capex + acquisitions − D&A + ΔWC.
B44: 3. VALUATION SUMMARY
...

Sheet Charts
B2: General Electric Company (GE Aerospace) — Operating Performance (FY2023–FY2025) and Model Forecast (FY2026E–FY2031E)
B3: USDm · calendar years · Linked to Model. Bars = contribution of each segment to adjusted revenue growth (pp; segments as reported in each year, Jan-2026 structure from 2026). Adjusted EBITDA = operating profit + D&A (model). ROIC / RONTA on operating profit (full-cost); charts start in 2023, the first year with a GE Aerospace balance sheet.
C7: 2023 | D7: 2024 | E7: 2025 | F7: 2026E | G7: 2027E | H7: 2028E | I7: 2029E | J7: 2030E | K7: 2031E
B8: CES contribution to growth (pp) | C8: =IFERROR(Model!H272+0,0) -> 0.19257505 | D8: =IFERROR(Model!M272+0,0) -> 0.094683814 | E8: =IFERROR(Model!R272+0,0) -> 0.18317198 | F8: =IFERROR(Model!W272+0,0) -> 0.12561306 | G8: =IFERROR(Model!X272+0,0) -> 0.10460708 | H8: =IFERROR(Model!Y272+0,0) -> 0.083783799 | I8: =IFERROR(Model!Z272+0,0) -> 0.067495788 | J8: =IFERROR(Model!AA272+0,0) -> 0.058332425 | K8: =IFERROR(Model!AB272+0,0) -> 0.050717577
B9: DPT contribution to growth (pp) | C9: =IFERROR(Model!H273+0,0) -> 0.037124742 | D9: =IFERROR(Model!M273+0,0) -> 0.016176977 | E9: =IFERROR(Model!R273+0,0) -> 0.030637813 | F9: =IFERROR(Model!W273+0,0) -> 0.069392449 | G9: =IFERROR(Model!X273+0,0) -> 0.021611274 | H9: =IFERROR(Model!Y273+0,0) -> 0.018100928 | I9: =IFERROR(Model!Z273+0,0) -> 0.014826397 | J9: =IFERROR(Model!AA273+0,0) -> 0.014526151 | K9: =IFERROR(Model!AB273+0,0) -> 0.011949664
C11: =C7 -> 2023 | D11: =D7 -> 2024 | E11: =E7 -> 2025 | F11: =F7 -> 2026E | G11: =G7 -> 2027E | H11: =H7 -> 2028E | I11: =I7 -> 2029E | J11: =J7 -> 2030E | K11: =K7 -> 2031E
B12: Adjusted EBITDA | C12: =Model!H224 -> 6738 | D12: =Model!M224 -> 8438 | E12: =Model!R224 -> 10276 | F12: =Model!W224 -> 11907 | G12: =Model!X224 -> 13777.983 | H12: =Model!Y224 -> 15833.7 | I12: =Model!Z224 -> 17525.083 | J12: =Model!AA224 -> 19197.499 | K12: =Model!AB224 -> 20658.915
B13: Profit before tax (GAAP) | C13: =Model!H172 -> 10441 | D13: =Model!M172 -> 7620 | E13: =Model!R172 -> 10000 | F13: =Model!W172 -> 10301 | G13: =Model!X172 -> 12265.538 | H13: =Model!Y172 -> 13543.22 | I13: =Model!Z172 -> 15189.124 | J13: =Model!AA172 -> 16612.473 | K13: =Model!AB172 -> 17861.293
B14: Adj. EBITDA Margin % | C14: =Model!H267 -> 0.21083263 | D14: =Model!M267 -> 0.24026196 | E14: =Model!R267 -> 0.24280516 | F14: =Model!W267 -> 0.2384263 | G14: =Model!X267 -> 0.2445266 | H14: =Model!Y267 -> 0.25096933 | I14: =Model!Z267 -> 0.25674819 | J14: =Model!AA267 -> 0.26192231 | K14: =Model!AB267 -> 0.26490372
B15: Profit Margin (GAAP) % | C15: =Model!H268 -> 0.29537739 | D15: =Model!M268 -> 0.19688905 | E15: =Model!R268 -> 0.21807873 | F15: =Model!W268 -> 0.19463039 | G15: =Model!X268 -> 0.2070414 | H15: =Model!Y268 -> 0.2055126 | I15: =Model!Z268 -> 0.21398224 | J15: =Model!AA268 -> 0.21876331 | K15: =Model!AB268 -> 0.22173981
C17: =C7 -> 2023 | D17: =D7 -> 2024 | E17: =E7 -> 2025 | F17: =F7 -> 2026E | G17: =G7 -> 2027E | H17: =H7 -> 2028E | I17: =I7 -> 2029E | J17: =J7 -> 2030E | K17: =K7 -> 2031E
B18: ROIC | C18: =IFERROR(Model!H447+0,NA()) -> 0.1171593 | D18: =IFERROR(Model!M447+0,NA()) -> 0.23110345 | E18: =IFERROR(Model!R447+0,NA()) -> 0.27815169 | F18: =IFERROR(Model!W447+0,NA()) -> 0.31935731 | G18: =IFERROR(Model!X447+0,NA()) -> 0.25925911 | H18: =IFERROR(Model!Y447+0,NA()) -> 0.29901478 | I18: =IFERROR(Model!Z447+0,NA()) -> 0.33208645 | J18: =IFERROR(Model!AA447+0,NA()) -> 0.36522213 | K18: =IFERROR(Model!AB447+0,NA()) -> 0.39301733
B19: RONTA | C19: =IFERROR(Model!H459+0,NA()) -> 0.14409608 | D19: =IFERROR(Model!M459+0,NA()) -> 0.23509329 | E19: =IFERROR(Model!R459+0,NA()) -> 0.28281287 | F19: =IFERROR(Model!W459+0,NA()) -> 0.32632787 | G19: =IFERROR(Model!X459+0,NA()) -> 0.35524766 | H19: =IFERROR(Model!Y459+0,NA()) -> 0.41804085 | I19: =IFERROR(Model!Z459+0,NA()) -> 0.47710265 | J19: =IFERROR(Model!AA459+0,NA()) -> 0.53911923 | K19: =IFERROR(Model!AB459+0,NA()) -> 0.5952346
B20: Adj. EBITDA margin % | C20: =IFERROR(Model!H267+0,NA()) -> 0.21083263 | D20: =IFERROR(Model!M267+0,NA()) -> 0.24026196 | E20: =IFERROR(Model!R267+0,NA()) -> 0.24280516 | F20: =IFERROR(Model!W267+0,NA()) -> 0.2384263 | G20: =IFERROR(Model!X267+0,NA()) -> 0.2445266 | H20: =IFERROR(Model!Y267+0,NA()) -> 0.25096933 | I20: =IFERROR(Model!Z267+0,NA()) -> 0.25674819 | J20: =IFERROR(Model!AA267+0,NA()) -> 0.26192231 | K20: =IFERROR(Model!AB267+0,NA()) -> 0.26490372
B21: FCF margin % | C21: =IFERROR(Model!H293+0,NA()) -> 0.14844019 | D21: =IFERROR(Model!M293+0,NA()) -> 0.17337699 | E21: =IFERROR(Model!R293+0,NA()) -> 0.1817967 | F21: =IFERROR(Model!W293+0,NA()) -> 0.18121761 | G21: =IFERROR(Model!X293+0,NA()) -> 0.1962678 | H21: =IFERROR(Model!Y293+0,NA()) -> 0.19643491 | I21: =IFERROR(Model!Z293+0,NA()) -> 0.19597397 | J21: =IFERROR(Model!AA293+0,NA()) -> 0.19884824 | K21: =IFERROR(Model!AB293+0,NA()) -> 0.19893517
