Workbook

Sheet Model
CF1: SCENARIO SWITCH ▼ (Bull / Base / Bear) — drives all scenario-linked forecast drivers
B2: Alphabet Inc. (NASDAQ: GOOG) — 3-Statement Financial Model | CF2: Base
B3: US GAAP as originally reported · USD millions (per-share data in USD; shares in millions, split-adjusted) · Calendar fiscal year · Source: SEC EDGAR only — Google Inc. (CIK 1288776, to Q3-2015) and Alphabet Inc. (CIK 1652044) Forms 10-K / 10-Q (XBRL instance documents), Form 8-K earnings releases (Ex. 99.1); investor-relations releases are the same documents as filed on EDGAR. Capex outlook from the earnings call is UNVERIFIED.
B4: Basis notes: statements as originally reported; revenue types and segments from the latest filing presenting the period (recasts: Cloud split Q4-20, performance fees to OI&E 2019, Google DeepMind to Alphabet-level 2023). Splits: 2-for-1 Class C dividend Apr-2014, 20-for-1 Jul-2022. Disc ops: Motorola Home 2012–13, Motorola Mobile 2014. Deals: Wiz (11-Mar-2026, $29.5bn), Intersect (10-Mar-2026, $5.9bn); GFiber divestiture pending (late 2026). Jun-2026: $30.5bn common + $19.0bn 6.25% mandatory convertible preferred. No company guidance: Q3–Q4/26E from the 1H26 run-rate with scenario shifts.
CH5: Forecast | CI5: Historical | CJ5: Historical | CK5: Historical
B6: (USDm) | C6: 2006 | D6: 2007 | E6: 2008 | F6: 2009 | G6: 2010 | H6: 2011 | I6: 2012 | J6: Q1/13 | K6: Q2/13 | L6: Q3/13 | M6: Q4/13 | N6: 2013 | O6: Q1/14 | P6: Q2/14 | Q6: Q3/14 | R6: Q4/14 | S6: 2014 | T6: Q1/15 | U6: Q2/15 | V6: Q3/15 | W6: Q4/15 | X6: 2015 | Y6: Q1/16 | Z6: Q2/16 | AA6: Q3/16 | AB6: Q4/16 | AC6: 2016 | AD6: Q1/17 | AE6: Q2/17 | AF6: Q3/17 | AG6: Q4/17 | AH6: 2017 | AI6: Q1/18 | AJ6: Q2/18 | AK6: Q3/18 | AL6: Q4/18 | AM6: 2018 | AN6: Q1/19 | AO6: Q2/19 | AP6: Q3/19 | AQ6: Q4/19 | AR6: 2019 | AS6: Q1/20 | AT6: Q2/20 | AU6: Q3/20 | AV6: Q4/20 | AW6: 2020 | AX6: Q1/21 | AY6: Q2/21 | AZ6: Q3/21 | BA6: Q4/21 | BB6: 2021 | BC6: Q1/22 | BD6: Q2/22 | BE6: Q3/22 | BF6: Q4/22 | BG6: 2022 | BH6: Q1/23 | BI6: Q2/23 | BJ6: Q3/23 | BK6: Q4/23 | BL6: 2023 | BM6: Q1/24 | BN6: Q2/24 | BO6: Q3/24 | BP6: Q4/24 | BQ6: 2024 | BR6: Q1/25 | BS6: Q2/25 | BT6: Q3/25 | BU6: Q4/25 | BV6: 2025 | BW6: Q1/26 | BX6: Q2/26 | BY6: Q3/26E | BZ6: Q4/26E | CA6: 2026E | CB6: 2027E | CC6: 2028E | CD6: 2029E | CE6: 2030E | CF6: Modelling Notes | CH6: 5Y CAGR | CI6: 5Y CAGR | CJ6: 10Y CAGR | CK6: 19Y CAGR
CH7: 25-'30 | CI7: 20-'25 | CJ7: 15-'25 | CK7: 06-'25
B8: REVENUE BUILD — GOOGLE SERVICES (Search · YouTube · Network · Subscriptions/platforms/devices) · GOOGLE CLOUD · OTHER BETS | CF8: REVENUE BUILD — modelling logic (revenue by type → segment revenue → segment operating income → Alphabet-level costs → GAAP P&L)
CN9: SCENARIO INPUT TABLE — driver assumptions per Bull / Base / Bear | CO9: Bull | CP9: Base | CQ9: Bear | CR9: Bull / Bear = Base + Δ (Δ inputs on each block header). Alphabet gives no revenue / margin / EPS guidance: the Q3–Q4/26E block holds scenario shifts vs the 1H26 run-rate.
B10: Revenues by type (current taxonomy; latest filing presenting the period — annual from FY2017, quarterly from Q1/19) | CF10: REVENUE TYPES — Q3–Q4/26E: prior-year quarter × (1 + 1H26 y/y growth + scenario shift); 2027E–2030E: scenario levers
B11: Google Search & other | AH11: 69811 | AM11: 85296 | AN11: 22547 | AO11: 23642 | AP11: 24741 | AQ11: 27185 | AR11: 98115 | AS11: 24502 | AT11: 21319 | AU11: 26338 | AV11: 31903 | AW11: 104062 | AX11: 31879 | AY11: 35845 | AZ11: 37926 | BA11: 43301 | BB11: 148951 | BC11: 39618 | BD11: 40689 | BE11: 39539 | BF11: 42604 | BG11: 162450 | BH11: 40359 | BI11: 42628 | BJ11: 44026 | BK11: 48020 | BL11: 175033 | BM11: 46156 | BN11: 48509 | BO11: 49385 | BP11: 54034 | BQ11: 198084 | BR11: 50702 | BS11: 54190 | BT11: 56567 | BU11: 63073 | BV11: 224532 | BW11: 60399 | BX11: 63271 | BY11: =BT11*(1+BY12) -> 66693.751 | BZ11: =BU11*(1+BZ12) -> 74364.469 | CA11: =SUM(BW11:BZ11) -> 264728.22 | CB11: =CA11*(1+CB12) -> 293848.32 | CC11: =CB11*(1+CC12) -> 320294.67 | CD11: =CC11*(1+CD12) -> 345918.25 | CE11: =CD11*(1+CE12) -> 370132.52 | CF11: Revenue types per the 10-Q / 10-K revenue note (XBRL; latest filing presenting the period). YouTube ads and Cloud are disclosed from FY2017 (annual) / Q1-19 (quarterly). | CH11: =IFERROR((CE11/BV11)^(1/5)-1,"n/m") -> 0.10513619 | CI11: =IFERROR((BV11/AW11)^(1/5)-1,"n/m") -> 0.16626493 | CJ11: =IFERROR((BV11/X11)^(1/10)-1,"n/m") -> n/m | CK11: =IFERROR((BV11/C11)^(1/19)-1,"n/m") -> n/m | CN11: Q3–Q4/26E outlook — Alphabet gives no revenue, margin or EPS guidance (scenario shifts vs the 1H26 run-rate) | CO11: Bull | CP11: Base | CQ11: Bear | CR11: Capex outlook 2026 $195–205bn (raised from $180–190bn) is call-only (22-Jul-2026) and UNVERIFIED; the Q2-26 10-Q says only that 2026 technical-infrastructure investment will "significantly increase" vs 2025 (1H26 $80.6bn).
B12: y/y % | D12: =IF(AND(ISNUMBER(D11),ISNUMBER(C11)),IFERROR(D11/C11-1,""),"") | E12: =IF(AND(ISNUMBER(E11),ISNUMBER(D11)),IFERROR(E11/D11-1,""),"") | F12: =IF(AND(ISNUMBER(F11),ISNUMBER(E11)),IFERROR(F11/E11-1,""),"") | G12: =IF(AND(ISNUMBER(G11),ISNUMBER(F11)),IFERROR(G11/F11-1,""),"") | H12: =IF(AND(ISNUMBER(H11),ISNUMBER(G11)),IFERROR(H11/G11-1,""),"") | I12: =IF(AND(ISNUMBER(I11),ISNUMBER(H11)),IFERROR(I11/H11-1,""),"") | N12: =IF(AND(ISNUMBER(N11),ISNUMBER(I11)),IFERROR(N11/I11-1,""),"") | O12: =IF(AND(ISNUMBER(O11),ISNUMBER(J11)),IFERROR(O11/J11-1,""),"") | P12: =IF(AND(ISNUMBER(P11),ISNUMBER(K11)),IFERROR(P11/K11-1,""),"") | Q12: =IF(AND(ISNUMBER(Q11),ISNUMBER(L11)),IFERROR(Q11/L11-1,""),"") | R12: =IF(AND(ISNUMBER(R11),ISNUMBER(M11)),IFERROR(R11/M11-1,""),"") | S12: =IF(AND(ISNUMBER(S11),ISNUMBER(N11)),IFERROR(S11/N11-1,""),"") | T12: =IF(AND(ISNUMBER(T11),ISNUMBER(O11)),IFERROR(T11/O11-1,""),"") | U12: =IF(AND(ISNUMBER(U11),ISNUMBER(P11)),IFERROR(U11/P11-1,""),"") | ... BX12: =IF(AND(ISNUMBER(BX11),ISNUMBER(BS11)),IFERROR(BX11/BS11-1,""),"") -> 0.16757704 | BY12: =BY13+BY97 -> 0.17902223 | BZ12: =BY13+BY97 -> 0.17902223 | CA12: =IF(AND(ISNUMBER(CA11),ISNUMBER(BV11)),IFERROR(CA11/BV11-1,""),"") -> 0.17902223 | CB12: =CHOOSE(MATCH($CF$2,{"Bull","Base","Bear"},0),$CO$30,$CP$30,$CQ$30) -> 0.11 | CC12: =CHOOSE(MATCH($CF$2,{"Bull","Base","Bear"},0),$CO$31,$CP$31,$CQ$31) -> 0.09 | CD12: =CHOOSE(MATCH($CF$2,{"Bull","Base","Bear"},0),$CO$32,$CP$32,$CQ$32) -> 0.08 | CE12: =CHOOSE(MATCH($CF$2,{"Bull","Base","Bear"},0),$CO$33,$CP$33,$CQ$33) -> 0.07 | CF12: Q3–Q4/26E: 1H26 y/y growth + scenario shift (Group block). 2027E–2030E: scenario lever (Bull/Base/Bear table →). | CH12: =IFERROR(AVERAGE(CA12,CB12,CC12,CD12,CE12),"n/m") -> 0.10580445 | CI12: =IFERROR(AVERAGE(BB12,BG12,BL12,BQ12,BV12),"n/m") -> 0.17293338 | CJ12: =IFERROR(AVERAGE(AC12,AH12,AM12,AR12,AW12,BB12,BG12,BL12,BQ12,BV12),"n/m") -> 0.16217263 | CK12: =IFERROR(AVERAGE(C12,D12,E12,F12,G12,H12,I12,N12,S12,X12,AC12,AH12,AM12,AR12,AW12,BB12,BG12,BL12,BQ12,BV12),"n/m") -> 0.16217263 | CN12: Q3–Q4/26E revenue growth shift vs 1H26 y/y (pp; all revenue types) | CO12: 0.02 | CP12: 0 | CQ12: -0.03 | CR12: Base = 1H26 y/y run-rate (Search +17.9%, YouTube +11.8%, Network −2.3%, subscriptions +17.2%, Cloud +73% incl. Wiz from 11-Mar-2026). Assumption.
B13: 1H26 y/y growth (Q3–Q4/26E driver before scenario shift) | BY13: =IFERROR(SUM(BW11:BX11)/SUM(BR11:BS11)-1,0) -> 0.17902223 | BZ13: =IFERROR(SUM(BW11:BX11)/SUM(BR11:BS11)-1,0) -> 0.17902223 | CN13: Q3–Q4/26E Services / Cloud operating-margin shift (pp) | CO13: 0.01 | CP13: 0 | CQ13: -0.015 | CR13: Base = Q2-26 margins (Services with last year's sequential seasonality). Bear reflects leased third-party data-centre capacity in Q3 (call, unverified).
B14: YouTube ads | AH14: 8150 | AM14: 11155 | AN14: 3025 | AO14: 3603 | AP14: 3804 | AQ14: 4717 | AR14: 15149 | AS14: 4038 | AT14: 3812 | AU14: 5037 | AV14: 6885 | AW14: 19772 | AX14: 6005 | AY14: 7002 | AZ14: 7205 | BA14: 8633 | BB14: 28845 | BC14: 6869 | BD14: 7340 | BE14: 7071 | BF14: 7963 | BG14: 29243 | BH14: 6693 | BI14: 7665 | BJ14: 7952 | BK14: 9200 | BL14: 31510 | BM14: 8090 | BN14: 8663 | BO14: 8921 | BP14: 10473 | BQ14: 36147 | BR14: 8927 | BS14: 9796 | BT14: 10261 | BU14: 11383 | BV14: 40367 | BW14: 9883 | BX14: 11055 | BY14: =BT14*(1+BY15) -> 11474.914 | BZ14: =BU14*(1+BZ15) -> 12729.651 | CA14: =SUM(BW14:BZ14) -> 45142.565 | CB14: =CA14*(1+CB15) -> 50108.247 | CC14: =CB14*(1+CC15) -> 55119.072 | CD14: =CC14*(1+CD15) -> 60079.788 | CE14: =CD14*(1+CE15) -> 64886.172 | CH14: =IFERROR((CE14/BV14)^(1/5)-1,"n/m") -> 0.099575704 | CI14: =IFERROR((BV14/AW14)^(1/5)-1,"n/m") -> 0.15344044 | CJ14: =IFERROR((BV14/X14)^(1/10)-1,"n/m") -> n/m | CK14: =IFERROR((BV14/C14)^(1/19)-1,"n/m") -> n/m | CN14: 2H26E share repurchases ($m) | CO14: 5000 | CP14: 0 | CQ14: 0 | CR14: No repurchases in 1H26 after the Jun-2026 equity raise; $69.5bn authorization remaining.
B15: y/y % | D15: =IF(AND(ISNUMBER(D14),ISNUMBER(C14)),IFERROR(D14/C14-1,""),"") | E15: =IF(AND(ISNUMBER(E14),ISNUMBER(D14)),IFERROR(E14/D14-1,""),"") | F15: =IF(AND(ISNUMBER(F14),ISNUMBER(E14)),IFERROR(F14/E14-1,""),"") | G15: =IF(AND(ISNUMBER(G14),ISNUMBER(F14)),IFERROR(G14/F14-1,""),"") | H15: =IF(AND(ISNUMBER(H14),ISNUMBER(G14)),IFERROR(H14/G14-1,""),"") | I15: =IF(AND(ISNUMBER(I14),ISNUMBER(H14)),IFERROR(I14/H14-1,""),"") | N15: =IF(AND(ISNUMBER(N14),ISNUMBER(I14)),IFERROR(N14/I14-1,""),"") | O15: =IF(AND(ISNUMBER(O14),ISNUMBER(J14)),IFERROR(O14/J14-1,""),"") | P15: =IF(AND(ISNUMBER(P14),ISNUMBER(K14)),IFERROR(P14/K14-1,""),"") | Q15: =IF(AND(ISNUMBER(Q14),ISNUMBER(L14)),IFERROR(Q14/L14-1,""),"") | R15: =IF(AND(ISNUMBER(R14),ISNUMBER(M14)),IFERROR(R14/M14-1,""),"") | S15: =IF(AND(ISNUMBER(S14),ISNUMBER(N14)),IFERROR(S14/N14-1,""),"") | T15: =IF(AND(ISNUMBER(T14),ISNUMBER(O14)),IFERROR(T14/O14-1,""),"") | U15: =IF(AND(ISNUMBER(U14),ISNUMBER(P14)),IFERROR(U14/P14-1,""),"") | ... BX15: =IF(AND(ISNUMBER(BX14),ISNUMBER(BS14)),IFERROR(BX14/BS14-1,""),"") -> 0.12852185 | BY15: =BY16+BY97 -> 0.11830369 | BZ15: =BY16+BY97 -> 0.11830369 | CA15: =IF(AND(ISNUMBER(CA14),ISNUMBER(BV14)),IFERROR(CA14/BV14-1,""),"") -> 0.11830369 | CB15: =CHOOSE(MATCH($CF$2,{"Bull","Base","Bear"},0),$CO$35,$CP$35,$CQ$35) -> 0.11 | CC15: =CHOOSE(MATCH($CF$2,{"Bull","Base","Bear"},0),$CO$36,$CP$36,$CQ$36) -> 0.1 | CD15: =CHOOSE(MATCH($CF$2,{"Bull","Base","Bear"},0),$CO$37,$CP$37,$CQ$37) -> 0.09 | CE15: =CHOOSE(MATCH($CF$2,{"Bull","Base","Bear"},0),$CO$38,$CP$38,$CQ$38) -> 0.08 | CH15: =IFERROR(AVERAGE(CA15,CB15,CC15,CD15,CE15),"n/m") -> 0.099660738 | CI15: =IFERROR(AVERAGE(BB15,BG15,BL15,BQ15,BV15),"n/m") -> 0.16282142 | CJ15: =IFERROR(AVERAGE(AC15,AH15,AM15,AR15,AW15,BB15,BG15,BL15,BQ15,BV15),"n/m") -> 0.23075414 | CK15: =IFERROR(AVERAGE(C15,D15,E15,F15,G15,H15,I15,N15,S15,X15,AC15,AH15,AM15,AR15,AW15,BB15,BG15,BL15,BQ15,BV15),"n/m") -> 0.23075414
B16: 1H26 y/y growth (Q3–Q4/26E driver before scenario shift) | BY16: =IFERROR(SUM(BW14:BX14)/SUM(BR14:BS14)-1,0) -> 0.11830369 | BZ16: =IFERROR(SUM(BW14:BX14)/SUM(BR14:BS14)-1,0) -> 0.11830369 | CN16: Q3–Q4/26E point estimates (all cases)
B17: Google Network | AH17: 17616 | AM17: 20010 | AN17: 5015 | AO17: 5249 | AP17: 5251 | AQ17: 6032 | AR17: 21547 | AS17: 5223 | AT17: 4736 | AU17: 5720 | AV17: 7411 | AW17: 23090 | AX17: 6800 | AY17: 7597 | AZ17: 7999 | BA17: 9305 | BB17: 31701 | BC17: 8174 | BD17: 8259 | BE17: 7872 | BF17: 8475 | BG17: 32780 | BH17: 7496 | BI17: 7850 | BJ17: 7669 | BK17: 8297 | BL17: 31312 | BM17: 7413 | BN17: 7444 | BO17: 7548 | BP17: 7954 | BQ17: 30359 | BR17: 7256 | BS17: 7354 | BT17: 7354 | BU17: 7828 | BV17: 29792 | BW17: 6971 | BX17: 7303 | BY17: =BT17*(1+BY18) -> 7184.8731 | BZ17: =BU17*(1+BZ18) -> 7647.9721 | CA17: =SUM(BW17:BZ17) -> 29106.845 | CB17: =CA17*(1+CB18) -> 28233.64 | CC17: =CB17*(1+CC18) -> 27386.631 | CD17: =CC17*(1+CD18) -> 26565.032 | CE17: =CD17*(1+CE18) -> 25768.081 | CH17: =IFERROR((CE17/BV17)^(1/5)-1,"n/m") -> -0.028603616 | CI17: =IFERROR((BV17/AW17)^(1/5)-1,"n/m") -> 0.052289278 | CJ17: =IFERROR((BV17/X17)^(1/10)-1,"n/m") -> n/m | CK17: =IFERROR((BV17/C17)^(1/19)-1,"n/m") -> n/m | CN17: Optional FY26 revenue target ($m; blank = driver-based) | CR17: Blank by default (no company guidance). Enter a value (e.g. consensus) to solve the 2H revenue shift to it.
B18: y/y % | D18: =IF(AND(ISNUMBER(D17),ISNUMBER(C17)),IFERROR(D17/C17-1,""),"") | E18: =IF(AND(ISNUMBER(E17),ISNUMBER(D17)),IFERROR(E17/D17-1,""),"") | F18: =IF(AND(ISNUMBER(F17),ISNUMBER(E17)),IFERROR(F17/E17-1,""),"") | G18: =IF(AND(ISNUMBER(G17),ISNUMBER(F17)),IFERROR(G17/F17-1,""),"") | H18: =IF(AND(ISNUMBER(H17),ISNUMBER(G17)),IFERROR(H17/G17-1,""),"") | I18: =IF(AND(ISNUMBER(I17),ISNUMBER(H17)),IFERROR(I17/H17-1,""),"") | N18: =IF(AND(ISNUMBER(N17),ISNUMBER(I17)),IFERROR(N17/I17-1,""),"") | O18: =IF(AND(ISNUMBER(O17),ISNUMBER(J17)),IFERROR(O17/J17-1,""),"") | P18: =IF(AND(ISNUMBER(P17),ISNUMBER(K17)),IFERROR(P17/K17-1,""),"") | Q18: =IF(AND(ISNUMBER(Q17),ISNUMBER(L17)),IFERROR(Q17/L17-1,""),"") | R18: =IF(AND(ISNUMBER(R17),ISNUMBER(M17)),IFERROR(R17/M17-1,""),"") | S18: =IF(AND(ISNUMBER(S17),ISNUMBER(N17)),IFERROR(S17/N17-1,""),"") | T18: =IF(AND(ISNUMBER(T17),ISNUMBER(O17)),IFERROR(T17/O17-1,""),"") | U18: =IF(AND(ISNUMBER(U17),ISNUMBER(P17)),IFERROR(U17/P17-1,""),"") | ... BX18: =IF(AND(ISNUMBER(BX17),ISNUMBER(BS17)),IFERROR(BX17/BS17-1,""),"") -> -0.0069350014 | BY18: =BY19+BY97 -> -0.022997947 | BZ18: =BY19+BY97 -> -0.022997947 | CA18: =IF(AND(ISNUMBER(CA17),ISNUMBER(BV17)),IFERROR(CA17/BV17-1,""),"") -> -0.022997947 | CB18: =CHOOSE(MATCH($CF$2,{"Bull","Base","Bear"},0),$CO$40,$CP$40,$CQ$40) -> -0.03 | CC18: =CHOOSE(MATCH($CF$2,{"Bull","Base","Bear"},0),$CO$41,$CP$41,$CQ$41) -> -0.03 | CD18: =CHOOSE(MATCH($CF$2,{"Bull","Base","Bear"},0),$CO$42,$CP$42,$CQ$42) -> -0.03 | CE18: =CHOOSE(MATCH($CF$2,{"Bull","Base","Bear"},0),$CO$43,$CP$43,$CQ$43) -> -0.03 | CH18: =IFERROR(AVERAGE(CA18,CB18,CC18,CD18,CE18),"n/m") -> -0.028599589 | CI18: =IFERROR(AVERAGE(BB18,BG18,BL18,BQ18,BV18),"n/m") -> 0.062614652 | CJ18: =IFERROR(AVERAGE(AC18,AH18,AM18,AR18,AW18,BB18,BG18,BL18,BQ18,BV18),"n/m") -> 0.074674367 | CK18: =IFERROR(AVERAGE(C18,D18,E18,F18,G18,H18,I18,N18,S18,X18,AC18,AH18,AM18,AR18,AW18,BB18,BG18,BL18,BQ18,BV18),"n/m") -> 0.074674367 | CN18: FY26 capital expenditures ($m) — UNVERIFIED call guidance mid-point | CP18: 200000 | CR18: UNVERIFIED - Q2-2026 earnings call (CFO), reported by secondary sources (w.media, Nasdaq/Motley Fool); not in any EDGAR filing. The Q2-26 10-Q states only that 2026 investment in technical infrastructure will 'significantly increase, relative to 2025'.
B19: 1H26 y/y growth (Q3–Q4/26E driver before scenario shift) | BY19: =IFERROR(SUM(BW17:BX17)/SUM(BR17:BS17)-1,0) -> -0.022997947 | BZ19: =IFERROR(SUM(BW17:BX17)/SUM(BR17:BS17)-1,0) -> -0.022997947 | CN19: Q3–Q4/26E depreciation, sequential growth | CP19: 0.096 | CR19: Q2/Q1-26 +9.6% ($7,104m vs $6,482m); capex ramp.
B20: Google subscriptions, platforms & devices | AH20: 10914 | AM20: 14063 | AN20: 3620 | AO20: 4080 | AP20: 4050 | AQ20: 5264 | AR20: 17014 | AS20: 4435 | AT20: 5124 | AU20: 5478 | AV20: 6674 | AW20: 21711 | AX20: 6494 | AY20: 6623 | AZ20: 6754 | BA20: 8161 | BB20: 28032 | BC20: 6811 | BD20: 6553 | BE20: 6895 | BF20: 8796 | BG20: 29055 | BH20: 7413 | BI20: 8142 | BJ20: 8339 | BK20: 10794 | BL20: 34688 | BM20: 8739 | BN20: 9312 | BO20: 10656 | BP20: 11633 | BQ20: 40340 | BR20: 10379 | BS20: 11203 | BT20: 12870 | BU20: 13578 | BV20: 48030 | BW20: 12384 | BX20: 12911 | BY20: =BT20*(1+BY21) -> 15084.174 | BZ20: =BU20*(1+BZ21) -> 15913.98 | CA20: =SUM(BW20:BZ20) -> 56293.154 | CB20: =CA20*(1+CB21) -> 64174.196 | CC20: =CB20*(1+CC21) -> 71875.099 | CD20: =CC20*(1+CD21) -> 79781.36 | CE20: =CD20*(1+CE21) -> 87759.496 | CF20: "Google other" to Q4-23, renamed "Google subscriptions, platforms, and devices" from Q1-24 (no recast). | CH20: =IFERROR((CE20/BV20)^(1/5)-1,"n/m") -> 0.12812262 | CI20: =IFERROR((BV20/AW20)^(1/5)-1,"n/m") -> 0.17210509 | CJ20: =IFERROR((BV20/X20)^(1/10)-1,"n/m") -> n/m | CK20: =IFERROR((BV20/C20)^(1/19)-1,"n/m") -> n/m | CN20: Q3–Q4/26E amortization of intangibles ($m per quarter) | CP20: 370 | CR20: Q2-26 $367m (Wiz intangibles from Mar-2026).
B21: y/y % | D21: =IF(AND(ISNUMBER(D20),ISNUMBER(C20)),IFERROR(D20/C20-1,""),"") | E21: =IF(AND(ISNUMBER(E20),ISNUMBER(D20)),IFERROR(E20/D20-1,""),"") | F21: =IF(AND(ISNUMBER(F20),ISNUMBER(E20)),IFERROR(F20/E20-1,""),"") | G21: =IF(AND(ISNUMBER(G20),ISNUMBER(F20)),IFERROR(G20/F20-1,""),"") | H21: =IF(AND(ISNUMBER(H20),ISNUMBER(G20)),IFERROR(H20/G20-1,""),"") | I21: =IF(AND(ISNUMBER(I20),ISNUMBER(H20)),IFERROR(I20/H20-1,""),"") | N21: =IF(AND(ISNUMBER(N20),ISNUMBER(I20)),IFERROR(N20/I20-1,""),"") | O21: =IF(AND(ISNUMBER(O20),ISNUMBER(J20)),IFERROR(O20/J20-1,""),"") | P21: =IF(AND(ISNUMBER(P20),ISNUMBER(K20)),IFERROR(P20/K20-1,""),"") | Q21: =IF(AND(ISNUMBER(Q20),ISNUMBER(L20)),IFERROR(Q20/L20-1,""),"") | R21: =IF(AND(ISNUMBER(R20),ISNUMBER(M20)),IFERROR(R20/M20-1,""),"") | S21: =IF(AND(ISNUMBER(S20),ISNUMBER(N20)),IFERROR(S20/N20-1,""),"") | T21: =IF(AND(ISNUMBER(T20),ISNUMBER(O20)),IFERROR(T20/O20-1,""),"") | U21: =IF(AND(ISNUMBER(U20),ISNUMBER(P20)),IFERROR(U20/P20-1,""),"") | ... BX21: =IF(AND(ISNUMBER(BX20),ISNUMBER(BS20)),IFERROR(BX20/BS20-1,""),"") -> 0.15245916 | BY21: =BY22+BY97 -> 0.17204152 | BZ21: =BY22+BY97 -> 0.17204152 | CA21: =IF(AND(ISNUMBER(CA20),ISNUMBER(BV20)),IFERROR(CA20/BV20-1,""),"") -> 0.17204152 | CB21: =CHOOSE(MATCH($CF$2,{"Bull","Base","Bear"},0),$CO$45,$CP$45,$CQ$45) -> 0.14 | CC21: =CHOOSE(MATCH($CF$2,{"Bull","Base","Bear"},0),$CO$46,$CP$46,$CQ$46) -> 0.12 | CD21: =CHOOSE(MATCH($CF$2,{"Bull","Base","Bear"},0),$CO$47,$CP$47,$CQ$47) -> 0.11 | CE21: =CHOOSE(MATCH($CF$2,{"Bull","Base","Bear"},0),$CO$48,$CP$48,$CQ$48) -> 0.1 | CH21: =IFERROR(AVERAGE(CA21,CB21,CC21,CD21,CE21),"n/m") -> 0.1284083 | CI21: =IFERROR(AVERAGE(BB21,BG21,BL21,BQ21,BV21),"n/m") -> 0.17501565 | CJ21: =IFERROR(AVERAGE(AC21,AH21,AM21,AR21,AW21,BB21,BG21,BL21,BQ21,BV21),"n/m") -> 0.20618937 | CK21: =IFERROR(AVERAGE(C21,D21,E21,F21,G21,H21,I21,N21,S21,X21,AC21,AH21,AM21,AR21,AW21,BB21,BG21,BL21,BQ21,BV21),"n/m") -> 0.20618937 | CN21: Q3–Q4/26E effective tax rate | CP21: 0.18 | CR21: 1H26 19.1% incl. tax on equity-security gains; FY2025 16.8%.
B22: 1H26 y/y growth (Q3–Q4/26E driver before scenario shift) | BY22: =IFERROR(SUM(BW20:BX20)/SUM(BR20:BS20)-1,0) -> 0.17204152 | BZ22: =IFERROR(SUM(BW20:BX20)/SUM(BR20:BS20)-1,0) -> 0.17204152 | CN22: Q3–Q4/26E interest yield on cash + marketable securities (annual) | CP22: 0.033 | CR22: Q2-26 $1,430m on ~$185bn average cash and securities (~3.1%); $242.5bn at 30-Jun-2026.
B23: Google Cloud | AH23: 4056 | AM23: 5838 | AN23: 1825 | AO23: 2100 | AP23: 2379 | AQ23: 2614 | AR23: 8918 | AS23: 2777 | AT23: 3007 | AU23: 3444 | AV23: 3831 | AW23: 13059 | AX23: 4047 | AY23: 4628 | AZ23: 4990 | BA23: 5541 | BB23: 19206 | BC23: 5821 | BD23: 6276 | BE23: 6868 | BF23: 7315 | BG23: 26280 | BH23: 7454 | BI23: 8031 | BJ23: 8411 | BK23: 9192 | BL23: 33088 | BM23: 9574 | BN23: 10347 | BO23: 11353 | BP23: 11955 | BQ23: 43229 | BR23: 12260 | BS23: 13624 | BT23: 15157 | BU23: 17664 | BV23: 58705 | BW23: 20028 | BX23: 24768 | BY23: =BT23*(1+BY24) -> 26231.377 | BZ23: =BU23*(1+BZ24) -> 30570.103 | CA23: =SUM(BW23:BZ23) -> 101597.48 | CB23: =CA23*(1+CB24) -> 147316.35 | CC23: =CB23*(1+CC24) -> 194457.58 | CD23: =CC23*(1+CD24) -> 243071.97 | CE23: =CD23*(1+CE24) -> 291686.37 | CF23: Google Cloud segment revenues (from Q4-20; earlier the Google Cloud revenue type, incl. in the Google segment). Includes Wiz from 11-Mar-2026. | CH23: =IFERROR((CE23/BV23)^(1/5)-1,"n/m") -> 0.37799679 | CI23: =IFERROR((BV23/AW23)^(1/5)-1,"n/m") -> 0.35068176 | CJ23: =IFERROR((BV23/X23)^(1/10)-1,"n/m") -> n/m | CK23: =IFERROR((BV23/C23)^(1/19)-1,"n/m") -> n/m | CN23: Q3–Q4/26E interest expense ($m per quarter) | CP23: 1150 | CR23: Q2-26 $1,278m (net of $363m capitalized interest); ~$100bn of debt at ~4.0% weighted coupon.
B24: y/y % | D24: =IF(AND(ISNUMBER(D23),ISNUMBER(C23)),IFERROR(D23/C23-1,""),"") | E24: =IF(AND(ISNUMBER(E23),ISNUMBER(D23)),IFERROR(E23/D23-1,""),"") | F24: =IF(AND(ISNUMBER(F23),ISNUMBER(E23)),IFERROR(F23/E23-1,""),"") | G24: =IF(AND(ISNUMBER(G23),ISNUMBER(F23)),IFERROR(G23/F23-1,""),"") | H24: =IF(AND(ISNUMBER(H23),ISNUMBER(G23)),IFERROR(H23/G23-1,""),"") | I24: =IF(AND(ISNUMBER(I23),ISNUMBER(H23)),IFERROR(I23/H23-1,""),"") | N24: =IF(AND(ISNUMBER(N23),ISNUMBER(I23)),IFERROR(N23/I23-1,""),"") | O24: =IF(AND(ISNUMBER(O23),ISNUMBER(J23)),IFERROR(O23/J23-1,""),"") | P24: =IF(AND(ISNUMBER(P23),ISNUMBER(K23)),IFERROR(P23/K23-1,""),"") | Q24: =IF(AND(ISNUMBER(Q23),ISNUMBER(L23)),IFERROR(Q23/L23-1,""),"") | R24: =IF(AND(ISNUMBER(R23),ISNUMBER(M23)),IFERROR(R23/M23-1,""),"") | S24: =IF(AND(ISNUMBER(S23),ISNUMBER(N23)),IFERROR(S23/N23-1,""),"") | T24: =IF(AND(ISNUMBER(T23),ISNUMBER(O23)),IFERROR(T23/O23-1,""),"") | U24: =IF(AND(ISNUMBER(U23),ISNUMBER(P23)),IFERROR(U23/P23-1,""),"") | ... BX24: =IF(AND(ISNUMBER(BX23),ISNUMBER(BS23)),IFERROR(BX23/BS23-1,""),"") -> 0.81796829 | BY24: =BY25+BY97 -> 0.73064441 | BZ24: =BY25+BY97 -> 0.73064441 | CA24: =IF(AND(ISNUMBER(CA23),ISNUMBER(BV23)),IFERROR(CA23/BV23-1,""),"") -> 0.73064441 | CB24: =CHOOSE(MATCH($CF$2,{"Bull","Base","Bear"},0),$CO$50,$CP$50,$CQ$50) -> 0.45 | CC24: =CHOOSE(MATCH($CF$2,{"Bull","Base","Bear"},0),$CO$51,$CP$51,$CQ$51) -> 0.32 | CD24: =CHOOSE(MATCH($CF$2,{"Bull","Base","Bear"},0),$CO$52,$CP$52,$CQ$52) -> 0.25 | CE24: =CHOOSE(MATCH($CF$2,{"Bull","Base","Bear"},0),$CO$53,$CP$53,$CQ$53) -> 0.2 | CH24: =IFERROR(AVERAGE(CA24,CB24,CC24,CD24,CE24),"n/m") -> 0.39012888 | CI24: =IFERROR(AVERAGE(BB24,BG24,BL24,BQ24,BV24),"n/m") -> 0.35251494 | CJ24: =IFERROR(AVERAGE(AC24,AH24,AM24,AR24,AW24,BB24,BG24,BL24,BQ24,BV24),"n/m") -> 0.39923044 | CK24: =IFERROR(AVERAGE(C24,D24,E24,F24,G24,H24,I24,N24,S24,X24,AC24,AH24,AM24,AR24,AW24,BB24,BG24,BL24,BQ24,BV24),"n/m") -> 0.39923044 | CN24: Q3–Q4/26E preferred dividends accrued ($m per quarter) | CP24: 296.875 | CR24: 6.25% × $19.0bn liquidation preference ÷ 4.
B25: 1H26 y/y growth (Q3–Q4/26E driver before scenario shift) | BY25: =IFERROR(SUM(BW23:BX23)/SUM(BR23:BS23)-1,0) -> 0.73064441 | BZ25: =IFERROR(SUM(BW23:BX23)/SUM(BR23:BS23)-1,0) -> 0.73064441 | CN25: 2H26E deferred income taxes ($m) | CP25: 0 | CR25: Not forecast (assumption).
B26: Other Bets | N26: 12 | S26: 327 | T26: 80 | U26: 74 | V26: 141 | W26: 150 | X26: 445 | Y26: 165 | Z26: 185 | AA26: 197 | AB26: -259 | AC26: 288 | AD26: 132 | AE26: 97 | AF26: 117 | AG26: 131 | AH26: 477 | AI26: 150 | AJ26: 145 | AK26: 146 | AL26: 154 | AM26: 595 | AN26: 170 | AO26: 162 | AP26: 155 | AQ26: 172 | AR26: 659 | AS26: 135 | AT26: 148 | AU26: 178 | AV26: 196 | AW26: 657 | AX26: 198 | AY26: 192 | AZ26: 182 | BA26: 181 | BB26: 753 | BC26: 440 | BD26: 193 | BE26: 209 | BF26: 226 | BG26: 1068 | BH26: 288 | BI26: 285 | BJ26: 297 | BK26: 657 | BL26: 1527 | BM26: 495 | BN26: 365 | BO26: 388 | BP26: 400 | BQ26: 1648 | BR26: 450 | BS26: 373 | BT26: 344 | BU26: 370 | BV26: 1537 | BW26: 411 | BX26: 382 | BY26: =BT26*(1+BY27) -> 331.46051 | BZ26: =BU26*(1+BZ27) -> 356.51276 | CA26: =SUM(BW26:BZ26) -> 1480.9733 | CB26: =CA26*(1+CB27) -> 1036.6813 | CC26: =CB26*(1+CC27) -> 1295.8516 | CD26: =CC26*(1+CD27) -> 1619.8145 | CE26: =CD26*(1+CE27) -> 2024.7681 | CF26: Other Bets segment revenues (from FY2015; recast basis where presented).
B27: y/y % | D27: =IF(AND(ISNUMBER(D26),ISNUMBER(C26)),IFERROR(D26/C26-1,""),"") | E27: =IF(AND(ISNUMBER(E26),ISNUMBER(D26)),IFERROR(E26/D26-1,""),"") | F27: =IF(AND(ISNUMBER(F26),ISNUMBER(E26)),IFERROR(F26/E26-1,""),"") | G27: =IF(AND(ISNUMBER(G26),ISNUMBER(F26)),IFERROR(G26/F26-1,""),"") | H27: =IF(AND(ISNUMBER(H26),ISNUMBER(G26)),IFERROR(H26/G26-1,""),"") | I27: =IF(AND(ISNUMBER(I26),ISNUMBER(H26)),IFERROR(I26/H26-1,""),"") | N27: =IF(AND(ISNUMBER(N26),ISNUMBER(I26)),IFERROR(N26/I26-1,""),"") | O27: =IF(AND(ISNUMBER(O26),ISNUMBER(J26)),IFERROR(O26/J26-1,""),"") | P27: =IF(AND(ISNUMBER(P26),ISNUMBER(K26)),IFERROR(P26/K26-1,""),"") | Q27: =IF(AND(ISNUMBER(Q26),ISNUMBER(L26)),IFERROR(Q26/L26-1,""),"") | R27: =IF(AND(ISNUMBER(R26),ISNUMBER(M26)),IFERROR(R26/M26-1,""),"") | S27: =IF(AND(ISNUMBER(S26),ISNUMBER(N26)),IFERROR(S26/N26-1,""),"") -> 26.25 | T27: =IF(AND(ISNUMBER(T26),ISNUMBER(O26)),IFERROR(T26/O26-1,""),"") | U27: =IF(AND(ISNUMBER(U26),ISNUMBER(P26)),IFERROR(U26/P26-1,""),"") | ... BX27: =IF(AND(ISNUMBER(BX26),ISNUMBER(BS26)),IFERROR(BX26/BS26-1,""),"") -> 0.024128686 | BY27: =BY28+BY97 -> -0.036452005 | BZ27: =BY28+BY97 -> -0.036452005 | CA27: =IF(AND(ISNUMBER(CA26),ISNUMBER(BV26)),IFERROR(CA26/BV26-1,""),"") -> -0.036452005 | CB27: =CHOOSE(MATCH($CF$2,{"Bull","Base","Bear"},0),$CO$55,$CP$55,$CQ$55) -> -0.3 | CC27: =CHOOSE(MATCH($CF$2,{"Bull","Base","Bear"},0),$CO$56,$CP$56,$CQ$56) -> 0.25 | CD27: =CHOOSE(MATCH($CF$2,{"Bull","Base","Bear"},0),$CO$57,$CP$57,$CQ$57) -> 0.25 | CE27: =CHOOSE(MATCH($CF$2,{"Bull","Base","Bear"},0),$CO$58,$CP$58,$CQ$58) -> 0.25 | CN27: Target net debt / adjusted EBITDA (x; negative = net-cash floor) — buyback plug 2027E+ | CO27: -0.1 | CP27: -0.25 | CQ27: -0.4 | CR27: Alphabet is net cash ($142bn at 30-Jun-2026 after the $49.6bn equity raise; $100bn of debt vs $242bn of cash and marketable securities). Negative target = net-cash floor: buybacks return liquidity above |x| × adjusted EBITDA. Bull −0.10x (more buybacks), Base −0.25x, Bear −0.40x (assumption).
B28: 1H26 y/y growth (Q3–Q4/26E driver before scenario shift) | BY28: =IFERROR(SUM(BW26:BX26)/SUM(BR26:BS26)-1,0) -> -0.036452005 | BZ28: =IFERROR(SUM(BW26:BX26)/SUM(BR26:BS26)-1,0) -> -0.036452005
B29: Hedging gains (losses) (not allocated to segments; derived = revenues − segment revenues) | AM29: -138 | AR29: 455 | AS29: 49 | AT29: 151 | AU29: -22 | AV29: -2 | AW29: 176 | AX29: -109 | AY29: -7 | AZ29: 62 | BA29: 203 | BB29: 149 | BC29: 278 | BD29: 375 | BE29: 638 | BF29: 669 | BG29: 1960 | BH29: 84 | BI29: 3 | BJ29: -1 | BK29: 150 | BL29: 236 | BM29: 72 | BN29: 102 | BO29: 17 | BP29: 20 | BQ29: 211 | BR29: 260 | BS29: -112 | BT29: -207 | BU29: -67 | BV29: -127 | BW29: -180 | BX29: 106 | BY29: =0 -> 0 | BZ29: =0 -> 0 | CA29: =SUM(BW29:BZ29) -> -74 | CB29: =0 -> 0 | CC29: =0 -> 0 | CD29: =0 -> 0 | CE29: =0 -> 0 | CF29: Cash-flow hedging gains / losses recorded in revenues (Alphabet-level). Forecast nil. | CN29: SEARCH (Google Search & other y/y) | CO29: 0.02 | CP29: Δ → | CQ29: -0.04 | CR29: 1H26 +17.9% (FY2025 +13.4%, FY2024 +13.2%); AI Overviews / AI Mode monetisation vs competition from AI assistants. Assumption.
B30: Revenues not split on the current taxonomy / basis differences (derived) | C30: =IF(ISNUMBER(C132),C132-(N(C11)+N(C14)+N(C17)+N(C20)+N(C23)+N(C26)+N(C29)),"") -> 10604.917 | D30: =IF(ISNUMBER(D132),D132-(N(D11)+N(D14)+N(D17)+N(D20)+N(D23)+N(D26)+N(D29)),"") -> 16593.986 | E30: =IF(ISNUMBER(E132),E132-(N(E11)+N(E14)+N(E17)+N(E20)+N(E23)+N(E26)+N(E29)),"") -> 21795.55 | F30: =IF(ISNUMBER(F132),F132-(N(F11)+N(F14)+N(F17)+N(F20)+N(F23)+N(F26)+N(F29)),"") -> 23650.563 | G30: =IF(ISNUMBER(G132),G132-(N(G11)+N(G14)+N(G17)+N(G20)+N(G23)+N(G26)+N(G29)),"") -> 29321 | H30: =IF(ISNUMBER(H132),H132-(N(H11)+N(H14)+N(H17)+N(H20)+N(H23)+N(H26)+N(H29)),"") -> 37905 | I30: =IF(ISNUMBER(I132),I132-(N(I11)+N(I14)+N(I17)+N(I20)+N(I23)+N(I26)+N(I29)),"") -> 50175 | J30: =IF(ISNUMBER(J132),J132-(N(J11)+N(J14)+N(J17)+N(J20)+N(J23)+N(J26)+N(J29)),"") -> 13969 | ... BX30: =IF(ISNUMBER(BX132),BX132-(N(BX11)+N(BX14)+N(BX17)+N(BX20)+N(BX23)+N(BX26)+N(BX29)),"") -> 0 | BY30: =0 -> 0 | BZ30: =0 -> 0 | CA30: =SUM(BW30:BZ30) -> 0 | CB30: =0 -> 0 | CC30: =0 -> 0 | CD30: =0 -> 0 | CE30: =0 -> 0 | CF30: Consolidated revenues (as originally reported) − Σ revenue types (latest filing presenting the period). Equals total revenues before FY2017 / Q1-19 (legacy split in the memo block below); Other Bets before FY2015. | CN30: 2027E | CO30: =CP30+$CO$29 -> 0.13 | CP30: 0.11 | CQ30: =CP30+$CQ$29 -> 0.07
B31: Total revenues (revenue build) | C31: =IF(ISNUMBER(C132),N(C11)+N(C14)+N(C17)+N(C20)+N(C23)+N(C26)+N(C29)+N(C30),"") -> 10604.917 | D31: =IF(ISNUMBER(D132),N(D11)+N(D14)+N(D17)+N(D20)+N(D23)+N(D26)+N(D29)+N(D30),"") -> 16593.986 | E31: =IF(ISNUMBER(E132),N(E11)+N(E14)+N(E17)+N(E20)+N(E23)+N(E26)+N(E29)+N(E30),"") -> 21795.55 | F31: =IF(ISNUMBER(F132),N(F11)+N(F14)+N(F17)+N(F20)+N(F23)+N(F26)+N(F29)+N(F30),"") -> 23650.563 | G31: =IF(ISNUMBER(G132),N(G11)+N(G14)+N(G17)+N(G20)+N(G23)+N(G26)+N(G29)+N(G30),"") -> 29321 | H31: =IF(ISNUMBER(H132),N(H11)+N(H14)+N(H17)+N(H20)+N(H23)+N(H26)+N(H29)+N(H30),"") -> 37905 | I31: =IF(ISNUMBER(I132),N(I11)+N(I14)+N(I17)+N(I20)+N(I23)+N(I26)+N(I29)+N(I30),"") -> 50175 | J31: =IF(ISNUMBER(J132),N(J11)+N(J14)+N(J17)+N(J20)+N(J23)+N(J26)+N(J29)+N(J30),"") -> 13969 | ... BX31: =IF(ISNUMBER(BX132),N(BX11)+N(BX14)+N(BX17)+N(BX20)+N(BX23)+N(BX26)+N(BX29)+N(BX30),"") -> 119796 | BY31: =N(BY11)+N(BY14)+N(BY17)+N(BY20)+N(BY23)+N(BY26)+N(BY29) -> 127000.55 | BZ31: =N(BZ11)+N(BZ14)+N(BZ17)+N(BZ20)+N(BZ23)+N(BZ26)+N(BZ29) -> 141582.69 | CA31: =N(CA11)+N(CA14)+N(CA17)+N(CA20)+N(CA23)+N(CA26)+N(CA29) -> 498275.24 | CB31: =N(CB11)+N(CB14)+N(CB17)+N(CB20)+N(CB23)+N(CB26)+N(CB29) -> 584717.43 | CC31: =N(CC11)+N(CC14)+N(CC17)+N(CC20)+N(CC23)+N(CC26)+N(CC29) -> 670428.9 | CD31: =N(CD11)+N(CD14)+N(CD17)+N(CD20)+N(CD23)+N(CD26)+N(CD29) -> 757036.21 | CE31: =N(CE11)+N(CE14)+N(CE17)+N(CE20)+N(CE23)+N(CE26)+N(CE29) -> 842257.41 | CH31: =IFERROR((CE31/BV31)^(1/5)-1,"n/m") -> 0.1589463 | CI31: =IFERROR((BV31/AW31)^(1/5)-1,"n/m") -> 0.17154839 | CJ31: =IFERROR((BV31/X31)^(1/10)-1,"n/m") -> 0.18307716 | CK31: =IFERROR((BV31/C31)^(1/19)-1,"n/m") -> 0.21098272 | CN31: 2028E | CO31: =CP31+$CO$29 -> 0.11 | CP31: 0.09 | CQ31: =CP31+$CQ$29 -> 0.05
B32: Total revenues y/y % | D32: =IF(AND(ISNUMBER(D31),ISNUMBER(C31)),IFERROR(D31/C31-1,""),"") -> 0.56474454 | E32: =IF(AND(ISNUMBER(E31),ISNUMBER(D31)),IFERROR(E31/D31-1,""),"") -> 0.31346079 | F32: =IF(AND(ISNUMBER(F31),ISNUMBER(E31)),IFERROR(F31/E31-1,""),"") -> 0.085109713 | G32: =IF(AND(ISNUMBER(G31),ISNUMBER(F31)),IFERROR(G31/F31-1,""),"") -> 0.23975907 | H32: =IF(AND(ISNUMBER(H31),ISNUMBER(G31)),IFERROR(H31/G31-1,""),"") -> 0.29275946 | I32: =IF(AND(ISNUMBER(I31),ISNUMBER(H31)),IFERROR(I31/H31-1,""),"") -> 0.323704 | N32: =IF(AND(ISNUMBER(N31),ISNUMBER(I31)),IFERROR(N31/I31-1,""),"") -> 0.19232686 | O32: =IF(AND(ISNUMBER(O31),ISNUMBER(J31)),IFERROR(O31/J31-1,""),"") -> 0.10387286 | P32: =IF(AND(ISNUMBER(P31),ISNUMBER(K31)),IFERROR(P31/K31-1,""),"") -> 0.13115916 | Q32: =IF(AND(ISNUMBER(Q31),ISNUMBER(L31)),IFERROR(Q31/L31-1,""),"") -> 0.10944739 | R32: =IF(AND(ISNUMBER(R31),ISNUMBER(M31)),IFERROR(R31/M31-1,""),"") -> 0.073852177 | S32: =IF(AND(ISNUMBER(S31),ISNUMBER(N31)),IFERROR(S31/N31-1,""),"") -> 0.10323443 | T32: =IF(AND(ISNUMBER(T31),ISNUMBER(O31)),IFERROR(T31/O31-1,""),"") -> 0.11919585 | U32: =IF(AND(ISNUMBER(U31),ISNUMBER(P31)),IFERROR(U31/P31-1,""),"") -> 0.11106236 | ... CA32: =IF(AND(ISNUMBER(CA31),ISNUMBER(BV31)),IFERROR(CA31/BV31-1,""),"") -> 0.23691834 | CB32: =IF(AND(ISNUMBER(CB31),ISNUMBER(CA31)),IFERROR(CB31/CA31-1,""),"") -> 0.17348283 | CC32: =IF(AND(ISNUMBER(CC31),ISNUMBER(CB31)),IFERROR(CC31/CB31-1,""),"") -> 0.14658614 | CD32: =IF(AND(ISNUMBER(CD31),ISNUMBER(CC31)),IFERROR(CD31/CC31-1,""),"") -> 0.12918194 | CE32: =IF(AND(ISNUMBER(CE31),ISNUMBER(CD31)),IFERROR(CE31/CD31-1,""),"") -> 0.11257215 | CH32: =IFERROR(AVERAGE(CA32,CB32,CC32,CD32,CE32),"n/m") -> 0.15974828 | CI32: =IFERROR(AVERAGE(BB32,BG32,BL32,BQ32,BV32),"n/m") -> 0.17713997 | CJ32: =IFERROR(AVERAGE(AC32,AH32,AM32,AR32,AW32,BB32,BG32,BL32,BQ32,BV32),"n/m") -> 0.18624361 | CK32: =IFERROR(AVERAGE(C32,D32,E32,F32,G32,H32,I32,N32,S32,X32,AC32,AH32,AM32,AR32,AW32,BB32,BG32,BL32,BQ32,BV32),"n/m") -> 0.2165113 | CN32: 2029E | CO32: =CP32+$CO$29 -> 0.1 | CP32: 0.08 | CQ32: =CP32+$CQ$29 -> 0.04
B33: Google Services revenues (Σ Search, YouTube, Network, subscriptions/platforms/devices) | C33: =IF(ISNUMBER(C11),C11+C14+C17+C20,"") | D33: =IF(ISNUMBER(D11),D11+D14+D17+D20,"") | E33: =IF(ISNUMBER(E11),E11+E14+E17+E20,"") | F33: =IF(ISNUMBER(F11),F11+F14+F17+F20,"") | G33: =IF(ISNUMBER(G11),G11+G14+G17+G20,"") | H33: =IF(ISNUMBER(H11),H11+H14+H17+H20,"") | I33: =IF(ISNUMBER(I11),I11+I14+I17+I20,"") | J33: =IF(ISNUMBER(J11),J11+J14+J17+J20,"") | ... CE33: =IF(ISNUMBER(CE11),CE11+CE14+CE17+CE20,"") -> 548546.27 | CH33: =IFERROR((CE33/BV33)^(1/5)-1,"n/m") -> 0.098637732 | CI33: =IFERROR((BV33/AW33)^(1/5)-1,"n/m") -> 0.15238766 | CJ33: =IFERROR((BV33/X33)^(1/10)-1,"n/m") -> n/m | CK33: =IFERROR((BV33/C33)^(1/19)-1,"n/m") -> n/m | CN33: 2030E | CO33: =CP33+$CO$29 -> 0.09 | CP33: 0.07 | CQ33: =CP33+$CQ$29 -> 0.03
B34: Google Services y/y % | D34: =IF(AND(ISNUMBER(D33),ISNUMBER(C33)),IFERROR(D33/C33-1,""),"") | E34: =IF(AND(ISNUMBER(E33),ISNUMBER(D33)),IFERROR(E33/D33-1,""),"") | F34: =IF(AND(ISNUMBER(F33),ISNUMBER(E33)),IFERROR(F33/E33-1,""),"") | G34: =IF(AND(ISNUMBER(G33),ISNUMBER(F33)),IFERROR(G33/F33-1,""),"") | H34: =IF(AND(ISNUMBER(H33),ISNUMBER(G33)),IFERROR(H33/G33-1,""),"") | I34: =IF(AND(ISNUMBER(I33),ISNUMBER(H33)),IFERROR(I33/H33-1,""),"") | N34: =IF(AND(ISNUMBER(N33),ISNUMBER(I33)),IFERROR(N33/I33-1,""),"") | O34: =IF(AND(ISNUMBER(O33),ISNUMBER(J33)),IFERROR(O33/J33-1,""),"") | P34: =IF(AND(ISNUMBER(P33),ISNUMBER(K33)),IFERROR(P33/K33-1,""),"") | Q34: =IF(AND(ISNUMBER(Q33),ISNUMBER(L33)),IFERROR(Q33/L33-1,""),"") | R34: =IF(AND(ISNUMBER(R33),ISNUMBER(M33)),IFERROR(R33/M33-1,""),"") | S34: =IF(AND(ISNUMBER(S33),ISNUMBER(N33)),IFERROR(S33/N33-1,""),"") | T34: =IF(AND(ISNUMBER(T33),ISNUMBER(O33)),IFERROR(T33/O33-1,""),"") | U34: =IF(AND(ISNUMBER(U33),ISNUMBER(P33)),IFERROR(U33/P33-1,""),"") | ... CA34: =IF(AND(ISNUMBER(CA33),ISNUMBER(BV33)),IFERROR(CA33/BV33-1,""),"") -> 0.15333109 | CB34: =IF(AND(ISNUMBER(CB33),ISNUMBER(CA33)),IFERROR(CB33/CA33-1,""),"") -> 0.10396322 | CC34: =IF(AND(ISNUMBER(CC33),ISNUMBER(CB33)),IFERROR(CC33/CB33-1,""),"") -> 0.087796043 | CD34: =IF(AND(ISNUMBER(CD33),ISNUMBER(CC33)),IFERROR(CD33/CC33-1,""),"") -> 0.079357275 | CE34: =IF(AND(ISNUMBER(CE33),ISNUMBER(CD33)),IFERROR(CE33/CD33-1,""),"") -> 0.070659196 | CN34: YOUTUBE (YouTube ads y/y) | CO34: 0.02 | CP34: Δ → | CQ34: -0.04 | CR34: 1H26 +11.8% (FY2025 +11.7%). Assumption.
B35: Memo: Google Services segment revenues as reported (segment note) | AM35: 130524 | AR35: 151825 | AS35: 38198 | AT35: 34991 | AU35: 42573 | AV35: 52873 | AW35: 168635 | AX35: 51178 | AY35: 57067 | AZ35: 59884 | BA35: 69400 | BB35: 237529 | BC35: 61472 | BD35: 62841 | BE35: 61377 | BF35: 67838 | BG35: 253528 | BH35: 61961 | BI35: 66285 | BJ35: 67986 | BK35: 76311 | BL35: 272543 | BM35: 70398 | BN35: 73928 | BO35: 76510 | BP35: 84094 | BQ35: 304930 | BR35: 77264 | BS35: 82543 | BT35: 87052 | BU35: 95862 | BV35: 342721 | BW35: 89637 | BX35: 94540 | CN35: 2027E | CO35: =CP35+$CO$34 -> 0.13 | CP35: 0.11 | CQ35: =CP35+$CQ$34 -> 0.07
B36: Check: revenue types vs Google Services segment revenues (should be 0) | C36: =IF(AND(ISNUMBER(C33),ISNUMBER(C35)),IF(ABS(C33-C35)<=1,0,ROUND(C33-C35,0)),"") | D36: =IF(AND(ISNUMBER(D33),ISNUMBER(D35)),IF(ABS(D33-D35)<=1,0,ROUND(D33-D35,0)),"") | E36: =IF(AND(ISNUMBER(E33),ISNUMBER(E35)),IF(ABS(E33-E35)<=1,0,ROUND(E33-E35,0)),"") | F36: =IF(AND(ISNUMBER(F33),ISNUMBER(F35)),IF(ABS(F33-F35)<=1,0,ROUND(F33-F35,0)),"") | G36: =IF(AND(ISNUMBER(G33),ISNUMBER(G35)),IF(ABS(G33-G35)<=1,0,ROUND(G33-G35,0)),"") | H36: =IF(AND(ISNUMBER(H33),ISNUMBER(H35)),IF(ABS(H33-H35)<=1,0,ROUND(H33-H35,0)),"") | I36: =IF(AND(ISNUMBER(I33),ISNUMBER(I35)),IF(ABS(I33-I35)<=1,0,ROUND(I33-I35,0)),"") | J36: =IF(AND(ISNUMBER(J33),ISNUMBER(J35)),IF(ABS(J33-J35)<=1,0,ROUND(J33-J35,0)),"") | ... BX36: =IF(AND(ISNUMBER(BX33),ISNUMBER(BX35)),IF(ABS(BX33-BX35)<=1,0,ROUND(BX33-BX35,0)),"") -> 0 | CN36: 2028E | CO36: =CP36+$CO$34 -> 0.12 | CP36: 0.1 | CQ36: =CP36+$CQ$34 -> 0.06
B37: Google advertising (Search + YouTube + Network) | C37: =IF(ISNUMBER(C11),C11+C14+C17,"") | D37: =IF(ISNUMBER(D11),D11+D14+D17,"") | E37: =IF(ISNUMBER(E11),E11+E14+E17,"") | F37: =IF(ISNUMBER(F11),F11+F14+F17,"") | G37: =IF(ISNUMBER(G11),G11+G14+G17,"") | H37: =IF(ISNUMBER(H11),H11+H14+H17,"") | I37: =IF(ISNUMBER(I11),I11+I14+I17,"") | J37: =IF(ISNUMBER(J11),J11+J14+J17,"") | ... CE37: =IF(ISNUMBER(CE11),CE11+CE14+CE17,"") -> 460786.78 | CH37: =IFERROR((CE37/BV37)^(1/5)-1,"n/m") -> 0.093519739 | CI37: =IFERROR((BV37/AW37)^(1/5)-1,"n/m") -> 0.14935668 | CJ37: =IFERROR((BV37/X37)^(1/10)-1,"n/m") -> n/m | CK37: =IFERROR((BV37/C37)^(1/19)-1,"n/m") -> n/m | CN37: 2029E | CO37: =CP37+$CO$34 -> 0.11 | CP37: 0.09 | CQ37: =CP37+$CQ$34 -> 0.05
B38: Google Cloud % of total revenues | C38: =IF(AND(ISNUMBER(C23),ISNUMBER(C132)),IFERROR(C23/C132,""),"") | D38: =IF(AND(ISNUMBER(D23),ISNUMBER(D132)),IFERROR(D23/D132,""),"") | E38: =IF(AND(ISNUMBER(E23),ISNUMBER(E132)),IFERROR(E23/E132,""),"") | F38: =IF(AND(ISNUMBER(F23),ISNUMBER(F132)),IFERROR(F23/F132,""),"") | G38: =IF(AND(ISNUMBER(G23),ISNUMBER(G132)),IFERROR(G23/G132,""),"") | H38: =IF(AND(ISNUMBER(H23),ISNUMBER(H132)),IFERROR(H23/H132,""),"") | I38: =IF(AND(ISNUMBER(I23),ISNUMBER(I132)),IFERROR(I23/I132,""),"") | J38: =IF(AND(ISNUMBER(J23),ISNUMBER(J132)),IFERROR(J23/J132,""),"") | ... CE38: =IF(AND(ISNUMBER(CE23),ISNUMBER(CE132)),IFERROR(CE23/CE132,""),"") -> 0.34569878 | CH38: =IFERROR(AVERAGE(CA38,CB38,CC38,CD38,CE38),"n/m") -> 0.28239203 | CI38: =IFERROR(AVERAGE(BB38,BG38,BL38,BQ38,BV38),"n/m") -> 0.1088675 | CJ38: =IFERROR(AVERAGE(AC38,AH38,AM38,AR38,AW38,BB38,BG38,BL38,BQ38,BV38),"n/m") -> 0.083359882 | CK38: =IFERROR(AVERAGE(C38,D38,E38,F38,G38,H38,I38,N38,S38,X38,AC38,AH38,AM38,AR38,AW38,BB38,BG38,BL38,BQ38,BV38),"n/m") -> 0.083359882 | CN38: 2030E | CO38: =CP38+$CO$34 -> 0.1 | CP38: 0.08 | CQ38: =CP38+$CQ$34 -> 0.04
B39: Contribution to revenue growth — Google Services (pp) | D39: =IFERROR((D33-C33)/C132,"") | E39: =IFERROR((E33-D33)/D132,"") | F39: =IFERROR((F33-E33)/E132,"") | G39: =IFERROR((G33-F33)/F132,"") | H39: =IFERROR((H33-G33)/G132,"") | I39: =IFERROR((I33-H33)/H132,"") | N39: =IFERROR((N33-I33)/I132,"") | O39: =IFERROR((O33-J33)/J132,"") | P39: =IFERROR((P33-K33)/K132,"") | Q39: =IFERROR((Q33-L33)/L132,"") | R39: =IFERROR((R33-M33)/M132,"") | S39: =IFERROR((S33-N33)/N132,"") | T39: =IFERROR((T33-O33)/O132,"") | U39: =IFERROR((U33-P33)/P132,"") | ... CA39: =IFERROR((CA33-BV33)/BV132,"") -> 0.13044957 | CB39: =IFERROR((CB33-CA33)/CA132,"") -> 0.082471733 | CC39: =IFERROR((CC33-CB33)/CB132,"") -> 0.065501983 | CD39: =IFERROR((CD33-CC33)/CC132,"") -> 0.056141688 | CE39: =IFERROR((CE33-CD33)/CD132,"") -> 0.047759089 | CN39: NETWORK (Google Network y/y) | CO39: 0.02 | CP39: Δ → | CQ39: -0.03 | CR39: 1H26 −2.3% (FY2025 −1.9%, FY2024 −3.0%): structural decline. Assumption.
B40: Contribution to revenue growth — Google Cloud (pp) | D40: =IFERROR((D23-C23)/C132,"") -> 0 | E40: =IFERROR((E23-D23)/D132,"") -> 0 | F40: =IFERROR((F23-E23)/E132,"") -> 0 | G40: =IFERROR((G23-F23)/F132,"") -> 0 | H40: =IFERROR((H23-G23)/G132,"") -> 0 | I40: =IFERROR((I23-H23)/H132,"") -> 0 | N40: =IFERROR((N23-I23)/I132,"") -> 0 | O40: =IFERROR((O23-J23)/J132,"") -> 0 | P40: =IFERROR((P23-K23)/K132,"") -> 0 | Q40: =IFERROR((Q23-L23)/L132,"") -> 0 | R40: =IFERROR((R23-M23)/M132,"") -> 0 | S40: =IFERROR((S23-N23)/N132,"") -> 0 | T40: =IFERROR((T23-O23)/O132,"") -> 0 | U40: =IFERROR((U23-P23)/P132,"") -> 0 | ... CA40: =IFERROR((CA23-BV23)/BV132,"") -> 0.10647628 | CB40: =IFERROR((CB23-CA23)/CA132,"") -> 0.091754241 | CC40: =IFERROR((CC23-CB23)/CB132,"") -> 0.080599269 | CD40: =IFERROR((CD23-CC23)/CC132,"") -> 0.07245474 | CE40: =IFERROR((CE23-CD23)/CD132,"") -> 0.064134277 | CN40: 2027E | CO40: =CP40+$CO$39 -> -0.01 | CP40: -0.03 | CQ40: =CP40+$CQ$39 -> -0.06
...

Sheet Bull-Base-Bear
B2: Alphabet Inc. (GOOG) — Bull / Base / Bear Case P&L Summary | J2: Share price ($): | K2: =Model!$CA$407 -> 350
B3: Model-defined adjusted figures (adjusted EBITDA / operating income / EPS exclude company-reconciled EC fines and severance charges, equity-security gains and the Tax Act; Alphabet publishes no EBITDA or adjusted EPS) · USD millions · Live panel linked to Model — toggle scenario via Model!CF2. Bull and Bear panels are value snapshots generated from the Model with the switch set to each case. 2026E = Q1–Q2 actual + Q3–Q4 estimate (no company guidance). | J3: As of: | K3: =TODAY() -> 2026-10-13 00:00:00
B5: Scenario: | C5: =Model!$CF$2 -> Base | N5: Scenario: | O5: Bull | P5: Snapshot (values) — Model run with switch = Bull | Z5: Scenario: | AA5: Bear | AB5: Snapshot (values) — Model run with switch = Bear
B7: (USDm, except EPS and shares) | C7: 2025A | D7: 2026E | E7: 2027E | F7: 2028E | G7: 2029E | H7: 2030E | I7: 25-'30 CAGR | J7: LT Hist Avg | K7: LT Hist Min | L7: LT Hist Max | N7: (USDm, except EPS and shares) | O7: 2025A | P7: 2026E | Q7: 2027E | R7: 2028E | S7: 2029E | T7: 2030E | U7: 25-'30 CAGR | V7: LT Hist Avg | W7: LT Hist Min | X7: LT Hist Max | Z7: (USDm, except EPS and shares) | AA7: 2025A | AB7: 2026E | AC7: 2027E | AD7: 2028E | AE7: 2029E | AF7: 2030E | AG7: 25-'30 CAGR | AH7: LT Hist Avg | AI7: LT Hist Min | AJ7: LT Hist Max
B9: Revenues | C9: =Model!BV132 -> 402836 | D9: =Model!CA132 -> 498275.24 | E9: =Model!CB132 -> 584884.1 | F9: =Model!CC132 -> 670962.24 | G9: =Model!CD132 -> 758009.55 | H9: =Model!CE132 -> 843758.74 | I9: =IFERROR((H9/C9)^(1/5)-1,"n/m") -> 0.15935917 | N9: Revenues | O9: 402836 | P9: 502604.22 | Q9: 606355.04 | R9: 718406.35 | S9: 841460.72 | T9: 974322 | U9: 0.1932044 | Z9: Revenues | AA9: 402836 | AB9: 491781.77 | AC9: 549699.33 | AD9: 596689.15 | AE9: 635070.54 | AF9: 663838.88 | AG9: 0.1050626
B10: Revenues y/y % | D10: =IFERROR(D9/C9-1,"") -> 0.23691834 | E10: =IFERROR(E9/D9-1,"") -> 0.17381731 | F10: =IFERROR(F9/E9-1,"") -> 0.14717127 | G10: =IFERROR(G9/F9-1,"") -> 0.12973504 | H10: =IFERROR(H9/G9-1,"") -> 0.11312416 | N10: Revenues y/y % | P10: 0.2476646 | Q10: 0.20642649 | R10: 0.18479489 | S10: 0.17128798 | T10: 0.15789362 | Z10: Revenues y/y % | AB10: 0.22079895 | AC10: 0.11777087 | AD10: 0.085482764 | AE10: 0.064323931 | AF10: 0.045299438
B11: Google Cloud revenues y/y % | C11: =Model!BV230 -> 0.35800042 | D11: =Model!CA230 -> 0.73064441 | E11: =Model!CB230 -> 0.45 | F11: =Model!CC230 -> 0.32 | G11: =Model!CD230 -> 0.25 | H11: =Model!CE230 -> 0.2 | N11: Google Cloud revenues y/y % | O11: 0.35800042 | P11: 0.74182608 | Q11: 0.53 | R11: 0.4 | S11: 0.33 | T11: 0.28 | Z11: Google Cloud revenues y/y % | AA11: 0.35800042 | AB11: 0.71387191 | AC11: 0.33 | AD11: 0.2 | AE11: 0.13 | AF11: 0.08
B12: Adjusted EBITDA (model) | C12: =Model!BV191 -> 153632 | D12: =Model!CA191 -> 204129.25 | E12: =Model!CB191 -> 244974.62 | F12: =Model!CC191 -> 286016.96 | G12: =Model!CD191 -> 331272.46 | H12: =Model!CE191 -> 375223.2 | I12: =IFERROR((H12/C12)^(1/5)-1,"n/m") -> 0.19553308 | N12: Adjusted EBITDA (model) | O12: 153632 | P12: 208622.97 | Q12: 265933.87 | R12: 315961.49 | S12: 373500.21 | T12: 433081.09 | U12: 0.23031837 | Z12: Adjusted EBITDA (model) | AA12: 153632 | AB12: 197550.49 | AC12: 210807.6 | AD12: 239741.89 | AE12: 270285.34 | AF12: 297678.14 | AG12: 0.1414399
B13: Adjusted EBITDA margin % | C13: =IFERROR(C12/C9,"") -> 0.38137604 | D13: =IFERROR(D12/D9,"") -> 0.40967168 | E13: =IFERROR(E12/E9,"") -> 0.41884301 | F13: =IFERROR(F12/F9,"") -> 0.42627878 | G13: =IFERROR(G12/G9,"") -> 0.4370294 | H13: =IFERROR(H12/H9,"") -> 0.44470437 | J13: =IFERROR(AVERAGE(Model!C192,Model!D192,Model!E192,Model!F192,Model!G192,Model!H192,Model!I192,Model!N192,Model!S192,Model!X192,Model!AC192,Model!AH192,Model!AM192,Model!AR192,Model!AW192,Model!BB192,Model!BG192,Model!BL192,Model!BQ192,Model!BV192),"") -> 0.34277958 | K13: =IFERROR(MIN(Model!C192,Model!D192,Model!E192,Model!F192,Model!G192,Model!H192,Model!I192,Model!N192,Model!S192,Model!X192,Model!AC192,Model!AH192,Model!AM192,Model!AR192,Model!AW192,Model!BB192,Model!BG192,Model!BL192,Model!BQ192,Model!BV192),"") -> 0.29476019 | L13: =IFERROR(MAX(Model!C192,Model!D192,Model!E192,Model!F192,Model!G192,Model!H192,Model!I192,Model!N192,Model!S192,Model!X192,Model!AC192,Model!AH192,Model!AM192,Model!AR192,Model!AW192,Model!BB192,Model!BG192,Model!BL192,Model!BQ192,Model!BV192),"") -> 0.41590951 | N13: Adjusted EBITDA margin % | O13: 0.38137604 | P13: 0.41508399 | Q13: 0.43857782 | R13: 0.43980887 | S13: 0.44387123 | T13: 0.44449483 | V13: 0.34277958 | W13: 0.29476019 | X13: 0.41590951 | Z13: Adjusted EBITDA margin % | AA13: 0.38137604 | AB13: 0.40170357 | AC13: 0.38349619 | AD13: 0.40178691 | AE13: 0.42559892 | AF13: 0.44841925 | AH13: 0.34277958 | AI13: 0.29476019 | AJ13: 0.41590951
B15: Income from operations (GAAP) | C15: =Model!BV140 -> 129039 | D15: =Model!CA140 -> 172938.83 | E15: =Model!CB140 -> 194643.24 | F15: =Model!CC140 -> 212421.88 | G15: =Model!CD140 -> 234774.62 | H15: =Model!CE140 -> 256717.05 | I15: =IFERROR((H15/C15)^(1/5)-1,"n/m") -> 0.14748428 | N15: Income from operations (GAAP) | O15: 129039 | P15: 177432.54 | Q15: 215515 | R15: 243253.91 | S15: 278732.63 | T15: 317030.91 | U15: 0.19695031 | Z15: Income from operations (GAAP) | AA15: 129039 | AB15: 166360.07 | AC15: 160563.73 | AD15: 164684.31 | AE15: 170973.38 | AF15: 175181.8 | AG15: 0.063049777
B16: Operating income y/y % | D16: =IFERROR(D15/C15-1,"") -> 0.34020592 | E16: =IFERROR(E15/D15-1,"") -> 0.12550338 | F16: =IFERROR(F15/E15-1,"") -> 0.091339623 | G16: =IFERROR(G15/F15-1,"") -> 0.10522805 | H16: =IFERROR(H15/G15-1,"") -> 0.093461672 | N16: Operating income y/y % | P16: 0.37503036 | Q16: 0.21463061 | R16: 0.12870988 | S16: 0.14585056 | T16: 0.1374015 | Z16: Operating income y/y % | AB16: 0.28922316 | AC16: -0.034842146 | AD16: 0.025663232 | AE16: 0.03818863 | AF16: 0.02461451
B17: Operating margin (GAAP) % | C17: =IFERROR(C15/C9,"") -> 0.32032639 | D17: =IFERROR(D15/D9,"") -> 0.34707491 | E17: =IFERROR(E15/E9,"") -> 0.33278942 | F17: =IFERROR(F15/F9,"") -> 0.3165929 | G17: =IFERROR(G15/G9,"") -> 0.30972515 | H17: =IFERROR(H15/H9,"") -> 0.30425409 | J17: =IFERROR(AVERAGE(Model!C239,Model!D239,Model!E239,Model!F239,Model!G239,Model!H239,Model!I239,Model!N239,Model!S239,Model!X239,Model!AC239,Model!AH239,Model!AM239,Model!AR239,Model!AW239,Model!BB239,Model!BG239,Model!BL239,Model!BQ239,Model!BV239),"") -> 0.27853231 | K17: =IFERROR(MIN(Model!C239,Model!D239,Model!E239,Model!F239,Model!G239,Model!H239,Model!I239,Model!N239,Model!S239,Model!X239,Model!AC239,Model!AH239,Model!AM239,Model!AR239,Model!AW239,Model!BB239,Model!BG239,Model!BL239,Model!BQ239,Model!BV239),"") -> 0.19237825 | L17: =IFERROR(MAX(Model!C239,Model!D239,Model!E239,Model!F239,Model!G239,Model!H239,Model!I239,Model!N239,Model!S239,Model!X239,Model!AC239,Model!AH239,Model!AM239,Model!AR239,Model!AW239,Model!BB239,Model!BG239,Model!BL239,Model!BQ239,Model!BV239),"") -> 0.35404659 | N17: Operating margin (GAAP) % | O17: 0.32032639 | P17: 0.35302637 | Q17: 0.35542707 | R17: 0.33860211 | S17: 0.33124853 | T17: 0.32538617 | V17: 0.27853231 | W17: 0.19237825 | X17: 0.35404659 | Z17: Operating margin (GAAP) % | AA17: 0.32032639 | AB17: 0.33828027 | AC17: 0.29209372 | AD17: 0.27599682 | AE17: 0.26921951 | AF17: 0.26389205 | AH17: 0.27853231 | AI17: 0.19237825 | AJ17: 0.35404659
B19: Adjusted Net Income (model) | C19: =Model!BV207 -> 116603.8 | D19: =Model!CA207 -> 144596.06 | E19: =Model!CB207 -> 162952.16 | F19: =Model!CC207 -> 176055.03 | G19: =Model!CD207 -> 194039.03 | H19: =Model!CE207 -> 212409.08 | I19: =IFERROR((H19/C19)^(1/5)-1,"n/m") -> 0.12743645 | N19: Adjusted Net Income (model) | O19: 116603.8 | P19: 148280.9 | Q19: 180144.02 | R19: 200576.69 | S19: 229978.7 | T19: 261726.69 | U19: 0.17551198 | Z19: Adjusted Net Income (model) | AA19: 116603.8 | AB19: 139201.47 | AC19: 134683.2 | AD19: 136244.82 | AE19: 139631.71 | AF19: 141595.15 | AG19: 0.039602064
B21: FDSO (m) | C21: =Model!BV159 -> 12230 | D21: =Model!CA159 -> 12364.626 | E21: =Model!CB159 -> 12508.809 | F21: =Model!CC159 -> 12588.631 | G21: =Model!CD159 -> 12699.797 | H21: =Model!CE159 -> 12825.184 | I21: =IFERROR((H21/C21)^(1/5)-1,"n/m") -> 0.0095490546 | N21: FDSO (m) | O21: 12230 | P21: 12361.054 | Q21: 12421.043 | R21: 12417.434 | S21: 12465.915 | T21: 12446.329 | U21: 0.0035129077 | Z21: FDSO (m) | AA21: 12230 | AB21: 12364.626 | AC21: 12545.265 | AD21: 12661.541 | AE21: 12772.707 | AF21: 12898.094 | AG21: 0.010694295
B23: Adjusted EPS — Diluted ($) | C23: =Model!BV209 -> 9.5342437 | D23: =Model!CA209 -> 11.694334 | E23: =Model!CB209 -> 13.026992 | F23: =Model!CC209 -> 13.98524 | G23: =Model!CD209 -> 15.278909 | H23: =Model!CE209 -> 16.561874 | I23: =IFERROR((H23/C23)^(1/5)-1,"n/m") -> 0.11677233 | N23: Adjusted EPS — Diluted ($) | O23: 9.5342437 | P23: 11.995813 | Q23: 14.503131 | R23: 16.152829 | S23: 18.448602 | T23: 21.028424 | U23: 0.17139697 | Z23: Adjusted EPS — Diluted ($) | AA23: 9.5342437 | AB23: 11.258042 | AC23: 10.73578 | AD23: 10.760524 | AE23: 10.932037 | AF23: 10.97799 | AG23: 0.028601891
B24: EPS y/y % | D24: =IFERROR(D23/C23-1,"") -> 0.22656123 | E24: =IFERROR(E23/D23-1,"") -> 0.11395759 | F24: =IFERROR(F23/E23-1,"") -> 0.073558701 | G24: =IFERROR(G23/F23-1,"") -> 0.092502397 | H24: =IFERROR(H23/G23-1,"") -> 0.083969714 | N24: EPS y/y % | P24: 0.25818197 | Q24: 0.20901609 | R24: 0.11374765 | S24: 0.14212828 | T24: 0.13983836 | Z24: EPS y/y % | AB24: 0.1808007 | AC24: -0.046390114 | AD24: 0.0023048784 | AE24: 0.015939097 | AF24: 0.0042034928
B26: P / E (x) — assumed (adjusted EPS) | G26: 26 | H26: 26 | N26: P / E (x) — assumed (adjusted EPS) | S26: 30 | T26: 30 | Z26: P / E (x) — assumed (adjusted EPS) | AD26: 20 | AE26: 20 | AF26: 20
B27: Price Target ($) | G27: =G26*G23 -> 397.25162 | H27: =H26*H23 -> 430.60873 | N27: Price Target ($) | S27: =S26*S23 -> 553.45807 | T27: =T26*T23 -> 630.85273 | Z27: Price Target ($) | AD27: =AD26*AD23 -> 215.21049 | AE27: =AE26*AE23 -> 218.64075 | AF27: =AF26*AF23 -> 219.5598
B28: Upside / (Downside) vs current | G28: =IFERROR(G27/$K$2-1,"") -> 0.13500464 | H28: =IFERROR(H27/$K$2-1,"") -> 0.23031065 | N28: Upside / (Downside) vs current | S28: =IFERROR(S27/$K$2-1,"") -> 0.58130877 | T28: =IFERROR(T27/$K$2-1,"") -> 0.80243638 | Z28: Upside / (Downside) vs current | AD28: =IFERROR(AD27/$K$2-1,"") -> -0.38511289 | AE28: =IFERROR(AE27/$K$2-1,"") -> -0.37531214 | AF28: =IFERROR(AF27/$K$2-1,"") -> -0.37268627
B29: IRR (to Dec-Y-1) | G29: =IFERROR((G27/$K$2)^(1/((DATE(2029-1,12,31)-$K$3)/365.25))-1,"") -> 0.058765692 | H29: =IFERROR((H27/$K$2)^(1/((DATE(2030-1,12,31)-$K$3)/365.25))-1,"") -> 0.06654993 | N29: IRR (to Dec-Y-1) | S29: =IFERROR((S27/$K$2)^(1/((DATE(2029-1,12,31)-$K$3)/365.25))-1,"") -> 0.2295375 | T29: =IFERROR((T27/$K$2)^(1/((DATE(2030-1,12,31)-$K$3)/365.25))-1,"") -> 0.20097602 | Z29: IRR (to Dec-Y-1) | AD29: =IFERROR((AD27/$K$2)^(1/((DATE(2028-1,12,31)-$K$3)/365.25))-1,"") -> -0.32972092 | AE29: =IFERROR((AE27/$K$2)^(1/((DATE(2029-1,12,31)-$K$3)/365.25))-1,"") -> -0.19116641 | AF29: =IFERROR((AF27/$K$2)^(1/((DATE(2030-1,12,31)-$K$3)/365.25))-1,"") -> -0.13493661
B31: Free Cash Flow | C31: =Model!BV273 -> 73266 | D31: =Model!CA273 -> -2821.4772 | E31: =Model!CB273 -> 8523.4065 | F31: =Model!CC273 -> 26877.572 | G31: =Model!CD273 -> 57836.084 | H31: =Model!CE273 -> 88769.812 | I31: =IFERROR((H31/C31)^(1/5)-1,"n/m") -> 0.039136415 | N31: Free Cash Flow | O31: 73266 | P31: 1139.7089 | Q31: 36284.752 | R31: 64010.17 | S31: 108030.73 | T31: 154839.92 | U31: 0.16143816 | Z31: Free Cash Flow | AA31: 73266 | AB31: -8630.5793 | AC31: -35763.039 | AD31: -31880.431 | AE31: -17460.223 | AF31: -5571.8398 | AG31: -1.5973367
B32: FCF % | C32: =IFERROR(C31/C9,"") -> 0.1818755 | D32: =IFERROR(D31/D9,"") -> -0.0056624873 | E32: =IFERROR(E31/E9,"") -> 0.014572813 | F32: =IFERROR(F31/F9,"") -> 0.040058249 | G32: =IFERROR(G31/G9,"") -> 0.076299941 | H32: =IFERROR(H31/H9,"") -> 0.10520758 | J32: =IFERROR(AVERAGE(Model!C277,Model!D277,Model!E277,Model!F277,Model!G277,Model!H277,Model!I277,Model!N277,Model!S277,Model!X277,Model!AC277,Model!AH277,Model!AM277,Model!AR277,Model!AW277,Model!BB277,Model!BG277,Model!BL277,Model!BQ277,Model!BV277),"") -> 0.22665589 | K32: =IFERROR(MIN(Model!C277,Model!D277,Model!E277,Model!F277,Model!G277,Model!H277,Model!I277,Model!N277,Model!S277,Model!X277,Model!AC277,Model!AH277,Model!AM277,Model!AR277,Model!AW277,Model!BB277,Model!BG277,Model!BL277,Model!BQ277,Model!BV277),"") -> 0.15820114 | L32: =IFERROR(MAX(Model!C277,Model!D277,Model!E277,Model!F277,Model!G277,Model!H277,Model!I277,Model!N277,Model!S277,Model!X277,Model!AC277,Model!AH277,Model!AM277,Model!AR277,Model!AW277,Model!BB277,Model!BG277,Model!BL277,Model!BQ277,Model!BV277),"") -> 0.35966628 | N32: FCF % | O32: 0.1818755 | P32: 0.0022676071 | Q32: 0.059840769 | R32: 0.089100228 | S32: 0.12838476 | T32: 0.15892068 | V32: 0.22665589 | W32: 0.15820114 | X32: 0.35966628 | Z32: FCF % | AA32: 0.1818755 | AB32: -0.017549612 | AC32: -0.065059274 | AD32: -0.053428877 | AE32: -0.02749336 | AF32: -0.0083933616 | AH32: 0.22665589 | AI32: 0.15820114 | AJ32: 0.35966628
B33: FCF / share ($) | C33: =IFERROR(C31/C21,"") -> 5.9906787 | D33: =IFERROR(D31/D21,"") -> -0.22818946 | E33: =IFERROR(E31/E21,"") -> 0.68139231 | F33: =IFERROR(F31/F21,"") -> 2.1350671 | G33: =IFERROR(G31/G21,"") -> 4.5540952 | H33: =IFERROR(H31/H21,"") -> 6.9215237 | N33: FCF / share ($) | O33: 5.9906787 | P33: 0.092201593 | Q33: 2.9212323 | R33: 5.1548628 | S33: 8.6660896 | T33: 12.44061 | Z33: FCF / share ($) | AA33: 5.9906787 | AB33: -0.69800572 | AC33: -2.8507202 | AD33: -2.517895 | AE33: -1.3669947 | AF33: -0.4319894
B34: FCF Yield (on PT) | F34: =IFERROR(F33/F$27,"") | G34: =IFERROR(G33/G$27,"") -> 0.011464007 | H34: =IFERROR(H33/H$27,"") -> 0.016073812 | N34: FCF Yield (on PT) | R34: =IFERROR(R33/R$27,"") | S34: =IFERROR(S33/S$27,"") -> 0.015658078 | T34: =IFERROR(T33/T$27,"") -> 0.019720307 | Z34: FCF Yield (on PT) | AD34: =IFERROR(AD33/AD$27,"") -> -0.011699685 | AE34: =IFERROR(AE33/AE$27,"") -> -0.0062522413 | AF34: =IFERROR(AF33/AF$27,"") -> -0.001967525
B35: Adjusted EBITDA (leverage basis) | C35: =Model!BV191 -> 153632 | D35: =Model!CA191 -> 204129.25 | E35: =Model!CB191 -> 244974.62 | F35: =Model!CC191 -> 286016.96 | G35: =Model!CD191 -> 331272.46 | H35: =Model!CE191 -> 375223.2 | I35: =IFERROR((H35/C35)^(1/5)-1,"n/m") -> 0.19553308 | N35: Adjusted EBITDA (leverage basis) | O35: 153632 | P35: 208622.97 | Q35: 265933.87 | R35: 315961.49 | S35: 373500.21 | T35: 433081.09 | U35: 0.23031837 | Z35: Adjusted EBITDA (leverage basis) | AA35: 153632 | AB35: 197550.49 | AC35: 210807.6 | AD35: 239741.89 | AE35: 270285.34 | AF35: 297678.14 | AG35: 0.1414399
B36: Adjusted EBITDA % of revenues | C36: =IFERROR(C35/C9,"") -> 0.38137604 | D36: =IFERROR(D35/D9,"") -> 0.40967168 | E36: =IFERROR(E35/E9,"") -> 0.41884301 | F36: =IFERROR(F35/F9,"") -> 0.42627878 | G36: =IFERROR(G35/G9,"") -> 0.4370294 | H36: =IFERROR(H35/H9,"") -> 0.44470437 | J36: =IFERROR(AVERAGE(Model!C238,Model!D238,Model!E238,Model!F238,Model!G238,Model!H238,Model!I238,Model!N238,Model!S238,Model!X238,Model!AC238,Model!AH238,Model!AM238,Model!AR238,Model!AW238,Model!BB238,Model!BG238,Model!BL238,Model!BQ238,Model!BV238),"") -> 0.34277958 | K36: =IFERROR(MIN(Model!C238,Model!D238,Model!E238,Model!F238,Model!G238,Model!H238,Model!I238,Model!N238,Model!S238,Model!X238,Model!AC238,Model!AH238,Model!AM238,Model!AR238,Model!AW238,Model!BB238,Model!BG238,Model!BL238,Model!BQ238,Model!BV238),"") -> 0.29476019 | L36: =IFERROR(MAX(Model!C238,Model!D238,Model!E238,Model!F238,Model!G238,Model!H238,Model!I238,Model!N238,Model!S238,Model!X238,Model!AC238,Model!AH238,Model!AM238,Model!AR238,Model!AW238,Model!BB238,Model!BG238,Model!BL238,Model!BQ238,Model!BV238),"") -> 0.41590951 | N36: Adjusted EBITDA % of revenues | O36: 0.38137604 | P36: 0.41508399 | Q36: 0.43857782 | R36: 0.43980887 | S36: 0.44387123 | T36: 0.44449483 | V36: 0.34277958 | W36: 0.29476019 | X36: 0.41590951 | Z36: Adjusted EBITDA % of revenues | AA36: 0.38137604 | AB36: 0.40170357 | AC36: 0.38349619 | AD36: 0.40178691 | AE36: 0.42559892 | AF36: 0.44841925 | AH36: 0.34277958 | AI36: 0.29476019 | AJ36: 0.41590951
B38: Net Debt (negative = net cash) | C38: =Model!BV401 -> -78300 | D38: =Model!CA401 -> -120505.2 | E38: =Model!CB401 -> -61243.654 | F38: =Model!CC401 -> -43932.771 | G38: =Model!CD401 -> -54066.777 | H38: =Model!CE401 -> -91584.275 | N38: Net Debt (negative = net cash) | O38: -78300 | P38: -119469.53 | Q38: -26593.387 | R38: -31596.149 | S38: -37350.021 | T38: -43308.109 | Z38: Net Debt (negative = net cash) | AA38: -78300 | AB38: -114696.1 | AC38: -45080.369 | AD38: 23161.801 | AE38: 78602.912 | AF38: 123487.29
B39: Net Debt / Adjusted EBITDA (x) | C39: =IFERROR(C38/C35,"") -> -0.50965945 | D39: =IFERROR(D38/D35,"") -> -0.59033772 | E39: =IFERROR(E38/E35,"") -> -0.25 | F39: =IFERROR(F38/F35,"") -> -0.15360198 | G39: =IFERROR(G38/G35,"") -> -0.16320939 | H39: =IFERROR(H38/H35,"") -> -0.24407946 | N39: Net Debt / Adjusted EBITDA (x) | O39: -0.50965945 | P39: -0.57265761 | Q39: -0.1 | R39: -0.1 | S39: -0.1 | T39: -0.1 | Z39: Net Debt / Adjusted EBITDA (x) | AA39: -0.50965945 | AB39: -0.58059131 | AC39: -0.21384603 | AD39: 0.096611407 | AE39: 0.29081456 | AF39: 0.41483494
B40: Share repurchases ($m; 2026E = 2H) | D40: =Model!CA286 -> 0 | E40: =Model!CB286 -> 27560.057 | F40: =Model!CC286 -> 0 | G40: =Model!CD286 -> 0 | H40: =Model!CE286 -> 0 | N40: Share repurchases ($m; 2026E = 2H) | P40: 5000 | Q40: 83111.681 | R40: 8123.2972 | S40: 46502.626 | T40: 87840.646 | AB40: 0 | AC40: 0 | AD40: 0 | AE40: 0 | AF40: 0
B41: Implied avg buyback price ($) | D41: =Model!CA285 -> 350 | E41: =Model!CB285 -> 378 | F41: =Model!CC285 -> 408.24 | G41: =Model!CD285 -> 440.8992 | H41: =Model!CE285 -> 476.17114 | N41: Implied avg buyback price ($) | P41: 350 | Q41: 378 | R41: 408.24 | S41: 440.8992 | T41: 476.17114 | AB41: 350 | AC41: 378 | AD41: 408.24 | AE41: 440.8992 | AF41: 476.17114
B42: Shares repurchased (m) | D42: =Model!CA287 -> 0 | E42: =Model!CB287 -> 72.910203 | F42: =Model!CC287 -> 0 | G42: =Model!CD287 -> 0 | H42: =Model!CE287 -> 0 | N42: Shares repurchased (m) | P42: 14.285714 | Q42: 219.87217 | R42: 19.898337 | S42: 105.47224 | T42: 184.47285 | AB42: 0 | AC42: 0 | AD42: 0 | AE42: 0 | AF42: 0
B44: ROIC | C44: =Model!BV384 -> 0.41098786 | D44: =Model!CA384 -> 0.30090251 | E44: =Model!CB384 -> 0.24179208 | F44: =Model!CC384 -> 0.20332356 | G44: =Model!CD384 -> 0.18404673 | H44: =Model!CE384 -> 0.17136984 | J44: =IFERROR(AVERAGE(Model!C384,Model!D384,Model!E384,Model!F384,Model!G384,Model!H384,Model!I384,Model!N384,Model!S384,Model!X384,Model!AC384,Model!AH384,Model!AM384,Model!AR384,Model!AW384,Model!BB384,Model!BG384,Model!BL384,Model!BQ384,Model!BV384),"") -> 0.46714538 | K44: =IFERROR(MIN(Model!C384,Model!D384,Model!E384,Model!F384,Model!G384,Model!H384,Model!I384,Model!N384,Model!S384,Model!X384,Model!AC384,Model!AH384,Model!AM384,Model!AR384,Model!AW384,Model!BB384,Model!BG384,Model!BL384,Model!BQ384,Model!BV384),"") -> 0.33257369 | L44: =IFERROR(MAX(Model!C384,Model!D384,Model!E384,Model!F384,Model!G384,Model!H384,Model!I384,Model!N384,Model!S384,Model!X384,Model!AC384,Model!AH384,Model!AM384,Model!AR384,Model!AW384,Model!BB384,Model!BG384,Model!BL384,Model!BQ384,Model!BV384),"") -> 0.67822935 | N44: ROIC | O44: 0.41098786 | P44: 0.30894766 | Q44: 0.26952571 | R44: 0.23528562 | S44: 0.22119877 | T44: 0.21442073 | V44: 0.46714538 | W44: 0.33257369 | X44: 0.67822935 | Z44: ROIC | AA44: 0.41098786 | AB44: 0.28913726 | AC44: 0.19674821 | AD44: 0.15435959 | AE44: 0.13077981 | AF44: 0.11390053 | AH44: 0.46714538 | AI44: 0.33257369 | AJ44: 0.67822935
