Workbook

Sheet Model
CA1: SCENARIO SWITCH ▼ (Bull / Base / Bear) — drives all scenario-linked forecast drivers
B2: Huntington Ingalls Industries, Inc. (NYSE: HII) — 3-Statement Financial Model | CA2: Base
B3: US GAAP as reported · USD millions (per-share data in USD) · Source: HII Forms 10-K / 10-Q (XBRL financial data) and Form 8-K earnings releases (Ex. 99.1), SEC EDGAR CIK 0001501585
B4: Basis notes: FY2015–16 as originally reported; FY2017+ as recast in the 2018 10-K for ASU 2017-07 (non-service pension moved below operating income). Technical Solutions formed Dec-2016 (renamed Mission Technologies 2022); Q1–Q3/15 shown on the original segment basis ("Other"), Q4/15 and FY2015 recast. Q3/26E–Q4/26E = FY26 guidance less 1H/26 actuals.
CC5: Forecast | CD5: Historical | CE5: Historical
B6: (USDm) | C6: Q1/15 | D6: Q2/15 | E6: 1H/15 | F6: Q3/15 | G6: Q4/15 | H6: 2015 | I6: Q1/16 | J6: Q2/16 | K6: 1H/16 | L6: Q3/16 | M6: Q4/16 | N6: 2016 | O6: Q1/17 | P6: Q2/17 | Q6: 1H/17 | R6: Q3/17 | S6: Q4/17 | T6: 2017 | U6: Q1/18 | V6: Q2/18 | W6: 1H/18 | X6: Q3/18 | Y6: Q4/18 | Z6: 2018 | AA6: Q1/19 | AB6: Q2/19 | AC6: 1H/19 | AD6: Q3/19 | AE6: Q4/19 | AF6: 2019 | AG6: Q1/20 | AH6: Q2/20 | AI6: 1H/20 | AJ6: Q3/20 | AK6: Q4/20 | AL6: 2020 | AM6: Q1/21 | AN6: Q2/21 | AO6: 1H/21 | AP6: Q3/21 | AQ6: Q4/21 | AR6: 2021 | AS6: Q1/22 | AT6: Q2/22 | AU6: 1H/22 | AV6: Q3/22 | AW6: Q4/22 | AX6: 2022 | AY6: Q1/23 | AZ6: Q2/23 | BA6: 1H/23 | BB6: Q3/23 | BC6: Q4/23 | BD6: 2023 | BE6: Q1/24 | BF6: Q2/24 | BG6: 1H/24 | BH6: Q3/24 | BI6: Q4/24 | BJ6: 2024 | BK6: Q1/25 | BL6: Q2/25 | BM6: 1H/25 | BN6: Q3/25 | BO6: Q4/25 | BP6: 2025 | BQ6: Q1/26 | BR6: Q2/26 | BS6: 1H/26 | BT6: Q3/26E | BU6: Q4/26E | BV6: 2026E | BW6: 2027E | BX6: 2028E | BY6: 2029E | BZ6: 2030E | CA6: Modelling Notes | CC6: 5Y CAGR | CD6: 5Y CAGR | CE6: 10Y CAGR
CC7: 25-'30 | CD7: 20-'25 | CE7: 15-'25
B8: SEGMENT P&L — BY DIVISION
CH9: SCENARIO INPUT TABLE — driver assumptions per Bull / Base / Bear | CI9: Bull | CJ9: Base | CK9: Bear | CL9: Bull / Bear = Base + Δ (Δ inputs on each block header). Guidance block = high / mid / low end of FY26 ranges.
B10: Ingalls Shipbuilding | CA10: INGALLS SHIPBUILDING — modelling logic
B11: Revenue (external) | C11: =IF(ISNUMBER(C12),C13-C12,"n/d") -> n/d | D11: =IF(ISNUMBER(D12),D13-D12,"n/d") -> n/d | E11: =IF(ISNUMBER(E12),E13-E12,"n/d") -> n/d | F11: =IF(ISNUMBER(F12),F13-F12,"n/d") -> n/d | G11: =IF(ISNUMBER(G12),G13-G12,"n/d") -> n/d | H11: =IF(ISNUMBER(H12),H13-H12,"n/d") -> n/d | I11: =IF(ISNUMBER(I12),I13-I12,"n/d") -> n/d | J11: =IF(ISNUMBER(J12),J13-J12,"n/d") -> n/d | ... BZ11: =IF(ISNUMBER(BZ12),BZ13-BZ12,"n/d") -> 3887.7541 | CA11: External revenue = segment revenue less intersegment sales. Intersegment sales by segment not disclosed before FY2018 (n/d). | CH11: FY26 guidance — Q2-26 release (30-Jul-26) | CI11: High | CJ11: Mid | CK11: Low
B12: Intersegment revenue | X12: 2 | Y12: 0 | Z12: 2 | AB12: 1 | AC12: =AA12+AB12 -> 1 | AD12: 1 | AE12: 1 | AF12: 3 | AG12: 1 | AH12: 1 | AI12: =AG12+AH12 -> 2 | AJ12: 0 | AK12: 2 | AL12: 4 | AM12: 3 | AN12: 5 | AO12: =AM12+AN12 -> 8 | AP12: 4 | AQ12: 3 | AR12: 15 | AS12: 3 | AU12: =AS12+AT12 -> 3 | AV12: 5 | AW12: 2 | AX12: 12 | AY12: 2 | AZ12: 3 | BA12: =AY12+AZ12 -> 5 | BB12: 1 | BC12: 3 | BD12: 9 | BE12: 2 | BF12: 1 | BG12: =BE12+BF12 -> 3 | BH12: 2 | BI12: 3 | BJ12: 8 | BK12: 4 | BL12: 3 | BM12: =BK12+BL12 -> 7 | BN12: 3 | BO12: 2 | BP12: 12 | BQ12: 3 | BR12: 2 | BS12: =BQ12+BR12 -> 5 | BT12: =BS12/2 -> 2.5 | BU12: =BS12/2 -> 2.5 | BV12: =SUM(BQ12,BR12,BT12,BU12) -> 10 | BW12: =BW13*BW31 -> 13.144674 | BX12: =BX13*BX31 -> 13.867631 | BY12: =BY13*BY31 -> 14.561013 | BZ12: =BZ13*BZ31 -> 15.216259 | CA12: Q3/Q4-26E at 1H/26 run-rate; 2027E+ = segment revenue × intersegment % (held at FY2025 level). | CH12: Shipbuilding revenue ($m) | CI12: 10400 | CJ12: 10300 | CK12: 10200
B13: Segment revenue (as reported, incl. intersegment) | C13: 469 | D13: 546 | E13: =C13+D13 -> 1015 | F13: 593 | G13: 580 | H13: 2188 | I13: 586 | J13: 585 | K13: =I13+J13 -> 1171 | L13: 577 | M13: 641 | N13: 2389 | O13: 550 | P13: 639 | Q13: =O13+P13 -> 1189 | R13: 593 | S13: 638 | T13: 2420 | U13: 585 | V13: 629 | W13: =U13+V13 -> 1214 | X13: 694 | Y13: 699 | Z13: 2607 | AA13: 584 | AB13: 622 | AC13: =AA13+AB13 -> 1206 | AD13: 647 | AE13: 702 | AF13: 2555 | AG13: 629 | AH13: 622 | AI13: =AG13+AH13 -> 1251 | AJ13: 675 | AK13: 752 | AL13: 2678 | AM13: 649 | AN13: 670 | AO13: =AM13+AN13 -> 1319 | AP13: 628 | AQ13: 581 | AR13: 2528 | AS13: 631 | AT13: 658 | AU13: =AS13+AT13 -> 1289 | AV13: 623 | AW13: 658 | AX13: 2570 | AY13: 577 | AZ13: 664 | BA13: =AY13+AZ13 -> 1241 | BB13: 711 | BC13: 800 | BD13: 2752 | BE13: 655 | BF13: 712 | BG13: =BE13+BF13 -> 1367 | BH13: 664 | BI13: 736 | BJ13: 2767 | BK13: 637 | BL13: 724 | BM13: =BK13+BL13 -> 1361 | BN13: 828 | BO13: 889 | BP13: 3078 | BQ13: 725 | BR13: 845 | BS13: =BQ13+BR13 -> 1570 | BT13: =(CHOOSE(MATCH($CA$2,{"Bull","Base","Bear"},0),$CI$12,$CJ$12,$CK$12)-BS13-BS39)*BS13/(BS13+BS39)/2 -> 805.38159 | BU13: =(CHOOSE(MATCH($CA$2,{"Bull","Base","Bear"},0),$CI$12,$CJ$12,$CK$12)-BS13-BS39)*BS13/(BS13+BS39)/2 -> 805.38159 | BV13: =SUM(BQ13,BR13,BT13,BU13) -> 3180.7632 | BW13: =BV13*(1+BW17) -> 3371.609 | BX13: =BW13*(1+BX17) -> 3557.0475 | BY13: =BX13*(1+BY17) -> 3734.8998 | BZ13: =BY13*(1+BZ17) -> 3902.9703 | CA13: Q3/26E–Q4/26E: FY26 guidance (scenario: high / mid / low end) less 1H/26 actuals, split evenly across Q3 and Q4. Shipbuilding guidance allocated between Ingalls and Newport News by 1H/26 revenue mix; 2H shipbuilding OI allocated by 2H revenue × 1H margin weights. 2027E+: prior year × (1 + scenario revenue growth). | CC13: =IFERROR((BZ13/BP13)^(1/5)-1,"n/m") -> 0.048637361 | CD13: =IFERROR((BP13/AL13)^(1/5)-1,"n/m") -> 0.028233167 | CE13: =IFERROR((BP13/H13)^(1/10)-1,"n/m") -> 0.034718299 | CH13: Shipbuilding OI margin | CI13: 0.065 | CJ13: 0.0625 | CK13: 0.06
B14: Segment operating income | C14: 45 | D14: 198 | E14: =C14+D14 -> 243 | F14: 77 | G14: 59 | H14: 379 | I14: 82 | J14: 88 | K14: =I14+J14 -> 170 | L14: 66 | M14: 85 | N14: 321 | O14: 66 | P14: 98 | Q14: =O14+P14 -> 164 | R14: 74 | S14: 75 | T14: 313 | U14: 64 | V14: 83 | W14: =U14+V14 -> 147 | X14: 82 | Y14: 84 | Z14: 313 | AA14: 46 | AB14: 69 | AC14: =AA14+AB14 -> 115 | AD14: 61 | AE14: 59 | AF14: 235 | AG14: 68 | AH14: 55 | AI14: =AG14+AH14 -> 123 | AJ14: 62 | AK14: 96 | AL14: 281 | AM14: 91 | AN14: 80 | AO14: =AM14+AN14 -> 171 | AP14: 62 | AQ14: 48 | AR14: 281 | AS14: 86 | AT14: 106 | AU14: =AS14+AT14 -> 192 | AV14: 50 | AW14: 50 | AX14: 292 | AY14: 55 | AZ14: 65 | BA14: =AY14+AZ14 -> 120 | BB14: 73 | BC14: 169 | BD14: 362 | BE14: 60 | BF14: 56 | BG14: =BE14+BF14 -> 116 | BH14: 49 | BI14: 46 | BJ14: 211 | BK14: 46 | BL14: 54 | BM14: =BK14+BL14 -> 100 | BN14: 65 | BO14: 68 | BP14: 233 | BQ14: 49 | BR14: 58 | BS14: =BQ14+BR14 -> 107 | BT14: =(CHOOSE(MATCH($CA$2,{"Bull","Base","Bear"},0),$CI$12,$CJ$12,$CK$12)*CHOOSE(MATCH($CA$2,{"Bull","Base","Bear"},0),$CI$13,$CJ$13,$CK$13)-BS14-BS40)*BT13*BS14/BS13/(BT13*BS14/BS13+BT39*BS40/BS39)/2 -> 59.051062 | BU14: =(CHOOSE(MATCH($CA$2,{"Bull","Base","Bear"},0),$CI$12,$CJ$12,$CK$12)*CHOOSE(MATCH($CA$2,{"Bull","Base","Bear"},0),$CI$13,$CJ$13,$CK$13)-BS14-BS40)*BU13*BS14/BS13/(BU13*BS14/BS13+BU39*BS40/BS39)/2 -> 59.051062 | BV14: =SUM(BQ14,BR14,BT14,BU14) -> 225.10212 | BW14: =BW13*BW20 -> 244.44165 | BX14: =BX13*BX20 -> 266.77856 | BY14: =BY13*BY20 -> 289.45474 | BZ14: =BZ13*BZ20 -> 312.23763 | CA14: Q3/26E–Q4/26E: FY26 guidance (scenario: high / mid / low end) less 1H/26 actuals, split evenly across Q3 and Q4. Shipbuilding guidance allocated between Ingalls and Newport News by 1H/26 revenue mix; 2H shipbuilding OI allocated by 2H revenue × 1H margin weights. 2027E+: segment revenue × scenario segment operating margin. | CC14: =IFERROR((BZ14/BP14)^(1/5)-1,"n/m") -> 0.060292924 | CD14: =IFERROR((BP14/AL14)^(1/5)-1,"n/m") -> -0.036770178 | CE14: =IFERROR((BP14/H14)^(1/10)-1,"n/m") -> -0.047485334 | CH14: MT revenue ($m) | CI14: 3200 | CJ14: 3100 | CK14: 3000
B15: Depreciation & amortization | H15: 65 | N15: 68 | T15: 73 | Z15: 69 | AF15: 70 | AL15: 73 | AR15: 74 | AX15: 79 | BD15: 76 | BE15: 19 | BF15: 19 | BG15: =BE15+BF15 -> 38 | BH15: 20 | BI15: 20 | BJ15: 78 | BK15: 20 | BL15: 20 | BM15: =BK15+BL15 -> 40 | BN15: 20 | BO15: 21 | BP15: 81 | BQ15: 20 | BR15: 20 | BS15: =BQ15+BR15 -> 40 | BT15: =BS15/2*($CJ$24-BS102)/BS102 -> 22.580645 | BU15: =BS15/2*($CJ$24-BS102)/BS102 -> 22.580645 | BV15: =SUM(BQ15,BR15,BT15,BU15) -> 85.16129 | BW15: =BW13*BW32 -> 87.661833 | BX15: =BX13*BX32 -> 92.483234 | BY15: =BY13*BY32 -> 97.107396 | BZ15: =BZ13*BZ32 -> 101.47723 | CA15: FY D&A by segment from 10-K segment note (quarterly disclosure from FY2024 under ASU 2023-07). Q3/Q4-26E: 1H/26 run-rate scaled to FY26 D&A guidance (~$330m). 2027E+: revenue × D&A %. | CH15: MT segment OI margin | CI15: 0.0525 | CJ15: 0.05 | CK15: 0.0475
B16: Segment EBITDA (segment OI + D&A) | C16: =IF(ISNUMBER(C15),C14+C15,"") | D16: =IF(ISNUMBER(D15),D14+D15,"") | E16: =IF(ISNUMBER(E15),E14+E15,"") | F16: =IF(ISNUMBER(F15),F14+F15,"") | G16: =IF(ISNUMBER(G15),G14+G15,"") | H16: =IF(ISNUMBER(H15),H14+H15,"") -> 444 | I16: =IF(ISNUMBER(I15),I14+I15,"") | J16: =IF(ISNUMBER(J15),J14+J15,"") | ... BZ16: =IF(ISNUMBER(BZ15),BZ14+BZ15,"") -> 413.71485 | CA16: Segment EBITDA = segment operating income + segment D&A (HII publishes MT EBITDA incl. state tax add-back; shown here on a simple OI + D&A basis for all segments). | CC16: =IFERROR((BZ16/BP16)^(1/5)-1,"n/m") -> 0.056706292 | CD16: =IFERROR((BP16/AL16)^(1/5)-1,"n/m") -> -0.023695531 | CE16: =IFERROR((BP16/H16)^(1/10)-1,"n/m") -> -0.034049953 | CH16: Free cash flow ($m) | CI16: 600 | CJ16: 550 | CK16: 500
B17: Revenue y/y % | I17: =IFERROR(I13/C13-1,"") -> 0.24946695 | J17: =IFERROR(J13/D13-1,"") -> 0.071428571 | K17: =IFERROR(K13/E13-1,"") -> 0.15369458 | L17: =IFERROR(L13/F13-1,"") -> -0.02698145 | M17: =IFERROR(M13/G13-1,"") -> 0.10517241 | N17: =IFERROR(N13/H13-1,"") -> 0.091864717 | O17: =IFERROR(O13/I13-1,"") -> -0.061433447 | P17: =IFERROR(P13/J13-1,"") -> 0.092307692 | ... BV17: =IFERROR(BV13/BP13-1,"") -> 0.033386348 | BW17: =CHOOSE(MATCH($CA$2,{"Bull","Base","Bear"},0),$CI$28,$CJ$28,$CK$28) -> 0.06 | BX17: =CHOOSE(MATCH($CA$2,{"Bull","Base","Bear"},0),$CI$29,$CJ$29,$CK$29) -> 0.055 | BY17: =CHOOSE(MATCH($CA$2,{"Bull","Base","Bear"},0),$CI$30,$CJ$30,$CK$30) -> 0.05 | BZ17: =CHOOSE(MATCH($CA$2,{"Bull","Base","Bear"},0),$CI$31,$CJ$31,$CK$31) -> 0.045 | CA17: 2027E–2030E revenue growth: scenario lever (ING_revGrowth, Bull/Base/Bear table →). 2026E growth is an output of FY26 guidance.
B18: Segment OI y/y % | I18: =IFERROR(I14/C14-1,"") -> 0.82222222 | J18: =IFERROR(J14/D14-1,"") -> -0.55555556 | K18: =IFERROR(K14/E14-1,"") -> -0.30041152 | L18: =IFERROR(L14/F14-1,"") -> -0.14285714 | M18: =IFERROR(M14/G14-1,"") -> 0.44067797 | N18: =IFERROR(N14/H14-1,"") -> -0.1530343 | O18: =IFERROR(O14/I14-1,"") -> -0.19512195 | P18: =IFERROR(P14/J14-1,"") -> 0.11363636 | ... BV18: =IFERROR(BV14/BP14-1,"") -> -0.033896463 | BW18: =IFERROR(BW14/BV14-1,"") -> 0.085914454 | BX18: =IFERROR(BX14/BW14-1,"") -> 0.09137931 | BY18: =IFERROR(BY14/BX14-1,"") -> 0.085 | BZ18: =IFERROR(BZ14/BY14-1,"") -> 0.078709677 | CH18: FY26 guidance — point estimates (all cases)
B19: Segment EBITDA y/y % | I19: =IFERROR(I16/C16-1,"") | J19: =IFERROR(J16/D16-1,"") | K19: =IFERROR(K16/E16-1,"") | L19: =IFERROR(L16/F16-1,"") | M19: =IFERROR(M16/G16-1,"") | N19: =IFERROR(N16/H16-1,"") -> -0.12387387 | O19: =IFERROR(O16/I16-1,"") | P19: =IFERROR(P16/J16-1,"") | ... BV19: =IFERROR(BV16/BP16-1,"") -> -0.011899954 | BW19: =IFERROR(BW16/BV16-1,"") -> 0.070392022 | BX19: =IFERROR(BX16/BW16-1,"") -> 0.08177665 | BY19: =IFERROR(BY16/BX16-1,"") -> 0.075990099 | BZ19: =IFERROR(BZ16/BY16-1,"") -> 0.070241546 | CH19: Operating FAS/CAS adjustment ($m) | CJ19: 44
B20: Segment operating margin % | C20: =IFERROR(C14/C13,"") -> 0.095948827 | D20: =IFERROR(D14/D13,"") -> 0.36263736 | E20: =IFERROR(E14/E13,"") -> 0.23940887 | F20: =IFERROR(F14/F13,"") -> 0.12984823 | G20: =IFERROR(G14/G13,"") -> 0.10172414 | H20: =IFERROR(H14/H13,"") -> 0.17321755 | I20: =IFERROR(I14/I13,"") -> 0.13993174 | J20: =IFERROR(J14/J13,"") -> 0.15042735 | ... BV20: =IFERROR(BV14/BV13,"") -> 0.070769847 | BW20: =CHOOSE(MATCH($CA$2,{"Bull","Base","Bear"},0),$CI$46,$CJ$46,$CK$46) -> 0.0725 | BX20: =CHOOSE(MATCH($CA$2,{"Bull","Base","Bear"},0),$CI$47,$CJ$47,$CK$47) -> 0.075 | BY20: =CHOOSE(MATCH($CA$2,{"Bull","Base","Bear"},0),$CI$48,$CJ$48,$CK$48) -> 0.0775 | BZ20: =CHOOSE(MATCH($CA$2,{"Bull","Base","Bear"},0),$CI$49,$CJ$49,$CK$49) -> 0.08 | CA20: 2027E–2030E segment operating margin: scenario lever (ING_margin). 2026E margin is an output of FY26 guidance. | CC20: =IFERROR(AVERAGE(BV20,BW20,BX20,BY20,BZ20),"n/m") -> 0.075153969 | CD20: =IFERROR(AVERAGE(AR20,AX20,BD20,BJ20,BP20),"n/m") -> 0.10165376 | CE20: =IFERROR(AVERAGE(N20,T20,Z20,AF20,AL20,AR20,AX20,BD20,BJ20,BP20),"n/m") -> 0.10889404 | CH20: Non-current state income taxes ($m) | CJ20: 20
B21: Segment EBITDA margin % | C21: =IFERROR(C16/C13,"") | D21: =IFERROR(D16/D13,"") | E21: =IFERROR(E16/E13,"") | F21: =IFERROR(F16/F13,"") | G21: =IFERROR(G16/G13,"") | H21: =IFERROR(H16/H13,"") -> 0.20292505 | I21: =IFERROR(I16/I13,"") | J21: =IFERROR(J16/J13,"") | ... BZ21: =IFERROR(BZ16/BZ13,"") -> 0.106 | CC21: =IFERROR(AVERAGE(BV21,BW21,BX21,BY21,BZ21),"n/m") -> 0.10130874 | CD21: =IFERROR(AVERAGE(AR21,AX21,BD21,BJ21,BP21),"n/m") -> 0.13008034 | CE21: =IFERROR(AVERAGE(N21,T21,Z21,AF21,AL21,AR21,AX21,BD21,BJ21,BP21),"n/m") -> 0.1370826 | CH21: Interest expense ($m) | CJ21: 105
B22: Incremental OI margin (ΔOI / ΔRev) | I22: =IFERROR((I14-C14)/(I13-C13),"") -> 0.31623932 | J22: =IFERROR((J14-D14)/(J13-D13),"") -> -2.8205128 | K22: =IFERROR((K14-E14)/(K13-E13),"") -> -0.46794872 | L22: =IFERROR((L14-F14)/(L13-F13),"") -> 0.6875 | M22: =IFERROR((M14-G14)/(M13-G13),"") -> 0.42622951 | N22: =IFERROR((N14-H14)/(N13-H13),"") -> -0.28855721 | O22: =IFERROR((O14-I14)/(O13-I13),"") -> 0.44444444 | P22: =IFERROR((P14-J14)/(P13-J13),"") -> 0.18518519 | ... BV22: =IFERROR((BV14-BP14)/(BV13-BP13),"") -> -0.076855114 | BW22: =IFERROR((BW14-BV14)/(BW13-BV13),"") -> 0.10133588 | BX22: =IFERROR((BX14-BW14)/(BX13-BW13),"") -> 0.12045455 | BY22: =IFERROR((BY14-BX14)/(BY13-BX13),"") -> 0.1275 | BZ22: =IFERROR((BZ14-BY14)/(BZ13-BY13),"") -> 0.13555556 | CH22: Non-operating retirement benefit ($m) | CJ22: 213
B23: Operating metrics — Ingalls | CH23: Effective tax rate | CJ23: 0.17
B24: Funded backlog | C24: 6356 | D24: 5842 | E24: =D24 -> 5842 | F24: 5458 | G24: 5153 | H24: =G24 -> 5153 | I24: 5327 | J24: 5088 | K24: =J24 -> 5088 | L24: 4834 | M24: 6033 | N24: =M24 -> 6033 | O24: 5593 | P24: 6894 | Q24: =P24 -> 6894 | R24: 6472 | S24: 5920 | T24: =S24 -> 5920 | U24: 7090 | V24: 6564 | W24: =V24 -> 6564 | X24: 8694 | Y24: 9943 | Z24: =Y24 -> 9943 | AA24: 10825 | AB24: 10340 | AC24: =AB24 -> 10340 | AD24: 9712 | AE24: 9062 | AF24: =AE24 -> 9062 | AG24: 9457 | AH24: 10085 | AI24: =AH24 -> 10085 | AJ24: 11186 | AK24: 10443 | AL24: =AK24 -> 10443 | AM24: 10516 | AN24: 11077 | AO24: =AN24 -> 11077 | AP24: 10561 | AQ24: 10216 | AR24: =AQ24 -> 10216 | AS24: 10515 | AT24: 10208 | AU24: =AT24 -> 10208 | AV24: 9698 | AW24: 9231 | AX24: =AW24 -> 9231 | AY24: 10852 | AZ24: 10345 | BA24: =AZ24 -> 10345 | BB24: 13100 | BC24: 12546 | BD24: =BC24 -> 12546 | BE24: 13133 | BF24: 13917 | BG24: =BF24 -> 13917 | BH24: 14143 | BI24: 13519 | BJ24: =BI24 -> 13519 | BK24: 12993 | BL24: 15783 | BM24: =BL24 -> 15783 | BN24: 15640 | BO24: 14925 | BP24: =BO24 -> 14925 | BQ24: 15775 | BR24: 16883 | BS24: =BR24 -> 16883 | CH24: D&A ($m) | CJ24: 330
B25: Unfunded backlog | C25: 1287 | D25: 1294 | E25: =D25 -> 1294 | F25: 1303 | G25: 1290 | H25: =G25 -> 1290 | I25: 720 | J25: 695 | K25: =J25 -> 695 | L25: 791 | M25: 692 | N25: =M25 -> 692 | O25: 679 | P25: 1699 | Q25: =P25 -> 1699 | R25: 1627 | S25: 2071 | T25: =S25 -> 2071 | U25: 2155 | V25: 2165 | W25: =V25 -> 2165 | X25: 1261 | Y25: 1422 | Z25: =Y25 -> 1422 | AA25: 1541 | AB25: 1626 | AC25: =AB25 -> 1626 | AD25: 1677 | AE25: 1693 | AF25: =AE25 -> 1693 | AG25: 1510 | AH25: 2216 | AI25: =AH25 -> 2216 | AJ25: 1792 | AK25: 1758 | AL25: =AK25 -> 1758 | AM25: 1687 | AN25: 660 | AO25: =AN25 -> 660 | AP25: 661 | AQ25: 792 | AR25: =AQ25 -> 792 | AS25: 815 | AT25: 940 | AU25: =AT25 -> 940 | AV25: 1028 | AW25: 3546 | AX25: =AW25 -> 3546 | AY25: 2786 | AZ25: 3157 | BA25: =AZ25 -> 3157 | BB25: 2968 | BC25: 3201 | BD25: =BC25 -> 3201 | BE25: 2059 | BF25: 2232 | BG25: =BF25 -> 2232 | BH25: 2244 | BI25: 2333 | BJ25: =BI25 -> 2333 | BK25: 2407 | BL25: 3308 | BM25: =BL25 -> 3308 | BN25: 2906 | BO25: 2856 | BP25: =BO25 -> 2856 | BQ25: 2477 | BR25: 2470 | BS25: =BR25 -> 2470 | CH25: Capex % of sales | CJ25: 0.045
B26: Total backlog | C26: =C24+C25 -> 7643 | D26: =D24+D25 -> 7136 | E26: =E24+E25 -> 7136 | F26: =F24+F25 -> 6761 | G26: =G24+G25 -> 6443 | H26: =H24+H25 -> 6443 | I26: =I24+I25 -> 6047 | J26: =J24+J25 -> 5783 | ... BS26: =BS24+BS25 -> 19353 | BT26: =BR26+BT27-BT13 -> 19353 | BU26: =BT26+BU27-BU13 -> 19353 | BV26: =BU26 -> 19353 | BW26: =BV26+BW27-BW13 -> 19353 | BX26: =BW26+BX27-BX13 -> 19353 | BY26: =BX26+BY27-BY13 -> 19353 | BZ26: =BY26+BZ27-BZ13 -> 19353 | CA26: Forecast backlog = prior backlog + new awards − segment revenue; awards = revenue × book-to-bill assumption. | CC26: =IFERROR((BZ26/BP26)^(1/5)-1,"n/m") -> 0.017087748 | CD26: =IFERROR((BP26/AL26)^(1/5)-1,"n/m") -> 0.078231837 | CE26: =IFERROR((BP26/H26)^(1/10)-1,"n/m") -> 0.10684499
B27: Implied new awards (ΔBacklog + Revenue) | D27: =IF(AND(ISNUMBER(D26),ISNUMBER(C26)),D26-C26+D13,"") -> 39 | E27: =IF(AND(ISNUMBER(C27),ISNUMBER(D27)),C27+D27,"") | F27: =IF(AND(ISNUMBER(F26),ISNUMBER(D26)),F26-D26+F13,"") -> 218 | G27: =IF(AND(ISNUMBER(G26),ISNUMBER(F26)),G26-F26+G13,"") -> 262 | I27: =IF(AND(ISNUMBER(I26),ISNUMBER(G26)),I26-G26+I13,"") -> 190 | J27: =IF(AND(ISNUMBER(J26),ISNUMBER(I26)),J26-I26+J13,"") -> 321 | K27: =IF(AND(ISNUMBER(I27),ISNUMBER(J27)),I27+J27,"") -> 511 | L27: =IF(AND(ISNUMBER(L26),ISNUMBER(J26)),L26-J26+L13,"") -> 419 | M27: =IF(AND(ISNUMBER(M26),ISNUMBER(L26)),M26-L26+M13,"") -> 1741 | N27: =IF(AND(ISNUMBER(N26),ISNUMBER(H26)),N26-H26+N13,"") -> 2671 | O27: =IF(AND(ISNUMBER(O26),ISNUMBER(M26)),O26-M26+O13,"") -> 97 | P27: =IF(AND(ISNUMBER(P26),ISNUMBER(O26)),P26-O26+P13,"") -> 2960 | Q27: =IF(AND(ISNUMBER(O27),ISNUMBER(P27)),O27+P27,"") -> 3057 | R27: =IF(AND(ISNUMBER(R26),ISNUMBER(P26)),R26-P26+R13,"") -> 99 | S27: =IF(AND(ISNUMBER(S26),ISNUMBER(R26)),S26-R26+S13,"") -> 530 | T27: =IF(AND(ISNUMBER(T26),ISNUMBER(N26)),T26-N26+T13,"") -> 3686 | U27: =IF(AND(ISNUMBER(U26),ISNUMBER(S26)),U26-S26+U13,"") -> 1839 | V27: =IF(AND(ISNUMBER(V26),ISNUMBER(U26)),V26-U26+V13,"") -> 113 | W27: =IF(AND(ISNUMBER(U27),ISNUMBER(V27)),U27+V27,"") -> 1952 | X27: =IF(AND(ISNUMBER(X26),ISNUMBER(V26)),X26-V26+X13,"") -> 1920 | Y27: =IF(AND(ISNUMBER(Y26),ISNUMBER(X26)),Y26-X26+Y13,"") -> 2109 | Z27: =IF(AND(ISNUMBER(Z26),ISNUMBER(T26)),Z26-T26+Z13,"") -> 5981 | AA27: =IF(AND(ISNUMBER(AA26),ISNUMBER(Y26)),AA26-Y26+AA13,"") -> 1585 | AB27: =IF(AND(ISNUMBER(AB26),ISNUMBER(AA26)),AB26-AA26+AB13,"") -> 222 | AC27: =IF(AND(ISNUMBER(AA27),ISNUMBER(AB27)),AA27+AB27,"") -> 1807 | AD27: =IF(AND(ISNUMBER(AD26),ISNUMBER(AB26)),AD26-AB26+AD13,"") -> 70 | AE27: =IF(AND(ISNUMBER(AE26),ISNUMBER(AD26)),AE26-AD26+AE13,"") -> 68 | AF27: =IF(AND(ISNUMBER(AF26),ISNUMBER(Z26)),AF26-Z26+AF13,"") -> 1945 | AG27: =IF(AND(ISNUMBER(AG26),ISNUMBER(AE26)),AG26-AE26+AG13,"") -> 841 | AH27: =IF(AND(ISNUMBER(AH26),ISNUMBER(AG26)),AH26-AG26+AH13,"") -> 1956 | AI27: =IF(AND(ISNUMBER(AG27),ISNUMBER(AH27)),AG27+AH27,"") -> 2797 | AJ27: =IF(AND(ISNUMBER(AJ26),ISNUMBER(AH26)),AJ26-AH26+AJ13,"") -> 1352 | AK27: =IF(AND(ISNUMBER(AK26),ISNUMBER(AJ26)),AK26-AJ26+AK13,"") -> -25 | AL27: =IF(AND(ISNUMBER(AL26),ISNUMBER(AF26)),AL26-AF26+AL13,"") -> 4124 | AM27: =IF(AND(ISNUMBER(AM26),ISNUMBER(AK26)),AM26-AK26+AM13,"") -> 651 | AN27: =IF(AND(ISNUMBER(AN26),ISNUMBER(AM26)),AN26-AM26+AN13,"") -> 204 | AO27: =IF(AND(ISNUMBER(AM27),ISNUMBER(AN27)),AM27+AN27,"") -> 855 | AP27: =IF(AND(ISNUMBER(AP26),ISNUMBER(AN26)),AP26-AN26+AP13,"") -> 113 | AQ27: =IF(AND(ISNUMBER(AQ26),ISNUMBER(AP26)),AQ26-AP26+AQ13,"") -> 367 | AR27: =IF(AND(ISNUMBER(AR26),ISNUMBER(AL26)),AR26-AL26+AR13,"") -> 1335 | AS27: =IF(AND(ISNUMBER(AS26),ISNUMBER(AQ26)),AS26-AQ26+AS13,"") -> 953 | AT27: =IF(AND(ISNUMBER(AT26),ISNUMBER(AS26)),AT26-AS26+AT13,"") -> 476 | AU27: =IF(AND(ISNUMBER(AS27),ISNUMBER(AT27)),AS27+AT27,"") -> 1429 | AV27: =IF(AND(ISNUMBER(AV26),ISNUMBER(AT26)),AV26-AT26+AV13,"") -> 201 | AW27: =IF(AND(ISNUMBER(AW26),ISNUMBER(AV26)),AW26-AV26+AW13,"") -> 2709 | AX27: =IF(AND(ISNUMBER(AX26),ISNUMBER(AR26)),AX26-AR26+AX13,"") -> 4339 | AY27: =IF(AND(ISNUMBER(AY26),ISNUMBER(AW26)),AY26-AW26+AY13,"") -> 1438 | AZ27: =IF(AND(ISNUMBER(AZ26),ISNUMBER(AY26)),AZ26-AY26+AZ13,"") -> 528 | BA27: =IF(AND(ISNUMBER(AY27),ISNUMBER(AZ27)),AY27+AZ27,"") -> 1966 | BB27: =IF(AND(ISNUMBER(BB26),ISNUMBER(AZ26)),BB26-AZ26+BB13,"") -> 3277 | BC27: =IF(AND(ISNUMBER(BC26),ISNUMBER(BB26)),BC26-BB26+BC13,"") -> 479 | BD27: =IF(AND(ISNUMBER(BD26),ISNUMBER(AX26)),BD26-AX26+BD13,"") -> 5722 | BE27: =IF(AND(ISNUMBER(BE26),ISNUMBER(BC26)),BE26-BC26+BE13,"") -> 100 | BF27: =IF(AND(ISNUMBER(BF26),ISNUMBER(BE26)),BF26-BE26+BF13,"") -> 1669 | BG27: =IF(AND(ISNUMBER(BE27),ISNUMBER(BF27)),BE27+BF27,"") -> 1769 | BH27: =IF(AND(ISNUMBER(BH26),ISNUMBER(BF26)),BH26-BF26+BH13,"") -> 902 | BI27: =IF(AND(ISNUMBER(BI26),ISNUMBER(BH26)),BI26-BH26+BI13,"") -> 201 | BJ27: =IF(AND(ISNUMBER(BJ26),ISNUMBER(BD26)),BJ26-BD26+BJ13,"") -> 2872 | BK27: =IF(AND(ISNUMBER(BK26),ISNUMBER(BI26)),BK26-BI26+BK13,"") -> 185 | BL27: =IF(AND(ISNUMBER(BL26),ISNUMBER(BK26)),BL26-BK26+BL13,"") -> 4415 | BM27: =IF(AND(ISNUMBER(BK27),ISNUMBER(BL27)),BK27+BL27,"") -> 4600 | BN27: =IF(AND(ISNUMBER(BN26),ISNUMBER(BL26)),BN26-BL26+BN13,"") -> 283 | BO27: =IF(AND(ISNUMBER(BO26),ISNUMBER(BN26)),BO26-BN26+BO13,"") -> 124 | BP27: =IF(AND(ISNUMBER(BP26),ISNUMBER(BJ26)),BP26-BJ26+BP13,"") -> 5007 | BQ27: =IF(AND(ISNUMBER(BQ26),ISNUMBER(BO26)),BQ26-BO26+BQ13,"") -> 1196 | BR27: =IF(AND(ISNUMBER(BR26),ISNUMBER(BQ26)),BR26-BQ26+BR13,"") -> 1946 | BS27: =IF(AND(ISNUMBER(BQ27),ISNUMBER(BR27)),BQ27+BR27,"") -> 3142 | BT27: =BT13*BT28 -> 805.38159 | BU27: =BU13*BU28 -> 805.38159 | BV27: =SUM(BQ27,BR27,BT27,BU27) -> 4752.7632 | BW27: =BW13*BW28 -> 3371.609 | BX27: =BX13*BX28 -> 3557.0475 | BY27: =BY13*BY28 -> 3734.8998 | BZ27: =BZ13*BZ28 -> 3902.9703 | CA27: Implied awards = change in total backlog + segment revenue (backlog also moves for de-obligations/adjustments; not separately disclosed). | CH27: ING_revGrowth | CI27: 0.02 | CJ27: Δ → | CK27: -0.03
B28: Book-to-bill (x) | C28: =IF(ISNUMBER(C27),IFERROR(C27/C13,""),"") | D28: =IF(ISNUMBER(D27),IFERROR(D27/D13,""),"") -> 0.071428571 | E28: =IF(ISNUMBER(E27),IFERROR(E27/E13,""),"") | F28: =IF(ISNUMBER(F27),IFERROR(F27/F13,""),"") -> 0.36762226 | G28: =IF(ISNUMBER(G27),IFERROR(G27/G13,""),"") -> 0.45172414 | H28: =IF(ISNUMBER(H27),IFERROR(H27/H13,""),"") | I28: =IF(ISNUMBER(I27),IFERROR(I27/I13,""),"") -> 0.32423208 | J28: =IF(ISNUMBER(J27),IFERROR(J27/J13,""),"") -> 0.54871795 | ... BS28: =IF(ISNUMBER(BS27),IFERROR(BS27/BS13,""),"") -> 2.0012739 | BT28: =$BV$28 -> 1 | BU28: =$BV$28 -> 1 | BV28: 1 | BW28: 1 | BX28: 1 | BY28: 1 | BZ28: 1 | CA28: Book-to-bill input (blue): 2026E cell = 2H/26 assumption applied to Q3/Q4-26E; 2027E+ held at 1.0x (backlog stable in $). Shipbuilding awards are lumpy (multi-ship / multi-year contracts) — adjust for known awards. | CH28: 2027E | CI28: =CJ28+$CI$27 -> 0.08 | CJ28: 0.06 | CK28: =CJ28+$CK$27 -> 0.03
B29: Backlog / revenue (years) | H29: =IFERROR(H26/H13,"") -> 2.9446984 | N29: =IFERROR(N26/N13,"") -> 2.8149853 | T29: =IFERROR(T26/T13,"") -> 3.3020661 | Z29: =IFERROR(Z26/Z13,"") -> 4.359417 | AF29: =IFERROR(AF26/AF13,"") -> 4.2093933 | AL29: =IFERROR(AL26/AL13,"") -> 4.5560119 | AR29: =IFERROR(AR26/AR13,"") -> 4.3544304 | AX29: =IFERROR(AX26/AX13,"") -> 4.9715953 | BD29: =IFERROR(BD26/BD13,"") -> 5.7220203 | BJ29: =IFERROR(BJ26/BJ13,"") -> 5.7289483 | BP29: =IFERROR(BP26/BP13,"") -> 5.7768031 | BV29: =IFERROR(BV26/BV13,"") -> 6.0843888 | BW29: =IFERROR(BW26/BW13,"") -> 5.7399895 | BX29: =IFERROR(BX26/BX13,"") -> 5.4407483 | BY29: =IFERROR(BY26/BY13,"") -> 5.1816651 | BZ29: =IFERROR(BZ26/BZ13,"") -> 4.9585312 | CH29: 2028E | CI29: =CJ29+$CI$27 -> 0.075 | CJ29: 0.055 | CK29: =CJ29+$CK$27 -> 0.025
B30: % of Revenue — Ingalls | CA30: % OF REVENUE drivers — hardcoded inputs that drive forecast segment cost / capital intensity | CH30: 2029E | CI30: =CJ30+$CI$27 -> 0.07 | CJ30: 0.05 | CK30: =CJ30+$CK$27 -> 0.02
B31: Intersegment revenue % of segment revenue | C31: =IFERROR(C12/C13,"n/d") -> 0 | D31: =IFERROR(D12/D13,"n/d") -> 0 | E31: =IFERROR(E12/E13,"n/d") -> 0 | F31: =IFERROR(F12/F13,"n/d") -> 0 | G31: =IFERROR(G12/G13,"n/d") -> 0 | H31: =IFERROR(H12/H13,"n/d") -> 0 | I31: =IFERROR(I12/I13,"n/d") -> 0 | J31: =IFERROR(J12/J13,"n/d") -> 0 | ... BS31: =IFERROR(BS12/BS13,"n/d") -> 0.0031847134 | BT31: =IFERROR(BT12/BT13,"") -> 0.0031041186 | BU31: =IFERROR(BU12/BU13,"") -> 0.0031041186 | BV31: =IFERROR(BV12/BV13,"") -> 0.0031438996 | BW31: =$BP$31 -> 0.0038986355 | BX31: =$BP$31 -> 0.0038986355 | BY31: =$BP$31 -> 0.0038986355 | BZ31: =$BP$31 -> 0.0038986355 | CA31: Held at FY2025 actual level (linked). | CH31: 2030E | CI31: =CJ31+$CI$27 -> 0.065 | CJ31: 0.045 | CK31: =CJ31+$CK$27 -> 0.015
B32: D&A % of revenue | C32: =IFERROR(C15/C13,"") -> 0 | D32: =IFERROR(D15/D13,"") -> 0 | E32: =IFERROR(E15/E13,"") -> 0 | F32: =IFERROR(F15/F13,"") -> 0 | G32: =IFERROR(G15/G13,"") -> 0 | H32: =IFERROR(H15/H13,"") -> 0.029707495 | I32: =IFERROR(I15/I13,"") -> 0 | J32: =IFERROR(J15/J13,"") -> 0 | ... BV32: =IFERROR(BV15/BV13,"") -> 0.026773854 | BW32: 0.026 | BX32: 0.026 | BY32: 0.026 | BZ32: 0.026 | CA32: Ingalls D&A ~2.6% of revenue (FY25 2.6%); held flat — capex step-up offsets revenue growth.
B33: Capital expenditures (segment) | H33: 53 | N33: 97 | T33: 131 | Z33: 134 | AF33: 182 | AL33: 104 | AR33: 72 | AX33: 69 | BD33: 65 | BE33: 11 | BF33: 13 | BG33: =BE33+BF33 -> 24 | BH33: 16 | BI33: 20 | BJ33: 60 | BK33: 14 | BL33: 16 | BM33: =BK33+BL33 -> 30 | BN33: 19 | BO33: 25 | BP33: 74 | BQ33: 10 | BV33: =BV13*BV34 -> 106.8648 | BW33: =BW13*BW34 -> 106.98353 | BX33: =BX13*BX34 -> 106.22836 | BY33: =BY13*BY34 -> 104.56854 | BZ33: =BZ13*BZ34 -> 101.98918 | CA33: Segment capex = revenue × segment capex %. Illustrative allocation of group capex (group capex in the CF statement is driven by the group capex % of revenue line). | CH33: NNS_revGrowth | CI33: 0.02 | CJ33: Δ → | CK33: -0.03
B34: Capex % of revenue | H34: =IFERROR(H33/H13,"") -> 0.024223035 | N34: =IFERROR(N33/N13,"") -> 0.040602763 | T34: =IFERROR(T33/T13,"") -> 0.054132231 | Z34: =IFERROR(Z33/Z13,"") -> 0.051400077 | AF34: =IFERROR(AF33/AF13,"") -> 0.071232877 | AL34: =IFERROR(AL33/AL13,"") -> 0.038834951 | AR34: =IFERROR(AR33/AR13,"") -> 0.028481013 | AX34: =IFERROR(AX33/AX13,"") -> 0.026848249 | BD34: =IFERROR(BD33/BD13,"") -> 0.023619186 | BJ34: =IFERROR(BJ33/BJ13,"") -> 0.021684134 | BP34: =IFERROR(BP33/BP13,"") -> 0.024041585 | BV34: =IFERROR($BP$34/$BP$227*BV227,0) -> 0.033597219 | BW34: =IFERROR($BP$34/$BP$227*BW227,0) -> 0.031730706 | BX34: =IFERROR($BP$34/$BP$227*BX227,0) -> 0.029864194 | BY34: =IFERROR($BP$34/$BP$227*BY227,0) -> 0.027997682 | BZ34: =IFERROR($BP$34/$BP$227*BZ227,0) -> 0.02613117 | CA34: Segment capex % = group capex % (CF memo) × FY2025 segment capex intensity relative to group. | CH34: 2027E | CI34: =CJ34+$CI$33 -> 0.09 | CJ34: 0.07 | CK34: =CJ34+$CK$33 -> 0.04
CH35: 2028E | CI35: =CJ35+$CI$33 -> 0.08 | CJ35: 0.06 | CK35: =CJ35+$CK$33 -> 0.03
B36: Newport News Shipbuilding | CA36: NEWPORT NEWS SHIPBUILDING — modelling logic | CH36: 2029E | CI36: =CJ36+$CI$33 -> 0.075 | CJ36: 0.055 | CK36: =CJ36+$CK$33 -> 0.025
B37: Revenue (external) | C37: =IF(ISNUMBER(C38),C39-C38,"n/d") -> n/d | D37: =IF(ISNUMBER(D38),D39-D38,"n/d") -> n/d | E37: =IF(ISNUMBER(E38),E39-E38,"n/d") -> n/d | F37: =IF(ISNUMBER(F38),F39-F38,"n/d") -> n/d | G37: =IF(ISNUMBER(G38),G39-G38,"n/d") -> n/d | H37: =IF(ISNUMBER(H38),H39-H38,"n/d") -> n/d | I37: =IF(ISNUMBER(I38),I39-I38,"n/d") -> n/d | J37: =IF(ISNUMBER(J38),J39-J38,"n/d") -> n/d | ... BZ37: =IF(ISNUMBER(BZ38),BZ39-BZ38,"n/d") -> 8943.3061 | CA37: External revenue = segment revenue less intersegment sales. Intersegment sales by segment not disclosed before FY2018 (n/d). | CH37: 2030E | CI37: =CJ37+$CI$33 -> 0.07 | CJ37: 0.05 | CK37: =CJ37+$CK$33 -> 0.02
B38: Intersegment revenue | V38: 3 | W38: =U38+V38 -> 3 | X38: 2 | Y38: 3 | Z38: 8 | AB38: 3 | AC38: =AA38+AB38 -> 3 | AD38: 1 | AE38: 4 | AF38: 8 | AG38: 2 | AH38: 2 | AI38: =AG38+AH38 -> 4 | AJ38: 3 | AK38: 5 | AL38: 12 | AM38: 2 | AN38: 4 | AO38: =AM38+AN38 -> 6 | AP38: 3 | AQ38: 2 | AR38: 11 | AS38: 2 | AU38: =AS38+AT38 -> 2 | AV38: 1 | AW38: 1 | AX38: 5 | AY38: 1 | AZ38: 0 | BA38: =AY38+AZ38 -> 1 | BB38: 2 | BC38: 0 | BD38: 3 | BE38: 1 | BF38: 1 | BG38: =BE38+BF38 -> 2 | BH38: 0 | BI38: 1 | BJ38: 3 | BL38: 1 | BM38: =BK38+BL38 -> 1 | BN38: 0 | BO38: 0 | BP38: 1 | BS38: =BQ38+BR38 -> 0 | BT38: =BS38/2 -> 0 | BU38: =BS38/2 -> 0 | BV38: =SUM(BQ38,BR38,BT38,BU38) -> 0 | BW38: =BW39*BW57 -> 1.1706752 | BX38: =BX39*BX57 -> 1.2409157 | BY38: =BY39*BY57 -> 1.3091661 | BZ38: =BZ39*BZ57 -> 1.3746244 | CA38: Q3/Q4-26E at 1H/26 run-rate; 2027E+ = segment revenue × intersegment % (held at FY2025 level).
B39: Segment revenue (as reported, incl. intersegment) | C39: 1061 | D39: 1166 | E39: =C39+D39 -> 2227 | F39: 1177 | G39: 1194 | H39: 4298 | I39: 993 | J39: 999 | K39: =I39+J39 -> 1992 | L39: 978 | M39: 1119 | N39: 4089 | O39: 971 | P39: 1001 | Q39: =O39+P39 -> 1972 | R39: 1053 | S39: 1139 | T39: 4164 | U39: 1082 | V39: 1183 | W39: =U39+V39 -> 2265 | X39: 1179 | Y39: 1352 | Z39: 4796 | AA39: 1279 | AB39: 1279 | AC39: =AA39+AB39 -> 2558 | AD39: 1274 | AE39: 1399 | AF39: 5231 | AG39: 1341 | AH39: 1122 | AI39: =AG39+AH39 -> 2463 | AJ39: 1358 | AK39: 1750 | AL39: 5571 | AM39: 1407 | AN39: 1363 | AO39: =AM39+AN39 -> 2770 | AP39: 1354 | AQ39: 1539 | AR39: 5663 | AS39: 1390 | AT39: 1433 | AU39: =AS39+AT39 -> 2823 | AV39: 1445 | AW39: 1584 | AX39: 5852 | AY39: 1506 | AZ39: 1509 | BA39: =AY39+AZ39 -> 3015 | BB39: 1453 | BC39: 1665 | BD39: 6133 | BE39: 1434 | BF39: 1535 | BG39: =BE39+BF39 -> 2969 | BH39: 1412 | BI39: 1588 | BJ39: 5969 | BK39: 1396 | BL39: 1603 | BM39: =BK39+BL39 -> 2999 | BN39: 1617 | BO39: 1891 | BP39: 6507 | BQ39: 1665 | BR39: 1849 | BS39: =BQ39+BR39 -> 3514 | BT39: =(CHOOSE(MATCH($CA$2,{"Bull","Base","Bear"},0),$CI$12,$CJ$12,$CK$12)-BS39-BS13)*BS39/(BS39+BS13)/2 -> 1802.6184 | BU39: =(CHOOSE(MATCH($CA$2,{"Bull","Base","Bear"},0),$CI$12,$CJ$12,$CK$12)-BS39-BS13)*BS39/(BS39+BS13)/2 -> 1802.6184 | BV39: =SUM(BQ39,BR39,BT39,BU39) -> 7119.2368 | BW39: =BV39*(1+BW43) -> 7617.5834 | BX39: =BW39*(1+BX43) -> 8074.6384 | BY39: =BX39*(1+BY43) -> 8518.7435 | BZ39: =BY39*(1+BZ43) -> 8944.6807 | CA39: Q3/26E–Q4/26E: FY26 guidance (scenario: high / mid / low end) less 1H/26 actuals, split evenly across Q3 and Q4. Shipbuilding guidance allocated between Ingalls and Newport News by 1H/26 revenue mix; 2H shipbuilding OI allocated by 2H revenue × 1H margin weights. 2027E+: prior year × (1 + scenario revenue growth). | CC39: =IFERROR((BZ39/BP39)^(1/5)-1,"n/m") -> 0.065704518 | CD39: =IFERROR((BP39/AL39)^(1/5)-1,"n/m") -> 0.03154821 | CE39: =IFERROR((BP39/H39)^(1/10)-1,"n/m") -> 0.042344885 | CH39: MT_revGrowth | CI39: 0.02 | CJ39: Δ → | CK39: -0.03
B40: Segment operating income | C40: 93 | D40: 109 | E40: =C40+D40 -> 202 | F40: 100 | G40: 116 | H40: 401 | I40: 81 | J40: 98 | K40: =I40+J40 -> 179 | L40: 68 | M40: 139 | N40: 386 | O40: 72 | P40: 80 | Q40: =O40+P40 -> 152 | R40: 96 | S40: 106 | T40: 354 | U40: 51 | V40: 91 | W40: =U40+V40 -> 142 | X40: 119 | Y40: 69 | Z40: 330 | AA40: 81 | AB40: 71 | AC40: =AA40+AB40 -> 152 | AD40: 121 | AE40: 137 | AF40: 410 | AG40: 95 | AH40: -69 | AI40: =AG40+AH40 -> 26 | AJ40: 79 | AK40: 128 | AL40: 233 | AM40: 93 | AN40: 76 | AO40: =AM40+AN40 -> 169 | AP40: 88 | AQ40: 95 | AR40: 352 | AS40: 81 | AT40: 94 | AU40: =AS40+AT40 -> 175 | AV40: 102 | AW40: 80 | AX40: 357 | AY40: 84 | AZ40: 95 | BA40: =AY40+AZ40 -> 179 | BB40: 90 | BC40: 110 | BD40: 379 | BE40: 82 | BF40: 111 | BG40: =BE40+BF40 -> 193 | BH40: 15 | BI40: 38 | BJ40: 246 | BK40: 85 | BL40: 82 | BM40: =BK40+BL40 -> 167 | BN40: 80 | BO40: 84 | BP40: 331 | BQ40: 88 | BR40: 111 | BS40: =BQ40+BR40 -> 199 | BT40: =(CHOOSE(MATCH($CA$2,{"Bull","Base","Bear"},0),$CI$12,$CJ$12,$CK$12)*CHOOSE(MATCH($CA$2,{"Bull","Base","Bear"},0),$CI$13,$CJ$13,$CK$13)-BS40-BS14)*BT39*BS40/BS39/(BT39*BS40/BS39+BT13*BS14/BS13)/2 -> 109.82394 | BU40: =(CHOOSE(MATCH($CA$2,{"Bull","Base","Bear"},0),$CI$12,$CJ$12,$CK$12)*CHOOSE(MATCH($CA$2,{"Bull","Base","Bear"},0),$CI$13,$CJ$13,$CK$13)-BS40-BS14)*BU39*BS40/BS39/(BU39*BS40/BS39+BU13*BS14/BS13)/2 -> 109.82394 | BV40: =SUM(BQ40,BR40,BT40,BU40) -> 418.64788 | BW40: =BW39*BW46 -> 514.18688 | BX40: =BX39*BX46 -> 565.22469 | BY40: =BY39*BY46 -> 617.6089 | BZ40: =BZ39*BZ46 -> 670.85105 | CA40: Q3/26E–Q4/26E: FY26 guidance (scenario: high / mid / low end) less 1H/26 actuals, split evenly across Q3 and Q4. Shipbuilding guidance allocated between Ingalls and Newport News by 1H/26 revenue mix; 2H shipbuilding OI allocated by 2H revenue × 1H margin weights. 2027E+: segment revenue × scenario segment operating margin. | CC40: =IFERROR((BZ40/BP40)^(1/5)-1,"n/m") -> 0.15175372 | CD40: =IFERROR((BP40/AL40)^(1/5)-1,"n/m") -> 0.072739851 | CE40: =IFERROR((BP40/H40)^(1/10)-1,"n/m") -> -0.019001458 | CH40: 2027E | CI40: =CJ40+$CI$39 -> 0.06 | CJ40: 0.04 | CK40: =CJ40+$CK$39 -> 0.01
...

Sheet Bull-Base-Bear
B2: Huntington Ingalls Industries (HII) — Bull / Base / Bear Case P&L Summary | J2: Share price ($): | K2: =Model!$BV$350 -> 275
B3: Adjusted figures · USD millions · Live panel linked to Model — toggle scenario via Model!CA2. Bull and Bear panels are value snapshots generated from the Model with the switch set to each case. | J3: As of: | K3: =TODAY() -> 46297
B5: Scenario: | C5: =Model!CA2 -> Base | N5: Scenario: | O5: Bull | P5: Snapshot (values) — Model run with switch = Bull | Z5: Scenario: | AA5: Bear | AB5: Snapshot (values) — Model run with switch = Bear
B7: (USDm, except EPS and shares) | C7: 2025A | D7: 2026E | E7: 2027E | F7: 2028E | G7: 2029E | H7: 2030E | I7: 25-'30 CAGR | J7: LT Hist Avg | K7: LT Hist Min | L7: LT Hist Max | N7: (USDm, except EPS and shares) | O7: 2025A | P7: 2026E | Q7: 2027E | R7: 2028E | S7: 2029E | T7: 2030E | U7: 25-'30 CAGR | V7: LT Hist Avg | W7: LT Hist Min | X7: LT Hist Max | Z7: (USDm, except EPS and shares) | AA7: 2025A | AB7: 2026E | AC7: 2027E | AD7: 2028E | AE7: 2029E | AF7: 2030E | AG7: 25-'30 CAGR | AH7: LT Hist Avg | AI7: LT Hist Min | AJ7: LT Hist Max
B9: Revenue | C9: =Model!BP119 -> 12484 | D9: =Model!BV119 -> 13250 | E9: =Model!BW119 -> 14059.071 | F9: =Model!BX119 -> 14824.14 | G9: =Model!BY119 -> 15589.676 | H9: =Model!BZ119 -> 16333.798 | I9: =IFERROR((H9/C9)^(1/5)-1,"n/m") -> 0.055228921 | N9: Revenue | O9: 12484 | P9: 13450 | Q9: 14534.066 | R9: 15614.618 | S9: 16732.747 | T9: 17865.853 | U9: 0.074320835 | Z9: Revenue | AA9: 12484 | AB9: 13050 | AC9: 13461.333 | AD9: 13791.042 | AE9: 14089.98 | AF9: 14340.028 | AG9: 0.028109202
B10: Revenue y/y % | D10: =IFERROR(D9/C9-1,"") -> 0.061358539 | E10: =IFERROR(E9/D9-1,"") -> 0.061062 | F10: =IFERROR(F9/E9-1,"") -> 0.054418109 | G10: =IFERROR(G9/F9-1,"") -> 0.051641186 | H10: =IFERROR(H9/G9-1,"") -> 0.047731755 | N10: Revenue y/y % | P10: 0.077379045 | Q10: 0.080599705 | R10: 0.074346148 | S10: 0.071607861 | T10: 0.067717842 | Z10: Revenue y/y % | AB10: 0.045338033 | AC10: 0.031519756 | AD10: 0.024493057 | AE10: 0.021676209 | AF10: 0.017746526
B12: Segment Operating Income (Adj. EBIT) | C12: =Model!BP97 -> 717 | D12: =Model!BV97 -> 798.75 | E12: =Model!BW97 -> 927.88853 | F12: =Model!BX97 -> 1016.416 | G12: =Model!BY97 -> 1108.5346 | H12: =Model!BZ97 -> 1202.7796 | I12: =IFERROR((H12/C12)^(1/5)-1,"n/m") -> 0.10900469 | N12: Segment Operating Income (Adj. EBIT) | O12: 717 | P12: 844 | Q12: 1031.9144 | R12: 1148.6886 | S12: 1273.4809 | T12: 1404.934 | U12: 0.14400351 | Z12: Segment Operating Income (Adj. EBIT) | AA12: 717 | AB12: 754.5 | AC12: 734.27946 | AD12: 787.45221 | AE12: 840.24339 | AF12: 891.39776 | AG12: 0.044504887
B13: Segment operating margin % | C13: =IFERROR(C12/C9,"") -> 0.057433515 | D13: =IFERROR(D12/D9,"") -> 0.060283019 | E13: =IFERROR(E12/E9,"") -> 0.065999275 | F13: =IFERROR(F12/F9,"") -> 0.068564927 | G13: =IFERROR(G12/G9,"") -> 0.071106971 | H13: =IFERROR(H12/H9,"") -> 0.073637474 | J13: =AVERAGE(Model!H107,Model!N107,Model!T107,Model!Z107,Model!AF107,Model!AL107,Model!AR107,Model!AX107,Model!BD107,Model!BJ107,Model!BP107) -> 0.074449685 | K13: =MIN(Model!H107,Model!N107,Model!T107,Model!Z107,Model!AF107,Model!AL107,Model!AR107,Model!AX107,Model!BD107,Model!BJ107,Model!BP107) -> 0.049674902 | L13: =MAX(Model!H107,Model!N107,Model!T107,Model!Z107,Model!AF107,Model!AL107,Model!AR107,Model!AX107,Model!BD107,Model!BJ107,Model!BP107) -> 0.10116016 | N13: Segment operating margin % | O13: 0.057433515 | P13: 0.062750929 | Q13: 0.070999707 | R13: 0.073564954 | S13: 0.0761071 | T13: 0.07863795 | V13: 0.074449685 | W13: 0.049674902 | X13: 0.10116016 | Z13: Segment operating margin % | AA13: 0.057433515 | AB13: 0.057816092 | AC13: 0.054547307 | AD13: 0.057098819 | AE13: 0.05963411 | AF13: 0.062161509 | AH13: 0.074449685 | AI13: 0.049674902 | AJ13: 0.10116016
B15: Operating Income (GAAP) | C15: =Model!BP126 -> 657 | D15: =Model!BV126 -> 734.75 | E15: =Model!BW126 -> 863.88853 | F15: =Model!BX126 -> 952.41605 | G15: =Model!BY126 -> 1044.5346 | H15: =Model!BZ126 -> 1138.7796 | I15: =IFERROR((H15/C15)^(1/5)-1,"n/m") -> 0.11628443 | N15: Operating Income (GAAP) | O15: 657 | P15: 780 | Q15: 967.91444 | R15: 1084.6886 | S15: 1209.4809 | T15: 1340.934 | U15: 0.15336936 | Z15: Operating Income (GAAP) | AA15: 657 | AB15: 690.5 | AC15: 670.27946 | AD15: 723.45221 | AE15: 776.24339 | AF15: 827.39776 | AG15: 0.047200387
B16: Operating income y/y % | D16: =IFERROR(D15/C15-1,"") -> 0.11834094 | E16: =IFERROR(E15/D15-1,"") -> 0.17575846 | F16: =IFERROR(F15/E15-1,"") -> 0.10247563 | G16: =IFERROR(G15/F15-1,"") -> 0.096720943 | H16: =IFERROR(H15/G15-1,"") -> 0.090226804 | N16: Operating income y/y % | P16: 0.18721461 | Q16: 0.24091595 | R16: 0.12064518 | S16: 0.11504889 | T16: 0.1086856 | Z16: Operating income y/y % | AB16: 0.050989346 | AC16: -0.029283914 | AD16: 0.079329234 | AE16: 0.072971198 | AF16: 0.065899912
B17: Operating margin (GAAP) % | C17: =IFERROR(C15/C9,"") -> 0.052627363 | D17: =IFERROR(D15/D9,"") -> 0.05545283 | E17: =IFERROR(E15/E9,"") -> 0.061447054 | F17: =IFERROR(F15/F9,"") -> 0.064247644 | G17: =IFERROR(G15/G9,"") -> 0.06700169 | H17: =IFERROR(H15/H9,"") -> 0.069719218 | J17: =AVERAGE(Model!H180,Model!N180,Model!T180,Model!Z180,Model!AF180,Model!AL180,Model!AR180,Model!AX180,Model!BD180,Model!BJ180,Model!BP180) -> 0.082517328 | K17: =MIN(Model!H180,Model!N180,Model!T180,Model!Z180,Model!AF180,Model!AL180,Model!AR180,Model!AX180,Model!BD180,Model!BJ180,Model!BP180) -> 0.046380581 | L17: =MAX(Model!H180,Model!N180,Model!T180,Model!Z180,Model!AF180,Model!AL180,Model!AR180,Model!AX180,Model!BD180,Model!BJ180,Model!BP180) -> 0.12139219 | N17: Operating margin (GAAP) % | O17: 0.052627363 | P17: 0.057992565 | Q17: 0.06659626 | R17: 0.069466231 | S17: 0.072282265 | T17: 0.075055697 | V17: 0.082517328 | W17: 0.046380581 | X17: 0.12139219 | Z17: Operating margin (GAAP) % | AA17: 0.052627363 | AB17: 0.052911877 | AC17: 0.049792949 | AD17: 0.052458126 | AE17: 0.055091875 | AF17: 0.057698477 | AH17: 0.082517328 | AI17: 0.046380581 | AJ17: 0.12139219
B19: Net Income (Adjusted, model) | C19: =Model!BP164 -> 502.3 | D19: =Model!BV164 -> 598.3725 | E19: =Model!BW164 -> 676.77859 | F19: =Model!BX164 -> 749.37116 | G19: =Model!BY164 -> 824.90839 | H19: =Model!BZ164 -> 902.18931 | I19: =IFERROR((H19/C19)^(1/5)-1,"n/m") -> 0.12426036 | N19: Net Income (Adjusted, model) | O19: 502.3 | P19: 635.93 | Q19: 762.07984 | R19: 857.83469 | S19: 960.16432 | T19: 1067.9559 | U19: 0.16283482 | Z19: Net Income (Adjusted, model) | AA19: 502.3 | AB19: 561.645 | AC19: 518.01915 | AD19: 561.62081 | AE19: 604.90958 | AF19: 646.85616 | AG19: 0.051886565
B21: FDSO (m) | C21: =Model!BP137 -> 39.3 | D21: =Model!BV137 -> 39.45 | E21: =Model!BW137 -> 39.485153 | F21: =Model!BX137 -> 38.898288 | G21: =Model!BY137 -> 38.206017 | H21: =Model!BZ137 -> 37.425285 | I21: =IFERROR((H21/C21)^(1/5)-1,"n/m") -> -0.0097279683 | N21: FDSO (m) | O21: 39.3 | P21: 39.45 | Q21: 38.684813 | R21: 37.604853 | S21: 36.451744 | T21: 35.240323 | U21: -0.021570662 | Z21: FDSO (m) | AA21: 39.3 | AB21: 39.45 | AC21: 39.825 | AD21: 39.895596 | AE21: 39.817775 | AF21: 39.611295 | AG21: 0.001579203
B23: Adjusted EPS — Diluted ($) | C23: =Model!BP166 -> 12.78117 | D23: =Model!BV166 -> 15.167871 | E23: =Model!BW166 -> 17.140078 | F23: =Model!BX166 -> 19.264888 | G23: =Model!BY166 -> 21.59106 | H23: =Model!BZ166 -> 24.106411 | I23: =IFERROR((H23/C23)^(1/5)-1,"n/m") -> 0.13530457 | N23: Adjusted EPS — Diluted ($) | O23: 12.78117 | P23: 16.119899 | Q23: 19.699716 | R23: 22.811808 | S23: 26.340696 | T23: 30.304941 | U23: 0.18847093 | Z23: Adjusted EPS — Diluted ($) | AA23: 12.78117 | AB23: 14.236882 | AC23: 13.007386 | AD23: 14.077263 | AE23: 15.191948 | AF23: 16.330094 | AG23: 0.050228042
B24: EPS y/y % | D24: =IFERROR(D23/C23-1,"") -> 0.18673565 | E24: =IFERROR(E23/D23-1,"") -> 0.13002531 | F24: =IFERROR(F23/E23-1,"") -> 0.12396735 | G24: =IFERROR(G23/F23-1,"") -> 0.12074671 | H24: =IFERROR(H23/G23-1,"") -> 0.11649968 | N24: EPS y/y % | P24: 0.26122241 | Q24: 0.22207445 | R24: 0.1579765 | S24: 0.15469565 | T24: 0.15049886 | Z24: EPS y/y % | AB24: 0.11389502 | AC24: -0.086359916 | AD24: 0.082251504 | AE24: 0.079183356 | AF24: 0.074917683
B26: P / E (x) — assumed | E26: 16.5 | F26: =E26 -> 16.5 | G26: =F26 -> 16.5 | H26: =G26 -> 16.5 | N26: P / E (x) — assumed | Q26: 19 | R26: 19 | S26: 19 | T26: 19 | Z26: P / E (x) — assumed | AC26: 14 | AD26: 14 | AE26: 14 | AF26: 14
B27: Price Target ($) | E27: =E26*E23 -> 282.81128 | F27: =F26*F23 -> 317.87065 | G27: =G26*G23 -> 356.25248 | H27: =H26*H23 -> 397.75578 | N27: Price Target ($) | Q27: 374.29461 | R27: 433.42436 | S27: 500.47322 | T27: 575.79388 | Z27: Price Target ($) | AC27: 182.10341 | AD27: 197.08169 | AE27: 212.68727 | AF27: 228.62131
B28: Upside / (Downside) vs current | E28: =IFERROR(E27/$K$2-1,"") -> 0.02840467 | F28: =IFERROR(F27/$K$2-1,"") -> 0.15589327 | G28: =IFERROR(G27/$K$2-1,"") -> 0.29546357 | H28: =IFERROR(H27/$K$2-1,"") -> 0.44638467 | N28: Upside / (Downside) vs current | Q28: 0.3610713 | R28: 0.57608858 | S28: 0.81990263 | T28: 1.0937959 | Z28: Upside / (Downside) vs current | AC28: -0.33780579 | AD28: -0.28333932 | AE28: -0.22659173 | AF28: -0.16864977
B29: IRR (to Dec-Y-1) | F29: =IFERROR((F27/$K$2)^(1/((DATE(VALUE(LEFT(F$7,4))-1,12,31)-$K$3)/365.25))-1,"") -> 0.12332918 | G29: =IFERROR((G27/$K$2)^(1/((DATE(VALUE(LEFT(G$7,4))-1,12,31)-$K$3)/365.25))-1,"") -> 0.12206033 | H29: =IFERROR((H27/$K$2)^(1/((DATE(VALUE(LEFT(H$7,4))-1,12,31)-$K$3)/365.25))-1,"") -> 0.12037208 | N29: IRR (to Dec-Y-1) | R29: 0.44081195 | S29: 0.30524289 | T29: 0.25556007 | Z29: IRR (to Dec-Y-1) | AD29: -0.23466184 | AE29: -0.10802058 | AF29: -0.05529536
B31: Free Cash Flow | C31: =Model!BP221 -> 800 | D31: =Model!BV221 -> 550 | E31: =Model!BW221 -> 416.48627 | F31: =Model!BX221 -> 577.77523 | G31: =Model!BY221 -> 671.64027 | H31: =Model!BZ221 -> 781.51157 | I31: =IFERROR((H31/C31)^(1/5)-1,"n/m") -> -0.0046654374 | N31: Free Cash Flow | O31: 800 | P31: 600 | Q31: 490.65185 | R31: 673.10027 | S31: 790.66309 | T31: 929.26664 | U31: 0.030410017 | Z31: Free Cash Flow | AA31: 800 | AB31: 500 | AC31: 275.82468 | AD31: 409.15287 | AE31: 474.90789 | AF31: 551.56894 | AG31: -0.071670903
B32: FCF % | C32: =IFERROR(C31/C9,"") -> 0.064082025 | D32: =IFERROR(D31/D9,"") -> 0.041509434 | E32: =IFERROR(E31/E9,"") -> 0.029624024 | F32: =IFERROR(F31/F9,"") -> 0.038975296 | G32: =IFERROR(G31/G9,"") -> 0.043082376 | H32: =IFERROR(H31/H9,"") -> 0.047846285 | J32: =AVERAGE(Model!H223,Model!N223,Model!T223,Model!Z223,Model!AF223,Model!AL223,Model!AR223,Model!AX223,Model!BD223,Model!BJ223,Model!BP223) -> 0.059026037 | K32: =MIN(Model!H223,Model!N223,Model!T223,Model!Z223,Model!AF223,Model!AL223,Model!AR223,Model!AX223,Model!BD223,Model!BJ223,Model!BP223) -> 0.003467707 | L32: =MAX(Model!H223,Model!N223,Model!T223,Model!Z223,Model!AF223,Model!AL223,Model!AR223,Model!AX223,Model!BD223,Model!BJ223,Model!BP223) -> 0.095868946 | N32: FCF % | O32: 0.064082025 | P32: 0.044609665 | Q32: 0.033758746 | R32: 0.04310706 | S32: 0.047252437 | T32: 0.052013562 | V32: 0.059026037 | W32: 0.003467707 | X32: 0.095868946 | Z32: FCF % | AA32: 0.064082025 | AB32: 0.038314176 | AC32: 0.020490146 | AD32: 0.029668017 | AE32: 0.033705364 | AF32: 0.038463589 | AH32: 0.059026037 | AI32: 0.003467707 | AJ32: 0.095868946
B33: FCF / share ($) | C33: =IFERROR(C31/C21,"") -> 20.356234 | D33: =IFERROR(D31/D21,"") -> 13.941698 | E33: =IFERROR(E31/E21,"") -> 10.547921 | F33: =IFERROR(F31/F21,"") -> 14.853487 | G33: =IFERROR(G31/G21,"") -> 17.579437 | H33: =IFERROR(H31/H21,"") -> 20.881914 | N33: FCF / share ($) | O33: 20.356234 | P33: 15.209125 | Q33: 12.68332 | R33: 17.899293 | S33: 21.690679 | T33: 26.369413 | Z33: FCF / share ($) | AA33: 20.356234 | AB33: 12.674271 | AC33: 6.9259179 | AD33: 10.25559 | AE33: 11.927032 | AF33: 13.924537
B34: FCF Yield (on PT) | E34: =IFERROR(E33/E$27,"") -> 0.037296676 | F34: =IFERROR(F33/F$27,"") -> 0.046728087 | G34: =IFERROR(G33/G$27,"") -> 0.049345444 | H34: =IFERROR(H33/H$27,"") -> 0.052499334 | N34: FCF Yield (on PT) | Q34: 0.033885927 | R34: 0.041297385 | S34: 0.043340339 | T34: 0.04579662 | Z34: FCF Yield (on PT) | AC34: 0.038032885 | AD34: 0.052037254 | AE34: 0.05607779 | AF34: 0.060906556
B35: Segment EBITDA | C35: =Model!BP103 -> 1046 | D35: =Model!BV103 -> 1128.75 | E35: =Model!BW103 -> 1267.1524 | F35: =Model!BX103 -> 1373.681 | G35: =Model!BY103 -> 1483.8949 | H35: =Model!BZ103 -> 1595.7669 | I35: =IFERROR((H35/C35)^(1/5)-1,"n/m") -> 0.088146965 | N35: Segment EBITDA | O35: 1046 | P35: 1174 | Q35: 1382.7485 | R35: 1525.0547 | S35: 1676.3548 | T35: 1834.7127 | U35: 0.11894123 | Z35: Segment EBITDA | AA35: 1046 | AB35: 1084.5 | AC35: 1059.0539 | AD35: 1119.8526 | AE35: 1179.6257 | AF35: 1236.643 | AG35: 0.034052364
B36: Segment EBITDA margin % | C36: =IFERROR(C35/C9,"") -> 0.083787248 | D36: =IFERROR(D35/D9,"") -> 0.085188679 | E36: =IFERROR(E35/E9,"") -> 0.09013059 | F36: =IFERROR(F35/F9,"") -> 0.09266514 | G36: =IFERROR(G35/G9,"") -> 0.095184464 | H36: =IFERROR(H35/H9,"") -> 0.097697235 | J36: =AVERAGE(Model!H110,Model!N110,Model!T110,Model!Z110,Model!AF110,Model!AL110,Model!AR110,Model!AX110,Model!BD110,Model!BJ110,Model!BP110) -> 0.10221681 | K36: =MIN(Model!H110,Model!N110,Model!T110,Model!Z110,Model!AF110,Model!AL110,Model!AR110,Model!AX110,Model!BD110,Model!BJ110,Model!BP110) -> 0.077936714 | L36: =MAX(Model!H110,Model!N110,Model!T110,Model!Z110,Model!AF110,Model!AL110,Model!AR110,Model!AX110,Model!BD110,Model!BJ110,Model!BP110) -> 0.12747595 | N36: Segment EBITDA margin % | O36: 0.083787248 | P36: 0.087286245 | Q36: 0.095138451 | R36: 0.097668398 | S36: 0.10018408 | T36: 0.10269382 | V36: 0.10221681 | W36: 0.077936714 | X36: 0.12747595 | Z36: Segment EBITDA margin % | AA36: 0.083787248 | AB36: 0.083103448 | AC36: 0.07867378 | AD36: 0.081201446 | AE36: 0.083720899 | AF36: 0.086237142 | AH36: 0.10221681 | AI36: 0.077936714 | AJ36: 0.12747595
B38: Net Debt | C38: =Model!BP324 -> 1926 | D38: =Model!BV324 -> 1638.764 | E38: =Model!BW324 -> 1666.206 | F38: =Model!BX324 -> 1585.64 | G38: =Model!BY324 -> 1463.8496 | H38: =Model!BZ324 -> 1284.2329 | N38: Net Debt | O38: 1926 | P38: 1738.764 | Q38: 1837.49 | R38: 1804.0244 | S38: 1702.6297 | T38: 1511.6832 | Z38: Net Debt | AA38: 1926 | AB38: 1688.764 | AC38: 1658.7998 | AD38: 1552.6966 | AE38: 1437.3605 | AF38: 1301.2677
B39: Net Debt / Segment EBITDA (x) | C39: =IFERROR(C38/C35,"") -> 1.8413002 | D39: =IFERROR(D38/D35,"") -> 1.4518396 | E39: =IFERROR(E38/E35,"") -> 1.3149215 | F39: =IFERROR(F38/F35,"") -> 1.1543001 | G39: =IFERROR(G38/G35,"") -> 0.98649144 | H39: =IFERROR(H38/H35,"") -> 0.80477475 | N39: Net Debt / Segment EBITDA (x) | O39: 1.8413002 | P39: 1.4810596 | Q39: 1.3288678 | R39: 1.1829244 | S39: 1.0156738 | T39: 0.82393454 | Z39: Net Debt / Segment EBITDA (x) | AA39: 1.8413002 | AB39: 1.5571821 | AC39: 1.5663034 | AD39: 1.3865188 | AE39: 1.2184886 | AF39: 1.0522581
B41: ROIC | C41: =Model!BP325 -> 0.079765946 | D41: =Model!BV325 -> 0.091758468 | E41: =Model!BW325 -> 0.099290118 | F41: =Model!BX325 -> 0.10399557 | G41: =Model!BY325 -> 0.10887031 | H41: =Model!BZ325 -> 0.11397123 | J41: =AVERAGE(Model!H325,Model!N325,Model!T325,Model!Z325,Model!AF325,Model!AL325,Model!AR325,Model!AX325,Model!BD325,Model!BJ325,Model!BP325) -> 0.15198199 | K41: =MIN(Model!H325,Model!N325,Model!T325,Model!Z325,Model!AF325,Model!AL325,Model!AR325,Model!AX325,Model!BD325,Model!BJ325,Model!BP325) -> 0.06963973 | L41: =MAX(Model!H325,Model!N325,Model!T325,Model!Z325,Model!AF325,Model!AL325,Model!AR325,Model!AX325,Model!BD325,Model!BJ325,Model!BP325) -> 0.23635014 | N41: ROIC | O41: 0.079765946 | P41: 0.097123938 | Q41: 0.1104404 | R41: 0.11735592 | S41: 0.12465086 | T41: 0.13242161 | V41: 0.15198199 | W41: 0.06963973 | X41: 0.23635014 | Z41: ROIC | AA41: 0.079765946 | AB41: 0.086516204 | AC41: 0.078622193 | AD41: 0.080810446 | AE41: 0.082990509 | AF41: 0.08518048 | AH41: 0.15198199 | AI41: 0.06963973 | AJ41: 0.23635014
B42: RONTA | C42: =Model!BP337 -> 0.087780166 | D42: =Model!BV337 -> 0.09367425 | E42: =Model!BW337 -> 0.099984324 | F42: =Model!BX337 -> 0.1022934 | G42: =Model!BY337 -> 0.10454844 | H42: =Model!BZ337 -> 0.10651512 | J42: =AVERAGE(Model!H337,Model!N337,Model!T337,Model!Z337,Model!AF337,Model!AL337,Model!AR337,Model!AX337,Model!BD337,Model!BJ337,Model!BP337) -> 0.1333038 | K42: =MIN(Model!H337,Model!N337,Model!T337,Model!Z337,Model!AF337,Model!AL337,Model!AR337,Model!AX337,Model!BD337,Model!BJ337,Model!BP337) -> 0.078382283 | L42: =MAX(Model!H337,Model!N337,Model!T337,Model!Z337,Model!AF337,Model!AL337,Model!AR337,Model!AX337,Model!BD337,Model!BJ337,Model!BP337) -> 0.20393778 | N42: RONTA | O42: 0.087780166 | P42: 0.10057896 | Q42: 0.11377398 | R42: 0.11861242 | S42: 0.12308798 | T42: 0.12690316 | V42: 0.1333038 | W42: 0.078382283 | X42: 0.20393778 | Z42: RONTA | AA42: 0.087780166 | AB42: 0.088946368 | AC42: 0.079095217 | AD42: 0.079162846 | AE42: 0.079434675 | AF42: 0.079711651 | AH42: 0.1333038 | AI42: 0.078382283 | AJ42: 0.20393778
B44: Implied Market Cap (USDm) | E44: =E27*E21 -> 11166.847 | F44: =F27*F21 -> 12364.624 | G44: =G27*G21 -> 13610.988 | H44: =H27*H21 -> 14886.124 | N44: Implied Market Cap (USDm) | Q44: 14479.517 | R44: 16298.859 | S44: 18243.122 | T44: 20291.162 | Z44: Implied Market Cap (USDm) | AC44: 7252.2682 | AD44: 7862.6914 | AE44: 8468.7341 | AF44: 9055.9863
B45: (+) Net Debt | E45: =E38 -> 1666.206 | F45: =F38 -> 1585.64 | G45: =G38 -> 1463.8496 | H45: =H38 -> 1284.2329 | N45: (+) Net Debt | Q45: 1837.49 | R45: 1804.0244 | S45: 1702.6297 | T45: 1511.6832 | Z45: (+) Net Debt | AC45: 1658.7998 | AD45: 1552.6966 | AE45: 1437.3605 | AF45: 1301.2677
B46: Implied Enterprise Value (USDm) | E46: =E44+E45 -> 12833.053 | F46: =F44+F45 -> 13950.264 | G46: =G44+G45 -> 15074.838 | H46: =H44+H45 -> 16170.357 | N46: Implied Enterprise Value (USDm) | Q46: 16317.007 | R46: 18102.884 | S46: 19945.752 | T46: 21802.845 | Z46: Implied Enterprise Value (USDm) | AC46: 8911.0679 | AD46: 9415.388 | AE46: 9906.0946 | AF46: 10357.254
B47: Implied EV / Segment EBITDA (x) | E47: =IFERROR(E46/E35,"") -> 10.127474 | F47: =IFERROR(F46/F35,"") -> 10.155389 | G47: =IFERROR(G46/G35,"") -> 10.158966 | H47: =IFERROR(H46/H35,"") -> 10.133282 | N47: Implied EV / Segment EBITDA (x) | Q47: 11.800415 | R47: 11.870317 | S47: 11.898288 | T47: 11.88352 | Z47: Implied EV / Segment EBITDA (x) | AC47: 8.4141776 | AD47: 8.4077033 | AE47: 8.3976588 | AF47: 8.3752982

Sheet DCF
B2: DCF VALUATION — HUNTINGTON INGALLS INDUSTRIES (HII)
B4: 1. WACC BUILD
B5: Risk-free rate (US 10Y govt) | C5: 0.0425 | D5: Assumption (~US 10Y Treasury yield); update to market
B6: Equity risk premium | C6: 0.055 | D6: Damodaran-style US ERP estimate
B7: Levered beta | C7: 0.65 | D7: Defense prime / shipbuilder beta range ~0.5–0.8 (US-government-funded, long-cycle backlog)
B8: Cost of equity | C8: =C5+C7*C6 -> 0.07825
B9: Pre-tax cost of debt | C9: 0.05 | D9: HII senior notes (BBB- / Baa3) — FY26 interest guidance $105m on $2.7bn debt ≈ 3.9% coupon; marginal cost ~5%
B10: Tax rate | C10: 0.21 | D10: US federal statutory rate
B11: After-tax cost of debt | C11: =C9*(1-C10) -> 0.0395
B12: Target D/V | C12: 0.15 | D12: Target leverage; net debt / total capital
B13: WACC | C13: =C8*(1-C12)+C11*C12 -> 0.0724375
B15: Valuation date (live) | C15: =TODAY() -> 46297 | D15: Periods = (Dec-31-Year − today) / 365.25; cash flows assumed at year-end
B16: 2. UNLEVERED FREE CASH FLOW BUILD (USDm)
D17: 2026E | E17: 2027E | F17: 2028E | G17: 2029E | H17: 2030E | I17: 2031E | J17: 2032E | K17: 2033E | L17: 2034E | M17: 2035E | N17: Terminal
B18: Segment operating income (Adj. EBIT) | D18: =Model!BV97 -> 798.75 | E18: =Model!BW97 -> 927.88853 | F18: =Model!BX97 -> 1016.416 | G18: =Model!BY97 -> 1108.5346 | H18: =Model!BZ97 -> 1202.7796 | I18: =H18*(1+I$26) -> 1250.8908 | J18: =I18*(1+J$26) -> 1294.672 | K18: =J18*(1+K$26) -> 1333.5122 | L18: =K18*(1+L$26) -> 1370.1838 | M18: =L18*(1+M$26) -> 1404.4384
B19: × (1 − tax rate) | D19: =1-$C$10 -> 0.79 | E19: =1-$C$10 -> 0.79 | F19: =1-$C$10 -> 0.79 | G19: =1-$C$10 -> 0.79 | H19: =1-$C$10 -> 0.79 | I19: =1-$C$10 -> 0.79 | J19: =1-$C$10 -> 0.79 | K19: =1-$C$10 -> 0.79 | ... M19: =1-$C$10 -> 0.79
B20: NOPAT | D20: =D18*D19 -> 631.0125 | E20: =E18*E19 -> 733.03194 | F20: =F18*F19 -> 802.96868 | G20: =G18*G19 -> 875.74235 | H20: =H18*H19 -> 950.19592 | I20: =I18*I19 -> 988.20376 | J20: =J18*J19 -> 1022.7909 | K20: =K18*K19 -> 1053.4746 | ... M20: =M18*M19 -> 1109.5063
B21: plus D&A | D21: =Model!BV102 -> 330 | E21: =Model!BW102 -> 339.26388 | F21: =Model!BX102 -> 357.26492 | G21: =Model!BY102 -> 375.3603 | H21: =Model!BZ102 -> 392.98728 | I21: =H21*(1+I$26) -> 408.70677 | J21: =I21*(1+J$26) -> 423.01151 | K21: =J21*(1+K$26) -> 435.70186 | L21: =K21*(1+L$26) -> 447.68366 | M21: =L21*(1+M$26) -> 458.87575
B22: − Capex (net of grant proceeds) | D22: =Model!BV204+Model!BV205 -> -590.25 | E22: =Model!BW204+Model!BW205 -> -587.51054 | F22: =Model!BX204+Model!BX205 -> -582.96558 | G22: =Model!BY204+Model!BY205 -> -574.61284 | H22: =Model!BZ204+Model!BZ205 -> -561.68294 | I22: =H22*(1+I$26) -> -584.15026 | J22: =I22*(1+J$26) -> -604.59552 | K22: =J22*(1+K$26) -> -622.73338 | L22: =K22*(1+L$26) -> -639.85855 | M22: =L22*(1+M$26) -> -655.85502
B23: − Δ Working capital (CF statement) | D23: =SUM(Model!BV197:BV201) -> 83.1675 | E23: =SUM(Model!BW197:BW201) -> -80.755666 | F23: =SUM(Model!BX197:BX201) -> -6.6052624 | G23: =SUM(Model!BY197:BY201) -> -6.7255851 | H23: =SUM(Model!BZ197:BZ201) -> -6.6920823 | I23: =H23*(1+I$26) -> -6.9597656 | J23: =I23*(1+J$26) -> -7.2033574 | K23: =J23*(1+K$26) -> -7.4194581 | L23: =K23*(1+L$26) -> -7.6234932 | M23: =L23*(1+M$26) -> -7.8140805
B24: Unlevered FCF | D24: =D20+D21+D22+D23 -> 453.93 | E24: =E20+E21+E22+E23 -> 404.02961 | F24: =F20+F21+F22+F23 -> 570.66275 | G24: =G20+G21+G22+G23 -> 669.76423 | H24: =H20+H21+H22+H23 -> 774.80818 | I24: =I20+I21+I22+I23 -> 805.80051 | J24: =J20+J21+J22+J23 -> 834.00353 | K24: =K20+K21+K22+K23 -> 859.02363 | ... M24: =M20+M21+M22+M23 -> 904.71295 | N24: =M24*(1+$C$27) -> 927.33077
B25: Terminal Value (Gordon Growth) | N25: =N24/($C$13-$C$27) -> 19548.475
B26: Fade-period growth (2031E–35E) | I26: 0.04 | J26: 0.035 | K26: 0.03 | L26: 0.0275 | M26: 0.025
B27: Terminal growth rate | C27: 0.025
B29: Discount period (years) | D29: =(DATE(2026,12,31)-$C$15)/365.25 -> 0.24640657 | E29: =(DATE(2027,12,31)-$C$15)/365.25 -> 1.2457221 | F29: =(DATE(2028,12,31)-$C$15)/365.25 -> 2.2477755 | G29: =(DATE(2029,12,31)-$C$15)/365.25 -> 3.247091 | H29: =(DATE(2030,12,31)-$C$15)/365.25 -> 4.2464066 | I29: =(DATE(2031,12,31)-$C$15)/365.25 -> 5.2457221 | J29: =(DATE(2032,12,31)-$C$15)/365.25 -> 6.2477755 | K29: =(DATE(2033,12,31)-$C$15)/365.25 -> 7.247091 | L29: =(DATE(2034,12,31)-$C$15)/365.25 -> 8.2464066 | M29: =(DATE(2035,12,31)-$C$15)/365.25 -> 9.2457221 | N29: =M29 -> 9.2457221
B30: Discount factor | D30: =1/(1+$C$13)^D29 -> 0.9829154 | E30: =1/(1+$C$13)^E29 -> 0.91656852 | F30: =1/(1+$C$13)^F29 -> 0.85453643 | G30: =1/(1+$C$13)^G29 -> 0.79685514 | H30: =1/(1+$C$13)^H29 -> 0.74306734 | I30: =1/(1+$C$13)^I29 -> 0.69291023 | J30: =1/(1+$C$13)^J29 -> 0.64601502 | K30: =1/(1+$C$13)^K29 -> 0.60240895 | ... N30: =1/(1+$C$13)^N29 -> 0.52382836
B31: PV of UFCF | D31: =D24*D30 -> 446.17479 | E31: =E24*E30 -> 370.32082 | F31: =F24*F30 -> 487.65211 | G31: =G24*G30 -> 533.70507 | H31: =H24*H30 -> 575.73466 | I31: =I24*I30 -> 558.34741 | J31: =J24*J30 -> 538.7788 | K31: =K24*K30 -> 517.48352 | ... M31: =M24*M30 -> 473.9143 | N31: =N25*N30 -> 10240.045
D32: Pension: HII carries a net pension asset (Model BS); CAS pension recovery is embedded in segment OI and the non-cash FAS income is excluded from UFCF — no pension adjustment to net debt.
B34: 3. VALUATION SUMMARY
B35: Sum of PV (explicit + fade) | C35: =SUM(D31:M31) -> 4997.935
B36: PV of Terminal Value | C36: =N31 -> 10240.045
B37: Enterprise Value | C37: =C35+C36 -> 15237.981
B38: Less: Net debt (Model 2026E YE) | C38: =Model!BV324 -> 1638.764
B39: Equity Value | C39: =C37-C38 -> 13599.217
B40: Diluted shares (m, Model 2026E) | C40: =Model!BV137 -> 39.45
B41: Implied share price ($) | C41: =C39/C40 -> 344.72032
B42: Current share price ($) | C42: =Model!BV350 -> 275
B43: Implied upside / (downside) | C43: =C41/C42-1 -> 0.25352843
B46: 4. SENSITIVITY: IMPLIED PRICE ($) — WACC × Terminal Growth
B48: WACC (across):
...

Sheet Charts
B2: HII — Historical Operating Performance (2015–2025)
B3: All historicals · USDm · Linked to Model. M&A % reflects disclosed acquired revenue only (Camber FY2017, Alion FY2021).
C7: 2015 | D7: 2016 | E7: 2017 | F7: 2018 | G7: 2019 | H7: 2020 | I7: 2021 | J7: 2022 | K7: 2023 | L7: 2024 | M7: 2025
B8: Organic % | C8: =0 -> 0 | D8: =IFERROR(Model!N172+0,0) -> 0.0068376068 | E8: =IFERROR(Model!T172+0,0) -> 0.0090548953 | F8: =IFERROR(Model!Z172+0,0) -> 0.098777046 | G8: =IFERROR(Model!AF172+0,0) -> 0.08842955 | H8: =IFERROR(Model!AL172+0,0) -> 0.051915946 | I8: =IFERROR(Model!AR172+0,0) -> -0.036641384 | J8: =IFERROR(Model!AX172+0,0) -> 0.12095758 | K8: =IFERROR(Model!BD172+0,0) -> 0.072873735 | L8: =IFERROR(Model!BJ172+0,0) -> 0.0070717653 | M8: =IFERROR(Model!BP172+0,0) -> 0.082271348
B9: M&A % | C9: =0 -> 0 | D9: =IFERROR(Model!N173+0,0) -> 0 | E9: =IFERROR(Model!T173+0,0) -> 0.043718166 | F9: =IFERROR(Model!Z173+0,0) -> 0 | G9: =IFERROR(Model!AF173+0,0) -> 0 | H9: =IFERROR(Model!AL173+0,0) -> 0 | I9: =IFERROR(Model!AR173+0,0) -> 0.054054054 | J9: =IFERROR(Model!AX173+0,0) -> 0 | K9: =IFERROR(Model!BD173+0,0) -> 0 | L9: =IFERROR(Model!BJ173+0,0) -> 0 | M9: =IFERROR(Model!BP173+0,0) -> 0
C11: =C7 -> 2015 | D11: =D7 -> 2016 | E11: =E7 -> 2017 | F11: =F7 -> 2018 | G11: =G7 -> 2019 | H11: =H7 -> 2020 | I11: =I7 -> 2021 | J11: =J7 -> 2022 | ... M11: =M7 -> 2025
