Workbook

Sheet Model
CF1: SCENARIO SWITCH ▼ (Bull / Base / Bear) — drives all scenario-linked forecast drivers
B2: Lincoln Electric Holdings, Inc. (Nasdaq: LECO) — 3-Statement Financial Model | CF2: Base
B3: US GAAP as reported · USD millions (per-share data in USD; shares in millions) · Source: Lincoln Electric Forms 10-K / 10-Q and Form 8-K earnings releases (Ex. 99.1), segment-recast 8-K (10-Feb-2016), SEC EDGAR CIK 0000059527 (investor-relations releases are the same documents as filed on EDGAR); XBRL company facts used to cross-check totals
B4: Basis notes: calendar fiscal year. Three reportable segments (Americas Welding, International Welding, The Harris Products Group) from Q1/16, recast for FY2013 and 2014–15 quarters (no 2013 quarterly recast); five legacy segments (North America / Europe / Asia Pacific / South America Welding + Harris) 2009–2015 and North America / Europe / Other Countries 2006–2008 shown as memo. Per-share data 2006–2010 restated for the 2-for-1 split (May-2011). Venezuela deconsolidated Q4/15. Adjusted measures = company definitions (special items: rationalization & asset impairments, acquisition costs & inventory step-up, pension settlements, Venezuela, disposal gains, discrete tax items). FY26 outlook per the Q2-26 call (30-Jul-2026).
CH5: Forecast | CI5: Historical | CJ5: Historical | CK5: Historical
B6: (USDm) | C6: 2006 | D6: 2007 | E6: 2008 | F6: 2009 | G6: 2010 | H6: 2011 | I6: 2012 | J6: Q1/13 | K6: Q2/13 | L6: Q3/13 | M6: Q4/13 | N6: 2013 | O6: Q1/14 | P6: Q2/14 | Q6: Q3/14 | R6: Q4/14 | S6: 2014 | T6: Q1/15 | U6: Q2/15 | V6: Q3/15 | W6: Q4/15 | X6: 2015 | Y6: Q1/16 | Z6: Q2/16 | AA6: Q3/16 | AB6: Q4/16 | AC6: 2016 | AD6: Q1/17 | AE6: Q2/17 | AF6: Q3/17 | AG6: Q4/17 | AH6: 2017 | AI6: Q1/18 | AJ6: Q2/18 | AK6: Q3/18 | AL6: Q4/18 | AM6: 2018 | AN6: Q1/19 | AO6: Q2/19 | AP6: Q3/19 | AQ6: Q4/19 | AR6: 2019 | AS6: Q1/20 | AT6: Q2/20 | AU6: Q3/20 | AV6: Q4/20 | AW6: 2020 | AX6: Q1/21 | AY6: Q2/21 | AZ6: Q3/21 | BA6: Q4/21 | BB6: 2021 | BC6: Q1/22 | BD6: Q2/22 | BE6: Q3/22 | BF6: Q4/22 | BG6: 2022 | BH6: Q1/23 | BI6: Q2/23 | BJ6: Q3/23 | BK6: Q4/23 | BL6: 2023 | BM6: Q1/24 | BN6: Q2/24 | BO6: Q3/24 | BP6: Q4/24 | BQ6: 2024 | BR6: Q1/25 | BS6: Q2/25 | BT6: Q3/25 | BU6: Q4/25 | BV6: 2025 | BW6: Q1/26 | BX6: Q2/26 | BY6: Q3/26E | BZ6: Q4/26E | CA6: 2026E | CB6: 2027E | CC6: 2028E | CD6: 2029E | CE6: 2030E | CF6: Modelling Notes | CH6: 5Y CAGR | CI6: 5Y CAGR | CJ6: 10Y CAGR | CK6: 19Y CAGR
CH7: 25-'30 | CI7: 20-'25 | CJ7: 15-'25 | CK7: 06-'25
B8: SEGMENT P&L — AMERICAS WELDING · INTERNATIONAL WELDING · THE HARRIS PRODUCTS GROUP (volume × price × acquisitions × FX build) | CF8: SEGMENT BUILD — modelling logic (prior-year net sales × (1 + volume + price + acquisitions + FX) → total segment sales × adjusted EBIT margin → group adjusted EBIT)
CN9: SCENARIO INPUT TABLE — driver assumptions per Bull / Base / Bear | CO9: Bull | CP9: Base | CQ9: Bear | CR9: Bull / Bear = Base + Δ (Δ inputs on each lever header). Outlook block = high / mid / low end of the FY26 ranges.
B10: Americas Welding (arc-welding equipment, consumables, automation & cutting — North and South America) | CF10: AMERICAS WELDING — modelling logic
B11: Net sales (external customers) | N11: 1848.663 | O11: 441.849 | P11: 465.524 | Q11: 469.39 | R11: 460.907 | S11: 1837.67 | T11: 448.837 | U11: 451.001 | V11: 454.172 | W11: 387.34 | X11: 1741.35 | Y11: 359.008 | Z11: 388.372 | AA11: 377.52 | AB11: 370.082 | AC11: 1494.982 | AD11: 383.324 | AE11: 405.147 | AF11: 398.289 | AG11: 423.019 | AH11: 1609.779 | AI11: 434.772 | AJ11: 462.515 | AK11: 454.01 | AL11: 455.217 | AM11: 1806.514 | AN11: 457.719 | AO11: 476.607 | AP11: 443.521 | AQ11: 437.899 | AR11: 1815.746 | AS11: 418.535 | AT11: 333.229 | AU11: 371.535 | AV11: 386.571 | AW11: 1509.87 | AX11: 425.242 | AY11: 457.468 | AZ11: 461.508 | BA11: 480.263 | BB11: 1824.481 | BC11: 534.055 | BD11: 595.659 | BE11: 585.628 | BF11: 573.592 | BG11: 2288.934 | BH11: 658.645 | BI11: 676.966 | BJ11: 665.228 | BK11: 654.707 | BL11: 2655.546 | BM11: 624.099 | BN11: 648.936 | BO11: 637.026 | BP11: 654.786 | BQ11: 2564.847 | BR11: 653.107 | BS11: 696.73 | BT11: 691.794 | BU11: 681.93 | BV11: 2723.561 | BW11: 706.225 | BX11: 774.438 | BY11: =BT11*(1+BY12) -> 774.64165 | BZ11: =BU11*(1+BZ12) -> 763.59636 | CA11: =SUM(BW11,BX11,BY11,BZ11) -> 3018.901 | CB11: =CA11*(1+CB12) -> 3200.0351 | CC11: =CB11*(1+CC12) -> 3376.037 | CD11: =CC11*(1+CD12) -> 3544.8389 | CE11: =CD11*(1+CE12) -> 3722.0808 | CF11: Historical: segment table of the earnings release (current 3-segment basis from FY2013 / Q1-14, per the Feb-2016 recast 8-K). Q3/Q4-26E: prior-year quarter × (1 + volume + price + acquisitions + FX). 2027E+: prior year × (1 + scenario levers AW_vol + AW_price (+ FX)). | CH11: =IFERROR((CE11/BV11)^(1/5)-1,"n/m") -> 0.06446096 | CI11: =IFERROR((BV11/AW11)^(1/5)-1,"n/m") -> 0.12522536 | CJ11: =IFERROR((BV11/X11)^(1/10)-1,"n/m") -> 0.045743331 | CK11: =IFERROR((BV11/C11)^(1/19)-1,"n/m") -> n/m | CN11: FY26 outlook — Q2-26 earnings call (30-Jul-26); company assumptions | CO11: High | CP11: Mid | CQ11: Low | CR11: Lincoln Electric gives qualitative / range outlook on its earnings call (not in the 8-K). Captured from call coverage; IR site & slides not reachable from this environment — verify against the Q2-26 presentation.
B12: Net sales y/y % | S12: =IF(AND(ISNUMBER(S11),ISNUMBER(N11)),IFERROR(S11/N11-1,""),"") -> -0.0059464597 | T12: =IF(AND(ISNUMBER(T11),ISNUMBER(O11)),IFERROR(T11/O11-1,""),"") -> 0.015815358 | U12: =IF(AND(ISNUMBER(U11),ISNUMBER(P11)),IFERROR(U11/P11-1,""),"") -> -0.031197103 | V12: =IF(AND(ISNUMBER(V11),ISNUMBER(Q11)),IFERROR(V11/Q11-1,""),"") -> -0.032420801 | W12: =IF(AND(ISNUMBER(W11),ISNUMBER(R11)),IFERROR(W11/R11-1,""),"") -> -0.15961354 | X12: =IF(AND(ISNUMBER(X11),ISNUMBER(S11)),IFERROR(X11/S11-1,""),"") -> -0.052414198 | Y12: =IF(AND(ISNUMBER(Y11),ISNUMBER(T11)),IFERROR(Y11/T11-1,""),"") -> -0.20013724 | Z12: =IF(AND(ISNUMBER(Z11),ISNUMBER(U11)),IFERROR(Z11/U11-1,""),"") -> -0.13886665 | ... BX12: =IF(AND(ISNUMBER(BX11),ISNUMBER(BS11)),IFERROR(BX11/BS11-1,""),"") -> 0.11153244 | BY12: =BY13+BY14+BY15+BY16 -> 0.11975769 | BZ12: =BZ13+BZ14+BZ15+BZ16 -> 0.11975769 | CA12: =IFERROR(CA11/BV11-1,"") -> 0.10843892 | CB12: =CB13+CB14+CB15+CB16 -> 0.06 | CC12: =CC13+CC14+CC15+CC16 -> 0.055 | CD12: =CD13+CD14+CD15+CD16 -> 0.05 | CE12: =CE13+CE14+CE15+CE16 -> 0.05 | CN12: FY26 net sales growth — "low double-digit %" | CO12: 0.13 | CP12: 0.115 | CQ12: 0.1 | CR12: Raised on the Q2-26 call to low double-digit (from mid-to-high single digit). 1H/26 +11.9%. Drives the Q3/Q4-26E volume calibration.
B13: Volume % (company "change in net sales due to volume") | Y13: -0.19 | Z13: -0.133 | AA13: -0.179 | AB13: -0.058 | AC13: -0.143 | AD13: 0.041 | AE13: 0.017 | AF13: 0.022 | AG13: 0.101 | AH13: 0.045 | AI13: 0.075 | AJ13: 0.077 | AK13: 0.058 | AL13: -0.001 | AM13: 0.051 | AN13: -0.029 | AO13: -0.036 | AP13: -0.045 | AQ13: -0.065 | AR13: -0.044 | AS13: -0.082 | AT13: -0.292 | AU13: -0.156 | AV13: -0.124 | AW13: -0.165 | AX13: -0.009 | AY13: 0.271 | AZ13: 0.114 | BA13: 0.093 | BB13: 0.109 | BC13: 0.052 | BD13: 0.099 | BE13: 0.114 | BF13: 0.077 | BG13: 0.086 | BH13: 0.11 | BI13: 0.058 | BJ13: 0.004 | BK13: 0.026 | BL13: 0.048 | BM13: -0.065 | BN13: -0.067 | BO13: -0.086 | BP13: -0.072 | BQ13: -0.072 | BR13: -0.04 | BS13: -0.034 | BT13: -0.024 | BU13: -0.069 | BV13: -0.042 | BW13: -0.004 | BX13: 0.071 | BY13: =$BX$13+BY139 -> 0.082757692 | BZ13: =$BX$13+BZ139 -> 0.082757692 | CA13: =IFERROR(CA18/BV11,"") -> 0.059023913 | CB13: =CHOOSE(MATCH($CF$2,{"Bull","Base","Bear"},0),$CO$23,$CP$23,$CQ$23) -> 0.03 | CC13: =CHOOSE(MATCH($CF$2,{"Bull","Base","Bear"},0),$CO$24,$CP$24,$CQ$24) -> 0.03 | CD13: =CHOOSE(MATCH($CF$2,{"Bull","Base","Bear"},0),$CO$25,$CP$25,$CQ$25) -> 0.025 | CE13: =CHOOSE(MATCH($CF$2,{"Bull","Base","Bear"},0),$CO$26,$CP$26,$CQ$26) -> 0.025 | CF13: Q3/Q4-26E: Q2/26 y/y volume + outlook calibration Δ (Group block). 2027E–2030E: scenario lever AW_vol (Bull/Base/Bear table →). | CN13: FY26 organic sales growth — "high single-digit to low double-digit" (memo) | CO13: 0.11 | CP13: 0.095 | CQ13: 0.08 | CR13: ~1/3 volume, ~2/3 price per management. Memo / cross-check only.
B14: Price % | Y14: 0.179 | Z14: 0.43 | AA14: -0.012 | AB14: 0 | AC14: 0.154 | AD14: 0.015 | AE14: 0.027 | AF14: 0.024 | AG14: 0.029 | AH14: 0.024 | AI14: 0.046 | AJ14: 0.054 | AK14: 0.091 | AL14: 0.083 | AM14: 0.069 | AN14: 0.063 | AO14: 0.025 | AP14: -0.012 | AQ14: -0.017 | AR14: 0.014 | AS14: -0.012 | AT14: -0.003 | AU14: -0.002 | AV14: 0.012 | AW14: -0.001 | AX14: 0.022 | AY14: 0.082 | AZ14: 0.118 | BA14: 0.146 | BB14: 0.091 | BC14: 0.198 | BD14: 0.196 | BE14: 0.151 | BF14: 0.114 | BG14: 0.164 | BH14: 0.046 | BI14: 0.01 | BJ14: 0.006 | BK14: 0.005 | BL14: 0.016 | BM14: 0.003 | BN14: 0.01 | BO14: 0.004 | BP14: -0.001 | BQ14: 0.004 | BR14: 0.021 | BS14: 0.065 | BT14: 0.096 | BU14: 0.104 | BV14: 0.072 | BW14: 0.076 | BX14: 0.037 | BY14: =$BX$14 -> 0.037 | BZ14: =$BX$14 -> 0.037 | CA14: =IFERROR(CA19/BV11,"") -> 0.046258479 | CB14: =CHOOSE(MATCH($CF$2,{"Bull","Base","Bear"},0),$CO$28,$CP$28,$CQ$28) -> 0.03 | CC14: =CHOOSE(MATCH($CF$2,{"Bull","Base","Bear"},0),$CO$29,$CP$29,$CQ$29) -> 0.025 | CD14: =CHOOSE(MATCH($CF$2,{"Bull","Base","Bear"},0),$CO$30,$CP$30,$CQ$30) -> 0.025 | CE14: =CHOOSE(MATCH($CF$2,{"Bull","Base","Bear"},0),$CO$31,$CP$31,$CQ$31) -> 0.025 | CF14: Q3/Q4-26E: Q2/26 y/y price held (carry-over of the 2025–26 increases; HPG includes metals pass-through). 2027E+: scenario lever. Note: 2016 Americas Welding as published includes Venezuela hyperinflationary price (+15.4%) offset by FX (−17.7%); ex-Venezuela price −0.5%, FX −1.0%. | CN14: 2H/26 incremental adjusted operating income margin — "mid-20%" | CO14: 0.275 | CP14: 0.25 | CQ14: 0.225 | CR14: Q2-26 call: adjusted operating margin to improve y/y at mid-20% incrementals in 2H; price/cost neutral in 2H. Drives the Q3/Q4-26E margin calibration.
B15: Acquisitions % | Y15: 0.016 | Z15: 0.036 | AA15: 0.027 | AB15: 0.019 | AC15: 0.025 | AD15: 0.009 | AE15: 0.003 | AF15: 0.003 | AG15: 0.007 | AH15: 0.006 | AI15: 0.009 | AJ15: 0.01 | AK15: 0.003 | AL15: 0.007 | AM15: 0.007 | AN15: 0.029 | AO15: 0.047 | AP15: 0.038 | AQ15: 0.043 | AR15: 0.039 | AS15: 0.014 | AT15: 0 | AU15: 0 | AV15: 0 | AW15: 0.003 | AX15: 0 | AY15: 0 | AZ15: 0 | BA15: 0 | BB15: 0 | BC15: 0.004 | BD15: 0.012 | BE15: 0.01 | BF15: 0.012 | BG15: 0.01 | BH15: 0.085 | BI15: 0.074 | BJ15: 0.123 | BK15: 0.107 | BL15: 0.097 | BM15: 0.006 | BN15: 0.018 | BO15: 0.045 | BP15: 0.083 | BQ15: 0.038 | BR15: 0.076 | BS15: 0.047 | BT15: 0.014 | BU15: 0 | BV15: 0.034 | BW15: 0 | BX15: 0 | BY15: 0 | BZ15: 0 | CA15: =IFERROR(CA20/BV11,"") -> 0 | CB15: 0 | CC15: 0 | CD15: 0 | CE15: 0 | CF15: No Americas Welding acquisitions in the last 12 months (Vanair Jul-24 and RedViking Apr-24 fully anniversaried). 2027E+: future deals in the M&A lever. | CN15: FY26 interest expense, net ($m) | CO15: 50 | CP15: 52.5 | CQ15: 55 | CR15: Company assumption $50–55m (maintained on the Q2-26 call).
B16: Foreign exchange % | Y16: -0.205 | Z16: -0.472 | AA16: -0.004 | AB16: -0.005 | AC16: -0.177 | AD16: 0.002 | AE16: -0.005 | AF16: 0.005 | AG16: 0.006 | AH16: 0.002 | AI16: 0.004 | AJ16: 0.001 | AK16: -0.012 | AL16: -0.013 | AM16: -0.005 | AN16: -0.011 | AO16: -0.005 | AP16: -0.004 | AQ16: 0.001 | AR16: -0.005 | AS16: -0.005 | AT16: -0.006 | AU16: -0.005 | AV16: -0.005 | AW16: -0.005 | AX16: 0.003 | AY16: 0.02 | AZ16: 0.01 | BA16: 0.003 | BB16: 0.009 | BC16: 0.002 | BD16: -0.005 | BE16: -0.007 | BF16: -0.009 | BG16: -0.005 | BH16: -0.008 | BI16: -0.005 | BJ16: 0.003 | BK16: 0.004 | BL16: -0.001 | BM16: 0.003 | BN16: -0.002 | BO16: -0.005 | BP16: -0.01 | BQ16: -0.004 | BR16: -0.011 | BS16: -0.004 | BT16: 0 | BU16: 0.006 | BV16: -0.002 | BW16: 0.009 | BX16: 0.004 | BY16: 0 | BZ16: 0 | CA16: =IFERROR(CA21/BV11,"") -> 0.0031565293 | CB16: 0 | CC16: 0 | CD16: 0 | CE16: 0 | CF16: Q3/Q4-26E: FX input (spot-rate translation vs prior-year quarter). 2027E+: International Welding FX lever; Americas & Harris 0%. | CN16: FY26 effective tax rate — "low-to-mid 20%" | CO16: 0.22 | CP16: 0.23 | CQ16: 0.24 | CR16: Company assumption (adjusted ETR). 1H/26 22.7% adjusted.
B17: Organic growth % (volume + price) | Y17: =Y13+Y14 -> -0.011 | Z17: =Z13+Z14 -> 0.297 | AA17: =AA13+AA14 -> -0.191 | AB17: =AB13+AB14 -> -0.058 | AC17: =AC13+AC14 -> 0.011 | AD17: =AD13+AD14 -> 0.056 | AE17: =AE13+AE14 -> 0.044 | AF17: =AF13+AF14 -> 0.046 | ... CE17: =CE13+CE14 -> 0.05 | CN17: FY26 capital expenditures ($m) | CO17: 130 | CP17: 120 | CQ17: 110 | CR17: Company assumption $110–130m.
B18: Δ Net sales — volume ($) | Y18: -85.063 | Z18: -59.999 | AA18: -81.338 | AB18: -22.315 | AC18: -248.715 | AD18: 14.761 | AE18: 6.766 | AF18: 8.401 | AG18: 37.378 | AH18: 67.306 | AI18: 28.562 | AJ18: 31.023 | AK18: 23.084 | AL18: -0.411 | AM18: 82.258 | AN18: -12.395 | AO18: -16.756 | AP18: -20.605 | AQ18: -29.529 | AR18: -79.285 | AS18: -37.692 | AT18: -139.035 | AU18: -69.028 | AV18: -54.412 | AW18: -300.167 | AX18: -3.79 | AY18: 90.285 | AZ18: 42.341 | BA18: 35.759 | BB18: 164.595 | BC18: 22.004 | BD18: 45.284 | BE18: 52.521 | BF18: 36.752 | BG18: 156.561 | BH18: 58.65 | BI18: 34.384 | BJ18: 2.072 | BK18: 14.754 | BL18: 109.86 | BM18: -42.653 | BN18: -45.665 | BO18: -57.292 | BP18: -46.844 | BQ18: -192.454 | BR18: -24.74 | BS18: -22.346 | BT18: -15.011 | BU18: -45.383 | BV18: -107.48 | BW18: -2.635 | BX18: 49.704 | BY18: =BT11*BY13 -> 57.251275 | BZ18: =BU11*BZ13 -> 56.434953 | CA18: =SUM(BW18,BX18,BY18,BZ18) -> 160.75523 | CB18: =CA11*CB13 -> 90.56703 | CC18: =CB11*CC13 -> 96.001052 | CD18: =CC11*CD13 -> 84.400925 | CE18: =CD11*CE13 -> 88.620971 | CN18: FY26 cash conversion (FCF / adjusted net income; memo) | CO18: 1 | CP18: 1 | CQ18: 1 | CR18: Company target ~100% cash conversion.
B19: Δ Net sales — price ($) | Y19: 80.32 | Z19: 193.706 | AA19: -5.645 | AB19: -0.176 | AC19: 268.205 | AD19: 5.52 | AE19: 10.508 | AF19: 9.197 | AG19: 10.784 | AH19: 36.009 | AI19: 17.682 | AJ19: 21.958 | AK19: 36.128 | AL19: 35.27 | AM19: 111.038 | AN19: 27.428 | AO19: 11.599 | AP19: -5.603 | AQ19: -7.719 | AR19: 25.705 | AS19: -5.392 | AT19: -1.405 | AU19: -0.682 | AV19: 5.164 | AW19: -2.315 | AX19: 9.065 | AY19: 27.33 | AZ19: 43.957 | BA19: 56.615 | BB19: 136.967 | BC19: 84.218 | BD19: 89.854 | BE19: 69.888 | BF19: 54.968 | BG19: 298.928 | BH19: 24.699 | BI19: 5.974 | BJ19: 3.488 | BK19: 2.964 | BL19: 37.125 | BM19: 2.284 | BN19: 6.522 | BO19: 2.505 | BP19: -0.541 | BQ19: 10.77 | BR19: 13.369 | BS19: 42.265 | BT19: 60.885 | BU19: 67.964 | BV19: 184.483 | BW19: 49.479 | BX19: 25.681 | BY19: =BT11*BY14 -> 25.596378 | BZ19: =BU11*BZ14 -> 25.23141 | CA19: =SUM(BW19,BX19,BY19,BZ19) -> 125.98779 | CB19: =CA11*CB14 -> 90.56703 | CC19: =CB11*CC14 -> 80.000877 | CD19: =CC11*CD14 -> 84.400925 | CE19: =CD11*CE14 -> 88.620971 | CN19: Capital returns | CO19: Bull | CP19: Base | CQ19: Bear
B20: Δ Net sales — acquisitions ($) | Y20: 6.977 | Z20: 16.323 | AA20: 12.3 | AB20: 7.232 | AC20: 42.832 | AD20: 3.338 | AE20: 1.354 | AF20: 1.14 | AG20: 2.638 | AH20: 8.47 | AI20: 3.606 | AJ20: 4.059 | AK20: 1.148 | AL20: 2.831 | AM20: 11.644 | AN20: 12.72 | AO20: 21.512 | AP20: 17.38 | AQ20: 19.45 | AR20: 71.062 | AS20: 6.19 | AT20: 0 | AU20: 0 | AV20: 0 | AW20: 6.19 | AX20: 0 | AY20: 0 | AZ20: 0 | BA20: 0 | BB20: 0 | BC20: 1.745 | BD20: 5.437 | BE20: 4.724 | BF20: 5.696 | BG20: 17.602 | BH20: 45.249 | BI20: 43.947 | BJ20: 72.159 | BK20: 61.138 | BL20: 222.493 | BM20: 4.164 | BN20: 12.42 | BO20: 30.212 | BP20: 54.301 | BQ20: 101.097 | BR20: 47.327 | BS20: 30.192 | BT20: 8.842 | BU20: 0 | BV20: 86.361 | BW20: 0 | BX20: 0 | BY20: =BT11*BY15 -> 0 | BZ20: =BU11*BZ15 -> 0 | CA20: =SUM(BW20,BX20,BY20,BZ20) -> 0 | CB20: =CA11*CB15 -> 0 | CC20: =CB11*CC15 -> 0 | CD20: =CC11*CD15 -> 0 | CE20: =CD11*CE15 -> 0 | CN20: 2H/26 share repurchases ($m) | CO20: 160 | CP20: 130 | CQ20: 100 | CR20: 1H/26 repurchases $133m (Q1 $57m, Q2 $76m). Base keeps the 1H pace.
B21: Δ Net sales — foreign exchange ($) | Y21: -92.063 | Z21: -212.659 | AA21: -1.969 | AB21: -1.999 | AC21: -308.69 | AD21: 0.697 | AE21: -1.853 | AF21: 2.031 | AG21: 2.137 | AH21: 3.012 | AI21: 1.598 | AJ21: 0.328 | AK21: -4.639 | AL21: -5.492 | AM21: -8.205 | AN21: -4.806 | AO21: -2.263 | AP21: -1.661 | AQ21: 0.48 | AR21: -8.25 | AS21: -2.29 | AT21: -2.938 | AU21: -2.276 | AV21: -2.08 | AW21: -9.584 | AX21: 1.432 | AY21: 6.624 | AZ21: 3.675 | BA21: 1.318 | BB21: 13.049 | BC21: 0.846 | BD21: -2.384 | BE21: -3.013 | BF21: -4.087 | BG21: -8.638 | BH21: -4.008 | BI21: -2.998 | BJ21: 1.881 | BK21: 2.259 | BL21: -2.866 | BM21: 1.659 | BN21: -1.307 | BO21: -3.627 | BP21: -6.837 | BQ21: -10.112 | BR21: -6.948 | BS21: -2.317 | BT21: 0.052 | BU21: 4.563 | BV21: -4.65 | BW21: 6.274 | BX21: 2.323 | BY21: =BT11*BY16 -> 0 | BZ21: =BU11*BZ16 -> 0 | CA21: =SUM(BW21,BX21,BY21,BZ21) -> 8.597 | CB21: =CA11*CB16 -> 0 | CC21: =CB11*CC16 -> 0 | CD21: =CC11*CD16 -> 0 | CE21: =CD11*CE16 -> 0 | CN21: Minimum net debt / Adjusted EBITDA (x) — buyback floor 2027E+ | CO21: 1.25 | CP21: 1 | CQ21: 0.75 | CR21: LECO runs ~0.5–1.0x net leverage; surplus cash above the floor is returned through repurchases.
B22: Inter-segment sales | N22: 105.811 | O22: 28.217 | P22: 28.989 | Q22: 27.244 | R22: 26.074 | S22: 110.524 | T22: 23.023 | U22: 23.902 | V22: 25.571 | W22: 20.042 | X22: 92.538 | Y22: 23.831 | Z22: 23.456 | AA22: 22.386 | AB22: 23.939 | AC22: 93.612 | AD22: 22.46 | AE22: 27.374 | AF22: 25.546 | AG22: 22.002 | AH22: 97.382 | AI22: 26.586 | AJ22: 31.24 | AK22: 31.845 | AL22: 29.265 | AM22: 118.936 | AN22: 29.388 | AO22: 34.811 | AP22: 31.101 | AQ22: 28.042 | AR22: 123.342 | AS22: 24.783 | AT22: 27.493 | AU22: 29.368 | AV22: 27.734 | AW22: 109.378 | AX22: 32.748 | AY22: 39.765 | AZ22: 37.48 | BA22: 30.657 | BB22: 140.65 | BC22: 28.156 | BD22: 29.031 | BE22: 35.353 | BF22: 29.479 | BG22: 122.019 | BH22: 32.318 | BI22: 30.85 | BJ22: 28.875 | BK22: 35.493 | BL22: 127.536 | BM22: 29.978 | BN22: 37.8 | BO22: 30.845 | BP22: 37.134 | BQ22: 135.758 | BR22: 30.372 | BS22: 43.391 | BT22: 30.058 | BU22: 25.101 | BV22: 128.922 | BW22: 36.709 | BX22: 28.904 | BY22: =BY11*BT22/BT11 -> 33.657677 | BZ22: =BZ11*BU22/BU11 -> 28.107038 | CA22: =SUM(BW22,BX22,BY22,BZ22) -> 127.37771 | CB22: =CB11*CA22/CA11 -> 135.02038 | CC22: =CC11*CB22/CB11 -> 142.4465 | CD22: =CD11*CC22/CC11 -> 149.56882 | CE22: =CE11*CD22/CD11 -> 157.04726 | CF22: Forecast: prior-year inter-segment sales ratio to external net sales. | CN22: AW_vol (Americas Welding volume y/y) | CO22: 0.02 | CP22: Δ → | CQ22: -0.02 | CR22: Americas industrial capex, fabrication & automation demand; volume inflected +7.1% in Q2/26 after nine quarters of declines (2025 −4.2%).
B23: Total segment sales (incl. inter-segment) | N23: =N11+N(N22) -> 1954.474 | O23: =O11+N(O22) -> 470.066 | P23: =P11+N(P22) -> 494.513 | Q23: =Q11+N(Q22) -> 496.634 | R23: =R11+N(R22) -> 486.981 | S23: =S11+N(S22) -> 1948.194 | T23: =T11+N(T22) -> 471.86 | U23: =U11+N(U22) -> 474.903 | ... BX23: =BX11+N(BX22) -> 803.342 | BY23: =BY11+BY22 -> 808.29933 | BZ23: =BZ11+BZ22 -> 791.7034 | CA23: =CA11+CA22 -> 3146.2787 | CB23: =CB11+CB22 -> 3335.0555 | CC23: =CC11+CC22 -> 3518.4835 | CD23: =CD11+CD22 -> 3694.4077 | CE23: =CE11+CE22 -> 3879.1281 | CN23: 2027E | CO23: =CP23+$CO$22 -> 0.05 | CP23: 0.03 | CQ23: =CP23+$CQ$22 -> 0.01
B24: Adjusted EBIT (segment profit, company definition) | N24: 377.436 | O24: 83.688 | P24: 95.941 | Q24: 84.026 | R24: 89.6 | S24: 353.255 | T24: 75.415 | U24: 79.421 | V24: 82.765 | W24: 79.088 | X24: 316.689 | Y24: 61.438 | Z24: 65.201 | AA24: 68.285 | AB24: 71.709 | AC24: 266.633 | AD24: 68.723 | AE24: 74.498 | AF24: 74.096 | AG24: 74.549 | AH24: 291.866 | AI24: 77.439 | AJ24: 88.158 | AK24: 89.253 | AL24: 85.894 | AM24: 340.744 | AN24: 81.752 | AO24: 84.851 | AP24: 74.11 | AQ24: 75.006 | AR24: 315.719 | AS24: 70.702 | AT24: 46.702 | AU24: 59.12 | AV24: 69.204 | AW24: 245.728 | AX24: 76.617 | AY24: 84.134 | AZ24: 84.557 | BA24: 83.708 | BB24: 329.016 | BC24: 111.568 | BD24: 118.067 | BE24: 118.804 | BF24: 114.38 | BG24: 462.819 | BH24: 132.453 | BI24: 139.87 | BJ24: 136.476 | BK24: 129.469 | BL24: 538.269 | BM24: 136.1 | BN24: 136.651 | BO24: 125.515 | BP24: 131.923 | BQ24: 530.188 | BR24: 124.198 | BS24: 137.915 | BT24: 131.615 | BU24: 141.111 | BV24: 534.839 | BW24: 127.468 | BX24: 158.095 | BY24: =BY23*BY26 -> 152.20207 | BZ24: =BZ23*BZ26 -> 162.73622 | CA24: =SUM(BW24,BX24,BY24,BZ24) -> 600.50129 | CB24: =CA24+CB30 -> 659.36986 | CC24: =CB24+CC30 -> 716.97049 | CD24: =CC24+CD30 -> 771.83109 | CE24: =CD24+CE30 -> 829.43472 | CF24: 2027E+: prior-year adjusted EBIT + Δ bridge (price $ × fall-through + volume $ × incremental margin + (acquisitions + FX) $ × prior-year margin). 2026E = sum of quarters. | CH24: =IFERROR((CE24/BV24)^(1/5)-1,"n/m") -> 0.091721413 | CI24: =IFERROR((BV24/AW24)^(1/5)-1,"n/m") -> 0.16829814 | CJ24: =IFERROR((BV24/X24)^(1/10)-1,"n/m") -> 0.053801977 | CK24: =IFERROR((BV24/C24)^(1/19)-1,"n/m") -> n/m | CN24: 2028E | CO24: =CP24+$CO$22 -> 0.05 | CP24: 0.03 | CQ24: =CP24+$CQ$22 -> 0.01
B25: Adjusted EBIT margin before outlook calibration % (Q3/Q4-26E helper) | BY25: =BT26+($BW$24+$BX$24)/($BW$23+$BX$23)-($BR$24+$BS$24)/($BR$23+$BS$23) -> 0.18288768 | BZ25: =BU26+($BW$24+$BX$24)/($BW$23+$BX$23)-($BR$24+$BS$24)/($BR$23+$BS$23) -> 0.20014054 | CF25: Q3/Q4-26E: prior-year quarter margin + (1H/26 − 1H/25 margin drift). | CN25: 2029E | CO25: =CP25+$CO$22 -> 0.045 | CP25: 0.025 | CQ25: =CP25+$CQ$22 -> 0.005
B26: Adjusted EBIT margin % (on total segment sales) | N26: =IF(AND(ISNUMBER(N24),ISNUMBER(N23)),IFERROR(N24/N23,""),"") -> 0.19311385 | O26: =IF(AND(ISNUMBER(O24),ISNUMBER(O23)),IFERROR(O24/O23,""),"") -> 0.17803457 | P26: =IF(AND(ISNUMBER(P24),ISNUMBER(P23)),IFERROR(P24/P23,""),"") -> 0.19401108 | Q26: =IF(AND(ISNUMBER(Q24),ISNUMBER(Q23)),IFERROR(Q24/Q23,""),"") -> 0.16919099 | R26: =IF(AND(ISNUMBER(R24),ISNUMBER(R23)),IFERROR(R24/R23,""),"") -> 0.18399075 | S26: =IF(AND(ISNUMBER(S24),ISNUMBER(S23)),IFERROR(S24/S23,""),"") -> 0.18132434 | T26: =IF(AND(ISNUMBER(T24),ISNUMBER(T23)),IFERROR(T24/T23,""),"") -> 0.15982495 | U26: =IF(AND(ISNUMBER(U24),ISNUMBER(U23)),IFERROR(U24/U23,""),"") -> 0.16723626 | ... BX26: =IF(AND(ISNUMBER(BX24),ISNUMBER(BX23)),IFERROR(BX24/BX23,""),"") -> 0.19679663 | BY26: =BY25+BY144 -> 0.18829914 | BZ26: =BZ25+BZ144 -> 0.205552 | CA26: =IFERROR(CA24/CA23,"") -> 0.1908608 | CB26: =IFERROR(CB24/CB23,"") -> 0.19770881 | CC26: =IFERROR(CC24/CC23,"") -> 0.20377259 | CD26: =IFERROR(CD24/CD23,"") -> 0.20891876 | CE26: =IFERROR(CE24/CE23,"") -> 0.21381989 | CF26: Q3/Q4-26E: margin before calibration + outlook calibration Δ. 2027E+: output of the Δ adjusted EBIT bridge. | CH26: =IFERROR(AVERAGE(CA26,CB26,CC26,CD26,CE26),"n/m") -> 0.20301617 | CI26: =IFERROR(AVERAGE(AW26,BB26,BG26,BL26,BQ26,BV26),"n/m") -> 0.18139591 | CJ26: =IFERROR(AVERAGE(X26,AC26,AH26,AM26,AR26,AW26,BB26,BG26,BL26,BQ26,BV26),"n/m") -> 0.17633248 | CK26: =IFERROR(AVERAGE(C26,D26,E26,F26,G26,H26,I26,N26,S26,X26,AC26,AH26,AM26,AR26,AW26,BB26,BG26,BL26,BQ26,BV26),"n/m") -> 0.17800735 | CN26: 2030E | CO26: =CP26+$CO$22 -> 0.045 | CP26: 0.025 | CQ26: =CP26+$CQ$22 -> 0.005
B27: Incremental adjusted EBIT margin (Δ adj. EBIT / Δ total sales) | S27: =IFERROR((S24-N24)/(S23-N23),"") -> 3.8504777 | T27: =IFERROR((T24-O24)/(T23-O23),"") -> -4.6114827 | U27: =IFERROR((U24-P24)/(U23-P23),"") -> 0.84242733 | V27: =IFERROR((V24-Q24)/(V23-Q23),"") -> 0.074655142 | W27: =IFERROR((W24-R24)/(W23-R23),"") -> 0.13206196 | X27: =IFERROR((X24-S24)/(X23-S23),"") -> 0.31989572 | Y27: =IFERROR((Y24-T24)/(Y23-T23),"") -> 0.1570079 | Z27: =IFERROR((Z24-U24)/(Z23-U23),"") -> 0.2254459 | ... CA27: =IFERROR((CA24-BV24)/(CA23-BV23),"") -> 0.22349639 | CB27: =IFERROR((CB24-CA24)/(CB23-CA23),"") -> 0.31184231 | CC27: =IFERROR((CC24-CB24)/(CC23-CB23),"") -> 0.31402303 | CD27: =IFERROR((CD24-CC24)/(CD23-CC23),"") -> 0.31184231 | CE27: =IFERROR((CE24-CD24)/(CE23-CD23),"") -> 0.31184231 | CN27: AW_price (Americas Welding price y/y) | CO27: 0.01 | CP27: Δ → | CQ27: -0.01 | CR27: Pricing to offset steel / tariff-driven inflation; 2025 +7.2%, 1H/26 +5.6%. Normalises to low-single-digit.
B28: Price fall-through to adjusted EBIT % | CB28: 0.3 | CC28: 0.3 | CD28: 0.3 | CE28: 0.3 | CF28: Input: share of price-driven sales growth that falls through to adjusted EBIT (price/cost broadly neutral — LECO prices to offset inflation; HPG price is largely metals pass-through). | CN28: 2027E | CO28: =CP28+$CO$27 -> 0.04 | CP28: 0.03 | CQ28: =CP28+$CQ$27 -> 0.02
B29: Volume incremental adjusted EBIT margin % | CB29: 0.35 | CC29: 0.35 | CD29: 0.35 | CE29: 0.35 | CF29: Input: incremental margin on volume-driven sales (company targets mid-20s–30s% incrementals through the cycle). | CN29: 2028E | CO29: =CP29+$CO$27 -> 0.035 | CP29: 0.025 | CQ29: =CP29+$CQ$27 -> 0.015
B30: Δ Adjusted EBIT (price × fall-through + volume × incremental + (acq. + FX) × prior margin) | CB30: =CB19*CB28+CB18*CB29+(CB20+CB21)*CA26 -> 58.86857 | CC30: =CC19*CC28+CC18*CC29+(CC20+CC21)*CB26 -> 57.600631 | CD30: =CD19*CD28+CD18*CD29+(CD20+CD21)*CC26 -> 54.860601 | CE30: =CE19*CE28+CE18*CE29+(CE20+CE21)*CD26 -> 57.603631 | CN30: 2029E | CO30: =CP30+$CO$27 -> 0.035 | CP30: 0.025 | CQ30: =CP30+$CQ$27 -> 0.015
B31: Special items (pre-tax, charged to the segment) | N31: 13.25 | O31: 17.618 | P31: 3.447 | Q31: 0.582 | R31: 0 | S31: 21.647 | T31: 0 | U31: 0 | V31: 166.178 | W31: 7.061 | X31: 173.239 | Y31: 0 | Z31: 0 | AA31: 0 | AB31: 0 | AC31: 0 | AD31: 0 | AE31: 0 | AF31: 5.283 | AG31: 3.959 | AH31: 9.242 | AI31: 0.758 | AJ31: 0 | AK31: 4.232 | AL31: 1.696 | AM31: 6.686 | AN31: 1.336 | AO31: 1.779 | AP31: 0 | AQ31: 0 | AR31: 3.115 | AS31: 1.19 | AT31: 26.007 | AU31: 7.044 | AV31: 0.748 | AW31: 34.989 | AX31: 4.44 | AY31: 1.65 | AZ31: 73.574 | BA31: 43.45 | BB31: 123.114 | BC31: -3.735 | BD31: 0.461 | BE31: -0.353 | BF31: 0.567 | BG31: -3.06 | BH31: 2.785 | BI31: 2.957 | BJ31: 4.056 | BK31: 0.06 | BL31: 9.858 | BM31: 0 | BN31: 0.354 | BO31: 23.357 | BP31: 4.11 | BQ31: 27.821 | BR31: 2.135 | BS31: 0.905 | BT31: 4.375 | BU31: 3.295 | BV31: 10.71 | BW31: 0.573 | BX31: 1.012 | CF31: Historical disclosure only; forecast special items are modelled at the consolidated level. | CN31: 2030E | CO31: =CP31+$CO$27 -> 0.035 | CP31: 0.025 | CQ31: =CP31+$CQ$27 -> 0.015
B32: EBIT (GAAP, as reported in the segment table) | N32: 364.186 | O32: 66.07 | P32: 92.494 | Q32: 83.444 | R32: 89.6 | S32: 331.608 | T32: 75.415 | U32: 79.421 | V32: -83.413 | W32: 72.027 | X32: 143.45 | Y32: 61.438 | Z32: 65.201 | AA32: 68.285 | AB32: 71.709 | AC32: 266.633 | AD32: 68.723 | AE32: 74.498 | AF32: 68.813 | AG32: 70.59 | AH32: 282.624 | AI32: 76.681 | AJ32: 88.158 | AK32: 85.021 | AL32: 84.198 | AM32: 334.058 | AN32: 80.416 | AO32: 83.072 | AP32: 74.11 | AQ32: 75.006 | AR32: 312.604 | AS32: 69.512 | AT32: 20.695 | AU32: 52.076 | AV32: 68.456 | AW32: 210.739 | AX32: 72.177 | AY32: 82.484 | AZ32: 10.983 | BA32: 40.258 | BB32: 205.902 | BC32: 115.303 | BD32: 117.606 | BE32: 119.157 | BF32: 113.813 | BG32: 465.879 | BH32: 129.668 | BI32: 136.913 | BJ32: 132.42 | BK32: 129.409 | BL32: 528.411 | BM32: 136.1 | BN32: 136.297 | BO32: 102.158 | BP32: 127.813 | BQ32: 502.367 | BR32: 122.063 | BS32: 137.01 | BT32: 127.24 | BU32: 137.816 | BV32: 524.129 | BW32: 126.895 | BX32: 157.083 | CN32: IW_vol (International Welding volume y/y) | CO32: 0.02 | CP32: Δ → | CQ32: -0.02 | CR32: Europe weak (2024–1H/26 volumes −4% to −10% p.a.); Asia Pacific improving. Base assumes a gradual recovery.
CN33: 2027E | CO33: =CP33+$CO$32 -> 0.04 | CP33: 0.02 | CQ33: =CP33+$CQ$32 -> 0
B34: International Welding (welding & cutting — Europe, Middle East, Africa, Asia Pacific) | CF34: INTERNATIONAL WELDING — modelling logic | CN34: 2028E | CO34: =CP34+$CO$32 -> 0.045 | CP34: 0.025 | CQ34: =CP34+$CQ$32 -> 0.005
B35: Net sales (external customers) | N35: 695.831 | O35: 170.742 | P35: 185.588 | Q35: 168.004 | R35: 157.09 | S35: 681.424 | T35: 139.247 | U35: 141.927 | V35: 128.072 | W35: 121.214 | X35: 530.46 | Y35: 124.305 | Z35: 132.815 | AA35: 119.564 | AB35: 130.605 | AC35: 507.289 | AD35: 128.888 | AE35: 141.498 | AF35: 197.617 | AG35: 256.021 | AH35: 724.024 | AI35: 247.32 | AJ35: 243.373 | AK35: 209.622 | AL35: 219.456 | AM35: 919.771 | AN35: 218.086 | AO35: 212.306 | AP35: 205.378 | AQ35: 218.606 | AR35: 854.376 | AS35: 197.923 | AT35: 177.167 | AU35: 196.937 | AV35: 214.782 | AW35: 786.809 | AX35: 223.079 | AY35: 252.352 | AZ35: 227.165 | BA35: 245.529 | BB35: 948.125 | BC35: 258.041 | BD35: 236.629 | BE35: 216.497 | BF35: 243.114 | BG35: 954.281 | BH35: 252.416 | BI35: 253.403 | BJ35: 242.01 | BK35: 292.177 | BL35: 1040.006 | BM35: 235.761 | BN35: 238.758 | BO35: 216.224 | BP35: 242.979 | BQ35: 933.722 | BR35: 219.061 | BS35: 232.824 | BT35: 219.629 | BU35: 259.351 | BV35: 930.865 | BW35: 227.035 | BX35: 243.292 | BY35: =BT35*(1+BY36) -> 220.8057 | BZ35: =BU35*(1+BZ36) -> 254.36049 | CA35: =SUM(BW35,BX35,BY35,BZ35) -> 945.49319 | CB35: =CA35*(1+CB36) -> 978.58545 | CC35: =CB35*(1+CC36) -> 1017.7289 | CD35: =CC35*(1+CD36) -> 1058.438 | CE35: =CD35*(1+CE36) -> 1100.7755 | CF35: Historical: segment table of the earnings release (current 3-segment basis from FY2013 / Q1-14, per the Feb-2016 recast 8-K). Q3/Q4-26E: prior-year quarter × (1 + volume + price + acquisitions + FX). 2027E+: prior year × (1 + scenario levers IW_vol + IW_price (+ FX)). | CH35: =IFERROR((CE35/BV35)^(1/5)-1,"n/m") -> 0.034099706 | CI35: =IFERROR((BV35/AW35)^(1/5)-1,"n/m") -> 0.034197483 | CJ35: =IFERROR((BV35/X35)^(1/10)-1,"n/m") -> 0.057848333 | CK35: =IFERROR((BV35/C35)^(1/19)-1,"n/m") -> n/m | CN35: 2029E | CO35: =CP35+$CO$32 -> 0.045 | CP35: 0.025 | CQ35: =CP35+$CQ$32 -> 0.005
B36: Net sales y/y % | S36: =IF(AND(ISNUMBER(S35),ISNUMBER(N35)),IFERROR(S35/N35-1,""),"") -> -0.02070474 | T36: =IF(AND(ISNUMBER(T35),ISNUMBER(O35)),IFERROR(T35/O35-1,""),"") -> -0.18445959 | U36: =IF(AND(ISNUMBER(U35),ISNUMBER(P35)),IFERROR(U35/P35-1,""),"") -> -0.23525767 | V36: =IF(AND(ISNUMBER(V35),ISNUMBER(Q35)),IFERROR(V35/Q35-1,""),"") -> -0.23768482 | W36: =IF(AND(ISNUMBER(W35),ISNUMBER(R35)),IFERROR(W35/R35-1,""),"") -> -0.22837864 | X36: =IF(AND(ISNUMBER(X35),ISNUMBER(S35)),IFERROR(X35/S35-1,""),"") -> -0.22154195 | Y36: =IF(AND(ISNUMBER(Y35),ISNUMBER(T35)),IFERROR(Y35/T35-1,""),"") -> -0.10730572 | Z36: =IF(AND(ISNUMBER(Z35),ISNUMBER(U35)),IFERROR(Z35/U35-1,""),"") -> -0.064202019 | ... BX36: =IF(AND(ISNUMBER(BX35),ISNUMBER(BS35)),IFERROR(BX35/BS35-1,""),"") -> 0.044961001 | BY36: =BY37+BY38+BY39+BY40 -> 0.0053576923 | BZ36: =BZ37+BZ38+BZ39+BZ40 -> -0.019242308 | CA36: =IFERROR(CA35/BV35-1,"") -> 0.015714623 | CB36: =CB37+CB38+CB39+CB40 -> 0.035 | CC36: =CC37+CC38+CC39+CC40 -> 0.04 | CD36: =CD37+CD38+CD39+CD40 -> 0.04 | CE36: =CE37+CE38+CE39+CE40 -> 0.04 | CN36: 2030E | CO36: =CP36+$CO$32 -> 0.045 | CP36: 0.025 | CQ36: =CP36+$CQ$32 -> 0.005
B37: Volume % (company "change in net sales due to volume") | Y37: -0.071 | Z37: -0.036 | AA37: -0.049 | AB37: 0.104 | AC37: -0.016 | AD37: 0.027 | AE37: 0.033 | AF37: 0.067 | AG37: -0.025 | AH37: 0.025 | AI37: -0.037 | AJ37: -0.045 | AK37: -0.105 | AL37: -0.137 | AM37: -0.092 | AN37: -0.072 | AO37: -0.097 | AP37: -0.062 | AQ37: -0.078 | AR37: -0.078 | AS37: -0.14 | AT37: -0.209 | AU37: -0.053 | AV37: -0.034 | AW37: -0.109 | AX37: 0.057 | AY37: 0.255 | AZ37: 0.038 | BA37: -0.008 | BB37: 0.079 | BC37: -0.005 | BD37: -0.067 | BE37: 0.024 | BF37: 0.014 | BG37: -0.01 | BH37: -0.057 | BI37: 0.038 | BJ37: 0.029 | BK37: 0.049 | BL37: 0.013 | BM37: -0.049 | BN37: -0.038 | BO37: -0.119 | BP37: -0.157 | BQ37: -0.093 | BR37: -0.058 | BS37: -0.068 | BT37: -0.042 | BU37: -0.036 | BV37: -0.051 | BW37: -0.099 | BX37: -0.047 | BY37: =$BX$37+BY139 -> -0.035242308 | BZ37: =$BX$37+BZ139 -> -0.035242308 | CA37: =IFERROR(CA42/BV35,"") -> -0.053114426 | CB37: =CHOOSE(MATCH($CF$2,{"Bull","Base","Bear"},0),$CO$33,$CP$33,$CQ$33) -> 0.02 | CC37: =CHOOSE(MATCH($CF$2,{"Bull","Base","Bear"},0),$CO$34,$CP$34,$CQ$34) -> 0.025 | CD37: =CHOOSE(MATCH($CF$2,{"Bull","Base","Bear"},0),$CO$35,$CP$35,$CQ$35) -> 0.025 | CE37: =CHOOSE(MATCH($CF$2,{"Bull","Base","Bear"},0),$CO$36,$CP$36,$CQ$36) -> 0.025 | CF37: Q3/Q4-26E: Q2/26 y/y volume + outlook calibration Δ (Group block). 2027E–2030E: scenario lever IW_vol (Bull/Base/Bear table →). | CN37: IW_price (International Welding price y/y) | CO37: 0.01 | CP37: Δ → | CQ37: -0.01 | CR37: Limited pricing power in Europe; 1H/26 +0.9%.
B38: Price % | Y38: -0.022 | Z38: -0.027 | AA38: -0.01 | AB38: -0.002 | AC38: -0.016 | AD38: 0.026 | AE38: 0.033 | AF38: 0.029 | AG38: 0.056 | AH38: 0.036 | AI38: 0.054 | AJ38: 0.055 | AK38: 0.052 | AL38: 0.038 | AM38: 0.048 | AN38: 0.026 | AO38: 0.012 | AP38: 0.003 | AQ38: -0.003 | AR38: 0.01 | AS38: -0.008 | AT38: -0.006 | AU38: 0 | AV38: 0.005 | AW38: -0.002 | AX38: 0.023 | AY38: 0.083 | AZ38: 0.108 | BA38: 0.139 | BB38: 0.09 | BC38: 0.234 | BD38: 0.186 | BE38: 0.138 | BF38: 0.117 | BG38: 0.168 | BH38: 0.058 | BI38: 0.004 | BJ38: 0.002 | BK38: -0.007 | BL38: 0.015 | BM38: -0.016 | BN38: -0.012 | BO38: -0.006 | BP38: 0 | BQ38: -0.008 | BR38: 0.004 | BS38: 0.004 | BT38: 0 | BU38: 0.005 | BV38: 0.003 | BW38: 0.001 | BX38: 0.016 | BY38: =$BX$38 -> 0.016 | BZ38: =$BX$38 -> 0.016 | CA38: =IFERROR(CA43/BV35,"") -> 0.012608359 | CB38: =CHOOSE(MATCH($CF$2,{"Bull","Base","Bear"},0),$CO$38,$CP$38,$CQ$38) -> 0.015 | CC38: =CHOOSE(MATCH($CF$2,{"Bull","Base","Bear"},0),$CO$39,$CP$39,$CQ$39) -> 0.015 | CD38: =CHOOSE(MATCH($CF$2,{"Bull","Base","Bear"},0),$CO$40,$CP$40,$CQ$40) -> 0.015 | CE38: =CHOOSE(MATCH($CF$2,{"Bull","Base","Bear"},0),$CO$41,$CP$41,$CQ$41) -> 0.015 | CF38: Q3/Q4-26E: Q2/26 y/y price held (carry-over of the 2025–26 increases; HPG includes metals pass-through). 2027E+: scenario lever. Note: 2016 Americas Welding as published includes Venezuela hyperinflationary price (+15.4%) offset by FX (−17.7%); ex-Venezuela price −0.5%, FX −1.0%. | CN38: 2027E | CO38: =CP38+$CO$37 -> 0.025 | CP38: 0.015 | CQ38: =CP38+$CQ$37 -> 0.005
B39: Acquisitions % | Y39: 0.025 | Z39: 0.026 | AA39: 0.011 | AB39: 0 | AC39: 0.016 | AD39: 0 | AE39: 0 | AF39: 0.515 | AG39: 0.857 | AH39: 0.342 | AI39: 0.799 | AJ39: 0.681 | AK39: 0.143 | AL39: 0 | AM39: 0.314 | AN39: 0 | AO39: 0 | AP39: 0.083 | AQ39: 0.09 | AR39: 0.04 | AS39: 0.084 | AT39: 0.072 | AU39: 0 | AV39: 0 | AW39: 0.039 | AX39: 0 | AY39: 0.02 | AZ39: 0.017 | BA39: 0.082 | BB39: 0.031 | BC39: 0.079 | BD39: 0 | BE39: 0 | BF39: 0 | BG39: 0.019 | BH39: 0.029 | BI39: 0.025 | BJ39: 0.049 | BK39: 0.124 | BL39: 0.057 | BM39: 0 | BN39: 0 | BO39: 0.004 | BP39: 0.002 | BQ39: 0.002 | BR39: 0.003 | BS39: 0.001 | BT39: 0.037 | BU39: 0.047 | BV39: 0.022 | BW39: 0.072 | BX39: 0.07 | BY39: 0.0246 | BZ39: 0 | CA39: =IFERROR(CA44/BV35,"") -> 0.040166805 | CB39: 0 | CC39: 0 | CD39: 0 | CE39: 0 | CF39: Alloy Steel (Australia; ~$48m sales; 100% consolidated from 1-Aug-2025) anniversaries on 1-Aug-2026: Q3/26E = one month (Q2/26 acquisition sales $16.2m ÷ 3 ÷ Q3/25 IW sales = 2.5%); Q4/26E 0%. | CN39: 2028E | CO39: =CP39+$CO$37 -> 0.025 | CP39: 0.015 | CQ39: =CP39+$CQ$37 -> 0.005
B40: Foreign exchange % | Y40: -0.039 | Z40: -0.027 | AA40: -0.019 | AB40: -0.025 | AC40: -0.028 | AD40: -0.016 | AE40: -0.001 | AF40: 0.043 | AG40: 0.072 | AH40: 0.025 | AI40: 0.102 | AJ40: 0.029 | AK40: -0.031 | AL40: -0.043 | AM40: 0 | AN40: -0.072 | AO40: -0.043 | AP40: -0.044 | AQ40: -0.012 | AR40: -0.044 | AS40: -0.029 | AT40: -0.022 | AU40: 0.012 | AV40: 0.011 | AW40: -0.007 | AX40: 0.047 | AY40: 0.067 | AZ40: -0.009 | BA40: -0.069 | BB40: 0.006 | BC40: -0.152 | BD40: -0.181 | BE40: -0.21 | BF40: -0.14 | BG40: -0.17 | BH40: -0.051 | BI40: 0.003 | BJ40: 0.038 | BK40: 0.036 | BL40: 0.005 | BM40: -0.001 | BN40: -0.008 | BO40: 0.014 | BP40: -0.013 | BQ40: -0.003 | BR40: -0.02 | BS40: 0.038 | BT40: 0.021 | BU40: 0.051 | BV40: 0.023 | BW40: 0.062 | BX40: 0.006 | BY40: 0 | BZ40: 0 | CA40: =IFERROR(CA45/BV35,"") -> 0.016053885 | CB40: =CHOOSE(MATCH($CF$2,{"Bull","Base","Bear"},0),$CO$53,$CP$53,$CQ$53) -> 0 | CC40: =CHOOSE(MATCH($CF$2,{"Bull","Base","Bear"},0),$CO$54,$CP$54,$CQ$54) -> 0 | CD40: =CHOOSE(MATCH($CF$2,{"Bull","Base","Bear"},0),$CO$55,$CP$55,$CQ$55) -> 0 | CE40: =CHOOSE(MATCH($CF$2,{"Bull","Base","Bear"},0),$CO$56,$CP$56,$CQ$56) -> 0 | CF40: Q3/Q4-26E: FX input (spot-rate translation vs prior-year quarter). 2027E+: International Welding FX lever; Americas & Harris 0%. | CN40: 2029E | CO40: =CP40+$CO$37 -> 0.025 | CP40: 0.015 | CQ40: =CP40+$CQ$37 -> 0.005
...

Sheet Bull-Base-Bear
B2: Lincoln Electric (LECO) — Bull / Base / Bear Case P&L Summary | J2: Share price ($): | K2: =Model!$CA$424 -> 275.54
B3: Adjusted figures (company definitions: adjusted EBIT / adjusted net income / adjusted diluted EPS) · USD millions · Live panel linked to Model — toggle scenario via Model!CF2. Bull and Bear panels are value snapshots generated from the Model with the switch set to each case. Adjusted EBITDA is a model measure (adjusted EBIT + D&A). | J3: As of: | K3: =TODAY() -> 2026-10-07 00:00:00
B5: Scenario: | C5: =Model!$CF$2 -> Base | N5: Scenario: | O5: Bull | P5: Snapshot (values) — Model run with switch = Bull | Z5: Scenario: | AA5: Bear | AB5: Snapshot (values) — Model run with switch = Bear
B7: (USDm, except EPS and shares) | C7: 2025A | D7: 2026E | E7: 2027E | F7: 2028E | G7: 2029E | H7: 2030E | I7: 25-'30 CAGR | J7: LT Hist Avg | K7: LT Hist Min | L7: LT Hist Max | N7: (USDm, except EPS and shares) | O7: 2025A | P7: 2026E | Q7: 2027E | R7: 2028E | S7: 2029E | T7: 2030E | U7: 25-'30 CAGR | V7: LT Hist Avg | W7: LT Hist Min | X7: LT Hist Max | Z7: (USDm, except EPS and shares) | AA7: 2025A | AB7: 2026E | AC7: 2027E | AD7: 2028E | AE7: 2029E | AF7: 2030E | AG7: 25-'30 CAGR | AH7: LT Hist Avg | AI7: LT Hist Min | AJ7: LT Hist Max
B9: Net sales | C9: =Model!BV154 -> 4233.003 | D9: =Model!CA154 -> 4719.7983 | E9: =Model!CB154 -> 5029.3489 | F9: =Model!CC154 -> 5405.0343 | G9: =Model!CD154 -> 5795.1676 | H9: =Model!CE154 -> 6203.2911 | I9: =IFERROR((H9/C9)^(1/5)-1,"n/m") -> 0.079430581 | N9: Net sales | O9: 4233.003 | P9: 4783.2934 | Q9: 5290.7139 | R9: 5926.5111 | S9: 6602.4699 | T9: 7324.7147 | U9: 0.11590809 | Z9: Net sales | AA9: 4233.003 | AB9: 4656.3033 | AC9: 4772.1632 | AD9: 4902.6613 | AE9: 5034.2021 | AF9: 5169.4344 | AG9: 0.040779887
B10: Net sales y/y % | D10: =IFERROR(D9/C9-1,"") -> 0.115 | E10: =IFERROR(E9/D9-1,"") -> 0.06558555 | F10: =IFERROR(F9/E9-1,"") -> 0.074698617 | G10: =IFERROR(G9/F9-1,"") -> 0.07217961 | H10: =IFERROR(H9/G9-1,"") -> 0.070424806 | N10: Net sales y/y % | P10: 0.13 | Q10: 0.10608182 | R10: 0.1201723 | S10: 0.11405677 | T10: 0.1093901 | Z10: Net sales y/y % | AB10: 0.1 | AC10: 0.024882368 | AD10: 0.027345711 | AE10: 0.026830475 | AF10: 0.026862717
B11: Organic sales growth % (volume + price) | C11: =Model!BV252 -> 0.025 | D11: =Model!CA252 -> 0.099686788 | E11: =Model!CB252 -> 0.054991877 | F11: =Model!CC252 -> 0.051534585 | G11: =Model!CD252 -> 0.047358306 | H11: =Model!CE252 -> 0.04634847 | N11: Organic sales growth % (volume + price) | O11: 0.025 | P11: 0.11468679 | Q11: 0.085782614 | R11: 0.081459788 | S11: 0.075851804 | T11: 0.073657298 | Z11: Organic sales growth % (volume + price) | AA11: 0.025 | AB11: 0.084686788 | AC11: 0.024197879 | AD11: 0.021219819 | AE11: 0.017901905 | AF11: 0.017746009
B12: Adjusted EBIT (company definition) | C12: =Model!BV222 -> 752.632 | D12: =Model!CA222 -> 851.86284 | E12: =Model!CB222 -> 939.65903 | F12: =Model!CC222 -> 1036.9539 | G12: =Model!CD222 -> 1135.2148 | H12: =Model!CE222 -> 1238.132 | I12: =IFERROR((H12/C12)^(1/5)-1,"n/m") -> 0.10468092 | N12: Adjusted EBIT (company definition) | O12: 752.632 | P12: 875.29296 | Q12: 1016.4334 | R12: 1179.813 | S12: 1351.4855 | T12: 1535.9238 | U12: 0.15334012 | Z12: Adjusted EBIT (company definition) | AA12: 752.632 | AB12: 831.60747 | AC12: 867.33955 | AD12: 903.06978 | AE12: 936.15335 | AF12: 970.01102 | AG12: 0.052055855
B13: Adjusted EBIT margin % | C13: =IFERROR(C12/C9,"") -> 0.17780096 | D13: =IFERROR(D12/D9,"") -> 0.18048713 | E13: =IFERROR(E12/E9,"") -> 0.18683512 | F13: =IFERROR(F12/F9,"") -> 0.19184965 | G13: =IFERROR(G12/G9,"") -> 0.19588989 | H13: =IFERROR(H12/H9,"") -> 0.19959276 | J13: =IFERROR(AVERAGE(Model!C223,Model!D223,Model!E223,Model!F223,Model!G223,Model!H223,Model!I223,Model!N223,Model!S223,Model!X223,Model!AC223,Model!AH223,Model!AM223,Model!AR223,Model!AW223,Model!BB223,Model!BG223,Model!BL223,Model!BQ223,Model!BV223),"") -> 0.13919665 | K13: =IFERROR(MIN(Model!C223,Model!D223,Model!E223,Model!F223,Model!G223,Model!H223,Model!I223,Model!N223,Model!S223,Model!X223,Model!AC223,Model!AH223,Model!AM223,Model!AR223,Model!AW223,Model!BB223,Model!BG223,Model!BL223,Model!BQ223,Model!BV223),"") -> 0.070647695 | L13: =IFERROR(MAX(Model!C223,Model!D223,Model!E223,Model!F223,Model!G223,Model!H223,Model!I223,Model!N223,Model!S223,Model!X223,Model!AC223,Model!AH223,Model!AM223,Model!AR223,Model!AW223,Model!BB223,Model!BG223,Model!BL223,Model!BQ223,Model!BV223),"") -> 0.1780154 | N13: Adjusted EBIT margin % | O13: 0.17780096 | P13: 0.1829896 | Q13: 0.19211649 | R13: 0.19907378 | S13: 0.20469394 | T13: 0.2096906 | V13: 0.13919665 | W13: 0.070647695 | X13: 0.1780154 | Z13: Adjusted EBIT margin % | AA13: 0.17780096 | AB13: 0.17859822 | AC13: 0.18174977 | AD13: 0.18419991 | AE13: 0.18595864 | AF13: 0.18764355 | AH13: 0.13919665 | AI13: 0.070647695 | AJ13: 0.1780154
B15: Operating income (GAAP) | C15: =Model!BV162 -> 718.059 | D15: =Model!CA162 -> 838.58084 | E15: =Model!CB162 -> 918.65903 | F15: =Model!CC162 -> 1015.4539 | G15: =Model!CD162 -> 1113.7148 | H15: =Model!CE162 -> 1216.632 | I15: =IFERROR((H15/C15)^(1/5)-1,"n/m") -> 0.11121942 | N15: Operating income (GAAP) | O15: 718.059 | P15: 862.01096 | Q15: 993.93339 | R15: 1156.813 | S15: 1328.4855 | T15: 1512.9238 | U15: 0.16073047 | Z15: Operating income (GAAP) | AA15: 718.059 | AB15: 818.32547 | AC15: 846.33955 | AD15: 882.06978 | AE15: 915.15335 | AF15: 949.01102 | AG15: 0.057358413
B16: Operating income y/y % | D16: =IFERROR(D15/C15-1,"") -> 0.16784392 | E16: =IFERROR(E15/D15-1,"") -> 0.095492512 | F16: =IFERROR(F15/E15-1,"") -> 0.10536544 | G16: =IFERROR(G15/F15-1,"") -> 0.096765403 | H16: =IFERROR(H15/G15-1,"") -> 0.092408984 | N16: Operating income y/y % | P16: 0.20047372 | Q16: 0.15304032 | R16: 0.16387373 | S16: 0.14840133 | T16: 0.13883346 | Z16: Operating income y/y % | AB16: 0.13963542 | AC16: 0.034233424 | AD16: 0.042217367 | AE16: 0.037506754 | AF16: 0.036996715
B17: Operating margin (GAAP) % | C17: =IFERROR(C15/C9,"") -> 0.16963347 | D17: =IFERROR(D15/D9,"") -> 0.17767302 | E17: =IFERROR(E15/E9,"") -> 0.18265963 | F17: =IFERROR(F15/F9,"") -> 0.18787188 | G17: =IFERROR(G15/G9,"") -> 0.1921799 | H17: =IFERROR(H15/H9,"") -> 0.19612686 | J17: =IFERROR(AVERAGE(Model!C264,Model!D264,Model!E264,Model!F264,Model!G264,Model!H264,Model!I264,Model!N264,Model!S264,Model!X264,Model!AC264,Model!AH264,Model!AM264,Model!AR264,Model!AW264,Model!BB264,Model!BG264,Model!BL264,Model!BQ264,Model!BV264),"") -> 0.12583033 | K17: =IFERROR(MIN(Model!C264,Model!D264,Model!E264,Model!F264,Model!G264,Model!H264,Model!I264,Model!N264,Model!S264,Model!X264,Model!AC264,Model!AH264,Model!AM264,Model!AR264,Model!AW264,Model!BB264,Model!BG264,Model!BL264,Model!BQ264,Model!BV264),"") -> 0.053765574 | L17: =IFERROR(MAX(Model!C264,Model!D264,Model!E264,Model!F264,Model!G264,Model!H264,Model!I264,Model!N264,Model!S264,Model!X264,Model!AC264,Model!AH264,Model!AM264,Model!AR264,Model!AW264,Model!BB264,Model!BG264,Model!BL264,Model!BQ264,Model!BV264),"") -> 0.17125748 | N17: Operating margin (GAAP) % | O17: 0.16963347 | P17: 0.18021285 | Q17: 0.18786376 | R17: 0.19519291 | S17: 0.20121039 | T17: 0.20655054 | V17: 0.12583033 | W17: 0.053765574 | X17: 0.17125748 | Z17: Operating margin (GAAP) % | AA17: 0.16963347 | AB17: 0.17574574 | AC17: 0.17734925 | AD17: 0.17991652 | AE17: 0.18178717 | AF17: 0.18358121 | AH17: 0.12583033 | AI17: 0.053765574 | AJ17: 0.17125748
B19: Adjusted net income (attributable to Lincoln Electric) | C19: =Model!BV240 -> 551.331 | D19: =Model!CA240 -> 616.79554 | E19: =Model!CB240 -> 684.53279 | F19: =Model!CC240 -> 752.98508 | G19: =Model!CD240 -> 823.94264 | H19: =Model!CE240 -> 898.38767 | I19: =IFERROR((H19/C19)^(1/5)-1,"n/m") -> 0.10258041 | N19: Adjusted net income (attributable to Lincoln Electric) | O19: 551.331 | P19: 641.07607 | Q19: 742.39053 | R19: 848.16754 | S19: 970.65276 | T19: 1102.4268 | U19: 0.14864934 | Z19: Adjusted net income (attributable to Lincoln Electric) | AA19: 551.331 | AB19: 595.44644 | AC19: 629.73856 | AD19: 659.70549 | AE19: 684.43909 | AF19: 709.79468 | AG19: 0.051826397
B21: FDSO (m) | C21: =Model!BV182 -> 55.875 | D21: =Model!CA182 -> 55.0378 | E21: =Model!CB182 -> 54.025826 | F21: =Model!CC182 -> 53.043562 | G21: =Model!CD182 -> 52.109948 | H21: =Model!CE182 -> 51.04691 | I21: =IFERROR((H21/C21)^(1/5)-1,"n/m") -> -0.017912046 | N21: FDSO (m) | O21: 55.875 | P21: 55.010581 | Q21: 53.53954 | R21: 52.127954 | S21: 51.001888 | T21: 49.569621 | U21: -0.023663306 | Z21: FDSO (m) | AA21: 55.875 | AB21: 55.065019 | AC21: 54.427595 | AD21: 53.725732 | AE21: 52.843762 | AF21: 51.981826 | AG21: -0.014340758
B23: Adjusted EPS — Diluted ($) | C23: =Model!BV244 -> 9.8672215 | D23: =Model!CA244 -> 11.208023 | E23: =Model!CB244 -> 12.670473 | F23: =Model!CC244 -> 14.195598 | G23: =Model!CD244 -> 15.811619 | H23: =Model!CE244 -> 17.599257 | I23: =IFERROR((H23/C23)^(1/5)-1,"n/m") -> 0.12269009 | N23: Adjusted EPS — Diluted ($) | O23: 9.8672215 | P23: 11.656834 | Q23: 13.86621 | R23: 16.270877 | S23: 19.031702 | T23: 22.239968 | U23: 0.17648896 | Z23: Adjusted EPS — Diluted ($) | AA23: 9.8672215 | AB23: 10.813488 | AC23: 11.570207 | AD23: 12.279134 | AE23: 12.952126 | AF23: 13.65467 | AG23: 0.067129848
B24: EPS y/y % | D24: =IFERROR(D23/C23-1,"") -> 0.13588443 | E24: =IFERROR(E23/D23-1,"") -> 0.13048242 | F24: =IFERROR(F23/E23-1,"") -> 0.12036841 | G24: =IFERROR(G23/F23-1,"") -> 0.11383959 | H24: =IFERROR(H23/G23-1,"") -> 0.11305848 | N24: EPS y/y % | P24: 0.18136947 | Q24: 0.18953484 | R24: 0.17341918 | S24: 0.16967894 | T24: 0.16857478 | Z24: EPS y/y % | AB24: 0.095899998 | AC24: 0.069979215 | AD24: 0.061271767 | AE24: 0.054807772 | AF24: 0.05424157
B26: P / E (x) — assumed (adjusted EPS) | G26: 22 | H26: 22 | N26: P / E (x) — assumed (adjusted EPS) | S26: 25 | T26: 25 | Z26: P / E (x) — assumed (adjusted EPS) | AD26: 18 | AE26: 18 | AF26: 18
B27: Price Target ($) | G27: =G26*G23 -> 347.85562 | H27: =H26*H23 -> 387.18365 | N27: Price Target ($) | S27: =S26*S23 -> 475.79256 | T27: =T26*T23 -> 555.99919 | Z27: Price Target ($) | AD27: =AD26*AD23 -> 221.02442 | AE27: =AE26*AE23 -> 233.13828 | AF27: =AF26*AF23 -> 245.78406
B28: Upside / (Downside) vs current | G28: =IFERROR(G27/$K$2-1,"") -> 0.26245052 | H28: =IFERROR(H27/$K$2-1,"") -> 0.40518127 | N28: Upside / (Downside) vs current | S28: =IFERROR(S27/$K$2-1,"") -> 0.72676403 | T28: =IFERROR(T27/$K$2-1,"") -> 1.0178529 | Z28: Upside / (Downside) vs current | AD28: =IFERROR(AD27/$K$2-1,"") -> -0.19784997 | AE28: =IFERROR(AE27/$K$2-1,"") -> -0.15388591 | AF28: =IFERROR(AF27/$K$2-1,"") -> -0.10799135
B29: IRR (to Dec-Y-1) | G29: =IFERROR((G27/$K$2)^(1/((DATE(2029-1,12,31)-$K$3)/365.25))-1,"") -> 0.10995301 | H29: =IFERROR((H27/$K$2)^(1/((DATE(2030-1,12,31)-$K$3)/365.25))-1,"") -> 0.11093705 | N29: IRR (to Dec-Y-1) | S29: =IFERROR((S27/$K$2)^(1/((DATE(2029-1,12,31)-$K$3)/365.25))-1,"") -> 0.27699128 | T29: =IFERROR((T27/$K$2)^(1/((DATE(2030-1,12,31)-$K$3)/365.25))-1,"") -> 0.24249236 | Z29: IRR (to Dec-Y-1) | AD29: =IFERROR((AD27/$K$2)^(1/((DATE(2028-1,12,31)-$K$3)/365.25))-1,"") -> -0.1638437 | AE29: =IFERROR((AE27/$K$2)^(1/((DATE(2029-1,12,31)-$K$3)/365.25))-1,"") -> -0.072067383 | AF29: =IFERROR((AF27/$K$2)^(1/((DATE(2030-1,12,31)-$K$3)/365.25))-1,"") -> -0.034726128
B31: Free Cash Flow | C31: =Model!BV298 -> 534.199 | D31: =Model!CA298 -> 514.23245 | E31: =Model!CB298 -> 635.62039 | F31: =Model!CC298 -> 695.52003 | G31: =Model!CD298 -> 769.61802 | H31: =Model!CE298 -> 847.11167 | I31: =IFERROR((H31/C31)^(1/5)-1,"n/m") -> 0.096598176 | N31: Free Cash Flow | O31: 534.199 | P31: 519.67497 | Q31: 663.5142 | R31: 754.11973 | S31: 879.28816 | T31: 1013.4279 | U31: 0.13662697 | Z31: Free Cash Flow | AA31: 534.199 | AB31: 512.04316 | AC31: 608.86746 | AD31: 635.88476 | AE31: 662.34701 | AF31: 689.38192 | AG31: 0.052328576
B32: FCF % | C32: =IFERROR(C31/C9,"") -> 0.12619859 | D32: =IFERROR(D31/D9,"") -> 0.10895221 | E32: =IFERROR(E31/E9,"") -> 0.12638224 | F32: =IFERROR(F31/F9,"") -> 0.12868004 | G32: =IFERROR(G31/G9,"") -> 0.13280341 | H32: =IFERROR(H31/H9,"") -> 0.13655843 | J32: =IFERROR(AVERAGE(Model!C300,Model!D300,Model!E300,Model!F300,Model!G300,Model!H300,Model!I300,Model!N300,Model!S300,Model!X300,Model!AC300,Model!AH300,Model!AM300,Model!AR300,Model!AW300,Model!BB300,Model!BG300,Model!BL300,Model!BQ300,Model!BV300),"") -> 0.094282002 | K32: =IFERROR(MIN(Model!C300,Model!D300,Model!E300,Model!F300,Model!G300,Model!H300,Model!I300,Model!N300,Model!S300,Model!X300,Model!AC300,Model!AH300,Model!AM300,Model!AR300,Model!AW300,Model!BB300,Model!BG300,Model!BL300,Model!BQ300,Model!BV300),"") -> 0.021642921 | L32: =IFERROR(MAX(Model!C300,Model!D300,Model!E300,Model!F300,Model!G300,Model!H300,Model!I300,Model!N300,Model!S300,Model!X300,Model!AC300,Model!AH300,Model!AM300,Model!AR300,Model!AW300,Model!BB300,Model!BG300,Model!BL300,Model!BQ300,Model!BV300),"") -> 0.13754892 | N32: FCF % | O32: 0.12619859 | P32: 0.10864376 | Q32: 0.12541109 | R32: 0.12724514 | S32: 0.13317564 | T32: 0.13835732 | V32: 0.094282002 | W32: 0.021642921 | X32: 0.13754892 | Z32: FCF % | AA32: 0.12619859 | AB32: 0.10996774 | AC32: 0.12758731 | AD32: 0.12970195 | AE32: 0.13156941 | AF32: 0.13335732 | AH32: 0.094282002 | AI32: 0.021642921 | AJ32: 0.13754892
B33: FCF / share ($) | C33: =IFERROR(C31/C21,"") -> 9.5606085 | D33: =IFERROR(D31/D21,"") -> 9.3432596 | E33: =IFERROR(E31/E21,"") -> 11.765121 | F33: =IFERROR(F31/F21,"") -> 13.112242 | G33: =IFERROR(G31/G21,"") -> 14.769119 | H33: =IFERROR(H31/H21,"") -> 16.594769 | N33: FCF / share ($) | O33: 9.5606085 | P33: 9.4468186 | Q33: 12.392975 | R33: 14.466705 | S33: 17.240306 | T33: 20.444536 | Z33: FCF / share ($) | AA33: 9.5606085 | AB33: 9.2988829 | AC33: 11.186742 | AD33: 11.835758 | AE33: 12.534062 | AF33: 13.26198
B34: FCF Yield (on PT) | F34: =IFERROR(F33/F$27,"") | G34: =IFERROR(G33/G$27,"") -> 0.042457613 | H34: =IFERROR(H33/H$27,"") -> 0.042860201 | N34: FCF Yield (on PT) | R34: =IFERROR(R33/R$27,"") | S34: =IFERROR(S33/S$27,"") -> 0.036234921 | T34: =IFERROR(T33/T$27,"") -> 0.036770802 | Z34: FCF Yield (on PT) | AD34: =IFERROR(AD33/AD$27,"") -> 0.053549548 | AE34: =IFERROR(AE33/AE$27,"") -> 0.053762353 | AF34: =IFERROR(AF33/AF$27,"") -> 0.053957851
B35: Adjusted EBITDA (model: adjusted EBIT + D&A) | C35: =Model!BV229 -> 851.178 | D35: =Model!CA229 -> 955.81884 | E35: =Model!CB229 -> 1054.6944 | F35: =Model!CC229 -> 1164.811 | G35: =Model!CD229 -> 1276.8808 | H35: =Model!CE229 -> 1394.213 | I35: =IFERROR((H35/C35)^(1/5)-1,"n/m") -> 0.10372721 | N35: Adjusted EBITDA (model: adjusted EBIT + D&A) | O35: 851.178 | P35: 979.24896 | Q35: 1138.7557 | R35: 1323.7345 | S35: 1518.6891 | T35: 1727.7738 | U35: 0.15210828 | Z35: Adjusted EBITDA (model: adjusted EBIT + D&A) | AA35: 851.178 | AB35: 935.56347 | AC35: 975.18197 | AD35: 1015.2922 | AE35: 1053.3244 | AF35: 1092.2934 | AG35: 0.051147787
B36: Adjusted EBITDA % of net sales | C36: =IFERROR(C35/C9,"") -> 0.20108136 | D36: =IFERROR(D35/D9,"") -> 0.20251264 | E36: =IFERROR(E35/E9,"") -> 0.20970794 | F36: =IFERROR(F35/F9,"") -> 0.21550482 | G36: =IFERROR(G35/G9,"") -> 0.22033543 | H36: =IFERROR(H35/H9,"") -> 0.22475377 | J36: =IFERROR(AVERAGE(Model!C230,Model!D230,Model!E230,Model!F230,Model!G230,Model!H230,Model!I230,Model!N230,Model!S230,Model!X230,Model!AC230,Model!AH230,Model!AM230,Model!AR230,Model!AW230,Model!BB230,Model!BG230,Model!BL230,Model!BQ230,Model!BV230),"") -> 0.16412065 | K36: =IFERROR(MIN(Model!C230,Model!D230,Model!E230,Model!F230,Model!G230,Model!H230,Model!I230,Model!N230,Model!S230,Model!X230,Model!AC230,Model!AH230,Model!AM230,Model!AR230,Model!AW230,Model!BB230,Model!BG230,Model!BL230,Model!BQ230,Model!BV230),"") -> 0.10337683 | L36: =IFERROR(MAX(Model!C230,Model!D230,Model!E230,Model!F230,Model!G230,Model!H230,Model!I230,Model!N230,Model!S230,Model!X230,Model!AC230,Model!AH230,Model!AM230,Model!AR230,Model!AW230,Model!BB230,Model!BG230,Model!BL230,Model!BQ230,Model!BV230),"") -> 0.20108136 | N36: Adjusted EBITDA % of net sales | O36: 0.20108136 | P36: 0.20472275 | Q36: 0.21523668 | R36: 0.22335813 | S36: 0.23001833 | T36: 0.23588274 | V36: 0.16412065 | W36: 0.10337683 | X36: 0.20108136 | Z36: Adjusted EBITDA % of net sales | AA36: 0.20108136 | AB36: 0.20092408 | AC36: 0.20434799 | AD36: 0.20709 | AE36: 0.20923363 | AF36: 0.21129843 | AH36: 0.16412065 | AI36: 0.10337683 | AJ36: 0.20108136
B38: Net Debt | C38: =Model!BV419 -> 985.219 | D38: =Model!CA419 -> 896.79696 | E38: =Model!CB419 -> 1054.6944 | F38: =Model!CC419 -> 1164.811 | G38: =Model!CD419 -> 1276.8808 | H38: =Model!CE419 -> 1394.213 | N38: Net Debt | O38: 985.219 | P38: 921.2652 | Q38: 1423.4446 | R38: 1654.6681 | S38: 1898.3614 | T38: 2159.7172 | Z38: Net Debt | AA38: 985.219 | AB38: 869.07548 | AC38: 731.38648 | AD38: 761.46912 | AE38: 789.9933 | AF38: 819.22002
B39: Net Debt / Adjusted EBITDA (x) | C39: =IFERROR(C38/C35,"") -> 1.157477 | D39: =IFERROR(D38/D35,"") -> 0.93824993 | E39: =IFERROR(E38/E35,"") -> 1 | F39: =IFERROR(F38/F35,"") -> 1 | G39: =IFERROR(G38/G35,"") -> 1 | H39: =IFERROR(H38/H35,"") -> 1 | N39: Net Debt / Adjusted EBITDA (x) | O39: 1.157477 | P39: 0.94078752 | Q39: 1.25 | R39: 1.25 | S39: 1.25 | T39: 1.25 | Z39: Net Debt / Adjusted EBITDA (x) | AA39: 1.157477 | AB39: 0.92893268 | AC39: 0.75 | AD39: 0.75 | AE39: 0.75 | AF39: 0.75
B40: Share repurchases ($m) | D40: =Model!CA311 -> 130 | E40: =Model!CB311 -> 411.65614 | F40: =Model!CC311 -> 368.54886 | G40: =Model!CD311 -> 438.4616 | H40: =Model!CE311 -> 515.44136 | N40: Share repurchases ($m) | P40: 160 | Q40: 634.19773 | R40: 401.30207 | S40: 533.33877 | T40: 680.63699
B41: Implied avg buyback price ($) | D41: =Model!CA310 -> 275.54 | E41: =Model!CB310 -> 294.8278 | F41: =Model!CC310 -> 315.46575 | G41: =Model!CD310 -> 337.54835 | H41: =Model!CE310 -> 361.17673 | N41: Implied avg buyback price ($) | P41: 275.54 | Q41: 294.8278 | R41: 315.46575 | S41: 337.54835 | T41: 361.17673
B42: Shares repurchased (m) | D42: =Model!CA312 -> 0.47180083 | E42: =Model!CB312 -> 1.3962596 | F42: =Model!CC312 -> 1.168269 | G42: =Model!CD312 -> 1.2989594 | H42: =Model!CE312 -> 1.4271167 | N42: Shares repurchased (m) | P42: 0.58067794 | Q42: 2.1510784 | R42: 1.2720939 | S42: 1.5800367 | T42: 1.8844984
B44: ROIC | C44: =Model!BV401 -> 0.2362566 | D44: =Model!CA401 -> 0.25681884 | E44: =Model!CB401 -> 0.25438012 | F44: =Model!CC401 -> 0.2516436 | G44: =Model!CD401 -> 0.24969055 | H44: =Model!CE401 -> 0.24904773 | J44: =IFERROR(AVERAGE(Model!C401,Model!D401,Model!E401,Model!F401,Model!G401,Model!H401,Model!I401,Model!N401,Model!S401,Model!X401,Model!AC401,Model!AH401,Model!AM401,Model!AR401,Model!AW401,Model!BB401,Model!BG401,Model!BL401,Model!BQ401,Model!BV401),"") -> 0.23179876 | K44: =IFERROR(MIN(Model!C401,Model!D401,Model!E401,Model!F401,Model!G401,Model!H401,Model!I401,Model!N401,Model!S401,Model!X401,Model!AC401,Model!AH401,Model!AM401,Model!AR401,Model!AW401,Model!BB401,Model!BG401,Model!BL401,Model!BQ401,Model!BV401),"") -> 0.083557813 | L44: =IFERROR(MAX(Model!C401,Model!D401,Model!E401,Model!F401,Model!G401,Model!H401,Model!I401,Model!N401,Model!S401,Model!X401,Model!AC401,Model!AH401,Model!AM401,Model!AR401,Model!AW401,Model!BB401,Model!BG401,Model!BL401,Model!BQ401,Model!BV401),"") -> 0.29017761 | N44: ROIC | O44: 0.2362566 | P44: 0.26369813 | Q44: 0.25700927 | R44: 0.2549212 | S44: 0.25484156 | T44: 0.25680474 | V44: 0.23179876 | W44: 0.083557813 | X44: 0.29017761 | Z44: ROIC | AA44: 0.2362566 | AB44: 0.25101859 | AC44: 0.25260296 | AD44: 0.2496794 | AE44: 0.24642107 | AF44: 0.24372468 | AH44: 0.23179876 | AI44: 0.083557813 | AJ44: 0.29017761
B45: RONTA | C45: =Model!BV413 -> 0.27912348 | D45: =Model!CA413 -> 0.30593875 | E45: =Model!CB413 -> 0.30962273 | F45: =Model!CC413 -> 0.31284435 | G45: =Model!CD413 -> 0.31592508 | H45: =Model!CE413 -> 0.31982968 | J45: =IFERROR(AVERAGE(Model!C413,Model!D413,Model!E413,Model!F413,Model!G413,Model!H413,Model!I413,Model!N413,Model!S413,Model!X413,Model!AC413,Model!AH413,Model!AM413,Model!AR413,Model!AW413,Model!BB413,Model!BG413,Model!BL413,Model!BQ413,Model!BV413),"") -> 0.19908104 | K45: =IFERROR(MIN(Model!C413,Model!D413,Model!E413,Model!F413,Model!G413,Model!H413,Model!I413,Model!N413,Model!S413,Model!X413,Model!AC413,Model!AH413,Model!AM413,Model!AR413,Model!AW413,Model!BB413,Model!BG413,Model!BL413,Model!BQ413,Model!BV413),"") -> 0.048889066 | L45: =IFERROR(MAX(Model!C413,Model!D413,Model!E413,Model!F413,Model!G413,Model!H413,Model!I413,Model!N413,Model!S413,Model!X413,Model!AC413,Model!AH413,Model!AM413,Model!AR413,Model!AW413,Model!BB413,Model!BG413,Model!BL413,Model!BQ413,Model!BV413),"") -> 0.3007133 | N45: RONTA | O45: 0.27912348 | P45: 0.31415055 | Q45: 0.31688774 | R45: 0.32363074 | S45: 0.33081271 | T45: 0.33922689 | V45: 0.19908104 | W45: 0.048889066 | X45: 0.3007133 | Z45: RONTA | AA45: 0.27912348 | AB45: 0.29562115 | AC45: 0.28131259 | AD45: 0.28502842 | AE45: 0.28766469 | AF45: 0.29057559 | AH45: 0.19908104 | AI45: 0.048889066 | AJ45: 0.3007133
B47: Implied Market Cap (USDm) | F47: =F27*F21 -> 0 | G47: =G27*G21 -> 18126.738 | H47: =H27*H21 -> 19764.529 | N47: Implied Market Cap (USDm) | R47: =R27*R21 -> 0 | S47: =S27*S21 -> 24266.319 | T47: =T27*T21 -> 27560.669 | Z47: Implied Market Cap (USDm) | AD47: =AD27*AD21 -> 11874.699 | AE47: =AE27*AE21 -> 12319.904 | AF47: =AF27*AF21 -> 12776.304
B48: (+) Net Debt & NCI | F48: =F38+Model!CC345 -> 1164.811 | G48: =G38+Model!CD345 -> 1276.8808 | H48: =H38+Model!CE345 -> 1394.213 | N48: (+) Net Debt & NCI | R48: =R38+Model!CC345 -> 1654.6681 | S48: =S38+Model!CD345 -> 1898.3614 | T48: =T38+Model!CE345 -> 2159.7172 | Z48: (+) Net Debt & NCI | AD48: =AD38+Model!CC345 -> 761.46912 | AE48: =AE38+Model!CD345 -> 789.9933 | AF48: =AF38+Model!CE345 -> 819.22002
B49: Implied Enterprise Value (USDm) | F49: =F47+F48 -> 1164.811 | G49: =G47+G48 -> 19403.619 | H49: =H47+H48 -> 21158.742 | N49: Implied Enterprise Value (USDm) | R49: =R47+R48 -> 1654.6681 | S49: =S47+S48 -> 26164.68 | T49: =T47+T48 -> 29720.386 | Z49: Implied Enterprise Value (USDm) | AD49: =AD47+AD48 -> 12636.168 | AE49: =AE47+AE48 -> 13109.897 | AF49: =AF47+AF48 -> 13595.524
B50: Implied EV / Adjusted EBITDA (x) | F50: =IFERROR(F49/F35,"") -> 1 | G50: =IFERROR(G49/G35,"") -> 15.196109 | H50: =IFERROR(H49/H35,"") -> 15.176118 | N50: Implied EV / Adjusted EBITDA (x) | R50: =IFERROR(R49/R35,"") -> 1.25 | S50: =IFERROR(S49/S35,"") -> 17.228464 | T50: =IFERROR(T49/T35,"") -> 17.201549 | Z50: Implied EV / Adjusted EBITDA (x) | AD50: =IFERROR(AD49/AD35,"") -> 12.445844 | AE50: =IFERROR(AE49/AE35,"") -> 12.44621 | AF50: =IFERROR(AF49/AF35,"") -> 12.44677

Sheet DCF
B2: DCF VALUATION — LINCOLN ELECTRIC HOLDINGS (LECO)
B4: 1. WACC BUILD
B5: Risk-free rate (US 10Y govt) | C5: 0.055 | D5: Assumption (~US 10Y Treasury yield); update to market
B6: Equity risk premium | C6: 0.05 | D6: US implied ERP ~4.5–5.5% (Damodaran)
B7: Levered beta | C7: 1.1 | D7: Diversified industrials / welding peers (ESAB, ITW, Kennametal, Snap-on) ~1.0–1.2; short-cycle industrial capex exposure, partly offset by consumables (~2/3 of welding sales) and automation growth
B8: Cost of equity | C8: =C5+C7*C6 -> 0.11
B9: Pre-tax cost of debt | C9: 0.055 | D9: Investment-grade private-placement notes (2024 Notes priced at 5.55%–5.74%); marginal cost ~5.5%
