Workbook

Sheet Model
AP1: SCENARIO SWITCH ▼ (Bull / Base / Bear) — drives all scenario-linked forecast drivers
B2: Loar Holdings Inc. (NYSE: LOAR) — 3-Statement Financial Model | AP2: Base
B3: US GAAP as reported · USD millions (per-share data in USD; shares in millions) · Source: Loar Forms 10-K / 10-Q, Form 8-K earnings releases (Ex. 99.1), deal 8-Ks and the IPO prospectus (424B4, 26-Apr-2024), SEC EDGAR CIK 0002000178 (investor-relations releases at ir.loargroup.com are the same documents as filed on EDGAR)
B4: Basis notes: calendar fiscal year; single reportable segment; all periods as originally reported. FY2012–21: prospectus net income → Adjusted EBITDA reconciliation only (FY2017 = predecessor Jan–Oct + successor Oct–Dec: acquisition of Loar Group Inc. by Loar Holdings, LLC, 2-Oct-2017). Loar Holdings, LLC to the IPO (29-Apr-2024; follow-on Dec-2024) — per-share data from Q2-24. Acquisitions: SCHROTH Jul-22, DAC Jul-23, CAV Sep-23, Applied Avionics Aug-24, Beadlight Jul-25, LMB Dec-25, Harper Engineering Jan-26. Adjusted EPS on the current definition (adds back amortization of acquired intangibles, from Q1-26) for all periods. Q3/26E–Q4/26E calibrated to FY26 sales and Adjusted EBITDA guidance.
AR5: Forecast | AS5: Historical | AT5: Historical | AU5: Historical
B6: (USDm) | C6: 2012 | D6: 2013 | E6: 2014 | F6: 2015 | G6: 2016 | H6: 2017 | I6: 2018 | J6: 2019 | K6: 2020 | L6: 2021 | M6: Q1/22 | N6: Q2/22 | O6: Q3/22 | P6: Q4/22 | Q6: 2022 | R6: Q1/23 | S6: Q2/23 | T6: Q3/23 | U6: Q4/23 | V6: 2023 | W6: Q1/24 | X6: Q2/24 | Y6: Q3/24 | Z6: Q4/24 | AA6: 2024 | AB6: Q1/25 | AC6: Q2/25 | AD6: Q3/25 | AE6: Q4/25 | AF6: 2025 | AG6: Q1/26 | AH6: Q2/26 | AI6: Q3/26E | AJ6: Q4/26E | AK6: 2026E | AL6: 2027E | AM6: 2028E | AN6: 2029E | AO6: 2030E | AP6: Modelling Notes | AR6: 5Y CAGR | AS6: 5Y CAGR | AT6: 10Y CAGR | AU6: 13Y CAGR
AR7: 25-'30 | AS7: 20-'25 | AT7: 15-'25 | AU7: 12-'25
B8: END-MARKET P&L — COMMERCIAL AEROSPACE · BUSINESS JET & GA · DEFENSE · OTHER (OEM × aftermarket build) | AP8: END-MARKET BUILD — modelling logic (OEM / aftermarket net sales by end market → net sales × Adjusted EBITDA margin → Adjusted EBITDA → GAAP P&L)
AX9: SCENARIO INPUT TABLE — driver assumptions per Bull / Base / Bear | AY9: Bull | AZ9: Base | BA9: Bear | BB9: Bull / Bear = Base + Δ (Δ inputs on each block header). Outlook block = high / mid / low end of the FY26 guidance ranges.
B10: Commercial aerospace (seat-belt & airbag restraints, interiors latches, fluid & ice protection, avionics interface) | AP10: COMMERCIAL AEROSPACE — modelling logic
B11: OEM net sales | Q11: 40.792 | R11: 12.211 | S11: 13.702 | T11: 14.574 | U11: 14.239 | V11: 54.726 | W11: 16.193 | X11: 14.299 | Y11: 15.824 | Z11: 18.695 | AA11: 65.011 | AB11: 16.064 | AC11: 19.44 | AD11: 20.659 | AE11: 21.228 | AF11: 77.391 | AG11: 31.521 | AH11: 37.16 | AI11: =AD11*(1+AI12) | AJ11: =AE11*(1+AJ12) | AK11: =SUM(AG11,AH11,AI11,AJ11) | AL11: =AK11*(1+AL12) | AM11: =AL11*(1+AM12) | AN11: =AM11*(1+AN12) | AO11: =AN11*(1+AO12) | AP11: End-market sales as published (release Table 5; FY2022-23 prospectus note; Q1-23 = 1H-23 − Q2-23). Not published before 2022 or for 2022 quarters. Q3/Q4-26E: prior-year quarter × (1 + growth). 2027E+: prior year × (1 + scenario lever). | AX11: FY26 outlook — Q2-26 release (6-Aug-26) | AY11: High | AZ11: Mid | BA11: Low | BB11: Raised in the Q2-26 release (from $645–655m sales / $257–262m Adjusted EBITDA / $1.26–1.30 Adjusted EPS in Q1-26). Includes LMB (Dec-25) and Harper Engineering (Jan-26).
B12: y/y % | D12: =IF(AND(ISNUMBER(D11),ISNUMBER(C11)),IFERROR(D11/C11-1,""),"") | E12: =IF(AND(ISNUMBER(E11),ISNUMBER(D11)),IFERROR(E11/D11-1,""),"") | F12: =IF(AND(ISNUMBER(F11),ISNUMBER(E11)),IFERROR(F11/E11-1,""),"") | G12: =IF(AND(ISNUMBER(G11),ISNUMBER(F11)),IFERROR(G11/F11-1,""),"") | H12: =IF(AND(ISNUMBER(H11),ISNUMBER(G11)),IFERROR(H11/G11-1,""),"") | I12: =IF(AND(ISNUMBER(I11),ISNUMBER(H11)),IFERROR(I11/H11-1,""),"") | J12: =IF(AND(ISNUMBER(J11),ISNUMBER(I11)),IFERROR(J11/I11-1,""),"") | K12: =IF(AND(ISNUMBER(K11),ISNUMBER(J11)),IFERROR(K11/J11-1,""),"") | L12: =IF(AND(ISNUMBER(L11),ISNUMBER(K11)),IFERROR(L11/K11-1,""),"") | Q12: =IF(AND(ISNUMBER(Q11),ISNUMBER(L11)),IFERROR(Q11/L11-1,""),"") | R12: =IF(AND(ISNUMBER(R11),ISNUMBER(M11)),IFERROR(R11/M11-1,""),"") | S12: =IF(AND(ISNUMBER(S11),ISNUMBER(N11)),IFERROR(S11/N11-1,""),"") | T12: =IF(AND(ISNUMBER(T11),ISNUMBER(O11)),IFERROR(T11/O11-1,""),"") | U12: =IF(AND(ISNUMBER(U11),ISNUMBER(P11)),IFERROR(U11/P11-1,""),"") | V12: =IF(AND(ISNUMBER(V11),ISNUMBER(Q11)),IFERROR(V11/Q11-1,""),"") | W12: =IF(AND(ISNUMBER(W11),ISNUMBER(R11)),IFERROR(W11/R11-1,""),"") | X12: =IF(AND(ISNUMBER(X11),ISNUMBER(S11)),IFERROR(X11/S11-1,""),"") | ... AH12: =IF(AND(ISNUMBER(AH11),ISNUMBER(AC11)),IFERROR(AH11/AC11-1,""),"") | AI12: =AI13+$AI$101 | AJ12: =AJ13+$AI$101 | AK12: =IF(AND(ISNUMBER(AK11),ISNUMBER(AF11)),IFERROR(AK11/AF11-1,""),"") | AL12: =CHOOSE(MATCH($AP$2,{"Bull","Base","Bear"},0),$AY$29,$AZ$29,$BA$29) | AM12: =CHOOSE(MATCH($AP$2,{"Bull","Base","Bear"},0),$AY$30,$AZ$30,$BA$30) | AN12: =CHOOSE(MATCH($AP$2,{"Bull","Base","Bear"},0),$AY$31,$AZ$31,$BA$31) | AO12: =CHOOSE(MATCH($AP$2,{"Bull","Base","Bear"},0),$AY$32,$AZ$32,$BA$32) | AP12: Q3/Q4-26E: growth before calibration (row below) + revenue-outlook calibration Δ (Group block). 2027E–2030E: scenario lever (Bull/Base/Bear table →). | AX12: FY26 net sales ($m) | AY12: 675 | AZ12: 670 | BA12: 665 | BB12: Guided $665–675m (+35% y/y at mid). Drives the Q3/Q4-26E revenue calibration.
B13: Q3/Q4-26E growth before revenue calibration (1H/26 y/y) | AI13: =IFERROR((AG11+AH11)/(AB11+AC11)-1,0) | AJ13: =IFERROR((AG11+AH11)/(AB11+AC11)-1,0) | AP13: 1H/26 y/y growth of the line: includes LMB (closed 23-Dec-2025) and Harper Engineering (21-Jan-2026), which stay inorganic through Q4/26E; Beadlight anniversaries 28-Jul-2026. | AX13: FY26 Adjusted EBITDA ($m) | AY13: 270 | AZ13: 267.5 | BA13: 265 | BB13: Guided $265–270m (~40% margin). Drives the Q3/Q4-26E margin calibration.
B14: Aftermarket net sales | Q14: 66.697 | R14: 22.919 | S14: 20.211 | T14: 23.886 | U14: 22.188 | V14: 89.204 | W14: 25.149 | X14: 26.894 | Y14: 29.058 | Z14: 28.204 | AA14: 109.305 | AB14: 32.403 | AC14: 34.836 | AD14: 38.169 | AE14: 39.06 | AF14: 144.468 | AG14: 43.515 | AH14: 46.256 | AI14: =AD14*(1+AI15) | AJ14: =AE14*(1+AJ15) | AK14: =SUM(AG14,AH14,AI14,AJ14) | AL14: =AK14*(1+AL15) | AM14: =AL14*(1+AM15) | AN14: =AM14*(1+AN15) | AO14: =AN14*(1+AO15) | AX14: FY26 net income ($m) — memo | AY14: 60 | AZ14: 58 | BA14: 56 | BB14: Guided $56–60m (memo; compared with the model, not forced).
B15: y/y % | D15: =IF(AND(ISNUMBER(D14),ISNUMBER(C14)),IFERROR(D14/C14-1,""),"") | E15: =IF(AND(ISNUMBER(E14),ISNUMBER(D14)),IFERROR(E14/D14-1,""),"") | F15: =IF(AND(ISNUMBER(F14),ISNUMBER(E14)),IFERROR(F14/E14-1,""),"") | G15: =IF(AND(ISNUMBER(G14),ISNUMBER(F14)),IFERROR(G14/F14-1,""),"") | H15: =IF(AND(ISNUMBER(H14),ISNUMBER(G14)),IFERROR(H14/G14-1,""),"") | I15: =IF(AND(ISNUMBER(I14),ISNUMBER(H14)),IFERROR(I14/H14-1,""),"") | J15: =IF(AND(ISNUMBER(J14),ISNUMBER(I14)),IFERROR(J14/I14-1,""),"") | K15: =IF(AND(ISNUMBER(K14),ISNUMBER(J14)),IFERROR(K14/J14-1,""),"") | L15: =IF(AND(ISNUMBER(L14),ISNUMBER(K14)),IFERROR(L14/K14-1,""),"") | Q15: =IF(AND(ISNUMBER(Q14),ISNUMBER(L14)),IFERROR(Q14/L14-1,""),"") | R15: =IF(AND(ISNUMBER(R14),ISNUMBER(M14)),IFERROR(R14/M14-1,""),"") | S15: =IF(AND(ISNUMBER(S14),ISNUMBER(N14)),IFERROR(S14/N14-1,""),"") | T15: =IF(AND(ISNUMBER(T14),ISNUMBER(O14)),IFERROR(T14/O14-1,""),"") | U15: =IF(AND(ISNUMBER(U14),ISNUMBER(P14)),IFERROR(U14/P14-1,""),"") | V15: =IF(AND(ISNUMBER(V14),ISNUMBER(Q14)),IFERROR(V14/Q14-1,""),"") | W15: =IF(AND(ISNUMBER(W14),ISNUMBER(R14)),IFERROR(W14/R14-1,""),"") | X15: =IF(AND(ISNUMBER(X14),ISNUMBER(S14)),IFERROR(X14/S14-1,""),"") | ... AH15: =IF(AND(ISNUMBER(AH14),ISNUMBER(AC14)),IFERROR(AH14/AC14-1,""),"") | AI15: =AI16+$AI$101 | AJ15: =AJ16+$AI$101 | AK15: =IF(AND(ISNUMBER(AK14),ISNUMBER(AF14)),IFERROR(AK14/AF14-1,""),"") | AL15: =CHOOSE(MATCH($AP$2,{"Bull","Base","Bear"},0),$AY$34,$AZ$34,$BA$34) | AM15: =CHOOSE(MATCH($AP$2,{"Bull","Base","Bear"},0),$AY$35,$AZ$35,$BA$35) | AN15: =CHOOSE(MATCH($AP$2,{"Bull","Base","Bear"},0),$AY$36,$AZ$36,$BA$36) | AO15: =CHOOSE(MATCH($AP$2,{"Bull","Base","Bear"},0),$AY$37,$AZ$37,$BA$37) | AX15: FY26 Adjusted EPS ($, current definition) — memo | AY15: 1.36 | AZ15: 1.34 | BA15: 1.32 | BB15: Guided $1.32–1.36 (diluted EPS $0.57–0.62).
B16: Q3/Q4-26E growth before revenue calibration (1H/26 y/y) | AI16: =IFERROR((AG14+AH14)/(AB14+AC14)-1,0) | AJ16: =IFERROR((AG14+AH14)/(AB14+AC14)-1,0) | AX16: 2H/26 share repurchases ($m) | AY16: 0 | AZ16: 0 | BA16: 0 | BB16: No repurchase authorization; capital deployed to M&A / deleveraging.
B17: Commercial aerospace — net sales | C17: =IF(ISNUMBER(C11),C11+C14,"") | D17: =IF(ISNUMBER(D11),D11+D14,"") | E17: =IF(ISNUMBER(E11),E11+E14,"") | F17: =IF(ISNUMBER(F11),F11+F14,"") | G17: =IF(ISNUMBER(G11),G11+G14,"") | H17: =IF(ISNUMBER(H11),H11+H14,"") | I17: =IF(ISNUMBER(I11),I11+I14,"") | J17: =IF(ISNUMBER(J11),J11+J14,"") | ... AO17: =IF(ISNUMBER(AO11),AO11+AO14,"") | AR17: =IFERROR((AO17/AF17)^(1/5)-1,"n/m") | AS17: =IFERROR((AF17/K17)^(1/5)-1,"n/m") | AT17: =IFERROR((AF17/F17)^(1/10)-1,"n/m") | AU17: =IFERROR((AF17/C17)^(1/13)-1,"n/m")
B18: Net sales y/y % | D18: =IF(AND(ISNUMBER(D17),ISNUMBER(C17)),IFERROR(D17/C17-1,""),"") | E18: =IF(AND(ISNUMBER(E17),ISNUMBER(D17)),IFERROR(E17/D17-1,""),"") | F18: =IF(AND(ISNUMBER(F17),ISNUMBER(E17)),IFERROR(F17/E17-1,""),"") | G18: =IF(AND(ISNUMBER(G17),ISNUMBER(F17)),IFERROR(G17/F17-1,""),"") | H18: =IF(AND(ISNUMBER(H17),ISNUMBER(G17)),IFERROR(H17/G17-1,""),"") | I18: =IF(AND(ISNUMBER(I17),ISNUMBER(H17)),IFERROR(I17/H17-1,""),"") | J18: =IF(AND(ISNUMBER(J17),ISNUMBER(I17)),IFERROR(J17/I17-1,""),"") | K18: =IF(AND(ISNUMBER(K17),ISNUMBER(J17)),IFERROR(K17/J17-1,""),"") | L18: =IF(AND(ISNUMBER(L17),ISNUMBER(K17)),IFERROR(L17/K17-1,""),"") | Q18: =IF(AND(ISNUMBER(Q17),ISNUMBER(L17)),IFERROR(Q17/L17-1,""),"") | R18: =IF(AND(ISNUMBER(R17),ISNUMBER(M17)),IFERROR(R17/M17-1,""),"") | S18: =IF(AND(ISNUMBER(S17),ISNUMBER(N17)),IFERROR(S17/N17-1,""),"") | T18: =IF(AND(ISNUMBER(T17),ISNUMBER(O17)),IFERROR(T17/O17-1,""),"") | U18: =IF(AND(ISNUMBER(U17),ISNUMBER(P17)),IFERROR(U17/P17-1,""),"") | V18: =IF(AND(ISNUMBER(V17),ISNUMBER(Q17)),IFERROR(V17/Q17-1,""),"") | W18: =IF(AND(ISNUMBER(W17),ISNUMBER(R17)),IFERROR(W17/R17-1,""),"") | X18: =IF(AND(ISNUMBER(X17),ISNUMBER(S17)),IFERROR(X17/S17-1,""),"") | ... AK18: =IF(AND(ISNUMBER(AK17),ISNUMBER(AF17)),IFERROR(AK17/AF17-1,""),"") | AL18: =IF(AND(ISNUMBER(AL17),ISNUMBER(AK17)),IFERROR(AL17/AK17-1,""),"") | AM18: =IF(AND(ISNUMBER(AM17),ISNUMBER(AL17)),IFERROR(AM17/AL17-1,""),"") | AN18: =IF(AND(ISNUMBER(AN17),ISNUMBER(AM17)),IFERROR(AN17/AM17-1,""),"") | AO18: =IF(AND(ISNUMBER(AO17),ISNUMBER(AN17)),IFERROR(AO17/AN17-1,""),"") | AX18: FY26 point estimates (all cases)
B19: % of total net sales | C19: =IF(AND(ISNUMBER(C17),ISNUMBER(C90)),IFERROR(C17/C90,""),"") | D19: =IF(AND(ISNUMBER(D17),ISNUMBER(D90)),IFERROR(D17/D90,""),"") | E19: =IF(AND(ISNUMBER(E17),ISNUMBER(E90)),IFERROR(E17/E90,""),"") | F19: =IF(AND(ISNUMBER(F17),ISNUMBER(F90)),IFERROR(F17/F90,""),"") | G19: =IF(AND(ISNUMBER(G17),ISNUMBER(G90)),IFERROR(G17/G90,""),"") | H19: =IF(AND(ISNUMBER(H17),ISNUMBER(H90)),IFERROR(H17/H90,""),"") | I19: =IF(AND(ISNUMBER(I17),ISNUMBER(I90)),IFERROR(I17/I90,""),"") | J19: =IF(AND(ISNUMBER(J17),ISNUMBER(J90)),IFERROR(J17/J90,""),"") | ... AO19: =IF(AND(ISNUMBER(AO17),ISNUMBER(AO90)),IFERROR(AO17/AO90,""),"") | AX19: Interest expense, net ($m) | AZ19: 80 | BB19: FY26 guidance: ~$80m (1H/26 $38.7m).
B20: Aftermarket % of end-market sales | C20: =IF(AND(ISNUMBER(C14),ISNUMBER(C17)),IFERROR(C14/C17,""),"") | D20: =IF(AND(ISNUMBER(D14),ISNUMBER(D17)),IFERROR(D14/D17,""),"") | E20: =IF(AND(ISNUMBER(E14),ISNUMBER(E17)),IFERROR(E14/E17,""),"") | F20: =IF(AND(ISNUMBER(F14),ISNUMBER(F17)),IFERROR(F14/F17,""),"") | G20: =IF(AND(ISNUMBER(G14),ISNUMBER(G17)),IFERROR(G14/G17,""),"") | H20: =IF(AND(ISNUMBER(H14),ISNUMBER(H17)),IFERROR(H14/H17,""),"") | I20: =IF(AND(ISNUMBER(I14),ISNUMBER(I17)),IFERROR(I14/I17,""),"") | J20: =IF(AND(ISNUMBER(J14),ISNUMBER(J17)),IFERROR(J14/J17,""),"") | ... AO20: =IF(AND(ISNUMBER(AO14),ISNUMBER(AO17)),IFERROR(AO14/AO17,""),"") | AX20: Depreciation ($m) | AZ20: 15 | BB20: FY26 guidance: ~$15m (1H/26 $6.6m).
AX21: Amortization ($m) | AZ21: 65 | BB21: FY26 guidance: ~$65m (1H/26 $32.3m).
B22: Business jet & general aviation (auto-throttles, brakes, actuation, restraints) | AP22: BUSINESS JET & GENERAL AVIATION — modelling logic | AX22: Tax rate (GAAP & adjusted) | AZ22: 0.24 | BB22: 1H/26 effective rate 23.9% (Q2-26 23.3%); not guided. Net income guidance mid-point implies ~24%.
B23: OEM net sales | Q23: 31.207 | R23: 9.26 | S23: 10.43 | T23: 11.701 | U23: 15.625 | V23: 47.016 | W23: 16.207 | X23: 17.438 | Y23: 19.911 | Z23: 16.542 | AA23: 70.098 | AB23: 19.423 | AC23: 17.895 | AD23: 19.859 | AE23: 17.568 | AF23: 74.745 | AG23: 19.633 | AH23: 20.304 | AI23: =AD23*(1+AI24) | AJ23: =AE23*(1+AJ24) | AK23: =SUM(AG23,AH23,AI23,AJ23) | AL23: =AK23*(1+AL24) | AM23: =AL23*(1+AM24) | AN23: =AM23*(1+AN24) | AO23: =AN23*(1+AO24) | AP23: End-market sales as published (release Table 5; FY2022-23 prospectus note; Q1-23 = 1H-23 − Q2-23). Not published before 2022 or for 2022 quarters. Q3/Q4-26E: prior-year quarter × (1 + growth). 2027E+: prior year × (1 + scenario lever). | AX23: Capital expenditures ($m) | AZ23: 16 | BB23: Not guided; 1H/26 $7.0m, FY25 $13.0m; ~2.4% of FY26E sales.
B24: y/y % | D24: =IF(AND(ISNUMBER(D23),ISNUMBER(C23)),IFERROR(D23/C23-1,""),"") | E24: =IF(AND(ISNUMBER(E23),ISNUMBER(D23)),IFERROR(E23/D23-1,""),"") | F24: =IF(AND(ISNUMBER(F23),ISNUMBER(E23)),IFERROR(F23/E23-1,""),"") | G24: =IF(AND(ISNUMBER(G23),ISNUMBER(F23)),IFERROR(G23/F23-1,""),"") | H24: =IF(AND(ISNUMBER(H23),ISNUMBER(G23)),IFERROR(H23/G23-1,""),"") | I24: =IF(AND(ISNUMBER(I23),ISNUMBER(H23)),IFERROR(I23/H23-1,""),"") | J24: =IF(AND(ISNUMBER(J23),ISNUMBER(I23)),IFERROR(J23/I23-1,""),"") | K24: =IF(AND(ISNUMBER(K23),ISNUMBER(J23)),IFERROR(K23/J23-1,""),"") | L24: =IF(AND(ISNUMBER(L23),ISNUMBER(K23)),IFERROR(L23/K23-1,""),"") | Q24: =IF(AND(ISNUMBER(Q23),ISNUMBER(L23)),IFERROR(Q23/L23-1,""),"") | R24: =IF(AND(ISNUMBER(R23),ISNUMBER(M23)),IFERROR(R23/M23-1,""),"") | S24: =IF(AND(ISNUMBER(S23),ISNUMBER(N23)),IFERROR(S23/N23-1,""),"") | T24: =IF(AND(ISNUMBER(T23),ISNUMBER(O23)),IFERROR(T23/O23-1,""),"") | U24: =IF(AND(ISNUMBER(U23),ISNUMBER(P23)),IFERROR(U23/P23-1,""),"") | V24: =IF(AND(ISNUMBER(V23),ISNUMBER(Q23)),IFERROR(V23/Q23-1,""),"") | W24: =IF(AND(ISNUMBER(W23),ISNUMBER(R23)),IFERROR(W23/R23-1,""),"") | X24: =IF(AND(ISNUMBER(X23),ISNUMBER(S23)),IFERROR(X23/S23-1,""),"") | ... AH24: =IF(AND(ISNUMBER(AH23),ISNUMBER(AC23)),IFERROR(AH23/AC23-1,""),"") | AI24: =AI25+$AI$101 | AJ24: =AJ25+$AI$101 | AK24: =IF(AND(ISNUMBER(AK23),ISNUMBER(AF23)),IFERROR(AK23/AF23-1,""),"") | AL24: =CHOOSE(MATCH($AP$2,{"Bull","Base","Bear"},0),$AY$39,$AZ$39,$BA$39) | AM24: =CHOOSE(MATCH($AP$2,{"Bull","Base","Bear"},0),$AY$40,$AZ$40,$BA$40) | AN24: =CHOOSE(MATCH($AP$2,{"Bull","Base","Bear"},0),$AY$41,$AZ$41,$BA$41) | AO24: =CHOOSE(MATCH($AP$2,{"Bull","Base","Bear"},0),$AY$42,$AZ$42,$BA$42) | AP24: Q3/Q4-26E: growth before calibration (row below) + revenue-outlook calibration Δ (Group block). 2027E–2030E: scenario lever (Bull/Base/Bear table →). | AX24: Transaction expenses ($m) | AZ24: 4 | BB24: 1H/26 $2.8m (Harper Engineering); analyst point estimate for ongoing deal activity.
B25: Q3/Q4-26E growth before revenue calibration (1H/26 y/y) | AI25: =IFERROR((AG23+AH23)/(AB23+AC23)-1,0) | AJ25: =IFERROR((AG23+AH23)/(AB23+AC23)-1,0) | AP25: 1H/26 y/y growth of the line: includes LMB (closed 23-Dec-2025) and Harper Engineering (21-Jan-2026), which stay inorganic through Q4/26E; Beadlight anniversaries 28-Jul-2026.
B26: Aftermarket net sales | Q26: 17.053 | R26: 6.479 | S26: 6.308 | T26: 7.729 | U26: 8.512 | V26: 29.028 | W26: 9.407 | X26: 9.725 | Y26: 10.121 | Z26: 9.853 | AA26: 39.106 | AB26: 11.435 | AC26: 12.267 | AD26: 12.738 | AE26: 12.936 | AF26: 49.376 | AG26: 11.066 | AH26: 13.099 | AI26: =AD26*(1+AI27) | AJ26: =AE26*(1+AJ27) | AK26: =SUM(AG26,AH26,AI26,AJ26) | AL26: =AK26*(1+AL27) | AM26: =AL26*(1+AM27) | AN26: =AM26*(1+AN27) | AO26: =AN26*(1+AO27) | AX26: Minimum net debt / Adjusted EBITDA (x) — buyback floor 2027E+ | AY26: 3 | AZ26: 2.5 | BA26: 2 | BB26: Net debt $830m at 30-Jun-26 = ~3.6x LTM Adjusted EBITDA (~3.1x FY26E guidance mid-point) after LMB / Harper; < 5.5x keeps the SOFR + 4.25% margin. Floor = leverage at which surplus cash is returned via buybacks; until then free cash flow prepays term loans. Bull keeps more firepower deployed (higher floor).
B27: y/y % | D27: =IF(AND(ISNUMBER(D26),ISNUMBER(C26)),IFERROR(D26/C26-1,""),"") | E27: =IF(AND(ISNUMBER(E26),ISNUMBER(D26)),IFERROR(E26/D26-1,""),"") | F27: =IF(AND(ISNUMBER(F26),ISNUMBER(E26)),IFERROR(F26/E26-1,""),"") | G27: =IF(AND(ISNUMBER(G26),ISNUMBER(F26)),IFERROR(G26/F26-1,""),"") | H27: =IF(AND(ISNUMBER(H26),ISNUMBER(G26)),IFERROR(H26/G26-1,""),"") | I27: =IF(AND(ISNUMBER(I26),ISNUMBER(H26)),IFERROR(I26/H26-1,""),"") | J27: =IF(AND(ISNUMBER(J26),ISNUMBER(I26)),IFERROR(J26/I26-1,""),"") | K27: =IF(AND(ISNUMBER(K26),ISNUMBER(J26)),IFERROR(K26/J26-1,""),"") | L27: =IF(AND(ISNUMBER(L26),ISNUMBER(K26)),IFERROR(L26/K26-1,""),"") | Q27: =IF(AND(ISNUMBER(Q26),ISNUMBER(L26)),IFERROR(Q26/L26-1,""),"") | R27: =IF(AND(ISNUMBER(R26),ISNUMBER(M26)),IFERROR(R26/M26-1,""),"") | S27: =IF(AND(ISNUMBER(S26),ISNUMBER(N26)),IFERROR(S26/N26-1,""),"") | T27: =IF(AND(ISNUMBER(T26),ISNUMBER(O26)),IFERROR(T26/O26-1,""),"") | U27: =IF(AND(ISNUMBER(U26),ISNUMBER(P26)),IFERROR(U26/P26-1,""),"") | V27: =IF(AND(ISNUMBER(V26),ISNUMBER(Q26)),IFERROR(V26/Q26-1,""),"") | W27: =IF(AND(ISNUMBER(W26),ISNUMBER(R26)),IFERROR(W26/R26-1,""),"") | X27: =IF(AND(ISNUMBER(X26),ISNUMBER(S26)),IFERROR(X26/S26-1,""),"") | ... AH27: =IF(AND(ISNUMBER(AH26),ISNUMBER(AC26)),IFERROR(AH26/AC26-1,""),"") | AI27: =AI28+$AI$101 | AJ27: =AJ28+$AI$101 | AK27: =IF(AND(ISNUMBER(AK26),ISNUMBER(AF26)),IFERROR(AK26/AF26-1,""),"") | AL27: =CHOOSE(MATCH($AP$2,{"Bull","Base","Bear"},0),$AY$44,$AZ$44,$BA$44) | AM27: =CHOOSE(MATCH($AP$2,{"Bull","Base","Bear"},0),$AY$45,$AZ$45,$BA$45) | AN27: =CHOOSE(MATCH($AP$2,{"Bull","Base","Bear"},0),$AY$46,$AZ$46,$BA$46) | AO27: =CHOOSE(MATCH($AP$2,{"Bull","Base","Bear"},0),$AY$47,$AZ$47,$BA$47)
B28: Q3/Q4-26E growth before revenue calibration (1H/26 y/y) | AI28: =IFERROR((AG26+AH26)/(AB26+AC26)-1,0) | AJ28: =IFERROR((AG26+AH26)/(AB26+AC26)-1,0) | AX28: COM_OEM (commercial aerospace OEM sales y/y) | AY28: 0.03 | AZ28: Δ → | BA28: -0.06 | BB28: Boeing 737 / 787 and Airbus A320 / A350 rate ramps; Harper interiors latches; FY26 commercial + BJ OEM outlook +17–20%.
B29: Business jet & general aviation — net sales | C29: =IF(ISNUMBER(C23),C23+C26,"") | D29: =IF(ISNUMBER(D23),D23+D26,"") | E29: =IF(ISNUMBER(E23),E23+E26,"") | F29: =IF(ISNUMBER(F23),F23+F26,"") | G29: =IF(ISNUMBER(G23),G23+G26,"") | H29: =IF(ISNUMBER(H23),H23+H26,"") | I29: =IF(ISNUMBER(I23),I23+I26,"") | J29: =IF(ISNUMBER(J23),J23+J26,"") | ... AO29: =IF(ISNUMBER(AO23),AO23+AO26,"") | AR29: =IFERROR((AO29/AF29)^(1/5)-1,"n/m") | AS29: =IFERROR((AF29/K29)^(1/5)-1,"n/m") | AT29: =IFERROR((AF29/F29)^(1/10)-1,"n/m") | AU29: =IFERROR((AF29/C29)^(1/13)-1,"n/m") | AX29: 2027E | AY29: =AZ29+$AY$28 | AZ29: 0.14 | BA29: =AZ29+$BA$28
B30: Net sales y/y % | D30: =IF(AND(ISNUMBER(D29),ISNUMBER(C29)),IFERROR(D29/C29-1,""),"") | E30: =IF(AND(ISNUMBER(E29),ISNUMBER(D29)),IFERROR(E29/D29-1,""),"") | F30: =IF(AND(ISNUMBER(F29),ISNUMBER(E29)),IFERROR(F29/E29-1,""),"") | G30: =IF(AND(ISNUMBER(G29),ISNUMBER(F29)),IFERROR(G29/F29-1,""),"") | H30: =IF(AND(ISNUMBER(H29),ISNUMBER(G29)),IFERROR(H29/G29-1,""),"") | I30: =IF(AND(ISNUMBER(I29),ISNUMBER(H29)),IFERROR(I29/H29-1,""),"") | J30: =IF(AND(ISNUMBER(J29),ISNUMBER(I29)),IFERROR(J29/I29-1,""),"") | K30: =IF(AND(ISNUMBER(K29),ISNUMBER(J29)),IFERROR(K29/J29-1,""),"") | L30: =IF(AND(ISNUMBER(L29),ISNUMBER(K29)),IFERROR(L29/K29-1,""),"") | Q30: =IF(AND(ISNUMBER(Q29),ISNUMBER(L29)),IFERROR(Q29/L29-1,""),"") | R30: =IF(AND(ISNUMBER(R29),ISNUMBER(M29)),IFERROR(R29/M29-1,""),"") | S30: =IF(AND(ISNUMBER(S29),ISNUMBER(N29)),IFERROR(S29/N29-1,""),"") | T30: =IF(AND(ISNUMBER(T29),ISNUMBER(O29)),IFERROR(T29/O29-1,""),"") | U30: =IF(AND(ISNUMBER(U29),ISNUMBER(P29)),IFERROR(U29/P29-1,""),"") | V30: =IF(AND(ISNUMBER(V29),ISNUMBER(Q29)),IFERROR(V29/Q29-1,""),"") | W30: =IF(AND(ISNUMBER(W29),ISNUMBER(R29)),IFERROR(W29/R29-1,""),"") | X30: =IF(AND(ISNUMBER(X29),ISNUMBER(S29)),IFERROR(X29/S29-1,""),"") | ... AK30: =IF(AND(ISNUMBER(AK29),ISNUMBER(AF29)),IFERROR(AK29/AF29-1,""),"") | AL30: =IF(AND(ISNUMBER(AL29),ISNUMBER(AK29)),IFERROR(AL29/AK29-1,""),"") | AM30: =IF(AND(ISNUMBER(AM29),ISNUMBER(AL29)),IFERROR(AM29/AL29-1,""),"") | AN30: =IF(AND(ISNUMBER(AN29),ISNUMBER(AM29)),IFERROR(AN29/AM29-1,""),"") | AO30: =IF(AND(ISNUMBER(AO29),ISNUMBER(AN29)),IFERROR(AO29/AN29-1,""),"") | AX30: 2028E | AY30: =AZ30+$AY$28 | AZ30: 0.12 | BA30: =AZ30+$BA$28
B31: % of total net sales | C31: =IF(AND(ISNUMBER(C29),ISNUMBER(C90)),IFERROR(C29/C90,""),"") | D31: =IF(AND(ISNUMBER(D29),ISNUMBER(D90)),IFERROR(D29/D90,""),"") | E31: =IF(AND(ISNUMBER(E29),ISNUMBER(E90)),IFERROR(E29/E90,""),"") | F31: =IF(AND(ISNUMBER(F29),ISNUMBER(F90)),IFERROR(F29/F90,""),"") | G31: =IF(AND(ISNUMBER(G29),ISNUMBER(G90)),IFERROR(G29/G90,""),"") | H31: =IF(AND(ISNUMBER(H29),ISNUMBER(H90)),IFERROR(H29/H90,""),"") | I31: =IF(AND(ISNUMBER(I29),ISNUMBER(I90)),IFERROR(I29/I90,""),"") | J31: =IF(AND(ISNUMBER(J29),ISNUMBER(J90)),IFERROR(J29/J90,""),"") | ... AO31: =IF(AND(ISNUMBER(AO29),ISNUMBER(AO90)),IFERROR(AO29/AO90,""),"") | AX31: 2029E | AY31: =AZ31+$AY$28 | AZ31: 0.1 | BA31: =AZ31+$BA$28
B32: Aftermarket % of end-market sales | C32: =IF(AND(ISNUMBER(C26),ISNUMBER(C29)),IFERROR(C26/C29,""),"") | D32: =IF(AND(ISNUMBER(D26),ISNUMBER(D29)),IFERROR(D26/D29,""),"") | E32: =IF(AND(ISNUMBER(E26),ISNUMBER(E29)),IFERROR(E26/E29,""),"") | F32: =IF(AND(ISNUMBER(F26),ISNUMBER(F29)),IFERROR(F26/F29,""),"") | G32: =IF(AND(ISNUMBER(G26),ISNUMBER(G29)),IFERROR(G26/G29,""),"") | H32: =IF(AND(ISNUMBER(H26),ISNUMBER(H29)),IFERROR(H26/H29,""),"") | I32: =IF(AND(ISNUMBER(I26),ISNUMBER(I29)),IFERROR(I26/I29,""),"") | J32: =IF(AND(ISNUMBER(J26),ISNUMBER(J29)),IFERROR(J26/J29,""),"") | ... AO32: =IF(AND(ISNUMBER(AO26),ISNUMBER(AO29)),IFERROR(AO26/AO29,""),"") | AX32: 2030E | AY32: =AZ32+$AY$28 | AZ32: 0.09 | BA32: =AZ32+$BA$28
AX33: COM_AM (commercial aerospace aftermarket y/y) | AY33: 0.02 | AZ33: Δ → | BA33: -0.04 | BB33: Installed-base growth, aging fleets and price (proprietary, sole-source parts); FY26 outlook low-double digits.
B34: Defense (military aircraft components, restraints, sensors; LMB fans & motors from Dec-2025) | AP34: DEFENSE — modelling logic | AX34: 2027E | AY34: =AZ34+$AY$33 | AZ34: 0.1 | BA34: =AZ34+$BA$33
B35: OEM net sales | Q35: 26.631 | R35: 7.392 | S35: 7.15 | T35: 8.004 | U35: 7.853 | V35: 30.399 | W35: 7.786 | X35: 8.855 | Y35: 10.152 | Z35: 11.523 | AA35: 38.316 | AB35: 11.726 | AC35: 14.332 | AD35: 13.752 | AE35: 16.16 | AF35: 55.97 | AG35: 23.042 | AH35: 26.971 | AI35: =AD35*(1+AI36) | AJ35: =AE35*(1+AJ36) | AK35: =SUM(AG35,AH35,AI35,AJ35) | AL35: =AK35*(1+AL36) | AM35: =AL35*(1+AM36) | AN35: =AM35*(1+AN36) | AO35: =AN35*(1+AO36) | AP35: End-market sales as published (release Table 5; FY2022-23 prospectus note; Q1-23 = 1H-23 − Q2-23). Not published before 2022 or for 2022 quarters. Q3/Q4-26E: prior-year quarter × (1 + growth). 2027E+: prior year × (1 + scenario lever). | AX35: 2028E | AY35: =AZ35+$AY$33 | AZ35: 0.09 | BA35: =AZ35+$BA$33
B36: y/y % | D36: =IF(AND(ISNUMBER(D35),ISNUMBER(C35)),IFERROR(D35/C35-1,""),"") | E36: =IF(AND(ISNUMBER(E35),ISNUMBER(D35)),IFERROR(E35/D35-1,""),"") | F36: =IF(AND(ISNUMBER(F35),ISNUMBER(E35)),IFERROR(F35/E35-1,""),"") | G36: =IF(AND(ISNUMBER(G35),ISNUMBER(F35)),IFERROR(G35/F35-1,""),"") | H36: =IF(AND(ISNUMBER(H35),ISNUMBER(G35)),IFERROR(H35/G35-1,""),"") | I36: =IF(AND(ISNUMBER(I35),ISNUMBER(H35)),IFERROR(I35/H35-1,""),"") | J36: =IF(AND(ISNUMBER(J35),ISNUMBER(I35)),IFERROR(J35/I35-1,""),"") | K36: =IF(AND(ISNUMBER(K35),ISNUMBER(J35)),IFERROR(K35/J35-1,""),"") | L36: =IF(AND(ISNUMBER(L35),ISNUMBER(K35)),IFERROR(L35/K35-1,""),"") | Q36: =IF(AND(ISNUMBER(Q35),ISNUMBER(L35)),IFERROR(Q35/L35-1,""),"") | R36: =IF(AND(ISNUMBER(R35),ISNUMBER(M35)),IFERROR(R35/M35-1,""),"") | S36: =IF(AND(ISNUMBER(S35),ISNUMBER(N35)),IFERROR(S35/N35-1,""),"") | T36: =IF(AND(ISNUMBER(T35),ISNUMBER(O35)),IFERROR(T35/O35-1,""),"") | U36: =IF(AND(ISNUMBER(U35),ISNUMBER(P35)),IFERROR(U35/P35-1,""),"") | V36: =IF(AND(ISNUMBER(V35),ISNUMBER(Q35)),IFERROR(V35/Q35-1,""),"") | W36: =IF(AND(ISNUMBER(W35),ISNUMBER(R35)),IFERROR(W35/R35-1,""),"") | X36: =IF(AND(ISNUMBER(X35),ISNUMBER(S35)),IFERROR(X35/S35-1,""),"") | ... AH36: =IF(AND(ISNUMBER(AH35),ISNUMBER(AC35)),IFERROR(AH35/AC35-1,""),"") | AI36: =AI37+$AI$101 | AJ36: =AJ37+$AI$101 | AK36: =IF(AND(ISNUMBER(AK35),ISNUMBER(AF35)),IFERROR(AK35/AF35-1,""),"") | AL36: =CHOOSE(MATCH($AP$2,{"Bull","Base","Bear"},0),$AY$49,$AZ$49,$BA$49) | AM36: =CHOOSE(MATCH($AP$2,{"Bull","Base","Bear"},0),$AY$50,$AZ$50,$BA$50) | AN36: =CHOOSE(MATCH($AP$2,{"Bull","Base","Bear"},0),$AY$51,$AZ$51,$BA$51) | AO36: =CHOOSE(MATCH($AP$2,{"Bull","Base","Bear"},0),$AY$52,$AZ$52,$BA$52) | AP36: Q3/Q4-26E: growth before calibration (row below) + revenue-outlook calibration Δ (Group block). 2027E–2030E: scenario lever (Bull/Base/Bear table →). | AX36: 2029E | AY36: =AZ36+$AY$33 | AZ36: 0.08 | BA36: =AZ36+$BA$33
B37: Q3/Q4-26E growth before revenue calibration (1H/26 y/y) | AI37: =IFERROR((AG35+AH35)/(AB35+AC35)-1,0) | AJ37: =IFERROR((AG35+AH35)/(AB35+AC35)-1,0) | AP37: 1H/26 y/y growth of the line: includes LMB (closed 23-Dec-2025) and Harper Engineering (21-Jan-2026), which stay inorganic through Q4/26E; Beadlight anniversaries 28-Jul-2026. | AX37: 2030E | AY37: =AZ37+$AY$33 | AZ37: 0.08 | BA37: =AZ37+$BA$33
B38: Aftermarket net sales | Q38: 31.554 | R38: 7.842 | S38: 5.996 | T38: 7.218 | U38: 7.783 | V38: 28.839 | W38: 8.849 | X38: 12.022 | Y38: 11.81 | Z38: 17.951 | AA38: 50.632 | AB38: 17.056 | AC38: 17.139 | AD38: 15.032 | AE38: 17.442 | AF38: 66.669 | AG38: 17.607 | AH38: 18.062 | AI38: =AD38*(1+AI39) | AJ38: =AE38*(1+AJ39) | AK38: =SUM(AG38,AH38,AI38,AJ38) | AL38: =AK38*(1+AL39) | AM38: =AL38*(1+AM39) | AN38: =AM38*(1+AN39) | AO38: =AN38*(1+AO39) | AX38: BJ_OEM (business jet & GA OEM y/y) | AY38: 0.02 | AZ38: Δ → | BA38: -0.05 | BB38: Business-jet deliveries (Gulfstream G700/G800, Bombardier Global 8000, Textron); auto-throttle content.
B39: y/y % | D39: =IF(AND(ISNUMBER(D38),ISNUMBER(C38)),IFERROR(D38/C38-1,""),"") | E39: =IF(AND(ISNUMBER(E38),ISNUMBER(D38)),IFERROR(E38/D38-1,""),"") | F39: =IF(AND(ISNUMBER(F38),ISNUMBER(E38)),IFERROR(F38/E38-1,""),"") | G39: =IF(AND(ISNUMBER(G38),ISNUMBER(F38)),IFERROR(G38/F38-1,""),"") | H39: =IF(AND(ISNUMBER(H38),ISNUMBER(G38)),IFERROR(H38/G38-1,""),"") | I39: =IF(AND(ISNUMBER(I38),ISNUMBER(H38)),IFERROR(I38/H38-1,""),"") | J39: =IF(AND(ISNUMBER(J38),ISNUMBER(I38)),IFERROR(J38/I38-1,""),"") | K39: =IF(AND(ISNUMBER(K38),ISNUMBER(J38)),IFERROR(K38/J38-1,""),"") | L39: =IF(AND(ISNUMBER(L38),ISNUMBER(K38)),IFERROR(L38/K38-1,""),"") | Q39: =IF(AND(ISNUMBER(Q38),ISNUMBER(L38)),IFERROR(Q38/L38-1,""),"") | R39: =IF(AND(ISNUMBER(R38),ISNUMBER(M38)),IFERROR(R38/M38-1,""),"") | S39: =IF(AND(ISNUMBER(S38),ISNUMBER(N38)),IFERROR(S38/N38-1,""),"") | T39: =IF(AND(ISNUMBER(T38),ISNUMBER(O38)),IFERROR(T38/O38-1,""),"") | U39: =IF(AND(ISNUMBER(U38),ISNUMBER(P38)),IFERROR(U38/P38-1,""),"") | V39: =IF(AND(ISNUMBER(V38),ISNUMBER(Q38)),IFERROR(V38/Q38-1,""),"") | W39: =IF(AND(ISNUMBER(W38),ISNUMBER(R38)),IFERROR(W38/R38-1,""),"") | X39: =IF(AND(ISNUMBER(X38),ISNUMBER(S38)),IFERROR(X38/S38-1,""),"") | ... AH39: =IF(AND(ISNUMBER(AH38),ISNUMBER(AC38)),IFERROR(AH38/AC38-1,""),"") | AI39: =AI40+$AI$101 | AJ39: =AJ40+$AI$101 | AK39: =IF(AND(ISNUMBER(AK38),ISNUMBER(AF38)),IFERROR(AK38/AF38-1,""),"") | AL39: =CHOOSE(MATCH($AP$2,{"Bull","Base","Bear"},0),$AY$54,$AZ$54,$BA$54) | AM39: =CHOOSE(MATCH($AP$2,{"Bull","Base","Bear"},0),$AY$55,$AZ$55,$BA$55) | AN39: =CHOOSE(MATCH($AP$2,{"Bull","Base","Bear"},0),$AY$56,$AZ$56,$BA$56) | AO39: =CHOOSE(MATCH($AP$2,{"Bull","Base","Bear"},0),$AY$57,$AZ$57,$BA$57) | AX39: 2027E | AY39: =AZ39+$AY$38 | AZ39: 0.07 | BA39: =AZ39+$BA$38
B40: Q3/Q4-26E growth before revenue calibration (1H/26 y/y) | AI40: =IFERROR((AG38+AH38)/(AB38+AC38)-1,0) | AJ40: =IFERROR((AG38+AH38)/(AB38+AC38)-1,0) | AX40: 2028E | AY40: =AZ40+$AY$38 | AZ40: 0.06 | BA40: =AZ40+$BA$38
...

Sheet Bull-Base-Bear
B2: Loar Holdings (LOAR) — Bull / Base / Bear Case P&L Summary | J2: Share price ($): | K2: =Model!$AK$393
B3: Adjusted figures (company definitions: Adjusted EBITDA; Adjusted EPS on the current definition, adding back amortization of acquired intangibles) · USD millions · Live panel linked to Model — toggle scenario via Model!AP2. Bull and Bear panels are value snapshots generated from the Model with the switch set to each case. 2026E includes LMB (from 23-Dec-2025) and Harper Engineering (from 21-Jan-2026). | J3: As of: | K3: =TODAY()
B5: Scenario: | C5: =Model!$AP$2 | N5: Scenario: | O5: Bull | P5: Snapshot (values) — Model run with switch = Bull | Z5: Scenario: | AA5: Bear | AB5: Snapshot (values) — Model run with switch = Bear
B7: (USDm, except EPS and shares) | C7: 2025A | D7: 2026E | E7: 2027E | F7: 2028E | G7: 2029E | H7: 2030E | I7: 25-'30 CAGR | J7: LT Hist Avg | K7: LT Hist Min | L7: LT Hist Max | N7: (USDm, except EPS and shares) | O7: 2025A | P7: 2026E | Q7: 2027E | R7: 2028E | S7: 2029E | T7: 2030E | U7: 25-'30 CAGR | V7: LT Hist Avg | W7: LT Hist Min | X7: LT Hist Max | Z7: (USDm, except EPS and shares) | AA7: 2025A | AB7: 2026E | AC7: 2027E | AD7: 2028E | AE7: 2029E | AF7: 2030E | AG7: 25-'30 CAGR | AH7: LT Hist Avg | AI7: LT Hist Min | AJ7: LT Hist Max
B9: Net Sales | C9: =Model!AF127 | D9: =Model!AK127 | E9: =Model!AL127 | F9: =Model!AM127 | G9: =Model!AN127 | H9: =Model!AO127 | I9: =IFERROR((H9/C9)^(1/5)-1,"n/m") | N9: Net Sales | O9: 496.283 | P9: 675 | Q9: 794.54342 | R9: 963.20177 | S9: 1139.9748 | T9: 1326.5022 | U9: 0.21729466 | Z9: Net Sales | AA9: 496.283 | AB9: 665 | AC9: 697.87358 | AD9: 725.24344 | AE9: 747.81509 | AF9: 766.97823 | AG9: 0.090964773
B10: Net sales y/y % | D10: =IFERROR(D9/C9-1,"") | E10: =IFERROR(E9/D9-1,"") | F10: =IFERROR(F9/E9-1,"") | G10: =IFERROR(G9/F9-1,"") | H10: =IFERROR(H9/G9-1,"") | N10: Net sales y/y % | P10: 0.36011107 | Q10: 0.17710137 | R10: 0.21227077 | S10: 0.18352653 | T10: 0.16362411 | Z10: Net sales y/y % | AB10: 0.33996127 | AC10: 0.049433959 | AD10: 0.039218938 | AE10: 0.031122861 | AF10: 0.025625499
B11: Organic growth % | C11: =Model!AF220 | D11: =Model!AK220 | E11: =Model!AL220 | F11: =Model!AM220 | G11: =Model!AN220 | H11: =Model!AO220 | N11: Organic growth % | O11: 0.127 | P11: 0.11293959 | Q11: 0.11537297 | R11: 0.10558392 | S11: 0.09775088 | T11: 0.092412591 | Z11: Organic growth % | AA11: 0.127 | AB11: 0.092789799 | AC11: 0.049433959 | AD11: 0.039218938 | AE11: 0.031122861 | AF11: 0.025625499
B12: Adjusted EBITDA | C12: =Model!AF174 | D12: =Model!AK174 | E12: =Model!AL174 | F12: =Model!AM174 | G12: =Model!AN174 | H12: =Model!AO174 | I12: =IFERROR((H12/C12)^(1/5)-1,"n/m") | N12: Adjusted EBITDA | O12: 189.124 | P12: 270 | Q12: 329.11052 | R12: 401.92807 | S12: 478.83327 | T12: 560.54609 | U12: 0.242719 | Z12: Adjusted EBITDA | AA12: 189.124 | AB12: 265 | AC12: 265.19196 | AD12: 279.21873 | AE12: 291.64789 | AF12: 302.9564 | AG12: 0.098820359
B13: Adjusted EBITDA margin % | C13: =IFERROR(C12/C9,"") | D13: =IFERROR(D12/D9,"") | E13: =IFERROR(E12/E9,"") | F13: =IFERROR(F12/F9,"") | G13: =IFERROR(G12/G9,"") | H13: =IFERROR(H12/H9,"") | J13: =IFERROR(AVERAGE(Model!C175,Model!D175,Model!E175,Model!F175,Model!G175,Model!H175,Model!I175,Model!N175,Model!S175,Model!X175,Model!AC175,Model!AH175,Model!AM175,Model!AR175,Model!AW175,Model!BB175,Model!BG175,Model!BL175,Model!BQ175,Model!AF175),"") | K13: =IFERROR(MIN(Model!C175,Model!D175,Model!E175,Model!F175,Model!G175,Model!H175,Model!I175,Model!N175,Model!S175,Model!X175,Model!AC175,Model!AH175,Model!AM175,Model!AR175,Model!AW175,Model!BB175,Model!BG175,Model!BL175,Model!BQ175,Model!AF175),"") | L13: =IFERROR(MAX(Model!C175,Model!D175,Model!E175,Model!F175,Model!G175,Model!H175,Model!I175,Model!N175,Model!S175,Model!X175,Model!AC175,Model!AH175,Model!AM175,Model!AR175,Model!AW175,Model!BB175,Model!BG175,Model!BL175,Model!BQ175,Model!AF175),"") | N13: Adjusted EBITDA margin % | O13: 0.38108096 | P13: 0.4 | Q13: 0.41421338 | R13: 0.41728337 | S13: 0.42003845 | T13: 0.42257456 | V13: 0.32168135 | W13: 0.16764565 | X13: 0.41728337 | Z13: Adjusted EBITDA margin % | AA13: 0.38108096 | AB13: 0.39849624 | AC13: 0.38 | AD13: 0.385 | AE13: 0.39 | AF13: 0.395 | AH13: 0.31785428 | AI13: 0.16764565 | AJ13: 0.40476399
B15: Operating Income (GAAP) | C15: =Model!AF134 | D15: =Model!AK134 | E15: =Model!AL134 | F15: =Model!AM134 | G15: =Model!AN134 | H15: =Model!AO134 | I15: =IFERROR((H15/C15)^(1/5)-1,"n/m") | N15: Operating Income (GAAP) | O15: 106.243 | P15: 160.414 | Q15: 207.9391 | R15: 256.09439 | S15: 307.84781 | T15: 366.54065 | U15: 0.28104494 | Z15: Operating Income (GAAP) | AA15: 106.243 | AB15: 155.414 | AC15: 164.49403 | AD15: 177.30704 | AE15: 188.65276 | AF15: 201.64145 | AG15: 0.13672627
B16: Operating income y/y % | D16: =IFERROR(D15/C15-1,"") | E16: =IFERROR(E15/D15-1,"") | F16: =IFERROR(F15/E15-1,"") | G16: =IFERROR(G15/F15-1,"") | H16: =IFERROR(H15/G15-1,"") | N16: Operating income y/y % | P16: 0.5098783 | Q16: 0.29626531 | R16: 0.23158361 | S16: 0.20208728 | T16: 0.1906554 | Z16: Operating income y/y % | AB16: 0.46281637 | AC16: 0.058424785 | AD16: 0.077893471 | AE16: 0.063989122 | AF16: 0.068849685
B17: Operating margin (GAAP) % | C17: =IFERROR(C15/C9,"") | D17: =IFERROR(D15/D9,"") | E17: =IFERROR(E15/E9,"") | F17: =IFERROR(F15/F9,"") | G17: =IFERROR(G15/G9,"") | H17: =IFERROR(H15/H9,"") | J17: =IFERROR(AVERAGE(Model!C231,Model!D231,Model!E231,Model!F231,Model!G231,Model!H231,Model!I231,Model!N231,Model!S231,Model!X231,Model!AC231,Model!AH231,Model!AM231,Model!AR231,Model!AW231,Model!BB231,Model!BG231,Model!BL231,Model!BQ231,Model!AF231),"") | K17: =IFERROR(MIN(Model!C231,Model!D231,Model!E231,Model!F231,Model!G231,Model!H231,Model!I231,Model!N231,Model!S231,Model!X231,Model!AC231,Model!AH231,Model!AM231,Model!AR231,Model!AW231,Model!BB231,Model!BG231,Model!BL231,Model!BQ231,Model!AF231),"") | L17: =IFERROR(MAX(Model!C231,Model!D231,Model!E231,Model!F231,Model!G231,Model!H231,Model!I231,Model!N231,Model!S231,Model!X231,Model!AC231,Model!AH231,Model!AM231,Model!AR231,Model!AW231,Model!BB231,Model!BG231,Model!BL231,Model!BQ231,Model!AF231),"") | N17: Operating margin (GAAP) % | O17: 0.21407745 | P17: 0.23765037 | Q17: 0.26170892 | R17: 0.26587824 | S17: 0.2700479 | T17: 0.27632118 | V17: 0.12499872 | W17: -0.24991595 | X17: 0.26587824 | Z17: Operating margin (GAAP) % | AA17: 0.21407745 | AB17: 0.23370526 | AC17: 0.23570749 | AD17: 0.24447934 | AE17: 0.25227194 | AF17: 0.26290374 | AH17: 0.12247161 | AI17: -0.24991595 | AJ17: 0.24581355
B19: Adjusted Net Income | C19: =Model!AF202 | D19: =Model!AK202 | E19: =Model!AL202 | F19: =Model!AM202 | G19: =Model!AN202 | H19: =Model!AO202 | I19: =IFERROR((H19/C19)^(1/5)-1,"n/m") | N19: Adjusted Net Income | O19: 131.19987 | P19: 137.59084 | Q19: 193.17193 | R19: 228.47467 | S19: 266.666 | T19: 310.85746 | U19: 0.18829858 | Z19: Adjusted Net Income | AA19: 131.19987 | AB19: 133.79084 | AC19: 143.67701 | AD19: 164.39548 | AE19: 177.04488 | AF19: 183.92714 | AG19: 0.069898262
B21: FDSO (m) | C21: =Model!AF148 | D21: =Model!AK148 | E21: =Model!AL148 | F21: =Model!AM148 | G21: =Model!AN148 | H21: =Model!AO148 | I21: =IFERROR((H21/C21)^(1/5)-1,"n/m") | N21: FDSO (m) | O21: 95.893 | P21: 95.5785 | Q21: 95.834471 | R21: 96.134471 | S21: 96.434471 | T21: 96.734471 | U21: 0.0017488927 | Z21: FDSO (m) | AA21: 95.893 | AB21: 95.5785 | AC21: 95.834471 | AD21: 95.480576 | AE21: 94.017563 | AF21: 92.15394 | AG21: -0.0079229568
B23: Adjusted EPS — Diluted ($) | C23: =Model!AF204 | D23: =Model!AK204 | E23: =Model!AL204 | F23: =Model!AM204 | G23: =Model!AN204 | H23: =Model!AO204 | I23: =IFERROR((H23/C23)^(1/5)-1,"n/m") | N23: Adjusted EPS — Diluted ($) | O23: 1.3681903 | P23: 1.4395585 | Q23: 2.0156831 | R23: 2.3766155 | S23: 2.765256 | T23: 3.2135128 | U23: 0.186224 | Z23: Adjusted EPS — Diluted ($) | AA23: 1.3681903 | AB23: 1.3998006 | AC23: 1.4992205 | AD23: 1.7217689 | AE23: 1.8831044 | AF23: 1.9958684 | AG23: 0.078442717
B24: EPS y/y % | D24: =IFERROR(D23/C23-1,"") | E24: =IFERROR(E23/D23-1,"") | F24: =IFERROR(F23/E23-1,"") | G24: =IFERROR(G23/F23-1,"") | H24: =IFERROR(H23/G23-1,"") | N24: EPS y/y % | P24: 0.052162484 | Q24: 0.40020927 | R24: 0.17906206 | S24: 0.16352686 | T24: 0.16210321 | Z24: EPS y/y % | AB24: 0.023103737 | AC24: 0.071024369 | AD24: 0.1484427 | AE24: 0.093703336 | AF24: 0.059882004
B26: P / E (x) — assumed (adjusted EPS) | G26: 45 | H26: 45 | N26: P / E (x) — assumed (adjusted EPS) | S26: 52 | T26: 52 | Z26: P / E (x) — assumed (adjusted EPS) | AD26: 35 | AE26: 35 | AF26: 35
B27: Price Target ($) | G27: =G26*G23 | H27: =H26*H23 | N27: Price Target ($) | S27: =S26*S23 | T27: =T26*T23 | Z27: Price Target ($) | AD27: =AD26*AD23 | AE27: =AE26*AE23 | AF27: =AF26*AF23
B28: Upside / (Downside) vs current | G28: =IFERROR(G27/$K$2-1,"") | H28: =IFERROR(H27/$K$2-1,"") | N28: Upside / (Downside) vs current | S28: =IFERROR(S27/$K$2-1,"") | T28: =IFERROR(T27/$K$2-1,"") | Z28: Upside / (Downside) vs current | AD28: =IFERROR(AD27/$K$2-1,"") | AE28: =IFERROR(AE27/$K$2-1,"") | AF28: =IFERROR(AF27/$K$2-1,"")
B29: IRR (to Dec-Y-1) | G29: =IFERROR((G27/$K$2)^(1/((DATE(2029-1,12,31)-$K$3)/365.25))-1,"") | H29: =IFERROR((H27/$K$2)^(1/((DATE(2030-1,12,31)-$K$3)/365.25))-1,"") | N29: IRR (to Dec-Y-1) | S29: =IFERROR((S27/$K$2)^(1/((DATE(2029-1,12,31)-$K$3)/365.25))-1,"") | T29: =IFERROR((T27/$K$2)^(1/((DATE(2030-1,12,31)-$K$3)/365.25))-1,"") | Z29: IRR (to Dec-Y-1) | AD29: =IFERROR((AD27/$K$2)^(1/((DATE(2028-1,12,31)-$K$3)/365.25))-1,"") | AE29: =IFERROR((AE27/$K$2)^(1/((DATE(2029-1,12,31)-$K$3)/365.25))-1,"") | AF29: =IFERROR((AF27/$K$2)^(1/((DATE(2030-1,12,31)-$K$3)/365.25))-1,"")
B31: Free Cash Flow | C31: =Model!AF261 | D31: =Model!AK261 | E31: =Model!AL261 | F31: =Model!AM261 | G31: =Model!AN261 | H31: =Model!AO261 | I31: =IFERROR((H31/C31)^(1/5)-1,"n/m") | N31: Free Cash Flow | O31: 99.257 | P31: 125.11873 | Q31: 175.50475 | R31: 199.30195 | S31: 239.57443 | T31: 285.70382 | U31: 0.23546652 | Z31: Free Cash Flow | AA31: 99.257 | AB31: 123.04674 | AC31: 146.09834 | AD31: 172.98095 | AE31: 186.71697 | AF31: 194.57957 | AG31: 0.14410852
B32: FCF % | C32: =IFERROR(C31/C9,"") | D32: =IFERROR(D31/D9,"") | E32: =IFERROR(E31/E9,"") | F32: =IFERROR(F31/F9,"") | G32: =IFERROR(G31/G9,"") | H32: =IFERROR(H31/H9,"") | J32: =IFERROR(AVERAGE(Model!C263,Model!D263,Model!E263,Model!F263,Model!G263,Model!H263,Model!I263,Model!N263,Model!S263,Model!X263,Model!AC263,Model!AH263,Model!AM263,Model!AR263,Model!AW263,Model!BB263,Model!BG263,Model!BL263,Model!BQ263,Model!AF263),"") | K32: =IFERROR(MIN(Model!C263,Model!D263,Model!E263,Model!F263,Model!G263,Model!H263,Model!I263,Model!N263,Model!S263,Model!X263,Model!AC263,Model!AH263,Model!AM263,Model!AR263,Model!AW263,Model!BB263,Model!BG263,Model!BL263,Model!BQ263,Model!AF263),"") | L32: =IFERROR(MAX(Model!C263,Model!D263,Model!E263,Model!F263,Model!G263,Model!H263,Model!I263,Model!N263,Model!S263,Model!X263,Model!AC263,Model!AH263,Model!AM263,Model!AR263,Model!AW263,Model!BB263,Model!BG263,Model!BL263,Model!BQ263,Model!AF263),"") | N32: FCF % | O32: 0.20000081 | P32: 0.18536109 | Q32: 0.22088754 | R32: 0.20691609 | S32: 0.21015765 | T32: 0.21538134 | V32: 0.11558704 | W32: -0.088499642 | X32: 0.20774074 | Z32: FCF % | AA32: 0.20000081 | AB32: 0.1850327 | AC32: 0.20934786 | AD32: 0.23851432 | AE32: 0.24968335 | AF32: 0.25369634 | AH32: 0.12197609 | AI32: -0.088499642 | AJ32: 0.23851432
B33: FCF / share ($) | C33: =IFERROR(C31/C21,"") | D33: =IFERROR(D31/D21,"") | E33: =IFERROR(E31/E21,"") | F33: =IFERROR(F31/F21,"") | G33: =IFERROR(G31/G21,"") | H33: =IFERROR(H31/H21,"") | N33: FCF / share ($) | O33: 1.0350808 | P33: 1.3090678 | Q33: 1.8313321 | R33: 2.073158 | S33: 2.4843236 | T33: 2.9534851 | Z33: FCF / share ($) | AA33: 1.0350808 | AB33: 1.2873894 | AC33: 1.5244863 | AD33: 1.8116873 | AE33: 1.9859797 | AF33: 2.1114623
B34: FCF Yield (on PT) | F34: =IFERROR(F33/F$27,"") | G34: =IFERROR(G33/G$27,"") | H34: =IFERROR(H33/H$27,"") | N34: FCF Yield (on PT) | R34: =IFERROR(R33/R$27,"") | S34: =IFERROR(S33/S$27,"") | T34: =IFERROR(T33/T$27,"") | Z34: FCF Yield (on PT) | AD34: =IFERROR(AD33/AD$27,"") | AE34: =IFERROR(AE33/AE$27,"") | AF34: =IFERROR(AF33/AF$27,"")
B35: Adjusted EBITDA (leverage basis) | C35: =Model!AF174 | D35: =Model!AK174 | E35: =Model!AL174 | F35: =Model!AM174 | G35: =Model!AN174 | H35: =Model!AO174 | I35: =IFERROR((H35/C35)^(1/5)-1,"n/m") | N35: Adjusted EBITDA (leverage basis) | O35: 189.124 | P35: 270 | Q35: 329.11052 | R35: 401.92807 | S35: 478.83327 | T35: 560.54609 | U35: 0.242719 | Z35: Adjusted EBITDA (leverage basis) | AA35: 189.124 | AB35: 265 | AC35: 265.19196 | AD35: 279.21873 | AE35: 291.64789 | AF35: 302.9564 | AG35: 0.098820359
B36: Adjusted EBITDA % of net sales | C36: =IFERROR(C35/C9,"") | D36: =IFERROR(D35/D9,"") | E36: =IFERROR(E35/E9,"") | F36: =IFERROR(F35/F9,"") | G36: =IFERROR(G35/G9,"") | H36: =IFERROR(H35/H9,"") | J36: =IFERROR(AVERAGE(Model!C228,Model!D228,Model!E228,Model!F228,Model!G228,Model!H228,Model!I228,Model!N228,Model!S228,Model!X228,Model!AC228,Model!AH228,Model!AM228,Model!AR228,Model!AW228,Model!BB228,Model!BG228,Model!BL228,Model!BQ228,Model!AF228),"") | K36: =IFERROR(MIN(Model!C228,Model!D228,Model!E228,Model!F228,Model!G228,Model!H228,Model!I228,Model!N228,Model!S228,Model!X228,Model!AC228,Model!AH228,Model!AM228,Model!AR228,Model!AW228,Model!BB228,Model!BG228,Model!BL228,Model!BQ228,Model!AF228),"") | L36: =IFERROR(MAX(Model!C228,Model!D228,Model!E228,Model!F228,Model!G228,Model!H228,Model!I228,Model!N228,Model!S228,Model!X228,Model!AC228,Model!AH228,Model!AM228,Model!AR228,Model!AW228,Model!BB228,Model!BG228,Model!BL228,Model!BQ228,Model!AF228),"") | N36: Adjusted EBITDA % of net sales | O36: 0.38108096 | P36: 0.4 | Q36: 0.41421338 | R36: 0.41728337 | S36: 0.42003845 | T36: 0.42257456 | V36: 0.32168135 | W36: 0.16764565 | X36: 0.41728337 | Z36: Adjusted EBITDA % of net sales | AA36: 0.38108096 | AB36: 0.39849624 | AC36: 0.38 | AD36: 0.385 | AE36: 0.39 | AF36: 0.395 | AH36: 0.31785428 | AI36: 0.16764565 | AJ36: 0.40476399
B38: Net Debt | C38: =Model!AF388 | D38: =Model!AK388 | E38: =Model!AL388 | F38: =Model!AM388 | G38: =Model!AN388 | H38: =Model!AO388 | N38: Net Debt | O38: 634.043 | P38: 761.03927 | Q38: 1087.5345 | R38: 1390.2326 | S38: 1652.6581 | T38: 1868.9543 | Z38: Net Debt | AA38: 634.043 | AB38: 763.11126 | AC38: 619.01292 | AD38: 562.43745 | AE38: 587.29577 | AF38: 609.9128
B39: Net Debt / Adjusted EBITDA (x) | C39: =IFERROR(C38/C35,"") | D39: =IFERROR(D38/D35,"") | E39: =IFERROR(E38/E35,"") | F39: =IFERROR(F38/F35,"") | G39: =IFERROR(G38/G35,"") | H39: =IFERROR(H38/H35,"") | N39: Net Debt / Adjusted EBITDA (x) | O39: 3.3525253 | P39: 2.8186639 | Q39: 3.304466 | R39: 3.4589088 | S39: 3.4514271 | T39: 3.3341671 | Z39: Net Debt / Adjusted EBITDA (x) | AA39: 3.3525253 | AB39: 2.8796651 | AC39: 2.3342069 | AD39: 2.0143257 | AE39: 2.0137152 | AF39: 2.0132032
B41: ROIC | C41: =Model!AF371 | D41: =Model!AK371 | E41: =Model!AL371 | F41: =Model!AM371 | G41: =Model!AN371 | H41: =Model!AO371 | J41: =IFERROR(AVERAGE(Model!C371,Model!D371,Model!E371,Model!F371,Model!G371,Model!H371,Model!I371,Model!N371,Model!S371,Model!X371,Model!AC371,Model!AH371,Model!AM371,Model!AR371,Model!AW371,Model!BB371,Model!BG371,Model!BL371,Model!BQ371,Model!AF371),"") | K41: =IFERROR(MIN(Model!C371,Model!D371,Model!E371,Model!F371,Model!G371,Model!H371,Model!I371,Model!N371,Model!S371,Model!X371,Model!AC371,Model!AH371,Model!AM371,Model!AR371,Model!AW371,Model!BB371,Model!BG371,Model!BL371,Model!BQ371,Model!AF371),"") | L41: =IFERROR(MAX(Model!C371,Model!D371,Model!E371,Model!F371,Model!G371,Model!H371,Model!I371,Model!N371,Model!S371,Model!X371,Model!AC371,Model!AH371,Model!AM371,Model!AR371,Model!AW371,Model!BB371,Model!BG371,Model!BL371,Model!BQ371,Model!AF371),"") | N41: ROIC | O41: 0.068371535 | P41: 0.072144773 | Q41: 0.073575466 | R41: 0.075772324 | S41: 0.078577842 | T41: 0.082445739 | V41: 0.073549029 | W41: 0.068371535 | X41: 0.076503229 | Z41: ROIC | AA41: 0.068371535 | AB41: 0.070309544 | AC41: 0.07190832 | AD41: 0.079438109 | AE41: 0.086816519 | AF41: 0.095273552 | AH41: 0.076186284 | AI41: 0.068371535 | AJ41: 0.080749209
B42: RONTA | C42: =Model!AF382 | D42: =Model!AK382 | E42: =Model!AL382 | F42: =Model!AM382 | G42: =Model!AN382 | H42: =Model!AO382 | J42: =IFERROR(AVERAGE(Model!C382,Model!D382,Model!E382,Model!F382,Model!G382,Model!H382,Model!I382,Model!N382,Model!S382,Model!X382,Model!AC382,Model!AH382,Model!AM382,Model!AR382,Model!AW382,Model!BB382,Model!BG382,Model!BL382,Model!BQ382,Model!AF382),"") | K42: =IFERROR(MIN(Model!C382,Model!D382,Model!E382,Model!F382,Model!G382,Model!H382,Model!I382,Model!N382,Model!S382,Model!X382,Model!AC382,Model!AH382,Model!AM382,Model!AR382,Model!AW382,Model!BB382,Model!BG382,Model!BL382,Model!BQ382,Model!AF382),"") | L42: =IFERROR(MAX(Model!C382,Model!D382,Model!E382,Model!F382,Model!G382,Model!H382,Model!I382,Model!N382,Model!S382,Model!X382,Model!AC382,Model!AH382,Model!AM382,Model!AR382,Model!AW382,Model!BB382,Model!BG382,Model!BL382,Model!BQ382,Model!AF382),"") | N42: RONTA | O42: 0.34743884 | P42: 0.36545608 | Q42: 0.41825233 | R42: 0.45503848 | S42: 0.48824816 | T42: 0.52327581 | V42: 0.4175105 | W42: 0.34743884 | X42: 0.45503848 | Z42: RONTA | AA42: 0.34743884 | AB42: 0.35741445 | AC42: 0.34535156 | AD42: 0.36479598 | AE42: 0.38173985 | AF42: 0.40256154 | AH42: 0.36086917 | AI42: 0.34743884 | AJ42: 0.37037268
B44: Implied Market Cap (USDm) | F44: =F27*F21 | G44: =G27*G21 | H44: =H27*H21 | N44: Implied Market Cap (USDm) | R44: =R27*R21 | S44: =S27*S21 | T44: =T27*T21 | Z44: Implied Market Cap (USDm) | AD44: =AD27*AD21 | AE44: =AE27*AE21 | AF44: =AF27*AF21
B45: (+) Net Debt & NCI | F45: =F38+Model!AM397 | G45: =G38+Model!AN397 | H45: =H38+Model!AO397 | N45: (+) Net Debt & NCI | R45: =R38+Model!AM397 | S45: =S38+Model!AN397 | T45: =T38+Model!AO397 | Z45: (+) Net Debt & NCI | AD45: =AD38+Model!AM397 | AE45: =AE38+Model!AN397 | AF45: =AF38+Model!AO397
B46: Implied Enterprise Value (USDm) | F46: =F44+F45 | G46: =G44+G45 | H46: =H44+H45 | N46: Implied Enterprise Value (USDm) | R46: =R44+R45 | S46: =S44+S45 | T46: =T44+T45 | Z46: Implied Enterprise Value (USDm) | AD46: =AD44+AD45 | AE46: =AE44+AE45 | AF46: =AF44+AF45
B47: Implied EV / Adjusted EBITDA (x) | F47: =IFERROR(F46/F35,"") | G47: =IFERROR(G46/G35,"") | H47: =IFERROR(H46/H35,"") | N47: Implied EV / Adjusted EBITDA (x) | R47: =IFERROR(R46/R35,"") | S47: =IFERROR(S46/S35,"") | T47: =IFERROR(T46/T35,"") | Z47: Implied EV / Adjusted EBITDA (x) | AD47: =IFERROR(AD46/AD35,"") | AE47: =IFERROR(AE46/AE35,"") | AF47: =IFERROR(AF46/AF35,"")

Sheet DCF
B2: DCF VALUATION — LOAR HOLDINGS (LOAR)
B4: 1. WACC BUILD
B5: Risk-free rate (US 10Y govt) | C5: 0.042 | D5: Assumption (~US 10Y Treasury yield); update to market
B6: Equity risk premium | C6: 0.05 | D6: US implied ERP ~4.5–5.5% (Damodaran)
B7: Levered beta | C7: 1.1 | D7: Aerospace components peers (TransDigm, HEICO, Ducommun, Karman) ~1.0–1.2; proprietary, sole-source content and ~50% aftermarket mix dampen cyclicality
B8: Cost of equity | C8: =C5+C7*C6
B9: Pre-tax cost of debt | C9: 0.082 | D9: Term loans at SOFR + 4.25% (B-rated, secured; ~8.2% all-in at 30-Jun-2026)
B10: Tax rate | C10: 0.24 | D10: Model 2027E+ effective tax rate
B11: After-tax cost of debt | C11: =C9*(1-C10)
B12: Target D/V | C12: 0.12 | D12: Net debt ~$0.83bn at 30-Jun-26 vs ~$7.2bn market cap ($75 × ~95.6m diluted shares); D/V ~10–15%
B13: WACC | C13: =C8*(1-C12)+C11*C12
B15: Valuation date (live) | C15: =TODAY() | D15: Periods = (Dec-31-Year − today) / 365.25; cash flows assumed at year-end
B16: 2. UNLEVERED FREE CASH FLOW BUILD (USDm)
D17: 2026E | E17: 2027E | F17: 2028E | G17: 2029E | H17: 2030E | I17: 2031E | J17: 2032E | K17: 2033E | L17: 2034E | M17: 2035E | N17: Terminal | P17: CAGR 26–30E | Q17: CAGR 26–35E
B18: Adjusted EBIT (Model; Adjusted EBITDA − DD&A) | D18: =Model!AK183 | E18: =Model!AL183 | F18: =Model!AM183 | G18: =Model!AN183 | H18: =Model!AO183 | I18: =H18*(1+I$31) | J18: =I18*(1+J$31) | K18: =J18*(1+K$31) | L18: =K18*(1+L$31) | M18: =L18*(1+M$31) | P18: =IFERROR(($H18/$D18)^(1/(VALUE(LEFT($H$17,4))-VALUE(LEFT($D$17,4))))-1,"n/m") | Q18: =IFERROR(($M18/$D18)^(1/(VALUE(LEFT($M$17,4))-VALUE(LEFT($D$17,4))))-1,"n/m")
B19: y/y % | E19: =IFERROR(E18/D18-1,"") | F19: =IFERROR(F18/E18-1,"") | G19: =IFERROR(G18/F18-1,"") | H19: =IFERROR(H18/G18-1,"") | I19: =IFERROR(I18/H18-1,"") | J19: =IFERROR(J18/I18-1,"") | K19: =IFERROR(K18/J18-1,"") | L19: =IFERROR(L18/K18-1,"") | M19: =IFERROR(M18/L18-1,"")
B20: (−) Transaction & integration costs (cash; added back in Adjusted EBITDA) | D20: =-(Model!AK120+Model!AK122) | E20: =-(Model!AL120+Model!AL122) | F20: =-(Model!AM120+Model!AM122) | G20: =-(Model!AN120+Model!AN122) | H20: =-(Model!AO120+Model!AO122) | I20: =H20*(1+I$31) | J20: =I20*(1+J$31) | K20: =J20*(1+K$31) | L20: =K20*(1+L$31) | M20: =L20*(1+M$31)
B21: × (1 − tax rate) | D21: =1-$C$10 | E21: =1-$C$10 | F21: =1-$C$10 | G21: =1-$C$10 | H21: =1-$C$10 | I21: =1-$C$10 | J21: =1-$C$10 | K21: =1-$C$10 | ... M21: =1-$C$10
B22: NOPAT = (Adjusted EBIT − transaction & integration costs) × (1 − t) | D22: =(D18+D20)*D21 | E22: =(E18+E20)*E21 | F22: =(F18+F20)*F21 | G22: =(G18+G20)*G21 | H22: =(H18+H20)*H21 | I22: =(I18+I20)*I21 | J22: =(J18+J20)*J21 | K22: =(K18+K20)*K21 | ... M22: =(M18+M20)*M21
B23: plus depreciation & amortization (total, incl. acquired-intangible amortization) | D23: =Model!AK144 | E23: =Model!AL144 | F23: =Model!AM144 | G23: =Model!AN144 | H23: =Model!AO144 | I23: =H23*(1+I$31) | J23: =I23*(1+J$31) | K23: =J23*(1+K$31) | L23: =K23*(1+L$31) | M23: =L23*(1+M$31)
B24: − Capex (PP&E) and acquisitions (M&A lever, 2027E+) | D24: =D29 | E24: =E29+Model!AL245 | F24: =F29+Model!AM245 | G24: =G29+Model!AN245 | H24: =H29+Model!AO245 | I24: =I29 | J24: =J29 | K24: =K29 | L24: =L29 | M24: =M29
B25: − Δ Working capital (CF statement) | D25: =Model!AK242 | E25: =Model!AL242 | F25: =Model!AM242 | G25: =Model!AN242 | H25: =Model!AO242 | I25: =H25*(1+I$31) | J25: =I25*(1+J$31) | K25: =J25*(1+K$31) | L25: =K25*(1+L$31) | M25: =L25*(1+M$31)
B26: Unlevered FCF | D26: =D22+D23+D24+D25 | E26: =E22+E23+E24+E25 | F26: =F22+F23+F24+F25 | G26: =G22+G23+G24+G25 | H26: =H22+H23+H24+H25 | I26: =I22+I23+I24+I25 | J26: =J22+J23+J24+J25 | K26: =K22+K23+K24+K25 | ... M26: =M22+M23+M24+M25 | N26: =M26*(1+$C$32) | P26: =IFERROR(($H26/$D26)^(1/(VALUE(LEFT($H$17,4))-VALUE(LEFT($D$17,4))))-1,"n/m") | Q26: =IFERROR(($M26/$D26)^(1/(VALUE(LEFT($M$17,4))-VALUE(LEFT($D$17,4))))-1,"n/m")
B27: y/y % | E27: =IFERROR(E26/D26-1,"") | F27: =IFERROR(F26/E26-1,"") | G27: =IFERROR(G26/F26-1,"") | H27: =IFERROR(H26/G26-1,"") | I27: =IFERROR(I26/H26-1,"") | J27: =IFERROR(J26/I26-1,"") | K27: =IFERROR(K26/J26-1,"") | L27: =IFERROR(L26/K26-1,"") | M27: =IFERROR(M26/L26-1,"")
B28: Terminal Value (Gordon Growth) | N28: =N26/($C$13-$C$32)
B29: memo: PP&E capex only (fade years carry no new acquisitions) | D29: =Model!AK244 | E29: =Model!AL244 | F29: =Model!AM244 | G29: =Model!AN244 | H29: =Model!AO244 | I29: =H29*(1+I$31) | J29: =I29*(1+J$31) | K29: =J29*(1+K$31) | L29: =K29*(1+L$31) | M29: =L29*(1+M$31)
B31: Fade-period growth (2031E–35E) | I31: 0.08 | J31: =I31+($M$31-$I$31)/(COLUMNS($I$31:$M$31)-1) | K31: =J31+($M$31-$I$31)/(COLUMNS($I$31:$M$31)-1) | L31: =K31+($M$31-$I$31)/(COLUMNS($I$31:$M$31)-1) | M31: 0.05
B32: Terminal growth rate | C32: 0.035
B34: Discount period (years) | D34: =(DATE(2026,12,31)-$C$15)/365.25 | E34: =(DATE(2027,12,31)-$C$15)/365.25 | F34: =(DATE(2028,12,31)-$C$15)/365.25 | G34: =(DATE(2029,12,31)-$C$15)/365.25 | H34: =(DATE(2030,12,31)-$C$15)/365.25 | I34: =(DATE(2031,12,31)-$C$15)/365.25 | J34: =(DATE(2032,12,31)-$C$15)/365.25 | K34: =(DATE(2033,12,31)-$C$15)/365.25 | L34: =(DATE(2034,12,31)-$C$15)/365.25 | M34: =(DATE(2035,12,31)-$C$15)/365.25 | N34: =M34
B35: Discount factor | D35: =1/(1+$C$13)^D34 | E35: =1/(1+$C$13)^E34 | F35: =1/(1+$C$13)^F34 | G35: =1/(1+$C$13)^G34 | H35: =1/(1+$C$13)^H34 | I35: =1/(1+$C$13)^I34 | J35: =1/(1+$C$13)^J34 | K35: =1/(1+$C$13)^K34 | ... N35: =1/(1+$C$13)^N34
B36: PV of UFCF | D36: =D26*D35 | E36: =E26*E35 | F36: =F26*F35 | G36: =G26*G35 | H36: =H26*H35 | I36: =I26*I35 | J36: =J26*J35 | K36: =K26*K35 | ... M36: =M26*M35 | N36: =N28*N35
D37: Loar's Adjusted EBITDA excludes stock-based compensation (~2.6% of sales), which is a real cost; Adjusted EBIT here deducts all D&A incl. ~$65m p.a. of acquired-intangible amortization (non-cash, added back in row 23). The 1H/26 Harper Engineering consideration ($249.8m) is excluded from 2026E UFCF and added to opening invested capital.
B39: Implied ROIC & incremental ROIC (USDm) | D39: =D17 | E39: =E17 | F39: =F17 | G39: =G17 | H39: =H17 | I39: =I17 | J39: =J17 | K39: =K17 | ... M39: =M17 | N39: Terminal
B40: NOPAT (row 22) | D40: =D22 | E40: =E22 | F40: =F22 | G40: =G22 | H40: =H22 | I40: =I22 | J40: =J22 | K40: =K22 | ... M40: =M22 | N40: =M40*(1+$C$32)
B41: Net investment = NOPAT − UFCF | D41: =D40-D26 | E41: =E40-E26 | F41: =F40-F26 | G41: =G40-G26 | H41: =H40-H26 | I41: =I40-I26 | J41: =J40-J26 | K41: =K40-K26 | ... N41: =N40-N26
B42: Opening invested capital | D42: =Model!AF368-Model!AK245 | E42: =D43 | F42: =E43 | G42: =F43 | H42: =G43 | I42: =H43 | J42: =I43 | K42: =J43 | L42: =K43 | ... N42: =M43
B43: Closing invested capital | D43: =D42+D41 | E43: =E42+E41 | F43: =F42+F41 | G43: =G42+G41 | H43: =H42+H41 | I43: =I42+I41 | J43: =J42+J41 | K43: =K42+K41 | ... M43: =M42+M41
B44: Implied ROIC = NOPAT / opening IC | D44: =IFERROR(D40/D42,"") | E44: =IFERROR(E40/E42,"") | F44: =IFERROR(F40/F42,"") | G44: =IFERROR(G40/G42,"") | H44: =IFERROR(H40/H42,"") | I44: =IFERROR(I40/I42,"") | J44: =IFERROR(J40/J42,"") | K44: =IFERROR(K40/K42,"") | ... N44: =IFERROR(N40/N42,"")
B45: Reinvestment rate = net inv. / NOPAT | D45: =IFERROR(D41/D40,"") | E45: =IFERROR(E41/E40,"") | F45: =IFERROR(F41/F40,"") | G45: =IFERROR(G41/G40,"") | H45: =IFERROR(H41/H40,"") | I45: =IFERROR(I41/I40,"") | J45: =IFERROR(J41/J40,"") | K45: =IFERROR(K41/K40,"") | ... N45: =IFERROR(N41/N40,"")
B46: Incremental ROIC = Δ NOPAT / prior-yr net inv. | E46: =IFERROR((E40-D40)/D41,"") | F46: =IFERROR((F40-E40)/E41,"") | G46: =IFERROR((G40-F40)/F41,"") | H46: =IFERROR((H40-G40)/G41,"") | I46: =IFERROR((I40-H40)/H41,"") | J46: =IFERROR((J40-I40)/I41,"") | K46: =IFERROR((K40-J40)/J41,"") | L46: =IFERROR((L40-K40)/K41,"") | M46: =IFERROR((M40-L40)/L41,"") | N46: =IFERROR($C$32/N45,"")
...

Sheet Charts
B2: Loar Holdings — Operating Performance (2012–2025) and Model Forecast (2026E–2030E)
B3: USDm · Linked to Model. Bars = organic growth vs acquisition contribution (as published from 2023; earlier years: total growth shown as organic where no split is available). Adjusted EBITDA as reconciled by Loar in each period (prospectus for FY2012–23). ROIC / RONTA on Adjusted EBIT (balance sheets from FY2022).
C7: 2012 | D7: 2013 | E7: 2014 | F7: 2015 | G7: 2016 | H7: 2017 | I7: 2018 | J7: 2019 | K7: 2020 | L7: 2021 | M7: 2022 | N7: 2023 | O7: 2024 | P7: 2025 | Q7: 2026E | R7: 2027E | S7: 2028E | T7: 2029E | U7: 2030E
B8: Organic growth % | C8: =IFERROR(Model!C70+0,IFERROR(Model!C219+0,0)) | D8: =IFERROR(Model!D70+0,IFERROR(Model!D219+0,0)) | E8: =IFERROR(Model!E70+0,IFERROR(Model!E219+0,0)) | F8: =IFERROR(Model!F70+0,IFERROR(Model!F219+0,0)) | G8: =IFERROR(Model!G70+0,IFERROR(Model!G219+0,0)) | H8: =IFERROR(Model!H70+0,IFERROR(Model!H219+0,0)) | I8: =IFERROR(Model!I70+0,IFERROR(Model!I219+0,0)) | J8: =IFERROR(Model!J70+0,IFERROR(Model!J219+0,0)) | ... L8: =IFERROR(Model!L70+0,IFERROR(Model!L219+0,0)) | M8: =IFERROR(Model!Q70+0,IFERROR(Model!Q219+0,0)) | N8: =IFERROR(Model!V70+0,IFERROR(Model!V219+0,0)) | O8: =IFERROR(Model!AA70+0,IFERROR(Model!AA219+0,0)) | P8: =IFERROR(Model!AF70+0,IFERROR(Model!AF219+0,0)) | Q8: =IFERROR(Model!AK70+0,IFERROR(Model!AK219+0,0)) | R8: =IFERROR(Model!AL70+0,IFERROR(Model!AL219+0,0)) | S8: =IFERROR(Model!AM70+0,IFERROR(Model!AM219+0,0)) | T8: =IFERROR(Model!AN70+0,IFERROR(Model!AN219+0,0)) | U8: =IFERROR(Model!AO70+0,IFERROR(Model!AO219+0,0))
B9: Acquisition contribution % | C9: =IFERROR(Model!C71+0,0) | D9: =IFERROR(Model!D71+0,0) | E9: =IFERROR(Model!E71+0,0) | F9: =IFERROR(Model!F71+0,0) | G9: =IFERROR(Model!G71+0,0) | H9: =IFERROR(Model!H71+0,0) | I9: =IFERROR(Model!I71+0,0) | J9: =IFERROR(Model!J71+0,0) | ... L9: =IFERROR(Model!L71+0,0) | M9: =IFERROR(Model!Q71+0,0) | N9: =IFERROR(Model!V71+0,0) | O9: =IFERROR(Model!AA71+0,0) | P9: =IFERROR(Model!AF71+0,0) | Q9: =IFERROR(Model!AK71+0,0) | R9: =IFERROR(Model!AL71+0,0) | S9: =IFERROR(Model!AM71+0,0) | T9: =IFERROR(Model!AN71+0,0) | U9: =IFERROR(Model!AO71+0,0)
C11: =C7 | D11: =D7 | E11: =E7 | F11: =F7 | G11: =G7 | H11: =H7 | I11: =I7 | J11: =J7 | ... U11: =U7
B12: Adjusted EBITDA | C12: =Model!C174 | D12: =Model!D174 | E12: =Model!E174 | F12: =Model!F174 | G12: =Model!G174 | H12: =Model!H174 | I12: =Model!I174 | J12: =Model!J174 | ... L12: =Model!L174 | M12: =Model!Q174 | N12: =Model!V174 | O12: =Model!AA174 | P12: =Model!AF174 | Q12: =Model!AK174 | R12: =Model!AL174 | S12: =Model!AM174 | T12: =Model!AN174 | U12: =Model!AO174
B13: Operating Income (GAAP) | C13: =Model!C134 | D13: =Model!D134 | E13: =Model!E134 | F13: =Model!F134 | G13: =Model!G134 | H13: =Model!H134 | I13: =Model!I134 | J13: =Model!J134 | ... L13: =Model!L134 | M13: =Model!Q134 | N13: =Model!V134 | O13: =Model!AA134 | P13: =Model!AF134 | Q13: =Model!AK134 | R13: =Model!AL134 | S13: =Model!AM134 | T13: =Model!AN134 | U13: =Model!AO134
B14: Adj. EBITDA Margin % | C14: =Model!C228 | D14: =Model!D228 | E14: =Model!E228 | F14: =Model!F228 | G14: =Model!G228 | H14: =Model!H228 | I14: =Model!I228 | J14: =Model!J228 | ... L14: =Model!L228 | M14: =Model!Q228 | N14: =Model!V228 | O14: =Model!AA228 | P14: =Model!AF228 | Q14: =Model!AK228 | R14: =Model!AL228 | S14: =Model!AM228 | T14: =Model!AN228 | U14: =Model!AO228
B15: GAAP Op. Margin % | C15: =Model!C231 | D15: =Model!D231 | E15: =Model!E231 | F15: =Model!F231 | G15: =Model!G231 | H15: =Model!H231 | I15: =Model!I231 | J15: =Model!J231 | ... L15: =Model!L231 | M15: =Model!Q231 | N15: =Model!V231 | O15: =Model!AA231 | P15: =Model!AF231 | Q15: =Model!AK231 | R15: =Model!AL231 | S15: =Model!AM231 | T15: =Model!AN231 | U15: =Model!AO231
C17: =C7 | D17: =D7 | E17: =E7 | F17: =F7 | G17: =G7 | H17: =H7 | I17: =I7 | J17: =J7 | ... U17: =U7
B18: ROIC | C18: =IFERROR(Model!C371+0,NA()) | D18: =IFERROR(Model!D371+0,NA()) | E18: =IFERROR(Model!E371+0,NA()) | F18: =IFERROR(Model!F371+0,NA()) | G18: =IFERROR(Model!G371+0,NA()) | H18: =IFERROR(Model!H371+0,NA()) | I18: =IFERROR(Model!I371+0,NA()) | J18: =IFERROR(Model!J371+0,NA()) | ... L18: =IFERROR(Model!L371+0,NA()) | M18: =IFERROR(Model!Q371+0,NA()) | N18: =IFERROR(Model!V371+0,NA()) | O18: =IFERROR(Model!AA371+0,NA()) | P18: =IFERROR(Model!AF371+0,NA()) | Q18: =IFERROR(Model!AK371+0,NA()) | R18: =IFERROR(Model!AL371+0,NA()) | S18: =IFERROR(Model!AM371+0,NA()) | T18: =IFERROR(Model!AN371+0,NA()) | U18: =IFERROR(Model!AO371+0,NA())
