Workbook

Sheet Model
CF1: SCENARIO SWITCH ▼ (Bull / Base / Bear) — drives all scenario-linked forecast drivers
B2: Mastercard Incorporated (NYSE: MA) — 3-Statement Financial Model | CF2: Base
B3: US GAAP as reported · USD millions (per-share data in USD; shares in millions; GDV in USD billions) · Fiscal years ended 31 December · Source: Mastercard Forms 10-K / 10-Q, Form 8-K earnings releases (Ex. 99.1), SEC EDGAR (CIK 1141391); XBRL company facts for cross-checks · FY26 outlook from the Q2-26 call is UNVERIFIED (not in an SEC filing)
B4: Basis notes: as originally reported in each release (2014 net revenue re-presented in 2015 kept as memo; 2018 cost reclassification; Q1-26 ending cash per the 10-Q). One reportable segment; net revenue = payment network + value-added services and solutions (presentation from the FY2022 10-K; legacy categories in memo). 10-for-1 split Jan-2014. Cash flow includes restricted cash and security deposits from 2018. Acquisitions: Vocalink 2017, Finicity / Nets A2A / Ekata 2020–21, Recorded Future Dec-2024; BVNK pending (assumed 30-Sep-2026).
CH5: Forecast | CI5: Historical | CJ5: Historical | CK5: Historical
B6: (USDm) | C6: 2006 | D6: 2007 | E6: 2008 | F6: 2009 | G6: 2010 | H6: 2011 | I6: 2012 | J6: Q1/13 | K6: Q2/13 | L6: Q3/13 | M6: Q4/13 | N6: 2013 | O6: Q1/14 | P6: Q2/14 | Q6: Q3/14 | R6: Q4/14 | S6: 2014 | T6: Q1/15 | U6: Q2/15 | V6: Q3/15 | W6: Q4/15 | X6: 2015 | Y6: Q1/16 | Z6: Q2/16 | AA6: Q3/16 | AB6: Q4/16 | AC6: 2016 | AD6: Q1/17 | AE6: Q2/17 | AF6: Q3/17 | AG6: Q4/17 | AH6: 2017 | AI6: Q1/18 | AJ6: Q2/18 | AK6: Q3/18 | AL6: Q4/18 | AM6: 2018 | AN6: Q1/19 | AO6: Q2/19 | AP6: Q3/19 | AQ6: Q4/19 | AR6: 2019 | AS6: Q1/20 | AT6: Q2/20 | AU6: Q3/20 | AV6: Q4/20 | AW6: 2020 | AX6: Q1/21 | AY6: Q2/21 | AZ6: Q3/21 | BA6: Q4/21 | BB6: 2021 | BC6: Q1/22 | BD6: Q2/22 | BE6: Q3/22 | BF6: Q4/22 | BG6: 2022 | BH6: Q1/23 | BI6: Q2/23 | BJ6: Q3/23 | BK6: Q4/23 | BL6: 2023 | BM6: Q1/24 | BN6: Q2/24 | BO6: Q3/24 | BP6: Q4/24 | BQ6: 2024 | BR6: Q1/25 | BS6: Q2/25 | BT6: Q3/25 | BU6: Q4/25 | BV6: 2025 | BW6: Q1/26 | BX6: Q2/26 | BY6: Q3/26E | BZ6: Q4/26E | CA6: 2026E | CB6: 2027E | CC6: 2028E | CD6: 2029E | CE6: 2030E | CF6: Modelling Notes | CH6: 5Y CAGR | CI6: 5Y CAGR | CJ6: 10Y CAGR | CK6: 19Y CAGR
CH7: 25-'30 | CI7: 20-'25 | CJ7: 15-'25 | CK7: 06-'25
B8: NET REVENUE BUILD — PAYMENT NETWORK (GDV × YIELD) · VALUE-ADDED SERVICES & SOLUTIONS (single reportable segment) | CF8: REVENUE BUILD — modelling logic (GDV → payment network net revenue at the network yield; value-added services and solutions by growth; Σ = net revenue → adjusted opex → adjusted operating income → GAAP P&L)
CN9: SCENARIO INPUT TABLE — driver assumptions per Bull / Base / Bear | CO9: Bull | CP9: Base | CQ9: Bear | CR9: Bull / Bear = Base + Δ (Δ inputs on each block header). Outlook block = high / mid / low end of the FY26 guidance (UNVERIFIED: call commentary, not in an SEC filing).
B10: Network volume drivers (Mastercard-branded programs, worldwide; operating-performance tables in each release) | CF10: VOLUME DRIVERS — GDV in USD = prior year × (1 + local-currency growth) × (1 + FX translation)
B11: Gross dollar volume (GDV), USD bn | C11: 1956 | D11: 2276 | E11: 2533 | F11: 2454 | G11: 2727 | H11: 3249 | I11: 3647 | J11: 947 | K11: 1007 | L11: 1045 | M11: 1104 | N11: 4103 | O11: 1045 | P11: 1124 | Q11: 1157 | R11: 1172 | S11: 4499 | T11: 1063 | U11: 1141 | V11: 1159 | W11: 1199 | X11: 4564 | Y11: 1141 | Z11: 1228 | AA11: 1221 | AB11: 1232 | AC11: 4827 | AD11: 1181 | AE11: 1282 | AF11: 1353 | AG11: 1420 | AH11: 5242 | AI11: 1415 | AJ11: 1475 | AK11: 1468 | AL11: 1550 | AM11: 5901 | AN11: 1484 | AO11: 1598 | AP11: 1652 | AQ11: 1726 | AR11: 6461 | AS11: 1565 | AT11: 1383 | AU11: 1648 | AV11: 1747 | AW11: 6337 | AX11: 1711 | AY11: 1904 | AZ11: 1993 | BA11: 2113 | BB11: 7720 | BC11: 1919 | BD11: 2054 | BE11: 2069 | BF11: 2133 | BG11: 8177 | BH11: 2108 | BI11: 2267 | BJ11: 2305 | BK11: 2352 | BL11: 9030 | BM11: 2290 | BN11: 2403 | BO11: 2502 | BP11: 2561 | BQ11: 9757 | BR11: 2417 | BS11: 2631 | BT11: 2747 | BU11: 2819 | BV11: 10632 | BW11: 2703 | BX11: 2881 | BY11: =BT11*(1+BY14) -> 2971.9312 | BZ11: =BU11*(1+BZ14) -> 3034.6535 | CA11: =SUM(BW11:BZ11) -> 11590.585 | CB11: =CA11*(1+CB14) -> 12575.784 | CC11: =CB11*(1+CC14) -> 13581.847 | CD11: =CC11*(1+CD14) -> 14668.395 | CE11: =CD11*(1+CE14) -> 15768.525 | CF11: Release "Mastercard Incorporated Operating Performance" table, all programs, worldwide (three months; annual = full-year table). GDV = purchase + cash volume; customer-reported and revised over time. | CH11: =IFERROR((CE11/BV11)^(1/5)-1,"n/m") -> 0.082019826 | CI11: =IFERROR((BV11/AW11)^(1/5)-1,"n/m") -> 0.10903755 | CJ11: =IFERROR((BV11/X11)^(1/10)-1,"n/m") -> 0.088245633 | CK11: =IFERROR((BV11/C11)^(1/19)-1,"n/m") -> 0.09319381 | CN11: FY26 outlook — Q2-26 earnings call (30-Jul-2026) — UNVERIFIED (not in an SEC filing) | CO11: High | CP11: Mid | CQ11: Low | CR11: Net revenue growth at the high end of a low-double-digits rate (currency-neutral, ex-acquisitions; raised), FX ~+1 ppt; adjusted opex growth low double digits (currency-neutral, ex-acquisitions), FX 0.5–1 ppt headwind; Q3 other expense ~$(125)m; non-GAAP tax rate 20–21% in Q3 and Q4. Source: third-party call transcripts (web search); Mastercard's 8-K release has no outlook. Numeric end-points are model translations of the wording.
B12: GDV growth, local currency % | C12: 14.17 | D12: 0.144 | E12: 0.107 | F12: 0.014 | G12: 0.091 | H12: 0.161 | I12: 0.154 | J12: 0.121 | K12: 0.133 | L12: 0.152 | M12: 0.138 | N12: 0.136 | O12: 0.138 | P12: 0.129 | Q12: 0.119 | R12: 0.129 | S12: 0.128 | T12: 0.121 | U12: 0.128 | V12: 0.13 | W12: 0.125 | X12: 0.126 | Y12: 0.132 | Z12: 0.114 | AA12: 0.073 | AB12: 0.053 | AC12: 0.092 | AD12: 0.047 | AE12: 0.061 | AF12: 0.101 | AG12: 0.127 | AH12: 0.086 | AI12: 0.141 | AJ12: 0.142 | AK12: 0.133 | AL12: 0.143 | AM12: 0.14 | AN12: 0.116 | AO12: 0.129 | AP12: 0.144 | AQ12: 0.123 | AR12: 0.13 | AS12: 0.081 | AT12: -0.1 | AU12: 0.012 | AV12: 0.014 | AW12: 0.001 | AX12: 0.075 | AY12: 0.328 | AZ12: 0.199 | BA12: 0.23 | BB12: 0.205 | BC12: 0.173 | BD12: 0.136 | BE12: 0.114 | BF12: 0.076 | BG12: 0.123 | BH12: 0.15 | BI12: 0.125 | BJ12: 0.108 | BK12: 0.099 | BL12: 0.119 | BM12: 0.104 | BN12: 0.094 | BO12: 0.105 | BP12: 0.116 | BQ12: 0.105 | BR12: 0.093 | BS12: 0.09 | BT12: 0.087 | BU12: 0.074 | BV12: 0.086 | BW12: 0.073 | BX12: 0.08 | BY12: =AVERAGE(BW12:BX12) -> 0.0765 | BZ12: =AVERAGE(BW12:BX12) -> 0.0765 | CA12: =AVERAGE(BW12:BZ12) -> 0.0765 | CB12: =CHOOSE(MATCH($CF$2,{"Bull","Base","Bear"},0),$CO$28,$CP$28,$CQ$28) -> 0.085 | CC12: =CHOOSE(MATCH($CF$2,{"Bull","Base","Bear"},0),$CO$29,$CP$29,$CQ$29) -> 0.08 | CD12: =CHOOSE(MATCH($CF$2,{"Bull","Base","Bear"},0),$CO$30,$CP$30,$CQ$30) -> 0.08 | CE12: =CHOOSE(MATCH($CF$2,{"Bull","Base","Bear"},0),$CO$31,$CP$31,$CQ$31) -> 0.075 | CF12: As published (EU-rule-adjusted figures 2016–17 are in the transcription notes, not used). Q3/Q4-26E: H1-26 average (8.0%, 7.3%→8.0%); 2027E+: scenario lever. | CH12: =IFERROR(AVERAGE(CA12,CB12,CC12,CD12,CE12),"n/m") -> 0.0793 | CI12: =IFERROR(AVERAGE(BB12,BG12,BL12,BQ12,BV12),"n/m") -> 0.1276 | CJ12: =IFERROR(AVERAGE(AC12,AH12,AM12,AR12,AW12,BB12,BG12,BL12,BQ12,BV12),"n/m") -> 0.1087 | CK12: =IFERROR(AVERAGE(C12,D12,E12,F12,G12,H12,I12,N12,S12,X12,AC12,AH12,AM12,AR12,AW12,BB12,BG12,BL12,BQ12,BV12),"n/m") -> 0.8159 | CN12: FY26 net revenue growth, reported (UNVERIFIED) | CO12: 0.14 | CP12: 0.135 | CQ12: 0.13 | CR12: Model end-points (reported USD growth): currency-neutral 13.0 / 12.5 / 12.0% (high end of low double digits) + ~1 ppt FX = 14.0 / 13.5 / 13.0% (Bull / Base / Bear). H1-26 actual +15% reported, +12% currency-neutral.
B13: FX translation (USD growth − local-currency growth), pp | C13: =IF(AND(ISNUMBER(C14),ISNUMBER(C12)),C14-C12,"") -> -14.021 | D13: =IF(AND(ISNUMBER(D14),ISNUMBER(D12)),D14-D12,"") -> 0.04 | E13: =IF(AND(ISNUMBER(E14),ISNUMBER(E12)),E14-E12,"") -> 0.008 | F13: =IF(AND(ISNUMBER(F14),ISNUMBER(F12)),F14-F12,"") -> -0.047 | G13: =IF(AND(ISNUMBER(G14),ISNUMBER(G12)),G14-G12,"") -> 0.016 | H13: =IF(AND(ISNUMBER(H14),ISNUMBER(H12)),H14-H12,"") -> 0.032 | I13: =IF(AND(ISNUMBER(I14),ISNUMBER(I12)),I14-I12,"") -> -0.033 | J13: =IF(AND(ISNUMBER(J14),ISNUMBER(J12)),J14-J12,"") -> -0.007 | ... BX13: =IF(AND(ISNUMBER(BX14),ISNUMBER(BX12)),BX14-BX12,"") -> 0.012 | BY13: 0.005 | BZ13: 0 | CA13: =CA14-CA12 -> 0.013660339 | CB13: 0 | CC13: 0 | CD13: 0 | CE13: 0 | CF13: Q3/Q4-26E: point estimates consistent with the ~1 ppt FY26 FX tailwind in the (unverified) outlook after +2.6 ppt in H1-26; 2027E+: constant currency (0). | CN13: FY26 adjusted operating expense growth, reported (UNVERIFIED; Bull = low end) | CO13: 0.11 | CP13: 0.115 | CQ13: 0.12 | CR13: Model end-points for adjusted operating expense growth (reported USD): low double digits currency-neutral (~10–11%) + 0.5–1 ppt FX headwind = 11.0 / 11.5 / 12.0% (Bull = low end). H1-26 actual +11% reported, +9% currency-neutral.
B14: GDV growth, USD % | C14: 0.149 | D14: 0.184 | E14: 0.115 | F14: -0.033 | G14: 0.107 | H14: 0.193 | I14: 0.121 | J14: 0.114 | K14: 0.128 | L14: 0.136 | M14: 0.118 | N14: 0.124 | O14: 0.103 | P14: 0.114 | Q14: 0.106 | R14: 0.06 | S14: 0.095 | T14: 0.018 | U14: 0.014 | V14: 0 | W14: 0.022 | X14: 0.014 | Y14: 0.072 | Z14: 0.076 | AA14: 0.054 | AB14: 0.026 | AC14: 0.056 | AD14: 0.034 | AE14: 0.042 | AF14: 0.11 | AG14: 0.155 | AH14: 0.087 | AI14: 0.193 | AJ14: 0.153 | AK14: 0.089 | AL14: 0.094 | AM14: 0.13 | AN14: 0.054 | AO14: 0.084 | AP14: 0.124 | AQ14: 0.115 | AR14: 0.096 | AS14: 0.055 | AT14: -0.137 | AU14: -0.003 | AV14: 0.01 | AW14: -0.02 | AX14: 0.093 | AY14: 0.383 | AZ14: 0.211 | BA14: 0.21 | BB14: 0.219 | BC14: 0.123 | BD14: 0.077 | BE14: 0.038 | BF14: 0.008 | BG14: 0.059 | BH14: 0.1 | BI14: 0.101 | BJ14: 0.112 | BK14: 0.103 | BL14: 0.104 | BM14: 0.086 | BN14: 0.061 | BO14: 0.086 | BP14: 0.089 | BQ14: 0.081 | BR14: 0.055 | BS14: 0.094 | BT14: 0.098 | BU14: 0.098 | BV14: 0.087 | BW14: 0.115 | BX14: 0.092 | BY14: =(1+BY12)*(1+BY13)-1 -> 0.0818825 | BZ14: =(1+BZ12)*(1+BZ13)-1 -> 0.0765 | CA14: =IF(AND(ISNUMBER(CA11),ISNUMBER(BV11)),IFERROR(CA11/BV11-1,""),"") -> 0.090160339 | CB14: =(1+CB12)*(1+CB13)-1 -> 0.085 | CC14: =(1+CC12)*(1+CC13)-1 -> 0.08 | CD14: =(1+CD12)*(1+CD13)-1 -> 0.08 | CE14: =(1+CE12)*(1+CE13)-1 -> 0.075 | CF14: 2026E = 2026E GDV ÷ 2025 GDV − 1; local-currency 2026E = average of the quarters (approximation). | CN14: H2-26E share repurchases ($m) | CO14: 7800 | CP14: 7000 | CQ14: 6000 | CR14: H1-26 $8,933m (Q2 $4.9bn); $0.7bn repurchased 1–27 Jul; $7.8bn of authorization left at 27-Jul-2026 (a new program is usually approved in December). Assumption.
B15: Memo: cross-border volume growth, local currency % (release text) | G15: 0.152 | H15: 0.187 | I15: 0.16 | J15: 0.16 | K15: 0.17 | L15: 0.19 | M15: 0.18 | N15: 0.18 | O15: 0.17 | P15: 0.16 | Q15: 0.15 | R15: 0.19 | S15: 0.16 | T15: 0.19 | U15: 0.17 | V15: 0.16 | W15: 0.12 | X15: 0.16 | Y15: 0.12 | Z15: 0.1 | AA15: 0.12 | AB15: 0.13 | AC15: 0.12 | AD15: 0.13 | AE15: 0.14 | AF15: 0.15 | AG15: 0.17 | AH15: 0.15 | AI15: 0.21 | AJ15: 0.19 | AK15: 0.17 | AL15: 0.17 | AM15: 0.18 | AN15: 0.13 | AO15: 0.16 | AP15: 0.17 | AQ15: 0.16 | AR15: 0.16 | AS15: -0.01 | AT15: -0.45 | AU15: -0.36 | AV15: -0.29 | AW15: -0.29 | AX15: -0.17 | AY15: 0.58 | AZ15: 0.52 | BA15: 0.53 | BB15: 0.32 | BC15: 0.53 | BD15: 0.58 | BE15: 0.44 | BF15: 0.31 | BG15: 0.45 | BH15: 0.35 | BI15: 0.24 | BJ15: 0.21 | BK15: 0.18 | BL15: 0.24 | BM15: 0.18 | BN15: 0.17 | BO15: 0.17 | BP15: 0.2 | BQ15: 0.18 | BR15: 0.15 | BS15: 0.15 | BT15: 0.15 | BU15: 0.14 | BV15: 0.15 | BW15: 0.13 | BX15: 0.12 | CF15: Release narrative ("cross-border volume growth of x% on a local currency basis"); 2006–09 not stated. Drives cross-border assessments inside payment network yield. | CH15: =IFERROR(AVERAGE(CA15,CB15,CC15,CD15,CE15),"n/m") -> n/m | CI15: =IFERROR(AVERAGE(BB15,BG15,BL15,BQ15,BV15),"n/m") -> 0.268 | CJ15: =IFERROR(AVERAGE(AC15,AH15,AM15,AR15,AW15,BB15,BG15,BL15,BQ15,BV15),"n/m") -> 0.166 | CK15: =IFERROR(AVERAGE(C15,D15,E15,F15,G15,H15,I15,N15,S15,X15,AC15,AH15,AM15,AR15,AW15,BB15,BG15,BL15,BQ15,BV15),"n/m") -> 0.1661875
B16: Memo: switched transactions growth % ("processed transactions" to Q3-16; release text) | F16: 0.069 | H16: 0.183 | I16: 0.25 | J16: 0.12 | K16: 0.11 | L16: 0.16 | M16: 0.13 | N16: 0.13 | O16: 0.14 | P16: 0.12 | Q16: 0.1 | R16: 0.11 | S16: 0.12 | T16: 0.12 | U16: 0.13 | V16: 0.12 | W16: 0.12 | X16: 0.12 | Y16: 0.14 | Z16: 0.14 | AA16: 0.18 | AB16: 0.17 | AC16: 0.16 | AD16: 0.17 | AE16: 0.17 | AF16: 0.17 | AG16: 0.17 | AH16: 0.17 | AI16: 0.17 | AJ16: 0.17 | AK16: 0.16 | AL16: 0.17 | AM16: 0.17 | AN16: 0.17 | AO16: 0.18 | AP16: 0.2 | AQ16: 0.19 | AR16: 0.19 | AS16: 0.13 | AT16: -0.1 | AU16: 0.05 | AV16: 0.04 | AW16: 0.03 | AX16: 0.09 | AY16: 0.41 | AZ16: 0.25 | BA16: 0.27 | BB16: 0.25 | BC16: 0.22 | BD16: 0.12 | BE16: 0.09 | BF16: 0.08 | BG16: 0.12 | BH16: 0.12 | BI16: 0.17 | BJ16: 0.15 | BK16: 0.12 | BL16: 0.14 | BM16: 0.13 | BN16: 0.11 | BO16: 0.11 | BP16: 0.11 | BQ16: 0.11 | BR16: 0.09 | BS16: 0.1 | BT16: 0.1 | BU16: 0.1 | BV16: 0.1 | BW16: 0.09 | BX16: 0.09 | CH16: =IFERROR(AVERAGE(CA16,CB16,CC16,CD16,CE16),"n/m") -> n/m | CI16: =IFERROR(AVERAGE(BB16,BG16,BL16,BQ16,BV16),"n/m") -> 0.144 | CJ16: =IFERROR(AVERAGE(AC16,AH16,AM16,AR16,AW16,BB16,BG16,BL16,BQ16,BV16),"n/m") -> 0.144 | CK16: =IFERROR(AVERAGE(C16,D16,E16,F16,G16,H16,I16,N16,S16,X16,AC16,AH16,AM16,AR16,AW16,BB16,BG16,BL16,BQ16,BV16),"n/m") -> 0.1445 | CN16: Q3/26E – Q4/26E and FY26 point estimates (all cases)
B17: Memo: Mastercard and Maestro-branded cards issued (bn; period end, release text) | C17: 0.817 | D17: 0.916 | E17: 0.981 | F17: 0.966 | G17: 1.6 | H17: 1.8 | I17: 1.9 | J17: 1.9 | K17: 1.9 | L17: 2 | M17: 2 | N17: 2 | O17: 2 | P17: 2 | Q17: 2.1 | R17: 2.1 | S17: 2.1 | T17: 2.2 | U17: 2.2 | V17: 2.2 | W17: 2.3 | X17: 2.3 | Y17: 2.3 | Z17: 2.3 | AA17: 2.3 | AB17: 2.3 | AC17: 2.3 | AD17: 2.4 | AE17: 2.4 | AF17: 2.4 | AG17: 2.4 | AH17: 2.4 | AI17: 2.4 | AJ17: 2.4 | AK17: 2.5 | AL17: 2.5 | AM17: 2.5 | AN17: 2.5 | AO17: 2.6 | AP17: 2.6 | AQ17: 2.6 | AR17: 2.6 | AS17: 2.6 | AT17: 2.6 | AU17: 2.7 | AV17: 2.8 | AW17: 2.8 | AX17: 2.8 | AY17: 2.9 | AZ17: 2.9 | BA17: 3 | BB17: 3 | BC17: 2.9 | BD17: 3 | BE17: 3 | BF17: 3.1 | BG17: 3.1 | BH17: 3.2 | BI17: 3.2 | BJ17: 3.3 | BK17: 3.3 | BL17: 3.3 | BM17: 3.4 | BN17: 3.4 | BO17: 3.4 | BP17: 3.5 | BQ17: 3.5 | BR17: 3.5 | BS17: 3.6 | BT17: 3.6 | BU17: 3.7 | BV17: 3.7 | BW17: 3.7 | BX17: 3.7 | CF17: Mastercard-branded only to 2009 (0.8–1.0bn); including Maestro from 2010. | CH17: =IFERROR((CE17/BV17)^(1/5)-1,"n/m") -> -1 | CI17: =IFERROR((BV17/AW17)^(1/5)-1,"n/m") -> 0.057325578 | CJ17: =IFERROR((BV17/X17)^(1/10)-1,"n/m") -> 0.048690633 | CK17: =IFERROR((BV17/C17)^(1/19)-1,"n/m") -> 0.082742653 | CN17: FY26 FX effect on net revenue growth (pp; memo) | CP17: 0.01 | CR17: Outlook: ~1 ppt FX tailwind for the year (H1-26: +2.6 ppt) — UNVERIFIED.
CN18: Q3/Q4-26E depreciation & amortization ($m per quarter) | CP18: 325 | CR18: Q2-26 $309m, Q1-26 $299m; rising with capitalized software and the June-2026 property additions.
B19: Payment network (assessments for switching, cross-border, scheme fees, less payment network rebates & incentives) | CF19: PAYMENT NETWORK — modelling logic (2027E+: GDV × yield; 2026E H2: prior-year quarter × (1 + H1-26 y/y + calibration Δ)) | CN19: Q3/Q4-26E investment income ($m per quarter) | CP19: 85 | CR19: Q2-26 $88m, Q1-26 $81m.
B20: Payment network net revenue | AW20: 9897 | AX20: 2648 | AY20: 2875 | AZ20: 3234 | BA20: 3186 | BB20: 11943 | BC20: 3399 | BD20: 3609 | BE20: 3765 | BF20: 3585 | BG20: 14358 | BH20: 3650 | BI20: 4073 | BJ20: 4210 | BK20: 3891 | BL20: 15824 | BM20: 3920 | BN20: 4375 | BO20: 4629 | BP20: 4411 | BQ20: 17335 | BR20: 4432 | BS20: 4945 | BT20: 5179 | BU20: 4920 | BV20: 19476 | BW20: 4948 | BX20: 5451 | BY20: =BT20*(1+BY21) -> 5591.3051 | BZ20: =BU20*(1+BZ21) -> 5311.6859 | CA20: =SUM(BW20:BZ20) -> 21301.991 | CB20: =CB11*CB23/10 -> 23459.35 | CC20: =CC11*CC23/10 -> 25716.14 | CD20: =CD11*CD23/10 -> 28051.165 | CE20: =CE11*CE23/10 -> 30456.552 | CF20: 10-Q / 10-K revenue tables (current presentation from the FY2022 10-K; FY2020–21 and 2021–22 quarters from the next filings' comparatives, Q4 = FY − 9M). Before 2020 net revenue is not split this way (legacy categories in memo below). | CH20: =IFERROR((CE20/BV20)^(1/5)-1,"n/m") -> 0.093543831 | CI20: =IFERROR((BV20/AW20)^(1/5)-1,"n/m") -> 0.14498353 | CJ20: =IFERROR((BV20/X20)^(1/10)-1,"n/m") -> n/m | CK20: =IFERROR((BV20/C20)^(1/19)-1,"n/m") -> n/m | CN20: Q3/Q4-26E interest expense ($m per quarter) | CP20: 255 | CR20: Q2-26 $218m; + a full quarter of the $5.0bn June-2026 notes (~4.5%, ~$55m) less the Nov-2026 $750m maturity.
B21: y/y % | D21: =IF(AND(ISNUMBER(D20),ISNUMBER(C20)),IFERROR(D20/C20-1,""),"") | E21: =IF(AND(ISNUMBER(E20),ISNUMBER(D20)),IFERROR(E20/D20-1,""),"") | F21: =IF(AND(ISNUMBER(F20),ISNUMBER(E20)),IFERROR(F20/E20-1,""),"") | G21: =IF(AND(ISNUMBER(G20),ISNUMBER(F20)),IFERROR(G20/F20-1,""),"") | H21: =IF(AND(ISNUMBER(H20),ISNUMBER(G20)),IFERROR(H20/G20-1,""),"") | I21: =IF(AND(ISNUMBER(I20),ISNUMBER(H20)),IFERROR(I20/H20-1,""),"") | N21: =IF(AND(ISNUMBER(N20),ISNUMBER(I20)),IFERROR(N20/I20-1,""),"") | O21: =IF(AND(ISNUMBER(O20),ISNUMBER(J20)),IFERROR(O20/J20-1,""),"") | P21: =IF(AND(ISNUMBER(P20),ISNUMBER(K20)),IFERROR(P20/K20-1,""),"") | Q21: =IF(AND(ISNUMBER(Q20),ISNUMBER(L20)),IFERROR(Q20/L20-1,""),"") | R21: =IF(AND(ISNUMBER(R20),ISNUMBER(M20)),IFERROR(R20/M20-1,""),"") | S21: =IF(AND(ISNUMBER(S20),ISNUMBER(N20)),IFERROR(S20/N20-1,""),"") | T21: =IF(AND(ISNUMBER(T20),ISNUMBER(O20)),IFERROR(T20/O20-1,""),"") | U21: =IF(AND(ISNUMBER(U20),ISNUMBER(P20)),IFERROR(U20/P20-1,""),"") | ... BX21: =IF(AND(ISNUMBER(BX20),ISNUMBER(BS20)),IFERROR(BX20/BS20-1,""),"") -> 0.10232558 | BY21: =BY22+$CA$95 -> 0.079610947 | BZ21: =BZ22+$CA$95 -> 0.079610947 | CA21: =IF(AND(ISNUMBER(CA20),ISNUMBER(BV20)),IFERROR(CA20/BV20-1,""),"") -> 0.093755954 | CB21: =IF(AND(ISNUMBER(CB20),ISNUMBER(CA20)),IFERROR(CB20/CA20-1,""),"") -> 0.101275 | CC21: =IF(AND(ISNUMBER(CC20),ISNUMBER(CB20)),IFERROR(CC20/CB20-1,""),"") -> 0.0962 | CD21: =IF(AND(ISNUMBER(CD20),ISNUMBER(CC20)),IFERROR(CD20/CC20-1,""),"") -> 0.0908 | CE21: =IF(AND(ISNUMBER(CE20),ISNUMBER(CD20)),IFERROR(CE20/CD20-1,""),"") -> 0.08575 | CF21: Q3/Q4-26E: H1-26 y/y growth + net revenue calibration Δ (Group block). | CN21: Q3/Q4-26E other income (expense), net ($m per quarter) | CP21: 45 | CR21: Set so total other income (expense) ≈ −$125m in Q3 (85 − 255 + 45), per the UNVERIFIED call guidance; H1-26 $106m incl. government grants.
B22: Q3/Q4-26E growth before revenue calibration (H1-26 y/y) | BY22: =IFERROR(SUM(BW20:BX20)/SUM(BR20:BS20)-1,0) -> 0.10899008 | BZ22: =IFERROR(SUM(BW20:BX20)/SUM(BR20:BS20)-1,0) -> 0.10899008 | CN22: Q3/Q4-26E tax rate (GAAP & adjusted) | CP22: 0.205 | CR22: Non-GAAP tax rate guided 20–21% for Q3 and Q4 (UNVERIFIED); H1-26 19.7%.
B23: Payment network yield (net revenue ÷ GDV, bps) | C23: =IF(AND(ISNUMBER(C20),ISNUMBER(C11)),IFERROR(C20/C11*10,""),"") | D23: =IF(AND(ISNUMBER(D20),ISNUMBER(D11)),IFERROR(D20/D11*10,""),"") | E23: =IF(AND(ISNUMBER(E20),ISNUMBER(E11)),IFERROR(E20/E11*10,""),"") | F23: =IF(AND(ISNUMBER(F20),ISNUMBER(F11)),IFERROR(F20/F11*10,""),"") | G23: =IF(AND(ISNUMBER(G20),ISNUMBER(G11)),IFERROR(G20/G11*10,""),"") | H23: =IF(AND(ISNUMBER(H20),ISNUMBER(H11)),IFERROR(H20/H11*10,""),"") | I23: =IF(AND(ISNUMBER(I20),ISNUMBER(I11)),IFERROR(I20/I11*10,""),"") | J23: =IF(AND(ISNUMBER(J20),ISNUMBER(J11)),IFERROR(J20/J11*10,""),"") | ... CA23: =IF(AND(ISNUMBER(CA20),ISNUMBER(CA11)),IFERROR(CA20/CA11*10,""),"") -> 18.378703 | CB23: =CA23*(1+CB24) -> 18.654383 | CC23: =CB23*(1+CC24) -> 18.934199 | CD23: =CC23*(1+CD24) -> 19.123541 | CE23: =CD23*(1+CE24) -> 19.314776 | CF23: bps of GDV (USD m ÷ USD bn × 10). Mix of cross-border (higher yield), switching, pricing, less rebates & incentives on new and renewed deals. 2027E+: prior year × (1 + yield change lever). | CH23: =IFERROR(AVERAGE(CA23,CB23,CC23,CD23,CE23),"n/m") -> 18.88112 | CI23: =IFERROR(AVERAGE(BB23,BG23,BL23,BQ23,BV23),"n/m") -> 17.327608 | CJ23: =IFERROR(AVERAGE(AC23,AH23,AM23,AR23,AW23,BB23,BG23,BL23,BQ23,BV23),"n/m") -> 17.04264 | CK23: =IFERROR(AVERAGE(C23,D23,E23,F23,G23,H23,I23,N23,S23,X23,AC23,AH23,AM23,AR23,AW23,BB23,BG23,BL23,BQ23,BV23),"n/m") -> 17.04264 | CN23: H2-26E capital expenditures incl. capitalized software ($m) | CP23: 700 | CR23: H1-26 $813m (property $445m, software $368m); FY2025 $1,215m.
B24: Payment network yield change y/y % (scenario lever 2027E+) | D24: =IF(AND(ISNUMBER(D23),ISNUMBER(C23)),IFERROR(D23/C23-1,""),"") | E24: =IF(AND(ISNUMBER(E23),ISNUMBER(D23)),IFERROR(E23/D23-1,""),"") | F24: =IF(AND(ISNUMBER(F23),ISNUMBER(E23)),IFERROR(F23/E23-1,""),"") | G24: =IF(AND(ISNUMBER(G23),ISNUMBER(F23)),IFERROR(G23/F23-1,""),"") | H24: =IF(AND(ISNUMBER(H23),ISNUMBER(G23)),IFERROR(H23/G23-1,""),"") | I24: =IF(AND(ISNUMBER(I23),ISNUMBER(H23)),IFERROR(I23/H23-1,""),"") | N24: =IF(AND(ISNUMBER(N23),ISNUMBER(I23)),IFERROR(N23/I23-1,""),"") | O24: =IF(AND(ISNUMBER(O23),ISNUMBER(J23)),IFERROR(O23/J23-1,""),"") | P24: =IF(AND(ISNUMBER(P23),ISNUMBER(K23)),IFERROR(P23/K23-1,""),"") | Q24: =IF(AND(ISNUMBER(Q23),ISNUMBER(L23)),IFERROR(Q23/L23-1,""),"") | R24: =IF(AND(ISNUMBER(R23),ISNUMBER(M23)),IFERROR(R23/M23-1,""),"") | S24: =IF(AND(ISNUMBER(S23),ISNUMBER(N23)),IFERROR(S23/N23-1,""),"") | T24: =IF(AND(ISNUMBER(T23),ISNUMBER(O23)),IFERROR(T23/O23-1,""),"") | U24: =IF(AND(ISNUMBER(U23),ISNUMBER(P23)),IFERROR(U23/P23-1,""),"") | ... CA24: =IF(AND(ISNUMBER(CA23),ISNUMBER(BV23)),IFERROR(CA23/BV23-1,""),"") -> 0.0032982437 | CB24: =CHOOSE(MATCH($CF$2,{"Bull","Base","Bear"},0),$CO$33,$CP$33,$CQ$33) -> 0.015 | CC24: =CHOOSE(MATCH($CF$2,{"Bull","Base","Bear"},0),$CO$34,$CP$34,$CQ$34) -> 0.015 | CD24: =CHOOSE(MATCH($CF$2,{"Bull","Base","Bear"},0),$CO$35,$CP$35,$CQ$35) -> 0.01 | CE24: =CHOOSE(MATCH($CF$2,{"Bull","Base","Bear"},0),$CO$36,$CP$36,$CQ$36) -> 0.01
B25: Memo: payment network rebates & incentives growth % (release text, from 2020) | AT25: -0.1 | AU25: 0 | AV25: 0 | AW25: 0.03 | AX25: 0.06 | AY25: 0.53 | AZ25: 0.35 | BA25: 0.37 | BB25: 0.32 | BC25: 0.26 | BD25: 0.19 | BE25: 0.2 | BF25: 0.14 | BG25: 0.19 | BH25: 0.25 | BI25: 0.22 | BJ25: 0.22 | BK25: 0.19 | BL25: 0.22 | BM25: 0.2 | BN25: 0.14 | BO25: 0.17 | BP25: 0.14 | BQ25: 0.16 | BR25: 0.12 | BS25: 0.17 | BT25: 0.16 | BU25: 0.2 | BV25: 0.16 | BW25: 0.23 | BX25: 0.22 | CN25: Target net debt / adjusted EBITDA (x) — buyback plug 2027E+ | CO25: 0.7 | CP25: 0.5 | CQ25: 0.3 | CR25: Net debt (total debt − unrestricted cash − investments) $13.0bn at 30-Jun-2026 ≈ 0.6x LTM adjusted EBITDA (model); FY2023–25 0.3–0.4x. Mastercard has no stated leverage target; it returns excess capital through buybacks (FY2025 $11.7bn). Target = leverage up to which surplus cash is returned (assumption).
B26: Memo: payment network growth, currency-neutral % (release text) | BH26: 0.1 | BI26: 0.14 | BJ26: 0.1 | BK26: 0.07 | BL26: 0.1 | BM26: 0.08 | BN26: 0.09 | BO26: 0.11 | BP26: 0.15 | BQ26: 0.11 | BR26: 0.16 | BS26: 0.13 | BT26: 0.1 | BU26: 0.09 | BV26: 0.12 | BW26: 0.08 | BX26: 0.08
CN27: GDV (gross dollar volume growth, local currency) | CO27: 0.015 | CP27: Δ → | CQ27: -0.025 | CR27: H1-26 +7.7% local (FY2025 +8.6%, FY2024 +9.2%); purchase volume +9–10%. Secular cash-to-card and tokenized / e-commerce shift; Bear = consumer slowdown / U.S. debit share loss.
B28: Value-added services and solutions (cyber & intelligence, data & services, open banking, loyalty, processing) | CF28: VALUE-ADDED SERVICES — prior year × (1 + growth); includes acquisitions (Recorded Future Dec-2024) — the company reports VAS growth incl. M&A | CN28: 2027E | CO28: =CP28+$CO$27 -> 0.1 | CP28: 0.085 | CQ28: =CP28+$CQ$27 -> 0.06
B29: Value-added services and solutions net revenue | AW29: 5404 | AX29: 1507 | AY29: 1653 | AZ29: 1751 | BA29: 2030 | BB29: 6941 | BC29: 1768 | BD29: 1888 | BE29: 1991 | BF29: 2232 | BG29: 7879 | BH29: 2098 | BI29: 2196 | BJ29: 2323 | BK29: 2657 | BL29: 9274 | BM29: 2428 | BN29: 2586 | BO29: 2740 | BP29: 3078 | BQ29: 10832 | BR29: 2818 | BS29: 3188 | BT29: 3423 | BU29: 3886 | BV29: 13315 | BW29: 3450 | BX29: 3826 | BY29: =BT29*(1+BY30) -> 4046.2464 | BZ29: =BU29*(1+BZ30) -> 4593.5476 | CA29: =SUM(BW29:BZ29) -> 15915.794 | CB29: =CA29*(1+CB30) -> 18303.163 | CC29: =CB29*(1+CC30) -> 20865.606 | CD29: =CC29*(1+CD30) -> 23578.135 | CE29: =CD29*(1+CE30) -> 26407.511 | CF29: Same sources as payment network. Q3/Q4-26E: prior-year quarter × (1 + H1-26 y/y + calibration Δ); 2027E+: scenario lever. | CH29: =IFERROR((CE29/BV29)^(1/5)-1,"n/m") -> 0.14677247 | CI29: =IFERROR((BV29/AW29)^(1/5)-1,"n/m") -> 0.19763689 | CJ29: =IFERROR((BV29/X29)^(1/10)-1,"n/m") -> n/m | CK29: =IFERROR((BV29/C29)^(1/19)-1,"n/m") -> n/m | CN29: 2028E | CO29: =CP29+$CO$27 -> 0.095 | CP29: 0.08 | CQ29: =CP29+$CQ$27 -> 0.055
B30: y/y % | D30: =IF(AND(ISNUMBER(D29),ISNUMBER(C29)),IFERROR(D29/C29-1,""),"") | E30: =IF(AND(ISNUMBER(E29),ISNUMBER(D29)),IFERROR(E29/D29-1,""),"") | F30: =IF(AND(ISNUMBER(F29),ISNUMBER(E29)),IFERROR(F29/E29-1,""),"") | G30: =IF(AND(ISNUMBER(G29),ISNUMBER(F29)),IFERROR(G29/F29-1,""),"") | H30: =IF(AND(ISNUMBER(H29),ISNUMBER(G29)),IFERROR(H29/G29-1,""),"") | I30: =IF(AND(ISNUMBER(I29),ISNUMBER(H29)),IFERROR(I29/H29-1,""),"") | N30: =IF(AND(ISNUMBER(N29),ISNUMBER(I29)),IFERROR(N29/I29-1,""),"") | O30: =IF(AND(ISNUMBER(O29),ISNUMBER(J29)),IFERROR(O29/J29-1,""),"") | P30: =IF(AND(ISNUMBER(P29),ISNUMBER(K29)),IFERROR(P29/K29-1,""),"") | Q30: =IF(AND(ISNUMBER(Q29),ISNUMBER(L29)),IFERROR(Q29/L29-1,""),"") | R30: =IF(AND(ISNUMBER(R29),ISNUMBER(M29)),IFERROR(R29/M29-1,""),"") | S30: =IF(AND(ISNUMBER(S29),ISNUMBER(N29)),IFERROR(S29/N29-1,""),"") | T30: =IF(AND(ISNUMBER(T29),ISNUMBER(O29)),IFERROR(T29/O29-1,""),"") | U30: =IF(AND(ISNUMBER(U29),ISNUMBER(P29)),IFERROR(U29/P29-1,""),"") | ... BX30: =IF(AND(ISNUMBER(BX29),ISNUMBER(BS29)),IFERROR(BX29/BS29-1,""),"") -> 0.20012547 | BY30: =BY31+$CA$95 -> 0.18207608 | BZ30: =BZ31+$CA$95 -> 0.18207608 | CA30: =IF(AND(ISNUMBER(CA29),ISNUMBER(BV29)),IFERROR(CA29/BV29-1,""),"") -> 0.19532813 | CB30: =CHOOSE(MATCH($CF$2,{"Bull","Base","Bear"},0),$CO$38,$CP$38,$CQ$38) -> 0.15 | CC30: =CHOOSE(MATCH($CF$2,{"Bull","Base","Bear"},0),$CO$39,$CP$39,$CQ$39) -> 0.14 | CD30: =CHOOSE(MATCH($CF$2,{"Bull","Base","Bear"},0),$CO$40,$CP$40,$CQ$40) -> 0.13 | CE30: =CHOOSE(MATCH($CF$2,{"Bull","Base","Bear"},0),$CO$41,$CP$41,$CQ$41) -> 0.12 | CN30: 2029E | CO30: =CP30+$CO$27 -> 0.095 | CP30: 0.08 | CQ30: =CP30+$CQ$27 -> 0.055
B31: Q3/Q4-26E growth before revenue calibration (H1-26 y/y) | BY31: =IFERROR(SUM(BW29:BX29)/SUM(BR29:BS29)-1,0) -> 0.21145521 | BZ31: =IFERROR(SUM(BW29:BX29)/SUM(BR29:BS29)-1,0) -> 0.21145521 | CN31: 2030E | CO31: =CP31+$CO$27 -> 0.09 | CP31: 0.075 | CQ31: =CP31+$CQ$27 -> 0.05
B32: Memo: value-added services growth, currency-neutral % (release text) | BH32: 0.21 | BI32: 0.16 | BJ32: 0.14 | BK32: 0.17 | BL32: 0.17 | BM32: 0.15 | BN32: 0.19 | BO32: 0.19 | BP32: 0.17 | BQ32: 0.17 | BR32: 0.18 | BS32: 0.22 | BT32: 0.22 | BU32: 0.22 | BV32: 0.21 | BW32: 0.18 | BX32: 0.18 | CN32: YLD (payment network yield change y/y) | CO32: 0.01 | CP32: Δ → | CQ32: -0.015 | CR32: Yield 15.5 bps (2021) → 18.3 bps (2025): cross-border recovery (higher-yield), pricing and switching, partly offset by rising rebates & incentives (+22% in H1-26). Bear = rebate pressure / regulation (interchange / CCCA).
B33: Value-added services % of net revenue | C33: =IF(AND(ISNUMBER(C29),ISNUMBER(C77)),IFERROR(C29/C77,""),"") | D33: =IF(AND(ISNUMBER(D29),ISNUMBER(D77)),IFERROR(D29/D77,""),"") | E33: =IF(AND(ISNUMBER(E29),ISNUMBER(E77)),IFERROR(E29/E77,""),"") | F33: =IF(AND(ISNUMBER(F29),ISNUMBER(F77)),IFERROR(F29/F77,""),"") | G33: =IF(AND(ISNUMBER(G29),ISNUMBER(G77)),IFERROR(G29/G77,""),"") | H33: =IF(AND(ISNUMBER(H29),ISNUMBER(H77)),IFERROR(H29/H77,""),"") | I33: =IF(AND(ISNUMBER(I29),ISNUMBER(I77)),IFERROR(I29/I77,""),"") | J33: =IF(AND(ISNUMBER(J29),ISNUMBER(J77)),IFERROR(J29/J77,""),"") | ... CE33: =IF(AND(ISNUMBER(CE29),ISNUMBER(CE77)),IFERROR(CE29/CE77,""),"") -> 0.46006935 | CH33: =IFERROR(AVERAGE(CA33,CB33,CC33,CD33,CE33),"n/m") -> 0.44496864 | CI33: =IFERROR(AVERAGE(BB33,BG33,BL33,BQ33,BV33),"n/m") -> 0.37640215 | CJ33: =IFERROR(AVERAGE(AC33,AH33,AM33,AR33,AW33,BB33,BG33,BL33,BQ33,BV33),"n/m") -> 0.37253172 | CK33: =IFERROR(AVERAGE(C33,D33,E33,F33,G33,H33,I33,N33,S33,X33,AC33,AH33,AM33,AR33,AW33,BB33,BG33,BL33,BQ33,BV33),"n/m") -> 0.37253172 | CN33: 2027E | CO33: =CP33+$CO$32 -> 0.025 | CP33: 0.015 | CQ33: =CP33+$CQ$32 -> 0
CN34: 2028E | CO34: =CP34+$CO$32 -> 0.025 | CP34: 0.015 | CQ34: =CP34+$CQ$32 -> 0
B35: Net revenue not split into payment network / value-added services (FY2006–19, Q1-13 – Q4-20) | C35: =IF(ISNUMBER(C20),0,C123) -> 3326.074 | D35: =IF(ISNUMBER(D20),0,D123) -> 4067.599 | E35: =IF(ISNUMBER(E20),0,E123) -> 4991.6 | F35: =IF(ISNUMBER(F20),0,F123) -> 5098.684 | G35: =IF(ISNUMBER(G20),0,G123) -> 5539 | H35: =IF(ISNUMBER(H20),0,H123) -> 6714 | I35: =IF(ISNUMBER(I20),0,I123) -> 7391 | J35: =IF(ISNUMBER(J20),0,J123) -> 1906 | ... BX35: =IF(ISNUMBER(BX20),0,BX123) -> 0 | BY35: =0 -> 0 | BZ35: =0 -> 0 | CA35: =SUM(BW35:BZ35) -> 0 | CB35: =0 -> 0 | CC35: =0 -> 0 | CD35: =0 -> 0 | CE35: =0 -> 0 | CF35: History before the current presentation (first presented in the FY2022 10-K, with FY2020–21 comparatives): consolidated net revenue. The legacy categories are in the memo block below. | CN35: 2029E | CO35: =CP35+$CO$32 -> 0.02 | CP35: 0.01 | CQ35: =CP35+$CQ$32 -> -0.005
B36: Legacy revenue categories (as presented FY2006–Q3-22; FY2006 not published; 2007–08 recast in the FY2009 10-K) — memo: | CN36: 2030E | CO36: =CP36+$CO$32 -> 0.02 | CP36: 0.01 | CQ36: =CP36+$CQ$32 -> -0.005
B37: Domestic assessments | D37: 2099 | E37: 2386 | F37: 2382 | G37: 2642 | H37: 3246 | I37: 3586 | J37: 901 | K37: 940 | L37: 963 | M37: 1001 | N37: 3805 | O37: 938 | P37: 1008 | Q37: 1003 | R37: 1018 | S37: 3967 | T37: 963 | U37: 1028 | V37: 1028 | W37: 1067 | X37: 4086 | Y37: 1027 | Z37: 1110 | AA37: 1132 | AB37: 1142 | AC37: 4411 | AD37: 1189 | AE37: 1260 | AF37: 1302 | AG37: 1379 | AH37: 5130 | AI37: 1458 | AJ37: 1537 | AK37: 1564 | AL37: 1579 | AM37: 6138 | AN37: 1605 | AO37: 1680 | AP37: 1722 | AQ37: 1774 | AR37: 6781 | AS37: 1683 | AT37: 1474 | AU37: 1750 | AV37: 1749 | AW37: 6656 | AX37: 1798 | AY37: 2056 | AZ37: 2139 | BA37: 2165 | BB37: 8158 | BC37: 2134 | BD37: 2283 | BE37: 2252 | CH37: =IFERROR((CE37/BV37)^(1/5)-1,"n/m") -> n/m | CI37: =IFERROR((BV37/AW37)^(1/5)-1,"n/m") -> -1 | CJ37: =IFERROR((BV37/X37)^(1/10)-1,"n/m") -> -1 | CK37: =IFERROR((BV37/C37)^(1/19)-1,"n/m") -> n/m | CN37: VAS (value-added services and solutions growth) | CO37: 0.03 | CP37: Δ → | CQ37: -0.05 | CR37: FY2025 +23% (incl. Recorded Future from Dec-2024), H1-26 +21% (+18% currency-neutral). Security, digital & authentication, consumer engagement, data & insights, open banking.
B38: Cross-border volume fees | D38: 1180 | E38: 1547 | F38: 1509 | G38: 1927 | H38: 2094 | I38: 2343 | J38: 607 | K38: 677 | L38: 760 | M38: 749 | N38: 2793 | O38: 695 | P38: 750 | Q38: 835 | R38: 774 | S38: 3054 | T38: 724 | U38: 777 | V38: 880 | W38: 844 | X38: 3225 | Y38: 796 | Z38: 866 | AA38: 996 | AB38: 910 | AC38: 3568 | AD38: 916 | AE38: 984 | AF38: 1157 | AG38: 1117 | AH38: 4174 | AI38: 1157 | AJ38: 1198 | AK38: 1338 | AL38: 1261 | AM38: 4954 | AN38: 1263 | AO38: 1374 | AP38: 1517 | AQ38: 1452 | AR38: 5606 | AS38: 1217 | AT38: 637 | AU38: 791 | AV38: 867 | AW38: 3512 | AX38: 932 | AY38: 1076 | AZ38: 1276 | BA38: 1380 | BB38: 4664 | BC38: 1395 | BD38: 1615 | BE38: 1803 | CH38: =IFERROR((CE38/BV38)^(1/5)-1,"n/m") -> n/m | CI38: =IFERROR((BV38/AW38)^(1/5)-1,"n/m") -> -1 | CJ38: =IFERROR((BV38/X38)^(1/10)-1,"n/m") -> -1 | CK38: =IFERROR((BV38/C38)^(1/19)-1,"n/m") -> n/m | CN38: 2027E | CO38: =CP38+$CO$37 -> 0.18 | CP38: 0.15 | CQ38: =CP38+$CQ$37 -> 0.1
B39: Transaction processing fees | D39: 1490 | E39: 1777 | F39: 2042 | G39: 2198 | H39: 2595 | I39: 3017 | J39: 775 | K39: 818 | L39: 865 | M39: 901 | N39: 3359 | O39: 936 | P39: 995 | Q39: 1041 | R39: 1063 | S39: 4035 | T39: 1006 | U39: 1051 | V39: 1140 | W39: 1148 | X39: 4345 | Y39: 1165 | Z39: 1271 | AA39: 1357 | AB39: 1350 | AC39: 5143 | AD39: 1347 | AE39: 1496 | AF39: 1662 | AG39: 1683 | AH39: 6188 | AI39: 1707 | AJ39: 1830 | AK39: 1912 | AL39: 1942 | AM39: 7391 | AN39: 1922 | AO39: 2053 | AP39: 2231 | AQ39: 2263 | AR39: 8469 | AS39: 2200 | AT39: 1901 | AU39: 2251 | AV39: 2379 | AW39: 8731 | AX39: 2351 | AY39: 2612 | AZ39: 2849 | BA39: 2987 | BB39: 10799 | BC39: 2912 | BD39: 3061 | BE39: 3288 | CH39: =IFERROR((CE39/BV39)^(1/5)-1,"n/m") -> n/m | CI39: =IFERROR((BV39/AW39)^(1/5)-1,"n/m") -> -1 | CJ39: =IFERROR((BV39/X39)^(1/10)-1,"n/m") -> -1 | CK39: =IFERROR((BV39/C39)^(1/19)-1,"n/m") -> n/m | CN39: 2028E | CO39: =CP39+$CO$37 -> 0.17 | CP39: 0.14 | CQ39: =CP39+$CQ$37 -> 0.09
B40: Other revenues | D40: 622 | E40: 751 | F40: 784 | G40: 791 | H40: 1000 | I40: 1154 | J40: 280 | K40: 315 | L40: 336 | M40: 400 | N40: 1331 | O40: 341 | P40: 392 | Q40: 460 | R40: 495 | S40: 1688 | T40: 418 | U40: 474 | V40: 501 | W40: 598 | X40: 1991 | Y40: 497 | Z40: 590 | AA40: 620 | AB40: 724 | AC40: 2431 | AD40: 561 | AE40: 694 | AF40: 747 | AG40: 851 | AH40: 2853 | AI40: 748 | AJ40: 785 | AK40: 819 | AL40: 996 | AM40: 3348 | AN40: 842 | AO40: 962 | AP40: 1087 | AQ40: 1233 | AR40: 4124 | AS40: 1062 | AT40: 1081 | AU40: 1143 | AV40: 1431 | AW40: 4717 | AX40: 1347 | AY40: 1475 | AZ40: 1562 | BA40: 1840 | BB40: 6224 | BC40: 1584 | BD40: 1745 | BE40: 1824 | CH40: =IFERROR((CE40/BV40)^(1/5)-1,"n/m") -> n/m | CI40: =IFERROR((BV40/AW40)^(1/5)-1,"n/m") -> -1 | CJ40: =IFERROR((BV40/X40)^(1/10)-1,"n/m") -> -1 | CK40: =IFERROR((BV40/C40)^(1/19)-1,"n/m") -> n/m | CN40: 2029E | CO40: =CP40+$CO$37 -> 0.16 | CP40: 0.13 | CQ40: =CP40+$CQ$37 -> 0.08
...

Sheet Bull-Base-Bear
B2: Mastercard Incorporated (MA) — Bull / Base / Bear Case P&L Summary | J2: Share price ($): | K2: =Model!$CA$392 -> 595
B3: Adjusted figures (company definitions: adjusted operating income, adjusted EPS; adjusted EBITDA is a model definition) · USD millions · Live panel linked to Model — toggle the scenario on the Model sheet (cell CF2). Bull and Bear panels are value snapshots generated from the Model with the switch set to each case. 2026E = Q1–Q2 actual + Q3/Q4 calibrated to the FY26 outlook (net revenue growth high end of low double digits; adjusted opex growth low double digits) — outlook UNVERIFIED (earnings call, not an SEC filing). | J3: As of: | K3: =TODAY() -> 2026-10-13 00:00:00
B5: Scenario: | C5: =Model!$CF$2 -> Base | N5: Scenario: | O5: Bull | P5: Snapshot (values) — Model run with switch = Bull | Z5: Scenario: | AA5: Bear | AB5: Snapshot (values) — Model run with switch = Bear
B7: (USDm, except EPS and shares) | C7: 2025A | D7: 2026E | E7: 2027E | F7: 2028E | G7: 2029E | H7: 2030E | I7: 25-'30 CAGR | J7: LT Hist Avg | K7: LT Hist Min | L7: LT Hist Max | N7: (USDm, except EPS and shares) | O7: 2025A | P7: 2026E | Q7: 2027E | R7: 2028E | S7: 2029E | T7: 2030E | U7: 25-'30 CAGR | V7: LT Hist Avg | W7: LT Hist Min | X7: LT Hist Max | Z7: (USDm, except EPS and shares) | AA7: 2025A | AB7: 2026E | AC7: 2027E | AD7: 2028E | AE7: 2029E | AF7: 2030E | AG7: 25-'30 CAGR | AH7: LT Hist Avg | AI7: LT Hist Min | AJ7: LT Hist Max
B9: Net revenue | C9: =Model!BV123 -> 32791 | D9: =Model!CA123 -> 37217.785 | E9: =Model!CB123 -> 41825.013 | F9: =Model!CC123 -> 46784.246 | G9: =Model!CD123 -> 51988.6 | H9: =Model!CE123 -> 57398.979 | I9: =IFERROR((H9/C9)^(1/5)-1,"n/m") -> 0.11848432 | N9: Net revenue | O9: 32791 | P9: 37381.74 | Q9: 43080.855 | R9: 49449.698 | S9: 56381.207 | T9: 63865.69 | U9: 0.14262202 | Z9: Net revenue | AA9: 32791 | AB9: 37053.83 | AC9: 39942.188 | AD9: 42817.397 | AE9: 45595.098 | AF9: 48233.391 | AG9: 0.08023595
B10: Net revenue y/y % | D10: =IFERROR(D9/C9-1,"") -> 0.135 | E10: =IFERROR(E9/D9-1,"") -> 0.12379104 | F10: =IFERROR(F9/E9-1,"") -> 0.11857097 | G10: =IFERROR(G9/F9-1,"") -> 0.1112416 | H10: =IFERROR(H9/G9-1,"") -> 0.10406858 | N10: Net revenue y/y % | P10: 0.14 | Q10: 0.15245719 | R10: 0.14783466 | S10: 0.14017292 | T10: 0.13274782 | Z10: Net revenue y/y % | AB10: 0.13 | AC10: 0.077950323 | AD10: 0.071984273 | AE10: 0.064873176 | AF10: 0.057863521
B11: Payment network y/y % | C11: =Model!BV212 -> 0.12350736 | D11: =Model!CA212 -> 0.093755954 | E11: =Model!CB212 -> 0.101275 | F11: =Model!CC212 -> 0.0962 | G11: =Model!CD212 -> 0.0908 | H11: =Model!CE212 -> 0.08575 | N11: Payment network y/y % | O11: 0.12350736 | P11: 0.098639715 | Q11: 0.1275 | R11: 0.122375 | S11: 0.1169 | T11: 0.1118 | Z11: Payment network y/y % | AA11: 0.12350736 | AB11: 0.088872193 | AC11: 0.06 | AD11: 0.055 | AE11: 0.049725 | AF11: 0.04475
B12: Adjusted EBITDA (model) | C12: =Model!BV185 -> 20544 | D12: =Model!CA185 -> 23545.935 | E12: =Model!CB185 -> 26679.846 | F12: =Model!CC185 -> 30045.866 | G12: =Model!CD185 -> 33610.893 | H12: =Model!CE185 -> 37351.919 | I12: =IFERROR((H12/C12)^(1/5)-1,"n/m") -> 0.12700432 | N12: Adjusted EBITDA (model) | O12: 20544 | P12: 23776.84 | Q12: 27904.907 | R12: 32230.298 | S12: 36975.03 | T12: 42139.302 | U12: 0.15451736 | Z12: Adjusted EBITDA (model) | AA12: 20544 | AB12: 23315.03 | AC12: 24886.603 | AD12: 26876.654 | AE12: 28829.369 | AF12: 30716.011 | AG12: 0.0837671
B13: Adjusted EBITDA margin % | C13: =IFERROR(C12/C9,"") -> 0.62651337 | D13: =IFERROR(D12/D9,"") -> 0.63265278 | E13: =IFERROR(E12/E9,"") -> 0.63789211 | F13: =IFERROR(F12/F9,"") -> 0.64222187 | G13: =IFERROR(G12/G9,"") -> 0.64650507 | H13: =IFERROR(H12/H9,"") -> 0.65074186 | J13: =IFERROR(AVERAGE(Model!C186,Model!D186,Model!E186,Model!F186,Model!G186,Model!H186,Model!I186,Model!N186,Model!S186,Model!X186,Model!AC186,Model!AH186,Model!AM186,Model!AR186,Model!AW186,Model!BB186,Model!BG186,Model!BL186,Model!BQ186,Model!BV186),"") -> 0.53713235 | K13: =IFERROR(MIN(Model!C186,Model!D186,Model!E186,Model!F186,Model!G186,Model!H186,Model!I186,Model!N186,Model!S186,Model!X186,Model!AC186,Model!AH186,Model!AM186,Model!AR186,Model!AW186,Model!BB186,Model!BG186,Model!BL186,Model!BQ186,Model!BV186),"") -> 0.2252737 | L13: =IFERROR(MAX(Model!C186,Model!D186,Model!E186,Model!F186,Model!G186,Model!H186,Model!I186,Model!N186,Model!S186,Model!X186,Model!AC186,Model!AH186,Model!AM186,Model!AR186,Model!AW186,Model!BB186,Model!BG186,Model!BL186,Model!BQ186,Model!BV186),"") -> 0.62651337 | N13: Adjusted EBITDA margin % | O13: 0.62651337 | P13: 0.63605493 | Q13: 0.64773336 | R13: 0.65177947 | S13: 0.65580415 | T13: 0.65981127 | V13: 0.53713235 | W13: 0.2252737 | X13: 0.62651337 | Z13: Adjusted EBITDA margin % | AA13: 0.62651337 | AB13: 0.62922052 | AC13: 0.6230656 | AD13: 0.62770407 | AE13: 0.63229097 | AF13: 0.63682049 | AH13: 0.53713235 | AI13: 0.2252737 | AJ13: 0.62651337
B15: Operating income (GAAP) | C15: =Model!BV130 -> 18897 | D15: =Model!CA130 -> 21803.935 | E15: =Model!CB130 -> 24742.17 | F15: =Model!CC130 -> 27902.076 | G15: =Model!CD130 -> 31252.656 | H15: =Model!CE130 -> 34772.229 | I15: =IFERROR((H15/C15)^(1/5)-1,"n/m") -> 0.1297125 | N15: Operating income (GAAP) | O15: 18897 | P15: 22034.84 | Q15: 25915.158 | R15: 29967.759 | S15: 34420.569 | T15: 39274.118 | U15: 0.15755788 | Z15: Operating income (GAAP) | AA15: 18897 | AB15: 21573.03 | AC15: 23022.319 | AD15: 24895.863 | AE15: 26735.385 | AF15: 28513.576 | AG15: 0.085754819
B16: Operating income y/y % | D16: =IFERROR(D15/C15-1,"") -> 0.1538305 | E16: =IFERROR(E15/D15-1,"") -> 0.13475712 | F16: =IFERROR(F15/E15-1,"") -> 0.12771336 | G16: =IFERROR(G15/F15-1,"") -> 0.12008352 | H16: =IFERROR(H15/G15-1,"") -> 0.11261676 | N16: Operating income y/y % | P16: 0.16604964 | Q16: 0.17609921 | R16: 0.15637955 | S16: 0.14858669 | T16: 0.14100725 | Z16: Operating income y/y % | AB16: 0.14161137 | AC16: 0.067180598 | AD16: 0.081379458 | AE16: 0.073888681 | AF16: 0.066510762
B17: Operating margin (GAAP) % | C17: =IFERROR(C15/C9,"") -> 0.57628618 | D17: =IFERROR(D15/D9,"") -> 0.5858472 | E17: =IFERROR(E15/E9,"") -> 0.59156396 | F17: =IFERROR(F15/F9,"") -> 0.59639898 | G17: =IFERROR(G15/G9,"") -> 0.6011444 | H17: =IFERROR(H15/H9,"") -> 0.60579873 | J17: =IFERROR(AVERAGE(Model!C225,Model!D225,Model!E225,Model!F225,Model!G225,Model!H225,Model!I225,Model!N225,Model!S225,Model!X225,Model!AC225,Model!AH225,Model!AM225,Model!AR225,Model!AW225,Model!BB225,Model!BG225,Model!BL225,Model!BQ225,Model!BV225),"") -> 0.45701046 | K17: =IFERROR(MIN(Model!C225,Model!D225,Model!E225,Model!F225,Model!G225,Model!H225,Model!I225,Model!N225,Model!S225,Model!X225,Model!AC225,Model!AH225,Model!AM225,Model!AR225,Model!AW225,Model!BB225,Model!BG225,Model!BL225,Model!BQ225,Model!BV225),"") -> -0.1070809 | L17: =IFERROR(MAX(Model!C225,Model!D225,Model!E225,Model!F225,Model!G225,Model!H225,Model!I225,Model!N225,Model!S225,Model!X225,Model!AC225,Model!AH225,Model!AM225,Model!AR225,Model!AW225,Model!BB225,Model!BG225,Model!BL225,Model!BQ225,Model!BV225),"") -> 0.57628618 | N17: Operating margin (GAAP) % | O17: 0.57628618 | P17: 0.58945464 | Q17: 0.60154697 | R17: 0.6060251 | S17: 0.61049719 | T17: 0.61494863 | V17: 0.45701046 | W17: -0.1070809 | X17: 0.57628618 | Z17: Operating margin (GAAP) % | AA17: 0.57628618 | AB17: 0.58220783 | AC17: 0.57639103 | AD17: 0.58144269 | AE17: 0.58636535 | AF17: 0.59115844 | AH17: 0.45701046 | AI17: -0.1070809 | AJ17: 0.57628618
B19: Adjusted Net Income | C19: =Model!BV198 -> 15415 | D19: =Model!CA198 -> 17507.648 | E19: =Model!CB198 -> 19686.972 | F19: =Model!CC198 -> 22159.558 | G19: =Model!CD198 -> 24756.254 | H19: =Model!CE198 -> 27480.942 | I19: =IFERROR((H19/C19)^(1/5)-1,"n/m") -> 0.12258082 | N19: Adjusted Net Income | O19: 15415 | P19: 17691.218 | Q19: 20605.266 | R19: 23616.242 | S19: 27039.932 | T19: 30771.294 | U19: 0.14826055 | Z19: Adjusted Net Income | AA19: 15415 | AB19: 17324.079 | AC19: 18338.367 | AD19: 19900.373 | AE19: 21319.953 | AF19: 22689.489 | AG19: 0.080379255
B21: FDSO (m) | C21: =Model!BV152 -> 906 | D21: =Model!CA152 -> 880.28382 | E21: =Model!CB152 -> 856.33569 | F21: =Model!CC152 -> 833.74802 | G21: =Model!CD152 -> 809.29611 | H21: =Model!CE152 -> 784.00495 | I21: =IFERROR((H21/C21)^(1/5)-1,"n/m") -> -0.028510477 | N21: FDSO (m) | O21: 906 | P21: 879.94769 | Q21: 850.47719 | R21: 821.80707 | S21: 793.6735 | T21: 763.59132 | U21: -0.033623063 | Z21: FDSO (m) | AA21: 906 | AB21: 880.70399 | AC21: 862.40428 | AD21: 846.10548 | AE21: 826.15156 | AF21: 806.73753 | AG21: -0.022940947
B23: Adjusted EPS — Diluted ($) | C23: =Model!BV201 -> 17.014349 | D23: =Model!CA201 -> 19.88864 | E23: =Model!CB201 -> 22.989783 | F23: =Model!CC201 -> 26.578244 | G23: =Model!CD201 -> 30.58986 | H23: =Model!CE201 -> 35.052001 | I23: =IFERROR((H23/C23)^(1/5)-1,"n/m") -> 0.1555254 | N23: Adjusted EPS — Diluted ($) | O23: 17.014349 | P23: 20.104852 | Q23: 24.227887 | R23: 28.736967 | S23: 34.06934 | T23: 40.298119 | U23: 0.18821187 | Z23: Adjusted EPS — Diluted ($) | AA23: 17.014349 | AB23: 19.670717 | AC23: 21.264234 | AD23: 23.519967 | AE23: 25.806346 | AF23: 28.124995 | AG23: 0.10574612
B24: EPS y/y % | D24: =IFERROR(D23/C23-1,"") -> 0.16893338 | E24: =IFERROR(E23/D23-1,"") -> 0.15592533 | F24: =IFERROR(F23/E23-1,"") -> 0.15608938 | G24: =IFERROR(G23/F23-1,"") -> 0.15093606 | H24: =IFERROR(H23/G23-1,"") -> 0.14586994 | N24: EPS y/y % | P24: 0.18164098 | Q24: 0.20507665 | R24: 0.18611113 | S24: 0.18555796 | T24: 0.18282653 | Z24: EPS y/y % | AB24: 0.15612517 | AC24: 0.081009624 | AD24: 0.10608106 | AE24: 0.097210117 | AF24: 0.089848022
B26: P / E (x) — assumed (adjusted EPS) | G26: 33 | H26: 33 | N26: P / E (x) — assumed (adjusted EPS) | S26: 37 | T26: 37 | Z26: P / E (x) — assumed (adjusted EPS) | AD26: 26 | AE26: 26 | AF26: 26
B27: Price Target ($) | G27: =G26*G23 -> 1009.4654 | H27: =H26*H23 -> 1156.716 | N27: Price Target ($) | S27: =S26*S23 -> 1260.5656 | T27: =T26*T23 -> 1491.0304 | Z27: Price Target ($) | AD27: =AD26*AD23 -> 611.51914 | AE27: =AE26*AE23 -> 670.96498 | AF27: =AF26*AF23 -> 731.24986
B28: Upside / (Downside) vs current | G28: =IFERROR(G27/$K$2-1,"") -> 0.69658045 | H28: =IFERROR(H27/$K$2-1,"") -> 0.94406055 | N28: Upside / (Downside) vs current | S28: =IFERROR(S27/$K$2-1,"") -> 1.1185976 | T28: =IFERROR(T27/$K$2-1,"") -> 1.5059334 | Z28: Upside / (Downside) vs current | AD28: =IFERROR(AD27/$K$2-1,"") -> 0.027763257 | AE28: =IFERROR(AE27/$K$2-1,"") -> 0.12767224 | AF28: =IFERROR(AF27/$K$2-1,"") -> 0.22899136
B29: IRR (to Dec-Y-1) | G29: =IFERROR((G27/$K$2)^(1/((DATE(2029-1,12,31)-$K$3)/365.25))-1,"") -> 0.26917373 | H29: =IFERROR((H27/$K$2)^(1/((DATE(2030-1,12,31)-$K$3)/365.25))-1,"") -> 0.22954873 | N29: IRR (to Dec-Y-1) | S29: =IFERROR((S27/$K$2)^(1/((DATE(2029-1,12,31)-$K$3)/365.25))-1,"") -> 0.40289029 | T29: =IFERROR((T27/$K$2)^(1/((DATE(2030-1,12,31)-$K$3)/365.25))-1,"") -> 0.330516 | Z29: IRR (to Dec-Y-1) | AD29: =IFERROR((AD27/$K$2)^(1/((DATE(2028-1,12,31)-$K$3)/365.25))-1,"") -> 0.022783402 | AE29: =IFERROR((AE27/$K$2)^(1/((DATE(2029-1,12,31)-$K$3)/365.25))-1,"") -> 0.055675927 | AF29: =IFERROR((AF27/$K$2)^(1/((DATE(2030-1,12,31)-$K$3)/365.25))-1,"") -> 0.066194283
B31: Free Cash Flow | C31: =Model!BV256 -> 16433 | D31: =Model!CA256 -> 16244.423 | E31: =Model!CB256 -> 19293.651 | F31: =Model!CC256 -> 21813.145 | G31: =Model!CD256 -> 24479.783 | H31: =Model!CE256 -> 27277.671 | I31: =IFERROR((H31/C31)^(1/5)-1,"n/m") -> 0.10666987 | N31: Free Cash Flow | O31: 16433 | P31: 16403.936 | Q31: 20089.048 | R31: 23138.294 | S31: 26627.369 | T31: 30427.326 | U31: 0.13112183 | Z31: Free Cash Flow | AA31: 16433 | AB31: 16084.91 | AC31: 18143.838 | AD31: 19759.568 | AE31: 21248.287 | AF31: 22686.529 | AG31: 0.066621274
B32: FCF % | C32: =IFERROR(C31/C9,"") -> 0.50114361 | D32: =IFERROR(D31/D9,"") -> 0.43646938 | E32: =IFERROR(E31/E9,"") -> 0.46129457 | F32: =IFERROR(F31/F9,"") -> 0.46624979 | G32: =IFERROR(G31/G9,"") -> 0.47086829 | H32: =IFERROR(H31/H9,"") -> 0.4752292 | J32: =IFERROR(AVERAGE(Model!C258,Model!D258,Model!E258,Model!F258,Model!G258,Model!H258,Model!I258,Model!N258,Model!S258,Model!X258,Model!AC258,Model!AH258,Model!AM258,Model!AR258,Model!AW258,Model!BB258,Model!BG258,Model!BL258,Model!BQ258,Model!BV258),"") -> 0.3584562 | K32: =IFERROR(MIN(Model!C258,Model!D258,Model!E258,Model!F258,Model!G258,Model!H258,Model!I258,Model!N258,Model!S258,Model!X258,Model!AC258,Model!AH258,Model!AM258,Model!AR258,Model!AW258,Model!BB258,Model!BG258,Model!BL258,Model!BQ258,Model!BV258),"") -> 0.04867277 | L32: =IFERROR(MAX(Model!C258,Model!D258,Model!E258,Model!F258,Model!G258,Model!H258,Model!I258,Model!N258,Model!S258,Model!X258,Model!AC258,Model!AH258,Model!AM258,Model!AR258,Model!AW258,Model!BB258,Model!BG258,Model!BL258,Model!BQ258,Model!BV258),"") -> 0.50114361 | N32: FCF % | O32: 0.50114361 | P32: 0.43882218 | Q32: 0.46631033 | R32: 0.46791577 | S32: 0.47227383 | T32: 0.47642679 | V32: 0.3584562 | W32: 0.04867277 | X32: 0.50114361 | Z32: FCF % | AA32: 0.50114361 | AB32: 0.43409576 | AC32: 0.45425248 | AD32: 0.46148456 | AE32: 0.46602131 | AF32: 0.47034905 | AH32: 0.3584562 | AI32: 0.04867277 | AJ32: 0.50114361
B33: FCF / share ($) | C33: =IFERROR(C31/C21,"") -> 18.137969 | D33: =IFERROR(D31/D21,"") -> 18.45362 | E33: =IFERROR(E31/E21,"") -> 22.530477 | F33: =IFERROR(F31/F21,"") -> 26.162754 | G33: =IFERROR(G31/G21,"") -> 30.24824 | H33: =IFERROR(H31/H21,"") -> 34.792728 | N33: FCF / share ($) | O33: 18.137969 | P33: 18.641945 | Q33: 23.620913 | R33: 28.155384 | S33: 33.549525 | T33: 39.847658 | Z33: FCF / share ($) | AA33: 18.137969 | AB33: 18.263697 | AC33: 21.038669 | AD33: 23.353551 | AE33: 25.719599 | AF33: 28.121326
B34: FCF Yield (on PT) | F34: =IFERROR(F33/F$27,"") | G34: =IFERROR(G33/G$27,"") -> 0.029964614 | H34: =IFERROR(H33/H$27,"") -> 0.030078885 | N34: FCF Yield (on PT) | R34: =IFERROR(R33/R$27,"") | S34: =IFERROR(S33/S$27,"") -> 0.026614661 | T34: =IFERROR(T33/T$27,"") -> 0.026724913 | Z34: FCF Yield (on PT) | AD34: =IFERROR(AD33/AD$27,"") -> 0.038189404 | AE34: =IFERROR(AE33/AE$27,"") -> 0.038332253 | AF34: =IFERROR(AF33/AF$27,"") -> 0.038456522
B35: Adjusted EBITDA (leverage basis) | C35: =Model!BV185 -> 20544 | D35: =Model!CA185 -> 23545.935 | E35: =Model!CB185 -> 26679.846 | F35: =Model!CC185 -> 30045.866 | G35: =Model!CD185 -> 33610.893 | H35: =Model!CE185 -> 37351.919 | I35: =IFERROR((H35/C35)^(1/5)-1,"n/m") -> 0.12700432 | N35: Adjusted EBITDA (leverage basis) | O35: 20544 | P35: 23776.84 | Q35: 27904.907 | R35: 32230.298 | S35: 36975.03 | T35: 42139.302 | U35: 0.15451736 | Z35: Adjusted EBITDA (leverage basis) | AA35: 20544 | AB35: 23315.03 | AC35: 24886.603 | AD35: 26876.654 | AE35: 28829.369 | AF35: 30716.011 | AG35: 0.0837671
B36: Adjusted EBITDA % of net revenue | C36: =IFERROR(C35/C9,"") -> 0.62651337 | D36: =IFERROR(D35/D9,"") -> 0.63265278 | E36: =IFERROR(E35/E9,"") -> 0.63789211 | F36: =IFERROR(F35/F9,"") -> 0.64222187 | G36: =IFERROR(G35/G9,"") -> 0.64650507 | H36: =IFERROR(H35/H9,"") -> 0.65074186 | J36: =IFERROR(AVERAGE(Model!C224,Model!D224,Model!E224,Model!F224,Model!G224,Model!H224,Model!I224,Model!N224,Model!S224,Model!X224,Model!AC224,Model!AH224,Model!AM224,Model!AR224,Model!AW224,Model!BB224,Model!BG224,Model!BL224,Model!BQ224,Model!BV224),"") -> 0.53713235 | K36: =IFERROR(MIN(Model!C224,Model!D224,Model!E224,Model!F224,Model!G224,Model!H224,Model!I224,Model!N224,Model!S224,Model!X224,Model!AC224,Model!AH224,Model!AM224,Model!AR224,Model!AW224,Model!BB224,Model!BG224,Model!BL224,Model!BQ224,Model!BV224),"") -> 0.2252737 | L36: =IFERROR(MAX(Model!C224,Model!D224,Model!E224,Model!F224,Model!G224,Model!H224,Model!I224,Model!N224,Model!S224,Model!X224,Model!AC224,Model!AH224,Model!AM224,Model!AR224,Model!AW224,Model!BB224,Model!BG224,Model!BL224,Model!BQ224,Model!BV224),"") -> 0.62651337 | N36: Adjusted EBITDA % of net revenue | O36: 0.62651337 | P36: 0.63605493 | Q36: 0.64773336 | R36: 0.65177947 | S36: 0.65580415 | T36: 0.65981127 | V36: 0.53713235 | W36: 0.2252737 | X36: 0.62651337 | Z36: Adjusted EBITDA % of net revenue | AA36: 0.62651337 | AB36: 0.62922052 | AC36: 0.6230656 | AD36: 0.62770407 | AE36: 0.63229097 | AF36: 0.63682049 | AH36: 0.53713235 | AI36: 0.2252737 | AJ36: 0.62651337
B38: Net Debt | C38: =Model!BV386 -> 8102 | D38: =Model!CA386 -> 12815.104 | E38: =Model!CB386 -> 13339.923 | F38: =Model!CC386 -> 15022.933 | G38: =Model!CD386 -> 16805.447 | H38: =Model!CE386 -> 18675.959 | N38: Net Debt | O38: 8102 | P38: 13454.421 | Q38: 19533.435 | R38: 22561.209 | S38: 25882.521 | T38: 29497.511 | Z38: Net Debt | AA38: 8102 | AB38: 11976.079 | AC38: 7465.981 | AD38: 8062.9963 | AE38: 8648.8106 | AF38: 9214.8034
B39: Net Debt / Adjusted EBITDA (x) | C39: =IFERROR(C38/C35,"") -> 0.39437305 | D39: =IFERROR(D38/D35,"") -> 0.54425973 | E39: =IFERROR(E38/E35,"") -> 0.5 | F39: =IFERROR(F38/F35,"") -> 0.5 | G39: =IFERROR(G38/G35,"") -> 0.5 | H39: =IFERROR(H38/H35,"") -> 0.5 | N39: Net Debt / Adjusted EBITDA (x) | O39: 0.39437305 | P39: 0.56586247 | Q39: 0.7 | R39: 0.7 | S39: 0.7 | T39: 0.7 | Z39: Net Debt / Adjusted EBITDA (x) | AA39: 0.39437305 | AB39: 0.51366348 | AC39: 0.3 | AD39: 0.3 | AE39: 0.3 | AF39: 0.3
B40: Share repurchases ($m; 2026E = H2) | D40: =Model!CA269 -> 7000 | E40: =Model!CB269 -> 15045.845 | F40: =Model!CC269 -> 18363.038 | G40: =Model!CD269 -> 20748.917 | H40: =Model!CE269 -> 23226.883 | N40: Share repurchases ($m; 2026E = H2) | P40: 7800 | Q40: 20900.906 | R40: 20580.632 | S40: 24005.475 | T40: 27725.119 | AB40: 6000 | AC40: 9354.2776 | AD40: 15675.399 | AE40: 16746.658 | AF40: 17717.041
B41: Implied avg buyback price ($) | D41: =Model!CA268 -> 595 | E41: =Model!CB268 -> 648.55 | F41: =Model!CC268 -> 706.9195 | G41: =Model!CD268 -> 770.54225 | H41: =Model!CE268 -> 839.89106 | N41: Implied avg buyback price ($) | P41: 595 | Q41: 648.55 | R41: 706.9195 | S41: 770.54225 | T41: 839.89106 | AB41: 595 | AC41: 648.55 | AD41: 706.9195 | AE41: 770.54225 | AF41: 839.89106
B42: Shares repurchased (m) | D42: =Model!CA270 -> 11.764706 | E42: =Model!CB270 -> 23.199207 | F42: =Model!CC270 -> 25.976137 | G42: =Model!CD270 -> 26.927683 | H42: =Model!CE270 -> 27.654638 | N42: Shares repurchased (m) | P42: 13.109244 | Q42: 32.227131 | R42: 29.113119 | S42: 31.154002 | T42: 33.010376 | AB42: 10.084034 | AC42: 14.423372 | AD42: 22.174235 | AE42: 21.733601 | AF42: 21.094452
B44: ROIC | C44: =Model!BV369 -> 0.98439879 | D44: =Model!CA369 -> 0.93967132 | E44: =Model!CB369 -> 0.96558791 | F44: =Model!CC369 -> 0.99856396 | G44: =Model!CD369 -> 1.0318003 | H44: =Model!CE369 -> 1.0644783 | J44: =IFERROR(AVERAGE(Model!C369,Model!D369,Model!E369,Model!F369,Model!G369,Model!H369,Model!I369,Model!N369,Model!S369,Model!X369,Model!AC369,Model!AH369,Model!AM369,Model!AR369,Model!AW369,Model!BB369,Model!BG369,Model!BL369,Model!BQ369,Model!BV369),"") -> 9.5416715 | K44: =IFERROR(MIN(Model!C369,Model!D369,Model!E369,Model!F369,Model!G369,Model!H369,Model!I369,Model!N369,Model!S369,Model!X369,Model!AC369,Model!AH369,Model!AM369,Model!AR369,Model!AW369,Model!BB369,Model!BG369,Model!BL369,Model!BQ369,Model!BV369),"") -> 0.64710137 | L44: =IFERROR(MAX(Model!C369,Model!D369,Model!E369,Model!F369,Model!G369,Model!H369,Model!I369,Model!N369,Model!S369,Model!X369,Model!AC369,Model!AH369,Model!AM369,Model!AR369,Model!AW369,Model!BB369,Model!BG369,Model!BL369,Model!BQ369,Model!BV369),"") -> 159.25146 | N44: ROIC | O44: 0.98439879 | P44: 0.94815247 | Q44: 0.97894579 | R44: 1.0108995 | S44: 1.04647 | T44: 1.0842456 | V44: 9.5416715 | W44: 0.64710137 | X44: 159.25146 | Z44: ROIC | AA44: 0.98439879 | AB44: 0.93116863 | AC44: 0.9337345 | AD44: 0.95776311 | AE44: 0.97912352 | AF44: 0.99737687 | AH44: 9.5416715 | AI44: 0.64710137 | AJ44: 159.25146
B45: RONTA | C45: =Model!BV380 -> 0.91607469 | D45: =Model!CA380 -> 1.0006567 | E45: =Model!CB380 -> 1.0467311 | F45: =Model!CC380 -> 1.161544 | G45: =Model!CD380 -> 1.2659362 | H45: =Model!CE380 -> 1.3339749 | J45: =IFERROR(AVERAGE(Model!C380,Model!D380,Model!E380,Model!F380,Model!G380,Model!H380,Model!I380,Model!N380,Model!S380,Model!X380,Model!AC380,Model!AH380,Model!AM380,Model!AR380,Model!AW380,Model!BB380,Model!BG380,Model!BL380,Model!BQ380,Model!BV380),"") -> 0.55050691 | K45: =IFERROR(MIN(Model!C380,Model!D380,Model!E380,Model!F380,Model!G380,Model!H380,Model!I380,Model!N380,Model!S380,Model!X380,Model!AC380,Model!AH380,Model!AM380,Model!AR380,Model!AW380,Model!BB380,Model!BG380,Model!BL380,Model!BQ380,Model!BV380),"") -> 0.15084563 | L45: =IFERROR(MAX(Model!C380,Model!D380,Model!E380,Model!F380,Model!G380,Model!H380,Model!I380,Model!N380,Model!S380,Model!X380,Model!AC380,Model!AH380,Model!AM380,Model!AR380,Model!AW380,Model!BB380,Model!BG380,Model!BL380,Model!BQ380,Model!BV380),"") -> 0.92159376 | N45: RONTA | O45: 0.91607469 | P45: 1.0471695 | Q45: 1.1570017 | R45: 1.2543015 | S45: 1.3482638 | T45: 1.4375118 | V45: 0.55050691 | W45: 0.15084563 | X45: 0.92159376 | Z45: RONTA | AA45: 0.91607469 | AB45: 0.94698143 | AC45: 0.75424459 | AD45: 0.78127174 | AE45: 0.80496466 | AF45: 0.82356469 | AH45: 0.55050691 | AI45: 0.15084563 | AJ45: 0.92159376
B47: Implied Market Cap (USDm) | F47: =F27*F21 -> 0 | G47: =G27*G21 -> 816956.4 | H47: =H27*H21 -> 906871.09 | N47: Implied Market Cap (USDm) | R47: =R27*R21 -> 0 | S47: =S27*S21 -> 1000477.5 | T47: =T27*T21 -> 1138537.9 | Z47: Implied Market Cap (USDm) | AD47: =AD27*AD21 -> 517409.69 | AE47: =AE27*AE21 -> 554318.77 | AF47: =AF27*AF21 -> 589926.71
B48: (+) Net Debt & NCI | F48: =F38+Model!CC306 -> 15017.933 | G48: =G38+Model!CD306 -> 16800.447 | H48: =H38+Model!CE306 -> 18670.959 | N48: (+) Net Debt & NCI | R48: =R38+Model!CC306 -> 22556.209 | S48: =S38+Model!CD306 -> 25877.521 | T48: =T38+Model!CE306 -> 29492.511 | Z48: (+) Net Debt & NCI | AD48: =AD38+Model!CC306 -> 8057.9963 | AE48: =AE38+Model!CD306 -> 8643.8106 | AF48: =AF38+Model!CE306 -> 9209.8034
B49: Implied Enterprise Value (USDm) | F49: =F47+F48 -> 15017.933 | G49: =G47+G48 -> 833756.84 | H49: =H47+H48 -> 925542.05 | N49: Implied Enterprise Value (USDm) | R49: =R47+R48 -> 22556.209 | S49: =S47+S48 -> 1026355 | T49: =T47+T48 -> 1168030.4 | Z49: Implied Enterprise Value (USDm) | AD49: =AD47+AD48 -> 525467.69 | AE49: =AE47+AE48 -> 562962.58 | AF49: =AF47+AF48 -> 599136.51
B50: Implied EV / Adjusted EBITDA (x) | F50: =IFERROR(F49/F35,"") -> 0.49983359 | G50: =IFERROR(G49/G35,"") -> 24.80615 | H50: =IFERROR(H49/H35,"") -> 24.778969 | N50: Implied EV / Adjusted EBITDA (x) | R50: =IFERROR(R49/R35,"") -> 0.69984487 | S50: =IFERROR(S49/S35,"") -> 27.758058 | T50: =IFERROR(T49/T35,"") -> 27.718313 | Z50: Implied EV / Adjusted EBITDA (x) | AD50: =IFERROR(AD49/AD35,"") -> 19.551083 | AE50: =IFERROR(AE49/AE35,"") -> 19.527399 | AF50: =IFERROR(AF49/AF35,"") -> 19.505674

Sheet DCF
B2: DCF VALUATION — MASTERCARD INCORPORATED (MA)
B4: 1. WACC BUILD
B5: Risk-free rate (US 10Y govt) | C5: 0.0425 | D5: Assumption (~US 10Y Treasury yield, Oct-2026; government rate sources are not reachable from the build environment); update to market
B6: Equity risk premium | C6: 0.05 | D6: Assumption: US implied ERP ~4.5–5.5%
B7: Levered beta | C7: 1 | D7: Assumption: payment networks (V, AXP, PYPL) ~0.9–1.2; volume-linked, recurring network revenue with consumer-spending cyclicality
B8: Cost of equity | C8: =C5+C7*C6 -> 0.0925
B9: Pre-tax cost of debt | C9: 0.047 | D9: June-2026 notes priced at 4.325%–5.0% (SOFR + 0.39% floaters); A+/Aa3-rated; commercial paper 3.84% (Q2-26 10-Q Note 9)
B10: Tax rate | C10: 0.205 | D10: Model 2027E+ effective tax rate (non-GAAP rate guided 20–21% for H2-26, UNVERIFIED)
B11: After-tax cost of debt | C11: =C9*(1-C10) -> 0.037365
B12: Target D/V | C12: 0.03 | D12: Net debt ~$13bn at 30-Jun-2026 vs ~$520bn market cap ($595 × ~879m diluted shares)
B13: WACC | C13: =C8*(1-C12)+C11*C12 -> 0.09084595
B15: Valuation date (live) | C15: =TODAY() -> 2026-10-13 00:00:00 | D15: Periods = (31-Dec of the year − today) / 365.25; cash flows assumed at year end. 2026E UFCF excluded (its cash flows sit in YE2026E net debt; valuation date Oct-2026).
B16: 2. UNLEVERED FREE CASH FLOW BUILD (USDm)
D17: 2026E | E17: 2027E | F17: 2028E | G17: 2029E | H17: 2030E | I17: 2031E | J17: 2032E | K17: 2033E | L17: 2034E | M17: 2035E | N17: Terminal | P17: CAGR 26–30E | Q17: CAGR 26–35E
B18: Adj. EBIT (adjusted operating income, full-cost) less litigation provisions & restructuring (cash) | D18: =Model!CA189-Model!CA191 -> 21803.935 | E18: =Model!CB189-Model!CB191 -> 24742.17 | F18: =Model!CC189-Model!CC191 -> 27902.076 | G18: =Model!CD189-Model!CD191 -> 31252.656 | H18: =Model!CE189-Model!CE191 -> 34772.229 | I18: =H18*(1+I$26) -> 37901.729 | J18: =I18*(1+J$26) -> 41028.622 | K18: =J18*(1+K$26) -> 44105.768 | L18: =K18*(1+L$26) -> 47082.908 | M18: =L18*(1+M$26) -> 49907.882 | P18: =(H18/D18)^(1/(COLUMNS(D18:H18)-1))-1 -> 0.12376218 | Q18: =(M18/D18)^(1/(COLUMNS(D18:M18)-1))-1 -> 0.096375602
B19: × (1 − tax rate) | D19: =1-$C$10 -> 0.795 | E19: =1-$C$10 -> 0.795 | F19: =1-$C$10 -> 0.795 | G19: =1-$C$10 -> 0.795 | H19: =1-$C$10 -> 0.795 | I19: =1-$C$10 -> 0.795 | J19: =1-$C$10 -> 0.795 | K19: =1-$C$10 -> 0.795 | ... M19: =1-$C$10 -> 0.795
B20: NOPAT | D20: =D18*D19 -> 17334.128 | E20: =E18*E19 -> 19670.026 | F20: =F18*F19 -> 22182.151 | G20: =G18*G19 -> 24845.861 | H20: =H18*H19 -> 27643.922 | I20: =I18*I19 -> 30131.875 | J20: =J18*J19 -> 32617.754 | K20: =K18*K19 -> 35064.086 | ... M20: =M18*M19 -> 39676.766
B21: plus D&A (depreciation + amortization of capitalized software and acquired intangibles) | D21: =Model!CA148 -> 1258 | E21: =Model!CB148 -> 1487.6755 | F21: =Model!CC148 -> 1693.7893 | G21: =Model!CD148 -> 1908.2374 | H21: =Model!CE148 -> 2129.6903 | I21: =H21*(1+I$26) -> 2321.3624 | J21: =I21*(1+J$26) -> 2512.8748 | K21: =J21*(1+K$26) -> 2701.3404 | L21: =K21*(1+L$26) -> 2883.6809 | M21: =L21*(1+M$26) -> 3056.7018
