Workbook

Sheet Model
AC1: SCENARIO SWITCH ▼ (Bull / Base / Bear) — drives all scenario-linked forecast drivers
B2: Mobility Global Inc. (NYSE: MBGL) — 3-Statement Financial Model | AC2: Base
B3: US GAAP · USD millions (whole millions as published; per-share data in USD; shares in millions) · calendar fiscal year · Source: Mobility Global Form 10 (information statement, 10-12B/A, 27-May-2026; first draft DRS 23-Oct-2025), Form 10-Q (Q2-26), Form 8-K (earnings release Ex. 99.1 and FY2025 quarterly data Ex. 99.2, 7-Aug-2026; separation 2-Jul-2026), SEC EDGAR CIK 0002090312 ("S&P Global Mobility Holding Co" to Jan-2026); S&P Global Inc. earnings releases (CIK 0000064040) for the Mobility segment memo; investor-relations sites are blocked — the releases are the documents filed on EDGAR
B4: Basis notes: spun off from S&P Global on 1-Jul-2026 (one MBGL share per SPGI share; 294.8m shares). History to 30-Jun-2026 = carve-out (combined) statements incl. S&P Global corporate allocations: FY2023–25 annual, 2025 quarters (Q3/Q4 "unaudited and preliminary"), Q1/Q2-26. Pre-2025 quarters and FY2022 = S&P Global "Mobility" segment memo (revenue comparable within $0–4m; profit not comparable). Segments: CARFAX, B2B (2025 realignment; recast by the company). Acquisition: Market Scan Feb-2023. $2.0bn senior notes (May-2026) funded a $2.0bn dividend to S&P Global. Q3/Q4-26E calibrated to FY26 revenue and Adjusted EBITDA guidance (7-Aug-2026).
AE5: Forecast | AF5: Historical | AG5: Historical | AH5: Historical
B6: (USDm) | C6: 2022 | D6: Q1/23 | E6: Q2/23 | F6: Q3/23 | G6: Q4/23 | H6: 2023 | I6: Q1/24 | J6: Q2/24 | K6: Q3/24 | L6: Q4/24 | M6: 2024 | N6: Q1/25 | O6: Q2/25 | P6: Q3/25 | Q6: Q4/25 | R6: 2025 | S6: Q1/26 | T6: Q2/26 | U6: Q3/26E | V6: Q4/26E | W6: 2026E | X6: 2027E | Y6: 2028E | Z6: 2029E | AA6: 2030E | AB6: 2031E | AC6: Modelling Notes | AE6: 5Y CAGR | AF6: 2Y CAGR | AG6: 1Y | AH6: 3Y CAGR
AE7: 26-'31 | AF7: 23-'25 | AG7: 24-'25 | AH7: 22-'25
B8: SEGMENT P&L — CARFAX · B2B · CORPORATE (revenue × Segment Adjusted EBITDA margin) | AC8: SEGMENT BUILD — modelling logic (segment revenue → Segment Adjusted EBITDA margin → Adjusted EBITDA → GAAP P&L). Carve-out basis to 30-Jun-2026; consolidated from Q3-26.
AK9: SCENARIO INPUT TABLE — driver assumptions per Bull / Base / Bear | AL9: Bull | AM9: Base | AN9: Bear | AO9: Bull / Bear = Base + Δ (Δ inputs on each block header). Outlook block = high / mid / low end of the FY26 guidance ranges.
B10: CARFAX | AC10: CFX — modelling logic
B11: Segment revenue | H11: 928 | M11: 1039 | N11: 275 | O11: 289 | P11: 291 | Q11: 287 | R11: 1142 | S11: 298 | T11: 312 | U11: =P11*(1+U12) -> 313.83911 | V11: =Q11*(1+V12) -> 309.52517 | W11: =SUM(S11:V11) -> 1233.3643 | X11: =W11*(1+X12) -> 1332.0334 | Y11: =X11*(1+Y12) -> 1435.932 | Z11: =Y11*(1+Z12) -> 1543.6269 | AA11: =Z11*(1+AA12) -> 1654.7681 | AB11: =AA11*(1+AB12) -> 1770.6018 | AC11: Carve-out segment revenue as published (Form 10 MD&A FY2023–25, Q1-25 / Q1-26; 10-Q / release Q2; FY2025 quarterly data Ex. 99.2 for Q3-25 / Q4-25). Q3/Q4-26E: prior-year quarter × (1 + growth). 2027E+: prior year × (1 + scenario lever). | AE11: =IFERROR((AB11/W11)^(1/5)-1,"n/m") -> 0.074993674 | AF11: =IFERROR((R11/H11)^(1/2)-1,"n/m") -> 0.10932567 | AG11: =IFERROR(R11/M11-1,"n/m") -> 0.099133782 | AH11: =IFERROR((R11/C11)^(1/3)-1,"n/m") -> n/m | AK11: FY26 outlook — Q2-26 release (7-Aug-2026) | AL11: High | AM11: Mid | AN11: Low | AO11: First guidance as a public company: revenue $1,870–1,885m (+6.9–7.7%), Adjusted EBITDA $745–760m (~40% margin); 1H carve-out + 2H consolidated. No EPS / interest / tax / capex / FCF guidance. "Medium-term financial targets" referenced in the release are not filed on EDGAR (unverified; not used).
B12: y/y % | H12: =IF(AND(ISNUMBER(H11),ISNUMBER(C11)),IFERROR(H11/C11-1,""),"") | I12: =IF(AND(ISNUMBER(I11),ISNUMBER(D11)),IFERROR(I11/D11-1,""),"") | J12: =IF(AND(ISNUMBER(J11),ISNUMBER(E11)),IFERROR(J11/E11-1,""),"") | K12: =IF(AND(ISNUMBER(K11),ISNUMBER(F11)),IFERROR(K11/F11-1,""),"") | L12: =IF(AND(ISNUMBER(L11),ISNUMBER(G11)),IFERROR(L11/G11-1,""),"") | M12: =IF(AND(ISNUMBER(M11),ISNUMBER(H11)),IFERROR(M11/H11-1,""),"") -> 0.11961207 | N12: =IF(AND(ISNUMBER(N11),ISNUMBER(I11)),IFERROR(N11/I11-1,""),"") | O12: =IF(AND(ISNUMBER(O11),ISNUMBER(J11)),IFERROR(O11/J11-1,""),"") | ... T12: =IF(AND(ISNUMBER(T11),ISNUMBER(O11)),IFERROR(T11/O11-1,""),"") -> 0.079584775 | U12: =U13+$U$94 -> 0.07848492 | V12: =V13+$U$94 -> 0.07848492 | W12: =IF(AND(ISNUMBER(W11),ISNUMBER(R11)),IFERROR(W11/R11-1,""),"") -> 0.080003751 | X12: =CHOOSE(MATCH($AC$2,{"Bull","Base","Bear"},0),$AL$24,$AM$24,$AN$24) -> 0.08 | Y12: =CHOOSE(MATCH($AC$2,{"Bull","Base","Bear"},0),$AL$25,$AM$25,$AN$25) -> 0.078 | Z12: =CHOOSE(MATCH($AC$2,{"Bull","Base","Bear"},0),$AL$26,$AM$26,$AN$26) -> 0.075 | AA12: =CHOOSE(MATCH($AC$2,{"Bull","Base","Bear"},0),$AL$27,$AM$27,$AN$27) -> 0.072 | AB12: =CHOOSE(MATCH($AC$2,{"Bull","Base","Bear"},0),$AL$28,$AM$28,$AN$28) -> 0.07 | AC12: Q3/Q4-26E: growth before calibration (row below) + revenue-outlook calibration Δ (Group block). 2027E–2031E: scenario lever. | AK12: FY26 revenue ($m) | AL12: 1885 | AM12: 1877.5 | AN12: 1870 | AO12: Guided $1,870–1,885m. Drives the Q3/Q4-26E revenue calibration.
B13: Q3/Q4-26E growth before revenue calibration (1H/26 y/y) | U13: =IFERROR((S11+T11)/(N11+O11)-1,0) -> 0.081560284 | V13: =IFERROR((S11+T11)/(N11+O11)-1,0) -> 0.081560284 | AK13: FY26 Adjusted EBITDA ($m) | AL13: 760 | AM13: 752.5 | AN13: 745 | AO13: Guided $745–760m. Drives the Q3/Q4-26E segment-margin calibration.
B14: Subscription revenue | H14: 748 | M14: 843 | N14: 225 | O14: 234 | P14: 235 | Q14: 233 | R14: 927 | S14: 242 | T14: 252 | AK14: 2H/26 share repurchases ($m) | AL14: 0 | AM14: 0 | AN14: 0 | AO14: No repurchase authorization announced (10-Q, 8-Ks). Dividend $0.06 a quarter.
B15: Non-subscription revenue | H15: 180 | M15: 196 | N15: 50 | O15: 55 | P15: 56 | Q15: 54 | R15: 215 | S15: 56 | T15: 60
B16: Subscription % of segment revenue | C16: =IF(AND(ISNUMBER(C14),ISNUMBER(C11)),IFERROR(C14/C11,""),"") | D16: =IF(AND(ISNUMBER(D14),ISNUMBER(D11)),IFERROR(D14/D11,""),"") | E16: =IF(AND(ISNUMBER(E14),ISNUMBER(E11)),IFERROR(E14/E11,""),"") | F16: =IF(AND(ISNUMBER(F14),ISNUMBER(F11)),IFERROR(F14/F11,""),"") | G16: =IF(AND(ISNUMBER(G14),ISNUMBER(G11)),IFERROR(G14/G11,""),"") | H16: =IF(AND(ISNUMBER(H14),ISNUMBER(H11)),IFERROR(H14/H11,""),"") -> 0.80603448 | I16: =IF(AND(ISNUMBER(I14),ISNUMBER(I11)),IFERROR(I14/I11,""),"") | J16: =IF(AND(ISNUMBER(J14),ISNUMBER(J11)),IFERROR(J14/J11,""),"") | ... AB16: =IF(AND(ISNUMBER(AB14),ISNUMBER(AB11)),IFERROR(AB14/AB11,""),"") | AE16: =IFERROR(AVERAGE(X16,Y16,Z16,AA16,AB16),"n/m") -> n/m | AF16: =IFERROR(AVERAGE(H16,M16,R16),"n/m") -> 0.80970845 | AG16: =IFERROR(AVERAGE(M16,R16),"n/m") -> 0.81154544 | AH16: =IFERROR(AVERAGE(C16,H16,M16,R16),"n/m") -> 0.80970845 | AK16: FY26 point estimates (all cases; not guided — assumptions unless stated)
B17: International revenue (memo) | H17: 137 | M17: 155 | N17: 39 | O17: 43 | R17: 168 | S17: 45 | T17: 47 | AK17: 2H/26 interest expense, net ($m) | AM17: 54 | AO17: Assumption: coupons on $2.0bn notes $27.7m a quarter + ~$0.8m accretion/fees − interest on ~$250m cash. Form 10 pro forma: $114m p.a. gross (5.74% incl. amortization).
B18: Segment Adjusted EBITDA | H18: 422 | M18: 476 | N18: 130 | O18: 142 | P18: 146 | Q18: 118 | R18: 536 | S18: 140 | T18: 153 | U18: =U11*U19 -> 154.69458 | V18: =V11*V19 -> 124.535 | W18: =SUM(S18:V18) -> 572.22959 | X18: =X11*X19 -> 639.37604 | Y18: =Y11*Y19 -> 696.42704 | Z18: =Z11*Z19 -> 756.3772 | AA18: =AA11*AA19 -> 819.1102 | AB18: =AB11*AB19 -> 885.30092 | AC18: Company measure: segment operating profit + D&A + SBC + transaction costs + severance & other. Forecast = revenue × margin. | AE18: =IFERROR((AB18/W18)^(1/5)-1,"n/m") -> 0.091199408 | AF18: =IFERROR((R18/H18)^(1/2)-1,"n/m") -> 0.12700585 | AG18: =IFERROR(R18/M18-1,"n/m") -> 0.12605042 | AH18: =IFERROR((R18/C18)^(1/3)-1,"n/m") -> n/m | AK18: 2H/26 effective tax rate | AM18: 0.29 | AO18: Assumption: 1H/26 29.4% (Q2 29.3%); not guided.
B19: Segment Adjusted EBITDA margin % | C19: =IF(AND(ISNUMBER(C18),ISNUMBER(C11)),IFERROR(C18/C11,""),"") | D19: =IF(AND(ISNUMBER(D18),ISNUMBER(D11)),IFERROR(D18/D11,""),"") | E19: =IF(AND(ISNUMBER(E18),ISNUMBER(E11)),IFERROR(E18/E11,""),"") | F19: =IF(AND(ISNUMBER(F18),ISNUMBER(F11)),IFERROR(F18/F11,""),"") | G19: =IF(AND(ISNUMBER(G18),ISNUMBER(G11)),IFERROR(G18/G11,""),"") | H19: =IF(AND(ISNUMBER(H18),ISNUMBER(H11)),IFERROR(H18/H11,""),"") -> 0.45474138 | I19: =IF(AND(ISNUMBER(I18),ISNUMBER(I11)),IFERROR(I18/I11,""),"") | J19: =IF(AND(ISNUMBER(J18),ISNUMBER(J11)),IFERROR(J18/J11,""),"") | ... T19: =IF(AND(ISNUMBER(T18),ISNUMBER(T11)),IFERROR(T18/T11,""),"") -> 0.49038462 | U19: =U20+$U$98 -> 0.49291047 | V19: =V20+$U$98 -> 0.40234208 | W19: =IF(AND(ISNUMBER(W18),ISNUMBER(W11)),IFERROR(W18/W11,""),"") -> 0.46395829 | X19: =CHOOSE(MATCH($AC$2,{"Bull","Base","Bear"},0),$AL$36,$AM$36,$AN$36) -> 0.48 | Y19: =CHOOSE(MATCH($AC$2,{"Bull","Base","Bear"},0),$AL$37,$AM$37,$AN$37) -> 0.485 | Z19: =CHOOSE(MATCH($AC$2,{"Bull","Base","Bear"},0),$AL$38,$AM$38,$AN$38) -> 0.49 | AA19: =CHOOSE(MATCH($AC$2,{"Bull","Base","Bear"},0),$AL$39,$AM$39,$AN$39) -> 0.495 | AB19: =CHOOSE(MATCH($AC$2,{"Bull","Base","Bear"},0),$AL$40,$AM$40,$AN$40) -> 0.5 | AC19: Q3/Q4-26E: margin before calibration + Adjusted-EBITDA-outlook calibration Δ. 2027E–2031E: scenario lever. | AE19: =IFERROR(AVERAGE(X19,Y19,Z19,AA19,AB19),"n/m") -> 0.49 | AF19: =IFERROR(AVERAGE(H19,M19,R19),"n/m") -> 0.46074207 | AG19: =IFERROR(AVERAGE(M19,R19),"n/m") -> 0.46374242 | AH19: =IFERROR(AVERAGE(C19,H19,M19,R19),"n/m") -> 0.46074207 | AK19: FY26 capital expenditures ($m) | AM19: 26 | AO19: Assumption: 1H/26 $12m; FY2025 $24m.
B20: Q3/Q4-26E margin before calibration (prior-year quarter + 1H/26 y/y drift) | U20: =P19+((S18+T18)/(S11+T11)-(N18+O18)/(N11+O11)) -> 0.49977658 | V20: =Q19+((S18+T18)/(S11+T11)-(N18+O18)/(N11+O11)) -> 0.40920819
B21: Segment operating profit (GAAP) | H21: 210 | M21: 259 | N21: 77 | O21: 89 | P21: 92 | Q21: 64 | R21: 322 | S21: 89 | T21: 101 | AK21: Target net debt / Adjusted EBITDA (x) — buyback plug 2027E+ | AL21: 2.5 | AM21: 2 | AN21: 1.5 | AO21: Assumption — no leverage target published. Net debt ~$1.8bn at 30-Jun-26 ≈ 2.5x LTM Adjusted EBITDA ($740m); covenant ≤ 3.50x; notes rated investment grade (change-of-control put on a downgrade below IG). Target = leverage at which surplus cash is returned via buybacks; Bull = more buybacks (higher target).
B22: Segment D&A (memo) | H22: 198 | M22: 199 | N22: 50 | O22: 50 | P22: 50 | Q22: 48 | R22: 198 | S22: 50 | T22: 50
B23: Segment stock-based compensation (memo) | H23: 14 | M23: 18 | N23: 3 | O23: 2 | P23: 4 | Q23: 4 | R23: 13 | S23: 1 | T23: 2 | AK23: CFX_G (CARFAX revenue y/y) | AL23: 0.02 | AM23: Δ → | AN23: -0.03 | AO23: FY2024 +12%, FY2025 +10%, 1H/26 +8%: dealer subscriptions (Advantage, Listings, CARFAX for Life), BIG data customers, Showroom / Homegrown launches, CARFAX Germany.
B24: Segment transaction costs, severance & other items (memo) | H24: 0 | M24: 0 | N24: 0 | O24: 1 | P24: 0 | Q24: 2 | R24: 3 | S24: 0 | T24: 0 | AK24: 2027E | AL24: =AM24+$AL$23 -> 0.1 | AM24: 0.08 | AN24: =AM24+$AN$23 -> 0.05
B25: Check: segment OP + D&A + SBC + items vs Segment Adjusted EBITDA (should be 0; ±1 rounding) | C25: =IF(AND(ISNUMBER(C21),ISNUMBER(C18)),IF(ABS(C21+C22+N(C23)+N(C24)-C18)<=1,0,C21+C22+N(C23)+N(C24)-C18),"") | D25: =IF(AND(ISNUMBER(D21),ISNUMBER(D18)),IF(ABS(D21+D22+N(D23)+N(D24)-D18)<=1,0,D21+D22+N(D23)+N(D24)-D18),"") | E25: =IF(AND(ISNUMBER(E21),ISNUMBER(E18)),IF(ABS(E21+E22+N(E23)+N(E24)-E18)<=1,0,E21+E22+N(E23)+N(E24)-E18),"") | F25: =IF(AND(ISNUMBER(F21),ISNUMBER(F18)),IF(ABS(F21+F22+N(F23)+N(F24)-F18)<=1,0,F21+F22+N(F23)+N(F24)-F18),"") | G25: =IF(AND(ISNUMBER(G21),ISNUMBER(G18)),IF(ABS(G21+G22+N(G23)+N(G24)-G18)<=1,0,G21+G22+N(G23)+N(G24)-G18),"") | H25: =IF(AND(ISNUMBER(H21),ISNUMBER(H18)),IF(ABS(H21+H22+N(H23)+N(H24)-H18)<=1,0,H21+H22+N(H23)+N(H24)-H18),"") -> 0 | I25: =IF(AND(ISNUMBER(I21),ISNUMBER(I18)),IF(ABS(I21+I22+N(I23)+N(I24)-I18)<=1,0,I21+I22+N(I23)+N(I24)-I18),"") | J25: =IF(AND(ISNUMBER(J21),ISNUMBER(J18)),IF(ABS(J21+J22+N(J23)+N(J24)-J18)<=1,0,J21+J22+N(J23)+N(J24)-J18),"") | ... T25: =IF(AND(ISNUMBER(T21),ISNUMBER(T18)),IF(ABS(T21+T22+N(T23)+N(T24)-T18)<=1,0,T21+T22+N(T23)+N(T24)-T18),"") -> 0 | AK25: 2028E | AL25: =AM25+$AL$23 -> 0.098 | AM25: 0.078 | AN25: =AM25+$AN$23 -> 0.048
B26: Segment Adjusted operating profit (company; Form 10 periods) | H26: 400 | M26: 449 | N26: 124 | R26: 514 | S26: 136 | AK26: 2029E | AL26: =AM26+$AL$23 -> 0.095 | AM26: 0.075 | AN26: =AM26+$AN$23 -> 0.045
AK27: 2030E | AL27: =AM27+$AL$23 -> 0.092 | AM27: 0.072 | AN27: =AM27+$AN$23 -> 0.042
B28: B2B (automotiveMastermind, Polk Automotive Solutions, Market Scan, OEM & supplier data) | AC28: B2B — modelling logic | AK28: 2031E | AL28: =AM28+$AL$23 -> 0.09 | AM28: 0.07 | AN28: =AM28+$AN$23 -> 0.04
B29: Segment revenue | H29: 557 | M29: 574 | N29: 145 | O29: 150 | P29: 154 | Q29: 159 | R29: 608 | S29: 157 | T29: 156 | U29: =P29*(1+U30) -> 162.923 | V29: =Q29*(1+V30) -> 168.21271 | W29: =SUM(S29:V29) -> 644.13572 | X29: =W29*(1+X30) -> 676.3425 | Y29: =X29*(1+Y30) -> 710.15963 | Z29: =Y29*(1+Z30) -> 742.11681 | AA29: =Z29*(1+AA30) -> 775.51207 | AB29: =AA29*(1+AB30) -> 806.53255 | AE29: =IFERROR((AB29/W29)^(1/5)-1,"n/m") -> 0.045993302 | AF29: =IFERROR((R29/H29)^(1/2)-1,"n/m") -> 0.044778416 | AG29: =IFERROR(R29/M29-1,"n/m") -> 0.059233449 | AH29: =IFERROR((R29/C29)^(1/3)-1,"n/m") -> n/m | AK29: B2B_G (B2B revenue y/y) | AL29: 0.02 | AM29: Δ → | AN29: -0.03 | AO29: FY2024 +3%, FY2025 +6%, 1H/26 +6% (Q2 +4%): OEM / dealer marketing (automotiveMastermind), Polk data, Market Scan; non-subscription (recalls, marketing) cyclical.
B30: y/y % | H30: =IF(AND(ISNUMBER(H29),ISNUMBER(C29)),IFERROR(H29/C29-1,""),"") | I30: =IF(AND(ISNUMBER(I29),ISNUMBER(D29)),IFERROR(I29/D29-1,""),"") | J30: =IF(AND(ISNUMBER(J29),ISNUMBER(E29)),IFERROR(J29/E29-1,""),"") | K30: =IF(AND(ISNUMBER(K29),ISNUMBER(F29)),IFERROR(K29/F29-1,""),"") | L30: =IF(AND(ISNUMBER(L29),ISNUMBER(G29)),IFERROR(L29/G29-1,""),"") | M30: =IF(AND(ISNUMBER(M29),ISNUMBER(H29)),IFERROR(M29/H29-1,""),"") -> 0.030520646 | N30: =IF(AND(ISNUMBER(N29),ISNUMBER(I29)),IFERROR(N29/I29-1,""),"") | O30: =IF(AND(ISNUMBER(O29),ISNUMBER(J29)),IFERROR(O29/J29-1,""),"") | ... T30: =IF(AND(ISNUMBER(T29),ISNUMBER(O29)),IFERROR(T29/O29-1,""),"") -> 0.04 | U30: =U31+$U$94 -> 0.057941585 | V30: =V31+$U$94 -> 0.057941585 | W30: =IF(AND(ISNUMBER(W29),ISNUMBER(R29)),IFERROR(W29/R29-1,""),"") -> 0.059433744 | X30: =CHOOSE(MATCH($AC$2,{"Bull","Base","Bear"},0),$AL$30,$AM$30,$AN$30) -> 0.05 | Y30: =CHOOSE(MATCH($AC$2,{"Bull","Base","Bear"},0),$AL$31,$AM$31,$AN$31) -> 0.05 | Z30: =CHOOSE(MATCH($AC$2,{"Bull","Base","Bear"},0),$AL$32,$AM$32,$AN$32) -> 0.045 | AA30: =CHOOSE(MATCH($AC$2,{"Bull","Base","Bear"},0),$AL$33,$AM$33,$AN$33) -> 0.045 | AB30: =CHOOSE(MATCH($AC$2,{"Bull","Base","Bear"},0),$AL$34,$AM$34,$AN$34) -> 0.04 | AK30: 2027E | AL30: =AM30+$AL$29 -> 0.07 | AM30: 0.05 | AN30: =AM30+$AN$29 -> 0.02
B31: Q3/Q4-26E growth before revenue calibration (1H/26 y/y) | U31: =IFERROR((S29+T29)/(N29+O29)-1,0) -> 0.061016949 | V31: =IFERROR((S29+T29)/(N29+O29)-1,0) -> 0.061016949 | AK31: 2028E | AL31: =AM31+$AL$29 -> 0.07 | AM31: 0.05 | AN31: =AM31+$AN$29 -> 0.02
B32: Subscription revenue | H32: 422 | M32: 460 | N32: 118 | O32: 124 | P32: 127 | Q32: 130 | R32: 499 | S32: 130 | T32: 131 | AK32: 2029E | AL32: =AM32+$AL$29 -> 0.065 | AM32: 0.045 | AN32: =AM32+$AN$29 -> 0.015
B33: Non-subscription revenue | H33: 135 | M33: 114 | N33: 27 | O33: 26 | P33: 27 | Q33: 29 | R33: 109 | S33: 27 | T33: 25 | AK33: 2030E | AL33: =AM33+$AL$29 -> 0.065 | AM33: 0.045 | AN33: =AM33+$AN$29 -> 0.015
B34: Subscription % of segment revenue | C34: =IF(AND(ISNUMBER(C32),ISNUMBER(C29)),IFERROR(C32/C29,""),"") | D34: =IF(AND(ISNUMBER(D32),ISNUMBER(D29)),IFERROR(D32/D29,""),"") | E34: =IF(AND(ISNUMBER(E32),ISNUMBER(E29)),IFERROR(E32/E29,""),"") | F34: =IF(AND(ISNUMBER(F32),ISNUMBER(F29)),IFERROR(F32/F29,""),"") | G34: =IF(AND(ISNUMBER(G32),ISNUMBER(G29)),IFERROR(G32/G29,""),"") | H34: =IF(AND(ISNUMBER(H32),ISNUMBER(H29)),IFERROR(H32/H29,""),"") -> 0.75763016 | I34: =IF(AND(ISNUMBER(I32),ISNUMBER(I29)),IFERROR(I32/I29,""),"") | J34: =IF(AND(ISNUMBER(J32),ISNUMBER(J29)),IFERROR(J32/J29,""),"") | ... AB34: =IF(AND(ISNUMBER(AB32),ISNUMBER(AB29)),IFERROR(AB32/AB29,""),"") | AE34: =IFERROR(AVERAGE(X34,Y34,Z34,AA34,AB34),"n/m") -> n/m | AF34: =IFERROR(AVERAGE(H34,M34,R34),"n/m") -> 0.79324919 | AG34: =IFERROR(AVERAGE(M34,R34),"n/m") -> 0.81105871 | AH34: =IFERROR(AVERAGE(C34,H34,M34,R34),"n/m") -> 0.79324919 | AK34: 2031E | AL34: =AM34+$AL$29 -> 0.06 | AM34: 0.04 | AN34: =AM34+$AN$29 -> 0.01
B35: International revenue (memo) | H35: 124 | M35: 129 | N35: 31 | O35: 31 | R35: 128 | S35: 34 | T35: 32 | AK35: CFX_M (CARFAX Segment Adjusted EBITDA margin) | AL35: 0.01 | AM35: Δ → | AN35: -0.025 | AO35: FY2023 45.5%, FY2024 45.8%, FY2025 46.9%, 1H/26 48.0%; operating leverage on the data estate vs advertising / strategic investment.
B36: Segment Adjusted EBITDA | H36: 191 | M36: 203 | N36: 44 | O36: 49 | P36: 55 | Q36: 49 | R36: 197 | S36: 49 | T36: 53 | U36: =U29*U37 -> 58.799092 | V36: =V29*V37 -> 52.471323 | W36: =SUM(S36:V36) -> 213.27041 | X36: =X29*X37 -> 226.57474 | Y36: =Y29*Y37 -> 241.45427 | Z36: =Z29*Z37 -> 256.0303 | AA36: =AA29*AA37 -> 271.42922 | AB36: =AB29*AB37 -> 286.31906 | AE36: =IFERROR((AB36/W36)^(1/5)-1,"n/m") -> 0.060678896 | AF36: =IFERROR((R36/H36)^(1/2)-1,"n/m") -> 0.015585355 | AG36: =IFERROR(R36/M36-1,"n/m") -> -0.02955665 | AH36: =IFERROR((R36/C36)^(1/3)-1,"n/m") -> n/m | AK36: 2027E | AL36: =AM36+$AL$35 -> 0.49 | AM36: 0.48 | AN36: =AM36+$AN$35 -> 0.455
B37: Segment Adjusted EBITDA margin % | C37: =IF(AND(ISNUMBER(C36),ISNUMBER(C29)),IFERROR(C36/C29,""),"") | D37: =IF(AND(ISNUMBER(D36),ISNUMBER(D29)),IFERROR(D36/D29,""),"") | E37: =IF(AND(ISNUMBER(E36),ISNUMBER(E29)),IFERROR(E36/E29,""),"") | F37: =IF(AND(ISNUMBER(F36),ISNUMBER(F29)),IFERROR(F36/F29,""),"") | G37: =IF(AND(ISNUMBER(G36),ISNUMBER(G29)),IFERROR(G36/G29,""),"") | H37: =IF(AND(ISNUMBER(H36),ISNUMBER(H29)),IFERROR(H36/H29,""),"") -> 0.34290844 | I37: =IF(AND(ISNUMBER(I36),ISNUMBER(I29)),IFERROR(I36/I29,""),"") | J37: =IF(AND(ISNUMBER(J36),ISNUMBER(J29)),IFERROR(J36/J29,""),"") | ... T37: =IF(AND(ISNUMBER(T36),ISNUMBER(T29)),IFERROR(T36/T29,""),"") -> 0.33974359 | U37: =U38+$U$98 -> 0.3609011 | V37: =V38+$U$98 -> 0.31193435 | W37: =IF(AND(ISNUMBER(W36),ISNUMBER(W29)),IFERROR(W36/W29,""),"") -> 0.33109547 | X37: =CHOOSE(MATCH($AC$2,{"Bull","Base","Bear"},0),$AL$42,$AM$42,$AN$42) -> 0.335 | Y37: =CHOOSE(MATCH($AC$2,{"Bull","Base","Bear"},0),$AL$43,$AM$43,$AN$43) -> 0.34 | Z37: =CHOOSE(MATCH($AC$2,{"Bull","Base","Bear"},0),$AL$44,$AM$44,$AN$44) -> 0.345 | AA37: =CHOOSE(MATCH($AC$2,{"Bull","Base","Bear"},0),$AL$45,$AM$45,$AN$45) -> 0.35 | AB37: =CHOOSE(MATCH($AC$2,{"Bull","Base","Bear"},0),$AL$46,$AM$46,$AN$46) -> 0.355 | AE37: =IFERROR(AVERAGE(X37,Y37,Z37,AA37,AB37),"n/m") -> 0.345 | AF37: =IFERROR(AVERAGE(H37,M37,R37),"n/m") -> 0.34019338 | AG37: =IFERROR(AVERAGE(M37,R37),"n/m") -> 0.33883585 | AH37: =IFERROR(AVERAGE(C37,H37,M37,R37),"n/m") -> 0.34019338 | AK37: 2028E | AL37: =AM37+$AL$35 -> 0.495 | AM37: 0.485 | AN37: =AM37+$AN$35 -> 0.46
B38: Q3/Q4-26E margin before calibration (prior-year quarter + 1H/26 y/y drift) | U38: =P37+((S36+T36)/(S29+T29)-(N36+O36)/(N29+O29)) -> 0.36776721 | V38: =Q37+((S36+T36)/(S29+T29)-(N36+O36)/(N29+O29)) -> 0.31880046 | AK38: 2029E | AL38: =AM38+$AL$35 -> 0.5 | AM38: 0.49 | AN38: =AM38+$AN$35 -> 0.465
B39: Segment operating profit (GAAP) | H39: 61 | M39: 69 | N39: 14 | O39: 16 | P39: 23 | Q39: 9 | R39: 62 | S39: 5 | T39: 3 | AK39: 2030E | AL39: =AM39+$AL$35 -> 0.505 | AM39: 0.495 | AN39: =AM39+$AN$35 -> 0.47
B40: Segment D&A (memo) | H40: 110 | M40: 111 | N40: 28 | O40: 27 | P40: 27 | Q40: 30 | R40: 112 | S40: 28 | T40: 27 | AK40: 2031E | AL40: =AM40+$AL$35 -> 0.51 | AM40: 0.5 | AN40: =AM40+$AN$35 -> 0.475
...

Sheet Bull-Base-Bear
B2: Mobility Global Inc. (MBGL) — Bull / Base / Bear Case P&L Summary | J2: Share price ($): | K2: =Model!$X$351 -> 18
B3: Company definitions: Adjusted EBITDA (company), Adjusted EPS = model definition (Mobility Global publishes none: + amortization of intangibles, transaction and other items, tax-effected) · USD millions · Live panel linked to Model — toggle scenario via Model!AC2. Bull and Bear panels are value snapshots generated from the Model with the switch set to each case. 2026E = 1H carve-out actual + 2H calibrated to the FY26 outlook (revenue $1,870–1,885m, Adjusted EBITDA $745–760m). | J3: As of: | K3: =TODAY() -> 2026-10-13 00:00:00
B5: Scenario: | C5: =Model!$AC$2 -> Base | N5: Scenario: | O5: Bull | P5: Snapshot (values) — Model run with switch = Bull | Z5: Scenario: | AA5: Bear | AB5: Snapshot (values) — Model run with switch = Bear
B7: (USDm, except EPS and shares) | C7: 2026E | D7: 2027E | E7: 2028E | F7: 2029E | G7: 2030E | H7: 2031E | I7: 26-'31 CAGR | J7: LT Hist Avg | K7: LT Hist Min | L7: LT Hist Max | N7: (USDm, except EPS and shares) | O7: 2026E | P7: 2027E | Q7: 2028E | R7: 2029E | S7: 2030E | T7: 2031E | U7: 26-'31 CAGR | V7: LT Hist Avg | W7: LT Hist Min | X7: LT Hist Max | Z7: (USDm, except EPS and shares) | AA7: 2026E | AB7: 2027E | AC7: 2028E | AD7: 2029E | AE7: 2030E | AF7: 2031E | AG7: 26-'31 CAGR | AH7: LT Hist Avg | AI7: LT Hist Min | AJ7: LT Hist Max
B9: Revenue | C9: =Model!W115 -> 1877.5 | D9: =Model!X115 -> 2008.3759 | E9: =Model!Y115 -> 2146.0917 | F9: =Model!Z115 -> 2285.7437 | G9: =Model!AA115 -> 2430.2801 | H9: =Model!AB115 -> 2577.1344 | I9: =IFERROR((H9/C9)^(1/5)-1,"n/m") -> 0.065396889 | N9: Revenue | O9: 1885 | P9: 2064.0969 | Q9: 2267.2211 | R9: 2479.9005 | S9: 2705.6412 | T9: 2942.2277 | U9: 0.09313295 | Z9: Revenue | AA9: 1870 | AB9: 1944.255 | AC9: 2019.2579 | AD9: 2090.102 | AE9: 2159.5957 | AF9: 2225.3518 | AG9: 0.03540776
B10: Revenue y/y % | D10: =IFERROR(D9/C9-1,"") -> 0.069707552 | E10: =IFERROR(E9/D9-1,"") -> 0.068570695 | F10: =IFERROR(F9/E9-1,"") -> 0.06507275 | G10: =IFERROR(G9/F9-1,"") -> 0.063233858 | H10: =IFERROR(H9/G9-1,"") -> 0.060426881 | N10: Revenue y/y % | P10: 0.095011612 | Q10: 0.098408294 | R10: 0.093806194 | S10: 0.091028098 | T10: 0.087441956 | Z10: Revenue y/y % | AB10: 0.03970854 | AC10: 0.038576715 | AD10: 0.035084214 | AE10: 0.033248953 | AF10: 0.030448346
B11: CARFAX revenue y/y % | C11: =Model!W192 -> 0.080003751 | D11: =Model!X192 -> 0.08 | E11: =Model!Y192 -> 0.078 | F11: =Model!Z192 -> 0.075 | G11: =Model!AA192 -> 0.072 | H11: =Model!AB192 -> 0.07 | N11: CARFAX revenue y/y % | O11: 0.084264101 | P11: 0.1 | Q11: 0.098 | R11: 0.095 | S11: 0.092 | T11: 0.09 | Z11: CARFAX revenue y/y % | AA11: 0.075743401 | AB11: 0.05 | AC11: 0.048 | AD11: 0.045 | AE11: 0.042 | AF11: 0.04
B12: Adjusted EBITDA | C12: =Model!W153 -> 752.5 | D12: =Model!X153 -> 817.74976 | E12: =Model!Y153 -> 888.5212 | F12: =Model!Z153 -> 962.12114 | G12: =Model!AA153 -> 1039.5035 | H12: =Model!AB153 -> 1120.0773 | I12: =IFERROR((H12/C12)^(1/5)-1,"n/m") -> 0.082800125 | N12: Adjusted EBITDA | O12: 760 | P12: 863.08294 | Q12: 960.37614 | R12: 1064.2514 | S12: 1176.0613 | T12: 1295.4777 | U12: 0.11255956 | Z12: Adjusted EBITDA | AA12: 745 | AB12: 739.82423 | AC12: 782.30307 | AD12: 824.30085 | AE12: 866.51992 | AF12: 908.36514 | AG12: 0.040449097
B13: Adjusted EBITDA margin % | C13: =IFERROR(C12/C9,"") -> 0.40079893 | D13: =IFERROR(D12/D9,"") -> 0.40716967 | E13: =IFERROR(E12/E9,"") -> 0.41401829 | F13: =IFERROR(F12/F9,"") -> 0.42092257 | G13: =IFERROR(G12/G9,"") -> 0.42772992 | H13: =IFERROR(H12/H9,"") -> 0.43462122 | J13: =IFERROR(AVERAGE(Model!H154,Model!M154,Model!R154),"") -> 0.40584493 | K13: =IFERROR(MIN(Model!H154,Model!M154,Model!R154),"") -> 0.4026936 | L13: =IFERROR(MAX(Model!H154,Model!M154,Model!R154),"") -> 0.40855549 | N13: Adjusted EBITDA margin % | O13: 0.40318302 | P13: 0.41814071 | Q13: 0.42359174 | R13: 0.42915083 | S13: 0.43467009 | T13: 0.44030504 | V13: 0.40584493 | W13: 0.4026936 | X13: 0.40855549 | Z13: Adjusted EBITDA margin % | AA13: 0.39839572 | AB13: 0.38051811 | AC13: 0.38742107 | AD13: 0.39438307 | AE13: 0.40124173 | AF13: 0.40818945 | AH13: 0.40584493 | AI13: 0.4026936 | AJ13: 0.40855549
B15: Operating Profit (GAAP) | C15: =Model!W119 -> 338.5 | D15: =Model!X119 -> 461.57387 | E15: =Model!Y119 -> 539.45328 | F15: =Model!Z119 -> 610.12052 | G15: =Model!AA119 -> 687.46765 | H15: =Model!AB119 -> 767.95747 | I15: =IFERROR((H15/C15)^(1/5)-1,"n/m") -> 0.17802823 | N15: Operating Profit (GAAP) | O15: 346 | P15: 504.40358 | Q15: 604.7645 | R15: 701.5068 | S15: 808.90949 | T15: 923.69091 | U15: 0.2169987 | Z15: Operating Profit (GAAP) | AA15: 331 | AB15: 384.99488 | AC15: 435.89865 | AD15: 476.40871 | AE15: 520.16841 | AF15: 563.63275 | AG15: 0.11232999
B16: Operating profit y/y % | D16: =IFERROR(D15/C15-1,"") -> 0.36358602 | E16: =IFERROR(E15/D15-1,"") -> 0.16872578 | F16: =IFERROR(F15/E15-1,"") -> 0.13099789 | G16: =IFERROR(G15/F15-1,"") -> 0.12677354 | H16: =IFERROR(H15/G15-1,"") -> 0.1170816 | N16: Operating profit y/y % | P16: 0.4578138 | Q16: 0.19896948 | R16: 0.1599669 | S16: 0.15310285 | T16: 0.1418965 | Z16: Operating profit y/y % | AB16: 0.16312652 | AC16: 0.13221935 | AD16: 0.092934581 | AE16: 0.091853279 | AF16: 0.083558215
B17: Operating margin (GAAP) % | C17: =IFERROR(C15/C9,"") -> 0.18029294 | D17: =IFERROR(D15/D9,"") -> 0.22982444 | E17: =IFERROR(E15/E9,"") -> 0.25136544 | F17: =IFERROR(F15/F9,"") -> 0.26692429 | G17: =IFERROR(G15/G9,"") -> 0.28287589 | H17: =IFERROR(H15/H9,"") -> 0.29798891 | J17: =IFERROR(AVERAGE(Model!H201,Model!M201,Model!R201),"") -> 0.17980199 | K17: =IFERROR(MIN(Model!H201,Model!M201,Model!R201),"") -> 0.16094276 | L17: =IFERROR(MAX(Model!H201,Model!M201,Model!R201),"") -> 0.19371429 | N17: Operating margin (GAAP) % | O17: 0.18355438 | P17: 0.24437011 | Q17: 0.26674261 | R17: 0.28287699 | S17: 0.29897146 | T17: 0.3139427 | V17: 0.17980199 | W17: 0.16094276 | X17: 0.19371429 | Z17: Operating margin (GAAP) % | AA17: 0.17700535 | AB17: 0.19801666 | AC17: 0.21587071 | AD17: 0.22793562 | AE17: 0.24086379 | AF17: 0.25327804 | AH17: 0.17980199 | AI17: 0.16094276 | AJ17: 0.19371429
B19: Adjusted Net Income (model definition) | C19: =Model!W183 -> 462.48516 | D19: =Model!X183 -> 480.45345 | E19: =Model!Y183 -> 528.6376 | F19: =Model!Z183 -> 576.19294 | G19: =Model!AA183 -> 621.74028 | H19: =Model!AB183 -> 671.17735 | I19: =IFERROR((H19/C19)^(1/5)-1,"n/m") -> 0.077327875 | N19: Adjusted Net Income (model definition) | O19: 467.8333 | P19: 512.14809 | Q19: 560.34056 | R19: 621.97081 | S19: 686.28614 | T19: 757.24219 | U19: 0.101105 | Z19: Adjusted Net Income (model definition) | AA19: 457.13573 | AB19: 425.5814 | AC19: 462.6494 | AD19: 493.53595 | AE19: 519.24721 | AF19: 546.88517 | AG19: 0.036502121
B21: FDSO (m) | C21: =Model!W133 -> 295.58799 | D21: =Model!X133 -> 285.66545 | E21: =Model!Y133 -> 260.48561 | F21: =Model!Z133 -> 231.64119 | G21: =Model!AA133 -> 202.51682 | H21: =Model!AB133 -> 173.25637 | I21: =IFERROR((H21/C21)^(1/5)-1,"n/m") -> -0.1013295 | N21: FDSO (m) | O21: 295.58799 | P21: 273.79994 | Q21: 235.7323 | R21: 204.31997 | S21: 171.52949 | T21: 137.47839 | U21: -0.14195605 | Z21: FDSO (m) | AA21: 295.58799 | AB21: 296.92132 | AC21: 290.194 | AD21: 272.50747 | AE21: 251.63355 | AF21: 231.24969 | AG21: -0.047908084
B23: Adjusted EPS — Diluted ($) | C23: =Model!W185 -> 1.5646277 | D23: =Model!X185 -> 1.6818746 | E23: =Model!Y185 -> 2.0294311 | F23: =Model!Z185 -> 2.4874373 | G23: =Model!AA185 -> 3.0700673 | H23: =Model!AB185 -> 3.8738971 | I23: =IFERROR((H23/C23)^(1/5)-1,"n/m") -> 0.19880187 | N23: Adjusted EPS — Diluted ($) | O23: 1.5827209 | P23: 1.8705194 | Q23: 2.3770207 | R23: 3.0441019 | S23: 4.0009804 | T23: 5.5080814 | U23: 0.28327342 | Z23: Adjusted EPS — Diluted ($) | AA23: 1.5465301 | AB23: 1.4333137 | AC23: 1.5942763 | AD23: 1.8110915 | AE23: 2.0635055 | AF23: 2.3649119 | AG23: 0.088657621
B24: EPS y/y % | D24: =IFERROR(D23/C23-1,"") -> 0.074935919 | E24: =IFERROR(E23/D23-1,"") -> 0.2066483 | F24: =IFERROR(F23/E23-1,"") -> 0.22568206 | G24: =IFERROR(G23/F23-1,"") -> 0.23422903 | H24: =IFERROR(H23/G23-1,"") -> 0.26182806 | N24: EPS y/y % | P24: 0.18183778 | Q24: 0.2707811 | R24: 0.28063753 | S24: 0.31433852 | T24: 0.37668292 | Z24: EPS y/y % | AB24: -0.07320674 | AC24: 0.11230099 | AD24: 0.13599601 | AE24: 0.13937122 | AF24: 0.14606524
B26: P / E (x) — assumed (adjusted EPS) | G26: 13 | H26: 13 | N26: P / E (x) — assumed (adjusted EPS) | S26: 15 | T26: 15 | Z26: P / E (x) — assumed (adjusted EPS) | AD26: 10 | AE26: 10 | AF26: 10
B27: Price Target ($) | G27: =G26*G23 -> 39.910875 | H27: =H26*H23 -> 50.360662 | N27: Price Target ($) | S27: =S26*S23 -> 60.014706 | T27: =T26*T23 -> 82.621221 | Z27: Price Target ($) | AD27: =AD26*AD23 -> 18.110915 | AE27: =AE26*AE23 -> 20.635055 | AF27: =AF26*AF23 -> 23.649119
B28: Upside / (Downside) vs current | G28: =IFERROR(G27/$K$2-1,"") -> 1.2172708 | H28: =IFERROR(H27/$K$2-1,"") -> 1.7978146 | N28: Upside / (Downside) vs current | S28: =IFERROR(S27/$K$2-1,"") -> 2.3341503 | T28: =IFERROR(T27/$K$2-1,"") -> 3.5900678 | Z28: Upside / (Downside) vs current | AD28: =IFERROR(AD27/$K$2-1,"") -> 0.0061619345 | AE28: =IFERROR(AE27/$K$2-1,"") -> 0.14639195 | AF28: =IFERROR(AF27/$K$2-1,"") -> 0.31383997
B29: IRR (to 31-Dec of Y-1) | G29: =IFERROR((G27/$K$2)^(1/((DATE(2030-1,12,31)-$K$3)/365.25))-1,"") -> 0.28084956 | H29: =IFERROR((H27/$K$2)^(1/((DATE(2031-1,12,31)-$K$3)/365.25))-1,"") -> 0.27636364 | N29: IRR (to 31-Dec of Y-1) | S29: =IFERROR((S27/$K$2)^(1/((DATE(2030-1,12,31)-$K$3)/365.25))-1,"") -> 0.4540204 | T29: =IFERROR((T27/$K$2)^(1/((DATE(2031-1,12,31)-$K$3)/365.25))-1,"") -> 0.43538089 | Z29: IRR (to 31-Dec of Y-1) | AD29: =IFERROR((AD27/$K$2)^(1/((DATE(2029-1,12,31)-$K$3)/365.25))-1,"") -> 0.0027738904 | AE29: =IFERROR((AE27/$K$2)^(1/((DATE(2030-1,12,31)-$K$3)/365.25))-1,"") -> 0.043383023 | AF29: =IFERROR((AF27/$K$2)^(1/((DATE(2031-1,12,31)-$K$3)/365.25))-1,"") -> 0.066879447
B31: Free Cash Flow | C31: =Model!W232 -> 392.6964 | D31: =Model!X232 -> 492.13414 | E31: =Model!Y232 -> 548.59599 | F31: =Model!Z232 -> 597.17523 | G31: =Model!AA232 -> 642.99622 | H31: =Model!AB232 -> 692.66173 | I31: =IFERROR((H31/C31)^(1/5)-1,"n/m") -> 0.120193 | N31: Free Cash Flow | O31: 398.20089 | P31: 525.75283 | Q31: 583.85218 | R31: 647.95985 | S31: 714.07294 | T31: 786.84965 | U31: 0.14592952 | Z31: Free Cash Flow | AA31: 387.19192 | AB31: 435.45822 | AC31: 480.21914 | AD31: 511.50207 | AE31: 536.81247 | AF31: 563.96627 | AG31: 0.078115698
B32: FCF % | C32: =IFERROR(C31/C9,"") -> 0.2091592 | D32: =IFERROR(D31/D9,"") -> 0.24504085 | E32: =IFERROR(E31/E9,"") -> 0.25562561 | F32: =IFERROR(F31/F9,"") -> 0.26126079 | G32: =IFERROR(G31/G9,"") -> 0.264577 | H32: =IFERROR(H31/H9,"") -> 0.26877206 | J32: =IFERROR(AVERAGE(Model!H236,Model!M236,Model!R236),"") -> 0.25712617 | K32: =IFERROR(MIN(Model!H236,Model!M236,Model!R236),"") -> 0.25252525 | L32: =IFERROR(MAX(Model!H236,Model!M236,Model!R236),"") -> 0.26342857 | N32: FCF % | O32: 0.21124716 | P32: 0.25471325 | Q32: 0.25751885 | R32: 0.26128461 | S32: 0.26392005 | T32: 0.2674333 | V32: 0.25712617 | W32: 0.25252525 | X32: 0.26342857 | Z32: FCF % | AA32: 0.2070545 | AB32: 0.22397176 | AC32: 0.23781961 | AD32: 0.24472589 | AE32: 0.24857082 | AF32: 0.25342791 | AH32: 0.25712617 | AI32: 0.25252525 | AJ32: 0.26342857
B33: FCF / share ($) | C33: =IFERROR(C31/C21,"") -> 1.3285263 | D33: =IFERROR(D31/D21,"") -> 1.722764 | E33: =IFERROR(E31/E21,"") -> 2.106051 | F33: =IFERROR(F31/F21,"") -> 2.5780183 | G33: =IFERROR(G31/G21,"") -> 3.1750262 | H33: =IFERROR(H31/H21,"") -> 3.9979005 | N33: FCF / share ($) | O33: 1.3471484 | P33: 1.920208 | Q33: 2.4767593 | R33: 3.1712997 | S33: 4.1629747 | T33: 5.7234423 | Z33: FCF / share ($) | AA33: 1.3099041 | AB33: 1.4665778 | AC33: 1.6548211 | AD33: 1.8770204 | AE33: 2.1333104 | AF33: 2.4387763
B34: FCF Yield (on PT) | F34: =IFERROR(F33/F$27,"") | G34: =IFERROR(G33/G$27,"") -> 0.079552908 | H34: =IFERROR(H33/H$27,"") -> 0.079385384 | N34: FCF Yield (on PT) | R34: =IFERROR(R33/R$27,"") | S34: =IFERROR(S33/S$27,"") -> 0.06936591 | T34: =IFERROR(T33/T$27,"") -> 0.069273271 | Z34: FCF Yield (on PT) | AD34: =IFERROR(AD33/AD$27,"") -> 0.10364029 | AE34: =IFERROR(AE33/AE$27,"") -> 0.10338283 | AF34: =IFERROR(AF33/AF$27,"") -> 0.10312334
B35: Adjusted EBITDA (leverage basis) | C35: =Model!W153 -> 752.5 | D35: =Model!X153 -> 817.74976 | E35: =Model!Y153 -> 888.5212 | F35: =Model!Z153 -> 962.12114 | G35: =Model!AA153 -> 1039.5035 | H35: =Model!AB153 -> 1120.0773 | I35: =IFERROR((H35/C35)^(1/5)-1,"n/m") -> 0.082800125 | N35: Adjusted EBITDA (leverage basis) | O35: 760 | P35: 863.08294 | Q35: 960.37614 | R35: 1064.2514 | S35: 1176.0613 | T35: 1295.4777 | U35: 0.11255956 | Z35: Adjusted EBITDA (leverage basis) | AA35: 745 | AB35: 739.82423 | AC35: 782.30307 | AD35: 824.30085 | AE35: 866.51992 | AF35: 908.36514 | AG35: 0.040449097
B36: Adjusted EBITDA % of revenue | C36: =IFERROR(C35/C9,"") -> 0.40079893 | D36: =IFERROR(D35/D9,"") -> 0.40716967 | E36: =IFERROR(E35/E9,"") -> 0.41401829 | F36: =IFERROR(F35/F9,"") -> 0.42092257 | G36: =IFERROR(G35/G9,"") -> 0.42772992 | H36: =IFERROR(H35/H9,"") -> 0.43462122 | J36: =IFERROR(AVERAGE(Model!H198,Model!M198,Model!R198),"") -> 0.40584493 | K36: =IFERROR(MIN(Model!H198,Model!M198,Model!R198),"") -> 0.4026936 | L36: =IFERROR(MAX(Model!H198,Model!M198,Model!R198),"") -> 0.40855549 | N36: Adjusted EBITDA % of revenue | O36: 0.40318302 | P36: 0.41814071 | Q36: 0.42359174 | R36: 0.42915083 | S36: 0.43467009 | T36: 0.44030504 | V36: 0.40584493 | W36: 0.4026936 | X36: 0.40855549 | Z36: Adjusted EBITDA % of revenue | AA36: 0.39839572 | AB36: 0.38051811 | AC36: 0.38742107 | AD36: 0.39438307 | AE36: 0.40124173 | AF36: 0.40818945 | AH36: 0.40584493 | AI36: 0.4026936 | AJ36: 0.40855549
B38: Net Debt | C38: =Model!W346 -> 1616.2002 | D38: =Model!X346 -> 1635.4995 | E38: =Model!Y346 -> 1777.0424 | F38: =Model!Z346 -> 1924.2423 | G38: =Model!AA346 -> 2079.0071 | H38: =Model!AB346 -> 2240.1546 | N38: Net Debt | O38: 1610.6957 | P38: 2157.7074 | Q38: 2400.9403 | R38: 2660.6284 | S38: 2940.1532 | T38: 3238.6942 | Z38: Net Debt | AA38: 1621.7046 | AB38: 1260.0515 | AC38: 1173.4546 | AD38: 1236.4513 | AE38: 1299.7799 | AF38: 1362.5477
B39: Net Debt / Adjusted EBITDA (x) | C39: =IFERROR(C38/C35,"") -> 2.1477743 | D39: =IFERROR(D38/D35,"") -> 2 | E39: =IFERROR(E38/E35,"") -> 2 | F39: =IFERROR(F38/F35,"") -> 2 | G39: =IFERROR(G38/G35,"") -> 2 | H39: =IFERROR(H38/H35,"") -> 2 | N39: Net Debt / Adjusted EBITDA (x) | O39: 2.1193364 | P39: 2.5 | Q39: 2.5 | R39: 2.5 | S39: 2.5 | T39: 2.5 | Z39: Net Debt / Adjusted EBITDA (x) | AA39: 2.1767848 | AB39: 1.7031769 | AC39: 1.5 | AD39: 1.5 | AE39: 1.5 | AF39: 1.5
B40: Share repurchases ($m; 2026E = 2H) | D40: =Model!X246 -> 437.62839 | E40: =Model!Y246 -> 618.26486 | F40: =Model!Z246 -> 676.63762 | G40: =Model!AA246 -> 734.85512 | H40: =Model!AB246 -> 796.42857 | N40: Share repurchases ($m; 2026E = 2H) | P40: 898.95941 | Q40: 661.19137 | R40: 746.7307 | S40: 838.71188 | T40: 937.66828 | AB40: 0 | AC40: 316.07523 | AD40: 496.9962 | AE40: 524.78073 | AF40: 553.77379
B41: Implied avg buyback price ($) | D41: =Model!X245 -> 19.44 | E41: =Model!Y245 -> 20.9952 | F41: =Model!Z245 -> 22.674816 | G41: =Model!AA245 -> 24.488801 | H41: =Model!AB245 -> 26.447905 | N41: Implied avg buyback price ($) | P41: 19.44 | Q41: 20.9952 | R41: 22.674816 | S41: 24.488801 | T41: 26.447905 | AB41: 19.44 | AC41: 20.9952 | AD41: 22.674816 | AE41: 24.488801 | AF41: 26.447905
B42: Shares repurchased (m) | D42: =Model!X247 -> 22.511748 | E42: =Model!Y247 -> 29.447915 | F42: =Model!Z247 -> 29.840931 | G42: =Model!AA247 -> 30.007803 | H42: =Model!AB247 -> 30.113106 | N42: Shares repurchased (m) | P42: 46.242768 | Q42: 31.492502 | R42: 32.932161 | S42: 34.248793 | T42: 35.453404 | AB42: 0 | AC42: 15.054643 | AD42: 21.918423 | AE42: 21.429417 | AF42: 20.938286
B44: ROIC | C44: =Model!W329 -> 0.027197982 | D44: =Model!X329 -> 0.031976969 | E44: =Model!Y329 -> 0.037059097 | F44: =Model!Z329 -> 0.042515347 | G44: =Model!AA329 -> 0.048615522 | H44: =Model!AB329 -> 0.055146588 | J44: =IFERROR(AVERAGE(Model!H329,Model!M329,Model!R329),"") -> 0.021215496 | K44: =IFERROR(MIN(Model!H329,Model!M329,Model!R329),"") -> 0.018013991 | L44: =IFERROR(MAX(Model!H329,Model!M329,Model!R329),"") -> 0.023640561 | N44: ROIC | O44: 0.027661781 | P44: 0.034433691 | Q44: 0.040660968 | R44: 0.047435008 | S44: 0.055040043 | T44: 0.063281907 | V44: 0.021215496 | W44: 0.018013991 | X44: 0.023640561 | Z44: ROIC | AA44: 0.026734147 | AB44: 0.027079014 | AC44: 0.03027767 | AD44: 0.03356608 | AE44: 0.037184821 | AF44: 0.04090566 | AH44: 0.021215496 | AI44: 0.018013991 | AJ44: 0.023640561
B45: RONTA | C45: =Model!W340 -> 0.62460937 | D45: =Model!X340 -> 0.73192811 | E45: =Model!Y340 -> 1.1269825 | F45: =Model!Z340 -> 1.2727433 | G45: =Model!AA340 -> 1.3860319 | H45: =Model!AB340 -> 1.4954717 | J45: =IFERROR(AVERAGE(Model!H340,Model!M340,Model!R340),"") -> 2.4457308 | K45: =IFERROR(MIN(Model!H340,Model!M340,Model!R340),"") -> 2.138934 | L45: =IFERROR(MAX(Model!H340,Model!M340,Model!R340),"") -> 2.7334697 | N45: RONTA | O45: 0.62857471 | P45: 1.1449519 | Q45: 1.3055485 | R45: 1.4669968 | S45: 1.6361956 | T45: 1.8043981 | V45: 2.4457308 | W45: 2.138934 | X45: 2.7334697 | Z45: RONTA | AA45: 0.62055774 | AB45: 0.35173266 | AC45: 0.34637366 | AD45: 0.39700361 | AE45: 0.45592813 | AF45: 0.52091189 | AH45: 2.4457308 | AI45: 2.138934 | AJ45: 2.7334697
B47: Implied Market Cap (USDm) | F47: =F27*F21 -> 0 | G47: =G27*G21 -> 8082.6237 | H47: =H27*H21 -> 8725.3055 | N47: Implied Market Cap (USDm) | R47: =R27*R21 -> 0 | S47: =S27*S21 -> 10294.292 | T47: =T27*T21 -> 11358.633 | Z47: Implied Market Cap (USDm) | AD47: =AD27*AD21 -> 4935.3595 | AE47: =AE27*AE21 -> 5192.4721 | AF47: =AF27*AF21 -> 5468.8517
B48: (+) Net Debt & NCI | F48: =F38+Model!Z355 -> 1924.2423 | G48: =G38+Model!AA355 -> 2079.0071 | H48: =H38+Model!AB355 -> 2240.1546 | N48: (+) Net Debt & NCI | R48: =R38+Model!Z355 -> 2660.6284 | S48: =S38+Model!AA355 -> 2940.1532 | T48: =T38+Model!AB355 -> 3238.6942 | Z48: (+) Net Debt & NCI | AD48: =AD38+Model!Z355 -> 1236.4513 | AE48: =AE38+Model!AA355 -> 1299.7799 | AF48: =AF38+Model!AB355 -> 1362.5477
B49: Implied Enterprise Value (USDm) | F49: =F47+F48 -> 1924.2423 | G49: =G47+G48 -> 10161.631 | H49: =H47+H48 -> 10965.46 | N49: Implied Enterprise Value (USDm) | R49: =R47+R48 -> 2660.6284 | S49: =S47+S48 -> 13234.445 | T49: =T47+T48 -> 14597.327 | Z49: Implied Enterprise Value (USDm) | AD49: =AD47+AD48 -> 6171.8108 | AE49: =AE47+AE48 -> 6492.252 | AF49: =AF47+AF48 -> 6831.3994
B50: Implied EV / Adjusted EBITDA (x) | F50: =IFERROR(F49/F35,"") -> 2 | G50: =IFERROR(G49/G35,"") -> 9.7754653 | H50: =IFERROR(H49/H35,"") -> 9.7899138 | N50: Implied EV / Adjusted EBITDA (x) | R50: =IFERROR(R49/R35,"") -> 2.5 | S50: =IFERROR(S49/S35,"") -> 11.253194 | T50: =IFERROR(T49/T35,"") -> 11.267911 | Z50: Implied EV / Adjusted EBITDA (x) | AD50: =IFERROR(AD49/AD35,"") -> 7.4873279 | AE50: =IFERROR(AE49/AE35,"") -> 7.4923286 | AF50: =IFERROR(AF49/AF35,"") -> 7.5205433

Sheet DCF
B2: DCF VALUATION — MOBILITY GLOBAL INC. (MBGL)
B4: 1. WACC BUILD
B5: Risk-free rate (US 10Y govt) | C5: 0.0425 | D5: Assumption (~US 10Y Treasury yield, Oct-2026; rate sources not reachable from the build environment); update to market
B6: Equity risk premium | C6: 0.05 | D6: Assumption: US implied ERP ~4.5–5.5%
B7: Levered beta | C7: 1.15 | D7: Assumption: no trading history before Jul-2026; data / information-services peers ~0.9–1.2, raised for a newly levered spin (~2.2x) with auto-dealer and OEM end-market exposure; ~81% subscription revenue dampens cyclicality
B8: Cost of equity | C8: =C5+C7*C6 -> 0.1
B9: Pre-tax cost of debt | C9: 0.0575 | D9: Senior notes 5.050% 2029 / 5.450% 2031 / 6.050% 2036 (May-2026; 5.74% all-in per the Form 10 pro forma); revolver SOFR + 1.0–1.625%
B10: Tax rate | C10: 0.27 | D10: Assumption: normalised tax rate on adjusted EBIT (model 2027E+ GAAP effective rate 28.5%; amortization is largely non-deductible)
B11: After-tax cost of debt | C11: =C9*(1-C10) -> 0.041975
B12: Target D/V | C12: 0.25 | D12: Net debt ~$1.8bn at 30-Jun-2026 vs ~$5.3bn market cap ($18.00 × ~296m diluted shares); D/V ~25%
B13: WACC | C13: =C8*(1-C12)+C11*C12 -> 0.08549375
B15: Valuation date (live) | C15: =TODAY() -> 2026-10-13 00:00:00 | D15: Periods = (31-Dec of the year − today) / 365.25; cash flows assumed at year-end; 2026E (valuation date in Q4) is the base year and its cash flow sits in YE2026E net debt
B16: 2. UNLEVERED FREE CASH FLOW BUILD (USDm)
D17: 2027E | E17: 2028E | F17: 2029E | G17: 2030E | H17: 2031E | I17: 2032E | J17: 2033E | K17: 2034E | L17: 2035E | M17: 2036E | N17: Terminal | P17: CAGR 27–31E | Q17: CAGR 27–36E
B18: Adj. EBITA (Adjusted EBITDA − depreciation) less SBC and cash transaction / severance / other costs | D18: =Model!X161-Model!X158-Model!X109 -> 757.57387 | E18: =Model!Y161-Model!Y158-Model!Y109 -> 835.45328 | F18: =Model!Z161-Model!Z158-Model!Z109 -> 906.12052 | G18: =Model!AA161-Model!AA158-Model!AA109 -> 980.46765 | H18: =Model!AB161-Model!AB158-Model!AB109 -> 1057.9575 | I18: =H18*(1+I$26) -> 1121.4349 | J18: =I18*(1+J$26) -> 1183.1138 | K18: =J18*(1+K$26) -> 1242.2695 | L18: =K18*(1+L$26) -> 1298.1717 | M18: =L18*(1+M$26) -> 1350.0985 | P18: =(H18/D18)^(1/(COLUMNS(D18:H18)-1))-1 -> 0.087078248 | Q18: =(M18/D18)^(1/(COLUMNS(D18:M18)-1))-1 -> 0.066307037
B19: × (1 − tax rate) | D19: =1-$C$10 -> 0.73 | E19: =1-$C$10 -> 0.73 | F19: =1-$C$10 -> 0.73 | G19: =1-$C$10 -> 0.73 | H19: =1-$C$10 -> 0.73 | I19: =1-$C$10 -> 0.73 | J19: =1-$C$10 -> 0.73 | K19: =1-$C$10 -> 0.73 | ... M19: =1-$C$10 -> 0.73
B20: NOPAT | D20: =D18*D19 -> 553.02892 | E20: =E18*E19 -> 609.88089 | F20: =F18*F19 -> 661.46798 | G20: =G18*G19 -> 715.74139 | H20: =H18*H19 -> 772.30895 | I20: =I18*I19 -> 818.64749 | J20: =J18*J19 -> 863.6731 | K20: =K18*K19 -> 906.85675 | ... M20: =M18*M19 -> 985.57192
B21: plus depreciation (amortization of acquired intangibles is excluded above, not added back) | D21: =Model!X104 -> 16.067007 | E21: =Model!Y104 -> 17.168733 | F21: =Model!Z104 -> 18.28595 | G21: =Model!AA104 -> 19.442241 | H21: =Model!AB104 -> 20.617075 | I21: =H21*(1+I$26) -> 21.8541 | J21: =I21*(1+J$26) -> 23.056075 | K21: =J21*(1+K$26) -> 24.208879 | L21: =K21*(1+L$26) -> 25.298278 | M21: =L21*(1+M$26) -> 26.31021
B22: − Capex and acquisitions (M&A lever 2027E–31E) | D22: =Model!X214+Model!X215 -> -28.117263 | E22: =Model!Y214+Model!Y215 -> -30.045283 | F22: =Model!Z214+Model!Z215 -> -32.000412 | G22: =Model!AA214+Model!AA215 -> -34.023922 | H22: =Model!AB214+Model!AB215 -> -36.079881 | I22: =Model!AB214*(1+I$26) -> -38.244674 | J22: =I22*(1+J$26) -> -40.348131 | K22: =J22*(1+K$26) -> -42.365538 | L22: =K22*(1+L$26) -> -44.271987 | M22: =L22*(1+M$26) -> -46.042867
B23: − Δ Working capital (CF statement) | D23: =Model!X212 -> 3.1320582 | E23: =Model!Y212 -> 3.295745 | F23: =Model!Z212 -> 3.3420848 | G23: =Model!AA212 -> 3.4589737 | H23: =Model!AB212 -> 3.5144434 | I23: =H23*(1+I$26) -> 3.72531 | J23: =I23*(1+J$26) -> 3.9302021 | K23: =J23*(1+K$26) -> 4.1267122 | L23: =K23*(1+L$26) -> 4.3124143 | M23: =L23*(1+M$26) -> 4.4849108
B24: Unlevered FCF | D24: =D20+D21+D22+D23 -> 544.11072 | E24: =E20+E21+E22+E23 -> 600.30009 | F24: =F20+F21+F22+F23 -> 651.0956 | G24: =G20+G21+G22+G23 -> 704.61868 | H24: =H20+H21+H22+H23 -> 760.36059 | I24: =I20+I21+I22+I23 -> 805.98222 | J24: =J20+J21+J22+J23 -> 850.31124 | K24: =K20+K21+K22+K23 -> 892.82681 | ... M24: =M20+M21+M22+M23 -> 970.32417 | N24: =M24*(1+$C$27) -> 999.4339 | P24: =(H24/D24)^(1/(COLUMNS(D24:H24)-1))-1 -> 0.087259166 | Q24: =(M24/D24)^(1/(COLUMNS(D24:M24)-1))-1 -> 0.066385905
B25: Terminal Value (Gordon Growth) | N25: =N24/($C$13-$C$27) -> 18009.846
B26: Fade-period growth (2032E–36E; 6.0% → 4.0% linear) | I26: 0.06 | J26: =I26+($M$26-$I$26)/4 -> 0.055 | K26: =J26+($M$26-$I$26)/4 -> 0.05 | L26: =K26+($M$26-$I$26)/4 -> 0.045 | M26: 0.04
B27: Terminal growth rate | C27: 0.03
B29: Discount period (years) | D29: =(DATE(2027,12,31)-$C$15)/365.25 -> 1.2156057 | E29: =(DATE(2028,12,31)-$C$15)/365.25 -> 2.2176591 | F29: =(DATE(2029,12,31)-$C$15)/365.25 -> 3.2169747 | G29: =(DATE(2030,12,31)-$C$15)/365.25 -> 4.2162902 | H29: =(DATE(2031,12,31)-$C$15)/365.25 -> 5.2156057 | I29: =(DATE(2032,12,31)-$C$15)/365.25 -> 6.2176591 | J29: =(DATE(2033,12,31)-$C$15)/365.25 -> 7.2169747 | K29: =(DATE(2034,12,31)-$C$15)/365.25 -> 8.2162902 | L29: =(DATE(2035,12,31)-$C$15)/365.25 -> 9.2156057 | M29: =(DATE(2036,12,31)-$C$15)/365.25 -> 10.217659 | N29: =M29 -> 10.217659
B30: Discount factor | D30: =1/(1+$C$13)^D29 -> 0.90508885 | E30: =1/(1+$C$13)^E29 -> 0.83366339 | F30: =1/(1+$C$13)^F29 -> 0.76804699 | G30: =1/(1+$C$13)^G29 -> 0.70759515 | H30: =1/(1+$C$13)^H29 -> 0.65190139 | I30: =1/(1+$C$13)^I29 -> 0.60045632 | J30: =1/(1+$C$13)^J29 -> 0.5531953 | K30: =1/(1+$C$13)^K29 -> 0.50965412 | ... N30: =1/(1+$C$13)^N29 -> 0.43248606
B31: PV of UFCF | D31: =D24*D30 -> 492.46855 | E31: =E24*E30 -> 500.44821 | F31: =F24*F30 -> 500.07201 | G31: =G24*G30 -> 498.58476 | H31: =H24*H30 -> 495.68012 | I31: =I24*I30 -> 483.95712 | J31: =J24*J30 -> 470.38818 | K31: =K24*K30 -> 455.03286 | ... M31: =M24*M30 -> 419.65168 | N31: =N25*N30 -> 7789.0074
D32: NOPAT basis (standard): taxed on pre-amortization Adjusted EBITA with a depreciation-only add-back. The ~$296m p.a. of acquired-intangible amortization (IHS Markit purchase accounting) is non-cash and largely non-deductible (deferred-tax liability $967m at 30-Jun-2026), so taxing EBIT after amortization would overstate the cash tax shield. Mobility Global's Adjusted EBITDA adds back stock-based compensation, a real cost: row 18 deducts SBC and the cash transaction (separation stand-up), severance and other items the company excludes. Base year 2026E: valuation date (Oct-2026) inside the year; YE2026E net debt captures 2H/26 cash flow.
B33: IMPLIED ROIC — invested capital roll-forward (USDm)
B34: Opening invested capital | D34: =Model!W326 -> 11514.069 | E34: =D38 -> 11522.987 | F34: =E38 -> 11532.568 | G34: =F38 -> 11542.94 | H34: =G38 -> 11554.063 | I34: =H38 -> 11566.011 | J34: =I38 -> 11578.676 | K34: =J38 -> 11592.038 | L34: =K38 -> 11606.068 | M34: =L38 -> 11620.729
B35: plus Capex and acquisitions | D35: =-D22 -> 28.117263 | E35: =-E22 -> 30.045283 | F35: =-F22 -> 32.000412 | G35: =-G22 -> 34.023922 | H35: =-H22 -> 36.079881 | I35: =-I22 -> 38.244674 | J35: =-J22 -> 40.348131 | K35: =-K22 -> 42.365538 | ... M35: =-M22 -> 46.042867
B36: less DD&A | D36: =-D21 -> -16.067007 | E36: =-E21 -> -17.168733 | F36: =-F21 -> -18.28595 | G36: =-G21 -> -19.442241 | H36: =-H21 -> -20.617075 | I36: =-I21 -> -21.8541 | J36: =-J21 -> -23.056075 | K36: =-K21 -> -24.208879 | ... M36: =-M21 -> -26.31021
B37: plus Δ Working capital investment | D37: =-D23 -> -3.1320582 | E37: =-E23 -> -3.295745 | F37: =-F23 -> -3.3420848 | G37: =-G23 -> -3.4589737 | H37: =-H23 -> -3.5144434 | I37: =-I23 -> -3.72531 | J37: =-J23 -> -3.9302021 | K37: =-K23 -> -4.1267122 | ... M37: =-M23 -> -4.4849108
B38: Closing invested capital | D38: =SUM(D34:D37) -> 11522.987 | E38: =SUM(E34:E37) -> 11532.568 | F38: =SUM(F34:F37) -> 11542.94 | G38: =SUM(G34:G37) -> 11554.063 | H38: =SUM(H34:H37) -> 11566.011 | I38: =SUM(I34:I37) -> 11578.676 | J38: =SUM(J34:J37) -> 11592.038 | K38: =SUM(K34:K37) -> 11606.068 | ... M38: =SUM(M34:M37) -> 11635.977
B39: NOPAT (row 20) | D39: =D20 -> 553.02892 | E39: =E20 -> 609.88089 | F39: =F20 -> 661.46798 | G39: =G20 -> 715.74139 | H39: =H20 -> 772.30895 | I39: =I20 -> 818.64749 | J39: =J20 -> 863.6731 | K39: =K20 -> 906.85675 | ... M39: =M20 -> 985.57192
B40: Implied ROIC (NOPAT / avg. invested capital) | D40: =IFERROR(D39/AVERAGE(D34,D38),"") -> 0.048012119 | E40: =IFERROR(E39/AVERAGE(E34,E38),"") -> 0.052905333 | F40: =IFERROR(F39/AVERAGE(F34,F38),"") -> 0.057330741 | G40: =IFERROR(G39/AVERAGE(G34,G38),"") -> 0.061976993 | H40: =IFERROR(H39/AVERAGE(H34,H38),"") -> 0.06680852 | I40: =IFERROR(I39/AVERAGE(I34,I38),"") -> 0.070741719 | J40: =IFERROR(J39/AVERAGE(J34,J38),"") -> 0.074548681 | K40: =IFERROR(K39/AVERAGE(K34,K38),"") -> 0.078183688 | ... M40: =IFERROR(M39/AVERAGE(M34,M38),"") -> 0.084755932
B41: Reinvestment rate (net investment / NOPAT) | D41: =IFERROR(SUM(D35:D37)/D39,"") -> 0.016126096 | E41: =IFERROR(SUM(E35:E37)/E39,"") -> 0.015709305 | F41: =IFERROR(SUM(F35:F37)/F39,"") -> 0.015680846 | G41: =IFERROR(SUM(G35:G37)/G39,"") -> 0.01554012 | H41: =IFERROR(SUM(H35:H37)/H39,"") -> 0.015470963 | I41: =IFERROR(SUM(I35:I37)/I39,"") -> 0.015470963 | J41: =IFERROR(SUM(J35:J37)/J39,"") -> 0.015470963 | K41: =IFERROR(SUM(K35:K37)/K39,"") -> 0.015470963 | ... M41: =IFERROR(SUM(M35:M37)/M39,"") -> 0.015470963
B42: Implied terminal RONIC (g / reinvestment rate) | N42: =IFERROR($C$27/M41,"") -> 1.9391166
D43: Opening IC = Model 2026E book IC (equity + net debt at 31-Dec-2026; equity carries the IHS Markit purchase goodwill and intangibles), rolled forward with capex + M&A − D&A + ΔWC.
B44: 3. VALUATION SUMMARY
...

Sheet Charts
B2: Mobility Global — Operating Performance (2023–2025) and Model Forecast (2026E–2031E)
B3: USDm · Linked to Model. Bars = CARFAX / B2B revenue growth (carve-out; 2023 growth n/a on the carve-out basis — see the S&P Global segment memo). Adjusted EBITDA = company definition. ROIC / RONTA on Adjusted EBIT (full-cost); returns are depressed by the IHS Markit purchase-accounting goodwill and intangibles in equity. Carve-out history starts in FY2023.
C7: 2023 | D7: 2024 | E7: 2025 | F7: 2026E | G7: 2027E | H7: 2028E | I7: 2029E | J7: 2030E | K7: 2031E
B8: CARFAX revenue y/y % | C8: =IFERROR(Model!H192+0,0) -> 0 | D8: =IFERROR(Model!M192+0,0) -> 0.11961207 | E8: =IFERROR(Model!R192+0,0) -> 0.099133782 | F8: =IFERROR(Model!W192+0,0) -> 0.080003751 | G8: =IFERROR(Model!X192+0,0) -> 0.08 | H8: =IFERROR(Model!Y192+0,0) -> 0.078 | I8: =IFERROR(Model!Z192+0,0) -> 0.075 | J8: =IFERROR(Model!AA192+0,0) -> 0.072 | K8: =IFERROR(Model!AB192+0,0) -> 0.07
B9: B2B revenue y/y % | C9: =IFERROR(Model!H193+0,0) -> 0 | D9: =IFERROR(Model!M193+0,0) -> 0.030520646 | E9: =IFERROR(Model!R193+0,0) -> 0.059233449 | F9: =IFERROR(Model!W193+0,0) -> 0.059433744 | G9: =IFERROR(Model!X193+0,0) -> 0.05 | H9: =IFERROR(Model!Y193+0,0) -> 0.05 | I9: =IFERROR(Model!Z193+0,0) -> 0.045 | J9: =IFERROR(Model!AA193+0,0) -> 0.045 | K9: =IFERROR(Model!AB193+0,0) -> 0.04
C11: =C7 -> 2023 | D11: =D7 -> 2024 | E11: =E7 -> 2025 | F11: =F7 -> 2026E | G11: =G7 -> 2027E | H11: =H7 -> 2028E | I11: =I7 -> 2029E | J11: =J7 -> 2030E | K11: =K7 -> 2031E
B12: Adjusted EBITDA | C12: =IFERROR(Model!H153+0,NA()) -> 598 | D12: =IFERROR(Model!M153+0,NA()) -> 659 | E12: =IFERROR(Model!R153+0,NA()) -> 711 | F12: =IFERROR(Model!W153+0,NA()) -> 752.5 | G12: =IFERROR(Model!X153+0,NA()) -> 817.74976 | H12: =IFERROR(Model!Y153+0,NA()) -> 888.5212 | I12: =IFERROR(Model!Z153+0,NA()) -> 962.12114 | J12: =IFERROR(Model!AA153+0,NA()) -> 1039.5035 | K12: =IFERROR(Model!AB153+0,NA()) -> 1120.0773
B13: Operating profit (GAAP) | C13: =IFERROR(Model!H119+0,NA()) -> 239 | D13: =IFERROR(Model!M119+0,NA()) -> 298 | E13: =IFERROR(Model!R119+0,NA()) -> 339 | F13: =IFERROR(Model!W119+0,NA()) -> 338.5 | G13: =IFERROR(Model!X119+0,NA()) -> 461.57387 | H13: =IFERROR(Model!Y119+0,NA()) -> 539.45328 | I13: =IFERROR(Model!Z119+0,NA()) -> 610.12052 | J13: =IFERROR(Model!AA119+0,NA()) -> 687.46765 | K13: =IFERROR(Model!AB119+0,NA()) -> 767.95747
B14: Adj. EBITDA Margin % | C14: =IFERROR(Model!H198+0,NA()) -> 0.4026936 | D14: =IFERROR(Model!M198+0,NA()) -> 0.40855549 | E14: =IFERROR(Model!R198+0,NA()) -> 0.40628571 | F14: =IFERROR(Model!W198+0,NA()) -> 0.40079893 | G14: =IFERROR(Model!X198+0,NA()) -> 0.40716967 | H14: =IFERROR(Model!Y198+0,NA()) -> 0.41401829 | I14: =IFERROR(Model!Z198+0,NA()) -> 0.42092257 | J14: =IFERROR(Model!AA198+0,NA()) -> 0.42772992 | K14: =IFERROR(Model!AB198+0,NA()) -> 0.43462122
B15: GAAP Op. Margin % | C15: =IFERROR(Model!H201+0,NA()) -> 0.16094276 | D15: =IFERROR(Model!M201+0,NA()) -> 0.18474892 | E15: =IFERROR(Model!R201+0,NA()) -> 0.19371429 | F15: =IFERROR(Model!W201+0,NA()) -> 0.18029294 | G15: =IFERROR(Model!X201+0,NA()) -> 0.22982444 | H15: =IFERROR(Model!Y201+0,NA()) -> 0.25136544 | I15: =IFERROR(Model!Z201+0,NA()) -> 0.26692429 | J15: =IFERROR(Model!AA201+0,NA()) -> 0.28287589 | K15: =IFERROR(Model!AB201+0,NA()) -> 0.29798891
C17: =C7 -> 2023 | D17: =D7 -> 2024 | E17: =E7 -> 2025 | F17: =F7 -> 2026E | G17: =G7 -> 2027E | H17: =H7 -> 2028E | I17: =I7 -> 2029E | J17: =J7 -> 2030E | K17: =K7 -> 2031E
B18: ROIC | C18: =IFERROR(Model!H329+0,NA()) -> 0.018013991 | D18: =IFERROR(Model!M329+0,NA()) -> 0.021991938 | E18: =IFERROR(Model!R329+0,NA()) -> 0.023640561 | F18: =IFERROR(Model!W329+0,NA()) -> 0.027197982 | G18: =IFERROR(Model!X329+0,NA()) -> 0.031976969 | H18: =IFERROR(Model!Y329+0,NA()) -> 0.037059097 | I18: =IFERROR(Model!Z329+0,NA()) -> 0.042515347 | J18: =IFERROR(Model!AA329+0,NA()) -> 0.048615522 | K18: =IFERROR(Model!AB329+0,NA()) -> 0.055146588
B19: RONTA | C19: =IFERROR(Model!H340+0,NA()) -> 2.138934 | D19: =IFERROR(Model!M340+0,NA()) -> 2.4647887 | E19: =IFERROR(Model!R340+0,NA()) -> 2.7334697 | F19: =IFERROR(Model!W340+0,NA()) -> 0.62460937 | G19: =IFERROR(Model!X340+0,NA()) -> 0.73192811 | H19: =IFERROR(Model!Y340+0,NA()) -> 1.1269825 | I19: =IFERROR(Model!Z340+0,NA()) -> 1.2727433 | J19: =IFERROR(Model!AA340+0,NA()) -> 1.3860319 | K19: =IFERROR(Model!AB340+0,NA()) -> 1.4954717
B20: Adj. EBITDA margin % | C20: =IFERROR(Model!H198+0,NA()) -> 0.4026936 | D20: =IFERROR(Model!M198+0,NA()) -> 0.40855549 | E20: =IFERROR(Model!R198+0,NA()) -> 0.40628571 | F20: =IFERROR(Model!W198+0,NA()) -> 0.40079893 | G20: =IFERROR(Model!X198+0,NA()) -> 0.40716967 | H20: =IFERROR(Model!Y198+0,NA()) -> 0.41401829 | I20: =IFERROR(Model!Z198+0,NA()) -> 0.42092257 | J20: =IFERROR(Model!AA198+0,NA()) -> 0.42772992 | K20: =IFERROR(Model!AB198+0,NA()) -> 0.43462122
B21: FCF margin % | C21: =IFERROR(Model!H236+0,NA()) -> 0.25252525 | D21: =IFERROR(Model!M236+0,NA()) -> 0.25542467 | E21: =IFERROR(Model!R236+0,NA()) -> 0.26342857 | F21: =IFERROR(Model!W236+0,NA()) -> 0.2091592 | G21: =IFERROR(Model!X236+0,NA()) -> 0.24504085 | H21: =IFERROR(Model!Y236+0,NA()) -> 0.25562561 | I21: =IFERROR(Model!Z236+0,NA()) -> 0.26126079 | J21: =IFERROR(Model!AA236+0,NA()) -> 0.264577 | K21: =IFERROR(Model!AB236+0,NA()) -> 0.26877206
