Workbook

Sheet Model
CF1: SCENARIO SWITCH ▼ (Bull / Base / Bear) — drives all scenario-linked forecast drivers
B2: Moody's Corporation (NYSE: MCO) — 3-Statement Financial Model | CF2: Base
B3: US GAAP as reported · USD millions (per-share data in USD; shares in millions) · Calendar fiscal year · Source: Moody's Forms 10-K / 10-Q, Form 8-K earnings releases (Ex. 99.1), SEC EDGAR (CIK 1059556); XBRL company facts; investor-relations releases (ir.moodys.com) are the same documents as filed on EDGAR
B4: Basis notes: as originally reported (10-K over the Q4 release for annual columns). Segments: MIS (ratings) and MA (analytics) since the Jan-2008 reorganisation (2006–07 revenue lines on the 2008 basis). MA lines on the current structure from 2021 (restated comparatives). Acquisitions: BvD Aug-17, Reis Oct-18, RDC Feb-20, RMS Sep-21; divestitures: MAKS Nov-19, Learning Solutions Q4-25, Regulatory Solutions Q2-26. Q3/Q4-26E calibrated to the FY26 guidance (22-Jul-2026). Share price $470.00 (user, 12-Oct-2026).
CH5: Forecast | CI5: Historical | CJ5: Historical | CK5: Historical
B6: (USDm) | C6: 2006 | D6: 2007 | E6: 2008 | F6: 2009 | G6: 2010 | H6: 2011 | I6: 2012 | J6: Q1/13 | K6: Q2/13 | L6: Q3/13 | M6: Q4/13 | N6: 2013 | O6: Q1/14 | P6: Q2/14 | Q6: Q3/14 | R6: Q4/14 | S6: 2014 | T6: Q1/15 | U6: Q2/15 | V6: Q3/15 | W6: Q4/15 | X6: 2015 | Y6: Q1/16 | Z6: Q2/16 | AA6: Q3/16 | AB6: Q4/16 | AC6: 2016 | AD6: Q1/17 | AE6: Q2/17 | AF6: Q3/17 | AG6: Q4/17 | AH6: 2017 | AI6: Q1/18 | AJ6: Q2/18 | AK6: Q3/18 | AL6: Q4/18 | AM6: 2018 | AN6: Q1/19 | AO6: Q2/19 | AP6: Q3/19 | AQ6: Q4/19 | AR6: 2019 | AS6: Q1/20 | AT6: Q2/20 | AU6: Q3/20 | AV6: Q4/20 | AW6: 2020 | AX6: Q1/21 | AY6: Q2/21 | AZ6: Q3/21 | BA6: Q4/21 | BB6: 2021 | BC6: Q1/22 | BD6: Q2/22 | BE6: Q3/22 | BF6: Q4/22 | BG6: 2022 | BH6: Q1/23 | BI6: Q2/23 | BJ6: Q3/23 | BK6: Q4/23 | BL6: 2023 | BM6: Q1/24 | BN6: Q2/24 | BO6: Q3/24 | BP6: Q4/24 | BQ6: 2024 | BR6: Q1/25 | BS6: Q2/25 | BT6: Q3/25 | BU6: Q4/25 | BV6: 2025 | BW6: Q1/26 | BX6: Q2/26 | BY6: Q3/26E | BZ6: Q4/26E | CA6: 2026E | CB6: 2027E | CC6: 2028E | CD6: 2029E | CE6: 2030E | CF6: Modelling Notes | CH6: 5Y CAGR | CI6: 5Y CAGR | CJ6: 10Y CAGR | CK6: 19Y CAGR
CH7: 25-'30 | CI7: 20-'25 | CJ7: 15-'25 | CK7: 06-'25
B8: SEGMENT P&L — MIS · MA (revenue by line of business × segment Adjusted Operating Margin) | CF8: SEGMENT BUILD — modelling logic (revenue by line → segment external revenue + intersegment revenue → × segment Adjusted Operating Margin = segment Adjusted Operating Income → Σ = Adjusted Operating Income (company measure) → GAAP P&L)
CN9: SCENARIO INPUT TABLE — driver assumptions per Bull / Base / Bear | CO9: Bull | CP9: Base | CQ9: Bear | CR9: Bull / Bear = Base + Δ (Δ inputs on each block header). Outlook block = high / mid / low of the FY26 guidance (22-Jul-2026).
B10: Moody's Investors Service (credit ratings; ratings revenue by line of business + MIS Other) | CF10: MIS — modelling logic
B11: Corporate Finance (CFG) | C11: 335.9 | D11: 411.5 | E11: 300.5 | F11: 408.2 | G11: 563.9 | H11: 652.1 | I11: 857.6 | J11: 258.3 | K11: 262.9 | L11: 233 | M11: 242.6 | N11: 996.8 | O11: 264.4 | P11: 320.9 | Q11: 260.7 | R11: 263.3 | S11: 1109.3 | T11: 298.7 | U11: 319.6 | V11: 248.3 | W11: 246.1 | X11: 1112.7 | Y11: 240.3 | Z11: 304.8 | AA11: 299.6 | AB11: 277.6 | AC11: 1122.3 | AD11: 352.8 | AE11: 355.8 | AF11: 350.2 | AG11: 333.9 | AH11: 1392.7 | AI11: 377.7 | AJ11: 377.6 | AK11: 296.1 | AL11: 282.7 | AM11: 1334.1 | AN11: 355.4 | AO11: 387.4 | AP11: 392 | AQ11: 362 | AR11: 1497 | AS11: 453 | AT11: 572 | AU11: 461 | AV11: 371 | AW11: 1857 | AX11: 605 | AY11: 550 | AZ11: 488 | BA11: 444 | BB11: 2087 | BC11: 417 | BD11: 322 | BE11: 277 | BF11: 253 | BG11: 1269 | BH11: 356 | BI11: 365 | BJ11: 346 | BK11: 337 | BL11: 1404 | BM11: 529 | BN11: 525 | BO11: 515 | BP11: 381 | BQ11: 1950 | BR11: 564 | BS11: 512 | BT11: 576 | BU11: 480 | BV11: 2132 | BW11: 633 | BX11: 651 | BY11: =BT11*(1+BY12) -> 591.97905 | BZ11: =BU11*(1+BZ12) -> 493.31588 | CA11: =SUM(BW11:BZ11) -> 2369.2949 | CB11: =CA11*(1+CB12) -> 2535.1456 | CC11: =CB11*(1+CC12) -> 2687.2543 | CD11: =CC11*(1+CD12) -> 2848.4896 | CE11: =CD11*(1+CE12) -> 2990.914 | CF11: External revenue by line as originally reported in each release. Q3/Q4-26E: prior-year quarter × (1 + growth). 2027E+: prior year × (1 + scenario lever). | CH11: =IFERROR((CE11/BV11)^(1/5)-1,"n/m") -> 0.070048214 | CI11: =IFERROR((BV11/AW11)^(1/5)-1,"n/m") -> 0.028004603 | CJ11: =IFERROR((BV11/X11)^(1/10)-1,"n/m") -> 0.067187946 | CK11: =IFERROR((BV11/C11)^(1/19)-1,"n/m") -> 0.10215051 | CN11: FY26 guidance — Q2-26 release (22-Jul-2026) | CO11: High | CP11: Mid | CQ11: Low | CR11: Revenue up high-single-digit %, adjusted operating margin 52–53%, adjusted diluted EPS $16.50–17.00 (raised from $16.40–17.00), diluted EPS $16.00–16.50, FCF $2.7–2.9bn, share repurchases up to $3.0bn, ETR 23–25%, net interest $220–240m; MIS revenue up high-single-digit % at ~65% margin; MA revenue up mid-single-digit % at 34–35%. Qualitative ranges are read as high-single-digit = 7–9% and mid-single-digit = 4–6% (model interpretation).
B12: y/y % | D12: =IF(AND(ISNUMBER(D11),ISNUMBER(C11)),IFERROR(D11/C11-1,""),"") -> 0.22506698 | E12: =IF(AND(ISNUMBER(E11),ISNUMBER(D11)),IFERROR(E11/D11-1,""),"") -> -0.26974484 | F12: =IF(AND(ISNUMBER(F11),ISNUMBER(E11)),IFERROR(F11/E11-1,""),"") -> 0.35840266 | G12: =IF(AND(ISNUMBER(G11),ISNUMBER(F11)),IFERROR(G11/F11-1,""),"") -> 0.38143067 | H12: =IF(AND(ISNUMBER(H11),ISNUMBER(G11)),IFERROR(H11/G11-1,""),"") -> 0.15641071 | I12: =IF(AND(ISNUMBER(I11),ISNUMBER(H11)),IFERROR(I11/H11-1,""),"") -> 0.31513572 | N12: =IF(AND(ISNUMBER(N11),ISNUMBER(I11)),IFERROR(N11/I11-1,""),"") -> 0.16231343 | O12: =IF(AND(ISNUMBER(O11),ISNUMBER(J11)),IFERROR(O11/J11-1,""),"") -> 0.02361595 | P12: =IF(AND(ISNUMBER(P11),ISNUMBER(K11)),IFERROR(P11/K11-1,""),"") -> 0.2206162 | Q12: =IF(AND(ISNUMBER(Q11),ISNUMBER(L11)),IFERROR(Q11/L11-1,""),"") -> 0.11888412 | R12: =IF(AND(ISNUMBER(R11),ISNUMBER(M11)),IFERROR(R11/M11-1,""),"") -> 0.085325639 | S12: =IF(AND(ISNUMBER(S11),ISNUMBER(N11)),IFERROR(S11/N11-1,""),"") -> 0.11286116 | T12: =IF(AND(ISNUMBER(T11),ISNUMBER(O11)),IFERROR(T11/O11-1,""),"") -> 0.12972769 | U12: =IF(AND(ISNUMBER(U11),ISNUMBER(P11)),IFERROR(U11/P11-1,""),"") -> -0.0040511063 | ... BX12: =IF(AND(ISNUMBER(BX11),ISNUMBER(BS11)),IFERROR(BX11/BS11-1,""),"") -> 0.27148438 | BY12: =BY13+$CA$120 -> 0.027741409 | BZ12: =BZ13+$CA$120 -> 0.027741409 | CA12: =IF(AND(ISNUMBER(CA11),ISNUMBER(BV11)),IFERROR(CA11/BV11-1,""),"") -> 0.11130156 | CB12: =CHOOSE(MATCH($CF$2,{"Bull","Base","Bear"},0),$CO$38,$CP$38,$CQ$38) -> 0.07 | CC12: =CHOOSE(MATCH($CF$2,{"Bull","Base","Bear"},0),$CO$39,$CP$39,$CQ$39) -> 0.06 | CD12: =CHOOSE(MATCH($CF$2,{"Bull","Base","Bear"},0),$CO$40,$CP$40,$CQ$40) -> 0.06 | CE12: =CHOOSE(MATCH($CF$2,{"Bull","Base","Bear"},0),$CO$41,$CP$41,$CQ$41) -> 0.05 | CF12: Q3/Q4-26E: 1H26 y/y growth of the line + MIS revenue-guidance calibration Δ (Group block). 2027E–2030E: scenario lever (table →). | CN12: FY26 MIS revenue growth | CO12: 0.09 | CP12: 0.08 | CQ12: 0.07 | CR12: Guided "increase in the high-single-digit percent range" (read as 7–9%). Drives the Q3/Q4-26E MIS revenue calibration.
B13: Q3/Q4-26E growth before calibration (1H26 y/y) | BY13: =IFERROR(SUM(BW11:BX11)/SUM(BR11:BS11)-1,0) -> 0.19330855 | BZ13: =IFERROR(SUM(BW11:BX11)/SUM(BR11:BS11)-1,0) -> 0.19330855 | CN13: FY26 MA revenue growth | CO13: 0.06 | CP13: 0.05 | CQ13: 0.04 | CR13: Guided "increase in the mid-single-digit percent range" (read as 4–6%; incl. ~4 pts inorganic drag from the Learning and Regulatory Solutions divestitures and ~(0.5) pts FX). Drives the MA calibration.
B14: Structured Finance (SFG) | C14: 872.6 | D14: 873.3 | E14: 411.2 | F14: 304.9 | G14: 290.8 | H14: 344.6 | I14: 381 | J14: 93 | K14: 97.2 | L14: 83.5 | M14: 108.8 | N14: 382.5 | O14: 95.3 | P14: 110.6 | Q14: 102.1 | R14: 118.5 | S14: 426.5 | T14: 101.3 | U14: 121.2 | V14: 112.5 | W14: 114.1 | X14: 449.1 | Y14: 90.6 | Z14: 111.5 | AA14: 104.2 | AB14: 130.5 | AC14: 436.8 | AD14: 100.2 | AE14: 119.2 | AF14: 128.3 | AG14: 147.8 | AH14: 495.5 | AI14: 129.7 | AJ14: 141.6 | AK14: 125.4 | AL14: 129.8 | AM14: 526.5 | AN14: 100.7 | AO14: 112.1 | AP14: 105.4 | AQ14: 109 | AR14: 427 | AS14: 96 | AT14: 81 | AU14: 88 | AV14: 97 | AW14: 362 | AX14: 116 | AY14: 140 | AZ14: 143 | BA14: 161 | BB14: 560 | BC14: 144 | BD14: 123 | BE14: 101 | BF14: 94 | BG14: 462 | BH14: 99 | BI14: 102 | BJ14: 102 | BK14: 102 | BL14: 405 | BM14: 114 | BN14: 131 | BO14: 135 | BP14: 138 | BQ14: 518 | BR14: 138 | BS14: 135 | BT14: 146 | BU14: 139 | BV14: 558 | BW14: 137 | BX14: 151 | BY14: =BT14*(1+BY15) -> 129.84918 | BZ14: =BU14*(1+BZ15) -> 123.62353 | CA14: =SUM(BW14:BZ14) -> 541.47271 | CB14: =CA14*(1+CB15) -> 568.54634 | CC14: =CB14*(1+CC15) -> 591.28819 | CD14: =CC14*(1+CD15) -> 614.93972 | CE14: =CD14*(1+CE15) -> 639.53731 | CH14: =IFERROR((CE14/BV14)^(1/5)-1,"n/m") -> 0.027652629 | CI14: =IFERROR((BV14/AW14)^(1/5)-1,"n/m") -> 0.090398199 | CJ14: =IFERROR((BV14/X14)^(1/10)-1,"n/m") -> 0.021948744 | CK14: =IFERROR((BV14/C14)^(1/19)-1,"n/m") -> -0.023257811 | CN14: FY26 adjusted diluted EPS ($) | CO14: 17 | CP14: 16.75 | CQ14: 16.5 | CR14: Guided $16.50–17.00. Drives the Q3/Q4-26E segment-margin calibration.
B15: y/y % | D15: =IF(AND(ISNUMBER(D14),ISNUMBER(C14)),IFERROR(D14/C14-1,""),"") -> 0.00080220032 | E15: =IF(AND(ISNUMBER(E14),ISNUMBER(D14)),IFERROR(E14/D14-1,""),"") -> -0.52914233 | F15: =IF(AND(ISNUMBER(F14),ISNUMBER(E14)),IFERROR(F14/E14-1,""),"") -> -0.25851167 | G15: =IF(AND(ISNUMBER(G14),ISNUMBER(F14)),IFERROR(G14/F14-1,""),"") -> -0.04624467 | H15: =IF(AND(ISNUMBER(H14),ISNUMBER(G14)),IFERROR(H14/G14-1,""),"") -> 0.18500688 | I15: =IF(AND(ISNUMBER(I14),ISNUMBER(H14)),IFERROR(I14/H14-1,""),"") -> 0.10562972 | N15: =IF(AND(ISNUMBER(N14),ISNUMBER(I14)),IFERROR(N14/I14-1,""),"") -> 0.0039370079 | O15: =IF(AND(ISNUMBER(O14),ISNUMBER(J14)),IFERROR(O14/J14-1,""),"") -> 0.024731183 | P15: =IF(AND(ISNUMBER(P14),ISNUMBER(K14)),IFERROR(P14/K14-1,""),"") -> 0.13786008 | Q15: =IF(AND(ISNUMBER(Q14),ISNUMBER(L14)),IFERROR(Q14/L14-1,""),"") -> 0.22275449 | R15: =IF(AND(ISNUMBER(R14),ISNUMBER(M14)),IFERROR(R14/M14-1,""),"") -> 0.089154412 | S15: =IF(AND(ISNUMBER(S14),ISNUMBER(N14)),IFERROR(S14/N14-1,""),"") -> 0.11503268 | T15: =IF(AND(ISNUMBER(T14),ISNUMBER(O14)),IFERROR(T14/O14-1,""),"") -> 0.062959077 | U15: =IF(AND(ISNUMBER(U14),ISNUMBER(P14)),IFERROR(U14/P14-1,""),"") -> 0.095840868 | ... BX15: =IF(AND(ISNUMBER(BX14),ISNUMBER(BS14)),IFERROR(BX14/BS14-1,""),"") -> 0.11851852 | BY15: =BY16+$CA$120 -> -0.11062209 | BZ15: =BZ16+$CA$120 -> -0.11062209 | CA15: =IF(AND(ISNUMBER(CA14),ISNUMBER(BV14)),IFERROR(CA14/BV14-1,""),"") -> -0.029618807 | CB15: =CHOOSE(MATCH($CF$2,{"Bull","Base","Bear"},0),$CO$43,$CP$43,$CQ$43) -> 0.05 | CC15: =CHOOSE(MATCH($CF$2,{"Bull","Base","Bear"},0),$CO$44,$CP$44,$CQ$44) -> 0.04 | CD15: =CHOOSE(MATCH($CF$2,{"Bull","Base","Bear"},0),$CO$45,$CP$45,$CQ$45) -> 0.04 | CE15: =CHOOSE(MATCH($CF$2,{"Bull","Base","Bear"},0),$CO$46,$CP$46,$CQ$46) -> 0.04 | CN15: FY26 MCO revenue growth — memo | CO15: 0.09 | CP15: 0.08 | CQ15: 0.07 | CR15: Guided "high-single-digit" (information row; the model total follows the segment end-points).
B16: Q3/Q4-26E growth before calibration (1H26 y/y) | BY16: =IFERROR(SUM(BW14:BX14)/SUM(BR14:BS14)-1,0) -> 0.054945055 | BZ16: =IFERROR(SUM(BW14:BX14)/SUM(BR14:BS14)-1,0) -> 0.054945055 | CN16: FY26 Adjusted Operating Margin — memo | CO16: 0.53 | CP16: 0.525 | CQ16: 0.52 | CR16: Guided 52–53% (information row).
B17: Financial Institutions (FIG) | C17: 233.1 | D17: 274.3 | E17: 263 | F17: 258.5 | G17: 278.7 | H17: 294.9 | I17: 325.5 | J17: 86.5 | K17: 84.5 | L17: 78.9 | M17: 88.9 | N17: 338.8 | O17: 85.4 | P17: 92.2 | Q17: 91.8 | R17: 85.3 | S17: 354.7 | T17: 93.8 | U17: 90.4 | V17: 89.5 | W17: 91.9 | X17: 365.6 | Y17: 94.9 | Z17: 89.7 | AA17: 95.8 | AB17: 88.5 | AC17: 368.9 | AD17: 112.3 | AE17: 102.4 | AF17: 102.1 | AG17: 119 | AH17: 435.8 | AI17: 114.3 | AJ17: 120.6 | AK17: 119.5 | AL17: 87.3 | AM17: 441.7 | AN17: 115.8 | AO17: 125.2 | AP17: 120.5 | AQ17: 115 | AR17: 476 | AS17: 125 | AT17: 142 | AU17: 134 | AV17: 129 | AW17: 530 | AX17: 162 | AY17: 150 | AZ17: 153 | BA17: 137 | BB17: 602 | BC17: 131 | BD17: 128 | BE17: 109 | BF17: 123 | BG17: 491 | BH17: 142 | BI17: 145 | BJ17: 126 | BK17: 132 | BL17: 545 | BM17: 195 | BN17: 195 | BO17: 170 | BP17: 167 | BQ17: 727 | BR17: 191 | BS17: 191 | BT17: 208 | BU17: 169 | BV17: 759 | BW17: 194 | BX17: 222 | BY17: =BT17*(1+BY18) -> 192.07512 | BZ17: =BU17*(1+BZ18) -> 156.06104 | CA17: =SUM(BW17:BZ17) -> 764.13616 | CB17: =CA17*(1+CB18) -> 809.98433 | CC17: =CB17*(1+CC18) -> 850.48355 | CD17: =CC17*(1+CD18) -> 893.00773 | CE17: =CD17*(1+CE18) -> 937.65811 | CH17: =IFERROR((CE17/BV17)^(1/5)-1,"n/m") -> 0.043183112 | CI17: =IFERROR((BV17/AW17)^(1/5)-1,"n/m") -> 0.074467247 | CJ17: =IFERROR((BV17/X17)^(1/10)-1,"n/m") -> 0.07578023 | CK17: =IFERROR((BV17/C17)^(1/19)-1,"n/m") -> 0.064104266 | CN17: FY26 MIS Adjusted Operating Margin — memo | CO17: 0.65 | CP17: 0.65 | CQ17: 0.65 | CR17: Guided ~65% (information row).
B18: y/y % | D18: =IF(AND(ISNUMBER(D17),ISNUMBER(C17)),IFERROR(D17/C17-1,""),"") -> 0.17674818 | E18: =IF(AND(ISNUMBER(E17),ISNUMBER(D17)),IFERROR(E17/D17-1,""),"") -> -0.041195771 | F18: =IF(AND(ISNUMBER(F17),ISNUMBER(E17)),IFERROR(F17/E17-1,""),"") -> -0.017110266 | G18: =IF(AND(ISNUMBER(G17),ISNUMBER(F17)),IFERROR(G17/F17-1,""),"") -> 0.078143133 | H18: =IF(AND(ISNUMBER(H17),ISNUMBER(G17)),IFERROR(H17/G17-1,""),"") -> 0.058127018 | I18: =IF(AND(ISNUMBER(I17),ISNUMBER(H17)),IFERROR(I17/H17-1,""),"") -> 0.10376399 | N18: =IF(AND(ISNUMBER(N17),ISNUMBER(I17)),IFERROR(N17/I17-1,""),"") -> 0.040860215 | O18: =IF(AND(ISNUMBER(O17),ISNUMBER(J17)),IFERROR(O17/J17-1,""),"") -> -0.012716763 | P18: =IF(AND(ISNUMBER(P17),ISNUMBER(K17)),IFERROR(P17/K17-1,""),"") -> 0.09112426 | Q18: =IF(AND(ISNUMBER(Q17),ISNUMBER(L17)),IFERROR(Q17/L17-1,""),"") -> 0.1634981 | R18: =IF(AND(ISNUMBER(R17),ISNUMBER(M17)),IFERROR(R17/M17-1,""),"") -> -0.040494938 | S18: =IF(AND(ISNUMBER(S17),ISNUMBER(N17)),IFERROR(S17/N17-1,""),"") -> 0.046930342 | T18: =IF(AND(ISNUMBER(T17),ISNUMBER(O17)),IFERROR(T17/O17-1,""),"") -> 0.098360656 | U18: =IF(AND(ISNUMBER(U17),ISNUMBER(P17)),IFERROR(U17/P17-1,""),"") -> -0.019522777 | ... BX18: =IF(AND(ISNUMBER(BX17),ISNUMBER(BS17)),IFERROR(BX17/BS17-1,""),"") -> 0.16230366 | BY18: =BY19+$CA$120 -> -0.076561906 | BZ18: =BZ19+$CA$120 -> -0.076561906 | CA18: =IF(AND(ISNUMBER(CA17),ISNUMBER(BV17)),IFERROR(CA17/BV17-1,""),"") -> 0.0067670113 | CB18: =CHOOSE(MATCH($CF$2,{"Bull","Base","Bear"},0),$CO$48,$CP$48,$CQ$48) -> 0.06 | CC18: =CHOOSE(MATCH($CF$2,{"Bull","Base","Bear"},0),$CO$49,$CP$49,$CQ$49) -> 0.05 | CD18: =CHOOSE(MATCH($CF$2,{"Bull","Base","Bear"},0),$CO$50,$CP$50,$CQ$50) -> 0.05 | CE18: =CHOOSE(MATCH($CF$2,{"Bull","Base","Bear"},0),$CO$51,$CP$51,$CQ$51) -> 0.05 | CN18: FY26 MA Adjusted Operating Margin — memo | CO18: 0.35 | CP18: 0.345 | CQ18: 0.34 | CR18: Guided 34–35% (information row).
B19: Q3/Q4-26E growth before calibration (1H26 y/y) | BY19: =IFERROR(SUM(BW17:BX17)/SUM(BR17:BS17)-1,0) -> 0.089005236 | BZ19: =IFERROR(SUM(BW17:BX17)/SUM(BR17:BS17)-1,0) -> 0.089005236 | CN19: FY26 diluted EPS ($) — memo | CO19: 16.5 | CP19: 16.25 | CQ19: 16 | CR19: Guided $16.00–16.50 (information row).
B20: Public, Project & Infrastructure Finance (PPIF) | C20: 198.2 | D20: 220.8 | E20: 230 | F20: 246.1 | G20: 271.6 | H20: 277.3 | I20: 322.7 | J20: 83.4 | K20: 92.7 | L20: 82.7 | M20: 82.5 | N20: 341.3 | O20: 80.7 | P20: 98 | Q20: 88.5 | R20: 90.1 | S20: 357.3 | T20: 100.7 | U20: 99.9 | V20: 90.6 | W20: 85.2 | X20: 376.4 | Y20: 91.5 | Z20: 112.3 | AA20: 105.2 | AB20: 103.2 | AC20: 412.2 | AD20: 98.1 | AE20: 104.7 | AF20: 109.2 | AG20: 119.3 | AH20: 431.3 | AI20: 93.2 | AJ20: 108.1 | AK20: 99 | AL20: 90.8 | AM20: 391.1 | AN20: 92.7 | AO20: 108.6 | AP20: 119.8 | AQ20: 125 | AR20: 446 | AS20: 109 | AT20: 133 | AU20: 133 | AV20: 121 | AW20: 496 | AX20: 143 | AY20: 130 | AZ20: 130 | BA20: 118 | BB20: 521 | BC20: 123 | BD20: 122 | BE20: 92 | BF20: 94 | BG20: 431 | BH20: 129 | BI20: 127 | BJ20: 115 | BK20: 105 | BL20: 476 | BM20: 141 | BN20: 154 | BO20: 154 | BP20: 115 | BQ20: 564 | BR20: 163 | BS20: 162 | BT20: 161 | BU20: 149 | BV20: 635 | BW20: 176 | BX20: 224 | BY20: =BT20*(1+BY21) -> 171.49754 | BZ20: =BU20*(1+BZ21) -> 158.71511 | CA20: =SUM(BW20:BZ20) -> 730.21265 | CB20: =CA20*(1+CB21) -> 774.02541 | CC20: =CB20*(1+CC21) -> 820.46693 | CD20: =CC20*(1+CD21) -> 861.49028 | CE20: =CD20*(1+CE21) -> 904.56479 | CH20: =IFERROR((CE20/BV20)^(1/5)-1,"n/m") -> 0.073329809 | CI20: =IFERROR((BV20/AW20)^(1/5)-1,"n/m") -> 0.050650834 | CJ20: =IFERROR((BV20/X20)^(1/10)-1,"n/m") -> 0.053688915 | CK20: =IFERROR((BV20/C20)^(1/19)-1,"n/m") -> 0.063198155 | CN20: FY26 Free Cash Flow ($m) — memo | CO20: 2900 | CP20: 2800 | CQ20: 2700 | CR20: Guided $2.7–2.9bn (operating cash flow $3.15–3.35bn less capex ~$450m) (information row).
B21: y/y % | D21: =IF(AND(ISNUMBER(D20),ISNUMBER(C20)),IFERROR(D20/C20-1,""),"") -> 0.11402624 | E21: =IF(AND(ISNUMBER(E20),ISNUMBER(D20)),IFERROR(E20/D20-1,""),"") -> 0.041666667 | F21: =IF(AND(ISNUMBER(F20),ISNUMBER(E20)),IFERROR(F20/E20-1,""),"") -> 0.07 | G21: =IF(AND(ISNUMBER(G20),ISNUMBER(F20)),IFERROR(G20/F20-1,""),"") -> 0.10361642 | H21: =IF(AND(ISNUMBER(H20),ISNUMBER(G20)),IFERROR(H20/G20-1,""),"") -> 0.020986745 | I21: =IF(AND(ISNUMBER(I20),ISNUMBER(H20)),IFERROR(I20/H20-1,""),"") -> 0.1637216 | N21: =IF(AND(ISNUMBER(N20),ISNUMBER(I20)),IFERROR(N20/I20-1,""),"") -> 0.057638674 | O21: =IF(AND(ISNUMBER(O20),ISNUMBER(J20)),IFERROR(O20/J20-1,""),"") -> -0.032374101 | P21: =IF(AND(ISNUMBER(P20),ISNUMBER(K20)),IFERROR(P20/K20-1,""),"") -> 0.057173679 | Q21: =IF(AND(ISNUMBER(Q20),ISNUMBER(L20)),IFERROR(Q20/L20-1,""),"") -> 0.070133011 | R21: =IF(AND(ISNUMBER(R20),ISNUMBER(M20)),IFERROR(R20/M20-1,""),"") -> 0.092121212 | S21: =IF(AND(ISNUMBER(S20),ISNUMBER(N20)),IFERROR(S20/N20-1,""),"") -> 0.046879578 | T21: =IF(AND(ISNUMBER(T20),ISNUMBER(O20)),IFERROR(T20/O20-1,""),"") -> 0.24783147 | U21: =IF(AND(ISNUMBER(U20),ISNUMBER(P20)),IFERROR(U20/P20-1,""),"") -> 0.019387755 | ... BX21: =IF(AND(ISNUMBER(BX20),ISNUMBER(BS20)),IFERROR(BX20/BS20-1,""),"") -> 0.38271605 | BY21: =BY22+$CA$120 -> 0.06520209 | BZ21: =BZ22+$CA$120 -> 0.06520209 | CA21: =IF(AND(ISNUMBER(CA20),ISNUMBER(BV20)),IFERROR(CA20/BV20-1,""),"") -> 0.14994118 | CB21: =CHOOSE(MATCH($CF$2,{"Bull","Base","Bear"},0),$CO$53,$CP$53,$CQ$53) -> 0.06 | CC21: =CHOOSE(MATCH($CF$2,{"Bull","Base","Bear"},0),$CO$54,$CP$54,$CQ$54) -> 0.06 | CD21: =CHOOSE(MATCH($CF$2,{"Bull","Base","Bear"},0),$CO$55,$CP$55,$CQ$55) -> 0.05 | CE21: =CHOOSE(MATCH($CF$2,{"Bull","Base","Bear"},0),$CO$56,$CP$56,$CQ$56) -> 0.05 | CN21: 2H26E share repurchases ($m) | CO21: 835 | CP21: 685 | CQ21: 535 | CR21: 1H26 $2,165m (treasury shares); FY26 guidance "up to $3.0bn" → 2H up to $835m (high), $2.85bn FY (mid), $2.7bn FY (low). $1.8bn authorization remaining at 30-Jun-2026.
B22: Q3/Q4-26E growth before calibration (1H26 y/y) | BY22: =IFERROR(SUM(BW20:BX20)/SUM(BR20:BS20)-1,0) -> 0.23076923 | BZ22: =IFERROR(SUM(BW20:BX20)/SUM(BR20:BS20)-1,0) -> 0.23076923
B23: MIS Other (ICRA non-ratings, data / research) | R23: 7.9 | S23: 18 | T23: 7.8 | U23: 8.1 | V23: 7.2 | W23: 7.3 | X23: 30.4 | Y23: 7.8 | Z23: 7.3 | AA23: 7.5 | AB23: 8 | AC23: 30.6 | AD23: 4.8 | AE23: 4.6 | AF23: 4.4 | AG23: 4.7 | AH23: 18.5 | AI23: 5 | AJ23: 4.4 | AK23: 4.8 | AL23: 4.8 | AM23: 19 | AN23: 5.5 | AO23: 5.1 | AP23: 8.9 | AQ23: 9 | AR23: 29 | AS23: 11 | AT23: 10 | AU23: 9 | AV23: 17 | AW23: 47 | AX23: 10 | AY23: 10 | AZ23: 11 | BA23: 11 | BB23: 42 | BC23: 12 | BD23: 11 | BE23: 11 | BF23: 12 | BG23: 46 | BH23: 7 | BI23: 8 | BJ23: 7 | BK23: 8 | BL23: 30 | BM23: 8 | BN23: 10 | BO23: 8 | BP23: 8 | BQ23: 34 | BR23: 9 | BS23: 10 | BT23: 7 | BU23: 9 | BV23: 35 | BW23: 13 | BX23: 12 | BY23: =BT23*(1+BY24) -> 8.0515563 | BZ23: =BU23*(1+BZ24) -> 10.352001 | CA23: =SUM(BW23:BZ23) -> 43.403557 | CB23: =CA23*(1+CB24) -> 46.007771 | CC23: =CB23*(1+CC24) -> 48.308159 | CD23: =CC23*(1+CD24) -> 50.723567 | CE23: =CD23*(1+CE24) -> 53.259746 | CN23: Q3/26E–Q4/26E and FY26 point estimates (all cases)
B24: y/y % | D24: =IF(AND(ISNUMBER(D23),ISNUMBER(C23)),IFERROR(D23/C23-1,""),"") | E24: =IF(AND(ISNUMBER(E23),ISNUMBER(D23)),IFERROR(E23/D23-1,""),"") | F24: =IF(AND(ISNUMBER(F23),ISNUMBER(E23)),IFERROR(F23/E23-1,""),"") | G24: =IF(AND(ISNUMBER(G23),ISNUMBER(F23)),IFERROR(G23/F23-1,""),"") | H24: =IF(AND(ISNUMBER(H23),ISNUMBER(G23)),IFERROR(H23/G23-1,""),"") | I24: =IF(AND(ISNUMBER(I23),ISNUMBER(H23)),IFERROR(I23/H23-1,""),"") | N24: =IF(AND(ISNUMBER(N23),ISNUMBER(I23)),IFERROR(N23/I23-1,""),"") | O24: =IF(AND(ISNUMBER(O23),ISNUMBER(J23)),IFERROR(O23/J23-1,""),"") | P24: =IF(AND(ISNUMBER(P23),ISNUMBER(K23)),IFERROR(P23/K23-1,""),"") | Q24: =IF(AND(ISNUMBER(Q23),ISNUMBER(L23)),IFERROR(Q23/L23-1,""),"") | R24: =IF(AND(ISNUMBER(R23),ISNUMBER(M23)),IFERROR(R23/M23-1,""),"") | S24: =IF(AND(ISNUMBER(S23),ISNUMBER(N23)),IFERROR(S23/N23-1,""),"") | T24: =IF(AND(ISNUMBER(T23),ISNUMBER(O23)),IFERROR(T23/O23-1,""),"") | U24: =IF(AND(ISNUMBER(U23),ISNUMBER(P23)),IFERROR(U23/P23-1,""),"") | ... BX24: =IF(AND(ISNUMBER(BX23),ISNUMBER(BS23)),IFERROR(BX23/BS23-1,""),"") -> 0.2 | BY24: =BY25+$CA$120 -> 0.15022233 | BZ24: =BZ25+$CA$120 -> 0.15022233 | CA24: =IF(AND(ISNUMBER(CA23),ISNUMBER(BV23)),IFERROR(CA23/BV23-1,""),"") -> 0.24010164 | CB24: =CHOOSE(MATCH($CF$2,{"Bull","Base","Bear"},0),$CO$58,$CP$58,$CQ$58) -> 0.06 | CC24: =CHOOSE(MATCH($CF$2,{"Bull","Base","Bear"},0),$CO$59,$CP$59,$CQ$59) -> 0.05 | CD24: =CHOOSE(MATCH($CF$2,{"Bull","Base","Bear"},0),$CO$60,$CP$60,$CQ$60) -> 0.05 | CE24: =CHOOSE(MATCH($CF$2,{"Bull","Base","Bear"},0),$CO$61,$CP$61,$CQ$61) -> 0.05 | CN24: Q3/Q4-26E interest expense, net (per quarter, $m; expense −) | CP24: -53 | CR24: FY26 guidance $220–240m (mid $230m) − 1H26 $124m = $106m for 2H.
B25: Q3/Q4-26E growth before calibration (1H26 y/y) | BY25: =IFERROR(SUM(BW23:BX23)/SUM(BR23:BS23)-1,0) -> 0.31578947 | BZ25: =IFERROR(SUM(BW23:BX23)/SUM(BR23:BS23)-1,0) -> 0.31578947 | CN25: Q3/Q4-26E other non-operating income, net (per quarter, $m) | CP25: 0 | CR25: Guided non-operating income $70–90m incl. interest and divestiture gains → other non-operating ≈ nil in 2H (1H26 +$16m).
B26: MIS revenue not split on the current lines (history before the current line structure; derived) | C26: =IF(ISNUMBER(C30),C30-(N(C11)+N(C14)+N(C17)+N(C20)+N(C23)),"") -> 0 | D26: =IF(ISNUMBER(D30),D30-(N(D11)+N(D14)+N(D17)+N(D20)+N(D23)),"") -> 0 | E26: =IF(ISNUMBER(E30),E30-(N(E11)+N(E14)+N(E17)+N(E20)+N(E23)),"") -> 0 | F26: =IF(ISNUMBER(F30),F30-(N(F11)+N(F14)+N(F17)+N(F20)+N(F23)),"") -> 0 | G26: =IF(ISNUMBER(G30),G30-(N(G11)+N(G14)+N(G17)+N(G20)+N(G23)),"") -> 0 | H26: =IF(ISNUMBER(H30),H30-(N(H11)+N(H14)+N(H17)+N(H20)+N(H23)),"") -> 0 | I26: =IF(ISNUMBER(I30),I30-(N(I11)+N(I14)+N(I17)+N(I20)+N(I23)),"") -> 0 | J26: =IF(ISNUMBER(J30),J30-(N(J11)+N(J14)+N(J17)+N(J20)+N(J23)),"") -> 0 | ... BX26: =IF(ISNUMBER(BX30),BX30-(N(BX11)+N(BX14)+N(BX17)+N(BX20)+N(BX23)),"") -> 0 | BY26: =0 -> 0 | BZ26: =0 -> 0 | CA26: =SUM(BW26:BZ26) -> 0 | CB26: =0 -> 0 | CC26: =0 -> 0 | CD26: =0 -> 0 | CE26: =0 -> 0 | CF26: Consolidated segment revenue less the current lines: carries the periods before each line was first published (MIS Other from 2013; MA lines on the 2022 / 2024 bases; legacy MA lines are memo rows below). | CN26: Q4/26E contingent gain on the Regulatory Solutions divestiture ($m) | CP26: 119 | CR26: Up to $119m of contingent consideration payable on post-closing conditions in 2H26 (Q2-26 10-Q); the FY26 EPS bridge gain of ~$(1.25) less the Q2 $(0.72) implies ~$0.53 net ≈ $119m pre-tax. Timing assumed Q4.
B27: MIS — external revenue | C27: =IF(ISNUMBER(C30),N(C11)+N(C14)+N(C17)+N(C20)+N(C23)+C26,"") -> 1639.8 | D27: =IF(ISNUMBER(D30),N(D11)+N(D14)+N(D17)+N(D20)+N(D23)+D26,"") -> 1779.9 | E27: =IF(ISNUMBER(E30),N(E11)+N(E14)+N(E17)+N(E20)+N(E23)+E26,"") -> 1204.7 | F27: =IF(ISNUMBER(F30),N(F11)+N(F14)+N(F17)+N(F20)+N(F23)+F26,"") -> 1217.7 | G27: =IF(ISNUMBER(G30),N(G11)+N(G14)+N(G17)+N(G20)+N(G23)+G26,"") -> 1405 | H27: =IF(ISNUMBER(H30),N(H11)+N(H14)+N(H17)+N(H20)+N(H23)+H26,"") -> 1568.9 | I27: =IF(ISNUMBER(I30),N(I11)+N(I14)+N(I17)+N(I20)+N(I23)+I26,"") -> 1886.8 | J27: =IF(ISNUMBER(J30),N(J11)+N(J14)+N(J17)+N(J20)+N(J23)+J26,"") -> 521.2 | ... BX27: =IF(ISNUMBER(BX30),N(BX11)+N(BX14)+N(BX17)+N(BX20)+N(BX23)+BX26,"") -> 1260 | BY27: =BY11+BY14+BY17+BY20+BY23 -> 1093.4524 | BZ27: =BZ11+BZ14+BZ17+BZ20+BZ23 -> 942.06756 | CA27: =SUM(BW27:BZ27) -> 4448.52 | CB27: =CB11+CB14+CB17+CB20+CB23 -> 4733.7094 | CC27: =CC11+CC14+CC17+CC20+CC23 -> 4997.8011 | CD27: =CD11+CD14+CD17+CD20+CD23 -> 5268.6509 | CE27: =CE11+CE14+CE17+CE20+CE23 -> 5525.934 | CF27: Σ lines (+ not-split residual in history) = segment external revenue as reported. | CH27: =IFERROR((CE27/BV27)^(1/5)-1,"n/m") -> 0.060529566 | CI27: =IFERROR((BV27/AW27)^(1/5)-1,"n/m") -> 0.045842757 | CJ27: =IFERROR((BV27/X27)^(1/10)-1,"n/m") -> 0.058437876 | CK27: =IFERROR((BV27/C27)^(1/19)-1,"n/m") -> 0.049669745 | CN27: Q3/Q4-26E acquired-intangible amortization (per quarter, $m) | CP27: 50.5 | CR27: FY2025 10-K schedule 2026 $207m − 1H26 $106m, split evenly.
B28: Segment revenue y/y % | D28: =IF(AND(ISNUMBER(D27),ISNUMBER(C27)),IFERROR(D27/C27-1,""),"") -> 0.085437248 | E28: =IF(AND(ISNUMBER(E27),ISNUMBER(D27)),IFERROR(E27/D27-1,""),"") -> -0.32316422 | F28: =IF(AND(ISNUMBER(F27),ISNUMBER(E27)),IFERROR(F27/E27-1,""),"") -> 0.010791068 | G28: =IF(AND(ISNUMBER(G27),ISNUMBER(F27)),IFERROR(G27/F27-1,""),"") -> 0.15381457 | H28: =IF(AND(ISNUMBER(H27),ISNUMBER(G27)),IFERROR(H27/G27-1,""),"") -> 0.1166548 | I28: =IF(AND(ISNUMBER(I27),ISNUMBER(H27)),IFERROR(I27/H27-1,""),"") -> 0.20262604 | N28: =IF(AND(ISNUMBER(N27),ISNUMBER(I27)),IFERROR(N27/I27-1,""),"") -> 0.091477634 | O28: =IF(AND(ISNUMBER(O27),ISNUMBER(J27)),IFERROR(O27/J27-1,""),"") -> 0.0088257866 | P28: =IF(AND(ISNUMBER(P27),ISNUMBER(K27)),IFERROR(P27/K27-1,""),"") -> 0.1570817 | Q28: =IF(AND(ISNUMBER(Q27),ISNUMBER(L27)),IFERROR(Q27/L27-1,""),"") -> 0.13595482 | R28: =IF(AND(ISNUMBER(R27),ISNUMBER(M27)),IFERROR(R27/M27-1,""),"") -> 0.080910482 | S28: =IF(AND(ISNUMBER(S27),ISNUMBER(N27)),IFERROR(S27/N27-1,""),"") -> 0.10022337 | T28: =IF(AND(ISNUMBER(T27),ISNUMBER(O27)),IFERROR(T27/O27-1,""),"") -> 0.14549258 | U28: =IF(AND(ISNUMBER(U27),ISNUMBER(P27)),IFERROR(U27/P27-1,""),"") -> 0.028148625 | ... CA28: =IF(AND(ISNUMBER(CA27),ISNUMBER(BV27)),IFERROR(CA27/BV27-1,""),"") -> 0.08 | CB28: =IF(AND(ISNUMBER(CB27),ISNUMBER(CA27)),IFERROR(CB27/CA27-1,""),"") -> 0.064108832 | CC28: =IF(AND(ISNUMBER(CC27),ISNUMBER(CB27)),IFERROR(CC27/CB27-1,""),"") -> 0.055789592 | CD28: =IF(AND(ISNUMBER(CD27),ISNUMBER(CC27)),IFERROR(CD27/CC27-1,""),"") -> 0.054193777 | CE28: =IF(AND(ISNUMBER(CE27),ISNUMBER(CD27)),IFERROR(CE27/CD27-1,""),"") -> 0.048832833 | CN28: Q3/Q4-26E other depreciation & amortization (per quarter, $m) | CP28: 68 | CR28: D&A guided ~6% of revenue; 1H26 other D&A $142m ($71m/qtr) → $68m/qtr with amortization ≈ 6.1% of FY revenue.
B29: % of total revenue | C29: =IF(AND(ISNUMBER(C27),ISNUMBER(C110)),IFERROR(C27/C110,""),"") -> 0.80496785 | D29: =IF(AND(ISNUMBER(D27),ISNUMBER(D110)),IFERROR(D27/D110,""),"") -> 0.78791501 | E29: =IF(AND(ISNUMBER(E27),ISNUMBER(E110)),IFERROR(E27/E110,""),"") -> 0.68628233 | F29: =IF(AND(ISNUMBER(F27),ISNUMBER(F110)),IFERROR(F27/F110,""),"") -> 0.67755397 | G29: =IF(AND(ISNUMBER(G27),ISNUMBER(G110)),IFERROR(G27/G110,""),"") -> 0.69143701 | H29: =IF(AND(ISNUMBER(H27),ISNUMBER(H110)),IFERROR(H27/H110,""),"") -> 0.68790284 | I29: =IF(AND(ISNUMBER(I27),ISNUMBER(I110)),IFERROR(I27/I110,""),"") -> 0.69105959 | J29: =IF(AND(ISNUMBER(J27),ISNUMBER(J110)),IFERROR(J27/J110,""),"") -> 0.71221645 | ... CE29: =IF(AND(ISNUMBER(CE27),ISNUMBER(CE110)),IFERROR(CE27/CE110,""),"") -> 0.51985742 | CH29: =IFERROR(AVERAGE(CA29,CB29,CC29,CD29,CE29),"n/m") -> 0.53065065 | CI29: =IFERROR(AVERAGE(BB29,BG29,BL29,BQ29,BV29),"n/m") -> 0.531782 | CJ29: =IFERROR(AVERAGE(AC29,AH29,AM29,AR29,AW29,BB29,BG29,BL29,BQ29,BV29),"n/m") -> 0.57952949 | CK29: =IFERROR(AVERAGE(C29,D29,E29,F29,G29,H29,I29,N29,S29,X29,AC29,AH29,AM29,AR29,AW29,BB29,BG29,BL29,BQ29,BV29),"n/m") -> 0.64323274 | CN29: Q3/Q4-26E restructuring (per quarter, $m) | CP29: 30 | CR29: Guided ~1.5% of revenue (≈ $118m) − 1H26 $59m ≈ $59m for 2H (programme expanded Jul-2026 to $300–350m total).
B30: Memo: MIS external revenue as reported | C30: 1639.8 | D30: 1779.9 | E30: 1204.7 | F30: 1217.7 | G30: 1405 | H30: 1568.9 | I30: 1886.8 | J30: 521.2 | K30: 537.3 | L30: 478.1 | M30: 522.8 | N30: 2059.4 | O30: 525.8 | P30: 621.7 | Q30: 543.1 | R30: 565.1 | S30: 2265.8 | T30: 602.3 | U30: 639.2 | V30: 548.1 | W30: 544.6 | X30: 2334.2 | Y30: 525.1 | Z30: 625.6 | AA30: 612.3 | AB30: 607.8 | AC30: 2370.8 | AD30: 668.2 | AE30: 686.7 | AF30: 694.2 | AG30: 724.7 | AH30: 2773.8 | AI30: 719.9 | AJ30: 752.3 | AK30: 644.8 | AL30: 595.4 | AM30: 2712.4 | AN30: 670.1 | AO30: 738.4 | AP30: 746.6 | AQ30: 720 | AR30: 2875 | AS30: 794 | AT30: 938 | AU30: 825 | AV30: 735 | AW30: 3292 | AX30: 1036 | AY30: 980 | AZ30: 925 | BA30: 871 | BB30: 3812 | BC30: 827 | BD30: 706 | BE30: 590 | BF30: 576 | BG30: 2699 | BH30: 733 | BI30: 747 | BJ30: 696 | BK30: 684 | BL30: 2860 | BM30: 987 | BN30: 1015 | BO30: 982 | BP30: 809 | BQ30: 3793 | BR30: 1065 | BS30: 1010 | BT30: 1098 | BU30: 946 | BV30: 4119 | BW30: 1153 | BX30: 1260 | CN30: Q3/Q4-26E other items excluded from Adjusted Operating Income (per quarter, $m) | CP30: 11.5 | CR30: Reserve for an international non-income tax obligation ~0.5% of revenue (1H26 $36m) and duplicate rent (NY HQ; EPS bridge ~$0.10 ≈ $22m pre-tax for FY; 1H26 $2m).
B31: Check: MIS line build vs reported (should be 0) | C31: =IF(AND(ISNUMBER(C27),ISNUMBER(C30)),IF(ABS(C27-C30)<=0.6,0,ROUND(C27-C30,1)),"") -> 0 | D31: =IF(AND(ISNUMBER(D27),ISNUMBER(D30)),IF(ABS(D27-D30)<=0.6,0,ROUND(D27-D30,1)),"") -> 0 | E31: =IF(AND(ISNUMBER(E27),ISNUMBER(E30)),IF(ABS(E27-E30)<=0.6,0,ROUND(E27-E30,1)),"") -> 0 | F31: =IF(AND(ISNUMBER(F27),ISNUMBER(F30)),IF(ABS(F27-F30)<=0.6,0,ROUND(F27-F30,1)),"") -> 0 | G31: =IF(AND(ISNUMBER(G27),ISNUMBER(G30)),IF(ABS(G27-G30)<=0.6,0,ROUND(G27-G30,1)),"") -> 0 | H31: =IF(AND(ISNUMBER(H27),ISNUMBER(H30)),IF(ABS(H27-H30)<=0.6,0,ROUND(H27-H30,1)),"") -> 0 | I31: =IF(AND(ISNUMBER(I27),ISNUMBER(I30)),IF(ABS(I27-I30)<=0.6,0,ROUND(I27-I30,1)),"") -> 0 | J31: =IF(AND(ISNUMBER(J27),ISNUMBER(J30)),IF(ABS(J27-J30)<=0.6,0,ROUND(J27-J30,1)),"") -> 0 | ... BX31: =IF(AND(ISNUMBER(BX27),ISNUMBER(BX30)),IF(ABS(BX27-BX30)<=0.6,0,ROUND(BX27-BX30,1)),"") -> 0 | CN31: Q3/Q4-26E tax rate (GAAP and on adjusting items) | CP31: 0.24 | CR31: FY26 guidance 23–25%; 1H26 24.5%.
B32: Memo: MIS recurring revenue (as reported) | P32: 218.9 | Q32: 216.6 | R32: 226.7 | S32: 882.5 | T32: 221.4 | U32: 227 | V32: 231.8 | W32: 222 | X32: 901.8 | Y32: 230.6 | Z32: 236.4 | AA32: 229.6 | AB32: 233.3 | AC32: 929.8 | AD32: 237.2 | AE32: 237.6 | AF32: 243.7 | AG32: 247.5 | AH32: 966 | AI32: 256.9 | AJ32: 256.4 | AK32: 254.3 | AL32: 258.7 | AM32: 1026.3 | AN32: 260.2 | AO32: 260.8 | AP32: 268 | AQ32: 277 | AR32: 1066 | AS32: 275 | AT32: 274 | AU32: 277 | AV32: 284 | AW32: 1110 | AX32: 291 | AY32: 294 | AZ32: 294 | BA32: 293 | BB32: 1172 | BC32: 298 | BD32: 294 | BE32: 294 | BF32: 299 | BG32: 1187 | BH32: 302 | BI32: 304 | BJ32: 308 | BK32: 309 | BL32: 1222 | BM32: 310 | BN32: 323 | BO32: 319 | BP32: 324 | BQ32: 1276 | BR32: 333 | BS32: 347 | BT32: 345 | BU32: 353 | BV32: 1378 | BW32: 363 | BX32: 369 | CH32: =IFERROR((CE32/BV32)^(1/5)-1,"n/m") -> -1 | CI32: =IFERROR((BV32/AW32)^(1/5)-1,"n/m") -> 0.044203748 | CJ32: =IFERROR((BV32/X32)^(1/10)-1,"n/m") -> 0.04331127 | CK32: =IFERROR((BV32/C32)^(1/19)-1,"n/m") -> n/m | CN32: Q3/Q4-26E net income attributable to NCI (per quarter, $m) | CP32: 1 | CR32: ICRA minority; 1H26 $1m.
B33: MIS recurring revenue % of segment revenue | C33: =IF(ISNUMBER(C32),IFERROR(C32/C27,""),"") | D33: =IF(ISNUMBER(D32),IFERROR(D32/D27,""),"") | E33: =IF(ISNUMBER(E32),IFERROR(E32/E27,""),"") | F33: =IF(ISNUMBER(F32),IFERROR(F32/F27,""),"") | G33: =IF(ISNUMBER(G32),IFERROR(G32/G27,""),"") | H33: =IF(ISNUMBER(H32),IFERROR(H32/H27,""),"") | I33: =IF(ISNUMBER(I32),IFERROR(I32/I27,""),"") | J33: =IF(ISNUMBER(J32),IFERROR(J32/J27,""),"") | ... BX33: =IF(ISNUMBER(BX32),IFERROR(BX32/BX27,""),"") -> 0.29285714 | CH33: =IFERROR(AVERAGE(CA33,CB33,CC33,CD33,CE33),"n/m") -> n/m | CI33: =IFERROR(AVERAGE(BB33,BG33,BL33,BQ33,BV33),"n/m") -> 0.36909436 | CJ33: =IFERROR(AVERAGE(AC33,AH33,AM33,AR33,AW33,BB33,BG33,BL33,BQ33,BV33),"n/m") -> 0.36722558 | CK33: =IFERROR(AVERAGE(C33,D33,E33,F33,G33,H33,I33,N33,S33,X33,AC33,AH33,AM33,AR33,AW33,BB33,BG33,BL33,BQ33,BV33),"n/m") -> 0.37067377 | CN33: FY26 capital additions ($m) | CP33: 450 | CR33: Guided ~$450m (incl. ~$100m of New York and London office relocations); 1H26 $186m.
B34: MIS intersegment revenue | E34: 63.6 | F34: 60 | G34: 61.3 | H34: 65.8 | I34: 71.5 | J34: 18.9 | K34: 19 | L34: 19.6 | M34: 21.1 | N34: 78.6 | O34: 21.5 | P34: 21.9 | Q34: 22.3 | R34: 21.9 | S34: 87.6 | T34: 22.3 | U34: 23.7 | V34: 23.5 | W34: 24 | X34: 93.5 | Y34: 24 | Z34: 24.6 | AA34: 25.3 | AB34: 26.3 | AC34: 100.2 | AD34: 26 | AE34: 27 | AF34: 29 | AG34: 29.7 | AH34: 111.7 | AI34: 29.8 | AJ34: 30.6 | AK34: 31.6 | AL34: 32 | AM34: 124 | AN34: 32.3 | AO34: 33 | AP34: 34.3 | AQ34: 35 | AR34: 134 | AS34: 37 | AT34: 35 | AU34: 38 | AV34: 38 | AW34: 148 | AX34: 40 | AY34: 42 | AZ34: 42 | BA34: 41 | BB34: 165 | BC34: 43 | BD34: 43 | BE34: 43 | BF34: 45 | BG34: 174 | BH34: 45 | BI34: 46 | BJ34: 47 | BK34: 48 | BL34: 186 | BM34: 47 | BN34: 49 | BO34: 48 | BP34: 49 | BQ34: 193 | BR34: 49 | BS34: 50 | BT34: 50 | BU34: 49 | BV34: 198 | BW34: 51 | BX34: 52 | BY34: =BY27*BY35 -> 46.674514 | BZ34: =BZ27*BZ35 -> 40.212581 | CA34: =SUM(BW34:BZ34) -> 189.88709 | CB34: =CB27*CB35 -> 202.06053 | CC34: =CC27*CC35 -> 213.33341 | CD34: =CD27*CD35 -> 224.89475 | CE34: =CE27*CE35 -> 235.877 | CF34: MIS: royalty / fees charged to MA for use of ratings content; MA: products and services sold to MIS. Eliminated on consolidation. Forecast: % of segment external revenue held at the 1H26 ratio.
B35: Intersegment revenue % of external revenue | C35: =IF(AND(ISNUMBER(C34),ISNUMBER(C27)),IFERROR(C34/C27,""),"") | D35: =IF(AND(ISNUMBER(D34),ISNUMBER(D27)),IFERROR(D34/D27,""),"") | E35: =IF(AND(ISNUMBER(E34),ISNUMBER(E27)),IFERROR(E34/E27,""),"") -> 0.052793227 | F35: =IF(AND(ISNUMBER(F34),ISNUMBER(F27)),IFERROR(F34/F27,""),"") -> 0.04927322 | G35: =IF(AND(ISNUMBER(G34),ISNUMBER(G27)),IFERROR(G34/G27,""),"") -> 0.043629893 | H35: =IF(AND(ISNUMBER(H34),ISNUMBER(H27)),IFERROR(H34/H27,""),"") -> 0.041940213 | I35: =IF(AND(ISNUMBER(I34),ISNUMBER(I27)),IFERROR(I34/I27,""),"") -> 0.037894848 | J35: =IF(AND(ISNUMBER(J34),ISNUMBER(J27)),IFERROR(J34/J27,""),"") -> 0.036262471 | ... BX35: =IF(AND(ISNUMBER(BX34),ISNUMBER(BX27)),IFERROR(BX34/BX27,""),"") -> 0.041269841 | BY35: =IFERROR(SUM(BW34:BX34)/SUM(BW27:BX27),0) -> 0.042685454 | BZ35: =IFERROR(SUM(BW34:BX34)/SUM(BW27:BX27),0) -> 0.042685454 | CA35: =IFERROR(SUM(BW34:BX34)/SUM(BW27:BX27),0) -> 0.042685454 | CB35: =$CA$35 -> 0.042685454 | CC35: =$CA$35 -> 0.042685454 | CD35: =$CA$35 -> 0.042685454 | CE35: =$CA$35 -> 0.042685454 | CN35: Target net debt / Adjusted Operating Income (x) — buyback plug 2027E+ | CO35: 1.5 | CP35: 1.25 | CQ35: 1 | CR35: Net debt / Adjusted Operating Income was ~1.2x at YE2025 (total debt $7.0bn less cash and short-term investments $2.4bn ÷ $4.0bn); FY2021–25 range 1.2–2.4x (2.4x after the RMS acquisition). Target = leverage up to which surplus cash is returned via buybacks (assumption; Moody's gives no numeric net-leverage target). Bull = more buybacks.
B36: MIS — total segment revenue (external + intersegment) | C36: =IF(AND(ISNUMBER(C27),ISNUMBER(C34)),C27+C34,"") | D36: =IF(AND(ISNUMBER(D27),ISNUMBER(D34)),D27+D34,"") | E36: =IF(AND(ISNUMBER(E27),ISNUMBER(E34)),E27+E34,"") -> 1268.3 | F36: =IF(AND(ISNUMBER(F27),ISNUMBER(F34)),F27+F34,"") -> 1277.7 | G36: =IF(AND(ISNUMBER(G27),ISNUMBER(G34)),G27+G34,"") -> 1466.3 | H36: =IF(AND(ISNUMBER(H27),ISNUMBER(H34)),H27+H34,"") -> 1634.7 | I36: =IF(AND(ISNUMBER(I27),ISNUMBER(I34)),I27+I34,"") -> 1958.3 | J36: =IF(AND(ISNUMBER(J27),ISNUMBER(J34)),J27+J34,"") -> 540.1 | ... CE36: =IF(AND(ISNUMBER(CE27),ISNUMBER(CE34)),CE27+CE34,"") -> 5761.811
B37: MIS Adjusted Operating Income (segment measure) | I37: 991.2 | J37: 255.8 | K37: 320.1 | L37: 262.1 | M37: 277.4 | N37: 1115.4 | O37: 301.6 | P37: 374.7 | Q37: 304.6 | R37: 294.4 | S37: 1277.2 | T37: 343.3 | U37: 375.9 | V37: 303.5 | W37: 284.7 | X37: 1307.4 | Y37: 270.5 | Z37: 368.9 | AA37: 364.8 | AB37: 348.6 | AC37: 1355.4 | AD37: 405.9 | AE37: 422.3 | AF37: 404 | AG37: 406.4 | AH37: 1638.6 | AI37: 439.3 | AJ37: 479.3 | AK37: 388.7 | AL37: 350.1 | AM37: 1657.4 | AN37: 385.6 | AO37: 464.4 | AP37: 468.3 | AQ37: 427 | AR37: 1745 | AS37: 503 | AT37: 623 | AU37: 554 | AV37: 373 | AW37: 2053 | AX37: 728 | AY37: 678 | AZ37: 580 | BA37: 489 | BB37: 2474 | BC37: 510 | BD37: 415 | BE37: 289 | BF37: 274 | BG37: 1488 | BH37: 442 | BI37: 443 | BJ37: 395 | BK37: 380 | BL37: 1660 | BM37: 668 | BN37: 672 | BO37: 614 | BP37: 440 | BQ37: 2394 | BR37: 735 | BS37: 680 | BT37: 749 | BU37: 582 | BV37: 2746 | BW37: 803 | BX37: 896 | BY37: =BY36*BY38 -> 749.30908 | BZ37: =BZ36*BZ38 -> 579.25165 | CA37: =SUM(BW37:BZ37) -> 3027.5607 | CB37: =CB36*CB38 -> 3232.9293 | CC37: =CC36*CC38 -> 3439.3488 | CD37: =CD36*CD38 -> 3653.2078 | CE37: =CE36*CE38 -> 3860.4134 | CF37: Company segment measure (operating income + D&A + restructuring + other items excluded by the company; includes intersegment revenue and expense). Forecast = total segment revenue × Adjusted Operating Margin. | CH37: =IFERROR((CE37/BV37)^(1/5)-1,"n/m") -> 0.070499961 | CI37: =IFERROR((BV37/AW37)^(1/5)-1,"n/m") -> 0.059893715 | CJ37: =IFERROR((BV37/X37)^(1/10)-1,"n/m") -> 0.077033484 | CK37: =IFERROR((BV37/C37)^(1/19)-1,"n/m") -> n/m | CN37: MIS_CFG (Corporate Finance y/y) | CO37: 0.03 | CP37: Δ → | CQ37: -0.05 | CR37: FY2015–25 CAGR 6.7%; 1H26 +19% on refinancing / M&A issuance; leveraged-finance refinancing walls 2027–28.
B38: MIS Adjusted Operating Margin % (company basis: on total segment revenue) | C38: =IF(AND(ISNUMBER(C37),ISNUMBER(C36)),IFERROR(C37/C36,""),"") | D38: =IF(AND(ISNUMBER(D37),ISNUMBER(D36)),IFERROR(D37/D36,""),"") | E38: =IF(AND(ISNUMBER(E37),ISNUMBER(E36)),IFERROR(E37/E36,""),"") | F38: =IF(AND(ISNUMBER(F37),ISNUMBER(F36)),IFERROR(F37/F36,""),"") | G38: =IF(AND(ISNUMBER(G37),ISNUMBER(G36)),IFERROR(G37/G36,""),"") | H38: =IF(AND(ISNUMBER(H37),ISNUMBER(H36)),IFERROR(H37/H36,""),"") | I38: =IF(AND(ISNUMBER(I37),ISNUMBER(I36)),IFERROR(I37/I36,""),"") -> 0.5061533 | J38: =IF(AND(ISNUMBER(J37),ISNUMBER(J36)),IFERROR(J37/J36,""),"") -> 0.473616 | ... BX38: =IF(AND(ISNUMBER(BX37),ISNUMBER(BX36)),IFERROR(BX37/BX36,""),"") -> 0.68292683 | BY38: =BY39+$CA$135 -> 0.65721547 | BZ38: =BZ39+$CA$135 -> 0.58970107 | CA38: =IF(AND(ISNUMBER(CA37),ISNUMBER(CA36)),IFERROR(CA37/CA36,""),"") -> 0.65271561 | CB38: =CHOOSE(MATCH($CF$2,{"Bull","Base","Bear"},0),$CO$88,$CP$88,$CQ$88) -> 0.655 | CC38: =CHOOSE(MATCH($CF$2,{"Bull","Base","Bear"},0),$CO$89,$CP$89,$CQ$89) -> 0.66 | CD38: =CHOOSE(MATCH($CF$2,{"Bull","Base","Bear"},0),$CO$90,$CP$90,$CQ$90) -> 0.665 | CE38: =CHOOSE(MATCH($CF$2,{"Bull","Base","Bear"},0),$CO$91,$CP$91,$CQ$91) -> 0.67 | CF38: Q3/Q4-26E: margin before calibration + adjusted-EPS-guidance calibration Δ (Group block). 2027E+: scenario lever. | CH38: =IFERROR(AVERAGE(CA38,CB38,CC38,CD38,CE38),"n/m") -> 0.66054312 | CI38: =IFERROR(AVERAGE(BB38,BG38,BL38,BQ38,BV38),"n/m") -> 0.58433429 | CJ38: =IFERROR(AVERAGE(AC38,AH38,AM38,AR38,AW38,BB38,BG38,BL38,BQ38,BV38),"n/m") -> 0.57991296 | CK38: =IFERROR(AVERAGE(C38,D38,E38,F38,G38,H38,I38,N38,S38,X38,AC38,AH38,AM38,AR38,AW38,BB38,BG38,BL38,BQ38,BV38),"n/m") -> 0.56487315 | CN38: 2027E | CO38: =CP38+$CO$37 -> 0.1 | CP38: 0.07 | CQ38: =CP38+$CQ$37 -> 0.02
B39: Q3/Q4-26E margin before EPS calibration (prior-year quarter + 1H26 y/y drift) | BY39: =BT38+IFERROR(SUM(BW37:BX37)/SUM(BW36:BX36)-SUM(BR37:BS37)/SUM(BR36:BS36),0) -> 0.67684328 | BZ39: =BU38+IFERROR(SUM(BW37:BX37)/SUM(BW36:BX36)-SUM(BR37:BS37)/SUM(BR36:BS36),0) -> 0.60932888 | CN39: 2028E | CO39: =CP39+$CO$37 -> 0.09 | CP39: 0.06 | CQ39: =CP39+$CQ$37 -> 0.01
B40: Memo: MIS Adjusted Operating Margin as published (%) | I40: 0.506 | J40: 0.474 | K40: 0.575 | L40: 0.527 | M40: 0.51 | N40: 0.522 | O40: 0.551 | P40: 0.582 | Q40: 0.539 | R40: 0.502 | S40: 0.543 | T40: 0.55 | U40: 0.567 | V40: 0.531 | W40: 0.501 | X40: 0.539 | Y40: 0.493 | Z40: 0.567 | AA40: 0.572 | AB40: 0.55 | AC40: 0.549 | AD40: 0.585 | AE40: 0.592 | AF40: 0.559 | AG40: 0.539 | AH40: 0.568 | AI40: 0.586 | AJ40: 0.612 | AK40: 0.575 | AL40: 0.558 | AM40: 0.584 | AN40: 0.549 | AO40: 0.602 | AP40: 0.6 | AQ40: 0.566 | AR40: 0.58 | AS40: 0.605 | AT40: 0.64 | AU40: 0.642 | AV40: 0.483 | AW40: 0.597 | AX40: 0.677 | AY40: 0.663 | AZ40: 0.6 | BA40: 0.536 | BB40: 0.622 | BC40: 0.586 | BD40: 0.554 | BE40: 0.457 | BF40: 0.441 | BG40: 0.518 | BH40: 0.568 | BI40: 0.559 | BJ40: 0.532 | BK40: 0.519 | BL40: 0.545 | BM40: 0.646 | BN40: 0.632 | BO40: 0.596 | BP40: 0.513 | BQ40: 0.601 | BR40: 0.66 | BS40: 0.642 | BT40: 0.652 | BU40: 0.585 | BV40: 0.636 | BW40: 0.667 | BX40: 0.683 | CN40: 2029E | CO40: =CP40+$CO$37 -> 0.09 | CP40: 0.06 | CQ40: =CP40+$CQ$37 -> 0.01
...

Sheet Bull-Base-Bear
B2: Moody's Corporation (MCO) — Bull / Base / Bear Case P&L Summary | J2: Share price ($): | K2: =Model!$CA$423 -> 470
B3: Adjusted figures (company definitions: Adjusted Operating Income = model Adjusted EBITDA; adjusted diluted EPS) · USD millions · Live panel linked to Model — toggle scenario via Model!CF2. Bull and Bear panels are value snapshots generated from the Model with the switch set to each case. 2026E = Q1–Q2 actual + Q3–Q4 calibrated to the FY26 guidance (MIS revenue up HSD, MA up MSD, adjusted EPS $16.50–17.00). | J3: As of: | K3: =TODAY() -> 2026-10-12 00:00:00
B5: Scenario: | C5: =Model!$CF$2 -> Base | N5: Scenario: | O5: Bull | P5: Snapshot (values) — Model run with switch = Bull | Z5: Scenario: | AA5: Bear | AB5: Snapshot (values) — Model run with switch = Bear
B7: (USDm, except EPS and shares) | C7: 2025A | D7: 2026E | E7: 2027E | F7: 2028E | G7: 2029E | H7: 2030E | I7: 25-'30 CAGR | J7: LT Hist Avg | K7: LT Hist Min | L7: LT Hist Max | N7: (USDm, except EPS and shares) | O7: 2025A | P7: 2026E | Q7: 2027E | R7: 2028E | S7: 2029E | T7: 2030E | U7: 25-'30 CAGR | V7: LT Hist Avg | W7: LT Hist Min | X7: LT Hist Max | Z7: (USDm, except EPS and shares) | AA7: 2025A | AB7: 2026E | AC7: 2027E | AD7: 2028E | AE7: 2029E | AF7: 2030E | AG7: 25-'30 CAGR | AH7: LT Hist Avg | AI7: LT Hist Min | AJ7: LT Hist Max
B9: Revenue | C9: =Model!BV163 -> 7718 | D9: =Model!CA163 -> 8227.47 | E9: =Model!CB163 -> 8820.4421 | F9: =Model!CC163 -> 9419.2267 | G9: =Model!CD163 -> 10027.233 | H9: =Model!CE163 -> 10629.711 | I9: =IFERROR((H9/C9)^(1/5)-1,"n/m") -> 0.066113234 | N9: Revenue | O9: 7718 | P9: 8304.65 | Q9: 9132.3187 | R9: 10023.117 | S9: 10960.66 | T9: 11930.637 | U9: 0.091017643 | Z9: Revenue | AA9: 7718 | AB9: 8150.29 | AC9: 8381.9835 | AD9: 8572.7801 | AE9: 8742.1364 | AF9: 8878.714 | AG9: 0.028416554
B10: Revenue y/y % | D10: =IFERROR(D9/C9-1,"") -> 0.066010625 | E10: =IFERROR(E9/D9-1,"") -> 0.072072232 | F10: =IFERROR(F9/E9-1,"") -> 0.067886009 | G10: =IFERROR(G9/F9-1,"") -> 0.064549457 | H10: =IFERROR(H9/G9-1,"") -> 0.060084175 | N10: Revenue y/y % | P10: 0.076010625 | Q10: 0.099663286 | R10: 0.097543477 | S10: 0.093538136 | T10: 0.088496201 | Z10: Revenue y/y % | AB10: 0.056010625 | AC10: 0.028427634 | AD10: 0.022762706 | AE10: 0.019755125 | AF10: 0.015622907
B11: MIS revenue y/y % | C11: =Model!BV247 -> 0.085947799 | D11: =Model!CA247 -> 0.08 | E11: =Model!CB247 -> 0.064108832 | F11: =Model!CC247 -> 0.055789592 | G11: =Model!CD247 -> 0.054193777 | H11: =Model!CE247 -> 0.048832833 | N11: MIS revenue y/y % | O11: 0.085947799 | P11: 0.09 | Q11: 0.092289457 | R11: 0.083998082 | S11: 0.082429634 | T11: 0.077071809 | Z11: MIS revenue y/y % | AA11: 0.085947799 | AB11: 0.07 | AC11: 0.016024025 | AD11: 0.0077063507 | AE11: 0.006112985 | AF11: 0.00078070649
B12: Adjusted Operating Income (= Adjusted EBITDA) | C12: =Model!BV219 -> 3942 | D12: =Model!CA219 -> 4319.482 | E12: =Model!CB219 -> 4686.9057 | F12: =Model!CC219 -> 5053.2219 | G12: =Model!CD219 -> 5433.7829 | H12: =Model!CE219 -> 5816.6537 | I12: =IFERROR((H12/C12)^(1/5)-1,"n/m") -> 0.080914437 | N12: Adjusted Operating Income (= Adjusted EBITDA) | O12: 3942 | P12: 4375.0815 | Q12: 4944.5743 | R12: 5470.5785 | S12: 6034.7439 | T12: 6625.69 | U12: 0.10943764 | Z12: Adjusted Operating Income (= Adjusted EBITDA) | AA12: 3942 | AB12: 4263.83 | AC12: 4230.2749 | AD12: 4369.5499 | AE12: 4502.5661 | AF12: 4619.4721 | AG12: 0.032226838
B13: Adjusted Operating Margin % | C13: =IFERROR(C12/C9,"") -> 0.51075408 | D13: =IFERROR(D12/D9,"") -> 0.52500732 | E13: =IFERROR(E12/E9,"") -> 0.53136857 | F13: =IFERROR(F12/F9,"") -> 0.53647948 | G13: =IFERROR(G12/G9,"") -> 0.54190254 | H13: =IFERROR(H12/H9,"") -> 0.54720715 | J13: =IFERROR(AVERAGE(Model!C220,Model!D220,Model!E220,Model!F220,Model!G220,Model!H220,Model!I220,Model!N220,Model!S220,Model!X220,Model!AC220,Model!AH220,Model!AM220,Model!AR220,Model!AW220,Model!BB220,Model!BG220,Model!BL220,Model!BQ220,Model!BV220),"") -> 0.46801913 | K13: =IFERROR(MIN(Model!C220,Model!D220,Model!E220,Model!F220,Model!G220,Model!H220,Model!I220,Model!N220,Model!S220,Model!X220,Model!AC220,Model!AH220,Model!AM220,Model!AR220,Model!AW220,Model!BB220,Model!BG220,Model!BL220,Model!BQ220,Model!BV220),"") -> 0.41299213 | L13: =IFERROR(MAX(Model!C220,Model!D220,Model!E220,Model!F220,Model!G220,Model!H220,Model!I220,Model!N220,Model!S220,Model!X220,Model!AC220,Model!AH220,Model!AM220,Model!AR220,Model!AW220,Model!BB220,Model!BG220,Model!BL220,Model!BQ220,Model!BV220),"") -> 0.55883364 | N13: Adjusted Operating Margin % | O13: 0.51075408 | P13: 0.52682311 | Q13: 0.5414369 | R13: 0.54579614 | S13: 0.55058214 | T13: 0.55535088 | V13: 0.46801913 | W13: 0.41299213 | X13: 0.55883364 | Z13: Adjusted Operating Margin % | AA13: 0.51075408 | AB13: 0.52315071 | AC13: 0.50468662 | AD13: 0.50970045 | AE13: 0.51504184 | AF13: 0.52028617 | AH13: 0.46801913 | AI13: 0.41299213 | AJ13: 0.55883364
B15: Operating Income (GAAP) | C15: =Model!BV170 -> 3351 | D15: =Model!CA170 -> 3654.482 | E15: =Model!CB170 -> 4091.7031 | F15: =Model!CC170 -> 4514.7105 | G15: =Model!CD170 -> 4889.4147 | H15: =Model!CE170 -> 5268.058 | I15: =IFERROR((H15/C15)^(1/5)-1,"n/m") -> 0.094700267 | N15: Operating Income (GAAP) | O15: 3351 | P15: 3710.0815 | Q15: 4334.1442 | R15: 4897.7232 | S15: 5434.9054 | T15: 5999.6591 | U15: 0.12354489 | Z15: Operating Income (GAAP) | AA15: 3351 | AB15: 3598.83 | AC15: 3653.5235 | AD15: 3870.357 | AE15: 4020.3649 | AF15: 4156.081 | AG15: 0.044003405
B16: Operating income y/y % | D16: =IFERROR(D15/C15-1,"") -> 0.090564606 | E16: =IFERROR(E15/D15-1,"") -> 0.1196397 | F16: =IFERROR(F15/E15-1,"") -> 0.10338173 | G16: =IFERROR(G15/F15-1,"") -> 0.082996287 | H16: =IFERROR(H15/G15-1,"") -> 0.07744144 | N16: Operating income y/y % | P16: 0.10715653 | Q16: 0.16820726 | R16: 0.13003237 | S16: 0.10967999 | T16: 0.10391232 | Z16: Operating income y/y % | AB16: 0.073957016 | AC16: 0.015197595 | AD16: 0.059349136 | AE16: 0.038758153 | AF16: 0.033757167
B17: Operating margin (GAAP) % | C17: =IFERROR(C15/C9,"") -> 0.43417984 | D17: =IFERROR(D15/D9,"") -> 0.44418053 | E17: =IFERROR(E15/E9,"") -> 0.46388867 | F17: =IFERROR(F15/F9,"") -> 0.47930797 | G17: =IFERROR(G15/G9,"") -> 0.48761357 | H17: =IFERROR(H15/H9,"") -> 0.4955975 | J17: =IFERROR(AVERAGE(Model!C256,Model!D256,Model!E256,Model!F256,Model!G256,Model!H256,Model!I256,Model!N256,Model!S256,Model!X256,Model!AC256,Model!AH256,Model!AM256,Model!AR256,Model!AW256,Model!BB256,Model!BG256,Model!BL256,Model!BQ256,Model!BV256),"") -> 0.41255603 | K17: =IFERROR(MIN(Model!C256,Model!D256,Model!E256,Model!F256,Model!G256,Model!H256,Model!I256,Model!N256,Model!S256,Model!X256,Model!AC256,Model!AH256,Model!AM256,Model!AR256,Model!AW256,Model!BB256,Model!BG256,Model!BL256,Model!BQ256,Model!BV256),"") -> 0.17720992 | L17: =IFERROR(MAX(Model!C256,Model!D256,Model!E256,Model!F256,Model!G256,Model!H256,Model!I256,Model!N256,Model!S256,Model!X256,Model!AC256,Model!AH256,Model!AM256,Model!AR256,Model!AW256,Model!BB256,Model!BG256,Model!BL256,Model!BQ256,Model!BV256),"") -> 0.61828089 | N17: Operating margin (GAAP) % | O17: 0.43417984 | P17: 0.44674749 | Q17: 0.47459406 | R17: 0.48864273 | S17: 0.49585565 | T17: 0.50287834 | V17: 0.41255603 | W17: 0.17720992 | X17: 0.61828089 | Z17: Operating margin (GAAP) % | AA17: 0.43417984 | AB17: 0.44155852 | AC17: 0.43587816 | AD17: 0.45147046 | AE17: 0.45988357 | AF17: 0.46809493 | AH17: 0.41255603 | AI17: 0.17720992 | AJ17: 0.61828089
B19: Adjusted Net Income (attributable to Moody's) | C19: =Model!BV235 -> 2687 | D19: =Model!CA235 -> 2922.0063 | E19: =Model!CB235 -> 3136.1109 | F19: =Model!CC235 -> 3361.5854 | G19: =Model!CD235 -> 3607.015 | H19: =Model!CE235 -> 3854.0686 | I19: =IFERROR((H19/C19)^(1/5)-1,"n/m") -> 0.074806677 | N19: Adjusted Net Income (attributable to Moody's) | O19: 2687 | P19: 2964.262 | Q19: 3321.8985 | R19: 3610.1636 | S19: 3974.6325 | T19: 4356.999 | U19: 0.10149862 | Z19: Adjusted Net Income (attributable to Moody's) | AA19: 2687 | AB19: 2879.7108 | AC19: 2802.5746 | AD19: 2890.5478 | AE19: 2965.9978 | AF19: 3029.5823 | AG19: 0.024290202
B21: FDSO (m) | C21: =Model!BV189 -> 179.9 | D21: =Model!CA189 -> 174.44814 | E21: =Model!CB189 -> 169.75645 | F21: =Model!CC189 -> 164.60191 | G21: =Model!CD189 -> 159.77157 | H21: =Model!CE189 -> 154.98752 | I21: =IFERROR((H21/C21)^(1/5)-1,"n/m") -> -0.029371335 | N21: FDSO (m) | O21: 179.9 | P21: 174.36835 | Q21: 168.08029 | R21: 161.25853 | S21: 155.68239 | T21: 149.9091 | U21: -0.035817233 | Z21: FDSO (m) | AA21: 179.9 | AB21: 174.52793 | AC21: 171.76105 | AD21: 168.9024 | AE21: 165.42983 | AF21: 162.26194 | AG21: -0.020426333
B23: Adjusted EPS — Diluted ($) | C23: =Model!BV238 -> 14.936076 | D23: =Model!CA238 -> 16.75 | E23: =Model!CB238 -> 18.474177 | F23: =Model!CC238 -> 20.422518 | G23: =Model!CD238 -> 22.576075 | H23: =Model!CE238 -> 24.866961 | I23: =IFERROR((H23/C23)^(1/5)-1,"n/m") -> 0.10733045 | N23: Adjusted EPS — Diluted ($) | O23: 14.936076 | P23: 17 | Q23: 19.763761 | R23: 22.387427 | S23: 25.530392 | T23: 29.064273 | U23: 0.14241683 | Z23: Adjusted EPS — Diluted ($) | AA23: 14.936076 | AB23: 16.5 | AC23: 16.316706 | AD23: 17.113717 | AE23: 17.929038 | AF23: 18.670936 | AG23: 0.045648975
B24: EPS y/y % | D24: =IFERROR(D23/C23-1,"") -> 0.12144585 | E24: =IFERROR(E23/D23-1,"") -> 0.10293597 | F24: =IFERROR(F23/E23-1,"") -> 0.10546292 | G24: =IFERROR(G23/F23-1,"") -> 0.10545011 | H24: =IFERROR(H23/G23-1,"") -> 0.10147407 | N24: EPS y/y % | P24: 0.13818385 | Q24: 0.16257416 | R24: 0.13275137 | S24: 0.14038975 | T24: 0.1384186 | Z24: EPS y/y % | AB24: 0.10470785 | AC24: -0.011108702 | AD24: 0.048846267 | AE24: 0.047641409 | AF24: 0.041379663
B26: P / E (x) — assumed (adjusted EPS) | F26: 31 | G26: 31 | H26: 31 | N26: P / E (x) — assumed (adjusted EPS) | R26: 35 | S26: 35 | T26: 35 | Z26: P / E (x) — assumed (adjusted EPS) | AD26: 24 | AE26: 24 | AF26: 24
B27: Price Target ($) | F27: =F26*F23 -> 633.09806 | G27: =G26*G23 -> 699.85832 | H27: =H26*H23 -> 770.8758 | N27: Price Target ($) | R27: =R26*R23 -> 783.55994 | S27: =S26*S23 -> 893.56373 | T27: =T26*T23 -> 1017.2496 | Z27: Price Target ($) | AD27: =AD26*AD23 -> 410.7292 | AE27: =AE26*AE23 -> 430.29692 | AF27: =AF26*AF23 -> 448.10246
B28: Upside / (Downside) vs current | F28: =IFERROR(F27/$K$2-1,"") -> 0.34701716 | G28: =IFERROR(G27/$K$2-1,"") -> 0.48906026 | H28: =IFERROR(H27/$K$2-1,"") -> 0.64016127 | N28: Upside / (Downside) vs current | R28: =IFERROR(R27/$K$2-1,"") -> 0.66714881 | S28: =IFERROR(S27/$K$2-1,"") -> 0.90119942 | T28: =IFERROR(T27/$K$2-1,"") -> 1.1643608 | Z28: Upside / (Downside) vs current | AD28: =IFERROR(AD27/$K$2-1,"") -> -0.12610809 | AE28: =IFERROR(AE27/$K$2-1,"") -> -0.084474646 | AF28: =IFERROR(AF27/$K$2-1,"") -> -0.046590516
B29: IRR (to Dec-Y-1) | F29: =IFERROR((F27/$K$2)^(1/((DATE(2028-1,12,31)-$K$3)/365.25))-1,"") -> 0.27699065 | G29: =IFERROR((G27/$K$2)^(1/((DATE(2029-1,12,31)-$K$3)/365.25))-1,"") -> 0.19639471 | H29: =IFERROR((H27/$K$2)^(1/((DATE(2030-1,12,31)-$K$3)/365.25))-1,"") -> 0.16611374 | N29: IRR (to Dec-Y-1) | R29: =IFERROR((R27/$K$2)^(1/((DATE(2028-1,12,31)-$K$3)/365.25))-1,"") -> 0.5212254 | S29: =IFERROR((S27/$K$2)^(1/((DATE(2029-1,12,31)-$K$3)/365.25))-1,"") -> 0.33556697 | T29: =IFERROR((T27/$K$2)^(1/((DATE(2030-1,12,31)-$K$3)/365.25))-1,"") -> 0.27100993 | Z29: IRR (to Dec-Y-1) | AD29: =IFERROR((AD27/$K$2)^(1/((DATE(2028-1,12,31)-$K$3)/365.25))-1,"") -> -0.10473978 | AE29: =IFERROR((AE27/$K$2)^(1/((DATE(2029-1,12,31)-$K$3)/365.25))-1,"") -> -0.038968793 | AF29: =IFERROR((AF27/$K$2)^(1/((DATE(2030-1,12,31)-$K$3)/365.25))-1,"") -> -0.014709087
B31: Free Cash Flow | C31: =Model!BV288 -> 2575 | D31: =Model!CA288 -> 2933.7428 | E31: =Model!CB288 -> 3296.0488 | F31: =Model!CC288 -> 3617.7692 | G31: =Model!CD288 -> 3878.1855 | H31: =Model!CE288 -> 4130.9902 | I31: =IFERROR((H31/C31)^(1/5)-1,"n/m") -> 0.099146008 | N31: Free Cash Flow | O31: 2575 | P31: 2984.5644 | Q31: 3513.2109 | R31: 3911.903 | S31: 4303.9789 | T31: 4704.8446 | U31: 0.12811561 | Z31: Free Cash Flow | AA31: 2575 | AB31: 2882.8813 | AC31: 2915.6372 | AD31: 3085.1408 | AE31: 3162.1525 | AF31: 3218.7974 | AG31: 0.045642633
B32: FCF % | C32: =IFERROR(C31/C9,"") -> 0.33363566 | D32: =IFERROR(D31/D9,"") -> 0.35657897 | E32: =IFERROR(E31/E9,"") -> 0.37368295 | F32: =IFERROR(F31/F9,"") -> 0.38408346 | G32: =IFERROR(G31/G9,"") -> 0.38676528 | H32: =IFERROR(H31/H9,"") -> 0.38862678 | J32: =IFERROR(AVERAGE(Model!C292,Model!D292,Model!E292,Model!F292,Model!G292,Model!H292,Model!I292,Model!N292,Model!S292,Model!X292,Model!AC292,Model!AH292,Model!AM292,Model!AR292,Model!AW292,Model!BB292,Model!BG292,Model!BL292,Model!BQ292,Model!BV292),"") -> 0.30304136 | K32: =IFERROR(MIN(Model!C292,Model!D292,Model!E292,Model!F292,Model!G292,Model!H292,Model!I292,Model!N292,Model!S292,Model!X292,Model!AC292,Model!AH292,Model!AM292,Model!AR292,Model!AW292,Model!BB292,Model!BG292,Model!BL292,Model!BQ292,Model!BV292),"") -> 0.15625223 | L32: =IFERROR(MAX(Model!C292,Model!D292,Model!E292,Model!F292,Model!G292,Model!H292,Model!I292,Model!N292,Model!S292,Model!X292,Model!AC292,Model!AH292,Model!AM292,Model!AR292,Model!AW292,Model!BB292,Model!BG292,Model!BL292,Model!BQ292,Model!BV292),"") -> 0.38037609 | N32: FCF % | O32: 0.33363566 | P32: 0.35938472 | Q32: 0.38470086 | R32: 0.39028808 | S32: 0.39267514 | T32: 0.39434981 | V32: 0.30304136 | W32: 0.15625223 | X32: 0.38037609 | Z32: FCF % | AA32: 0.33363566 | AB32: 0.35371518 | AC32: 0.34784573 | AD32: 0.35987635 | AE32: 0.36171393 | AF32: 0.36252969 | AH32: 0.30304136 | AI32: 0.15625223 | AJ32: 0.38037609
B33: FCF / share ($) | C33: =IFERROR(C31/C21,"") -> 14.313508 | D33: =IFERROR(D31/D21,"") -> 16.817278 | E33: =IFERROR(E31/E21,"") -> 19.416339 | F33: =IFERROR(F31/F21,"") -> 21.978902 | G33: =IFERROR(G31/G21,"") -> 24.273314 | H33: =IFERROR(H31/H21,"") -> 26.653696 | N33: FCF / share ($) | O33: 14.313508 | P33: 17.116434 | Q33: 20.901981 | R33: 24.25858 | S33: 27.645894 | T33: 31.38465 | Z33: FCF / share ($) | AA33: 14.313508 | AB33: 16.518166 | AC33: 16.974961 | AD33: 18.26582 | AE33: 19.114766 | AF33: 19.837045
B34: FCF Yield (on PT) | F34: =IFERROR(F33/F$27,"") -> 0.034716426 | G34: =IFERROR(G33/G$27,"") -> 0.034683182 | H34: =IFERROR(H33/H$27,"") -> 0.034575863 | N34: FCF Yield (on PT) | R34: =IFERROR(R33/R$27,"") -> 0.030959444 | S34: =IFERROR(S33/S$27,"") -> 0.030938917 | T34: =IFERROR(T33/T$27,"") -> 0.030852459 | Z34: FCF Yield (on PT) | AD34: =IFERROR(AD33/AD$27,"") -> 0.044471687 | AE34: =IFERROR(AE33/AE$27,"") -> 0.04442227 | AF34: =IFERROR(AF33/AF$27,"") -> 0.044268993
B35: Adjusted Operating Income (leverage basis) | C35: =Model!BV219 -> 3942 | D35: =Model!CA219 -> 4319.482 | E35: =Model!CB219 -> 4686.9057 | F35: =Model!CC219 -> 5053.2219 | G35: =Model!CD219 -> 5433.7829 | H35: =Model!CE219 -> 5816.6537 | I35: =IFERROR((H35/C35)^(1/5)-1,"n/m") -> 0.080914437 | N35: Adjusted Operating Income (leverage basis) | O35: 3942 | P35: 4375.0815 | Q35: 4944.5743 | R35: 5470.5785 | S35: 6034.7439 | T35: 6625.69 | U35: 0.10943764 | Z35: Adjusted Operating Income (leverage basis) | AA35: 3942 | AB35: 4263.83 | AC35: 4230.2749 | AD35: 4369.5499 | AE35: 4502.5661 | AF35: 4619.4721 | AG35: 0.032226838
B36: Adjusted Operating Income % of revenue | C36: =IFERROR(C35/C9,"") -> 0.51075408 | D36: =IFERROR(D35/D9,"") -> 0.52500732 | E36: =IFERROR(E35/E9,"") -> 0.53136857 | F36: =IFERROR(F35/F9,"") -> 0.53647948 | G36: =IFERROR(G35/G9,"") -> 0.54190254 | H36: =IFERROR(H35/H9,"") -> 0.54720715 | J36: =IFERROR(AVERAGE(Model!C255,Model!D255,Model!E255,Model!F255,Model!G255,Model!H255,Model!I255,Model!N255,Model!S255,Model!X255,Model!AC255,Model!AH255,Model!AM255,Model!AR255,Model!AW255,Model!BB255,Model!BG255,Model!BL255,Model!BQ255,Model!BV255),"") -> 0.46801913 | K36: =IFERROR(MIN(Model!C255,Model!D255,Model!E255,Model!F255,Model!G255,Model!H255,Model!I255,Model!N255,Model!S255,Model!X255,Model!AC255,Model!AH255,Model!AM255,Model!AR255,Model!AW255,Model!BB255,Model!BG255,Model!BL255,Model!BQ255,Model!BV255),"") -> 0.41299213 | L36: =IFERROR(MAX(Model!C255,Model!D255,Model!E255,Model!F255,Model!G255,Model!H255,Model!I255,Model!N255,Model!S255,Model!X255,Model!AC255,Model!AH255,Model!AM255,Model!AR255,Model!AW255,Model!BB255,Model!BG255,Model!BL255,Model!BQ255,Model!BV255),"") -> 0.55883364 | N36: Adjusted Operating Income % of revenue | O36: 0.51075408 | P36: 0.52682311 | Q36: 0.5414369 | R36: 0.54579614 | S36: 0.55058214 | T36: 0.55535088 | V36: 0.46801913 | W36: 0.41299213 | X36: 0.55883364 | Z36: Adjusted Operating Income % of revenue | AA36: 0.51075408 | AB36: 0.52315071 | AC36: 0.50468662 | AD36: 0.50970045 | AE36: 0.51504184 | AF36: 0.52028617 | AH36: 0.46801913 | AI36: 0.41299213 | AJ36: 0.55883364
B38: Net Debt | C38: =Model!BV417 -> 4546 | D38: =Model!CA417 -> 4991.0492 | E38: =Model!CB417 -> 5829.6321 | F38: =Model!CC417 -> 6287.5274 | G38: =Model!CD417 -> 6763.2286 | H38: =Model!CE417 -> 7241.8171 | N38: Net Debt | O38: 4546 | P38: 5090.2276 | Q38: 7387.8615 | R38: 8176.8678 | S38: 9023.1158 | T38: 9909.5349 | Z38: Net Debt | AA38: 4546 | AB38: 4891.9107 | AC38: 4201.2749 | AD38: 4340.5499 | AE38: 4473.5661 | AF38: 4590.4721
B39: Net Debt / Adjusted Operating Income (x) | C39: =IFERROR(C38/C35,"") -> 1.1532217 | D39: =IFERROR(D38/D35,"") -> 1.155474 | E39: =IFERROR(E38/E35,"") -> 1.2438125 | F39: =IFERROR(F38/F35,"") -> 1.2442611 | G39: =IFERROR(G38/G35,"") -> 1.244663 | H39: =IFERROR(H38/H35,"") -> 1.2450143 | N39: Net Debt / Adjusted Operating Income (x) | O39: 1.1532217 | P39: 1.1634589 | Q39: 1.494135 | R39: 1.4946989 | S39: 1.4951945 | T39: 1.4956231 | Z39: Net Debt / Adjusted Operating Income (x) | AA39: 1.1532217 | AB39: 1.1473044 | AC39: 0.99314465 | AD39: 0.99336316 | AE39: 0.99355923 | AF39: 0.99372223
B40: Share repurchases ($m; 2026E = 2H) | D40: =Model!CA302 -> 685 | E40: =Model!CB302 -> 3082.2476 | F40: =Model!CC302 -> 2980.5519 | G40: =Model!CD302 -> 3211.2215 | H40: =Model!CE302 -> 3417.3273 | N40: Share repurchases ($m; 2026E = 2H) | P40: 835 | Q40: 4459.8938 | R40: 3320.6442 | S40: 3727.0553 | T40: 4125.3273 | AB40: 535 | AC40: 1371.184 | AD40: 2311.2407 | AE40: 2326.3011 | AF40: 2306.199
