Workbook

Sheet Model
CD1: SCENARIO SWITCH ▼ (Bull / Base / Bear) — drives all scenario-linked forecast drivers
B2: Meta Platforms, Inc. (NASDAQ: META) — 3-Statement Financial Model | CD2: Base
B3: US GAAP as reported · USD millions (per-share data in USD; shares and people in millions) · Fiscal years ended 31 December · Source: SEC EDGAR only (CIK 1326801): Forms 10-K / 10-Q, Form 8-K earnings releases (Ex. 99.1), IPO prospectus (424B4, 18-May-2012), notes-issue 8-Ks; XBRL company facts. Investor-relations releases are the same documents as filed on EDGAR; all guidance is from the 8-K releases (no unverified guidance used)
B4: Basis notes: as originally reported (FY2011 cost reclassification, FY2016 ASU 2016-09 and 2018 restricted-cash re-presentations not recast). Facebook, Inc. until 28-Oct-2021 (ticker FB until 9-Jun-2022); IPO 18-May-2012 (FY2009–11 from the prospectus; no FY2009 balance sheet). Segments FoA / RL from Q4-21 (2019–21 recast). Acquisitions: Instagram 2012, WhatsApp and Oculus 2014. Q3/26E calibrated to revenue guidance, 2H/26E to FY26 expense guidance (29-Jul-2026).
CF5: Forecast | CG5: Historical | CH5: Historical | CI5: Historical
B6: (USDm) | C6: 2009 | D6: 2010 | E6: 2011 | F6: 2012 | G6: Q1/13 | H6: Q2/13 | I6: Q3/13 | J6: Q4/13 | K6: 2013 | L6: Q1/14 | M6: Q2/14 | N6: Q3/14 | O6: Q4/14 | P6: 2014 | Q6: Q1/15 | R6: Q2/15 | S6: Q3/15 | T6: Q4/15 | U6: 2015 | V6: Q1/16 | W6: Q2/16 | X6: Q3/16 | Y6: Q4/16 | Z6: 2016 | AA6: Q1/17 | AB6: Q2/17 | AC6: Q3/17 | AD6: Q4/17 | AE6: 2017 | AF6: Q1/18 | AG6: Q2/18 | AH6: Q3/18 | AI6: Q4/18 | AJ6: 2018 | AK6: Q1/19 | AL6: Q2/19 | AM6: Q3/19 | AN6: Q4/19 | AO6: 2019 | AP6: Q1/20 | AQ6: Q2/20 | AR6: Q3/20 | AS6: Q4/20 | AT6: 2020 | AU6: Q1/21 | AV6: Q2/21 | AW6: Q3/21 | AX6: Q4/21 | AY6: 2021 | AZ6: Q1/22 | BA6: Q2/22 | BB6: Q3/22 | BC6: Q4/22 | BD6: 2022 | BE6: Q1/23 | BF6: Q2/23 | BG6: Q3/23 | BH6: Q4/23 | BI6: 2023 | BJ6: Q1/24 | BK6: Q2/24 | BL6: Q3/24 | BM6: Q4/24 | BN6: 2024 | BO6: Q1/25 | BP6: Q2/25 | BQ6: Q3/25 | BR6: Q4/25 | BS6: 2025 | BT6: Q1/26 | BU6: Q2/26 | BV6: Q3/26E | BW6: Q4/26E | BX6: 2026E | BY6: 2027E | BZ6: 2028E | CA6: 2029E | CB6: 2030E | CC6: 2031E | CD6: Modelling Notes | CF6: 5Y CAGR | CG6: 5Y CAGR | CH6: 10Y CAGR | CI6: 16Y CAGR
CF7: 26-'31 | CG7: 20-'25 | CH7: 15-'25 | CI7: 09-'25
B8: OPERATING BUILD — FAMILY OF APPS (ADVERTISING = AD IMPRESSIONS × PRICE PER AD; OTHER REVENUE) · REALITY LABS | CD8: OPERATING BUILD — modelling logic (advertising = prior-year period × (1 + impressions growth) × (1 + price-per-ad growth); other revenue by line; segment profit; costs built separately below)
CL9: SCENARIO INPUT TABLE — driver assumptions per Bull / Base / Bear | CM9: Bull | CN9: Base | CO9: Bear | CP9: Bull / Bear = Base + Δ (Δ inputs on each block header). Outlook block = high / mid / low end of the 2026 guidance ranges.
B10: Family of Apps — advertising (Facebook, Instagram, Messenger, WhatsApp, Threads) | CD10: ADVERTISING — modelling logic
B11: Advertising revenue | C11: 764 | D11: 1868 | E11: 3154 | F11: 4279 | G11: 1245 | H11: 1599 | I11: 1798 | J11: 2344 | K11: 6986 | L11: 2265 | M11: 2676 | N11: 2957 | O11: 3594 | P11: 11492 | Q11: 3317 | R11: 3827 | S11: 4299 | T11: 5637 | U11: 17079 | V11: 5201 | W11: 6239 | X11: 6816 | Y11: 8629 | Z11: 26885 | AA11: 7857 | AB11: 9164 | AC11: 10142 | AD11: 12779 | AE11: 39942 | AF11: 11795 | AG11: 13038 | AH11: 13539 | AI11: 16640 | AJ11: 55013 | AK11: 14912 | AL11: 16624 | AM11: 17383 | AN11: 20736 | AO11: 69655 | AP11: 17440 | AQ11: 18321 | AR11: 21221 | AS11: 27187 | AT11: 84169 | AU11: 25439 | AV11: 28580 | AW11: 28276 | AX11: 32639 | AY11: 114934 | AZ11: 26998 | BA11: 28152 | BB11: 27237 | BC11: 31254 | BD11: 113642 | BE11: 28101 | BF11: 31498 | BG11: 33643 | BH11: 38706 | BI11: 131948 | BJ11: 35635 | BK11: 38329 | BL11: 39885 | BM11: 46783 | BN11: 160633 | BO11: 41392 | BP11: 46563 | BQ11: 50082 | BR11: 58137 | BS11: 196175 | BT11: 55024 | BU11: 59363 | BV11: =BQ11*(1+BV12) -> 60804.947 | BW11: =BR11*(1+BW12) -> 70584.585 | BX11: =SUM(BT11:BW11) -> 245776.53 | BY11: =BX11*(1+BY12) -> 291982.52 | BZ11: =BY11*(1+BZ12) -> 337356.6 | CA11: =BZ11*(1+CA12) -> 382562.39 | CB11: =CA11*(1+CB12) -> 425715.43 | CC11: =CB11*(1+CC12) -> 469308.69 | CD11: History: release reconciliation ("GAAP advertising revenue"; 2009-11 prospectus; segment table from Q4-2021). Forecast: prior-year period × (1 + ad impressions growth) × (1 + price-per-ad growth). | CF11: =IFERROR((CC11/BX11)^(1/5)-1,"n/m") -> 0.13810842 | CG11: =IFERROR((BS11/AT11)^(1/5)-1,"n/m") -> 0.18439973 | CH11: =IFERROR((BS11/U11)^(1/10)-1,"n/m") -> 0.27649207 | CI11: =IFERROR((BS11/C11)^(1/16)-1,"n/m") -> 0.41448027 | CL11: Outlook — Q2-26 release (8-K Ex. 99.1, 29-Jul-2026) | CM11: High | CN11: Mid | CO11: Low | CP11: Q3/26 revenue $61–64bn (FX ~1% headwind); FY26 total expenses $165–169bn (low end raised for the $2.4bn Q2 legal charges); FY26 operating income above 2025; FY26 capital expenditures incl. principal payments on finance leases $130–145bn; tax rate 15–17% for the remaining quarters. All from the 8-K (SEC EDGAR).
B12: y/y % | D12: =IF(AND(ISNUMBER(D11),ISNUMBER(C11)),IFERROR(D11/C11-1,""),"") -> 1.4450262 | E12: =IF(AND(ISNUMBER(E11),ISNUMBER(D11)),IFERROR(E11/D11-1,""),"") -> 0.68843683 | F12: =IF(AND(ISNUMBER(F11),ISNUMBER(E11)),IFERROR(F11/E11-1,""),"") -> 0.35668992 | K12: =IF(AND(ISNUMBER(K11),ISNUMBER(F11)),IFERROR(K11/F11-1,""),"") -> 0.63262444 | L12: =IF(AND(ISNUMBER(L11),ISNUMBER(G11)),IFERROR(L11/G11-1,""),"") -> 0.81927711 | M12: =IF(AND(ISNUMBER(M11),ISNUMBER(H11)),IFERROR(M11/H11-1,""),"") -> 0.67354597 | N12: =IF(AND(ISNUMBER(N11),ISNUMBER(I11)),IFERROR(N11/I11-1,""),"") -> 0.64460512 | O12: =IF(AND(ISNUMBER(O11),ISNUMBER(J11)),IFERROR(O11/J11-1,""),"") -> 0.53327645 | P12: =IF(AND(ISNUMBER(P11),ISNUMBER(K11)),IFERROR(P11/K11-1,""),"") -> 0.64500429 | Q12: =IF(AND(ISNUMBER(Q11),ISNUMBER(L11)),IFERROR(Q11/L11-1,""),"") -> 0.46445916 | R12: =IF(AND(ISNUMBER(R11),ISNUMBER(M11)),IFERROR(R11/M11-1,""),"") -> 0.43011958 | ... BU12: =IF(AND(ISNUMBER(BU11),ISNUMBER(BP11)),IFERROR(BU11/BP11-1,""),"") -> 0.27489638 | BV12: =(1+BV13)*(1+BV14)-1 -> 0.21410781 | BW12: =(1+BW13)*(1+BW14)-1 -> 0.21410781 | BX12: =IF(AND(ISNUMBER(BX11),ISNUMBER(BS11)),IFERROR(BX11/BS11-1,""),"") -> 0.25284329 | BY12: =(1+BY13)*(1+BY14)-1 -> 0.188 | BZ12: =(1+BZ13)*(1+BZ14)-1 -> 0.1554 | CA12: =(1+CA13)*(1+CA14)-1 -> 0.134 | CB12: =(1+CB13)*(1+CB14)-1 -> 0.1128 | CC12: =(1+CC13)*(1+CC14)-1 -> 0.1024 | CF12: =IFERROR(AVERAGE(BY12,BZ12,CA12,CB12,CC12),"n/m") -> 0.13852 | CG12: =IFERROR(AVERAGE(AY12,BD12,BI12,BN12,BS12),"n/m") -> 0.19080331 | CH12: =IFERROR(AVERAGE(Z12,AE12,AJ12,AO12,AT12,AY12,BD12,BI12,BN12,BS12),"n/m") -> 0.28656803 | CI12: =IFERROR(AVERAGE(C12,D12,E12,F12,K12,P12,U12,Z12,AE12,AJ12,AO12,AT12,AY12,BD12,BI12,BN12,BS12),"n/m") -> 0.44497664 | CL12: Q3/26 total revenue ($m) | CM12: 64000 | CN12: 62500 | CO12: 61000 | CP12: Guided $61–64bn. Drives the Q3/26E price-per-ad calibration.
B13: Ad impressions delivered y/y % (company-reported, rounded) | L13: -0.17 | M13: -0.25 | N13: -0.56 | P13: -0.4 | Q13: -0.62 | R13: -0.55 | S13: -0.1 | U13: -0.38 | V13: 0.5 | W13: 0.49 | X13: 0.5 | Z13: 0.5 | AA13: 0.32 | AB13: 0.19 | AC13: 0.1 | AE13: 0.15 | AF13: 0.08 | AG13: 0.21 | AH13: 0.25 | AJ13: 0.22 | AK13: 0.32 | AL13: 0.33 | AM13: 0.37 | AO13: 0.33 | AP13: 0.39 | AQ13: 0.4 | AR13: 0.35 | AT13: 0.34 | AU13: 0.12 | AV13: 0.06 | AW13: 0.09 | AX13: 0.13 | AY13: 0.1 | AZ13: 0.15 | BA13: 0.15 | BB13: 0.17 | BC13: 0.23 | BD13: 0.18 | BE13: 0.26 | BF13: 0.34 | BG13: 0.31 | BH13: 0.21 | BI13: 0.28 | BJ13: 0.2 | BK13: 0.1 | BL13: 0.07 | BM13: 0.06 | BN13: 0.11 | BO13: 0.05 | BP13: 0.11 | BQ13: 0.14 | BR13: 0.18 | BS13: 0.12 | BT13: 0.19 | BU13: 0.14 | BV13: =BV15 -> 0.14 | BW13: =BW15 -> 0.14 | BY13: =CHOOSE(MATCH($CD$2,{"Bull","Base","Bear"},0),$CM$28,$CN$28,$CO$28) -> 0.1 | BZ13: =CHOOSE(MATCH($CD$2,{"Bull","Base","Bear"},0),$CM$29,$CN$29,$CO$29) -> 0.09 | CA13: =CHOOSE(MATCH($CD$2,{"Bull","Base","Bear"},0),$CM$30,$CN$30,$CO$30) -> 0.08 | CB13: =CHOOSE(MATCH($CD$2,{"Bull","Base","Bear"},0),$CM$31,$CN$31,$CO$31) -> 0.07 | CC13: =CHOOSE(MATCH($CD$2,{"Bull","Base","Bear"},0),$CM$32,$CN$32,$CO$32) -> 0.06 | CD13: Releases from Q4-2021; before that the 10-Q / 10-K MD&A ("number of ads delivered", 2014-21; Q4 not published, year from the 10-K). Q3/Q4-26E: Q2/26 y/y held. 2027E+: scenario lever. | CF13: =IFERROR(AVERAGE(BY13,BZ13,CA13,CB13,CC13),"n/m") -> 0.08 | CG13: =IFERROR(AVERAGE(AY13,BD13,BI13,BN13,BS13),"n/m") -> 0.158 | CH13: =IFERROR(AVERAGE(Z13,AE13,AJ13,AO13,AT13,AY13,BD13,BI13,BN13,BS13),"n/m") -> 0.233 | CI13: =IFERROR(AVERAGE(C13,D13,E13,F13,K13,P13,U13,Z13,AE13,AJ13,AO13,AT13,AY13,BD13,BI13,BN13,BS13),"n/m") -> 0.12916667 | CL13: FY26 total expenses ($m) — Bull = low end, Bear = high end | CM13: 165000 | CN13: 167000 | CO13: 169000 | CP13: Guided $165–169bn. Drives the 2H/26E other-operating-cost calibration (lower expenses in the Bull case).
B14: Average price per ad y/y % (company-reported, rounded) | L14: 1.18 | M14: 1.23 | N14: 2.74 | P14: 1.73 | Q14: 2.85 | R14: 2.2 | S14: 0.61 | U14: 1.4 | V14: 0.05 | W14: 0.09 | X14: 0.06 | Z14: 0.05 | AA14: 0.14 | AB14: 0.24 | AC14: 0.35 | AE14: 0.29 | AF14: 0.39 | AG14: 0.17 | AH14: 0.07 | AJ14: 0.13 | AK14: -0.04 | AL14: -0.04 | AM14: -0.06 | AO14: -0.05 | AP14: -0.16 | AQ14: -0.21 | AR14: -0.09 | AT14: -0.1 | AU14: 0.3 | AV14: 0.47 | AW14: 0.22 | AX14: 0.06 | AY14: 0.24 | AZ14: -0.08 | BA14: -0.14 | BB14: -0.18 | BC14: -0.22 | BD14: -0.16 | BE14: -0.17 | BF14: -0.16 | BG14: -0.06 | BH14: 0.02 | BI14: -0.09 | BJ14: 0.06 | BK14: 0.1 | BL14: 0.11 | BM14: 0.14 | BN14: 0.1 | BO14: 0.1 | BP14: 0.09 | BQ14: 0.1 | BR14: 0.06 | BS14: 0.09 | BT14: 0.12 | BU14: 0.12 | BV14: =BV16+$BV$77 -> 0.065006847 | BW14: =BW16+$BV$77 -> 0.065006847 | BY14: =CHOOSE(MATCH($CD$2,{"Bull","Base","Bear"},0),$CM$34,$CN$34,$CO$34) -> 0.08 | BZ14: =CHOOSE(MATCH($CD$2,{"Bull","Base","Bear"},0),$CM$35,$CN$35,$CO$35) -> 0.06 | CA14: =CHOOSE(MATCH($CD$2,{"Bull","Base","Bear"},0),$CM$36,$CN$36,$CO$36) -> 0.05 | CB14: =CHOOSE(MATCH($CD$2,{"Bull","Base","Bear"},0),$CM$37,$CN$37,$CO$37) -> 0.04 | CC14: =CHOOSE(MATCH($CD$2,{"Bull","Base","Bear"},0),$CM$38,$CN$38,$CO$38) -> 0.04 | CD14: Not disclosed 2019-Q3 2021 in some quarters. Q3/Q4-26E: Q2/26 y/y + revenue-guidance calibration Δ (solved in Q3, carried into Q4). 2027E+: scenario lever. | CF14: =IFERROR(AVERAGE(BY14,BZ14,CA14,CB14,CC14),"n/m") -> 0.054 | CG14: =IFERROR(AVERAGE(AY14,BD14,BI14,BN14,BS14),"n/m") -> 0.036 | CH14: =IFERROR(AVERAGE(Z14,AE14,AJ14,AO14,AT14,AY14,BD14,BI14,BN14,BS14),"n/m") -> 0.05 | CI14: =IFERROR(AVERAGE(C14,D14,E14,F14,K14,P14,U14,Z14,AE14,AJ14,AO14,AT14,AY14,BD14,BI14,BN14,BS14),"n/m") -> 0.3025 | CL14: 2H/26E share repurchases ($m) | CM14: 5000 | CN14: 0 | CO14: 0 | CP14: No repurchases in 1H/26 (Q4/25 none either) while capex is funded; $50bn+ authorization remaining (10-Q). Base / Bear nil, Bull $5bn (assumption).
B15: Q3/Q4-26E ad impressions growth (Q2/26 y/y, held) | BV15: =$BU$13 -> 0.14 | BW15: =$BU$13 -> 0.14
B16: Q3/Q4-26E price-per-ad growth before calibration (Q2/26 y/y, held) | BV16: =$BU$14 -> 0.12 | BW16: =$BU$14 -> 0.12 | CL16: Q3/26E, Q4/26E and FY26 point estimates (all cases)
B17: Memo: implied advertising growth = (1 + impressions) × (1 + price) − 1 | C17: =IF(AND(ISNUMBER(C13),ISNUMBER(C14)),(1+C13)*(1+C14)-1,"") | D17: =IF(AND(ISNUMBER(D13),ISNUMBER(D14)),(1+D13)*(1+D14)-1,"") | E17: =IF(AND(ISNUMBER(E13),ISNUMBER(E14)),(1+E13)*(1+E14)-1,"") | F17: =IF(AND(ISNUMBER(F13),ISNUMBER(F14)),(1+F13)*(1+F14)-1,"") | G17: =IF(AND(ISNUMBER(G13),ISNUMBER(G14)),(1+G13)*(1+G14)-1,"") | H17: =IF(AND(ISNUMBER(H13),ISNUMBER(H14)),(1+H13)*(1+H14)-1,"") | I17: =IF(AND(ISNUMBER(I13),ISNUMBER(I14)),(1+I13)*(1+I14)-1,"") | J17: =IF(AND(ISNUMBER(J13),ISNUMBER(J14)),(1+J13)*(1+J14)-1,"") | ... BU17: =IF(AND(ISNUMBER(BU13),ISNUMBER(BU14)),(1+BU13)*(1+BU14)-1,"") -> 0.2768 | CL17: Q3/Q4-26E D&A growth q/q | CN17: 0.07 | CP17: Q4/25 → Q1/26 +10.9%, Q1 → Q2/26 +6.0% (servers and data centers placed in service). Assumption.
B18: Memo: reported advertising growth − implied (rounding of the published whole-% figures; not a check) | D18: =IF(AND(ISNUMBER(D17),ISNUMBER(D12)),D12-D17,"") | E18: =IF(AND(ISNUMBER(E17),ISNUMBER(E12)),E12-E17,"") | F18: =IF(AND(ISNUMBER(F17),ISNUMBER(F12)),F12-F17,"") | K18: =IF(AND(ISNUMBER(K17),ISNUMBER(K12)),K12-K17,"") | L18: =IF(AND(ISNUMBER(L17),ISNUMBER(L12)),L12-L17,"") -> 0.0098771084 | M18: =IF(AND(ISNUMBER(M17),ISNUMBER(M12)),M12-M17,"") -> 0.0010459662 | N18: =IF(AND(ISNUMBER(N17),ISNUMBER(N12)),N12-N17,"") -> -0.0009948832 | O18: =IF(AND(ISNUMBER(O17),ISNUMBER(O12)),O12-O17,"") | P18: =IF(AND(ISNUMBER(P17),ISNUMBER(P12)),P12-P17,"") -> 0.0070042943 | Q18: =IF(AND(ISNUMBER(Q17),ISNUMBER(Q12)),Q12-Q17,"") -> 0.0014591611 | R18: =IF(AND(ISNUMBER(R17),ISNUMBER(R12)),R12-R17,"") -> -0.0098804185 | ... BU18: =IF(AND(ISNUMBER(BU17),ISNUMBER(BU12)),BU12-BU17,"") -> -0.001903623 | CL18: Q3/Q4-26E share-based compensation ($m) | CN18: 7658 | CP18: Q2/26 level held ($7,658m; Q1/26 $6,032m).
B19: Memo: advertising revenue excluding foreign-exchange effect (company non-GAAP) | F19: 4402 | H19: 1612 | I19: 1801 | J19: 2346 | K19: 7008 | M19: 2646 | N19: 2936 | O19: 3697 | P19: 11553 | Q19: 3505 | R19: 4159 | S19: 4641 | T19: 5959 | U19: 18264 | V19: 5403 | W19: 6240 | X19: 6847 | Y19: 8664 | Z19: 27154 | AA19: 7879 | AB19: 9305 | AC19: 10014 | AD19: 12452 | AE19: 39650 | AF19: 11260 | AG19: 12667 | AH19: 13698 | AI19: 16987 | AJ19: 54612 | AK19: 15415 | AL19: 17196 | AM19: 17678 | AN19: 21030 | AO19: 71319 | AP19: 17714 | AQ19: 18616 | AR19: 21112 | AS19: 26855 | AT19: 84298 | AU19: 24744 | AV19: 27605 | AW19: 28020 | AX19: 32945 | AY19: 113314 | AZ19: 27886 | BA19: 29407 | BB19: 29013 | BC19: 33231 | BD19: 119538 | BE19: 28907 | BF19: 31767 | BG19: 32998 | BH19: 37897 | BI19: 131569 | BJ19: 35530 | BK19: 38696 | BL19: 40423 | BM19: 46864 | BN19: 161513 | BO19: 42616 | BP19: 46643 | BQ19: 49673 | BR19: 57664 | BS19: 196595 | BT19: 53290 | BU19: 58670 | CL19: Q3/Q4-26E tax rate | CN19: 0.16 | CP19: Guided 15–17% for the remaining quarters of 2026 (mid-point).
B20: Advertising growth at constant currency % | D20: =IF(AND(ISNUMBER(D19),ISNUMBER(C11)),IFERROR(D19/C11-1,""),"") | E20: =IF(AND(ISNUMBER(E19),ISNUMBER(D11)),IFERROR(E19/D11-1,""),"") | F20: =IF(AND(ISNUMBER(F19),ISNUMBER(E11)),IFERROR(F19/E11-1,""),"") -> 0.39568802 | K20: =IF(AND(ISNUMBER(K19),ISNUMBER(F11)),IFERROR(K19/F11-1,""),"") -> 0.63776583 | L20: =IF(AND(ISNUMBER(L19),ISNUMBER(G11)),IFERROR(L19/G11-1,""),"") | M20: =IF(AND(ISNUMBER(M19),ISNUMBER(H11)),IFERROR(M19/H11-1,""),"") -> 0.65478424 | N20: =IF(AND(ISNUMBER(N19),ISNUMBER(I11)),IFERROR(N19/I11-1,""),"") -> 0.63292547 | O20: =IF(AND(ISNUMBER(O19),ISNUMBER(J11)),IFERROR(O19/J11-1,""),"") -> 0.57721843 | P20: =IF(AND(ISNUMBER(P19),ISNUMBER(K11)),IFERROR(P19/K11-1,""),"") -> 0.65373604 | Q20: =IF(AND(ISNUMBER(Q19),ISNUMBER(L11)),IFERROR(Q19/L11-1,""),"") -> 0.54746137 | R20: =IF(AND(ISNUMBER(R19),ISNUMBER(M11)),IFERROR(R19/M11-1,""),"") -> 0.55418535 | ... BU20: =IF(AND(ISNUMBER(BU19),ISNUMBER(BP11)),IFERROR(BU19/BP11-1,""),"") -> 0.26001332 | CL20: FY26 capital expenditures incl. finance-lease principal ($m) | CN20: 137500 | CP20: Guided $130–145bn (narrowed from $125–145bn); mid-point. 1H/26 $50.9bn.
B21: FX effect on advertising growth (pp) | D21: =IF(AND(ISNUMBER(D20),ISNUMBER(D12)),D12-D20,"") | E21: =IF(AND(ISNUMBER(E20),ISNUMBER(E12)),E12-E20,"") | F21: =IF(AND(ISNUMBER(F20),ISNUMBER(F12)),F12-F20,"") -> -0.038998098 | K21: =IF(AND(ISNUMBER(K20),ISNUMBER(K12)),K12-K20,"") -> -0.0051413882 | L21: =IF(AND(ISNUMBER(L20),ISNUMBER(L12)),L12-L20,"") | M21: =IF(AND(ISNUMBER(M20),ISNUMBER(M12)),M12-M20,"") -> 0.018761726 | N21: =IF(AND(ISNUMBER(N20),ISNUMBER(N12)),N12-N20,"") -> 0.011679644 | O21: =IF(AND(ISNUMBER(O20),ISNUMBER(O12)),O12-O20,"") -> -0.04394198 | P21: =IF(AND(ISNUMBER(P20),ISNUMBER(P12)),P12-P20,"") -> -0.0087317492 | Q21: =IF(AND(ISNUMBER(Q20),ISNUMBER(Q12)),Q12-Q20,"") -> -0.083002208 | R21: =IF(AND(ISNUMBER(R20),ISNUMBER(R12)),R12-R20,"") -> -0.12406577 | ... BU21: =IF(AND(ISNUMBER(BU20),ISNUMBER(BU12)),BU12-BU20,"") -> 0.014883062 | CL21: Q3/Q4-26E interest-income yield on cash and marketable securities | CN21: 0.04 | CP21: Q2/26 interest income $859m on ~$86bn average (~4.0%, 10-Q).
CL22: Q3/Q4-26E interest rate on debt, net of capitalized interest | CN22: 0.042 | CP22: Q2/26 interest expense $783m (notes $754m net of capitalized interest) on ~$71.5bn average notes (~4.2%, 10-Q).
B23: Other revenue — FoA other revenue (WhatsApp business messaging, Meta Verified; payments & other fees to 2017) · Reality Labs (Quest, AI glasses) | CD23: OTHER REVENUE — FoA other revenue and Reality Labs split from 2019 (segment recast in the Q4-2021 release); before that total non-advertising revenue only | CL23: Q3/Q4-26E dividend per share ($) | CN23: 0.525 | CP23: Quarterly $0.525 declared in 2025 and 2026 (XBRL).
B24: Family of Apps other revenue | AO24: 541 | AS24: 168 | AT24: 657 | AU24: 198 | AV24: 192 | AW24: 176 | AX24: 155 | AY24: 721 | AZ24: 215 | BA24: 218 | BB24: 192 | BC24: 184 | BD24: 808 | BE24: 205 | BF24: 225 | BG24: 293 | BH24: 334 | BI24: 1058 | BJ24: 380 | BK24: 389 | BL24: 434 | BM24: 519 | BN24: 1722 | BO24: 510 | BP24: 583 | BQ24: 690 | BR24: 801 | BS24: 2584 | BT24: 885 | BU24: 1007 | BV24: =BQ24*(1+BV25) -> 1194.4007 | BW24: =BR24*(1+BW25) -> 1386.5435 | BX24: =SUM(BT24:BW24) -> 4472.9442 | BY24: =BX24*(1+BY25) -> 6262.1219 | BZ24: =BY24*(1+BZ25) -> 8140.7584 | CA24: =BZ24*(1+CA25) -> 10175.948 | CB24: =CA24*(1+CB25) -> 12211.138 | CC24: =CB24*(1+CC25) -> 14042.808 | CF24: =IFERROR((CC24/BX24)^(1/5)-1,"n/m") -> 0.25710657 | CG24: =IFERROR((BS24/AT24)^(1/5)-1,"n/m") -> 0.31505958 | CH24: =IFERROR((BS24/U24)^(1/10)-1,"n/m") -> n/m | CI24: =IFERROR((BS24/C24)^(1/16)-1,"n/m") -> n/m
B25: y/y % | D25: =IF(AND(ISNUMBER(D24),ISNUMBER(C24)),IFERROR(D24/C24-1,""),"") | E25: =IF(AND(ISNUMBER(E24),ISNUMBER(D24)),IFERROR(E24/D24-1,""),"") | F25: =IF(AND(ISNUMBER(F24),ISNUMBER(E24)),IFERROR(F24/E24-1,""),"") | K25: =IF(AND(ISNUMBER(K24),ISNUMBER(F24)),IFERROR(K24/F24-1,""),"") | L25: =IF(AND(ISNUMBER(L24),ISNUMBER(G24)),IFERROR(L24/G24-1,""),"") | M25: =IF(AND(ISNUMBER(M24),ISNUMBER(H24)),IFERROR(M24/H24-1,""),"") | N25: =IF(AND(ISNUMBER(N24),ISNUMBER(I24)),IFERROR(N24/I24-1,""),"") | O25: =IF(AND(ISNUMBER(O24),ISNUMBER(J24)),IFERROR(O24/J24-1,""),"") | P25: =IF(AND(ISNUMBER(P24),ISNUMBER(K24)),IFERROR(P24/K24-1,""),"") | Q25: =IF(AND(ISNUMBER(Q24),ISNUMBER(L24)),IFERROR(Q24/L24-1,""),"") | R25: =IF(AND(ISNUMBER(R24),ISNUMBER(M24)),IFERROR(R24/M24-1,""),"") | ... BU25: =IF(AND(ISNUMBER(BU24),ISNUMBER(BP24)),IFERROR(BU24/BP24-1,""),"") -> 0.72727273 | BV25: =IFERROR(SUM(BT24:BU24)/SUM(BO24:BP24)-1,0) -> 0.73101555 | BW25: =IFERROR(SUM(BT24:BU24)/SUM(BO24:BP24)-1,0) -> 0.73101555 | BX25: =IF(AND(ISNUMBER(BX24),ISNUMBER(BS24)),IFERROR(BX24/BS24-1,""),"") -> 0.73101555 | BY25: =CHOOSE(MATCH($CD$2,{"Bull","Base","Bear"},0),$CM$40,$CN$40,$CO$40) -> 0.4 | BZ25: =CHOOSE(MATCH($CD$2,{"Bull","Base","Bear"},0),$CM$41,$CN$41,$CO$41) -> 0.3 | CA25: =CHOOSE(MATCH($CD$2,{"Bull","Base","Bear"},0),$CM$42,$CN$42,$CO$42) -> 0.25 | CB25: =CHOOSE(MATCH($CD$2,{"Bull","Base","Bear"},0),$CM$43,$CN$43,$CO$43) -> 0.2 | CC25: =CHOOSE(MATCH($CD$2,{"Bull","Base","Bear"},0),$CM$44,$CN$44,$CO$44) -> 0.15 | CD25: Q3/Q4-26E: 1H/26 y/y. 2027E+: scenario lever. | CL25: Maximum net debt / adjusted EBITDA before buybacks (x) — buyback ceiling 2027E+ | CM25: 0.5 | CN25: 0.25 | CO25: 0 | CP25: Meta moved from net cash ($22bn at YE2025, cash and marketable securities $81.6bn vs notes $58.7bn) to ~$6.6bn net cash at 30-Jun-2026 as capex outran operating cash flow. Ceiling (assumption) up to which surplus cash is returned via buybacks; above it, cash flow reduces debt. Bull = more buybacks.
B26: Reality Labs revenue | AO26: 501 | AS26: 717 | AT26: 1139 | AU26: 534 | AV26: 305 | AW26: 558 | AX26: 877 | AY26: 2274 | AZ26: 695 | BA26: 452 | BB26: 285 | BC26: 727 | BD26: 2159 | BE26: 339 | BF26: 276 | BG26: 210 | BH26: 1071 | BI26: 1896 | BJ26: 440 | BK26: 353 | BL26: 270 | BM26: 1083 | BN26: 2146 | BO26: 412 | BP26: 370 | BQ26: 470 | BR26: 955 | BS26: 2207 | BT26: 402 | BU26: 431 | BV26: =BQ26*(1+BV27) -> 500.65217 | BW26: =BR26*(1+BW27) -> 1017.2826 | BX26: =SUM(BT26:BW26) -> 2350.9348 | BY26: =BX26*(1+BY27) -> 2586.0283 | BZ26: =BY26*(1+BZ27) -> 2844.6311 | CA26: =BZ26*(1+CA27) -> 3129.0942 | CB26: =CA26*(1+CB27) -> 3442.0036 | CC26: =CB26*(1+CC27) -> 3786.204 | CF26: =IFERROR((CC26/BX26)^(1/5)-1,"n/m") -> 0.1 | CG26: =IFERROR((BS26/AT26)^(1/5)-1,"n/m") -> 0.14144692 | CH26: =IFERROR((BS26/U26)^(1/10)-1,"n/m") -> n/m | CI26: =IFERROR((BS26/C26)^(1/16)-1,"n/m") -> n/m
B27: y/y % | D27: =IF(AND(ISNUMBER(D26),ISNUMBER(C26)),IFERROR(D26/C26-1,""),"") | E27: =IF(AND(ISNUMBER(E26),ISNUMBER(D26)),IFERROR(E26/D26-1,""),"") | F27: =IF(AND(ISNUMBER(F26),ISNUMBER(E26)),IFERROR(F26/E26-1,""),"") | K27: =IF(AND(ISNUMBER(K26),ISNUMBER(F26)),IFERROR(K26/F26-1,""),"") | L27: =IF(AND(ISNUMBER(L26),ISNUMBER(G26)),IFERROR(L26/G26-1,""),"") | M27: =IF(AND(ISNUMBER(M26),ISNUMBER(H26)),IFERROR(M26/H26-1,""),"") | N27: =IF(AND(ISNUMBER(N26),ISNUMBER(I26)),IFERROR(N26/I26-1,""),"") | O27: =IF(AND(ISNUMBER(O26),ISNUMBER(J26)),IFERROR(O26/J26-1,""),"") | P27: =IF(AND(ISNUMBER(P26),ISNUMBER(K26)),IFERROR(P26/K26-1,""),"") | Q27: =IF(AND(ISNUMBER(Q26),ISNUMBER(L26)),IFERROR(Q26/L26-1,""),"") | R27: =IF(AND(ISNUMBER(R26),ISNUMBER(M26)),IFERROR(R26/M26-1,""),"") | ... BU27: =IF(AND(ISNUMBER(BU26),ISNUMBER(BP26)),IFERROR(BU26/BP26-1,""),"") -> 0.16486486 | BV27: =IFERROR(SUM(BT26:BU26)/SUM(BO26:BP26)-1,0) -> 0.065217391 | BW27: =IFERROR(SUM(BT26:BU26)/SUM(BO26:BP26)-1,0) -> 0.065217391 | BX27: =IF(AND(ISNUMBER(BX26),ISNUMBER(BS26)),IFERROR(BX26/BS26-1,""),"") -> 0.065217391 | BY27: =CHOOSE(MATCH($CD$2,{"Bull","Base","Bear"},0),$CM$46,$CN$46,$CO$46) -> 0.1 | BZ27: =CHOOSE(MATCH($CD$2,{"Bull","Base","Bear"},0),$CM$47,$CN$47,$CO$47) -> 0.1 | CA27: =CHOOSE(MATCH($CD$2,{"Bull","Base","Bear"},0),$CM$48,$CN$48,$CO$48) -> 0.1 | CB27: =CHOOSE(MATCH($CD$2,{"Bull","Base","Bear"},0),$CM$49,$CN$49,$CO$49) -> 0.1 | CC27: =CHOOSE(MATCH($CD$2,{"Bull","Base","Bear"},0),$CM$50,$CN$50,$CO$50) -> 0.1 | CD27: Q3/Q4-26E: 1H/26 y/y. 2027E+: scenario lever. | CL27: IMPR (ad impressions y/y) | CM27: 0.02 | CN27: Δ → | CO27: -0.04 | CP27: 1H/26 +19% / +14% (Q1 / Q2); FY25 +12%, FY24 +11%; Threads, WhatsApp Status and Reels add inventory; DAP growth ~3–4% p.a. Assumption.
B28: Total non-advertising revenue | C28: =IF(ISNUMBER(C24),C24+C26,IF(ISNUMBER(C11),C109-C11,"")) -> 13 | D28: =IF(ISNUMBER(D24),D24+D26,IF(ISNUMBER(D11),D109-D11,"")) -> 106 | E28: =IF(ISNUMBER(E24),E24+E26,IF(ISNUMBER(E11),E109-E11,"")) -> 557 | F28: =IF(ISNUMBER(F24),F24+F26,IF(ISNUMBER(F11),F109-F11,"")) -> 810 | G28: =IF(ISNUMBER(G24),G24+G26,IF(ISNUMBER(G11),G109-G11,"")) -> 213 | H28: =IF(ISNUMBER(H24),H24+H26,IF(ISNUMBER(H11),H109-H11,"")) -> 214 | I28: =IF(ISNUMBER(I24),I24+I26,IF(ISNUMBER(I11),I109-I11,"")) -> 218 | J28: =IF(ISNUMBER(J24),J24+J26,IF(ISNUMBER(J11),J109-J11,"")) -> 241 | ... BU28: =IF(ISNUMBER(BU24),BU24+BU26,IF(ISNUMBER(BU11),BU109-BU11,"")) -> 1438 | BV28: =BV24+BV26 -> 1695.0529 | BW28: =BW24+BW26 -> 2403.8261 | BX28: =SUM(BT28:BW28) -> 6823.879 | BY28: =BY24+BY26 -> 8848.1501 | BZ28: =BZ24+BZ26 -> 10985.39 | CA28: =CA24+CA26 -> 13305.042 | CB28: =CB24+CB26 -> 15653.141 | CC28: =CC24+CC26 -> 17829.012 | CD28: History: FoA other + Reality Labs where the segment split is published; otherwise revenue − advertising (payments and other fees, Oculus hardware). | CF28: =IFERROR((CC28/BX28)^(1/5)-1,"n/m") -> 0.2117672 | CG28: =IFERROR((BS28/AT28)^(1/5)-1,"n/m") -> 0.21681336 | CH28: =IFERROR((BS28/U28)^(1/10)-1,"n/m") -> 0.18891785 | CI28: =IFERROR((BS28/C28)^(1/16)-1,"n/m") -> 0.44678893 | CL28: 2027E | CM28: =CN28+$CM$27 -> 0.12 | CN28: 0.1 | CO28: =CN28+$CO$27 -> 0.06
B29: y/y % | D29: =IF(AND(ISNUMBER(D28),ISNUMBER(C28)),IFERROR(D28/C28-1,""),"") -> 7.1538462 | E29: =IF(AND(ISNUMBER(E28),ISNUMBER(D28)),IFERROR(E28/D28-1,""),"") -> 4.254717 | F29: =IF(AND(ISNUMBER(F28),ISNUMBER(E28)),IFERROR(F28/E28-1,""),"") -> 0.45421903 | K29: =IF(AND(ISNUMBER(K28),ISNUMBER(F28)),IFERROR(K28/F28-1,""),"") -> 0.09382716 | L29: =IF(AND(ISNUMBER(L28),ISNUMBER(G28)),IFERROR(L28/G28-1,""),"") -> 0.11267606 | M29: =IF(AND(ISNUMBER(M28),ISNUMBER(H28)),IFERROR(M28/H28-1,""),"") -> 0.093457944 | N29: =IF(AND(ISNUMBER(N28),ISNUMBER(I28)),IFERROR(N28/I28-1,""),"") -> 0.12844037 | O29: =IF(AND(ISNUMBER(O28),ISNUMBER(J28)),IFERROR(O28/J28-1,""),"") -> 0.066390041 | P29: =IF(AND(ISNUMBER(P28),ISNUMBER(K28)),IFERROR(P28/K28-1,""),"") -> 0.099322799 | Q29: =IF(AND(ISNUMBER(Q28),ISNUMBER(L28)),IFERROR(Q28/L28-1,""),"") -> -0.046413502 | R29: =IF(AND(ISNUMBER(R28),ISNUMBER(M28)),IFERROR(R28/M28-1,""),"") -> -0.081196581 | ... BX29: =IF(AND(ISNUMBER(BX28),ISNUMBER(BS28)),IFERROR(BX28/BS28-1,""),"") -> 0.42431204 | BY29: =IF(AND(ISNUMBER(BY28),ISNUMBER(BX28)),IFERROR(BY28/BX28-1,""),"") -> 0.29664523 | BZ29: =IF(AND(ISNUMBER(BZ28),ISNUMBER(BY28)),IFERROR(BZ28/BY28-1,""),"") -> 0.24154647 | CA29: =IF(AND(ISNUMBER(CA28),ISNUMBER(BZ28)),IFERROR(CA28/BZ28-1,""),"") -> 0.21115799 | CB29: =IF(AND(ISNUMBER(CB28),ISNUMBER(CA28)),IFERROR(CB28/CA28-1,""),"") -> 0.17648189 | CC29: =IF(AND(ISNUMBER(CC28),ISNUMBER(CB28)),IFERROR(CC28/CB28-1,""),"") -> 0.13900539 | CL29: 2028E | CM29: =CN29+$CM$27 -> 0.11 | CN29: 0.09 | CO29: =CN29+$CO$27 -> 0.05
B30: Contribution to revenue growth — advertising (pp) | D30: =IFERROR((D11-C11)/C109,"") -> 1.4208494 | E30: =IFERROR((E11-D11)/D109,"") -> 0.6514691 | F30: =IFERROR((F11-E11)/E109,"") -> 0.30315279 | K30: =IFERROR((K11-F11)/F109,"") -> 0.53193162 | L30: =IFERROR((L11-G11)/G109,"") -> 0.69958848 | M30: =IFERROR((M11-H11)/H109,"") -> 0.59404302 | N30: =IFERROR((N11-I11)/I109,"") -> 0.57490079 | O30: =IFERROR((O11-J11)/J109,"") -> 0.48355899 | P30: =IFERROR((P11-K11)/K109,"") -> 0.57240854 | Q30: =IFERROR((Q11-L11)/L109,"") -> 0.42046363 | R30: =IFERROR((R11-M11)/M109,"") -> 0.39553265 | ... BX30: =IFERROR((BX11-BS11)/BS109,"") -> 0.24681554 | BY30: =IFERROR((BY11-BX11)/BX109,"") -> 0.18292127 | BZ30: =IFERROR((BZ11-BY11)/BY109,"") -> 0.15082931 | CA30: =IFERROR((CA11-BZ11)/BZ109,"") -> 0.12977415 | CB30: =IFERROR((CB11-CA11)/CA109,"") -> 0.10900881 | CC30: =IFERROR((CC11-CB11)/CB109,"") -> 0.098768383 | CL30: 2029E | CM30: =CN30+$CM$27 -> 0.1 | CN30: 0.08 | CO30: =CN30+$CO$27 -> 0.04
B31: Contribution to revenue growth — other revenue (pp) | D31: =IFERROR((D28-C28)/C109,"") -> 0.11969112 | E31: =IFERROR((E28-D28)/D109,"") -> 0.22847011 | F31: =IFERROR((F28-E28)/E109,"") -> 0.068175694 | K31: =IFERROR((K28-F28)/F109,"") -> 0.014934172 | L31: =IFERROR((L28-G28)/G109,"") -> 0.016460905 | M31: =IFERROR((M28-H28)/H109,"") -> 0.01103144 | N31: =IFERROR((N28-I28)/I109,"") -> 0.013888889 | O31: =IFERROR((O28-J28)/J109,"") -> 0.0061895551 | P31: =IFERROR((P28-K28)/K109,"") -> 0.011178862 | Q31: =IFERROR((Q28-L28)/L109,"") -> -0.0043964828 | R31: =IFERROR((R28-M28)/M109,"") -> -0.0065292096 | ... BX31: =IFERROR((BX28-BS28)/BS109,"") -> 0.010115537 | BY31: =IFERROR((BY28-BX28)/BX109,"") -> 0.0080137286 | BZ31: =IFERROR((BZ28-BY28)/BY109,"") -> 0.0071044597 | CA31: =IFERROR((CA28-BZ28)/BZ109,"") -> 0.0066591245 | CB31: =IFERROR((CB28-CA28)/CA109,"") -> 0.0059315287 | CC31: =IFERROR((CC28-CB28)/CB109,"") -> 0.0049298277 | CL31: 2030E | CM31: =CN31+$CM$27 -> 0.09 | CN31: 0.07 | CO31: =CN31+$CO$27 -> 0.03
CL32: 2031E | CM32: =CN32+$CM$27 -> 0.08 | CN32: 0.06 | CO32: =CN32+$CO$27 -> 0.02
B33: Segment results — Family of Apps · Reality Labs (first presented in the Q4-2021 release; FY2019-20, Q4-2020 and 2021 quarters recast) | CD33: SEGMENTS — FoA income = consolidated income from operations − Reality Labs result (forecast) | CL33: PRICE (average price per ad y/y) | CM33: 0.02 | CN33: Δ → | CO33: -0.04 | CP33: 1H/26 +12% (both quarters); FY25 +9%, FY24 +10%; AI ranking and ad-format gains vs mix shift to lower-monetizing geographies. Assumption.
B34: Family of Apps revenue | AO34: 70196 | AS34: 27355 | AT34: 84826 | AU34: 25637 | AV34: 28772 | AW34: 28452 | AX34: 32794 | AY34: 115655 | AZ34: 27213 | BA34: 28370 | BB34: 27429 | BC34: 31438 | BD34: 114450 | BE34: 28306 | BF34: 31723 | BG34: 33936 | BH34: 39040 | BI34: 133006 | BJ34: 36015 | BK34: 38718 | BL34: 40319 | BM34: 47302 | BN34: 162355 | BO34: 41902 | BP34: 47146 | BQ34: 50772 | BR34: 58938 | BS34: 198759 | BT34: 55909 | BU34: 60370 | BV34: =BV11+BV24 -> 61999.348 | BW34: =BW11+BW24 -> 71971.129 | BX34: =SUM(BT34:BW34) -> 250249.48 | BY34: =BY11+BY24 -> 298244.64 | BZ34: =BZ11+BZ24 -> 345497.36 | CA34: =CA11+CA24 -> 392738.34 | CB34: =CB11+CB24 -> 437926.56 | CC34: =CC11+CC24 -> 483351.49 | CF34: =IFERROR((CC34/BX34)^(1/5)-1,"n/m") -> 0.14071717 | CG34: =IFERROR((BS34/AT34)^(1/5)-1,"n/m") -> 0.18565835 | CH34: =IFERROR((BS34/U34)^(1/10)-1,"n/m") -> n/m | CI34: =IFERROR((BS34/C34)^(1/16)-1,"n/m") -> n/m | CL34: 2027E | CM34: =CN34+$CM$33 -> 0.1 | CN34: 0.08 | CO34: =CN34+$CO$33 -> 0.04
B35: y/y % | D35: =IF(AND(ISNUMBER(D34),ISNUMBER(C34)),IFERROR(D34/C34-1,""),"") | E35: =IF(AND(ISNUMBER(E34),ISNUMBER(D34)),IFERROR(E34/D34-1,""),"") | F35: =IF(AND(ISNUMBER(F34),ISNUMBER(E34)),IFERROR(F34/E34-1,""),"") | K35: =IF(AND(ISNUMBER(K34),ISNUMBER(F34)),IFERROR(K34/F34-1,""),"") | L35: =IF(AND(ISNUMBER(L34),ISNUMBER(G34)),IFERROR(L34/G34-1,""),"") | M35: =IF(AND(ISNUMBER(M34),ISNUMBER(H34)),IFERROR(M34/H34-1,""),"") | N35: =IF(AND(ISNUMBER(N34),ISNUMBER(I34)),IFERROR(N34/I34-1,""),"") | O35: =IF(AND(ISNUMBER(O34),ISNUMBER(J34)),IFERROR(O34/J34-1,""),"") | P35: =IF(AND(ISNUMBER(P34),ISNUMBER(K34)),IFERROR(P34/K34-1,""),"") | Q35: =IF(AND(ISNUMBER(Q34),ISNUMBER(L34)),IFERROR(Q34/L34-1,""),"") | R35: =IF(AND(ISNUMBER(R34),ISNUMBER(M34)),IFERROR(R34/M34-1,""),"") | ... BX35: =IF(AND(ISNUMBER(BX34),ISNUMBER(BS34)),IFERROR(BX34/BS34-1,""),"") -> 0.25905985 | BY35: =IF(AND(ISNUMBER(BY34),ISNUMBER(BX34)),IFERROR(BY34/BX34-1,""),"") -> 0.19178928 | BZ35: =IF(AND(ISNUMBER(BZ34),ISNUMBER(BY34)),IFERROR(BZ34/BY34-1,""),"") -> 0.15843611 | CA35: =IF(AND(ISNUMBER(CA34),ISNUMBER(BZ34)),IFERROR(CA34/BZ34-1,""),"") -> 0.13673324 | CB35: =IF(AND(ISNUMBER(CB34),ISNUMBER(CA34)),IFERROR(CB34/CA34-1,""),"") -> 0.11505937 | CC35: =IF(AND(ISNUMBER(CC34),ISNUMBER(CB34)),IFERROR(CC34/CB34-1,""),"") -> 0.10372728 | CL35: 2028E | CM35: =CN35+$CM$33 -> 0.08 | CN35: 0.06 | CO35: =CN35+$CO$33 -> 0.02
B36: Family of Apps income from operations | AO36: 28489 | AS36: 14874 | AT36: 39294 | AU36: 13205 | AV36: 14799 | AW36: 13054 | AX36: 15889 | AY36: 56946 | AZ36: 11484 | BA36: 11164 | BB36: 9336 | BC36: 10678 | BD36: 42661 | BE36: 11219 | BF36: 13131 | BG36: 17490 | BH36: 21030 | BI36: 62871 | BJ36: 17664 | BK36: 19335 | BL36: 21778 | BM36: 28332 | BN36: 87109 | BO36: 21765 | BP36: 24971 | BQ36: 24967 | BR36: 30766 | BS36: 102469 | BT36: 26900 | BU36: 23394 | BV36: =BV116-BV38 -> 24203.719 | BW36: =BW116-BW38 -> 30091.465 | BX36: =SUM(BT36:BW36) -> 104589.18 | BY36: =BY116-BY38 -> 122233.46 | BZ36: =BZ116-BZ38 -> 138615.08 | CA36: =CA116-CA38 -> 153765.02 | CB36: =CB116-CB38 -> 173014.51 | CC36: =CC116-CC38 -> 192281.07 | CD36: Forecast: consolidated income from operations − Reality Labs operating loss (FoA carries all one-off items in the forecast). | CF36: =IFERROR((CC36/BX36)^(1/5)-1,"n/m") -> 0.12950966 | CG36: =IFERROR((BS36/AT36)^(1/5)-1,"n/m") -> 0.21130428 | CH36: =IFERROR((BS36/U36)^(1/10)-1,"n/m") -> n/m | CI36: =IFERROR((BS36/C36)^(1/16)-1,"n/m") -> n/m | CL36: 2029E | CM36: =CN36+$CM$33 -> 0.07 | CN36: 0.05 | CO36: =CN36+$CO$33 -> 0.01
B37: FoA operating margin % | C37: =IF(AND(ISNUMBER(C36),ISNUMBER(C34)),IFERROR(C36/C34,""),"") | D37: =IF(AND(ISNUMBER(D36),ISNUMBER(D34)),IFERROR(D36/D34,""),"") | E37: =IF(AND(ISNUMBER(E36),ISNUMBER(E34)),IFERROR(E36/E34,""),"") | F37: =IF(AND(ISNUMBER(F36),ISNUMBER(F34)),IFERROR(F36/F34,""),"") | G37: =IF(AND(ISNUMBER(G36),ISNUMBER(G34)),IFERROR(G36/G34,""),"") | H37: =IF(AND(ISNUMBER(H36),ISNUMBER(H34)),IFERROR(H36/H34,""),"") | I37: =IF(AND(ISNUMBER(I36),ISNUMBER(I34)),IFERROR(I36/I34,""),"") | J37: =IF(AND(ISNUMBER(J36),ISNUMBER(J34)),IFERROR(J36/J34,""),"") | ... CC37: =IF(AND(ISNUMBER(CC36),ISNUMBER(CC34)),IFERROR(CC36/CC34,""),"") -> 0.39780795 | CF37: =IFERROR(AVERAGE(BY37,BZ37,CA37,CB37,CC37),"n/m") -> 0.39909043 | CG37: =IFERROR(AVERAGE(AY37,BD37,BI37,BN37,BS37),"n/m") -> 0.47797943 | CH37: =IFERROR(AVERAGE(Z37,AE37,AJ37,AO37,AT37,AY37,BD37,BI37,BN37,BS37),"n/m") -> 0.46556816 | CI37: =IFERROR(AVERAGE(C37,D37,E37,F37,K37,P37,U37,Z37,AE37,AJ37,AO37,AT37,AY37,BD37,BI37,BN37,BS37),"n/m") -> 0.46556816 | CL37: 2030E | CM37: =CN37+$CM$33 -> 0.06 | CN37: 0.04 | CO37: =CN37+$CO$33 -> 0
B38: Reality Labs income (loss) from operations | AO38: -4503 | AS38: -2099 | AT38: -6623 | AU38: -1827 | AV38: -2432 | AW38: -2631 | AX38: -3304 | AY38: -10193 | AZ38: -2960 | BA38: -2806 | BB38: -3672 | BC38: -4279 | BD38: -13717 | BE38: -3992 | BF38: -3739 | BG38: -3742 | BH38: -4646 | BI38: -16120 | BJ38: -3846 | BK38: -4488 | BL38: -4428 | BM38: -4967 | BN38: -17729 | BO38: -4210 | BP38: -4530 | BQ38: -4432 | BR38: -6021 | BS38: -19193 | BT38: -4028 | BU38: -4619 | BV38: =BQ38*IFERROR(SUM(BT38:BU38)/SUM(BO38:BP38),1) -> -4384.8403 | BW38: =BR38*IFERROR(SUM(BT38:BU38)/SUM(BO38:BP38),1) -> -5956.9322 | BX38: =SUM(BT38:BW38) -> -18988.772 | BY38: =-CHOOSE(MATCH($CD$2,{"Bull","Base","Bear"},0),$CM$52,$CN$52,$CO$52) -> -20000 | BZ38: =-CHOOSE(MATCH($CD$2,{"Bull","Base","Bear"},0),$CM$53,$CN$53,$CO$53) -> -19500 | CA38: =-CHOOSE(MATCH($CD$2,{"Bull","Base","Bear"},0),$CM$54,$CN$54,$CO$54) -> -19000 | CB38: =-CHOOSE(MATCH($CD$2,{"Bull","Base","Bear"},0),$CM$55,$CN$55,$CO$55) -> -18000 | CC38: =-CHOOSE(MATCH($CD$2,{"Bull","Base","Bear"},0),$CM$56,$CN$56,$CO$56) -> -17000 | CD38: Q3/Q4-26E: prior-year quarter × 1H/26 ÷ 1H/25 loss ratio. 2027E+: scenario lever (operating loss, $m). | CL38: 2031E | CM38: =CN38+$CM$33 -> 0.06 | CN38: 0.04 | CO38: =CN38+$CO$33 -> 0
B39: y/y % | D39: =IF(AND(ISNUMBER(D38),ISNUMBER(C38)),IFERROR(D38/C38-1,""),"") | E39: =IF(AND(ISNUMBER(E38),ISNUMBER(D38)),IFERROR(E38/D38-1,""),"") | F39: =IF(AND(ISNUMBER(F38),ISNUMBER(E38)),IFERROR(F38/E38-1,""),"") | K39: =IF(AND(ISNUMBER(K38),ISNUMBER(F38)),IFERROR(K38/F38-1,""),"") | L39: =IF(AND(ISNUMBER(L38),ISNUMBER(G38)),IFERROR(L38/G38-1,""),"") | M39: =IF(AND(ISNUMBER(M38),ISNUMBER(H38)),IFERROR(M38/H38-1,""),"") | N39: =IF(AND(ISNUMBER(N38),ISNUMBER(I38)),IFERROR(N38/I38-1,""),"") | O39: =IF(AND(ISNUMBER(O38),ISNUMBER(J38)),IFERROR(O38/J38-1,""),"") | P39: =IF(AND(ISNUMBER(P38),ISNUMBER(K38)),IFERROR(P38/K38-1,""),"") | Q39: =IF(AND(ISNUMBER(Q38),ISNUMBER(L38)),IFERROR(Q38/L38-1,""),"") | R39: =IF(AND(ISNUMBER(R38),ISNUMBER(M38)),IFERROR(R38/M38-1,""),"") | ... BX39: =IF(AND(ISNUMBER(BX38),ISNUMBER(BS38)),IFERROR(BX38/BS38-1,""),"") -> -0.010640732 | BY39: =IF(AND(ISNUMBER(BY38),ISNUMBER(BX38)),IFERROR(BY38/BX38-1,""),"") -> 0.053253973 | BZ39: =IF(AND(ISNUMBER(BZ38),ISNUMBER(BY38)),IFERROR(BZ38/BY38-1,""),"") -> -0.025 | CA39: =IF(AND(ISNUMBER(CA38),ISNUMBER(BZ38)),IFERROR(CA38/BZ38-1,""),"") -> -0.025641026 | CB39: =IF(AND(ISNUMBER(CB38),ISNUMBER(CA38)),IFERROR(CB38/CA38-1,""),"") -> -0.052631579 | CC39: =IF(AND(ISNUMBER(CC38),ISNUMBER(CB38)),IFERROR(CC38/CB38-1,""),"") -> -0.055555556 | CL39: FOTH (FoA other revenue y/y) | CM39: 0.1 | CN39: Δ → | CO39: -0.15 | CP39: 1H/26 +73%; FY25 +50% (WhatsApp business messaging, Meta Verified subscriptions). Assumption.
B40: Check: segment revenue vs consolidated revenue (should be 0) | C40: =IF(ISNUMBER(C34),ROUND(C34+C26-C109,1),"") | D40: =IF(ISNUMBER(D34),ROUND(D34+D26-D109,1),"") | E40: =IF(ISNUMBER(E34),ROUND(E34+E26-E109,1),"") | F40: =IF(ISNUMBER(F34),ROUND(F34+F26-F109,1),"") | G40: =IF(ISNUMBER(G34),ROUND(G34+G26-G109,1),"") | H40: =IF(ISNUMBER(H34),ROUND(H34+H26-H109,1),"") | I40: =IF(ISNUMBER(I34),ROUND(I34+I26-I109,1),"") | J40: =IF(ISNUMBER(J34),ROUND(J34+J26-J109,1),"") | ... BU40: =IF(ISNUMBER(BU34),ROUND(BU34+BU26-BU109,1),"") -> 0 | CL40: 2027E | CM40: =CN40+$CM$39 -> 0.5 | CN40: 0.4 | CO40: =CN40+$CO$39 -> 0.25
...

Sheet Bull-Base-Bear
B2: Meta Platforms, Inc. (META) — Bull / Base / Bear Case P&L Summary | J2: Share price ($): | K2: =Model!$BY$371 -> 745
B3: Adjusted figures (current definition: GAAP + company-quantified one-offs, share-based compensation expensed; adjusted EBITDA = model definition) · USD millions · Live panel linked to Model — toggle scenario via Model!CD2. Bull and Bear panels are value snapshots generated from the Model with the switch set to each case. 2026E = Q1–Q2 actual + Q3 calibrated to revenue guidance ($61–64bn) and 2H to FY26 expense guidance ($165–169bn). | J3: As of: | K3: =TODAY() -> 2026-10-13 00:00:00
B5: Scenario: | C5: =Model!$CD$2 -> Base | N5: Scenario: | O5: Bull | P5: Snapshot (values) — Model run with switch = Bull | Z5: Scenario: | AA5: Bear | AB5: Snapshot (values) — Model run with switch = Bear
B7: (USDm, except EPS and shares) | C7: 2026E | D7: 2027E | E7: 2028E | F7: 2029E | G7: 2030E | H7: 2031E | I7: 26-'31 CAGR | J7: LT Hist Avg | K7: LT Hist Min | L7: LT Hist Max | N7: (USDm, except EPS and shares) | O7: 2026E | P7: 2027E | Q7: 2028E | R7: 2029E | S7: 2030E | T7: 2031E | U7: 26-'31 CAGR | V7: LT Hist Avg | W7: LT Hist Min | X7: LT Hist Max | Z7: (USDm, except EPS and shares) | AA7: 2026E | AB7: 2027E | AC7: 2028E | AD7: 2029E | AE7: 2030E | AF7: 2031E | AG7: 26-'31 CAGR | AH7: LT Hist Avg | AI7: LT Hist Min | AJ7: LT Hist Max
B9: Revenue | C9: =Model!BX109 -> 252600.41 | D9: =Model!BY109 -> 300830.67 | E9: =Model!BZ109 -> 348341.99 | F9: =Model!CA109 -> 395867.43 | G9: =Model!CB109 -> 441368.57 | H9: =Model!CC109 -> 487137.7 | I9: =IFERROR((H9/C9)^(1/5)-1,"n/m") -> 0.1403641 | N9: Revenue | O9: 255841.67 | P9: 316320.45 | Q9: 380558.28 | R9: 449619.98 | S9: 521505.75 | T9: 599023.1 | U9: 0.18548062 | Z9: Revenue | AA9: 249359.16 | AB9: 275313.01 | AC9: 295135.02 | AD9: 310210.25 | AE9: 319587.49 | AF9: 325783.69 | AG9: 0.054923104
B10: Revenue y/y % | D10: =IFERROR(D9/C9-1,"") -> 0.190935 | E10: =IFERROR(E9/D9-1,"") -> 0.15793377 | F10: =IFERROR(F9/E9-1,"") -> 0.13643327 | G10: =IFERROR(G9/F9-1,"") -> 0.11494034 | H10: =IFERROR(H9/G9-1,"") -> 0.10369821 | N10: Revenue y/y % | P10: 0.23639146 | Q10: 0.20307832 | R10: 0.1814747 | S10: 0.15988118 | T10: 0.14864142 | Z10: Revenue y/y % | AB10: 0.1040822 | AC10: 0.071998089 | AD10: 0.051079126 | AE10: 0.030228648 | AF10: 0.019388122
B11: Advertising revenue y/y % | C11: =Model!BX201 -> 0.25284329 | D11: =Model!BY201 -> 0.188 | E11: =Model!BZ201 -> 0.1554 | F11: =Model!CA201 -> 0.134 | G11: =Model!CB201 -> 0.1128 | H11: =Model!CC201 -> 0.1024 | N11: Advertising revenue y/y % | O11: 0.26936555 | P11: 0.232 | Q11: 0.1988 | R11: 0.177 | S11: 0.1554 | T11: 0.1448 | Z11: Advertising revenue y/y % | AA11: 0.23632103 | AB11: 0.1024 | AC11: 0.071 | AD11: 0.0504 | AE11: 0.03 | AF11: 0.02
B12: Adjusted EBITDA (model definition) | C12: =Model!BX168 -> 115613.32 | D12: =Model!BY168 -> 142894.57 | E12: =Model!BZ168 -> 170687.58 | F12: =Model!CA168 -> 197933.72 | G12: =Model!CB168 -> 225097.97 | H12: =Model!CC168 -> 250875.91 | I12: =IFERROR((H12/C12)^(1/5)-1,"n/m") -> 0.16758961 | N12: Adjusted EBITDA (model definition) | O12: 120854.57 | P12: 156578.62 | Q12: 194084.72 | R12: 233802.39 | S12: 276398.05 | T12: 320477.36 | U12: 0.21536536 | Z12: Adjusted EBITDA (model definition) | AA12: 110372.06 | AB12: 122514.29 | AC12: 135762.11 | AD12: 145798.82 | AE12: 153402 | AF12: 158005.09 | AG12: 0.074391058
B13: Adjusted EBITDA margin % | C13: =IFERROR(C12/C9,"") -> 0.45769251 | D13: =IFERROR(D12/D9,"") -> 0.475 | E13: =IFERROR(E12/E9,"") -> 0.49 | F13: =IFERROR(F12/F9,"") -> 0.5 | G13: =IFERROR(G12/G9,"") -> 0.51 | H13: =IFERROR(H12/H9,"") -> 0.515 | J13: =IFERROR(AVERAGE(Model!C169,Model!D169,Model!E169,Model!F169,Model!K169,Model!P169,Model!U169,Model!Z169,Model!AE169,Model!AJ169,Model!AO169,Model!AT169,Model!AY169,Model!BD169,Model!BI169,Model!BN169,Model!BS169),"") -> 0.47964081 | K13: =IFERROR(MIN(Model!C169,Model!D169,Model!E169,Model!F169,Model!K169,Model!P169,Model!U169,Model!Z169,Model!AE169,Model!AJ169,Model!AO169,Model!AT169,Model!AY169,Model!BD169,Model!BI169,Model!BN169,Model!BS169),"") -> 0.23324818 | L13: =IFERROR(MAX(Model!C169,Model!D169,Model!E169,Model!F169,Model!K169,Model!P169,Model!U169,Model!Z169,Model!AE169,Model!AJ169,Model!AO169,Model!AT169,Model!AY169,Model!BD169,Model!BI169,Model!BN169,Model!BS169),"") -> 0.59321175 | N13: Adjusted EBITDA margin % | O13: 0.47238033 | P13: 0.495 | Q13: 0.51 | R13: 0.52 | S13: 0.53 | T13: 0.535 | V13: 0.47964081 | W13: 0.23324818 | X13: 0.59321175 | Z13: Adjusted EBITDA margin % | AA13: 0.44262285 | AB13: 0.445 | AC13: 0.46 | AD13: 0.47 | AE13: 0.48 | AF13: 0.485 | AH13: 0.47964081 | AI13: 0.23324818 | AJ13: 0.59321175
B15: Income from operations (GAAP) | C15: =Model!BX116 -> 85600.412 | D15: =Model!BY116 -> 102233.46 | E15: =Model!BZ116 -> 119115.08 | F15: =Model!CA116 -> 134765.02 | G15: =Model!CB116 -> 155014.51 | H15: =Model!CC116 -> 175281.07 | I15: =IFERROR((H15/C15)^(1/5)-1,"n/m") -> 0.1541223 | N15: Income from operations (GAAP) | O15: 90841.666 | P15: 116171.53 | Q15: 143100.72 | R15: 171318.18 | S15: 206869 | T15: 245132.4 | U15: 0.21961603 | Z15: Income from operations (GAAP) | AA15: 80359.157 | AB15: 81766.667 | AC15: 84354.252 | AD15: 83787.582 | AE15: 85944.051 | AF15: 86903.045 | AG15: 0.015780624
B16: Income from operations y/y % | D16: =IFERROR(D15/C15-1,"") -> 0.1943104 | E16: =IFERROR(E15/D15-1,"") -> 0.16512809 | F16: =IFERROR(F15/E15-1,"") -> 0.1313851 | G16: =IFERROR(G15/F15-1,"") -> 0.15025769 | H16: =IFERROR(H15/G15-1,"") -> 0.13073978 | N16: Income from operations y/y % | P16: 0.27883532 | Q16: 0.23180538 | R16: 0.19718601 | S16: 0.20751342 | T16: 0.18496442 | Z16: Income from operations y/y % | AB16: 0.017515241 | AC16: 0.031645965 | AD16: -0.0067177477 | AE16: 0.025737336 | AF16: 0.011158356
B17: Operating margin (GAAP) % | C17: =IFERROR(C15/C9,"") -> 0.33887677 | D17: =IFERROR(D15/D9,"") -> 0.33983723 | E17: =IFERROR(E15/E9,"") -> 0.34194866 | F17: =IFERROR(F15/F9,"") -> 0.34042968 | G17: =IFERROR(G15/G9,"") -> 0.35121329 | H17: =IFERROR(H15/H9,"") -> 0.35981832 | J17: =IFERROR(AVERAGE(Model!C214,Model!D214,Model!E214,Model!F214,Model!K214,Model!P214,Model!U214,Model!Z214,Model!AE214,Model!AJ214,Model!AO214,Model!AT214,Model!AY214,Model!BD214,Model!BI214,Model!BN214,Model!BS214),"") -> 0.38131634 | K17: =IFERROR(MIN(Model!C214,Model!D214,Model!E214,Model!F214,Model!K214,Model!P214,Model!U214,Model!Z214,Model!AE214,Model!AJ214,Model!AO214,Model!AT214,Model!AY214,Model!BD214,Model!BI214,Model!BN214,Model!BS214),"") -> 0.10571822 | L17: =IFERROR(MAX(Model!C214,Model!D214,Model!E214,Model!F214,Model!K214,Model!P214,Model!U214,Model!Z214,Model!AE214,Model!AJ214,Model!AO214,Model!AT214,Model!AY214,Model!BD214,Model!BI214,Model!BN214,Model!BS214),"") -> 0.52279635 | N17: Operating margin (GAAP) % | O17: 0.35506987 | P17: 0.36725899 | Q17: 0.37602839 | R17: 0.38102884 | S17: 0.39667635 | T17: 0.40922028 | V17: 0.38131634 | W17: 0.10571822 | X17: 0.52279635 | Z17: Operating margin (GAAP) % | AA17: 0.32226271 | AB17: 0.29699529 | AC17: 0.28581581 | AD17: 0.27009933 | AE17: 0.26892182 | AF17: 0.26675075 | AH17: 0.38131634 | AI17: 0.10571822 | AJ17: 0.52279635
B19: Adjusted net income (current definition) | C19: =Model!BX192 -> 74577.344 | D19: =Model!BY192 -> 84127.364 | E19: =Model!BZ192 -> 97359.247 | F19: =Model!CA192 -> 110612.77 | G19: =Model!CB192 -> 126479.06 | H19: =Model!CC192 -> 143129.45 | I19: =IFERROR((H19/C19)^(1/5)-1,"n/m") -> 0.13926412 | N19: Adjusted net income (current definition) | O19: 78979.998 | P19: 95820.904 | Q19: 116349.77 | R19: 139170.87 | S19: 167075.45 | T19: 198171.78 | U19: 0.2020013 | Z19: Adjusted net income (current definition) | AA19: 70174.691 | AB19: 66760.827 | AC19: 67216.473 | AD19: 65995.435 | AE19: 67594.184 | AF19: 69501.906 | AG19: -0.0019248509
B21: Diluted shares (m) | C21: =Model!BX133 -> 2570 | D21: =Model!BY133 -> 2604 | E21: =Model!BZ133 -> 2630.4982 | F21: =Model!CA133 -> 2628.8759 | G21: =Model!CB133 -> 2589.5104 | H21: =Model!CC133 -> 2528.4359 | I21: =IFERROR((H21/C21)^(1/5)-1,"n/m") -> -0.0032556937 | N21: Diluted shares (m) | O21: 2568.3221 | P21: 2569.416 | Q21: 2541.7434 | R21: 2491.06 | S21: 2401.4499 | T21: 2280.6168 | U21: -0.0234813 | Z21: Diluted shares (m) | AA21: 2570 | AB21: 2604 | AC21: 2634 | AD21: 2664 | AE21: 2694 | AF21: 2724 | AG21: 0.011707096
B23: Adjusted EPS — Diluted ($) | C23: =Model!BX193 -> 29.018422 | D23: =Model!BY193 -> 32.306975 | E23: =Model!BZ193 -> 37.011713 | F23: =Model!CA193 -> 42.076071 | G23: =Model!CB193 -> 48.842847 | H23: =Model!CC193 -> 56.607904 | I23: =IFERROR((H23/C23)^(1/5)-1,"n/m") -> 0.14298533 | N23: Adjusted EPS — Diluted ($) | O23: 30.751593 | P23: 37.292873 | Q23: 45.775576 | R23: 55.868132 | S23: 69.572741 | T23: 86.89394 | U23: 0.23090454 | Z23: Adjusted EPS — Diluted ($) | AA23: 27.305327 | AB23: 25.637798 | AC23: 25.518782 | AD23: 24.773061 | AE23: 25.09064 | AF23: 25.51465 | AG23: -0.013474203
B24: EPS y/y % | D24: =IFERROR(D23/C23-1,"") -> 0.11332641 | E24: =IFERROR(E23/D23-1,"") -> 0.14562607 | F24: =IFERROR(F23/E23-1,"") -> 0.13683122 | G24: =IFERROR(G23/F23-1,"") -> 0.16082243 | H24: =IFERROR(H23/G23-1,"") -> 0.15898043 | N24: EPS y/y % | P24: 0.21271353 | Q24: 0.22746177 | R24: 0.22047906 | S24: 0.2453028 | T24: 0.24896531 | Z24: EPS y/y % | AB24: -0.061069722 | AC24: -0.0046422047 | AD24: -0.029222452 | AE24: 0.012819526 | AF24: 0.016899131
B26: P / E (x) — assumed (adjusted EPS) | G26: 24 | H26: 24 | N26: P / E (x) — assumed (adjusted EPS) | S26: 28 | T26: 28 | Z26: P / E (x) — assumed (adjusted EPS) | AD26: 18 | AE26: 18 | AF26: 18
B27: Price Target ($) | G27: =G26*G23 -> 1172.2283 | H27: =H26*H23 -> 1358.5897 | N27: Price Target ($) | S27: =S26*S23 -> 1948.0368 | T27: =T26*T23 -> 2433.0303 | Z27: Price Target ($) | AD27: =AD26*AD23 -> 445.9151 | AE27: =AE26*AE23 -> 451.63152 | AF27: =AF26*AF23 -> 459.2637
B28: Upside / (Downside) vs current | G28: =IFERROR(G27/$K$2-1,"") -> 0.57346084 | H28: =IFERROR(H27/$K$2-1,"") -> 0.82361032 | N28: Upside / (Downside) vs current | S28: =IFERROR(S27/$K$2-1,"") -> 1.6148144 | T28: =IFERROR(T27/$K$2-1,"") -> 2.2658125 | Z28: Upside / (Downside) vs current | AD28: =IFERROR(AD27/$K$2-1,"") -> -0.40145624 | AE28: =IFERROR(AE27/$K$2-1,"") -> -0.3937832 | AF28: =IFERROR(AF27/$K$2-1,"") -> -0.38353866
B29: IRR (to 31-Dec of Y-1) | G29: =IFERROR((G27/$K$2)^(1/((DATE(2030-1,12,31)-$K$3)/365.25))-1,"") -> 0.15131159 | H29: =IFERROR((H27/$K$2)^(1/((DATE(2031-1,12,31)-$K$3)/365.25))-1,"") -> 0.15315223 | N29: IRR (to 31-Dec of Y-1) | S29: =IFERROR((S27/$K$2)^(1/((DATE(2030-1,12,31)-$K$3)/365.25))-1,"") -> 0.34822364 | T29: =IFERROR((T27/$K$2)^(1/((DATE(2031-1,12,31)-$K$3)/365.25))-1,"") -> 0.32405505 | Z29: IRR (to 31-Dec of Y-1) | AD29: =IFERROR((AD27/$K$2)^(1/((DATE(2029-1,12,31)-$K$3)/365.25))-1,"") -> -0.20660992 | AE29: =IFERROR((AE27/$K$2)^(1/((DATE(2030-1,12,31)-$K$3)/365.25))-1,"") -> -0.1440869 | AF29: =IFERROR((AF27/$K$2)^(1/((DATE(2031-1,12,31)-$K$3)/365.25))-1,"") -> -0.10839838
B31: Free Cash Flow | C31: =Model!BX249 -> -8258.7406 | D31: =Model!BY249 -> 20755.194 | E31: =Model!BZ249 -> 53245.721 | F31: =Model!CA249 -> 92527.627 | G31: =Model!CB249 -> 126145.34 | H31: =Model!CC249 -> 156490.17 | I31: =IFERROR((H31/C31)^(1/5)-1,"n/m") -> -2.8010039 | N31: Free Cash Flow | O31: -3644.2066 | P31: 39624.364 | Q31: 79578.421 | R31: 129247.37 | S31: 176510.57 | T31: 223554.3 | U31: -3.278012 | Z31: Free Cash Flow | AA31: -12873.275 | AB31: -2693.7057 | AC31: 19816.191 | AD31: 45565.994 | AE31: 64599.443 | AF31: 79030.97 | AG31: -2.4375457
B32: FCF % | C32: =IFERROR(C31/C9,"") -> -0.032694882 | D32: =IFERROR(D31/D9,"") -> 0.068992945 | E32: =IFERROR(E31/E9,"") -> 0.15285473 | F32: =IFERROR(F31/F9,"") -> 0.23373387 | G32: =IFERROR(G31/G9,"") -> 0.28580499 | H32: =IFERROR(H31/H9,"") -> 0.32124422 | J32: =IFERROR(AVERAGE(Model!C254,Model!D254,Model!E254,Model!F254,Model!K254,Model!P254,Model!U254,Model!Z254,Model!AE254,Model!AJ254,Model!AO254,Model!AT254,Model!AY254,Model!BD254,Model!BI254,Model!BN254,Model!BS254),"") -> 0.27671393 | K32: =IFERROR(MIN(Model!C254,Model!D254,Model!E254,Model!F254,Model!K254,Model!P254,Model!U254,Model!Z254,Model!AE254,Model!AJ254,Model!AO254,Model!AT254,Model!AY254,Model!BD254,Model!BI254,Model!BN254,Model!BS254),"") -> 0.074081352 | L32: =IFERROR(MAX(Model!C254,Model!D254,Model!E254,Model!F254,Model!K254,Model!P254,Model!U254,Model!Z254,Model!AE254,Model!AJ254,Model!AO254,Model!AT254,Model!AY254,Model!BD254,Model!BI254,Model!BN254,Model!BS254),"") -> 0.43005436 | N32: FCF % | O32: -0.014243992 | P32: 0.12526652 | Q32: 0.20910968 | R32: 0.28745914 | S32: 0.33846333 | T32: 0.37319813 | V32: 0.27671393 | W32: 0.074081352 | X32: 0.43005436 | Z32: FCF % | AA32: -0.051625433 | AB32: -0.009784157 | AC32: 0.067142799 | AD32: 0.14688745 | AE32: 0.20213383 | AF32: 0.24258725 | AH32: 0.27671393 | AI32: 0.074081352 | AJ32: 0.43005436
B33: FCF / share ($) | C33: =IFERROR(C31/C21,"") -> -3.2135177 | D33: =IFERROR(D31/D21,"") -> 7.9705046 | E33: =IFERROR(E31/E21,"") -> 20.241687 | F33: =IFERROR(F31/F21,"") -> 35.19665 | G33: =IFERROR(G31/G21,"") -> 48.713973 | H33: =IFERROR(H31/H21,"") -> 61.892085 | N33: FCF / share ($) | O33: -1.4189056 | P33: 15.421545 | Q33: 31.308597 | R33: 51.884487 | S33: 73.501667 | T33: 98.023613 | Z33: FCF / share ($) | AA33: -5.0090563 | AB33: -1.0344492 | AC33: 7.5232312 | AD33: 17.104352 | AE33: 23.979006 | AF33: 29.012838
B34: FCF Yield (on PT) | F34: =IFERROR(F33/F$27,"") | G34: =IFERROR(G33/G$27,"") -> 0.041556728 | H34: =IFERROR(H33/H$27,"") -> 0.045556128 | N34: FCF Yield (on PT) | R34: =IFERROR(R33/R$27,"") | S34: =IFERROR(S33/S$27,"") -> 0.03773115 | T34: =IFERROR(T33/T$27,"") -> 0.040288693 | Z34: FCF Yield (on PT) | AD34: =IFERROR(AD33/AD$27,"") -> 0.038357867 | AE34: =IFERROR(AE33/AE$27,"") -> 0.053094182 | AF34: =IFERROR(AF33/AF$27,"") -> 0.063172504
B35: Adjusted EBITDA (leverage basis) | C35: =Model!BX168 -> 115613.32 | D35: =Model!BY168 -> 142894.57 | E35: =Model!BZ168 -> 170687.58 | F35: =Model!CA168 -> 197933.72 | G35: =Model!CB168 -> 225097.97 | H35: =Model!CC168 -> 250875.91 | I35: =IFERROR((H35/C35)^(1/5)-1,"n/m") -> 0.16758961 | N35: Adjusted EBITDA (leverage basis) | O35: 120854.57 | P35: 156578.62 | Q35: 194084.72 | R35: 233802.39 | S35: 276398.05 | T35: 320477.36 | U35: 0.21536536 | Z35: Adjusted EBITDA (leverage basis) | AA35: 110372.06 | AB35: 122514.29 | AC35: 135762.11 | AD35: 145798.82 | AE35: 153402 | AF35: 158005.09 | AG35: 0.074391058
B36: Adjusted EBITDA % of revenue | C36: =IFERROR(C35/C9,"") -> 0.45769251 | D36: =IFERROR(D35/D9,"") -> 0.475 | E36: =IFERROR(E35/E9,"") -> 0.49 | F36: =IFERROR(F35/F9,"") -> 0.5 | G36: =IFERROR(G35/G9,"") -> 0.51 | H36: =IFERROR(H35/H9,"") -> 0.515 | J36: =IFERROR(AVERAGE(Model!C213,Model!D213,Model!E213,Model!F213,Model!K213,Model!P213,Model!U213,Model!Z213,Model!AE213,Model!AJ213,Model!AO213,Model!AT213,Model!AY213,Model!BD213,Model!BI213,Model!BN213,Model!BS213),"") -> 0.47964081 | K36: =IFERROR(MIN(Model!C213,Model!D213,Model!E213,Model!F213,Model!K213,Model!P213,Model!U213,Model!Z213,Model!AE213,Model!AJ213,Model!AO213,Model!AT213,Model!AY213,Model!BD213,Model!BI213,Model!BN213,Model!BS213),"") -> 0.23324818 | L36: =IFERROR(MAX(Model!C213,Model!D213,Model!E213,Model!F213,Model!K213,Model!P213,Model!U213,Model!Z213,Model!AE213,Model!AJ213,Model!AO213,Model!AT213,Model!AY213,Model!BD213,Model!BI213,Model!BN213,Model!BS213),"") -> 0.59321175 | N36: Adjusted EBITDA % of revenue | O36: 0.47238033 | P36: 0.495 | Q36: 0.51 | R36: 0.52 | S36: 0.53 | T36: 0.535 | V36: 0.47964081 | W36: 0.23324818 | X36: 0.59321175 | Z36: Adjusted EBITDA % of revenue | AA36: 0.44262285 | AB36: 0.445 | AC36: 0.46 | AD36: 0.47 | AE36: 0.48 | AF36: 0.485 | AH36: 0.47964081 | AI36: 0.23324818 | AJ36: 0.59321175
B38: Net Debt | C38: =Model!BX365 -> 31296.741 | D38: =Model!BY365 -> 48335.551 | E38: =Model!BZ365 -> 42671.894 | F38: =Model!CA365 -> 49483.429 | G38: =Model!CB365 -> 56274.492 | H38: =Model!CC365 -> 62718.979 | N38: Net Debt | O38: 31678.683 | P38: 78289.312 | Q38: 97042.361 | R38: 116901.19 | S38: 138199.02 | T38: 160238.68 | Z38: Net Debt | AA38: 35911.275 | AB38: 72757.906 | AC38: 88170.471 | AD38: 79699.131 | AE38: 52080.313 | AF38: 11034.896
B39: Net Debt / Adjusted EBITDA (x) | C39: =IFERROR(C38/C35,"") -> 0.27070187 | D39: =IFERROR(D38/D35,"") -> 0.33826024 | E39: =IFERROR(E38/E35,"") -> 0.25 | F39: =IFERROR(F38/F35,"") -> 0.25 | G39: =IFERROR(G38/G35,"") -> 0.25 | H39: =IFERROR(H38/H35,"") -> 0.25 | N39: Net Debt / Adjusted EBITDA (x) | O39: 0.26212234 | P39: 0.5 | Q39: 0.5 | R39: 0.5 | S39: 0.5 | T39: 0.5 | Z39: Net Debt / Adjusted EBITDA (x) | AA39: 0.32536562 | AB39: 0.59387283 | AC39: 0.64944831 | AD39: 0.54663769 | AE39: 0.33950219 | AF39: 0.069838863
B40: Share repurchases ($m; 2026E = 2H) | D40: =Model!BY264 -> 0 | E40: =Model!BZ264 -> 6085.8177 | F40: =Model!CA264 -> 52781.473 | G40: =Model!CB264 -> 83608.902 | H40: =Model!CC264 -> 109091.74 | N40: Share repurchases ($m; 2026E = 2H) | P40: 44852.594 | Q40: 51790.414 | R40: 95506.71 | S40: 139317.82 | T40: 179755.57 | AB40: 0 | AC40: 0 | AD40: 0 | AE40: 0 | AF40: 0
B41: Implied avg buyback price ($) | D41: =Model!BY263 -> 804.6 | E41: =Model!BZ263 -> 868.968 | F41: =Model!CA263 -> 938.48544 | G41: =Model!CB263 -> 1013.5643 | H41: =Model!CC263 -> 1094.6494 | N41: Implied avg buyback price ($) | P41: 804.6 | Q41: 868.968 | R41: 938.48544 | S41: 1013.5643 | T41: 1094.6494 | AB41: 804.6 | AC41: 868.968 | AD41: 938.48544 | AE41: 1013.5643 | AF41: 1094.6494
B42: Shares repurchased (m) | D42: =Model!BY265 -> 0 | E42: =Model!BZ265 -> 7.0035004 | F42: =Model!CA265 -> 56.241121 | G42: =Model!CB265 -> 82.489985 | H42: =Model!CC265 -> 99.659071 | N42: Shares repurchased (m) | P42: 55.745208 | Q42: 59.599909 | R42: 101.76685 | S42: 137.45337 | T42: 164.21291 | AB42: 0 | AC42: 0 | AD42: 0 | AE42: 0 | AF42: 0
B44: ROIC | C44: =Model!BX347 -> 0.22995314 | D44: =Model!BY347 -> 0.20097435 | E44: =Model!BZ347 -> 0.19590913 | F44: =Model!CA347 -> 0.19743706 | G44: =Model!CB347 -> 0.20842061 | H44: =Model!CC347 -> 0.22181535 | J44: =IFERROR(AVERAGE(Model!C347,Model!D347,Model!E347,Model!F347,Model!K347,Model!P347,Model!U347,Model!Z347,Model!AE347,Model!AJ347,Model!AO347,Model!AT347,Model!AY347,Model!BD347,Model!BI347,Model!BN347,Model!BS347),"") -> 0.39499745 | K44: =IFERROR(MIN(Model!C347,Model!D347,Model!E347,Model!F347,Model!K347,Model!P347,Model!U347,Model!Z347,Model!AE347,Model!AJ347,Model!AO347,Model!AT347,Model!AY347,Model!BD347,Model!BI347,Model!BN347,Model!BS347),"") -> 0.01286971 | L44: =IFERROR(MAX(Model!C347,Model!D347,Model!E347,Model!F347,Model!K347,Model!P347,Model!U347,Model!Z347,Model!AE347,Model!AJ347,Model!AO347,Model!AT347,Model!AY347,Model!BD347,Model!BI347,Model!BN347,Model!BS347),"") -> 0.72991597 | N44: ROIC | O44: 0.24351824 | P44: 0.2303181 | Q44: 0.23787563 | R44: 0.25348858 | S44: 0.28040126 | T44: 0.31176165 | V44: 0.39499745 | W44: 0.01286971 | X44: 0.72991597 | Z44: ROIC | AA44: 0.21640569 | AB44: 0.15985717 | AC44: 0.1390663 | AD44: 0.12477315 | AE44: 0.11948048 | AF44: 0.11604567 | AH44: 0.39499745 | AI44: 0.01286971 | AJ44: 0.72991597
B45: RONTA | C45: =Model!BX359 -> 0.21350994 | D45: =Model!BY359 -> 0.19015553 | E45: =Model!BZ359 -> 0.18733135 | F45: =Model!CA359 -> 0.18997823 | G45: =Model!CB359 -> 0.20138834 | H45: =Model!CC359 -> 0.21500159 | J45: =IFERROR(AVERAGE(Model!C359,Model!D359,Model!E359,Model!F359,Model!K359,Model!P359,Model!U359,Model!Z359,Model!AE359,Model!AJ359,Model!AO359,Model!AT359,Model!AY359,Model!BD359,Model!BI359,Model!BN359,Model!BS359),"") -> 0.51428198 | K45: =IFERROR(MIN(Model!C359,Model!D359,Model!E359,Model!F359,Model!K359,Model!P359,Model!U359,Model!Z359,Model!AE359,Model!AJ359,Model!AO359,Model!AT359,Model!AY359,Model!BD359,Model!BI359,Model!BN359,Model!BS359),"") -> 0.016966681 | L45: =IFERROR(MAX(Model!C359,Model!D359,Model!E359,Model!F359,Model!K359,Model!P359,Model!U359,Model!Z359,Model!AE359,Model!AJ359,Model!AO359,Model!AT359,Model!AY359,Model!BD359,Model!BI359,Model!BN359,Model!BS359),"") -> 0.94249403 | N45: RONTA | O45: 0.22609461 | P45: 0.21877208 | Q45: 0.22899979 | R45: 0.24613497 | S45: 0.27395908 | T45: 0.30609199 | V45: 0.51428198 | W45: 0.016966681 | X45: 0.94249403 | Z45: RONTA | AA45: 0.20094049 | AB45: 0.15097225 | AC45: 0.13249119 | AD45: 0.11941988 | AE45: 0.11465364 | AF45: 0.11153542 | AH45: 0.51428198 | AI45: 0.016966681 | AJ45: 0.94249403
B47: Implied Market Cap (USDm) | F47: =F27*F21 -> 0 | G47: =G27*G21 -> 3035497.4 | H47: =H27*H21 -> 3435106.9 | N47: Implied Market Cap (USDm) | R47: =R27*R21 -> 0 | S47: =S27*S21 -> 4678112.7 | T47: =T27*T21 -> 5548809.8 | Z47: Implied Market Cap (USDm) | AD47: =AD27*AD21 -> 1187917.8 | AE47: =AE27*AE21 -> 1216695.3 | AF47: =AF27*AF21 -> 1251034.3
B48: (+) Net Debt & NCI | F48: =F38+Model!CA375 -> 49483.429 | G48: =G38+Model!CB375 -> 56274.492 | H48: =H38+Model!CC375 -> 62718.979 | N48: (+) Net Debt & NCI | R48: =R38+Model!CA375 -> 116901.19 | S48: =S38+Model!CB375 -> 138199.02 | T48: =T38+Model!CC375 -> 160238.68 | Z48: (+) Net Debt & NCI | AD48: =AD38+Model!CA375 -> 79699.131 | AE48: =AE38+Model!CB375 -> 52080.313 | AF48: =AF38+Model!CC375 -> 11034.896
B49: Implied Enterprise Value (USDm) | F49: =F47+F48 -> 49483.429 | G49: =G47+G48 -> 3091771.9 | H49: =H47+H48 -> 3497825.9 | N49: Implied Enterprise Value (USDm) | R49: =R47+R48 -> 116901.19 | S49: =S47+S48 -> 4816311.8 | T49: =T47+T48 -> 5709048.5 | Z49: Implied Enterprise Value (USDm) | AD49: =AD47+AD48 -> 1267617 | AE49: =AE47+AE48 -> 1268775.6 | AF49: =AF47+AF48 -> 1262069.2
B50: Implied EV / Adjusted EBITDA (x) | F50: =IFERROR(F49/F35,"") -> 0.25 | G50: =IFERROR(G49/G35,"") -> 13.735228 | H50: =IFERROR(H49/H35,"") -> 13.942454 | N50: Implied EV / Adjusted EBITDA (x) | R50: =IFERROR(R49/R35,"") -> 0.5 | S50: =IFERROR(S49/S35,"") -> 17.425274 | T50: =IFERROR(T49/T35,"") -> 17.814202 | Z50: Implied EV / Adjusted EBITDA (x) | AD50: =IFERROR(AD49/AD35,"") -> 8.6942882 | AE50: =IFERROR(AE49/AE35,"") -> 8.2709199 | AF50: =IFERROR(AF49/AF35,"") -> 7.9875225

Sheet DCF
B2: DCF VALUATION — META PLATFORMS, INC. (META)
B4: 1. WACC BUILD
B5: Risk-free rate (US 10Y govt) | C5: 0.0425 | D5: Assumption (~US 10Y Treasury yield, Oct-2026; government rate sources not reachable from the build environment); update to market
B6: Equity risk premium | C6: 0.05 | D6: Assumption: US implied ERP ~4.5–5.5%
B7: Levered beta | C7: 1.2 | D7: Assumption: mega-cap internet and advertising peers (GOOGL, AMZN, MSFT, SNAP, PINS) ~1.0–1.3; advertising is cyclical and the AI capex cycle raises operating leverage
B8: Cost of equity | C8: =C5+C7*C6 -> 0.1025
B9: Pre-tax cost of debt | C9: 0.05 | D9: May-2026 notes 4.55%–6.45% (effective 4.60%–6.48%); Nov-2025 notes 4.20%–5.75% (Q2-26 10-Q Note 8); AA- / Aa3 class issuer
B10: Tax rate | C10: 0.16 | D10: Model 2027E+ effective tax rate (2026 guidance 15–17% for the remaining quarters)
B11: After-tax cost of debt | C11: =C9*(1-C10) -> 0.042
B12: Target D/V | C12: 0.05 | D12: Notes ~$84bn at 30-Jun-2026 vs ~$1.9tn market cap ($745 × ~2.57bn diluted shares); net debt ≈ 0 (cash and marketable securities $90.3bn)
B13: WACC | C13: =C8*(1-C12)+C11*C12 -> 0.099475
B15: Valuation date (live) | C15: =TODAY() -> 2026-10-13 00:00:00 | D15: Periods = (31-Dec of the year − today) / 365.25; cash flows assumed at year-end; 2026E is the base year (its cash flows are in YE2026E net debt)
B16: 2. UNLEVERED FREE CASH FLOW BUILD (USDm)
