Workbook

Sheet Model
CF1: SCENARIO SWITCH ▼ (Bull / Base / Bear) — drives all scenario-linked forecast drivers
B2: Martin Marietta Materials, Inc. (NYSE: MLM) — 3-Statement Financial Model | CF2: Base
B3: US GAAP as reported · USD millions (per-share data in USD; shipments in millions of tons) · Source: Martin Marietta Forms 10-K (incl. Exhibit 13 annual reports to 2018) / 10-Q and Form 8-K earnings releases (Ex. 99.1), deal 8-Ks (LNA, Aug-2026), SEC EDGAR CIK 0000916076 (investor-relations releases are the same documents as filed on EDGAR)
B4: Basis notes: calendar fiscal year. Revenues incl. freight (net sales + freight & delivery revenues to 2017; ASC 606 from 2018). Product-line revenues: net sales basis to 2017, products & services (ex freight) 2018–22, total revenues from 2023. TXI from 1-Jul-2014 (cement); Bluegrass Apr-2018; Lehigh West Oct-2021; Blue Water Apr-2024; South Texas cement sold Feb-2024; Midlothian cement & Texas ready mix = discontinued operations from Q3/25 (2025 quarters shown on the recast continuing-ops basis; 2024 and earlier as originally reported); QUIKRETE asset exchange closed Feb-2026; NFM May-2026; LNA (Lhoist North America) closed 21-Aug-2026 — excluded from company FY26 guidance, modelled separately from Q3/26E.
CH5: Forecast | CI5: Historical | CJ5: Historical | CK5: Historical
B6: (USDm) | C6: 2006 | D6: 2007 | E6: 2008 | F6: 2009 | G6: 2010 | H6: 2011 | I6: 2012 | J6: Q1/13 | K6: Q2/13 | L6: Q3/13 | M6: Q4/13 | N6: 2013 | O6: Q1/14 | P6: Q2/14 | Q6: Q3/14 | R6: Q4/14 | S6: 2014 | T6: Q1/15 | U6: Q2/15 | V6: Q3/15 | W6: Q4/15 | X6: 2015 | Y6: Q1/16 | Z6: Q2/16 | AA6: Q3/16 | AB6: Q4/16 | AC6: 2016 | AD6: Q1/17 | AE6: Q2/17 | AF6: Q3/17 | AG6: Q4/17 | AH6: 2017 | AI6: Q1/18 | AJ6: Q2/18 | AK6: Q3/18 | AL6: Q4/18 | AM6: 2018 | AN6: Q1/19 | AO6: Q2/19 | AP6: Q3/19 | AQ6: Q4/19 | AR6: 2019 | AS6: Q1/20 | AT6: Q2/20 | AU6: Q3/20 | AV6: Q4/20 | AW6: 2020 | AX6: Q1/21 | AY6: Q2/21 | AZ6: Q3/21 | BA6: Q4/21 | BB6: 2021 | BC6: Q1/22 | BD6: Q2/22 | BE6: Q3/22 | BF6: Q4/22 | BG6: 2022 | BH6: Q1/23 | BI6: Q2/23 | BJ6: Q3/23 | BK6: Q4/23 | BL6: 2023 | BM6: Q1/24 | BN6: Q2/24 | BO6: Q3/24 | BP6: Q4/24 | BQ6: 2024 | BR6: Q1/25 | BS6: Q2/25 | BT6: Q3/25 | BU6: Q4/25 | BV6: 2025 | BW6: Q1/26 | BX6: Q2/26 | BY6: Q3/26E | BZ6: Q4/26E | CA6: 2026E | CB6: 2027E | CC6: 2028E | CD6: 2029E | CE6: 2030E | CF6: Modelling Notes | CH6: 5Y CAGR | CI6: 5Y CAGR | CJ6: 10Y CAGR | CK6: 19Y CAGR
CH7: 25-'30 | CI7: 20-'25 | CJ7: 15-'25 | CK7: 06-'25
B8: PRODUCT-LINE P&L — AGGREGATES · OTHER BUILDING MATERIALS · SPECIALTIES · LNA (volume × price build) | CF8: PRODUCT-LINE BUILD — modelling logic (shipments × ASP → revenues → gross profit → Adjusted EBITDA)
CN9: SCENARIO INPUT TABLE — driver assumptions per Bull / Base / Bear | CO9: Bull | CP9: Base | CQ9: Bear | CR9: Bull / Bear = Base + Δ (Δ inputs on each block header). Outlook block = high / mid / low end of FY26 ranges.
B10: Aggregates (crushed stone, sand & gravel; shipments incl. internal tons) — Building Materials business | CF10: AGGREGATES — modelling logic
B11: Shipments (million tons) | C11: 198.49 | D11: 182.326 | E11: 159.355 | F11: 123.401 | G11: 130.007 | H11: 125.074 | I11: 128.331 | J11: 22.779 | K11: 34.574 | L11: 39.631 | M11: 31.448 | N11: 128.433 | O11: 24.619 | P11: 38.974 | Q11: 45.107 | R11: 37.35 | S11: 146.05 | T11: 28.836 | U11: 42.003 | V11: 47.521 | W11: 38.001 | X11: 156.422 | Y11: 32.665 | Z11: 42.554 | AA11: 45.239 | AB11: 38.168 | AC11: 158.626 | AD11: 32.611 | AE11: 43.423 | AF11: 43.805 | AG11: 37.858 | AH11: 157.698 | AI11: 30.02 | AJ11: 48.319 | AK11: 50.324 | AL11: 42.173 | AM11: 170.836 | AN11: 37.286 | AO11: 53.153 | AP11: 56.669 | AQ11: 43.923 | AR11: 191.126 | AS11: 38.3 | AT11: 51.2 | AU11: 51.8 | AV11: 45.2 | AW11: 186.5 | AX11: 37.1 | AY11: 52.9 | AZ11: 57 | BA11: 54.2 | BB11: 201.2 | BC11: 42.1 | BD11: 57.8 | BE11: 60.2 | BF11: 47.7 | BG11: 207.7 | BH11: 41.7 | BI11: 54.5 | BJ11: 55.9 | BK11: 46.6 | BL11: 198.8 | BM11: 36.6 | BN11: 53 | BO11: 53.7 | BP11: 47.9 | BQ11: 191.1 | BR11: 39 | BS11: 52.7 | BT11: 57.9 | BU11: 48.9 | BV11: 198.5 | BW11: 43.9 | BX11: 61.6 | BY11: =BT11*(1+BY12) -> 70.412778 | BZ11: =BU11*(1+BZ12) -> 59.467787 | CA11: =SUM(BW11,BX11,BY11,BZ11) -> 235.38057 | CB11: =CA11*(1+CB12) -> 242.44198 | CC11: =CB11*(1+CC12) -> 249.71524 | CD11: =CC11*(1+CD12) -> 255.95812 | CE11: =CD11*(1+CE12) -> 262.35708 | CF11: Q3/26E–Q4/26E: prior-year quarter × (1 + Q2/26 y/y shipment growth, which includes the Feb-26 QUIKRETE aggregates sites and May-26 NFM). 2027E+: prior year × (1 + scenario volume lever AGG_vol). | CH11: =IFERROR((CE11/BV11)^(1/5)-1,"n/m") -> 0.057368709 | CI11: =IFERROR((BV11/AW11)^(1/5)-1,"n/m") -> 0.012549667 | CJ11: =IFERROR((BV11/X11)^(1/10)-1,"n/m") -> 0.0241092 | CK11: =IFERROR((BV11/C11)^(1/19)-1,"n/m") -> 2.6515352e-06 | CN11: FY26 outlook — Q2-26 release (30-Jul-26); legacy MLM, excludes LNA | CO11: High | CP11: Mid | CQ11: Low | CR11: Company guidance excludes the LNA acquisition (closed 21-Aug-26) — the model adds LNA separately.
B12: Shipments y/y % | D12: =IF(AND(ISNUMBER(D11),ISNUMBER(C11)),IFERROR(D11/C11-1,""),"") -> -0.081434833 | E12: =IF(AND(ISNUMBER(E11),ISNUMBER(D11)),IFERROR(E11/D11-1,""),"") -> -0.12598861 | F12: =IF(AND(ISNUMBER(F11),ISNUMBER(E11)),IFERROR(F11/E11-1,""),"") -> -0.22562204 | G12: =IF(AND(ISNUMBER(G11),ISNUMBER(F11)),IFERROR(G11/F11-1,""),"") -> 0.053532791 | H12: =IF(AND(ISNUMBER(H11),ISNUMBER(G11)),IFERROR(H11/G11-1,""),"") -> -0.037944111 | I12: =IF(AND(ISNUMBER(I11),ISNUMBER(H11)),IFERROR(I11/H11-1,""),"") -> 0.026040584 | N12: =IF(AND(ISNUMBER(N11),ISNUMBER(I11)),IFERROR(N11/I11-1,""),"") -> 0.00079481965 | O12: =IF(AND(ISNUMBER(O11),ISNUMBER(J11)),IFERROR(O11/J11-1,""),"") -> 0.080776153 | P12: =IF(AND(ISNUMBER(P11),ISNUMBER(K11)),IFERROR(P11/K11-1,""),"") -> 0.12726326 | Q12: =IF(AND(ISNUMBER(Q11),ISNUMBER(L11)),IFERROR(Q11/L11-1,""),"") -> 0.13817466 | R12: =IF(AND(ISNUMBER(R11),ISNUMBER(M11)),IFERROR(R11/M11-1,""),"") -> 0.18767489 | S12: =IF(AND(ISNUMBER(S11),ISNUMBER(N11)),IFERROR(S11/N11-1,""),"") -> 0.1371688 | T12: =IF(AND(ISNUMBER(T11),ISNUMBER(O11)),IFERROR(T11/O11-1,""),"") -> 0.17129047 | U12: =IF(AND(ISNUMBER(U11),ISNUMBER(P11)),IFERROR(U11/P11-1,""),"") -> 0.077718479 | ... BX12: =IF(AND(ISNUMBER(BX11),ISNUMBER(BS11)),IFERROR(BX11/BS11-1,""),"") -> 0.16888046 | BY12: =$BX$12+BY118 -> 0.21611016 | BZ12: =$BX$12+BZ118 -> 0.21611016 | CA12: =IFERROR(CA11/BV11-1,"") -> 0.1857963 | CB12: =CHOOSE(MATCH($CF$2,{"Bull","Base","Bear"},0),$CO$25,$CP$25,$CQ$25) -> 0.03 | CC12: =CHOOSE(MATCH($CF$2,{"Bull","Base","Bear"},0),$CO$26,$CP$26,$CQ$26) -> 0.03 | CD12: =CHOOSE(MATCH($CF$2,{"Bull","Base","Bear"},0),$CO$27,$CP$27,$CQ$27) -> 0.025 | CE12: =CHOOSE(MATCH($CF$2,{"Bull","Base","Bear"},0),$CO$28,$CP$28,$CQ$28) -> 0.025 | CF12: Q3/Q4-26E: Q2/26 y/y + revenue-outlook calibration Δ (Group block). 2027E–2030E: scenario lever AGG_vol (Bull/Base/Bear table →). | CN12: FY26 revenues ($m) | CO12: 7400 | CP12: 7300 | CQ12: 7200 | CR12: Raised to $7.2–7.4bn in the Q2-26 release (from $7.00–7.32bn).
B13: Average selling price — ASP ($ / ton, as reported) | I13: 10.33 | J13: 10.97 | K13: 10.48 | L13: 10.55 | M13: 10.67 | N13: 10.63 | O13: 10.82 | P13: 11 | Y13: 13.04 | Z13: 12.78 | AA13: 12.77 | AB13: 13.03 | AC13: 12.88 | AD13: 13.73 | AE13: 13.24 | AF13: 13.4 | AG13: 13.55 | AH13: 13.46 | AI13: 14.04 | AJ13: 13.7 | AK13: 13.6 | AL13: 13.61 | AM13: 13.71 | AN13: 14.36 | AO13: 14.18 | AP13: 14.37 | AQ13: 14.38 | AR13: 14.33 | AS13: 14.8 | AT13: 14.66 | AU13: 14.75 | AV13: 14.88 | AW13: 14.77 | AX13: 15.31 | AY13: 15.07 | AZ13: 14.93 | BA13: 15.09 | BB13: 15.08 | BC13: 16.17 | BD13: 16.34 | BE13: 16.65 | BF13: 17.58 | BG13: 16.68 | BH13: 19.83 | BI13: 19.37 | BJ13: 19.98 | BK13: 20.22 | BL13: 19.84 | BM13: 22.26 | BN13: 21.61 | BO13: 21.52 | BP13: 21.95 | BQ13: 21.8 | BR13: 23.77 | BS13: 23.21 | BT13: 23.24 | BU13: 23.11 | BV13: 23.3 | BW13: 23.7 | BX13: 22.74 | BY13: =BT13*(1+BY14) -> 22.769393 | BZ13: =BU13*(1+BZ14) -> 22.642025 | CA13: =IFERROR((BW11*BW13+BX11*BX13+BY11*BY13+BZ11*BZ13)/CA11,"") -> 22.903086 | CB13: =CA13*(1+CB14) -> 24.277271 | CC13: =CB13*(1+CC14) -> 25.612521 | CD13: =CC13*(1+CD14) -> 26.893147 | CE13: =CD13*(1+CE14) -> 28.237804 | CF13: Q3/26E–Q4/26E: prior-year quarter × (1 + Q2/26 y/y ASP change, which reflects acquisition mix). FY = shipment-weighted. 2027E+: scenario lever AGG_ASP. | CH13: =IFERROR((CE13/BV13)^(1/5)-1,"n/m") -> 0.0391901 | CI13: =IFERROR((BV13/AW13)^(1/5)-1,"n/m") -> 0.09545637 | CJ13: =IFERROR((BV13/X13)^(1/10)-1,"n/m") -> n/m | CK13: =IFERROR((BV13/C13)^(1/19)-1,"n/m") -> n/m | CN13: FY26 Adjusted EBITDA from continuing operations ($m) | CO13: 2500 | CP13: 2430 | CQ13: 2360 | CR13: Reaffirmed $2.36–2.50bn. Drives the Q3/Q4-26E margin calibration.
B14: ASP y/y % | D14: =IF(AND(ISNUMBER(D13),ISNUMBER(C13)),IFERROR(D13/C13-1,""),"") | E14: =IF(AND(ISNUMBER(E13),ISNUMBER(D13)),IFERROR(E13/D13-1,""),"") | F14: =IF(AND(ISNUMBER(F13),ISNUMBER(E13)),IFERROR(F13/E13-1,""),"") | G14: =IF(AND(ISNUMBER(G13),ISNUMBER(F13)),IFERROR(G13/F13-1,""),"") | H14: =IF(AND(ISNUMBER(H13),ISNUMBER(G13)),IFERROR(H13/G13-1,""),"") | I14: =IF(AND(ISNUMBER(I13),ISNUMBER(H13)),IFERROR(I13/H13-1,""),"") | N14: =IF(AND(ISNUMBER(N13),ISNUMBER(I13)),IFERROR(N13/I13-1,""),"") -> 0.029041626 | O14: =IF(AND(ISNUMBER(O13),ISNUMBER(J13)),IFERROR(O13/J13-1,""),"") -> -0.013673655 | P14: =IF(AND(ISNUMBER(P13),ISNUMBER(K13)),IFERROR(P13/K13-1,""),"") -> 0.049618321 | Q14: =IF(AND(ISNUMBER(Q13),ISNUMBER(L13)),IFERROR(Q13/L13-1,""),"") | R14: =IF(AND(ISNUMBER(R13),ISNUMBER(M13)),IFERROR(R13/M13-1,""),"") | S14: =IF(AND(ISNUMBER(S13),ISNUMBER(N13)),IFERROR(S13/N13-1,""),"") | T14: =IF(AND(ISNUMBER(T13),ISNUMBER(O13)),IFERROR(T13/O13-1,""),"") | U14: =IF(AND(ISNUMBER(U13),ISNUMBER(P13)),IFERROR(U13/P13-1,""),"") | ... BX14: =IF(AND(ISNUMBER(BX13),ISNUMBER(BS13)),IFERROR(BX13/BS13-1,""),"") -> -0.020249892 | BY14: =$BX$14 -> -0.020249892 | BZ14: =$BX$14 -> -0.020249892 | CA14: =IFERROR(CA13/BV13-1,"") -> -0.01703494 | CB14: =CHOOSE(MATCH($CF$2,{"Bull","Base","Bear"},0),$CO$30,$CP$30,$CQ$30) -> 0.06 | CC14: =CHOOSE(MATCH($CF$2,{"Bull","Base","Bear"},0),$CO$31,$CP$31,$CQ$31) -> 0.055 | CD14: =CHOOSE(MATCH($CF$2,{"Bull","Base","Bear"},0),$CO$32,$CP$32,$CQ$32) -> 0.05 | CE14: =CHOOSE(MATCH($CF$2,{"Bull","Base","Bear"},0),$CO$33,$CP$33,$CQ$33) -> 0.05 | CN14: FY26 net earnings from continuing ops attributable ($m, mid-point reconciliation) | CO14: 1043 | CP14: 1043 | CQ14: 1043 | CR14: Q2-26 release mid-point reconciliation (memo only).
B15: Revenue ÷ (shipments × ASP) — freight, internal & other (x) | C15: =IFERROR(C16/(C11*C13),"") | D15: =IFERROR(D16/(D11*D13),"") | E15: =IFERROR(E16/(E11*E13),"") | F15: =IFERROR(F16/(F11*F13),"") | G15: =IFERROR(G16/(G11*G13),"") | H15: =IFERROR(H16/(H11*H13),"") | I15: =IFERROR(I16/(I11*I13),"") -> 0.98366154 | J15: =IFERROR(J16/(J11*J13),"") -> 0.99165366 | ... BX15: =IFERROR(BX16/(BX11*BX13),"") -> 1.0943871 | BY15: =BT15 -> 1.0835347 | BZ15: =BU15 -> 1.083995 | CA15: =IFERROR(CA16/(CA11*CA13),"") -> 1.0891886 | CB15: =CA15 -> 1.0891886 | CC15: =CB15 -> 1.0891886 | CD15: =CC15 -> 1.0891886 | CE15: =CD15 -> 1.0891886 | CF15: Bridges shipments × ASP to product-line revenues (freight revenues included from 2018/2023 basis; internal sales). Forecast: prior-year quarter (Q3/Q4-26E) / prior year (2027E+). | CN15: FY26 point estimates (all cases)
B16: Revenues | H16: 1213.2 | I16: 1304 | J16: 247.8 | K16: 357.2 | L16: 411.2 | M16: 331.2 | N16: 1347.5 | O16: 263.9 | P16: 422 | Q16: 478.8 | R16: 405.4 | S16: 1570 | T16: 332.2 | U16: 481.5 | V16: 530 | W16: 449.9 | X16: 1793.7 | Y16: 406.5 | Z16: 516.3 | AA16: 542.7 | AB16: 501.2 | AC16: 2060.9 | AD16: 451.4 | AE16: 578.4 | AF16: 591.2 | AG16: 516.3 | AH16: 2137.2 | AI16: 425 | AJ16: 665.308 | AK16: 687.8 | AL16: 577.549 | AM16: 2355.673 | AN16: 541.473 | AO16: 757.802 | AP16: 818.693 | AQ16: 635.295 | AR16: 2756.738 | AS16: 570.3 | AT16: 754.9 | AU16: 766.9 | AV16: 677.2 | AW16: 2769.3 | AX16: 572.6 | AY16: 801.8 | AZ16: 857.1 | BA16: 827 | BB16: 3058.5 | BC16: 685.9 | BD16: 955.2 | BE16: 1015.7 | BF16: 849.2 | BG16: 3506 | BH16: 911.9 | BI16: 1151.4 | BJ16: 1216.3 | BK16: 1021.9 | BL16: 4301.6 | BM16: 885 | BN16: 1242 | BO16: 1250 | BP16: 1137 | BQ16: 4514 | BR16: 1002 | BS16: 1320 | BT16: 1458 | BU16: 1225 | BV16: 5004 | BW16: 1142 | BX16: 1533 | BY16: =BY11*BY13*BY15 -> 1737.1838 | BZ16: =BZ11*BZ13*BZ15 -> 1459.568 | CA16: =SUM(BW16,BX16,BY16,BZ16) -> 5871.7517 | CB16: =CB11*CB13*CB15 -> 6410.7786 | CC16: =CC11*CC13*CC15 -> 6966.2725 | CD16: =CD11*CD13*CD15 -> 7497.4508 | CE16: =CE11*CE13*CE15 -> 8069.1314 | CH16: =IFERROR((CE16/BV16)^(1/5)-1,"n/m") -> 0.10027665 | CI16: =IFERROR((BV16/AW16)^(1/5)-1,"n/m") -> 0.12561393 | CJ16: =IFERROR((BV16/X16)^(1/10)-1,"n/m") -> 0.10804334 | CK16: =IFERROR((BV16/C16)^(1/19)-1,"n/m") -> n/m | CN16: Interest expense, net of interest income ($m) | CP16: 223 | CR16: Q2-26 mid-point reconciliation (legacy; LNA financing added separately).
B17: Revenues y/y % | D17: =IF(AND(ISNUMBER(D16),ISNUMBER(C16)),IFERROR(D16/C16-1,""),"") | E17: =IF(AND(ISNUMBER(E16),ISNUMBER(D16)),IFERROR(E16/D16-1,""),"") | F17: =IF(AND(ISNUMBER(F16),ISNUMBER(E16)),IFERROR(F16/E16-1,""),"") | G17: =IF(AND(ISNUMBER(G16),ISNUMBER(F16)),IFERROR(G16/F16-1,""),"") | H17: =IF(AND(ISNUMBER(H16),ISNUMBER(G16)),IFERROR(H16/G16-1,""),"") | I17: =IF(AND(ISNUMBER(I16),ISNUMBER(H16)),IFERROR(I16/H16-1,""),"") -> 0.074843389 | N17: =IF(AND(ISNUMBER(N16),ISNUMBER(I16)),IFERROR(N16/I16-1,""),"") -> 0.033358896 | O17: =IF(AND(ISNUMBER(O16),ISNUMBER(J16)),IFERROR(O16/J16-1,""),"") -> 0.064971751 | P17: =IF(AND(ISNUMBER(P16),ISNUMBER(K16)),IFERROR(P16/K16-1,""),"") -> 0.18141097 | Q17: =IF(AND(ISNUMBER(Q16),ISNUMBER(L16)),IFERROR(Q16/L16-1,""),"") -> 0.16439689 | R17: =IF(AND(ISNUMBER(R16),ISNUMBER(M16)),IFERROR(R16/M16-1,""),"") -> 0.22403382 | S17: =IF(AND(ISNUMBER(S16),ISNUMBER(N16)),IFERROR(S16/N16-1,""),"") -> 0.16512059 | T17: =IF(AND(ISNUMBER(T16),ISNUMBER(O16)),IFERROR(T16/O16-1,""),"") -> 0.25881016 | U17: =IF(AND(ISNUMBER(U16),ISNUMBER(P16)),IFERROR(U16/P16-1,""),"") -> 0.14099526 | ... BX17: =IF(AND(ISNUMBER(BX16),ISNUMBER(BS16)),IFERROR(BX16/BS16-1,""),"") -> 0.16136364 | BY17: =IFERROR(BY16/BT16-1,"") -> 0.19148406 | BZ17: =IFERROR(BZ16/BU16-1,"") -> 0.19148406 | CA17: =IFERROR(CA16/BV16-1,"") -> 0.17341162 | CB17: =IFERROR(CB16/CA16-1,"") -> 0.0918 | CC17: =IFERROR(CC16/CB16-1,"") -> 0.08665 | CD17: =IFERROR(CD16/CC16-1,"") -> 0.07625 | CE17: =IFERROR(CE16/CD16-1,"") -> 0.07625 | CN17: Tax rate (GAAP) | CP17: =279/(1043+279) -> 0.21104387 | CR17: Implied by the Q2-26 mid-point reconciliation: tax $279m / pre-tax $1,322m.
B18: Gross profit (GAAP) | I18: 240.6 | J18: 2.1 | K18: 78.9 | L18: 108.2 | M18: 69.9 | N18: 259.1 | O18: 10.1 | P18: 100.1 | Q18: 119.3 | R18: 94.6 | S18: 324.1 | T18: 41.4 | U18: 137.2 | V18: 166.1 | W18: 122.2 | X18: 467 | Y18: 81.1 | Z18: 164.4 | AA18: 173 | AB18: 136.3 | AC18: 554.8 | AD18: 79.3 | AE18: 173.5 | AF18: 188 | AG18: 161.3 | AH18: 601.9 | AI18: 53 | AJ18: 198.54 | AK18: 209.082 | AL18: 146.133 | AM18: 606.759 | AN18: 97.562 | AO18: 251.422 | AP18: 287.024 | AQ18: 171.377 | AR18: 807.884 | AS18: 93.4 | AT18: 268 | AU18: 279.1 | AV18: 208.2 | AW18: 848.5 | AX18: 121.8 | AY18: 273 | AZ18: 292.9 | BA18: 217.1 | BB18: 904.8 | BC18: 101.9 | BD18: 309 | BE18: 330.3 | BF18: 239 | BG18: 980.3 | BH18: 238.1 | BI18: 370.9 | BJ18: 440.6 | BK18: 328.6 | BL18: 1378.1 | BM18: 239 | BN18: 392 | BO18: 438 | BP18: 379 | BQ18: 1449 | BR18: 297 | BS18: 430 | BT18: 531 | BU18: 420 | BV18: 1677 | BW18: 288 | BX18: 418 | BY18: =BY16*BY20 -> 588.09944 | BZ18: =BZ16*BZ20 -> 462.96873 | CA18: =SUM(BW18,BX18,BY18,BZ18) -> 1757.0682 | CB18: =CB16*CB20 -> 2115.5569 | CC18: =CC16*CC20 -> 2368.5327 | CD18: =CD16*CD20 -> 2624.1078 | CE18: =CE16*CE20 -> 2864.5417 | CF18: Forecast gross profit = revenues × gross margin. | CH18: =IFERROR((CE18/BV18)^(1/5)-1,"n/m") -> 0.11302371 | CI18: =IFERROR((BV18/AW18)^(1/5)-1,"n/m") -> 0.1459779 | CJ18: =IFERROR((BV18/X18)^(1/10)-1,"n/m") -> 0.13637486 | CK18: =IFERROR((BV18/C18)^(1/19)-1,"n/m") -> n/m | CN18: DD&A incl. equity-affiliate results ($m) | CP18: 800 | CR18: Q2-26 mid-point reconciliation.
B19: Gross margin before outlook calibration % (Q3/Q4-26E helper) | BY19: =BT20+(BW18+BX18)/(BW16+BX16)-(BR18+BS18)/(BR16+BS16) -> 0.3150306 | BZ19: =BU20+(BW18+BX18)/(BW16+BX16)-(BR18+BS18)/(BR16+BS16) -> 0.29369021 | CF19: Q3/Q4-26E: prior-year quarter margin + (1H/26 − 1H/25 margin drift). | CN19: Capital expenditures ($m) | CO19: 600 | CP19: 575 | CQ19: 550 | CR19: Latest published range $550–600m (Q1-26 release guidance table); Q2 release cites capex reductions without a new range.
B20: Gross margin % | C20: =IF(AND(ISNUMBER(C18),ISNUMBER(C16)),IFERROR(C18/C16,""),"") | D20: =IF(AND(ISNUMBER(D18),ISNUMBER(D16)),IFERROR(D18/D16,""),"") | E20: =IF(AND(ISNUMBER(E18),ISNUMBER(E16)),IFERROR(E18/E16,""),"") | F20: =IF(AND(ISNUMBER(F18),ISNUMBER(F16)),IFERROR(F18/F16,""),"") | G20: =IF(AND(ISNUMBER(G18),ISNUMBER(G16)),IFERROR(G18/G16,""),"") | H20: =IF(AND(ISNUMBER(H18),ISNUMBER(H16)),IFERROR(H18/H16,""),"") | I20: =IF(AND(ISNUMBER(I18),ISNUMBER(I16)),IFERROR(I18/I16,""),"") -> 0.1845092 | J20: =IF(AND(ISNUMBER(J18),ISNUMBER(J16)),IFERROR(J18/J16,""),"") -> 0.0084745763 | ... BX20: =IF(AND(ISNUMBER(BX18),ISNUMBER(BX16)),IFERROR(BX18/BX16,""),"") -> 0.27266797 | BY20: =BY19+BY121 -> 0.33853612 | BZ20: =BZ19+BZ121 -> 0.31719573 | CA20: =IFERROR(CA18/CA16,"") -> 0.29924088 | CB20: =CHOOSE(MATCH($CF$2,{"Bull","Base","Bear"},0),$CO$35,$CP$35,$CQ$35) -> 0.33 | CC20: =CHOOSE(MATCH($CF$2,{"Bull","Base","Bear"},0),$CO$36,$CP$36,$CQ$36) -> 0.34 | CD20: =CHOOSE(MATCH($CF$2,{"Bull","Base","Bear"},0),$CO$37,$CP$37,$CQ$37) -> 0.35 | CE20: =CHOOSE(MATCH($CF$2,{"Bull","Base","Bear"},0),$CO$38,$CP$38,$CQ$38) -> 0.355 | CF20: Q3/Q4-26E: margin before calibration + outlook calibration Δ (row "Outlook calibration"). 2027E+: scenario lever AGG_GM. | CH20: =IFERROR(AVERAGE(CA20,CB20,CC20,CD20,CE20),"n/m") -> 0.33484818 | CI20: =IFERROR(AVERAGE(BB20,BG20,BL20,BQ20,BV20),"n/m") -> 0.31038801 | CJ20: =IFERROR(AVERAGE(AC20,AH20,AM20,AR20,AW20,BB20,BG20,BL20,BQ20,BV20),"n/m") -> 0.29597996 | CK20: =IFERROR(AVERAGE(C20,D20,E20,F20,G20,H20,I20,N20,S20,X20,AC20,AH20,AM20,AR20,AW20,BB20,BG20,BL20,BQ20,BV20),"n/m") -> 0.27166997 | CN20: LNA run-rate cost synergies ($m) | CP20: 85 | CR20: Deal release (29-Jun-2026): ~$85m annual run-rate cost synergies.
B21: Gross profit per ton ($) | C21: =IF(AND(ISNUMBER(C18),ISNUMBER(C11)),IFERROR(C18/C11,""),"") | D21: =IF(AND(ISNUMBER(D18),ISNUMBER(D11)),IFERROR(D18/D11,""),"") | E21: =IF(AND(ISNUMBER(E18),ISNUMBER(E11)),IFERROR(E18/E11,""),"") | F21: =IF(AND(ISNUMBER(F18),ISNUMBER(F11)),IFERROR(F18/F11,""),"") | G21: =IF(AND(ISNUMBER(G18),ISNUMBER(G11)),IFERROR(G18/G11,""),"") | H21: =IF(AND(ISNUMBER(H18),ISNUMBER(H11)),IFERROR(H18/H11,""),"") | I21: =IF(AND(ISNUMBER(I18),ISNUMBER(I11)),IFERROR(I18/I11,""),"") -> 1.8748393 | J21: =IF(AND(ISNUMBER(J18),ISNUMBER(J11)),IFERROR(J18/J11,""),"") -> 0.092190175 | ... BX21: =IF(AND(ISNUMBER(BX18),ISNUMBER(BX11)),IFERROR(BX18/BX11,""),"") -> 6.7857143 | BY21: =IFERROR(BY18/BY11,"") -> 8.3521693 | BZ21: =IFERROR(BZ18/BZ11,"") -> 7.7852019 | CA21: =IFERROR(CA18/CA11,"") -> 7.4647971 | CB21: =IFERROR(CB18/CB11,"") -> 8.7260338 | CC21: =IFERROR(CC18/CC11,"") -> 9.4849343 | CD21: =IFERROR(CD18/CD11,"") -> 10.252098 | CE21: =IFERROR(CE18/CE11,"") -> 10.918484 | CH21: =IFERROR((CE21/BV21)^(1/5)-1,"n/m") -> 0.052635377 | CI21: =IFERROR((BV21/AW21)^(1/5)-1,"n/m") -> 0.13177451 | CJ21: =IFERROR((BV21/X21)^(1/10)-1,"n/m") -> 0.10962275 | CK21: =IFERROR((BV21/C21)^(1/19)-1,"n/m") -> n/m | CN21: 2H/26 share repurchases ($m) | CO21: 100 | CP21: 0 | CQ21: 0 | CR21: Post-LNA deleveraging: Base assumes no 2H buybacks (1H/26: $200m).
B22: DD&A in cost of revenues (where disclosed) | BR22: 113 | BS22: 125 | BW22: 131 | BX22: 166 | CN22: Minimum net debt / Adjusted EBITDA (x) — buyback floor 2027E+ | CO22: 2.5 | CP22: 2.25 | CQ22: 2 | CR22: MLM target: < 2.5x within 24 months of closing.
B23: Cash gross profit per ton ($) (where DD&A disclosed) | C23: =IFERROR(IF(ISNUMBER(C22),(C18+C22)/C11,""),"") | D23: =IFERROR(IF(ISNUMBER(D22),(D18+D22)/D11,""),"") | E23: =IFERROR(IF(ISNUMBER(E22),(E18+E22)/E11,""),"") | F23: =IFERROR(IF(ISNUMBER(F22),(F18+F22)/F11,""),"") | G23: =IFERROR(IF(ISNUMBER(G22),(G18+G22)/G11,""),"") | H23: =IFERROR(IF(ISNUMBER(H22),(H18+H22)/H11,""),"") | I23: =IFERROR(IF(ISNUMBER(I22),(I18+I22)/I11,""),"") | J23: =IFERROR(IF(ISNUMBER(J22),(J18+J22)/J11,""),"") | ... BX23: =IFERROR(IF(ISNUMBER(BX22),(BX18+BX22)/BX11,""),"") -> 9.4805195
B24: Memo: reported aggregates volume change % (company) | C24: -0.023 | D24: -0.081 | E24: -0.126 | F24: -0.226 | G24: 0.054 | H24: -0.038 | I24: 0.026 | J24: -0.088 | K24: -0.016 | L24: 0.081 | M24: -0.004 | N24: 0.001 | O24: 0.081 | P24: 0.127 | Q24: 0.138 | R24: 0.188 | S24: 0.137 | T24: 0.173 | U24: 0.078 | V24: 0.054 | W24: 0.017 | X24: 0.071 | Y24: 0.133 | Z24: 0.013 | AA24: -0.047 | AB24: 0.004 | AC24: 0.014 | AD24: -0.002 | AE24: 0.02 | AF24: -0.032 | AG24: -0.009 | AH24: -0.006 | AI24: -0.079 | AJ24: 0.113 | AK24: 0.149 | AL24: 0.114 | AM24: 0.083 | AN24: 0.242 | AO24: 0.099 | AP24: 0.124 | AQ24: 0.04 | AR24: 0.117 | AS24: 0.023 | AT24: -0.037 | AU24: -0.087 | AV24: 0.03 | AW24: -0.024 | AX24: -0.03 | AY24: 0.033 | AZ24: 0.102 | BA24: 0.197 | BB24: 0.079 | BC24: 0.134 | BD24: 0.093 | BE24: 0.056 | BF24: -0.12 | BG24: 0.033 | BH24: -0.008 | BI24: -0.057 | BJ24: -0.073 | BK24: -0.021 | BM24: -0.123 | BN24: -0.028 | BO24: -0.039 | BP24: 0.027 | BQ24: -0.04 | BT24: 0.08 | BU24: 0.02 | BV24: 0.04 | BW24: 0.124 | BX24: 0.17 | CN24: AGG_vol (aggregates shipments y/y) | CO24: 0.02 | CP24: Δ → | CQ24: -0.02 | CR24: Infrastructure (IIJA tail), data centers / heavy nonresidential vs. soft housing; 2026 organic guide +1–3%.
B25: Memo: reported aggregates ASP change % (company) | C25: 0.135 | D25: 0.104 | E25: 0.069 | F25: 0.021 | G25: -0.034 | H25: 0.027 | I25: 0.008 | J25: 0.057 | K25: 0.017 | L25: 0.023 | M25: 0.034 | N25: 0.03 | O25: -0.013 | P25: 0.05 | Q25: 0.058 | R25: 0.067 | S25: 0.045 | T25: 0.114 | U25: 0.085 | V25: 0.054 | W25: 0.084 | X25: 0.08 | Y25: 0.081 | Z25: 0.068 | AA25: 0.085 | AB25: 0.056 | AC25: 0.073 | AD25: 0.053 | AE25: 0.038 | AF25: 0.051 | AG25: 0.04 | AH25: 0.045 | AI25: 0.023 | AJ25: 0.035 | AK25: 0.015 | AL25: 0.005 | AM25: 0.019 | AN25: 0.023 | AO25: 0.034 | AP25: 0.053 | AQ25: 0.053 | AR25: 0.042 | AS25: 0.027 | AT25: 0.033 | AU25: 0.027 | AV25: 0.035 | AW25: 0.031 | AX25: 0.034 | AY25: 0.029 | AZ25: 0.012 | BA25: 0.014 | BB25: 0.021 | BC25: 0.056 | BD25: 0.084 | BE25: 0.116 | BF25: 0.165 | BG25: 0.106 | BH25: 0.226 | BI25: 0.186 | BJ25: 0.2 | BK25: 0.15 | BM25: 0.122 | BN25: 0.116 | BO25: 0.077 | BP25: 0.086 | BQ25: 0.099 | BT25: 0.08 | BU25: 0.053 | BV25: 0.07 | BW25: 0 | BX25: -0.02 | CN25: 2027E | CO25: =CP25+$CO$24 -> 0.05 | CP25: 0.03 | CQ25: =CP25+$CQ$24 -> 0.01
CN26: 2028E | CO26: =CP26+$CO$24 -> 0.05 | CP26: 0.03 | CQ26: =CP26+$CQ$24 -> 0.01
B27: Other Building Materials (ready mixed concrete · asphalt & paving; cement Jul-2014 → divested / discontinued 2024–26) | CF27: OTHER BUILDING MATERIALS — modelling logic | CN27: 2029E | CO27: =CP27+$CO$24 -> 0.045 | CP27: 0.025 | CQ27: =CP27+$CQ$24 -> 0.005
B28: Revenues | H28: =N(H33)+N(H36)+N(H39)+N(H42)+N(H44)+N(H46) -> 106.2 | I28: =N(I33)+N(I36)+N(I39)+N(I42)+N(I44)+N(I46) -> 332.5 | J28: =N(J33)+N(J36)+N(J39)+N(J42)+N(J44)+N(J46) -> 42.2 | K28: =N(K33)+N(K36)+N(K39)+N(K42)+N(K44)+N(K46) -> 94.9 | L28: =N(L33)+N(L36)+N(L39)+N(L42)+N(L44)+N(L46) -> 133.5 | M28: =N(M33)+N(M36)+N(M39)+N(M42)+N(M44)+N(M46) -> 102.1 | N28: =N(N33)+N(N36)+N(N39)+N(N42)+N(N44)+N(N46) -> 370.1 | O28: =N(O33)+N(O36)+N(O39)+N(O42)+N(O44)+N(O46) -> 58.4 | ... BX28: =N(BX33)+N(BX36)+N(BX39)+N(BX42)+N(BX44)+N(BX46) -> 303 | BY28: =BT28*(1+BY29) -> 409.02412 | BZ28: =BU28*(1+BZ29) -> 288.9971 | CA28: =SUM(BW28,BX28,BY28,BZ28) -> 1117.0212 | CB28: =CA28*(1+CB29) -> 1150.5319 | CC28: =CB28*(1+CC29) -> 1185.0478 | CD28: =CC28*(1+CD29) -> 1220.5992 | CE28: =CD28*(1+CE29) -> 1257.2172 | CF28: Historical = sum of the product lines reported in each period (memo rows below). Q3/Q4-26E: prior-year quarter × (1 + Q2/26 y/y). 2027E+: scenario lever OBM_growth. | CH28: =IFERROR((CE28/BV28)^(1/5)-1,"n/m") -> 0.04852727 | CI28: =IFERROR((BV28/AW28)^(1/5)-1,"n/m") -> -0.10591794 | CJ28: =IFERROR((BV28/X28)^(1/10)-1,"n/m") -> -0.022609745 | CK28: =IFERROR((BV28/C28)^(1/19)-1,"n/m") -> n/m | CN28: 2030E | CO28: =CP28+$CO$24 -> 0.045 | CP28: 0.025 | CQ28: =CP28+$CQ$24 -> 0.005
B29: Revenues y/y % | D29: =IF(AND(ISNUMBER(D28),ISNUMBER(C28)),IFERROR(D28/C28-1,""),"") | E29: =IF(AND(ISNUMBER(E28),ISNUMBER(D28)),IFERROR(E28/D28-1,""),"") | F29: =IF(AND(ISNUMBER(F28),ISNUMBER(E28)),IFERROR(F28/E28-1,""),"") | G29: =IF(AND(ISNUMBER(G28),ISNUMBER(F28)),IFERROR(G28/F28-1,""),"") | H29: =IF(AND(ISNUMBER(H28),ISNUMBER(G28)),IFERROR(H28/G28-1,""),"") | I29: =IF(AND(ISNUMBER(I28),ISNUMBER(H28)),IFERROR(I28/H28-1,""),"") -> 2.1308851 | N29: =IF(AND(ISNUMBER(N28),ISNUMBER(I28)),IFERROR(N28/I28-1,""),"") -> 0.11308271 | O29: =IF(AND(ISNUMBER(O28),ISNUMBER(J28)),IFERROR(O28/J28-1,""),"") -> 0.38388626 | P29: =IF(AND(ISNUMBER(P28),ISNUMBER(K28)),IFERROR(P28/K28-1,""),"") -> 0.24341412 | Q29: =IF(AND(ISNUMBER(Q28),ISNUMBER(L28)),IFERROR(Q28/L28-1,""),"") -> 1.8494382 | R29: =IF(AND(ISNUMBER(R28),ISNUMBER(M28)),IFERROR(R28/M28-1,""),"") -> 2.0940255 | S29: =IF(AND(ISNUMBER(S28),ISNUMBER(N28)),IFERROR(S28/N28-1,""),"") -> 1.3588219 | T29: =IF(AND(ISNUMBER(T28),ISNUMBER(O28)),IFERROR(T28/O28-1,""),"") -> 3.125 | U29: =IF(AND(ISNUMBER(U28),ISNUMBER(P28)),IFERROR(U28/P28-1,""),"") -> 1.6118644 | ... BX29: =IF(AND(ISNUMBER(BX28),ISNUMBER(BS28)),IFERROR(BX28/BS28-1,""),"") -> 0.11808118 | BY29: =$BX$29+BY118 -> 0.16531089 | BZ29: =$BX$29+BZ118 -> 0.16531089 | CA29: =IFERROR(CA28/BV28-1,"") -> 0.12602946 | CB29: =CHOOSE(MATCH($CF$2,{"Bull","Base","Bear"},0),$CO$40,$CP$40,$CQ$40) -> 0.03 | CC29: =CHOOSE(MATCH($CF$2,{"Bull","Base","Bear"},0),$CO$41,$CP$41,$CQ$41) -> 0.03 | CD29: =CHOOSE(MATCH($CF$2,{"Bull","Base","Bear"},0),$CO$42,$CP$42,$CQ$42) -> 0.03 | CE29: =CHOOSE(MATCH($CF$2,{"Bull","Base","Bear"},0),$CO$43,$CP$43,$CQ$43) -> 0.03 | CF29: Note: 2025 y/y compares the continuing-operations recast with 2024 as reported (2024 still includes Texas/California cement & ready mix). | CN29: AGG_ASP (aggregates ASP y/y) | CO29: 0.015 | CP29: Δ → | CQ29: -0.015 | CR29: Organic ASP guide +4–6% for 2026; mid-single-digit pricing through the cycle.
B30: Gross profit (GAAP) | I30: =N(I34)+N(I37)+N(I40)+N(I43)+N(I45)+N(I47) -> 13.5 | J30: =N(J34)+N(J37)+N(J40)+N(J43)+N(J45)+N(J47) -> -7.1 | K30: =N(K34)+N(K37)+N(K40)+N(K43)+N(K45)+N(K47) -> 6.3 | L30: =N(L34)+N(L37)+N(L40)+N(L43)+N(L45)+N(L47) -> 14.7 | M30: =N(M34)+N(M37)+N(M40)+N(M43)+N(M45)+N(M47) -> 8.3 | N30: =N(N34)+N(N37)+N(N40)+N(N43)+N(N45)+N(N47) -> 22.6 | O30: =N(O34)+N(O37)+N(O40)+N(O43)+N(O45)+N(O47) -> -2.5 | P30: =N(P34)+N(P37)+N(P40)+N(P43)+N(P45)+N(P47) -> 11.6 | ... BX30: =N(BX34)+N(BX37)+N(BX40)+N(BX43)+N(BX45)+N(BX47) -> 34 | BY30: =BY28*BY32 -> 69.297075 | BZ30: =BZ28*BZ32 -> 31.303094 | CA30: =SUM(BW30,BX30,BY30,BZ30) -> 118.60017 | CB30: =CB28*CB32 -> 115.05319 | CC30: =CC28*CC32 -> 124.43002 | CD30: =CD28*CD32 -> 134.26592 | CE30: =CE28*CE32 -> 138.29389 | CH30: =IFERROR((CE30/BV30)^(1/5)-1,"n/m") -> 0.071310562 | CI30: =IFERROR((BV30/AW30)^(1/5)-1,"n/m") -> -0.20618177 | CJ30: =IFERROR((BV30/X30)^(1/10)-1,"n/m") -> -0.060181606 | CK30: =IFERROR((BV30/C30)^(1/19)-1,"n/m") -> n/m | CN30: 2027E | CO30: =CP30+$CO$29 -> 0.075 | CP30: 0.06 | CQ30: =CP30+$CQ$29 -> 0.045
B31: Gross margin before outlook calibration % (Q3/Q4-26E helper) | BY31: =BT32+(BW30+BX30)/(BW28+BX28)-(BR30+BS30)/(BR28+BS28) -> 0.145915 | BZ31: =BU32+(BW30+BX30)/(BW28+BX28)-(BR30+BS30)/(BR28+BS28) -> 0.084810777 | CN31: 2028E | CO31: =CP31+$CO$29 -> 0.07 | CP31: 0.055 | CQ31: =CP31+$CQ$29 -> 0.04
B32: Gross margin % | C32: =IF(AND(ISNUMBER(C30),ISNUMBER(C28)),IFERROR(C30/C28,""),"") | D32: =IF(AND(ISNUMBER(D30),ISNUMBER(D28)),IFERROR(D30/D28,""),"") | E32: =IF(AND(ISNUMBER(E30),ISNUMBER(E28)),IFERROR(E30/E28,""),"") | F32: =IF(AND(ISNUMBER(F30),ISNUMBER(F28)),IFERROR(F30/F28,""),"") | G32: =IF(AND(ISNUMBER(G30),ISNUMBER(G28)),IFERROR(G30/G28,""),"") | H32: =IF(AND(ISNUMBER(H30),ISNUMBER(H28)),IFERROR(H30/H28,""),"") | I32: =IF(AND(ISNUMBER(I30),ISNUMBER(I28)),IFERROR(I30/I28,""),"") -> 0.040601504 | J32: =IF(AND(ISNUMBER(J30),ISNUMBER(J28)),IFERROR(J30/J28,""),"") -> -0.16824645 | ... BX32: =IF(AND(ISNUMBER(BX30),ISNUMBER(BX28)),IFERROR(BX30/BX28,""),"") -> 0.11221122 | BY32: =BY31+BY121 -> 0.16942051 | BZ32: =BZ31+BZ121 -> 0.10831629 | CA32: =IFERROR(CA30/CA28,"") -> 0.10617539 | CB32: =CHOOSE(MATCH($CF$2,{"Bull","Base","Bear"},0),$CO$45,$CP$45,$CQ$45) -> 0.1 | CC32: =CHOOSE(MATCH($CF$2,{"Bull","Base","Bear"},0),$CO$46,$CP$46,$CQ$46) -> 0.105 | CD32: =CHOOSE(MATCH($CF$2,{"Bull","Base","Bear"},0),$CO$47,$CP$47,$CQ$47) -> 0.11 | CE32: =CHOOSE(MATCH($CF$2,{"Bull","Base","Bear"},0),$CO$48,$CP$48,$CQ$48) -> 0.11 | CH32: =IFERROR(AVERAGE(CA32,CB32,CC32,CD32,CE32),"n/m") -> 0.10623508 | CI32: =IFERROR(AVERAGE(BB32,BG32,BL32,BQ32,BV32),"n/m") -> 0.15965129 | CJ32: =IFERROR(AVERAGE(AC32,AH32,AM32,AR32,AW32,BB32,BG32,BL32,BQ32,BV32),"n/m") -> 0.16366271 | CK32: =IFERROR(AVERAGE(C32,D32,E32,F32,G32,H32,I32,N32,S32,X32,AC32,AH32,AM32,AR32,AW32,BB32,BG32,BL32,BQ32,BV32),"n/m") -> 0.14373791 | CN32: 2029E | CO32: =CP32+$CO$29 -> 0.065 | CP32: 0.05 | CQ32: =CP32+$CQ$29 -> 0.035
B33: Memo: Cement revenues (TXI from Jul-2014) | Q33: 109.5 | R33: 100 | S33: 209.6 | T33: 96.6 | U33: 100.4 | V33: 110.5 | W33: 60.1 | X33: 367.6 | Y33: 69.9 | Z33: 59.8 | AA33: 60.1 | AB33: 85.4 | AC33: 364.4 | AD33: 93.7 | AE33: 99 | AF33: 88.6 | AG33: 90.2 | AH33: 371.5 | AI33: 89.2 | AJ33: 113.148 | AK33: 98.223 | AL33: 87.277 | AM33: 387.83 | AN33: 99.017 | AO33: 112.35 | AP33: 119.609 | AQ33: 108.136 | AR33: 439.112 | AS33: 106.6 | AT33: 109.5 | AU33: 115.6 | AV33: 120.8 | AW33: 452.5 | AX33: 109.6 | AY33: 116.5 | AZ33: 132.3 | BA33: 136.1 | BB33: 494.5 | BC33: 134.3 | BD33: 157.9 | BE33: 163.2 | BF33: 146.9 | BG33: 602.3 | BH33: 168.6 | BI33: 197.7 | BJ33: 199.1 | BK33: 160.2 | BL33: 725.5 | CN33: 2030E | CO33: =CP33+$CO$29 -> 0.065 | CP33: 0.05 | CQ33: =CP33+$CQ$29 -> 0.035
B34: Memo: Cement gross profit | Q34: 24.2 | R34: 28.3 | S34: 52.5 | T34: 19 | U34: 30.4 | V34: 38.2 | W34: 15.8 | X34: 103.5 | Y34: 32.6 | Z34: 24 | AA34: 29.7 | AB34: 26.7 | AC34: 120.1 | AD34: 30.9 | AE34: 29.4 | AF34: 27.6 | AG34: 29.4 | AH34: 117.3 | AI34: 23.7 | AJ34: 41.305 | AK34: 32.543 | AL34: 28.631 | AM34: 126.213 | AN34: 13.779 | AO34: 42.229 | AP34: 48.519 | AQ34: 38.895 | AR34: 143.421 | AS34: 27.3 | AT34: 43.4 | AU34: 46.5 | AV34: 53.7 | AW34: 170.9 | AX34: 15.3 | AY34: 36.1 | AZ34: 49.9 | BA34: 55.8 | BB34: 157 | BC34: 27.3 | BD34: 51.1 | BE34: 67.7 | BF34: 58.2 | BG34: 204.4 | BH34: 47.1 | BI34: 93.3 | BJ34: 108.7 | BK34: 84.5 | BL34: 333.6 | CN34: AGG_GM (aggregates gross margin) | CO34: 0.02 | CP34: Δ → | CQ34: -0.02 | CR34: FY25 33.5%; 1H/26 26.4% (inventory markup, acquired-site mix). Unit-margin expansion as pricing > cost.
B35: Memo: Cement shipments (million tons) | Q35: 1.525 | R35: 1.3 | S35: 2.824 | T35: 1.217 | U35: 1.203 | V35: 1.337 | W35: 0.802 | X35: 4.558 | Y35: 0.957 | Z35: 0.854 | AA35: 0.905 | AB35: 0.81 | AC35: 3.525 | AD35: 0.905 | AE35: 0.922 | AF35: 0.817 | AG35: 0.824 | AH35: 3.467 | AI35: 0.825 | AJ35: 1.028 | AK35: 0.879 | AL35: 0.775 | AM35: 3.508 | AN35: 0.885 | AO35: 0.978 | AP35: 1.06 | AQ35: 0.948 | AR35: 3.871 | AS35: 0.9 | AT35: 1 | AU35: 1 | AV35: 1.1 | AW35: 4 | AX35: 0.9 | AY35: 0.9 | AZ35: 1.1 | BA35: 1.1 | BB35: 4 | BC35: 1 | BD35: 1.1 | BE35: 1.1 | BF35: 0.9 | BG35: 4.2 | BH35: 1 | BI35: 1.1 | BJ35: 1.1 | BK35: 0.9 | BL35: 4 | BM35: 0.6 | BN35: 0.5 | BO35: 0.6 | BP35: 0.5 | BQ35: 2.3 | CN35: 2027E | CO35: =CP35+$CO$34 -> 0.35 | CP35: 0.33 | CQ35: =CP35+$CQ$34 -> 0.31
B36: Memo: Ready mixed concrete revenues | H36: 33 | I36: 116.3 | J36: 27.4 | K36: 36.7 | L36: 41.8 | M36: 42.7 | N36: 146.1 | O36: 38 | P36: 52.4 | Q36: 183.7 | R36: 156.3 | S36: 430.5 | T36: 127.6 | U36: 149.8 | V36: 209.6 | W36: 168.9 | X36: 655.8 | Y36: 186.8 | Z36: 214.9 | AA36: 263.7 | AB36: 237.1 | AC36: 902.6 | AD36: 222.4 | AE36: 241.9 | AF36: 240.2 | AG36: 231.6 | AH36: 936.1 | AI36: 218.5 | AJ36: 277.202 | AK36: 254.686 | AL36: 213.346 | AM36: 963.77 | AN36: 211.156 | AO36: 241.178 | AP36: 271.844 | AQ36: 223.873 | AR36: 948.052 | AS36: 189.7 | AT36: 245.1 | AU36: 254.6 | AV36: 262.7 | AW36: 952.1 | AX36: 235.3 | AY36: 268.4 | AZ36: 320.8 | BA36: 321.3 | BB36: 1145.8 | BC36: 290.1 | BD36: 226.1 | BE36: 227.4 | BF36: 207.7 | BG36: 951.3 | BH36: 220 | BI36: 271.4 | BJ36: 285.2 | BK36: 232.8 | BL36: 1009.3 | CN36: 2028E | CO36: =CP36+$CO$34 -> 0.36 | CP36: 0.34 | CQ36: =CP36+$CQ$34 -> 0.32
B37: Memo: Ready mixed concrete gross profit | I37: -1.2 | J37: -0.3 | K37: 1.6 | L37: 3.1 | M37: 3.4 | N37: 8.3 | O37: 2.9 | P37: 7 | Q37: 18.6 | R37: 10.5 | S37: 39.1 | T37: 2.1 | U37: 9.4 | V37: 23.6 | W37: 8 | X37: 43 | Y37: 18.1 | Z37: 25.3 | AA37: 39.9 | AB37: 23.1 | AC37: 99.1 | AD37: 19.8 | AE37: 26.9 | AF37: 23.9 | AG37: 21.1 | AH37: 91.7 | AI37: 15.6 | AJ37: 29.952 | AK37: 20.632 | AL37: 7.95 | AM37: 74.175 | AN37: 14.492 | AO37: 19.014 | AP37: 28.948 | AQ37: 16.324 | AR37: 78.778 | AS37: 5.9 | AT37: 26.1 | AU37: 24.7 | AV37: 22.9 | AW37: 79.6 | AX37: 19.4 | AY37: 19.1 | AZ37: 31.4 | BA37: 25.7 | BB37: 95.6 | BC37: 21.1 | BD37: 14.3 | BE37: 18.7 | BF37: 15.5 | BG37: 69.6 | BH37: 11.2 | BI37: 35.4 | BJ37: 34.1 | BK37: 21.3 | BL37: 102 | CN37: 2029E | CO37: =CP37+$CO$34 -> 0.37 | CP37: 0.35 | CQ37: =CP37+$CQ$34 -> 0.33
B38: Memo: Ready mixed concrete shipments (million cubic yards) | I38: 1.481 | J38: 0.329 | K38: 0.436 | L38: 0.496 | M38: 0.481 | N38: 1.742 | O38: 0.407 | P38: 0.552 | Q38: 2.046 | R38: 1.773 | S38: 4.779 | T38: 1.363 | U38: 1.613 | V38: 2.111 | W38: 1.618 | X38: 6.707 | Y38: 1.786 | Z38: 1.997 | AA38: 2.486 | AB38: 2.22 | AC38: 8.49 | AD38: 2.056 | AE38: 2.226 | AF38: 2.16 | AG38: 2.116 | AH38: 8.559 | AI38: 2.009 | AJ38: 2.559 | AK38: 2.232 | AL38: 1.886 | AM38: 8.685 | AN38: 1.932 | AO38: 2.162 | AP38: 2.433 | AQ38: 1.986 | AR38: 8.516 | AS38: 1.7 | AT38: 2.2 | AU38: 2.2 | AV38: 2.3 | AW38: 8.4 | AX38: 2.1 | AY38: 2.3 | AZ38: 2.7 | BA38: 2.8 | BB38: 10 | BC38: 2.4 | BD38: 1.8 | BE38: 1.7 | BF38: 1.5 | BG38: 7.4 | BH38: 1.5 | BI38: 1.8 | BJ38: 1.8 | BK38: 1.5 | BL38: 6.5 | BM38: 1.2 | BN38: 1.2 | BO38: 1.3 | BP38: 1.2 | BQ38: 5 | CN38: 2030E | CO38: =CP38+$CO$34 -> 0.375 | CP38: 0.355 | CQ38: =CP38+$CQ$34 -> 0.335
B39: Memo: Asphalt & paving revenues (asphalt + road paving before 2016) | H39: 72.6 | I39: 216.2 | J39: 14.8 | K39: 58.2 | L39: 91.7 | M39: 59.4 | N39: 224 | O39: 20.4 | P39: 65.6 | Q39: 87.2 | R39: 59.6 | S39: 232.9 | T39: 16.7 | U39: 58 | V39: 97.8 | W39: 50.9 | X39: 223.5 | Y39: 11.3 | Z39: 65.6 | AA39: 111.6 | AB39: 89.7 | AC39: 341.4 | AD39: 26.6 | AE39: 112 | AF39: 149.6 | AG39: 76.9 | AH39: 292.5 | AI39: 16.4 | AJ39: 83.14 | AK39: 99.983 | AL39: 69.19 | AM39: 268.679 | AN39: 15.846 | AO39: 82.198 | AP39: 131.099 | AQ39: 68.366 | AR39: 294.036 | AS39: 18.1 | AT39: 107 | AU39: 129.8 | AV39: 76.8 | AW39: 331.7 | AX39: 12.2 | AY39: 135.3 | AZ39: 195.9 | BA39: 170.7 | BB39: 514.2 | BC39: 54.8 | BD39: 212.3 | BE39: 309.8 | BF39: 198.6 | BG39: 775.4 | BH39: 58 | BI39: 240.9 | BJ39: 359.9 | BK39: 228.4 | BL39: 887.1 | BM39: 59 | BN39: 245 | BO39: 343 | BP39: 223 | BQ39: 869 | CN39: OBM_growth (Other Building Materials revenues y/y) | CO39: 0.03 | CP39: Δ → | CQ39: -0.03 | CR39: Ready mixed concrete & asphalt/paving (Texas ready mix divested).
B40: Memo: Asphalt & paving gross profit | I40: 14.7 | J40: -6.8 | K40: 4.7 | L40: 11.6 | M40: 4.9 | N40: 14.3 | O40: -5.4 | P40: 4.6 | Q40: 14.3 | R40: 6.6 | S40: 20 | T40: -4.8 | U40: 7.9 | V40: 22.1 | W40: 10.5 | X40: 35.8 | Y40: -6.2 | Z40: 12.8 | AA40: 30.4 | AB40: 16.5 | AC40: 53.6 | AD40: -4.8 | AE40: 20.4 | AF40: 28.8 | AG40: 20.2 | AH40: 64.7 | AI40: -7.6 | AJ40: 18.512 | AK40: 25.606 | AL40: 16.438 | AM40: 52.917 | AN40: -7.829 | AO40: 15.742 | AP40: 31.102 | AQ40: 12.168 | AR40: 50.687 | AS40: -8.1 | AT40: 21.9 | AU40: 32.6 | AV40: 13.9 | AW40: 60.4 | AX40: -8.2 | AY40: 28.7 | AZ40: 38.9 | BA40: 19.8 | BB40: 79.2 | BC40: -13.3 | BD40: 26.4 | BE40: 50.5 | BF40: 18.4 | BG40: 81.9 | BH40: -20.5 | BI40: 36.5 | BJ40: 66.1 | BK40: 26.9 | BL40: 109 | BM40: -22 | BN40: 37 | BO40: 61 | BP40: 25 | BQ40: 101 | CN40: 2027E | CO40: =CP40+$CO$39 -> 0.06 | CP40: 0.03 | CQ40: =CP40+$CQ$39 -> 0
...

Sheet Bull-Base-Bear
B2: Martin Marietta Materials (MLM) — Bull / Base / Bear Case P&L Summary | J2: Share price ($): | K2: =Model!$CA$426 -> 518.7
B3: Adjusted figures (company current definition: Adjusted EBITDA / adjusted EPS from continuing operations) · USD millions · Live panel linked to Model — toggle scenario via Model!CF2. Bull and Bear panels are value snapshots generated from the Model with the switch set to each case. 2026E includes LNA from 21-Aug-2026. | J3: As of: | K3: =TODAY() -> 46299
B5: Scenario: | C5: =Model!$CF$2 -> Base | N5: Scenario: | O5: Bull | P5: Snapshot (values) — Model run with switch = Bull | Z5: Scenario: | AA5: Bear | AB5: Snapshot (values) — Model run with switch = Bear
B7: (USDm, except EPS and shares) | C7: 2025A | D7: 2026E | E7: 2027E | F7: 2028E | G7: 2029E | H7: 2030E | I7: 25-'30 CAGR | J7: LT Hist Avg | K7: LT Hist Min | L7: LT Hist Max | N7: (USDm, except EPS and shares) | O7: 2025A | P7: 2026E | Q7: 2027E | R7: 2028E | S7: 2029E | T7: 2030E | U7: 25-'30 CAGR | V7: LT Hist Avg | W7: LT Hist Min | X7: LT Hist Max | Z7: (USDm, except EPS and shares) | AA7: 2025A | AB7: 2026E | AC7: 2027E | AD7: 2028E | AE7: 2029E | AF7: 2030E | AG7: 25-'30 CAGR | AH7: LT Hist Avg | AI7: LT Hist Min | AJ7: LT Hist Max
B9: Revenues | C9: =Model!BV152 -> 6150 | D9: =Model!CA152 -> 7969.4587 | E9: =Model!CB152 -> 9816.819 | F9: =Model!CC152 -> 10602.49 | G9: =Model!CD152 -> 11493.629 | H9: =Model!CE152 -> 12485.772 | I9: =IFERROR((H9/C9)^(1/5)-1,"n/m") -> 0.15214743 | N9: Revenues | O9: 6150 | P9: 8069.4587 | Q9: 10326.592 | R9: 11672.073 | S9: 13190.641 | T9: 14888.058 | U9: 0.19341801 | Z9: Revenues | AA9: 6150 | AB9: 7869.4587 | AC9: 9400.9541 | AD9: 9752.4 | AE9: 10086.628 | AF9: 10477.544 | AG9: 0.11244071
B10: Revenues y/y % | D10: =IFERROR(D9/C9-1,"") -> 0.29584694 | E10: =IFERROR(E9/D9-1,"") -> 0.231805 | F10: =IFERROR(F9/E9-1,"") -> 0.080033158 | G10: =IFERROR(G9/F9-1,"") -> 0.08404993 | H10: =IFERROR(H9/G9-1,"") -> 0.086321149 | N10: Revenues y/y % | P10: 0.31210711 | Q10: 0.27971306 | R10: 0.13029283 | S10: 0.13010275 | T10: 0.1286834 | Z10: Revenues y/y % | AB10: 0.27958678 | AC10: 0.19461254 | AD10: 0.037384072 | AE10: 0.034271353 | AF10: 0.038755825
B11: Aggregates shipments y/y % | C11: =Model!BV231 -> 0.038723182 | D11: =Model!CA231 -> 0.1857963 | E11: =Model!CB231 -> 0.03 | F11: =Model!CC231 -> 0.03 | G11: =Model!CD231 -> 0.025 | H11: =Model!CE231 -> 0.025 | N11: Aggregates shipments y/y % | O11: 0.038723182 | P11: 0.20197455 | Q11: 0.05 | R11: 0.05 | S11: 0.045 | T11: 0.045 | Z11: Aggregates shipments y/y % | AA11: 0.038723182 | AB11: 0.16961805 | AC11: 0.01 | AD11: 0.01 | AE11: 0.005 | AF11: 0.005
B12: Adjusted EBITDA (continuing operations) | C12: =Model!BV204 -> 2065 | D12: =Model!CA204 -> 2709.5629 | E12: =Model!CB204 -> 3592.3373 | F12: =Model!CC204 -> 4007.7658 | G12: =Model!CD204 -> 4411.5047 | H12: =Model!CE204 -> 4811.2674 | I12: =IFERROR((H12/C12)^(1/5)-1,"n/m") -> 0.18431679 | N12: Adjusted EBITDA (continuing operations) | O12: 2065 | P12: 2779.5629 | Q12: 3991.8064 | R12: 4627.5928 | S12: 5283.3716 | T12: 5966.5414 | U12: 0.23640434 | Z12: Adjusted EBITDA (continuing operations) | AA12: 2065 | AB12: 2639.5629 | AC12: 3238.4502 | AD12: 3488.1157 | AE12: 3682.491 | AF12: 3856.7328 | AG12: 0.13307824
B13: Adjusted EBITDA margin % | C13: =IFERROR(C12/C9,"") -> 0.33577236 | D13: =IFERROR(D12/D9,"") -> 0.33999334 | E13: =IFERROR(E12/E9,"") -> 0.365937 | F13: =IFERROR(F12/F9,"") -> 0.37800232 | G13: =IFERROR(G12/G9,"") -> 0.38382176 | H13: =IFERROR(H12/H9,"") -> 0.38534001 | J13: =IFERROR(AVERAGE(Model!C205,Model!D205,Model!E205,Model!F205,Model!G205,Model!H205,Model!I205,Model!N205,Model!S205,Model!X205,Model!AC205,Model!AH205,Model!AM205,Model!AR205,Model!AW205,Model!BB205,Model!BG205,Model!BL205,Model!BQ205,Model!BV205),"") -> 0.24703766 | K13: =IFERROR(MIN(Model!C205,Model!D205,Model!E205,Model!F205,Model!G205,Model!H205,Model!I205,Model!N205,Model!S205,Model!X205,Model!AC205,Model!AH205,Model!AM205,Model!AR205,Model!AW205,Model!BB205,Model!BG205,Model!BL205,Model!BQ205,Model!BV205),"") -> 0.16190616 | L13: =IFERROR(MAX(Model!C205,Model!D205,Model!E205,Model!F205,Model!G205,Model!H205,Model!I205,Model!N205,Model!S205,Model!X205,Model!AC205,Model!AH205,Model!AM205,Model!AR205,Model!AW205,Model!BB205,Model!BG205,Model!BL205,Model!BQ205,Model!BV205),"") -> 0.33577236 | N13: Adjusted EBITDA margin % | O13: 0.33577236 | P13: 0.34445469 | Q13: 0.38655604 | R13: 0.3964671 | S13: 0.4005394 | T13: 0.40076023 | V13: 0.24703766 | W13: 0.16190616 | X13: 0.33577236 | Z13: Adjusted EBITDA margin % | AA13: 0.33577236 | AB13: 0.33541861 | AC13: 0.34448102 | AD13: 0.35766742 | AE13: 0.36508643 | AF13: 0.36809513 | AH13: 0.24703766 | AI13: 0.16190616 | AJ13: 0.33577236
B15: Earnings from Operations (GAAP) | C15: =Model!BV160 -> 1437 | D15: =Model!CA160 -> 1487.3104 | E15: =Model!CB160 -> 2221.7368 | F15: =Model!CC160 -> 2571.3706 | G15: =Model!CD160 -> 2881.0247 | H15: =Model!CE160 -> 3175.3209 | I15: =IFERROR((H15/C15)^(1/5)-1,"n/m") -> 0.17183421 | N15: Earnings from Operations (GAAP) | O15: 1437 | P15: 1557.3104 | Q15: 2567.9904 | R15: 3078.826 | S15: 3574.3263 | T15: 4077.7144 | U15: 0.23194695 | Z15: Earnings from Operations (GAAP) | AA15: 1437 | AB15: 1417.3104 | AC15: 1909.902 | AD15: 2138.4196 | AE15: 2297.5341 | AF15: 2429.85 | AG15: 0.11077102
B16: Earnings from operations y/y % | D16: =IFERROR(D15/C15-1,"") -> 0.035010717 | E16: =IFERROR(E15/D15-1,"") -> 0.49379497 | F16: =IFERROR(F15/E15-1,"") -> 0.15736959 | G16: =IFERROR(G15/F15-1,"") -> 0.12042374 | H16: =IFERROR(H15/G15-1,"") -> 0.10214986 | N16: Earnings from operations y/y % | P16: 0.083723313 | Q16: 0.6489907 | R16: 0.19892427 | S16: 0.16093809 | T16: 0.1408344 | Z16: Earnings from operations y/y % | AB16: -0.013701879 | AC16: 0.34755378 | AD16: 0.11964885 | AE16: 0.074407551 | AF16: 0.057590386
B17: Operating margin (GAAP) % | C17: =IFERROR(C15/C9,"") -> 0.23365854 | D17: =IFERROR(D15/D9,"") -> 0.18662628 | E17: =IFERROR(E15/E9,"") -> 0.22631942 | F17: =IFERROR(F15/F9,"") -> 0.24252516 | G17: =IFERROR(G15/G9,"") -> 0.25066276 | H17: =IFERROR(H15/H9,"") -> 0.25431515 | J17: =IFERROR(AVERAGE(Model!C240,Model!D240,Model!E240,Model!F240,Model!G240,Model!H240,Model!I240,Model!N240,Model!S240,Model!X240,Model!AC240,Model!AH240,Model!AM240,Model!AR240,Model!AW240,Model!BB240,Model!BG240,Model!BL240,Model!BQ240,Model!BV240),"") -> 0.17151852 | K17: =IFERROR(MIN(Model!C240,Model!D240,Model!E240,Model!F240,Model!G240,Model!H240,Model!I240,Model!N240,Model!S240,Model!X240,Model!AC240,Model!AH240,Model!AM240,Model!AR240,Model!AW240,Model!BB240,Model!BG240,Model!BL240,Model!BQ240,Model!BV240),"") -> 0.076069886 | L17: =IFERROR(MAX(Model!C240,Model!D240,Model!E240,Model!F240,Model!G240,Model!H240,Model!I240,Model!N240,Model!S240,Model!X240,Model!AC240,Model!AH240,Model!AM240,Model!AR240,Model!AW240,Model!BB240,Model!BG240,Model!BL240,Model!BQ240,Model!BV240),"") -> 0.41416769 | N17: Operating margin (GAAP) % | O17: 0.23365854 | P17: 0.19298821 | Q17: 0.24867744 | R17: 0.26377714 | S17: 0.27097442 | T17: 0.27389163 | V17: 0.17151852 | W17: 0.076069886 | X17: 0.41416769 | Z17: Operating margin (GAAP) % | AA17: 0.23365854 | AB17: 0.18010265 | AC17: 0.20316044 | AD17: 0.21927111 | AE17: 0.2277802 | AF17: 0.23191028 | AH17: 0.17151852 | AI17: 0.076069886 | AJ17: 0.41416769
B19: Adjusted Net Earnings (continuing ops, attributable to MLM) | C19: =Model!BV222 -> 1020.6852 | D19: =Model!CA222 -> 1088.1684 | E19: =Model!CB222 -> 1307.885 | F19: =Model!CC222 -> 1617.8143 | G19: =Model!CD222 -> 1887.9942 | H19: =Model!CE222 -> 2108.0983 | I19: =IFERROR((H19/C19)^(1/5)-1,"n/m") -> 0.15611174 | N19: Adjusted Net Earnings (continuing ops, attributable to MLM) | O19: 1020.6852 | P19: 1143.3954 | Q19: 1575.7248 | R19: 2000.612 | S19: 2370.8108 | T19: 2695.3047 | U19: 0.21434814 | Z19: Adjusted Net Earnings (continuing ops, attributable to MLM) | AA19: 1020.6852 | AB19: 1032.9415 | AC19: 1062.9974 | AD19: 1270.102 | AE19: 1432.0514 | AF19: 1560.9968 | AG19: 0.088684505
B21: FDSO (m) | C21: =Model!BV180 -> 60.6 | D21: =Model!CA180 -> 64.208753 | E21: =Model!CB180 -> 71.329402 | F21: =Model!CC180 -> 71.479402 | G21: =Model!CD180 -> 70.543924 | H21: =Model!CE180 -> 67.941507 | I21: =IFERROR((H21/C21)^(1/5)-1,"n/m") -> 0.023133984 | N21: FDSO (m) | O21: 60.6 | P21: 64.160556 | Q21: 71.136612 | R21: 70.166257 | S21: 67.066573 | T21: 62.804938 | U21: 0.0071733669 | Z21: FDSO (m) | AA21: 60.6 | AB21: 64.208753 | AC21: 71.329402 | AD21: 71.479402 | AE21: 71.629402 | AF21: 71.308869 | AG21: 0.033080551
B23: Adjusted EPS — Diluted ($) | C23: =Model!BV224 -> 16.842989 | D23: =Model!CA224 -> 16.947354 | E23: =Model!CB224 -> 18.335847 | F23: =Model!CC224 -> 22.633294 | G23: =Model!CD224 -> 26.763385 | H23: =Model!CE224 -> 31.028136 | I23: =IFERROR((H23/C23)^(1/5)-1,"n/m") -> 0.12997101 | N23: Adjusted EPS — Diluted ($) | O23: 16.842989 | P23: 17.820846 | Q23: 22.150687 | R23: 28.512452 | S23: 35.350111 | T23: 42.91549 | U23: 0.20569922 | Z23: Adjusted EPS — Diluted ($) | AA23: 16.842989 | AB23: 16.087238 | AC23: 14.902654 | AD23: 17.768783 | AE23: 19.992508 | AF23: 21.89064 | AG23: 0.053823445
B24: EPS y/y % | D24: =IFERROR(D23/C23-1,"") -> 0.0061963014 | E24: =IFERROR(E23/D23-1,"") -> 0.081929834 | F24: =IFERROR(F23/E23-1,"") -> 0.23437401 | G24: =IFERROR(G23/F23-1,"") -> 0.18247858 | H24: =IFERROR(H23/G23-1,"") -> 0.15935022 | N24: EPS y/y % | P24: 0.058057181 | Q24: 0.24296496 | R24: 0.28720397 | S24: 0.23981307 | T24: 0.21401287 | Z24: EPS y/y % | AB24: -0.044870362 | AC24: -0.073635015 | AD24: 0.19232335 | AE24: 0.12514789 | AF24: 0.094942135
B26: P / E (x) — assumed (adjusted EPS) | F26: 26 | G26: 26 | H26: 26 | N26: P / E (x) — assumed (adjusted EPS) | R26: 30 | S26: 30 | T26: 30 | Z26: P / E (x) — assumed (adjusted EPS) | AD26: 21 | AE26: 21 | AF26: 21
B27: Price Target ($) | F27: =F26*F23 -> 588.46563 | G27: =G26*G23 -> 695.84801 | H27: =H26*H23 -> 806.73154 | N27: Price Target ($) | R27: =R26*R23 -> 855.37357 | S27: =S26*S23 -> 1060.5033 | T27: =T26*T23 -> 1287.4647 | Z27: Price Target ($) | AD27: =AD26*AD23 -> 373.14444 | AE27: =AE26*AE23 -> 419.84268 | AF27: =AF26*AF23 -> 459.70344
B28: Upside / (Downside) vs current | F28: =IFERROR(F27/$K$2-1,"") -> 0.13450093 | G28: =IFERROR(G27/$K$2-1,"") -> 0.34152305 | H28: =IFERROR(H27/$K$2-1,"") -> 0.55529504 | N28: Upside / (Downside) vs current | R28: =IFERROR(R27/$K$2-1,"") -> 0.64907185 | S28: =IFERROR(S27/$K$2-1,"") -> 1.0445408 | T28: =IFERROR(T27/$K$2-1,"") -> 1.4820989 | Z28: Upside / (Downside) vs current | AD28: =IFERROR(AD27/$K$2-1,"") -> -0.28061609 | AE28: =IFERROR(AE27/$K$2-1,"") -> -0.1905867 | AF28: =IFERROR(AF27/$K$2-1,"") -> -0.11373928
B29: IRR (to Dec-Y-1) | F29: =IFERROR((F27/$K$2)^(1/((DATE(2028-1,12,31)-$K$3)/365.25))-1,"") -> 0.10710467 | G29: =IFERROR((G27/$K$2)^(1/((DATE(2029-1,12,31)-$K$3)/365.25))-1,"") -> 0.14000047 | H29: =IFERROR((H27/$K$2)^(1/((DATE(2030-1,12,31)-$K$3)/365.25))-1,"") -> 0.14596665 | N29: IRR (to Dec-Y-1) | R29: =IFERROR((R27/$K$2)^(1/((DATE(2028-1,12,31)-$K$3)/365.25))-1,"") -> 0.49678148 | S29: =IFERROR((S27/$K$2)^(1/((DATE(2029-1,12,31)-$K$3)/365.25))-1,"") -> 0.37567746 | T29: =IFERROR((T27/$K$2)^(1/((DATE(2030-1,12,31)-$K$3)/365.25))-1,"") -> 0.3237227 | Z29: IRR (to Dec-Y-1) | AD29: =IFERROR((AD27/$K$2)^(1/((DATE(2028-1,12,31)-$K$3)/365.25))-1,"") -> -0.23322373 | AE29: =IFERROR((AE27/$K$2)^(1/((DATE(2029-1,12,31)-$K$3)/365.25))-1,"") -> -0.089988962 | AF29: =IFERROR((AF27/$K$2)^(1/((DATE(2030-1,12,31)-$K$3)/365.25))-1,"") -> -0.03656295
B31: Free Cash Flow | C31: =Model!BV273 -> 978 | D31: =Model!CA273 -> 937.96654 | E31: =Model!CB273 -> 1666.42 | F31: =Model!CC273 -> 1961.0007 | G31: =Model!CD273 -> 2225.1111 | H31: =Model!CE273 -> 2445.3569 | I31: =IFERROR((H31/C31)^(1/5)-1,"n/m") -> 0.2011595 | N31: Free Cash Flow | O31: 978 | P31: 980.41439 | Q31: 1889.3287 | R31: 2257.8324 | S31: 2626.1709 | T31: 2954.2639 | U31: 0.24744695 | Z31: Free Cash Flow | AA31: 978 | AB31: 895.49296 | AC31: 1452.2135 | AD31: 1682.6312 | AE31: 1849.2934 | AF31: 1971.0496 | AG31: 0.15046057
B32: FCF % | C32: =IFERROR(C31/C9,"") -> 0.15902439 | D32: =IFERROR(D31/D9,"") -> 0.11769514 | E32: =IFERROR(E31/E9,"") -> 0.16975152 | F32: =IFERROR(F31/F9,"") -> 0.18495661 | G32: =IFERROR(G31/G9,"") -> 0.19359518 | H32: =IFERROR(H31/H9,"") -> 0.19585148 | J32: =IFERROR(AVERAGE(Model!C275,Model!D275,Model!E275,Model!F275,Model!G275,Model!H275,Model!I275,Model!N275,Model!S275,Model!X275,Model!AC275,Model!AH275,Model!AM275,Model!AR275,Model!AW275,Model!BB275,Model!BG275,Model!BL275,Model!BQ275,Model!BV275),"") -> 0.084088729 | K32: =IFERROR(MIN(Model!C275,Model!D275,Model!E275,Model!F275,Model!G275,Model!H275,Model!I275,Model!N275,Model!S275,Model!X275,Model!AC275,Model!AH275,Model!AM275,Model!AR275,Model!AW275,Model!BB275,Model!BG275,Model!BL275,Model!BQ275,Model!BV275),"") -> 0.032730239 | L32: =IFERROR(MAX(Model!C275,Model!D275,Model!E275,Model!F275,Model!G275,Model!H275,Model!I275,Model!N275,Model!S275,Model!X275,Model!AC275,Model!AH275,Model!AM275,Model!AR275,Model!AW275,Model!BB275,Model!BG275,Model!BL275,Model!BQ275,Model!BV275),"") -> 0.15902439 | N32: FCF % | O32: 0.15902439 | P32: 0.12149692 | Q32: 0.18295763 | R32: 0.19343886 | S32: 0.1990935 | T32: 0.19843179 | V32: 0.084088729 | W32: 0.032730239 | X32: 0.15902439 | Z32: FCF % | AA32: 0.15902439 | AB32: 0.11379346 | AC32: 0.15447512 | AD32: 0.17253509 | AE32: 0.18334109 | AF32: 0.18812134 | AH32: 0.084088729 | AI32: 0.032730239 | AJ32: 0.15902439
B33: FCF / share ($) | C33: =IFERROR(C31/C21,"") -> 16.138614 | D33: =IFERROR(D31/D21,"") -> 14.608079 | E33: =IFERROR(E31/E21,"") -> 23.362315 | F33: =IFERROR(F31/F21,"") -> 27.434486 | G33: =IFERROR(G31/G21,"") -> 31.542208 | H33: =IFERROR(H31/H21,"") -> 35.992091 | N33: FCF / share ($) | O33: 16.138614 | P33: 15.280641 | Q33: 26.55916 | R33: 32.178321 | S33: 39.157672 | T33: 47.038721 | Z33: FCF / share ($) | AA33: 16.138614 | AB33: 13.946587 | AC33: 20.359255 | AD33: 23.540085 | AE33: 25.817518 | AF33: 27.641016
B34: FCF Yield (on PT) | F34: =IFERROR(F33/F$27,"") -> 0.046620371 | G34: =IFERROR(G33/G$27,"") -> 0.045329163 | H34: =IFERROR(H33/H$27,"") -> 0.044614706 | N34: FCF Yield (on PT) | R34: =IFERROR(R33/R$27,"") -> 0.037619027 | S34: =IFERROR(S33/S$27,"") -> 0.036923667 | T34: =IFERROR(T33/T$27,"") -> 0.036535931 | Z34: FCF Yield (on PT) | AD34: =IFERROR(AD33/AD$27,"") -> 0.06308572 | AE34: =IFERROR(AE33/AE$27,"") -> 0.061493316 | AF34: =IFERROR(AF33/AF$27,"") -> 0.060127929
B35: Adjusted EBITDA — pro forma (2026E incl. LNA full year) | C35: =Model!BV214 -> 2065 | D35: =Model!CA214 -> 3197.2214 | E35: =Model!CB214 -> 3592.3373 | F35: =Model!CC214 -> 4007.7658 | G35: =Model!CD214 -> 4411.5047 | H35: =Model!CE214 -> 4811.2674 | I35: =IFERROR((H35/C35)^(1/5)-1,"n/m") -> 0.18431679 | N35: Adjusted EBITDA — pro forma (2026E incl. LNA full year) | O35: 2065 | P35: 3267.2214 | Q35: 3991.8064 | R35: 4627.5928 | S35: 5283.3716 | T35: 5966.5414 | U35: 0.23640434 | Z35: Adjusted EBITDA — pro forma (2026E incl. LNA full year) | AA35: 2065 | AB35: 3127.2214 | AC35: 3238.4502 | AD35: 3488.1157 | AE35: 3682.491 | AF35: 3856.7328 | AG35: 0.13307824
B36: Adjusted EBITDA (pro forma) % of revenues | C36: =IFERROR(C35/C9,"") -> 0.33577236 | D36: =IFERROR(D35/D9,"") -> 0.40118426 | E36: =IFERROR(E35/E9,"") -> 0.365937 | F36: =IFERROR(F35/F9,"") -> 0.37800232 | G36: =IFERROR(G35/G9,"") -> 0.38382176 | H36: =IFERROR(H35/H9,"") -> 0.38534001 | J36: =IFERROR(AVERAGE(Model!C238,Model!D238,Model!E238,Model!F238,Model!G238,Model!H238,Model!I238,Model!N238,Model!S238,Model!X238,Model!AC238,Model!AH238,Model!AM238,Model!AR238,Model!AW238,Model!BB238,Model!BG238,Model!BL238,Model!BQ238,Model!BV238),"") -> 0.24703766 | K36: =IFERROR(MIN(Model!C238,Model!D238,Model!E238,Model!F238,Model!G238,Model!H238,Model!I238,Model!N238,Model!S238,Model!X238,Model!AC238,Model!AH238,Model!AM238,Model!AR238,Model!AW238,Model!BB238,Model!BG238,Model!BL238,Model!BQ238,Model!BV238),"") -> 0.16190616 | L36: =IFERROR(MAX(Model!C238,Model!D238,Model!E238,Model!F238,Model!G238,Model!H238,Model!I238,Model!N238,Model!S238,Model!X238,Model!AC238,Model!AH238,Model!AM238,Model!AR238,Model!AW238,Model!BB238,Model!BG238,Model!BL238,Model!BQ238,Model!BV238),"") -> 0.33577236 | N36: Adjusted EBITDA (pro forma) % of revenues | O36: 0.33577236 | P36: 0.40488731 | Q36: 0.38655604 | R36: 0.3964671 | S36: 0.4005394 | T36: 0.40076023 | V36: 0.24703766 | W36: 0.16190616 | X36: 0.33577236 | Z36: Adjusted EBITDA (pro forma) % of revenues | AA36: 0.33577236 | AB36: 0.39738711 | AC36: 0.34448102 | AD36: 0.35766742 | AE36: 0.36508643 | AF36: 0.36809513 | AH36: 0.24703766 | AI36: 0.16190616 | AJ36: 0.33577236
B38: Net Debt | C38: =Model!BV421 -> 5256 | D38: =Model!CA421 -> 12240.588 | E38: =Model!CB421 -> 10860.654 | F38: =Model!CC421 -> 9702.1028 | G38: =Model!CD421 -> 9925.8856 | H38: =Model!CE421 -> 10825.352 | N38: Net Debt | O38: 5256 | P38: 12297.972 | Q38: 11194.434 | R38: 11568.982 | S38: 13208.429 | T38: 14916.354 | Z38: Net Debt | AA38: 5256 | AB38: 12283.062 | AC38: 11117.334 | AD38: 9737.1523 | AE38: 8457.2629 | AF38: 7713.4655
B39: Net Debt / Adjusted EBITDA (x) | C39: =IFERROR(C38/C35,"") -> 2.5452785 | D39: =IFERROR(D38/D35,"") -> 3.828508 | E39: =IFERROR(E38/E35,"") -> 3.0232836 | F39: =IFERROR(F38/F35,"") -> 2.4208258 | G39: =IFERROR(G38/G35,"") -> 2.25 | H39: =IFERROR(H38/H35,"") -> 2.25 | N39: Net Debt / Adjusted EBITDA (x) | O39: 2.5452785 | P39: 3.7640461 | Q39: 2.8043531 | R39: 2.5 | S39: 2.5 | T39: 2.5 | Z39: Net Debt / Adjusted EBITDA (x) | AA39: 2.5452785 | AB39: 3.9277876 | AC39: 3.4329181 | AD39: 2.7915222 | AE39: 2.2966147 | AF39: 2
B41: ROIC | C41: =Model!BV404 -> 0.078373843 | D41: =Model!CA404 -> 0.044428423 | E41: =Model!CB404 -> 0.058228754 | F41: =Model!CC404 -> 0.066354824 | G41: =Model!CD404 -> 0.073105328 | H41: =Model!CE404 -> 0.07925012 | J41: =IFERROR(AVERAGE(Model!C404,Model!D404,Model!E404,Model!F404,Model!G404,Model!H404,Model!I404,Model!N404,Model!S404,Model!X404,Model!AC404,Model!AH404,Model!AM404,Model!AR404,Model!AW404,Model!BB404,Model!BG404,Model!BL404,Model!BQ404,Model!BV404),"") -> 0.08428637 | K41: =IFERROR(MIN(Model!C404,Model!D404,Model!E404,Model!F404,Model!G404,Model!H404,Model!I404,Model!N404,Model!S404,Model!X404,Model!AC404,Model!AH404,Model!AM404,Model!AR404,Model!AW404,Model!BB404,Model!BG404,Model!BL404,Model!BQ404,Model!BV404),"") -> 0.03361715 | L41: =IFERROR(MAX(Model!C404,Model!D404,Model!E404,Model!F404,Model!G404,Model!H404,Model!I404,Model!N404,Model!S404,Model!X404,Model!AC404,Model!AH404,Model!AM404,Model!AR404,Model!AW404,Model!BB404,Model!BG404,Model!BL404,Model!BQ404,Model!BV404),"") -> 0.14888392 | N41: ROIC | O41: 0.078373843 | P41: 0.046221187 | Q41: 0.065919196 | R41: 0.076428957 | S41: 0.085709904 | T41: 0.094557447 | V41: 0.08428637 | W41: 0.03361715 | X41: 0.14888392 | Z41: ROIC | AA41: 0.078373843 | AB41: 0.042632747 | AC41: 0.05027949 | AD41: 0.056441901 | AE41: 0.060805271 | AF41: 0.064473684 | AH41: 0.08428637 | AI41: 0.03361715 | AJ41: 0.14888392
B42: RONTA | C42: =Model!BV415 -> 0.087006175 | D42: =Model!CA415 -> 0.069373529 | E42: =Model!CB415 -> 0.09004483 | F42: =Model!CC415 -> 0.097158068 | G42: =Model!CD415 -> 0.10755667 | H42: =Model!CE415 -> 0.11994091 | J42: =IFERROR(AVERAGE(Model!C415,Model!D415,Model!E415,Model!F415,Model!G415,Model!H415,Model!I415,Model!N415,Model!S415,Model!X415,Model!AC415,Model!AH415,Model!AM415,Model!AR415,Model!AW415,Model!BB415,Model!BG415,Model!BL415,Model!BQ415,Model!BV415),"") -> 0.094662288 | K42: =IFERROR(MIN(Model!C415,Model!D415,Model!E415,Model!F415,Model!G415,Model!H415,Model!I415,Model!N415,Model!S415,Model!X415,Model!AC415,Model!AH415,Model!AM415,Model!AR415,Model!AW415,Model!BB415,Model!BG415,Model!BL415,Model!BQ415,Model!BV415),"") -> 0.039851224 | L42: =IFERROR(MAX(Model!C415,Model!D415,Model!E415,Model!F415,Model!G415,Model!H415,Model!I415,Model!N415,Model!S415,Model!X415,Model!AC415,Model!AH415,Model!AM415,Model!AR415,Model!AW415,Model!BB415,Model!BG415,Model!BL415,Model!BQ415,Model!BV415),"") -> 0.16330395 | N42: RONTA | O42: 0.087006175 | P42: 0.072154325 | Q42: 0.10206301 | R42: 0.1174961 | S42: 0.13097034 | T42: 0.14360784 | V42: 0.094662288 | W42: 0.039851224 | X42: 0.16330395 | Z42: RONTA | AA42: 0.087006175 | AB42: 0.066586741 | AC42: 0.07781899 | AD42: 0.0826806 | AE42: 0.083200725 | AF42: 0.084675586 | AH42: 0.094662288 | AI42: 0.039851224 | AJ42: 0.16330395
B44: Implied Market Cap (USDm) | F44: =F27*F21 -> 42063.172 | G44: =G27*G21 -> 49087.849 | H44: =H27*H21 -> 54810.557 | N44: Implied Market Cap (USDm) | R44: =R27*R21 -> 60018.361 | S44: =S27*S21 -> 71124.324 | T44: =T27*T21 -> 80859.14 | Z44: Implied Market Cap (USDm) | AD44: =AD27*AD21 -> 26672.141 | AE44: =AE27*AE21 -> 30073.08 | AF44: =AF27*AF21 -> 32780.932
B45: (+) Net Debt & NCI | F45: =F38+Model!CC324 -> 9704.1028 | G45: =G38+Model!CD324 -> 9927.8856 | H45: =H38+Model!CE324 -> 10827.352 | N45: (+) Net Debt & NCI | R45: =R38+Model!CC324 -> 11570.982 | S45: =S38+Model!CD324 -> 13210.429 | T45: =T38+Model!CE324 -> 14918.354 | Z45: (+) Net Debt & NCI | AD45: =AD38+Model!CC324 -> 9739.1523 | AE45: =AE38+Model!CD324 -> 8459.2629 | AF45: =AF38+Model!CE324 -> 7715.4655
B46: Implied Enterprise Value (USDm) | F46: =F44+F45 -> 51767.274 | G46: =G44+G45 -> 59015.735 | H46: =H44+H45 -> 65637.908 | N46: Implied Enterprise Value (USDm) | R46: =R44+R45 -> 71589.343 | S46: =S44+S45 -> 84334.753 | T46: =T44+T45 -> 95777.493 | Z46: Implied Enterprise Value (USDm) | AD46: =AD44+AD45 -> 36411.293 | AE46: =AE44+AE45 -> 38532.343 | AF46: =AF44+AF45 -> 40496.398
B47: Implied EV / Adjusted EBITDA (x) | F47: =IFERROR(F46/F35,"") -> 12.916741 | G47: =IFERROR(G46/G35,"") -> 13.377688 | H47: =IFERROR(H46/H35,"") -> 13.64254 | N47: Implied EV / Adjusted EBITDA (x) | R47: =IFERROR(R46/R35,"") -> 15.470104 | S47: =IFERROR(S46/S35,"") -> 15.962298 | T47: =IFERROR(T46/T35,"") -> 16.052431 | Z47: Implied EV / Adjusted EBITDA (x) | AD47: =IFERROR(AD46/AD35,"") -> 10.438671 | AE47: =IFERROR(AE46/AE35,"") -> 10.463662 | AF47: =IFERROR(AF46/AF35,"") -> 10.500183

Sheet DCF
B2: DCF VALUATION — MARTIN MARIETTA MATERIALS (MLM)
B4: 1. WACC BUILD
B5: Risk-free rate (US 10Y govt) | C5: 0.045 | D5: Assumption (~US 10Y Treasury yield); update to market
B6: Equity risk premium | C6: 0.05 | D6: US implied ERP ~4.5–5.5% (Damodaran)
B7: Levered beta | C7: 1 | D7: Construction-materials peers (VMC, CRH, EXP, Knife River) ~0.9–1.1; infrastructure-weighted demand and aggregates pricing power dampen cyclicality
B8: Cost of equity | C8: =C5+C7*C6 -> 0.095
B9: Pre-tax cost of debt | C9: 0.055 | D9: Investment grade (BBB+/Baa2); Aug-2026 LNA notes priced at 4.85%–6.375% (5.52% blended); marginal cost ~5.5%
B10: Tax rate | C10: 0.22 | D10: Model 2027E+ effective tax rate
B11: After-tax cost of debt | C11: =C9*(1-C10) -> 0.0429
B12: Target D/V | C12: 0.25 | D12: Net debt ~$12.2bn at YE2026E (post-LNA) vs ~$37bn market cap ($518.70 × ~71m shares); 3.8x pro forma leverage, targeted < 2.5x
