Workbook

Sheet Model
CK1: SCENARIO SWITCH ▼ (Bull / Base / Bear) — drives all scenario-linked forecast drivers
B2: Microsoft Corporation (NASDAQ: MSFT) — 3-Statement Financial Model | CK2: Base
B3: US GAAP as reported · USD millions (per-share data in USD; shares in millions) · Fiscal years ended 30 June (2027 = Jul-2026 – Jun-2027) · Source: Microsoft Forms 10-K / 10-Q, Form 8-K earnings releases (Ex. 99.1) and the 8-K of 2-Sep-2026 (FY27 segments, restated history, Q1 FY27 outlook), SEC EDGAR (CIK 0000789019); XBRL company facts. FY27 full-year call commentary is UNVERIFIED (information rows only).
B4: Basis notes: as originally reported (FY2016–17 ASC 606 / 842 restatement and later segment recasts not applied; memo comments). Segment build on the FY27 structure (Agents and Infra / Devices and Consumer), restated history Q1/25–Q4/26 only; earlier structures as memo. Acquisitions: LinkedIn Dec-16, Nuance Mar-22, Activision Blizzard Oct-23. Q1/27E calibrated to the Q1 FY27 outlook; Q2–Q4/27E carry the Q1 calibration. Share price $541 (user, 12-Oct-2026).
CM5: Forecast | CN5: Historical | CO5: Historical | CP5: Historical
B6: (USDm) | C6: 2006 | D6: 2007 | E6: 2008 | F6: 2009 | G6: 2010 | H6: 2011 | I6: 2012 | J6: Q1/13 | K6: Q2/13 | L6: Q3/13 | M6: Q4/13 | N6: 2013 | O6: Q1/14 | P6: Q2/14 | Q6: Q3/14 | R6: Q4/14 | S6: 2014 | T6: Q1/15 | U6: Q2/15 | V6: Q3/15 | W6: Q4/15 | X6: 2015 | Y6: Q1/16 | Z6: Q2/16 | AA6: Q3/16 | AB6: Q4/16 | AC6: 2016 | AD6: Q1/17 | AE6: Q2/17 | AF6: Q3/17 | AG6: Q4/17 | AH6: 2017 | AI6: Q1/18 | AJ6: Q2/18 | AK6: Q3/18 | AL6: Q4/18 | AM6: 2018 | AN6: Q1/19 | AO6: Q2/19 | AP6: Q3/19 | AQ6: Q4/19 | AR6: 2019 | AS6: Q1/20 | AT6: Q2/20 | AU6: Q3/20 | AV6: Q4/20 | AW6: 2020 | AX6: Q1/21 | AY6: Q2/21 | AZ6: Q3/21 | BA6: Q4/21 | BB6: 2021 | BC6: Q1/22 | BD6: Q2/22 | BE6: Q3/22 | BF6: Q4/22 | BG6: 2022 | BH6: Q1/23 | BI6: Q2/23 | BJ6: Q3/23 | BK6: Q4/23 | BL6: 2023 | BM6: Q1/24 | BN6: Q2/24 | BO6: Q3/24 | BP6: Q4/24 | BQ6: 2024 | BR6: Q1/25 | BS6: Q2/25 | BT6: Q3/25 | BU6: Q4/25 | BV6: 2025 | BW6: Q1/26 | BX6: Q2/26 | BY6: Q3/26 | BZ6: Q4/26 | CA6: 2026 | CB6: Q1/27E | CC6: Q2/27E | CD6: Q3/27E | CE6: Q4/27E | CF6: 2027E | CG6: 2028E | CH6: 2029E | CI6: 2030E | CJ6: 2031E | CK6: Modelling Notes | CM6: 5Y CAGR | CN6: 5Y CAGR | CO6: 10Y CAGR | CP6: 20Y CAGR
CM7: 26-'31 | CN7: 21-'26 | CO7: 16-'26 | CP7: 06-'26
B8: SEGMENT P&L — AGENTS AND INFRA · DEVICES AND CONSUMER (FY27 structure: product & service lines × segment operating margin) | CK8: SEGMENT BUILD — modelling logic (product & service revenue → segment revenue → segment operating income at the segment margin → operating income → GAAP P&L)
CS9: SCENARIO INPUT TABLE — driver assumptions per Bull / Base / Bear | CT9: Bull | CU9: Base | CV9: Bear | CW9: Bull / Bear = Base + Δ (Δ inputs on each block header). Outlook block = high / mid / low end of the Q1 FY27 guidance ranges (costs: low / mid / high).
B10: Agents and Infra (Azure, Microsoft 365 cloud, productivity & server licensing, industry solutions — Dynamics 365, LinkedIn Talent / Sales, healthcare — and frontier & support services) | CK10: AGENTS AND INFRA — modelling logic (history: restated FY27 basis, 8-K 2-Sep-2026, Q1/25–Q4/26 only)
B11: Azure revenue | BR11: 16021 | BS11: 17337 | BT11: 18540 | BU11: 20712 | BV11: 72610 | BW11: 22384 | BX11: 24129 | BY11: 26008 | BZ11: 29417 | CA11: 101938 | CB11: =BW11*(1+CB12) -> 31523.127 | CC11: =BX11*(1+CC12) -> 33980.59 | CD11: =BY11*(1+CD12) -> 36626.764 | CE11: =BZ11*(1+CE12) -> 41427.619 | CF11: =SUM(CB11:CE11) -> 143558.1 | CG11: =CF11*(1+CG12) -> 189496.69 | CH11: =CG11*(1+CH12) -> 238765.83 | CI11: =CH11*(1+CI12) -> 288906.65 | CJ11: =CI11*(1+CJ12) -> 338020.79 | CK11: Restated product & service revenue (FY27 definitions; 8-K 2-Sep-2026, Ex. 99.1). Q1–Q4/27E: prior-year quarter × (1 + growth). 2028E+: prior year × (1 + scenario lever). | CM11: =IFERROR((CJ11/CA11)^(1/5)-1,"n/m") -> 0.2709295 | CN11: =IFERROR((CA11/BB11)^(1/5)-1,"n/m") -> n/m | CO11: =IFERROR((CA11/AC11)^(1/10)-1,"n/m") -> n/m | CP11: =IFERROR((CA11/C11)^(1/20)-1,"n/m") -> n/m | CS11: Q1 FY27 guidance — 29-Jul-2026 call, re-filed in 8-K 2-Sep-2026 (Item 7.01, Ex. 99.1; SEC-filed) | CT11: High | CU11: Mid | CV11: Low | CW11: Total revenue $89.85–90.95bn: Agents and Infra $75.15–75.75bn, Devices and Consumer $14.7–15.2bn (adjusted to the FY27 segments); COGS $29.6–29.8bn; operating expenses $16.8–16.9bn; other income ~$(100)m ex OpenAI; operating margin relatively flat y/y; ETR ~20%; capex over $50bn. Cost rows: Bull = low end, Bear = high end.
B12: y/y % | D12: =IF(AND(ISNUMBER(D11),ISNUMBER(C11)),IFERROR(D11/C11-1,""),"") | E12: =IF(AND(ISNUMBER(E11),ISNUMBER(D11)),IFERROR(E11/D11-1,""),"") | F12: =IF(AND(ISNUMBER(F11),ISNUMBER(E11)),IFERROR(F11/E11-1,""),"") | G12: =IF(AND(ISNUMBER(G11),ISNUMBER(F11)),IFERROR(G11/F11-1,""),"") | H12: =IF(AND(ISNUMBER(H11),ISNUMBER(G11)),IFERROR(H11/G11-1,""),"") | I12: =IF(AND(ISNUMBER(I11),ISNUMBER(H11)),IFERROR(I11/H11-1,""),"") | N12: =IF(AND(ISNUMBER(N11),ISNUMBER(I11)),IFERROR(N11/I11-1,""),"") | O12: =IF(AND(ISNUMBER(O11),ISNUMBER(J11)),IFERROR(O11/J11-1,""),"") | P12: =IF(AND(ISNUMBER(P11),ISNUMBER(K11)),IFERROR(P11/K11-1,""),"") | Q12: =IF(AND(ISNUMBER(Q11),ISNUMBER(L11)),IFERROR(Q11/L11-1,""),"") | R12: =IF(AND(ISNUMBER(R11),ISNUMBER(M11)),IFERROR(R11/M11-1,""),"") | S12: =IF(AND(ISNUMBER(S11),ISNUMBER(N11)),IFERROR(S11/N11-1,""),"") | T12: =IF(AND(ISNUMBER(T11),ISNUMBER(O11)),IFERROR(T11/O11-1,""),"") | U12: =IF(AND(ISNUMBER(U11),ISNUMBER(P11)),IFERROR(U11/P11-1,""),"") | ... CA12: =IF(AND(ISNUMBER(CA11),ISNUMBER(BV11)),IFERROR(CA11/BV11-1,""),"") -> 0.40391131 | CB12: =CB13+$CB$139 -> 0.40828836 | CC12: =CC13+$CB$139 -> 0.40828836 | CD12: =CD13+$CB$139 -> 0.40828836 | CE12: =CE13+$CB$139 -> 0.40828836 | CF12: =IF(AND(ISNUMBER(CF11),ISNUMBER(CA11)),IFERROR(CF11/CA11-1,""),"") -> 0.40828836 | CG12: =CHOOSE(MATCH($CK$2,{"Bull","Base","Bear"},0),$CT$27,$CU$27,$CV$27) -> 0.32 | CH12: =CHOOSE(MATCH($CK$2,{"Bull","Base","Bear"},0),$CT$28,$CU$28,$CV$28) -> 0.26 | CI12: =CHOOSE(MATCH($CK$2,{"Bull","Base","Bear"},0),$CT$29,$CU$29,$CV$29) -> 0.21 | CJ12: =CHOOSE(MATCH($CK$2,{"Bull","Base","Bear"},0),$CT$30,$CU$30,$CV$30) -> 0.17 | CK12: Q1–Q4/27E: Q4/26 y/y growth of the line + the segment calibration Δ solved in Q1/27E to the segment revenue guidance (carried to Q2–Q4). 2028E–2031E: scenario lever (Bull/Base/Bear table →). | CS12: Q1 FY27 Agents and Infra revenue ($m) | CT12: 75750 | CU12: 75450 | CV12: 75150 | CW12: Guided $75.15–75.75bn (8-K 2-Sep-2026). Drives the Agents and Infra growth calibration.
B13: Growth before calibration (Q4/26 y/y, latest actual quarter) | CB13: =IFERROR(BZ11/BU11-1,0) -> 0.42028776 | CC13: =IFERROR(BZ11/BU11-1,0) -> 0.42028776 | CD13: =IFERROR(BZ11/BU11-1,0) -> 0.42028776 | CE13: =IFERROR(BZ11/BU11-1,0) -> 0.42028776 | CS13: Q1 FY27 Devices and Consumer revenue ($m) | CT13: 15200 | CU13: 14950 | CV13: 14700 | CW13: Guided $14.7–15.2bn. Drives the Devices and Consumer growth calibration.
B14: Microsoft 365 cloud revenue | BR14: 20017 | BS14: 20686 | BT14: 20967 | BU14: 22935 | BV14: 84605 | BW14: 23694 | BX14: 24466 | BY14: 25418 | BZ14: 26721 | CA14: 100299 | CB14: =BW14*(1+CB15) -> 27320.978 | CC14: =BX14*(1+CC15) -> 28211.153 | CD14: =BY14*(1+CD15) -> 29308.881 | CE14: =BZ14*(1+CE15) -> 30811.339 | CF14: =SUM(CB14:CE14) -> 115652.35 | CG14: =CF14*(1+CG15) -> 131843.68 | CH14: =CG14*(1+CH15) -> 148983.36 | CI14: =CH14*(1+CI15) -> 166861.36 | CJ14: =CI14*(1+CJ15) -> 185216.11 | CM14: =IFERROR((CJ14/CA14)^(1/5)-1,"n/m") -> 0.13051527 | CN14: =IFERROR((CA14/BB14)^(1/5)-1,"n/m") -> n/m | CO14: =IFERROR((CA14/AC14)^(1/10)-1,"n/m") -> n/m | CP14: =IFERROR((CA14/C14)^(1/20)-1,"n/m") -> n/m | CS14: Q1 FY27 cost of revenue ($m; Bull = low end) | CT14: 29600 | CU14: 29700 | CV14: 29800 | CW14: Guided $29.6–29.8bn. With opex, sets the guided operating income for the margin calibration.
B15: y/y % | D15: =IF(AND(ISNUMBER(D14),ISNUMBER(C14)),IFERROR(D14/C14-1,""),"") | E15: =IF(AND(ISNUMBER(E14),ISNUMBER(D14)),IFERROR(E14/D14-1,""),"") | F15: =IF(AND(ISNUMBER(F14),ISNUMBER(E14)),IFERROR(F14/E14-1,""),"") | G15: =IF(AND(ISNUMBER(G14),ISNUMBER(F14)),IFERROR(G14/F14-1,""),"") | H15: =IF(AND(ISNUMBER(H14),ISNUMBER(G14)),IFERROR(H14/G14-1,""),"") | I15: =IF(AND(ISNUMBER(I14),ISNUMBER(H14)),IFERROR(I14/H14-1,""),"") | N15: =IF(AND(ISNUMBER(N14),ISNUMBER(I14)),IFERROR(N14/I14-1,""),"") | O15: =IF(AND(ISNUMBER(O14),ISNUMBER(J14)),IFERROR(O14/J14-1,""),"") | P15: =IF(AND(ISNUMBER(P14),ISNUMBER(K14)),IFERROR(P14/K14-1,""),"") | Q15: =IF(AND(ISNUMBER(Q14),ISNUMBER(L14)),IFERROR(Q14/L14-1,""),"") | R15: =IF(AND(ISNUMBER(R14),ISNUMBER(M14)),IFERROR(R14/M14-1,""),"") | S15: =IF(AND(ISNUMBER(S14),ISNUMBER(N14)),IFERROR(S14/N14-1,""),"") | T15: =IF(AND(ISNUMBER(T14),ISNUMBER(O14)),IFERROR(T14/O14-1,""),"") | U15: =IF(AND(ISNUMBER(U14),ISNUMBER(P14)),IFERROR(U14/P14-1,""),"") | ... CA15: =IF(AND(ISNUMBER(CA14),ISNUMBER(BV14)),IFERROR(CA14/BV14-1,""),"") -> 0.18549731 | CB15: =CB16+$CB$139 -> 0.15307582 | CC15: =CC16+$CB$139 -> 0.15307582 | CD15: =CD16+$CB$139 -> 0.15307582 | CE15: =CE16+$CB$139 -> 0.15307582 | CF15: =IF(AND(ISNUMBER(CF14),ISNUMBER(CA14)),IFERROR(CF14/CA14-1,""),"") -> 0.15307582 | CG15: =CHOOSE(MATCH($CK$2,{"Bull","Base","Bear"},0),$CT$32,$CU$32,$CV$32) -> 0.14 | CH15: =CHOOSE(MATCH($CK$2,{"Bull","Base","Bear"},0),$CT$33,$CU$33,$CV$33) -> 0.13 | CI15: =CHOOSE(MATCH($CK$2,{"Bull","Base","Bear"},0),$CT$34,$CU$34,$CV$34) -> 0.12 | CJ15: =CHOOSE(MATCH($CK$2,{"Bull","Base","Bear"},0),$CT$35,$CU$35,$CV$35) -> 0.11 | CS15: Q1 FY27 operating expenses ($m; Bull = low end) | CT15: 16800 | CU15: 16850 | CV15: 16900 | CW15: Guided $16.8–16.9bn. Drives Q1/27E R&D, S&M and G&A (prior-year mix).
B16: Growth before calibration (Q4/26 y/y, latest actual quarter) | CB16: =IFERROR(BZ14/BU14-1,0) -> 0.16507521 | CC16: =IFERROR(BZ14/BU14-1,0) -> 0.16507521 | CD16: =IFERROR(BZ14/BU14-1,0) -> 0.16507521 | CE16: =IFERROR(BZ14/BU14-1,0) -> 0.16507521
B17: Productivity and server licensing revenue | BR17: 8051 | BS17: 8307 | BT17: 8731 | BU17: 10302 | BV17: 35391 | BW17: 8678 | BX17: 8814 | BY17: 8760 | BZ17: 11033 | CA17: 37285 | CB17: =BW17*(1+CB18) -> 9189.6349 | CC17: =BX17*(1+CC18) -> 9333.6532 | CD17: =BY17*(1+CD18) -> 9276.4695 | CE17: =BZ17*(1+CE18) -> 11683.48 | CF17: =SUM(CB17:CE17) -> 39483.238 | CG17: =CF17*(1+CG18) -> 38693.573 | CH17: =CG17*(1+CH18) -> 37919.702 | CI17: =CH17*(1+CI18) -> 36782.111 | CJ17: =CI17*(1+CJ18) -> 35678.647 | CM17: =IFERROR((CJ17/CA17)^(1/5)-1,"n/m") -> -0.0087690663 | CN17: =IFERROR((CA17/BB17)^(1/5)-1,"n/m") -> n/m | CO17: =IFERROR((CA17/AC17)^(1/10)-1,"n/m") -> n/m | CP17: =IFERROR((CA17/C17)^(1/20)-1,"n/m") -> n/m | CS17: FY2027E point estimates (all cases)
B18: y/y % | D18: =IF(AND(ISNUMBER(D17),ISNUMBER(C17)),IFERROR(D17/C17-1,""),"") | E18: =IF(AND(ISNUMBER(E17),ISNUMBER(D17)),IFERROR(E17/D17-1,""),"") | F18: =IF(AND(ISNUMBER(F17),ISNUMBER(E17)),IFERROR(F17/E17-1,""),"") | G18: =IF(AND(ISNUMBER(G17),ISNUMBER(F17)),IFERROR(G17/F17-1,""),"") | H18: =IF(AND(ISNUMBER(H17),ISNUMBER(G17)),IFERROR(H17/G17-1,""),"") | I18: =IF(AND(ISNUMBER(I17),ISNUMBER(H17)),IFERROR(I17/H17-1,""),"") | N18: =IF(AND(ISNUMBER(N17),ISNUMBER(I17)),IFERROR(N17/I17-1,""),"") | O18: =IF(AND(ISNUMBER(O17),ISNUMBER(J17)),IFERROR(O17/J17-1,""),"") | P18: =IF(AND(ISNUMBER(P17),ISNUMBER(K17)),IFERROR(P17/K17-1,""),"") | Q18: =IF(AND(ISNUMBER(Q17),ISNUMBER(L17)),IFERROR(Q17/L17-1,""),"") | R18: =IF(AND(ISNUMBER(R17),ISNUMBER(M17)),IFERROR(R17/M17-1,""),"") | S18: =IF(AND(ISNUMBER(S17),ISNUMBER(N17)),IFERROR(S17/N17-1,""),"") | T18: =IF(AND(ISNUMBER(T17),ISNUMBER(O17)),IFERROR(T17/O17-1,""),"") | U18: =IF(AND(ISNUMBER(U17),ISNUMBER(P17)),IFERROR(U17/P17-1,""),"") | ... CA18: =IF(AND(ISNUMBER(CA17),ISNUMBER(BV17)),IFERROR(CA17/BV17-1,""),"") -> 0.053516431 | CB18: =CB19+$CB$139 -> 0.058957703 | CC18: =CC19+$CB$139 -> 0.058957703 | CD18: =CD19+$CB$139 -> 0.058957703 | CE18: =CE19+$CB$139 -> 0.058957703 | CF18: =IF(AND(ISNUMBER(CF17),ISNUMBER(CA17)),IFERROR(CF17/CA17-1,""),"") -> 0.058957703 | CG18: =CHOOSE(MATCH($CK$2,{"Bull","Base","Bear"},0),$CT$37,$CU$37,$CV$37) -> -0.02 | CH18: =CHOOSE(MATCH($CK$2,{"Bull","Base","Bear"},0),$CT$38,$CU$38,$CV$38) -> -0.02 | CI18: =CHOOSE(MATCH($CK$2,{"Bull","Base","Bear"},0),$CT$39,$CU$39,$CV$39) -> -0.03 | CJ18: =CHOOSE(MATCH($CK$2,{"Bull","Base","Bear"},0),$CT$40,$CU$40,$CV$40) -> -0.03 | CS18: Q1–Q4/27E other income (expense), net per quarter ($m) | CU18: -100 | CW18: Guided ~$(100)m for Q1 excluding any impact from investments in OpenAI; held for Q2–Q4 (assumption).
B19: Growth before calibration (Q4/26 y/y, latest actual quarter) | CB19: =IFERROR(BZ17/BU17-1,0) -> 0.070957096 | CC19: =IFERROR(BZ17/BU17-1,0) -> 0.070957096 | CD19: =IFERROR(BZ17/BU17-1,0) -> 0.070957096 | CE19: =IFERROR(BZ17/BU17-1,0) -> 0.070957096 | CS19: FY27E effective tax rate | CU19: 0.2 | CW19: Guided ~20% for Q1 (8-K 2-Sep-2026); held for the year (assumption). FY26 19.4%.
B20: Industry solutions revenue | BR20: 4459 | BS20: 4544 | BT20: 4579 | BU20: 4835 | BV20: 18417 | BW20: 4894 | BX20: 4994 | BY20: 5165 | BZ20: 5292 | CA20: 20345 | CB20: =BW20*(1+CB21) -> 5297.8516 | CC20: =BX20*(1+CC21) -> 5406.1036 | CD20: =BY20*(1+CD21) -> 5591.2145 | CE20: =BZ20*(1+CE21) -> 5728.6945 | CF20: =SUM(CB20:CE20) -> 22023.864 | CG20: =CF20*(1+CG21) -> 24006.012 | CH20: =CG20*(1+CH21) -> 26166.553 | CI20: =CH20*(1+CI21) -> 28259.877 | CJ20: =CI20*(1+CJ21) -> 30520.667 | CM20: =IFERROR((CJ20/CA20)^(1/5)-1,"n/m") -> 0.084494281 | CN20: =IFERROR((CA20/BB20)^(1/5)-1,"n/m") -> n/m | CO20: =IFERROR((CA20/AC20)^(1/10)-1,"n/m") -> n/m | CP20: =IFERROR((CA20/C20)^(1/20)-1,"n/m") -> n/m | CS20: FY27E quarterly dividend declared ($) | CU20: 1 | CW20: Assumption: $0.91 + ~10% (Sep-2025 raise +9.6%); the Sep-2026 declaration is not in the EDGAR filings reviewed. Update when filed.
B21: y/y % | D21: =IF(AND(ISNUMBER(D20),ISNUMBER(C20)),IFERROR(D20/C20-1,""),"") | E21: =IF(AND(ISNUMBER(E20),ISNUMBER(D20)),IFERROR(E20/D20-1,""),"") | F21: =IF(AND(ISNUMBER(F20),ISNUMBER(E20)),IFERROR(F20/E20-1,""),"") | G21: =IF(AND(ISNUMBER(G20),ISNUMBER(F20)),IFERROR(G20/F20-1,""),"") | H21: =IF(AND(ISNUMBER(H20),ISNUMBER(G20)),IFERROR(H20/G20-1,""),"") | I21: =IF(AND(ISNUMBER(I20),ISNUMBER(H20)),IFERROR(I20/H20-1,""),"") | N21: =IF(AND(ISNUMBER(N20),ISNUMBER(I20)),IFERROR(N20/I20-1,""),"") | O21: =IF(AND(ISNUMBER(O20),ISNUMBER(J20)),IFERROR(O20/J20-1,""),"") | P21: =IF(AND(ISNUMBER(P20),ISNUMBER(K20)),IFERROR(P20/K20-1,""),"") | Q21: =IF(AND(ISNUMBER(Q20),ISNUMBER(L20)),IFERROR(Q20/L20-1,""),"") | R21: =IF(AND(ISNUMBER(R20),ISNUMBER(M20)),IFERROR(R20/M20-1,""),"") | S21: =IF(AND(ISNUMBER(S20),ISNUMBER(N20)),IFERROR(S20/N20-1,""),"") | T21: =IF(AND(ISNUMBER(T20),ISNUMBER(O20)),IFERROR(T20/O20-1,""),"") | U21: =IF(AND(ISNUMBER(U20),ISNUMBER(P20)),IFERROR(U20/P20-1,""),"") | ... CA21: =IF(AND(ISNUMBER(CA20),ISNUMBER(BV20)),IFERROR(CA20/BV20-1,""),"") -> 0.10468589 | CB21: =CB22+$CB$139 -> 0.082519739 | CC21: =CC22+$CB$139 -> 0.082519739 | CD21: =CD22+$CB$139 -> 0.082519739 | CE21: =CE22+$CB$139 -> 0.082519739 | CF21: =IF(AND(ISNUMBER(CF20),ISNUMBER(CA20)),IFERROR(CF20/CA20-1,""),"") -> 0.082519739 | CG21: =CHOOSE(MATCH($CK$2,{"Bull","Base","Bear"},0),$CT$42,$CU$42,$CV$42) -> 0.09 | CH21: =CHOOSE(MATCH($CK$2,{"Bull","Base","Bear"},0),$CT$43,$CU$43,$CV$43) -> 0.09 | CI21: =CHOOSE(MATCH($CK$2,{"Bull","Base","Bear"},0),$CT$44,$CU$44,$CV$44) -> 0.08 | CJ21: =CHOOSE(MATCH($CK$2,{"Bull","Base","Bear"},0),$CT$45,$CU$45,$CV$45) -> 0.08 | CS21: FY27 revenue / operating-income growth "double-digit" — UNVERIFIED | CU21: 0.1 | CW21: UNVERIFIED: 29-Jul-2026 call commentary as reported by third parties (MarketBeat, Nasdaq, Motley Fool transcript); not in an SEC filing. Information row only — not used as a solve target.
B22: Growth before calibration (Q4/26 y/y, latest actual quarter) | CB22: =IFERROR(BZ20/BU20-1,0) -> 0.094519131 | CC22: =IFERROR(BZ20/BU20-1,0) -> 0.094519131 | CD22: =IFERROR(BZ20/BU20-1,0) -> 0.094519131 | CE22: =IFERROR(BZ20/BU20-1,0) -> 0.094519131
B23: Frontier and support services revenue | BR23: 1928 | BS23: 1892 | BT23: 1946 | BU23: 1994 | BV23: 7760 | BW23: 2022 | BX23: 2038 | BY23: 2087 | BZ23: 2113 | CA23: 8260 | CB23: =BW23*(1+CB24) -> 2118.4082 | CC23: =BX23*(1+CC24) -> 2135.1711 | CD23: =BY23*(1+CD24) -> 2186.5074 | CE23: =BZ23*(1+CE24) -> 2213.7471 | CF23: =SUM(CB23:CE23) -> 8653.8339 | CG23: =CF23*(1+CG24) -> 8999.9872 | CH23: =CG23*(1+CH24) -> 9359.9867 | CI23: =CH23*(1+CI24) -> 9640.7863 | CJ23: =CI23*(1+CJ24) -> 9930.0099 | CM23: =IFERROR((CJ23/CA23)^(1/5)-1,"n/m") -> 0.037513907 | CN23: =IFERROR((CA23/BB23)^(1/5)-1,"n/m") -> n/m | CO23: =IFERROR((CA23/AC23)^(1/10)-1,"n/m") -> n/m | CP23: =IFERROR((CA23/C23)^(1/20)-1,"n/m") -> n/m | CS23: Target cash & short-term investments before buybacks ($m) — buyback plug FY2027E+ | CT23: 60000 | CU23: 70000 | CV23: 80000 | CW23: Cash & short-term investments $76.8bn at 30-Jun-2026 ($94.6bn a year earlier) against $40.3bn of debt and $66.6bn of finance leases. Surplus above the target is returned through buybacks ($40.6bn left on the $60bn program); Bull = lower target (more buybacks). Assumption.
B24: y/y % | D24: =IF(AND(ISNUMBER(D23),ISNUMBER(C23)),IFERROR(D23/C23-1,""),"") | E24: =IF(AND(ISNUMBER(E23),ISNUMBER(D23)),IFERROR(E23/D23-1,""),"") | F24: =IF(AND(ISNUMBER(F23),ISNUMBER(E23)),IFERROR(F23/E23-1,""),"") | G24: =IF(AND(ISNUMBER(G23),ISNUMBER(F23)),IFERROR(G23/F23-1,""),"") | H24: =IF(AND(ISNUMBER(H23),ISNUMBER(G23)),IFERROR(H23/G23-1,""),"") | I24: =IF(AND(ISNUMBER(I23),ISNUMBER(H23)),IFERROR(I23/H23-1,""),"") | N24: =IF(AND(ISNUMBER(N23),ISNUMBER(I23)),IFERROR(N23/I23-1,""),"") | O24: =IF(AND(ISNUMBER(O23),ISNUMBER(J23)),IFERROR(O23/J23-1,""),"") | P24: =IF(AND(ISNUMBER(P23),ISNUMBER(K23)),IFERROR(P23/K23-1,""),"") | Q24: =IF(AND(ISNUMBER(Q23),ISNUMBER(L23)),IFERROR(Q23/L23-1,""),"") | R24: =IF(AND(ISNUMBER(R23),ISNUMBER(M23)),IFERROR(R23/M23-1,""),"") | S24: =IF(AND(ISNUMBER(S23),ISNUMBER(N23)),IFERROR(S23/N23-1,""),"") | T24: =IF(AND(ISNUMBER(T23),ISNUMBER(O23)),IFERROR(T23/O23-1,""),"") | U24: =IF(AND(ISNUMBER(U23),ISNUMBER(P23)),IFERROR(U23/P23-1,""),"") | ... CA24: =IF(AND(ISNUMBER(CA23),ISNUMBER(BV23)),IFERROR(CA23/BV23-1,""),"") -> 0.06443299 | CB24: =CB25+$CB$139 -> 0.047679645 | CC24: =CC25+$CB$139 -> 0.047679645 | CD24: =CD25+$CB$139 -> 0.047679645 | CE24: =CE25+$CB$139 -> 0.047679645 | CF24: =IF(AND(ISNUMBER(CF23),ISNUMBER(CA23)),IFERROR(CF23/CA23-1,""),"") -> 0.047679645 | CG24: =CHOOSE(MATCH($CK$2,{"Bull","Base","Bear"},0),$CT$47,$CU$47,$CV$47) -> 0.04 | CH24: =CHOOSE(MATCH($CK$2,{"Bull","Base","Bear"},0),$CT$48,$CU$48,$CV$48) -> 0.04 | CI24: =CHOOSE(MATCH($CK$2,{"Bull","Base","Bear"},0),$CT$49,$CU$49,$CV$49) -> 0.03 | CJ24: =CHOOSE(MATCH($CK$2,{"Bull","Base","Bear"},0),$CT$50,$CU$50,$CV$50) -> 0.03 | CS24: Minimum share repurchases per year ($m) | CT24: 25000 | CU24: 20000 | CV24: 15000 | CW24: FY2026 repurchases $22.3bn (program $16.7bn + $5.6bn tax withholding); FY2025 $18.4bn. Minimum per year by scenario (assumption).
B25: Growth before calibration (Q4/26 y/y, latest actual quarter) | CB25: =IFERROR(BZ23/BU23-1,0) -> 0.059679037 | CC25: =IFERROR(BZ23/BU23-1,0) -> 0.059679037 | CD25: =IFERROR(BZ23/BU23-1,0) -> 0.059679037 | CE25: =IFERROR(BZ23/BU23-1,0) -> 0.059679037
B26: Agents and Infra — segment revenue | C26: =IF(ISNUMBER(C11),C11+C14+C17+C20+C23,"") | D26: =IF(ISNUMBER(D11),D11+D14+D17+D20+D23,"") | E26: =IF(ISNUMBER(E11),E11+E14+E17+E20+E23,"") | F26: =IF(ISNUMBER(F11),F11+F14+F17+F20+F23,"") | G26: =IF(ISNUMBER(G11),G11+G14+G17+G20+G23,"") | H26: =IF(ISNUMBER(H11),H11+H14+H17+H20+H23,"") | I26: =IF(ISNUMBER(I11),I11+I14+I17+I20+I23,"") | J26: =IF(ISNUMBER(J11),J11+J14+J17+J20+J23,"") | ... CJ26: =IF(ISNUMBER(CJ11),CJ11+CJ14+CJ17+CJ20+CJ23,"") -> 599366.22 | CK26: Σ product & service lines. | CM26: =IFERROR((CJ26/CA26)^(1/5)-1,"n/m") -> 0.17454685 | CN26: =IFERROR((CA26/BB26)^(1/5)-1,"n/m") -> n/m | CO26: =IFERROR((CA26/AC26)^(1/10)-1,"n/m") -> n/m | CP26: =IFERROR((CA26/C26)^(1/20)-1,"n/m") -> n/m | CS26: AI_AZ (Azure y/y) | CT26: 0.06 | CU26: Δ → | CV26: -0.1 | CW26: FY26 +40% restated (Q4 +42%); Q1 FY27 guided +44–45% cc; capacity-constrained AI demand, commercial RPO +84% to $678bn. Decelerating with scale (assumption).
B27: Segment revenue y/y % | D27: =IF(AND(ISNUMBER(D26),ISNUMBER(C26)),IFERROR(D26/C26-1,""),"") | E27: =IF(AND(ISNUMBER(E26),ISNUMBER(D26)),IFERROR(E26/D26-1,""),"") | F27: =IF(AND(ISNUMBER(F26),ISNUMBER(E26)),IFERROR(F26/E26-1,""),"") | G27: =IF(AND(ISNUMBER(G26),ISNUMBER(F26)),IFERROR(G26/F26-1,""),"") | H27: =IF(AND(ISNUMBER(H26),ISNUMBER(G26)),IFERROR(H26/G26-1,""),"") | I27: =IF(AND(ISNUMBER(I26),ISNUMBER(H26)),IFERROR(I26/H26-1,""),"") | N27: =IF(AND(ISNUMBER(N26),ISNUMBER(I26)),IFERROR(N26/I26-1,""),"") | O27: =IF(AND(ISNUMBER(O26),ISNUMBER(J26)),IFERROR(O26/J26-1,""),"") | P27: =IF(AND(ISNUMBER(P26),ISNUMBER(K26)),IFERROR(P26/K26-1,""),"") | Q27: =IF(AND(ISNUMBER(Q26),ISNUMBER(L26)),IFERROR(Q26/L26-1,""),"") | R27: =IF(AND(ISNUMBER(R26),ISNUMBER(M26)),IFERROR(R26/M26-1,""),"") | S27: =IF(AND(ISNUMBER(S26),ISNUMBER(N26)),IFERROR(S26/N26-1,""),"") | T27: =IF(AND(ISNUMBER(T26),ISNUMBER(O26)),IFERROR(T26/O26-1,""),"") | U27: =IF(AND(ISNUMBER(U26),ISNUMBER(P26)),IFERROR(U26/P26-1,""),"") | ... CF27: =IF(AND(ISNUMBER(CF26),ISNUMBER(CA26)),IFERROR(CF26/CA26-1,""),"") -> 0.22841559 | CG27: =IF(AND(ISNUMBER(CG26),ISNUMBER(CF26)),IFERROR(CG26/CF26-1,""),"") -> 0.19330324 | CH27: =IF(AND(ISNUMBER(CH26),ISNUMBER(CG26)),IFERROR(CH26/CG26-1,""),"") -> 0.17340601 | CI27: =IF(AND(ISNUMBER(CI26),ISNUMBER(CH26)),IFERROR(CI26/CH26-1,""),"") -> 0.15016489 | CJ27: =IF(AND(ISNUMBER(CJ26),ISNUMBER(CI26)),IFERROR(CJ26/CI26-1,""),"") -> 0.12991861 | CS27: 2028E | CT27: =CU27+$CT$26 -> 0.38 | CU27: 0.32 | CV27: =CU27+$CV$26 -> 0.22
B28: % of total revenue | C28: =IF(AND(ISNUMBER(C26),ISNUMBER(C130)),IFERROR(C26/C130,""),"") | D28: =IF(AND(ISNUMBER(D26),ISNUMBER(D130)),IFERROR(D26/D130,""),"") | E28: =IF(AND(ISNUMBER(E26),ISNUMBER(E130)),IFERROR(E26/E130,""),"") | F28: =IF(AND(ISNUMBER(F26),ISNUMBER(F130)),IFERROR(F26/F130,""),"") | G28: =IF(AND(ISNUMBER(G26),ISNUMBER(G130)),IFERROR(G26/G130,""),"") | H28: =IF(AND(ISNUMBER(H26),ISNUMBER(H130)),IFERROR(H26/H130,""),"") | I28: =IF(AND(ISNUMBER(I26),ISNUMBER(I130)),IFERROR(I26/I130,""),"") | J28: =IF(AND(ISNUMBER(J26),ISNUMBER(J130)),IFERROR(J26/J130,""),"") | ... CJ28: =IF(AND(ISNUMBER(CJ26),ISNUMBER(CJ130)),IFERROR(CJ26/CJ130,""),"") -> 0.89231376 | CS28: 2029E | CT28: =CU28+$CT$26 -> 0.32 | CU28: 0.26 | CV28: =CU28+$CV$26 -> 0.16
B29: Memo: Agents and Infra segment revenue as restated (8-K 2-Sep-2026) | BR29: 50476 | BS29: 52766 | BT29: 54763 | BU29: 60778 | BV29: 218783 | BW29: 61672 | BX29: 64441 | BY29: 67438 | BZ29: 74576 | CA29: 268127 | CS29: 2030E | CT29: =CU29+$CT$26 -> 0.27 | CU29: 0.21 | CV29: =CU29+$CV$26 -> 0.11
B30: Check: product & service lines vs segment revenue (should be 0) | C30: =IF(AND(ISNUMBER(C26),ISNUMBER(C29)),IF(ABS(C26-C29)<=1,0,ROUND(C26-C29,0)),"") | D30: =IF(AND(ISNUMBER(D26),ISNUMBER(D29)),IF(ABS(D26-D29)<=1,0,ROUND(D26-D29,0)),"") | E30: =IF(AND(ISNUMBER(E26),ISNUMBER(E29)),IF(ABS(E26-E29)<=1,0,ROUND(E26-E29,0)),"") | F30: =IF(AND(ISNUMBER(F26),ISNUMBER(F29)),IF(ABS(F26-F29)<=1,0,ROUND(F26-F29,0)),"") | G30: =IF(AND(ISNUMBER(G26),ISNUMBER(G29)),IF(ABS(G26-G29)<=1,0,ROUND(G26-G29,0)),"") | H30: =IF(AND(ISNUMBER(H26),ISNUMBER(H29)),IF(ABS(H26-H29)<=1,0,ROUND(H26-H29,0)),"") | I30: =IF(AND(ISNUMBER(I26),ISNUMBER(I29)),IF(ABS(I26-I29)<=1,0,ROUND(I26-I29,0)),"") | J30: =IF(AND(ISNUMBER(J26),ISNUMBER(J29)),IF(ABS(J26-J29)<=1,0,ROUND(J26-J29,0)),"") | ... CA30: =IF(AND(ISNUMBER(CA26),ISNUMBER(CA29)),IF(ABS(CA26-CA29)<=1,0,ROUND(CA26-CA29,0)),"") -> 0 | CS30: 2031E | CT30: =CU30+$CT$26 -> 0.23 | CU30: 0.17 | CV30: =CU30+$CV$26 -> 0.07
B31: Agents and Infra — segment operating income | BR31: 26171 | BS31: 26718 | BT31: 27704 | BU31: 30221 | BV31: 110814 | BW31: 32718 | BX31: 33167 | BY31: 33748 | BZ31: 36732 | CA31: 136365 | CB31: =CB26*CB32 -> 38971.019 | CC31: =CC26*CC32 -> 39587.581 | CD31: =CD26*CD32 -> 40368.6 | CE31: =CE26*CE32 -> 43961.271 | CF31: =SUM(CB31:CE31) -> 162888.47 | CG31: =CG26*CG32 -> 184728.77 | CH31: =CH26*CH32 -> 214455.88 | CI31: =CI26*CI32 -> 249311.87 | CJ31: =CJ26*CJ32 -> 284698.96 | CK31: Segment operating income as restated (segment revenue − cost of revenue − operating expenses; all costs are allocated, no corporate line). Forecast = revenue × margin. | CM31: =IFERROR((CJ31/CA31)^(1/5)-1,"n/m") -> 0.15860818 | CN31: =IFERROR((CA31/BB31)^(1/5)-1,"n/m") -> n/m | CO31: =IFERROR((CA31/AC31)^(1/10)-1,"n/m") -> n/m | CP31: =IFERROR((CA31/C31)^(1/20)-1,"n/m") -> n/m | CS31: AI_M365 (Microsoft 365 cloud y/y) | CT31: 0.03 | CU31: Δ → | CV31: -0.05 | CW31: FY26 +18.5% (incl. GitHub, Security Copilot); Q1 FY27 M365 commercial cloud ~17% cc; seats +7%, ARPU from E5 / Copilot.
B32: Segment operating margin % | C32: =IF(AND(ISNUMBER(C31),ISNUMBER(C26)),IFERROR(C31/C26,""),"") | D32: =IF(AND(ISNUMBER(D31),ISNUMBER(D26)),IFERROR(D31/D26,""),"") | E32: =IF(AND(ISNUMBER(E31),ISNUMBER(E26)),IFERROR(E31/E26,""),"") | F32: =IF(AND(ISNUMBER(F31),ISNUMBER(F26)),IFERROR(F31/F26,""),"") | G32: =IF(AND(ISNUMBER(G31),ISNUMBER(G26)),IFERROR(G31/G26,""),"") | H32: =IF(AND(ISNUMBER(H31),ISNUMBER(H26)),IFERROR(H31/H26,""),"") | I32: =IF(AND(ISNUMBER(I31),ISNUMBER(I26)),IFERROR(I31/I26,""),"") | J32: =IF(AND(ISNUMBER(J31),ISNUMBER(J26)),IFERROR(J31/J26,""),"") | ... CA32: =IF(AND(ISNUMBER(CA31),ISNUMBER(CA26)),IFERROR(CA31/CA26,""),"") -> 0.50858362 | CB32: =CB33+$CB$148 -> 0.5165145 | CC32: =CC33+$CB$148 -> 0.50068607 | CD32: =CD33+$CB$148 -> 0.48642824 | CE32: =CE33+$CB$148 -> 0.47854274 | CF32: =IF(AND(ISNUMBER(CF31),ISNUMBER(CF26)),IFERROR(CF31/CF26,""),"") -> 0.49454348 | CG32: =CHOOSE(MATCH($CK$2,{"Bull","Base","Bear"},0),$CT$67,$CU$67,$CV$67) -> 0.47 | CH32: =CHOOSE(MATCH($CK$2,{"Bull","Base","Bear"},0),$CT$68,$CU$68,$CV$68) -> 0.465 | CI32: =CHOOSE(MATCH($CK$2,{"Bull","Base","Bear"},0),$CT$69,$CU$69,$CV$69) -> 0.47 | CJ32: =CHOOSE(MATCH($CK$2,{"Bull","Base","Bear"},0),$CT$70,$CU$70,$CV$70) -> 0.475 | CK32: Q1–Q4/27E: margin before calibration + uniform margin Δ solved in Q1/27E to the guided operating income (revenue − COGS − opex guidance), carried to Q2–Q4. 2028E+: scenario lever. | CM32: =IFERROR(AVERAGE(CF32,CG32,CH32,CI32,CJ32),"n/m") -> 0.4749087 | CN32: =IFERROR(AVERAGE(BG32,BL32,BQ32,BV32,CA32),"n/m") -> 0.50754275 | CO32: =IFERROR(AVERAGE(AH32,AM32,AR32,AW32,BB32,BG32,BL32,BQ32,BV32,CA32),"n/m") -> 0.50754275 | CP32: =IFERROR(AVERAGE(C32,D32,E32,F32,G32,H32,I32,N32,S32,X32,AC32,AH32,AM32,AR32,AW32,BB32,BG32,BL32,BQ32,BV32,CA32),"n/m") -> 0.50754275 | CS32: 2028E | CT32: =CU32+$CT$31 -> 0.17 | CU32: 0.14 | CV32: =CU32+$CV$31 -> 0.09
B33: Margin before calibration (prior-year quarter + FY26 vs FY25 margin drift) | CB33: =BW32+IFERROR(CA31/CA26-BV31/BV26,0) -> 0.53259802 | CC33: =BX32+IFERROR(CA31/CA26-BV31/BV26,0) -> 0.5167696 | CD33: =BY32+IFERROR(CA31/CA26-BV31/BV26,0) -> 0.50251177 | CE33: =BZ32+IFERROR(CA31/CA26-BV31/BV26,0) -> 0.49462626 | CS33: 2029E | CT33: =CU33+$CT$31 -> 0.16 | CU33: 0.13 | CV33: =CU33+$CV$31 -> 0.08
B34: Memo: segment gross margin % (revenue − cost of revenue, restated) | C34: =IF(AND(ISNUMBER(C29),ISNUMBER(C35)),IFERROR(1-C35/C29,""),"") | D34: =IF(AND(ISNUMBER(D29),ISNUMBER(D35)),IFERROR(1-D35/D29,""),"") | E34: =IF(AND(ISNUMBER(E29),ISNUMBER(E35)),IFERROR(1-E35/E29,""),"") | F34: =IF(AND(ISNUMBER(F29),ISNUMBER(F35)),IFERROR(1-F35/F29,""),"") | G34: =IF(AND(ISNUMBER(G29),ISNUMBER(G35)),IFERROR(1-G35/G29,""),"") | H34: =IF(AND(ISNUMBER(H29),ISNUMBER(H35)),IFERROR(1-H35/H29,""),"") | I34: =IF(AND(ISNUMBER(I29),ISNUMBER(I35)),IFERROR(1-I35/I29,""),"") | J34: =IF(AND(ISNUMBER(J29),ISNUMBER(J35)),IFERROR(1-J35/J29,""),"") | ... CA34: =IF(AND(ISNUMBER(CA29),ISNUMBER(CA35)),IFERROR(1-CA35/CA29,""),"") -> 0.69634912 | CS34: 2030E | CT34: =CU34+$CT$31 -> 0.15 | CU34: 0.12 | CV34: =CU34+$CV$31 -> 0.07
B35: Memo: segment cost of revenue (restated) | BR35: 13619 | BS35: 14630 | BT35: 15510 | BU35: 17533 | BV35: 61292 | BW35: 17701 | BX35: 19307 | BY35: 20949 | BZ35: 23460 | CA35: 81417 | CS35: 2031E | CT35: =CU35+$CT$31 -> 0.14 | CU35: 0.11 | CV35: =CU35+$CV$31 -> 0.06
B36: Memo: segment operating expenses (restated) | BR36: 10686 | BS36: 11418 | BT36: 11549 | BU36: 13024 | BV36: 46677 | BW36: 11253 | BX36: 11967 | BY36: 12741 | BZ36: 14384 | CA36: 50345 | CS36: AI_PSL (Productivity & server licensing y/y) | CT36: 0.03 | CU36: Δ → | CV36: -0.04 | CW36: FY26 +5.4% (lumpy on-premises server / Office transactional); Q1 FY27 guided to decline low-single digits; long-run cloud migration.
B37: Incremental segment margin (Δ operating income / Δ revenue) | D37: =IFERROR((D31-C31)/(D26-C26),"") | E37: =IFERROR((E31-D31)/(E26-D26),"") | F37: =IFERROR((F31-E31)/(F26-E26),"") | G37: =IFERROR((G31-F31)/(G26-F26),"") | H37: =IFERROR((H31-G31)/(H26-G26),"") | I37: =IFERROR((I31-H31)/(I26-H26),"") | N37: =IFERROR((N31-I31)/(N26-I26),"") | O37: =IFERROR((O31-J31)/(O26-J26),"") | P37: =IFERROR((P31-K31)/(P26-K26),"") | Q37: =IFERROR((Q31-L31)/(Q26-L26),"") | R37: =IFERROR((R31-M31)/(R26-M26),"") | S37: =IFERROR((S31-N31)/(S26-N26),"") | T37: =IFERROR((T31-O31)/(T26-O26),"") | U37: =IFERROR((U31-P31)/(U26-P26),"") | ... CF37: =IFERROR((CF31-CA31)/(CF26-CA26),"") -> 0.43307594 | CG37: =IFERROR((CG31-CF31)/(CG26-CF26),"") -> 0.34303123 | CH37: =IFERROR((CH31-CG31)/(CH26-CG26),"") -> 0.43616594 | CI37: =IFERROR((CI31-CH31)/(CI26-CH26),"") -> 0.50329673 | CJ37: =IFERROR((CJ31-CI31)/(CJ26-CI26),"") -> 0.51348563 | CS37: 2028E | CT37: =CU37+$CT$36 -> 0.01 | CU37: -0.02 | CV37: =CU37+$CV$36 -> -0.06
CS38: 2029E | CT38: =CU38+$CT$36 -> 0.01 | CU38: -0.02 | CV38: =CU38+$CV$36 -> -0.06
B39: Devices and Consumer (search & advertising incl. LinkedIn Marketing / Premium, XBOX content, services & hardware, Windows OEM & devices) | CK39: DEVICES AND CONSUMER — modelling logic (history: restated FY27 basis, 8-K 2-Sep-2026, Q1/25–Q4/26 only) | CS39: 2030E | CT39: =CU39+$CT$36 -> 0 | CU39: -0.03 | CV39: =CU39+$CV$36 -> -0.07
B40: Search and advertising revenue | BR40: 5159 | BS40: 5773 | BT40: 5437 | BU40: 5802 | BV40: 22171 | BW40: 5942 | BX40: 6393 | BY40: 6065 | BZ40: 6435 | CA40: 24835 | CB40: =BW40*(1+CB41) -> 6285.5982 | CC40: =BX40*(1+CC41) -> 6762.6774 | CD40: =BY40*(1+CD41) -> 6415.7107 | CE40: =BZ40*(1+CE41) -> 6807.1061 | CF40: =SUM(CB40:CE40) -> 26271.092 | CG40: =CF40*(1+CG41) -> 28372.78 | CH40: =CG40*(1+CH41) -> 30642.602 | CI40: =CH40*(1+CI41) -> 32787.584 | CJ40: =CI40*(1+CJ41) -> 35082.715 | CK40: Restated product & service revenue (FY27 definitions; 8-K 2-Sep-2026, Ex. 99.1). Q1–Q4/27E: prior-year quarter × (1 + growth). 2028E+: prior year × (1 + scenario lever). | CM40: =IFERROR((CJ40/CA40)^(1/5)-1,"n/m") -> 0.071533633 | CN40: =IFERROR((CA40/BB40)^(1/5)-1,"n/m") -> n/m | CO40: =IFERROR((CA40/AC40)^(1/10)-1,"n/m") -> n/m | CP40: =IFERROR((CA40/C40)^(1/20)-1,"n/m") -> n/m | CS40: 2031E | CT40: =CU40+$CT$36 -> 0 | CU40: -0.03 | CV40: =CU40+$CV$36 -> -0.07
...

Sheet Bull-Base-Bear
B2: Microsoft Corporation (MSFT) — Bull / Base / Bear Case P&L Summary | J2: Share price ($): | K2: =Model!$CF$449 -> 541
B3: Adjusted figures (company "As Adjusted" definitions; adjusted EBITDA is a model definition) · USD millions · fiscal years ended 30 June · Live panel linked to Model — toggle scenario via Model!CK2. Bull and Bear panels are value snapshots generated from the Model with the switch set to each case. FY2027E = Q1/27E calibrated to the Q1 FY27 outlook (8-K 2-Sep-2026) + Q2–Q4/27E carrying the Q1 calibration. | J3: As of: | K3: =TODAY() -> 2026-10-13 00:00:00
B5: Scenario: | C5: =Model!$CK$2 -> Base | N5: Scenario: | O5: Bull | P5: Snapshot (values) — Model run with switch = Bull | Z5: Scenario: | AA5: Bear | AB5: Snapshot (values) — Model run with switch = Bear
B7: (USDm, except EPS and shares) | C7: 2026A | D7: 2027E | E7: 2028E | F7: 2029E | G7: 2030E | H7: 2031E | I7: 26-'31 CAGR | J7: LT Hist Avg | K7: LT Hist Min | L7: LT Hist Max | N7: (USDm, except EPS and shares) | O7: 2026A | P7: 2027E | Q7: 2028E | R7: 2029E | S7: 2030E | T7: 2031E | U7: 26-'31 CAGR | V7: LT Hist Avg | W7: LT Hist Min | X7: LT Hist Max | Z7: (USDm, except EPS and shares) | AA7: 2026A | AB7: 2027E | AC7: 2028E | AD7: 2029E | AE7: 2030E | AF7: 2031E | AG7: 26-'31 CAGR | AH7: LT Hist Avg | AI7: LT Hist Min | AJ7: LT Hist Max
B9: Revenue | C9: =Model!CA179 -> 331839 | D9: =Model!CF179 -> 389116.32 | E9: =Model!CG179 -> 455406.77 | F9: =Model!CH179 -> 526872.13 | G9: =Model!CI179 -> 599356.93 | H9: =Model!CJ179 -> 671698.96 | I9: =IFERROR((H9/C9)^(1/5)-1,"n/m") -> 0.15146158 | N9: Revenue | O9: 331839 | P9: 391416.05 | Q9: 474243.89 | R9: 569347.74 | S9: 673400.05 | T9: 785851.67 | U9: 0.18818108 | Z9: Revenue | AA9: 331839 | AB9: 386816.6 | AC9: 426941.19 | AD9: 463783.94 | AE9: 493711.76 | AF9: 516561.11 | AG9: 0.092543798
B10: Revenue y/y % | D10: =IFERROR(D9/C9-1,"") -> 0.17260576 | E10: =IFERROR(E9/D9-1,"") -> 0.17036152 | F10: =IFERROR(F9/E9-1,"") -> 0.15692643 | G10: =IFERROR(G9/F9-1,"") -> 0.1375757 | H10: =IFERROR(H9/G9-1,"") -> 0.12069941 | N10: Revenue y/y % | P10: 0.17953601 | Q10: 0.21161074 | R10: 0.20053785 | S10: 0.18275705 | T10: 0.16699082 | Z10: Revenue y/y % | AB10: 0.16567551 | AC10: 0.10373028 | AD10: 0.086294673 | AE10: 0.064529647 | AF10: 0.046280757
B11: Agents and Infra revenue y/y % | C11: =Model!CA271 -> 0.22553855 | D11: =Model!CF271 -> 0.22841559 | E11: =Model!CG271 -> 0.19330324 | F11: =Model!CH271 -> 0.17340601 | G11: =Model!CI271 -> 0.15016489 | H11: =Model!CJ271 -> 0.12991861 | N11: Agents and Infra revenue y/y % | O11: 0.22553855 | P11: 0.23328003 | Q11: 0.23605419 | R11: 0.21843731 | S11: 0.19685169 | T11: 0.17771728 | Z11: Agents and Infra revenue y/y % | AA11: 0.22553855 | AB11: 0.22355115 | AC11: 0.12394647 | AD11: 0.10031603 | AE11: 0.074674234 | AF11: 0.053162697
B12: Adjusted EBITDA (model) | C12: =Model!CA242 -> 193771 | D12: =Model!CF242 -> 236821.05 | E12: =Model!CG242 -> 283174.46 | F12: =Model!CH242 -> 335306.7 | G12: =Model!CI242 -> 389934.94 | H12: =Model!CJ242 -> 441920.38 | I12: =IFERROR((H12/C12)^(1/5)-1,"n/m") -> 0.17926403 | N12: Adjusted EBITDA (model) | O12: 193771 | P12: 239754.23 | Q12: 300970.72 | R12: 366971.48 | S12: 440929.69 | T12: 517793.03 | U12: 0.21723234 | Z12: Adjusted EBITDA (model) | AA12: 193771 | AB12: 233887.18 | AC12: 254004.81 | AD12: 287017.79 | AE12: 316753.99 | AF12: 339118.27 | AG12: 0.11843946
B13: Adjusted EBITDA margin % | C13: =IFERROR(C12/C9,"") -> 0.58393076 | D13: =IFERROR(D12/D9,"") -> 0.60861249 | E13: =IFERROR(E12/E9,"") -> 0.62180556 | F13: =IFERROR(F12/F9,"") -> 0.63641002 | G13: =IFERROR(G12/G9,"") -> 0.65058886 | H13: =IFERROR(H12/H9,"") -> 0.65791435 | J13: =IFERROR(AVERAGE(Model!C243,Model!D243,Model!E243,Model!F243,Model!G243,Model!H243,Model!I243,Model!N243,Model!S243,Model!X243,Model!AC243,Model!AH243,Model!AM243,Model!AR243,Model!AW243,Model!BB243,Model!BG243,Model!BL243,Model!BQ243,Model!BV243,Model!CA243),"") -> 0.44301264 | K13: =IFERROR(MIN(Model!C243,Model!D243,Model!E243,Model!F243,Model!G243,Model!H243,Model!I243,Model!N243,Model!S243,Model!X243,Model!AC243,Model!AH243,Model!AM243,Model!AR243,Model!AW243,Model!BB243,Model!BG243,Model!BL243,Model!BQ243,Model!BV243,Model!CA243),"") -> 0.364704 | L13: =IFERROR(MAX(Model!C243,Model!D243,Model!E243,Model!F243,Model!G243,Model!H243,Model!I243,Model!N243,Model!S243,Model!X243,Model!AC243,Model!AH243,Model!AM243,Model!AR243,Model!AW243,Model!BB243,Model!BG243,Model!BL243,Model!BQ243,Model!BV243,Model!CA243),"") -> 0.58393076 | N13: Adjusted EBITDA margin % | O13: 0.58393076 | P13: 0.61253041 | Q13: 0.63463279 | R13: 0.64454719 | S13: 0.6547812 | T13: 0.6588941 | V13: 0.44301264 | W13: 0.364704 | X13: 0.58393076 | Z13: Adjusted EBITDA margin % | AA13: 0.58393076 | AB13: 0.60464619 | AC13: 0.59494098 | AD13: 0.618861 | AE13: 0.64157677 | AF13: 0.65649207 | AH13: 0.44301264 | AI13: 0.364704 | AJ13: 0.58393076
B15: Operating income (GAAP) | C15: =Model!CA190 -> 155237 | D15: =Model!CF190 -> 180501.13 | E15: =Model!CG190 -> 202794.15 | F15: =Model!CH190 -> 233435.76 | G15: =Model!CI190 -> 269519.72 | H15: =Model!CJ190 -> 306218.5 | I15: =IFERROR((H15/C15)^(1/5)-1,"n/m") -> 0.14553203 | N15: Operating income (GAAP) | O15: 155237 | P15: 183434.31 | Q15: 220547.56 | R15: 263524.13 | S15: 316203.33 | T15: 373978.4 | U15: 0.19225803 | Z15: Operating income (GAAP) | AA15: 155237 | AB15: 177567.26 | AC15: 173688.79 | AD15: 187527.52 | AE15: 202776.28 | AF15: 215238.83 | AG15: 0.067542262
B16: Operating income y/y % | D16: =IFERROR(D15/C15-1,"") -> 0.16274557 | E16: =IFERROR(E15/D15-1,"") -> 0.12350626 | F16: =IFERROR(F15/E15-1,"") -> 0.15109708 | G16: =IFERROR(G15/F15-1,"") -> 0.15457767 | H16: =IFERROR(H15/G15-1,"") -> 0.13616365 | N16: Operating income y/y % | P16: 0.18164042 | Q16: 0.20232442 | R16: 0.19486307 | S16: 0.19990276 | T16: 0.18271494 | Z16: Operating income y/y % | AB16: 0.14384625 | AC16: -0.021842288 | AD16: 0.079675473 | AE16: 0.081314783 | AF16: 0.061459607
B17: Operating margin (GAAP) % | C17: =IFERROR(C15/C9,"") -> 0.46780818 | D17: =IFERROR(D15/D9,"") -> 0.46387449 | E17: =IFERROR(E15/E9,"") -> 0.44530333 | F17: =IFERROR(F15/F9,"") -> 0.44305961 | G17: =IFERROR(G15/G9,"") -> 0.44968148 | H17: =IFERROR(H15/H9,"") -> 0.45588652 | J17: =IFERROR(AVERAGE(Model!C283,Model!D283,Model!E283,Model!F283,Model!G283,Model!H283,Model!I283,Model!N283,Model!S283,Model!X283,Model!AC283,Model!AH283,Model!AM283,Model!AR283,Model!AW283,Model!BB283,Model!BG283,Model!BL283,Model!BQ283,Model!BV283,Model!CA283),"") -> 0.35812314 | K17: =IFERROR(MIN(Model!C283,Model!D283,Model!E283,Model!F283,Model!G283,Model!H283,Model!I283,Model!N283,Model!S283,Model!X283,Model!AC283,Model!AH283,Model!AM283,Model!AR283,Model!AW283,Model!BB283,Model!BG283,Model!BL283,Model!BQ283,Model!BV283,Model!CA283),"") -> 0.19406925 | L17: =IFERROR(MAX(Model!C283,Model!D283,Model!E283,Model!F283,Model!G283,Model!H283,Model!I283,Model!N283,Model!S283,Model!X283,Model!AC283,Model!AH283,Model!AM283,Model!AR283,Model!AW283,Model!BB283,Model!BG283,Model!BL283,Model!BQ283,Model!BV283,Model!CA283),"") -> 0.46780818 | N17: Operating margin (GAAP) % | O17: 0.46780818 | P17: 0.4686428 | Q17: 0.46505092 | R17: 0.46285269 | S17: 0.46956238 | T17: 0.4758893 | V17: 0.35812314 | W17: 0.19406925 | X17: 0.46780818 | Z17: Operating margin (GAAP) % | AA17: 0.46780818 | AB17: 0.45904768 | AC17: 0.40682134 | AD17: 0.40434242 | AE17: 0.41071795 | AF17: 0.41667642 | AH17: 0.35812314 | AI17: 0.19406925 | AJ17: 0.46780818
B19: Adjusted Net Income | C19: =Model!CA258 -> 128786 | D19: =Model!CF258 -> 144080.91 | E19: =Model!CG258 -> 162330.11 | F19: =Model!CH258 -> 186079.81 | G19: =Model!CI258 -> 214296.71 | H19: =Model!CJ258 -> 243062.9 | I19: =IFERROR((H19/C19)^(1/5)-1,"n/m") -> 0.1354552 | N19: Adjusted Net Income | O19: 128786 | P19: 146427.45 | Q19: 176426.87 | R19: 210113.81 | S19: 251668.11 | T19: 297351.43 | U19: 0.18217093 | Z19: Adjusted Net Income | AA19: 128786 | AB19: 141733.81 | AC19: 138860.23 | AD19: 149259.34 | AE19: 160755.23 | AF19: 170110.04 | AG19: 0.057236765
B21: FDSO (m) | C21: =Model!CA208 -> 7453 | D21: =Model!CF208 -> 7438.2282 | E21: =Model!CG208 -> 7407.4635 | F21: =Model!CH208 -> 7314.0087 | G21: =Model!CI208 -> 7165.7318 | H21: =Model!CJ208 -> 6970.4006 | I21: =IFERROR((H21/C21)^(1/5)-1,"n/m") -> -0.013299558 | N21: FDSO (m) | O21: 7453 | P21: 7426.5164 | Q21: 7377.4772 | R21: 7266.6004 | S21: 7089.6002 | T21: 6850.1554 | U21: -0.016727573 | Z21: FDSO (m) | AA21: 7453 | AB21: 7444.1368 | AC21: 7436.4614 | AD21: 7377.1408 | AE21: 7271.3536 | AF21: 7136.6404 | AG21: -0.0086373814
B23: Adjusted EPS — Diluted ($) | C23: =Model!CA262 -> 17.279753 | D23: =Model!CF262 -> 19.370326 | E23: =Model!CG262 -> 21.914399 | F23: =Model!CH262 -> 25.441562 | G23: =Model!CI262 -> 29.905768 | H23: =Model!CJ262 -> 34.870722 | I23: =IFERROR((H23/C23)^(1/5)-1,"n/m") -> 0.1507598 | N23: Adjusted EPS — Diluted ($) | O23: 17.279753 | P23: 19.716842 | Q23: 23.914254 | R23: 28.915009 | S23: 35.498209 | T23: 43.407983 | U23: 0.20228219 | Z23: Adjusted EPS — Diluted ($) | AA23: 17.279753 | AB23: 19.039657 | AC23: 18.672891 | AD23: 20.232682 | AE23: 22.10802 | AF23: 23.836151 | AG23: 0.066448084
B24: EPS y/y % | D24: =IFERROR(D23/C23-1,"") -> 0.12098397 | E24: =IFERROR(E23/D23-1,"") -> 0.13133866 | F24: =IFERROR(F23/E23-1,"") -> 0.16095184 | G24: =IFERROR(G23/F23-1,"") -> 0.17546902 | H24: =IFERROR(H23/G23-1,"") -> 0.16601996 | N24: EPS y/y % | P24: 0.14103726 | Q24: 0.21288461 | R24: 0.20911187 | S24: 0.22767417 | T24: 0.22282176 | Z24: EPS y/y % | AB24: 0.10184773 | AC24: -0.019263241 | AD24: 0.083532351 | AE24: 0.092688584 | AF24: 0.078167585
B26: P / E (x) — assumed (adjusted EPS) | G26: 30 | H26: 30 | N26: P / E (x) — assumed (adjusted EPS) | S26: 34 | T26: 34 | Z26: P / E (x) — assumed (adjusted EPS) | AD26: 24 | AE26: 24 | AF26: 24
B27: Price Target ($) | G27: =G26*G23 -> 897.17304 | H27: =H26*H23 -> 1046.1217 | N27: Price Target ($) | S27: =S26*S23 -> 1206.9391 | T27: =T26*T23 -> 1475.8714 | Z27: Price Target ($) | AD27: =AD26*AD23 -> 485.58436 | AE27: =AE26*AE23 -> 530.59249 | AF27: =AF26*AF23 -> 572.06762
B28: Upside / (Downside) vs current | G28: =IFERROR(G27/$K$2-1,"") -> 0.65836051 | H28: =IFERROR(H27/$K$2-1,"") -> 0.93368145 | N28: Upside / (Downside) vs current | S28: =IFERROR(S27/$K$2-1,"") -> 1.2309411 | T28: =IFERROR(T27/$K$2-1,"") -> 1.7280433 | Z28: Upside / (Downside) vs current | AD28: =IFERROR(AD27/$K$2-1,"") -> -0.10243187 | AE28: =IFERROR(AE27/$K$2-1,"") -> -0.019237547 | AF28: =IFERROR(AF27/$K$2-1,"") -> 0.057426286
B29: IRR (to 30-Jun of Y-1) | G29: =IFERROR((G27/$K$2)^(1/((DATE(2030-1,6,30)-$K$3)/365.25))-1,"") -> 0.20494281 | H29: =IFERROR((H27/$K$2)^(1/((DATE(2031-1,6,30)-$K$3)/365.25))-1,"") -> 0.19437358 | N29: IRR (to 30-Jun of Y-1) | S29: =IFERROR((S27/$K$2)^(1/((DATE(2030-1,6,30)-$K$3)/365.25))-1,"") -> 0.34412992 | T29: =IFERROR((T27/$K$2)^(1/((DATE(2031-1,6,30)-$K$3)/365.25))-1,"") -> 0.31038889 | Z29: IRR (to 30-Jun of Y-1) | AD29: =IFERROR((AD27/$K$2)^(1/((DATE(2029-1,6,30)-$K$3)/365.25))-1,"") -> -0.061106317 | AE29: =IFERROR((AE27/$K$2)^(1/((DATE(2030-1,6,30)-$K$3)/365.25))-1,"") -> -0.0071338471 | AF29: =IFERROR((AF27/$K$2)^(1/((DATE(2031-1,6,30)-$K$3)/365.25))-1,"") -> 0.01515409
B31: Free Cash Flow | C31: =Model!CA314 -> 66987 | D31: =Model!CF314 -> 55969.862 | E31: =Model!CG314 -> 97395.811 | F31: =Model!CH314 -> 141021.36 | G31: =Model!CI314 -> 191374.16 | H31: =Model!CJ314 -> 233824.58 | I31: =IFERROR((H31/C31)^(1/5)-1,"n/m") -> 0.28404406 | N31: Free Cash Flow | O31: 66987 | P31: 58642.022 | Q31: 106961.72 | R31: 156648.72 | S31: 217704.56 | T31: 274491.18 | U31: 0.32589024 | Z31: Free Cash Flow | AA31: 66987 | AB31: 53297.148 | AC31: 80650.719 | AD31: 116698.62 | AE31: 153558.42 | AF31: 179110.2 | AG31: 0.21737942
B32: FCF % | C32: =IFERROR(C31/C9,"") -> 0.20186597 | D32: =IFERROR(D31/D9,"") -> 0.14383838 | E32: =IFERROR(E31/E9,"") -> 0.21386553 | F32: =IFERROR(F31/F9,"") -> 0.26765766 | G32: =IFERROR(G31/G9,"") -> 0.31929916 | H32: =IFERROR(H31/H9,"") -> 0.34810919 | J32: =IFERROR(AVERAGE(Model!C317,Model!D317,Model!E317,Model!F317,Model!G317,Model!H317,Model!I317,Model!N317,Model!S317,Model!X317,Model!AC317,Model!AH317,Model!AM317,Model!AR317,Model!AW317,Model!BB317,Model!BG317,Model!BL317,Model!BQ317,Model!BV317,Model!CA317),"") -> 0.304809 | K32: =IFERROR(MIN(Model!C317,Model!D317,Model!E317,Model!F317,Model!G317,Model!H317,Model!I317,Model!N317,Model!S317,Model!X317,Model!AC317,Model!AH317,Model!AM317,Model!AR317,Model!AW317,Model!BB317,Model!BG317,Model!BL317,Model!BQ317,Model!BV317,Model!CA317),"") -> 0.20186597 | L32: =IFERROR(MAX(Model!C317,Model!D317,Model!E317,Model!F317,Model!G317,Model!H317,Model!I317,Model!N317,Model!S317,Model!X317,Model!AC317,Model!AH317,Model!AM317,Model!AR317,Model!AW317,Model!BB317,Model!BG317,Model!BL317,Model!BQ317,Model!BV317,Model!CA317),"") -> 0.39771849 | N32: FCF % | O32: 0.20186597 | P32: 0.14982018 | Q32: 0.2255416 | R32: 0.27513716 | S32: 0.32329157 | T32: 0.34929134 | V32: 0.304809 | W32: 0.20186597 | X32: 0.39771849 | Z32: FCF % | AA32: 0.20186597 | AB32: 0.13778403 | AC32: 0.18890358 | AD32: 0.25162282 | AE32: 0.31102849 | AF32: 0.34673574 | AH32: 0.304809 | AI32: 0.20186597 | AJ32: 0.39771849
B33: FCF / share ($) | C33: =IFERROR(C31/C21,"") -> 8.9879243 | D33: =IFERROR(D31/D21,"") -> 7.5246229 | E33: =IFERROR(E31/E21,"") -> 13.148335 | F33: =IFERROR(F31/F21,"") -> 19.280994 | G33: =IFERROR(G31/G21,"") -> 26.706856 | H33: =IFERROR(H31/H21,"") -> 33.545358 | N33: FCF / share ($) | O33: 8.9879243 | P33: 7.8963027 | Q33: 14.498415 | R33: 21.55736 | S33: 30.707593 | T33: 40.070796 | Z33: FCF / share ($) | AA33: 8.9879243 | AB33: 7.1596142 | AC33: 10.845309 | AD33: 15.81895 | AE33: 21.118272 | AF33: 25.097271
B34: FCF Yield (on PT) | F34: =IFERROR(F33/F$27,"") | G34: =IFERROR(G33/G$27,"") -> 0.029767787 | H34: =IFERROR(H33/H$27,"") -> 0.032066402 | N34: FCF Yield (on PT) | R34: =IFERROR(R33/R$27,"") | S34: =IFERROR(S33/S$27,"") -> 0.025442537 | T34: =IFERROR(T33/T$27,"") -> 0.027150601 | Z34: FCF Yield (on PT) | AD34: =IFERROR(AD33/AD$27,"") -> 0.03257714 | AE34: =IFERROR(AE33/AE$27,"") -> 0.039801302 | AF34: =IFERROR(AF33/AF$27,"") -> 0.043871161
B35: Adjusted EBITDA (leverage basis) | C35: =Model!CA242 -> 193771 | D35: =Model!CF242 -> 236821.05 | E35: =Model!CG242 -> 283174.46 | F35: =Model!CH242 -> 335306.7 | G35: =Model!CI242 -> 389934.94 | H35: =Model!CJ242 -> 441920.38 | I35: =IFERROR((H35/C35)^(1/5)-1,"n/m") -> 0.17926403 | N35: Adjusted EBITDA (leverage basis) | O35: 193771 | P35: 239754.23 | Q35: 300970.72 | R35: 366971.48 | S35: 440929.69 | T35: 517793.03 | U35: 0.21723234 | Z35: Adjusted EBITDA (leverage basis) | AA35: 193771 | AB35: 233887.18 | AC35: 254004.81 | AD35: 287017.79 | AE35: 316753.99 | AF35: 339118.27 | AG35: 0.11843946
B36: Adjusted EBITDA % of revenue | C36: =IFERROR(C35/C9,"") -> 0.58393076 | D36: =IFERROR(D35/D9,"") -> 0.60861249 | E36: =IFERROR(E35/E9,"") -> 0.62180556 | F36: =IFERROR(F35/F9,"") -> 0.63641002 | G36: =IFERROR(G35/G9,"") -> 0.65058886 | H36: =IFERROR(H35/H9,"") -> 0.65791435 | J36: =IFERROR(AVERAGE(Model!C282,Model!D282,Model!E282,Model!F282,Model!G282,Model!H282,Model!I282,Model!N282,Model!S282,Model!X282,Model!AC282,Model!AH282,Model!AM282,Model!AR282,Model!AW282,Model!BB282,Model!BG282,Model!BL282,Model!BQ282,Model!BV282,Model!CA282),"") -> 0.44301264 | K36: =IFERROR(MIN(Model!C282,Model!D282,Model!E282,Model!F282,Model!G282,Model!H282,Model!I282,Model!N282,Model!S282,Model!X282,Model!AC282,Model!AH282,Model!AM282,Model!AR282,Model!AW282,Model!BB282,Model!BG282,Model!BL282,Model!BQ282,Model!BV282,Model!CA282),"") -> 0.364704 | L36: =IFERROR(MAX(Model!C282,Model!D282,Model!E282,Model!F282,Model!G282,Model!H282,Model!I282,Model!N282,Model!S282,Model!X282,Model!AC282,Model!AH282,Model!AM282,Model!AR282,Model!AW282,Model!BB282,Model!BG282,Model!BL282,Model!BQ282,Model!BV282,Model!CA282),"") -> 0.58393076 | N36: Adjusted EBITDA % of revenue | O36: 0.58393076 | P36: 0.61253041 | Q36: 0.63463279 | R36: 0.64454719 | S36: 0.6547812 | T36: 0.6588941 | V36: 0.44301264 | W36: 0.364704 | X36: 0.58393076 | Z36: Adjusted EBITDA % of revenue | AA36: 0.58393076 | AB36: 0.60464619 | AC36: 0.59494098 | AD36: 0.618861 | AE36: 0.64157677 | AF36: 0.65649207 | AH36: 0.44301264 | AI36: 0.364704 | AJ36: 0.58393076
B38: Net Debt | C38: =Model!CA443 -> 30045 | D38: =Model!CF443 -> 58176.202 | E38: =Model!CG443 -> 87531.628 | F38: =Model!CH443 -> 113937.01 | G38: =Model!CI443 -> 140269.72 | H38: =Model!CJ443 -> 165242.67 | N38: Net Debt | O38: 30045 | P38: 68176.202 | Q38: 99015.051 | R38: 128294.33 | S38: 158870.25 | T38: 189659.51 | Z38: Net Debt | AA38: 30045 | AB38: 54455.852 | AC38: 75289.963 | AD38: 97429.36 | AE38: 117727.32 | AF38: 134852.89
B39: Net Debt / Adjusted EBITDA (x) | C39: =IFERROR(C38/C35,"") -> 0.15505416 | D39: =IFERROR(D38/D35,"") -> 0.24565469 | E39: =IFERROR(E38/E35,"") -> 0.30910848 | F39: =IFERROR(F38/F35,"") -> 0.33979937 | G39: =IFERROR(G38/G35,"") -> 0.35972596 | H39: =IFERROR(H38/H35,"") -> 0.37391955 | N39: Net Debt / Adjusted EBITDA (x) | O39: 0.15505416 | P39: 0.2843587 | Q39: 0.32898566 | R39: 0.349603 | S39: 0.36030744 | T39: 0.36628441 | Z39: Net Debt / Adjusted EBITDA (x) | AA39: 0.15505416 | AB39: 0.23282957 | AC39: 0.29641157 | AD39: 0.33945408 | AE39: 0.37166798 | AF39: 0.3976574
B40: Share repurchases ($m) | D40: =Model!CF327 -> 21393.064 | E40: =Model!CG327 -> 57251.145 | F40: =Model!CH327 -> 93974.252 | G40: =Model!CI327 -> 141500.83 | H40: =Model!CJ327 -> 178877.69 | N40: Share repurchases ($m) | P40: 34065.224 | Q40: 64920.122 | R40: 107679.12 | S40: 165849.5 | T40: 217518.53 | Z40: Share repurchases ($m) | AB40: 15000 | AC40: 37174.408 | AD40: 72578.199 | AE40: 106694.73 | AF40: 127235.53
B41: Implied avg buyback price ($) | D41: =Model!CF326 -> 541 | E41: =Model!CG326 -> 584.28 | F41: =Model!CH326 -> 631.0224 | G41: =Model!CI326 -> 681.50419 | H41: =Model!CJ326 -> 736.02453 | N41: Implied avg buyback price ($) | P41: 541 | Q41: 584.28 | R41: 631.0224 | S41: 681.50419 | T41: 736.02453 | Z41: Implied avg buyback price ($) | AB41: 541 | AC41: 584.28 | AD41: 631.0224 | AE41: 681.50419 | AF41: 736.02453
B42: Shares repurchased (m) | D42: =Model!CF329 -> 39.543557 | E42: =Model!CG329 -> 97.985803 | F42: =Model!CH329 -> 148.9238 | G42: =Model!CI329 -> 207.63017 | H42: =Model!CJ329 -> 243.03224 | N42: Shares repurchased (m) | P42: 62.967142 | Q42: 111.11132 | R42: 170.6423 | S42: 243.35801 | T42: 295.53163 | Z42: Shares repurchased (m) | AB42: 27.726433 | AC42: 63.624303 | AD42: 115.01683 | AE42: 156.5577 | AF42: 172.8686
B44: ROIC | C44: =Model!CA426 -> 0.26485678 | D44: =Model!CF426 -> 0.23668981 | E44: =Model!CG426 -> 0.22479256 | F44: =Model!CH426 -> 0.22640154 | G44: =Model!CI426 -> 0.23730078 | H44: =Model!CJ426 -> 0.24936307 | J44: =IFERROR(AVERAGE(Model!C426,Model!D426,Model!E426,Model!F426,Model!G426,Model!H426,Model!I426,Model!N426,Model!S426,Model!X426,Model!AC426,Model!AH426,Model!AM426,Model!AR426,Model!AW426,Model!BB426,Model!BG426,Model!BL426,Model!BQ426,Model!BV426,Model!CA426),"") -> 0.98736816 | K44: =IFERROR(MIN(Model!C426,Model!D426,Model!E426,Model!F426,Model!G426,Model!H426,Model!I426,Model!N426,Model!S426,Model!X426,Model!AC426,Model!AH426,Model!AM426,Model!AR426,Model!AW426,Model!BB426,Model!BG426,Model!BL426,Model!BQ426,Model!BV426,Model!CA426),"") -> 0.26485678 | L44: =IFERROR(MAX(Model!C426,Model!D426,Model!E426,Model!F426,Model!G426,Model!H426,Model!I426,Model!N426,Model!S426,Model!X426,Model!AC426,Model!AH426,Model!AM426,Model!AR426,Model!AW426,Model!BB426,Model!BG426,Model!BL426,Model!BQ426,Model!BV426,Model!CA426),"") -> 1.9121781 | N44: ROIC | O44: 0.26485678 | P44: 0.24063055 | Q44: 0.24167001 | R44: 0.24861067 | S44: 0.26576816 | T44: 0.28452532 | V44: 0.98736816 | W44: 0.26485678 | X44: 1.9121781 | Z44: ROIC | AA44: 0.26485678 | AB44: 0.23275125 | AC44: 0.19595713 | AD44: 0.18983884 | AE44: 0.19191482 | AF44: 0.19482281 | AH44: 0.98736816 | AI44: 0.26485678 | AJ44: 1.9121781
B45: RONTA | C45: =Model!CA437 -> 0.27170886 | D45: =Model!CF437 -> 0.24292535 | E45: =Model!CG437 -> 0.22995176 | F45: =Model!CH437 -> 0.23116165 | G45: =Model!CI437 -> 0.24212752 | H45: =Model!CJ437 -> 0.25440195 | J45: =IFERROR(AVERAGE(Model!C437,Model!D437,Model!E437,Model!F437,Model!G437,Model!H437,Model!I437,Model!N437,Model!S437,Model!X437,Model!AC437,Model!AH437,Model!AM437,Model!AR437,Model!AW437,Model!BB437,Model!BG437,Model!BL437,Model!BQ437,Model!BV437,Model!CA437),"") -> 0.29201731 | K45: =IFERROR(MIN(Model!C437,Model!D437,Model!E437,Model!F437,Model!G437,Model!H437,Model!I437,Model!N437,Model!S437,Model!X437,Model!AC437,Model!AH437,Model!AM437,Model!AR437,Model!AW437,Model!BB437,Model!BG437,Model!BL437,Model!BQ437,Model!BV437,Model!CA437),"") -> 0.099162492 | L45: =IFERROR(MAX(Model!C437,Model!D437,Model!E437,Model!F437,Model!G437,Model!H437,Model!I437,Model!N437,Model!S437,Model!X437,Model!AC437,Model!AH437,Model!AM437,Model!AR437,Model!AW437,Model!BB437,Model!BG437,Model!BL437,Model!BQ437,Model!BV437,Model!CA437),"") -> 0.57931953 | N45: RONTA | O45: 0.27170886 | P45: 0.25120011 | Q45: 0.25129471 | R45: 0.25790647 | S45: 0.27543813 | T45: 0.29472804 | V45: 0.29201731 | W45: 0.099162492 | X45: 0.57931953 | Z45: RONTA | AA45: 0.27170886 | AB45: 0.23739537 | AC45: 0.19692233 | AD45: 0.19021326 | AE45: 0.1919368 | AF45: 0.19459883 | AH45: 0.29201731 | AI45: 0.099162492 | AJ45: 0.57931953
B47: Implied Market Cap (USDm) | F47: =F27*F21 -> 0 | G47: =G27*G21 -> 6428901.3 | H47: =H27*H21 -> 7291887 | N47: Implied Market Cap (USDm) | R47: =R27*R21 -> 0 | S47: =S27*S21 -> 8556715.9 | T47: =T27*T21 -> 10109949 | Z47: Implied Market Cap (USDm) | AD47: =AD27*AD21 -> 3582224.2 | AE47: =AE27*AE21 -> 3858125.6 | AF47: =AF27*AF21 -> 4082640.9
B48: (+) Net Debt & NCI | F48: =F38+Model!CH360 -> 113937.01 | G48: =G38+Model!CI360 -> 140269.72 | H48: =H38+Model!CJ360 -> 165242.67 | N48: (+) Net Debt & NCI | R48: =R38+Model!CH360 -> 128294.33 | S48: =S38+Model!CI360 -> 158870.25 | T48: =T38+Model!CJ360 -> 189659.51 | Z48: (+) Net Debt & NCI | AD48: =AD38+Model!CH360 -> 97429.36 | AE48: =AE38+Model!CI360 -> 117727.32 | AF48: =AF38+Model!CJ360 -> 134852.89
B49: Implied Enterprise Value (USDm) | F49: =F47+F48 -> 113937.01 | G49: =G47+G48 -> 6569171 | H49: =H47+H48 -> 7457129.7 | N49: Implied Enterprise Value (USDm) | R49: =R47+R48 -> 128294.33 | S49: =S47+S48 -> 8715586.1 | T49: =T47+T48 -> 10299608 | Z49: Implied Enterprise Value (USDm) | AD49: =AD47+AD48 -> 3679653.6 | AE49: =AE47+AE48 -> 3975852.9 | AF49: =AF47+AF48 -> 4217493.8
B50: Implied EV / Adjusted EBITDA (x) | F50: =IFERROR(F49/F35,"") -> 0.33979937 | G50: =IFERROR(G49/G35,"") -> 16.846839 | H50: =IFERROR(H49/H35,"") -> 16.874374 | N50: Implied EV / Adjusted EBITDA (x) | R50: =IFERROR(R49/R35,"") -> 0.349603 | S50: =IFERROR(S49/S35,"") -> 19.766385 | T50: =IFERROR(T49/T35,"") -> 19.891361 | Z50: Implied EV / Adjusted EBITDA (x) | AD50: =IFERROR(AD49/AD35,"") -> 12.820298 | AE50: =IFERROR(AE49/AE35,"") -> 12.551864 | AF50: =IFERROR(AF49/AF35,"") -> 12.436646

Sheet DCF
B2: DCF VALUATION — MICROSOFT CORPORATION (MSFT)
B4: 1. WACC BUILD
B5: Risk-free rate (US 10Y govt) | C5: 0.0425 | D5: Assumption (~US 10Y Treasury yield, Oct-2026; government rate sources not reachable from the build environment); update to market
B6: Equity risk premium | C6: 0.05 | D6: Assumption: US implied ERP ~4.5–5.5%
B7: Levered beta | C7: 1.05 | D7: Assumption: mega-cap software / cloud peers (ORCL, CRM, SAP, AMZN, GOOGL) ~0.9–1.2; capex intensity of the AI build-out adds operating leverage
B8: Cost of equity | C8: =C5+C7*C6 -> 0.095
B9: Pre-tax cost of debt | C9: 0.045 | D9: Assumption: AAA-rated issuer; finance-lease discount rate 4.5% (FY2026 10-K); senior notes carry ~1.2% net of capitalised interest
B10: Tax rate | C10: 0.19 | D10: Model FY2028E+ effective tax rate (FY26 19.4%; Q1 FY27 guided ~20%)
B11: After-tax cost of debt | C11: =C9*(1-C10) -> 0.03645
B12: Target D/V | C12: 0.02 | D12: Debt $40.3bn + finance leases $66.6bn vs ~$4.0trn market cap ($541 × ~7.45bn diluted shares): D/V ~2–3%
B13: WACC | C13: =C8*(1-C12)+C11*C12 -> 0.093829
B15: Valuation date (live) | C15: =TODAY() -> 2026-10-13 00:00:00 | D15: Periods = (30-Jun of fiscal year − today) / 365.25; cash flows assumed at fiscal year-end (30 June); FY2026A (ended 30-Jun-2026) is the base year
B16: 2. UNLEVERED FREE CASH FLOW BUILD (USDm)
D17: 2027E | E17: 2028E | F17: 2029E | G17: 2030E | H17: 2031E | I17: 2032E | J17: 2033E | K17: 2034E | L17: 2035E | M17: 2036E | N17: Terminal | P17: CAGR 27–31E | Q17: CAGR 27–36E
B18: Adj. EBIT (= adjusted operating income; amortization and SBC are expensed) | D18: =Model!CF246-Model!CF248 -> 180501.13 | E18: =Model!CG246-Model!CG248 -> 202794.15 | F18: =Model!CH246-Model!CH248 -> 233435.76 | G18: =Model!CI246-Model!CI248 -> 269519.72 | H18: =Model!CJ246-Model!CJ248 -> 306218.5 | I18: =H18*(1+I$26) -> 336840.35 | J18: =I18*(1+J$26) -> 367155.98 | K18: =J18*(1+K$26) -> 396528.46 | L18: =K18*(1+L$26) -> 424285.46 | M18: =L18*(1+M$26) -> 449742.58 | P18: =(H18/D18)^(1/(COLUMNS(D18:H18)-1))-1 -> 0.14126861 | Q18: =(M18/D18)^(1/(COLUMNS(D18:M18)-1))-1 -> 0.10676084
B19: × (1 − tax rate) | D19: =1-$C$10 -> 0.81 | E19: =1-$C$10 -> 0.81 | F19: =1-$C$10 -> 0.81 | G19: =1-$C$10 -> 0.81 | H19: =1-$C$10 -> 0.81 | I19: =1-$C$10 -> 0.81 | J19: =1-$C$10 -> 0.81 | K19: =1-$C$10 -> 0.81 | ... M19: =1-$C$10 -> 0.81
B20: NOPAT | D20: =D18*D19 -> 146205.92 | E20: =E18*E19 -> 164263.26 | F20: =F18*F19 -> 189082.96 | G20: =G18*G19 -> 218310.97 | H20: =H18*H19 -> 248036.99 | I20: =I18*I19 -> 272840.69 | J20: =J18*J19 -> 297396.35 | K20: =K18*K19 -> 321188.06 | ... M20: =M18*M19 -> 364291.49
B21: plus D&A (depreciation, amortization & other) | D21: =Model!CF204 -> 56319.92 | E21: =Model!CG204 -> 80380.309 | F21: =Model!CH204 -> 101870.94 | G21: =Model!CI204 -> 120415.23 | H21: =Model!CJ204 -> 135701.88 | I21: =H21*(1+I$26) -> 149272.07 | J21: =I21*(1+J$26) -> 162706.55 | K21: =J21*(1+K$26) -> 175723.08 | L21: =K21*(1+L$26) -> 188023.69 | M21: =L21*(1+M$26) -> 199305.11
B22: − Capex incl. finance-lease assets and acquisitions (M&A lever 2028E–31E) | D22: =Model!CF297+Model!CF298-Model!CF168 -> -200000 | E22: =Model!CG297+Model!CG298-Model!CG168 -> -207933.05 | F22: =Model!CH297+Model!CH298-Model!CH168 -> -213748.85 | G22: =Model!CI297+Model!CI298-Model!CI168 -> -212774.93 | H22: =Model!CJ297+Model!CJ298-Model!CJ168 -> -217943.67 | I22: =Model!CJ297*(1+I$26) -> -195061.38 | J22: =I22*(1+J$26) -> -212616.9 | K22: =J22*(1+K$26) -> -229626.25 | L22: =K22*(1+L$26) -> -245700.09 | M22: =L22*(1+M$26) -> -260442.1
B23: − Δ Working capital (CF statement) | D23: =Model!CF295 -> 6027.0618 | E23: =Model!CG295 -> 6905.1039 | F23: =Model!CH295 -> 7444.1451 | G23: =Model!CI295 -> 7550.3346 | H23: =Model!CJ295 -> 7535.4628 | I23: =H23*(1+I$26) -> 8289.0091 | J23: =I23*(1+J$26) -> 9035.0199 | K23: =J23*(1+K$26) -> 9757.8215 | L23: =K23*(1+L$26) -> 10440.869 | M23: =L23*(1+M$26) -> 11067.321
B24: Unlevered FCF | D24: =D20+D21+D22+D23 -> 8552.9008 | E24: =E20+E21+E22+E23 -> 43615.63 | F24: =F20+F21+F22+F23 -> 84649.202 | G24: =G20+G21+G22+G23 -> 133501.6 | H24: =H20+H21+H22+H23 -> 173330.66 | I24: =I20+I21+I22+I23 -> 235340.38 | J24: =J20+J21+J22+J23 -> 256521.02 | K24: =K20+K21+K22+K23 -> 277042.7 | ... M24: =M20+M21+M22+M23 -> 314221.83 | N24: =M24*(1+$C$27) -> 325219.59 | P24: =(H24/D24)^(1/(COLUMNS(D24:H24)-1))-1 -> 1.1217318 | Q24: =(M24/D24)^(1/(COLUMNS(D24:M24)-1))-1 -> 0.49245947
B25: Terminal Value (Gordon Growth) | N25: =N24/($C$13-$C$27) -> 5528219
B26: Fade-period growth (2032E–36E; 10.0% → 6.0% linear) | I26: 0.1 | J26: =I26+($M$26-$I$26)/4 -> 0.09 | K26: =J26+($M$26-$I$26)/4 -> 0.08 | L26: =K26+($M$26-$I$26)/4 -> 0.07 | M26: 0.06
B27: Terminal growth rate | C27: 0.035
B29: Discount period (years) | D29: =(DATE(2027,6,30)-$C$15)/365.25 -> 0.7118412 | E29: =(DATE(2028,6,30)-$C$15)/365.25 -> 1.7138946 | F29: =(DATE(2029,6,30)-$C$15)/365.25 -> 2.7132101 | G29: =(DATE(2030,6,30)-$C$15)/365.25 -> 3.7125257 | H29: =(DATE(2031,6,30)-$C$15)/365.25 -> 4.7118412 | I29: =(DATE(2032,6,30)-$C$15)/365.25 -> 5.7138946 | J29: =(DATE(2033,6,30)-$C$15)/365.25 -> 6.7132101 | K29: =(DATE(2034,6,30)-$C$15)/365.25 -> 7.7125257 | L29: =(DATE(2035,6,30)-$C$15)/365.25 -> 8.7118412 | M29: =(DATE(2036,6,30)-$C$15)/365.25 -> 9.7138946 | N29: =M29 -> 9.7138946
