Workbook

Sheet Model
CF1: SCENARIO SWITCH ▼ (Bull / Base / Bear) — drives all scenario-linked forecast drivers
B2: Old Dominion Freight Line, Inc. (Nasdaq: ODFL) — 3-Statement Financial Model | CF2: Base
B3: US GAAP as reported · USD millions (per-share data in USD; shares in millions, split-adjusted; tons, shipments & miles in thousands) · Source: ODFL Forms 10-K / 10-Q, Form 8-K earnings releases (Ex. 99.1) and mid-quarter updates, SEC XBRL companyfacts, SEC EDGAR CIK 0000878927 (investor-relations releases are the same documents as filed on EDGAR)
B4: Basis notes: calendar fiscal year; single reportable segment (LTL); all periods as originally reported. Stock splits 3-for-2 Aug-2010, Sep-2012, Mar-2020 and 2-for-1 Mar-2024 (earlier shares / per-share data restated). Operating statistics on the total-tons basis to 2013, LTL from 2014; LTL / other services revenue split from 2019. ODFL publishes no non-GAAP measures or annual guidance: EBITDA / Adjusted EBITDA / adjusted EPS are model definitions; Q3/26E anchored to the 3-Sep-26 mid-quarter update, Q4/26E and the Q3/Q4 operating ratio on 2016–25 seasonality.
CH5: Forecast | CI5: Historical | CJ5: Historical | CK5: Historical
B6: (USDm) | C6: 2006 | D6: 2007 | E6: 2008 | F6: 2009 | G6: 2010 | H6: 2011 | I6: 2012 | J6: Q1/13 | K6: Q2/13 | L6: Q3/13 | M6: Q4/13 | N6: 2013 | O6: Q1/14 | P6: Q2/14 | Q6: Q3/14 | R6: Q4/14 | S6: 2014 | T6: Q1/15 | U6: Q2/15 | V6: Q3/15 | W6: Q4/15 | X6: 2015 | Y6: Q1/16 | Z6: Q2/16 | AA6: Q3/16 | AB6: Q4/16 | AC6: 2016 | AD6: Q1/17 | AE6: Q2/17 | AF6: Q3/17 | AG6: Q4/17 | AH6: 2017 | AI6: Q1/18 | AJ6: Q2/18 | AK6: Q3/18 | AL6: Q4/18 | AM6: 2018 | AN6: Q1/19 | AO6: Q2/19 | AP6: Q3/19 | AQ6: Q4/19 | AR6: 2019 | AS6: Q1/20 | AT6: Q2/20 | AU6: Q3/20 | AV6: Q4/20 | AW6: 2020 | AX6: Q1/21 | AY6: Q2/21 | AZ6: Q3/21 | BA6: Q4/21 | BB6: 2021 | BC6: Q1/22 | BD6: Q2/22 | BE6: Q3/22 | BF6: Q4/22 | BG6: 2022 | BH6: Q1/23 | BI6: Q2/23 | BJ6: Q3/23 | BK6: Q4/23 | BL6: 2023 | BM6: Q1/24 | BN6: Q2/24 | BO6: Q3/24 | BP6: Q4/24 | BQ6: 2024 | BR6: Q1/25 | BS6: Q2/25 | BT6: Q3/25 | BU6: Q4/25 | BV6: 2025 | BW6: Q1/26 | BX6: Q2/26 | BY6: Q3/26E | BZ6: Q4/26E | CA6: 2026E | CB6: 2027E | CC6: 2028E | CD6: 2029E | CE6: 2030E | CF6: Modelling Notes | CH6: 5Y CAGR | CI6: 5Y CAGR | CJ6: 10Y CAGR | CK6: 19Y CAGR
CH7: 25-'30 | CI7: 20-'25 | CJ7: 15-'25 | CK7: 06-'25
B8: LTL OPERATING BUILD — TONS PER DAY × WORK DAYS × REVENUE PER HUNDREDWEIGHT (EX-FUEL + FUEL SURCHARGE) · OTHER SERVICES · NETWORK | CF8: LTL OPERATING BUILD — modelling logic (tons/day × work days → tons; × 20 cwt × revenue/cwt → LTL revenue (statistics basis) → reported revenue → operating ratio → EPS)
CN9: SCENARIO INPUT TABLE — driver assumptions per Bull / Base / Bear | CO9: Bull | CP9: Base | CQ9: Bear | CR9: Bull / Bear = Base + Δ (Δ inputs on each block header). FY26 block: Q3/26E anchored to the 3-Sep-26 mid-quarter update; Q4/26E and the Q3/Q4 operating ratio from 2016–25 seasonality (best / average / worst).
B10: LTL volume — tonnage, shipments & weight per shipment (operating statistics as published; total tons & shipments to 2013, LTL from 2014) | CF10: VOLUME — modelling logic
B11: Work days | C11: 252 | D11: 253 | E11: 254 | F11: 253 | G11: 252 | H11: 253 | I11: 254 | J11: 63 | K11: 64 | L11: 64 | M11: 63 | N11: 254 | O11: 63 | P11: 64 | Q11: 64 | R11: 63 | S11: 254 | T11: 63 | U11: 64 | V11: 64 | W11: 63 | X11: 254 | Y11: 64 | Z11: 64 | AA11: 64 | AB11: 62 | AC11: 254 | AD11: 64 | AE11: 64 | AF11: 63 | AG11: 62 | AH11: 253 | AI11: 64 | AJ11: 64 | AK11: 63 | AL11: 62 | AM11: 253 | AN11: 63 | AO11: 64 | AP11: 64 | AQ11: 62 | AR11: 253 | AS11: 64 | AT11: 64 | AU11: 64 | AV11: 62 | AW11: 254 | AX11: 63 | AY11: 64 | AZ11: 64 | BA11: 61 | BB11: 252 | BC11: 64 | BD11: 64 | BE11: 64 | BF11: 61 | BG11: 253 | BH11: 64 | BI11: 64 | BJ11: 63 | BK11: 61 | BL11: 252 | BM11: 64 | BN11: 64 | BO11: 64 | BP11: 62 | BQ11: 254 | BR11: 63 | BS11: 64 | BT11: 64 | BU11: 62 | BV11: 253 | BW11: 63 | BX11: 64 | BY11: 64 | BZ11: 62 | CA11: =SUM(BW11,BX11,BY11,BZ11) | CB11: 252 | CC11: 253 | CD11: 253 | CE11: 253 | CF11: Published in the releases from 2012 (Q4) / 2013; earlier years per the ODFL calendar (weekdays less New Year, Memorial Day, July 4, Labor Day, Thanksgiving + Friday, Christmas Eve & Day — reproduces every published count 2012–26). Q3/26E 64, Q4/26E 62; 2027E–30E 252 / 253 / 253 / 253. | CN11: FY26 calibration — Q3/26E anchored to the 3-Sep-26 mid-quarter update; seasonality 2016–25 (formulas on the historical columns) | CO11: Bull | CP11: Base | CQ11: Bear | CR11: ODFL gives no revenue / EPS guidance. Bull / Base / Bear = best / average / worst historical sequential change, 2016–2025 (Q2→Q3 and Q3→Q4).
B12: LTL tons per day (total tons per day to 2013) | C12: 19281.746 | D12: 20833.992 | E12: 21830.709 | F12: 19375.494 | G12: 22444.444 | H12: 25284.585 | I12: 27066.929 | J12: 27253.968 | K12: 29359.375 | L12: 30062.5 | M12: 29619.048 | N12: 29074.803 | O12: 26666.667 | P12: 29109.375 | Q12: 30406.25 | R12: 30190.476 | S12: 29098.425 | T12: 29714.286 | U12: 31750 | V12: 32421.875 | W12: 31095.238 | X12: 31251.969 | Y12: 30060 | Z12: 31640 | AA12: 32016 | AB12: 31177 | AC12: 31224 | AD12: 30781 | AE12: 33563 | AF12: 34762 | AG12: 35661 | AH12: 33672 | AI12: 35531 | AJ12: 38468.75 | AK12: 37571.429 | AL12: 36693.548 | AM12: 37071.146 | AN12: 35016 | AO12: 36031 | AP12: 35609 | AQ12: 35048.387 | AR12: 35430.83 | AS12: 33641 | AT12: 31688 | AU12: 36078 | AV12: 36758 | AW12: 34528 | AX12: 37010 | AY12: 40600 | AZ12: 41020 | BA12: 42020 | BB12: 40153 | BC12: 41454 | BD12: 41746 | BE12: 39941 | BF12: 38195 | BG12: 40359 | BH12: 36540 | BI12: 35878 | BJ12: 37181 | BK12: 37419 | BL12: 36745 | BM12: 35380 | BN12: 36560 | BO12: 35408 | BP12: 34351 | BQ12: 35433 | BR12: 33135 | BS12: 33178 | BT12: 32231 | BU12: 30691 | BV12: 32319 | BW12: 30584 | BX12: 31804 | BY12: =BT12*(1+$CP$19) | BZ12: =BY12*(1+CHOOSE(MATCH($CF$2,{"Bull","Base","Bear"},0),$CO$14,$CP$14,$CQ$14)) | CA12: =IFERROR(CA15*1000/CA11,"") | CB12: =CA12*(1+CB13) | CC12: =CB12*(1+CC13) | CD12: =CC12*(1+CD13) | CE12: =CD12*(1+CE13) | CF12: Q3/26E: Q3/25 × (1 + Aug-26 tons/day y/y from the 3-Sep-26 update). Q4/26E: Q3/26E × (1 + 2016–25 Q3→Q4 sequential change: best / average / worst by scenario). 2027E+: prior year × (1 + scenario lever). Derived as tons ÷ work days where not published (2014–15, 2018–19). | CH12: =IFERROR((CE12/BV12)^(1/5)-1,"n/m") | CI12: =IFERROR((BV12/AW12)^(1/5)-1,"n/m") | CJ12: =IFERROR((BV12/X12)^(1/10)-1,"n/m") | CK12: =IFERROR((BV12/C12)^(1/19)-1,"n/m") | CN12: Q2→Q3 operating-ratio change (best / average / worst, 2016–25) | CO12: =MIN(AA92,AF92,AK92,AP92,AU92,AZ92,BE92,BJ92,BO92,BT92) | CP12: =AVERAGE(AA92,AF92,AK92,AP92,AU92,AZ92,BE92,BJ92,BO92,BT92) | CQ12: =MAX(AA92,AF92,AK92,AP92,AU92,AZ92,BE92,BJ92,BO92,BT92) | CR12: Applied to the Q2/26 operating ratio (70.1%). Best case = 2020 (−332 bps, COVID rebound); excluding 2020 the best is −166 bps (2023).
B13: y/y % | D13: =IF(AND(ISNUMBER(D12),ISNUMBER(C12)),IFERROR(D12/C12-1,""),"") | E13: =IF(AND(ISNUMBER(E12),ISNUMBER(D12)),IFERROR(E12/D12-1,""),"") | F13: =IF(AND(ISNUMBER(F12),ISNUMBER(E12)),IFERROR(F12/E12-1,""),"") | G13: =IF(AND(ISNUMBER(G12),ISNUMBER(F12)),IFERROR(G12/F12-1,""),"") | H13: =IF(AND(ISNUMBER(H12),ISNUMBER(G12)),IFERROR(H12/G12-1,""),"") | I13: =IF(AND(ISNUMBER(I12),ISNUMBER(H12)),IFERROR(I12/H12-1,""),"") | N13: =IF(AND(ISNUMBER(N12),ISNUMBER(I12)),IFERROR(N12/I12-1,""),"") | O13: =IF(AND(ISNUMBER(O12),ISNUMBER(J12)),IFERROR(O12/J12-1,""),"") | P13: =IF(AND(ISNUMBER(P12),ISNUMBER(K12)),IFERROR(P12/K12-1,""),"") | Q13: =IF(AND(ISNUMBER(Q12),ISNUMBER(L12)),IFERROR(Q12/L12-1,""),"") | R13: =IF(AND(ISNUMBER(R12),ISNUMBER(M12)),IFERROR(R12/M12-1,""),"") | S13: =IF(AND(ISNUMBER(S12),ISNUMBER(N12)),IFERROR(S12/N12-1,""),"") | T13: =IF(AND(ISNUMBER(T12),ISNUMBER(O12)),IFERROR(T12/O12-1,""),"") | U13: =IF(AND(ISNUMBER(U12),ISNUMBER(P12)),IFERROR(U12/P12-1,""),"") | ... CA13: =IF(AND(ISNUMBER(CA12),ISNUMBER(BV12)),IFERROR(CA12/BV12-1,""),"") | CB13: =CHOOSE(MATCH($CF$2,{"Bull","Base","Bear"},0),$CO$31,$CP$31,$CQ$31) | CC13: =CHOOSE(MATCH($CF$2,{"Bull","Base","Bear"},0),$CO$32,$CP$32,$CQ$32) | CD13: =CHOOSE(MATCH($CF$2,{"Bull","Base","Bear"},0),$CO$33,$CP$33,$CQ$33) | CE13: =CHOOSE(MATCH($CF$2,{"Bull","Base","Bear"},0),$CO$34,$CP$34,$CQ$34) | CF13: 2027E–2030E: scenario lever TPD (Bull / Base / Bear table →). | CH13: =IFERROR(AVERAGE(CA13,CB13,CC13,CD13,CE13),"n/m") | CI13: =IFERROR(AVERAGE(BB13,BG13,BL13,BQ13,BV13),"n/m") | CJ13: =IFERROR(AVERAGE(AC13,AH13,AM13,AR13,AW13,BB13,BG13,BL13,BQ13,BV13),"n/m") | CK13: =IFERROR(AVERAGE(C13,D13,E13,F13,G13,H13,I13,N13,S13,X13,AC13,AH13,AM13,AR13,AW13,BB13,BG13,BL13,BQ13,BV13),"n/m") | CN13: Q3→Q4 operating-ratio change (best / average / worst, 2016–25) | CO13: =MIN(AB92,AG92,AL92,AQ92,AV92,BA92,BF92,BK92,BP92,BU92) | CP13: =AVERAGE(AB92,AG92,AL92,AQ92,AV92,BA92,BF92,BK92,BP92,BU92) | CQ13: =MAX(AB92,AG92,AL92,AQ92,AV92,BA92,BF92,BK92,BP92,BU92) | CR13: Applied to the Q3/26E operating ratio. Q4 is seasonally weaker (fewer work days, winter weather, holiday freight mix).
B14: sequential % (vs prior quarter) | K14: =IF(AND(ISNUMBER(K12),ISNUMBER(J12)),IFERROR(K12/J12-1,""),"") | L14: =IF(AND(ISNUMBER(L12),ISNUMBER(K12)),IFERROR(L12/K12-1,""),"") | M14: =IF(AND(ISNUMBER(M12),ISNUMBER(L12)),IFERROR(M12/L12-1,""),"") | O14: =IF(AND(ISNUMBER(O12),ISNUMBER(M12)),IFERROR(O12/M12-1,""),"") | P14: =IF(AND(ISNUMBER(P12),ISNUMBER(O12)),IFERROR(P12/O12-1,""),"") | Q14: =IF(AND(ISNUMBER(Q12),ISNUMBER(P12)),IFERROR(Q12/P12-1,""),"") | R14: =IF(AND(ISNUMBER(R12),ISNUMBER(Q12)),IFERROR(R12/Q12-1,""),"") | T14: =IF(AND(ISNUMBER(T12),ISNUMBER(R12)),IFERROR(T12/R12-1,""),"") | U14: =IF(AND(ISNUMBER(U12),ISNUMBER(T12)),IFERROR(U12/T12-1,""),"") | V14: =IF(AND(ISNUMBER(V12),ISNUMBER(U12)),IFERROR(V12/U12-1,""),"") | W14: =IF(AND(ISNUMBER(W12),ISNUMBER(V12)),IFERROR(W12/V12-1,""),"") | Y14: =IF(AND(ISNUMBER(Y12),ISNUMBER(W12)),IFERROR(Y12/W12-1,""),"") | Z14: =IF(AND(ISNUMBER(Z12),ISNUMBER(Y12)),IFERROR(Z12/Y12-1,""),"") | AA14: =IF(AND(ISNUMBER(AA12),ISNUMBER(Z12)),IFERROR(AA12/Z12-1,""),"") | AB14: =IF(AND(ISNUMBER(AB12),ISNUMBER(AA12)),IFERROR(AB12/AA12-1,""),"") | AD14: =IF(AND(ISNUMBER(AD12),ISNUMBER(AB12)),IFERROR(AD12/AB12-1,""),"") | AE14: =IF(AND(ISNUMBER(AE12),ISNUMBER(AD12)),IFERROR(AE12/AD12-1,""),"") | AF14: =IF(AND(ISNUMBER(AF12),ISNUMBER(AE12)),IFERROR(AF12/AE12-1,""),"") | AG14: =IF(AND(ISNUMBER(AG12),ISNUMBER(AF12)),IFERROR(AG12/AF12-1,""),"") | AI14: =IF(AND(ISNUMBER(AI12),ISNUMBER(AG12)),IFERROR(AI12/AG12-1,""),"") | AJ14: =IF(AND(ISNUMBER(AJ12),ISNUMBER(AI12)),IFERROR(AJ12/AI12-1,""),"") | AK14: =IF(AND(ISNUMBER(AK12),ISNUMBER(AJ12)),IFERROR(AK12/AJ12-1,""),"") | AL14: =IF(AND(ISNUMBER(AL12),ISNUMBER(AK12)),IFERROR(AL12/AK12-1,""),"") | AN14: =IF(AND(ISNUMBER(AN12),ISNUMBER(AL12)),IFERROR(AN12/AL12-1,""),"") | AO14: =IF(AND(ISNUMBER(AO12),ISNUMBER(AN12)),IFERROR(AO12/AN12-1,""),"") | AP14: =IF(AND(ISNUMBER(AP12),ISNUMBER(AO12)),IFERROR(AP12/AO12-1,""),"") | AQ14: =IF(AND(ISNUMBER(AQ12),ISNUMBER(AP12)),IFERROR(AQ12/AP12-1,""),"") | AS14: =IF(AND(ISNUMBER(AS12),ISNUMBER(AQ12)),IFERROR(AS12/AQ12-1,""),"") | AT14: =IF(AND(ISNUMBER(AT12),ISNUMBER(AS12)),IFERROR(AT12/AS12-1,""),"") | AU14: =IF(AND(ISNUMBER(AU12),ISNUMBER(AT12)),IFERROR(AU12/AT12-1,""),"") | AV14: =IF(AND(ISNUMBER(AV12),ISNUMBER(AU12)),IFERROR(AV12/AU12-1,""),"") | AX14: =IF(AND(ISNUMBER(AX12),ISNUMBER(AV12)),IFERROR(AX12/AV12-1,""),"") | AY14: =IF(AND(ISNUMBER(AY12),ISNUMBER(AX12)),IFERROR(AY12/AX12-1,""),"") | AZ14: =IF(AND(ISNUMBER(AZ12),ISNUMBER(AY12)),IFERROR(AZ12/AY12-1,""),"") | BA14: =IF(AND(ISNUMBER(BA12),ISNUMBER(AZ12)),IFERROR(BA12/AZ12-1,""),"") | BC14: =IF(AND(ISNUMBER(BC12),ISNUMBER(BA12)),IFERROR(BC12/BA12-1,""),"") | BD14: =IF(AND(ISNUMBER(BD12),ISNUMBER(BC12)),IFERROR(BD12/BC12-1,""),"") | BE14: =IF(AND(ISNUMBER(BE12),ISNUMBER(BD12)),IFERROR(BE12/BD12-1,""),"") | BF14: =IF(AND(ISNUMBER(BF12),ISNUMBER(BE12)),IFERROR(BF12/BE12-1,""),"") | BH14: =IF(AND(ISNUMBER(BH12),ISNUMBER(BF12)),IFERROR(BH12/BF12-1,""),"") | BI14: =IF(AND(ISNUMBER(BI12),ISNUMBER(BH12)),IFERROR(BI12/BH12-1,""),"") | BJ14: =IF(AND(ISNUMBER(BJ12),ISNUMBER(BI12)),IFERROR(BJ12/BI12-1,""),"") | BK14: =IF(AND(ISNUMBER(BK12),ISNUMBER(BJ12)),IFERROR(BK12/BJ12-1,""),"") | BM14: =IF(AND(ISNUMBER(BM12),ISNUMBER(BK12)),IFERROR(BM12/BK12-1,""),"") | BN14: =IF(AND(ISNUMBER(BN12),ISNUMBER(BM12)),IFERROR(BN12/BM12-1,""),"") | BO14: =IF(AND(ISNUMBER(BO12),ISNUMBER(BN12)),IFERROR(BO12/BN12-1,""),"") | BP14: =IF(AND(ISNUMBER(BP12),ISNUMBER(BO12)),IFERROR(BP12/BO12-1,""),"") | BR14: =IF(AND(ISNUMBER(BR12),ISNUMBER(BP12)),IFERROR(BR12/BP12-1,""),"") | BS14: =IF(AND(ISNUMBER(BS12),ISNUMBER(BR12)),IFERROR(BS12/BR12-1,""),"") | BT14: =IF(AND(ISNUMBER(BT12),ISNUMBER(BS12)),IFERROR(BT12/BS12-1,""),"") | BU14: =IF(AND(ISNUMBER(BU12),ISNUMBER(BT12)),IFERROR(BU12/BT12-1,""),"") | BW14: =IF(AND(ISNUMBER(BW12),ISNUMBER(BU12)),IFERROR(BW12/BU12-1,""),"") | BX14: =IF(AND(ISNUMBER(BX12),ISNUMBER(BW12)),IFERROR(BX12/BW12-1,""),"") | BY14: =IF(AND(ISNUMBER(BY12),ISNUMBER(BX12)),IFERROR(BY12/BX12-1,""),"") | BZ14: =IF(AND(ISNUMBER(BZ12),ISNUMBER(BY12)),IFERROR(BZ12/BY12-1,""),"") | CN14: Q3→Q4 LTL tons per day, sequential % (best / average / worst) | CO14: =MAX(AB14,AG14,AL14,AQ14,AV14,BA14,BF14,BK14,BP14,BU14) | CP14: =AVERAGE(AB14,AG14,AL14,AQ14,AV14,BA14,BF14,BK14,BP14,BU14) | CQ14: =MIN(AB14,AG14,AL14,AQ14,AV14,BA14,BF14,BK14,BP14,BU14) | CR14: Applied to Q3/26E tons per day.
B15: LTL tons (thousands; total tons to 2013) | C15: 4859 | D15: 5271 | E15: 5545 | F15: 4902 | G15: 5656 | H15: 6397 | I15: 6875 | J15: 1717 | K15: 1879 | L15: 1924 | M15: 1866 | N15: 7385 | O15: 1680 | P15: 1863 | Q15: 1946 | R15: 1902 | S15: 7391 | T15: 1872 | U15: 2032 | V15: 2075 | W15: 1959 | X15: 7938 | Y15: 1924 | Z15: 2025 | AA15: 2049 | AB15: 1933 | AC15: 7931 | AD15: 1970 | AE15: 2148 | AF15: 2190 | AG15: 2211 | AH15: 8519 | AI15: 2274 | AJ15: 2462 | AK15: 2367 | AL15: 2275 | AM15: 9379 | AN15: 2206 | AO15: 2306 | AP15: 2279 | AQ15: 2173 | AR15: 8964 | AS15: 2153 | AT15: 2028 | AU15: 2309 | AV15: 2279 | AW15: 8770 | AX15: 2332 | AY15: 2598 | AZ15: 2625 | BA15: 2563 | BB15: 10119 | BC15: 2653 | BD15: 2672 | BE15: 2556 | BF15: 2330 | BG15: 10211 | BH15: 2339 | BI15: 2296 | BJ15: 2342 | BK15: 2283 | BL15: 9260 | BM15: 2264 | BN15: 2340 | BO15: 2266 | BP15: 2130 | BQ15: 9000 | BR15: 2087 | BS15: 2123 | BT15: 2063 | BU15: 1903 | BV15: 8177 | BW15: 1927 | BX15: 2035 | BY15: =BY12*BY11/1000 | BZ15: =BZ12*BZ11/1000 | CA15: =SUM(BW15,BX15,BY15,BZ15) | CB15: =CB12*CB11/1000 | CC15: =CC12*CC11/1000 | CD15: =CD12*CD11/1000 | CE15: =CE12*CE11/1000 | CH15: =IFERROR((CE15/BV15)^(1/5)-1,"n/m") | CI15: =IFERROR((BV15/AW15)^(1/5)-1,"n/m") | CJ15: =IFERROR((BV15/X15)^(1/10)-1,"n/m") | CK15: =IFERROR((BV15/C15)^(1/19)-1,"n/m") | CN15: Q3→Q4 LTL revenue/cwt ex fuel, sequential % (best / average / worst) | CO15: =MAX(AB30,AG30,AL30,AQ30,AV30,BA30,BF30,BK30,BP30,BU30) | CP15: =AVERAGE(AB30,AG30,AL30,AQ30,AV30,BA30,BF30,BK30,BP30,BU30) | CQ15: =MIN(AB30,AG30,AL30,AQ30,AV30,BA30,BF30,BK30,BP30,BU30) | CR15: Applied to Q3/26E ex-fuel yield.
B16: y/y % | D16: =IF(AND(ISNUMBER(D15),ISNUMBER(C15)),IFERROR(D15/C15-1,""),"") | E16: =IF(AND(ISNUMBER(E15),ISNUMBER(D15)),IFERROR(E15/D15-1,""),"") | F16: =IF(AND(ISNUMBER(F15),ISNUMBER(E15)),IFERROR(F15/E15-1,""),"") | G16: =IF(AND(ISNUMBER(G15),ISNUMBER(F15)),IFERROR(G15/F15-1,""),"") | H16: =IF(AND(ISNUMBER(H15),ISNUMBER(G15)),IFERROR(H15/G15-1,""),"") | I16: =IF(AND(ISNUMBER(I15),ISNUMBER(H15)),IFERROR(I15/H15-1,""),"") | N16: =IF(AND(ISNUMBER(N15),ISNUMBER(I15)),IFERROR(N15/I15-1,""),"") | O16: =IF(AND(ISNUMBER(O15),ISNUMBER(J15)),IFERROR(O15/J15-1,""),"") | P16: =IF(AND(ISNUMBER(P15),ISNUMBER(K15)),IFERROR(P15/K15-1,""),"") | Q16: =IF(AND(ISNUMBER(Q15),ISNUMBER(L15)),IFERROR(Q15/L15-1,""),"") | R16: =IF(AND(ISNUMBER(R15),ISNUMBER(M15)),IFERROR(R15/M15-1,""),"") | S16: =IF(AND(ISNUMBER(S15),ISNUMBER(N15)),IFERROR(S15/N15-1,""),"") | T16: =IF(AND(ISNUMBER(T15),ISNUMBER(O15)),IFERROR(T15/O15-1,""),"") | U16: =IF(AND(ISNUMBER(U15),ISNUMBER(P15)),IFERROR(U15/P15-1,""),"") | ... CA16: =IF(AND(ISNUMBER(CA15),ISNUMBER(BV15)),IFERROR(CA15/BV15-1,""),"") | CB16: =IF(AND(ISNUMBER(CB15),ISNUMBER(CA15)),IFERROR(CB15/CA15-1,""),"") | CC16: =IF(AND(ISNUMBER(CC15),ISNUMBER(CB15)),IFERROR(CC15/CB15-1,""),"") | CD16: =IF(AND(ISNUMBER(CD15),ISNUMBER(CC15)),IFERROR(CD15/CC15-1,""),"") | CE16: =IF(AND(ISNUMBER(CE15),ISNUMBER(CD15)),IFERROR(CE15/CD15-1,""),"") | CN16: 2H/26 share repurchases ($m) | CO16: 400 | CP16: 300 | CQ16: 150 | CR16: 1H/26 $239.7m; $1.31bn remaining under the $3.0bn 2023 programme at 30-Jun-26. FY25 $730m, FY24 $967m.
B17: LTL weight per shipment (lbs.) | C17: 1512 | D17: 1558 | E17: 1657 | F17: 1705 | G17: 1788 | H17: 1763 | I17: 1771 | J17: 1787 | K17: 1777 | L17: 1773 | M17: 1801 | N17: 1784 | O17: 1627 | P17: 1637 | Q17: 1617 | R17: 1636 | S17: 1629 | T17: 1598 | U17: 1574 | V17: 1543 | W17: 1558 | X17: 1567 | Y17: 1546 | Z17: 1559 | AA17: 1551 | AB17: 1597 | AC17: 1563 | AD17: 1561 | AE17: 1567 | AF17: 1579 | AG17: 1640 | AH17: 1587 | AI17: 1631 | AJ17: 1615 | AK17: 1557 | AL17: 1586 | AM17: 1597 | AN17: 1566 | AO17: 1553 | AP17: 1545 | AQ17: 1580 | AR17: 1560 | AS17: 1586 | AT17: 1636 | AU17: 1615 | AV17: 1619 | AW17: 1614 | AX17: 1606 | AY17: 1571 | AZ17: 1538 | BA17: 1575 | BB17: 1571 | BC17: 1589 | BD17: 1572 | BE17: 1561 | BF17: 1565 | BG17: 1572 | BH17: 1550 | BI17: 1527 | BJ17: 1497 | BK17: 1511 | BL17: 1521 | BM17: 1508 | BN17: 1509 | BO17: 1476 | BP17: 1501 | BQ17: 1499 | BR17: 1487 | BS17: 1478 | BT17: 1458 | BU17: 1486 | BV17: 1477 | BW17: 1491 | BX17: 1503 | BY17: =BT17*$BX$17/$BS$17 | BZ17: =BU17*$BX$17/$BS$17 | CA17: =IFERROR(CA15*2000/CA19,"") | CB17: =CA17 | CC17: =CB17 | CD17: =CC17 | CE17: =CD17 | CF17: Q3/Q4-26E: prior-year quarter × Q2/26 y/y change (+1.7%; Aug-26 +1.7%). 2027E+ flat.
B18: y/y % | D18: =IF(AND(ISNUMBER(D17),ISNUMBER(C17)),IFERROR(D17/C17-1,""),"") | E18: =IF(AND(ISNUMBER(E17),ISNUMBER(D17)),IFERROR(E17/D17-1,""),"") | F18: =IF(AND(ISNUMBER(F17),ISNUMBER(E17)),IFERROR(F17/E17-1,""),"") | G18: =IF(AND(ISNUMBER(G17),ISNUMBER(F17)),IFERROR(G17/F17-1,""),"") | H18: =IF(AND(ISNUMBER(H17),ISNUMBER(G17)),IFERROR(H17/G17-1,""),"") | I18: =IF(AND(ISNUMBER(I17),ISNUMBER(H17)),IFERROR(I17/H17-1,""),"") | N18: =IF(AND(ISNUMBER(N17),ISNUMBER(I17)),IFERROR(N17/I17-1,""),"") | O18: =IF(AND(ISNUMBER(O17),ISNUMBER(J17)),IFERROR(O17/J17-1,""),"") | P18: =IF(AND(ISNUMBER(P17),ISNUMBER(K17)),IFERROR(P17/K17-1,""),"") | Q18: =IF(AND(ISNUMBER(Q17),ISNUMBER(L17)),IFERROR(Q17/L17-1,""),"") | R18: =IF(AND(ISNUMBER(R17),ISNUMBER(M17)),IFERROR(R17/M17-1,""),"") | S18: =IF(AND(ISNUMBER(S17),ISNUMBER(N17)),IFERROR(S17/N17-1,""),"") | T18: =IF(AND(ISNUMBER(T17),ISNUMBER(O17)),IFERROR(T17/O17-1,""),"") | U18: =IF(AND(ISNUMBER(U17),ISNUMBER(P17)),IFERROR(U17/P17-1,""),"") | ... CA18: =IF(AND(ISNUMBER(CA17),ISNUMBER(BV17)),IFERROR(CA17/BV17-1,""),"") | CB18: =IF(AND(ISNUMBER(CB17),ISNUMBER(CA17)),IFERROR(CB17/CA17-1,""),"") | CC18: =IF(AND(ISNUMBER(CC17),ISNUMBER(CB17)),IFERROR(CC17/CB17-1,""),"") | CD18: =IF(AND(ISNUMBER(CD17),ISNUMBER(CC17)),IFERROR(CD17/CC17-1,""),"") | CE18: =IF(AND(ISNUMBER(CE17),ISNUMBER(CD17)),IFERROR(CE17/CD17-1,""),"") | CN18: FY26 point estimates & Q3/26E anchors (all cases)
B19: LTL shipments (thousands; total shipments to 2013) | C19: 6428 | D19: 6765 | E19: 6691 | F19: 5750 | G19: 6327 | H19: 7256 | I19: 7765 | J19: 1922 | K19: 2115 | L19: 2170 | M19: 2072 | N19: 8279 | O19: 2065 | P19: 2276 | Q19: 2407 | R19: 2325 | S19: 9073 | T19: 2344 | U19: 2582 | V19: 2689 | W19: 2515 | X19: 10129 | Y19: 2489 | Z19: 2597 | AA19: 2641 | AB19: 2421 | AC19: 10148 | AD19: 2523 | AE19: 2742 | AF19: 2774 | AG19: 2696 | AH19: 10736 | AI19: 2788 | AJ19: 3049 | AK19: 3042 | AL19: 2870 | AM19: 11748 | AN19: 2818 | AO19: 2970 | AP19: 2951 | AQ19: 2751 | AR19: 11491 | AS19: 2716 | AT19: 2478 | AU19: 2859 | AV19: 2816 | AW19: 10869 | AX19: 2904 | AY19: 3307 | AZ19: 3413 | BA19: 3256 | BB19: 12880 | BC19: 3340 | BD19: 3398 | BE19: 3274 | BF19: 2977 | BG19: 12989 | BH19: 3018 | BI19: 3008 | BJ19: 3129 | BK19: 3021 | BL19: 12176 | BM19: 3004 | BN19: 3100 | BO19: 3070 | BP19: 2837 | BQ19: 12011 | BR19: 2808 | BS19: 2874 | BT19: 2829 | BU19: 2561 | BV19: 11072 | BW19: 2585 | BX19: 2709 | BY19: =IFERROR(BY15*2000/BY17,"") | BZ19: =IFERROR(BZ15*2000/BZ17,"") | CA19: =SUM(BW19,BX19,BY19,BZ19) | CB19: =IFERROR(CB15*2000/CB17,"") | CC19: =IFERROR(CC15*2000/CC17,"") | CD19: =IFERROR(CD15*2000/CD17,"") | CE19: =IFERROR(CE15*2000/CE17,"") | CH19: =IFERROR((CE19/BV19)^(1/5)-1,"n/m") | CI19: =IFERROR((BV19/AW19)^(1/5)-1,"n/m") | CJ19: =IFERROR((BV19/X19)^(1/10)-1,"n/m") | CK19: =IFERROR((BV19/C19)^(1/19)-1,"n/m") | CN19: Q3/26E LTL tons per day y/y (Aug-26, 3-Sep-26 update) | CP19: -0.009 | CR19: August 2026 LTL tons per day −0.9% y/y (shipments/day −2.4%, weight/shipment +1.7%). July not separately disclosed; Q2/26 −4.1%.
B20: LTL shipments per day | C20: 25507.937 | D20: 26739.13 | E20: 26342.52 | F20: 22727.273 | G20: 25107.143 | H20: 28679.842 | I20: 30570.866 | J20: 30507.937 | K20: 33046.875 | L20: 33906.25 | M20: 32888.889 | N20: 32594.488 | O20: 32777.778 | P20: 35562.5 | Q20: 37609.375 | R20: 36904.762 | S20: 35720.472 | T20: 37206.349 | U20: 40343.75 | V20: 42015.625 | W20: 39920.635 | X20: 39877.953 | Y20: 38890.625 | Z20: 40578.125 | AA20: 41265.625 | AB20: 39048.387 | AC20: 39952.756 | AD20: 39421.875 | AE20: 42843.75 | AF20: 44031.746 | AG20: 43483.871 | AH20: 42434.783 | AI20: 43562.5 | AJ20: 47640.625 | AK20: 48285.714 | AL20: 46290.323 | AM20: 46434.783 | AN20: 44730 | AO20: 46406 | AP20: 46109 | AQ20: 44370.968 | AR20: 45418.972 | AS20: 42438 | AT20: 38719 | AU20: 44672 | AV20: 45419 | AW20: 42791 | AX20: 46090 | AY20: 51672 | AZ20: 53335 | BA20: 53374 | BB20: 51111 | BC20: 52190 | BD20: 53096 | BE20: 51162 | BF20: 48798 | BG20: 51341 | BH20: 47155 | BI20: 46998 | BJ20: 49670 | BK20: 49520 | BL20: 48317 | BM20: 46931 | BN20: 48444 | BO20: 47967 | BP20: 45763 | BQ20: 47288 | BR20: 44566 | BS20: 44907 | BT20: 44201 | BU20: 41308 | BV20: 43762 | BW20: 41037 | BX20: 42332 | BY20: =IFERROR(BY19*1000/BY11,"") | BZ20: =IFERROR(BZ19*1000/BZ11,"") | CA20: =IFERROR(CA19*1000/CA11,"") | CB20: =IFERROR(CB19*1000/CB11,"") | CC20: =IFERROR(CC19*1000/CC11,"") | CD20: =IFERROR(CD19*1000/CD11,"") | CE20: =IFERROR(CE19*1000/CE11,"") | CN20: Q3/26E LTL revenue/cwt ex fuel y/y (Jul–Aug QTD) | CP20: 0.048 | CR20: 3-Sep-26 update: quarter-to-date +4.8%.
B21: y/y % | D21: =IF(AND(ISNUMBER(D20),ISNUMBER(C20)),IFERROR(D20/C20-1,""),"") | E21: =IF(AND(ISNUMBER(E20),ISNUMBER(D20)),IFERROR(E20/D20-1,""),"") | F21: =IF(AND(ISNUMBER(F20),ISNUMBER(E20)),IFERROR(F20/E20-1,""),"") | G21: =IF(AND(ISNUMBER(G20),ISNUMBER(F20)),IFERROR(G20/F20-1,""),"") | H21: =IF(AND(ISNUMBER(H20),ISNUMBER(G20)),IFERROR(H20/G20-1,""),"") | I21: =IF(AND(ISNUMBER(I20),ISNUMBER(H20)),IFERROR(I20/H20-1,""),"") | N21: =IF(AND(ISNUMBER(N20),ISNUMBER(I20)),IFERROR(N20/I20-1,""),"") | O21: =IF(AND(ISNUMBER(O20),ISNUMBER(J20)),IFERROR(O20/J20-1,""),"") | P21: =IF(AND(ISNUMBER(P20),ISNUMBER(K20)),IFERROR(P20/K20-1,""),"") | Q21: =IF(AND(ISNUMBER(Q20),ISNUMBER(L20)),IFERROR(Q20/L20-1,""),"") | R21: =IF(AND(ISNUMBER(R20),ISNUMBER(M20)),IFERROR(R20/M20-1,""),"") | S21: =IF(AND(ISNUMBER(S20),ISNUMBER(N20)),IFERROR(S20/N20-1,""),"") | T21: =IF(AND(ISNUMBER(T20),ISNUMBER(O20)),IFERROR(T20/O20-1,""),"") | U21: =IF(AND(ISNUMBER(U20),ISNUMBER(P20)),IFERROR(U20/P20-1,""),"") | ... CA21: =IF(AND(ISNUMBER(CA20),ISNUMBER(BV20)),IFERROR(CA20/BV20-1,""),"") | CB21: =IF(AND(ISNUMBER(CB20),ISNUMBER(CA20)),IFERROR(CB20/CA20-1,""),"") | CC21: =IF(AND(ISNUMBER(CC20),ISNUMBER(CB20)),IFERROR(CC20/CB20-1,""),"") | CD21: =IF(AND(ISNUMBER(CD20),ISNUMBER(CC20)),IFERROR(CD20/CC20-1,""),"") | CE21: =IF(AND(ISNUMBER(CE20),ISNUMBER(CD20)),IFERROR(CE20/CD20-1,""),"") | CN21: Q3/26E LTL revenue/cwt incl. fuel y/y (Jul–Aug QTD) | CP21: 0.113 | CR21: 3-Sep-26 update: quarter-to-date +11.3% (fuel surcharge per cwt implied).
B22: Average length of haul (miles) | C22: 934 | D22: 935 | E22: 901 | F22: 928 | G22: 948 | H22: 952 | I22: 941 | J22: 935 | K22: 940 | L22: 938 | M22: 930 | N22: 936 | O22: 929 | P22: 927 | Q22: 929 | R22: 928 | S22: 928 | T22: 928 | U22: 928 | V22: 927 | W22: 927 | X22: 928 | Y22: 935 | Z22: 929 | AA22: 925 | AB22: 922 | AC22: 928 | AD22: 920 | AE22: 917 | AF22: 919 | AG22: 914 | AH22: 917 | AI22: 914 | AJ22: 915 | AK22: 920 | AL22: 923 | AM22: 918 | AN22: 918 | AO22: 917 | AP22: 918 | AQ22: 915 | AR22: 917 | AS22: 919 | AT22: 919 | AU22: 933 | AV22: 927 | AW22: 925 | AX22: 928 | AY22: 930 | AZ22: 940 | BA22: 944 | BB22: 935 | BC22: 939 | BD22: 934 | BE22: 932 | BF22: 932 | BG22: 934 | BH22: 925 | BI22: 925 | BJ22: 927 | BK22: 925 | BL22: 925 | BM22: 919 | BN22: 918 | BO22: 923 | BP22: 915 | BQ22: 919 | BR22: 916 | BS22: 912 | BT22: 909 | BU22: 906 | BV22: 911 | BW22: 913 | BX22: 909 | CN22: Memo: Aug-26 revenue per day y/y | CP22: 0.124 | CR22: 3-Sep-26 update: August revenue per day +12.4% (memo; not a calibration target).
B23: LTL intercity miles (thousands) | C23: 296464 | D23: 325268 | E23: 334219 | G23: 338535 | H23: 389588 | I23: 420214 | J23: 103472 | K23: 112321 | L23: 116215 | M23: 114525 | N23: 446532 | O23: 111555 | P23: 125186 | Q23: 133864 | R23: 133319 | S23: 503923 | T23: 129467 | U23: 143487 | V23: 149510 | W23: 143747 | X23: 566210 | Y23: 140816 | Z23: 145754 | AA23: 148993 | AB23: 141389 | AC23: 576953 | AD23: 139752 | AE23: 150991 | AF23: 156343 | AG23: 158119 | AH23: 605204 | AI23: 161190 | AJ23: 174013 | AK23: 173124 | AL23: 166180 | AM23: 674506 | AN23: 159654 | AO23: 163884 | AP23: 163061 | AQ23: 157687 | AR23: 644287 | AS23: 155949 | AT23: 141417 | AU23: 160543 | AV23: 159896 | AW23: 617805 | AX23: 161174 | AY23: 178938 | AZ23: 184812 | BA23: 182687 | BB23: 707611 | BC23: 183607 | BD23: 194726 | BE23: 190626 | BF23: 177068 | BG23: 746028 | BH23: 173637 | BI23: 170294 | BJ23: 176284 | BK23: 171417 | BL23: 691632 | BN23: 172361 | BO23: 168986 | BP23: 162124 | BQ23: 673237 | BR23: 157259 | BS23: 159582 | BT23: 155365 | BU23: 144055 | BV23: 616261 | BW23: 144718 | BX23: 151977 | CN23: FY26 depreciation & amortization ($m) | CP23: 372 | CR23: 1H/26 $184.0m + 2H at the Q2/26 run-rate ($91.7m) + new equipment; not guided on EDGAR.
B24: Average active full-time employees (from 2019 releases) | AT24: 17911 | AU24: 18766 | AV24: 19630 | AW24: 19064 | AX24: 20479 | AY24: 21621 | AZ24: 22682 | BA24: 23610 | BB24: 22098 | BC24: 24277 | BD24: 24893 | BE24: 24587 | BF24: 23799 | BG24: 24389 | BH24: 22971 | BI24: 22438 | BJ24: 22284 | BK24: 22814 | BL24: 22627 | BM24: 22891 | BN24: 22702 | BO24: 22465 | BP24: 22032 | BQ24: 22522 | BR24: 21817 | BS24: 21621 | BT24: 21073 | BU24: 20706 | BV24: 21304 | BW24: 20264 | BX24: 20081 | CN24: FY26 interest expense (income), net ($m) | CP24: -9 | CR24: 1H/26 −$4.3m (interest income $4.7m on cash; $20m notes).
B25: Statistics basis (definition in force) | C25: To 2013: total tons & shipments (LTL + truckload), revenue/cwt on the total basis; work days computed to 2011 | O25: From Q1-14: LTL tons, LTL shipments and LTL revenue/cwt (statistics exclude undelivered-freight adjustments & non-weight services) | CN25: Tax rate | CP25: 0.25 | CR25: 1H/26 effective rate 25.0%; FY25 24.8%.
CN26: Capital expenditures ($m) | CP26: 380 | CR26: Q2-26 release: ~$380m (real estate & service centers $180m; tractors & trailers $155m; IT & other $45m). 1H/26 $139.6m.
B27: Yield — LTL revenue per hundredweight (ex-fuel + fuel surcharge; statistics exclude undelivered-freight revenue adjustments) | CF27: YIELD — modelling logic
B28: LTL revenue per hundredweight, excluding fuel surcharges ($) | C28: 11.6 | D28: 11.65 | E28: 11.49 | F28: 11.49 | G28: 11.49 | H28: 12.31 | I28: 12.79 | J28: 12.89 | K28: 13.25 | L28: 13.54 | M28: 13.34 | N28: 13.3 | O28: 15.01 | P28: 15.34 | Q28: 15.64 | R28: 15.56 | S28: 15.4 | T28: 15.94 | U28: 16.16 | V28: 16.46 | W28: 16.51 | X28: 16.28 | Y28: 16.54 | Z28: 16.6 | AA28: 16.91 | AB28: 16.78 | AC28: 16.71 | AD28: 16.94 | AE28: 17.23 | AF28: 17.31 | AG28: 17.3 | AH28: 17.2 | AI28: 17.57 | AJ28: 17.94 | AK28: 18.86 | AL28: 19.16 | AM28: 18.38 | AN28: 19.26 | AO28: 19.73 | AP28: 19.95 | AQ28: 19.92 | AR28: 19.72 | AS28: 19.89 | AT28: 19.64 | AU28: 20.46 | AV28: 20.76 | AW28: 20.21 | AX28: 21.01 | AY28: 21.67 | AZ28: 22.52 | BA28: 22.67 | BB28: 21.99 | BC28: 23.11 | BD28: 23.69 | BE28: 24.15 | BF28: 24.65 | BG28: 23.87 | BH28: 25.09 | BI28: 25.5 | BJ28: 26.29 | BK28: 26.5 | BL28: 25.84 | BM28: 26.78 | BN28: 26.75 | BO28: 27.49 | BP28: 27.52 | BQ28: 27.13 | BR28: 27.89 | BS28: 28.17 | BT28: 28.78 | BU28: 28.88 | BV28: 28.42 | BW28: 29.13 | BX28: 29.71 | BY28: =BT28*(1+$CP$20) | BZ28: =BY28*(1+CHOOSE(MATCH($CF$2,{"Bull","Base","Bear"},0),$CO$15,$CP$15,$CQ$15)) | CA28: =IFERROR(SUMPRODUCT(BW28:BZ28,BW15:BZ15)/SUM(BW15:BZ15),"") | CB28: =CA28*(1+CB29) | CC28: =CB28*(1+CC29) | CD28: =CC28*(1+CD29) | CE28: =CD28*(1+CE29) | CF28: Q3/26E: Q3/25 × (1 + Jul–Aug quarter-to-date y/y from the 3-Sep-26 update, +4.8%). Q4/26E: Q3/26E × (1 + 2016–25 Q3→Q4 sequential change by scenario). 2027E+: scenario lever YXF. 2026E = tonnage-weighted average of the quarters. | CH28: =IFERROR((CE28/BV28)^(1/5)-1,"n/m") | CI28: =IFERROR((BV28/AW28)^(1/5)-1,"n/m") | CJ28: =IFERROR((BV28/X28)^(1/10)-1,"n/m") | CK28: =IFERROR((BV28/C28)^(1/19)-1,"n/m") | CN28: Target cash balance ($m) — buyback plug 2027E+ (surplus cash returned) | CO28: 150 | CP28: 250 | CQ28: 400 | CR28: ODFL runs with minimal debt and returns surplus cash (cash $120m at YE25, $284m at 30-Jun-26). Target cash: Bull $150m / Base $250m / Bear $400m.
B29: y/y % | D29: =IF(AND(ISNUMBER(D28),ISNUMBER(C28)),IFERROR(D28/C28-1,""),"") | E29: =IF(AND(ISNUMBER(E28),ISNUMBER(D28)),IFERROR(E28/D28-1,""),"") | F29: =IF(AND(ISNUMBER(F28),ISNUMBER(E28)),IFERROR(F28/E28-1,""),"") | G29: =IF(AND(ISNUMBER(G28),ISNUMBER(F28)),IFERROR(G28/F28-1,""),"") | H29: =IF(AND(ISNUMBER(H28),ISNUMBER(G28)),IFERROR(H28/G28-1,""),"") | I29: =IF(AND(ISNUMBER(I28),ISNUMBER(H28)),IFERROR(I28/H28-1,""),"") | N29: =IF(AND(ISNUMBER(N28),ISNUMBER(I28)),IFERROR(N28/I28-1,""),"") | O29: =IF(AND(ISNUMBER(O28),ISNUMBER(J28)),IFERROR(O28/J28-1,""),"") | P29: =IF(AND(ISNUMBER(P28),ISNUMBER(K28)),IFERROR(P28/K28-1,""),"") | Q29: =IF(AND(ISNUMBER(Q28),ISNUMBER(L28)),IFERROR(Q28/L28-1,""),"") | R29: =IF(AND(ISNUMBER(R28),ISNUMBER(M28)),IFERROR(R28/M28-1,""),"") | S29: =IF(AND(ISNUMBER(S28),ISNUMBER(N28)),IFERROR(S28/N28-1,""),"") | T29: =IF(AND(ISNUMBER(T28),ISNUMBER(O28)),IFERROR(T28/O28-1,""),"") | U29: =IF(AND(ISNUMBER(U28),ISNUMBER(P28)),IFERROR(U28/P28-1,""),"") | ... CA29: =IF(AND(ISNUMBER(CA28),ISNUMBER(BV28)),IFERROR(CA28/BV28-1,""),"") | CB29: =CHOOSE(MATCH($CF$2,{"Bull","Base","Bear"},0),$CO$36,$CP$36,$CQ$36) | CC29: =CHOOSE(MATCH($CF$2,{"Bull","Base","Bear"},0),$CO$37,$CP$37,$CQ$37) | CD29: =CHOOSE(MATCH($CF$2,{"Bull","Base","Bear"},0),$CO$38,$CP$38,$CQ$38) | CE29: =CHOOSE(MATCH($CF$2,{"Bull","Base","Bear"},0),$CO$39,$CP$39,$CQ$39) | CH29: =IFERROR(AVERAGE(CA29,CB29,CC29,CD29,CE29),"n/m") | CI29: =IFERROR(AVERAGE(BB29,BG29,BL29,BQ29,BV29),"n/m") | CJ29: =IFERROR(AVERAGE(AC29,AH29,AM29,AR29,AW29,BB29,BG29,BL29,BQ29,BV29),"n/m") | CK29: =IFERROR(AVERAGE(C29,D29,E29,F29,G29,H29,I29,N29,S29,X29,AC29,AH29,AM29,AR29,AW29,BB29,BG29,BL29,BQ29,BV29),"n/m")
B30: sequential % (vs prior quarter) | K30: =IF(AND(ISNUMBER(K28),ISNUMBER(J28)),IFERROR(K28/J28-1,""),"") | L30: =IF(AND(ISNUMBER(L28),ISNUMBER(K28)),IFERROR(L28/K28-1,""),"") | M30: =IF(AND(ISNUMBER(M28),ISNUMBER(L28)),IFERROR(M28/L28-1,""),"") | O30: =IF(AND(ISNUMBER(O28),ISNUMBER(M28)),IFERROR(O28/M28-1,""),"") | P30: =IF(AND(ISNUMBER(P28),ISNUMBER(O28)),IFERROR(P28/O28-1,""),"") | Q30: =IF(AND(ISNUMBER(Q28),ISNUMBER(P28)),IFERROR(Q28/P28-1,""),"") | R30: =IF(AND(ISNUMBER(R28),ISNUMBER(Q28)),IFERROR(R28/Q28-1,""),"") | T30: =IF(AND(ISNUMBER(T28),ISNUMBER(R28)),IFERROR(T28/R28-1,""),"") | U30: =IF(AND(ISNUMBER(U28),ISNUMBER(T28)),IFERROR(U28/T28-1,""),"") | V30: =IF(AND(ISNUMBER(V28),ISNUMBER(U28)),IFERROR(V28/U28-1,""),"") | W30: =IF(AND(ISNUMBER(W28),ISNUMBER(V28)),IFERROR(W28/V28-1,""),"") | Y30: =IF(AND(ISNUMBER(Y28),ISNUMBER(W28)),IFERROR(Y28/W28-1,""),"") | Z30: =IF(AND(ISNUMBER(Z28),ISNUMBER(Y28)),IFERROR(Z28/Y28-1,""),"") | AA30: =IF(AND(ISNUMBER(AA28),ISNUMBER(Z28)),IFERROR(AA28/Z28-1,""),"") | AB30: =IF(AND(ISNUMBER(AB28),ISNUMBER(AA28)),IFERROR(AB28/AA28-1,""),"") | AD30: =IF(AND(ISNUMBER(AD28),ISNUMBER(AB28)),IFERROR(AD28/AB28-1,""),"") | AE30: =IF(AND(ISNUMBER(AE28),ISNUMBER(AD28)),IFERROR(AE28/AD28-1,""),"") | AF30: =IF(AND(ISNUMBER(AF28),ISNUMBER(AE28)),IFERROR(AF28/AE28-1,""),"") | AG30: =IF(AND(ISNUMBER(AG28),ISNUMBER(AF28)),IFERROR(AG28/AF28-1,""),"") | AI30: =IF(AND(ISNUMBER(AI28),ISNUMBER(AG28)),IFERROR(AI28/AG28-1,""),"") | AJ30: =IF(AND(ISNUMBER(AJ28),ISNUMBER(AI28)),IFERROR(AJ28/AI28-1,""),"") | AK30: =IF(AND(ISNUMBER(AK28),ISNUMBER(AJ28)),IFERROR(AK28/AJ28-1,""),"") | AL30: =IF(AND(ISNUMBER(AL28),ISNUMBER(AK28)),IFERROR(AL28/AK28-1,""),"") | AN30: =IF(AND(ISNUMBER(AN28),ISNUMBER(AL28)),IFERROR(AN28/AL28-1,""),"") | AO30: =IF(AND(ISNUMBER(AO28),ISNUMBER(AN28)),IFERROR(AO28/AN28-1,""),"") | AP30: =IF(AND(ISNUMBER(AP28),ISNUMBER(AO28)),IFERROR(AP28/AO28-1,""),"") | AQ30: =IF(AND(ISNUMBER(AQ28),ISNUMBER(AP28)),IFERROR(AQ28/AP28-1,""),"") | AS30: =IF(AND(ISNUMBER(AS28),ISNUMBER(AQ28)),IFERROR(AS28/AQ28-1,""),"") | AT30: =IF(AND(ISNUMBER(AT28),ISNUMBER(AS28)),IFERROR(AT28/AS28-1,""),"") | AU30: =IF(AND(ISNUMBER(AU28),ISNUMBER(AT28)),IFERROR(AU28/AT28-1,""),"") | AV30: =IF(AND(ISNUMBER(AV28),ISNUMBER(AU28)),IFERROR(AV28/AU28-1,""),"") | AX30: =IF(AND(ISNUMBER(AX28),ISNUMBER(AV28)),IFERROR(AX28/AV28-1,""),"") | AY30: =IF(AND(ISNUMBER(AY28),ISNUMBER(AX28)),IFERROR(AY28/AX28-1,""),"") | AZ30: =IF(AND(ISNUMBER(AZ28),ISNUMBER(AY28)),IFERROR(AZ28/AY28-1,""),"") | BA30: =IF(AND(ISNUMBER(BA28),ISNUMBER(AZ28)),IFERROR(BA28/AZ28-1,""),"") | BC30: =IF(AND(ISNUMBER(BC28),ISNUMBER(BA28)),IFERROR(BC28/BA28-1,""),"") | BD30: =IF(AND(ISNUMBER(BD28),ISNUMBER(BC28)),IFERROR(BD28/BC28-1,""),"") | BE30: =IF(AND(ISNUMBER(BE28),ISNUMBER(BD28)),IFERROR(BE28/BD28-1,""),"") | BF30: =IF(AND(ISNUMBER(BF28),ISNUMBER(BE28)),IFERROR(BF28/BE28-1,""),"") | BH30: =IF(AND(ISNUMBER(BH28),ISNUMBER(BF28)),IFERROR(BH28/BF28-1,""),"") | BI30: =IF(AND(ISNUMBER(BI28),ISNUMBER(BH28)),IFERROR(BI28/BH28-1,""),"") | BJ30: =IF(AND(ISNUMBER(BJ28),ISNUMBER(BI28)),IFERROR(BJ28/BI28-1,""),"") | BK30: =IF(AND(ISNUMBER(BK28),ISNUMBER(BJ28)),IFERROR(BK28/BJ28-1,""),"") | BM30: =IF(AND(ISNUMBER(BM28),ISNUMBER(BK28)),IFERROR(BM28/BK28-1,""),"") | BN30: =IF(AND(ISNUMBER(BN28),ISNUMBER(BM28)),IFERROR(BN28/BM28-1,""),"") | BO30: =IF(AND(ISNUMBER(BO28),ISNUMBER(BN28)),IFERROR(BO28/BN28-1,""),"") | BP30: =IF(AND(ISNUMBER(BP28),ISNUMBER(BO28)),IFERROR(BP28/BO28-1,""),"") | BR30: =IF(AND(ISNUMBER(BR28),ISNUMBER(BP28)),IFERROR(BR28/BP28-1,""),"") | BS30: =IF(AND(ISNUMBER(BS28),ISNUMBER(BR28)),IFERROR(BS28/BR28-1,""),"") | BT30: =IF(AND(ISNUMBER(BT28),ISNUMBER(BS28)),IFERROR(BT28/BS28-1,""),"") | BU30: =IF(AND(ISNUMBER(BU28),ISNUMBER(BT28)),IFERROR(BU28/BT28-1,""),"") | BW30: =IF(AND(ISNUMBER(BW28),ISNUMBER(BU28)),IFERROR(BW28/BU28-1,""),"") | BX30: =IF(AND(ISNUMBER(BX28),ISNUMBER(BW28)),IFERROR(BX28/BW28-1,""),"") | BY30: =IF(AND(ISNUMBER(BY28),ISNUMBER(BX28)),IFERROR(BY28/BX28-1,""),"") | BZ30: =IF(AND(ISNUMBER(BZ28),ISNUMBER(BY28)),IFERROR(BZ28/BY28-1,""),"") | CN30: TPD (LTL tons per day y/y) | CO30: 0.02 | CP30: Δ → | CQ30: -0.03 | CR30: Freight-cycle recovery from the 2023–26 industrial recession (tons/day −15% from the 2022 peak) and share gains on service (99% on-time, 0.1% claims ratio).
B31: Fuel surcharge per hundredweight ($) | C31: =IF(AND(ISNUMBER(C33),ISNUMBER(C28)),C33-C28,"") | D31: =IF(AND(ISNUMBER(D33),ISNUMBER(D28)),D33-D28,"") | E31: =IF(AND(ISNUMBER(E33),ISNUMBER(E28)),E33-E28,"") | F31: =IF(AND(ISNUMBER(F33),ISNUMBER(F28)),F33-F28,"") | G31: =IF(AND(ISNUMBER(G33),ISNUMBER(G28)),G33-G28,"") | H31: =IF(AND(ISNUMBER(H33),ISNUMBER(H28)),H33-H28,"") | I31: =IF(AND(ISNUMBER(I33),ISNUMBER(I28)),I33-I28,"") | J31: =IF(AND(ISNUMBER(J33),ISNUMBER(J28)),J33-J28,"") | ... BX31: =IF(AND(ISNUMBER(BX33),ISNUMBER(BX28)),BX33-BX28,"") | BY31: =BY28*BY32 | BZ31: =BZ28*BZ32 | CA31: =CA33-CA28 | CB31: =CB28*CB32 | CC31: =CC28*CC32 | CD31: =CD28*CD32 | CE31: =CE28*CE32 | CN31: 2027E | CO31: =CP31+$CO$30 | CP31: 0.04 | CQ31: =CP31+$CQ$30
B32: Fuel surcharge % of ex-fuel yield | C32: =IF(AND(ISNUMBER(C31),ISNUMBER(C28)),IFERROR(C31/C28,""),"") | D32: =IF(AND(ISNUMBER(D31),ISNUMBER(D28)),IFERROR(D31/D28,""),"") | E32: =IF(AND(ISNUMBER(E31),ISNUMBER(E28)),IFERROR(E31/E28,""),"") | F32: =IF(AND(ISNUMBER(F31),ISNUMBER(F28)),IFERROR(F31/F28,""),"") | G32: =IF(AND(ISNUMBER(G31),ISNUMBER(G28)),IFERROR(G31/G28,""),"") | H32: =IF(AND(ISNUMBER(H31),ISNUMBER(H28)),IFERROR(H31/H28,""),"") | I32: =IF(AND(ISNUMBER(I31),ISNUMBER(I28)),IFERROR(I31/I28,""),"") | J32: =IF(AND(ISNUMBER(J31),ISNUMBER(J28)),IFERROR(J31/J28,""),"") | ... BX32: =IF(AND(ISNUMBER(BX31),ISNUMBER(BX28)),IFERROR(BX31/BX28,""),"") | BY32: =(1+$CP$21)*BT33/BY28-1 | BZ32: =BY32 | CA32: =IF(AND(ISNUMBER(CA31),ISNUMBER(CA28)),IFERROR(CA31/CA28,""),"") | CB32: =$BZ$32 | CC32: =$BZ$32 | CD32: =$BZ$32 | CE32: =$BZ$32 | CF32: Q3/26E implied by the Jul–Aug QTD revenue/cwt (+11.3% y/y) and ex-fuel (+4.8%) changes. Q4/26E and 2027E+ held at the Q3/26E level (diesel flat). | CH32: =IFERROR(AVERAGE(CA32,CB32,CC32,CD32,CE32),"n/m") | CI32: =IFERROR(AVERAGE(BB32,BG32,BL32,BQ32,BV32),"n/m") | CJ32: =IFERROR(AVERAGE(AC32,AH32,AM32,AR32,AW32,BB32,BG32,BL32,BQ32,BV32),"n/m") | CK32: =IFERROR(AVERAGE(C32,D32,E32,F32,G32,H32,I32,N32,S32,X32,AC32,AH32,AM32,AR32,AW32,BB32,BG32,BL32,BQ32,BV32),"n/m") | CN32: 2028E | CO32: =CP32+$CO$30 | CP32: 0.05 | CQ32: =CP32+$CQ$30
B33: LTL revenue per hundredweight ($) | C33: 13.16 | D33: 13.3 | E33: 13.88 | F33: 12.7 | G33: 13.09 | H33: 14.72 | I33: 15.35 | J33: 15.5 | K33: 15.75 | L33: 16.12 | M33: 15.83 | N33: 15.85 | O33: 18 | P33: 18.36 | Q33: 18.62 | R33: 18.3 | S33: 18.33 | T33: 18.08 | U33: 18.22 | V33: 18.33 | W33: 18.26 | X33: 18.23 | Y33: 18.14 | Z33: 18.37 | AA33: 18.79 | AB33: 18.74 | AC33: 18.51 | AD33: 19.03 | AE33: 19.31 | AF33: 19.47 | AG33: 19.7 | AH33: 19.39 | AI33: 20.16 | AJ33: 20.74 | AK33: 21.9 | AL33: 22.24 | AM33: 21.25 | AN33: 22.1 | AO33: 22.72 | AP33: 22.87 | AQ33: 22.84 | AR33: 22.64 | AS33: 22.68 | AT33: 21.85 | AU33: 22.74 | AV33: 23.1 | AW33: 22.62 | AX33: 23.96 | AY33: 25.1 | AZ33: 26.31 | BA33: 26.82 | BB33: 25.59 | BC33: 28.13 | BD33: 30.78 | BE33: 30.9 | BF33: 31.3 | BG33: 30.24 | BH33: 30.71 | BI33: 30.44 | BJ33: 31.87 | BK33: 32.23 | BL33: 31.31 | BM33: 31.98 | BN33: 31.77 | BO33: 32.36 | BP33: 32.1 | BQ33: 32.05 | BR33: 32.67 | BS33: 32.84 | BT33: 33.88 | BU33: 33.91 | BV33: 33.31 | BW33: 34.52 | BX33: 37.84 | BY33: =BY28+BY31 | BZ33: =BZ28+BZ31 | CA33: =IFERROR(SUMPRODUCT(BW33:BZ33,BW15:BZ15)/SUM(BW15:BZ15),"") | CB33: =CB28+CB31 | CC33: =CC28+CC31 | CD33: =CD28+CD31 | CE33: =CE28+CE31 | CH33: =IFERROR((CE33/BV33)^(1/5)-1,"n/m") | CI33: =IFERROR((BV33/AW33)^(1/5)-1,"n/m") | CJ33: =IFERROR((BV33/X33)^(1/10)-1,"n/m") | CK33: =IFERROR((BV33/C33)^(1/19)-1,"n/m") | CN33: 2029E | CO33: =CP33+$CO$30 | CP33: 0.04 | CQ33: =CP33+$CQ$30
B34: y/y % | D34: =IF(AND(ISNUMBER(D33),ISNUMBER(C33)),IFERROR(D33/C33-1,""),"") | E34: =IF(AND(ISNUMBER(E33),ISNUMBER(D33)),IFERROR(E33/D33-1,""),"") | F34: =IF(AND(ISNUMBER(F33),ISNUMBER(E33)),IFERROR(F33/E33-1,""),"") | G34: =IF(AND(ISNUMBER(G33),ISNUMBER(F33)),IFERROR(G33/F33-1,""),"") | H34: =IF(AND(ISNUMBER(H33),ISNUMBER(G33)),IFERROR(H33/G33-1,""),"") | I34: =IF(AND(ISNUMBER(I33),ISNUMBER(H33)),IFERROR(I33/H33-1,""),"") | N34: =IF(AND(ISNUMBER(N33),ISNUMBER(I33)),IFERROR(N33/I33-1,""),"") | O34: =IF(AND(ISNUMBER(O33),ISNUMBER(J33)),IFERROR(O33/J33-1,""),"") | P34: =IF(AND(ISNUMBER(P33),ISNUMBER(K33)),IFERROR(P33/K33-1,""),"") | Q34: =IF(AND(ISNUMBER(Q33),ISNUMBER(L33)),IFERROR(Q33/L33-1,""),"") | R34: =IF(AND(ISNUMBER(R33),ISNUMBER(M33)),IFERROR(R33/M33-1,""),"") | S34: =IF(AND(ISNUMBER(S33),ISNUMBER(N33)),IFERROR(S33/N33-1,""),"") | T34: =IF(AND(ISNUMBER(T33),ISNUMBER(O33)),IFERROR(T33/O33-1,""),"") | U34: =IF(AND(ISNUMBER(U33),ISNUMBER(P33)),IFERROR(U33/P33-1,""),"") | ... CA34: =IF(AND(ISNUMBER(CA33),ISNUMBER(BV33)),IFERROR(CA33/BV33-1,""),"") | CB34: =IF(AND(ISNUMBER(CB33),ISNUMBER(CA33)),IFERROR(CB33/CA33-1,""),"") | CC34: =IF(AND(ISNUMBER(CC33),ISNUMBER(CB33)),IFERROR(CC33/CB33-1,""),"") | CD34: =IF(AND(ISNUMBER(CD33),ISNUMBER(CC33)),IFERROR(CD33/CC33-1,""),"") | CE34: =IF(AND(ISNUMBER(CE33),ISNUMBER(CD33)),IFERROR(CE33/CD33-1,""),"") | CH34: =IFERROR(AVERAGE(CA34,CB34,CC34,CD34,CE34),"n/m") | CI34: =IFERROR(AVERAGE(BB34,BG34,BL34,BQ34,BV34),"n/m") | CJ34: =IFERROR(AVERAGE(AC34,AH34,AM34,AR34,AW34,BB34,BG34,BL34,BQ34,BV34),"n/m") | CK34: =IFERROR(AVERAGE(C34,D34,E34,F34,G34,H34,I34,N34,S34,X34,AC34,AH34,AM34,AR34,AW34,BB34,BG34,BL34,BQ34,BV34),"n/m") | CN34: 2030E | CO34: =CP34+$CO$30 | CP34: 0.035 | CQ34: =CP34+$CQ$30
B35: sequential % (vs prior quarter) | K35: =IF(AND(ISNUMBER(K33),ISNUMBER(J33)),IFERROR(K33/J33-1,""),"") | L35: =IF(AND(ISNUMBER(L33),ISNUMBER(K33)),IFERROR(L33/K33-1,""),"") | M35: =IF(AND(ISNUMBER(M33),ISNUMBER(L33)),IFERROR(M33/L33-1,""),"") | O35: =IF(AND(ISNUMBER(O33),ISNUMBER(M33)),IFERROR(O33/M33-1,""),"") | P35: =IF(AND(ISNUMBER(P33),ISNUMBER(O33)),IFERROR(P33/O33-1,""),"") | Q35: =IF(AND(ISNUMBER(Q33),ISNUMBER(P33)),IFERROR(Q33/P33-1,""),"") | R35: =IF(AND(ISNUMBER(R33),ISNUMBER(Q33)),IFERROR(R33/Q33-1,""),"") | T35: =IF(AND(ISNUMBER(T33),ISNUMBER(R33)),IFERROR(T33/R33-1,""),"") | U35: =IF(AND(ISNUMBER(U33),ISNUMBER(T33)),IFERROR(U33/T33-1,""),"") | V35: =IF(AND(ISNUMBER(V33),ISNUMBER(U33)),IFERROR(V33/U33-1,""),"") | W35: =IF(AND(ISNUMBER(W33),ISNUMBER(V33)),IFERROR(W33/V33-1,""),"") | Y35: =IF(AND(ISNUMBER(Y33),ISNUMBER(W33)),IFERROR(Y33/W33-1,""),"") | Z35: =IF(AND(ISNUMBER(Z33),ISNUMBER(Y33)),IFERROR(Z33/Y33-1,""),"") | AA35: =IF(AND(ISNUMBER(AA33),ISNUMBER(Z33)),IFERROR(AA33/Z33-1,""),"") | AB35: =IF(AND(ISNUMBER(AB33),ISNUMBER(AA33)),IFERROR(AB33/AA33-1,""),"") | AD35: =IF(AND(ISNUMBER(AD33),ISNUMBER(AB33)),IFERROR(AD33/AB33-1,""),"") | AE35: =IF(AND(ISNUMBER(AE33),ISNUMBER(AD33)),IFERROR(AE33/AD33-1,""),"") | AF35: =IF(AND(ISNUMBER(AF33),ISNUMBER(AE33)),IFERROR(AF33/AE33-1,""),"") | AG35: =IF(AND(ISNUMBER(AG33),ISNUMBER(AF33)),IFERROR(AG33/AF33-1,""),"") | AI35: =IF(AND(ISNUMBER(AI33),ISNUMBER(AG33)),IFERROR(AI33/AG33-1,""),"") | AJ35: =IF(AND(ISNUMBER(AJ33),ISNUMBER(AI33)),IFERROR(AJ33/AI33-1,""),"") | AK35: =IF(AND(ISNUMBER(AK33),ISNUMBER(AJ33)),IFERROR(AK33/AJ33-1,""),"") | AL35: =IF(AND(ISNUMBER(AL33),ISNUMBER(AK33)),IFERROR(AL33/AK33-1,""),"") | AN35: =IF(AND(ISNUMBER(AN33),ISNUMBER(AL33)),IFERROR(AN33/AL33-1,""),"") | AO35: =IF(AND(ISNUMBER(AO33),ISNUMBER(AN33)),IFERROR(AO33/AN33-1,""),"") | AP35: =IF(AND(ISNUMBER(AP33),ISNUMBER(AO33)),IFERROR(AP33/AO33-1,""),"") | AQ35: =IF(AND(ISNUMBER(AQ33),ISNUMBER(AP33)),IFERROR(AQ33/AP33-1,""),"") | AS35: =IF(AND(ISNUMBER(AS33),ISNUMBER(AQ33)),IFERROR(AS33/AQ33-1,""),"") | AT35: =IF(AND(ISNUMBER(AT33),ISNUMBER(AS33)),IFERROR(AT33/AS33-1,""),"") | AU35: =IF(AND(ISNUMBER(AU33),ISNUMBER(AT33)),IFERROR(AU33/AT33-1,""),"") | AV35: =IF(AND(ISNUMBER(AV33),ISNUMBER(AU33)),IFERROR(AV33/AU33-1,""),"") | AX35: =IF(AND(ISNUMBER(AX33),ISNUMBER(AV33)),IFERROR(AX33/AV33-1,""),"") | AY35: =IF(AND(ISNUMBER(AY33),ISNUMBER(AX33)),IFERROR(AY33/AX33-1,""),"") | AZ35: =IF(AND(ISNUMBER(AZ33),ISNUMBER(AY33)),IFERROR(AZ33/AY33-1,""),"") | BA35: =IF(AND(ISNUMBER(BA33),ISNUMBER(AZ33)),IFERROR(BA33/AZ33-1,""),"") | BC35: =IF(AND(ISNUMBER(BC33),ISNUMBER(BA33)),IFERROR(BC33/BA33-1,""),"") | BD35: =IF(AND(ISNUMBER(BD33),ISNUMBER(BC33)),IFERROR(BD33/BC33-1,""),"") | BE35: =IF(AND(ISNUMBER(BE33),ISNUMBER(BD33)),IFERROR(BE33/BD33-1,""),"") | BF35: =IF(AND(ISNUMBER(BF33),ISNUMBER(BE33)),IFERROR(BF33/BE33-1,""),"") | BH35: =IF(AND(ISNUMBER(BH33),ISNUMBER(BF33)),IFERROR(BH33/BF33-1,""),"") | BI35: =IF(AND(ISNUMBER(BI33),ISNUMBER(BH33)),IFERROR(BI33/BH33-1,""),"") | BJ35: =IF(AND(ISNUMBER(BJ33),ISNUMBER(BI33)),IFERROR(BJ33/BI33-1,""),"") | BK35: =IF(AND(ISNUMBER(BK33),ISNUMBER(BJ33)),IFERROR(BK33/BJ33-1,""),"") | BM35: =IF(AND(ISNUMBER(BM33),ISNUMBER(BK33)),IFERROR(BM33/BK33-1,""),"") | BN35: =IF(AND(ISNUMBER(BN33),ISNUMBER(BM33)),IFERROR(BN33/BM33-1,""),"") | BO35: =IF(AND(ISNUMBER(BO33),ISNUMBER(BN33)),IFERROR(BO33/BN33-1,""),"") | BP35: =IF(AND(ISNUMBER(BP33),ISNUMBER(BO33)),IFERROR(BP33/BO33-1,""),"") | BR35: =IF(AND(ISNUMBER(BR33),ISNUMBER(BP33)),IFERROR(BR33/BP33-1,""),"") | BS35: =IF(AND(ISNUMBER(BS33),ISNUMBER(BR33)),IFERROR(BS33/BR33-1,""),"") | BT35: =IF(AND(ISNUMBER(BT33),ISNUMBER(BS33)),IFERROR(BT33/BS33-1,""),"") | BU35: =IF(AND(ISNUMBER(BU33),ISNUMBER(BT33)),IFERROR(BU33/BT33-1,""),"") | BW35: =IF(AND(ISNUMBER(BW33),ISNUMBER(BU33)),IFERROR(BW33/BU33-1,""),"") | BX35: =IF(AND(ISNUMBER(BX33),ISNUMBER(BW33)),IFERROR(BX33/BW33-1,""),"") | BY35: =IF(AND(ISNUMBER(BY33),ISNUMBER(BX33)),IFERROR(BY33/BX33-1,""),"") | BZ35: =IF(AND(ISNUMBER(BZ33),ISNUMBER(BY33)),IFERROR(BZ33/BY33-1,""),"") | CN35: YXF (LTL revenue/cwt ex fuel y/y) | CO35: 0.01 | CP35: Δ → | CQ35: -0.015 | CR35: Yield discipline: cost-plus pricing targets inflation + reinvestment; ex-fuel revenue/cwt +4–6% p.a. 2016–25 (weight-per-shipment mix headwind as volumes recover).
B36: LTL revenue per shipment ($) | C36: 199.03 | D36: 207.24 | E36: 229.99 | F36: 216.49 | G36: 234.09 | H36: 259.5 | I36: 271.82 | J36: 276.97 | K36: 279.9 | L36: 285.7 | M36: 285.16 | N36: 282.78 | O36: 292.95 | P36: 300.5 | Q36: 301.08 | R36: 299.38 | S36: 298.65 | T36: 288.83 | U36: 286.85 | V36: 282.9 | W36: 284.47 | X36: 285.67 | Y36: 280.33 | Z36: 286.51 | AA36: 291.51 | AB36: 299.34 | AC36: 289.36 | AD36: 297.11 | AE36: 302.51 | AF36: 307.45 | AG36: 322.97 | AH36: 307.66 | AI36: 328.78 | AJ36: 334.95 | AK36: 340.91 | AL36: 352.65 | AM36: 339.35 | AN36: 346.02 | AO36: 352.88 | AP36: 353.24 | AQ36: 360.8 | AR36: 353.18 | AS36: 359.64 | AT36: 357.65 | AU36: 367.28 | AV36: 374.08 | AW36: 364.94 | AX36: 384.76 | AY36: 394.49 | AZ36: 404.65 | BA36: 422.28 | BB36: 402.01 | BC36: 446.86 | BD36: 484.08 | BE36: 482.46 | BF36: 489.96 | BG36: 475.45 | BH36: 475.88 | BI36: 464.79 | BJ36: 477.13 | BK36: 487.13 | BL36: 476.25 | BM36: 482.24 | BN36: 479.48 | BO36: 477.7 | BP36: 481.91 | BQ36: 480.29 | BR36: 485.79 | BS36: 485.31 | BT36: 494.17 | BU36: 503.95 | BV36: 492.01 | BW36: 514.56 | BX36: 568.55 | BY36: =BY33*BY17/100 | BZ36: =BZ33*BZ17/100 | CA36: =CA33*CA17/100 | CB36: =CB33*CB17/100 | CC36: =CC33*CC17/100 | CD36: =CD33*CD17/100 | CE36: =CE33*CE17/100 | CN36: 2027E | CO36: =CP36+$CO$35 | CP36: 0.05 | CQ36: =CP36+$CQ$35
B37: LTL revenue per shipment, excluding fuel surcharges ($) | C37: 175.38 | D37: 181.47 | E37: 190.44 | F37: 195.81 | G37: 205.38 | H37: 217.04 | I37: 226.5 | J37: 230.4 | K37: 235.36 | L37: 240 | M37: 240.27 | N37: 237.37 | O37: 244.24 | P37: 251.08 | Q37: 253.01 | R37: 254.54 | S37: 250.92 | T37: 254.75 | U37: 254.44 | V37: 254.01 | W37: 257.25 | X37: 255.1 | Y37: 255.72 | Z37: 258.9 | AA37: 262.35 | AB37: 268.1 | AC37: 261.21 | AD37: 264.47 | AE37: 269.92 | AF37: 273.38 | AG37: 283.6 | AH37: 272.97 | AI37: 286.66 | AJ37: 289.69 | AK37: 293.56 | AL37: 303.8 | AM37: 293.42 | AN37: 301.56 | AO37: 306.37 | AP37: 308.26 | AQ37: 314.7 | AR37: 307.67 | AS37: 315.43 | AT37: 321.47 | AU37: 330.43 | AV37: 336.04 | AW37: 326.09 | AX37: 337.46 | AY37: 340.48 | AZ37: 346.46 | BA37: 356.93 | BB37: 345.54 | BC37: 367.07 | BD37: 372.56 | BE37: 377.14 | BF37: 385.89 | BG37: 375.36 | BH37: 388.82 | BI37: 389.39 | BJ37: 393.57 | BK37: 400.45 | BL37: 393.07 | BM37: 403.71 | BN37: 403.77 | BO37: 405.85 | BP37: 413.21 | BQ37: 406.52 | BR37: 414.68 | BS37: 416.31 | BT37: 419.67 | BU37: 429.21 | BV37: 419.74 | BW37: 434.16 | BX37: 446.44 | BY37: =BY28*BY17/100 | BZ37: =BZ28*BZ17/100 | CA37: =CA28*CA17/100 | CB37: =CB28*CB17/100 | CC37: =CC28*CC17/100 | CD37: =CD28*CD17/100 | CE37: =CE28*CE17/100 | CN37: 2028E | CO37: =CP37+$CO$35 | CP37: 0.045 | CQ37: =CP37+$CQ$35
CN38: 2029E | CO38: =CP38+$CO$35 | CP38: 0.045 | CQ38: =CP38+$CQ$35
B39: Revenue build — LTL services (statistics basis × revenue-recognition adjustment) + other services | CF39: REVENUE BUILD — modelling logic | CN39: 2030E | CO39: =CP39+$CO$35 | CP39: 0.04 | CQ39: =CP39+$CQ$35
B40: LTL revenue — statistics basis (tons × 20 cwt × revenue/cwt) | C40: =IF(AND(ISNUMBER(C15),ISNUMBER(C33)),C15*20*C33/1000,"") | D40: =IF(AND(ISNUMBER(D15),ISNUMBER(D33)),D15*20*D33/1000,"") | E40: =IF(AND(ISNUMBER(E15),ISNUMBER(E33)),E15*20*E33/1000,"") | F40: =IF(AND(ISNUMBER(F15),ISNUMBER(F33)),F15*20*F33/1000,"") | G40: =IF(AND(ISNUMBER(G15),ISNUMBER(G33)),G15*20*G33/1000,"") | H40: =IF(AND(ISNUMBER(H15),ISNUMBER(H33)),H15*20*H33/1000,"") | I40: =IF(AND(ISNUMBER(I15),ISNUMBER(I33)),I15*20*I33/1000,"") | J40: =IF(AND(ISNUMBER(J15),ISNUMBER(J33)),J15*20*J33/1000,"") | ... CE40: =IF(AND(ISNUMBER(CE15),ISNUMBER(CE33)),CE15*20*CE33/1000,"") | CF40: Operating statistics exclude undelivered-freight adjustments (revenue recognised over transit) and non-weight-priced services. | CN40: OR (operating ratio) | CO40: -0.015 | CP40: Δ → | CQ40: 0.025 | CR40: FY2022 record 70.6%; FY25 74.7% (de-leverage at −8% tons/day). Density recovery on a network with ~30% excess capacity; long-term ambition low/mid-60s.
...

Sheet Bull-Base-Bear
B2: Old Dominion Freight Line (ODFL) — Bull / Base / Bear Case P&L Summary | J2: Share price ($): | K2: =Model!$CA$355
B3: Adjusted figures are model definitions (ODFL publishes no non-GAAP measures): Adjusted EBITDA / adjusted EPS exclude net gains on disposal of property & equipment and company-named one-offs · USD millions · Live panel linked to Model — toggle scenario via Model!CF2. Bull and Bear panels are value snapshots generated from the Model with the switch set to each case. | J3: As of: | K3: =TODAY()
B5: Scenario: | C5: =Model!$CF$2 | N5: Scenario: | O5: Bull | P5: Snapshot (values) — Model run with switch = Bull | Z5: Scenario: | AA5: Bear | AB5: Snapshot (values) — Model run with switch = Bear
B7: (USDm, except EPS and shares) | C7: 2025A | D7: 2026E | E7: 2027E | F7: 2028E | G7: 2029E | H7: 2030E | I7: 25-'30 CAGR | J7: LT Hist Avg | K7: LT Hist Min | L7: LT Hist Max | N7: (USDm, except EPS and shares) | O7: 2025A | P7: 2026E | Q7: 2027E | R7: 2028E | S7: 2029E | T7: 2030E | U7: 25-'30 CAGR | V7: LT Hist Avg | W7: LT Hist Min | X7: LT Hist Max | Z7: (USDm, except EPS and shares) | AA7: 2025A | AB7: 2026E | AC7: 2027E | AD7: 2028E | AE7: 2029E | AF7: 2030E | AG7: 25-'30 CAGR | AH7: LT Hist Avg | AI7: LT Hist Min | AJ7: LT Hist Max
B9: Revenue | C9: =Model!BV100 | D9: =Model!CA100 | E9: =Model!CB100 | F9: =Model!CC100 | G9: =Model!CD100 | H9: =Model!CE100 | I9: =IFERROR((H9/C9)^(1/5)-1,"n/m") | N9: Revenue | O9: 5496.389 | P9: 6008.4957 | Q9: 6770.3343 | R9: 7667.9167 | S9: 8570.5786 | T9: 9490.0515 | U9: 0.11541947 | Z9: Revenue | AA9: 5496.389 | AB9: 5856.3706 | AC9: 6144.2458 | AD9: 6479.9527 | AE9: 6741.0778 | AF9: 6944.7368 | AG9: 0.047889927
B10: Revenue y/y % | D10: =IFERROR(D9/C9-1,"") | E10: =IFERROR(E9/D9-1,"") | F10: =IFERROR(F9/E9-1,"") | G10: =IFERROR(G9/F9-1,"") | H10: =IFERROR(H9/G9-1,"") | N10: Revenue y/y % | P10: 0.093171473 | Q10: 0.12679358 | R10: 0.13257579 | S10: 0.1177193 | T10: 0.10728248 | Z10: Revenue y/y % | AB10: 0.065494193 | AC10: 0.049155917 | AD10: 0.054637612 | AE10: 0.040297367 | AF10: 0.030211637
B11: LTL tons per day y/y % | C11: =Model!BV185 | D11: =Model!CA185 | E11: =Model!CB185 | F11: =Model!CC185 | G11: =Model!CD185 | H11: =Model!CE185 | N11: LTL tons per day y/y % | O11: -0.087884176 | P11: -0.016991721 | Q11: 0.06 | R11: 0.07 | S11: 0.06 | T11: 0.055 | Z11: LTL tons per day y/y % | AA11: -0.087884176 | AB11: -0.034827178 | AC11: 0.01 | AD11: 0.02 | AE11: 0.01 | AF11: 0.005
B12: Adjusted EBITDA (model) | C12: =Model!BV157 | D12: =Model!CA157 | E12: =Model!CB157 | F12: =Model!CC157 | G12: =Model!CD157 | H12: =Model!CE157 | I12: =IFERROR((H12/C12)^(1/5)-1,"n/m") | N12: Adjusted EBITDA (model) | O12: 1728.666 | P12: 2167.8888 | Q12: 2545.6457 | R12: 2959.8159 | S12: 3351.0962 | T12: 3758.0604 | U12: 0.16802068 | Z12: Adjusted EBITDA (model) | AA12: 1728.666 | AB12: 1936.956 | AC12: 2064.4666 | AD12: 2242.0636 | AE12: 2366.1183 | AF12: 2472.3263 | AG12: 0.074184644
B13: Adjusted EBITDA margin % | C13: =IFERROR(C12/C9,"") | D13: =IFERROR(D12/D9,"") | E13: =IFERROR(E12/E9,"") | F13: =IFERROR(F12/F9,"") | G13: =IFERROR(G12/G9,"") | H13: =IFERROR(H12/H9,"") | J13: =IFERROR(AVERAGE(Model!C158,Model!D158,Model!E158,Model!F158,Model!G158,Model!H158,Model!I158,Model!N158,Model!S158,Model!X158,Model!AC158,Model!AH158,Model!AM158,Model!AR158,Model!AW158,Model!BB158,Model!BG158,Model!BL158,Model!BQ158,Model!BV158),"") | K13: =IFERROR(MIN(Model!C158,Model!D158,Model!E158,Model!F158,Model!G158,Model!H158,Model!I158,Model!N158,Model!S158,Model!X158,Model!AC158,Model!AH158,Model!AM158,Model!AR158,Model!AW158,Model!BB158,Model!BG158,Model!BL158,Model!BQ158,Model!BV158),"") | L13: =IFERROR(MAX(Model!C158,Model!D158,Model!E158,Model!F158,Model!G158,Model!H158,Model!I158,Model!N158,Model!S158,Model!X158,Model!AC158,Model!AH158,Model!AM158,Model!AR158,Model!AW158,Model!BB158,Model!BG158,Model!BL158,Model!BQ158,Model!BV158),"") | N13: Adjusted EBITDA margin % | O13: 0.3145094 | P13: 0.36080392 | Q13: 0.376 | R13: 0.386 | S13: 0.391 | T13: 0.396 | V13: 0.23023337 | W13: 0.13280911 | X13: 0.33505291 | Z13: Adjusted EBITDA margin % | AA13: 0.3145094 | AB13: 0.33074342 | AC13: 0.336 | AD13: 0.346 | AE13: 0.351 | AF13: 0.356 | AH13: 0.23023337 | AI13: 0.13280911 | AJ13: 0.33505291
B15: Operating Income (GAAP) | C15: =Model!BV114 | D15: =Model!CA114 | E15: =Model!CB114 | F15: =Model!CC114 | G15: =Model!CD114 | H15: =Model!CE114 | I15: =IFERROR((H15/C15)^(1/5)-1,"n/m") | N15: Operating Income (GAAP) | O15: 1361.045 | P15: 1815.9558 | Q15: 2098.8036 | R15: 2453.7334 | S15: 2785.438 | T15: 3131.717 | U15: 0.1813593 | Z15: Operating Income (GAAP) | AA15: 1361.045 | AB15: 1585.023 | AC15: 1658.9464 | AD15: 1814.3868 | AE15: 1921.2072 | AF15: 2013.9737 | AG15: 0.081524247
B16: Operating income y/y % | D16: =IFERROR(D15/C15-1,"") | E16: =IFERROR(E15/D15-1,"") | F16: =IFERROR(F15/E15-1,"") | G16: =IFERROR(G15/F15-1,"") | H16: =IFERROR(H15/G15-1,"") | N16: Operating income y/y % | P16: 0.33423641 | Q16: 0.15575701 | R16: 0.16911049 | S16: 0.13518367 | T16: 0.1243176 | Z16: Operating income y/y % | AB16: 0.16456326 | AC16: 0.046638671 | AD16: 0.093698264 | AE16: 0.058874106 | AF16: 0.048285526
B17: Operating margin (1 − operating ratio) % | C17: =IFERROR(C15/C9,"") | D17: =IFERROR(D15/D9,"") | E17: =IFERROR(E15/E9,"") | F17: =IFERROR(F15/F9,"") | G17: =IFERROR(G15/G9,"") | H17: =IFERROR(H15/H9,"") | J17: =IFERROR(AVERAGE(Model!C194,Model!D194,Model!E194,Model!F194,Model!G194,Model!H194,Model!I194,Model!N194,Model!S194,Model!X194,Model!AC194,Model!AH194,Model!AM194,Model!AR194,Model!AW194,Model!BB194,Model!BG194,Model!BL194,Model!BQ194,Model!BV194),"") | K17: =IFERROR(MIN(Model!C194,Model!D194,Model!E194,Model!F194,Model!G194,Model!H194,Model!I194,Model!N194,Model!S194,Model!X194,Model!AC194,Model!AH194,Model!AM194,Model!AR194,Model!AW194,Model!BB194,Model!BG194,Model!BL194,Model!BQ194,Model!BV194),"") | L17: =IFERROR(MAX(Model!C194,Model!D194,Model!E194,Model!F194,Model!G194,Model!H194,Model!I194,Model!N194,Model!S194,Model!X194,Model!AC194,Model!AH194,Model!AM194,Model!AR194,Model!AW194,Model!BB194,Model!BG194,Model!BL194,Model!BQ194,Model!BV194),"") | N17: Operating margin (1 − operating ratio) % | O17: 0.2476253 | P17: 0.30223136 | Q17: 0.31 | R17: 0.32 | S17: 0.325 | T17: 0.33 | V17: 0.17351843 | W17: 0.056538729 | X17: 0.29402705 | Z17: Operating margin (1 − operating ratio) % | AA17: 0.2476253 | AB17: 0.27064937 | AC17: 0.27 | AD17: 0.28 | AE17: 0.285 | AF17: 0.29 | AH17: 0.17351843 | AI17: 0.056538729 | AJ17: 0.29402705
B19: Adjusted Net Income (model) | C19: =Model!BV174 | D19: =Model!CA174 | E19: =Model!CB174 | F19: =Model!CC174 | G19: =Model!CD174 | H19: =Model!CE174 | I19: =IFERROR((H19/C19)^(1/5)-1,"n/m") | N19: Adjusted Net Income (model) | O19: 1025.9124 | P19: 1350.9031 | Q19: 1585.4945 | R19: 1841.6126 | S19: 2090.3911 | T19: 2350.1003 | U19: 0.18030766 | Z19: Adjusted Net Income (model) | AA19: 1025.9124 | AB19: 1177.7035 | AC19: 1257.7399 | AD19: 1368.6651 | AE19: 1448.7804 | AF19: 1518.3553 | AG19: 0.08156501
B21: FDSO (m) | C21: =Model!BV130 | D21: =Model!CA130 | E21: =Model!CB130 | F21: =Model!CC130 | G21: =Model!CD130 | H21: =Model!CE130 | I21: =IFERROR((H21/C21)^(1/5)-1,"n/m") | N21: FDSO (m) | O21: 211.598 | P21: 208.36144 | Q21: 203.29104 | R21: 197.38291 | S21: 191.89524 | T21: 186.03552 | U21: -0.025421422 | Z21: FDSO (m) | AA21: 211.598 | AB21: 208.67648 | AC21: 205.63979 | AD21: 201.73972 | AE21: 198.31803 | AF21: 194.97682 | AG21: -0.016228394
B23: Adjusted EPS — Diluted ($) | C23: =Model!BV176 | D23: =Model!CA176 | E23: =Model!CB176 | F23: =Model!CC176 | G23: =Model!CD176 | H23: =Model!CE176 | I23: =IFERROR((H23/C23)^(1/5)-1,"n/m") | N23: Adjusted EPS — Diluted ($) | O23: 4.848403 | P23: 6.4834601 | Q23: 7.7991361 | R23: 9.3301522 | S23: 10.893397 | T23: 12.632536 | U23: 0.21109543 | Z23: Adjusted EPS — Diluted ($) | AA23: 4.848403 | AB23: 5.6436812 | AC23: 6.1162282 | AD23: 6.7843116 | AE23: 7.3053392 | AF23: 7.7873633 | AG23: 0.099406614
B24: EPS y/y % | D24: =IFERROR(D23/C23-1,"") | E24: =IFERROR(E23/D23-1,"") | F24: =IFERROR(F23/E23-1,"") | G24: =IFERROR(G23/F23-1,"") | H24: =IFERROR(H23/G23-1,"") | N24: EPS y/y % | P24: 0.33723623 | Q24: 0.20292806 | R24: 0.19630585 | S24: 0.16754763 | T24: 0.15965072 | Z24: EPS y/y % | AB24: 0.1640289 | AC24: 0.083730286 | AD24: 0.10923127 | AE24: 0.076798884 | AF24: 0.065982448
B26: P / E (x) — assumed (adjusted EPS) | G26: 28 | H26: 28 | N26: P / E (x) — assumed (adjusted EPS) | S26: 32 | T26: 32 | Z26: P / E (x) — assumed (adjusted EPS) | AD26: 22 | AE26: 22 | AF26: 22
B27: Price Target ($) | G27: =G26*G23 | H27: =H26*H23 | N27: Price Target ($) | S27: =S26*S23 | T27: =T26*T23 | Z27: Price Target ($) | AD27: =AD26*AD23 | AE27: =AE26*AE23 | AF27: =AF26*AF23
B28: Upside / (Downside) vs current | G28: =IFERROR(G27/$K$2-1,"") | H28: =IFERROR(H27/$K$2-1,"") | N28: Upside / (Downside) vs current | S28: =IFERROR(S27/$K$2-1,"") | T28: =IFERROR(T27/$K$2-1,"") | Z28: Upside / (Downside) vs current | AD28: =IFERROR(AD27/$K$2-1,"") | AE28: =IFERROR(AE27/$K$2-1,"") | AF28: =IFERROR(AF27/$K$2-1,"")
B29: IRR (to Dec-Y-1) | G29: =IFERROR((G27/$K$2)^(1/((DATE(2029-1,12,31)-$K$3)/365.25))-1,"") | H29: =IFERROR((H27/$K$2)^(1/((DATE(2030-1,12,31)-$K$3)/365.25))-1,"") | N29: IRR (to Dec-Y-1) | S29: =IFERROR((S27/$K$2)^(1/((DATE(2029-1,12,31)-$K$3)/365.25))-1,"") | T29: =IFERROR((T27/$K$2)^(1/((DATE(2030-1,12,31)-$K$3)/365.25))-1,"") | Z29: IRR (to Dec-Y-1) | AD29: =IFERROR((AD27/$K$2)^(1/((DATE(2028-1,12,31)-$K$3)/365.25))-1,"") | AE29: =IFERROR((AE27/$K$2)^(1/((DATE(2029-1,12,31)-$K$3)/365.25))-1,"") | AF29: =IFERROR((AF27/$K$2)^(1/((DATE(2030-1,12,31)-$K$3)/365.25))-1,"")
B31: Free Cash Flow | C31: =Model!BV226 | D31: =Model!CA226 | E31: =Model!CB226 | F31: =Model!CC226 | G31: =Model!CD226 | H31: =Model!CE226 | I31: =IFERROR((H31/C31)^(1/5)-1,"n/m") | N31: Free Cash Flow | O31: 955.099 | P31: 1292.5544 | Q31: 1309.9746 | R31: 1526.4005 | S31: 1737.9512 | T31: 1958.9762 | U31: 0.15450589 | Z31: Free Cash Flow | AA31: 955.099 | AB31: 1124.3821 | AC31: 1017.3524 | AD31: 1112.6571 | AE31: 1183.5723 | AF31: 1245.5714 | AG31: 0.054542395
