Workbook

Sheet Model
AM1: SCENARIO SWITCH ▼ (Bull / Base / Bear) — drives all scenario-linked forecast drivers
B2: On Holding AG (NYSE: ONON) — 3-Statement Financial Model | AM2: Base
B3: IFRS as reported · CHF millions (per-share data in CHF; shares in millions, Class A-equivalent) · Source: On Holding Forms 20-F, Form 6-K earnings releases (Ex. 99.1 / 99.3) and MD&A exhibits (Ex. 99.2), Investor Day releases (Oct-2023, 22-Sep-2026) and the IPO prospectus (424B4, 16-Sep-2021), SEC EDGAR CIK 0001858985 (investor-relations releases at investors.on-running.com are the same documents as filed on EDGAR)
B4: Basis notes: calendar fiscal year; single segment (sales disclosed by region, channel and product). FY2019–20 from the IPO prospectus; quarters from Q1/21 (Q1–Q2/21 from the 2022 releases' comparatives). Regions: EMEA / Americas / APAC from 2023 (FY2021 and 2022 quarters restated); former Europe / North America / APAC / RoW as memo. Class A-equivalent shares = Class A + Class B ÷ 10. Q3/26E–Q4/26E calibrated to FY26 guidance (excl. tariff refund) and the Q3 cc guide; 2027E–2030E Base on the Investor Day 2029 targets. Valuation in CHF from the USD share price × USD/CHF.
AO5: Forecast | AP5: Historical | AQ5: Historical | AR5: Historical
B6: (CHFm) | C6: 2019 | D6: 2020 | E6: Q1/21 | F6: Q2/21 | G6: Q3/21 | H6: Q4/21 | I6: 2021 | J6: Q1/22 | K6: Q2/22 | L6: Q3/22 | M6: Q4/22 | N6: 2022 | O6: Q1/23 | P6: Q2/23 | Q6: Q3/23 | R6: Q4/23 | S6: 2023 | T6: Q1/24 | U6: Q2/24 | V6: Q3/24 | W6: Q4/24 | X6: 2024 | Y6: Q1/25 | Z6: Q2/25 | AA6: Q3/25 | AB6: Q4/25 | AC6: 2025 | AD6: Q1/26 | AE6: Q2/26 | AF6: Q3/26E | AG6: Q4/26E | AH6: 2026E | AI6: 2027E | AJ6: 2028E | AK6: 2029E | AL6: 2030E | AM6: Modelling Notes | AO6: 5Y CAGR | AP6: 5Y CAGR | AQ6: 3Y CAGR | AR6: 6Y CAGR
AO7: 25-'30 | AP7: 20-'25 | AQ7: 22-'25 | AR7: 19-'25
B8: NET SALES BUILD — AMERICAS · EMEA · ASIA-PACIFIC (constant-currency growth + FX translation) | AM8: REGION BUILD — modelling logic (prior-year net sales × (1 + constant-currency growth + FX translation effect) → net sales → gross margin / Adjusted EBITDA margin → IFRS P&L)
AU9: SCENARIO INPUT TABLE — driver assumptions per Bull / Base / Bear | AV9: Bull | AW9: Base | AX9: Bear | AY9: Bull / Bear = Base + Δ (Δ inputs on each block header). Outlook block = high / mid / low end of the FY26 guidance ranges.
B10: Americas (United States, Canada, Latin America; largest wholesale & DTC market) | AM10: AMERICAS — modelling logic
B11: Net sales (CHF m) | I11: 417.6 | J11: 140.8 | K11: 185.6 | L11: 183.7 | M11: 253.7 | N11: 763.8 | O11: 270.2 | P11: 296.6 | Q11: 294.9 | R11: 300.5 | S11: 1162.2 | T11: 329.6 | U11: 370 | V11: 395.5 | W11: 385.1 | X11: 1480.3 | Y11: 437.4 | Z11: 432.3 | AA11: 436.2 | AB11: 434.3 | AC11: 1740.1 | AD11: 450.7 | AE11: 451.6 | AF11: =AA11*(1+AF13+AF14) | AG11: =AB11*(1+AG13+AG14) | AH11: =SUM(AD11,AE11,AF11,AG11) | AI11: =AH11*(1+AI13+AI14) | AJ11: =AI11*(1+AJ13+AJ14) | AK11: =AJ11*(1+AK13+AK14) | AL11: =AK11*(1+AL13+AL14) | AM11: As published on the EMEA / Americas / APAC basis (from 2023; FY2021 and 2022 quarters restated in the 2023 filings). Q4 = FY − 9M where not printed. Forecast: prior-year period × (1 + constant-currency growth + FX translation effect). | AO11: =IFERROR((AL11/AC11)^(1/5)-1,"n/m") | AP11: =IFERROR((AC11/D11)^(1/5)-1,"n/m") | AQ11: =IFERROR((AC11/N11)^(1/3)-1,"n/m") | AR11: =IFERROR((AC11/C11)^(1/6)-1,"n/m") | AU11: FY26 outlook — Q2-26 release (11-Aug-26), reiterated at Investor Day (22-Sep-26) | AV11: High | AW11: Mid | AX11: Low | AY11: Q2-26: cc growth "low-20% range", CHF 3.47–3.56bn at spot, GM ≥65.0% (raised), Adj. EBITDA margin 19.5–20.0%; all excl. tariff refunds. Investor Day: Q3-26 cc growth ~17%; tariff refund up to CHF 53m in Q3-26.
B12: y/y % (reported, CHF) | D12: =IF(AND(ISNUMBER(D11),ISNUMBER(C11)),IFERROR(D11/C11-1,""),"") | I12: =IF(AND(ISNUMBER(I11),ISNUMBER(D11)),IFERROR(I11/D11-1,""),"") | J12: =IF(AND(ISNUMBER(J11),ISNUMBER(E11)),IFERROR(J11/E11-1,""),"") | K12: =IF(AND(ISNUMBER(K11),ISNUMBER(F11)),IFERROR(K11/F11-1,""),"") | L12: =IF(AND(ISNUMBER(L11),ISNUMBER(G11)),IFERROR(L11/G11-1,""),"") | M12: =IF(AND(ISNUMBER(M11),ISNUMBER(H11)),IFERROR(M11/H11-1,""),"") | N12: =IF(AND(ISNUMBER(N11),ISNUMBER(I11)),IFERROR(N11/I11-1,""),"") | O12: =IF(AND(ISNUMBER(O11),ISNUMBER(J11)),IFERROR(O11/J11-1,""),"") | P12: =IF(AND(ISNUMBER(P11),ISNUMBER(K11)),IFERROR(P11/K11-1,""),"") | ... AH12: =IF(AND(ISNUMBER(AH11),ISNUMBER(AC11)),IFERROR(AH11/AC11-1,""),"") | AI12: =IF(AND(ISNUMBER(AI11),ISNUMBER(AH11)),IFERROR(AI11/AH11-1,""),"") | AJ12: =IF(AND(ISNUMBER(AJ11),ISNUMBER(AI11)),IFERROR(AJ11/AI11-1,""),"") | AK12: =IF(AND(ISNUMBER(AK11),ISNUMBER(AJ11)),IFERROR(AK11/AJ11-1,""),"") | AL12: =IF(AND(ISNUMBER(AL11),ISNUMBER(AK11)),IFERROR(AL11/AK11-1,""),"") | AU12: FY26 net sales growth, constant currency | AV12: 0.23 | AW12: 0.215 | AX12: 0.2 | AY12: "Low-20% range" → 20–23%. Drives the Q4-26E cc calibration.
B13: y/y % constant currency | T13: 0.304 | U13: 0.258 | V13: 0.345 | W13: 0.339 | X13: 0.312 | Y13: 0.286 | Z13: 0.236 | AA13: 0.21 | AB13: 0.213 | AC13: 0.234 | AD13: 0.171 | AE13: 0.13 | AF13: =AF16+AF47 | AG13: =AG16+AG47 | AH13: =IFERROR(AH15/AC11-1,"") | AI13: =CHOOSE(MATCH($AM$2,{"Bull","Base","Bear"},0),$AV$30,$AW$30,$AX$30) | AJ13: =CHOOSE(MATCH($AM$2,{"Bull","Base","Bear"},0),$AV$31,$AW$31,$AX$31) | AK13: =CHOOSE(MATCH($AM$2,{"Bull","Base","Bear"},0),$AV$32,$AW$32,$AX$32) | AL13: =CHOOSE(MATCH($AM$2,{"Bull","Base","Bear"},0),$AV$33,$AW$33,$AX$33) | AM13: Published from Q1-24 (company: current period retranslated at prior-year rates). Q3/Q4-26E: 1H/26 constant-currency growth (row below) + outlook calibration Δ (Group block). 2026E = Σ quarterly constant-currency sales ÷ FY25 − 1. 2027E–2030E: scenario lever. | AU13: FY26 net sales at current spot rates (CHF m) | AV13: 3560 | AW13: 3515 | AX13: 3470 | AY13: Guided CHF 3.47–3.56bn. Drives the 2H FX calibration.
B14: FX translation effect (pts; reported − constant currency) | C14: =IF(AND(ISNUMBER(C12),ISNUMBER(C13)),C12-C13,"") | D14: =IF(AND(ISNUMBER(D12),ISNUMBER(D13)),D12-D13,"") | E14: =IF(AND(ISNUMBER(E12),ISNUMBER(E13)),E12-E13,"") | F14: =IF(AND(ISNUMBER(F12),ISNUMBER(F13)),F12-F13,"") | G14: =IF(AND(ISNUMBER(G12),ISNUMBER(G13)),G12-G13,"") | H14: =IF(AND(ISNUMBER(H12),ISNUMBER(H13)),H12-H13,"") | I14: =IF(AND(ISNUMBER(I12),ISNUMBER(I13)),I12-I13,"") | J14: =IF(AND(ISNUMBER(J12),ISNUMBER(J13)),J12-J13,"") | ... AE14: =IF(AND(ISNUMBER(AE12),ISNUMBER(AE13)),AE12-AE13,"") | AF14: =$AF$51 | AG14: =$AF$51 | AH14: =IF(AND(ISNUMBER(AH12),ISNUMBER(AH13)),AH12-AH13,"") | AI14: 0 | AJ14: 0 | AK14: 0 | AL14: 0 | AM14: Q3/Q4-26E: uniform FX Δ solved so FY26 CHF net sales = the guidance end-point (company: "at current spot rates"). 2027E+: input (0 = forecasts at constant spot FX; CHF strength vs USD is the main translation risk). | AU14: Q3-26 net sales growth, constant currency | AV14: 0.18 | AW14: 0.17 | AX14: 0.16 | AY14: Investor Day: "around 17%". Drives the Q3-26E cc calibration.
B15: Memo: constant-currency net sales (prior-year period × (1 + cc growth)) | D15: =IF(AND(ISNUMBER(D13),ISNUMBER(C11)),C11*(1+D13),"") | I15: =IF(AND(ISNUMBER(I13),ISNUMBER(D11)),D11*(1+I13),"") | J15: =IF(AND(ISNUMBER(J13),ISNUMBER(E11)),E11*(1+J13),"") | K15: =IF(AND(ISNUMBER(K13),ISNUMBER(F11)),F11*(1+K13),"") | L15: =IF(AND(ISNUMBER(L13),ISNUMBER(G11)),G11*(1+L13),"") | M15: =IF(AND(ISNUMBER(M13),ISNUMBER(H11)),H11*(1+M13),"") | N15: =IF(AND(ISNUMBER(N13),ISNUMBER(I11)),I11*(1+N13),"") | O15: =IF(AND(ISNUMBER(O13),ISNUMBER(J11)),J11*(1+O13),"") | P15: =IF(AND(ISNUMBER(P13),ISNUMBER(K11)),K11*(1+P13),"") | ... AG15: =IF(AND(ISNUMBER(AG13),ISNUMBER(AB11)),AB11*(1+AG13),"") | AH15: =SUM(AD15:AG15) | AI15: =IF(AND(ISNUMBER(AI13),ISNUMBER(AH11)),AH11*(1+AI13),"") | AJ15: =IF(AND(ISNUMBER(AJ13),ISNUMBER(AI11)),AI11*(1+AJ13),"") | AK15: =IF(AND(ISNUMBER(AK13),ISNUMBER(AJ11)),AJ11*(1+AK13),"") | AL15: =IF(AND(ISNUMBER(AL13),ISNUMBER(AK11)),AK11*(1+AL13),"") | AU15: FY26 gross margin (excl. tariff refund) | AV15: 0.658 | AW15: 0.654 | AX15: 0.65 | AY15: Guided "at least 65.0%" (1H/26 64.8%, Q2-26 65.4%).
B16: Q3/Q4-26E cc growth before calibration (1H/26 constant-currency growth) | AF16: =IFERROR((AD15+AE15)/(Y11+Z11)-1,0) | AG16: =IFERROR((AD15+AE15)/(Y11+Z11)-1,0) | AU16: FY26 Adjusted EBITDA margin (excl. tariff refund) | AV16: 0.2 | AW16: 0.1975 | AX16: 0.195 | AY16: Guided 19.5–20.0% (1H/26 20.3%).
B17: % of net sales | C17: =IF(AND(ISNUMBER(C11),ISNUMBER(C38)),IFERROR(C11/C38,""),"") | D17: =IF(AND(ISNUMBER(D11),ISNUMBER(D38)),IFERROR(D11/D38,""),"") | E17: =IF(AND(ISNUMBER(E11),ISNUMBER(E38)),IFERROR(E11/E38,""),"") | F17: =IF(AND(ISNUMBER(F11),ISNUMBER(F38)),IFERROR(F11/F38,""),"") | G17: =IF(AND(ISNUMBER(G11),ISNUMBER(G38)),IFERROR(G11/G38,""),"") | H17: =IF(AND(ISNUMBER(H11),ISNUMBER(H38)),IFERROR(H11/H38,""),"") | I17: =IF(AND(ISNUMBER(I11),ISNUMBER(I38)),IFERROR(I11/I38,""),"") | J17: =IF(AND(ISNUMBER(J11),ISNUMBER(J38)),IFERROR(J11/J38,""),"") | ... AL17: =IF(AND(ISNUMBER(AL11),ISNUMBER(AL38)),IFERROR(AL11/AL38,""),"") | AO17: =IFERROR(AVERAGE(AH17,AI17,AJ17,AK17,AL17),"n/m") | AP17: =IFERROR(AVERAGE(I17,N17,S17,X17,AC17),"n/m") | AQ17: =IFERROR(AVERAGE(S17,X17,AC17),"n/m") | AR17: =IFERROR(AVERAGE(C17,D17,I17,N17,S17,X17,AC17),"n/m") | AU17: Q3-26 tariff refund in gross profit (CHF m) | AV17: 53 | AW17: 53 | AX17: 40 | AY17: Up to USD 65m / CHF 53m expected in Q3-26 (Investor Day); Bear assumes partial recovery.
AU18: Q4-26 share repurchases (USD m) | AV18: 120 | AW18: 77 | AX18: 40 | AY18: USD 1bn authorization (22-Sep-26 to Dec-29); Base = 1/13 of the programme per quarter.
B19: Europe, Middle East & Africa (incl. home market Switzerland, Germany, UK) | AM19: EUROPE, MIDDLE EAST & AFRICA (EMEA) — modelling logic
B20: Net sales (CHF m) | I20: 264.3 | J20: 78.4 | K20: 88.1 | L20: 120.1 | M20: 91.5 | N20: 378.1 | O20: 118.9 | P20: 113.6 | Q20: 144 | R20: 112.4 | S20: 488.7 | T20: 126.2 | U20: 138.4 | V20: 165.8 | W20: 147.4 | X20: 577.8 | Y20: 168.6 | Z20: 197.8 | AA20: 213.3 | AB20: 183 | AC20: 762.7 | AD20: 207.1 | AE20: 228.2 | AF20: =AA20*(1+AF22+AF23) | AG20: =AB20*(1+AG22+AG23) | AH20: =SUM(AD20,AE20,AF20,AG20) | AI20: =AH20*(1+AI22+AI23) | AJ20: =AI20*(1+AJ22+AJ23) | AK20: =AJ20*(1+AK22+AK23) | AL20: =AK20*(1+AL22+AL23) | AO20: =IFERROR((AL20/AC20)^(1/5)-1,"n/m") | AP20: =IFERROR((AC20/D20)^(1/5)-1,"n/m") | AQ20: =IFERROR((AC20/N20)^(1/3)-1,"n/m") | AR20: =IFERROR((AC20/C20)^(1/6)-1,"n/m") | AU20: FY26 point estimates (all cases)
B21: y/y % (reported, CHF) | D21: =IF(AND(ISNUMBER(D20),ISNUMBER(C20)),IFERROR(D20/C20-1,""),"") | I21: =IF(AND(ISNUMBER(I20),ISNUMBER(D20)),IFERROR(I20/D20-1,""),"") | J21: =IF(AND(ISNUMBER(J20),ISNUMBER(E20)),IFERROR(J20/E20-1,""),"") | K21: =IF(AND(ISNUMBER(K20),ISNUMBER(F20)),IFERROR(K20/F20-1,""),"") | L21: =IF(AND(ISNUMBER(L20),ISNUMBER(G20)),IFERROR(L20/G20-1,""),"") | M21: =IF(AND(ISNUMBER(M20),ISNUMBER(H20)),IFERROR(M20/H20-1,""),"") | N21: =IF(AND(ISNUMBER(N20),ISNUMBER(I20)),IFERROR(N20/I20-1,""),"") | O21: =IF(AND(ISNUMBER(O20),ISNUMBER(J20)),IFERROR(O20/J20-1,""),"") | P21: =IF(AND(ISNUMBER(P20),ISNUMBER(K20)),IFERROR(P20/K20-1,""),"") | ... AH21: =IF(AND(ISNUMBER(AH20),ISNUMBER(AC20)),IFERROR(AH20/AC20-1,""),"") | AI21: =IF(AND(ISNUMBER(AI20),ISNUMBER(AH20)),IFERROR(AI20/AH20-1,""),"") | AJ21: =IF(AND(ISNUMBER(AJ20),ISNUMBER(AI20)),IFERROR(AJ20/AI20-1,""),"") | AK21: =IF(AND(ISNUMBER(AK20),ISNUMBER(AJ20)),IFERROR(AK20/AJ20-1,""),"") | AL21: =IF(AND(ISNUMBER(AL20),ISNUMBER(AK20)),IFERROR(AL20/AK20-1,""),"") | AU21: D&A (CHF m) | AW21: 150 | AY21: Not guided; 1H/26 CHF 71.9m (FY25 127.4m; ~62% right-of-use depreciation).
B22: y/y % constant currency | T22: 0.104 | U22: 0.222 | V22: 0.152 | W22: 0.331 | X22: 0.199 | Y22: 0.33 | Z22: 0.461 | AA22: 0.33 | AB22: 0.275 | AC22: 0.347 | AD22: 0.256 | AE22: 0.205 | AF22: =AF25+AF47 | AG22: =AG25+AG47 | AH22: =IFERROR(AH24/AC20-1,"") | AI22: =CHOOSE(MATCH($AM$2,{"Bull","Base","Bear"},0),$AV$35,$AW$35,$AX$35) | AJ22: =CHOOSE(MATCH($AM$2,{"Bull","Base","Bear"},0),$AV$36,$AW$36,$AX$36) | AK22: =CHOOSE(MATCH($AM$2,{"Bull","Base","Bear"},0),$AV$37,$AW$37,$AX$37) | AL22: =CHOOSE(MATCH($AM$2,{"Bull","Base","Bear"},0),$AV$38,$AW$38,$AX$38) | AU22: Share-based compensation (CHF m) | AW22: 66 | AY22: Not guided; 1H/26 CHF 33.5m (FY25 62.6m).
B23: FX translation effect (pts; reported − constant currency) | C23: =IF(AND(ISNUMBER(C21),ISNUMBER(C22)),C21-C22,"") | D23: =IF(AND(ISNUMBER(D21),ISNUMBER(D22)),D21-D22,"") | E23: =IF(AND(ISNUMBER(E21),ISNUMBER(E22)),E21-E22,"") | F23: =IF(AND(ISNUMBER(F21),ISNUMBER(F22)),F21-F22,"") | G23: =IF(AND(ISNUMBER(G21),ISNUMBER(G22)),G21-G22,"") | H23: =IF(AND(ISNUMBER(H21),ISNUMBER(H22)),H21-H22,"") | I23: =IF(AND(ISNUMBER(I21),ISNUMBER(I22)),I21-I22,"") | J23: =IF(AND(ISNUMBER(J21),ISNUMBER(J22)),J21-J22,"") | ... AE23: =IF(AND(ISNUMBER(AE21),ISNUMBER(AE22)),AE21-AE22,"") | AF23: =$AF$51 | AG23: =$AF$51 | AH23: =IF(AND(ISNUMBER(AH21),ISNUMBER(AH22)),AH21-AH22,"") | AI23: 0 | AJ23: 0 | AK23: 0 | AL23: 0 | AU23: Financial income (CHF m) | AW23: 36 | AY23: 1H/26 CHF 18.3m on ~CHF 1.1bn average cash.
B24: Memo: constant-currency net sales (prior-year period × (1 + cc growth)) | D24: =IF(AND(ISNUMBER(D22),ISNUMBER(C20)),C20*(1+D22),"") | I24: =IF(AND(ISNUMBER(I22),ISNUMBER(D20)),D20*(1+I22),"") | J24: =IF(AND(ISNUMBER(J22),ISNUMBER(E20)),E20*(1+J22),"") | K24: =IF(AND(ISNUMBER(K22),ISNUMBER(F20)),F20*(1+K22),"") | L24: =IF(AND(ISNUMBER(L22),ISNUMBER(G20)),G20*(1+L22),"") | M24: =IF(AND(ISNUMBER(M22),ISNUMBER(H20)),H20*(1+M22),"") | N24: =IF(AND(ISNUMBER(N22),ISNUMBER(I20)),I20*(1+N22),"") | O24: =IF(AND(ISNUMBER(O22),ISNUMBER(J20)),J20*(1+O22),"") | P24: =IF(AND(ISNUMBER(P22),ISNUMBER(K20)),K20*(1+P22),"") | ... AG24: =IF(AND(ISNUMBER(AG22),ISNUMBER(AB20)),AB20*(1+AG22),"") | AH24: =SUM(AD24:AG24) | AI24: =IF(AND(ISNUMBER(AI22),ISNUMBER(AH20)),AH20*(1+AI22),"") | AJ24: =IF(AND(ISNUMBER(AJ22),ISNUMBER(AI20)),AI20*(1+AJ22),"") | AK24: =IF(AND(ISNUMBER(AK22),ISNUMBER(AJ20)),AJ20*(1+AK22),"") | AL24: =IF(AND(ISNUMBER(AL22),ISNUMBER(AK20)),AK20*(1+AL22),"") | AU24: Financial expenses (CHF m) | AW24: 34 | AY24: 1H/26 CHF 16.3m (mostly lease interest).
B25: Q3/Q4-26E cc growth before calibration (1H/26 constant-currency growth) | AF25: =IFERROR((AD24+AE24)/(Y20+Z20)-1,0) | AG25: =IFERROR((AD24+AE24)/(Y20+Z20)-1,0) | AU25: Tax rate (Q3/Q4-26E) | AW25: 0.16 | AY25: 1H/26 13.9%, Q2-26 16.5%; FY24 13.4%.
B26: % of net sales | C26: =IF(AND(ISNUMBER(C20),ISNUMBER(C38)),IFERROR(C20/C38,""),"") | D26: =IF(AND(ISNUMBER(D20),ISNUMBER(D38)),IFERROR(D20/D38,""),"") | E26: =IF(AND(ISNUMBER(E20),ISNUMBER(E38)),IFERROR(E20/E38,""),"") | F26: =IF(AND(ISNUMBER(F20),ISNUMBER(F38)),IFERROR(F20/F38,""),"") | G26: =IF(AND(ISNUMBER(G20),ISNUMBER(G38)),IFERROR(G20/G38,""),"") | H26: =IF(AND(ISNUMBER(H20),ISNUMBER(H38)),IFERROR(H20/H38,""),"") | I26: =IF(AND(ISNUMBER(I20),ISNUMBER(I38)),IFERROR(I20/I38,""),"") | J26: =IF(AND(ISNUMBER(J20),ISNUMBER(J38)),IFERROR(J20/J38,""),"") | ... AL26: =IF(AND(ISNUMBER(AL20),ISNUMBER(AL38)),IFERROR(AL20/AL38,""),"") | AO26: =IFERROR(AVERAGE(AH26,AI26,AJ26,AK26,AL26),"n/m") | AP26: =IFERROR(AVERAGE(I26,N26,S26,X26,AC26),"n/m") | AQ26: =IFERROR(AVERAGE(S26,X26,AC26),"n/m") | AR26: =IFERROR(AVERAGE(C26,D26,I26,N26,S26,X26,AC26),"n/m") | AU26: Capital expenditures (CHF m) | AW26: 100 | AY26: Not guided; 1H/26 CHF 47.2m (FY25 78.6m; ~2.8% of sales).
AU27: Lease principal payments (CHF m) | AW27: 76 | AY27: 1H/26 CHF 35.8m (FY25 69.9m).
B28: Asia-Pacific (Greater China, Japan, South Korea, Australia) | AM28: ASIA-PACIFIC (APAC) — modelling logic
B29: Net sales (CHF m) | I29: 42.7 | J29: 16.4 | K29: 17.9 | L29: 24.2 | M29: 21.6 | N29: 80.2 | O29: 31.1 | P29: 34.1 | Q29: 41.6 | R29: 34.1 | S29: 141.1 | T29: 52.4 | U29: 59.2 | V29: 74.6 | W29: 74.1 | X29: 260.2 | Y29: 120.6 | Z29: 119.2 | AA29: 144.9 | AB29: 126.5 | AC29: 511.1 | AD29: 174 | AE29: 170.5 | AF29: =AA29*(1+AF31+AF32) | AG29: =AB29*(1+AG31+AG32) | AH29: =SUM(AD29,AE29,AF29,AG29) | AI29: =AH29*(1+AI31+AI32) | AJ29: =AI29*(1+AJ31+AJ32) | AK29: =AJ29*(1+AK31+AK32) | AL29: =AK29*(1+AL31+AL32) | AO29: =IFERROR((AL29/AC29)^(1/5)-1,"n/m") | AP29: =IFERROR((AC29/D29)^(1/5)-1,"n/m") | AQ29: =IFERROR((AC29/N29)^(1/3)-1,"n/m") | AR29: =IFERROR((AC29/C29)^(1/6)-1,"n/m") | AU29: AM_CC (Americas net sales growth, constant currency) | AV29: 0.03 | AW29: Δ → | AX29: -0.06 | AY29: Q2-26 +13.0% cc (wholesale sell-in managed); US premium running share gains, DTC / own stores, new categories (football, golf).
B30: y/y % (reported, CHF) | D30: =IF(AND(ISNUMBER(D29),ISNUMBER(C29)),IFERROR(D29/C29-1,""),"") | I30: =IF(AND(ISNUMBER(I29),ISNUMBER(D29)),IFERROR(I29/D29-1,""),"") | J30: =IF(AND(ISNUMBER(J29),ISNUMBER(E29)),IFERROR(J29/E29-1,""),"") | K30: =IF(AND(ISNUMBER(K29),ISNUMBER(F29)),IFERROR(K29/F29-1,""),"") | L30: =IF(AND(ISNUMBER(L29),ISNUMBER(G29)),IFERROR(L29/G29-1,""),"") | M30: =IF(AND(ISNUMBER(M29),ISNUMBER(H29)),IFERROR(M29/H29-1,""),"") | N30: =IF(AND(ISNUMBER(N29),ISNUMBER(I29)),IFERROR(N29/I29-1,""),"") | O30: =IF(AND(ISNUMBER(O29),ISNUMBER(J29)),IFERROR(O29/J29-1,""),"") | P30: =IF(AND(ISNUMBER(P29),ISNUMBER(K29)),IFERROR(P29/K29-1,""),"") | ... AH30: =IF(AND(ISNUMBER(AH29),ISNUMBER(AC29)),IFERROR(AH29/AC29-1,""),"") | AI30: =IF(AND(ISNUMBER(AI29),ISNUMBER(AH29)),IFERROR(AI29/AH29-1,""),"") | AJ30: =IF(AND(ISNUMBER(AJ29),ISNUMBER(AI29)),IFERROR(AJ29/AI29-1,""),"") | AK30: =IF(AND(ISNUMBER(AK29),ISNUMBER(AJ29)),IFERROR(AK29/AJ29-1,""),"") | AL30: =IF(AND(ISNUMBER(AL29),ISNUMBER(AK29)),IFERROR(AL29/AK29-1,""),"") | AU30: 2027E | AV30: =AW30+$AV$29 | AW30: 0.14 | AX30: =AW30+$AX$29
B31: y/y % constant currency | T31: 0.907 | U31: 0.847 | V31: 0.857 | W31: 1.246 | X31: 0.956 | Y31: 1.289 | Z31: 1.109 | AA31: 1.092 | AB31: 0.851 | AC31: 1.067 | AD31: 0.614 | AE31: 0.547 | AF31: =AF34+AF47 | AG31: =AG34+AG47 | AH31: =IFERROR(AH33/AC29-1,"") | AI31: =CHOOSE(MATCH($AM$2,{"Bull","Base","Bear"},0),$AV$40,$AW$40,$AX$40) | AJ31: =CHOOSE(MATCH($AM$2,{"Bull","Base","Bear"},0),$AV$41,$AW$41,$AX$41) | AK31: =CHOOSE(MATCH($AM$2,{"Bull","Base","Bear"},0),$AV$42,$AW$42,$AX$42) | AL31: =CHOOSE(MATCH($AM$2,{"Bull","Base","Bear"},0),$AV$43,$AW$43,$AX$43) | AU31: 2028E | AV31: =AW31+$AV$29 | AW31: 0.135 | AX31: =AW31+$AX$29
B32: FX translation effect (pts; reported − constant currency) | C32: =IF(AND(ISNUMBER(C30),ISNUMBER(C31)),C30-C31,"") | D32: =IF(AND(ISNUMBER(D30),ISNUMBER(D31)),D30-D31,"") | E32: =IF(AND(ISNUMBER(E30),ISNUMBER(E31)),E30-E31,"") | F32: =IF(AND(ISNUMBER(F30),ISNUMBER(F31)),F30-F31,"") | G32: =IF(AND(ISNUMBER(G30),ISNUMBER(G31)),G30-G31,"") | H32: =IF(AND(ISNUMBER(H30),ISNUMBER(H31)),H30-H31,"") | I32: =IF(AND(ISNUMBER(I30),ISNUMBER(I31)),I30-I31,"") | J32: =IF(AND(ISNUMBER(J30),ISNUMBER(J31)),J30-J31,"") | ... AE32: =IF(AND(ISNUMBER(AE30),ISNUMBER(AE31)),AE30-AE31,"") | AF32: =$AF$51 | AG32: =$AF$51 | AH32: =IF(AND(ISNUMBER(AH30),ISNUMBER(AH31)),AH30-AH31,"") | AI32: 0 | AJ32: 0 | AK32: 0 | AL32: 0 | AU32: 2029E | AV32: =AW32+$AV$29 | AW32: 0.13 | AX32: =AW32+$AX$29
B33: Memo: constant-currency net sales (prior-year period × (1 + cc growth)) | D33: =IF(AND(ISNUMBER(D31),ISNUMBER(C29)),C29*(1+D31),"") | I33: =IF(AND(ISNUMBER(I31),ISNUMBER(D29)),D29*(1+I31),"") | J33: =IF(AND(ISNUMBER(J31),ISNUMBER(E29)),E29*(1+J31),"") | K33: =IF(AND(ISNUMBER(K31),ISNUMBER(F29)),F29*(1+K31),"") | L33: =IF(AND(ISNUMBER(L31),ISNUMBER(G29)),G29*(1+L31),"") | M33: =IF(AND(ISNUMBER(M31),ISNUMBER(H29)),H29*(1+M31),"") | N33: =IF(AND(ISNUMBER(N31),ISNUMBER(I29)),I29*(1+N31),"") | O33: =IF(AND(ISNUMBER(O31),ISNUMBER(J29)),J29*(1+O31),"") | P33: =IF(AND(ISNUMBER(P31),ISNUMBER(K29)),K29*(1+P31),"") | ... AG33: =IF(AND(ISNUMBER(AG31),ISNUMBER(AB29)),AB29*(1+AG31),"") | AH33: =SUM(AD33:AG33) | AI33: =IF(AND(ISNUMBER(AI31),ISNUMBER(AH29)),AH29*(1+AI31),"") | AJ33: =IF(AND(ISNUMBER(AJ31),ISNUMBER(AI29)),AI29*(1+AJ31),"") | AK33: =IF(AND(ISNUMBER(AK31),ISNUMBER(AJ29)),AJ29*(1+AK31),"") | AL33: =IF(AND(ISNUMBER(AL31),ISNUMBER(AK29)),AK29*(1+AL31),"") | AU33: 2030E | AV33: =AW33+$AV$29 | AW33: 0.11 | AX33: =AW33+$AX$29
B34: Q3/Q4-26E cc growth before calibration (1H/26 constant-currency growth) | AF34: =IFERROR((AD33+AE33)/(Y29+Z29)-1,0) | AG34: =IFERROR((AD33+AE33)/(Y29+Z29)-1,0) | AU34: EMEA_CC (EMEA net sales growth, constant currency) | AV34: 0.03 | AW34: Δ → | AX34: -0.06 | AY34: 1H/26 +22.8% cc; under-penetrated markets (UK, France, Italy, Nordics) and apparel.
B35: % of net sales | C35: =IF(AND(ISNUMBER(C29),ISNUMBER(C38)),IFERROR(C29/C38,""),"") | D35: =IF(AND(ISNUMBER(D29),ISNUMBER(D38)),IFERROR(D29/D38,""),"") | E35: =IF(AND(ISNUMBER(E29),ISNUMBER(E38)),IFERROR(E29/E38,""),"") | F35: =IF(AND(ISNUMBER(F29),ISNUMBER(F38)),IFERROR(F29/F38,""),"") | G35: =IF(AND(ISNUMBER(G29),ISNUMBER(G38)),IFERROR(G29/G38,""),"") | H35: =IF(AND(ISNUMBER(H29),ISNUMBER(H38)),IFERROR(H29/H38,""),"") | I35: =IF(AND(ISNUMBER(I29),ISNUMBER(I38)),IFERROR(I29/I38,""),"") | J35: =IF(AND(ISNUMBER(J29),ISNUMBER(J38)),IFERROR(J29/J38,""),"") | ... AL35: =IF(AND(ISNUMBER(AL29),ISNUMBER(AL38)),IFERROR(AL29/AL38,""),"") | AO35: =IFERROR(AVERAGE(AH35,AI35,AJ35,AK35,AL35),"n/m") | AP35: =IFERROR(AVERAGE(I35,N35,S35,X35,AC35),"n/m") | AQ35: =IFERROR(AVERAGE(S35,X35,AC35),"n/m") | AR35: =IFERROR(AVERAGE(C35,D35,I35,N35,S35,X35,AC35),"n/m") | AU35: 2027E | AV35: =AW35+$AV$34 | AW35: 0.19 | AX35: =AW35+$AX$34
AU36: 2028E | AV36: =AW36+$AV$34 | AW36: 0.18 | AX36: =AW36+$AX$34
B37: Group Total — net sales (region build) → FY26 outlook calibration (constant-currency growth, CHF net sales, Q3 guide) | AM37: GROUP TOTAL (CONSOLIDATED) — modelling logic | AU37: 2029E | AV37: =AW37+$AV$34 | AW37: 0.17 | AX37: =AW37+$AX$34
B38: Net sales (region build) | C38: =IF(ISNUMBER(C11),N(C11)+N(C20)+N(C29),C109) | D38: =IF(ISNUMBER(D11),N(D11)+N(D20)+N(D29),D109) | E38: =IF(ISNUMBER(E11),N(E11)+N(E20)+N(E29),E109) | F38: =IF(ISNUMBER(F11),N(F11)+N(F20)+N(F29),F109) | G38: =IF(ISNUMBER(G11),N(G11)+N(G20)+N(G29),G109) | H38: =IF(ISNUMBER(H11),N(H11)+N(H20)+N(H29),H109) | I38: =IF(ISNUMBER(I11),N(I11)+N(I20)+N(I29),I109) | J38: =IF(ISNUMBER(J11),N(J11)+N(J20)+N(J29),J109) | ... AE38: =IF(ISNUMBER(AE11),N(AE11)+N(AE20)+N(AE29),AE109) | AF38: =AF11+AF20+AF29 | AG38: =AG11+AG20+AG29 | AH38: =AH11+AH20+AH29 | AI38: =AI11+AI20+AI29 | AJ38: =AJ11+AJ20+AJ29 | AK38: =AK11+AK20+AK29 | AL38: =AL11+AL20+AL29 | AM38: Σ Americas + EMEA + APAC. FY2019–20 and 2021 quarters (former Europe / North America / APAC / RoW regions only) = reported net sales. | AO38: =IFERROR((AL38/AC38)^(1/5)-1,"n/m") | AP38: =IFERROR((AC38/D38)^(1/5)-1,"n/m") | AQ38: =IFERROR((AC38/N38)^(1/3)-1,"n/m") | AR38: =IFERROR((AC38/C38)^(1/6)-1,"n/m") | AU38: 2030E | AV38: =AW38+$AV$34 | AW38: 0.14 | AX38: =AW38+$AX$34
B39: Net sales y/y % (reported, CHF) | D39: =IF(AND(ISNUMBER(D38),ISNUMBER(C38)),IFERROR(D38/C38-1,""),"") | I39: =IF(AND(ISNUMBER(I38),ISNUMBER(D38)),IFERROR(I38/D38-1,""),"") | J39: =IF(AND(ISNUMBER(J38),ISNUMBER(E38)),IFERROR(J38/E38-1,""),"") | K39: =IF(AND(ISNUMBER(K38),ISNUMBER(F38)),IFERROR(K38/F38-1,""),"") | L39: =IF(AND(ISNUMBER(L38),ISNUMBER(G38)),IFERROR(L38/G38-1,""),"") | M39: =IF(AND(ISNUMBER(M38),ISNUMBER(H38)),IFERROR(M38/H38-1,""),"") | N39: =IF(AND(ISNUMBER(N38),ISNUMBER(I38)),IFERROR(N38/I38-1,""),"") | O39: =IF(AND(ISNUMBER(O38),ISNUMBER(J38)),IFERROR(O38/J38-1,""),"") | P39: =IF(AND(ISNUMBER(P38),ISNUMBER(K38)),IFERROR(P38/K38-1,""),"") | ... AH39: =IF(AND(ISNUMBER(AH38),ISNUMBER(AC38)),IFERROR(AH38/AC38-1,""),"") | AI39: =IF(AND(ISNUMBER(AI38),ISNUMBER(AH38)),IFERROR(AI38/AH38-1,""),"") | AJ39: =IF(AND(ISNUMBER(AJ38),ISNUMBER(AI38)),IFERROR(AJ38/AI38-1,""),"") | AK39: =IF(AND(ISNUMBER(AK38),ISNUMBER(AJ38)),IFERROR(AK38/AJ38-1,""),"") | AL39: =IF(AND(ISNUMBER(AL38),ISNUMBER(AK38)),IFERROR(AL38/AK38-1,""),"") | AU39: APAC_CC (Asia-Pacific net sales growth, constant currency) | AV39: 0.04 | AW39: Δ → | AX39: -0.1 | AY39: 1H/26 +58.1% cc; Greater China, Japan, South Korea; >20% of group sales. Fades from very high growth.
B40: Check: region build vs consolidated net sales (should be 0) | C40: =IF(ISNUMBER(C38),IF(ABS(C38-C109)<=0.25,0,ROUND(C38-C109,1)),"") | D40: =IF(ISNUMBER(D38),IF(ABS(D38-D109)<=0.25,0,ROUND(D38-D109,1)),"") | E40: =IF(ISNUMBER(E38),IF(ABS(E38-E109)<=0.25,0,ROUND(E38-E109,1)),"") | F40: =IF(ISNUMBER(F38),IF(ABS(F38-F109)<=0.25,0,ROUND(F38-F109,1)),"") | G40: =IF(ISNUMBER(G38),IF(ABS(G38-G109)<=0.25,0,ROUND(G38-G109,1)),"") | H40: =IF(ISNUMBER(H38),IF(ABS(H38-H109)<=0.25,0,ROUND(H38-H109,1)),"") | I40: =IF(ISNUMBER(I38),IF(ABS(I38-I109)<=0.25,0,ROUND(I38-I109,1)),"") | J40: =IF(ISNUMBER(J38),IF(ABS(J38-J109)<=0.25,0,ROUND(J38-J109,1)),"") | ... AL40: =IF(ISNUMBER(AL38),IF(ABS(AL38-AL109)<=0.25,0,ROUND(AL38-AL109,1)),"") | AU40: 2027E | AV40: =AW40+$AV$39 | AW40: 0.3 | AX40: =AW40+$AX$39
...

Sheet Bull-Base-Bear
B2: On Holding (ONON) — Bull / Base / Bear Case P&L Summary | J2: Share price (CHF): | K2: =Model!$AH$350
B3: Adjusted figures (company definitions: Adjusted EBITDA excl. SBC; adjusted EPS Class A on Class A-equivalent shares) · CHF millions · Live panel linked to Model — toggle scenario via Model!AM2. Bull and Bear panels are value snapshots generated from the Model with the switch set to each case. 2026E reported figures include the Q3-26 tariff refund (row 35 excludes it, as guided). Price target / IRR in CHF (USD price × USD/CHF). | J3: As of: | K3: =TODAY()
B5: Scenario: | C5: =Model!$AM$2 | N5: Scenario: | O5: Bull | P5: Snapshot (values) — Model run with switch = Bull | Z5: Scenario: | AA5: Bear | AB5: Snapshot (values) — Model run with switch = Bear
B7: (CHFm, except EPS and shares) | C7: 2025A | D7: 2026E | E7: 2027E | F7: 2028E | G7: 2029E | H7: 2030E | I7: 25-'30 CAGR | J7: LT Hist Avg | K7: LT Hist Min | L7: LT Hist Max | N7: (CHFm, except EPS and shares) | O7: 2025A | P7: 2026E | Q7: 2027E | R7: 2028E | S7: 2029E | T7: 2030E | U7: 25-'30 CAGR | V7: LT Hist Avg | W7: LT Hist Min | X7: LT Hist Max | Z7: (CHFm, except EPS and shares) | AA7: 2025A | AB7: 2026E | AC7: 2027E | AD7: 2028E | AE7: 2029E | AF7: 2030E | AG7: 25-'30 CAGR | AH7: LT Hist Avg | AI7: LT Hist Min | AJ7: LT Hist Max
B9: Net Sales (CHF m) | C9: =Model!AC109 | D9: =Model!AH109 | E9: =Model!AI109 | F9: =Model!AJ109 | G9: =Model!AK109 | H9: =Model!AL109 | I9: =IFERROR((H9/C9)^(1/5)-1,"n/m") | N9: Net Sales (CHF m) | O9: 3014 | P9: 3560.1 | Q9: 4340.994 | R9: 5256.1329 | S9: 6312.2925 | T9: 7399.3566 | U9: 0.19676848 | Z9: Net Sales (CHF m) | AA9: 3014 | AB9: 3470.1 | AC9: 3882.1047 | AD9: 4304.0191 | AE9: 4724.0568 | AF9: 5045.767 | AG9: 0.10855384
B10: Net sales y/y % (reported) | D10: =IFERROR(D9/C9-1,"") | E10: =IFERROR(E9/D9-1,"") | F10: =IFERROR(F9/E9-1,"") | G10: =IFERROR(G9/F9-1,"") | H10: =IFERROR(H9/G9-1,"") | N10: Net sales y/y % (reported) | P10: 0.18118779 | Q10: 0.2193461 | R10: 0.21081319 | S10: 0.20093854 | T10: 0.17221383 | Z10: Net sales y/y % (reported) | AB10: 0.15132714 | AC10: 0.11872992 | AD10: 0.10868187 | AE10: 0.097591973 | AF10: 0.068100411
B11: Net sales y/y % (constant currency) | C11: =Model!AC194 | D11: =Model!AH194 | E11: =Model!AI194 | F11: =Model!AJ194 | G11: =Model!AK194 | H11: =Model!AL194 | N11: Net sales y/y % (constant currency) | O11: 0.35565725 | P11: 0.23 | Q11: 0.21938035 | R11: 0.21081319 | S11: 0.20093854 | T11: 0.17221383 | Z11: Net sales y/y % (constant currency) | AA11: 0.35565725 | AB11: 0.2 | AC11: 0.11876216 | AD11: 0.10868187 | AE11: 0.097591973 | AF11: 0.068100411
B12: Adjusted EBITDA (company definition) | C12: =Model!AC150 | D12: =Model!AH150 | E12: =Model!AI150 | F12: =Model!AJ150 | G12: =Model!AK150 | H12: =Model!AL150 | I12: =IFERROR((H12/C12)^(1/5)-1,"n/m") | N12: Adjusted EBITDA (company definition) | O12: 567 | P12: 765.02 | Q12: 933.31372 | R12: 1166.8615 | S12: 1451.8273 | T12: 1738.8488 | U12: 0.25122598 | Z12: Adjusted EBITDA (company definition) | AA12: 567 | AB12: 716.6695 | AC12: 698.77885 | AD12: 804.85157 | AE12: 921.19108 | AF12: 1009.1534 | AG12: 0.12221179
B13: Adjusted EBITDA margin % | C13: =IFERROR(C12/C9,"") | D13: =IFERROR(D12/D9,"") | E13: =IFERROR(E12/E9,"") | F13: =IFERROR(F12/F9,"") | G13: =IFERROR(G12/G9,"") | H13: =IFERROR(H12/H9,"") | J13: =IFERROR(AVERAGE(Model!C151,Model!D151,Model!I151,Model!N151,Model!S151,Model!X151,Model!AC151),"") | K13: =IFERROR(MIN(Model!C151,Model!D151,Model!I151,Model!N151,Model!S151,Model!X151,Model!AC151),"") | L13: =IFERROR(MAX(Model!C151,Model!D151,Model!I151,Model!N151,Model!S151,Model!X151,Model!AC151),"") | N13: Adjusted EBITDA margin % | O13: 0.1881221 | P13: 0.21488722 | Q13: 0.215 | R13: 0.222 | S13: 0.23 | T13: 0.235 | V13: 0.14386155 | W13: 0.11181866 | X13: 0.1881221 | Z13: Adjusted EBITDA margin % | AA13: 0.1881221 | AB13: 0.20652705 | AC13: 0.18 | AD13: 0.187 | AE13: 0.195 | AF13: 0.2 | AH13: 0.14386155 | AI13: 0.11181866 | AJ13: 0.1881221
B15: Operating Result (IFRS) | C15: =Model!AC114 | D15: =Model!AH114 | E15: =Model!AI114 | F15: =Model!AJ114 | G15: =Model!AK114 | H15: =Model!AL114 | I15: =IFERROR((H15/C15)^(1/5)-1,"n/m") | N15: Operating Result (IFRS) | O15: 377 | P15: 549.02 | Q15: 664.17209 | R15: 840.98126 | S15: 1060.4651 | T15: 1280.0887 | U15: 0.2769672 | Z15: Operating Result (IFRS) | AA15: 377 | AB15: 500.6695 | AC15: 458.08836 | AD15: 538.00239 | AE15: 628.29955 | AF15: 696.31585 | AG15: 0.13055836
B16: Operating result y/y % | D16: =IFERROR(D15/C15-1,"") | E16: =IFERROR(E15/D15-1,"") | F16: =IFERROR(F15/E15-1,"") | G16: =IFERROR(G15/F15-1,"") | H16: =IFERROR(H15/G15-1,"") | N16: Operating result y/y % | P16: 0.45628647 | Q16: 0.20974115 | R16: 0.26620988 | S16: 0.26098547 | T16: 0.20710114 | Z16: Operating result y/y % | AB16: 0.32803581 | AC16: -0.085048409 | AD16: 0.17445113 | AE16: 0.16783786 | AF16: 0.10825456
B17: Operating margin (IFRS) % | C17: =IFERROR(C15/C9,"") | D17: =IFERROR(D15/D9,"") | E17: =IFERROR(E15/E9,"") | F17: =IFERROR(F15/F9,"") | G17: =IFERROR(G15/G9,"") | H17: =IFERROR(H15/H9,"") | J17: =IFERROR(AVERAGE(Model!C204,Model!D204,Model!I204,Model!N204,Model!S204,Model!X204,Model!AC204),"") | K17: =IFERROR(MIN(Model!C204,Model!D204,Model!I204,Model!N204,Model!S204,Model!X204,Model!AC204),"") | L17: =IFERROR(MAX(Model!C204,Model!D204,Model!I204,Model!N204,Model!S204,Model!X204,Model!AC204),"") | N17: Operating margin (IFRS) % | O17: 0.12508295 | P17: 0.15421477 | Q17: 0.153 | R17: 0.16 | S17: 0.168 | T17: 0.173 | V17: 0.024704613 | W17: -0.19471536 | X17: 0.12508295 | Z17: Operating margin (IFRS) % | AA17: 0.12508295 | AB17: 0.144281 | AC17: 0.118 | AD17: 0.125 | AE17: 0.133 | AF17: 0.138 | AH17: 0.024704613 | AI17: -0.19471536 | AJ17: 0.12508295
B19: Adjusted Net Income (Class A + B) | C19: =Model!AC178 | D19: =Model!AH178 | E19: =Model!AI178 | F19: =Model!AJ178 | G19: =Model!AK178 | H19: =Model!AL178 | I19: =IFERROR((H19/C19)^(1/5)-1,"n/m") | N19: Adjusted Net Income (Class A + B) | O19: 266.2 | P19: 535.8648 | Q19: 638.74902 | R19: 801.29441 | S19: 1004.6561 | T19: 1212.1078 | U19: 0.35414959 | Z19: Adjusted Net Income (Class A + B) | AA19: 266.2 | AB19: 495.25038 | AC19: 460.24618 | AD19: 537.25641 | AE19: 624.93552 | AF19: 694.37848 | AG19: 0.21137231
B21: Diluted shares, Class A-equivalent (m) | C21: =Model!AC129 | D21: =Model!AH129 | E21: =Model!AI129 | F21: =Model!AJ129 | G21: =Model!AK129 | H21: =Model!AL129 | I21: =IFERROR((H21/C21)^(1/5)-1,"n/m") | N21: Diluted shares, Class A-equivalent (m) | O21: 333.85845 | P21: 335.49581 | Q21: 327.61202 | R21: 317.74798 | S21: 308.90149 | T21: 300.52116 | U21: -0.020819998 | Z21: Diluted shares, Class A-equivalent (m) | AA21: 333.85845 | AB21: 335.80831 | AC21: 333.66316 | AD21: 330.57855 | AE21: 327.8952 | AF21: 325.11771 | AG21: -0.00529191
B23: Adjusted EPS — Diluted, Class A (CHF) | C23: =Model!AC182 | D23: =Model!AH182 | E23: =Model!AI182 | F23: =Model!AJ182 | G23: =Model!AK182 | H23: =Model!AL182 | I23: =IFERROR((H23/C23)^(1/5)-1,"n/m") | N23: Adjusted EPS — Diluted, Class A (CHF) | O23: 0.7973439 | P23: 1.5972325 | Q23: 1.9497118 | R23: 2.5217923 | S23: 3.2523511 | T23: 4.0333528 | U23: 0.38294245 | Z23: Adjusted EPS — Diluted, Class A (CHF) | AA23: 0.7973439 | AB23: 1.4748008 | AC23: 1.3793737 | AD23: 1.6252004 | AE23: 1.9059002 | AF23: 2.1357756 | AG23: 0.21781688
B24: EPS y/y % | D24: =IFERROR(D23/C23-1,"") | E24: =IFERROR(E23/D23-1,"") | F24: =IFERROR(F23/E23-1,"") | G24: =IFERROR(G23/F23-1,"") | H24: =IFERROR(H23/G23-1,"") | N24: EPS y/y % | P24: 1.0031914 | Q24: 0.22068129 | R24: 0.29341801 | S24: 0.28969823 | T24: 0.2401345 | Z24: EPS y/y % | AB24: 0.84964209 | AC24: -0.064705128 | AD24: 0.17821624 | AE24: 0.17271701 | AF24: 0.12061253
B26: P / E (x) — assumed (adjusted EPS) | F26: 25 | G26: 25 | H26: 25 | N26: P / E (x) — assumed (adjusted EPS) | R26: 32 | S26: 32 | T26: 32 | Z26: P / E (x) — assumed (adjusted EPS) | AD26: 16 | AE26: 16 | AF26: 16
B27: Price Target (CHF) | F27: =F26*F23 | G27: =G26*G23 | H27: =H26*H23 | N27: Price Target (CHF) | R27: =R26*R23 | S27: =S26*S23 | T27: =T26*T23 | Z27: Price Target (CHF) | AD27: =AD26*AD23 | AE27: =AE26*AE23 | AF27: =AF26*AF23
B28: Upside / (Downside) vs current | F28: =IFERROR(F27/$K$2-1,"") | G28: =IFERROR(G27/$K$2-1,"") | H28: =IFERROR(H27/$K$2-1,"") | N28: Upside / (Downside) vs current | R28: =IFERROR(R27/$K$2-1,"") | S28: =IFERROR(S27/$K$2-1,"") | T28: =IFERROR(T27/$K$2-1,"") | Z28: Upside / (Downside) vs current | AD28: =IFERROR(AD27/$K$2-1,"") | AE28: =IFERROR(AE27/$K$2-1,"") | AF28: =IFERROR(AF27/$K$2-1,"")
B29: IRR (to Dec-Y-1) | F29: =IFERROR((F27/$K$2)^(1/((DATE(2028-1,12,31)-$K$3)/365.25))-1,"") | G29: =IFERROR((G27/$K$2)^(1/((DATE(2029-1,12,31)-$K$3)/365.25))-1,"") | H29: =IFERROR((H27/$K$2)^(1/((DATE(2030-1,12,31)-$K$3)/365.25))-1,"") | N29: IRR (to Dec-Y-1) | R29: =IFERROR((R27/$K$2)^(1/((DATE(2028-1,12,31)-$K$3)/365.25))-1,"") | S29: =IFERROR((S27/$K$2)^(1/((DATE(2029-1,12,31)-$K$3)/365.25))-1,"") | T29: =IFERROR((T27/$K$2)^(1/((DATE(2030-1,12,31)-$K$3)/365.25))-1,"") | Z29: IRR (to Dec-Y-1) | AD29: =IFERROR((AD27/$K$2)^(1/((DATE(2028-1,12,31)-$K$3)/365.25))-1,"") | AE29: =IFERROR((AE27/$K$2)^(1/((DATE(2029-1,12,31)-$K$3)/365.25))-1,"") | AF29: =IFERROR((AF27/$K$2)^(1/((DATE(2030-1,12,31)-$K$3)/365.25))-1,"")
B31: Free Cash Flow | C31: =Model!AC233 | D31: =Model!AH233 | E31: =Model!AI233 | F31: =Model!AJ233 | G31: =Model!AK233 | H31: =Model!AL233 | I31: =IFERROR((H31/C31)^(1/5)-1,"n/m") | N31: Free Cash Flow | O31: 211 | P31: 461.25454 | Q31: 514.69221 | R31: 668.60927 | S31: 851.70725 | T31: 1047.2029 | U31: 0.37768419 | Z31: Free Cash Flow | AA31: 211 | AB31: 422.50479 | AC31: 380.14637 | AD31: 470.27076 | AE31: 557.88396 | AF31: 636.1074 | AG31: 0.24695161
B32: FCF % | C32: =IFERROR(C31/C9,"") | D32: =IFERROR(D31/D9,"") | E32: =IFERROR(E31/E9,"") | F32: =IFERROR(F31/F9,"") | G32: =IFERROR(G31/G9,"") | H32: =IFERROR(H31/H9,"") | J32: =IFERROR(AVERAGE(Model!C235,Model!D235,Model!I235,Model!N235,Model!S235,Model!X235,Model!AC235),"") | K32: =IFERROR(MIN(Model!C235,Model!D235,Model!I235,Model!N235,Model!S235,Model!X235,Model!AC235),"") | L32: =IFERROR(MAX(Model!C235,Model!D235,Model!I235,Model!N235,Model!S235,Model!X235,Model!AC235),"") | N32: FCF % | O32: 0.070006636 | P32: 0.12956224 | Q32: 0.11856552 | R32: 0.12720555 | S32: 0.13492836 | T32: 0.14152621 | V32: -0.011430444 | W32: -0.26626299 | X32: 0.17008153 | Z32: FCF % | AA32: 0.070006636 | AB32: 0.1217558 | AC32: 0.097922751 | AD32: 0.10926317 | AE32: 0.11809425 | AF32: 0.12606753 | AH32: -0.011430444 | AI32: -0.26626299 | AJ32: 0.17008153
B33: FCF / share ($) | C33: =IFERROR(C31/C21,"") | D33: =IFERROR(D31/D21,"") | E33: =IFERROR(E31/E21,"") | F33: =IFERROR(F31/F21,"") | G33: =IFERROR(G31/G21,"") | H33: =IFERROR(H31/H21,"") | N33: FCF / share ($) | O33: 0.63200437 | P33: 1.3748444 | Q33: 1.5710419 | R33: 2.1042125 | S33: 2.7572132 | T33: 3.4846228 | Z33: FCF / share ($) | AA33: 0.63200437 | AB33: 1.2581725 | AC33: 1.1393118 | AD33: 1.4225689 | AE33: 1.7014094 | AF33: 1.9565449
B34: FCF Yield (on PT) | F34: =IFERROR(F33/F$27,"") | G34: =IFERROR(G33/G$27,"") | H34: =IFERROR(H33/H$27,"") | N34: FCF Yield (on PT) | R34: =IFERROR(R33/R$27,"") | S34: =IFERROR(S33/S$27,"") | T34: =IFERROR(T33/T$27,"") | Z34: FCF Yield (on PT) | AD34: =IFERROR(AD33/AD$27,"") | AE34: =IFERROR(AE33/AE$27,"") | AF34: =IFERROR(AF33/AF$27,"")
B35: Adjusted EBITDA excl. tariff refund (guidance basis) | C35: =Model!AC155 | D35: =Model!AH155 | E35: =Model!AI155 | F35: =Model!AJ155 | G35: =Model!AK155 | H35: =Model!AL155 | I35: =IFERROR((H35/C35)^(1/5)-1,"n/m") | N35: Adjusted EBITDA excl. tariff refund (guidance basis) | O35: 567 | P35: 712.02 | Q35: 933.31372 | R35: 1166.8615 | S35: 1451.8273 | T35: 1738.8488 | U35: 0.25122598 | Z35: Adjusted EBITDA excl. tariff refund (guidance basis) | AA35: 567 | AB35: 676.6695 | AC35: 698.77885 | AD35: 804.85157 | AE35: 921.19108 | AF35: 1009.1534 | AG35: 0.12221179
B36: Adjusted EBITDA (excl. refund) % of net sales | C36: =IFERROR(C35/C9,"") | D36: =IFERROR(D35/D9,"") | E36: =IFERROR(E35/E9,"") | F36: =IFERROR(F35/F9,"") | G36: =IFERROR(G35/G9,"") | H36: =IFERROR(H35/H9,"") | J36: =IFERROR(AVERAGE(Model!C156,Model!D156,Model!I156,Model!N156,Model!S156,Model!X156,Model!AC156),"") | K36: =IFERROR(MIN(Model!C156,Model!D156,Model!I156,Model!N156,Model!S156,Model!X156,Model!AC156),"") | L36: =IFERROR(MAX(Model!C156,Model!D156,Model!I156,Model!N156,Model!S156,Model!X156,Model!AC156),"") | N36: Adjusted EBITDA (excl. refund) % of net sales | O36: 0.1881221 | P36: 0.2 | Q36: 0.215 | R36: 0.222 | S36: 0.23 | T36: 0.235 | V36: 0.14386155 | W36: 0.11181866 | X36: 0.1881221 | Z36: Adjusted EBITDA (excl. refund) % of net sales | AA36: 0.1881221 | AB36: 0.195 | AC36: 0.18 | AD36: 0.187 | AE36: 0.195 | AF36: 0.2 | AH36: 0.14386155 | AI36: 0.11181866 | AJ36: 0.1881221
B38: Net Debt incl. leases (negative = net cash) | C38: =Model!AC343 | D38: =Model!AH343 | E38: =Model!AI343 | F38: =Model!AJ343 | G38: =Model!AK343 | H38: =Model!AL343 | N38: Net Debt incl. leases (negative = net cash) | O38: -438.9 | P38: -737.44104 | Q38: -774.29593 | R38: -937.60282 | S38: -1255.1479 | T38: -1719.9947 | Z38: Net Debt incl. leases (negative = net cash) | AA38: -438.9 | AB38: -776.64129 | AC38: -936.89544 | AD38: -1182.2256 | AE38: -1512.6631 | AF38: -1898.584
B39: Net Debt / Adjusted EBITDA (x) | C39: =IFERROR(C38/C35,"") | D39: =IFERROR(D38/D35,"") | E39: =IFERROR(E38/E35,"") | F39: =IFERROR(F38/F35,"") | G39: =IFERROR(G38/G35,"") | H39: =IFERROR(H38/H35,"") | N39: Net Debt / Adjusted EBITDA (x) | O39: -0.77407407 | P39: -1.0357027 | Q39: -0.82962022 | R39: -0.80352537 | S39: -0.86452977 | T39: -0.98915712 | Z39: Net Debt / Adjusted EBITDA (x) | AA39: -0.77407407 | AB39: -1.1477409 | AC39: -1.340761 | AD39: -1.4688741 | AE39: -1.6420731 | AF39: -1.8813631
B40: Share repurchases (CHF m) | D40: =Model!AH247 | E40: =Model!AI247 | F40: =Model!AJ247 | G40: =Model!AK247 | H40: =Model!AL247 | N40: Share repurchases (CHF m) | P40: 96 | Q40: 326.4 | R40: 326.4 | S40: 325.6 | T40: 360 | Z40: Share repurchases (CHF m) | AB40: 32 | AC40: 126.4 | AD40: 126.4 | AE40: 125.6 | AF40: 160
B41: Implied avg buyback price (USD) | D41: =Model!AH248 | E41: =Model!AI248 | F41: =Model!AJ248 | G41: =Model!AK248 | H41: =Model!AL248 | N41: Implied avg buyback price (USD) | P41: 32 | Q41: 35.2 | R41: 38.72 | S41: 42.592 | T41: 46.8512 | Z41: Implied avg buyback price (USD) | AB41: 32 | AC41: 35.2 | AD41: 38.72 | AE41: 42.592 | AF41: 46.8512
B42: Shares repurchased (m) | D42: =Model!AH249 | E42: =Model!AI249 | F42: =Model!AJ249 | G42: =Model!AK249 | H42: =Model!AL249 | N42: Shares repurchased (m) | P42: 3.75 | Q42: 11.590909 | R42: 10.53719 | S42: 9.5557851 | T42: 9.6048767 | Z42: Shares repurchased (m) | AB42: 1.25 | AC42: 4.4886364 | AD42: 4.0805785 | AE42: 3.6861382 | AF42: 4.2688341
B44: ROIC | C44: =Model!AC326 | D44: =Model!AH326 | E44: =Model!AI326 | F44: =Model!AJ326 | G44: =Model!AK326 | H44: =Model!AL326 | J44: =IFERROR(AVERAGE(Model!C326,Model!D326,Model!I326,Model!N326,Model!S326,Model!X326,Model!AC326),"") | K44: =IFERROR(MIN(Model!C326,Model!D326,Model!I326,Model!N326,Model!S326,Model!X326,Model!AC326),"") | L44: =IFERROR(MAX(Model!C326,Model!D326,Model!I326,Model!N326,Model!S326,Model!X326,Model!AC326),"") | N44: ROIC | O44: 0.29466276 | P44: 0.38056752 | Q44: 0.37487968 | R44: 0.39645708 | S44: 0.41936651 | T44: 0.43216829 | V44: 0.20003413 | W44: 0.11458291 | X44: 0.29466276 | Z44: ROIC | AA44: 0.29466276 | AB44: 0.35510981 | AC44: 0.28750411 | AD44: 0.30154647 | AE44: 0.31704381 | AF44: 0.32337549 | AH44: 0.20003413 | AI44: 0.11458291 | AJ44: 0.29466276
B45: RONTA | C45: =Model!AC337 | D45: =Model!AH337 | E45: =Model!AI337 | F45: =Model!AJ337 | G45: =Model!AK337 | H45: =Model!AL337 | J45: =IFERROR(AVERAGE(Model!C337,Model!D337,Model!I337,Model!N337,Model!S337,Model!X337,Model!AC337),"") | K45: =IFERROR(MIN(Model!C337,Model!D337,Model!I337,Model!N337,Model!S337,Model!X337,Model!AC337),"") | L45: =IFERROR(MAX(Model!C337,Model!D337,Model!I337,Model!N337,Model!S337,Model!X337,Model!AC337),"") | N45: RONTA | O45: 0.28610478 | P45: 0.36945134 | Q45: 0.36574231 | R45: 0.38831505 | S45: 0.41208166 | T45: 0.42572426 | V45: 0.19009128 | W45: 0.1101406 | X45: 0.28610478 | Z45: RONTA | AA45: 0.28610478 | AB45: 0.3446199 | AC45: 0.27997324 | AD45: 0.29441868 | AE45: 0.31022806 | AF45: 0.31693786 | AH45: 0.19009128 | AI45: 0.1101406 | AJ45: 0.28610478
B47: Implied Market Cap (CHF m) | F47: =F27*F21 | G47: =G27*G21 | H47: =H27*H21 | N47: Implied Market Cap (CHF m) | R47: =R27*R21 | S47: =S27*S21 | T47: =T27*T21 | Z47: Implied Market Cap (CHF m) | AD47: =AD27*AD21 | AE47: =AE27*AE21 | AF47: =AF27*AF21
B48: (+) Net Debt incl. leases & NCI | F48: =F38+Model!AJ355 | G48: =G38+Model!AK355 | H48: =H38+Model!AL355 | N48: (+) Net Debt incl. leases & NCI | R48: =R38+Model!AJ355 | S48: =S38+Model!AK355 | T48: =T38+Model!AL355 | Z48: (+) Net Debt incl. leases & NCI | AD48: =AD38+Model!AJ355 | AE48: =AE38+Model!AK355 | AF48: =AF38+Model!AL355
B49: Implied Enterprise Value (CHF m) | F49: =F47+F48 | G49: =G47+G48 | H49: =H47+H48 | N49: Implied Enterprise Value (CHF m) | R49: =R47+R48 | S49: =S47+S48 | T49: =T47+T48 | Z49: Implied Enterprise Value (CHF m) | AD49: =AD47+AD48 | AE49: =AE47+AE48 | AF49: =AF47+AF48
B50: Implied EV / Adjusted EBITDA (x) | F50: =IFERROR(F49/F35,"") | G50: =IFERROR(G49/G35,"") | H50: =IFERROR(H49/H35,"") | N50: Implied EV / Adjusted EBITDA (x) | R50: =IFERROR(R49/R35,"") | S50: =IFERROR(S49/S35,"") | T50: =IFERROR(T49/T35,"") | Z50: Implied EV / Adjusted EBITDA (x) | AD50: =IFERROR(AD49/AD35,"") | AE50: =IFERROR(AE49/AE35,"") | AF50: =IFERROR(AF49/AF35,"")

Sheet DCF
B2: DCF VALUATION — ON HOLDING AG (ONON)
B4: 1. WACC BUILD
B5: Risk-free rate (US 10Y govt) | C5: 0.042 | D5: US 10Y Treasury (~4.2%): forecasts hold FX at spot, so CHF cash flows carry USD / EUR economics (a CHF rate would need ~2–3% p.a. CHF appreciation built in)
B6: Equity risk premium | C6: 0.05 | D6: Implied ERP ~4.5–5.5% (Damodaran)
B7: Levered beta | C7: 1.25 | D7: Premium sportswear / footwear peers (Deckers, Lululemon, Nike, adidas, Amer Sports) ~1.0–1.4; high-growth, discretionary, founder-led
B8: Cost of equity | C8: =C5+C7*C6
B9: Pre-tax cost of debt | C9: 0.05 | D9: No bank debt; CHF 700m revolving facility undrawn (marginal cost ~SARON / SOFR + margin)
B10: Tax rate | C10: 0.17 | D10: Model 2027E+ effective tax rate (Swiss holding, global footprint)
B11: After-tax cost of debt | C11: =C9*(1-C10)
B12: Target D/V | C12: 0 | D12: Net cash (CHF ~1.2bn at 30-Jun-26) and no financial debt; leases treated as operating costs in UFCF (lease payments deducted, liabilities not in net debt)
B13: WACC | C13: =C8*(1-C12)+C11*C12
B15: Valuation date (live) | C15: =TODAY() | D15: Periods = (Dec-31-Year − today) / 365.25; cash flows assumed at year-end
B16: 2. UNLEVERED FREE CASH FLOW BUILD (USDm)
D17: 2026E | E17: 2027E | F17: 2028E | G17: 2029E | H17: 2030E | I17: 2031E | J17: 2032E | K17: 2033E | L17: 2034E | M17: 2035E | N17: Terminal | P17: CAGR 26–30E | Q17: CAGR 26–35E
B18: Adj. EBIT less share-based compensation (= IFRS operating result; SBC is a real cost) | D18: =Model!AH160-Model!AH104 | E18: =Model!AI160-Model!AI104 | F18: =Model!AJ160-Model!AJ104 | G18: =Model!AK160-Model!AK104 | H18: =Model!AL160-Model!AL104 | I18: =H18*(1+I$26) | J18: =I18*(1+J$26) | K18: =J18*(1+K$26) | L18: =K18*(1+L$26) | M18: =L18*(1+M$26) | P18: =(H18/D18)^(1/(COLUMNS(D18:H18)-1))-1 | Q18: =(M18/D18)^(1/(COLUMNS(D18:M18)-1))-1
B19: × (1 − tax rate) | D19: =1-$C$10 | E19: =1-$C$10 | F19: =1-$C$10 | G19: =1-$C$10 | H19: =1-$C$10 | I19: =1-$C$10 | J19: =1-$C$10 | K19: =1-$C$10 | ... M19: =1-$C$10
B20: NOPAT | D20: =D18*D19 | E20: =E18*E19 | F20: =F18*F19 | G20: =G18*G19 | H20: =H18*H19 | I20: =I18*I19 | J20: =J18*J19 | K20: =K18*K19 | ... M20: =M18*M19
B21: plus D&A (incl. right-of-use depreciation) | D21: =Model!AH125 | E21: =Model!AI125 | F21: =Model!AJ125 | G21: =Model!AK125 | H21: =Model!AL125 | I21: =H21*(1+I$26) | J21: =I21*(1+J$26) | K21: =J21*(1+K$26) | L21: =K21*(1+L$26) | M21: =L21*(1+M$26)
B22: − Capex (PP&E, intangibles) and lease principal payments | D22: =Model!AH217+Model!AH220 | E22: =Model!AI217+Model!AI220 | F22: =Model!AJ217+Model!AJ220 | G22: =Model!AK217+Model!AK220 | H22: =Model!AL217+Model!AL220 | I22: =H22*(1+I$26) | J22: =I22*(1+J$26) | K22: =J22*(1+K$26) | L22: =K22*(1+L$26) | M22: =L22*(1+M$26)
B23: − Δ Working capital (CF statement) | D23: =Model!AH214 | E23: =Model!AI214 | F23: =Model!AJ214 | G23: =Model!AK214 | H23: =Model!AL214 | I23: =H23*(1+I$26) | J23: =I23*(1+J$26) | K23: =J23*(1+K$26) | L23: =K23*(1+L$26) | M23: =L23*(1+M$26)
B24: Unlevered FCF | D24: =D20+D21+D22+D23 | E24: =E20+E21+E22+E23 | F24: =F20+F21+F22+F23 | G24: =G20+G21+G22+G23 | H24: =H20+H21+H22+H23 | I24: =I20+I21+I22+I23 | J24: =J20+J21+J22+J23 | K24: =K20+K21+K22+K23 | ... M24: =M20+M21+M22+M23 | N24: =M24*(1+$C$27) | P24: =(H24/D24)^(1/(COLUMNS(D24:H24)-1))-1 | Q24: =(M24/D24)^(1/(COLUMNS(D24:M24)-1))-1
B25: Terminal Value (Gordon Growth) | N25: =N24/($C$13-$C$27)
B26: Fade-period growth (2031E–35E; 12% → 6% linear) | I26: 0.12 | J26: =I26+($M$26-$I$26)/4 | K26: =J26+($M$26-$I$26)/4 | L26: =K26+($M$26-$I$26)/4 | M26: 0.06
B27: Terminal growth rate | C27: 0.035
B29: Discount period (years) | D29: =(DATE(2026,12,31)-$C$15)/365.25 | E29: =(DATE(2027,12,31)-$C$15)/365.25 | F29: =(DATE(2028,12,31)-$C$15)/365.25 | G29: =(DATE(2029,12,31)-$C$15)/365.25 | H29: =(DATE(2030,12,31)-$C$15)/365.25 | I29: =(DATE(2031,12,31)-$C$15)/365.25 | J29: =(DATE(2032,12,31)-$C$15)/365.25 | K29: =(DATE(2033,12,31)-$C$15)/365.25 | L29: =(DATE(2034,12,31)-$C$15)/365.25 | M29: =(DATE(2035,12,31)-$C$15)/365.25 | N29: =M29
B30: Discount factor | D30: =1/(1+$C$13)^D29 | E30: =1/(1+$C$13)^E29 | F30: =1/(1+$C$13)^F29 | G30: =1/(1+$C$13)^G29 | H30: =1/(1+$C$13)^H29 | I30: =1/(1+$C$13)^I29 | J30: =1/(1+$C$13)^J29 | K30: =1/(1+$C$13)^K29 | ... N30: =1/(1+$C$13)^N29
B31: PV of UFCF | D31: =D24*D30 | E31: =E24*E30 | F31: =F24*F30 | G31: =G24*G30 | H31: =H24*H30 | I31: =I24*I30 | J31: =J24*J30 | K31: =K24*K30 | ... M31: =M24*M30 | N31: =N25*N30
D32: On's Adjusted EBITDA excludes share-based compensation (~2% of sales), which is deducted here (row 18 = Adjusted EBIT − SBC = IFRS operating result). IFRS 16: D&A includes right-of-use depreciation, so lease principal payments are deducted with capex in row 22 and lease liabilities are excluded from net debt in the equity bridge (rent-as-opex basis). No acquisitions assumed. Forecasts at constant spot FX; FX translation is the largest swing factor (≈ 80%+ of sales outside Switzerland, ~50% in the Americas).
B33: IMPLIED ROIC — invested capital roll-forward (USDm)
B34: Opening invested capital | D34: =Model!AC324-Model!AC258 | E34: =D38 | F34: =E38 | G34: =F38 | H34: =G38 | I34: =H38 | J34: =I38 | K34: =J38 | L34: =K38 | M34: =L38
B35: plus Capex and acquisitions | D35: =-D22 | E35: =-E22 | F35: =-F22 | G35: =-G22 | H35: =-H22 | I35: =-I22 | J35: =-J22 | K35: =-K22 | ... M35: =-M22
B36: less DD&A | D36: =-D21 | E36: =-E21 | F36: =-F21 | G36: =-G21 | H36: =-H21 | I36: =-I21 | J36: =-J21 | K36: =-K21 | ... M36: =-M21
B37: plus Δ Working capital investment | D37: =-D23 | E37: =-E23 | F37: =-F23 | G37: =-G23 | H37: =-H23 | I37: =-I23 | J37: =-J23 | K37: =-K23 | ... M37: =-M23
B38: Closing invested capital | D38: =SUM(D34:D37) | E38: =SUM(E34:E37) | F38: =SUM(F34:F37) | G38: =SUM(G34:G37) | H38: =SUM(H34:H37) | I38: =SUM(I34:I37) | J38: =SUM(J34:J37) | K38: =SUM(K34:K37) | ... M38: =SUM(M34:M37)
B39: NOPAT (row 20) | D39: =D20 | E39: =E20 | F39: =F20 | G39: =G20 | H39: =H20 | I39: =I20 | J39: =J20 | K39: =K20 | ... M39: =M20
B40: Implied ROIC (NOPAT / avg. invested capital) | D40: =IFERROR(D39/AVERAGE(D34,D38),"") | E40: =IFERROR(E39/AVERAGE(E34,E38),"") | F40: =IFERROR(F39/AVERAGE(F34,F38),"") | G40: =IFERROR(G39/AVERAGE(G34,G38),"") | H40: =IFERROR(H39/AVERAGE(H34,H38),"") | I40: =IFERROR(I39/AVERAGE(I34,I38),"") | J40: =IFERROR(J39/AVERAGE(J34,J38),"") | K40: =IFERROR(K39/AVERAGE(K34,K38),"") | ... M40: =IFERROR(M39/AVERAGE(M34,M38),"")
B41: Reinvestment rate (net investment / NOPAT) | D41: =IFERROR(SUM(D35:D37)/D39,"") | E41: =IFERROR(SUM(E35:E37)/E39,"") | F41: =IFERROR(SUM(F35:F37)/F39,"") | G41: =IFERROR(SUM(G35:G37)/G39,"") | H41: =IFERROR(SUM(H35:H37)/H39,"") | I41: =IFERROR(SUM(I35:I37)/I39,"") | J41: =IFERROR(SUM(J35:J37)/J39,"") | K41: =IFERROR(SUM(K35:K37)/K39,"") | ... M41: =IFERROR(SUM(M35:M37)/M39,"")
B42: Implied terminal RONIC (g / reinvestment rate) | N42: =IFERROR($C$27/M41,"")
D43: Opening IC = Model 2025A equity − cash (leases treated as operating), rolled forward with capex + lease payments − D&A + ΔWC.
B44: 3. VALUATION SUMMARY
...

Sheet Charts
B2: On Holding — Operating Performance (2019–2025) and Model Forecast (2026E–2030E)
B3: CHFm · Linked to Model. Bars = constant-currency growth vs FX translation effect (published from 2024; earlier years: reported growth shown as constant currency). Adjusted EBITDA as reconciled by On in each period (prospectus for FY2019–20). ROIC / RONTA on Adjusted EBIT (balance sheets from FY2020).
C7: 2019 | D7: 2020 | E7: 2021 | F7: 2022 | G7: 2023 | H7: 2024 | I7: 2025 | J7: 2026E | K7: 2027E | L7: 2028E | M7: 2029E | N7: 2030E
B8: Constant-currency growth % | C8: =IFERROR(Model!C194+0,IFERROR(Model!C193+0,0)) | D8: =IFERROR(Model!D194+0,IFERROR(Model!D193+0,0)) | E8: =IFERROR(Model!I194+0,IFERROR(Model!I193+0,0)) | F8: =IFERROR(Model!N194+0,IFERROR(Model!N193+0,0)) | G8: =IFERROR(Model!S194+0,IFERROR(Model!S193+0,0)) | H8: =IFERROR(Model!X194+0,IFERROR(Model!X193+0,0)) | I8: =IFERROR(Model!AC194+0,IFERROR(Model!AC193+0,0)) | J8: =IFERROR(Model!AH194+0,IFERROR(Model!AH193+0,0)) | K8: =IFERROR(Model!AI194+0,IFERROR(Model!AI193+0,0)) | L8: =IFERROR(Model!AJ194+0,IFERROR(Model!AJ193+0,0)) | M8: =IFERROR(Model!AK194+0,IFERROR(Model!AK193+0,0)) | N8: =IFERROR(Model!AL194+0,IFERROR(Model!AL193+0,0))
B9: FX translation effect % | C9: =IFERROR(Model!C44+0,0) | D9: =IFERROR(Model!D44+0,0) | E9: =IFERROR(Model!I44+0,0) | F9: =IFERROR(Model!N44+0,0) | G9: =IFERROR(Model!S44+0,0) | H9: =IFERROR(Model!X44+0,0) | I9: =IFERROR(Model!AC44+0,0) | J9: =IFERROR(Model!AH44+0,0) | K9: =IFERROR(Model!AI44+0,0) | L9: =IFERROR(Model!AJ44+0,0) | M9: =IFERROR(Model!AK44+0,0) | N9: =IFERROR(Model!AL44+0,0)
C11: =C7 | D11: =D7 | E11: =E7 | F11: =F7 | G11: =G7 | H11: =H7 | I11: =I7 | J11: =J7 | ... N11: =N7
B12: Adjusted EBITDA | C12: =Model!C150 | D12: =Model!D150 | E12: =Model!I150 | F12: =Model!N150 | G12: =Model!S150 | H12: =Model!X150 | I12: =Model!AC150 | J12: =Model!AH150 | K12: =Model!AI150 | L12: =Model!AJ150 | M12: =Model!AK150 | N12: =Model!AL150
B13: Operating Result (IFRS) | C13: =Model!C114 | D13: =Model!D114 | E13: =Model!I114 | F13: =Model!N114 | G13: =Model!S114 | H13: =Model!X114 | I13: =Model!AC114 | J13: =Model!AH114 | K13: =Model!AI114 | L13: =Model!AJ114 | M13: =Model!AK114 | N13: =Model!AL114
B14: Adj. EBITDA Margin % | C14: =Model!C201 | D14: =Model!D201 | E14: =Model!I201 | F14: =Model!N201 | G14: =Model!S201 | H14: =Model!X201 | I14: =Model!AC201 | J14: =Model!AH201 | K14: =Model!AI201 | L14: =Model!AJ201 | M14: =Model!AK201 | N14: =Model!AL201
B15: IFRS Op. Margin % | C15: =Model!C204 | D15: =Model!D204 | E15: =Model!I204 | F15: =Model!N204 | G15: =Model!S204 | H15: =Model!X204 | I15: =Model!AC204 | J15: =Model!AH204 | K15: =Model!AI204 | L15: =Model!AJ204 | M15: =Model!AK204 | N15: =Model!AL204
C17: =C7 | D17: =D7 | E17: =E7 | F17: =F7 | G17: =G7 | H17: =H7 | I17: =I7 | J17: =J7 | ... N17: =N7
B18: ROIC | C18: =IFERROR(Model!C326+0,NA()) | D18: =IFERROR(Model!D326+0,NA()) | E18: =IFERROR(Model!I326+0,NA()) | F18: =IFERROR(Model!N326+0,NA()) | G18: =IFERROR(Model!S326+0,NA()) | H18: =IFERROR(Model!X326+0,NA()) | I18: =IFERROR(Model!AC326+0,NA()) | J18: =IFERROR(Model!AH326+0,NA()) | K18: =IFERROR(Model!AI326+0,NA()) | L18: =IFERROR(Model!AJ326+0,NA()) | M18: =IFERROR(Model!AK326+0,NA()) | N18: =IFERROR(Model!AL326+0,NA())
B19: RONTA | C19: =IFERROR(Model!C337+0,NA()) | D19: =IFERROR(Model!D337+0,NA()) | E19: =IFERROR(Model!I337+0,NA()) | F19: =IFERROR(Model!N337+0,NA()) | G19: =IFERROR(Model!S337+0,NA()) | H19: =IFERROR(Model!X337+0,NA()) | I19: =IFERROR(Model!AC337+0,NA()) | J19: =IFERROR(Model!AH337+0,NA()) | K19: =IFERROR(Model!AI337+0,NA()) | L19: =IFERROR(Model!AJ337+0,NA()) | M19: =IFERROR(Model!AK337+0,NA()) | N19: =IFERROR(Model!AL337+0,NA())
B20: Adj. EBITDA margin % | C20: =IFERROR(Model!C201+0,NA()) | D20: =IFERROR(Model!D201+0,NA()) | E20: =IFERROR(Model!I201+0,NA()) | F20: =IFERROR(Model!N201+0,NA()) | G20: =IFERROR(Model!S201+0,NA()) | H20: =IFERROR(Model!X201+0,NA()) | I20: =IFERROR(Model!AC201+0,NA()) | J20: =IFERROR(Model!AH201+0,NA()) | K20: =IFERROR(Model!AI201+0,NA()) | L20: =IFERROR(Model!AJ201+0,NA()) | M20: =IFERROR(Model!AK201+0,NA()) | N20: =IFERROR(Model!AL201+0,NA())
B21: FCF margin % | C21: =IFERROR(Model!C235+0,NA()) | D21: =IFERROR(Model!D235+0,NA()) | E21: =IFERROR(Model!I235+0,NA()) | F21: =IFERROR(Model!N235+0,NA()) | G21: =IFERROR(Model!S235+0,NA()) | H21: =IFERROR(Model!X235+0,NA()) | I21: =IFERROR(Model!AC235+0,NA()) | J21: =IFERROR(Model!AH235+0,NA()) | K21: =IFERROR(Model!AI235+0,NA()) | L21: =IFERROR(Model!AJ235+0,NA()) | M21: =IFERROR(Model!AK235+0,NA()) | N21: =IFERROR(Model!AL235+0,NA())
