Workbook

Sheet Model
CT1: SCENARIO SWITCH ▼ (Bull / Base / Bear) — drives all scenario-linked forecast drivers
B2: RB Global, Inc. (NYSE / TSX: RBA) — 3-Statement Financial Model | CT2: Base
B3: US GAAP as reported (2015+) · USD millions (per-share data in USD) · Source: RB Global / Ritchie Bros. Auctioneers Forms 40-F (2006–14), 6-K (2013–15 quarters), 10-K / 10-Q (2015+) and Form 8-K earnings releases (Ex. 99.1), SEC EDGAR CIK 0001046102
B4: Basis notes: FY2006–10 Canadian GAAP and FY2011–12 / 2013–14 quarters IFRS (40-F / 6-K), FY2013–14 annuals US GAAP as recast in the FY2015 10-K; 2015+ US GAAP. Pre-2017 revenue on the legacy net (agency) basis — ASC 606 (2018, full retrospective) recast 2017 to gross inventory sales; 2016 shown with a recast memo. IronPlanet from 31-May-2017; IAA from 20-Mar-2023 (single reportable segment since 2023). Q3/26E–Q4/26E = FY26 outlook less 1H/26 actuals.
CV5: Forecast | CW5: Historical | CX5: Historical | CY5: Historical
B6: (USDm) | C6: 2006 | D6: 2007 | E6: 2008 | F6: 2009 | G6: 2010 | H6: 2011 | I6: 2012 | J6: Q1/13 | K6: Q2/13 | L6: 1H/13 | M6: Q3/13 | N6: Q4/13 | O6: 2013 | P6: Q1/14 | Q6: Q2/14 | R6: 1H/14 | S6: Q3/14 | T6: Q4/14 | U6: 2014 | V6: Q1/15 | W6: Q2/15 | X6: 1H/15 | Y6: Q3/15 | Z6: Q4/15 | AA6: 2015 | AB6: Q1/16 | AC6: Q2/16 | AD6: 1H/16 | AE6: Q3/16 | AF6: Q4/16 | AG6: 2016 | AH6: Q1/17 | AI6: Q2/17 | AJ6: 1H/17 | AK6: Q3/17 | AL6: Q4/17 | AM6: 2017 | AN6: Q1/18 | AO6: Q2/18 | AP6: 1H/18 | AQ6: Q3/18 | AR6: Q4/18 | AS6: 2018 | AT6: Q1/19 | AU6: Q2/19 | AV6: 1H/19 | AW6: Q3/19 | AX6: Q4/19 | AY6: 2019 | AZ6: Q1/20 | BA6: Q2/20 | BB6: 1H/20 | BC6: Q3/20 | BD6: Q4/20 | BE6: 2020 | BF6: Q1/21 | BG6: Q2/21 | BH6: 1H/21 | BI6: Q3/21 | BJ6: Q4/21 | BK6: 2021 | BL6: Q1/22 | BM6: Q2/22 | BN6: 1H/22 | BO6: Q3/22 | BP6: Q4/22 | BQ6: 2022 | BR6: Q1/23 | BS6: Q2/23 | BT6: 1H/23 | BU6: Q3/23 | BV6: Q4/23 | BW6: 2023 | BX6: Q1/24 | BY6: Q2/24 | BZ6: 1H/24 | CA6: Q3/24 | CB6: Q4/24 | CC6: 2024 | CD6: Q1/25 | CE6: Q2/25 | CF6: 1H/25 | CG6: Q3/25 | CH6: Q4/25 | CI6: 2025 | CJ6: Q1/26 | CK6: Q2/26 | CL6: 1H/26 | CM6: Q3/26E | CN6: Q4/26E | CO6: 2026E | CP6: 2027E | CQ6: 2028E | CR6: 2029E | CS6: 2030E | CT6: Modelling Notes | CV6: 5Y CAGR | CW6: 5Y CAGR | CX6: 10Y CAGR | CY6: 19Y CAGR
CV7: 25-'30 | CW7: 20-'25 | CX7: 15-'25 | CY7: 06-'25
B8: REVENUE BUILD — GTV BY SECTOR × TAKE RATE + INVENTORY SALES (single reportable segment) | CT8: REVENUE BUILD — modelling logic (RB Global reports one operating segment; the build replaces HII's segment P&L)
DB9: SCENARIO INPUT TABLE — driver assumptions per Bull / Base / Bear | DC9: Bull | DD9: Base | DE9: Bear | DF9: Bull / Bear = Base + Δ (Δ inputs on each block header). Outlook block = high / mid / low end of FY26 ranges.
B10: Automotive (salvage & remarketed passenger vehicles; IAA from 20-Mar-2023) | CT10: AUTOMOTIVE — modelling logic
B11: GTV (USDm) | BR11: 331.7 | BS11: 2101.9 | BT11: =BR11+BS11 -> 2433.6 | BU11: 2051.1 | BV11: 2046.4 | BW11: 6531.2 | BX11: 2105 | BY11: 2007.7 | BZ11: =BX11+BY11 -> 4112.7 | CA11: 2031.1 | CB11: 2133.9 | CC11: 8277.6 | CD11: 2144.7 | CE11: 2161.5 | CF11: =CD11+CE11 -> 4306.2 | CG11: 2152.2 | CH11: 2200.7 | CI11: 8659.1 | CJ11: 2289.2 | CK11: 2448.7 | CL11: =CJ11+CK11 -> 4737.9 | CM11: =CM39*CG11*CL11/CF11/(CG11*CL11/CF11+CG19*CL19/CF19+CG29*CL29/CF29) -> 2273.9582 | CN11: =CN39*CH11*CL11/CF11/(CH11*CL11/CF11+CH19*CL19/CF19+CH29*CL29/CF29) -> 2320.9804 | CO11: =SUM(CJ11,CK11,CM11,CN11) -> 9332.8386 | CP11: =CO11*(1+CP15) -> 9799.4806 | CQ11: =CP11*(1+CQ15) -> 10289.455 | CR11: =CQ11*(1+CR15) -> 10752.48 | CS11: =CR11*(1+CS15) -> 11236.342 | CT11: Q3/26E–Q4/26E: total GTV (FY26 outlook) allocated across sectors by prior-year same-quarter sector GTV × 1H/26 sector y/y momentum. 2027E+: prior year × (1 + scenario sector GTV growth). | CV11: =IFERROR((CS11/CI11)^(1/5)-1,"n/m") -> 0.053490045 | CW11: =IFERROR((CI11/BE11)^(1/5)-1,"n/m") -> n/m | CX11: =IFERROR((CI11/AA11)^(1/10)-1,"n/m") -> n/m | CY11: =IFERROR((CI11/C11)^(1/19)-1,"n/m") -> n/m | DB11: FY26 outlook — Q2-26 release (4-Aug-26) | DC11: High | DD11: Mid | DE11: Low
B12: Lots sold (000s) | BR12: 87.5 | BS12: 573.4 | BT12: =BR12+BS12 -> 660.9 | BU12: 555 | BV12: 572.5 | BW12: 1788.4 | BX12: 584.6 | BY12: 547.7 | BZ12: =BX12+BY12 -> 1132.3 | CA12: 553.8 | CB12: 611.1 | CC12: 2297.2 | CD12: 625.6 | CE12: 595.9 | CF12: =CD12+CE12 -> 1221.5 | CG12: 601.7 | CH12: 624.5 | CI12: 2447.7 | CJ12: 631.3 | CK12: 658.8 | CL12: =CJ12+CK12 -> 1290.1 | CM12: =IFERROR(CM11/CM13*1000,"") -> 617.22376 | CN12: =IFERROR(CN11/CN13*1000,"") -> 639.44891 | CO12: =SUM(CJ12,CK12,CM12,CN12) -> 2546.7727 | CP12: =IFERROR(CP11/CP13*1000,"") -> 2608.8891 | CQ12: =IFERROR(CQ11/CQ13*1000,"") -> 2672.5205 | CR12: =IFERROR(CR11/CR13*1000,"") -> 2738.0235 | CS12: =IFERROR(CS11/CS13*1000,"") -> 2805.1319 | DB12: GTV growth % | DC12: 0.11 | DD12: 0.1 | DE12: 0.09
B13: GTV per lot sold ($) | C13: =IFERROR(C11/C12*1000,"") | D13: =IFERROR(D11/D12*1000,"") | E13: =IFERROR(E11/E12*1000,"") | F13: =IFERROR(F11/F12*1000,"") | G13: =IFERROR(G11/G12*1000,"") | H13: =IFERROR(H11/H12*1000,"") | I13: =IFERROR(I11/I12*1000,"") | J13: =IFERROR(J11/J12*1000,"") | ... CL13: =IFERROR(CL11/CL12*1000,"") -> 3672.506 | CM13: =CG13*(1+$CO$14) -> 3684.1715 | CN13: =CH13*(1+$CO$14) -> 3629.6573 | CO13: =IFERROR(CO11/CO12*1000,"") -> 3664.5747 | CP13: =CO13*(1+CP14) -> 3756.189 | CQ13: =CP13*(1+CQ14) -> 3850.0938 | CR13: =CQ13*(1+CR14) -> 3927.0956 | CS13: =CR13*(1+CS14) -> 4005.6376 | DB13: Adjusted EBITDA ($m) | DC13: 1545 | DD13: 1520 | DE13: 1495
B14: GTV per lot y/y % (forecast input) | D14: =IFERROR(D13/C13-1,"") | E14: =IFERROR(E13/D13-1,"") | F14: =IFERROR(F13/E13-1,"") | G14: =IFERROR(G13/F13-1,"") | H14: =IFERROR(H13/G13-1,"") | I14: =IFERROR(I13/H13-1,"") | O14: =IFERROR(O13/I13-1,"") | P14: =IFERROR(P13/J13-1,"") | Q14: =IFERROR(Q13/K13-1,"") | R14: =IFERROR(R13/L13-1,"") | S14: =IFERROR(S13/M13-1,"") | T14: =IFERROR(T13/N13-1,"") | U14: =IFERROR(U13/O13-1,"") | V14: =IFERROR(V13/P13-1,"") | ... CL14: =IFERROR(CL13/CF13-1,"") -> 0.041745875 | CO14: 0.03 | CP14: 0.025 | CQ14: 0.025 | CR14: 0.02 | CS14: 0.02 | CT14: Price/mix per lot (input). 2026E cell drives Q3/Q4-26E lots (vs prior-year quarter GTV per lot).
B15: GTV y/y % | D15: =IFERROR(D11/C11-1,"") | E15: =IFERROR(E11/D11-1,"") | F15: =IFERROR(F11/E11-1,"") | G15: =IFERROR(G11/F11-1,"") | H15: =IFERROR(H11/G11-1,"") | I15: =IFERROR(I11/H11-1,"") | O15: =IFERROR(O11/I11-1,"") | P15: =IFERROR(P11/J11-1,"") | Q15: =IFERROR(Q11/K11-1,"") | R15: =IFERROR(R11/L11-1,"") | S15: =IFERROR(S11/M11-1,"") | T15: =IFERROR(T11/N11-1,"") | U15: =IFERROR(U11/O11-1,"") | V15: =IFERROR(V11/P11-1,"") | ... CO15: =IFERROR(CO11/CI11-1,"") -> 0.077807003 | CP15: =CHOOSE(MATCH($CT$2,{"Bull","Base","Bear"},0),$DC$21,$DD$21,$DE$21) -> 0.05 | CQ15: =CHOOSE(MATCH($CT$2,{"Bull","Base","Bear"},0),$DC$22,$DD$22,$DE$22) -> 0.05 | CR15: =CHOOSE(MATCH($CT$2,{"Bull","Base","Bear"},0),$DC$23,$DD$23,$DE$23) -> 0.045 | CS15: =CHOOSE(MATCH($CT$2,{"Bull","Base","Bear"},0),$DC$24,$DD$24,$DE$24) -> 0.045 | CT15: 2027E–2030E: scenario lever (AUTO_gtvGrowth, Bull/Base/Bear table →). | DB15: FY26 outlook — point estimates (all cases)
B16: Lots sold y/y % | D16: =IFERROR(D12/C12-1,"") | E16: =IFERROR(E12/D12-1,"") | F16: =IFERROR(F12/E12-1,"") | G16: =IFERROR(G12/F12-1,"") | H16: =IFERROR(H12/G12-1,"") | I16: =IFERROR(I12/H12-1,"") | O16: =IFERROR(O12/I12-1,"") | P16: =IFERROR(P12/J12-1,"") | Q16: =IFERROR(Q12/K12-1,"") | R16: =IFERROR(R12/L12-1,"") | S16: =IFERROR(S12/M12-1,"") | T16: =IFERROR(T12/N12-1,"") | U16: =IFERROR(U12/O12-1,"") | V16: =IFERROR(V12/P12-1,"") | ... CO16: =IFERROR(CO12/CI12-1,"") -> 0.040475823 | CP16: =IFERROR(CP12/CO12-1,"") -> 0.024390244 | CQ16: =IFERROR(CQ12/CP12-1,"") -> 0.024390244 | CR16: =IFERROR(CR12/CQ12-1,"") -> 0.024509804 | CS16: =IFERROR(CS12/CR12-1,"") -> 0.024509804 | DB16: Tax rate (GAAP & adjusted) | DD16: 0.24
DB17: Capital expenditures ($m) | DD17: 375
B18: Heavy Equipment & Transportation (HE&T — current basis from Q1/25) | CT18: HEAVY EQUIPMENT & TRANSPORTATION — modelling logic
B19: GTV (USDm) | CD19: 1562.7 | CE19: 1928.1 | CF19: =CD19+CE19 -> 3490.8 | CG19: 1627.3 | CH19: 1957.7 | CI19: 7075.8 | CJ19: 1943.5 | CK19: 2076.6 | CL19: =CJ19+CK19 -> 4020.1 | CM19: =CM39*CG19*CL19/CF19/(CG11*CL11/CF11+CG19*CL19/CF19+CG29*CL29/CF29) -> 1799.6484 | CN19: =CN39*CH19*CL19/CF19/(CH11*CL11/CF11+CH19*CL19/CF19+CH29*CL29/CF29) -> 2161.1105 | CO19: =SUM(CJ19,CK19,CM19,CN19) -> 7980.8589 | CP19: =CO19*(1+CP23) -> 8459.7104 | CQ19: =CP19*(1+CQ23) -> 8840.3974 | CR19: =CQ19*(1+CR23) -> 9194.0133 | CS19: =CR19*(1+CS23) -> 9561.7738 | CT19: Q3/26E–Q4/26E: total GTV (FY26 outlook) allocated across sectors by prior-year same-quarter sector GTV × 1H/26 sector y/y momentum. 2027E+: prior year × (1 + scenario sector GTV growth). | CV19: =IFERROR((CS19/CI19)^(1/5)-1,"n/m") -> 0.062068635 | CW19: =IFERROR((CI19/BE19)^(1/5)-1,"n/m") -> n/m | CX19: =IFERROR((CI19/AA19)^(1/10)-1,"n/m") -> n/m | CY19: =IFERROR((CI19/C19)^(1/19)-1,"n/m") -> n/m
B20: Lots sold (000s) | CD20: 156.5 | CE20: 186.4 | CF20: =CD20+CE20 -> 342.9 | CG20: 163 | CH20: 197.4 | CI20: 703.3 | CJ20: 179.4 | CK20: 200 | CL20: =CJ20+CK20 -> 379.4 | CM20: =IFERROR(CM19/CM21*1000,"") -> 176.72886 | CN20: =IFERROR(CN19/CN21*1000,"") -> 213.63766 | CO20: =SUM(CJ20,CK20,CM20,CN20) -> 769.76652 | CP20: =IFERROR(CP19/CP21*1000,"") -> 799.95344 | CQ20: =IFERROR(CQ19/CQ21*1000,"") -> 819.56014 | CR20: =IFERROR(CR19/CR21*1000,"") -> 835.62995 | CS20: =IFERROR(CS19/CS21*1000,"") -> 852.01485 | DB20: AUTO_gtvGrowth (Automotive GTV y/y) | DC20: 0.02 | DD20: Δ → | DE20: -0.03 | DF20: Automotive: US salvage volumes (accident frequency × total-loss rate), insurer share gains, price per vehicle.
B21: GTV per lot sold ($) | C21: =IFERROR(C19/C20*1000,"") | D21: =IFERROR(D19/D20*1000,"") | E21: =IFERROR(E19/E20*1000,"") | F21: =IFERROR(F19/F20*1000,"") | G21: =IFERROR(G19/G20*1000,"") | H21: =IFERROR(H19/H20*1000,"") | I21: =IFERROR(I19/I20*1000,"") | J21: =IFERROR(J19/J20*1000,"") | ... CL21: =IFERROR(CL19/CL20*1000,"") -> 10595.941 | CM21: =CG21*(1+$CO$22) -> 10183.104 | CN21: =CH21*(1+$CO$22) -> 10115.775 | CO21: =IFERROR(CO19/CO20*1000,"") -> 10367.896 | CP21: =CO21*(1+CP22) -> 10575.254 | CQ21: =CP21*(1+CQ22) -> 10786.759 | CR21: =CQ21*(1+CR22) -> 11002.494 | CS21: =CR21*(1+CS22) -> 11222.544 | DB21: 2027E | DC21: =DD21+$DC$20 -> 0.07 | DD21: 0.05 | DE21: =DD21+$DE$20 -> 0.02
B22: GTV per lot y/y % (forecast input) | D22: =IFERROR(D21/C21-1,"") | E22: =IFERROR(E21/D21-1,"") | F22: =IFERROR(F21/E21-1,"") | G22: =IFERROR(G21/F21-1,"") | H22: =IFERROR(H21/G21-1,"") | I22: =IFERROR(I21/H21-1,"") | O22: =IFERROR(O21/I21-1,"") | P22: =IFERROR(P21/J21-1,"") | Q22: =IFERROR(Q21/K21-1,"") | R22: =IFERROR(R21/L21-1,"") | S22: =IFERROR(S21/M21-1,"") | T22: =IFERROR(T21/N21-1,"") | U22: =IFERROR(U21/O21-1,"") | V22: =IFERROR(V21/P21-1,"") | ... CL22: =IFERROR(CL21/CF21-1,"") -> 0.040835383 | CO22: 0.02 | CP22: 0.02 | CQ22: 0.02 | CR22: 0.02 | CS22: 0.02 | CT22: Price/mix per lot (input). 2026E cell drives Q3/Q4-26E lots (vs prior-year quarter GTV per lot). | DB22: 2028E | DC22: =DD22+$DC$20 -> 0.07 | DD22: 0.05 | DE22: =DD22+$DE$20 -> 0.02
B23: GTV y/y % | D23: =IFERROR(D19/C19-1,"") | E23: =IFERROR(E19/D19-1,"") | F23: =IFERROR(F19/E19-1,"") | G23: =IFERROR(G19/F19-1,"") | H23: =IFERROR(H19/G19-1,"") | I23: =IFERROR(I19/H19-1,"") | O23: =IFERROR(O19/I19-1,"") | P23: =IFERROR(P19/J19-1,"") | Q23: =IFERROR(Q19/K19-1,"") | R23: =IFERROR(R19/L19-1,"") | S23: =IFERROR(S19/M19-1,"") | T23: =IFERROR(T19/N19-1,"") | U23: =IFERROR(U19/O19-1,"") | V23: =IFERROR(V19/P19-1,"") | ... CO23: =IFERROR(CO19/CI19-1,"") -> 0.12790906 | CP23: =CHOOSE(MATCH($CT$2,{"Bull","Base","Bear"},0),$DC$27,$DD$27,$DE$27) -> 0.06 | CQ23: =CHOOSE(MATCH($CT$2,{"Bull","Base","Bear"},0),$DC$28,$DD$28,$DE$28) -> 0.045 | CR23: =CHOOSE(MATCH($CT$2,{"Bull","Base","Bear"},0),$DC$29,$DD$29,$DE$29) -> 0.04 | CS23: =CHOOSE(MATCH($CT$2,{"Bull","Base","Bear"},0),$DC$30,$DD$30,$DE$30) -> 0.04 | CT23: 2027E–2030E: scenario lever (HET_gtvGrowth, Bull/Base/Bear table →). | DB23: 2029E | DC23: =DD23+$DC$20 -> 0.065 | DD23: 0.045 | DE23: =DD23+$DE$20 -> 0.015
B24: Lots sold y/y % | D24: =IFERROR(D20/C20-1,"") | E24: =IFERROR(E20/D20-1,"") | F24: =IFERROR(F20/E20-1,"") | G24: =IFERROR(G20/F20-1,"") | H24: =IFERROR(H20/G20-1,"") | I24: =IFERROR(I20/H20-1,"") | O24: =IFERROR(O20/I20-1,"") | P24: =IFERROR(P20/J20-1,"") | Q24: =IFERROR(Q20/K20-1,"") | R24: =IFERROR(R20/L20-1,"") | S24: =IFERROR(S20/M20-1,"") | T24: =IFERROR(T20/N20-1,"") | U24: =IFERROR(U20/O20-1,"") | V24: =IFERROR(V20/P20-1,"") | ... CO24: =IFERROR(CO20/CI20-1,"") -> 0.094506636 | CP24: =IFERROR(CP20/CO20-1,"") -> 0.039215686 | CQ24: =IFERROR(CQ20/CP20-1,"") -> 0.024509804 | CR24: =IFERROR(CR20/CQ20-1,"") -> 0.019607843 | CS24: =IFERROR(CS20/CR20-1,"") -> 0.019607843 | DB24: 2030E | DC24: =DD24+$DC$20 -> 0.065 | DD24: 0.045 | DE24: =DD24+$DE$20 -> 0.015
B25: Memo: CC&T GTV — legacy basis (2023–Q1/26) | BR25: 1190 | BS25: 1481.3 | BT25: =BR25+BS25 -> 2671.3 | BU25: 1352.5 | BV25: 1422.8 | BW25: 5446.5 | BX25: 1561.2 | BY25: 1613.3 | BZ25: =BX25+BY25 -> 3174.5 | CA25: 1217.6 | CB25: 1413.7 | CC25: 5805.8 | CD25: 1276.7 | CE25: 1523.2 | CF25: =CD25+CE25 -> 2799.9 | CG25: 1328.9 | CH25: 1534.7 | CI25: 5663.6 | CJ25: 1622
B26: Memo: CC&T lots sold (000s) — legacy basis | BR26: 56.6 | BS26: 84.4 | BT26: =BR26+BS26 -> 141 | BU26: 86.6 | BV26: 86.9 | BW26: 314.5 | BX26: 108.8 | BY26: 118.2 | BZ26: =BX26+BY26 -> 227 | CA26: 103.1 | CB26: 102.2 | CC26: 432.3 | CD26: 87.6 | CE26: 97.5 | CF26: =CD26+CE26 -> 185.1 | CG26: 87.8 | CH26: 103.2 | CI26: 376.1 | CJ26: 97.8 | DB26: HET_gtvGrowth (Heavy Equipment & Transportation GTV y/y) | DC26: 0.02 | DD26: Δ → | DE26: -0.04 | DF26: HE&T: used-equipment supply (fleet de-fleeting, rental), pricing cycle, J.M. Wood / BigIron annualisation in 2026–27.
DB27: 2027E | DC27: =DD27+$DC$26 -> 0.08 | DD27: 0.06 | DE27: =DD27+$DE$26 -> 0.02
B28: Other (consumer goods, real estate, parts — current basis from Q1/25) | CT28: OTHER — modelling logic | DB28: 2028E | DC28: =DD28+$DC$26 -> 0.065 | DD28: 0.045 | DE28: =DD28+$DE$26 -> 0.005
B29: GTV (USDm) | CD29: 121.5 | CE29: 108.5 | CF29: =CD29+CE29 -> 230 | CG29: 114.3 | CH29: 122.8 | CI29: 467.1 | CJ29: 108.2 | CK29: 147.4 | CL29: =CJ29+CK29 -> 255.6 | CM29: =CM39*CG29*CL29/CF29/(CG11*CL11/CF11+CG19*CL19/CF19+CG29*CL29/CF29) -> 121.97966 | CN29: =CN39*CH29*CL29/CF29/(CH11*CL11/CF11+CH19*CL19/CF19+CH29*CL29/CF29) -> 130.81282 | CO29: =SUM(CJ29,CK29,CM29,CN29) -> 508.39248 | CP29: =CO29*(1+CP33) -> 533.8121 | CQ29: =CP29*(1+CQ33) -> 560.50271 | CR29: =CQ29*(1+CR33) -> 588.52784 | CS29: =CR29*(1+CS33) -> 617.95424 | CT29: Q3/26E–Q4/26E: total GTV (FY26 outlook) allocated across sectors by prior-year same-quarter sector GTV × 1H/26 sector y/y momentum. 2027E+: prior year × (1 + scenario sector GTV growth). | CV29: =IFERROR((CS29/CI29)^(1/5)-1,"n/m") -> 0.057570405 | CW29: =IFERROR((CI29/BE29)^(1/5)-1,"n/m") -> n/m | CX29: =IFERROR((CI29/AA29)^(1/10)-1,"n/m") -> n/m | CY29: =IFERROR((CI29/C29)^(1/19)-1,"n/m") -> n/m | DB29: 2029E | DC29: =DD29+$DC$26 -> 0.06 | DD29: 0.04 | DE29: =DD29+$DE$26 -> 0
B30: Lots sold (000s) | CD30: 73 | CE30: 64.9 | CF30: =CD30+CE30 -> 137.9 | CG30: 51.5 | CH30: 53.4 | CI30: 242.8 | CJ30: 46.8 | CK30: 52.4 | CL30: =CJ30+CK30 -> 99.2 | CM30: =IFERROR(CM29/CM31*1000,"") -> 54.960212 | CN30: =IFERROR(CN29/CN31*1000,"") -> 56.884404 | CO30: =SUM(CJ30,CK30,CM30,CN30) -> 211.04462 | CP30: =IFERROR(CP29/CP31*1000,"") -> 221.59685 | CQ30: =IFERROR(CQ29/CQ31*1000,"") -> 232.67669 | CR30: =IFERROR(CR29/CR31*1000,"") -> 244.31052 | CS30: =IFERROR(CS29/CS31*1000,"") -> 256.52605 | DB30: 2030E | DC30: =DD30+$DC$26 -> 0.06 | DD30: 0.04 | DE30: =DD30+$DE$26 -> 0
B31: GTV per lot sold ($) | C31: =IFERROR(C29/C30*1000,"") | D31: =IFERROR(D29/D30*1000,"") | E31: =IFERROR(E29/E30*1000,"") | F31: =IFERROR(F29/F30*1000,"") | G31: =IFERROR(G29/G30*1000,"") | H31: =IFERROR(H29/H30*1000,"") | I31: =IFERROR(I29/I30*1000,"") | J31: =IFERROR(J29/J30*1000,"") | ... CL31: =IFERROR(CL29/CL30*1000,"") -> 2576.6129 | CM31: =CG31*(1+$CO$32) -> 2219.4175 | CN31: =CH31*(1+$CO$32) -> 2299.6255 | CO31: =IFERROR(CO29/CO30*1000,"") -> 2408.9337 | CP31: =CO31*(1+CP32) -> 2408.9337 | CQ31: =CP31*(1+CQ32) -> 2408.9337 | CR31: =CQ31*(1+CR32) -> 2408.9337 | CS31: =CR31*(1+CS32) -> 2408.9337
B32: GTV per lot y/y % (forecast input) | D32: =IFERROR(D31/C31-1,"") | E32: =IFERROR(E31/D31-1,"") | F32: =IFERROR(F31/E31-1,"") | G32: =IFERROR(G31/F31-1,"") | H32: =IFERROR(H31/G31-1,"") | I32: =IFERROR(I31/H31-1,"") | O32: =IFERROR(O31/I31-1,"") | P32: =IFERROR(P31/J31-1,"") | Q32: =IFERROR(Q31/K31-1,"") | R32: =IFERROR(R31/L31-1,"") | S32: =IFERROR(S31/M31-1,"") | T32: =IFERROR(T31/N31-1,"") | U32: =IFERROR(U31/O31-1,"") | V32: =IFERROR(V31/P31-1,"") | ... CL32: =IFERROR(CL31/CF31-1,"") -> 0.54484748 | CO32: 0 | CP32: 0 | CQ32: 0 | CR32: 0 | CS32: 0 | CT32: Price/mix per lot (input). 2026E cell drives Q3/Q4-26E lots (vs prior-year quarter GTV per lot). | DB32: OTH_gtvGrowth (Other GTV y/y) | DC32: 0.02 | DD32: Δ → | DE32: -0.03
B33: GTV y/y % | D33: =IFERROR(D29/C29-1,"") | E33: =IFERROR(E29/D29-1,"") | F33: =IFERROR(F29/E29-1,"") | G33: =IFERROR(G29/F29-1,"") | H33: =IFERROR(H29/G29-1,"") | I33: =IFERROR(I29/H29-1,"") | O33: =IFERROR(O29/I29-1,"") | P33: =IFERROR(P29/J29-1,"") | Q33: =IFERROR(Q29/K29-1,"") | R33: =IFERROR(R29/L29-1,"") | S33: =IFERROR(S29/M29-1,"") | T33: =IFERROR(T29/N29-1,"") | U33: =IFERROR(U29/O29-1,"") | V33: =IFERROR(V29/P29-1,"") | ... CO33: =IFERROR(CO29/CI29-1,"") -> 0.088401795 | CP33: =CHOOSE(MATCH($CT$2,{"Bull","Base","Bear"},0),$DC$33,$DD$33,$DE$33) -> 0.05 | CQ33: =CHOOSE(MATCH($CT$2,{"Bull","Base","Bear"},0),$DC$34,$DD$34,$DE$34) -> 0.05 | CR33: =CHOOSE(MATCH($CT$2,{"Bull","Base","Bear"},0),$DC$35,$DD$35,$DE$35) -> 0.05 | CS33: =CHOOSE(MATCH($CT$2,{"Bull","Base","Bear"},0),$DC$36,$DD$36,$DE$36) -> 0.05 | CT33: 2027E–2030E: scenario lever (OTH_gtvGrowth, Bull/Base/Bear table →). | DB33: 2027E | DC33: =DD33+$DC$32 -> 0.07 | DD33: 0.05 | DE33: =DD33+$DE$32 -> 0.02
B34: Lots sold y/y % | D34: =IFERROR(D30/C30-1,"") | E34: =IFERROR(E30/D30-1,"") | F34: =IFERROR(F30/E30-1,"") | G34: =IFERROR(G30/F30-1,"") | H34: =IFERROR(H30/G30-1,"") | I34: =IFERROR(I30/H30-1,"") | O34: =IFERROR(O30/I30-1,"") | P34: =IFERROR(P30/J30-1,"") | Q34: =IFERROR(Q30/K30-1,"") | R34: =IFERROR(R30/L30-1,"") | S34: =IFERROR(S30/M30-1,"") | T34: =IFERROR(T30/N30-1,"") | U34: =IFERROR(U30/O30-1,"") | V34: =IFERROR(V30/P30-1,"") | ... CO34: =IFERROR(CO30/CI30-1,"") -> -0.13078824 | CP34: =IFERROR(CP30/CO30-1,"") -> 0.05 | CQ34: =IFERROR(CQ30/CP30-1,"") -> 0.05 | CR34: =IFERROR(CR30/CQ30-1,"") -> 0.05 | CS34: =IFERROR(CS30/CR30-1,"") -> 0.05 | DB34: 2028E | DC34: =DD34+$DC$32 -> 0.07 | DD34: 0.05 | DE34: =DD34+$DE$32 -> 0.02
B35: Memo: Other GTV — legacy basis (2023–Q1/26) | BR35: 377.5 | BS35: 560.8 | BT35: =BR35+BS35 -> 938.3 | BU35: 471.8 | BV35: 542.8 | BW35: 1952.9 | BX35: 411.2 | BY35: 483.1 | BZ35: =BX35+BY35 -> 894.3 | CA35: 373.5 | CB35: 553.6 | CC35: 1821.4 | CD35: 407.5 | CE35: 513.4 | CF35: =CD35+CE35 -> 920.9 | CG35: 412.7 | CH35: 545.7 | CI35: 1879.2 | CJ35: 429.7 | DB35: 2029E | DC35: =DD35+$DC$32 -> 0.07 | DD35: 0.05 | DE35: =DD35+$DE$32 -> 0.02
B36: Memo: Other lots sold (000s) — legacy basis | BR36: 105.2 | BS36: 172.8 | BT36: =BR36+BS36 -> 278 | BU36: 157.8 | BV36: 155.3 | BW36: 591.1 | BX36: 145.6 | BY36: 173.6 | BZ36: =BX36+BY36 -> 319.2 | CA36: 140.8 | CB36: 157.4 | CC36: 617.3 | CD36: 141.9 | CE36: 153.8 | CF36: =CD36+CE36 -> 295.7 | CG36: 126.7 | CH36: 147.6 | CI36: 570 | CJ36: 128.4 | DB36: 2030E | DC36: =DD36+$DC$32 -> 0.07 | DD36: 0.05 | DE36: =DD36+$DE$32 -> 0.02
B38: Total GTV & lots | CT38: TOTAL GTV — modelling logic | DB38: ADJ_EBITDA_margin (% of total revenue) | DC38: 0.01 | DD38: Δ → | DE38: -0.015 | DF38: FY25 31.6% of revenue; FY26 outlook implies ~30% (inventory-sales mix and acquisitions dilute).
B39: Gross transaction value (GTV; 'gross auction proceeds' to Q2/17) | C39: 2721.023 | D39: 3186.483 | E39: 3567.16 | F39: 3492.021 | G39: 3277.771 | H39: 3714.281 | I39: 3907.991 | J39: 845.353 | K39: 1072.942 | L39: =J39+K39 -> 1918.295 | M39: 789.64 | N39: 1109.834 | O39: 3817.769 | P39: 855.377 | Q39: 1229.204 | R39: =P39+Q39 -> 2084.581 | S39: 886.876 | T39: 1241.184 | U39: 4212.641 | V39: 955.561 | W39: 1262.168 | X39: =V39+W39 -> 2217.729 | Y39: 894.509 | Z39: 1135.397 | AA39: 4247.635 | AB39: 1019.922 | AC39: 1275.682 | AD39: =AB39+AC39 -> 2295.604 | AE39: 998.859 | AF39: 1040.352 | AG39: 4334.815 | AH39: 899.41 | AI39: 1254.318 | AJ39: =AH39+AI39 -> 2153.728 | AK39: 1019.322 | AL39: 1294.932 | AM39: 4467.982 | AN39: 1160.712 | AO39: 1426.412 | AP39: =AN39+AO39 -> 2587.124 | AQ39: 1039.427 | AR39: 1337.614 | AS39: 4964.165 | AT39: 1174.681 | AU39: 1497.757 | AV39: =AT39+AU39 -> 2672.438 | AW39: 1084.241 | AX39: 1383.908 | AY39: 5140.587 | AZ39: 1147.025 | BA39: 1493.982 | BB39: =AZ39+BA39 -> 2641.007 | BC39: 1321.379 | BD39: 1448.832 | BE39: 5411.218 | BF39: 1274.539 | BG39: 1527.642 | BH39: =BF39+BG39 -> 2802.181 | BI39: 1270.258 | BJ39: 1461.492 | BK39: 5533.931 | BL39: 1439.105 | BM39: 1684.276 | BN39: =BL39+BM39 -> 3123.381 | BO39: 1358.242 | BP39: 1544.267 | BQ39: 6025.889 | BR39: 1899.2 | BS39: 4144 | BT39: =BR39+BS39 -> 6043.2 | BU39: 3875.4 | BV39: 4012 | BW39: 13930.6 | BX39: 4077.4 | BY39: 4104.1 | BZ39: =BX39+BY39 -> 8181.5 | CA39: 3622.2 | CB39: 4101.2 | CC39: 15904.8 | CD39: 3828.9 | CE39: 4198.1 | CF39: =CD39+CE39 -> 8027 | CG39: 3893.8 | CH39: 4281.1 | CI39: 16201.9 | CJ39: 4340.9 | CK39: 4672.7 | CL39: =CJ39+CK39 -> 9013.6 | CM39: =(CI39*(1+CHOOSE(MATCH($CT$2,{"Bull","Base","Bear"},0),$DC$12,$DD$12,$DE$12))-CL39)*CG39/(CG39+CH39) -> 4195.5863 | CN39: =(CI39*(1+CHOOSE(MATCH($CT$2,{"Bull","Base","Bear"},0),$DC$12,$DD$12,$DE$12))-CL39)*CH39/(CG39+CH39) -> 4612.9037 | CO39: =SUM(CJ39,CK39,CM39,CN39) -> 17822.09 | CP39: =CP11+CP19+CP29 -> 18793.003 | CQ39: =CQ11+CQ19+CQ29 -> 19690.355 | CR39: =CR11+CR19+CR29 -> 20535.021 | CS39: =CS11+CS19+CS29 -> 21416.07 | CT39: Q3/26E–Q4/26E: FY26 outlook GTV growth (scenario: 11% / 10% / 9%) on FY25 GTV, less 1H/26 actual, split by Q3/Q4-25 seasonality. 2027E+: sum of sectors. | CV39: =IFERROR((CS39/CI39)^(1/5)-1,"n/m") -> 0.057388943 | CW39: =IFERROR((CI39/BE39)^(1/5)-1,"n/m") -> 0.24524321 | CX39: =IFERROR((CI39/AA39)^(1/10)-1,"n/m") -> 0.14325175 | CY39: =IFERROR((CI39/C39)^(1/19)-1,"n/m") -> 0.098451087 | DB39: 2027E | DC39: =DD39+$DC$38 -> 0.315 | DD39: 0.305 | DE39: =DD39+$DE$38 -> 0.29
B40: GTV y/y % | D40: =IFERROR(D39/C39-1,"") -> 0.17106066 | E40: =IFERROR(E39/D39-1,"") -> 0.1194662 | F40: =IFERROR(F39/E39-1,"") -> -0.021064096 | G40: =IFERROR(G39/F39-1,"") -> -0.061354156 | H40: =IFERROR(H39/G39-1,"") -> 0.13317282 | I40: =IFERROR(I39/H39-1,"") -> 0.052152759 | O40: =IFERROR(O39/I39-1,"") -> -0.023086542 | P40: =IFERROR(P39/J39-1,"") -> 0.011857768 | Q40: =IFERROR(Q39/K39-1,"") -> 0.14563881 | R40: =IFERROR(R39/L39-1,"") -> 0.086684269 | S40: =IFERROR(S39/M39-1,"") -> 0.12313966 | T40: =IFERROR(T39/N39-1,"") -> 0.11835103 | U40: =IFERROR(U39/O39-1,"") -> 0.10343004 | V40: =IFERROR(V39/P39-1,"") -> 0.11712263 | ... CO40: =IFERROR(CO39/CI39-1,"") -> 0.1 | CP40: =IFERROR(CP39/CO39-1,"") -> 0.054478071 | CQ40: =IFERROR(CQ39/CP39-1,"") -> 0.047749239 | CR40: =IFERROR(CR39/CQ39-1,"") -> 0.042897474 | CS40: =IFERROR(CS39/CR39-1,"") -> 0.042904681 | DB40: 2028E | DC40: =DD40+$DC$38 -> 0.32 | DD40: 0.31 | DE40: =DD40+$DE$38 -> 0.295
B41: Non-automotive GTV (HE&T + Other; total − Automotive) | C41: =IF(ISNUMBER(C11),C39-C11,"") | D41: =IF(ISNUMBER(D11),D39-D11,"") | E41: =IF(ISNUMBER(E11),E39-E11,"") | F41: =IF(ISNUMBER(F11),F39-F11,"") | G41: =IF(ISNUMBER(G11),G39-G11,"") | H41: =IF(ISNUMBER(H11),H39-H11,"") | I41: =IF(ISNUMBER(I11),I39-I11,"") | J41: =IF(ISNUMBER(J11),J39-J11,"") | ... CL41: =IF(ISNUMBER(CL11),CL39-CL11,"") -> 4275.7 | CM41: =CM39-CM11 -> 1921.6281 | CN41: =CN39-CN11 -> 2291.9233 | CO41: =SUM(CJ41,CK41,CM41,CN41) -> 8489.2514 | CP41: =CP39-CP11 -> 8993.5225 | CQ41: =CQ39-CQ11 -> 9400.9001 | CR41: =CR39-CR11 -> 9782.5411 | CS41: =CS39-CS11 -> 10179.728 | CT41: Comparable across the 2026 sector re-presentation (Automotive composition unchanged). | DB41: 2029E | DC41: =DD41+$DC$38 -> 0.325 | DD41: 0.315 | DE41: =DD41+$DE$38 -> 0.3
...

Sheet Bull-Base-Bear
B2: RB Global, Inc. (RBA) — Bull / Base / Bear Case P&L Summary | J2: Share price ($): | K2: =Model!$CO$381 -> 80
B3: Adjusted figures (company definitions) · USD millions · Live panel linked to Model — toggle scenario via Model!CT2. Bull and Bear panels are value snapshots generated from the Model with the switch set to each case. | J3: As of: | K3: =TODAY() -> 46298
B5: Scenario: | C5: =Model!CT2 -> Base | N5: Scenario: | O5: Bull | P5: Snapshot (values) — Model run with switch = Bull | Z5: Scenario: | AA5: Bear | AB5: Snapshot (values) — Model run with switch = Bear
B7: (USDm, except EPS and shares) | C7: 2025A | D7: 2026E | E7: 2027E | F7: 2028E | G7: 2029E | H7: 2030E | I7: 25-'30 CAGR | J7: LT Hist Avg | K7: LT Hist Min | L7: LT Hist Max | N7: (USDm, except EPS and shares) | O7: 2025A | P7: 2026E | Q7: 2027E | R7: 2028E | S7: 2029E | T7: 2030E | U7: 25-'30 CAGR | V7: LT Hist Avg | W7: LT Hist Min | X7: LT Hist Max | Z7: (USDm, except EPS and shares) | AA7: 2025A | AB7: 2026E | AC7: 2027E | AD7: 2028E | AE7: 2029E | AF7: 2030E | AG7: 25-'30 CAGR | AH7: LT Hist Avg | AI7: LT Hist Min | AJ7: LT Hist Max
B9: Revenue | C9: =Model!CI95 -> 4590.7 | D9: =Model!CO95 -> 5006.0521 | E9: =Model!CP95 -> 5262.0409 | F9: =Model!CQ95 -> 5513.2993 | G9: =Model!CR95 -> 5749.8059 | H9: =Model!CS95 -> 5996.4995 | I9: =IFERROR((H9/C9)^(1/5)-1,"n/m") -> 0.054881748 | N9: Revenue | O9: 4590.7 | P9: 5051.1963 | Q9: 5410.5894 | R9: 5777.1535 | S9: 6140.5221 | T9: 6526.7891 | U9: 0.072912074 | Z9: Revenue | AA9: 4590.7 | AB9: 4960.908 | AC9: 5043.7163 | AD9: 5110.7127 | AE9: 5154.0598 | AF9: 5198.0718 | AG9: 0.025162409
B10: Revenue y/y % | D10: =IFERROR(D9/C9-1,"") -> 0.090476862 | E10: =IFERROR(E9/D9-1,"") -> 0.051135851 | F10: =IFERROR(F9/E9-1,"") -> 0.047749239 | G10: =IFERROR(G9/F9-1,"") -> 0.042897474 | H10: =IFERROR(H9/G9-1,"") -> 0.042904681 | N10: Revenue y/y % | P10: 0.10031069 | Q10: 0.071150112 | R10: 0.067749374 | S10: 0.062897512 | T10: 0.062904583 | Z10: Revenue y/y % | AB10: 0.080643037 | AC10: 0.016692163 | AD10: 0.013283147 | AE10: 0.0084816217 | AF10: 0.0085392904
B11: GTV | C11: =Model!CI39 -> 16201.9 | D11: =Model!CO39 -> 17822.09 | E11: =Model!CP39 -> 18793.003 | F11: =Model!CQ39 -> 19690.355 | G11: =Model!CR39 -> 20535.021 | H11: =Model!CS39 -> 21416.07 | I11: =IFERROR((H11/C11)^(1/5)-1,"n/m") -> 0.057388943 | N11: GTV | O11: 16201.9 | P11: 17984.109 | Q11: 19323.534 | R11: 20632.691 | S11: 21930.436 | T11: 23309.961 | U11: 0.075462123 | Z11: GTV | AA11: 16201.9 | AB11: 17660.071 | AC11: 18013.272 | AD11: 18252.545 | AE11: 18407.357 | AF11: 18564.542 | AG11: 0.027598969
B12: Adjusted EBIT (model) | C12: =Model!CI87 -> 1198.7 | D12: =Model!CO87 -> 1303.608 | E12: =Model!CP87 -> 1378.6547 | F12: =Model!CQ87 -> 1472.0509 | G12: =Model!CR87 -> 1563.9472 | H12: =Model!CS87 -> 1661.0304 | I12: =IFERROR((H12/C12)^(1/5)-1,"n/m") -> 0.067415275 | N12: Adjusted EBIT (model) | O12: 1198.7 | P12: 1326.6566 | Q12: 1471.6803 | R12: 1600.2715 | S12: 1731.6272 | T12: 1873.1885 | U12: 0.093387724 | Z12: Adjusted EBIT (model) | AA12: 1198.7 | AB12: 1280.5594 | AC12: 1245.7979 | AD12: 1287.8996 | AE12: 1324.5934 | AF12: 1361.8948 | AG12: 0.025856496
B13: Adjusted EBIT margin % | C13: =IFERROR(C12/C9,"") -> 0.26111486 | D13: =IFERROR(D12/D9,"") -> 0.26040639 | E13: =IFERROR(E12/E9,"") -> 0.262 | F13: =IFERROR(F12/F9,"") -> 0.267 | G13: =IFERROR(G12/G9,"") -> 0.272 | H13: =IFERROR(H12/H9,"") -> 0.277 | J13: =IFERROR(AVERAGE(Model!C88,Model!D88,Model!E88,Model!F88,Model!G88,Model!H88,Model!I88,Model!O88,Model!U88,Model!AA88,Model!AG88,Model!AM88,Model!AS88,Model!AY88,Model!BE88,Model!BK88,Model!BQ88,Model!BW88,Model!CC88,Model!CI88),"") -> 0.268939 | K13: =IFERROR(MIN(Model!C88,Model!D88,Model!E88,Model!F88,Model!G88,Model!H88,Model!I88,Model!O88,Model!U88,Model!AA88,Model!AG88,Model!AM88,Model!AS88,Model!AY88,Model!BE88,Model!BK88,Model!BQ88,Model!BW88,Model!CC88,Model!CI88),"") -> 0.14294819 | L13: =IFERROR(MAX(Model!C88,Model!D88,Model!E88,Model!F88,Model!G88,Model!H88,Model!I88,Model!O88,Model!U88,Model!AA88,Model!AG88,Model!AM88,Model!AS88,Model!AY88,Model!BE88,Model!BK88,Model!BQ88,Model!BW88,Model!CC88,Model!CI88),"") -> 0.38089669 | N13: Adjusted EBIT margin % | O13: 0.26111486 | P13: 0.26264205 | Q13: 0.272 | R13: 0.277 | S13: 0.282 | T13: 0.287 | V13: 0.268939 | W13: 0.14294819 | X13: 0.38089669 | Z13: Adjusted EBIT margin % | AA13: 0.26111486 | AB13: 0.25813004 | AC13: 0.247 | AD13: 0.252 | AE13: 0.257 | AF13: 0.262 | AH13: 0.268939 | AI13: 0.14294819 | AJ13: 0.38089669
B15: Operating Income (GAAP) | C15: =Model!CI106 -> 713.4 | D15: =Model!CO106 -> 899.10797 | E15: =Model!CP106 -> 1045.6547 | F15: =Model!CQ106 -> 1188.0509 | G15: =Model!CR106 -> 1296.9472 | H15: =Model!CS106 -> 1396.0304 | I15: =IFERROR((H15/C15)^(1/5)-1,"n/m") -> 0.14370061 | N15: Operating Income (GAAP) | O15: 713.4 | P15: 922.15656 | Q15: 1138.6803 | R15: 1316.2715 | S15: 1464.6272 | T15: 1608.1885 | U15: 0.17652394 | Z15: Operating Income (GAAP) | AA15: 713.4 | AB15: 876.05937 | AC15: 912.79792 | AD15: 1003.8996 | AE15: 1057.5934 | AF15: 1096.8948 | AG15: 0.089849116
B16: Operating income y/y % | D16: =IFERROR(D15/C15-1,"") -> 0.26031394 | E16: =IFERROR(E15/D15-1,"") -> 0.16299126 | F16: =IFERROR(F15/E15-1,"") -> 0.136179 | G16: =IFERROR(G15/F15-1,"") -> 0.091659621 | H16: =IFERROR(H15/G15-1,"") -> 0.076397214 | N16: Operating income y/y % | P16: 0.29262204 | Q16: 0.23480152 | R16: 0.15596229 | S16: 0.11270905 | T16: 0.098018957 | Z16: Operating income y/y % | AB16: 0.22800585 | AC16: 0.041936141 | AD16: 0.099804873 | AE16: 0.053485205 | AF16: 0.037161207
B17: Operating margin (GAAP) % | C17: =IFERROR(C15/C9,"") -> 0.15540114 | D17: =IFERROR(D15/D9,"") -> 0.1796042 | E17: =IFERROR(E15/E9,"") -> 0.19871657 | F17: =IFERROR(F15/F9,"") -> 0.21548819 | G17: =IFERROR(G15/G9,"") -> 0.22556365 | H17: =IFERROR(H15/H9,"") -> 0.23280755 | J17: =IFERROR(AVERAGE(Model!C210,Model!D210,Model!E210,Model!F210,Model!G210,Model!H210,Model!I210,Model!O210,Model!U210,Model!AA210,Model!AG210,Model!AM210,Model!AS210,Model!AY210,Model!BE210,Model!BK210,Model!BQ210,Model!BW210,Model!CC210,Model!CI210),"") -> 0.23970623 | K17: =IFERROR(MIN(Model!C210,Model!D210,Model!E210,Model!F210,Model!G210,Model!H210,Model!I210,Model!O210,Model!U210,Model!AA210,Model!AG210,Model!AM210,Model!AS210,Model!AY210,Model!BE210,Model!BK210,Model!BQ210,Model!BW210,Model!CC210,Model!CI210),"") -> 0.11327638 | L17: =IFERROR(MAX(Model!C210,Model!D210,Model!E210,Model!F210,Model!G210,Model!H210,Model!I210,Model!O210,Model!U210,Model!AA210,Model!AG210,Model!AM210,Model!AS210,Model!AY210,Model!BE210,Model!BK210,Model!BQ210,Model!BW210,Model!CC210,Model!CI210),"") -> 0.34417081 | N17: Operating margin (GAAP) % | O17: 0.15540114 | P17: 0.18256201 | Q17: 0.21045403 | R17: 0.22784084 | S17: 0.23851836 | T17: 0.24639811 | V17: 0.23970623 | W17: 0.11327638 | X17: 0.34417081 | Z17: Operating margin (GAAP) % | AA17: 0.15540114 | AB17: 0.17659255 | AC17: 0.18097725 | AD17: 0.19643045 | AE17: 0.20519618 | AF17: 0.21101956 | AH17: 0.23970623 | AI17: 0.11327638 | AJ17: 0.34417081
B19: Net Income (Adjusted, available to common) | C19: =Model!CI188 -> 747 | D19: =Model!CO188 -> 821.88606 | E19: =Model!CP188 -> 872.71941 | F19: =Model!CQ188 -> 948.91795 | G19: =Model!CR188 -> 1024.9357 | H19: =Model!CS188 -> 1103.1648 | I19: =IFERROR((H19/C19)^(1/5)-1,"n/m") -> 0.081095246 | N19: Net Income (Adjusted, available to common) | O19: 747 | P19: 839.40299 | Q19: 938.63092 | R19: 1039.2725 | S19: 1143.3414 | T19: 1253.8575 | U19: 0.10913782 | Z19: Net Income (Adjusted, available to common) | AA19: 747 | AB19: 804.36912 | AC19: 778.50699 | AD19: 818.74764 | AE19: 855.25771 | AF19: 889.85779 | AG19: 0.035618979
B21: FDSO (m) | C21: =Model!CI127 -> 186.9 | D21: =Model!CO127 -> 186.1125 | E21: =Model!CP127 -> 182.36355 | F21: =Model!CQ127 -> 178.44351 | G21: =Model!CR127 -> 174.56407 | H21: =Model!CS127 -> 170.48419 | I21: =IFERROR((H21/C21)^(1/5)-1,"n/m") -> -0.018218239 | N21: FDSO (m) | O21: 186.9 | P21: 185.40938 | Q21: 179.61238 | R21: 173.99732 | S21: 168.53376 | T21: 162.97338 | U21: -0.027025465 | Z21: FDSO (m) | AA21: 186.9 | AB21: 187.05 | AC21: 186.03178 | AD21: 184.37175 | AE21: 182.60449 | AF21: 180.4986 | AG21: -0.0069459088
B23: Adjusted EPS — Diluted ($) | C23: =Model!CI191 -> 3.9967897 | D23: =Model!CO191 -> 4.4160712 | E23: =Model!CP191 -> 4.7856022 | F23: =Model!CQ191 -> 5.31775 | G23: =Model!CR191 -> 5.8714014 | H23: =Model!CS191 -> 6.4707749 | I23: =IFERROR((H23/C23)^(1/5)-1,"n/m") -> 0.10115638 | N23: Adjusted EPS — Diluted ($) | O23: 3.9967897 | P23: 4.5272953 | Q23: 5.2258697 | R23: 5.9729226 | S23: 6.78405 | T23: 7.6936337 | U23: 0.13994537 | Z23: Adjusted EPS — Diluted ($) | AA23: 3.9967897 | AB23: 4.3002893 | AC23: 4.1848065 | AD23: 4.4407433 | AE23: 4.683662 | AF23: 4.9299984 | AG23: 0.042862607
B24: EPS y/y % | D24: =IFERROR(D23/C23-1,"") -> 0.10490457 | E24: =IFERROR(E23/D23-1,"") -> 0.083678675 | F24: =IFERROR(F23/E23-1,"") -> 0.11119765 | G24: =IFERROR(G23/F23-1,"") -> 0.10411386 | H24: =IFERROR(H23/G23-1,"") -> 0.10208353 | N24: EPS y/y % | P24: 0.13273291 | Q24: 0.15430283 | R24: 0.14295282 | S24: 0.13580077 | T24: 0.13407678 | Z24: EPS y/y % | AB24: 0.075935849 | AC24: -0.026854667 | AD24: 0.061158584 | AE24: 0.054702259 | AF24: 0.05259482
B26: P / E (x) — assumed (adjusted EPS) | E26: 22 | F26: =E26 -> 22 | G26: =F26 -> 22 | H26: =G26 -> 22 | N26: P / E (x) — assumed (adjusted EPS) | Q26: 26 | R26: =Q26 -> 26 | S26: =R26 -> 26 | T26: =S26 -> 26 | Z26: P / E (x) — assumed (adjusted EPS) | AC26: 17 | AD26: =AC26 -> 17 | AE26: =AD26 -> 17 | AF26: =AE26 -> 17
B27: Price Target ($) | E27: =E26*E23 -> 105.28325 | F27: =F26*F23 -> 116.9905 | G27: =G26*G23 -> 129.17083 | H27: =H26*H23 -> 142.35705 | N27: Price Target ($) | Q27: =Q26*Q23 -> 135.87261 | R27: =R26*R23 -> 155.29599 | S27: =S26*S23 -> 176.3853 | T27: =T26*T23 -> 200.03447 | Z27: Price Target ($) | AC27: =AC26*AC23 -> 71.141711 | AD27: =AD26*AD23 -> 75.492637 | AE27: =AE26*AE23 -> 79.622255 | AF27: =AF26*AF23 -> 83.809973
B28: Upside / (Downside) vs current | E28: =IFERROR(E27/$K$2-1,"") -> 0.31604061 | F28: =IFERROR(F27/$K$2-1,"") -> 0.46238124 | G28: =IFERROR(G27/$K$2-1,"") -> 0.6146354 | H28: =IFERROR(H27/$K$2-1,"") -> 0.77946308 | N28: Upside / (Downside) vs current | Q28: =IFERROR(Q27/$K$2-1,"") -> 0.69840767 | R28: =IFERROR(R27/$K$2-1,"") -> 0.94119984 | S28: =IFERROR(S27/$K$2-1,"") -> 1.2048163 | T28: =IFERROR(T27/$K$2-1,"") -> 1.5004309 | Z28: Upside / (Downside) vs current | AC28: =IFERROR(AC27/$K$2-1,"") -> -0.11072862 | AD28: =IFERROR(AD27/$K$2-1,"") -> -0.056342038 | AE28: =IFERROR(AE27/$K$2-1,"") -> -0.0047218163 | AF28: =IFERROR(AF27/$K$2-1,"") -> 0.047624661
B29: IRR (to Dec-Y-1) | F29: =IFERROR((F27/$K$2)^(1/((DATE(2028-1,12,31)-$K$3)/365.25))-1,"") -> 0.35766869 | G29: =IFERROR((G27/$K$2)^(1/((DATE(2029-1,12,31)-$K$3)/365.25))-1,"") -> 0.2378897 | H29: =IFERROR((H27/$K$2)^(1/((DATE(2030-1,12,31)-$K$3)/365.25))-1,"") -> 0.19438966 | N29: IRR (to Dec-Y-1) | R29: =IFERROR((R27/$K$2)^(1/((DATE(2028-1,12,31)-$K$3)/365.25))-1,"") -> 0.70512788 | S29: =IFERROR((S27/$K$2)^(1/((DATE(2029-1,12,31)-$K$3)/365.25))-1,"") -> 0.42215614 | T29: =IFERROR((T27/$K$2)^(1/((DATE(2030-1,12,31)-$K$3)/365.25))-1,"") -> 0.32641451 | Z29: IRR (to Dec-Y-1) | AD29: =IFERROR((AD27/$K$2)^(1/((DATE(2028-1,12,31)-$K$3)/365.25))-1,"") -> -0.045583444 | AE29: =IFERROR((AE27/$K$2)^(1/((DATE(2029-1,12,31)-$K$3)/365.25))-1,"") -> -0.0021059841 | AF29: =IFERROR((AF27/$K$2)^(1/((DATE(2030-1,12,31)-$K$3)/365.25))-1,"") -> 0.014443733
B31: Free Cash Flow | C31: =Model!CI251 -> 608 | D31: =Model!CO251 -> 715.07608 | E31: =Model!CP251 -> 805.7705 | F31: =Model!CQ251 -> 889.86212 | G31: =Model!CR251 -> 976.26565 | H31: =Model!CS251 -> 1071.5299 | I31: =IFERROR((H31/C31)^(1/5)-1,"n/m") -> 0.12000547 | N31: Free Cash Flow | O31: 608 | P31: 737.99728 | Q31: 877.3761 | R31: 985.01347 | S31: 1098.8974 | T31: 1226.4717 | U31: 0.15067 | Z31: Free Cash Flow | AA31: 608 | AB31: 692.15489 | AC31: 701.36808 | AD31: 751.71846 | AE31: 800.24583 | AF31: 852.56091 | AG31: 0.069952178
B32: FCF % | C32: =IFERROR(C31/C9,"") -> 0.13244168 | D32: =IFERROR(D31/D9,"") -> 0.14284232 | E32: =IFERROR(E31/E9,"") -> 0.15312889 | F32: =IFERROR(F31/F9,"") -> 0.16140283 | G32: =IFERROR(G31/G9,"") -> 0.16979106 | H32: =IFERROR(H31/H9,"") -> 0.17869257 | J32: =IFERROR(AVERAGE(Model!C253,Model!D253,Model!E253,Model!F253,Model!G253,Model!H253,Model!I253,Model!O253,Model!U253,Model!AA253,Model!AG253,Model!AM253,Model!AS253,Model!AY253,Model!BE253,Model!BK253,Model!BQ253,Model!BW253,Model!CC253,Model!CI253),"") -> 0.14542509 | K32: =IFERROR(MIN(Model!C253,Model!D253,Model!E253,Model!F253,Model!G253,Model!H253,Model!I253,Model!O253,Model!U253,Model!AA253,Model!AG253,Model!AM253,Model!AS253,Model!AY253,Model!BE253,Model!BK253,Model!BQ253,Model!BW253,Model!CC253,Model!CI253),"") -> -0.057840921 | L32: =IFERROR(MAX(Model!C253,Model!D253,Model!E253,Model!F253,Model!G253,Model!H253,Model!I253,Model!O253,Model!U253,Model!AA253,Model!AG253,Model!AM253,Model!AS253,Model!AY253,Model!BE253,Model!BK253,Model!BQ253,Model!BW253,Model!CC253,Model!CI253),"") -> 0.35339375 | N32: FCF % | O32: 0.13244168 | P32: 0.14610346 | Q32: 0.16215906 | R32: 0.17050152 | S32: 0.1789583 | T32: 0.18791349 | V32: 0.14542509 | W32: -0.057840921 | X32: 0.35339375 | Z32: FCF % | AA32: 0.13244168 | AB32: 0.13952182 | AC32: 0.1390578 | AD32: 0.14708682 | AE32: 0.15526514 | AF32: 0.16401484 | AH32: 0.14542509 | AI32: -0.057840921 | AJ32: 0.35339375
B33: FCF / share ($) | C33: =IFERROR(C31/C21,"") -> 3.2530765 | D33: =IFERROR(D31/D21,"") -> 3.8421712 | E33: =IFERROR(E31/E21,"") -> 4.4184843 | F33: =IFERROR(F31/F21,"") -> 4.9868003 | G33: =IFERROR(G31/G21,"") -> 5.5925921 | H33: =IFERROR(H31/H21,"") -> 6.2852158 | N33: FCF / share ($) | O33: 3.2530765 | P33: 3.9803666 | Q33: 4.8848308 | R33: 5.6610842 | S33: 6.5203399 | T33: 7.5255954 | Z33: FCF / share ($) | AA33: 3.2530765 | AB33: 3.7003737 | AC33: 3.770152 | AD33: 4.0771889 | AE33: 4.3823996 | AF33: 4.7233659
B34: FCF Yield (on PT) | E34: =IFERROR(E33/E$27,"") -> 0.041967591 | F34: =IFERROR(F33/F$27,"") -> 0.042625686 | G34: =IFERROR(G33/G$27,"") -> 0.043296091 | H34: =IFERROR(H33/H$27,"") -> 0.044151069 | N34: FCF Yield (on PT) | Q34: =IFERROR(Q33/Q$27,"") -> 0.035951548 | R34: =IFERROR(R33/R$27,"") -> 0.036453512 | S34: =IFERROR(S33/S$27,"") -> 0.036966459 | T34: =IFERROR(T33/T$27,"") -> 0.037621492 | Z34: FCF Yield (on PT) | AC34: =IFERROR(AC33/AC$27,"") -> 0.052994959 | AD34: =IFERROR(AD33/AD$27,"") -> 0.054007769 | AE34: =IFERROR(AE33/AE$27,"") -> 0.055039883 | AF34: =IFERROR(AF33/AF$27,"") -> 0.056358041
B35: Adjusted EBITDA | C35: =Model!CI80 -> 1399.7 | D35: =Model!CO80 -> 1520 | E35: =Model!CP80 -> 1604.9225 | F35: =Model!CQ80 -> 1709.1228 | G35: =Model!CR80 -> 1811.1889 | H35: =Model!CS80 -> 1918.8798 | I35: =IFERROR((H35/C35)^(1/5)-1,"n/m") -> 0.065129869 | N35: Adjusted EBITDA | O35: 1399.7 | P35: 1545 | Q35: 1704.3357 | R35: 1848.6891 | S35: 1995.6697 | T35: 2153.8404 | U35: 0.090023123 | Z35: Adjusted EBITDA | AA35: 1399.7 | AB35: 1495 | AC35: 1462.6777 | AD35: 1507.6602 | AE35: 1546.218 | AF35: 1585.4119 | AG35: 0.025230295
B36: Adjusted EBITDA margin % | C36: =IFERROR(C35/C9,"") -> 0.30489904 | D36: =IFERROR(D35/D9,"") -> 0.30363248 | E36: =IFERROR(E35/E9,"") -> 0.305 | F36: =IFERROR(F35/F9,"") -> 0.31 | G36: =IFERROR(G35/G9,"") -> 0.315 | H36: =IFERROR(H35/H9,"") -> 0.32 | J36: =IFERROR(AVERAGE(Model!C209,Model!D209,Model!E209,Model!F209,Model!G209,Model!H209,Model!I209,Model!O209,Model!U209,Model!AA209,Model!AG209,Model!AM209,Model!AS209,Model!AY209,Model!BE209,Model!BK209,Model!BQ209,Model!BW209,Model!CC209,Model!CI209),"") -> 0.33418027 | K36: =IFERROR(MIN(Model!C209,Model!D209,Model!E209,Model!F209,Model!G209,Model!H209,Model!I209,Model!O209,Model!U209,Model!AA209,Model!AG209,Model!AM209,Model!AS209,Model!AY209,Model!BE209,Model!BK209,Model!BQ209,Model!BW209,Model!CC209,Model!CI209),"") -> 0.19720529 | L36: =IFERROR(MAX(Model!C209,Model!D209,Model!E209,Model!F209,Model!G209,Model!H209,Model!I209,Model!O209,Model!U209,Model!AA209,Model!AG209,Model!AM209,Model!AS209,Model!AY209,Model!BE209,Model!BK209,Model!BQ209,Model!BW209,Model!CC209,Model!CI209),"") -> 0.45069021 | N36: Adjusted EBITDA margin % | O36: 0.30489904 | P36: 0.30586814 | Q36: 0.315 | R36: 0.32 | S36: 0.325 | T36: 0.33 | V36: 0.33418027 | W36: 0.19720529 | X36: 0.45069021 | Z36: Adjusted EBITDA margin % | AA36: 0.30489904 | AB36: 0.30135612 | AC36: 0.29 | AD36: 0.295 | AE36: 0.3 | AF36: 0.305 | AH36: 0.33418027 | AI36: 0.19720529 | AJ36: 0.45069021
B38: Net Debt (adjusted) | C38: =Model!CI376 -> 1940 | D38: =Model!CO376 -> 2167.1119 | E38: =Model!CP376 -> 2018.8441 | F38: =Model!CQ376 -> 1795.595 | G38: =Model!CR376 -> 1545.323 | H38: =Model!CS376 -> 1259.0513 | N38: Net Debt (adjusted) | O38: 1940 | P38: 2293.2907 | Q38: 2219.6845 | R38: 2044.8896 | S38: 1812.7926 | T38: 1509.4419 | Z38: Net Debt (adjusted) | AA38: 1940 | AB38: 1991.2331 | AC38: 1752.3448 | AD38: 1475.7654 | AE38: 1213.7708 | AF38: 962.65114
B39: Net Debt / Adjusted EBITDA (x) | C39: =IFERROR(C38/C35,"") -> 1.3860113 | D39: =IFERROR(D38/D35,"") -> 1.4257315 | E39: =IFERROR(E38/E35,"") -> 1.2579076 | F39: =IFERROR(F38/F35,"") -> 1.0505945 | G39: =IFERROR(G38/G35,"") -> 0.85320919 | H39: =IFERROR(H38/H35,"") -> 0.65613871 | N39: Net Debt / Adjusted EBITDA (x) | O39: 1.3860113 | P39: 1.4843306 | Q39: 1.3023752 | R39: 1.1061295 | S39: 0.90836304 | T39: 0.70081417 | Z39: Net Debt / Adjusted EBITDA (x) | AA39: 1.3860113 | AB39: 1.3319285 | AC39: 1.1980389 | AD39: 0.97884481 | AE39: 0.78499334 | AF39: 0.60719308
B41: ROIC | C41: =Model!CI356 -> 0.11950879 | D41: =Model!CO356 -> 0.12006215 | E41: =Model!CP356 -> 0.1277394 | F41: =Model!CQ356 -> 0.13660667 | G41: =Model!CR356 -> 0.14518264 | H41: =Model!CS356 -> 0.15439116 | J41: =IFERROR(AVERAGE(Model!C356,Model!D356,Model!E356,Model!F356,Model!G356,Model!H356,Model!I356,Model!O356,Model!U356,Model!AA356,Model!AG356,Model!AM356,Model!AS356,Model!AY356,Model!BE356,Model!BK356,Model!BQ356,Model!BW356,Model!CC356,Model!CI356),"") -> 0.1488023 | K41: =IFERROR(MIN(Model!C356,Model!D356,Model!E356,Model!F356,Model!G356,Model!H356,Model!I356,Model!O356,Model!U356,Model!AA356,Model!AG356,Model!AM356,Model!AS356,Model!AY356,Model!BE356,Model!BK356,Model!BQ356,Model!BW356,Model!CC356,Model!CI356),"") -> 0.082450537 | L41: =IFERROR(MAX(Model!C356,Model!D356,Model!E356,Model!F356,Model!G356,Model!H356,Model!I356,Model!O356,Model!U356,Model!AA356,Model!AG356,Model!AM356,Model!AS356,Model!AY356,Model!BE356,Model!BK356,Model!BQ356,Model!BW356,Model!CC356,Model!CI356),"") -> 0.23134292 | N41: ROIC | O41: 0.11950879 | P41: 0.122265 | Q41: 0.13650361 | R41: 0.14869126 | S41: 0.16094825 | T41: 0.17430168 | V41: 0.1488023 | W41: 0.082450537 | X41: 0.23134292 | Z41: ROIC | AA41: 0.11950879 | AB41: 0.11786219 | AC41: 0.11525843 | AD41: 0.11929264 | AE41: 0.12272909 | AF41: 0.12637749 | AH41: 0.1488023 | AI41: 0.082450537 | AJ41: 0.23134292
B42: RONTA | C42: =Model!CI368 -> 0.26722621 | D42: =Model!CO368 -> 0.25952282 | E42: =Model!CP368 -> 0.26279298 | F42: =Model!CQ368 -> 0.2649087 | G42: =Model!CR368 -> 0.26509019 | H42: =Model!CS368 -> 0.26438957 | J42: =IFERROR(AVERAGE(Model!C368,Model!D368,Model!E368,Model!F368,Model!G368,Model!H368,Model!I368,Model!O368,Model!U368,Model!AA368,Model!AG368,Model!AM368,Model!AS368,Model!AY368,Model!BE368,Model!BK368,Model!BQ368,Model!BW368,Model!CC368,Model!CI368),"") -> 0.18381418 | K42: =IFERROR(MIN(Model!C368,Model!D368,Model!E368,Model!F368,Model!G368,Model!H368,Model!I368,Model!O368,Model!U368,Model!AA368,Model!AG368,Model!AM368,Model!AS368,Model!AY368,Model!BE368,Model!BK368,Model!BQ368,Model!BW368,Model!CC368,Model!CI368),"") -> 0.098495413 | L42: =IFERROR(MAX(Model!C368,Model!D368,Model!E368,Model!F368,Model!G368,Model!H368,Model!I368,Model!O368,Model!U368,Model!AA368,Model!AG368,Model!AM368,Model!AS368,Model!AY368,Model!BE368,Model!BK368,Model!BQ368,Model!BW368,Model!CC368,Model!CI368),"") -> 0.38071221 | N42: RONTA | O42: 0.26722621 | P42: 0.27362011 | Q42: 0.29645127 | R42: 0.30769135 | S42: 0.31440733 | T42: 0.31761069 | V42: 0.18381418 | W42: 0.098495413 | X42: 0.38071221 | Z42: RONTA | AA42: 0.26722621 | AB42: 0.24331119 | AC42: 0.22162639 | AD42: 0.21397281 | AE42: 0.20708654 | AF42: 0.20160121 | AH42: 0.18381418 | AI42: 0.098495413 | AJ42: 0.38071221
B44: Implied Market Cap (USDm) | E44: =E27*E21 -> 19199.827 | F44: =F27*F21 -> 20876.195 | G44: =G27*G21 -> 22548.586 | H44: =H27*H21 -> 24269.625 | N44: Implied Market Cap (USDm) | Q44: =Q27*Q21 -> 24404.404 | R44: =R27*R21 -> 27021.086 | S44: =S27*S21 -> 29726.878 | T44: =T27*T21 -> 32600.294 | Z44: Implied Market Cap (USDm) | AC44: =AC27*AC21 -> 13234.619 | AD44: =AD27*AD21 -> 13918.71 | AE44: =AE27*AE21 -> 14539.381 | AF44: =AF27*AF21 -> 15127.582
B45: (+) Net Debt, preferred & NCI | E45: =E38+Model!CP385 -> 2502.7441 | F45: =F38+Model!CQ385 -> 2279.495 | G45: =G38+Model!CR385 -> 2029.223 | H45: =H38+Model!CS385 -> 1742.9513 | N45: (+) Net Debt, preferred & NCI | Q45: =Q38+Model!CP385 -> 2703.5845 | R45: =R38+Model!CQ385 -> 2528.7896 | S45: =S38+Model!CR385 -> 2296.6926 | T45: =T38+Model!CS385 -> 1993.3419 | Z45: (+) Net Debt, preferred & NCI | AC45: =AC38+Model!CP385 -> 2236.2448 | AD45: =AD38+Model!CQ385 -> 1959.6654 | AE45: =AE38+Model!CR385 -> 1697.6708 | AF45: =AF38+Model!CS385 -> 1446.5511
B46: Implied Enterprise Value (USDm) | E46: =E44+E45 -> 21702.571 | F46: =F44+F45 -> 23155.69 | G46: =G44+G45 -> 24577.809 | H46: =H44+H45 -> 26012.577 | N46: Implied Enterprise Value (USDm) | Q46: =Q44+Q45 -> 27107.988 | R46: =R44+R45 -> 29549.875 | S46: =S44+S45 -> 32023.57 | T46: =T44+T45 -> 34593.636 | Z46: Implied Enterprise Value (USDm) | AC46: =AC44+AC45 -> 15470.864 | AD46: =AD44+AD45 -> 15878.375 | AE46: =AE44+AE45 -> 16237.052 | AF46: =AF44+AF45 -> 16574.134
B47: Implied EV / Adjusted EBITDA (x) | E47: =IFERROR(E46/E35,"") -> 13.522505 | F47: =IFERROR(F46/F35,"") -> 13.548289 | G47: =IFERROR(G46/G35,"") -> 13.569987 | H47: =IFERROR(H46/H35,"") -> 13.556126 | N47: Implied EV / Adjusted EBITDA (x) | Q47: =IFERROR(Q46/Q35,"") -> 15.905311 | R47: =IFERROR(R46/R35,"") -> 15.984232 | S47: =IFERROR(S46/S35,"") -> 16.046528 | T47: =IFERROR(T46/T35,"") -> 16.061374 | Z47: Implied EV / Adjusted EBITDA (x) | AC47: =IFERROR(AC46/AC35,"") -> 10.577083 | AD47: =IFERROR(AD46/AD35,"") -> 10.531799 | AE47: =IFERROR(AE46/AE35,"") -> 10.501141 | AF47: =IFERROR(AF46/AF35,"") -> 10.45415

Sheet DCF
B2: DCF VALUATION — RB GLOBAL, INC. (RBA)
B4: 1. WACC BUILD
B5: Risk-free rate (US 10Y govt) | C5: 0.0425 | D5: Assumption (~US 10Y Treasury yield); update to market
B6: Equity risk premium | C6: 0.055 | D6: Damodaran-style US ERP estimate
B7: Levered beta | C7: 1.05 | D7: Marketplace / auction peers (Copart ~1.0–1.1); cyclical used-equipment exposure, automotive salvage defensive
B8: Cost of equity | C8: =C5+C7*C6 -> 0.10025
B9: Pre-tax cost of debt | C9: 0.0625 | D9: BB-rated; 6.75% secured notes 2028, 7.75% unsecured 2031, TLA at SOFR + margin (~6.2% blended at 30-Jun-26)
B10: Tax rate | C10: 0.24 | D10: FY26 outlook 23–25% (GAAP and adjusted)
B11: After-tax cost of debt | C11: =C9*(1-C10) -> 0.0475
B12: Target D/V | C12: 0.2 | D12: Adjusted net debt / adjusted EBITDA target ~1.5–2.0x
B13: WACC | C13: =C8*(1-C12)+C11*C12 -> 0.0897
B15: Valuation date (live) | C15: =TODAY() -> 46298 | D15: Periods = (Dec-31-Year − today) / 365.25; cash flows assumed at year-end
B16: 2. UNLEVERED FREE CASH FLOW BUILD (USDm)
D17: 2026E | E17: 2027E | F17: 2028E | G17: 2029E | H17: 2030E | I17: 2031E | J17: 2032E | K17: 2033E | L17: 2034E | M17: 2035E | N17: Terminal
B18: Adjusted EBIT (Model) | D18: =Model!CO87 -> 1303.608 | E18: =Model!CP87 -> 1378.6547 | F18: =Model!CQ87 -> 1472.0509 | G18: =Model!CR87 -> 1563.9472 | H18: =Model!CS87 -> 1661.0304 | I18: =H18*(1+I$29) -> 1760.6922 | J18: =I18*(1+J$29) -> 1857.5303 | K18: =J18*(1+K$29) -> 1950.4068 | L18: =K18*(1+L$29) -> 2038.1751 | M18: =L18*(1+M$29) -> 2119.7021
B19: (−) Stock-based compensation (economic cost) | D19: =-Model!CO143 -> -69.2 | E19: =-Model!CP143 -> -75 | F19: =-Model!CQ143 -> -80 | G19: =-Model!CR143 -> -85 | H19: =-Model!CS143 -> -90 | I19: =H19*(1+I$29) -> -95.4 | J19: =I19*(1+J$29) -> -100.647 | K19: =J19*(1+K$29) -> -105.67935 | L19: =K19*(1+L$29) -> -110.43492 | M19: =L19*(1+M$29) -> -114.85232
B20: × (1 − tax rate) | D20: =1-$C$10 -> 0.76 | E20: =1-$C$10 -> 0.76 | F20: =1-$C$10 -> 0.76 | G20: =1-$C$10 -> 0.76 | H20: =1-$C$10 -> 0.76 | I20: =1-$C$10 -> 0.76 | J20: =1-$C$10 -> 0.76 | K20: =1-$C$10 -> 0.76 | ... M20: =1-$C$10 -> 0.76
B21: NOPAT = (Adj. EBIT − SBC) × (1 − t) | D21: =(D18+D19)*D20 -> 938.15006 | E21: =(E18+E19)*E20 -> 990.77758 | F21: =(F18+F19)*F20 -> 1057.9587 | G21: =(G18+G19)*G20 -> 1123.9999 | H21: =(H18+H19)*H20 -> 1193.9831 | I21: =(I18+I19)*I20 -> 1265.6221 | J21: =(J18+J19)*J20 -> 1335.2313 | K21: =(K18+K19)*K20 -> 1401.9928 | ... M21: =(M18+M19)*M20 -> 1523.6858
B22: plus adjusted D&A (ex acquired-intangible amortization) | D22: =Model!CO86 -> 216.39203 | E22: =Model!CP86 -> 226.26776 | F22: =Model!CQ86 -> 237.07187 | G22: =Model!CR86 -> 247.24165 | H22: =Model!CS86 -> 257.84948 | I22: =H22*(1+I$29) -> 273.32045 | J22: =I22*(1+J$29) -> 288.35307 | K22: =J22*(1+K$29) -> 302.77073 | L22: =K22*(1+L$29) -> 316.39541 | M22: =L22*(1+M$29) -> 329.05123
B23: − Capex (PP&E + intangibles, net of disposal proceeds) | D23: =Model!CO229+Model!CO230+Model!CO231 -> -371.7 | E23: =Model!CP229+Model!CP230+Model!CP231 -> -381.49796 | F23: =Model!CQ229+Model!CQ230+Model!CQ231 -> -385.93095 | G23: =Model!CR229+Model!CR230+Model!CR231 -> -388.1119 | H23: =Model!CS229+Model!CS230+Model!CS231 -> -389.77247 | I23: =H23*(1+I$29) -> -413.15882 | J23: =I23*(1+J$29) -> -435.88255 | K23: =J23*(1+K$29) -> -457.67668 | L23: =K23*(1+L$29) -> -478.27213 | M23: =L23*(1+M$29) -> -497.40302
B24: − Δ Working capital (CF statement) | D24: =Model!CO227 -> -3.9020033 | E24: =Model!CP227 -> 12.67825 | F24: =Model!CQ227 -> 18.686547 | G24: =Model!CR227 -> 17.57632 | H24: =Model!CS227 -> 18.326948 | I24: =H24*(1+I$29) -> 19.426565 | J24: =I24*(1+J$29) -> 20.495026 | K24: =J24*(1+K$29) -> 21.519777 | L24: =K24*(1+L$29) -> 22.488167 | M24: =L24*(1+M$29) -> 23.387694
B25: Unlevered FCF | D25: =D21+D22+D23+D24 -> 778.94008 | E25: =E21+E22+E23+E24 -> 848.22562 | F25: =F21+F22+F23+F24 -> 927.78616 | G25: =G21+G22+G23+G24 -> 1000.706 | H25: =H21+H22+H23+H24 -> 1080.387 | I25: =I21+I22+I23+I24 -> 1145.2103 | J25: =J21+J22+J23+J24 -> 1208.1968 | K25: =K21+K22+K23+K24 -> 1268.6067 | ... M25: =M21+M22+M23+M24 -> 1378.7217 | N25: =M25*(1+$C$30) -> 1420.0834
B26: Terminal Value (Gordon Growth) | N26: =N25/($C$13-$C$30) -> 23786.991
B29: Fade-period growth (2031E–35E) | I29: 0.06 | J29: 0.055 | K29: 0.05 | L29: 0.045 | M29: 0.04
B30: Terminal growth rate | C30: 0.03
B32: Discount period (years) | D32: =(DATE(2026,12,31)-$C$15)/365.25 -> 0.24366872 | E32: =(DATE(2027,12,31)-$C$15)/365.25 -> 1.2429843 | F32: =(DATE(2028,12,31)-$C$15)/365.25 -> 2.2450376 | G32: =(DATE(2029,12,31)-$C$15)/365.25 -> 3.2443532 | H32: =(DATE(2030,12,31)-$C$15)/365.25 -> 4.2436687 | I32: =(DATE(2031,12,31)-$C$15)/365.25 -> 5.2429843 | J32: =(DATE(2032,12,31)-$C$15)/365.25 -> 6.2450376 | K32: =(DATE(2033,12,31)-$C$15)/365.25 -> 7.2443532 | L32: =(DATE(2034,12,31)-$C$15)/365.25 -> 8.2436687 | M32: =(DATE(2035,12,31)-$C$15)/365.25 -> 9.2429843 | N32: =M32 -> 9.2429843
B33: Discount factor | D33: =1/(1+$C$13)^D32 -> 0.97928581 | E33: =1/(1+$C$13)^E32 -> 0.89872753 | F33: =1/(1+$C$13)^F32 -> 0.8246022 | G33: =1/(1+$C$13)^G32 -> 0.75676855 | H33: =1/(1+$C$13)^H32 -> 0.69451505 | I33: =1/(1+$C$13)^I32 -> 0.63738266 | J33: =1/(1+$C$13)^J32 -> 0.58481255 | K33: =1/(1+$C$13)^K32 -> 0.53670454 | ... N33: =1/(1+$C$13)^N32 -> 0.45203539
B34: PV of UFCF | D34: =D25*D33 -> 762.80497 | E34: =E25*E33 -> 762.32372 | F34: =F25*F33 -> 765.05451 | G34: =G25*G33 -> 757.3028 | H34: =H25*H33 -> 750.34505 | I34: =I25*I33 -> 729.93716 | J34: =J25*J33 -> 706.56867 | K34: =K25*K33 -> 680.86696 | ... M34: =M25*M33 -> 623.23102 | N34: =N26*N33 -> 10752.562
D35: SBC is deducted as an economic cost (RB Global adds it back in adjusted EBITDA / EPS). Acquired-intangible amortization is non-cash and excluded; operating-lease costs sit inside adjusted EBITDA (lease liabilities therefore not deducted as debt).
B37: 3. VALUATION SUMMARY
B38: Sum of PV (explicit + fade) | C38: =SUM(D34:M34) -> 7191.4107
B39: PV of Terminal Value | C39: =N34 -> 10752.562
B40: Enterprise Value | C40: =C38+C39 -> 17943.973
B41: Less: adjusted net debt (Model 2026E YE) | C41: =Model!CO376 -> 2167.1119
B42: Less: Series A preferred, redeemable NCI & NCI (Model 2026E) | C42: =Model!CO385 -> 483.9
B43: Equity Value | C43: =C40-C41-C42 -> 15292.961
B44: Diluted shares (m, Model 2026E) | C44: =Model!CO127 -> 186.1125
B45: Implied share price ($) | C45: =C43/C44 -> 82.170519
B46: Current share price ($) | C46: =Model!CO381 -> 80
B47: Implied upside / (downside) | C47: =C45/C46-1 -> 0.027131489
...

Sheet Charts
B2: RB Global — Historical Operating Performance (2006–2025)
B3: All historicals · USDm · Linked to Model. M&A % reflects disclosed acquired revenue only (e.g. IronPlanet 2017, IAA 2023). Pre-2018 revenue on the legacy net (agency) basis; 2017+ ASC 606 gross basis.
C7: 2006 | D7: 2007 | E7: 2008 | F7: 2009 | G7: 2010 | H7: 2011 | I7: 2012 | J7: 2013 | K7: 2014 | L7: 2015 | M7: 2016 | N7: 2017 | O7: 2018 | P7: 2019 | Q7: 2020 | R7: 2021 | S7: 2022 | T7: 2023 | U7: 2024 | V7: 2025
B8: Organic % | C8: =IFERROR(Model!C199+0,0) -> 0 | D8: =IFERROR(Model!D199+0,0) -> 0.20960843 | E8: =IFERROR(Model!E199+0,0) -> 0.13757991 | F8: =IFERROR(Model!F199+0,0) -> 0.063111229 | G8: =IFERROR(Model!G199+0,0) -> -0.052601859 | H8: =IFERROR(Model!H199+0,0) -> 0.10837538 | I8: =IFERROR(Model!I199+0,0) -> 0.08097723 | J8: =IFERROR(Model!O199+0,0) -> 0.067239785 | K8: =IFERROR(Model!U199+0,0) -> 0.029298058 | L8: =IFERROR(Model!AA199+0,0) -> 0.072288956 | M8: =IFERROR(Model!AG199+0,0) -> 0.0979307 | N8: =IFERROR(Model!AM199+0,0) -> 0.71468851 | O8: =IFERROR(Model!AS199+0,0) -> 0.20473316 | P8: =IFERROR(Model!AY199+0,0) -> 0.12701854 | Q8: =IFERROR(Model!BE199+0,0) -> 0.044454101 | R8: =IFERROR(Model!BK199+0,0) -> 0.0075592118 | S8: =IFERROR(Model!BQ199+0,0) -> 0.22360161 | T8: =IFERROR(Model!BW199+0,0) -> 0.10894632 | U8: =IFERROR(Model!CC199+0,0) -> 0.16431134 | V8: =IFERROR(Model!CI199+0,0) -> 0.071541945
B9: M&A % | C9: =IFERROR(Model!C200+0,0) -> 0 | D9: =IFERROR(Model!D200+0,0) -> 0 | E9: =IFERROR(Model!E200+0,0) -> 0 | F9: =IFERROR(Model!F200+0,0) -> 0 | G9: =IFERROR(Model!G200+0,0) -> 0 | H9: =IFERROR(Model!H200+0,0) -> 0 | I9: =IFERROR(Model!I200+0,0) -> 0.024693322 | J9: =IFERROR(Model!O200+0,0) -> 0 | K9: =IFERROR(Model!U200+0,0) -> 0 | L9: =IFERROR(Model!AA200+0,0) -> 0 | M9: =IFERROR(Model!AG200+0,0) -> 0 | N9: =IFERROR(Model!AM200+0,0) -> 0 | O9: =IFERROR(Model!AS200+0,0) -> 0 | P9: =IFERROR(Model!AY200+0,0) -> 0 | Q9: =IFERROR(Model!BE200+0,0) -> 0 | R9: =IFERROR(Model!BK200+0,0) -> 0.021274124 | S9: =IFERROR(Model!BQ200+0,0) -> 0 | T9: =IFERROR(Model!BW200+0,0) -> 1.0133187 | U9: =IFERROR(Model!CC200+0,0) -> 0 | V9: =IFERROR(Model!CI200+0,0) -> 0
C11: =C7 -> 2006 | D11: =D7 -> 2007 | E11: =E7 -> 2008 | F11: =F7 -> 2009 | G11: =G7 -> 2010 | H11: =H7 -> 2011 | I11: =I7 -> 2012 | J11: =J7 -> 2013 | ... V11: =V7 -> 2025
B12: Adjusted EBITDA | C12: =Model!C80 -> 101.591 | D12: =Model!D80 -> 125.125 | E12: =Model!E80 -> 159.913 | F12: =Model!F80 -> 161.428 | G12: =Model!G80 -> 131.352 | H12: =Model!H80 -> 153.638 | I12: =Model!I80 -> 157.593 | J12: =Model!O80 -> 175 | K12: =Model!U80 -> 182.8 | L12: =Model!AA80 -> 212.386 | M12: =Model!AG80 -> 210.086 | N12: =Model!AM80 -> 191.524 | O12: =Model!AS80 -> 257.331 | P12: =Model!AY80 -> 314.814 | Q12: =Model!BE80 -> 374.295 | R12: =Model!BK80 -> 385.324 | S12: =Model!BQ80 -> 465.215 | T12: =Model!BW80 -> 1032.8 | U12: =Model!CC80 -> 1302.7 | V12: =Model!CI80 -> 1399.7
B13: Operating Income (GAAP) | C13: =Model!C106 -> 85.946 | D13: =Model!D106 -> 101.435 | E13: =Model!E106 -> 122.118 | F13: =Model!F106 -> 127.895 | G13: =Model!G106 -> 91.765 | H13: =Model!H106 -> 107.573 | I13: =Model!I106 -> 117.965 | J13: =Model!O106 -> 136.931 | K13: =Model!U106 -> 125.885 | L13: =Model!AA106 -> 172.518 | M13: =Model!AG106 -> 137.153 | N13: =Model!AM106 -> 110.013 | O13: =Model!AS106 -> 184.977 | P13: =Model!AY106 -> 220.265 | Q13: =Model!BE106 -> 264.772 | R13: =Model!BK106 -> 240.939 | S13: =Model!BQ106 -> 453.591 | T13: =Model!BW106 -> 471.3 | U13: =Model!CC106 -> 761.2 | V13: =Model!CI106 -> 713.4
B14: Adj. EBITDA Margin % | C14: =Model!C209 -> 0.39398194 | D14: =Model!D209 -> 0.40116253 | E14: =Model!E209 -> 0.45069021 | F14: =Model!F209 -> 0.42795146 | G14: =Model!G209 -> 0.36755287 | H14: =Model!H209 -> 0.38787778 | I14: =Model!I209 -> 0.35983834 | J14: =Model!O209 -> 0.37440924 | K14: =Model!U209 -> 0.37996496 | L14: =Model!AA209 -> 0.41170051 | M14: =Model!AG209 -> 0.37091782 | N14: =Model!AM209 -> 0.19720529 | O14: =Model!AS209 -> 0.21993614 | P14: =Model!AY209 -> 0.23874125 | Q14: =Model!BE209 -> 0.27176786 | R14: =Model!BK209 -> 0.27193499 | S14: =Model!BQ209 -> 0.26831979 | T14: =Model!BW209 -> 0.28068268 | U14: =Model!CC209 -> 0.30407077 | V14: =Model!CI209 -> 0.30489904
B15: GAAP Op. Margin % | C15: =Model!C210 -> 0.33330877 | D15: =Model!D210 -> 0.32521016 | E15: =Model!E210 -> 0.34417081 | F15: =Model!F210 -> 0.33905427 | G15: =Model!G210 -> 0.25677941 | H15: =Model!H210 -> 0.27158109 | I15: =Model!I210 -> 0.26935416 | J15: =Model!O210 -> 0.29296132 | K15: =Model!U210 -> 0.26166241 | L15: =Model!AA210 -> 0.33441822 | M15: =Model!AG210 -> 0.2421508 | N15: =Model!AM210 -> 0.11327638 | O15: =Model!AS210 -> 0.15809649 | P15: =Model!AY210 -> 0.1670394 | Q15: =Model!BE210 -> 0.19224547 | R15: =Model!BK210 -> 0.17003806 | S15: =Model!BQ210 -> 0.26161547 | T15: =Model!BW210 -> 0.12808457 | U15: =Model!CC210 -> 0.17767611 | V15: =Model!CI210 -> 0.15540114
C17: =C7 -> 2006 | D17: =D7 -> 2007 | E17: =E7 -> 2008 | F17: =F7 -> 2009 | G17: =G7 -> 2010 | H17: =H7 -> 2011 | I17: =I7 -> 2012 | J17: =J7 -> 2013 | ... V17: =V7 -> 2025
B18: ROIC | C18: =IFERROR(Model!C356+0,NA()) -> 0.22424826 | D18: =IFERROR(Model!D356+0,NA()) -> 0.21759541 | E18: =IFERROR(Model!E356+0,NA()) -> 0.23134292 | F18: =IFERROR(Model!F356+0,NA()) -> 0.16532726 | G18: =IFERROR(Model!G356+0,NA()) -> 0.10481234 | H18: =IFERROR(Model!H356+0,NA()) -> 0.12046844 | I18: =IFERROR(Model!I356+0,NA()) -> 0.11506653 | J18: =IFERROR(Model!O356+0,NA()) -> 0.14383876 | K18: =IFERROR(Model!U356+0,NA()) -> 0.14413993 | L18: =IFERROR(Model!AA356+0,NA()) -> 0.2116185 | M18: =IFERROR(Model!AG356+0,NA()) -> 0.10949277 | N18: =IFERROR(Model!AM356+0,NA()) -> 0.1034524 | O18: =IFERROR(Model!AS356+0,NA()) -> 0.11423636 | P18: =IFERROR(Model!AY356+0,NA()) -> 0.17297738 | Q18: =IFERROR(Model!BE356+0,NA()) -> 0.16538527 | R18: =IFERROR(Model!BK356+0,NA()) -> 0.0967494 | S18: =IFERROR(Model!BQ356+0,NA()) -> 0.22482019 | T18: =IFERROR(Model!BW356+0,NA()) -> 0.082450537 | U18: =IFERROR(Model!CC356+0,NA()) -> 0.10851456 | V18: =IFERROR(Model!CI356+0,NA()) -> 0.11950879
