Workbook

Sheet Model
CL1: SCENARIO SWITCH ▼ (Bull / Base / Bear) — drives all scenario-linked forecast drivers
B2: RBC Bearings Incorporated (NYSE: RBC) — 3-Statement Financial Model | CL2: Base
B3: US GAAP as reported · USD millions (per-share data in USD; shares in millions) · Fiscal years end on the Saturday nearest 31 March (FY2027 = 29-Mar-2026 – 3-Apr-2027, 53 weeks) · Source: RBC Bearings Forms 10-K / 10-Q, Form 8-K earnings releases (Ex. 99.1) and deal / financing 8-Ks, SEC EDGAR (CIK 1324948); XBRL company facts; investor-relations releases are the same documents as filed on EDGAR
B4: Basis notes: as originally reported (the FY2022 10-K/A restatement of FY2020–22 stock-based compensation is shown as memo rows). Segments: Roller / Plain / Ball / Other (Engineered Products from FY2016) to Q2 FY22; Aerospace & Defense / Industrial from Q3 FY22 (FY2021 and Q3 FY21–Q2 FY22 re-presented). Acquisitions: Sargent Apr-15, Dodge 1-Nov-21 (MCPS / notes / term loan), VACCO 18-Jul-25, PSC Couplings 10-Aug-26. Q2/27E calibrated to the Q2 FY27 outlook (31-Jul-2026), Δ carried to Q3–Q4/27E; Q4/27E has 14 weeks.
CN5: Forecast | CO5: Historical | CP5: Historical | CQ5: Historical
B6: (USDm) | C6: 2006 | D6: 2007 | E6: 2008 | F6: 2009 | G6: 2010 | H6: 2011 | I6: 2012 | J6: Q1/13 | K6: Q2/13 | L6: Q3/13 | M6: Q4/13 | N6: 2013 | O6: Q1/14 | P6: Q2/14 | Q6: Q3/14 | R6: Q4/14 | S6: 2014 | T6: Q1/15 | U6: Q2/15 | V6: Q3/15 | W6: Q4/15 | X6: 2015 | Y6: Q1/16 | Z6: Q2/16 | AA6: Q3/16 | AB6: Q4/16 | AC6: 2016 | AD6: Q1/17 | AE6: Q2/17 | AF6: Q3/17 | AG6: Q4/17 | AH6: 2017 | AI6: Q1/18 | AJ6: Q2/18 | AK6: Q3/18 | AL6: Q4/18 | AM6: 2018 | AN6: Q1/19 | AO6: Q2/19 | AP6: Q3/19 | AQ6: Q4/19 | AR6: 2019 | AS6: Q1/20 | AT6: Q2/20 | AU6: Q3/20 | AV6: Q4/20 | AW6: 2020 | AX6: Q1/21 | AY6: Q2/21 | AZ6: Q3/21 | BA6: Q4/21 | BB6: 2021 | BC6: Q1/22 | BD6: Q2/22 | BE6: Q3/22 | BF6: Q4/22 | BG6: 2022 | BH6: Q1/23 | BI6: Q2/23 | BJ6: Q3/23 | BK6: Q4/23 | BL6: 2023 | BM6: Q1/24 | BN6: Q2/24 | BO6: Q3/24 | BP6: Q4/24 | BQ6: 2024 | BR6: Q1/25 | BS6: Q2/25 | BT6: Q3/25 | BU6: Q4/25 | BV6: 2025 | BW6: Q1/26 | BX6: Q2/26 | BY6: Q3/26 | BZ6: Q4/26 | CA6: 2026 | CB6: Q1/27 | CC6: Q2/27E | CD6: Q3/27E | CE6: Q4/27E | CF6: 2027E | CG6: 2028E | CH6: 2029E | CI6: 2030E | CJ6: 2031E | CK6: 2032E | CL6: Modelling Notes | CN6: 5Y CAGR | CO6: 5Y CAGR | CP6: 10Y CAGR | CQ6: 20Y CAGR
CN7: 27-'32 | CO7: 21-'26 | CP7: 16-'26 | CQ7: 06-'26
B8: SEGMENT P&L — AEROSPACE & DEFENSE · INDUSTRIAL (external net sales × segment gross margin) | CL8: SEGMENT BUILD — modelling logic (segment net sales → segment gross margin (the CODM measure) → − SG&A − other, net = operating income → GAAP P&L)
CT9: SCENARIO INPUT TABLE — driver assumptions per Bull / Base / Bear | CU9: Bull | CV9: Base | CW9: Bear | CX9: Bull / Bear = Base + Δ (Δ inputs on each block header). Outlook block = high / mid / low end of the Q2 FY27 guidance ranges.
B10: Aerospace & Defense (bearings, precision components and systems for commercial aerospace, defense aerospace / marine / ground, missiles, space; VACCO from 18-Jul-2025) | CL10: AEROSPACE & DEFENSE — modelling logic
B11: Aerospace & Defense — segment net external sales | AZ11: 93.267 | BA11: 96.389 | BB11: 396.222 | BC11: 90.365 | BD11: 92.915 | BE11: 93.203 | BF11: 104.985 | BG11: 381.468 | BH11: 99.399 | BI11: 103.548 | BJ11: 105.532 | BK11: 121.828 | BL11: 430.307 | BM11: 120.472 | BN11: 127.271 | BO11: 129.293 | BP11: 142.313 | BQ11: 519.349 | BR11: 149.1 | BS11: 143.2 | BT11: 143.2 | BU11: 157.3 | BV11: 592.8 | BW11: 164.6 | BX11: 198.8 | BY11: 202.5 | BZ11: 222.1 | CA11: 788 | CB11: 225.4 | CC11: =BX11*(1+CC12)*CC34+CC14 -> 234.90051 | CD11: =BY11*(1+CD12)*CD34+CD14 -> 231.22537 | CE11: =BZ11*(1+CE12)*CE34+CE14 -> 273.11383 | CF11: =SUM(CB11:CE11) -> 964.63971 | CG11: =CF11*(1+CG12) -> 1070.7501 | CH11: =CG11*(1+CH12) -> 1177.8251 | CI11: =CH11*(1+CI12) -> 1283.8293 | CJ11: =CI11*(1+CJ12) -> 1386.5357 | CK11: =CJ11*(1+CK12) -> 1483.5932 | CL11: Release segment data (Aerospace & Defense / Industrial from the Q3 FY22 release; FY2021 and Q3 FY21–Q2 FY22 from the re-presented comparatives). Q2–Q4/27E: prior-year quarter × (1 + organic growth) × week factor + acquired sales not in the prior-year base. FY2028E+: prior year × (1 + scenario growth). | CN11: =IFERROR((CK11/CF11)^(1/5)-1,"n/m") -> 0.089908248 | CO11: =IFERROR((CA11/BB11)^(1/5)-1,"n/m") -> 0.14740708 | CP11: =IFERROR((CA11/AC11)^(1/10)-1,"n/m") -> n/m | CQ11: =IFERROR((CA11/C11)^(1/20)-1,"n/m") -> n/m | CT11: Q2 FY27 guidance — Q1 FY27 release (31-Jul-2026) | CU11: High | CV11: Mid | CW11: Low | CX11: Net sales approximately $505.0 to $515.0 million in Q2 FY27 (vs $455.3 million, +10.9% to 13.1%); gross margin 45.5% to 45.75%; SG&A 16.5% to 16.75% of net sales. RBC guides one quarter ahead; no full-year guidance is published.
B12: y/y % (Q2–Q4/27E: organic, before acquired sales) | D12: =IF(AND(ISNUMBER(D11),ISNUMBER(C11)),IFERROR(D11/C11-1,""),"") | E12: =IF(AND(ISNUMBER(E11),ISNUMBER(D11)),IFERROR(E11/D11-1,""),"") | F12: =IF(AND(ISNUMBER(F11),ISNUMBER(E11)),IFERROR(F11/E11-1,""),"") | G12: =IF(AND(ISNUMBER(G11),ISNUMBER(F11)),IFERROR(G11/F11-1,""),"") | H12: =IF(AND(ISNUMBER(H11),ISNUMBER(G11)),IFERROR(H11/G11-1,""),"") | I12: =IF(AND(ISNUMBER(I11),ISNUMBER(H11)),IFERROR(I11/H11-1,""),"") | N12: =IF(AND(ISNUMBER(N11),ISNUMBER(I11)),IFERROR(N11/I11-1,""),"") | O12: =IF(AND(ISNUMBER(O11),ISNUMBER(J11)),IFERROR(O11/J11-1,""),"") | P12: =IF(AND(ISNUMBER(P11),ISNUMBER(K11)),IFERROR(P11/K11-1,""),"") | Q12: =IF(AND(ISNUMBER(Q11),ISNUMBER(L11)),IFERROR(Q11/L11-1,""),"") | R12: =IF(AND(ISNUMBER(R11),ISNUMBER(M11)),IFERROR(R11/M11-1,""),"") | S12: =IF(AND(ISNUMBER(S11),ISNUMBER(N11)),IFERROR(S11/N11-1,""),"") | T12: =IF(AND(ISNUMBER(T11),ISNUMBER(O11)),IFERROR(T11/O11-1,""),"") | U12: =IF(AND(ISNUMBER(U11),ISNUMBER(P11)),IFERROR(U11/P11-1,""),"") | ... CB12: =IF(AND(ISNUMBER(CB11),ISNUMBER(BW11)),IFERROR(CB11/BW11-1,""),"") -> 0.36938032 | CC12: =CC13+$CC$74 -> 0.14185367 | CD12: =CD13+$CC$74 -> 0.14185367 | CE12: =CE13+$CC$74 -> 0.14185367 | CF12: =IF(AND(ISNUMBER(CF11),ISNUMBER(CA11)),IFERROR(CF11/CA11-1,""),"") -> 0.22416206 | CG12: =CHOOSE(MATCH($CL$2,{"Bull","Base","Bear"},0),$CU$27,$CV$27,$CW$27) -> 0.11 | CH12: =CHOOSE(MATCH($CL$2,{"Bull","Base","Bear"},0),$CU$28,$CV$28,$CW$28) -> 0.1 | CI12: =CHOOSE(MATCH($CL$2,{"Bull","Base","Bear"},0),$CU$29,$CV$29,$CW$29) -> 0.09 | CJ12: =CHOOSE(MATCH($CL$2,{"Bull","Base","Bear"},0),$CU$30,$CV$30,$CW$30) -> 0.08 | CK12: =CHOOSE(MATCH($CL$2,{"Bull","Base","Bear"},0),$CU$31,$CV$31,$CW$31) -> 0.07 | CL12: Q2–Q4/27E: Q1 FY27 organic y/y + the Q2 sales-guidance calibration Δ (solved in Q2/27E, carried into Q3–Q4). FY2028E+: scenario lever. | CT12: Q2 FY27 net sales ($m) | CU12: 515 | CV12: 510 | CW12: 505 | CX12: Guided ~$505–515m. Drives the Q2/27E sales calibration (Δ carried into Q3–Q4).
B13: Q2–Q4/27E organic growth before calibration (Q1 FY27 organic y/y) | CC13: =IFERROR((SUM(CB11:CB11)-SUM(CB14:CB14))/SUM(BW11:BW11)-1,0) -> 0.16038882 | CD13: =IFERROR((SUM(CB11:CB11)-SUM(CB14:CB14))/SUM(BW11:BW11)-1,0) -> 0.16038882 | CE13: =IFERROR((SUM(CB11:CB11)-SUM(CB14:CB14))/SUM(BW11:BW11)-1,0) -> 0.16038882 | CT13: Q2 FY27 gross margin % | CU13: 0.4575 | CV13: 0.45625 | CW13: 0.455 | CX13: Guided 45.5–45.75%. Drives the Q2/27E segment gross-margin calibration (Δ carried).
B14: Acquired sales not in the prior-year base (VACCO / PSC Couplings; input) | CB14: 34.4 | CC14: 7.9 | CD14: 0 | CE14: 0 | CL14: Q1 FY27: VACCO $34.4m (release: "$34.4 of net sales this quarter came from VACCO, which we acquired on July 18, 2025"; not in the Q1 FY26 base). Q2/27E: VACCO sales for the ~3 weeks before the 18-Jul anniversary that are not in the Q2 FY26 base = $34.4m × 3/13 (assumption). Q3–Q4: nil. | CT14: Q2 FY27 SG&A % of net sales (Bull = low end) | CU14: 0.165 | CV14: 0.16625 | CW14: 0.1675 | CX14: Guided 16.5–16.75%. Applied directly in Q2/27E.
B15: % of total net sales | C15: =IF(AND(ISNUMBER(C11),ISNUMBER(C65)),IFERROR(C11/C65,""),"") | D15: =IF(AND(ISNUMBER(D11),ISNUMBER(D65)),IFERROR(D11/D65,""),"") | E15: =IF(AND(ISNUMBER(E11),ISNUMBER(E65)),IFERROR(E11/E65,""),"") | F15: =IF(AND(ISNUMBER(F11),ISNUMBER(F65)),IFERROR(F11/F65,""),"") | G15: =IF(AND(ISNUMBER(G11),ISNUMBER(G65)),IFERROR(G11/G65,""),"") | H15: =IF(AND(ISNUMBER(H11),ISNUMBER(H65)),IFERROR(H11/H65,""),"") | I15: =IF(AND(ISNUMBER(I11),ISNUMBER(I65)),IFERROR(I11/I65,""),"") | J15: =IF(AND(ISNUMBER(J11),ISNUMBER(J65)),IFERROR(J11/J65,""),"") | ... CK15: =IF(AND(ISNUMBER(CK11),ISNUMBER(CK65)),IFERROR(CK11/CK65,""),"") -> 0.42117003 | CN15: =IFERROR(AVERAGE(CG15,CH15,CI15,CJ15,CK15),"n/m") -> 0.43508658 | CO15: =IFERROR(AVERAGE(BG15,BL15,BQ15,BV15,CA15),"n/m") -> 0.36274884 | CP15: =IFERROR(AVERAGE(AH15,AM15,AR15,AW15,BB15,BG15,BL15,BQ15,BV15,CA15),"n/m") -> 0.41072869 | CQ15: =IFERROR(AVERAGE(C15,D15,E15,F15,G15,H15,I15,N15,S15,X15,AC15,AH15,AM15,AR15,AW15,BB15,BG15,BL15,BQ15,BV15,CA15),"n/m") -> 0.41072869
B16: Aerospace & Defense segment gross margin | AZ16: 38.056 | BA16: 39.23 | BB16: 161.19 | BC16: 38.632 | BD16: 36.58 | BE16: 37.486 | BF16: 42.461 | BG16: 155.127 | BH16: 38.6 | BI16: 41.033 | BJ16: 41.65 | BK16: 49.717 | BL16: 171 | BM16: 47.3 | BN16: 50.6 | BO16: 53.3 | BP16: 57.6 | BQ16: 208.8 | BR16: 63.1 | BS16: 56.8 | BT16: 57.9 | BU16: 65.3 | BV16: 243.1 | BW16: 70.2 | BX16: 76.9 | BY16: 81.2 | BZ16: 92.4 | CA16: 320.7 | CB16: 100.2 | CC16: =CC11*CC17 -> 92.135539 | CD16: =CD11*CD17 -> 93.969737 | CE16: =CE11*CE17 -> 115.10111 | CF16: =SUM(CB16:CE16) -> 401.40639 | CG16: =CG11*CG17 -> 471.13003 | CH16: =CH11*CH17 -> 524.13216 | CI16: =CI11*CI17 -> 577.7232 | CJ16: =CJ11*CJ17 -> 626.71413 | CK16: =CK11*CK17 -> 675.0349 | CL16: 10-Q / 10-K segment note (segment gross margin is the CODM measure; Q4 = fiscal year − nine months). Forecast = segment sales × gross margin %. | CN16: =IFERROR((CK16/CF16)^(1/5)-1,"n/m") -> 0.10955386 | CO16: =IFERROR((CA16/BB16)^(1/5)-1,"n/m") -> 0.14749862 | CP16: =IFERROR((CA16/AC16)^(1/10)-1,"n/m") -> n/m | CQ16: =IFERROR((CA16/C16)^(1/20)-1,"n/m") -> n/m | CT16: Q2–Q4 FY27E point estimates (all cases)
B17: Segment gross margin % | C17: =IF(AND(ISNUMBER(C16),ISNUMBER(C11)),IFERROR(C16/C11,""),"") | D17: =IF(AND(ISNUMBER(D16),ISNUMBER(D11)),IFERROR(D16/D11,""),"") | E17: =IF(AND(ISNUMBER(E16),ISNUMBER(E11)),IFERROR(E16/E11,""),"") | F17: =IF(AND(ISNUMBER(F16),ISNUMBER(F11)),IFERROR(F16/F11,""),"") | G17: =IF(AND(ISNUMBER(G16),ISNUMBER(G11)),IFERROR(G16/G11,""),"") | H17: =IF(AND(ISNUMBER(H16),ISNUMBER(H11)),IFERROR(H16/H11,""),"") | I17: =IF(AND(ISNUMBER(I16),ISNUMBER(I11)),IFERROR(I16/I11,""),"") | J17: =IF(AND(ISNUMBER(J16),ISNUMBER(J11)),IFERROR(J16/J11,""),"") | ... CB17: =IF(AND(ISNUMBER(CB16),ISNUMBER(CB11)),IFERROR(CB16/CB11,""),"") -> 0.44454303 | CC17: =CC18+$CC$78 -> 0.39223218 | CD17: =CD18+$CC$78 -> 0.40639891 | CE17: =CE18+$CC$78 -> 0.42144007 | CF17: =IF(AND(ISNUMBER(CF16),ISNUMBER(CF11)),IFERROR(CF16/CF11,""),"") -> 0.41612053 | CG17: =CHOOSE(MATCH($CL$2,{"Bull","Base","Bear"},0),$CU$39,$CV$39,$CW$39) -> 0.44 | CH17: =CHOOSE(MATCH($CL$2,{"Bull","Base","Bear"},0),$CU$40,$CV$40,$CW$40) -> 0.445 | CI17: =CHOOSE(MATCH($CL$2,{"Bull","Base","Bear"},0),$CU$41,$CV$41,$CW$41) -> 0.45 | CJ17: =CHOOSE(MATCH($CL$2,{"Bull","Base","Bear"},0),$CU$42,$CV$42,$CW$42) -> 0.452 | CK17: =CHOOSE(MATCH($CL$2,{"Bull","Base","Bear"},0),$CU$43,$CV$43,$CW$43) -> 0.455 | CL17: Q2–Q4/27E: margin before calibration + the Q2 gross-margin-guidance Δ (solved in Q2/27E, carried). FY2028E+: scenario lever. | CN17: =IFERROR(AVERAGE(CG17,CH17,CI17,CJ17,CK17),"n/m") -> 0.4484 | CO17: =IFERROR(AVERAGE(BG17,BL17,BQ17,BV17,CA17),"n/m") -> 0.40463157 | CP17: =IFERROR(AVERAGE(AH17,AM17,AR17,AW17,BB17,BG17,BL17,BQ17,BV17,CA17),"n/m") -> 0.40499588 | CQ17: =IFERROR(AVERAGE(C17,D17,E17,F17,G17,H17,I17,N17,S17,X17,AC17,AH17,AM17,AR17,AW17,BB17,BG17,BL17,BQ17,BV17,CA17),"n/m") -> 0.40499588 | CT17: Q2–Q4/27E tax rate (GAAP) | CV17: 0.225 | CX17: Not guided. Q1 FY27 22.1% (23.2% excluding discrete stock-compensation benefits); FY2026 22.1%.
B18: Q2–Q4/27E margin before calibration (prior-year quarter + Q1 FY27 y/y drift) | CC18: =BX17+IFERROR(SUM(CB16:CB16)/SUM(CB11:CB11)-SUM(BW16:BW16)/SUM(BW11:BW11),0) -> 0.4048755 | CD18: =BY17+IFERROR(SUM(CB16:CB16)/SUM(CB11:CB11)-SUM(BW16:BW16)/SUM(BW11:BW11),0) -> 0.41904223 | CE18: =BZ17+IFERROR(SUM(CB16:CB16)/SUM(CB11:CB11)-SUM(BW16:BW16)/SUM(BW11:BW11),0) -> 0.43408339 | CT18: Q2–Q4/27E adjusted tax rate | CV18: 0.22 | CX18: Q1 FY27 "overall tax rate applied to adjusted pre-tax earnings" 22.0% (Q1 FY26 22.5%).
B19: Incremental gross margin (Δ gross margin / Δ sales) | D19: =IFERROR((D16-C16)/(D11-C11),"") | E19: =IFERROR((E16-D16)/(E11-D11),"") | F19: =IFERROR((F16-E16)/(F11-E11),"") | G19: =IFERROR((G16-F16)/(G11-F11),"") | H19: =IFERROR((H16-G16)/(H11-G11),"") | I19: =IFERROR((I16-H16)/(I11-H11),"") | N19: =IFERROR((N16-I16)/(N11-I11),"") | O19: =IFERROR((O16-J16)/(O11-J11),"") | P19: =IFERROR((P16-K16)/(P11-K11),"") | Q19: =IFERROR((Q16-L16)/(Q11-L11),"") | R19: =IFERROR((R16-M16)/(R11-M11),"") | S19: =IFERROR((S16-N16)/(S11-N11),"") | T19: =IFERROR((T16-O16)/(T11-O11),"") | U19: =IFERROR((U16-P16)/(U11-P11),"") | ... CF19: =IFERROR((CF16-CA16)/(CF11-CA11),"") -> 0.45689833 | CG19: =IFERROR((CG16-CF16)/(CG11-CF11),"") -> 0.65708608 | CH19: =IFERROR((CH16-CG16)/(CH11-CG11),"") -> 0.495 | CI19: =IFERROR((CI16-CH16)/(CI11-CH11),"") -> 0.50555556 | CJ19: =IFERROR((CJ16-CI16)/(CJ11-CI11),"") -> 0.477 | CK19: =IFERROR((CK16-CJ16)/(CK11-CJ11),"") -> 0.49785714 | CT19: Q2–Q4/27E restructuring & consolidation per quarter ($m) | CV19: 0.5 | CX19: Q1 FY27 $0.4m; FY2026 $6.2m (assumption).
B20: Memo: Aerospace & Defense segment operating income as reported (FY2022–FY2025 segment note) | BA20: 28.756 | BB20: 122.402 | BE20: 28.543 | BF20: 33.229 | BG20: 117.858 | BH20: 29.504 | BI20: 31.48 | BJ20: 32.081 | BK20: 39.635 | BL20: 132.7 | BM20: 36.8 | BN20: 39.7 | BO20: 38.6 | BP20: 46.6 | BQ20: 161.7 | BR20: 50.6 | BS20: 46.3 | BT20: 46.8 | CT20: Q2–Q4/27E other, net excl. M&A amortization & items per quarter ($m) | CV20: 1.5 | CX20: Q1 FY27 $1.3m ($21.0m amortization of intangible assets − $19.5m M&A-related + $0.4m restructuring − $0.2m other items); mostly software amortization.
CT21: Q2–Q4/27E amortization of deferred finance fees per quarter ($m) | CV21: 0.4 | CX21: Q1 FY27 $0.8m; $0.6m of term-loan fees remain to Nov-2026 and $2.1m of revolver fees amortize to Oct-2030 (10-Q Note 10).
B22: Industrial (bearings, gearing and power-transmission components for construction, mining, food & beverage, warehousing, semicon, energy; Dodge from 1-Nov-2021) | CL22: INDUSTRIAL — modelling logic | CT22: Q2–Q4/27E other non-operating expense per quarter ($m) | CV22: 0.5 | CX22: Q1 FY27 $0.5m; FY2026 $1.9m (pension and other).
B23: Industrial — segment net external sales | AZ23: 52.594 | BA23: 63.906 | BB23: 212.762 | BC23: 65.84 | BD23: 67.985 | BE23: 173.75 | BF23: 253.894 | BG23: 561.469 | BH23: 254.681 | BI23: 265.619 | BJ23: 246.093 | BK23: 272.594 | BL23: 1038.987 | BM23: 266.65 | BN23: 258.301 | BO23: 244.613 | BP23: 271.367 | BQ23: 1040.931 | BR23: 257.2 | BS23: 254.7 | BT23: 251.2 | BU23: 280.4 | BV23: 1043.5 | BW23: 271.4 | BX23: 256.5 | BY23: 259.1 | BZ23: 295.9 | CA23: 1082.9 | CB23: 294.1 | CC23: =BX23*(1+CC24)*CC34+CC26 -> 275.09949 | CD23: =BY23*(1+CD24)*CD34+CD26 -> 279.76876 | CE23: =BZ23*(1+CE24)*CE34+CE26 -> 343.50807 | CF23: =SUM(CB23:CE23) -> 1192.4763 | CG23: =CF23*(1+CG24) -> 1264.0249 | CH23: =CG23*(1+CH24) -> 1333.5463 | CI23: =CH23*(1+CI24) -> 1400.2236 | CJ23: =CI23*(1+CJ24) -> 1470.2348 | CK23: =CJ23*(1+CK24) -> 1536.3953 | CN23: =IFERROR((CK23/CF23)^(1/5)-1,"n/m") -> 0.051987653 | CO23: =IFERROR((CA23/BB23)^(1/5)-1,"n/m") -> 0.38464633 | CP23: =IFERROR((CA23/AC23)^(1/10)-1,"n/m") -> n/m | CQ23: =IFERROR((CA23/C23)^(1/20)-1,"n/m") -> n/m
B24: y/y % (Q2–Q4/27E: organic, before acquired sales) | D24: =IF(AND(ISNUMBER(D23),ISNUMBER(C23)),IFERROR(D23/C23-1,""),"") | E24: =IF(AND(ISNUMBER(E23),ISNUMBER(D23)),IFERROR(E23/D23-1,""),"") | F24: =IF(AND(ISNUMBER(F23),ISNUMBER(E23)),IFERROR(F23/E23-1,""),"") | G24: =IF(AND(ISNUMBER(G23),ISNUMBER(F23)),IFERROR(G23/F23-1,""),"") | H24: =IF(AND(ISNUMBER(H23),ISNUMBER(G23)),IFERROR(H23/G23-1,""),"") | I24: =IF(AND(ISNUMBER(I23),ISNUMBER(H23)),IFERROR(I23/H23-1,""),"") | N24: =IF(AND(ISNUMBER(N23),ISNUMBER(I23)),IFERROR(N23/I23-1,""),"") | O24: =IF(AND(ISNUMBER(O23),ISNUMBER(J23)),IFERROR(O23/J23-1,""),"") | P24: =IF(AND(ISNUMBER(P23),ISNUMBER(K23)),IFERROR(P23/K23-1,""),"") | Q24: =IF(AND(ISNUMBER(Q23),ISNUMBER(L23)),IFERROR(Q23/L23-1,""),"") | R24: =IF(AND(ISNUMBER(R23),ISNUMBER(M23)),IFERROR(R23/M23-1,""),"") | S24: =IF(AND(ISNUMBER(S23),ISNUMBER(N23)),IFERROR(S23/N23-1,""),"") | T24: =IF(AND(ISNUMBER(T23),ISNUMBER(O23)),IFERROR(T23/O23-1,""),"") | U24: =IF(AND(ISNUMBER(U23),ISNUMBER(P23)),IFERROR(U23/P23-1,""),"") | ... CB24: =IF(AND(ISNUMBER(CB23),ISNUMBER(BW23)),IFERROR(CB23/BW23-1,""),"") -> 0.083640383 | CC24: =CC25+$CC$74 -> 0.065105228 | CD24: =CD25+$CC$74 -> 0.065105228 | CE24: =CE25+$CC$74 -> 0.065105228 | CF24: =IF(AND(ISNUMBER(CF23),ISNUMBER(CA23)),IFERROR(CF23/CA23-1,""),"") -> 0.10118785 | CG24: =CHOOSE(MATCH($CL$2,{"Bull","Base","Bear"},0),$CU$33,$CV$33,$CW$33) -> 0.06 | CH24: =CHOOSE(MATCH($CL$2,{"Bull","Base","Bear"},0),$CU$34,$CV$34,$CW$34) -> 0.055 | CI24: =CHOOSE(MATCH($CL$2,{"Bull","Base","Bear"},0),$CU$35,$CV$35,$CW$35) -> 0.05 | CJ24: =CHOOSE(MATCH($CL$2,{"Bull","Base","Bear"},0),$CU$36,$CV$36,$CW$36) -> 0.05 | CK24: =CHOOSE(MATCH($CL$2,{"Bull","Base","Bear"},0),$CU$37,$CV$37,$CW$37) -> 0.045 | CT24: Maximum net debt / adjusted EBITDA before buybacks (x) — buyback floor FY2028E+ | CU24: 1.5 | CV24: 1 | CW24: 0.5 | CX24: Net debt $682m at 27-Jun-2026 ≈ 1.0x LTM adjusted EBITDA (FY2026 $605m); the credit agreement allows up to 4.5x. RBC has made no open-market buybacks (the $100m 2019 authorization is unused) and has deployed cash to debt reduction and acquisitions. Target = leverage up to which surplus cash after the M&A lever is returned via buybacks (assumption).
B25: Q2–Q4/27E organic growth before calibration (Q1 FY27 organic y/y) | CC25: =IFERROR((SUM(CB23:CB23)-SUM(CB26:CB26))/SUM(BW23:BW23)-1,0) -> 0.083640383 | CD25: =IFERROR((SUM(CB23:CB23)-SUM(CB26:CB26))/SUM(BW23:BW23)-1,0) -> 0.083640383 | CE25: =IFERROR((SUM(CB23:CB23)-SUM(CB26:CB26))/SUM(BW23:BW23)-1,0) -> 0.083640383
B26: Acquired sales not in the prior-year base (VACCO / PSC Couplings; input) | CC26: 1.9 | CD26: 3.8 | CE26: 4.1 | CL26: PSC Couplings (closed 10-Aug-2026; LTM net sales ~$15.1m, 8-K 11-Aug-2026): run-rate × days consolidated (47 days in Q2, 91 in Q3, 98 in the 14-week Q4). Outside the Q2 guidance (issued 31-Jul-2026). | CT26: AERO_G (Aerospace & Defense sales y/y, organic + future acquisitions excluded) | CU26: 0.03 | CV26: Δ → | CW26: -0.05 | CX26: Q1 FY27 +36.9% (+16.0% organic ex VACCO $34.4m); backlog $2.3bn. Defense (submarines, munitions, space) and commercial aerospace rate increases; FY2023–26 A&D sales CAGR 22% incl. VACCO.
B27: % of total net sales | C27: =IF(AND(ISNUMBER(C23),ISNUMBER(C65)),IFERROR(C23/C65,""),"") | D27: =IF(AND(ISNUMBER(D23),ISNUMBER(D65)),IFERROR(D23/D65,""),"") | E27: =IF(AND(ISNUMBER(E23),ISNUMBER(E65)),IFERROR(E23/E65,""),"") | F27: =IF(AND(ISNUMBER(F23),ISNUMBER(F65)),IFERROR(F23/F65,""),"") | G27: =IF(AND(ISNUMBER(G23),ISNUMBER(G65)),IFERROR(G23/G65,""),"") | H27: =IF(AND(ISNUMBER(H23),ISNUMBER(H65)),IFERROR(H23/H65,""),"") | I27: =IF(AND(ISNUMBER(I23),ISNUMBER(I65)),IFERROR(I23/I65,""),"") | J27: =IF(AND(ISNUMBER(J23),ISNUMBER(J65)),IFERROR(J23/J65,""),"") | ... CK27: =IF(AND(ISNUMBER(CK23),ISNUMBER(CK65)),IFERROR(CK23/CK65,""),"") -> 0.43615978 | CN27: =IFERROR(AVERAGE(CG27,CH27,CI27,CJ27,CK27),"n/m") -> 0.47903713 | CO27: =IFERROR(AVERAGE(BG27,BL27,BQ27,BV27,CA27),"n/m") -> 0.63725116 | CP27: =IFERROR(AVERAGE(AH27,AM27,AR27,AW27,BB27,BG27,BL27,BQ27,BV27,CA27),"n/m") -> 0.58927131 | CQ27: =IFERROR(AVERAGE(C27,D27,E27,F27,G27,H27,I27,N27,S27,X27,AC27,AH27,AM27,AR27,AW27,BB27,BG27,BL27,BQ27,BV27,CA27),"n/m") -> 0.58927131 | CT27: 2028E | CU27: =CV27+$CU$26 -> 0.14 | CV27: 0.11 | CW27: =CV27+$CW$26 -> 0.06
B28: Industrial segment gross margin | AZ28: 17.532 | BA28: 23.239 | BB28: 72.916 | BC28: 25.141 | BD28: 25.884 | BE28: 55.859 | BF28: 95.025 | BG28: 201.941 | BH28: 102.552 | BI28: 110.114 | BJ28: 104.39 | BK28: 116.744 | BL28: 433.8 | BM28: 120.6 | BN28: 115.7 | BO28: 104.7 | BP28: 120.7 | BQ28: 461.7 | BR28: 120.9 | BS28: 117 | BT28: 117 | BU28: 128.1 | BV28: 483 | BW28: 125 | BX28: 123.7 | BY28: 123.2 | BZ28: 137.6 | CA28: 509.5 | CB28: 147.6 | CC28: =CC23*CC29 -> 140.55196 | CD28: =CD23*CD29 -> 141.04377 | CE28: =CE23*CE29 -> 169.58099 | CF28: =SUM(CB28:CE28) -> 598.77672 | CG28: =CG23*CG29 -> 613.05208 | CH28: =CH23*CH29 -> 653.43768 | CI28: =CI23*CI29 -> 693.11068 | CJ28: =CJ23*CJ29 -> 730.70668 | CK28: =CK23*CK29 -> 768.19767 | CN28: =IFERROR((CK28/CF28)^(1/5)-1,"n/m") -> 0.051094142 | CO28: =IFERROR((CA28/BB28)^(1/5)-1,"n/m") -> 0.4752454 | CP28: =IFERROR((CA28/AC28)^(1/10)-1,"n/m") -> n/m | CQ28: =IFERROR((CA28/C28)^(1/20)-1,"n/m") -> n/m | CT28: 2029E | CU28: =CV28+$CU$26 -> 0.13 | CV28: 0.1 | CW28: =CV28+$CW$26 -> 0.05
B29: Segment gross margin % | C29: =IF(AND(ISNUMBER(C28),ISNUMBER(C23)),IFERROR(C28/C23,""),"") | D29: =IF(AND(ISNUMBER(D28),ISNUMBER(D23)),IFERROR(D28/D23,""),"") | E29: =IF(AND(ISNUMBER(E28),ISNUMBER(E23)),IFERROR(E28/E23,""),"") | F29: =IF(AND(ISNUMBER(F28),ISNUMBER(F23)),IFERROR(F28/F23,""),"") | G29: =IF(AND(ISNUMBER(G28),ISNUMBER(G23)),IFERROR(G28/G23,""),"") | H29: =IF(AND(ISNUMBER(H28),ISNUMBER(H23)),IFERROR(H28/H23,""),"") | I29: =IF(AND(ISNUMBER(I28),ISNUMBER(I23)),IFERROR(I28/I23,""),"") | J29: =IF(AND(ISNUMBER(J28),ISNUMBER(J23)),IFERROR(J28/J23,""),"") | ... CB29: =IF(AND(ISNUMBER(CB28),ISNUMBER(CB23)),IFERROR(CB28/CB23,""),"") -> 0.50187011 | CC29: =CC30+$CC$78 -> 0.5109132 | CD29: =CD30+$CC$78 -> 0.50414408 | CE29: =CE30+$CC$78 -> 0.49367396 | CF29: =IF(AND(ISNUMBER(CF28),ISNUMBER(CF23)),IFERROR(CF28/CF23,""),"") -> 0.50212881 | CG29: =CHOOSE(MATCH($CL$2,{"Bull","Base","Bear"},0),$CU$45,$CV$45,$CW$45) -> 0.485 | CH29: =CHOOSE(MATCH($CL$2,{"Bull","Base","Bear"},0),$CU$46,$CV$46,$CW$46) -> 0.49 | CI29: =CHOOSE(MATCH($CL$2,{"Bull","Base","Bear"},0),$CU$47,$CV$47,$CW$47) -> 0.495 | CJ29: =CHOOSE(MATCH($CL$2,{"Bull","Base","Bear"},0),$CU$48,$CV$48,$CW$48) -> 0.497 | CK29: =CHOOSE(MATCH($CL$2,{"Bull","Base","Bear"},0),$CU$49,$CV$49,$CW$49) -> 0.5 | CN29: =IFERROR(AVERAGE(CG29,CH29,CI29,CJ29,CK29),"n/m") -> 0.4934 | CO29: =IFERROR(AVERAGE(BG29,BL29,BQ29,BV29,CA29),"n/m") -> 0.4308188 | CP29: =IFERROR(AVERAGE(AH29,AM29,AR29,AW29,BB29,BG29,BL29,BQ29,BV29,CA29),"n/m") -> 0.41613426 | CQ29: =IFERROR(AVERAGE(C29,D29,E29,F29,G29,H29,I29,N29,S29,X29,AC29,AH29,AM29,AR29,AW29,BB29,BG29,BL29,BQ29,BV29,CA29),"n/m") -> 0.41613426 | CT29: 2030E | CU29: =CV29+$CU$26 -> 0.12 | CV29: 0.09 | CW29: =CV29+$CW$26 -> 0.04
B30: Q2–Q4/27E margin before calibration (prior-year quarter + Q1 FY27 y/y drift) | CC30: =BX29+IFERROR(SUM(CB28:CB28)/SUM(CB23:CB23)-SUM(BW28:BW28)/SUM(BW23:BW23),0) -> 0.52355652 | CD30: =BY29+IFERROR(SUM(CB28:CB28)/SUM(CB23:CB23)-SUM(BW28:BW28)/SUM(BW23:BW23),0) -> 0.5167874 | CE30: =BZ29+IFERROR(SUM(CB28:CB28)/SUM(CB23:CB23)-SUM(BW28:BW28)/SUM(BW23:BW23),0) -> 0.50631728 | CT30: 2031E | CU30: =CV30+$CU$26 -> 0.11 | CV30: 0.08 | CW30: =CV30+$CW$26 -> 0.03
B31: Incremental gross margin (Δ gross margin / Δ sales) | D31: =IFERROR((D28-C28)/(D23-C23),"") | E31: =IFERROR((E28-D28)/(E23-D23),"") | F31: =IFERROR((F28-E28)/(F23-E23),"") | G31: =IFERROR((G28-F28)/(G23-F23),"") | H31: =IFERROR((H28-G28)/(H23-G23),"") | I31: =IFERROR((I28-H28)/(I23-H23),"") | N31: =IFERROR((N28-I28)/(N23-I23),"") | O31: =IFERROR((O28-J28)/(O23-J23),"") | P31: =IFERROR((P28-K28)/(P23-K23),"") | Q31: =IFERROR((Q28-L28)/(Q23-L23),"") | R31: =IFERROR((R28-M28)/(R23-M23),"") | S31: =IFERROR((S28-N28)/(S23-N23),"") | T31: =IFERROR((T28-O28)/(T23-O23),"") | U31: =IFERROR((U28-P28)/(U23-P23),"") | ... CF31: =IFERROR((CF28-CA28)/(CF23-CA23),"") -> 0.81474457 | CG31: =IFERROR((CG28-CF28)/(CG23-CF23),"") -> 0.19951986 | CH31: =IFERROR((CH28-CG28)/(CH23-CG23),"") -> 0.58090909 | CI31: =IFERROR((CI28-CH28)/(CI23-CH23),"") -> 0.595 | CJ31: =IFERROR((CJ28-CI28)/(CJ23-CI23),"") -> 0.537 | CK31: =IFERROR((CK28-CJ28)/(CK23-CJ23),"") -> 0.56666667 | CT31: 2032E | CU31: =CV31+$CU$26 -> 0.1 | CV31: 0.07 | CW31: =CV31+$CW$26 -> 0.02
B32: Memo: Industrial segment operating income as reported (FY2022–FY2025 segment note) | BA32: 17.664 | BB32: 52.911 | BE32: 23.197 | BF32: 45.064 | BG32: 107.478 | BH32: 53.295 | BI32: 60.05 | BJ32: 59.255 | BK32: 63.9 | BL32: 236.5 | BM32: 71.1 | BN32: 69.5 | BO32: 59.3 | BP32: 72.7 | BQ32: 272.6 | BR32: 72.5 | BS32: 68.5 | BT32: 68.2 | CT32: IND_G (Industrial sales y/y) | CU32: 0.02 | CV32: Δ → | CW32: -0.06 | CX32: Q1 FY27 +8.4% (semicon, grain, food & beverage); FY2023–26 Industrial sales flat to +4% a year after the Dodge-led FY2023 step-up; cyclical downside (FY2021 −12% legacy industrial).
CT33: 2028E | CU33: =CV33+$CU$32 -> 0.08 | CV33: 0.06 | CW33: =CV33+$CW$32 -> 0
B34: Week factor (Q4/27E: 14 of 13 weeks — FY2027 is a 53-week year) | CC34: 1 | CD34: 1 | CE34: 1.0769231 | CL34: Q1 FY27 10-Q, MD&A overview: fiscal 2027 has 53 weeks (FY2026 52); Q1 FY27 and Q1 FY26 had 13 weeks. The extra week falls in Q4 (Q1 had 13 weeks); applied to sales only (assumption). | CT34: 2029E | CU34: =CV34+$CU$32 -> 0.075 | CV34: 0.055 | CW34: =CV34+$CW$32 -> -0.005
B35: Net sales not on the current segment basis (FY2006–FY2020 and Q1–Q2 FY21: total) | C35: =IF(ISNUMBER(C11),"",C108) -> 274.509 | D35: =IF(ISNUMBER(D11),"",D108) -> 306.062 | E35: =IF(ISNUMBER(E11),"",E108) -> 330.6 | F35: =IF(ISNUMBER(F11),"",F108) -> 355.796 | G35: =IF(ISNUMBER(G11),"",G108) -> 274.702 | H35: =IF(ISNUMBER(H11),"",H108) -> 335.625 | I35: =IF(ISNUMBER(I11),"",I108) -> 397.511 | J35: =IF(ISNUMBER(J11),"",J108) -> 103.334 | ... CB35: =IF(ISNUMBER(CB11),"",CB108) | CL35: Aerospace & Defense / Industrial were introduced after the Dodge acquisition; earlier periods were never re-presented (legacy segments below). | CT35: 2030E | CU35: =CV35+$CU$32 -> 0.07 | CV35: 0.05 | CW35: =CV35+$CW$32 -> -0.01
B36: Memo: corporate operating loss as reported (segment note) | BA36: -16.68 | BB36: -63.855 | BE36: -37.369 | BF36: -20.447 | BG36: -95.273 | BH36: -18.329 | BI36: -19.513 | BJ36: -20.944 | BK36: -17.414 | BL36: -76.2 | BM36: -22.9 | BN36: -21.4 | BO36: -22.7 | BP36: -25.1 | BQ36: -92.1 | BR36: -25.6 | BS36: -28.7 | BT36: -29.4 | CT36: 2031E | CU36: =CV36+$CU$32 -> 0.07 | CV36: 0.05 | CW36: =CV36+$CW$32 -> -0.01
B37: Check: segment operating income + corporate vs operating income (should be 0) | C37: =IF(ISNUMBER(C20),IF(ABS(C20+C32+N(C36)-C116)<=0.15,0,ROUND(C20+C32+N(C36)-C116,1)),"") | D37: =IF(ISNUMBER(D20),IF(ABS(D20+D32+N(D36)-D116)<=0.15,0,ROUND(D20+D32+N(D36)-D116,1)),"") | E37: =IF(ISNUMBER(E20),IF(ABS(E20+E32+N(E36)-E116)<=0.15,0,ROUND(E20+E32+N(E36)-E116,1)),"") | F37: =IF(ISNUMBER(F20),IF(ABS(F20+F32+N(F36)-F116)<=0.15,0,ROUND(F20+F32+N(F36)-F116,1)),"") | G37: =IF(ISNUMBER(G20),IF(ABS(G20+G32+N(G36)-G116)<=0.15,0,ROUND(G20+G32+N(G36)-G116,1)),"") | H37: =IF(ISNUMBER(H20),IF(ABS(H20+H32+N(H36)-H116)<=0.15,0,ROUND(H20+H32+N(H36)-H116,1)),"") | I37: =IF(ISNUMBER(I20),IF(ABS(I20+I32+N(I36)-I116)<=0.15,0,ROUND(I20+I32+N(I36)-I116,1)),"") | J37: =IF(ISNUMBER(J20),IF(ABS(J20+J32+N(J36)-J116)<=0.15,0,ROUND(J20+J32+N(J36)-J116,1)),"") | ... CB37: =IF(ISNUMBER(CB20),IF(ABS(CB20+CB32+N(CB36)-CB116)<=0.15,0,ROUND(CB20+CB32+N(CB36)-CB116,1)),"") | CT37: 2032E | CU37: =CV37+$CU$32 -> 0.065 | CV37: 0.045 | CW37: =CV37+$CW$32 -> -0.015
B38: Legacy segments (net external sales as originally reported, FY2006–Q2 FY22): | CT38: AERO_M (Aerospace & Defense segment gross margin %) | CU38: 0.01 | CV38: Δ → | CW38: -0.025 | CX38: Q1 FY27 44.5%; FY2026 40.7% (VACCO integration), FY2023 39.7%; volume leverage and VACCO margin improvement.
B39: Plain bearings | C39: 115.091 | D39: 143.907 | E39: 154.535 | F39: 166.658 | G39: 134.303 | H39: 168.777 | I39: 200.141 | J39: 55.397 | K39: 53.272 | L39: 51.497 | M39: 55.797 | N39: 215.963 | O39: 57.09 | P39: 52.828 | Q39: 52.991 | R39: 60.19 | S39: 223.099 | T39: 59.873 | U39: 57.458 | V39: 53.77 | W39: 59.067 | X39: 230.168 | Y39: 65.677 | Z39: 67.607 | AA39: 64.171 | AB39: 73.079 | AC39: 270.534 | AD39: 70.45 | AE39: 68.835 | AF39: 65.822 | AG39: 72.593 | AH39: 277.7 | AI39: 72.653 | AJ39: 72.392 | AK39: 69.764 | AL39: 81.899 | AM39: 296.708 | AN39: 78.525 | AO39: 77.48 | AP39: 79.306 | AQ39: 87.94 | AR39: 323.251 | AS39: 87.489 | AT39: 90.007 | AU39: 86.876 | AV39: 93.919 | AW39: 358.291 | AX39: 78.875 | AY39: 71.053 | AZ39: 69.321 | BA39: 74.741 | BB39: 293.99 | BC39: 73.321 | BD39: 74.079 | CT39: 2028E | CU39: =CV39+$CU$38 -> 0.45 | CV39: 0.44 | CW39: =CV39+$CW$38 -> 0.415
B40: Roller bearings | C40: 96.466 | D40: 92.123 | E40: 97.019 | F40: 94.428 | G40: 73.164 | H40: 98.942 | I40: 123.803 | J40: 31.397 | K40: 30.052 | L40: 26.115 | M40: 27.457 | N40: 115.021 | O40: 28.35 | P40: 30.277 | Q40: 27.284 | R40: 29.895 | S40: 115.806 | T40: 31.765 | U40: 33.504 | V40: 31.358 | W40: 32.075 | X40: 128.702 | Y40: 30.58 | Z40: 27.151 | AA40: 26.294 | AB40: 28.014 | AC40: 112.039 | AD40: 27.834 | AE40: 26.795 | AF40: 26.157 | AG40: 28.697 | AH40: 109.483 | AI40: 31.413 | AJ40: 32.317 | AK40: 32.485 | AL40: 35.806 | AM40: 132.021 | AN40: 35.87 | AO40: 37 | AP40: 34.841 | AQ40: 36.121 | AR40: 143.832 | AS40: 36.859 | AT40: 32.585 | AU40: 31.829 | AV40: 31.369 | AW40: 132.642 | AX40: 22.9 | AY40: 21.579 | AZ40: 22.408 | BA40: 24.77 | BB40: 91.657 | BC40: 25.247 | BD40: 27.309 | CT40: 2029E | CU40: =CV40+$CU$38 -> 0.455 | CV40: 0.445 | CW40: =CV40+$CW$38 -> 0.42
...

Sheet Bull-Base-Bear
B2: RBC Bearings Incorporated (RBC) — Bull / Base / Bear Case P&L Summary | J2: Share price ($): | K2: =Model!$CG$393 -> 510
B3: Adjusted figures (company definitions: adjusted operating income, adjusted EBITDA, adjusted EPS — current definition) · USD millions · fiscal years ending ~31 March · Live panel linked to Model — toggle scenario via Model!CL2. Bull and Bear panels are value snapshots generated from the Model with the switch set to each case. FY2027E = Q1 actual + Q2 calibrated to the Q2 FY27 outlook (sales $505–515m, gross margin 45.5–45.75%) + Q3–Q4 with the same Δ. | J3: As of: | K3: =TODAY() -> 2026-10-13 00:00:00
B5: Scenario: | C5: =Model!$CL$2 -> Base | N5: Scenario: | O5: Bull | P5: Snapshot (values) — Model run with switch = Bull | Z5: Scenario: | AA5: Bear | AB5: Snapshot (values) — Model run with switch = Bear
B7: (USDm, except EPS and shares) | C7: 2027E | D7: 2028E | E7: 2029E | F7: 2030E | G7: 2031E | H7: 2032E | I7: 27-'32 CAGR | J7: LT Hist Avg | K7: LT Hist Min | L7: LT Hist Max | N7: (USDm, except EPS and shares) | O7: 2027E | P7: 2028E | Q7: 2029E | R7: 2030E | S7: 2031E | T7: 2032E | U7: 27-'32 CAGR | V7: LT Hist Avg | W7: LT Hist Min | X7: LT Hist Max | Z7: (USDm, except EPS and shares) | AA7: 2027E | AB7: 2028E | AC7: 2029E | AD7: 2030E | AE7: 2031E | AF7: 2032E | AG7: 27-'32 CAGR | AH7: LT Hist Avg | AI7: LT Hist Min | AJ7: LT Hist Max
B9: Net sales | C9: =Model!CF108 -> 2157.116 | D9: =Model!CG108 -> 2384.775 | E9: =Model!CH108 -> 2666.3714 | F9: =Model!CI108 -> 2949.3029 | G9: =Model!CJ108 -> 3237.783 | H9: =Model!CK108 -> 3522.5516 | I9: =IFERROR((H9/C9)^(1/5)-1,"n/m") -> 0.103054 | N9: Net sales | O9: 2173.3114 | P9: 2485.4767 | Q9: 2894.8113 | R9: 3319.0736 | S9: 3762.9974 | T9: 4216.9123 | U9: 0.14175921 | Z9: Net sales | AA9: 2140.9207 | AB9: 2198.3771 | AC9: 2243.2136 | AD9: 2274.0723 | AE9: 2295.6695 | AF9: 2301.194 | AG9: 0.014543164
B10: Net sales y/y % | D10: =IFERROR(D9/C9-1,"") -> 0.10553857 | E10: =IFERROR(E9/D9-1,"") -> 0.1180809 | F10: =IFERROR(F9/E9-1,"") -> 0.10611109 | G10: =IFERROR(G9/F9-1,"") -> 0.097812952 | H10: =IFERROR(H9/G9-1,"") -> 0.087951753 | N10: Net sales y/y % | P10: 0.1436358 | Q10: 0.16469061 | R10: 0.14655956 | S10: 0.13374929 | T10: 0.12062589 | Z10: Net sales y/y % | AB10: 0.026837221 | AC10: 0.020395294 | AD10: 0.013756443 | AE10: 0.0094971493 | AF10: 0.0024064937
B11: Aerospace & Defense sales y/y % | C11: =Model!CF217 -> 0.22416206 | D11: =Model!CG217 -> 0.11 | E11: =Model!CH217 -> 0.1 | F11: =Model!CI217 -> 0.09 | G11: =Model!CJ217 -> 0.08 | H11: =Model!CK217 -> 0.07 | N11: Aerospace & Defense sales y/y % | O11: 0.23308802 | P11: 0.14 | Q11: 0.13 | R11: 0.12 | S11: 0.11 | T11: 0.1 | Z11: Aerospace & Defense sales y/y % | AA11: 0.21523611 | AB11: 0.06 | AC11: 0.05 | AD11: 0.04 | AE11: 0.03 | AF11: 0.02
B12: Adjusted EBITDA | C12: =Model!CF179 -> 723.46302 | D12: =Model!CG179 -> 817.00911 | E12: =Model!CH179 -> 919.17164 | F12: =Model!CI179 -> 1023.6111 | G12: =Model!CJ179 -> 1123.385 | H12: =Model!CK179 -> 1222.068 | I12: =IFERROR((H12/C12)^(1/5)-1,"n/m") -> 0.1105441 | N12: Adjusted EBITDA | O12: 732.98677 | P12: 880.46334 | Q12: 1025.5206 | R12: 1178.3025 | S12: 1331.4106 | T12: 1488.3359 | U12: 0.15218168 | Z12: Adjusted EBITDA | AA12: 714.02024 | AB12: 690.77851 | AC12: 716.97415 | AD12: 739.22291 | AE12: 752.10774 | AF12: 759.91737 | AG12: 0.012537623
B13: Adjusted EBITDA margin % | C13: =IFERROR(C12/C9,"") -> 0.33538438 | D13: =IFERROR(D12/D9,"") -> 0.3425938 | E13: =IFERROR(E12/E9,"") -> 0.34472754 | F13: =IFERROR(F12/F9,"") -> 0.34706884 | G13: =IFERROR(G12/G9,"") -> 0.34696117 | H13: =IFERROR(H12/H9,"") -> 0.34692693 | J13: =IFERROR(AVERAGE(Model!C180,Model!D180,Model!E180,Model!F180,Model!G180,Model!H180,Model!I180,Model!N180,Model!S180,Model!X180,Model!AC180,Model!AH180,Model!AM180,Model!AR180,Model!AW180,Model!BB180,Model!BG180,Model!BL180,Model!BQ180,Model!BV180,Model!CA180),"") -> 0.26140804 | K13: =IFERROR(MIN(Model!C180,Model!D180,Model!E180,Model!F180,Model!G180,Model!H180,Model!I180,Model!N180,Model!S180,Model!X180,Model!AC180,Model!AH180,Model!AM180,Model!AR180,Model!AW180,Model!BB180,Model!BG180,Model!BL180,Model!BQ180,Model!BV180,Model!CA180),"") -> 0.19560833 | L13: =IFERROR(MAX(Model!C180,Model!D180,Model!E180,Model!F180,Model!G180,Model!H180,Model!I180,Model!N180,Model!S180,Model!X180,Model!AC180,Model!AH180,Model!AM180,Model!AR180,Model!AW180,Model!BB180,Model!BG180,Model!BL180,Model!BQ180,Model!BV180,Model!CA180),"") -> 0.32353413 | N13: Adjusted EBITDA margin % | O13: 0.33726726 | P13: 0.35424325 | Q13: 0.35426164 | R13: 0.35500946 | S13: 0.35381651 | T13: 0.35294448 | V13: 0.26140804 | W13: 0.19560833 | X13: 0.32353413 | Z13: Adjusted EBITDA margin % | AA13: 0.33351083 | AB13: 0.31422203 | AC13: 0.3196192 | AD13: 0.32506571 | AE13: 0.32762022 | AF13: 0.33022743 | AH13: 0.26140804 | AI13: 0.19560833 | AJ13: 0.32353413
B15: Operating income (GAAP) | C15: =Model!CF116 -> 558.42302 | D15: =Model!CG116 -> 620.95047 | E15: =Model!CH116 -> 704.98456 | F15: =Model!CI116 -> 794.3032 | G15: =Model!CJ116 -> 876.74794 | H15: =Model!CK116 -> 954.83164 | I15: =IFERROR((H15/C15)^(1/5)-1,"n/m") -> 0.11324998 | N15: Operating income (GAAP) | O15: 567.30768 | P15: 674.52241 | Q15: 791.0753 | R15: 917.73516 | S15: 1041.8637 | T15: 1165.909 | U15: 0.15496599 | Z15: Operating income (GAAP) | AA15: 549.61933 | AB15: 512.04417 | AC15: 538.50232 | AD15: 564.72558 | AE15: 580.05795 | AF15: 587.61345 | AG15: 0.013458445
B16: Operating income y/y % | D16: =IFERROR(D15/C15-1,"") -> 0.11197146 | E16: =IFERROR(E15/D15-1,"") -> 0.1353314 | F16: =IFERROR(F15/E15-1,"") -> 0.12669588 | G16: =IFERROR(G15/F15-1,"") -> 0.10379505 | H16: =IFERROR(H15/G15-1,"") -> 0.089060599 | N16: Operating income y/y % | P16: 0.18898867 | Q16: 0.1727932 | R16: 0.160111 | S16: 0.1352553 | T16: 0.11906093 | Z16: Operating income y/y % | AB16: -0.068365795 | AC16: 0.051671624 | AD16: 0.04869666 | AE16: 0.02715011 | AF16: 0.013025428
B17: Operating margin (GAAP) % | C17: =IFERROR(C15/C9,"") -> 0.25887482 | D17: =IFERROR(D15/D9,"") -> 0.26038116 | E17: =IFERROR(E15/E9,"") -> 0.26439849 | F17: =IFERROR(F15/F9,"") -> 0.26931896 | G17: =IFERROR(G15/G9,"") -> 0.27078651 | H17: =IFERROR(H15/H9,"") -> 0.27106249 | J17: =IFERROR(AVERAGE(Model!C228,Model!D228,Model!E228,Model!F228,Model!G228,Model!H228,Model!I228,Model!N228,Model!S228,Model!X228,Model!AC228,Model!AH228,Model!AM228,Model!AR228,Model!AW228,Model!BB228,Model!BG228,Model!BL228,Model!BQ228,Model!BV228,Model!CA228),"") -> 0.18525724 | K17: =IFERROR(MIN(Model!C228,Model!D228,Model!E228,Model!F228,Model!G228,Model!H228,Model!I228,Model!N228,Model!S228,Model!X228,Model!AC228,Model!AH228,Model!AM228,Model!AR228,Model!AW228,Model!BB228,Model!BG228,Model!BL228,Model!BQ228,Model!BV228,Model!CA228),"") -> 0.12620949 | L17: =IFERROR(MAX(Model!C228,Model!D228,Model!E228,Model!F228,Model!G228,Model!H228,Model!I228,Model!N228,Model!S228,Model!X228,Model!AC228,Model!AH228,Model!AM228,Model!AR228,Model!AW228,Model!BB228,Model!BG228,Model!BL228,Model!BQ228,Model!BV228,Model!CA228),"") -> 0.22605879 | N17: Operating margin (GAAP) % | O17: 0.26103378 | P17: 0.27138553 | Q17: 0.27327353 | R17: 0.27650341 | S17: 0.2768707 | T17: 0.27648404 | V17: 0.18525724 | W17: 0.12620949 | X17: 0.22605879 | Z17: Operating margin (GAAP) % | AA17: 0.25672101 | AB17: 0.23291917 | AC17: 0.24005842 | AD17: 0.24833229 | AE17: 0.25267485 | AF17: 0.25535155 | AH17: 0.18525724 | AI17: 0.12620949 | AJ17: 0.22605879
B19: Adjusted Net Income (to common) | C19: =Model!CF201 -> 491.12988 | D19: =Model!CG201 -> 560.40958 | E19: =Model!CH201 -> 620.04944 | F19: =Model!CI201 -> 688.9146 | G19: =Model!CJ201 -> 753.95524 | H19: =Model!CK201 -> 820.3889 | I19: =IFERROR((H19/C19)^(1/5)-1,"n/m") -> 0.10806359 | N19: Adjusted Net Income (to common) | O19: 498.22284 | P19: 607.47278 | Q19: 677.99492 | R19: 776.78594 | S19: 874.95404 | T19: 977.82183 | U19: 0.14437199 | Z19: Adjusted Net Income (to common) | AA19: 484.10008 | AB19: 466.55765 | AC19: 488.71607 | AD19: 503.10919 | AE19: 510.47682 | AF19: 516.30954 | AG19: 0.012966307
B21: FDSO (m) | C21: =Model!CF141 -> 31.744686 | D21: =Model!CG141 -> 31.435132 | E21: =Model!CH141 -> 30.746464 | F21: =Model!CI141 -> 30.219927 | G21: =Model!CJ141 -> 29.641862 | H21: =Model!CK141 -> 29.042475 | I21: =IFERROR((H21/C21)^(1/5)-1,"n/m") -> -0.017635822 | N21: FDSO (m) | O21: 31.744686 | P21: 31.090555 | Q21: 30.079967 | R21: 29.568066 | S21: 28.949695 | T21: 28.263129 | U21: -0.022965631 | Z21: FDSO (m) | AA21: 31.744686 | AB21: 31.687012 | AC21: 31.146111 | AD21: 30.46446 | AE21: 29.827319 | AF21: 29.249599 | AG21: -0.016238602
B23: Adjusted EPS — Diluted ($) | C23: =Model!CF203 -> 15.471247 | D23: =Model!CG203 -> 17.827492 | E23: =Model!CH203 -> 20.166529 | F23: =Model!CI203 -> 22.7967 | G23: =Model!CJ203 -> 25.435488 | H23: =Model!CK203 -> 28.247899 | I23: =IFERROR((H23/C23)^(1/5)-1,"n/m") -> 0.12795602 | N23: Adjusted EPS — Diluted ($) | O23: 15.694685 | P23: 19.538821 | Q23: 22.539749 | R23: 26.27111 | S23: 30.223256 | T23: 34.597083 | U23: 0.17127097 | Z23: Adjusted EPS — Diluted ($) | AA23: 15.249799 | AB23: 14.72394 | AC23: 15.691079 | AD23: 16.514627 | AE23: 17.114405 | AF23: 17.65185 | AG23: 0.029686983
B24: EPS y/y % | D24: =IFERROR(D23/C23-1,"") -> 0.15229835 | E24: =IFERROR(E23/D23-1,"") -> 0.13120388 | F24: =IFERROR(F23/E23-1,"") -> 0.13042262 | G24: =IFERROR(G23/F23-1,"") -> 0.11575309 | H24: =IFERROR(H23/G23-1,"") -> 0.11057033 | N24: EPS y/y % | P24: 0.24493236 | Q24: 0.153588 | R24: 0.16554582 | S24: 0.15043693 | T24: 0.14471729 | Z24: EPS y/y % | AB24: -0.034483024 | AC24: 0.065684784 | AD24: 0.052485126 | AE24: 0.036317994 | AF24: 0.031403091
B26: P / E (x) — assumed (adjusted EPS) | G26: 32 | H26: 32 | N26: P / E (x) — assumed (adjusted EPS) | S26: 36 | T26: 36 | Z26: P / E (x) — assumed (adjusted EPS) | AD26: 25 | AE26: 25 | AF26: 25
B27: Price Target ($) | G27: =G26*G23 -> 813.93563 | H27: =H26*H23 -> 903.93276 | N27: Price Target ($) | S27: =S26*S23 -> 1088.0372 | T27: =T26*T23 -> 1245.495 | Z27: Price Target ($) | AD27: =AD26*AD23 -> 412.86567 | AE27: =AE26*AE23 -> 427.86012 | AF27: =AF26*AF23 -> 441.29625
B28: Upside / (Downside) vs current | G28: =IFERROR(G27/$K$2-1,"") -> 0.59595222 | H28: =IFERROR(H27/$K$2-1,"") -> 0.77241719 | N28: Upside / (Downside) vs current | S28: =IFERROR(S27/$K$2-1,"") -> 1.1334063 | T28: =IFERROR(T27/$K$2-1,"") -> 1.4421471 | Z28: Upside / (Downside) vs current | AD28: =IFERROR(AD27/$K$2-1,"") -> -0.19045947 | AE28: =IFERROR(AE27/$K$2-1,"") -> -0.16105859 | AF28: =IFERROR(AF27/$K$2-1,"") -> -0.13471323
B29: IRR (to ~31-Mar of Y-1) | G29: =IFERROR((G27/$K$2)^(1/((DATE(2031-1,3,31)-$K$3)/365.25))-1,"") -> 0.1445084 | H29: =IFERROR((H27/$K$2)^(1/((DATE(2032-1,3,31)-$K$3)/365.25))-1,"") -> 0.13683804 | N29: IRR (to ~31-Mar of Y-1) | S29: =IFERROR((S27/$K$2)^(1/((DATE(2031-1,3,31)-$K$3)/365.25))-1,"") -> 0.24455793 | T29: =IFERROR((T27/$K$2)^(1/((DATE(2032-1,3,31)-$K$3)/365.25))-1,"") -> 0.22149533 | Z29: IRR (to ~31-Mar of Y-1) | AD29: =IFERROR((AD27/$K$2)^(1/((DATE(2030-1,3,31)-$K$3)/365.25))-1,"") -> -0.082174408 | AE29: =IFERROR((AE27/$K$2)^(1/((DATE(2031-1,3,31)-$K$3)/365.25))-1,"") -> -0.04944196 | AF29: =IFERROR((AF27/$K$2)^(1/((DATE(2032-1,3,31)-$K$3)/365.25))-1,"") -> -0.031903072
B31: Free Cash Flow | C31: =Model!CF257 -> 380.25447 | D31: =Model!CG257 -> 476.87711 | E31: =Model!CH257 -> 526.41701 | F31: =Model!CI257 -> 605.98123 | G31: =Model!CJ257 -> 663.30601 | H31: =Model!CK257 -> 720.30829 | I31: =IFERROR((H31/C31)^(1/5)-1,"n/m") -> 0.13628904 | N31: Free Cash Flow | O31: 382.0972 | P31: 500.93474 | Q31: 534.03671 | R31: 641.55513 | S31: 728.21924 | T31: 815.87445 | U31: 0.16383093 | Z31: Free Cash Flow | AA31: 378.49844 | AB31: 422.78235 | AC31: 489.347 | AD31: 514.82844 | AE31: 517.84261 | AF31: 520.51189 | AG31: 0.065794103
B32: FCF % | C32: =IFERROR(C31/C9,"") -> 0.1762791 | D32: =IFERROR(D31/D9,"") -> 0.19996734 | E32: =IFERROR(E31/E9,"") -> 0.19742824 | F32: =IFERROR(F31/F9,"") -> 0.20546592 | G32: =IFERROR(G31/G9,"") -> 0.20486426 | H32: =IFERROR(H31/H9,"") -> 0.20448481 | J32: =IFERROR(AVERAGE(Model!C260,Model!D260,Model!E260,Model!F260,Model!G260,Model!H260,Model!I260,Model!N260,Model!S260,Model!X260,Model!AC260,Model!AH260,Model!AM260,Model!AR260,Model!AW260,Model!BB260,Model!BG260,Model!BL260,Model!BQ260,Model!BV260,Model!CA260),"") -> 0.11532151 | K32: =IFERROR(MIN(Model!C260,Model!D260,Model!E260,Model!F260,Model!G260,Model!H260,Model!I260,Model!N260,Model!S260,Model!X260,Model!AC260,Model!AH260,Model!AM260,Model!AR260,Model!AW260,Model!BB260,Model!BG260,Model!BL260,Model!BQ260,Model!BV260,Model!CA260),"") -> 0.028188143 | L32: =IFERROR(MAX(Model!C260,Model!D260,Model!E260,Model!F260,Model!G260,Model!H260,Model!I260,Model!N260,Model!S260,Model!X260,Model!AC260,Model!AH260,Model!AM260,Model!AR260,Model!AW260,Model!BB260,Model!BG260,Model!BL260,Model!BQ260,Model!BV260,Model!CA260),"") -> 0.23100935 | N32: FCF % | O32: 0.17581337 | P32: 0.20154474 | Q32: 0.18448066 | R32: 0.19329343 | S32: 0.19352106 | T32: 0.19347674 | V32: 0.11532151 | W32: 0.028188143 | X32: 0.23100935 | Z32: FCF % | AA32: 0.17679237 | AB32: 0.19231567 | AC32: 0.21814552 | AD32: 0.22639054 | AE32: 0.22557368 | AF32: 0.2261921 | AH32: 0.11532151 | AI32: 0.028188143 | AJ32: 0.23100935
B33: FCF / share ($) | C33: =IFERROR(C31/C21,"") -> 11.978523 | D33: =IFERROR(D31/D21,"") -> 15.170196 | E33: =IFERROR(E31/E21,"") -> 17.121221 | F33: =IFERROR(F31/F21,"") -> 20.052373 | G33: =IFERROR(G31/G21,"") -> 22.377339 | H33: =IFERROR(H31/H21,"") -> 24.801891 | N33: FCF / share ($) | O33: 12.036572 | P33: 16.11212 | Q33: 17.753899 | R33: 21.697568 | S33: 25.154643 | T33: 28.867096 | Z33: FCF / share ($) | AA33: 11.923206 | AB33: 13.342449 | AC33: 15.711336 | AD33: 16.899313 | AE33: 17.361353 | AF33: 17.795522
B34: FCF Yield (on PT) | F34: =IFERROR(F33/F$27,"") | G34: =IFERROR(G33/G$27,"") -> 0.027492763 | H34: =IFERROR(H33/H$27,"") -> 0.027437761 | N34: FCF Yield (on PT) | R34: =IFERROR(R33/R$27,"") | S34: =IFERROR(S33/S$27,"") -> 0.023119285 | T34: =IFERROR(T33/T$27,"") -> 0.023177207 | Z34: FCF Yield (on PT) | AD34: =IFERROR(AD33/AD$27,"") -> 0.040931746 | AE34: =IFERROR(AE33/AE$27,"") -> 0.040577169 | AF34: =IFERROR(AF33/AF$27,"") -> 0.040325568
B35: Adjusted EBITDA (leverage basis) | C35: =Model!CF179 -> 723.46302 | D35: =Model!CG179 -> 817.00911 | E35: =Model!CH179 -> 919.17164 | F35: =Model!CI179 -> 1023.6111 | G35: =Model!CJ179 -> 1123.385 | H35: =Model!CK179 -> 1222.068 | I35: =IFERROR((H35/C35)^(1/5)-1,"n/m") -> 0.1105441 | N35: Adjusted EBITDA (leverage basis) | O35: 732.98677 | P35: 880.46334 | Q35: 1025.5206 | R35: 1178.3025 | S35: 1331.4106 | T35: 1488.3359 | U35: 0.15218168 | Z35: Adjusted EBITDA (leverage basis) | AA35: 714.02024 | AB35: 690.77851 | AC35: 716.97415 | AD35: 739.22291 | AE35: 752.10774 | AF35: 759.91737 | AG35: 0.012537623
B36: Adjusted EBITDA % of net sales | C36: =IFERROR(C35/C9,"") -> 0.33538438 | D36: =IFERROR(D35/D9,"") -> 0.3425938 | E36: =IFERROR(E35/E9,"") -> 0.34472754 | F36: =IFERROR(F35/F9,"") -> 0.34706884 | G36: =IFERROR(G35/G9,"") -> 0.34696117 | H36: =IFERROR(H35/H9,"") -> 0.34692693 | J36: =IFERROR(AVERAGE(Model!C227,Model!D227,Model!E227,Model!F227,Model!G227,Model!H227,Model!I227,Model!N227,Model!S227,Model!X227,Model!AC227,Model!AH227,Model!AM227,Model!AR227,Model!AW227,Model!BB227,Model!BG227,Model!BL227,Model!BQ227,Model!BV227,Model!CA227),"") -> 0.26140804 | K36: =IFERROR(MIN(Model!C227,Model!D227,Model!E227,Model!F227,Model!G227,Model!H227,Model!I227,Model!N227,Model!S227,Model!X227,Model!AC227,Model!AH227,Model!AM227,Model!AR227,Model!AW227,Model!BB227,Model!BG227,Model!BL227,Model!BQ227,Model!BV227,Model!CA227),"") -> 0.19560833 | L36: =IFERROR(MAX(Model!C227,Model!D227,Model!E227,Model!F227,Model!G227,Model!H227,Model!I227,Model!N227,Model!S227,Model!X227,Model!AC227,Model!AH227,Model!AM227,Model!AR227,Model!AW227,Model!BB227,Model!BG227,Model!BL227,Model!BQ227,Model!BV227,Model!CA227),"") -> 0.32353413 | N36: Adjusted EBITDA % of net sales | O36: 0.33726726 | P36: 0.35424325 | Q36: 0.35426164 | R36: 0.35500946 | S36: 0.35381651 | T36: 0.35294448 | V36: 0.26140804 | W36: 0.19560833 | X36: 0.32353413 | Z36: Adjusted EBITDA % of net sales | AA36: 0.33351083 | AB36: 0.31422203 | AC36: 0.3196192 | AD36: 0.32506571 | AE36: 0.32762022 | AF36: 0.33022743 | AH36: 0.26140804 | AI36: 0.19560833 | AJ36: 0.32353413
B38: Net Debt | C38: =Model!CF387 -> 470.54553 | D38: =Model!CG387 -> 817.00911 | E38: =Model!CH387 -> 919.17164 | F38: =Model!CI387 -> 1023.6111 | G38: =Model!CJ387 -> 1123.385 | H38: =Model!CK387 -> 1222.068 | N38: Net Debt | O38: 468.7028 | P38: 1320.695 | Q38: 1538.2809 | R38: 1767.4538 | S38: 1997.1159 | T38: 2232.5039 | Z38: Net Debt | AA38: 472.30156 | AB38: 345.38926 | AC38: 358.48707 | AD38: 369.61145 | AE38: 376.05387 | AF38: 379.95869
B39: Net Debt / Adjusted EBITDA (x) | C39: =IFERROR(C38/C35,"") -> 0.65040717 | D39: =IFERROR(D38/D35,"") -> 1 | E39: =IFERROR(E38/E35,"") -> 1 | F39: =IFERROR(F38/F35,"") -> 1 | G39: =IFERROR(G38/G35,"") -> 1 | H39: =IFERROR(H38/H35,"") -> 1 | N39: Net Debt / Adjusted EBITDA (x) | O39: 0.63944238 | P39: 1.5 | Q39: 1.5 | R39: 1.5 | S39: 1.5 | T39: 1.5 | Z39: Net Debt / Adjusted EBITDA (x) | AA39: 0.66146803 | AB39: 0.5 | AC39: 0.5 | AD39: 0.5 | AE39: 0.5 | AF39: 0.5
B40: Share repurchases ($m; open market, ex withholding) | D40: =Model!CG270 -> 573.34069 | E40: =Model!CH270 -> 378.57954 | F40: =Model!CI270 -> 460.42072 | G40: =Model!CJ270 -> 513.07983 | H40: =Model!CK270 -> 568.99135 | N40: Share repurchases ($m; open market, ex withholding) | P40: 952.92694 | Q40: 351.62263 | R40: 470.72802 | S40: 557.8813 | T40: 651.26247 | AB40: 295.87005 | AC40: 502.44482 | AD40: 525.95282 | AE40: 524.28502 | AF40: 524.41671
B41: Implied avg buyback price ($) | D41: =Model!CG269 -> 550.8 | E41: =Model!CH269 -> 594.864 | F41: =Model!CI269 -> 642.45312 | G41: =Model!CJ269 -> 693.84937 | H41: =Model!CK269 -> 749.35732 | N41: Implied avg buyback price ($) | P41: 550.8 | Q41: 594.864 | R41: 642.45312 | S41: 693.84937 | T41: 749.35732 | AB41: 550.8 | AC41: 594.864 | AD41: 642.45312 | AE41: 693.84937 | AF41: 749.35732
B42: Shares repurchased (m) | D42: =Model!CG271 -> 1.0409236 | E42: =Model!CH271 -> 0.6364136 | F42: =Model!CI271 -> 0.71666041 | G42: =Model!CJ271 -> 0.73946861 | H42: =Model!CK271 -> 0.75930579 | N42: Shares repurchased (m) | P42: 1.730078 | Q42: 0.59109752 | R42: 0.73270407 | S42: 0.80403805 | T42: 0.86909469 | AB42: 0.53716421 | AC42: 0.84463814 | AD42: 0.81866334 | AE42: 0.75561793 | AF42: 0.69982196
B44: ROIC | C44: =Model!CF370 -> 0.10272164 | D44: =Model!CG370 -> 0.10742003 | E44: =Model!CH370 -> 0.11471249 | F44: =Model!CI370 -> 0.12228657 | G44: =Model!CJ370 -> 0.12797612 | H44: =Model!CK370 -> 0.13240787 | J44: =IFERROR(AVERAGE(Model!C370,Model!D370,Model!E370,Model!F370,Model!G370,Model!H370,Model!I370,Model!N370,Model!S370,Model!X370,Model!AC370,Model!AH370,Model!AM370,Model!AR370,Model!AW370,Model!BB370,Model!BG370,Model!BL370,Model!BQ370,Model!BV370,Model!CA370),"") -> 0.11263111 | K44: =IFERROR(MIN(Model!C370,Model!D370,Model!E370,Model!F370,Model!G370,Model!H370,Model!I370,Model!N370,Model!S370,Model!X370,Model!AC370,Model!AH370,Model!AM370,Model!AR370,Model!AW370,Model!BB370,Model!BG370,Model!BL370,Model!BQ370,Model!BV370,Model!CA370),"") -> 0.039948322 | L44: =IFERROR(MAX(Model!C370,Model!D370,Model!E370,Model!F370,Model!G370,Model!H370,Model!I370,Model!N370,Model!S370,Model!X370,Model!AC370,Model!AH370,Model!AM370,Model!AR370,Model!AW370,Model!BB370,Model!BG370,Model!BL370,Model!BQ370,Model!BV370,Model!CA370),"") -> 0.16854484 | N44: ROIC | O44: 0.10422078 | P44: 0.11275862 | Q44: 0.11990058 | R44: 0.12751923 | S44: 0.13353192 | T44: 0.13852951 | V44: 0.11263111 | W44: 0.039948322 | X44: 0.16854484 | Z44: ROIC | AA44: 0.10123421 | AB44: 0.093914386 | AC44: 0.099995872 | AD44: 0.10636643 | AE44: 0.11065862 | AF44: 0.11347671 | AH44: 0.11263111 | AI44: 0.039948322 | AJ44: 0.16854484
B45: RONTA | C45: =Model!CF381 -> 0.28561418 | D45: =Model!CG381 -> 0.29256122 | E45: =Model!CH381 -> 0.3052408 | F45: =Model!CI381 -> 0.31969823 | G45: =Model!CJ381 -> 0.328226 | H45: =Model!CK381 -> 0.33236244 | J45: =IFERROR(AVERAGE(Model!C381,Model!D381,Model!E381,Model!F381,Model!G381,Model!H381,Model!I381,Model!N381,Model!S381,Model!X381,Model!AC381,Model!AH381,Model!AM381,Model!AR381,Model!AW381,Model!BB381,Model!BG381,Model!BL381,Model!BQ381,Model!BV381,Model!CA381),"") -> 0.15926997 | K45: =IFERROR(MIN(Model!C381,Model!D381,Model!E381,Model!F381,Model!G381,Model!H381,Model!I381,Model!N381,Model!S381,Model!X381,Model!AC381,Model!AH381,Model!AM381,Model!AR381,Model!AW381,Model!BB381,Model!BG381,Model!BL381,Model!BQ381,Model!BV381,Model!CA381),"") -> 0.081484184 | L45: =IFERROR(MAX(Model!C381,Model!D381,Model!E381,Model!F381,Model!G381,Model!H381,Model!I381,Model!N381,Model!S381,Model!X381,Model!AC381,Model!AH381,Model!AM381,Model!AR381,Model!AW381,Model!BB381,Model!BG381,Model!BL381,Model!BQ381,Model!BV381,Model!CA381),"") -> 0.25242312 | N45: RONTA | O45: 0.28914826 | P45: 0.31059453 | Q45: 0.32327794 | R45: 0.33807283 | S45: 0.34722586 | T45: 0.35214837 | V45: 0.15926997 | W45: 0.081484184 | X45: 0.25242312 | Z45: RONTA | AA45: 0.2821016 | AB45: 0.23698516 | AC45: 0.24811162 | AD45: 0.26062182 | AE45: 0.26684562 | AF45: 0.26857611 | AH45: 0.15926997 | AI45: 0.081484184 | AJ45: 0.25242312
B47: Implied Market Cap (USDm) | F47: =F27*F21 -> 0 | G47: =G27*G21 -> 24126.568 | H47: =H27*H21 -> 26252.445 | N47: Implied Market Cap (USDm) | R47: =R27*R21 -> 0 | S47: =S27*S21 -> 31498.346 | T47: =T27*T21 -> 35201.586 | Z47: Implied Market Cap (USDm) | AD47: =AD27*AD21 -> 12577.73 | AE47: =AE27*AE21 -> 12761.92 | AF47: =AF27*AF21 -> 12907.739
B48: (+) Net Debt & NCI | F48: =F38+Model!CI397 -> 1023.6111 | G48: =G38+Model!CJ397 -> 1123.385 | H48: =H38+Model!CK397 -> 1222.068 | N48: (+) Net Debt & NCI | R48: =R38+Model!CI397 -> 1767.4538 | S48: =S38+Model!CJ397 -> 1997.1159 | T48: =T38+Model!CK397 -> 2232.5039 | Z48: (+) Net Debt & NCI | AD48: =AD38+Model!CI397 -> 369.61145 | AE48: =AE38+Model!CJ397 -> 376.05387 | AF48: =AF38+Model!CK397 -> 379.95869
B49: Implied Enterprise Value (USDm) | F49: =F47+F48 -> 1023.6111 | G49: =G47+G48 -> 25249.953 | H49: =H47+H48 -> 27474.513 | N49: Implied Enterprise Value (USDm) | R49: =R47+R48 -> 1767.4538 | S49: =S47+S48 -> 33495.461 | T49: =T47+T48 -> 37434.09 | Z49: Implied Enterprise Value (USDm) | AD49: =AD47+AD48 -> 12947.341 | AE49: =AE47+AE48 -> 13137.974 | AF49: =AF47+AF48 -> 13287.697
B50: Implied EV / Adjusted EBITDA (x) | F50: =IFERROR(F49/F35,"") -> 1 | G50: =IFERROR(G49/G35,"") -> 22.47667 | H50: =IFERROR(H49/H35,"") -> 22.481983 | N50: Implied EV / Adjusted EBITDA (x) | R50: =IFERROR(R49/R35,"") -> 1.5 | S50: =IFERROR(S49/S35,"") -> 25.157875 | T50: =IFERROR(T49/T35,"") -> 25.15164 | Z50: Implied EV / Adjusted EBITDA (x) | AD50: =IFERROR(AD49/AD35,"") -> 17.5148 | AE50: =IFERROR(AE49/AE35,"") -> 17.468208 | AF50: =IFERROR(AF49/AF35,"") -> 17.485713

Sheet DCF
B2: DCF VALUATION — RBC BEARINGS INCORPORATED (RBC)
B4: 1. WACC BUILD
B5: Risk-free rate (US 10Y govt) | C5: 0.0425 | D5: Assumption (~US 10Y Treasury yield, Oct-2026; government rate sources are not reachable from the build environment); update to market
B6: Equity risk premium | C6: 0.05 | D6: Assumption: US implied ERP ~4.5–5.5%
B7: Levered beta | C7: 1.05 | D7: Assumption: precision-components / aerospace peers (TDG, HEI, CW, TKR, KMT) ~0.9–1.3; ~58% of sales Industrial (cyclical: mining, construction, oil & gas)
B8: Cost of equity | C8: =C5+C7*C6 -> 0.095
B9: Pre-tax cost of debt | C9: 0.055 | D9: Assumption: 4.375% senior notes due 2029 and the revolver at SOFR + 0.85% (~5.0%); marginal cost of new notes ~5.5%
B10: Tax rate | C10: 0.23 | D10: Model FY2028E+ effective tax rate (FY2026 22.1%; Q1 FY27 22.1%)
B11: After-tax cost of debt | C11: =C9*(1-C10) -> 0.04235
B12: Target D/V | C12: 0.05 | D12: Net debt ~$0.7bn at 27-Jun-2026 vs ~$16bn market cap ($510 × ~31.8m diluted shares); ~1.0x adjusted EBITDA
B13: WACC | C13: =C8*(1-C12)+C11*C12 -> 0.0923675
B15: Valuation date (live) | C15: =TODAY() -> 2026-10-13 00:00:00 | D15: Periods = (31-Mar of fiscal year − today) / 365.25; cash flows assumed at fiscal year end; FY2027E (ends 3-Apr-2027) is the base year — its cash flow is in the net debt below
B16: 2. UNLEVERED FREE CASH FLOW BUILD (USDm)
D17: 2028E | E17: 2029E | F17: 2030E | G17: 2031E | H17: 2032E | I17: 2033E | J17: 2034E | K17: 2035E | L17: 2036E | M17: 2037E | N17: Terminal | P17: CAGR 28–32E | Q17: CAGR 28–37E
B18: Adj. EBITA (after stock comp; before M&A amortization) less transaction & restructuring costs | D18: =Model!CG186-Model!CG187 -> 700.30947 | E18: =Model!CH186-Model!CH187 -> 789.51856 | F18: =Model!CI186-Model!CI187 -> 880.9432 | G18: =Model!CJ186-Model!CJ187 -> 967.44694 | H18: =Model!CK186-Model!CK187 -> 1053.0306 | I18: =H18*(1+I$26) -> 1126.7428 | J18: =I18*(1+J$26) -> 1199.9811 | K18: =J18*(1+K$26) -> 1271.9799 | L18: =K18*(1+L$26) -> 1341.9388 | M18: =L18*(1+M$26) -> 1409.0358 | P18: =(H18/D18)^(1/(COLUMNS(D18:H18)-1))-1 -> 0.10735725 | Q18: =(M18/D18)^(1/(COLUMNS(D18:M18)-1))-1 -> 0.080778984
B19: × (1 − tax rate) | D19: =1-$C$10 -> 0.77 | E19: =1-$C$10 -> 0.77 | F19: =1-$C$10 -> 0.77 | G19: =1-$C$10 -> 0.77 | H19: =1-$C$10 -> 0.77 | I19: =1-$C$10 -> 0.77 | J19: =1-$C$10 -> 0.77 | K19: =1-$C$10 -> 0.77 | ... M19: =1-$C$10 -> 0.77
B20: NOPAT | D20: =D18*D19 -> 539.23829 | E20: =E18*E19 -> 607.92929 | F20: =F18*F19 -> 678.32626 | G20: =G18*G19 -> 744.93414 | H20: =H18*H19 -> 810.83359 | I20: =I18*I19 -> 867.59194 | J20: =J18*J19 -> 923.98542 | K20: =K18*K19 -> 979.42454 | ... M20: =M18*M19 -> 1084.9575
B21: plus D&A excluding M&A-related amortization (depreciation & software) | D21: =Model!CG89 -> 66.773699 | E21: =Model!CH89 -> 74.658398 | F21: =Model!CI89 -> 82.580482 | G21: =Model!CJ89 -> 90.657923 | H21: =Model!CK89 -> 98.631446 | I21: =H21*(1+I$26) -> 105.53565 | J21: =I21*(1+J$26) -> 112.39546 | K21: =J21*(1+K$26) -> 119.13919 | L21: =K21*(1+L$26) -> 125.69185 | M21: =L21*(1+M$26) -> 131.97644
B22: − Capex (PP&E) and acquisitions (M&A lever FY2028E–32E) | D22: =Model!CG240+Model!CG241 -> -345.391 | E22: =Model!CH240+Model!CH241 -> -351.32211 | F22: =Model!CI240+Model!CI241 -> -353.2256 | G22: =Model!CJ240+Model!CJ241 -> -363.3224 | H22: =Model!CK240+Model!CK241 -> -373.28931 | I22: =Model!CK240*(1+I$26) -> -131.91956 | J22: =I22*(1+J$26) -> -140.49433 | K22: =J22*(1+K$26) -> -148.92399 | L22: =K22*(1+L$26) -> -157.11481 | M22: =L22*(1+M$26) -> -164.97055
B23: − Δ Working capital (CF statement) | D23: =Model!CG238 -> -73.573162 | E23: =Model!CH238 -> -87.597994 | F23: =Model!CI238 -> -84.12896 | G23: =Model!CJ238 -> -91.533718 | H23: =Model!CK238 -> -101.44705 | I23: =H23*(1+I$26) -> -108.54834 | J23: =I23*(1+J$26) -> -115.60398 | K23: =J23*(1+K$26) -> -122.54022 | L23: =K23*(1+L$26) -> -129.27993 | M23: =L23*(1+M$26) -> -135.74393
B24: Unlevered FCF | D24: =D20+D21+D22+D23 -> 187.04783 | E24: =E20+E21+E22+E23 -> 243.66759 | F24: =F20+F21+F22+F23 -> 323.55218 | G24: =G20+G21+G22+G23 -> 380.73594 | H24: =H20+H21+H22+H23 -> 434.72868 | I24: =I20+I21+I22+I23 -> 732.65969 | J24: =J20+J21+J22+J23 -> 780.28257 | K24: =K20+K21+K22+K23 -> 827.09952 | ... M24: =M20+M21+M22+M23 -> 916.2195 | N24: =M24*(1+$C$27) -> 952.86828 | P24: =(H24/D24)^(1/(COLUMNS(D24:H24)-1))-1 -> 0.2347141 | Q24: =(M24/D24)^(1/(COLUMNS(D24:M24)-1))-1 -> 0.19308634
B25: Terminal Value (Gordon Growth) | N25: =N24/($C$13-$C$27) -> 18195.795
B26: Fade-period growth (FY2033E–37E; 7.0% → 5.0% linear) | I26: 0.07 | J26: =I26+($M$26-$I$26)/4 -> 0.065 | K26: =J26+($M$26-$I$26)/4 -> 0.06 | L26: =K26+($M$26-$I$26)/4 -> 0.055 | M26: 0.05
B27: Terminal growth rate | C27: 0.04
B29: Discount period (years) | D29: =(DATE(2028,3,31)-$C$15)/365.25 -> 1.4647502 | E29: =(DATE(2029,3,31)-$C$15)/365.25 -> 2.4640657 | F29: =(DATE(2030,3,31)-$C$15)/365.25 -> 3.4633812 | G29: =(DATE(2031,3,31)-$C$15)/365.25 -> 4.4626968 | H29: =(DATE(2032,3,31)-$C$15)/365.25 -> 5.4647502 | I29: =(DATE(2033,3,31)-$C$15)/365.25 -> 6.4640657 | J29: =(DATE(2034,3,31)-$C$15)/365.25 -> 7.4633812 | K29: =(DATE(2035,3,31)-$C$15)/365.25 -> 8.4626968 | L29: =(DATE(2036,3,31)-$C$15)/365.25 -> 9.4647502 | M29: =(DATE(2037,3,31)-$C$15)/365.25 -> 10.464066 | N29: =M29 -> 10.464066
B30: Discount factor | D30: =1/(1+$C$13)^D29 -> 0.87861646 | E30: =1/(1+$C$13)^E29 -> 0.80437178 | F30: =1/(1+$C$13)^F29 -> 0.73640092 | G30: =1/(1+$C$13)^G29 -> 0.67417371 | H30: =1/(1+$C$13)^H29 -> 0.61705554 | I30: =1/(1+$C$13)^I29 -> 0.56491323 | J30: =1/(1+$C$13)^J29 -> 0.51717704 | K30: =1/(1+$C$13)^K29 -> 0.47347465 | ... N30: =1/(1+$C$13)^N29 -> 0.39674062
B31: PV of UFCF | D31: =D24*D30 -> 164.3433 | E31: =E24*E30 -> 195.99933 | F31: =F24*F30 -> 238.26412 | G31: =G24*G30 -> 256.68216 | H31: =H24*H30 -> 268.25174 | I31: =I24*I30 -> 413.88915 | J31: =J24*J30 -> 403.54423 | K31: =K24*K30 -> 391.61066 | ... M31: =M24*M30 -> 363.50149 | N31: =N25*N30 -> 7219.0108
D32: NOPAT basis (playbook 5.7): RBC's adjusted EPS and adjusted EBITDA add back stock compensation; here it is deducted (row 18 starts from adjusted operating income, which is after stock compensation) and M&A-related amortization of acquired intangibles is added back (EBITA), so the tax is charged on pre-amortization profit; row 21 adds back depreciation and non-acquired amortization only. Transaction, transition and restructuring costs (cash; adjusted out by the company) are deducted in row 18. Row 22 includes acquisitions from the M&A lever in FY2028E–32E; the fade period and terminal value assume no new acquisitions. The cash tax shield on acquired-intangible amortization (e.g. VACCO, Section 338(h)(10) election per the FY2026 10-K) is not modelled separately.
B33: IMPLIED ROIC — invested capital roll-forward (USDm)
