Workbook

Sheet Model
BD1: SCENARIO SWITCH ▼ (Bull / Base / Bear) — drives all scenario-linked forecast drivers
B2: Hermès International S.C.A. (Euronext Paris: RMS) — 3-Statement Financial Model | BD2: Base
B3: IFRS as reported · EUR millions (per-share data in EUR) · Source: Hermès registration documents / Universal Registration Documents (annual financial reports FY2010–FY2025; FY2009 comparatives and FY2006–08 key figures from the 2010 document), half-year financial reports (H1 2013–H1 2026), half-year / full-year results and quarterly revenue releases — finance.hermes.com (documents filed with the AMF). Hermès is not an SEC registrant: EDGAR holds only ADR (Form F-6) registrations, no 10-K / 10-Q / 8-K.
B4: Basis notes: calendar fiscal year; interim columns are half-years (Hermès publishes full statements for H1 and FY only): H1 as reported, H2 = FY − H1 (balances = 31-Dec). Each period as originally reported (2018 pre-IFRS 16; IFRS 16 from 2019, 2018 not restated). Tableware folded into Other Hermès sectors (separate to 2013). Free-share plan expense reclassified from S&A to other income & expenses from 2015 (2014 as reported). Non-recurring items: 2018 HK property gain €52.7m; 2020 Shang Xia deconsolidation €91.1m. French exceptional contribution on large companies' profits in 2025 (€331m) and renewed for 2026. H2/26E–2030E = forecast (no company numeric guidance; scenario-driven).
BF5: Forecast | BG5: Historical | BH5: Historical | BI5: Historical
B6: (EURm) | C6: 2006 | D6: 2007 | E6: 2008 | F6: 2009 | G6: 2010 | H6: 2011 | I6: 2012 | J6: H1/13 | K6: H2/13 | L6: 2013 | M6: H1/14 | N6: H2/14 | O6: 2014 | P6: H1/15 | Q6: H2/15 | R6: 2015 | S6: H1/16 | T6: H2/16 | U6: 2016 | V6: H1/17 | W6: H2/17 | X6: 2017 | Y6: H1/18 | Z6: H2/18 | AA6: 2018 | AB6: H1/19 | AC6: H2/19 | AD6: 2019 | AE6: H1/20 | AF6: H2/20 | AG6: 2020 | AH6: H1/21 | AI6: H2/21 | AJ6: 2021 | AK6: H1/22 | AL6: H2/22 | AM6: 2022 | AN6: H1/23 | AO6: H2/23 | AP6: 2023 | AQ6: H1/24 | AR6: H2/24 | AS6: 2024 | AT6: H1/25 | AU6: H2/25 | AV6: 2025 | AW6: H1/26 | AX6: H2/26E | AY6: 2026E | AZ6: 2027E | BA6: 2028E | BB6: 2029E | BC6: 2030E | BD6: Modelling Notes | BF6: 5Y CAGR | BG6: 5Y CAGR | BH6: 10Y CAGR | BI6: 19Y CAGR
BF7: 25-'30 | BG7: 20-'25 | BH7: 15-'25 | BI7: 06-'25
B8: MÉTIER REVENUE BUILD — SEVEN SECTORS (prior period × (1 + constant-currency growth + currency effect)) | BD8: MÉTIER BUILD — modelling logic (constant-currency growth by métier + group currency effect)
BL9: SCENARIO INPUT TABLE — driver assumptions per Bull / Base / Bear | BM9: Bull | BN9: Base | BO9: Bear | BP9: Bull / Bear = Base + Δ (Δ inputs on each block header). Point-estimate block applies to all cases except the H2/26E currency effect.
B10: Leather Goods & Saddlery (bags, travel, small leather goods, saddles & equestrian) | BD10: LEATHER GOODS & SADDLERY — modelling logic
B11: Revenue | F11: 936 | G11: 1205 | H11: 1348 | I11: 1596.6 | J11: 779.9 | K11: =L11-J11 -> 853.9 | L11: 1633.8 | M11: 840.7 | N11: =O11-M11 -> 1001.4 | O11: 1842.1 | P11: 1067.4 | Q11: =R11-P11 -> 1206.9 | R11: 2274.3 | S11: 1231.2 | T11: =U11-S11 -> 1372.5 | U11: 2603.7 | V11: 1404 | W11: =X11-V11 -> 1396.3 | X11: 2800.3 | Y11: 1425.1 | Z11: =AA11-Y11 -> 1550.7 | AA11: 2975.8 | AB11: 1652.4 | AC11: =AD11-AB11 -> 1761.9 | AD11: 3414.3 | AE11: 1280.1 | AF11: =AG11-AE11 -> 1929.1 | AG11: 3209.2 | AH11: 1999.3 | AI11: =AJ11-AH11 -> 2091.7 | AJ11: 4091 | AK11: 2358 | AL11: =AM11-AK11 -> 2605 | AM11: 4963 | AN11: 2780 | AO11: =AP11-AN11 -> 2767 | AP11: 5547 | AQ11: 3215 | AR11: =AS11-AQ11 -> 3242 | AS11: 6457 | AT11: 3578 | AU11: =AV11-AT11 -> 3492 | AV11: 7070 | AW11: 3761 | AX11: =AU11*(1+AX13+AX64) -> 3701.52 | AY11: =AW11+AX11 -> 7462.52 | AZ11: =AY11*(1+AZ13+AZ64) -> 8134.1468 | BA11: =AZ11*(1+BA13+BA64) -> 8866.22 | BB11: =BA11*(1+BB13+BB64) -> 9619.8487 | BC11: =BB11*(1+BC13+BC64) -> 10389.437 | BD11: H2/26E: H2/25 × (1 + scenario constant-currency growth + H2/26E currency effect). 2027E+: prior year × (1 + scenario cc growth + currency effect). | BF11: =IFERROR((BC11/AV11)^(1/5)-1,"n/m") -> 0.080026761 | BG11: =IFERROR((AV11/AG11)^(1/5)-1,"n/m") -> 0.17112844 | BH11: =IFERROR((AV11/R11)^(1/10)-1,"n/m") -> 0.12010095 | BI11: =IFERROR((AV11/C11)^(1/19)-1,"n/m") -> n/m | BL11: 2026E point estimates — H2/26E drivers (company has no numeric FY26 guidance)
B12: Revenue y/y % (reported) | D12: =IF(AND(ISNUMBER(D11),ISNUMBER(C11)),IFERROR(D11/C11-1,""),"") | E12: =IF(AND(ISNUMBER(E11),ISNUMBER(D11)),IFERROR(E11/D11-1,""),"") | F12: =IF(AND(ISNUMBER(F11),ISNUMBER(E11)),IFERROR(F11/E11-1,""),"") | G12: =IF(AND(ISNUMBER(G11),ISNUMBER(F11)),IFERROR(G11/F11-1,""),"") -> 0.28739316 | H12: =IF(AND(ISNUMBER(H11),ISNUMBER(G11)),IFERROR(H11/G11-1,""),"") -> 0.1186722 | I12: =IF(AND(ISNUMBER(I11),ISNUMBER(H11)),IFERROR(I11/H11-1,""),"") -> 0.18442136 | L12: =IF(AND(ISNUMBER(L11),ISNUMBER(I11)),IFERROR(L11/I11-1,""),"") -> 0.023299511 | M12: =IF(AND(ISNUMBER(M11),ISNUMBER(J11)),IFERROR(M11/J11-1,""),"") -> 0.077958713 | N12: =IF(AND(ISNUMBER(N11),ISNUMBER(K11)),IFERROR(N11/K11-1,""),"") -> 0.17273685 | O12: =IF(AND(ISNUMBER(O11),ISNUMBER(L11)),IFERROR(O11/L11-1,""),"") -> 0.12749419 | P12: =IF(AND(ISNUMBER(P11),ISNUMBER(M11)),IFERROR(P11/M11-1,""),"") -> 0.26965624 | Q12: =IF(AND(ISNUMBER(Q11),ISNUMBER(N11)),IFERROR(Q11/N11-1,""),"") -> 0.2052127 | R12: =IF(AND(ISNUMBER(R11),ISNUMBER(O11)),IFERROR(R11/O11-1,""),"") -> 0.23462353 | S12: =IF(AND(ISNUMBER(S11),ISNUMBER(P11)),IFERROR(S11/P11-1,""),"") -> 0.153457 | ... AY12: =IF(AND(ISNUMBER(AY11),ISNUMBER(AV11)),IFERROR(AY11/AV11-1,""),"") -> 0.055519095 | AZ12: =IF(AND(ISNUMBER(AZ11),ISNUMBER(AY11)),IFERROR(AZ11/AY11-1,""),"") -> 0.09 | BA12: =IF(AND(ISNUMBER(BA11),ISNUMBER(AZ11)),IFERROR(BA11/AZ11-1,""),"") -> 0.09 | BB12: =IF(AND(ISNUMBER(BB11),ISNUMBER(BA11)),IFERROR(BB11/BA11-1,""),"") -> 0.085 | BC12: =IF(AND(ISNUMBER(BC11),ISNUMBER(BB11)),IFERROR(BC11/BB11-1,""),"") -> 0.08 | BL12: H2/26E currency effect on revenue growth (pts) | BM12: -0.02 | BN12: -0.03 | BO12: -0.05 | BP12: H2/26E currency effect on reported revenue growth (H1/26: −4.5 pts: +1.6% reported vs +6.1% at constant rates). USD, JPY and CNY weaker vs the euro than in H2/25.
B13: Revenue y/y % at constant exchange rates (company) | G13: 0.208 | H13: 0.115 | I13: 0.118 | J13: 0.099 | L13: 0.088 | M13: 0.126 | O13: 0.146 | P13: 0.136 | R13: 0.126 | S13: 0.163 | U13: 0.14 | V13: 0.122 | X13: 0.097 | Y13: 0.08 | AA13: 0.094 | AB13: 0.124 | AD13: 0.113 | AE13: -0.233 | AG13: -0.048 | AH13: 0.629 | AJ13: 0.289 | AK13: 0.121 | AM13: 0.156 | AN13: 0.208 | AP13: 0.167 | AQ13: 0.191 | AS13: 0.183 | AT13: 0.124 | AV13: 0.131 | AW13: 0.098 | AX13: =CHOOSE(MATCH($BD$2,{"Bull","Base","Bear"},0),$BM$19,$BN$19,$BO$19) -> 0.09 | AY13: =(AT11*(1+AW13)+AU11*(1+AX13))/AV11-1 -> 0.094048656 | AZ13: =CHOOSE(MATCH($BD$2,{"Bull","Base","Bear"},0),$BM$20,$BN$20,$BO$20) -> 0.09 | BA13: =CHOOSE(MATCH($BD$2,{"Bull","Base","Bear"},0),$BM$21,$BN$21,$BO$21) -> 0.09 | BB13: =CHOOSE(MATCH($BD$2,{"Bull","Base","Bear"},0),$BM$22,$BN$22,$BO$22) -> 0.085 | BC13: =CHOOSE(MATCH($BD$2,{"Bull","Base","Bear"},0),$BM$23,$BN$23,$BO$23) -> 0.08 | BD13: Scenario lever (LEATHER_ccGrowth, Bull/Base/Bear table →). 2026E = H1/26 actual and H2/26E growth weighted by 2025 halves. Company figures to one decimal (press releases). | BF13: =IFERROR(AVERAGE(AY13,AZ13,BA13,BB13,BC13),"n/m") -> 0.087809731 | BG13: =IFERROR(AVERAGE(AJ13,AM13,AP13,AS13,AV13),"n/m") -> 0.1852 | BH13: =IFERROR(AVERAGE(U13,X13,AA13,AD13,AG13,AJ13,AM13,AP13,AS13,AV13),"n/m") -> 0.1322 | BI13: =IFERROR(AVERAGE(C13,D13,E13,F13,G13,H13,I13,L13,O13,R13,U13,X13,AA13,AD13,AG13,AJ13,AM13,AP13,AS13,AV13),"n/m") -> 0.1326875 | BL13: 2026E effective tax rate (incl. French exceptional contribution) | BN13: 0.33 | BP13: ETR 33% and contribution ≈ 5 pts of pre-tax income: H1/26 report outlook. Capex: 2025 €1,161m, H1/26 €344m; 2024 URD guided ~€1bn for 2025.
B14: Currency (and scope) effect on growth, pts (reported − constant FX) | C14: =IF(AND(ISNUMBER(C12),ISNUMBER(C13)),C12-C13,"") | D14: =IF(AND(ISNUMBER(D12),ISNUMBER(D13)),D12-D13,"") | E14: =IF(AND(ISNUMBER(E12),ISNUMBER(E13)),E12-E13,"") | F14: =IF(AND(ISNUMBER(F12),ISNUMBER(F13)),F12-F13,"") | G14: =IF(AND(ISNUMBER(G12),ISNUMBER(G13)),G12-G13,"") -> 0.079393162 | H14: =IF(AND(ISNUMBER(H12),ISNUMBER(H13)),H12-H13,"") -> 0.0036721992 | I14: =IF(AND(ISNUMBER(I12),ISNUMBER(I13)),I12-I13,"") -> 0.066421365 | J14: =IF(AND(ISNUMBER(J12),ISNUMBER(J13)),J12-J13,"") | ... AW14: =IF(AND(ISNUMBER(AW12),ISNUMBER(AW13)),AW12-AW13,"") -> -0.046854108 | AX14: =AX64 -> -0.03 | AY14: =AY12-AY13 -> -0.038529562 | AZ14: =AZ64 -> 0 | BA14: =BA64 -> 0 | BB14: =BB64 -> 0 | BC14: =BC64 -> 0 | BD14: Forecast: group currency effect applied to every métier. | BL14: 2026E exceptional contribution (pts of pre-tax income) | BN14: 0.05
B15: % of group revenue | C15: =IF(AND(ISNUMBER(C11),ISNUMBER(C61)),IFERROR(C11/C61,""),"") | D15: =IF(AND(ISNUMBER(D11),ISNUMBER(D61)),IFERROR(D11/D61,""),"") | E15: =IF(AND(ISNUMBER(E11),ISNUMBER(E61)),IFERROR(E11/E61,""),"") | F15: =IF(AND(ISNUMBER(F11),ISNUMBER(F61)),IFERROR(F11/F61,""),"") -> 0.48902821 | G15: =IF(AND(ISNUMBER(G11),ISNUMBER(G61)),IFERROR(G11/G61,""),"") -> 0.50166528 | H15: =IF(AND(ISNUMBER(H11),ISNUMBER(H61)),IFERROR(H11/H61,""),"") -> 0.47431386 | I15: =IF(AND(ISNUMBER(I11),ISNUMBER(I61)),IFERROR(I11/I61,""),"") -> 0.45824006 | J15: =IF(AND(ISNUMBER(J11),ISNUMBER(J61)),IFERROR(J11/J61,""),"") -> 0.44134458 | ... BC15: =IF(AND(ISNUMBER(BC11),ISNUMBER(BC61)),IFERROR(BC11/BC61,""),"") -> 0.47928867 | BF15: =IFERROR(AVERAGE(AY15,AZ15,BA15,BB15,BC15),"n/m") -> 0.46745655 | BG15: =IFERROR(AVERAGE(AJ15,AM15,AP15,AS15,AV15),"n/m") -> 0.43278761 | BH15: =IFERROR(AVERAGE(U15,X15,AA15,AD15,AG15,AJ15,AM15,AP15,AS15,AV15),"n/m") -> 0.4666144 | BI15: =IFERROR(AVERAGE(C15,D15,E15,F15,G15,H15,I15,L15,O15,R15,U15,X15,AA15,AD15,AG15,AJ15,AM15,AP15,AS15,AV15),"n/m") -> 0.46715038 | BL15: 2026E operating investments (€m) | BN15: 1150
B17: Ready-to-wear and Accessories (men's & women's RTW, belts, fashion jewellery, gloves, hats, shoes) | BD17: READY-TO-WEAR AND ACCESSORIES — modelling logic
B18: Revenue | F18: 360 | G18: 445 | H18: 576 | I18: 745.6 | J18: 395.6 | K18: =L18-J18 -> 447.5 | L18: 843.1 | M18: 440.6 | N18: =O18-M18 -> 493 | O18: 933.6 | P18: 534.1 | Q18: =R18-P18 -> 566.5 | R18: 1100.6 | S18: 517.5 | T18: =U18-S18 -> 581.6 | U18: 1099.1 | V18: 579.2 | W18: =X18-V18 -> 601.9 | X18: 1181.1 | Y18: 637.3 | Z18: =AA18-Y18 -> 673.1 | AA18: 1310.4 | AB18: 754.6 | AC18: =AD18-AB18 -> 819.6 | AD18: 1574.2 | AE18: 537 | AF18: =AG18-AE18 -> 871.9 | AG18: 1408.9 | AH18: 1025.1 | AI18: =AJ18-AH18 -> 1193.9 | AJ18: 2219 | AK18: 1458 | AL18: =AM18-AK18 -> 1694 | AM18: 3152 | AN18: 1922 | AO18: =AP18-AN18 -> 1957 | AP18: 3879 | AQ18: 2162 | AR18: =AS18-AQ18 -> 2243 | AS18: 4405 | AT18: 2255 | AU18: =AV18-AT18 -> 2270 | AV18: 4525 | AW18: 2198 | AX18: =AU18*(1+AX20+AX64) -> 2292.7 | AY18: =AW18+AX18 -> 4490.7 | AZ18: =AY18*(1+AZ20+AZ64) -> 4760.142 | BA18: =AZ18*(1+BA20+BA64) -> 5045.7505 | BB18: =BA18*(1+BB20+BB64) -> 5348.4956 | BC18: =BB18*(1+BC20+BC64) -> 5642.6628 | BD18: H2/26E: H2/25 × (1 + scenario constant-currency growth + H2/26E currency effect). 2027E+: prior year × (1 + scenario cc growth + currency effect). | BF18: =IFERROR((BC18/AV18)^(1/5)-1,"n/m") -> 0.045136711 | BG18: =IFERROR((AV18/AG18)^(1/5)-1,"n/m") -> 0.26283812 | BH18: =IFERROR((AV18/R18)^(1/10)-1,"n/m") -> 0.15185791 | BI18: =IFERROR((AV18/C18)^(1/19)-1,"n/m") -> n/m | BL18: LEATHER_ccGrowth (Leather Goods & Saddlery revenue y/y, constant FX) | BM18: 0.02 | BN18: Δ → | BO18: -0.03 | BP18: H1/26 +9.8% (Q2 slightly above Q1); FY25 +13.1%, FY24 +18.3%. Capacity: 25th workshop (Loupes, 2026), three more by 2030.
B19: Revenue y/y % (reported) | D19: =IF(AND(ISNUMBER(D18),ISNUMBER(C18)),IFERROR(D18/C18-1,""),"") | E19: =IF(AND(ISNUMBER(E18),ISNUMBER(D18)),IFERROR(E18/D18-1,""),"") | F19: =IF(AND(ISNUMBER(F18),ISNUMBER(E18)),IFERROR(F18/E18-1,""),"") | G19: =IF(AND(ISNUMBER(G18),ISNUMBER(F18)),IFERROR(G18/F18-1,""),"") -> 0.23611111 | H19: =IF(AND(ISNUMBER(H18),ISNUMBER(G18)),IFERROR(H18/G18-1,""),"") -> 0.29438202 | I19: =IF(AND(ISNUMBER(I18),ISNUMBER(H18)),IFERROR(I18/H18-1,""),"") -> 0.29444444 | L19: =IF(AND(ISNUMBER(L18),ISNUMBER(I18)),IFERROR(L18/I18-1,""),"") -> 0.13076717 | M19: =IF(AND(ISNUMBER(M18),ISNUMBER(J18)),IFERROR(M18/J18-1,""),"") -> 0.11375126 | N19: =IF(AND(ISNUMBER(N18),ISNUMBER(K18)),IFERROR(N18/K18-1,""),"") -> 0.10167598 | O19: =IF(AND(ISNUMBER(O18),ISNUMBER(L18)),IFERROR(O18/L18-1,""),"") -> 0.10734195 | P19: =IF(AND(ISNUMBER(P18),ISNUMBER(M18)),IFERROR(P18/M18-1,""),"") -> 0.21221062 | Q19: =IF(AND(ISNUMBER(Q18),ISNUMBER(N18)),IFERROR(Q18/N18-1,""),"") -> 0.14908722 | R19: =IF(AND(ISNUMBER(R18),ISNUMBER(O18)),IFERROR(R18/O18-1,""),"") -> 0.17887746 | S19: =IF(AND(ISNUMBER(S18),ISNUMBER(P18)),IFERROR(S18/P18-1,""),"") -> -0.031080322 | ... AY19: =IF(AND(ISNUMBER(AY18),ISNUMBER(AV18)),IFERROR(AY18/AV18-1,""),"") -> -0.0075801105 | AZ19: =IF(AND(ISNUMBER(AZ18),ISNUMBER(AY18)),IFERROR(AZ18/AY18-1,""),"") -> 0.06 | BA19: =IF(AND(ISNUMBER(BA18),ISNUMBER(AZ18)),IFERROR(BA18/AZ18-1,""),"") -> 0.06 | BB19: =IF(AND(ISNUMBER(BB18),ISNUMBER(BA18)),IFERROR(BB18/BA18-1,""),"") -> 0.06 | BC19: =IF(AND(ISNUMBER(BC18),ISNUMBER(BB18)),IFERROR(BC18/BB18-1,""),"") -> 0.055 | BL19: H2/26E | BM19: =BN19+$BM$18 -> 0.11 | BN19: 0.09 | BO19: =BN19+$BO$18 -> 0.06
B20: Revenue y/y % at constant exchange rates (company) | G20: 0.175 | H20: 0.3 | I20: 0.223 | J20: 0.208 | L20: 0.179 | M20: 0.158 | O20: 0.12 | P20: 0.081 | R20: 0.078 | S20: -0.017 | U20: 0.002 | V20: 0.104 | X20: 0.094 | Y20: 0.167 | AA20: 0.141 | AB20: 0.152 | AD20: 0.171 | AE20: -0.293 | AG20: -0.092 | AH20: 0.98 | AJ20: 0.588 | AK20: 0.359 | AM20: 0.358 | AN20: 0.348 | AP20: 0.282 | AQ20: 0.155 | AS20: 0.154 | AT20: 0.055 | AV20: 0.061 | AW20: 0.02 | AX20: =CHOOSE(MATCH($BD$2,{"Bull","Base","Bear"},0),$BM$25,$BN$25,$BO$25) -> 0.04 | AY20: =(AT18*(1+AW20)+AU18*(1+AX20))/AV18-1 -> 0.030033149 | AZ20: =CHOOSE(MATCH($BD$2,{"Bull","Base","Bear"},0),$BM$26,$BN$26,$BO$26) -> 0.06 | BA20: =CHOOSE(MATCH($BD$2,{"Bull","Base","Bear"},0),$BM$27,$BN$27,$BO$27) -> 0.06 | BB20: =CHOOSE(MATCH($BD$2,{"Bull","Base","Bear"},0),$BM$28,$BN$28,$BO$28) -> 0.06 | BC20: =CHOOSE(MATCH($BD$2,{"Bull","Base","Bear"},0),$BM$29,$BN$29,$BO$29) -> 0.055 | BD20: Scenario lever (RTW_ccGrowth, Bull/Base/Bear table →). 2026E = H1/26 actual and H2/26E growth weighted by 2025 halves. Company figures to one decimal (press releases). | BF20: =IFERROR(AVERAGE(AY20,AZ20,BA20,BB20,BC20),"n/m") -> 0.05300663 | BG20: =IFERROR(AVERAGE(AJ20,AM20,AP20,AS20,AV20),"n/m") -> 0.2886 | BH20: =IFERROR(AVERAGE(U20,X20,AA20,AD20,AG20,AJ20,AM20,AP20,AS20,AV20),"n/m") -> 0.1759 | BI20: =IFERROR(AVERAGE(C20,D20,E20,F20,G20,H20,I20,L20,O20,R20,U20,X20,AA20,AD20,AG20,AJ20,AM20,AP20,AS20,AV20),"n/m") -> 0.177125 | BL20: 2027E | BM20: =BN20+$BM$18 -> 0.11 | BN20: 0.09 | BO20: =BN20+$BO$18 -> 0.06
B21: Currency (and scope) effect on growth, pts (reported − constant FX) | C21: =IF(AND(ISNUMBER(C19),ISNUMBER(C20)),C19-C20,"") | D21: =IF(AND(ISNUMBER(D19),ISNUMBER(D20)),D19-D20,"") | E21: =IF(AND(ISNUMBER(E19),ISNUMBER(E20)),E19-E20,"") | F21: =IF(AND(ISNUMBER(F19),ISNUMBER(F20)),F19-F20,"") | G21: =IF(AND(ISNUMBER(G19),ISNUMBER(G20)),G19-G20,"") -> 0.061111111 | H21: =IF(AND(ISNUMBER(H19),ISNUMBER(H20)),H19-H20,"") -> -0.0056179775 | I21: =IF(AND(ISNUMBER(I19),ISNUMBER(I20)),I19-I20,"") -> 0.071444444 | J21: =IF(AND(ISNUMBER(J19),ISNUMBER(J20)),J19-J20,"") | ... AW21: =IF(AND(ISNUMBER(AW19),ISNUMBER(AW20)),AW19-AW20,"") -> -0.045277162 | AX21: =AX64 -> -0.03 | AY21: =AY19-AY20 -> -0.03761326 | AZ21: =AZ64 -> 0 | BA21: =BA64 -> 0 | BB21: =BB64 -> 0 | BC21: =BC64 -> 0 | BL21: 2028E | BM21: =BN21+$BM$18 -> 0.11 | BN21: 0.09 | BO21: =BN21+$BO$18 -> 0.06
B22: % of group revenue | C22: =IF(AND(ISNUMBER(C18),ISNUMBER(C61)),IFERROR(C18/C61,""),"") | D22: =IF(AND(ISNUMBER(D18),ISNUMBER(D61)),IFERROR(D18/D61,""),"") | E22: =IF(AND(ISNUMBER(E18),ISNUMBER(E61)),IFERROR(E18/E61,""),"") | F22: =IF(AND(ISNUMBER(F18),ISNUMBER(F61)),IFERROR(F18/F61,""),"") -> 0.18808777 | G22: =IF(AND(ISNUMBER(G18),ISNUMBER(G61)),IFERROR(G18/G61,""),"") -> 0.18526228 | H22: =IF(AND(ISNUMBER(H18),ISNUMBER(H61)),IFERROR(H18/H61,""),"") -> 0.20267417 | I22: =IF(AND(ISNUMBER(I18),ISNUMBER(I61)),IFERROR(I18/I61,""),"") -> 0.2139946 | J22: =IF(AND(ISNUMBER(J18),ISNUMBER(J61)),IFERROR(J18/J61,""),"") -> 0.22386962 | ... BC22: =IF(AND(ISNUMBER(BC18),ISNUMBER(BC61)),IFERROR(BC18/BC61,""),"") -> 0.26030905 | BF22: =IFERROR(AVERAGE(AY22,AZ22,BA22,BB22,BC22),"n/m") -> 0.26675409 | BG22: =IFERROR(AVERAGE(AJ22,AM22,AP22,AS22,AV22),"n/m") -> 0.27616879 | BH22: =IFERROR(AVERAGE(U22,X22,AA22,AD22,AG22,AJ22,AM22,AP22,AS22,AV22),"n/m") -> 0.24738038 | BI22: =IFERROR(AVERAGE(C22,D22,E22,F22,G22,H22,I22,L22,O22,R22,U22,X22,AA22,AD22,AG22,AJ22,AM22,AP22,AS22,AV22),"n/m") -> 0.2319047 | BL22: 2029E | BM22: =BN22+$BM$18 -> 0.105 | BN22: 0.085 | BO22: =BN22+$BO$18 -> 0.055
BL23: 2030E | BM23: =BN23+$BM$18 -> 0.1 | BN23: 0.08 | BO23: =BN23+$BO$18 -> 0.05
B24: Silk and Textiles | BD24: SILK AND TEXTILES — modelling logic | BL24: RTW_ccGrowth (Ready-to-wear and Accessories revenue y/y, constant FX) | BM24: 0.02 | BN24: Δ → | BO24: -0.03 | BP24: H1/26 +2.0% with a Q2 acceleration (women's AW26 collection); FY25 +6.1%, FY24 +15.4%.
B25: Revenue | F25: 227 | G25: 284 | H25: 347 | I25: 424.6 | J25: 201.7 | K25: =L25-J25 -> 252.2 | L25: 453.9 | M25: 216 | N25: =O25-M25 -> 266.3 | O25: 482.3 | P25: 250.6 | Q25: =R25-P25 -> 270.6 | R25: 521.2 | S25: 230.3 | T25: =U25-S25 -> 285 | U25: 515.3 | V25: 246.3 | W25: =X25-V25 -> 288 | X25: 534.3 | Y25: 249.4 | Z25: =AA25-Y25 -> 287.5 | AA25: 536.9 | AB25: 266.6 | AC25: =AD25-AB25 -> 325.9 | AD25: 592.5 | AE25: 165.2 | AF25: =AG25-AE25 -> 286.8 | AG25: 452 | AH25: 273.9 | AI25: =AJ25-AH25 -> 395.1 | AJ25: 669 | AK25: 372 | AL25: =AM25-AK25 -> 470 | AM25: 842 | AN25: 444 | AO25: =AP25-AN25 -> 488 | AP25: 932 | AQ25: 436 | AR25: =AS25-AQ25 -> 514 | AS25: 950 | AT25: 447 | AU25: =AV25-AT25 -> 517 | AV25: 964 | AW25: 469 | AX25: =AU25*(1+AX27+AX64) -> 542.85 | AY25: =AW25+AX25 -> 1011.85 | AZ25: =AY25*(1+AZ27+AZ64) -> 1072.561 | BA25: =AZ25*(1+BA27+BA64) -> 1136.9147 | BB25: =BA25*(1+BB27+BB64) -> 1199.445 | BC25: =BB25*(1+BC27+BC64) -> 1259.4172 | BD25: H2/26E: H2/25 × (1 + scenario constant-currency growth + H2/26E currency effect). 2027E+: prior year × (1 + scenario cc growth + currency effect). | BF25: =IFERROR((BC25/AV25)^(1/5)-1,"n/m") -> 0.054917552 | BG25: =IFERROR((AV25/AG25)^(1/5)-1,"n/m") -> 0.16355715 | BH25: =IFERROR((AV25/R25)^(1/10)-1,"n/m") -> 0.063425972 | BI25: =IFERROR((AV25/C25)^(1/19)-1,"n/m") -> n/m | BL25: H2/26E | BM25: =BN25+$BM$24 -> 0.06 | BN25: 0.04 | BO25: =BN25+$BO$24 -> 0.01
B26: Revenue y/y % (reported) | D26: =IF(AND(ISNUMBER(D25),ISNUMBER(C25)),IFERROR(D25/C25-1,""),"") | E26: =IF(AND(ISNUMBER(E25),ISNUMBER(D25)),IFERROR(E25/D25-1,""),"") | F26: =IF(AND(ISNUMBER(F25),ISNUMBER(E25)),IFERROR(F25/E25-1,""),"") | G26: =IF(AND(ISNUMBER(G25),ISNUMBER(F25)),IFERROR(G25/F25-1,""),"") -> 0.25110132 | H26: =IF(AND(ISNUMBER(H25),ISNUMBER(G25)),IFERROR(H25/G25-1,""),"") -> 0.22183099 | I26: =IF(AND(ISNUMBER(I25),ISNUMBER(H25)),IFERROR(I25/H25-1,""),"") -> 0.22363112 | L26: =IF(AND(ISNUMBER(L25),ISNUMBER(I25)),IFERROR(L25/I25-1,""),"") -> 0.069006123 | M26: =IF(AND(ISNUMBER(M25),ISNUMBER(J25)),IFERROR(M25/J25-1,""),"") -> 0.070897372 | N26: =IF(AND(ISNUMBER(N25),ISNUMBER(K25)),IFERROR(N25/K25-1,""),"") -> 0.05590801 | O26: =IF(AND(ISNUMBER(O25),ISNUMBER(L25)),IFERROR(O25/L25-1,""),"") -> 0.062568848 | P26: =IF(AND(ISNUMBER(P25),ISNUMBER(M25)),IFERROR(P25/M25-1,""),"") -> 0.16018519 | Q26: =IF(AND(ISNUMBER(Q25),ISNUMBER(N25)),IFERROR(Q25/N25-1,""),"") -> 0.016147202 | R26: =IF(AND(ISNUMBER(R25),ISNUMBER(O25)),IFERROR(R25/O25-1,""),"") -> 0.080655194 | S26: =IF(AND(ISNUMBER(S25),ISNUMBER(P25)),IFERROR(S25/P25-1,""),"") -> -0.081005587 | ... AY26: =IF(AND(ISNUMBER(AY25),ISNUMBER(AV25)),IFERROR(AY25/AV25-1,""),"") -> 0.049636929 | AZ26: =IF(AND(ISNUMBER(AZ25),ISNUMBER(AY25)),IFERROR(AZ25/AY25-1,""),"") -> 0.06 | BA26: =IF(AND(ISNUMBER(BA25),ISNUMBER(AZ25)),IFERROR(BA25/AZ25-1,""),"") -> 0.06 | BB26: =IF(AND(ISNUMBER(BB25),ISNUMBER(BA25)),IFERROR(BB25/BA25-1,""),"") -> 0.055 | BC26: =IF(AND(ISNUMBER(BC25),ISNUMBER(BB25)),IFERROR(BC25/BB25-1,""),"") -> 0.05 | BL26: 2027E | BM26: =BN26+$BM$24 -> 0.08 | BN26: 0.06 | BO26: =BN26+$BO$24 -> 0.03
B27: Revenue y/y % at constant exchange rates (company) | G27: 0.189 | H27: 0.226 | I27: 0.159 | J27: 0.129 | L27: 0.115 | M27: 0.113 | O27: 0.076 | P27: 0.046 | R27: -0.005 | S27: -0.069 | U27: -0.008 | V27: 0.058 | X27: 0.057 | Y27: 0.071 | AA27: 0.032 | AB27: 0.04 | AD27: 0.075 | AE27: -0.385 | AG27: -0.228 | AH27: 0.719 | AJ27: 0.491 | AK27: 0.29 | AM27: 0.203 | AN27: 0.224 | AP27: 0.156 | AQ27: 0.015 | AS27: 0.038 | AT27: 0.035 | AV27: 0.047 | AW27: 0.097 | AX27: =CHOOSE(MATCH($BD$2,{"Bull","Base","Bear"},0),$BM$31,$BN$31,$BO$31) -> 0.08 | AY27: =(AT25*(1+AW27)+AU25*(1+AX27))/AV25-1 -> 0.08788278 | AZ27: =CHOOSE(MATCH($BD$2,{"Bull","Base","Bear"},0),$BM$32,$BN$32,$BO$32) -> 0.06 | BA27: =CHOOSE(MATCH($BD$2,{"Bull","Base","Bear"},0),$BM$33,$BN$33,$BO$33) -> 0.06 | BB27: =CHOOSE(MATCH($BD$2,{"Bull","Base","Bear"},0),$BM$34,$BN$34,$BO$34) -> 0.055 | BC27: =CHOOSE(MATCH($BD$2,{"Bull","Base","Bear"},0),$BM$35,$BN$35,$BO$35) -> 0.05 | BD27: Scenario lever (SILK_ccGrowth, Bull/Base/Bear table →). 2026E = H1/26 actual and H2/26E growth weighted by 2025 halves. Company figures to one decimal (press releases). | BF27: =IFERROR(AVERAGE(AY27,AZ27,BA27,BB27,BC27),"n/m") -> 0.062576556 | BG27: =IFERROR(AVERAGE(AJ27,AM27,AP27,AS27,AV27),"n/m") -> 0.187 | BH27: =IFERROR(AVERAGE(U27,X27,AA27,AD27,AG27,AJ27,AM27,AP27,AS27,AV27),"n/m") -> 0.0863 | BI27: =IFERROR(AVERAGE(C27,D27,E27,F27,G27,H27,I27,L27,O27,R27,U27,X27,AA27,AD27,AG27,AJ27,AM27,AP27,AS27,AV27),"n/m") -> 0.1014375 | BL27: 2028E | BM27: =BN27+$BM$24 -> 0.08 | BN27: 0.06 | BO27: =BN27+$BO$24 -> 0.03
B28: Currency (and scope) effect on growth, pts (reported − constant FX) | C28: =IF(AND(ISNUMBER(C26),ISNUMBER(C27)),C26-C27,"") | D28: =IF(AND(ISNUMBER(D26),ISNUMBER(D27)),D26-D27,"") | E28: =IF(AND(ISNUMBER(E26),ISNUMBER(E27)),E26-E27,"") | F28: =IF(AND(ISNUMBER(F26),ISNUMBER(F27)),F26-F27,"") | G28: =IF(AND(ISNUMBER(G26),ISNUMBER(G27)),G26-G27,"") -> 0.062101322 | H28: =IF(AND(ISNUMBER(H26),ISNUMBER(H27)),H26-H27,"") -> -0.0041690141 | I28: =IF(AND(ISNUMBER(I26),ISNUMBER(I27)),I26-I27,"") -> 0.064631124 | J28: =IF(AND(ISNUMBER(J26),ISNUMBER(J27)),J26-J27,"") | ... AW28: =IF(AND(ISNUMBER(AW26),ISNUMBER(AW27)),AW26-AW27,"") -> -0.047782998 | AX28: =AX64 -> -0.03 | AY28: =AY26-AY27 -> -0.038245851 | AZ28: =AZ64 -> 0 | BA28: =BA64 -> 0 | BB28: =BB64 -> 0 | BC28: =BC64 -> 0 | BL28: 2029E | BM28: =BN28+$BM$24 -> 0.08 | BN28: 0.06 | BO28: =BN28+$BO$24 -> 0.03
B29: % of group revenue | C29: =IF(AND(ISNUMBER(C25),ISNUMBER(C61)),IFERROR(C25/C61,""),"") | D29: =IF(AND(ISNUMBER(D25),ISNUMBER(D61)),IFERROR(D25/D61,""),"") | E29: =IF(AND(ISNUMBER(E25),ISNUMBER(E61)),IFERROR(E25/E61,""),"") | F29: =IF(AND(ISNUMBER(F25),ISNUMBER(F61)),IFERROR(F25/F61,""),"") -> 0.11859979 | G29: =IF(AND(ISNUMBER(G25),ISNUMBER(G61)),IFERROR(G25/G61,""),"") -> 0.1182348 | H29: =IF(AND(ISNUMBER(H25),ISNUMBER(H61)),IFERROR(H25/H61,""),"") -> 0.12209711 | I29: =IF(AND(ISNUMBER(I25),ISNUMBER(I61)),IFERROR(I25/I61,""),"") -> 0.12186442 | J29: =IF(AND(ISNUMBER(J25),ISNUMBER(J61)),IFERROR(J25/J61,""),"") -> 0.11414181 | ... BC29: =IF(AND(ISNUMBER(BC25),ISNUMBER(BC61)),IFERROR(BC25/BC61,""),"") -> 0.05809982 | BF29: =IFERROR(AVERAGE(AY29,AZ29,BA29,BB29,BC29),"n/m") -> 0.059938706 | BG29: =IFERROR(AVERAGE(AJ29,AM29,AP29,AS29,AV29),"n/m") -> 0.067870551 | BH29: =IFERROR(AVERAGE(U29,X29,AA29,AD29,AG29,AJ29,AM29,AP29,AS29,AV29),"n/m") -> 0.078150238 | BI29: =IFERROR(AVERAGE(C29,D29,E29,F29,G29,H29,I29,L29,O29,R29,U29,X29,AA29,AD29,AG29,AJ29,AM29,AP29,AS29,AV29),"n/m") -> 0.094584996 | BL29: 2030E | BM29: =BN29+$BM$24 -> 0.075 | BN29: 0.055 | BO29: =BN29+$BO$24 -> 0.025
BL30: SILK_ccGrowth (Silk and Textiles revenue y/y, constant FX) | BM30: 0.02 | BN30: Δ → | BO30: -0.03 | BP30: H1/26 +9.7% (acceleration in Q2); FY25 +4.7%, FY24 +3.8%.
B31: Other Hermès sectors (Jewellery, Home / Art of Living & Tableware — Tableware folded in from 2014) | BD31: OTHER HERMÈS SECTORS — modelling logic | BL31: H2/26E | BM31: =BN31+$BM$30 -> 0.1 | BN31: 0.08 | BO31: =BN31+$BO$30 -> 0.05
B32: Revenue | F32: 116 | G32: 131 | H32: 160 | I32: 225.7 | J32: 123.6 | K32: =L32-J32 -> 154 | L32: 277.6 | M32: 124.5 | N32: =O32-M32 -> 156.4 | O32: 280.9 | P32: 154.9 | Q32: =R32-P32 -> 177 | R32: 331.9 | S32: 150.6 | T32: =U32-S32 -> 185.4 | U32: 336 | V32: 172.3 | W32: =X32-V32 -> 192.7 | X32: 365 | Y32: 201.7 | Z32: =AA32-Y32 -> 223 | AA32: 424.7 | AB32: 247.6 | AC32: =AD32-AB32 -> 277.3 | AD32: 524.9 | AE32: 239.2 | AF32: =AG32-AE32 -> 403.4 | AG32: 642.6 | AH32: 462.3 | AI32: =AJ32-AH32 -> 538.7 | AJ32: 1001 | AK32: 648 | AL32: =AM32-AK32 -> 723 | AM32: 1371 | AN32: 836 | AO32: =AP32-AN32 -> 817 | AP32: 1653 | AQ32: 967 | AR32: =AS32-AQ32 -> 942 | AS32: 1909 | AT32: 1056 | AU32: =AV32-AT32 -> 999 | AV32: 2055 | AW32: 1065 | AX32: =AU32*(1+AX34+AX64) -> 1028.97 | AY32: =AW32+AX32 -> 2093.97 | AZ32: =AY32*(1+AZ34+AZ64) -> 2261.4876 | BA32: =AZ32*(1+BA34+BA64) -> 2442.4066 | BB32: =BA32*(1+BB34+BB64) -> 2625.5871 | BC32: =BB32*(1+BC34+BC64) -> 2809.3782 | BD32: H2/26E: H2/25 × (1 + scenario constant-currency growth + H2/26E currency effect). 2027E+: prior year × (1 + scenario cc growth + currency effect). | BF32: =IFERROR((BC32/AV32)^(1/5)-1,"n/m") -> 0.064534342 | BG32: =IFERROR((AV32/AG32)^(1/5)-1,"n/m") -> 0.26175264 | BH32: =IFERROR((AV32/R32)^(1/10)-1,"n/m") -> 0.19999782 | BI32: =IFERROR((AV32/C32)^(1/19)-1,"n/m") -> n/m | BL32: 2027E | BM32: =BN32+$BM$30 -> 0.08 | BN32: 0.06 | BO32: =BN32+$BO$30 -> 0.03
B33: Revenue y/y % (reported) | D33: =IF(AND(ISNUMBER(D32),ISNUMBER(C32)),IFERROR(D32/C32-1,""),"") | E33: =IF(AND(ISNUMBER(E32),ISNUMBER(D32)),IFERROR(E32/D32-1,""),"") | F33: =IF(AND(ISNUMBER(F32),ISNUMBER(E32)),IFERROR(F32/E32-1,""),"") | G33: =IF(AND(ISNUMBER(G32),ISNUMBER(F32)),IFERROR(G32/F32-1,""),"") -> 0.12931034 | H33: =IF(AND(ISNUMBER(H32),ISNUMBER(G32)),IFERROR(H32/G32-1,""),"") -> 0.22137405 | I33: =IF(AND(ISNUMBER(I32),ISNUMBER(H32)),IFERROR(I32/H32-1,""),"") -> 0.410625 | L33: =IF(AND(ISNUMBER(L32),ISNUMBER(I32)),IFERROR(L32/I32-1,""),"") -> 0.22995126 | M33: =IF(AND(ISNUMBER(M32),ISNUMBER(J32)),IFERROR(M32/J32-1,""),"") -> 0.0072815534 | N33: =IF(AND(ISNUMBER(N32),ISNUMBER(K32)),IFERROR(N32/K32-1,""),"") -> 0.015584416 | O33: =IF(AND(ISNUMBER(O32),ISNUMBER(L32)),IFERROR(O32/L32-1,""),"") -> 0.011887608 | P33: =IF(AND(ISNUMBER(P32),ISNUMBER(M32)),IFERROR(P32/M32-1,""),"") -> 0.24417671 | Q33: =IF(AND(ISNUMBER(Q32),ISNUMBER(N32)),IFERROR(Q32/N32-1,""),"") -> 0.13171355 | R33: =IF(AND(ISNUMBER(R32),ISNUMBER(O32)),IFERROR(R32/O32-1,""),"") -> 0.18155927 | S33: =IF(AND(ISNUMBER(S32),ISNUMBER(P32)),IFERROR(S32/P32-1,""),"") -> -0.027759845 | ... AY33: =IF(AND(ISNUMBER(AY32),ISNUMBER(AV32)),IFERROR(AY32/AV32-1,""),"") -> 0.018963504 | AZ33: =IF(AND(ISNUMBER(AZ32),ISNUMBER(AY32)),IFERROR(AZ32/AY32-1,""),"") -> 0.08 | BA33: =IF(AND(ISNUMBER(BA32),ISNUMBER(AZ32)),IFERROR(BA32/AZ32-1,""),"") -> 0.08 | BB33: =IF(AND(ISNUMBER(BB32),ISNUMBER(BA32)),IFERROR(BB32/BA32-1,""),"") -> 0.075 | BC33: =IF(AND(ISNUMBER(BC32),ISNUMBER(BB32)),IFERROR(BC32/BB32-1,""),"") -> 0.07 | BL33: 2028E | BM33: =BN33+$BM$30 -> 0.08 | BN33: 0.06 | BO33: =BN33+$BO$30 -> 0.03
B34: Revenue y/y % at constant exchange rates (company) | G34: 0.075228359 | H34: 0.22459347 | I34: 0.35708799 | J34: 0.29684595 | L34: 0.27834669 | M34: 0.18 | O34: 0.151 | P34: 0.118 | R34: 0.085 | S34: -0.015 | U34: 0.016 | V34: 0.13 | X34: 0.105 | Y34: 0.241 | AA34: 0.196 | AB34: 0.194 | AD34: 0.204 | AE34: -0.042 | AG34: 0.239 | AH34: 1.004 | AJ34: 0.567 | AK34: 0.325 | AM34: 0.296 | AN34: 0.321 | AP34: 0.258 | AQ34: 0.187 | AS34: 0.171 | AT34: 0.103 | AV34: 0.112 | AW34: 0.054 | AX34: =CHOOSE(MATCH($BD$2,{"Bull","Base","Bear"},0),$BM$37,$BN$37,$BO$37) -> 0.06 | AY34: =(AT32*(1+AW34)+AU32*(1+AX34))/AV32-1 -> 0.056916788 | AZ34: =CHOOSE(MATCH($BD$2,{"Bull","Base","Bear"},0),$BM$38,$BN$38,$BO$38) -> 0.08 | BA34: =CHOOSE(MATCH($BD$2,{"Bull","Base","Bear"},0),$BM$39,$BN$39,$BO$39) -> 0.08 | BB34: =CHOOSE(MATCH($BD$2,{"Bull","Base","Bear"},0),$BM$40,$BN$40,$BO$40) -> 0.075 | BC34: =CHOOSE(MATCH($BD$2,{"Bull","Base","Bear"},0),$BM$41,$BN$41,$BO$41) -> 0.07 | BD34: Scenario lever (OTHER_HERMES_ccGrowth, Bull/Base/Bear table →). 2026E = H1/26 actual and H2/26E growth weighted by 2025 halves. Company figures to one decimal (press releases). | BF34: =IFERROR(AVERAGE(AY34,AZ34,BA34,BB34,BC34),"n/m") -> 0.072383358 | BG34: =IFERROR(AVERAGE(AJ34,AM34,AP34,AS34,AV34),"n/m") -> 0.2808 | BH34: =IFERROR(AVERAGE(U34,X34,AA34,AD34,AG34,AJ34,AM34,AP34,AS34,AV34),"n/m") -> 0.2164 | BI34: =IFERROR(AVERAGE(C34,D34,E34,F34,G34,H34,I34,L34,O34,R34,U34,X34,AA34,AD34,AG34,AJ34,AM34,AP34,AS34,AV34),"n/m") -> 0.20845353 | BL34: 2029E | BM34: =BN34+$BM$30 -> 0.075 | BN34: 0.055 | BO34: =BN34+$BO$30 -> 0.025
B35: Currency (and scope) effect on growth, pts (reported − constant FX) | C35: =IF(AND(ISNUMBER(C33),ISNUMBER(C34)),C33-C34,"") | D35: =IF(AND(ISNUMBER(D33),ISNUMBER(D34)),D33-D34,"") | E35: =IF(AND(ISNUMBER(E33),ISNUMBER(E34)),E33-E34,"") | F35: =IF(AND(ISNUMBER(F33),ISNUMBER(F34)),F33-F34,"") | G35: =IF(AND(ISNUMBER(G33),ISNUMBER(G34)),G33-G34,"") -> 0.054081986 | H35: =IF(AND(ISNUMBER(H33),ISNUMBER(H34)),H33-H34,"") -> -0.0032194223 | I35: =IF(AND(ISNUMBER(I33),ISNUMBER(I34)),I33-I34,"") -> 0.05353701 | J35: =IF(AND(ISNUMBER(J33),ISNUMBER(J34)),J33-J34,"") | ... AW35: =IF(AND(ISNUMBER(AW33),ISNUMBER(AW34)),AW33-AW34,"") -> -0.045477273 | AX35: =AX64 -> -0.03 | AY35: =AY33-AY34 -> -0.037953285 | AZ35: =AZ64 -> 0 | BA35: =BA64 -> 0 | BB35: =BB64 -> 0 | BC35: =BC64 -> 0 | BD35: 2014: Other Hermès sectors scope restated by the company (Tableware folded in, comparatives restated), so reported y/y vs 2013 as originally published is not like-for-like. | BL35: 2030E | BM35: =BN35+$BM$30 -> 0.07 | BN35: 0.05 | BO35: =BN35+$BO$30 -> 0.02
B36: % of group revenue | C36: =IF(AND(ISNUMBER(C32),ISNUMBER(C61)),IFERROR(C32/C61,""),"") | D36: =IF(AND(ISNUMBER(D32),ISNUMBER(D61)),IFERROR(D32/D61,""),"") | E36: =IF(AND(ISNUMBER(E32),ISNUMBER(E61)),IFERROR(E32/E61,""),"") | F36: =IF(AND(ISNUMBER(F32),ISNUMBER(F61)),IFERROR(F32/F61,""),"") -> 0.060606061 | G36: =IF(AND(ISNUMBER(G32),ISNUMBER(G61)),IFERROR(G32/G61,""),"") -> 0.054537885 | H36: =IF(AND(ISNUMBER(H32),ISNUMBER(H61)),IFERROR(H32/H61,""),"") -> 0.056298381 | I36: =IF(AND(ISNUMBER(I32),ISNUMBER(I61)),IFERROR(I32/I61,""),"") -> 0.064778141 | J36: =IF(AND(ISNUMBER(J32),ISNUMBER(J61)),IFERROR(J32/J61,""),"") -> 0.069945108 | ... BC36: =IF(AND(ISNUMBER(BC32),ISNUMBER(BC61)),IFERROR(BC32/BC61,""),"") -> 0.12960309 | BF36: =IFERROR(AVERAGE(AY36,AZ36,BA36,BB36,BC36),"n/m") -> 0.12874724 | BG36: =IFERROR(AVERAGE(AJ36,AM36,AP36,AS36,AV36),"n/m") -> 0.12140342 | BH36: =IFERROR(AVERAGE(U36,X36,AA36,AD36,AG36,AJ36,AM36,AP36,AS36,AV36),"n/m") -> 0.098539428 | BI36: =IFERROR(AVERAGE(C36,D36,E36,F36,G36,H36,I36,L36,O36,R36,U36,X36,AA36,AD36,AG36,AJ36,AM36,AP36,AS36,AV36),"n/m") -> 0.084253318 | BL36: OTHER_HERMES_ccGrowth (Other Hermès sectors revenue y/y, constant FX) | BM36: 0.02 | BN36: Δ → | BO36: -0.03 | BP36: Jewellery and Home: H1/26 +5.4%; FY25 +11.2%, FY24 +17.1%.
B37: Memo: Tableware (separate métier to 2013, as originally reported) | F37: 38 | G37: 44 | H37: 51 | I37: 60.5 | J37: 28.9 | K37: =L37-J37 -> 32.3 | L37: 61.2 | BL37: H2/26E | BM37: =BN37+$BM$36 -> 0.08 | BN37: 0.06 | BO37: =BN37+$BO$36 -> 0.03
BL38: 2027E | BM38: =BN38+$BM$36 -> 0.1 | BN38: 0.08 | BO38: =BN38+$BO$36 -> 0.05
B39: Perfume and Beauty (Perfumes to 2019; Beauty from 2020) | BD39: PERFUME AND BEAUTY — modelling logic | BL39: 2028E | BM39: =BN39+$BM$36 -> 0.1 | BN39: 0.08 | BO39: =BN39+$BO$36 -> 0.05
B40: Revenue | F40: 117 | G40: 138 | H40: 159 | I40: 184.1 | J40: 106.7 | K40: =L40-J40 -> 103 | L40: 209.7 | M40: 114.6 | N40: =O40-M40 -> 116.2 | O40: 230.8 | P40: 120.3 | Q40: =R40-P40 -> 121.1 | R40: 241.4 | S40: 124.6 | T40: =U40-S40 -> 137.3 | U40: 261.9 | V40: 134.4 | W40: =X40-V40 -> 153.1 | X40: 287.5 | Y40: 153.2 | Z40: =AA40-Y40 -> 158.5 | AA40: 311.7 | AB40: 158.7 | AC40: =AD40-AB40 -> 167.2 | AD40: 325.9 | AE40: 112.9 | AF40: =AG40-AE40 -> 150.3 | AG40: 263.2 | AH40: 184.1 | AI40: =AJ40-AH40 -> 200.9 | AJ40: 385 | AK40: 230 | AL40: =AM40-AK40 -> 218 | AM40: 448 | AN40: 249 | AO40: =AP40-AN40 -> 243 | AP40: 492 | AQ40: 259 | AR40: =AS40-AQ40 -> 276 | AS40: 535 | AT40: 248 | AU40: =AV40-AT40 -> 241 | AV40: 489 | AW40: 233 | AX40: =AU40*(1+AX42+AX64) -> 228.95 | AY40: =AW40+AX40 -> 461.95 | AZ40: =AY40*(1+AZ42+AZ64) -> 471.189 | BA40: =AZ40*(1+BA42+BA64) -> 485.32467 | BB40: =BA40*(1+BB42+BB64) -> 499.88441 | BC40: =BB40*(1+BC42+BC64) -> 514.88094 | BD40: H2/26E: H2/25 × (1 + scenario constant-currency growth + H2/26E currency effect). 2027E+: prior year × (1 + scenario cc growth + currency effect). | BF40: =IFERROR((BC40/AV40)^(1/5)-1,"n/m") -> 0.01036802 | BG40: =IFERROR((AV40/AG40)^(1/5)-1,"n/m") -> 0.13189097 | BH40: =IFERROR((AV40/R40)^(1/10)-1,"n/m") -> 0.073141918 | BI40: =IFERROR((AV40/C40)^(1/19)-1,"n/m") -> n/m | BL40: 2029E | BM40: =BN40+$BM$36 -> 0.095 | BN40: 0.075 | BO40: =BN40+$BO$36 -> 0.045
B41: Revenue y/y % (reported) | D41: =IF(AND(ISNUMBER(D40),ISNUMBER(C40)),IFERROR(D40/C40-1,""),"") | E41: =IF(AND(ISNUMBER(E40),ISNUMBER(D40)),IFERROR(E40/D40-1,""),"") | F41: =IF(AND(ISNUMBER(F40),ISNUMBER(E40)),IFERROR(F40/E40-1,""),"") | G41: =IF(AND(ISNUMBER(G40),ISNUMBER(F40)),IFERROR(G40/F40-1,""),"") -> 0.17948718 | H41: =IF(AND(ISNUMBER(H40),ISNUMBER(G40)),IFERROR(H40/G40-1,""),"") -> 0.15217391 | I41: =IF(AND(ISNUMBER(I40),ISNUMBER(H40)),IFERROR(I40/H40-1,""),"") -> 0.15786164 | L41: =IF(AND(ISNUMBER(L40),ISNUMBER(I40)),IFERROR(L40/I40-1,""),"") -> 0.13905486 | M41: =IF(AND(ISNUMBER(M40),ISNUMBER(J40)),IFERROR(M40/J40-1,""),"") -> 0.074039363 | N41: =IF(AND(ISNUMBER(N40),ISNUMBER(K40)),IFERROR(N40/K40-1,""),"") -> 0.12815534 | O41: =IF(AND(ISNUMBER(O40),ISNUMBER(L40)),IFERROR(O40/L40-1,""),"") -> 0.10061993 | P41: =IF(AND(ISNUMBER(P40),ISNUMBER(M40)),IFERROR(P40/M40-1,""),"") -> 0.04973822 | Q41: =IF(AND(ISNUMBER(Q40),ISNUMBER(N40)),IFERROR(Q40/N40-1,""),"") -> 0.042168675 | R41: =IF(AND(ISNUMBER(R40),ISNUMBER(O40)),IFERROR(R40/O40-1,""),"") -> 0.04592721 | S41: =IF(AND(ISNUMBER(S40),ISNUMBER(P40)),IFERROR(S40/P40-1,""),"") -> 0.035743973 | ... AY41: =IF(AND(ISNUMBER(AY40),ISNUMBER(AV40)),IFERROR(AY40/AV40-1,""),"") -> -0.055316973 | AZ41: =IF(AND(ISNUMBER(AZ40),ISNUMBER(AY40)),IFERROR(AZ40/AY40-1,""),"") -> 0.02 | BA41: =IF(AND(ISNUMBER(BA40),ISNUMBER(AZ40)),IFERROR(BA40/AZ40-1,""),"") -> 0.03 | BB41: =IF(AND(ISNUMBER(BB40),ISNUMBER(BA40)),IFERROR(BB40/BA40-1,""),"") -> 0.03 | BC41: =IF(AND(ISNUMBER(BC40),ISNUMBER(BB40)),IFERROR(BC40/BB40-1,""),"") -> 0.03 | BL41: 2030E | BM41: =BN41+$BM$36 -> 0.09 | BN41: 0.07 | BO41: =BN41+$BO$36 -> 0.04
...

Sheet Bull-Base-Bear
B2: Hermès International (RMS) — Bull / Base / Bear Case P&L Summary | J2: Share price (€): | K2: =Model!$AY$379 -> 1299.5
B3: Adjusted figures (Hermès APMs: recurring operating income, adjusted free cash flow, restated net cash; recurring net income / EPS and EBITDA = model bridges) · EUR millions · Live panel linked to Model — toggle scenario via Model!BD2. Bull and Bear panels are value snapshots generated from the Model with the switch set to each case. | J3: As of: | K3: =TODAY() -> 46299
B5: Scenario: | C5: =Model!$BD$2 -> Base | N5: Scenario: | O5: Bull | P5: Snapshot (values) — Model run with switch = Bull | Z5: Scenario: | AA5: Bear | AB5: Snapshot (values) — Model run with switch = Bear
B7: (EURm, except EPS and shares) | C7: 2025A | D7: 2026E | E7: 2027E | F7: 2028E | G7: 2029E | H7: 2030E | I7: 25-'30 CAGR | J7: LT Hist Avg | K7: LT Hist Min | L7: LT Hist Max | N7: (EURm, except EPS and shares) | O7: 2025A | P7: 2026E | Q7: 2027E | R7: 2028E | S7: 2029E | T7: 2030E | U7: 25-'30 CAGR | V7: LT Hist Avg | W7: LT Hist Min | X7: LT Hist Max | Z7: (EURm, except EPS and shares) | AA7: 2025A | AB7: 2026E | AC7: 2027E | AD7: 2028E | AE7: 2029E | AF7: 2030E | AG7: 25-'30 CAGR | AH7: LT Hist Avg | AI7: LT Hist Min | AJ7: LT Hist Max
B9: Revenue | C9: =Model!AV119 -> 16002 | D9: =Model!AY119 -> 16406.99 | E9: =Model!AZ119 -> 17626.336 | F9: =Model!BA119 -> 18946.137 | G9: =Model!BB119 -> 20307.483 | H9: =Model!BC119 -> 21676.783 | I9: =IFERROR((H9/C9)^(1/5)-1,"n/m") -> 0.062586059 | N9: Revenue | O9: 16002 | P9: 16646.03 | Q9: 18215.903 | R9: 19943.909 | S9: 21775.495 | T9: 23678.874 | U9: 0.081526977 | Z9: Revenue | AA9: 16002 | AB9: 16008.59 | AC9: 16718.335 | AD9: 17468.995 | AE9: 18200.61 | AF9: 18882.399 | AG9: 0.033657309
B10: Revenue y/y % | D10: =IFERROR(D9/C9-1,"") -> 0.025308711 | E10: =IFERROR(E9/D9-1,"") -> 0.074318714 | F10: =IFERROR(F9/E9-1,"") -> 0.074876647 | G10: =IFERROR(G9/F9-1,"") -> 0.071853461 | H10: =IFERROR(H9/G9-1,"") -> 0.067428365 | N10: Revenue y/y % | P10: 0.040246844 | Q10: 0.094309178 | R10: 0.094862444 | S10: 0.091836889 | T10: 0.087409224 | Z10: Revenue y/y % | AB10: 0.00041182352 | AC10: 0.044335241 | AD10: 0.04490044 | AE10: 0.041880774 | AF10: 0.03745965
B11: Revenue y/y % at constant exchange rates | C11: =Model!AV197 -> 0.089 | D11: =Model!AY197 -> 0.062825011 | E11: =Model!AZ197 -> 0.074318714 | F11: =Model!BA197 -> 0.074876647 | G11: =Model!BB197 -> 0.071853461 | H11: =Model!BC197 -> 0.067428365 | N11: Revenue y/y % at constant exchange rates | O11: 0.089 | P11: 0.072784388 | Q11: 0.094309178 | R11: 0.094862444 | S11: 0.091836889 | T11: 0.087409224 | Z11: Revenue y/y % at constant exchange rates | AA11: 0.089 | AB11: 0.047885945 | AC11: 0.044335241 | AD11: 0.04490044 | AE11: 0.041880774 | AF11: 0.03745965
B12: Recurring Operating Income | C12: =Model!AV124 -> 6569 | D12: =Model!AY124 -> 6664.084 | E12: =Model!AZ124 -> 7138.6662 | F12: =Model!BA124 -> 7730.024 | G12: =Model!BB124 -> 8326.068 | H12: =Model!BC124 -> 8887.4811 | I12: =IFERROR((H12/C12)^(1/5)-1,"n/m") -> 0.062321292 | N12: Recurring Operating Income | O12: 6569 | P12: 6887.4235 | Q12: 7650.6794 | R12: 8436.2733 | S12: 9254.5854 | T12: 10063.522 | U12: 0.089055828 | Z12: Recurring Operating Income | AA12: 6569 | AB12: 6307.7874 | AC12: 6352.9672 | AD12: 6690.6252 | AE12: 7007.235 | AF12: 7269.7235 | AG12: 0.020478189
B13: Recurring operating margin % | C13: =IFERROR(C12/C9,"") -> 0.41051119 | D13: =IFERROR(D12/D9,"") -> 0.40617347 | E13: =IFERROR(E12/E9,"") -> 0.405 | F13: =IFERROR(F12/F9,"") -> 0.408 | G13: =IFERROR(G12/G9,"") -> 0.41 | H13: =IFERROR(H12/H9,"") -> 0.41 | J13: =IFERROR(AVERAGE(Model!C203,Model!D203,Model!E203,Model!F203,Model!G203,Model!H203,Model!I203,Model!L203,Model!O203,Model!R203,Model!U203,Model!X203,Model!AA203,Model!AD203,Model!AG203,Model!AJ203,Model!AM203,Model!AP203,Model!AS203,Model!AV203),"") -> 0.32924659 | K13: =IFERROR(MIN(Model!C203,Model!D203,Model!E203,Model!F203,Model!G203,Model!H203,Model!I203,Model!L203,Model!O203,Model!R203,Model!U203,Model!X203,Model!AA203,Model!AD203,Model!AG203,Model!AJ203,Model!AM203,Model!AP203,Model!AS203,Model!AV203),"") -> 0.24181163 | L13: =IFERROR(MAX(Model!C203,Model!D203,Model!E203,Model!F203,Model!G203,Model!H203,Model!I203,Model!L203,Model!O203,Model!R203,Model!U203,Model!X203,Model!AA203,Model!AD203,Model!AG203,Model!AJ203,Model!AM203,Model!AP203,Model!AS203,Model!AV203),"") -> 0.42071945 | N13: Recurring operating margin % | O13: 0.41051119 | P13: 0.41375773 | Q13: 0.42 | R13: 0.423 | S13: 0.425 | T13: 0.425 | V13: 0.32924659 | W13: 0.24181163 | X13: 0.42071945 | Z13: Recurring operating margin % | AA13: 0.41051119 | AB13: 0.39402517 | AC13: 0.38 | AD13: 0.383 | AE13: 0.385 | AF13: 0.385 | AH13: 0.32924659 | AI13: 0.24181163 | AJ13: 0.42071945
B15: Operating Income (IFRS) | C15: =Model!AV127 -> 6569 | D15: =Model!AY127 -> 6664.084 | E15: =Model!AZ127 -> 7138.6662 | F15: =Model!BA127 -> 7730.024 | G15: =Model!BB127 -> 8326.068 | H15: =Model!BC127 -> 8887.4811 | I15: =IFERROR((H15/C15)^(1/5)-1,"n/m") -> 0.062321292 | N15: Operating Income (IFRS) | O15: 6569 | P15: 6887.4235 | Q15: 7650.6794 | R15: 8436.2733 | S15: 9254.5854 | T15: 10063.522 | U15: 0.089055828 | Z15: Operating Income (IFRS) | AA15: 6569 | AB15: 6307.7874 | AC15: 6352.9672 | AD15: 6690.6252 | AE15: 7007.235 | AF15: 7269.7235 | AG15: 0.020478189
B16: Operating income y/y % | D16: =IFERROR(D15/C15-1,"") -> 0.014474651 | E16: =IFERROR(E15/D15-1,"") -> 0.071214928 | F16: =IFERROR(F15/E15-1,"") -> 0.082838696 | G16: =IFERROR(G15/F15-1,"") -> 0.077107644 | H16: =IFERROR(H15/G15-1,"") -> 0.067428365 | N16: Operating income y/y % | P16: 0.048473666 | Q16: 0.11081879 | R16: 0.10268289 | S16: 0.096999239 | T16: 0.087409224 | Z16: Operating income y/y % | AB16: -0.039764434 | AC16: 0.0071625362 | AD16: 0.053149654 | AE16: 0.047321405 | AF16: 0.03745965
B17: Operating margin (IFRS) % | C17: =IFERROR(C15/C9,"") -> 0.41051119 | D17: =IFERROR(D15/D9,"") -> 0.40617347 | E17: =IFERROR(E15/E9,"") -> 0.405 | F17: =IFERROR(F15/F9,"") -> 0.408 | G17: =IFERROR(G15/G9,"") -> 0.41 | H17: =IFERROR(H15/H9,"") -> 0.41 | J17: =IFERROR(AVERAGE(Model!C205,Model!D205,Model!E205,Model!F205,Model!G205,Model!H205,Model!I205,Model!L205,Model!O205,Model!R205,Model!U205,Model!X205,Model!AA205,Model!AD205,Model!AG205,Model!AJ205,Model!AM205,Model!AP205,Model!AS205,Model!AV205),"") -> 0.33114958 | K17: =IFERROR(MIN(Model!C205,Model!D205,Model!E205,Model!F205,Model!G205,Model!H205,Model!I205,Model!L205,Model!O205,Model!R205,Model!U205,Model!X205,Model!AA205,Model!AD205,Model!AG205,Model!AJ205,Model!AM205,Model!AP205,Model!AS205,Model!AV205),"") -> 0.24181163 | L17: =IFERROR(MAX(Model!C205,Model!D205,Model!E205,Model!F205,Model!G205,Model!H205,Model!I205,Model!L205,Model!O205,Model!R205,Model!U205,Model!X205,Model!AA205,Model!AD205,Model!AG205,Model!AJ205,Model!AM205,Model!AP205,Model!AS205,Model!AV205),"") -> 0.42071945 | N17: Operating margin (IFRS) % | O17: 0.41051119 | P17: 0.41375773 | Q17: 0.42 | R17: 0.423 | S17: 0.425 | T17: 0.425 | V17: 0.33114958 | W17: 0.24181163 | X17: 0.42071945 | Z17: Operating margin (IFRS) % | AA17: 0.41051119 | AB17: 0.39402517 | AC17: 0.38 | AD17: 0.383 | AE17: 0.385 | AF17: 0.385 | AH17: 0.33114958 | AI17: 0.24181163 | AJ17: 0.42071945
B19: Recurring Net Income (attributable; excl. non-recurring & French exceptional contribution) | C19: =Model!AV187 -> 4855 | D19: =Model!AY187 -> 4959.7091 | E19: =Model!AZ187 -> 5292.0401 | F19: =Model!BA187 -> 5743.4712 | G19: =Model!BB187 -> 6203.7986 | H19: =Model!BC187 -> 6643.3671 | I19: =IFERROR((H19/C19)^(1/5)-1,"n/m") -> 0.064730767 | N19: Recurring Net Income (attributable; excl. non-recurring & French exceptional contribution) | O19: 4855 | P19: 5119.7654 | Q19: 5639.9582 | R19: 6210.8102 | S19: 6810.036 | T19: 7406.9707 | U19: 0.08815379 | Z19: Recurring Net Income (attributable; excl. non-recurring & French exceptional contribution) | AA19: 4855 | AB19: 4704.3692 | AC19: 4730.3208 | AD19: 4998.5459 | AE19: 5257.5688 | AF19: 5480.6251 | AG19: 0.024538237
B21: FDSO (m) | C21: =Model!AV148 -> 105.0367 | D21: =Model!AY148 -> 105.00298 | E21: =Model!AZ148 -> 104.93355 | F21: =Model!BA148 -> 104.83964 | G21: =Model!BB148 -> 104.7571 | H21: =Model!BC148 -> 104.68519 | I21: =IFERROR((H21/C21)^(1/5)-1,"n/m") -> -0.00067020514 | N21: FDSO (m) | O21: 105.0367 | P21: 105.00298 | Q21: 104.59482 | R21: 104.2922 | S21: 104.01462 | T21: 103.76043 | U21: -0.0024420426 | Z21: FDSO (m) | AA21: 105.0367 | AB21: 105.00298 | AC21: 105.04395 | AD21: 105.08916 | AE21: 105.13666 | AF21: 105.18627 | AG21: 0.00028463403
B23: Recurring EPS — Diluted (€) | C23: =Model!AV191 -> 46.221938 | D23: =Model!AY191 -> 47.233986 | E23: =Model!AZ191 -> 50.432298 | F23: =Model!BA191 -> 54.783395 | G23: =Model!BB191 -> 59.220794 | H23: =Model!BC191 -> 63.460427 | I23: =IFERROR((H23/C23)^(1/5)-1,"n/m") -> 0.065444833 | N23: Recurring EPS — Diluted (€) | O23: 46.221938 | P23: 48.758288 | Q23: 53.921967 | R23: 59.552009 | S23: 65.471911 | T23: 71.385311 | U23: 0.090817613 | Z23: Recurring EPS — Diluted (€) | AA23: 46.221938 | AB23: 44.802246 | AC23: 45.031827 | AD23: 47.564808 | AE23: 50.007001 | AF23: 52.103995 | AG23: 0.024246702
B24: EPS y/y % | D24: =IFERROR(D23/C23-1,"") -> 0.0218954 | E24: =IFERROR(E23/D23-1,"") -> 0.067712096 | F24: =IFERROR(F23/E23-1,"") -> 0.086276001 | G24: =IFERROR(G23/F23-1,"") -> 0.080998983 | H24: =IFERROR(H23/G23-1,"") -> 0.071590267 | N24: EPS y/y % | P24: 0.054873296 | Q24: 0.10590363 | R24: 0.10441091 | S24: 0.099407257 | T24: 0.090319658 | Z24: EPS y/y % | AB24: -0.03071468 | AC24: 0.0051243191 | AD24: 0.056248698 | AE24: 0.051344534 | AF24: 0.041933991
B26: P / E (x) — assumed (recurring EPS) | F26: 34 | G26: =F26 -> 34 | H26: =G26 -> 34 | N26: P / E (x) — assumed (recurring EPS) | R26: 42 | S26: =R26 -> 42 | T26: =S26 -> 42 | Z26: P / E (x) — assumed (recurring EPS) | AD26: 27 | AE26: =AD26 -> 27 | AF26: =AE26 -> 27
B27: Price Target (€) | F27: =F26*F23 -> 1862.6354 | G27: =G26*G23 -> 2013.507 | H27: =H26*H23 -> 2157.6545 | N27: Price Target (€) | R27: =R26*R23 -> 2501.1844 | S27: =S26*S23 -> 2749.8202 | T27: =T26*T23 -> 2998.1831 | Z27: Price Target (€) | AD27: =AD26*AD23 -> 1284.2498 | AE27: =AE26*AE23 -> 1350.189 | AF27: =AF26*AF23 -> 1406.8079
B28: Upside / (Downside) vs current | F28: =IFERROR(F27/$K$2-1,"") -> 0.43334777 | G28: =IFERROR(G27/$K$2-1,"") -> 0.54944748 | H28: =IFERROR(H27/$K$2-1,"") -> 0.66037284 | N28: Upside / (Downside) vs current | R28: =IFERROR(R27/$K$2-1,"") -> 0.92472826 | S28: =IFERROR(S27/$K$2-1,"") -> 1.1160602 | T28: =IFERROR(T27/$K$2-1,"") -> 1.3071821 | Z28: Upside / (Downside) vs current | AD28: =IFERROR(AD27/$K$2-1,"") -> -0.011735415 | AE28: =IFERROR(AE27/$K$2-1,"") -> 0.039006569 | AF28: =IFERROR(AF27/$K$2-1,"") -> 0.082576261
B29: IRR (to Dec-Y-1) | F29: =IFERROR((F27/$K$2)^(1/((DATE(2028-1,12,31)-$K$3)/365.25))-1,"") -> 0.33679536 | G29: =IFERROR((G27/$K$2)^(1/((DATE(2029-1,12,31)-$K$3)/365.25))-1,"") -> 0.2156633 | H29: =IFERROR((H27/$K$2)^(1/((DATE(2030-1,12,31)-$K$3)/365.25))-1,"") -> 0.16931314 | N29: IRR (to Dec-Y-1) | R29: =IFERROR((R27/$K$2)^(1/((DATE(2028-1,12,31)-$K$3)/365.25))-1,"") -> 0.69544856 | S29: =IFERROR((S27/$K$2)^(1/((DATE(2029-1,12,31)-$K$3)/365.25))-1,"") -> 0.39693423 | T29: =IFERROR((T27/$K$2)^(1/((DATE(2030-1,12,31)-$K$3)/365.25))-1,"") -> 0.2942151 | Z29: IRR (to Dec-Y-1) | AD29: =IFERROR((AD27/$K$2)^(1/((DATE(2028-1,12,31)-$K$3)/365.25))-1,"") -> -0.0094729698 | AE29: =IFERROR((AE27/$K$2)^(1/((DATE(2029-1,12,31)-$K$3)/365.25))-1,"") -> 0.017211524 | AF29: =IFERROR((AF27/$K$2)^(1/((DATE(2030-1,12,31)-$K$3)/365.25))-1,"") -> 0.024778581
B31: Adjusted Free Cash Flow | C31: =Model!AV239 -> 3881 | D31: =Model!AY239 -> 4263.1903 | E31: =Model!AZ239 -> 4623.7066 | F31: =Model!BA239 -> 5160.6671 | G31: =Model!BB239 -> 5627.1425 | H31: =Model!BC239 -> 6071.4717 | I31: =IFERROR((H31/C31)^(1/5)-1,"n/m") -> 0.093629123 | N31: Adjusted Free Cash Flow | O31: 3881 | P31: 4425.6071 | Q31: 4945.7078 | R31: 5567.5773 | S31: 6159.911 | T31: 6748.2488 | U31: 0.11699052 | Z31: Adjusted Free Cash Flow | AA31: 3881 | AB31: 4001.5519 | AC31: 4090.876 | AD31: 4501.4977 | AE31: 4781.842 | AF31: 5024.3371 | AG31: 0.052996739
B32: FCF % | C32: =IFERROR(C31/C9,"") -> 0.24253218 | D32: =IFERROR(D31/D9,"") -> 0.25983988 | E32: =IFERROR(E31/E9,"") -> 0.26231807 | F32: =IFERROR(F31/F9,"") -> 0.27238624 | G32: =IFERROR(G31/G9,"") -> 0.277097 | H32: =IFERROR(H31/H9,"") -> 0.28009099 | J32: =IFERROR(AVERAGE(Model!C244,Model!D244,Model!E244,Model!F244,Model!G244,Model!H244,Model!I244,Model!L244,Model!O244,Model!R244,Model!U244,Model!X244,Model!AA244,Model!AD244,Model!AG244,Model!AJ244,Model!AM244,Model!AP244,Model!AS244,Model!AV244),"") -> 0.21365323 | K32: =IFERROR(MIN(Model!C244,Model!D244,Model!E244,Model!F244,Model!G244,Model!H244,Model!I244,Model!L244,Model!O244,Model!R244,Model!U244,Model!X244,Model!AA244,Model!AD244,Model!AG244,Model!AJ244,Model!AM244,Model!AP244,Model!AS244,Model!AV244),"") -> 0.13566317 | L32: =IFERROR(MAX(Model!C244,Model!D244,Model!E244,Model!F244,Model!G244,Model!H244,Model!I244,Model!L244,Model!O244,Model!R244,Model!U244,Model!X244,Model!AA244,Model!AD244,Model!AG244,Model!AJ244,Model!AM244,Model!AP244,Model!AS244,Model!AV244),"") -> 0.29625919 | N32: FCF % | O32: 0.24253218 | P32: 0.26586562 | Q32: 0.27150494 | R32: 0.2791618 | S32: 0.28288271 | T32: 0.28499027 | V32: 0.21365323 | W32: 0.13566317 | X32: 0.29625919 | Z32: FCF % | AA32: 0.24253218 | AB32: 0.2499628 | AC32: 0.24469399 | AD32: 0.25768498 | AE32: 0.26272976 | AF32: 0.26608574 | AH32: 0.21365323 | AI32: 0.13566317 | AJ32: 0.29625919
B33: FCF / share (€) | C33: =IFERROR(C31/C21,"") -> 36.948989 | D33: =IFERROR(D31/D21,"") -> 40.600661 | E33: =IFERROR(E31/E21,"") -> 44.063186 | F33: =IFERROR(F31/F21,"") -> 49.22439 | G33: =IFERROR(G31/G21,"") -> 53.716097 | H33: =IFERROR(H31/H21,"") -> 57.997425 | N33: FCF / share (€) | O33: 36.948989 | P33: 42.147444 | Q33: 47.284446 | R33: 53.384406 | S33: 59.221588 | T33: 65.036822 | Z33: FCF / share (€) | AA33: 36.948989 | AB33: 38.108938 | AC33: 38.944425 | AD33: 42.835033 | AE33: 45.482158 | AF33: 47.766091
B34: FCF Yield (on PT) | F34: =IFERROR(F33/F$27,"") -> 0.026427281 | G34: =IFERROR(G33/G$27,"") -> 0.02667788 | H34: =IFERROR(H33/H$27,"") -> 0.026879848 | N34: FCF Yield (on PT) | R34: =IFERROR(R33/R$27,"") -> 0.021343651 | S34: =IFERROR(S33/S$27,"") -> 0.021536531 | T34: =IFERROR(T33/T$27,"") -> 0.021692078 | Z34: FCF Yield (on PT) | AD34: =IFERROR(AD33/AD$27,"") -> 0.033354128 | AE34: =IFERROR(AE33/AE$27,"") -> 0.033685771 | AF34: =IFERROR(AF33/AF$27,"") -> 0.033953529
B35: EBITDA (IFRS 16) | C35: =Model!AV171 -> 7495 | D35: =Model!AY171 -> 7661.5326 | E35: =Model!AZ171 -> 8217.0823 | F35: =Model!BA171 -> 8894.4554 | G35: =Model!BB171 -> 9579.8088 | H35: =Model!BC171 -> 10232.524 | I35: =IFERROR((H35/C35)^(1/5)-1,"n/m") -> 0.064246484 | N35: EBITDA (IFRS 16) | O35: 7495 | P35: 7893.7166 | Q35: 8752.541 | R35: 9642.9593 | S35: 10573.749 | T35: 11501.601 | U35: 0.089424988 | Z35: EBITDA (IFRS 16) | AA35: 7495 | AB35: 7290.4953 | AC35: 7395.0681 | AD35: 7792.0163 | AE35: 8166.1893 | AF35: 8483.4445 | AG35: 0.025085563
B36: EBITDA margin % | C36: =IFERROR(C35/C9,"") -> 0.46837895 | D36: =IFERROR(D35/D9,"") -> 0.46696759 | E36: =IFERROR(E35/E9,"") -> 0.46618209 | F36: =IFERROR(F35/F9,"") -> 0.46946009 | G36: =IFERROR(G35/G9,"") -> 0.47173787 | H36: =IFERROR(H35/H9,"") -> 0.47204991 | J36: =IFERROR(AVERAGE(Model!C204,Model!D204,Model!E204,Model!F204,Model!G204,Model!H204,Model!I204,Model!L204,Model!O204,Model!R204,Model!U204,Model!X204,Model!AA204,Model!AD204,Model!AG204,Model!AJ204,Model!AM204,Model!AP204,Model!AS204,Model!AV204),"") -> 0.39326349 | K36: =IFERROR(MIN(Model!C204,Model!D204,Model!E204,Model!F204,Model!G204,Model!H204,Model!I204,Model!L204,Model!O204,Model!R204,Model!U204,Model!X204,Model!AA204,Model!AD204,Model!AG204,Model!AJ204,Model!AM204,Model!AP204,Model!AS204,Model!AV204),"") -> 0.28595309 | L36: =IFERROR(MAX(Model!C204,Model!D204,Model!E204,Model!F204,Model!G204,Model!H204,Model!I204,Model!L204,Model!O204,Model!R204,Model!U204,Model!X204,Model!AA204,Model!AD204,Model!AG204,Model!AJ204,Model!AM204,Model!AP204,Model!AS204,Model!AV204),"") -> 0.47821554 | N36: EBITDA margin % | O36: 0.46837895 | P36: 0.47421016 | Q36: 0.48048899 | R36: 0.48350399 | S36: 0.48558018 | T36: 0.4857326 | V36: 0.39326349 | W36: 0.28595309 | X36: 0.47821554 | Z36: EBITDA margin % | AA36: 0.46837895 | AB36: 0.45541145 | AC36: 0.44233282 | AD36: 0.44604834 | AE36: 0.44867667 | AF36: 0.4492779 | AH36: 0.39326349 | AI36: 0.28595309 | AJ36: 0.47821554
B38: Net Debt (negative = net cash) | C38: =Model!AV372 -> -12773 | D38: =Model!AY372 -> -14747.19 | E38: =Model!AZ372 -> -17014.568 | F38: =Model!BA372 -> -19684.598 | G38: =Model!BB372 -> -22638.525 | H38: =Model!BC372 -> -25850.743 | N38: Net Debt (negative = net cash) | O38: -12773 | P38: -13609.607 | Q38: -14582.961 | R38: -15940.028 | S38: -17630.095 | T38: -19636.41 | Z38: Net Debt (negative = net cash) | AA38: -12773 | AB38: -14535.552 | AC38: -16574.154 | AD38: -19011.611 | AE38: -21620.979 | AF38: -24368.262
B39: Net Debt / EBITDA (x) | C39: =IFERROR(C38/C35,"") -> -1.7042028 | D39: =IFERROR(D38/D35,"") -> -1.9248355 | E39: =IFERROR(E38/E35,"") -> -2.0706337 | F39: =IFERROR(F38/F35,"") -> -2.2131314 | G39: =IFERROR(G38/G35,"") -> -2.36315 | H39: =IFERROR(H38/H35,"") -> -2.5263312 | N39: Net Debt / EBITDA (x) | O39: -1.7042028 | P39: -1.7241064 | Q39: -1.6661403 | R39: -1.6530225 | S39: -1.6673457 | T39: -1.7072762 | Z39: Net Debt / EBITDA (x) | AA39: -1.7042028 | AB39: -1.9937674 | AC39: -2.2412443 | AD39: -2.4398834 | AE39: -2.6476216 | AF39: -2.8724491
B41: ROIC | C41: =Model!AV351 -> 0.56005017 | D41: =Model!AY351 -> 0.52135649 | E41: =Model!AZ351 -> 0.4939499 | F41: =Model!BA351 -> 0.48481987 | G41: =Model!BB351 -> 0.47690758 | H41: =Model!BC351 -> 0.46788245 | J41: =IFERROR(AVERAGE(Model!C351,Model!D351,Model!E351,Model!F351,Model!G351,Model!H351,Model!I351,Model!L351,Model!O351,Model!R351,Model!U351,Model!X351,Model!AA351,Model!AD351,Model!AG351,Model!AJ351,Model!AM351,Model!AP351,Model!AS351,Model!AV351),"") -> 0.51955545 | K41: =IFERROR(MIN(Model!C351,Model!D351,Model!E351,Model!F351,Model!G351,Model!H351,Model!I351,Model!L351,Model!O351,Model!R351,Model!U351,Model!X351,Model!AA351,Model!AD351,Model!AG351,Model!AJ351,Model!AM351,Model!AP351,Model!AS351,Model!AV351),"") -> 0.2529689 | L41: =IFERROR(MAX(Model!C351,Model!D351,Model!E351,Model!F351,Model!G351,Model!H351,Model!I351,Model!L351,Model!O351,Model!R351,Model!U351,Model!X351,Model!AA351,Model!AD351,Model!AG351,Model!AJ351,Model!AM351,Model!AP351,Model!AS351,Model!AV351),"") -> 0.73200514 | N41: ROIC | O41: 0.56005017 | P41: 0.53897284 | Q41: 0.52687695 | R41: 0.52226192 | S41: 0.51852656 | T41: 0.51329395 | V41: 0.51955545 | W41: 0.2529689 | X41: 0.73200514 | Z41: ROIC | AA41: 0.56005017 | AB41: 0.49317615 | AC41: 0.44225992 | AD41: 0.42740684 | AE41: 0.41421831 | AF41: 0.40045195 | AH41: 0.51955545 | AI41: 0.2529689 | AJ41: 0.73200514
B42: RONTA | C42: =Model!AV364 -> 0.52877161 | D42: =Model!AY364 -> 0.4946952 | E42: =Model!AZ364 -> 0.47132623 | F42: =Model!BA364 -> 0.46460553 | G42: =Model!BB364 -> 0.45868199 | H42: =Model!BC364 -> 0.45139731 | J42: =IFERROR(AVERAGE(Model!C364,Model!D364,Model!E364,Model!F364,Model!G364,Model!H364,Model!I364,Model!L364,Model!O364,Model!R364,Model!U364,Model!X364,Model!AA364,Model!AD364,Model!AG364,Model!AJ364,Model!AM364,Model!AP364,Model!AS364,Model!AV364),"") -> 0.47015029 | K42: =IFERROR(MIN(Model!C364,Model!D364,Model!E364,Model!F364,Model!G364,Model!H364,Model!I364,Model!L364,Model!O364,Model!R364,Model!U364,Model!X364,Model!AA364,Model!AD364,Model!AG364,Model!AJ364,Model!AM364,Model!AP364,Model!AS364,Model!AV364),"") -> 0.23289532 | L42: =IFERROR(MAX(Model!C364,Model!D364,Model!E364,Model!F364,Model!G364,Model!H364,Model!I364,Model!L364,Model!O364,Model!R364,Model!U364,Model!X364,Model!AA364,Model!AD364,Model!AG364,Model!AJ364,Model!AM364,Model!AP364,Model!AS364,Model!AV364),"") -> 0.63300388 | N42: RONTA | O42: 0.52877161 | P42: 0.5114037 | Q42: 0.50285398 | R42: 0.50075687 | S42: 0.49912662 | T42: 0.49575284 | V42: 0.47015029 | W42: 0.23289532 | X42: 0.63300388 | Z42: RONTA | AA42: 0.52877161 | AB42: 0.46797079 | AC42: 0.42188613 | AD42: 0.40927005 | AE42: 0.39790155 | AF42: 0.3857128 | AH42: 0.47015029 | AI42: 0.23289532 | AJ42: 0.63300388
B44: Implied Market Cap (EURm) | F44: =F27*F21 -> 195278.02 | G44: =G27*G21 -> 210929.15 | H44: =H27*H21 -> 225874.48 | N44: Implied Market Cap (EURm) | R44: =R27*R21 -> 260854.03 | S44: =S27*S21 -> 286021.51 | T44: =T27*T21 -> 311092.77 | Z44: Implied Market Cap (EURm) | AD44: =AD27*AD21 -> 134960.74 | AE44: =AE27*AE21 -> 141954.36 | AF44: =AF27*AF21 -> 147976.88
B45: (+) Net Debt & NCI | F45: =F38+Model!BA383 -> -19678.598 | G45: =G38+Model!BB383 -> -22632.525 | H45: =H38+Model!BC383 -> -25844.743 | N45: (+) Net Debt & NCI | R45: =R38+Model!BA383 -> -15934.028 | S45: =S38+Model!BB383 -> -17624.095 | T45: =T38+Model!BC383 -> -19630.41 | Z45: (+) Net Debt & NCI | AD45: =AD38+Model!BA383 -> -19005.611 | AE45: =AE38+Model!BB383 -> -21614.979 | AF45: =AF38+Model!BC383 -> -24362.262
B46: Implied Enterprise Value (EURm) | F46: =F44+F45 -> 175599.42 | G46: =G44+G45 -> 188296.63 | H46: =H44+H45 -> 200029.74 | N46: Implied Enterprise Value (EURm) | R46: =R44+R45 -> 244920 | S46: =S44+S45 -> 268397.42 | T46: =T44+T45 -> 291462.36 | Z46: Implied Enterprise Value (EURm) | AD46: =AD44+AD45 -> 115955.13 | AE46: =AE44+AE45 -> 120339.38 | AF46: =AF44+AF45 -> 123614.61
B47: Implied EV / EBITDA (x) | F47: =IFERROR(F46/F35,"") -> 19.742571 | G47: =IFERROR(G46/G35,"") -> 19.655573 | H47: =IFERROR(H46/H35,"") -> 19.548427 | N47: Implied EV / EBITDA (x) | R47: =IFERROR(R46/R35,"") -> 25.398842 | S47: =IFERROR(S46/S35,"") -> 25.383374 | T47: =IFERROR(T46/T35,"") -> 25.341025 | Z47: Implied EV / EBITDA (x) | AD47: =IFERROR(AD46/AD35,"") -> 14.881274 | AE47: =IFERROR(AE46/AE35,"") -> 14.736296 | AF47: =IFERROR(AF46/AF35,"") -> 14.571276

Sheet DCF
B2: DCF VALUATION — HERMÈS INTERNATIONAL (RMS)
B4: 1. WACC BUILD
B5: Risk-free rate (EUR 10Y govt) | C5: 0.03 | D5: Assumption (~blend of 10Y Bund / OAT yields); update to market
B6: Equity risk premium | C6: 0.055 | D6: Euro-area implied ERP ~5–6% (Damodaran)
B7: Levered beta | C7: 0.9 | D7: Luxury peers (LVMH, Kering, Richemont, Prada) ~0.9–1.2; Hermès' pricing power and family-controlled shareholder base dampen cyclicality
B8: Cost of equity | C8: =C5+C7*C6 -> 0.0795
B9: Pre-tax cost of debt | C9: 0.035 | D9: No financial debt (net cash €12.9bn at 30-Jun-26); notional IG euro cost
B10: Tax rate | C10: 0.285 | D10: Model 2027E+ effective tax rate (excl. the French exceptional contribution)
B11: After-tax cost of debt | C11: =C9*(1-C10) -> 0.025025
B12: Target D/V | C12: 0 | D12: Net cash balance sheet; lease liabilities (~€2.3bn) treated as operating (ROU depreciation kept in EBIT)
B13: WACC | C13: =C8*(1-C12)+C11*C12 -> 0.0795
B15: Valuation date (live) | C15: =TODAY() -> 46299 | D15: Periods = (Dec-31-Year − today) / 365.25; cash flows assumed at year-end
B16: 2. UNLEVERED FREE CASH FLOW BUILD (EURm)
D17: 2026E | E17: 2027E | F17: 2028E | G17: 2029E | H17: 2030E | I17: 2031E | J17: 2032E | K17: 2033E | L17: 2034E | M17: 2035E | N17: Terminal
B18: Recurring operating income = adjusted EBIT (Model) | D18: =Model!AY124 -> 6664.084 | E18: =Model!AZ124 -> 7138.6662 | F18: =Model!BA124 -> 7730.024 | G18: =Model!BB124 -> 8326.068 | H18: =Model!BC124 -> 8887.4811 | I18: =H18*(1+I$31) -> 9509.6048 | J18: =I18*(1+J$31) -> 10115.842 | K18: =J18*(1+K$31) -> 10697.503 | L18: =K18*(1+L$31) -> 11245.75 | M18: =L18*(1+M$31) -> 11751.809
B19: y/y % | E19: =IFERROR(E18/D18-1,"") -> 0.071214928 | F19: =IFERROR(F18/E18-1,"") -> 0.082838696 | G19: =IFERROR(G18/F18-1,"") -> 0.077107644 | H19: =IFERROR(H18/G18-1,"") -> 0.067428365 | I19: =IFERROR(I18/H18-1,"") -> 0.07 | J19: =IFERROR(J18/I18-1,"") -> 0.06375 | K19: =IFERROR(K18/J18-1,"") -> 0.0575 | L19: =IFERROR(L18/K18-1,"") -> 0.05125 | M19: =IFERROR(M18/L18-1,"") -> 0.045
B20: (+) Non-recurring items (Model; nil in forecast) | D20: =Model!AY126 -> 0 | E20: =Model!AZ126 -> 0 | F20: =Model!BA126 -> 0 | G20: =Model!BB126 -> 0 | H20: =Model!BC126 -> 0 | I20: =H20*(1+I$31) -> 0 | J20: =I20*(1+J$31) -> 0 | K20: =J20*(1+K$31) -> 0 | L20: =K20*(1+L$31) -> 0 | M20: =L20*(1+M$31) -> 0
