Workbook

Sheet Model
CF1: SCENARIO SWITCH ▼ (Bull / Base / Bear) — drives all scenario-linked forecast drivers
B2: Saia, Inc. (NASDAQ: SAIA) — 3-Statement Financial Model | CF2: Base
B3: US GAAP as reported · USD millions (per-share data in USD; LTL tonnage & shipments in thousands; yields in $/cwt) · Source: Saia Forms 10-K / 10-Q and Form 8-K earnings releases (Ex. 99.1), interim LTL operating-data 8-Ks and call transcripts (8-K Ex. 99.1), SEC EDGAR CIK 0001177702 (investor-relations releases are the same documents as filed on EDGAR); DOE diesel from carrier 10-Q/10-Ks (Knight-Swift, Heartland, Marten) and EIA.
B4: Basis notes: calendar fiscal year. Continuing operations — Jevic Transportation sold Jun-2006 (discontinued operations to 2010). The Connection (Nov-2006) and Madison Freight (Jan-2007) integrated 2007; Robart (2012) and LinkEx (2015, sold 2018) small. Per-share data split-adjusted for the 3-for-2 split (May-2013). LTL statistics: TL statistics shown separately to 2017; from Q1/18 weight-priced truckload included in LTL (tonnage/shipment basis change — use company-reported change memos for y/y). ASC 606 adopted 1-Jan-2018 (2017 as originally reported). FY2008 per 10-K (Q4/08 release pre-dated the $35.5m goodwill impairment). Saia publishes no EBITDA; Adjusted EBITDA is model-defined. Last reported quarter Q2/26; Q3/26E uses Jul–Aug interim data (8-K 3-Sep-26).
CH5: Forecast | CI5: Historical | CJ5: Historical | CK5: Historical
B6: (USDm) | C6: 2006 | D6: 2007 | E6: 2008 | F6: 2009 | G6: 2010 | H6: 2011 | I6: 2012 | J6: Q1/13 | K6: Q2/13 | L6: Q3/13 | M6: Q4/13 | N6: 2013 | O6: Q1/14 | P6: Q2/14 | Q6: Q3/14 | R6: Q4/14 | S6: 2014 | T6: Q1/15 | U6: Q2/15 | V6: Q3/15 | W6: Q4/15 | X6: 2015 | Y6: Q1/16 | Z6: Q2/16 | AA6: Q3/16 | AB6: Q4/16 | AC6: 2016 | AD6: Q1/17 | AE6: Q2/17 | AF6: Q3/17 | AG6: Q4/17 | AH6: 2017 | AI6: Q1/18 | AJ6: Q2/18 | AK6: Q3/18 | AL6: Q4/18 | AM6: 2018 | AN6: Q1/19 | AO6: Q2/19 | AP6: Q3/19 | AQ6: Q4/19 | AR6: 2019 | AS6: Q1/20 | AT6: Q2/20 | AU6: Q3/20 | AV6: Q4/20 | AW6: 2020 | AX6: Q1/21 | AY6: Q2/21 | AZ6: Q3/21 | BA6: Q4/21 | BB6: 2021 | BC6: Q1/22 | BD6: Q2/22 | BE6: Q3/22 | BF6: Q4/22 | BG6: 2022 | BH6: Q1/23 | BI6: Q2/23 | BJ6: Q3/23 | BK6: Q4/23 | BL6: 2023 | BM6: Q1/24 | BN6: Q2/24 | BO6: Q3/24 | BP6: Q4/24 | BQ6: 2024 | BR6: Q1/25 | BS6: Q2/25 | BT6: Q3/25 | BU6: Q4/25 | BV6: 2025 | BW6: Q1/26 | BX6: Q2/26 | BY6: Q3/26E | BZ6: Q4/26E | CA6: 2026E | CB6: 2027E | CC6: 2028E | CD6: 2029E | CE6: 2030E | CF6: Modelling Notes | CH6: 5Y CAGR | CI6: 5Y CAGR | CJ6: 10Y CAGR | CK6: 19Y CAGR
CH7: 25-'30 | CI7: 20-'25 | CJ7: 15-'25 | CK7: 06-'25
B8: LTL OPERATING BUILD — VOLUME (TONNAGE) × CORE YIELD (REV/CWT EX-FUEL) + FUEL SURCHARGE (DOE DIESEL × SURCHARGE TABLE × CAPTURE) → REVENUE | CF8: LTL BUILD — modelling logic (tonnage × rev/cwt ex-fuel = freight revenue; + fuel surcharge per cwt = all-in yield)
CN9: SCENARIO INPUT TABLE — driver assumptions per Bull / Base / Bear | CO9: Bull | CP9: Base | CQ9: Bear | CR9: Bull / Bear = Base + Δ (Δ inputs on each lever header). Outlook block = Bull / Base / Bear end-points of company guidance.
B10: LTL volume (Saia LTL; shipments & tonnage in thousands; basis: statistics exclude services not priced by weight — truckload volumes priced by weight included from Q1/18) | CF10: VOLUME — modelling logic
B11: Workdays | C11: 252 | D11: 253 | E11: 254 | F11: 253 | G11: 252 | H11: 253 | I11: 253 | J11: 63 | K11: 64 | L11: 64 | M11: 62 | N11: 253 | O11: 63 | P11: 64 | Q11: 64 | R11: 62 | S11: 253 | T11: 63 | U11: 64 | V11: 64 | W11: 62 | X11: 253 | Y11: 64 | Z11: 64 | AA11: 64 | AB11: 61 | AC11: 253 | AD11: 64 | AE11: 64 | AF11: 63 | AG11: 61 | AH11: 252 | AI11: 64 | AJ11: 64 | AK11: 63 | AL11: 62 | AM11: 253 | AN11: 63 | AO11: 64 | AP11: 64 | AQ11: 62 | AR11: 253 | AS11: 64 | AT11: 64 | AU11: 64 | AV11: 62 | AW11: 254 | AX11: 63 | AY11: 64 | AZ11: 64 | BA11: 61 | BB11: 252 | BC11: 64 | BD11: 64 | BE11: 64 | BF11: 61 | BG11: 253 | BH11: 64 | BI11: 64 | BJ11: 63 | BK11: 61 | BL11: 252 | BM11: 64 | BN11: 64 | BO11: 64 | BP11: 62 | BQ11: 254 | BR11: 63 | BS11: 64 | BT11: 64 | BU11: 62 | BV11: 253 | BW11: 63 | BX11: 64 | BY11: 64 | BZ11: 62 | CA11: =SUM(BW11,BX11,BY11,BZ11) -> 253 | CB11: 253 | CC11: 253 | CD11: 253 | CE11: 253 | CF11: Q3/26E 64 (= Q3/25); Q4/26E 62 (= Q4/25); 2027E+ 253 workdays (2025: 253). | CN11: FY26 outlook — Q4-25 call (10-Feb-26), Q2-26 release & call (30-Jul-26), Jul–Aug data (3-Sep-26) | CO11: Bull | CP11: Base | CQ11: Bear
B12: LTL tonnage per workday (000 tons) | C12: =IF(AND(ISNUMBER(C14),ISNUMBER(C11)),IFERROR(C14/C11,""),"") -> 13.730159 | D12: =IF(AND(ISNUMBER(D14),ISNUMBER(D11)),IFERROR(D14/D11,""),"") -> 14.996047 | E12: =IF(AND(ISNUMBER(E14),ISNUMBER(E11)),IFERROR(E14/E11,""),"") -> 14.551181 | F12: =IF(AND(ISNUMBER(F14),ISNUMBER(F11)),IFERROR(F14/F11,""),"") -> 13.73913 | G12: =IF(AND(ISNUMBER(G14),ISNUMBER(G11)),IFERROR(G14/G11,""),"") -> 14.138889 | H12: =IF(AND(ISNUMBER(H14),ISNUMBER(H11)),IFERROR(H14/H11,""),"") -> 14.581028 | I12: =IF(AND(ISNUMBER(I14),ISNUMBER(I11)),IFERROR(I14/I11,""),"") -> 14.545455 | J12: =IF(AND(ISNUMBER(J14),ISNUMBER(J11)),IFERROR(J14/J11,""),"") -> 14.222222 | ... BX12: =IF(AND(ISNUMBER(BX14),ISNUMBER(BX11)),IFERROR(BX14/BX11,""),"") -> 26.703125 | BY12: =BT12*(1+BY13) -> 26.753484 | BZ12: =BU12*(1+BZ13) -> 25.179516 | CA12: =IF(AND(ISNUMBER(CA14),ISNUMBER(CA11)),IFERROR(CA14/CA11,""),"") -> 25.673332 | CB12: =CA12*(1+CB13) -> 26.956999 | CC12: =CB12*(1+CC13) -> 28.170064 | CD12: =CC12*(1+CD13) -> 29.296866 | CE12: =CD12*(1+CE13) -> 30.322256 | CN12: FY26 operating-ratio improvement vs FY25 adjusted OR (bps) | CO12: 150 | CP12: 100 | CQ12: 50 | CR12: Guide 100–200 bps (Feb-26); Q2 call: 200 bps needs mid-single-digit shipment growth → Base = low end.
B13: LTL tonnage per workday y/y % | D13: =IF(AND(ISNUMBER(D12),ISNUMBER(C12)),IFERROR(D12/C12-1,""),"") -> 0.092197674 | E13: =IF(AND(ISNUMBER(E12),ISNUMBER(D12)),IFERROR(E12/D12-1,""),"") -> -0.029665572 | F13: =IF(AND(ISNUMBER(F12),ISNUMBER(E12)),IFERROR(F12/E12-1,""),"") -> -0.055806512 | G13: =IF(AND(ISNUMBER(G12),ISNUMBER(F12)),IFERROR(G12/F12-1,""),"") -> 0.029096343 | H13: =IF(AND(ISNUMBER(H12),ISNUMBER(G12)),IFERROR(H12/G12-1,""),"") -> 0.031271112 | I13: =IF(AND(ISNUMBER(I12),ISNUMBER(H12)),IFERROR(I12/H12-1,""),"") -> -0.0024396856 | N13: =IF(AND(ISNUMBER(N12),ISNUMBER(I12)),IFERROR(N12/I12-1,""),"") -> -0.0024456522 | O13: =IF(AND(ISNUMBER(O12),ISNUMBER(J12)),IFERROR(O12/J12-1,""),"") -> 0.056919643 | P13: =IF(AND(ISNUMBER(P12),ISNUMBER(K12)),IFERROR(P12/K12-1,""),"") -> 0.069109948 | Q13: =IF(AND(ISNUMBER(Q12),ISNUMBER(L12)),IFERROR(Q12/L12-1,""),"") -> 0.081545064 | R13: =IF(AND(ISNUMBER(R12),ISNUMBER(M12)),IFERROR(R12/M12-1,""),"") -> 0.042792793 | S13: =IF(AND(ISNUMBER(S12),ISNUMBER(N12)),IFERROR(S12/N12-1,""),"") -> 0.062925633 | T13: =IF(AND(ISNUMBER(T12),ISNUMBER(O12)),IFERROR(T12/O12-1,""),"") -> -0.066525871 | U13: =IF(AND(ISNUMBER(U12),ISNUMBER(P12)),IFERROR(U12/P12-1,""),"") -> -0.059745348 | ... BX13: =IF(AND(ISNUMBER(BX12),ISNUMBER(BS12)),IFERROR(BX12/BS12-1,""),"") -> 0.084390863 | BY13: =BY59 -> 0.083 | BZ13: =CHOOSE(MATCH($CF$2,{"Bull","Base","Bear"},0),$CO$16,$CP$16,$CQ$16) -> 0.07 | CA13: =IF(AND(ISNUMBER(CA12),ISNUMBER(BV12)),IFERROR(CA12/BV12-1,""),"") -> 0.054269274 | CB13: =CHOOSE(MATCH($CF$2,{"Bull","Base","Bear"},0),$CO$36,$CP$36,$CQ$36) -> 0.05 | CC13: =CHOOSE(MATCH($CF$2,{"Bull","Base","Bear"},0),$CO$37,$CP$37,$CQ$37) -> 0.045 | CD13: =CHOOSE(MATCH($CF$2,{"Bull","Base","Bear"},0),$CO$38,$CP$38,$CQ$38) -> 0.04 | CE13: =CHOOSE(MATCH($CF$2,{"Bull","Base","Bear"},0),$CO$39,$CP$39,$CQ$39) -> 0.035 | CF13: Q3/26E = Jul–Aug QTD +8.3% (8-K 3-Sep-26); Q4/26E and 2027E+ = scenario lever TON (Bull/Base/Bear). | CN13: Q3/26 OR sequential change vs Q2/26 86.9% (bps; + = worse) | CO13: 50 | CP13: 100 | CQ13: 150 | CR13: Q2-26 call: ~100 bps degradation (typical 150–200 bps), assuming fuel near late-July level.
B14: LTL tonnage (000 tons) | C14: 3460 | D14: 3794 | E14: 3696 | F14: 3476 | G14: 3563 | H14: 3689 | I14: 3680 | J14: 896 | K14: 955 | L14: 932 | M14: 888 | N14: 3671 | O14: 947 | P14: 1021 | Q14: 1008 | R14: 926 | S14: 3902 | T14: 884 | U14: 960 | V14: 940 | W14: 844 | X14: 3628 | Y14: 868 | Z14: 919 | AA14: 913 | AB14: 842 | AC14: 3541 | AD14: 885 | AE14: 984 | AF14: 931 | AG14: 912 | AH14: 3711 | AI14: 1199 | AJ14: 1278 | AK14: 1208 | AL14: 1115 | AM14: 4801 | AN14: 1139 | AO14: 1254 | AP14: 1263 | AQ14: 1164 | AR14: 4820 | AS14: 1203 | AT14: 1142 | AU14: 1263 | AV14: 1233 | AW14: 4842 | AX14: 1247 | AY14: 1406 | AZ14: 1402 | BA14: 1346 | BB14: 5401 | BC14: 1387 | BD14: 1446 | BE14: 1397 | BF14: 1243 | BG14: 5473 | BH14: 1311 | BI14: 1421 | BJ14: 1467 | BK14: 1345 | BL14: 5543 | BM14: 1392 | BN14: 1559 | BO14: 1605 | BP14: 1481 | BQ14: 6037 | BR14: 1545 | BS14: 1576 | BT14: 1581 | BU14: 1459 | BV14: 6161 | BW14: 1513 | BX14: 1709 | BY14: =BY12*BY11 -> 1712.223 | BZ14: =BZ12*BZ11 -> 1561.13 | CA14: =SUM(BW14,BX14,BY14,BZ14) -> 6495.353 | CB14: =CB12*CB11 -> 6820.1206 | CC14: =CC12*CC11 -> 7127.0261 | CD14: =CD12*CD11 -> 7412.1071 | CE14: =CE12*CE11 -> 7671.5309 | CH14: =IFERROR((CE14/BV14)^(1/5)-1,"n/m") -> 0.044831279 | CI14: =IFERROR((BV14/AW14)^(1/5)-1,"n/m") -> 0.049361883 | CJ14: =IFERROR((BV14/X14)^(1/10)-1,"n/m") -> 0.054382995 | CK14: =IFERROR((BV14/C14)^(1/19)-1,"n/m") -> 0.030832645 | CN14: FY26 net capital expenditures ($m) | CO14: 400 | CP14: 375 | CQ14: 350 | CR14: Guidance $350–400m (Q2-26 release); 1H/26 net capex $158.0m.
B15: LTL weight per shipment (lbs) | C15: 1120.4663 | D15: 1101.626 | E15: 1101.6393 | F15: 1081.5184 | G15: 1113.6115 | H15: 1137.3516 | I15: 1169.1819 | J15: 1179 | K15: 1163 | L15: 1159 | M15: 1191 | N15: 1172.8435 | O15: 1195 | P15: 1179 | Q15: 1165 | R15: 1159 | S15: 1174 | T15: 1147 | U15: 1141 | V15: 1134 | W15: 1125 | X15: 1137 | Y15: 1118 | Z15: 1121 | AA15: 1114 | AB15: 1118 | AC15: 1118 | AD15: 1101 | AE15: 1118 | AF15: 1120 | AG15: 1114 | AH15: 1113 | AI15: 1355 | AJ15: 1370 | AK15: 1357 | AL15: 1322 | AM15: 1352 | AN15: 1308 | AO15: 1298 | AP15: 1302 | AQ15: 1297 | AR15: 1301 | AS15: 1331 | AT15: 1309 | AU15: 1289 | AV15: 1327 | AW15: 1314 | AX15: 1366 | AY15: 1397 | AZ15: 1400 | BA15: 1426 | BB15: 1397 | BC15: 1414 | BD15: 1412 | BE15: 1431 | BF15: 1433 | BG15: 1422 | BH15: 1439 | BI15: 1443 | BJ15: 1360 | BK15: 1314 | BL15: 1386 | BM15: 1321 | BN15: 1340 | BO15: 1349 | BP15: 1362 | BQ15: 1343 | BR15: 1424 | BS15: 1394 | BT15: 1355 | BU15: 1348 | BV15: 1380 | BW15: 1380 | BX15: 1448 | BY15: =BT15*(1+BY16) -> 1452.56 | BZ15: =BU15*(1+BZ16) -> 1415.4 | CA15: =IFERROR(CA14*2000/CA17,"") -> 1424.9749 | CB15: =CA15*(1+CB16) -> 1439.2247 | CC15: =CB15*(1+CC16) -> 1446.4208 | CD15: =CC15*(1+CD16) -> 1446.4208 | CE15: =CD15*(1+CE16) -> 1446.4208 | CN15: Q4/26E DOE diesel ($/gal) | CO15: 6.25 | CP15: 6.25 | CQ15: 6.25 | CR15: Late-Sep-26 weekly DOE $6.38 (record $6.53 on 21-Sep); held near spot in all cases (fuel is a pass-through lever, not a scenario call).
B16: Weight per shipment y/y % | D16: =IF(AND(ISNUMBER(D15),ISNUMBER(C15)),IFERROR(D15/C15-1,""),"") -> -0.0168147 | E16: =IF(AND(ISNUMBER(E15),ISNUMBER(D15)),IFERROR(E15/D15-1,""),"") -> 1.2098482e-05 | F16: =IF(AND(ISNUMBER(F15),ISNUMBER(E15)),IFERROR(F15/E15-1,""),"") -> -0.018264586 | G16: =IF(AND(ISNUMBER(G15),ISNUMBER(F15)),IFERROR(G15/F15-1,""),"") -> 0.029674156 | H16: =IF(AND(ISNUMBER(H15),ISNUMBER(G15)),IFERROR(H15/G15-1,""),"") -> 0.021318139 | I16: =IF(AND(ISNUMBER(I15),ISNUMBER(H15)),IFERROR(I15/H15-1,""),"") -> 0.0279863 | N16: =IF(AND(ISNUMBER(N15),ISNUMBER(I15)),IFERROR(N15/I15-1,""),"") -> 0.0031317284 | O16: =IF(AND(ISNUMBER(O15),ISNUMBER(J15)),IFERROR(O15/J15-1,""),"") -> 0.013570823 | P16: =IF(AND(ISNUMBER(P15),ISNUMBER(K15)),IFERROR(P15/K15-1,""),"") -> 0.013757524 | Q16: =IF(AND(ISNUMBER(Q15),ISNUMBER(L15)),IFERROR(Q15/L15-1,""),"") -> 0.0051768766 | R16: =IF(AND(ISNUMBER(R15),ISNUMBER(M15)),IFERROR(R15/M15-1,""),"") -> -0.026868178 | S16: =IF(AND(ISNUMBER(S15),ISNUMBER(N15)),IFERROR(S15/N15-1,""),"") -> 0.00098610733 | T16: =IF(AND(ISNUMBER(T15),ISNUMBER(O15)),IFERROR(T15/O15-1,""),"") -> -0.040167364 | U16: =IF(AND(ISNUMBER(U15),ISNUMBER(P15)),IFERROR(U15/P15-1,""),"") -> -0.032230704 | ... BX16: =IF(AND(ISNUMBER(BX15),ISNUMBER(BS15)),IFERROR(BX15/BS15-1,""),"") -> 0.038737446 | BY16: =BY61 -> 0.072 | BZ16: =CHOOSE(MATCH($CF$2,{"Bull","Base","Bear"},0),$CO$19,$CP$19,$CQ$19) -> 0.05 | CA16: =IF(AND(ISNUMBER(CA15),ISNUMBER(BV15)),IFERROR(CA15/BV15-1,""),"") -> 0.032590536 | CB16: =CHOOSE(MATCH($CF$2,{"Bull","Base","Bear"},0),$CO$46,$CP$46,$CQ$46) -> 0.01 | CC16: =CHOOSE(MATCH($CF$2,{"Bull","Base","Bear"},0),$CO$47,$CP$47,$CQ$47) -> 0.005 | CD16: =CHOOSE(MATCH($CF$2,{"Bull","Base","Bear"},0),$CO$48,$CP$48,$CQ$48) -> 0 | CE16: =CHOOSE(MATCH($CF$2,{"Bull","Base","Bear"},0),$CO$49,$CP$49,$CQ$49) -> 0 | CF16: Q3/26E = QTD +7.2%; heavier mix (customer/industrial mix initiatives) lowers rev/cwt — see mix effect below. | CN16: Q4/26E LTL tonnage/workday y/y | CO16: 0.09 | CP16: 0.07 | CQ16: 0.05 | CR16: QTD Jul–Aug +8.3%; Aug +8.7%. Comparison eases (Q4/25 tonnage/day −1.5%).
B17: LTL shipments (000s) | C17: 6176 | D17: 6888 | E17: 6710 | F17: 6428 | G17: 6399 | H17: 6487 | I17: 6295 | J17: 1520 | K17: 1642 | L17: 1608 | M17: 1490 | N17: 6260 | O17: 1586 | P17: 1732 | Q17: 1730 | R17: 1597 | S17: 6646 | T17: 1542 | U17: 1683 | V17: 1658 | W17: 1499 | X17: 6381 | Y17: 1553 | Z17: 1639 | AA17: 1638 | AB17: 1506 | AC17: 6335 | AD17: 1607 | AE17: 1760 | AF17: 1662 | AG17: 1636 | AH17: 6666 | AI17: 1770 | AJ17: 1866 | AK17: 1780 | AL17: 1687 | AM17: 7103 | AN17: 1741 | AO17: 1933 | AP17: 1941 | AQ17: 1794 | AR17: 7409 | AS17: 1809 | AT17: 1745 | AU17: 1959 | AV17: 1859 | AW17: 7371 | AX17: 1826 | AY17: 2012 | AZ17: 2004 | BA17: 1888 | BB17: 7730 | BC17: 1962 | BD17: 2048 | BE17: 1954 | BF17: 1734 | BG17: 7697 | BH17: 1822 | BI17: 1970 | BJ17: 2158 | BK17: 2047 | BL17: 7997 | BM17: 2108 | BN17: 2327 | BO17: 2379 | BP17: 2174 | BQ17: 8988 | BR17: 2170 | BS17: 2261 | BT17: 2333 | BU17: 2164 | BV17: 8929 | BW17: 2192 | BX17: 2361 | BY17: =IFERROR(BY14*2000/BY15,"") -> 2357.5246 | BZ17: =IFERROR(BZ14*2000/BZ15,"") -> 2205.9206 | CA17: =SUM(BW17,BX17,BY17,BZ17) -> 9116.4452 | CB17: =IFERROR(CB14*2000/CB15,"") -> 9477.4926 | CC17: =IFERROR(CC14*2000/CC15,"") -> 9854.7062 | CD17: =IFERROR(CD14*2000/CD15,"") -> 10248.894 | CE17: =IFERROR(CE14*2000/CE15,"") -> 10607.606 | CF17: Forecast shipments = tonnage × 2,000 ÷ weight per shipment. | CH17: =IFERROR((CE17/BV17)^(1/5)-1,"n/m") -> 0.035053765 | CI17: =IFERROR((BV17/AW17)^(1/5)-1,"n/m") -> 0.039095065 | CJ17: =IFERROR((BV17/X17)^(1/10)-1,"n/m") -> 0.034168744 | CK17: =IFERROR((BV17/C17)^(1/19)-1,"n/m") -> 0.019591206 | CN17: Q3/26E core price y/y (before weight mix) | CO17: 0.04 | CP17: 0.035 | CQ17: 0.03 | CR17: 7.1% GRI (early Jul-26) + renewals +10.7%; core yield ~+3% in Q2 after mix.
B18: LTL shipments per workday (000s) | C18: =IF(AND(ISNUMBER(C17),ISNUMBER(C11)),IFERROR(C17/C11,""),"") -> 24.507937 | D18: =IF(AND(ISNUMBER(D17),ISNUMBER(D11)),IFERROR(D17/D11,""),"") -> 27.225296 | E18: =IF(AND(ISNUMBER(E17),ISNUMBER(E11)),IFERROR(E17/E11,""),"") -> 26.417323 | F18: =IF(AND(ISNUMBER(F17),ISNUMBER(F11)),IFERROR(F17/F11,""),"") -> 25.407115 | G18: =IF(AND(ISNUMBER(G17),ISNUMBER(G11)),IFERROR(G17/G11,""),"") -> 25.392857 | H18: =IF(AND(ISNUMBER(H17),ISNUMBER(H11)),IFERROR(H17/H11,""),"") -> 25.640316 | I18: =IF(AND(ISNUMBER(I17),ISNUMBER(I11)),IFERROR(I17/I11,""),"") -> 24.881423 | J18: =IF(AND(ISNUMBER(J17),ISNUMBER(J11)),IFERROR(J17/J11,""),"") -> 24.126984 | ... CE18: =IF(AND(ISNUMBER(CE17),ISNUMBER(CE11)),IFERROR(CE17/CE11,""),"") -> 41.927295 | CN18: Q4/26E core price y/y (before weight mix) | CO18: 0.05 | CP18: 0.04 | CQ18: 0.03
B19: LTL shipments per workday y/y % | D19: =IF(AND(ISNUMBER(D18),ISNUMBER(C18)),IFERROR(D18/C18-1,""),"") -> 0.11087673 | E19: =IF(AND(ISNUMBER(E18),ISNUMBER(D18)),IFERROR(E18/D18-1,""),"") -> -0.029677312 | F19: =IF(AND(ISNUMBER(F18),ISNUMBER(E18)),IFERROR(F18/E18-1,""),"") -> -0.03824037 | G19: =IF(AND(ISNUMBER(G18),ISNUMBER(F18)),IFERROR(G18/F18-1,""),"") -> -0.00056116099 | H19: =IF(AND(ISNUMBER(H18),ISNUMBER(G18)),IFERROR(H18/G18-1,""),"") -> 0.0097452233 | I19: =IF(AND(ISNUMBER(I18),ISNUMBER(H18)),IFERROR(I18/H18-1,""),"") -> -0.029597657 | N19: =IF(AND(ISNUMBER(N18),ISNUMBER(I18)),IFERROR(N18/I18-1,""),"") -> -0.0055599682 | O19: =IF(AND(ISNUMBER(O18),ISNUMBER(J18)),IFERROR(O18/J18-1,""),"") -> 0.043421053 | P19: =IF(AND(ISNUMBER(P18),ISNUMBER(K18)),IFERROR(P18/K18-1,""),"") -> 0.054811206 | Q19: =IF(AND(ISNUMBER(Q18),ISNUMBER(L18)),IFERROR(Q18/L18-1,""),"") -> 0.075870647 | R19: =IF(AND(ISNUMBER(R18),ISNUMBER(M18)),IFERROR(R18/M18-1,""),"") -> 0.071812081 | S19: =IF(AND(ISNUMBER(S18),ISNUMBER(N18)),IFERROR(S18/N18-1,""),"") -> 0.061661342 | T19: =IF(AND(ISNUMBER(T18),ISNUMBER(O18)),IFERROR(T18/O18-1,""),"") -> -0.027742749 | U19: =IF(AND(ISNUMBER(U18),ISNUMBER(P18)),IFERROR(U18/P18-1,""),"") -> -0.028290993 | ... CA19: =IF(AND(ISNUMBER(CA18),ISNUMBER(BV18)),IFERROR(CA18/BV18-1,""),"") -> 0.020992859 | CB19: =IF(AND(ISNUMBER(CB18),ISNUMBER(CA18)),IFERROR(CB18/CA18-1,""),"") -> 0.03960396 | CC19: =IF(AND(ISNUMBER(CC18),ISNUMBER(CB18)),IFERROR(CC18/CB18-1,""),"") -> 0.039800995 | CD19: =IF(AND(ISNUMBER(CD18),ISNUMBER(CC18)),IFERROR(CD18/CC18-1,""),"") -> 0.04 | CE19: =IF(AND(ISNUMBER(CE18),ISNUMBER(CD18)),IFERROR(CE18/CD18-1,""),"") -> 0.035 | CF19: Check vs QTD Jul–Aug shipments/workday +1.0% (8-K 3-Sep-26). | CN19: Q4/26E weight per shipment y/y | CO19: 0.05 | CP19: 0.05 | CQ19: 0.05 | CR19: QTD +7.2%; laps the start of the weight increase from Q4/25–Q1/26.
B20: Memo: company-reported LTL tonnage/workday change % (release, like-for-like basis) | J20: -0.020212893 | K20: -0.015463918 | L20: -0.0006127451 | M20: 0.028968714 | O20: 0.056919643 | P20: 0.069109948 | Q20: 0.081545064 | R20: 0.042792793 | S20: 0.063215259 | T20: -0.066525871 | U20: -0.059745348 | V20: -0.067460317 | W20: -0.088552916 | X20: -0.0702204 | Y20: -0.033441742 | Z20: -0.042708333 | AA20: -0.028723404 | AB20: 0.013984927 | AC20: -0.023980154 | AD20: 0.019585253 | AE20: 0.070729053 | AF20: 0.03590118 | AG20: 0.083135392 | AH20: 0.052167803 | AI20: 0.12265918 | AJ20: 0.076663858 | AK20: 0.072824156 | AL20: -0.0063259701 | AM20: 0.066226024 | AN20: -0.034962998 | AO20: -0.018779343 | AP20: 0.029193398 | AQ20: 0.043946188 | AR20: 0.0039575089 | AS20: 0.039686677 | AT20: -0.089314195 | AU20: 0 | AV20: 0.059278351 | AW20: 0.00060933773 | AX20: 0.053028804 | AY20: 0.23117338 | AZ20: 0.11005542 | BA20: 0.10954223 | BB20: 0.12430093 | BC20: 0.094890237 | BD20: 0.028449502 | BE20: -0.0035663338 | BF20: -0.076523031 | BG20: 0.0093256043 | BH20: -0.054794521 | BI20: -0.017289073 | BJ20: 0.066775744 | BK20: 0.082059533 | BL20: 0.016809068 | BM20: 0.061784897 | BN20: 0.097114708 | BO20: 0.076974693 | BP20: 0.083355318 | BQ20: 0.080545655 | BR20: 0.12753147 | BS20: 0.010904426 | BT20: -0.014953271 | BU20: -0.014854828 | BV20: 0.024573758 | BW20: -0.020711974 | BX20: 0.084390863 | CF20: From the prior-year column of each release (restated basis) — use for y/y across the Q1/18 statistics-basis change. | CN20: 2H/26 share repurchases ($m) | CO20: 50 | CP20: 0 | CQ20: 0 | CR20: No active programme (last buyback 2007); leverage-floor plug applies from 2027E.
B21: Memo: company-reported LTL shipments/workday change % | J21: -0.034317083 | K21: -0.0084541063 | L21: 0.0056385006 | M21: 0.016371078 | O21: 0.043421053 | P21: 0.054811206 | Q21: 0.075870647 | R21: 0.071812081 | S21: 0.061661342 | T21: -0.027742749 | U21: -0.028290993 | V21: -0.041618497 | W21: -0.061365059 | X21: -0.039873608 | Y21: -0.0086028696 | Z21: -0.026143791 | AA21: -0.012062726 | AB21: 0.021139776 | AC21: -0.0072089014 | AD21: 0.03477141 | AE21: 0.073825503 | AF21: 0.030757602 | AG21: 0.086321381 | AH21: 0.056425001 | AI21: 0.083894672 | AJ21: 0.043624161 | AK21: 0.053254438 | AL21: -0.0019300526 | AM21: 0.044269358 | AN21: -0.00077123128 | AO21: 0.035905681 | AP21: 0.073411166 | AQ21: 0.0634262 | AR21: 0.043080389 | AS21: 0.022822731 | AT21: -0.097258148 | AU21: 0.0092735703 | AV21: 0.036231884 | AW21: -0.0090457127 | AX21: 0.025419639 | AY21: 0.1530086 | AZ21: 0.022970904 | BA21: 0.032248962 | BB21: 0.057027433 | BC21: 0.057690991 | BD21: 0.017892644 | BE21: -0.0249501 | BF21: -0.081567797 | BG21: -0.0082047768 | BH21: -0.071355759 | BI21: -0.038085938 | BJ21: 0.12193141 | BK21: 0.1805075 | BL21: 0.043099146 | BM21: 0.15697036 | BN21: 0.18121827 | BO21: 0.085184488 | BP21: 0.044912303 | BQ21: 0.1150717 | BR21: 0.045751634 | BS21: -0.028362699 | BT21: -0.019335855 | BU21: -0.004599816 | BV21: -0.0026376847 | BW21: 0.010138249 | BX21: 0.044228218 | CN21: FY26 point estimates & model constants (all cases) | CO21: Bull | CP21: Base | CQ21: Bear
B22: LTL average length of haul (miles) | J22: 734 | K22: 743 | L22: 742 | M22: 746 | N22: 741.27188 | O22: 753 | P22: 759 | Q22: 766 | R22: 773 | S22: 763 | T22: 773 | U22: 778 | V22: 773 | W22: 775 | X22: 775 | Y22: 781 | Z22: 786 | AA22: 789 | AB22: 792 | AC22: 787 | AD22: 797 | AE22: 806 | AF22: 813 | AG22: 828 | AH22: 811 | AI22: 837 | AJ22: 837 | AK22: 835 | AL22: 837 | AM22: 837 | AN22: 831 | AO22: 841 | AP22: 842 | AQ22: 846 | AR22: 840 | AS22: 848 | AT22: 876 | AU22: 893 | AV22: 898 | AW22: 879 | AX22: 904 | AY22: 911 | AZ22: 915 | BA22: 924 | BB22: 913 | BC22: 915 | BD22: 910 | BE22: 897 | BF22: 892 | BG22: 904 | BH22: 892 | BI22: 892 | BJ22: 896 | BK22: 895 | BL22: 894 | BM22: 888 | BN22: 888 | BO22: 890 | BP22: 898 | BQ22: 891 | BR22: 905 | BS22: 893 | BT22: 894 | BU22: 897 | BV22: 897 | BW22: 890 | BX22: 888 | CN22: FY25 adjusted operating ratio (base for the FY26 improvement guide) | CP22: 0.896 | CR22: Q4-25 release: adjusted OR 89.6% (GAAP 89.1% incl. $14.5m net real-estate gain).
CN23: Q3/Q4-26E effective tax rate | CP23: 0.245 | CR23: 1H/26 24.3%; Q2/26 24.9%.
B24: LTL yield — core price (revenue per hundredweight excluding fuel surcharge) | CF24: CORE YIELD — modelling logic | CN24: Q3/Q4-26E D&A sequential growth | CP24: 0.01 | CR24: Q2/26 D&A $64.2m (+2.6% y/y).
B25: LTL revenue/cwt excl. fuel surcharge — as reported ($) | C25: 10.264416 | AS25: 15.78 | AT25: 16.01 | AU25: 16.61 | AV25: 16.57 | AW25: 16.27 | AX25: 16.68 | AY25: 16.92 | AZ25: 18.31 | BA25: 18.89 | BB25: 17.72 | BC25: 19.28 | BD25: 19.44 | BE25: 19.74 | BF25: 20.11 | BG25: 19.63 | BH25: 20.15 | BI25: 19.96 | BJ25: 21.39 | BK25: 22.47 | BL25: 20.99 | BM25: 22.26 | BN25: 21.69 | BO25: 21.75 | BP25: 21.96 | BQ25: 21.9 | BR25: 21.12 | BS25: 21.42 | BT25: 21.72 | BU25: 22.07 | BV25: 21.58 | BW25: 21.52 | BX25: 20.94 | CF25: Reported in releases 2006–Q3/07 and from 2020 (2020 from the prior-year columns of 2021 releases). | CN25: Fuel-surcharge table: base diesel price ($/gal) | CP25: 1.25 | CR25: Saia LTL fuel-surcharge table mechanics (published carrier-table summaries; saia.com not reachable from this environment — verify vs current Saia tariff).
B26: LTL revenue/cwt excl. fuel surcharge — model ($) | C26: =IF(ISNUMBER(C25),C25,IF(AND(ISNUMBER(C40),ISNUMBER(C43)),C40*(1-C43),"")) -> 10.264416 | D26: =IF(ISNUMBER(D25),D25,IF(AND(ISNUMBER(D40),ISNUMBER(D43)),D40*(1-D43),"")) | E26: =IF(ISNUMBER(E25),E25,IF(AND(ISNUMBER(E40),ISNUMBER(E43)),E40*(1-E43),"")) | F26: =IF(ISNUMBER(F25),F25,IF(AND(ISNUMBER(F40),ISNUMBER(F43)),F40*(1-F43),"")) | G26: =IF(ISNUMBER(G25),G25,IF(AND(ISNUMBER(G40),ISNUMBER(G43)),G40*(1-G43),"")) -> 10.288393 | H26: =IF(ISNUMBER(H25),H25,IF(AND(ISNUMBER(H40),ISNUMBER(H43)),H40*(1-H43),"")) -> 10.772551 | I26: =IF(ISNUMBER(I25),I25,IF(AND(ISNUMBER(I40),ISNUMBER(I43)),I40*(1-I43),"")) -> 11.425171 | J26: =IF(ISNUMBER(J25),J25,IF(AND(ISNUMBER(J40),ISNUMBER(J43)),J40*(1-J43),"")) -> 11.71268 | ... BX26: =IF(ISNUMBER(BX25),BX25,IF(AND(ISNUMBER(BX40),ISNUMBER(BX43)),BX40*(1-BX43),"")) -> 20.94 | BY26: =BT26*(1+BY27) -> 21.30732 | BZ26: =BU26*(1+BZ27) -> 22.125175 | CA26: =IFERROR(CA46*1000/(CA14*20),"") -> 21.456783 | CB26: =CA26*(1+CB27) -> 22.368696 | CC26: =CB26*(1+CC27) -> 23.403248 | CD26: =CC26*(1+CD27) -> 24.456394 | CE26: =CD26*(1+CE27) -> 25.556932 | CF26: Historical: reported where disclosed, else derived = all-in rev/cwt × (1 − company fuel-surcharge % of revenue) (≈ ±1% vs reported on overlap years). FORECAST CORE PRICE INPUT. | CH26: =IFERROR((CE26/BV26)^(1/5)-1,"n/m") -> 0.034407011 | CI26: =IFERROR((BV26/AW26)^(1/5)-1,"n/m") -> 0.058114772 | CJ26: =IFERROR((BV26/X26)^(1/10)-1,"n/m") -> 0.046994365 | CK26: =IFERROR((BV26/C26)^(1/19)-1,"n/m") -> 0.039884525 | CN26: Fuel-surcharge table: price step ($/gal) | CP26: 0.05
B27: Rev/cwt ex-fuel y/y % | D27: =IF(AND(ISNUMBER(D26),ISNUMBER(C26)),IFERROR(D26/C26-1,""),"") | E27: =IF(AND(ISNUMBER(E26),ISNUMBER(D26)),IFERROR(E26/D26-1,""),"") | F27: =IF(AND(ISNUMBER(F26),ISNUMBER(E26)),IFERROR(F26/E26-1,""),"") | G27: =IF(AND(ISNUMBER(G26),ISNUMBER(F26)),IFERROR(G26/F26-1,""),"") | H27: =IF(AND(ISNUMBER(H26),ISNUMBER(G26)),IFERROR(H26/G26-1,""),"") -> 0.047058669 | I27: =IF(AND(ISNUMBER(I26),ISNUMBER(H26)),IFERROR(I26/H26-1,""),"") -> 0.060581813 | N27: =IF(AND(ISNUMBER(N26),ISNUMBER(I26)),IFERROR(N26/I26-1,""),"") -> 0.043820315 | O27: =IF(AND(ISNUMBER(O26),ISNUMBER(J26)),IFERROR(O26/J26-1,""),"") -> 0.026988699 | P27: =IF(AND(ISNUMBER(P26),ISNUMBER(K26)),IFERROR(P26/K26-1,""),"") -> 0.044951879 | Q27: =IF(AND(ISNUMBER(Q26),ISNUMBER(L26)),IFERROR(Q26/L26-1,""),"") -> 0.043328748 | R27: =IF(AND(ISNUMBER(R26),ISNUMBER(M26)),IFERROR(R26/M26-1,""),"") -> 0.070823375 | S27: =IF(AND(ISNUMBER(S26),ISNUMBER(N26)),IFERROR(S26/N26-1,""),"") -> 0.046186663 | T27: =IF(AND(ISNUMBER(T26),ISNUMBER(O26)),IFERROR(T26/O26-1,""),"") -> 0.10097607 | U27: =IF(AND(ISNUMBER(U26),ISNUMBER(P26)),IFERROR(U26/P26-1,""),"") -> 0.097183887 | ... BX27: =IF(AND(ISNUMBER(BX26),ISNUMBER(BS26)),IFERROR(BX26/BS26-1,""),"") -> -0.022408964 | BY27: =BY28-BY16*BY29 -> -0.019 | BZ27: =BZ28-BZ16*BZ29 -> 0.0025 | CA27: =IF(AND(ISNUMBER(CA26),ISNUMBER(BV26)),IFERROR(CA26/BV26-1,""),"") -> -0.0057097919 | CB27: =CB28-CB16*CB29 -> 0.0425 | CC27: =CC28-CC16*CC29 -> 0.04625 | CD27: =CD28-CD16*CD29 -> 0.045 | CE27: =CE28-CE16*CE29 -> 0.045 | CF27: Forecast = core price (contract renewals + GRI) − weight-per-shipment mix effect × elasticity. | CN27: Fuel-surcharge table: surcharge increment per step | CP27: 0.005
B28: Core price y/y % before weight-mix (contract renewals, GRI) — input | BY28: =CHOOSE(MATCH($CF$2,{"Bull","Base","Bear"},0),$CO$17,$CP$17,$CQ$17) -> 0.035 | BZ28: =CHOOSE(MATCH($CF$2,{"Bull","Base","Bear"},0),$CO$18,$CP$18,$CQ$18) -> 0.04 | CB28: =CHOOSE(MATCH($CF$2,{"Bull","Base","Bear"},0),$CO$41,$CP$41,$CQ$41) -> 0.05 | CC28: =CHOOSE(MATCH($CF$2,{"Bull","Base","Bear"},0),$CO$42,$CP$42,$CQ$42) -> 0.05 | CD28: =CHOOSE(MATCH($CF$2,{"Bull","Base","Bear"},0),$CO$43,$CP$43,$CQ$43) -> 0.045 | CE28: =CHOOSE(MATCH($CF$2,{"Bull","Base","Bear"},0),$CO$44,$CP$44,$CQ$44) -> 0.045 | CF28: Q2-26 call: core yield ex-fuel ~+3% after mix; contractual renewals +10.7% (Q2/26); 7.1% GRI from early Jul-26. | CN28: Fuel pass-through into FOS (Δ fuel cost per $1 Δ surcharge revenue) | CP28: 0.31 | CR28: Calibrated: Q2/26 vs Q2/25 FOS +$37.1m vs revenue ex-fuel +6.5% and fuel-surcharge revenue +$94m.
B29: Weight-mix elasticity of rev/cwt (−Δ rev/cwt per +1% weight/shipment) | BY29: =$CP$29 -> 0.75 | BZ29: =$CP$29 -> 0.75 | CB29: =$CP$29 -> 0.75 | CC29: =$CP$29 -> 0.75 | CD29: =$CP$29 -> 0.75 | CE29: =$CP$29 -> 0.75 | CF29: Heavier shipments carry lower rev/cwt. Q2/26: weight +3.9%, rev/cwt ex-fuel −2.2% with ~+3% core → implied ~1.3x incl. LOH/LA mix; 0.75x assumed. | CN29: Weight-mix elasticity of rev/cwt | CP29: 0.75
B30: Memo: company-reported rev/cwt ex-fuel change % | AX30: 0.057034221 | AY30: 0.056839475 | AZ30: 0.10234798 | BA30: 0.14001207 | BB30: 0.089121082 | BC30: 0.1558753 | BD30: 0.14893617 | BE30: 0.078099399 | BF30: 0.064584436 | BG30: 0.10778781 | BH30: 0.045124481 | BI30: 0.026748971 | BJ30: 0.083586626 | BK30: 0.11735455 | BL30: 0.069281712 | BM30: 0.10471464 | BN30: 0.086673347 | BO30: 0.016830295 | BP30: -0.022696929 | BQ30: 0.043353978 | BR30: -0.051212938 | BS30: -0.012448133 | BT30: -0.0013793103 | BU30: 0.0050091075 | BV30: -0.014611872 | BW30: 0.018939394 | BX30: -0.022408964 | CN30: Minimum cash balance ($m) | CP30: 25 | CR30: Saia runs lean cash ($19.7m at YE25) with revolver as liquidity.
B31: LTL revenue/shipment excl. fuel surcharge ($) | C31: =IF(ISNUMBER(C26),IFERROR(C26*C15/100,""),"") -> 115.00933 | D31: =IF(ISNUMBER(D26),IFERROR(D26*D15/100,""),"") | E31: =IF(ISNUMBER(E26),IFERROR(E26*E15/100,""),"") | F31: =IF(ISNUMBER(F26),IFERROR(F26*F15/100,""),"") | G31: =IF(ISNUMBER(G26),IFERROR(G26*G15/100,""),"") -> 114.57272 | H31: =IF(ISNUMBER(H26),IFERROR(H26*H15/100,""),"") -> 122.52178 | I31: =IF(ISNUMBER(I26),IFERROR(I26*I15/100,""),"") -> 133.58103 | J31: =IF(ISNUMBER(J26),IFERROR(J26*J15/100,""),"") -> 138.0925 | ... BX31: =IF(ISNUMBER(BX26),IFERROR(BX26*BX15/100,""),"") -> 303.2112 | BY31: =IFERROR(BY26*BY15/100,"") -> 309.50161 | BZ31: =IFERROR(BZ26*BZ15/100,"") -> 313.15973 | CA31: =IFERROR(CA26*CA15/100,"") -> 305.75378 | CB31: =IFERROR(CB26*CB15/100,"") -> 321.93579 | CC31: =IFERROR(CC26*CC15/100,"") -> 338.50945 | CD31: =IFERROR(CD26*CD15/100,"") -> 353.74238 | CE31: =IFERROR(CE26*CE15/100,"") -> 369.66078 | CH31: =IFERROR((CE31/BV31)^(1/5)-1,"n/m") -> 0.044178077 | CI31: =IFERROR((BV31/AW31)^(1/5)-1,"n/m") -> 0.068536894 | CJ31: =IFERROR((BV31/X31)^(1/10)-1,"n/m") -> 0.067471297 | CK31: =IFERROR((BV31/C31)^(1/19)-1,"n/m") -> 0.051349797 | CN31: Share-price appreciation % p.a. (buyback pricing) | CP31: 0.07
B33: Fuel surcharge — DOE diesel × Saia fuel-surcharge table × capture ratio | CF33: FUEL SURCHARGE — modelling logic | CN33: Minimum net debt / Adjusted EBITDA (x) — buyback floor 2026E+ | CO33: 0.5 | CP33: 0 | CQ33: 0 | CR33: Saia is under-levered (net debt ~$16m at Q2/26); Base returns surplus cash only once net debt reaches zero; Bull re-levers to 0.5x.
B34: DOE U.S. on-highway diesel — average of weekly prices ($/gal) | C34: 2.705 | D34: 2.885 | E34: 3.803 | F34: 2.47 | G34: 2.99 | H34: 3.85 | I34: 3.97 | J34: 4.03 | K34: 3.87 | L34: 3.92 | M34: =4*N34-J34-K34-L34 -> 3.86 | N34: 3.92 | O34: 3.96 | P34: 3.94 | Q34: 3.83 | R34: =4*S34-O34-P34-Q34 -> 3.59 | S34: 3.83 | T34: 2.92 | U34: 2.85 | V34: 2.63 | W34: =4*X34-T34-U34-V34 -> 2.44 | X34: 2.71 | Y34: 2.07 | Z34: 2.3 | AA34: 2.38 | AB34: =4*AC34-Y34-Z34-AA34 -> 2.45 | AC34: 2.3 | AD34: 2.57 | AE34: 2.55 | AF34: 2.63 | AG34: =4*AH34-AD34-AE34-AF34 -> 2.85 | AH34: 2.65 | AI34: 3.02 | AJ34: 3.19 | AK34: 3.24 | AL34: =4*AM34-AI34-AJ34-AK34 -> 3.27 | AM34: 3.18 | AN34: 3.02 | AO34: 3.12 | AP34: 3.02 | AQ34: =4*AR34-AN34-AO34-AP34 -> 3.08 | AR34: 3.06 | AS34: 2.92 | AT34: 2.44 | AU34: 2.43 | AV34: =4*AW34-AS34-AT34-AU34 -> 2.45 | AW34: 2.56 | AX34: 2.91 | AY34: 3.21 | AZ34: 3.36 | BA34: =4*BB34-AX34-AY34-AZ34 -> 3.68 | BB34: 3.29 | BC34: 4.36 | BD34: 5.53 | BE34: 5.09 | BF34: =4*BG34-BC34-BD34-BE34 -> 5.06 | BG34: 5.01 | BH34: 4.4 | BI34: 3.94 | BJ34: 4.27 | BK34: =4*BL34-BH34-BI34-BJ34 -> 4.19 | BL34: 4.2 | BM34: 3.96 | BN34: 3.86 | BO34: 3.69 | BP34: =4*BQ34-BM34-BN34-BO34 -> 3.53 | BQ34: 3.76 | BR34: 3.63 | BS34: 3.56 | BT34: 3.76 | BU34: =4*BV34-BR34-BS34-BT34 -> 3.69 | BV34: 3.66 | BW34: 4.12 | BX34: 5.33 | BY34: 5.56 | BZ34: =CHOOSE(MATCH($CF$2,{"Bull","Base","Bear"},0),$CO$15,$CP$15,$CQ$15) -> 6.25 | CA34: =AVERAGE(BW34,BX34,BY34,BZ34) -> 5.315 | CB34: =CHOOSE(MATCH($CF$2,{"Bull","Base","Bear"},0),$CO$51,$CP$51,$CQ$51) -> 5.25 | CC34: =CHOOSE(MATCH($CF$2,{"Bull","Base","Bear"},0),$CO$52,$CP$52,$CQ$52) -> 4.75 | CD34: =CHOOSE(MATCH($CF$2,{"Bull","Base","Bear"},0),$CO$53,$CP$53,$CQ$53) -> 4.5 | CE34: =CHOOSE(MATCH($CF$2,{"Bull","Base","Bear"},0),$CO$54,$CP$54,$CQ$54) -> 4.5 | CF34: Q1–Q3 & FY per Knight-Swift 10-Qs/10-Ks (weekly DOE average; Heartland & Marten 10-Qs cross-check); Q4 = 4×FY − Q1–Q3. 2006–08 EIA annual averages. Q3/26 $5.56 = 13-week EIA average (Jul $4.955 matches Heartland 10-Q $4.96).
B35: Diesel y/y % | D35: =IF(AND(ISNUMBER(D34),ISNUMBER(C34)),IFERROR(D34/C34-1,""),"") -> 0.066543438 | E35: =IF(AND(ISNUMBER(E34),ISNUMBER(D34)),IFERROR(E34/D34-1,""),"") -> 0.31819757 | F35: =IF(AND(ISNUMBER(F34),ISNUMBER(E34)),IFERROR(F34/E34-1,""),"") -> -0.35051275 | G35: =IF(AND(ISNUMBER(G34),ISNUMBER(F34)),IFERROR(G34/F34-1,""),"") -> 0.21052632 | H35: =IF(AND(ISNUMBER(H34),ISNUMBER(G34)),IFERROR(H34/G34-1,""),"") -> 0.28762542 | I35: =IF(AND(ISNUMBER(I34),ISNUMBER(H34)),IFERROR(I34/H34-1,""),"") -> 0.031168831 | N35: =IF(AND(ISNUMBER(N34),ISNUMBER(I34)),IFERROR(N34/I34-1,""),"") -> -0.012594458 | O35: =IF(AND(ISNUMBER(O34),ISNUMBER(J34)),IFERROR(O34/J34-1,""),"") -> -0.017369727 | P35: =IF(AND(ISNUMBER(P34),ISNUMBER(K34)),IFERROR(P34/K34-1,""),"") -> 0.018087855 | Q35: =IF(AND(ISNUMBER(Q34),ISNUMBER(L34)),IFERROR(Q34/L34-1,""),"") -> -0.022959184 | R35: =IF(AND(ISNUMBER(R34),ISNUMBER(M34)),IFERROR(R34/M34-1,""),"") -> -0.069948187 | S35: =IF(AND(ISNUMBER(S34),ISNUMBER(N34)),IFERROR(S34/N34-1,""),"") -> -0.022959184 | T35: =IF(AND(ISNUMBER(T34),ISNUMBER(O34)),IFERROR(T34/O34-1,""),"") -> -0.26262626 | U35: =IF(AND(ISNUMBER(U34),ISNUMBER(P34)),IFERROR(U34/P34-1,""),"") -> -0.27664975 | ... CA35: =IF(AND(ISNUMBER(CA34),ISNUMBER(BV34)),IFERROR(CA34/BV34-1,""),"") -> 0.45218579 | CB35: =IF(AND(ISNUMBER(CB34),ISNUMBER(CA34)),IFERROR(CB34/CA34-1,""),"") -> -0.012229539 | CC35: =IF(AND(ISNUMBER(CC34),ISNUMBER(CB34)),IFERROR(CC34/CB34-1,""),"") -> -0.095238095 | CD35: =IF(AND(ISNUMBER(CD34),ISNUMBER(CC34)),IFERROR(CD34/CC34-1,""),"") -> -0.052631579 | CE35: =IF(AND(ISNUMBER(CE34),ISNUMBER(CD34)),IFERROR(CE34/CD34-1,""),"") -> 0 | CN35: TON (LTL tonnage per workday y/y) | CO35: 0.02 | CP35: Δ → | CQ35: -0.02 | CR35: Industrial recovery + density on the national network (33 terminals added since 2022; ~25% more doors).
B36: Fuel-surcharge table % at average diesel (Saia LTL table: base $/gal, +x% per step) | C36: =IF(ISNUMBER(C34),MAX(0,ROUNDDOWN((C34-$CP$25)/$CP$26,0)*$CP$27),"") -> 0.145 | D36: =IF(ISNUMBER(D34),MAX(0,ROUNDDOWN((D34-$CP$25)/$CP$26,0)*$CP$27),"") -> 0.16 | E36: =IF(ISNUMBER(E34),MAX(0,ROUNDDOWN((E34-$CP$25)/$CP$26,0)*$CP$27),"") -> 0.255 | F36: =IF(ISNUMBER(F34),MAX(0,ROUNDDOWN((F34-$CP$25)/$CP$26,0)*$CP$27),"") -> 0.12 | G36: =IF(ISNUMBER(G34),MAX(0,ROUNDDOWN((G34-$CP$25)/$CP$26,0)*$CP$27),"") -> 0.17 | H36: =IF(ISNUMBER(H34),MAX(0,ROUNDDOWN((H34-$CP$25)/$CP$26,0)*$CP$27),"") -> 0.26 | I36: =IF(ISNUMBER(I34),MAX(0,ROUNDDOWN((I34-$CP$25)/$CP$26,0)*$CP$27),"") -> 0.27 | J36: =IF(ISNUMBER(J34),MAX(0,ROUNDDOWN((J34-$CP$25)/$CP$26,0)*$CP$27),"") -> 0.275 | ... CE36: =IF(ISNUMBER(CE34),MAX(0,ROUNDDOWN((CE34-$CP$25)/$CP$26,0)*$CP$27),"") -> 0.325 | CF36: Table parameters in the scenario panel (current Saia LTL table: $1.25 base, +0.5% per $0.05). Saia revised its program 18-Jan-2016 (10-K); apply to 2016+ only. | CN36: 2027E | CO36: =CP36+$CO$35 -> 0.07 | CP36: 0.05 | CQ36: =CP36+$CQ$35 -> 0.03
B37: Effective fuel surcharge % of ex-fuel yield ((all-in ÷ ex-fuel rev/cwt) − 1) | C37: =IF(AND(ISNUMBER(C40),ISNUMBER(C26)),IFERROR(C40/C26-1,""),"") -> 0.14339708 | D37: =IF(AND(ISNUMBER(D40),ISNUMBER(D26)),IFERROR(D40/D26-1,""),"") | E37: =IF(AND(ISNUMBER(E40),ISNUMBER(E26)),IFERROR(E40/E26-1,""),"") | F37: =IF(AND(ISNUMBER(F40),ISNUMBER(F26)),IFERROR(F40/F26-1,""),"") | G37: =IF(AND(ISNUMBER(G40),ISNUMBER(G26)),IFERROR(G40/G26-1,""),"") -> 0.14155251 | H37: =IF(AND(ISNUMBER(H40),ISNUMBER(H26)),IFERROR(H40/H26-1,""),"") -> 0.20048019 | I37: =IF(AND(ISNUMBER(I40),ISNUMBER(I26)),IFERROR(I40/I26-1,""),"") -> 0.20918984 | J37: =IF(AND(ISNUMBER(J40),ISNUMBER(J26)),IFERROR(J40/J26-1,""),"") -> 0.21065375 | ... BX37: =IF(AND(ISNUMBER(BX40),ISNUMBER(BX26)),IFERROR(BX40/BX26-1,""),"") -> 0.29799427 | BY37: =BY36*BY38 -> 0.31877415 | BZ37: =BZ36*BZ38 -> 0.37066762 | CA37: =IFERROR(CA40/CA26-1,"") -> 0.29970179 | CB37: =CB36*CB38 -> 0.2965341 | CC37: =CC36*CC38 -> 0.25946733 | CD37: =CD36*CD38 -> 0.24093395 | CE37: =CE36*CE38 -> 0.24093395 | CN37: 2028E | CO37: =CP37+$CO$35 -> 0.065 | CP37: 0.045 | CQ37: =CP37+$CQ$35 -> 0.025
B38: Capture ratio (effective ÷ table) — discounts, minimum charges, accessorials not surcharged | C38: =IF(AND(ISNUMBER(C37),ISNUMBER(C36)),IFERROR(C37/C36,""),"") -> 0.98894536 | D38: =IF(AND(ISNUMBER(D37),ISNUMBER(D36)),IFERROR(D37/D36,""),"") | E38: =IF(AND(ISNUMBER(E37),ISNUMBER(E36)),IFERROR(E37/E36,""),"") | F38: =IF(AND(ISNUMBER(F37),ISNUMBER(F36)),IFERROR(F37/F36,""),"") | G38: =IF(AND(ISNUMBER(G37),ISNUMBER(G36)),IFERROR(G37/G36,""),"") -> 0.83266183 | H38: =IF(AND(ISNUMBER(H37),ISNUMBER(H36)),IFERROR(H37/H36,""),"") -> 0.77107766 | I38: =IF(AND(ISNUMBER(I37),ISNUMBER(I36)),IFERROR(I37/I36,""),"") -> 0.7747772 | J38: =IF(AND(ISNUMBER(J37),ISNUMBER(J36)),IFERROR(J37/J36,""),"") -> 0.76601365 | ... BX38: =IF(AND(ISNUMBER(BX37),ISNUMBER(BX36)),IFERROR(BX37/BX36,""),"") -> 0.73578832 | BY38: =AVERAGE($BT$38,$BU$38,$BW$38,$BX$38) -> 0.74133524 | BZ38: =AVERAGE($BT$38,$BU$38,$BW$38,$BX$38) -> 0.74133524 | CA38: =IFERROR(CA37/CA36,"") -> 0.74000441 | CB38: =AVERAGE($BT$38,$BU$38,$BW$38,$BX$38) -> 0.74133524 | CC38: =AVERAGE($BT$38,$BU$38,$BW$38,$BX$38) -> 0.74133524 | CD38: =AVERAGE($BT$38,$BU$38,$BW$38,$BX$38) -> 0.74133524 | CE38: =AVERAGE($BT$38,$BU$38,$BW$38,$BX$38) -> 0.74133524 | CF38: Forecast = trailing-4Q average (Q3/25–Q2/26 ≈ 0.74); stable 0.69–0.77 since 2022. | CH38: =IFERROR(AVERAGE(CA38,CB38,CC38,CD38,CE38),"n/m") -> 0.74106907 | CI38: =IFERROR(AVERAGE(BB38,BG38,BL38,BQ38,BV38),"n/m") -> 0.74371411 | CJ38: =IFERROR(AVERAGE(AC38,AH38,AM38,AR38,AW38,BB38,BG38,BL38,BQ38,BV38),"n/m") -> 0.8302333 | CK38: =IFERROR(AVERAGE(C38,D38,E38,F38,G38,H38,I38,N38,S38,X38,AC38,AH38,AM38,AR38,AW38,BB38,BG38,BL38,BQ38,BV38),"n/m") -> 0.83094904 | CN38: 2029E | CO38: =CP38+$CO$35 -> 0.06 | CP38: 0.04 | CQ38: =CP38+$CQ$35 -> 0.02
B39: Fuel surcharge per cwt ($) | C39: =IF(AND(ISNUMBER(C40),ISNUMBER(C26)),C40-C26,"") -> 1.4718873 | D39: =IF(AND(ISNUMBER(D40),ISNUMBER(D26)),D40-D26,"") | E39: =IF(AND(ISNUMBER(E40),ISNUMBER(E26)),E40-E26,"") | F39: =IF(AND(ISNUMBER(F40),ISNUMBER(F26)),F40-F26,"") | G39: =IF(AND(ISNUMBER(G40),ISNUMBER(G26)),G40-G26,"") -> 1.4563478 | H39: =IF(AND(ISNUMBER(H40),ISNUMBER(H26)),H40-H26,"") -> 2.159683 | I39: =IF(AND(ISNUMBER(I40),ISNUMBER(I26)),I40-I26,"") -> 2.3900298 | J39: =IF(AND(ISNUMBER(J40),ISNUMBER(J26)),J40-J26,"") -> 2.46732 | ... BX39: =IF(AND(ISNUMBER(BX40),ISNUMBER(BX26)),BX40-BX26,"") -> 6.24 | BY39: =BY26*BY37 -> 6.7922229 | BZ39: =BZ26*BZ37 -> 8.2010859 | CA39: =IFERROR(CA47*1000/(CA14*20),"") -> 6.4306361 | CB39: =CB26*CB37 -> 6.633081 | CC39: =CC26*CC37 -> 6.0723784 | CD39: =CD26*CD37 -> 5.8923757 | CE39: =CE26*CE37 -> 6.1575326 | CN39: 2030E | CO39: =CP39+$CO$35 -> 0.055 | CP39: 0.035 | CQ39: =CP39+$CQ$35 -> 0.015
B40: LTL revenue/cwt incl. fuel surcharge ($) | C40: 11.736303 | D40: 11.983026 | E40: 12.946897 | F40: 11.420377 | G40: 11.74474 | H40: 12.932234 | I40: 13.815201 | J40: 14.18 | K40: 14.16 | L40: 14.54 | M40: 14.46 | N40: 14.333925 | O40: 14.51 | P40: 14.85 | Q40: 15.17 | R40: 15.33 | S40: 14.96 | T40: 15.17 | U40: 15.42 | V40: 15.51 | W40: 15.66 | X40: 15.44 | Y40: 15.49 | Z40: 15.73 | AA40: 16.08 | AB40: 16.45 | AC40: 15.93 | AD40: 16.68 | AE40: 16.89 | AF40: 17.36 | AG40: 17.89 | AH40: 17.2 | AI40: 15.92 | AJ40: 16.44 | AK40: 17.2 | AL40: 17.72 | AM40: 16.8 | AN40: 17.61 | AO40: 18.05 | AP40: 18.12 | AQ40: 18.38 | AR40: 18.05 | AS40: 18.16 | AT40: 17.95 | AU40: 18.59 | AV40: 18.6 | AW40: 18.33 | AX40: 19.18 | AY40: 19.84 | AZ40: 21.36 | BA40: 22.24 | BB40: 20.68 | BC40: 23.29 | BD40: 25.05 | BE40: 25.1 | BF40: 25.42 | BG40: 24.7 | BH40: 24.63 | BI40: 23.85 | BJ40: 25.87 | BK40: 27.21 | BL40: 25.38 | BM40: 26.51 | BN40: 25.75 | BO40: 25.64 | BP40: 25.73 | BQ40: 25.89 | BR40: 24.97 | BS40: 25.2 | BT40: 25.76 | BU40: 26.13 | BV40: 25.5 | BW40: 25.93 | BX40: 27.18 | BY40: =BY26+BY39 -> 28.099543 | BZ40: =BZ26+BZ39 -> 30.326261 | CA40: =IFERROR(CA48*1000/(CA14*20),"") -> 27.887419 | CB40: =CB26+CB39 -> 29.001777 | CC40: =CC26+CC39 -> 29.475627 | CD40: =CD26+CD39 -> 30.34877 | CE40: =CE26+CE39 -> 31.714465 | CF40: All-in yield = core yield + fuel surcharge per cwt; drives LTL revenue. | CH40: =IFERROR((CE40/BV40)^(1/5)-1,"n/m") -> 0.044584172 | CI40: =IFERROR((BV40/AW40)^(1/5)-1,"n/m") -> 0.068256498 | CJ40: =IFERROR((BV40/X40)^(1/10)-1,"n/m") -> 0.051451605 | CK40: =IFERROR((BV40/C40)^(1/19)-1,"n/m") -> 0.041687152 | CN40: PRICE (core rev/cwt ex-fuel y/y, before weight mix) | CO40: 0.015 | CP40: Δ → | CQ40: -0.015 | CR40: National-network service premium; pricing ahead of cost inflation (mgmt).
B41: Rev/cwt incl. fuel y/y % | D41: =IF(AND(ISNUMBER(D40),ISNUMBER(C40)),IFERROR(D40/C40-1,""),"") -> 0.021022153 | E41: =IF(AND(ISNUMBER(E40),ISNUMBER(D40)),IFERROR(E40/D40-1,""),"") -> 0.080436346 | F41: =IF(AND(ISNUMBER(F40),ISNUMBER(E40)),IFERROR(F40/E40-1,""),"") -> -0.11790623 | G41: =IF(AND(ISNUMBER(G40),ISNUMBER(F40)),IFERROR(G40/F40-1,""),"") -> 0.028402173 | H41: =IF(AND(ISNUMBER(H40),ISNUMBER(G40)),IFERROR(H40/G40-1,""),"") -> 0.10110852 | I41: =IF(AND(ISNUMBER(I40),ISNUMBER(H40)),IFERROR(I40/H40-1,""),"") -> 0.068276482 | N41: =IF(AND(ISNUMBER(N40),ISNUMBER(I40)),IFERROR(N40/I40-1,""),"") -> 0.037547356 | O41: =IF(AND(ISNUMBER(O40),ISNUMBER(J40)),IFERROR(O40/J40-1,""),"") -> 0.023272214 | P41: =IF(AND(ISNUMBER(P40),ISNUMBER(K40)),IFERROR(P40/K40-1,""),"") -> 0.048728814 | Q41: =IF(AND(ISNUMBER(Q40),ISNUMBER(L40)),IFERROR(Q40/L40-1,""),"") -> 0.043328748 | R41: =IF(AND(ISNUMBER(R40),ISNUMBER(M40)),IFERROR(R40/M40-1,""),"") -> 0.060165975 | S41: =IF(AND(ISNUMBER(S40),ISNUMBER(N40)),IFERROR(S40/N40-1,""),"") -> 0.043677822 | T41: =IF(AND(ISNUMBER(T40),ISNUMBER(O40)),IFERROR(T40/O40-1,""),"") -> 0.045485872 | U41: =IF(AND(ISNUMBER(U40),ISNUMBER(P40)),IFERROR(U40/P40-1,""),"") -> 0.038383838 | ... CA41: =IF(AND(ISNUMBER(CA40),ISNUMBER(BV40)),IFERROR(CA40/BV40-1,""),"") -> 0.093624266 | CB41: =IF(AND(ISNUMBER(CB40),ISNUMBER(CA40)),IFERROR(CB40/CA40-1,""),"") -> 0.039959172 | CC41: =IF(AND(ISNUMBER(CC40),ISNUMBER(CB40)),IFERROR(CC40/CB40-1,""),"") -> 0.016338639 | CD41: =IF(AND(ISNUMBER(CD40),ISNUMBER(CC40)),IFERROR(CD40/CC40-1,""),"") -> 0.02962256 | CE41: =IF(AND(ISNUMBER(CE40),ISNUMBER(CD40)),IFERROR(CE40/CD40-1,""),"") -> 0.045 | CN41: 2027E | CO41: =CP41+$CO$40 -> 0.065 | CP41: 0.05 | CQ41: =CP41+$CQ$40 -> 0.035
...

Sheet Bull-Base-Bear
B2: Saia, Inc. (SAIA) — Bull / Base / Bear Case P&L Summary | J2: Share price ($): | K2: =Model!$CA$322 -> 350
B3: Adjusted figures (company definition: adjusted operating income / adjusted operating ratio / adjusted diluted EPS; Adjusted EBITDA model-defined — Saia does not publish EBITDA) · USD millions · Live panel linked to Model — toggle scenario via Model!CF2. Bull and Bear panels are value snapshots generated from the Model with the switch set to each case. | J3: As of: | K3: =TODAY() -> 46300
B5: Scenario: | C5: =Model!$CF$2 -> Base | N5: Scenario: | O5: Bull | P5: Snapshot (values) — Model run with switch = Bull | Z5: Scenario: | AA5: Bear | AB5: Snapshot (values) — Model run with switch = Bear
B7: (USDm, except EPS and shares) | C7: 2025A | D7: 2026E | E7: 2027E | F7: 2028E | G7: 2029E | H7: 2030E | I7: 25-'30 CAGR | J7: LT Hist Avg | K7: LT Hist Min | L7: LT Hist Max | N7: (USDm, except EPS and shares) | O7: 2025A | P7: 2026E | Q7: 2027E | R7: 2028E | S7: 2029E | T7: 2030E | U7: 25-'30 CAGR | V7: LT Hist Avg | W7: LT Hist Min | X7: LT Hist Max | Z7: (USDm, except EPS and shares) | AA7: 2025A | AB7: 2026E | AC7: 2027E | AD7: 2028E | AE7: 2029E | AF7: 2030E | AG7: 25-'30 CAGR | AH7: LT Hist Avg | AI7: LT Hist Min | AJ7: LT Hist Max
B9: Revenues | C9: =Model!BV81 -> 3234.286 | D9: =Model!CA81 -> 3735.6295 | E9: =Model!CB81 -> 4079.1472 | F9: =Model!CC81 -> 4332.3557 | G9: =Model!CD81 -> 4639.1188 | H9: =Model!CE81 -> 5017.5549 | I9: =IFERROR((H9/C9)^(1/5)-1,"n/m") -> 0.091799128 | N9: Revenues | O9: 3234.286 | P9: 3768.9897 | Q9: 4252.5829 | R9: 4668.9913 | S9: 5168.8813 | T9: 5780.36 | U9: 0.12314362 | Z9: Revenues | AA9: 3234.286 | AB9: 3702.635 | AC9: 3910.6378 | AD9: 4015.4885 | AE9: 4156.5934 | AF9: 4345.5105 | AG9: 0.060846327
B10: Revenues y/y % | D10: =IFERROR(D9/C9-1,"") -> 0.155009 | E10: =IFERROR(E9/D9-1,"") -> 0.091957131 | F10: =IFERROR(F9/E9-1,"") -> 0.062073878 | G10: =IFERROR(G9/F9-1,"") -> 0.070807463 | H10: =IFERROR(H9/G9-1,"") -> 0.081575 | N10: Revenues y/y % | P10: 0.16532356 | Q10: 0.12830846 | R10: 0.097918939 | S10: 0.10706594 | T10: 0.1183 | Z10: Revenues y/y % | AB10: 0.14480755 | AC10: 0.056176948 | AD10: 0.026811662 | AE10: 0.035140155 | AF10: 0.04545
B11: LTL tonnage per workday y/y % | C11: =Model!BV168 -> 0.024573758 | D11: =Model!CA168 -> 0.054269274 | E11: =Model!CB168 -> 0.05 | F11: =Model!CC168 -> 0.045 | G11: =Model!CD168 -> 0.04 | H11: =Model!CE168 -> 0.035 | N11: LTL tonnage per workday y/y % | O11: 0.024573758 | P11: 0.059005519 | Q11: 0.07 | R11: 0.065 | S11: 0.06 | T11: 0.055 | Z11: LTL tonnage per workday y/y % | AA11: 0.024573758 | AB11: 0.04953303 | AC11: 0.03 | AD11: 0.025 | AE11: 0.02 | AF11: 0.015
B12: Adjusted EBITDA (model; Saia does not publish EBITDA) | C12: =Model!BV145 -> 587.752 | D12: =Model!CA145 -> 687.99461 | E12: =Model!CB145 -> 822.4307 | F12: =Model!CC145 -> 875.95179 | G12: =Model!CD145 -> 942.44591 | H12: =Model!CE145 -> 1052.2306 | I12: =IFERROR((H12/C12)^(1/5)-1,"n/m") -> 0.12352661 | N12: Adjusted EBITDA (model; Saia does not publish EBITDA) | O12: 587.752 | P12: 710.64262 | Q12: 920.66701 | R12: 1062.716 | S12: 1234.428 | T12: 1472.3368 | U12: 0.20160744 | Z12: Adjusted EBITDA (model; Saia does not publish EBITDA) | AA12: 587.752 | AB12: 665.72007 | AC12: 728.28877 | AD12: 703.54621 | AE12: 683.13335 | AF12: 693.2699 | AG12: 0.033574166
B13: Adjusted EBITDA margin % | C13: =IFERROR(C12/C9,"") -> 0.18172543 | D13: =IFERROR(D12/D9,"") -> 0.184171 | E13: =IFERROR(E12/E9,"") -> 0.20161829 | F13: =IFERROR(F12/F9,"") -> 0.20218834 | G13: =IFERROR(G12/G9,"") -> 0.20315192 | H13: =IFERROR(H12/H9,"") -> 0.20970983 | J13: =IFERROR(AVERAGE(Model!C146,Model!D146,Model!E146,Model!F146,Model!G146,Model!H146,Model!I146,Model!N146,Model!S146,Model!X146,Model!AC146,Model!AH146,Model!AM146,Model!AR146,Model!AW146,Model!BB146,Model!BG146,Model!BL146,Model!BQ146,Model!BV146),"n/m") -> 0.13127442 | K13: =IFERROR(MIN(Model!C146,Model!D146,Model!E146,Model!F146,Model!G146,Model!H146,Model!I146,Model!N146,Model!S146,Model!X146,Model!AC146,Model!AH146,Model!AM146,Model!AR146,Model!AW146,Model!BB146,Model!BG146,Model!BL146,Model!BQ146,Model!BV146),"n/m") -> 0.027742154 | L13: =IFERROR(MAX(Model!C146,Model!D146,Model!E146,Model!F146,Model!G146,Model!H146,Model!I146,Model!N146,Model!S146,Model!X146,Model!AC146,Model!AH146,Model!AM146,Model!AR146,Model!AW146,Model!BB146,Model!BG146,Model!BL146,Model!BQ146,Model!BV146),"n/m") -> 0.22487435 | N13: Adjusted EBITDA margin % | O13: 0.18172543 | P13: 0.1885499 | Q13: 0.21649596 | R13: 0.22761148 | S13: 0.23881917 | T13: 0.25471368 | V13: 0.13127442 | W13: 0.027742154 | X13: 0.22487435 | Z13: Adjusted EBITDA margin % | AA13: 0.18172543 | AB13: 0.1797963 | AC13: 0.18623274 | AD13: 0.17520813 | AE13: 0.16434933 | AF13: 0.15953704 | AH13: 0.13127442 | AI13: 0.027742154 | AJ13: 0.22487435
B15: Operating Income (GAAP) | C15: =Model!BV93 -> 352.2 | D15: =Model!CA93 -> 425.86176 | E15: =Model!CB93 -> 531.60843 | F15: =Model!CC93 -> 569.78081 | G15: =Model!CD93 -> 619.7106 | H15: =Model!CE93 -> 706.75092 | I15: =IFERROR((H15/C15)^(1/5)-1,"n/m") -> 0.14946408 | N15: Operating Income (GAAP) | O15: 352.2 | P15: 448.50977 | Q15: 627.41437 | R15: 752.49627 | S15: 904.4376 | T15: 1114.1272 | U15: 0.25900973 | Z15: Operating Income (GAAP) | AA15: 352.2 | AB15: 403.58722 | AC15: 439.89689 | AD15: 401.37133 | AE15: 367.39413 | AF15: 359.73524 | AG15: 0.0042428019
B16: Operating income y/y % | D16: =IFERROR(D15/C15-1,"") -> 0.20914752 | E16: =IFERROR(E15/D15-1,"") -> 0.24831221 | F16: =IFERROR(F15/E15-1,"") -> 0.071805432 | G16: =IFERROR(G15/F15-1,"") -> 0.08762983 | H16: =IFERROR(H15/G15-1,"") -> 0.14045317 | N16: Operating income y/y % | P16: 0.27345193 | Q16: 0.39888673 | R16: 0.19936091 | S16: 0.2019164 | T16: 0.23184532 | Z16: Operating income y/y % | AB16: 0.14590352 | AC16: 0.08996734 | AD16: -0.087578619 | AE16: -0.084652769 | AF16: -0.020846515
B17: Operating margin (GAAP) % (= 1 − operating ratio) | C17: =IFERROR(C15/C9,"") -> 0.10889575 | D17: =IFERROR(D15/D9,"") -> 0.114 | E17: =IFERROR(E15/E9,"") -> 0.13032342 | F17: =IFERROR(F15/F9,"") -> 0.13151755 | G17: =IFERROR(G15/G9,"") -> 0.13358369 | H17: =IFERROR(H15/H9,"") -> 0.14085564 | J17: =IFERROR(AVERAGE(Model!C179,Model!D179,Model!E179,Model!F179,Model!G179,Model!H179,Model!I179,Model!N179,Model!S179,Model!X179,Model!AC179,Model!AH179,Model!AM179,Model!AR179,Model!AW179,Model!BB179,Model!BG179,Model!BL179,Model!BQ179,Model!BV179),"n/m") -> 0.076008299 | K17: =IFERROR(MIN(Model!C179,Model!D179,Model!E179,Model!F179,Model!G179,Model!H179,Model!I179,Model!N179,Model!S179,Model!X179,Model!AC179,Model!AH179,Model!AM179,Model!AR179,Model!AW179,Model!BB179,Model!BG179,Model!BL179,Model!BQ179,Model!BV179),"n/m") -> -0.0095601701 | L17: =IFERROR(MAX(Model!C179,Model!D179,Model!E179,Model!F179,Model!G179,Model!H179,Model!I179,Model!N179,Model!S179,Model!X179,Model!AC179,Model!AH179,Model!AM179,Model!AR179,Model!AW179,Model!BB179,Model!BG179,Model!BL179,Model!BQ179,Model!BV179),"n/m") -> 0.16850945 | N17: Operating margin (GAAP) % (= 1 − operating ratio) | O17: 0.10889575 | P17: 0.119 | Q17: 0.14753724 | R17: 0.16116891 | S17: 0.17497744 | T17: 0.19274357 | V17: 0.076008299 | W17: -0.0095601701 | X17: 0.16850945 | Z17: Operating margin (GAAP) % (= 1 − operating ratio) | AA17: 0.10889575 | AB17: 0.109 | AC17: 0.11248725 | AD17: 0.099955791 | AE17: 0.088388279 | AF17: 0.082783195 | AH17: 0.076008299 | AI17: -0.0095601701 | AJ17: 0.16850945
B19: Adjusted Net Income (company definition) | C19: =Model!BV160 -> 244.02303 | D19: =Model!CA160 -> 320.94469 | E19: =Model!CB160 -> 399.36162 | F19: =Model!CC160 -> 426.94837 | G19: =Model!CD160 -> 464.64536 | H19: =Model!CE160 -> 530.3608 | I19: =IFERROR((H19/C19)^(1/5)-1,"n/m") -> 0.16796041 | N19: Adjusted Net Income (company definition) | O19: 244.02303 | P19: 338.04394 | Q19: 470.38677 | R19: 547.20116 | S19: 658.96757 | T19: 813.71807 | U19: 0.27235597 | Z19: Adjusted Net Income (company definition) | AA19: 244.02303 | AB19: 304.12741 | AC19: 330.30189 | AD19: 299.79921 | AE19: 274.14643 | AF19: 268.36397 | AG19: 0.019198274
B21: FDSO (m) | C21: =Model!BV112 -> 26.786 | D21: =Model!CA112 -> 26.8265 | E21: =Model!CB112 -> 26.356755 | F21: =Model!CC112 -> 25.599894 | G21: =Model!CD112 -> 24.962205 | H21: =Model!CE112 -> 24.346859 | I21: =IFERROR((H21/C21)^(1/5)-1,"n/m") -> -0.018914142 | N21: FDSO (m) | O21: 26.786 | P21: 26.8265 | Q21: 25.605316 | R21: 24.039405 | S21: 22.931296 | T21: 21.678441 | U21: -0.04142955 | Z21: FDSO (m) | AA21: 26.786 | AB21: 26.8265 | AC21: 26.415293 | AD21: 25.841668 | AE21: 25.501501 | AF21: 25.28488 | AG21: -0.011468284
B23: Adjusted EPS — Diluted ($) | C23: =Model!BV162 -> 9.1100958 | D23: =Model!CA162 -> 11.963718 | E23: =Model!CB162 -> 15.152155 | F23: =Model!CC162 -> 16.67774 | G23: =Model!CD162 -> 18.613955 | H23: =Model!CE162 -> 21.783541 | I23: =IFERROR((H23/C23)^(1/5)-1,"n/m") -> 0.19047727 | N23: Adjusted EPS — Diluted ($) | O23: 9.1100958 | P23: 12.60112 | Q23: 18.370668 | R23: 22.762674 | S23: 28.736604 | T23: 37.53582 | U23: 0.32734737 | Z23: Adjusted EPS — Diluted ($) | AA23: 9.1100958 | AB23: 11.336828 | AC23: 12.504192 | AD23: 11.601388 | AE23: 10.750208 | AF23: 10.613614 | AG23: 0.031022331
B24: EPS y/y % | D24: =IFERROR(D23/C23-1,"") -> 0.31323739 | E24: =IFERROR(E23/D23-1,"") -> 0.26650879 | F24: =IFERROR(F23/E23-1,"") -> 0.10068439 | G24: =IFERROR(G23/F23-1,"") -> 0.11609576 | H24: =IFERROR(H23/G23-1,"") -> 0.1702801 | N24: EPS y/y % | P24: 0.38320388 | Q24: 0.45785999 | R24: 0.2390771 | S24: 0.26244408 | T24: 0.3062024 | Z24: EPS y/y % | AB24: 0.24442467 | AC24: 0.10297093 | AD24: -0.072200111 | AE24: -0.073368802 | AF24: -0.012706115
B26: P / E (x) — assumed (adjusted EPS) | G26: 26 | H26: 26 | N26: P / E (x) — assumed (adjusted EPS) | S26: 30 | T26: 30 | Z26: P / E (x) — assumed (adjusted EPS) | AD26: 20 | AE26: 20 | AF26: 20
B27: Price Target ($) | G27: =G26*G23 -> 483.96283 | H27: =H26*H23 -> 566.37206 | N27: Price Target ($) | S27: =S26*S23 -> 862.09811 | T27: =T26*T23 -> 1126.0746 | Z27: Price Target ($) | AD27: =AD26*AD23 -> 232.02775 | AE27: =AE26*AE23 -> 215.00415 | AF27: =AF26*AF23 -> 212.27229
B28: Upside / (Downside) vs current | G28: =IFERROR(G27/$K$2-1,"") -> 0.38275093 | H28: =IFERROR(H27/$K$2-1,"") -> 0.6182059 | N28: Upside / (Downside) vs current | S28: =IFERROR(S27/$K$2-1,"") -> 1.4631374 | T28: =IFERROR(T27/$K$2-1,"") -> 2.217356 | Z28: Upside / (Downside) vs current | AD28: =IFERROR(AD27/$K$2-1,"") -> -0.33706357 | AE28: =IFERROR(AE27/$K$2-1,"") -> -0.38570242 | AF28: =IFERROR(AF27/$K$2-1,"") -> -0.39350775
B29: IRR (to Dec-Y-1) | G29: =IFERROR((G27/$K$2)^(1/((DATE(2029-1,12,31)-$K$3)/365.25))-1,"") -> 0.15569814 | H29: =IFERROR((H27/$K$2)^(1/((DATE(2030-1,12,31)-$K$3)/365.25))-1,"") -> 0.16021629 | N29: IRR (to Dec-Y-1) | S29: =IFERROR((S27/$K$2)^(1/((DATE(2029-1,12,31)-$K$3)/365.25))-1,"") -> 0.4955671 | T29: =IFERROR((T27/$K$2)^(1/((DATE(2030-1,12,31)-$K$3)/365.25))-1,"") -> 0.43446454 | Z29: IRR (to Dec-Y-1) | AD29: =IFERROR((AD27/$K$2)^(1/((DATE(2028-1,12,31)-$K$3)/365.25))-1,"") -> -0.28264215 | AE29: =IFERROR((AE27/$K$2)^(1/((DATE(2029-1,12,31)-$K$3)/365.25))-1,"") -> -0.19553385 | AF29: =IFERROR((AF27/$K$2)^(1/((DATE(2030-1,12,31)-$K$3)/365.25))-1,"") -> -0.1430657
B31: Free Cash Flow | C31: =Model!BV211 -> 27.334 | D31: =Model!CA211 -> 200.73254 | E31: =Model!CB211 -> 274.03499 | F31: =Model!CC211 -> 297.49462 | G31: =Model!CD211 -> 273.1689 | H31: =Model!CE211 -> 319.37689 | I31: =IFERROR((H31/C31)^(1/5)-1,"n/m") -> 0.63500867 | N31: Free Cash Flow | O31: 27.334 | P31: 192.96946 | Q31: 327.29232 | R31: 387.13093 | S31: 418.80561 | T31: 537.67641 | U31: 0.81452752 | Z31: Free Cash Flow | AA31: 27.334 | AB31: 208.78913 | AC31: 222.13319 | AD31: 197.55789 | AE31: 124.96823 | AF31: 112.09775 | AG31: 0.32610753
B32: FCF % | C32: =IFERROR(C31/C9,"") -> 0.0084513243 | D32: =IFERROR(D31/D9,"") -> 0.053734597 | E32: =IFERROR(E31/E9,"") -> 0.06717948 | F32: =IFERROR(F31/F9,"") -> 0.068668097 | G32: =IFERROR(G31/G9,"") -> 0.058883791 | H32: =IFERROR(H31/H9,"") -> 0.063651897 | J32: =IFERROR(AVERAGE(Model!C213,Model!D213,Model!E213,Model!F213,Model!G213,Model!H213,Model!I213,Model!N213,Model!S213,Model!X213,Model!AC213,Model!AH213,Model!AM213,Model!AR213,Model!AW213,Model!BB213,Model!BG213,Model!BL213,Model!BQ213,Model!BV213),"n/m") -> 0.0044078847 | K32: =IFERROR(MIN(Model!C213,Model!D213,Model!E213,Model!F213,Model!G213,Model!H213,Model!I213,Model!N213,Model!S213,Model!X213,Model!AC213,Model!AH213,Model!AM213,Model!AR213,Model!AW213,Model!BB213,Model!BG213,Model!BL213,Model!BQ213,Model!BV213),"n/m") -> -0.14329835 | L32: =IFERROR(MAX(Model!C213,Model!D213,Model!E213,Model!F213,Model!G213,Model!H213,Model!I213,Model!N213,Model!S213,Model!X213,Model!AC213,Model!AH213,Model!AM213,Model!AR213,Model!AW213,Model!BB213,Model!BG213,Model!BL213,Model!BQ213,Model!BV213),"n/m") -> 0.052921088 | N32: FCF % | O32: 0.0084513243 | P32: 0.051199254 | Q32: 0.076963184 | R32: 0.082915324 | S32: 0.081024419 | T32: 0.093017808 | V32: 0.0044078847 | W32: -0.14329835 | X32: 0.052921088 | Z32: FCF % | AA32: 0.0084513243 | AB32: 0.056389336 | AC32: 0.056802293 | AD32: 0.049198968 | AE32: 0.030065061 | AF32: 0.025796221 | AH32: 0.0044078847 | AI32: -0.14329835 | AJ32: 0.052921088
B33: FCF / share ($) | C33: =IFERROR(C31/C21,"") -> 1.0204584 | D33: =IFERROR(D31/D21,"") -> 7.4826214 | E33: =IFERROR(E31/E21,"") -> 10.397144 | F33: =IFERROR(F31/F21,"") -> 11.620932 | G33: =IFERROR(G31/G21,"") -> 10.9433 | H33: =IFERROR(H31/H21,"") -> 13.117786 | N33: FCF / share ($) | O33: 1.0204584 | P33: 7.1932403 | Q33: 12.782202 | R33: 16.104014 | S33: 18.263495 | T33: 24.802356 | Z33: FCF / share ($) | AA33: 1.0204584 | AB33: 7.7829434 | AC33: 8.4092648 | AD33: 7.6449355 | AE33: 4.9004266 | AF33: 4.4333906
B34: FCF Yield (on PT) | F34: =IFERROR(F33/F$27,"") | G34: =IFERROR(G33/G$27,"") -> 0.022611861 | H34: =IFERROR(H33/H$27,"") -> 0.023161075 | N34: FCF Yield (on PT) | R34: =IFERROR(R33/R$27,"") | S34: =IFERROR(S33/S$27,"") -> 0.021184938 | T34: =IFERROR(T33/T$27,"") -> 0.0220255 | Z34: FCF Yield (on PT) | AD34: =IFERROR(AD33/AD$27,"") -> 0.032948367 | AE34: =IFERROR(AE33/AE$27,"") -> 0.022792242 | AF34: =IFERROR(AF33/AF$27,"") -> 0.020885395
B35: Adjusted Operating Income (company definition) | C35: =Model!BV130 -> 337.697 | D35: =Model!CA130 -> 425.86176 | E35: =Model!CB130 -> 531.60843 | F35: =Model!CC130 -> 569.78081 | G35: =Model!CD130 -> 619.7106 | H35: =Model!CE130 -> 706.75092 | I35: =IFERROR((H35/C35)^(1/5)-1,"n/m") -> 0.15917188 | N35: Adjusted Operating Income (company definition) | O35: 337.697 | P35: 448.50977 | Q35: 627.41437 | R35: 752.49627 | S35: 904.4376 | T35: 1114.1272 | U35: 0.26964269 | Z35: Adjusted Operating Income (company definition) | AA35: 337.697 | AB35: 403.58722 | AC35: 439.89689 | AD35: 401.37133 | AE35: 367.39413 | AF35: 359.73524 | AG35: 0.012724129
B36: Adjusted operating ratio % | C36: =IFERROR(1-C35/C9,"") -> 0.89558839 | D36: =IFERROR(1-D35/D9,"") -> 0.886 | E36: =IFERROR(1-E35/E9,"") -> 0.86967658 | F36: =IFERROR(1-F35/F9,"") -> 0.86848245 | G36: =IFERROR(1-G35/G9,"") -> 0.86641631 | H36: =IFERROR(1-H35/H9,"") -> 0.85914436 | J36: =IFERROR(AVERAGE(Model!C131,Model!D131,Model!E131,Model!F131,Model!G131,Model!H131,Model!I131,Model!N131,Model!S131,Model!X131,Model!AC131,Model!AH131,Model!AM131,Model!AR131,Model!AW131,Model!BB131,Model!BG131,Model!BL131,Model!BQ131,Model!BV131),"n/m") -> 0.9229529 | K36: =IFERROR(MIN(Model!C131,Model!D131,Model!E131,Model!F131,Model!G131,Model!H131,Model!I131,Model!N131,Model!S131,Model!X131,Model!AC131,Model!AH131,Model!AM131,Model!AR131,Model!AW131,Model!BB131,Model!BG131,Model!BL131,Model!BQ131,Model!BV131),"n/m") -> 0.83149055 | L36: =IFERROR(MAX(Model!C131,Model!D131,Model!E131,Model!F131,Model!G131,Model!H131,Model!I131,Model!N131,Model!S131,Model!X131,Model!AC131,Model!AH131,Model!AM131,Model!AR131,Model!AW131,Model!BB131,Model!BG131,Model!BL131,Model!BQ131,Model!BV131),"n/m") -> 1.0188343 | N36: Adjusted operating ratio % | O36: 0.89558839 | P36: 0.881 | Q36: 0.85246276 | R36: 0.83883109 | S36: 0.82502256 | T36: 0.80725643 | V36: 0.9229529 | W36: 0.83149055 | X36: 1.0188343 | Z36: Adjusted operating ratio % | AA36: 0.89558839 | AB36: 0.891 | AC36: 0.88751275 | AD36: 0.90004421 | AE36: 0.91161172 | AF36: 0.91721681 | AH36: 0.9229529 | AI36: 0.83149055 | AJ36: 1.0188343
B38: Net Debt | C38: =Model!BV301 -> 144.26 | D38: =Model!CA301 -> -54.454544 | E38: =Model!CB301 -> 0 | F38: =Model!CC301 -> 0 | G38: =Model!CD301 -> 0 | H38: =Model!CE301 -> 0 | N38: Net Debt | O38: 144.26 | P38: 3.3085392 | Q38: 460.3335 | R38: 531.35801 | S38: 617.21398 | T38: 736.16838 | Z38: Net Debt | AA38: 144.26 | AB38: -62.511132 | AC38: 0 | AD38: 0 | AE38: 0 | AF38: 0
B39: Net Debt / Adjusted EBITDA (x) | C39: =IFERROR(C38/C12,"") -> 0.24544366 | D39: =IFERROR(D38/D12,"") -> -0.079149667 | E39: =IFERROR(E38/E12,"") -> 0 | F39: =IFERROR(F38/F12,"") -> 0 | G39: =IFERROR(G38/G12,"") -> 0 | H39: =IFERROR(H38/H12,"") -> 0 | N39: Net Debt / Adjusted EBITDA (x) | O39: 0.24544366 | P39: 0.0046557005 | Q39: 0.5 | R39: 0.5 | S39: 0.5 | T39: 0.5 | Z39: Net Debt / Adjusted EBITDA (x) | AA39: 0.24544366 | AB39: -0.093900026 | AC39: 0 | AD39: 0 | AE39: 0 | AF39: 0
