Workbook

Sheet Model
CC1: SCENARIO SWITCH ▼ (Bull / Base / Bear) — drives all scenario-linked forecast drivers
B2: S&P Global Inc. (NYSE: SPGI) — 3-Statement Financial Model | CC2: Base
B3: US GAAP · USD millions (per-share data in USD; shares in millions) · Fiscal years ended 31 December · Source: S&P Global Forms 10-K / 10-Q, Form 8-K earnings releases (Ex. 99.1), the 8-K / 8-K/A of 2 / 6-Jul-2026 (Mobility spin-off, pro forma and recast) and deal / financing 8-Ks, SEC EDGAR (CIK 64040; McGraw Hill Financial 2013–16, The McGraw-Hill Companies before); XBRL company facts; investor-relations releases are the same documents as filed on EDGAR
B4: Basis notes: hybrid recast — FY2010–11 continuing operations (McGraw-Hill Education sold Mar-2013); FY2012–2024 as originally reported; 2025 and 1H-26 pro forma excluding Mobility (spun off 1-Jul-2026 as Mobility Global, NYSE: MBGL). Divisions: Ratings, Indices (S&P DJI JV with CME 73/27 from Jul-2012), Energy (C&C / Platts / Commodity Insights), Market Intelligence (Capital IQ; SNL Sep-2015). IHS Markit merger 28-Feb-2022; Engineering Solutions sold May-2023; OSTTRA stake sold Q4-2025. Q3–Q4/26E calibrated to FY26 guidance (28-Jul-2026).
CE5: Forecast | CF5: Historical | CG5: Historical | CH5: Historical
B6: (USDm) | C6: 2010 | D6: 2011 | E6: 2012 | F6: Q1/13 | G6: Q2/13 | H6: Q3/13 | I6: Q4/13 | J6: 2013 | K6: Q1/14 | L6: Q2/14 | M6: Q3/14 | N6: Q4/14 | O6: 2014 | P6: Q1/15 | Q6: Q2/15 | R6: Q3/15 | S6: Q4/15 | T6: 2015 | U6: Q1/16 | V6: Q2/16 | W6: Q3/16 | X6: Q4/16 | Y6: 2016 | Z6: Q1/17 | AA6: Q2/17 | AB6: Q3/17 | AC6: Q4/17 | AD6: 2017 | AE6: Q1/18 | AF6: Q2/18 | AG6: Q3/18 | AH6: Q4/18 | AI6: 2018 | AJ6: Q1/19 | AK6: Q2/19 | AL6: Q3/19 | AM6: Q4/19 | AN6: 2019 | AO6: Q1/20 | AP6: Q2/20 | AQ6: Q3/20 | AR6: Q4/20 | AS6: 2020 | AT6: Q1/21 | AU6: Q2/21 | AV6: Q3/21 | AW6: Q4/21 | AX6: 2021 | AY6: Q1/22 | AZ6: Q2/22 | BA6: Q3/22 | BB6: Q4/22 | BC6: 2022 | BD6: Q1/23 | BE6: Q2/23 | BF6: Q3/23 | BG6: Q4/23 | BH6: 2023 | BI6: Q1/24 | BJ6: Q2/24 | BK6: Q3/24 | BL6: Q4/24 | BM6: 2024 | BN6: Q1/25 | BO6: Q2/25 | BP6: Q3/25 | BQ6: Q4/25 | BR6: 2025 | BS6: Q1/26 | BT6: Q2/26 | BU6: Q3/26E | BV6: Q4/26E | BW6: 2026E | BX6: 2027E | BY6: 2028E | BZ6: 2029E | CA6: 2030E | CB6: 2031E | CC6: Modelling Notes | CE6: 5Y CAGR | CF6: 5Y CAGR | CG6: 10Y CAGR | CH6: 15Y CAGR
CE7: 26-'31 | CF7: 20-'25 | CG7: 15-'25 | CH7: 10-'25
B8: DIVISION P&L — RATINGS · INDICES · ENERGY · MARKET INTELLIGENCE (revenue by type × adjusted operating margin) | CC8: DIVISION BUILD — modelling logic (revenue by type → division revenue → division adjusted OP at the adjusted margin → − adjusted corporate unallocated + adjusted equity income = adjusted OP → GAAP P&L)
CK9: SCENARIO INPUT TABLE — driver assumptions per Bull / Base / Bear | CL9: Bull | CM9: Base | CN9: Bear | CO9: Bull / Bear = Base + Δ (Δ inputs on each block header). Outlook block = high / mid / low end of the FY26 guidance ranges.
B10: S&P Global Ratings (credit ratings, research & analytics; Crisil) — "S&P Ratings" 2010–15 | CC10: RATINGS — modelling logic
B11: Transaction revenue (new issuance: bonds, bank loans, structured finance) | D11: 651 | E11: 903 | F11: 264 | G11: 287 | H11: 227 | I11: 257 | J11: 1035 | K11: 245 | L11: 327 | M11: 269 | N11: 288 | O11: 1129 | P11: 289 | Q11: 329 | R11: 244 | S11: 247 | T11: 1109 | U11: 225 | V11: 343 | W11: 299 | X11: 311 | Y11: 1178 | Z11: 373 | AA11: 394 | AB11: 372 | AC11: 401 | AD11: 1540 | AE11: 368 | AF11: 397 | AG11: 328 | AH11: 283 | AI11: 1377 | AJ11: 331 | AK11: 429 | AL11: 402 | AM11: 429 | AN11: 1577 | AO11: 432 | AP11: 624 | AQ11: 490 | AR11: 430 | AS11: 1977 | AT11: 582 | AU11: 615 | AV11: 551 | AW11: 504 | AX11: 2253 | AZ11: 344 | BA11: 244 | BB11: 249 | BD11: 379 | BE11: 383 | BF11: 326 | BG11: 338 | BH11: 1425 | BI11: 582 | BJ11: 626 | BK11: 597 | BL11: 521 | BM11: 2326 | BN11: 620 | BO11: 597 | BP11: 668 | BQ11: 585 | BR11: 2470 | BS11: 712 | BT11: 746 | BU11: =BP11*(1+BU12) -> 749.42934 | BV11: =BQ11*(1+BV12) -> 656.31162 | BW11: =SUM(BS11:BV11) -> 2863.741 | BX11: =BW11*(1+BX12) -> 2949.6532 | BY11: =BX11*(1+BY12) -> 3126.6324 | BZ11: =BY11*(1+BZ12) -> 3314.2303 | CA11: =BZ11*(1+CA12) -> 3479.9418 | CB11: =CA11*(1+CB12) -> 3653.9389 | CC11: Revenue by type (release revenue-information exhibit; 10-K / 10-Q revenue note). Q3–Q4/26E: prior-year quarter × (1 + growth). 2027E+: prior year × (1 + scenario lever). | CE11: =IFERROR((CB11/BW11)^(1/5)-1,"n/m") -> 0.049942488 | CF11: =IFERROR((BR11/AS11)^(1/5)-1,"n/m") -> 0.045533751 | CG11: =IFERROR((BR11/T11)^(1/10)-1,"n/m") -> 0.08336934 | CH11: =IFERROR((BR11/C11)^(1/15)-1,"n/m") -> n/m | CK11: FY26 guidance — Q2-26 release (28-Jul-2026), continuing operations excl. Mobility | CL11: High | CM11: Mid | CN11: Low | CO11: Revenue +5.9–7.9% (organic cc +6–8%) on FY2025 pro forma revenue $13,589m; adjusted EPS $17.50–17.75; GAAP EPS $16.35–16.60; adjusted margin +35–60 bp (+75–100 bp ex OSTTRA); deal amortization ~$785m; corporate unallocated $185–195m adjusted; interest $365–385m GAAP / $390–410m adjusted; tax 22–23%; capex $190–210m; >$7bn of 2026 buybacks. Source: SEC EDGAR 8-K Ex. 99.1 (no unverified guidance used).
B12: y/y % | D12: =IF(AND(ISNUMBER(D11),ISNUMBER(C11)),IFERROR(D11/C11-1,""),"") | E12: =IF(AND(ISNUMBER(E11),ISNUMBER(D11)),IFERROR(E11/D11-1,""),"") -> 0.38709677 | J12: =IF(AND(ISNUMBER(J11),ISNUMBER(E11)),IFERROR(J11/E11-1,""),"") -> 0.1461794 | K12: =IF(AND(ISNUMBER(K11),ISNUMBER(F11)),IFERROR(K11/F11-1,""),"") -> -0.071969697 | L12: =IF(AND(ISNUMBER(L11),ISNUMBER(G11)),IFERROR(L11/G11-1,""),"") -> 0.13937282 | M12: =IF(AND(ISNUMBER(M11),ISNUMBER(H11)),IFERROR(M11/H11-1,""),"") -> 0.18502203 | N12: =IF(AND(ISNUMBER(N11),ISNUMBER(I11)),IFERROR(N11/I11-1,""),"") -> 0.12062257 | O12: =IF(AND(ISNUMBER(O11),ISNUMBER(J11)),IFERROR(O11/J11-1,""),"") -> 0.090821256 | P12: =IF(AND(ISNUMBER(P11),ISNUMBER(K11)),IFERROR(P11/K11-1,""),"") -> 0.17959184 | Q12: =IF(AND(ISNUMBER(Q11),ISNUMBER(L11)),IFERROR(Q11/L11-1,""),"") -> 0.006116208 | ... BT12: =IF(AND(ISNUMBER(BT11),ISNUMBER(BO11)),IFERROR(BT11/BO11-1,""),"") -> 0.24958124 | BU12: =$BW$13+$BW$149 -> 0.12190021 | BV12: =$BW$13+$BW$149 -> 0.12190021 | BW12: =IF(AND(ISNUMBER(BW11),ISNUMBER(BR11)),IFERROR(BW11/BR11-1,""),"") -> 0.1594093 | BX12: =CHOOSE(MATCH($CC$2,{"Bull","Base","Bear"},0),$CL$35,$CM$35,$CN$35) -> 0.03 | BY12: =CHOOSE(MATCH($CC$2,{"Bull","Base","Bear"},0),$CL$36,$CM$36,$CN$36) -> 0.06 | BZ12: =CHOOSE(MATCH($CC$2,{"Bull","Base","Bear"},0),$CL$37,$CM$37,$CN$37) -> 0.06 | CA12: =CHOOSE(MATCH($CC$2,{"Bull","Base","Bear"},0),$CL$38,$CM$38,$CN$38) -> 0.05 | CB12: =CHOOSE(MATCH($CC$2,{"Bull","Base","Bear"},0),$CL$39,$CM$39,$CN$39) -> 0.05 | CC12: Q3–Q4/26E: 1H-26 y/y growth of the line + revenue-guidance calibration Δ (Group block). 2027E–2031E: scenario lever. | CK12: FY26 revenue growth (vs FY2025 pro forma) | CL12: 0.079 | CM12: 0.069 | CN12: 0.059 | CO12: Guided +5.9–7.9%. Drives the Q3–Q4/26E revenue calibration.
B13: Q3–Q4/26E growth before revenue calibration (1H-26 y/y) | BW13: =IFERROR(SUM(BS11:BT11)/SUM(BN11:BO11)-1,0) -> 0.19802794 | CK13: FY26 adjusted diluted EPS ($) | CL13: 17.75 | CM13: 17.625 | CN13: 17.5 | CO13: Guided $17.50–17.75. Drives the margin calibration.
B14: Non-transaction revenue (surveillance, frequent-issuer programs, Crisil & other) | D14: 1116 | E14: 1131 | F14: 297 | G14: 312 | H14: 313 | I14: 317 | J14: 1239 | K14: 324 | L14: 337 | M14: 335 | N14: 330 | O14: 1326 | P14: 317 | Q14: 329 | R14: 343 | S14: 331 | T14: 1319 | U14: 327 | V14: 339 | W14: 343 | X14: 347 | Y14: 1357 | Z14: 341 | AA14: 353 | AB14: 367 | AC14: 388 | AD14: 1448 | AE14: 380 | AF14: 378 | AG14: 372 | AH14: 378 | AI14: 1506 | AJ14: 365 | AK14: 372 | AL14: 387 | AM14: 391 | AN14: 1529 | AO14: 393 | AP14: 382 | AQ14: 404 | AR14: 451 | AS14: 1629 | AT14: 435 | AU14: 458 | AV14: 466 | AW14: 485 | AX14: 1844 | AZ14: 452 | BA14: 437 | BB14: 456 | BD14: 445 | BE14: 468 | BF14: 493 | BG14: 500 | BH14: 1907 | BI14: 480 | BJ14: 509 | BK14: 513 | BL14: 541 | BM14: 2044 | BN14: 529 | BO14: 551 | BP14: 572 | BQ14: 602 | BR14: 2254 | BS14: 590 | BT14: 593 | BU14: =BP14*(1+BU15) -> 583.00679 | BV14: =BQ14*(1+BV15) -> 613.58407 | BW14: =SUM(BS14:BV14) -> 2379.5909 | BX14: =BW14*(1+BX15) -> 2546.1622 | BY14: =BX14*(1+BY15) -> 2724.3936 | BZ14: =BY14*(1+BZ15) -> 2887.8572 | CA14: =BZ14*(1+CA15) -> 3061.1286 | CB14: =CA14*(1+CB15) -> 3244.7963 | CE14: =IFERROR((CB14/BW14)^(1/5)-1,"n/m") -> 0.063988736 | CF14: =IFERROR((BR14/AS14)^(1/5)-1,"n/m") -> 0.067103552 | CG14: =IFERROR((BR14/T14)^(1/10)-1,"n/m") -> 0.055044825 | CH14: =IFERROR((BR14/C14)^(1/15)-1,"n/m") -> n/m | CK14: FY26 GAAP diluted EPS, continuing ($) — memo | CL14: 16.6 | CM14: 16.475 | CN14: 16.35 | CO14: Guided $16.35–16.60 (information row).
B15: y/y % | D15: =IF(AND(ISNUMBER(D14),ISNUMBER(C14)),IFERROR(D14/C14-1,""),"") | E15: =IF(AND(ISNUMBER(E14),ISNUMBER(D14)),IFERROR(E14/D14-1,""),"") -> 0.01344086 | J15: =IF(AND(ISNUMBER(J14),ISNUMBER(E14)),IFERROR(J14/E14-1,""),"") -> 0.095490716 | K15: =IF(AND(ISNUMBER(K14),ISNUMBER(F14)),IFERROR(K14/F14-1,""),"") -> 0.090909091 | L15: =IF(AND(ISNUMBER(L14),ISNUMBER(G14)),IFERROR(L14/G14-1,""),"") -> 0.080128205 | M15: =IF(AND(ISNUMBER(M14),ISNUMBER(H14)),IFERROR(M14/H14-1,""),"") -> 0.07028754 | N15: =IF(AND(ISNUMBER(N14),ISNUMBER(I14)),IFERROR(N14/I14-1,""),"") -> 0.041009464 | O15: =IF(AND(ISNUMBER(O14),ISNUMBER(J14)),IFERROR(O14/J14-1,""),"") -> 0.070217918 | P15: =IF(AND(ISNUMBER(P14),ISNUMBER(K14)),IFERROR(P14/K14-1,""),"") -> -0.021604938 | Q15: =IF(AND(ISNUMBER(Q14),ISNUMBER(L14)),IFERROR(Q14/L14-1,""),"") -> -0.023738872 | ... BT15: =IF(AND(ISNUMBER(BT14),ISNUMBER(BO14)),IFERROR(BT14/BO14-1,""),"") -> 0.076225045 | BU15: =$BW$16+$BW$149 -> 0.019242642 | BV15: =$BW$16+$BW$149 -> 0.019242642 | BW15: =IF(AND(ISNUMBER(BW14),ISNUMBER(BR14)),IFERROR(BW14/BR14-1,""),"") -> 0.055719105 | BX15: =CHOOSE(MATCH($CC$2,{"Bull","Base","Bear"},0),$CL$41,$CM$41,$CN$41) -> 0.07 | BY15: =CHOOSE(MATCH($CC$2,{"Bull","Base","Bear"},0),$CL$42,$CM$42,$CN$42) -> 0.07 | BZ15: =CHOOSE(MATCH($CC$2,{"Bull","Base","Bear"},0),$CL$43,$CM$43,$CN$43) -> 0.06 | CA15: =CHOOSE(MATCH($CC$2,{"Bull","Base","Bear"},0),$CL$44,$CM$44,$CN$44) -> 0.06 | CB15: =CHOOSE(MATCH($CC$2,{"Bull","Base","Bear"},0),$CL$45,$CM$45,$CN$45) -> 0.06 | CK15: FY26 adjusted margin expansion (bp) — memo | CL15: 60 | CM15: 47.5 | CN15: 35 | CO15: Guided +35–60 bp vs FY2025 pro forma 51.3% (information row).
B16: Q3–Q4/26E growth before revenue calibration (1H-26 y/y) | BW16: =IFERROR(SUM(BS14:BT14)/SUM(BN14:BO14)-1,0) -> 0.09537037 | CK16: FY26 organic constant-currency growth — memo | CL16: 0.08 | CM16: 0.07 | CN16: 0.06 | CO16: Guided +6–8% (information row).
B17: Not split by type (history only: periods without a revenue-by-type table on this basis) | C17: =IF(ISNUMBER(C21),C21-(N(C11)+N(C14)),"") -> 1695 | D17: =IF(ISNUMBER(D21),D21-(N(D11)+N(D14)),"") -> 0 | E17: =IF(ISNUMBER(E21),E21-(N(E11)+N(E14)),"") -> 0 | F17: =IF(ISNUMBER(F21),F21-(N(F11)+N(F14)),"") -> 0 | G17: =IF(ISNUMBER(G21),G21-(N(G11)+N(G14)),"") -> 0 | H17: =IF(ISNUMBER(H21),H21-(N(H11)+N(H14)),"") -> 0 | I17: =IF(ISNUMBER(I21),I21-(N(I11)+N(I14)),"") -> 0 | J17: =IF(ISNUMBER(J21),J21-(N(J11)+N(J14)),"") -> 0 | ... BT17: =IF(ISNUMBER(BT21),BT21-(N(BT11)+N(BT14)),"") -> 0 | CK17: 2H-26 share repurchases ($m) | CL17: 6000 | CM17: 5750 | CN17: 5500 | CO17: 1H-26 $1,500m (ASRs at $426.70 and $414.76); company expects >$7bn for 2026 → 2H ≥ $5.5bn (assumption by case).
B18: Ratings — division revenue | C18: =IF(ISNUMBER(C21),N(C11)+N(C14)+N(C17),"") -> 1695 | D18: =IF(ISNUMBER(D21),N(D11)+N(D14)+N(D17),"") -> 1767 | E18: =IF(ISNUMBER(E21),N(E11)+N(E14)+N(E17),"") -> 2034 | F18: =IF(ISNUMBER(F21),N(F11)+N(F14)+N(F17),"") -> 561 | G18: =IF(ISNUMBER(G21),N(G11)+N(G14)+N(G17),"") -> 599 | H18: =IF(ISNUMBER(H21),N(H11)+N(H14)+N(H17),"") -> 540 | I18: =IF(ISNUMBER(I21),N(I11)+N(I14)+N(I17),"") -> 574 | J18: =IF(ISNUMBER(J21),N(J11)+N(J14)+N(J17),"") -> 2274 | ... BT18: =IF(ISNUMBER(BT21),N(BT11)+N(BT14)+N(BT17),"") -> 1339 | BU18: =BU11+BU14 -> 1332.4361 | BV18: =BV11+BV14 -> 1269.8957 | BW18: =BW11+BW14 -> 5243.3318 | BX18: =BX11+BX14 -> 5495.8154 | BY18: =BY11+BY14 -> 5851.026 | BZ18: =BZ11+BZ14 -> 6202.0875 | CA18: =CA11+CA14 -> 6541.0705 | CB18: =CB11+CB14 -> 6898.7353 | CC18: History: division revenue as reported (Σ revenue types + any unsplit remainder). | CE18: =IFERROR((CB18/BW18)^(1/5)-1,"n/m") -> 0.056409815 | CF18: =IFERROR((BR18/AS18)^(1/5)-1,"n/m") -> 0.055496587 | CG18: =IFERROR((BR18/T18)^(1/10)-1,"n/m") -> 0.068823812 | CH18: =IFERROR((BR18/C18)^(1/15)-1,"n/m") -> 0.07072024
B19: Division revenue y/y % | D19: =IF(AND(ISNUMBER(D18),ISNUMBER(C18)),IFERROR(D18/C18-1,""),"") -> 0.042477876 | E19: =IF(AND(ISNUMBER(E18),ISNUMBER(D18)),IFERROR(E18/D18-1,""),"") -> 0.15110357 | J19: =IF(AND(ISNUMBER(J18),ISNUMBER(E18)),IFERROR(J18/E18-1,""),"") -> 0.1179941 | K19: =IF(AND(ISNUMBER(K18),ISNUMBER(F18)),IFERROR(K18/F18-1,""),"") -> 0.01426025 | L19: =IF(AND(ISNUMBER(L18),ISNUMBER(G18)),IFERROR(L18/G18-1,""),"") -> 0.10851419 | M19: =IF(AND(ISNUMBER(M18),ISNUMBER(H18)),IFERROR(M18/H18-1,""),"") -> 0.11851852 | N19: =IF(AND(ISNUMBER(N18),ISNUMBER(I18)),IFERROR(N18/I18-1,""),"") -> 0.076655052 | O19: =IF(AND(ISNUMBER(O18),ISNUMBER(J18)),IFERROR(O18/J18-1,""),"") -> 0.079595427 | P19: =IF(AND(ISNUMBER(P18),ISNUMBER(K18)),IFERROR(P18/K18-1,""),"") -> 0.065026362 | Q19: =IF(AND(ISNUMBER(Q18),ISNUMBER(L18)),IFERROR(Q18/L18-1,""),"") -> -0.0090361446 | ... BW19: =IF(AND(ISNUMBER(BW18),ISNUMBER(BR18)),IFERROR(BW18/BR18-1,""),"") -> 0.10993476 | BX19: =IF(AND(ISNUMBER(BX18),ISNUMBER(BW18)),IFERROR(BX18/BW18-1,""),"") -> 0.048153273 | BY19: =IF(AND(ISNUMBER(BY18),ISNUMBER(BX18)),IFERROR(BY18/BX18-1,""),"") -> 0.064632911 | BZ19: =IF(AND(ISNUMBER(BZ18),ISNUMBER(BY18)),IFERROR(BZ18/BY18-1,""),"") -> 0.06 | CA19: =IF(AND(ISNUMBER(CA18),ISNUMBER(BZ18)),IFERROR(CA18/BZ18-1,""),"") -> 0.054656266 | CB19: =IF(AND(ISNUMBER(CB18),ISNUMBER(CA18)),IFERROR(CB18/CA18-1,""),"") -> 0.054679859 | CK19: Q3/26E–Q4/26E point estimates (all cases; per quarter unless stated)
B20: % of total revenue | C20: =IF(AND(ISNUMBER(C18),ISNUMBER(C138)),IFERROR(C18/C138,""),"") -> 0.4657873 | D20: =IF(AND(ISNUMBER(D18),ISNUMBER(D138)),IFERROR(D18/D138,""),"") -> 0.44688923 | E20: =IF(AND(ISNUMBER(E18),ISNUMBER(E138)),IFERROR(E18/E138,""),"") -> 0.45707865 | F20: =IF(AND(ISNUMBER(F18),ISNUMBER(F138)),IFERROR(F18/F138,""),"") -> 0.47502117 | G20: =IF(AND(ISNUMBER(G18),ISNUMBER(G138)),IFERROR(G18/G138,""),"") -> 0.4792 | H20: =IF(AND(ISNUMBER(H18),ISNUMBER(H138)),IFERROR(H18/H138,""),"") -> 0.45226131 | I20: =IF(AND(ISNUMBER(I18),ISNUMBER(I138)),IFERROR(I18/I138,""),"") -> 0.4592 | J20: =IF(AND(ISNUMBER(J18),ISNUMBER(J138)),IFERROR(J18/J138,""),"") -> 0.46646154 | ... CB20: =IF(AND(ISNUMBER(CB18),ISNUMBER(CB138)),IFERROR(CB18/CB138,""),"") -> 0.34421387 | CE20: =IFERROR(AVERAGE(BX20,BY20,BZ20,CA20,CB20),"n/m") -> 0.3507719 | CF20: =IFERROR(AVERAGE(AX20,BC20,BH20,BM20,BR20),"n/m") -> 0.33768169 | CG20: =IFERROR(AVERAGE(Y20,AD20,AI20,AN20,AS20,AX20,BC20,BH20,BM20,BR20),"n/m") -> 0.40379233 | CH20: =IFERROR(AVERAGE(C20,D20,E20,J20,O20,T20,Y20,AD20,AI20,AN20,AS20,AX20,BC20,BH20,BM20,BR20),"n/m") -> 0.42607342 | CK20: Adjusted corporate unallocated expense ($m / quarter) | CM20: 54 | CO20: FY26 guided $185–195m adjusted; 1H $82m → (190 − 82) ÷ 2.
B21: Memo: Ratings revenue as reported (segment exhibit; 2025+ adjusted as recast) | C21: 1695 | D21: 1767 | E21: 2034 | F21: 561 | G21: 599 | H21: 540 | I21: 574 | J21: 2274 | K21: 569 | L21: 664 | M21: 604 | N21: 618 | O21: 2455 | P21: 606 | Q21: 658 | R21: 587 | S21: 578 | T21: 2428 | U21: 552 | V21: 682 | W21: 642 | X21: 658 | Y21: 2535 | Z21: 714 | AA21: 747 | AB21: 739 | AC21: 789 | AD21: 2988 | AE21: 748 | AF21: 775 | AG21: 700 | AH21: 661 | AI21: 2883 | AJ21: 696 | AK21: 801 | AL21: 789 | AM21: 820 | AN21: 3106 | AO21: 825 | AP21: 1006 | AQ21: 894 | AR21: 881 | AS21: 3606 | AT21: 1017 | AU21: 1073 | AV21: 1017 | AW21: 989 | AX21: 4097 | AY21: 868 | AZ21: 796 | BA21: 681 | BB21: 705 | BC21: 3050 | BD21: 824 | BE21: 851 | BF21: 819 | BG21: 838 | BH21: 3332 | BI21: 1062 | BJ21: 1135 | BK21: 1110 | BL21: 1062 | BM21: 4370 | BN21: 1149 | BO21: 1148 | BP21: 1240 | BQ21: 1187 | BR21: 4724 | BS21: 1302 | BT21: 1339 | CK21: Deal-related amortization ($m / quarter) | CM21: 193 | CO21: FY26 guided ~$785m; 1H $399m → (785 − 399) ÷ 2.
B22: Check: revenue types vs division revenue (should be 0; ±1 rounding) | C22: =IF(AND(ISNUMBER(C11),ISNUMBER(C21)),IF(ABS(C18-C21)<=1.01,0,ROUND(C18-C21,0)),"") | D22: =IF(AND(ISNUMBER(D11),ISNUMBER(D21)),IF(ABS(D18-D21)<=1.01,0,ROUND(D18-D21,0)),"") -> 0 | E22: =IF(AND(ISNUMBER(E11),ISNUMBER(E21)),IF(ABS(E18-E21)<=1.01,0,ROUND(E18-E21,0)),"") -> 0 | F22: =IF(AND(ISNUMBER(F11),ISNUMBER(F21)),IF(ABS(F18-F21)<=1.01,0,ROUND(F18-F21,0)),"") -> 0 | G22: =IF(AND(ISNUMBER(G11),ISNUMBER(G21)),IF(ABS(G18-G21)<=1.01,0,ROUND(G18-G21,0)),"") -> 0 | H22: =IF(AND(ISNUMBER(H11),ISNUMBER(H21)),IF(ABS(H18-H21)<=1.01,0,ROUND(H18-H21,0)),"") -> 0 | I22: =IF(AND(ISNUMBER(I11),ISNUMBER(I21)),IF(ABS(I18-I21)<=1.01,0,ROUND(I18-I21,0)),"") -> 0 | J22: =IF(AND(ISNUMBER(J11),ISNUMBER(J21)),IF(ABS(J18-J21)<=1.01,0,ROUND(J18-J21,0)),"") -> 0 | ... BT22: =IF(AND(ISNUMBER(BT11),ISNUMBER(BT21)),IF(ABS(BT18-BT21)<=1.01,0,ROUND(BT18-BT21,0)),"") -> 0 | CK22: Interest expense, net — GAAP ($m / quarter) | CM22: 98 | CO22: FY26 guided $365–385m GAAP; 1H $179m → (375 − 179) ÷ 2.
B23: Ratings — adjusted operating profit | D23: 728 | E23: 865 | F23: 259 | G23: 277 | H23: 227 | I23: 231 | J23: 993 | K23: 240 | L23: 308 | M23: 266 | N23: 261 | O23: 1074 | P23: 285 | Q23: 329 | R23: 280 | S23: 252 | T23: 1146 | U23: 252 | V23: 369 | W23: 330 | X23: 313 | Y23: 1263 | Z23: 379 | AA23: 398 | AB23: 392 | AC23: 439 | AD23: 1608 | AE23: 408 | AF23: 443 | AG23: 396 | AH23: 367 | AI23: 1614 | AJ23: 364 | AK23: 467 | AL23: 472 | AM23: 473 | AN23: 1776 | AO23: 521 | AP23: 695 | AQ23: 552 | AR23: 481 | AS23: 2249 | AT23: 686 | AU23: 731 | AV23: 645 | AW23: 570 | AX23: 2632 | AY23: 518 | AZ23: 473 | BA23: 381 | BB23: 338 | BC23: 1710 | BD23: 480 | BE23: 491 | BF23: 464 | BG23: 447 | BH23: 1882 | BI23: 687 | BJ23: 747 | BK23: 684 | BL23: 634 | BM23: 2753 | BN23: 759 | BO23: 750 | BP23: 831 | BQ23: 735 | BR23: 3076 | BS23: 878 | BT23: 917 | BU23: =BU18*BU24 -> 889.37827 | BV23: =BV18*BV24 -> 782.92834 | BW23: =SUM(BS23:BV23) -> 3467.3066 | BX23: =BX18*BX24 -> 3654.7173 | BY23: =BY18*BY24 -> 3920.1874 | BZ23: =BZ18*BZ24 -> 4155.3986 | CA23: =CA18*CA24 -> 4382.5172 | CB23: =CB18*CB24 -> 4622.1526 | CC23: Division adjusted OP (company non-GAAP: OP + non-GAAP adjustments + deal-related amortization). 2025+: pro forma recast basis. Forecast = revenue × adjusted margin. | CE23: =IFERROR((CB23/BW23)^(1/5)-1,"n/m") -> 0.05918155 | CF23: =IFERROR((BR23/AS23)^(1/5)-1,"n/m") -> 0.064631655 | CG23: =IFERROR((BR23/T23)^(1/10)-1,"n/m") -> 0.10377403 | CH23: =IFERROR((BR23/C23)^(1/15)-1,"n/m") -> n/m | CK23: Premium amortization benefit in interest ($m / quarter) | CM23: 6 | CO23: IHS Markit notes fair-value premium: $6m a quarter (adjusted interest = GAAP + $6m).
B24: Adjusted operating margin % | C24: =IF(AND(ISNUMBER(C23),ISNUMBER(C18)),IFERROR(C23/C18,""),"") | D24: =IF(AND(ISNUMBER(D23),ISNUMBER(D18)),IFERROR(D23/D18,""),"") -> 0.41199774 | E24: =IF(AND(ISNUMBER(E23),ISNUMBER(E18)),IFERROR(E23/E18,""),"") -> 0.4252704 | F24: =IF(AND(ISNUMBER(F23),ISNUMBER(F18)),IFERROR(F23/F18,""),"") -> 0.46167558 | G24: =IF(AND(ISNUMBER(G23),ISNUMBER(G18)),IFERROR(G23/G18,""),"") -> 0.4624374 | H24: =IF(AND(ISNUMBER(H23),ISNUMBER(H18)),IFERROR(H23/H18,""),"") -> 0.42037037 | I24: =IF(AND(ISNUMBER(I23),ISNUMBER(I18)),IFERROR(I23/I18,""),"") -> 0.40243902 | J24: =IF(AND(ISNUMBER(J23),ISNUMBER(J18)),IFERROR(J23/J18,""),"") -> 0.43667546 | ... BT24: =IF(AND(ISNUMBER(BT23),ISNUMBER(BT18)),IFERROR(BT23/BT18,""),"") -> 0.68483943 | BU24: =BU25+$BW$159 -> 0.66748285 | BV24: =BV25+$BW$159 -> 0.61652965 | BW24: =IF(AND(ISNUMBER(BW23),ISNUMBER(BW18)),IFERROR(BW23/BW18,""),"") -> 0.66127926 | BX24: =CHOOSE(MATCH($CC$2,{"Bull","Base","Bear"},0),$CL$77,$CM$77,$CN$77) -> 0.665 | BY24: =CHOOSE(MATCH($CC$2,{"Bull","Base","Bear"},0),$CL$78,$CM$78,$CN$78) -> 0.67 | BZ24: =CHOOSE(MATCH($CC$2,{"Bull","Base","Bear"},0),$CL$79,$CM$79,$CN$79) -> 0.67 | CA24: =CHOOSE(MATCH($CC$2,{"Bull","Base","Bear"},0),$CL$80,$CM$80,$CN$80) -> 0.67 | CB24: =CHOOSE(MATCH($CC$2,{"Bull","Base","Bear"},0),$CL$81,$CM$81,$CN$81) -> 0.67 | CC24: Q3–Q4/26E: margin before calibration + adjusted-EPS-guidance calibration Δ (Group block). 2027E+: scenario lever. | CE24: =IFERROR(AVERAGE(BX24,BY24,BZ24,CA24,CB24),"n/m") -> 0.669 | CF24: =IFERROR(AVERAGE(AX24,BC24,BH24,BM24,BR24),"n/m") -> 0.60980463 | CG24: =IFERROR(AVERAGE(Y24,AD24,AI24,AN24,AS24,AX24,BC24,BH24,BM24,BR24),"n/m") -> 0.58407134 | CH24: =IFERROR(AVERAGE(C24,D24,E24,J24,O24,T24,Y24,AD24,AI24,AN24,AS24,AX24,BC24,BH24,BM24,BR24),"n/m") -> 0.53494166 | CK24: Other income, net ($m / quarter) | CM24: 3 | CO24: 1H-26 $6m (pension income).
B25: Q3–Q4/26E margin before EPS calibration (prior-year quarter + 1H-26 y/y drift) | BU25: =BP24+IFERROR(SUM(BS23:BT23)/SUM(BS18:BT18)-SUM(BN23:BO23)/SUM(BN18:BO18),0) -> 0.69288424 | BV25: =BQ24+IFERROR(SUM(BS23:BT23)/SUM(BS18:BT18)-SUM(BN23:BO23)/SUM(BN18:BO18),0) -> 0.64193104 | CK25: Depreciation ($m / quarter) | CM25: 29 | CO25: 1H-26 $56m continuing.
B26: Incremental adjusted margin (Δ adjusted OP / Δ revenue) | D26: =IFERROR((D23-C23)/(D18-C18),"") -> 10.111111 | E26: =IFERROR((E23-D23)/(E18-D18),"") -> 0.51310861 | J26: =IFERROR((J23-E23)/(J18-E18),"") -> 0.53333333 | K26: =IFERROR((K23-F23)/(K18-F18),"") -> -2.375 | L26: =IFERROR((L23-G23)/(L18-G18),"") -> 0.47692308 | M26: =IFERROR((M23-H23)/(M18-H18),"") -> 0.609375 | N26: =IFERROR((N23-I23)/(N18-I18),"") -> 0.68181818 | O26: =IFERROR((O23-J23)/(O18-J18),"") -> 0.44751381 | P26: =IFERROR((P23-K23)/(P18-K18),"") -> 1.2162162 | Q26: =IFERROR((Q23-L23)/(Q18-L18),"") -> -3.5 | ... BW26: =IFERROR((BW23-BR23)/(BW18-BR18),"") -> 0.7534809 | BX26: =IFERROR((BX23-BW23)/(BX18-BW18),"") -> 0.74226861 | BY26: =IFERROR((BY23-BX23)/(BY18-BX18),"") -> 0.74735997 | BZ26: =IFERROR((BZ23-BY23)/(BZ18-BY18),"") -> 0.67 | CA26: =IFERROR((CA23-BZ23)/(CA18-BZ18),"") -> 0.67 | CB26: =IFERROR((CB23-CA23)/(CB18-CA18),"") -> 0.67 | CK26: Severance & restructuring ($m / quarter) | CM26: 15 | CO26: Assumption (1H-26 continuing ~$45m).
B27: Memo: Ratings — operating profit (GAAP, as reported) | C27: 762 | D27: 720 | E27: 849 | F27: 259 | G27: 277 | H27: 243 | I27: 221 | J27: 1000 | K27: 240 | L27: 308 | M27: 183 | N27: -1313 | O27: -583 | P27: 291 | Q27: 361 | R27: 194 | S27: 232 | T27: 1078 | U27: 262 | V27: 396 | W27: 346 | X27: 258 | Y27: 1262 | Z27: 376 | AA27: 397 | AB27: 376 | AC27: 374 | AD27: 1524 | AE27: 408 | AF27: 369 | AG27: 395 | AH27: 357 | AI27: 1530 | AJ27: 363 | AK27: 455 | AL27: 472 | AM27: 473 | AN27: 1763 | AO27: 520 | AP27: 693 | AQ27: 544 | AR27: 465 | AS27: 2223 | AT27: 681 | AU27: 729 | AV27: 644 | AW27: 575 | AX27: 2629 | AY27: 511 | AZ27: 464 | BA27: 377 | BB27: 320 | BC27: 1672 | BD27: 477 | BE27: 486 | BF27: 459 | BG27: 442 | BH27: 1864 | BI27: 679 | BJ27: 725 | BK27: 676 | BL27: 627 | BM27: 2707 | CK27: Disposition / separation costs ($m / quarter) | CM27: 10 | CO27: Assumption: residual Mobility separation and geoscience / EDM disposition costs.
CK28: Gain on geoscience portfolio sale (Q4/26E; negative = gain) | CM28: -250 | CO28: Assumption implied by the guidance: GAAP vs adjusted margin guidance leaves ~$210m of net 2H gains after amortization, and the EPS bridge includes −$1.20 of divestiture gains ($0.60 booked in 1H).
B29: S&P Dow Jones Indices (73% / 27% JV with CME Group from Jul-2012; S&P DJ Indices to 2015) | CC29: INDICES (S&P DOW JONES INDICES) — modelling logic | CK29: Tax rate (GAAP & adjusted) | CM29: 0.225 | CO29: FY26 guided 22–23%.
B30: Asset-linked fees (ETFs, mutual funds, insurance products) | U30: 86 | V30: 92 | W30: 100 | X30: 104 | Y30: 381 | Z30: 108 | AA30: 114 | AB30: 118 | AC30: 121 | AD30: 461 | AE30: 131 | AF30: 135 | AG30: 131 | AH30: 126 | AI30: 522 | AJ30: 143 | AK30: 159 | AL30: 152 | AM30: 159 | AN30: 613 | AO30: 159 | AP30: 153 | AQ30: 156 | AR30: 179 | AS30: 647 | AT30: 183 | AU30: 195 | AV30: 211 | AW30: 210 | AX30: 800 | AZ30: 214 | BA30: 210 | BB30: 220 | BD30: 210 | BE30: 211 | BF30: 218 | BG30: 221 | BH30: 859 | BI30: 244 | BJ30: 245 | BK30: 266 | BL30: 291 | BM30: 1046 | BN30: 288 | BO30: 286 | BP30: 303 | BQ30: 329 | BR30: 1206 | BS30: 339 | BT30: 348 | BU30: =BP30*(1+BU31) -> 339.58312 | BV30: =BQ30*(1+BV31) -> 368.72227 | BW30: =SUM(BS30:BV30) -> 1395.3054 | BX30: =BW30*(1+BX31) -> 1534.8359 | BY30: =BX30*(1+BY31) -> 1672.9712 | BZ30: =BY30*(1+BZ31) -> 1823.5386 | CA30: =BZ30*(1+CA31) -> 1969.4217 | CB30: =CA30*(1+CB31) -> 2126.9754 | CE30: =IFERROR((CB30/BW30)^(1/5)-1,"n/m") -> 0.087974304 | CF30: =IFERROR((BR30/AS30)^(1/5)-1,"n/m") -> 0.13263142 | CG30: =IFERROR((BR30/T30)^(1/10)-1,"n/m") -> n/m | CH30: =IFERROR((BR30/C30)^(1/15)-1,"n/m") -> n/m | CK30: 2H-26 capital expenditures ($m) | CM30: 135 | CO30: FY26 guided $190–210m; 1H $65m.
B31: y/y % | D31: =IF(AND(ISNUMBER(D30),ISNUMBER(C30)),IFERROR(D30/C30-1,""),"") | E31: =IF(AND(ISNUMBER(E30),ISNUMBER(D30)),IFERROR(E30/D30-1,""),"") | J31: =IF(AND(ISNUMBER(J30),ISNUMBER(E30)),IFERROR(J30/E30-1,""),"") | K31: =IF(AND(ISNUMBER(K30),ISNUMBER(F30)),IFERROR(K30/F30-1,""),"") | L31: =IF(AND(ISNUMBER(L30),ISNUMBER(G30)),IFERROR(L30/G30-1,""),"") | M31: =IF(AND(ISNUMBER(M30),ISNUMBER(H30)),IFERROR(M30/H30-1,""),"") | N31: =IF(AND(ISNUMBER(N30),ISNUMBER(I30)),IFERROR(N30/I30-1,""),"") | O31: =IF(AND(ISNUMBER(O30),ISNUMBER(J30)),IFERROR(O30/J30-1,""),"") | P31: =IF(AND(ISNUMBER(P30),ISNUMBER(K30)),IFERROR(P30/K30-1,""),"") | Q31: =IF(AND(ISNUMBER(Q30),ISNUMBER(L30)),IFERROR(Q30/L30-1,""),"") | ... BT31: =IF(AND(ISNUMBER(BT30),ISNUMBER(BO30)),IFERROR(BT30/BO30-1,""),"") -> 0.21678322 | BU31: =$BW$32+$BW$149 -> 0.12073638 | BV31: =$BW$32+$BW$149 -> 0.12073638 | BW31: =IF(AND(ISNUMBER(BW30),ISNUMBER(BR30)),IFERROR(BW30/BR30-1,""),"") -> 0.15696965 | BX31: =CHOOSE(MATCH($CC$2,{"Bull","Base","Bear"},0),$CL$47,$CM$47,$CN$47) -> 0.1 | BY31: =CHOOSE(MATCH($CC$2,{"Bull","Base","Bear"},0),$CL$48,$CM$48,$CN$48) -> 0.09 | BZ31: =CHOOSE(MATCH($CC$2,{"Bull","Base","Bear"},0),$CL$49,$CM$49,$CN$49) -> 0.09 | CA31: =CHOOSE(MATCH($CC$2,{"Bull","Base","Bear"},0),$CL$50,$CM$50,$CN$50) -> 0.08 | CB31: =CHOOSE(MATCH($CC$2,{"Bull","Base","Bear"},0),$CL$51,$CM$51,$CN$51) -> 0.08
B32: Q3–Q4/26E growth before revenue calibration (1H-26 y/y) | BW32: =IFERROR(SUM(BS30:BT30)/SUM(BN30:BO30)-1,0) -> 0.19686411 | CK32: Target net debt / adjusted EBITDA (x) — buyback plug 2027E+ | CL32: 1.75 | CM32: 1.5 | CN32: 1.25 | CO32: Assumption: net debt / adjusted EBITDA target for 2027E+ buybacks. Model YE2026E ~1.4x after the $7bn+ 2026 buybacks; S&P Global has historically returned ~85% of adjusted FCF and kept leverage near 2x gross. Bull = more buybacks (higher target).
B33: Exchange-traded derivatives (sales usage-based royalties) | D33: 252 | E33: 301 | F33: 90 | G33: 97 | H33: 99 | I33: 103 | J33: 390 | K33: 111 | L33: 105 | M33: 114 | N33: 111 | O33: 441 | P33: 114 | Q33: 118 | R33: 124 | S33: 119 | T33: 475 | U33: 33 | V33: 29 | W33: 31 | X33: 30 | Y33: 125 | Z33: 32 | AA33: 33 | AB33: 33 | AC33: 34 | AD33: 131 | AE33: 50 | AF33: 38 | AG33: 33 | AH33: 48 | AI33: 171 | AJ33: 34 | AK33: 36 | AL33: 38 | AM33: 31 | AN33: 140 | AO33: 54 | AP33: 44 | AQ33: 35 | AR33: 32 | AS33: 165 | AT33: 41 | AU33: 35 | AV33: 40 | AW33: 42 | AX33: 158 | AZ33: 57 | BA33: 55 | BB33: 56 | BD33: 65 | BE33: 67 | BF33: 66 | BG33: 68 | BH33: 267 | BI33: 73 | BJ33: 70 | BK33: 76 | BL33: 71 | BM33: 290 | BN33: 81 | BO33: 80 | BP33: 77 | BQ33: 85 | BR33: 324 | BS33: 96 | BT33: 99 | BU33: =BP33*(1+BU34) -> 87.399035 | BV33: =BQ33*(1+BV34) -> 96.479454 | BW33: =SUM(BS33:BV33) -> 378.87849 | BX33: =BW33*(1+BX34) -> 397.82241 | BY33: =BX33*(1+BY34) -> 417.71353 | BZ33: =BY33*(1+BZ34) -> 438.59921 | CA33: =BZ33*(1+CA34) -> 460.52917 | CB33: =CA33*(1+CB34) -> 483.55563 | CE33: =IFERROR((CB33/BW33)^(1/5)-1,"n/m") -> 0.05 | CF33: =IFERROR((BR33/AS33)^(1/5)-1,"n/m") -> 0.14449056 | CG33: =IFERROR((BR33/T33)^(1/10)-1,"n/m") -> -0.037534569 | CH33: =IFERROR((BR33/C33)^(1/15)-1,"n/m") -> n/m
B34: y/y % | D34: =IF(AND(ISNUMBER(D33),ISNUMBER(C33)),IFERROR(D33/C33-1,""),"") | E34: =IF(AND(ISNUMBER(E33),ISNUMBER(D33)),IFERROR(E33/D33-1,""),"") -> 0.19444444 | J34: =IF(AND(ISNUMBER(J33),ISNUMBER(E33)),IFERROR(J33/E33-1,""),"") -> 0.29568106 | K34: =IF(AND(ISNUMBER(K33),ISNUMBER(F33)),IFERROR(K33/F33-1,""),"") -> 0.23333333 | L34: =IF(AND(ISNUMBER(L33),ISNUMBER(G33)),IFERROR(L33/G33-1,""),"") -> 0.082474227 | M34: =IF(AND(ISNUMBER(M33),ISNUMBER(H33)),IFERROR(M33/H33-1,""),"") -> 0.15151515 | N34: =IF(AND(ISNUMBER(N33),ISNUMBER(I33)),IFERROR(N33/I33-1,""),"") -> 0.077669903 | O34: =IF(AND(ISNUMBER(O33),ISNUMBER(J33)),IFERROR(O33/J33-1,""),"") -> 0.13076923 | P34: =IF(AND(ISNUMBER(P33),ISNUMBER(K33)),IFERROR(P33/K33-1,""),"") -> 0.027027027 | Q34: =IF(AND(ISNUMBER(Q33),ISNUMBER(L33)),IFERROR(Q33/L33-1,""),"") -> 0.12380952 | ... BT34: =IF(AND(ISNUMBER(BT33),ISNUMBER(BO33)),IFERROR(BT33/BO33-1,""),"") -> 0.2375 | BU34: =$BW$35+$BW$149 -> 0.1350524 | BV34: =$BW$35+$BW$149 -> 0.1350524 | BW34: =IF(AND(ISNUMBER(BW33),ISNUMBER(BR33)),IFERROR(BW33/BR33-1,""),"") -> 0.16937805 | BX34: =CHOOSE(MATCH($CC$2,{"Bull","Base","Bear"},0),$CL$53,$CM$53,$CN$53) -> 0.05 | BY34: =CHOOSE(MATCH($CC$2,{"Bull","Base","Bear"},0),$CL$54,$CM$54,$CN$54) -> 0.05 | BZ34: =CHOOSE(MATCH($CC$2,{"Bull","Base","Bear"},0),$CL$55,$CM$55,$CN$55) -> 0.05 | CA34: =CHOOSE(MATCH($CC$2,{"Bull","Base","Bear"},0),$CL$56,$CM$56,$CN$56) -> 0.05 | CB34: =CHOOSE(MATCH($CC$2,{"Bull","Base","Bear"},0),$CL$57,$CM$57,$CN$57) -> 0.05 | CK34: RAT_TR (Ratings transaction revenue y/y) | CL34: 0.04 | CM34: Δ → | CN34: -0.08 | CO34: 1H-26 +20% (record issuance, refinancing walls); FY2020–25 range −27% to +25% (cyclical). 2027E normalisation after two strong years.
B35: Q3–Q4/26E growth before revenue calibration (1H-26 y/y) | BW35: =IFERROR(SUM(BS33:BT33)/SUM(BN33:BO33)-1,0) -> 0.21118012 | CK35: 2027E | CL35: =CM35+$CL$34 -> 0.07 | CM35: 0.03 | CN35: =CM35+$CN$34 -> -0.05
B36: Data & custom subscriptions | D36: 71 | E36: 87 | F36: 25 | G36: 26 | H36: 25 | I36: 27 | J36: 103 | K36: 26 | L36: 28 | M36: 29 | N36: 29 | O36: 111 | P36: 29 | Q36: 30 | R36: 32 | S36: 32 | T36: 122 | U36: 32 | V36: 32 | W36: 33 | X36: 37 | Y36: 133 | Z36: 31 | AA36: 37 | AB36: 36 | AC36: 36 | AD36: 141 | AE36: 33 | AF36: 36 | AG36: 41 | AH36: 41 | AI36: 144 | AJ36: 40 | AK36: 40 | AL36: 42 | AM36: 43 | AN36: 165 | AO36: 46 | AP36: 43 | AQ36: 43 | AR36: 46 | AS36: 177 | AT36: 46 | AU36: 48 | AV36: 47 | AW36: 51 | AX36: 191 | AZ36: 67 | BA36: 69 | BB36: 68 | BD36: 66 | BE36: 70 | BF36: 70 | BG36: 71 | BH36: 277 | BI36: 70 | BJ36: 74 | BK36: 74 | BL36: 74 | BM36: 292 | BN36: 76 | BO36: 80 | BP36: 82 | BQ36: 84 | BR36: 320 | BS36: 84 | BT36: 87 | BU36: =BP36*(1+BU37) -> 83.642142 | BV36: =BQ36*(1+BV37) -> 85.682194 | BW36: =SUM(BS36:BV36) -> 340.32434 | BX36: =BW36*(1+BX37) -> 367.55028 | BY36: =BX36*(1+BY37) -> 396.95431 | BZ36: =BY36*(1+BZ37) -> 424.74111 | CA36: =BZ36*(1+CA37) -> 454.47298 | CB36: =CA36*(1+CB37) -> 486.28609 | CE36: =IFERROR((CB36/BW36)^(1/5)-1,"n/m") -> 0.073988841 | CF36: =IFERROR((BR36/AS36)^(1/5)-1,"n/m") -> 0.12573286 | CG36: =IFERROR((BR36/T36)^(1/10)-1,"n/m") -> 0.10123249 | CH36: =IFERROR((BR36/C36)^(1/15)-1,"n/m") -> n/m | CK36: 2028E | CL36: =CM36+$CL$34 -> 0.1 | CM36: 0.06 | CN36: =CM36+$CN$34 -> -0.02
B37: y/y % | D37: =IF(AND(ISNUMBER(D36),ISNUMBER(C36)),IFERROR(D36/C36-1,""),"") | E37: =IF(AND(ISNUMBER(E36),ISNUMBER(D36)),IFERROR(E36/D36-1,""),"") -> 0.22535211 | J37: =IF(AND(ISNUMBER(J36),ISNUMBER(E36)),IFERROR(J36/E36-1,""),"") -> 0.18390805 | K37: =IF(AND(ISNUMBER(K36),ISNUMBER(F36)),IFERROR(K36/F36-1,""),"") -> 0.04 | L37: =IF(AND(ISNUMBER(L36),ISNUMBER(G36)),IFERROR(L36/G36-1,""),"") -> 0.076923077 | M37: =IF(AND(ISNUMBER(M36),ISNUMBER(H36)),IFERROR(M36/H36-1,""),"") -> 0.16 | N37: =IF(AND(ISNUMBER(N36),ISNUMBER(I36)),IFERROR(N36/I36-1,""),"") -> 0.074074074 | O37: =IF(AND(ISNUMBER(O36),ISNUMBER(J36)),IFERROR(O36/J36-1,""),"") -> 0.077669903 | P37: =IF(AND(ISNUMBER(P36),ISNUMBER(K36)),IFERROR(P36/K36-1,""),"") -> 0.11538462 | Q37: =IF(AND(ISNUMBER(Q36),ISNUMBER(L36)),IFERROR(Q36/L36-1,""),"") -> 0.071428571 | ... BT37: =IF(AND(ISNUMBER(BT36),ISNUMBER(BO36)),IFERROR(BT36/BO36-1,""),"") -> 0.0875 | BU37: =$BW$38+$BW$149 -> 0.020026118 | BV37: =$BW$38+$BW$149 -> 0.020026118 | BW37: =IF(AND(ISNUMBER(BW36),ISNUMBER(BR36)),IFERROR(BW36/BR36-1,""),"") -> 0.063513549 | BX37: =CHOOSE(MATCH($CC$2,{"Bull","Base","Bear"},0),$CL$59,$CM$59,$CN$59) -> 0.08 | BY37: =CHOOSE(MATCH($CC$2,{"Bull","Base","Bear"},0),$CL$60,$CM$60,$CN$60) -> 0.08 | BZ37: =CHOOSE(MATCH($CC$2,{"Bull","Base","Bear"},0),$CL$61,$CM$61,$CN$61) -> 0.07 | CA37: =CHOOSE(MATCH($CC$2,{"Bull","Base","Bear"},0),$CL$62,$CM$62,$CN$62) -> 0.07 | CB37: =CHOOSE(MATCH($CC$2,{"Bull","Base","Bear"},0),$CL$63,$CM$63,$CN$63) -> 0.07 | CK37: 2029E | CL37: =CM37+$CL$34 -> 0.1 | CM37: 0.06 | CN37: =CM37+$CN$34 -> -0.02
B38: Q3–Q4/26E growth before revenue calibration (1H-26 y/y) | BW38: =IFERROR(SUM(BS36:BT36)/SUM(BN36:BO36)-1,0) -> 0.096153846 | CK38: 2030E | CL38: =CM38+$CL$34 -> 0.09 | CM38: 0.05 | CN38: =CM38+$CN$34 -> -0.03
B39: Not split by type (history only: periods without a revenue-by-type table on this basis) | C39: =IF(ISNUMBER(C43),C43-(N(C30)+N(C33)+N(C36)),"") -> 273 | D39: =IF(ISNUMBER(D43),D43-(N(D30)+N(D33)+N(D36)),"") -> 0 | E39: =IF(ISNUMBER(E43),E43-(N(E30)+N(E33)+N(E36)),"") -> 0 | F39: =IF(ISNUMBER(F43),F43-(N(F30)+N(F33)+N(F36)),"") -> 0 | G39: =IF(ISNUMBER(G43),G43-(N(G30)+N(G33)+N(G36)),"") -> 0 | H39: =IF(ISNUMBER(H43),H43-(N(H30)+N(H33)+N(H36)),"") -> 0 | I39: =IF(ISNUMBER(I43),I43-(N(I30)+N(I33)+N(I36)),"") -> 0 | J39: =IF(ISNUMBER(J43),J43-(N(J30)+N(J33)+N(J36)),"") -> 0 | ... BT39: =IF(ISNUMBER(BT43),BT43-(N(BT30)+N(BT33)+N(BT36)),"") -> 0 | CK39: 2031E | CL39: =CM39+$CL$34 -> 0.09 | CM39: 0.05 | CN39: =CM39+$CN$34 -> -0.03
B40: Indices (S&P Dow Jones Indices) — division revenue | C40: =IF(ISNUMBER(C43),N(C30)+N(C33)+N(C36)+N(C39),"") -> 273 | D40: =IF(ISNUMBER(D43),N(D30)+N(D33)+N(D36)+N(D39),"") -> 323 | E40: =IF(ISNUMBER(E43),N(E30)+N(E33)+N(E36)+N(E39),"") -> 388 | F40: =IF(ISNUMBER(F43),N(F30)+N(F33)+N(F36)+N(F39),"") -> 115 | G40: =IF(ISNUMBER(G43),N(G30)+N(G33)+N(G36)+N(G39),"") -> 123 | H40: =IF(ISNUMBER(H43),N(H30)+N(H33)+N(H36)+N(H39),"") -> 124 | I40: =IF(ISNUMBER(I43),N(I30)+N(I33)+N(I36)+N(I39),"") -> 130 | J40: =IF(ISNUMBER(J43),N(J30)+N(J33)+N(J36)+N(J39),"") -> 493 | ... BT40: =IF(ISNUMBER(BT43),N(BT30)+N(BT33)+N(BT36)+N(BT39),"") -> 534 | BU40: =BU30+BU33+BU36 -> 510.6243 | BV40: =BV30+BV33+BV36 -> 550.88392 | BW40: =BW30+BW33+BW36 -> 2114.5082 | BX40: =BX30+BX33+BX36 -> 2300.2086 | BY40: =BY30+BY33+BY36 -> 2487.639 | BZ40: =BZ30+BZ33+BZ36 -> 2686.8789 | CA40: =CA30+CA33+CA36 -> 2884.4238 | CB40: =CB30+CB33+CB36 -> 3096.8171 | CE40: =IFERROR((CB40/BW40)^(1/5)-1,"n/m") -> 0.079297662 | CF40: =IFERROR((BR40/AS40)^(1/5)-1,"n/m") -> 0.133431 | CG40: =IFERROR((BR40/T40)^(1/10)-1,"n/m") -> 0.11974657 | CH40: =IFERROR((BR40/C40)^(1/15)-1,"n/m") -> 0.13605826 | CK40: RAT_NT (Ratings non-transaction revenue y/y) | CL40: 0.02 | CM40: Δ → | CN40: -0.03 | CO40: 1H-26 +10%; surveillance and frequent-issuer fees, Crisil; price.
...

Sheet Bull-Base-Bear
B2: S&P Global Inc. (SPGI) — Bull / Base / Bear Case P&L Summary | J2: Share price ($): | K2: =Model!$BX$488 -> 415
B3: Adjusted figures (company definitions: adjusted operating profit, adjusted diluted EPS; adjusted EBITDA = model definition) · USD millions · continuing operations excluding Mobility · Live panel linked to Model — toggle scenario via Model!CC2. Bull and Bear panels are value snapshots generated from the Model with the switch set to each case. FY2026E = 1H actual (pro forma) + 2H calibrated to the FY26 guidance (revenue +5.9–7.9%, adjusted EPS $17.50–17.75). | J3: As of: | K3: =TODAY() -> 2026-10-12 00:00:00
B5: Scenario: | C5: =Model!$CC$2 -> Base | N5: Scenario: | O5: Bull | P5: Snapshot (values) — Model run with switch = Bull | Z5: Scenario: | AA5: Bear | AB5: Snapshot (values) — Model run with switch = Bear
B7: (USDm, except EPS and shares) | C7: 2026E | D7: 2027E | E7: 2028E | F7: 2029E | G7: 2030E | H7: 2031E | I7: 26-'31 CAGR | J7: LT Hist Avg | K7: LT Hist Min | L7: LT Hist Max | N7: (USDm, except EPS and shares) | O7: 2026E | P7: 2027E | Q7: 2028E | R7: 2029E | S7: 2030E | T7: 2031E | U7: 26-'31 CAGR | V7: LT Hist Avg | W7: LT Hist Min | X7: LT Hist Max | Z7: (USDm, except EPS and shares) | AA7: 2026E | AB7: 2027E | AC7: 2028E | AD7: 2029E | AE7: 2030E | AF7: 2031E | AG7: 26-'31 CAGR | AH7: LT Hist Avg | AI7: LT Hist Min | AJ7: LT Hist Max
B9: Revenue | C9: =Model!BW187 -> 14526.641 | D9: =Model!BX187 -> 15426.203 | E9: =Model!BY187 -> 16516.783 | F9: =Model!BZ187 -> 17650.843 | G9: =Model!CA187 -> 18809.309 | H9: =Model!CB187 -> 20042.002 | I9: =IFERROR((H9/C9)^(1/5)-1,"n/m") -> 0.066486056 | N9: Revenue | O9: 14662.531 | P9: 16002.395 | Q9: 17634.634 | R9: 19390.16 | S9: 21253.108 | T9: 23285.507 | U9: 0.096921005 | Z9: Revenue | AA9: 14390.751 | AB9: 14462.943 | AC9: 14641.292 | AD9: 14801.812 | AE9: 14933.161 | AF9: 15076.307 | AG9: 0.0093512033
B10: Revenue y/y % | D10: =IFERROR(D9/C9-1,"") -> 0.061924987 | E10: =IFERROR(E9/D9-1,"") -> 0.070696602 | F10: =IFERROR(F9/E9-1,"") -> 0.068661054 | G10: =IFERROR(G9/F9-1,"") -> 0.065632328 | H10: =IFERROR(H9/G9-1,"") -> 0.065536358 | N10: Revenue y/y % | P10: 0.091380163 | Q10: 0.10199963 | R10: 0.09954992 | S10: 0.096076989 | T10: 0.095628321 | Z10: Revenue y/y % | AB10: 0.0050165488 | AC10: 0.01233143 | AD10: 0.010963549 | AE10: 0.0088738142 | AF10: 0.0095858261
B11: Ratings revenue y/y % | C11: =Model!BW293 -> 0.10993476 | D11: =Model!BX293 -> 0.048153273 | E11: =Model!BY293 -> 0.064632911 | F11: =Model!BZ293 -> 0.06 | G11: =Model!CA293 -> 0.054656266 | H11: =Model!CB293 -> 0.054679859 | N11: Ratings revenue y/y % | O11: 0.11988131 | P11: 0.079081947 | Q11: 0.095413082 | R11: 0.090871496 | S11: 0.085481235 | T11: 0.085504053 | Z11: Ratings revenue y/y % | AA11: 0.099988221 | AB11: -0.0091794629 | AC11: 0.0085644453 | AD11: 0.0045456329 | AE11: 0.00020111902 | AF11: 0.0011008976
B12: Adjusted EBITDA (model) | C12: =Model!BW256 -> 7638.2824 | D12: =Model!BX256 -> 8309.2359 | E12: =Model!BY256 -> 8971.2164 | F12: =Model!BZ256 -> 9618.8125 | G12: =Model!CA256 -> 10291.886 | H12: =Model!CB256 -> 10979.397 | I12: =IFERROR((H12/C12)^(1/5)-1,"n/m") -> 0.075267583 | N12: Adjusted EBITDA (model) | O12: 7685.4478 | P12: 8775.4755 | Q12: 9750.4731 | R12: 10758.294 | S12: 11844.687 | T12: 13000.836 | U12: 0.11086279 | Z12: Adjusted EBITDA (model) | AA12: 7591.0685 | AB12: 7422.4785 | AC12: 7564.1227 | AD12: 7658.9854 | AE12: 7745.2453 | AF12: 7816.0513 | AG12: 0.0058585176
B13: Adjusted EBITDA margin % | C13: =IFERROR(C12/C9,"") -> 0.52581201 | D13: =IFERROR(D12/D9,"") -> 0.53864427 | E13: =IFERROR(E12/E9,"") -> 0.5431576 | F13: =IFERROR(F12/F9,"") -> 0.54494919 | G13: =IFERROR(G12/G9,"") -> 0.54716983 | H13: =IFERROR(H12/H9,"") -> 0.54781934 | J13: =IFERROR(AVERAGE(Model!C257,Model!D257,Model!E257,Model!J257,Model!O257,Model!T257,Model!Y257,Model!AD257,Model!AI257,Model!AN257,Model!AS257,Model!AX257,Model!BC257,Model!BH257,Model!BM257,Model!BR257),"") -> 0.44171145 | K13: =IFERROR(MIN(Model!C257,Model!D257,Model!E257,Model!J257,Model!O257,Model!T257,Model!Y257,Model!AD257,Model!AI257,Model!AN257,Model!AS257,Model!AX257,Model!BC257,Model!BH257,Model!BM257,Model!BR257),"") -> 0.30273141 | L13: =IFERROR(MAX(Model!C257,Model!D257,Model!E257,Model!J257,Model!O257,Model!T257,Model!Y257,Model!AD257,Model!AI257,Model!AN257,Model!AS257,Model!AX257,Model!BC257,Model!BH257,Model!BM257,Model!BR257),"") -> 0.56201037 | N13: Adjusted EBITDA margin % | O13: 0.52415561 | P13: 0.54838512 | Q13: 0.55291611 | R13: 0.55483264 | S13: 0.55731549 | T13: 0.55832306 | V13: 0.44171145 | W13: 0.30273141 | X13: 0.56201037 | Z13: Adjusted EBITDA margin % | AA13: 0.52749634 | AB13: 0.51320665 | AC13: 0.51662947 | AD13: 0.51743566 | AE13: 0.51866082 | AF13: 0.51843274 | AH13: 0.44171145 | AI13: 0.30273141 | AJ13: 0.56201037
B15: Operating profit (GAAP) | C15: =Model!BW196 -> 7057.2824 | D15: =Model!BX196 -> 7338.9929 | E15: =Model!BY196 -> 7998.5821 | F15: =Model!BZ196 -> 8651.4391 | G15: =Model!CA196 -> 9329.5785 | H15: =Model!CB196 -> 10020.561 | I15: =IFERROR((H15/C15)^(1/5)-1,"n/m") -> 0.072632385 | N15: Operating profit (GAAP) | O15: 7104.4478 | P15: 7784.7897 | Q15: 8741.3961 | R15: 9737.8392 | S15: 10811.995 | T15: 11953.552 | U15: 0.10966868 | Z15: Operating profit (GAAP) | AA15: 7010.0685 | AB15: 6475.7749 | AC15: 6633.9924 | AD15: 6753.5709 | AE15: 6864.78 | AF15: 6959.4408 | AG15: -0.0014486186
B16: Operating profit y/y % | D16: =IFERROR(D15/C15-1,"") -> 0.039917713 | E16: =IFERROR(E15/D15-1,"") -> 0.089874614 | F16: =IFERROR(F15/E15-1,"") -> 0.081621591 | G16: =IFERROR(G15/F15-1,"") -> 0.078384578 | H16: =IFERROR(H15/G15-1,"") -> 0.074063596 | N16: Operating profit y/y % | P16: 0.095762811 | Q16: 0.12288146 | R16: 0.11399131 | S16: 0.1103074 | T16: 0.10558243 | Z16: Operating profit y/y % | AB16: -0.07621803 | AC16: 0.024432212 | AD16: 0.018025119 | AE16: 0.016466713 | AF16: 0.013789342
B17: Operating margin (GAAP) % | C17: =IFERROR(C15/C9,"") -> 0.48581653 | D17: =IFERROR(D15/D9,"") -> 0.4757485 | E17: =IFERROR(E15/E9,"") -> 0.48426997 | F17: =IFERROR(F15/F9,"") -> 0.49014311 | G17: =IFERROR(G15/G9,"") -> 0.49600858 | H17: =IFERROR(H15/H9,"") -> 0.49997802 | J17: =IFERROR(AVERAGE(Model!C305,Model!D305,Model!E305,Model!J305,Model!O305,Model!T305,Model!Y305,Model!AD305,Model!AI305,Model!AN305,Model!AS305,Model!AX305,Model!BC305,Model!BH305,Model!BM305,Model!BR305),"") -> 0.37837768 | K17: =IFERROR(MIN(Model!C305,Model!D305,Model!E305,Model!J305,Model!O305,Model!T305,Model!Y305,Model!AD305,Model!AI305,Model!AN305,Model!AS305,Model!AX305,Model!BC305,Model!BH305,Model!BM305,Model!BR305),"") -> 0.022371808 | L17: =IFERROR(MAX(Model!C305,Model!D305,Model!E305,Model!J305,Model!O305,Model!T305,Model!Y305,Model!AD305,Model!AI305,Model!AN305,Model!AS305,Model!AX305,Model!BC305,Model!BH305,Model!BM305,Model!BR305),"") -> 0.59512454 | N17: Operating margin (GAAP) % | O17: 0.4845308 | P17: 0.48647652 | Q17: 0.49569479 | R17: 0.5022052 | S17: 0.50872535 | T17: 0.51334727 | V17: 0.37837768 | W17: 0.022371808 | X17: 0.59512454 | Z17: Operating margin (GAAP) % | AA17: 0.48712319 | AB17: 0.44774946 | AC17: 0.45310158 | AD17: 0.45626649 | AE17: 0.4597004 | AF17: 0.46161442 | AH17: 0.37837768 | AI17: 0.022371808 | AJ17: 0.59512454
B19: Adjusted Net Income | C19: =Model!BW270 -> 5151.1027 | D19: =Model!BX270 -> 5547.5621 | E19: =Model!BY270 -> 6003.5561 | F19: =Model!BZ270 -> 6405.5589 | G19: =Model!CA270 -> 6837.1597 | H19: =Model!CB270 -> 7283.3796 | I19: =IFERROR((H19/C19)^(1/5)-1,"n/m") -> 0.071732864 | N19: Adjusted Net Income | O19: 5184.9621 | P19: 5873.2227 | Q19: 6457.3802 | R19: 7094.3457 | S19: 7782.3107 | T19: 8519.3999 | U19: 0.10441598 | Z19: Adjusted Net Income | AA19: 5117.2056 | AB19: 4929.6586 | AC19: 5108.0194 | AD19: 5163.0276 | AE19: 5222.4277 | AF19: 5277.3579 | AG19: 0.0061824454
B21: FDSO (m) | C21: =Model!BW217 -> 292.26114 | D21: =Model!BX217 -> 277.39309 | E21: =Model!BY217 -> 267.67227 | F21: =Model!BZ217 -> 257.00028 | G21: =Model!CA217 -> 246.40775 | H21: =Model!CB217 -> 235.85994 | I21: =IFERROR((H21/C21)^(1/5)-1,"n/m") -> -0.041975488 | N21: FDSO (m) | O21: 292.11054 | P21: 273.83687 | Q21: 260.30007 | R21: 247.63317 | S21: 234.50842 | T21: 220.90521 | U21: -0.054347125 | Z21: FDSO (m) | AA21: 292.41175 | AB21: 281.71338 | AC21: 277.24308 | AD21: 269.92768 | AE21: 263.2582 | AF21: 257.14783 | AG21: -0.02537486
B23: Adjusted EPS — Diluted ($) | C23: =Model!BW274 -> 17.625 | D23: =Model!BX274 -> 19.99892 | E23: =Model!BY274 -> 22.428756 | F23: =Model!BZ274 -> 24.924327 | G23: =Model!CA274 -> 27.747341 | H23: =Model!CB274 -> 30.880105 | I23: =IFERROR((H23/C23)^(1/5)-1,"n/m") -> 0.11869044 | N23: Adjusted EPS — Diluted ($) | O23: 17.75 | P23: 21.447889 | Q23: 24.807448 | R23: 28.648608 | S23: 33.185634 | T23: 38.565861 | U23: 0.1678873 | Z23: Adjusted EPS — Diluted ($) | AA23: 17.5 | AB23: 17.498844 | AC23: 18.424335 | AD23: 19.127448 | AE23: 19.837664 | AF23: 20.522661 | AG23: 0.032378916
B24: EPS y/y % | D24: =IFERROR(D23/C23-1,"") -> 0.13469048 | E24: =IFERROR(E23/D23-1,"") -> 0.12149837 | F24: =IFERROR(F23/E23-1,"") -> 0.11126658 | G24: =IFERROR(G23/F23-1,"") -> 0.11326339 | H24: =IFERROR(H23/G23-1,"") -> 0.11290322 | N24: EPS y/y % | P24: 0.20833175 | Q24: 0.15663821 | R24: 0.15483901 | S24: 0.15836811 | T24: 0.16212519 | Z24: EPS y/y % | AB24: -6.6046231e-05 | AC24: 0.052888692 | AD24: 0.038162169 | AE24: 0.037130733 | AF24: 0.034530152
B26: P / E (x) — assumed (adjusted EPS) | F26: 26 | G26: 26 | H26: 26 | N26: P / E (x) — assumed (adjusted EPS) | R26: 30 | S26: 30 | T26: 30 | Z26: P / E (x) — assumed (adjusted EPS) | AD26: 20 | AE26: 20 | AF26: 20
B27: Price Target ($) | F27: =F26*F23 -> 648.0325 | G27: =G26*G23 -> 721.43085 | H27: =H26*H23 -> 802.88272 | N27: Price Target ($) | R27: =R26*R23 -> 859.45824 | S27: =S26*S23 -> 995.56902 | T27: =T26*T23 -> 1156.9758 | Z27: Price Target ($) | AD27: =AD26*AD23 -> 382.54896 | AE27: =AE26*AE23 -> 396.75328 | AF27: =AF26*AF23 -> 410.45323
B28: Upside / (Downside) vs current | F28: =IFERROR(F27/$K$2-1,"") -> 0.56152409 | G28: =IFERROR(G27/$K$2-1,"") -> 0.7383876 | H28: =IFERROR(H27/$K$2-1,"") -> 0.93465715 | N28: Upside / (Downside) vs current | R28: =IFERROR(R27/$K$2-1,"") -> 1.0709837 | S28: =IFERROR(S27/$K$2-1,"") -> 1.3989615 | T28: =IFERROR(T27/$K$2-1,"") -> 1.7878936 | Z28: Upside / (Downside) vs current | AD28: =IFERROR(AD27/$K$2-1,"") -> -0.078195289 | AE28: =IFERROR(AE27/$K$2-1,"") -> -0.043968004 | AF28: =IFERROR(AF27/$K$2-1,"") -> -0.010956073
B29: IRR (to 31-Dec of Y-1) | F29: =IFERROR((F27/$K$2)^(1/((DATE(2029-1,12,31)-$K$3)/365.25))-1,"") -> 0.22227381 | G29: =IFERROR((G27/$K$2)^(1/((DATE(2030-1,12,31)-$K$3)/365.25))-1,"") -> 0.18737077 | H29: =IFERROR((H27/$K$2)^(1/((DATE(2031-1,12,31)-$K$3)/365.25))-1,"") -> 0.16931437 | N29: IRR (to 31-Dec of Y-1) | R29: =IFERROR((R27/$K$2)^(1/((DATE(2029-1,12,31)-$K$3)/365.25))-1,"") -> 0.38802237 | S29: =IFERROR((S27/$K$2)^(1/((DATE(2030-1,12,31)-$K$3)/365.25))-1,"") -> 0.31229112 | T29: =IFERROR((T27/$K$2)^(1/((DATE(2031-1,12,31)-$K$3)/365.25))-1,"") -> 0.27508751 | Z29: IRR (to 31-Dec of Y-1) | AD29: =IFERROR((AD27/$K$2)^(1/((DATE(2029-1,12,31)-$K$3)/365.25))-1,"") -> -0.036005769 | AE29: =IFERROR((AE27/$K$2)^(1/((DATE(2030-1,12,31)-$K$3)/365.25))-1,"") -> -0.013868129 | AF29: =IFERROR((AF27/$K$2)^(1/((DATE(2031-1,12,31)-$K$3)/365.25))-1,"") -> -0.0026077482
B31: Free Cash Flow | C31: =Model!BW339 -> 5183.0146 | D31: =Model!BX339 -> 5846.5256 | E31: =Model!BY339 -> 6355.8976 | F31: =Model!BZ339 -> 6772.4646 | G31: =Model!CA339 -> 7213.9573 | H31: =Model!CB339 -> 7683.3266 | I31: =IFERROR((H31/C31)^(1/5)-1,"n/m") -> 0.081915572 | N31: Free Cash Flow | O31: 5251.2058 | P31: 6280.4455 | Q31: 6949.463 | R31: 7627.5096 | S31: 8353.1917 | T31: 9144.911 | U31: 0.11733676 | Z31: Free Cash Flow | AA31: 5114.7858 | AB31: 5020.2501 | AC31: 5222.4508 | AD31: 5268.068 | AE31: 5315.0361 | AF31: 5368.1808 | AG31: 0.0097176268
B32: FCF % | C32: =IFERROR(C31/C9,"") -> 0.35679374 | D32: =IFERROR(D31/D9,"") -> 0.37899965 | E32: =IFERROR(E31/E9,"") -> 0.3848145 | F32: =IFERROR(F31/F9,"") -> 0.38369072 | G32: =IFERROR(G31/G9,"") -> 0.38353123 | H32: =IFERROR(H31/H9,"") -> 0.38336122 | J32: =IFERROR(AVERAGE(Model!C343,Model!D343,Model!E343,Model!J343,Model!O343,Model!T343,Model!Y343,Model!AD343,Model!AI343,Model!AN343,Model!AS343,Model!AX343,Model!BC343,Model!BH343,Model!BM343,Model!BR343),"") -> 0.26407735 | K32: =IFERROR(MIN(Model!C343,Model!D343,Model!E343,Model!J343,Model!O343,Model!T343,Model!Y343,Model!AD343,Model!AI343,Model!AN343,Model!AS343,Model!AX343,Model!BC343,Model!BH343,Model!BM343,Model!BR343),"") -> -0.0090344438 | L32: =IFERROR(MAX(Model!C343,Model!D343,Model!E343,Model!J343,Model!O343,Model!T343,Model!Y343,Model!AD343,Model!AI343,Model!AN343,Model!AS343,Model!AX343,Model!BC343,Model!BH343,Model!BM343,Model!BR343),"") -> 0.44302607 | N32: FCF % | O32: 0.35813775 | P32: 0.39246909 | Q32: 0.39408037 | R32: 0.39337012 | S32: 0.39303388 | T32: 0.39272973 | V32: 0.26407735 | W32: -0.0090344438 | X32: 0.44302607 | Z32: FCF % | AA32: 0.35542174 | AB32: 0.34711124 | AC32: 0.35669331 | AD32: 0.35590696 | AE32: 0.35592171 | AF32: 0.35606735 | AH32: 0.26407735 | AI32: -0.0090344438 | AJ32: 0.44302607
B33: FCF / share ($) | C33: =IFERROR(C31/C21,"") -> 17.73419 | D33: =IFERROR(D31/D21,"") -> 21.076681 | E33: =IFERROR(E31/E21,"") -> 23.745073 | F33: =IFERROR(F31/F21,"") -> 26.351974 | G33: =IFERROR(G31/G21,"") -> 29.276504 | H33: =IFERROR(H31/H21,"") -> 32.575801 | N33: FCF / share ($) | O33: 17.976776 | P33: 22.934989 | Q33: 26.697892 | R33: 30.801647 | S33: 35.620007 | T33: 41.397443 | Z33: FCF / share ($) | AA33: 17.491725 | AB33: 17.820417 | AC33: 18.837083 | AD33: 19.51659 | AE33: 20.189442 | AF33: 20.875855
B34: FCF Yield (on PT) | F34: =IFERROR(F33/F$27,"") -> 0.040664587 | G34: =IFERROR(G33/G$27,"") -> 0.040581164 | H34: =IFERROR(H33/H$27,"") -> 0.040573549 | N34: FCF Yield (on PT) | R34: =IFERROR(R33/R$27,"") -> 0.035838445 | S34: =IFERROR(S33/S$27,"") -> 0.035778541 | T34: =IFERROR(T33/T$27,"") -> 0.035780732 | Z34: FCF Yield (on PT) | AD34: =IFERROR(AD33/AD$27,"") -> 0.051017236 | AE34: =IFERROR(AE33/AE$27,"") -> 0.050886641 | AF34: =IFERROR(AF33/AF$27,"") -> 0.050860497
B35: Adjusted EBITDA (leverage basis) | C35: =Model!BW256 -> 7638.2824 | D35: =Model!BX256 -> 8309.2359 | E35: =Model!BY256 -> 8971.2164 | F35: =Model!BZ256 -> 9618.8125 | G35: =Model!CA256 -> 10291.886 | H35: =Model!CB256 -> 10979.397 | I35: =IFERROR((H35/C35)^(1/5)-1,"n/m") -> 0.075267583 | N35: Adjusted EBITDA (leverage basis) | O35: 7685.4478 | P35: 8775.4755 | Q35: 9750.4731 | R35: 10758.294 | S35: 11844.687 | T35: 13000.836 | U35: 0.11086279 | Z35: Adjusted EBITDA (leverage basis) | AA35: 7591.0685 | AB35: 7422.4785 | AC35: 7564.1227 | AD35: 7658.9854 | AE35: 7745.2453 | AF35: 7816.0513 | AG35: 0.0058585176
B36: Adjusted EBITDA % of revenue | C36: =IFERROR(C35/C9,"") -> 0.52581201 | D36: =IFERROR(D35/D9,"") -> 0.53864427 | E36: =IFERROR(E35/E9,"") -> 0.5431576 | F36: =IFERROR(F35/F9,"") -> 0.54494919 | G36: =IFERROR(G35/G9,"") -> 0.54716983 | H36: =IFERROR(H35/H9,"") -> 0.54781934 | J36: =IFERROR(AVERAGE(Model!C304,Model!D304,Model!E304,Model!J304,Model!O304,Model!T304,Model!Y304,Model!AD304,Model!AI304,Model!AN304,Model!AS304,Model!AX304,Model!BC304,Model!BH304,Model!BM304,Model!BR304),"") -> 0.44171145 | K36: =IFERROR(MIN(Model!C304,Model!D304,Model!E304,Model!J304,Model!O304,Model!T304,Model!Y304,Model!AD304,Model!AI304,Model!AN304,Model!AS304,Model!AX304,Model!BC304,Model!BH304,Model!BM304,Model!BR304),"") -> 0.30273141 | L36: =IFERROR(MAX(Model!C304,Model!D304,Model!E304,Model!J304,Model!O304,Model!T304,Model!Y304,Model!AD304,Model!AI304,Model!AN304,Model!AS304,Model!AX304,Model!BC304,Model!BH304,Model!BM304,Model!BR304),"") -> 0.56201037 | N36: Adjusted EBITDA % of revenue | O36: 0.52415561 | P36: 0.54838512 | Q36: 0.55291611 | R36: 0.55483264 | S36: 0.55731549 | T36: 0.55832306 | V36: 0.44171145 | W36: 0.30273141 | X36: 0.56201037 | Z36: Adjusted EBITDA % of revenue | AA36: 0.52749634 | AB36: 0.51320665 | AC36: 0.51662947 | AD36: 0.51743566 | AE36: 0.51866082 | AF36: 0.51843274 | AH36: 0.44171145 | AI36: 0.30273141 | AJ36: 0.56201037
B38: Net Debt | C38: =Model!BW482 -> 12314.897 | D38: =Model!BX482 -> 12463.854 | E38: =Model!BY482 -> 13456.825 | F38: =Model!BZ482 -> 14428.219 | G38: =Model!CA482 -> 15437.829 | H38: =Model!CB482 -> 16469.095 | N38: Net Debt | O38: 12496.706 | P38: 15357.082 | Q38: 17063.328 | R38: 18827.014 | S38: 20728.201 | T38: 22751.463 | Z38: Net Debt | AA38: 12133.126 | AB38: 9278.0981 | AC38: 9455.1534 | AD38: 9573.7318 | AE38: 9681.5566 | AF38: 9770.0641
B39: Net Debt / Adjusted EBITDA (x) | C39: =IFERROR(C38/C35,"") -> 1.61226 | D39: =IFERROR(D38/D35,"") -> 1.5 | E39: =IFERROR(E38/E35,"") -> 1.5 | F39: =IFERROR(F38/F35,"") -> 1.5 | G39: =IFERROR(G38/G35,"") -> 1.5 | H39: =IFERROR(H38/H35,"") -> 1.5 | N39: Net Debt / Adjusted EBITDA (x) | O39: 1.6260219 | P39: 1.75 | Q39: 1.75 | R39: 1.75 | S39: 1.75 | T39: 1.75 | Z39: Net Debt / Adjusted EBITDA (x) | AA39: 1.5983423 | AB39: 1.25 | AC39: 1.25 | AD39: 1.25 | AE39: 1.25 | AF39: 1.25
B40: Share repurchases ($m; FY2026E = 2H) | D40: =Model!BX353 -> 4348.8769 | E40: =Model!BY353 -> 5682.1616 | F40: =Model!BZ353 -> 6067.0503 | G40: =Model!CA353 -> 6537.9356 | H40: =Model!CB353 -> 7022.0685 | N40: Share repurchases ($m; FY2026E = 2H) | P40: 6996.6706 | Q40: 6516.85 | R40: 7251.3727 | S40: 8118.2654 | T40: 9041.504 | AB40: 1016.1625 | AC40: 4198.4145 | AD40: 4159.9658 | AE40: 4167.6586 | AF40: 4170.3272
B41: Implied avg buyback price ($) | D41: =Model!BX352 -> 448.2 | E41: =Model!BY352 -> 484.056 | F41: =Model!BZ352 -> 522.78048 | G41: =Model!CA352 -> 564.60292 | H41: =Model!CB352 -> 609.77115 | N41: Implied avg buyback price ($) | P41: 448.2 | Q41: 484.056 | R41: 522.78048 | S41: 564.60292 | T41: 609.77115 | AB41: 448.2 | AC41: 484.056 | AD41: 522.78048 | AE41: 564.60292 | AF41: 609.77115
B42: Shares repurchased (m) | D42: =Model!BX354 -> 9.7029828 | E42: =Model!BY354 -> 11.738645 | F42: =Model!BZ354 -> 11.60535 | G42: =Model!CA354 -> 11.579706 | H42: =Model!CB354 -> 11.515908 | N42: Shares repurchased (m) | P42: 15.610599 | Q42: 13.463008 | R42: 13.870779 | S42: 14.378717 | T42: 14.8277 | AB42: 2.2672077 | AC42: 8.6734067 | AD42: 7.9573856 | AE42: 7.3815747 | AF42: 6.8391678
B44: ROIC | C44: =Model!BW465 -> 0.16235083 | D44: =Model!BX465 -> 0.18036487 | E44: =Model!BY465 -> 0.19645952 | F44: =Model!BZ465 -> 0.212428 | G44: =Model!CA465 -> 0.22912833 | H44: =Model!CB465 -> 0.24638904 | J44: =IFERROR(AVERAGE(Model!C465,Model!D465,Model!E465,Model!J465,Model!O465,Model!T465,Model!Y465,Model!AD465,Model!AI465,Model!AN465,Model!AS465,Model!AX465,Model!BC465,Model!BH465,Model!BM465,Model!BR465),"") -> 0.4313108 | K44: =IFERROR(MIN(Model!C465,Model!D465,Model!E465,Model!J465,Model!O465,Model!T465,Model!Y465,Model!AD465,Model!AI465,Model!AN465,Model!AS465,Model!AX465,Model!BC465,Model!BH465,Model!BM465,Model!BR465),"") -> -0.21665383 | L44: =IFERROR(MAX(Model!C465,Model!D465,Model!E465,Model!J465,Model!O465,Model!T465,Model!Y465,Model!AD465,Model!AI465,Model!AN465,Model!AS465,Model!AX465,Model!BC465,Model!BH465,Model!BM465,Model!BR465),"") -> 1.0746325 | N44: ROIC | O44: 0.16354826 | P44: 0.18847906 | Q44: 0.20920422 | R44: 0.23066584 | S44: 0.25386309 | T44: 0.27873661 | V44: 0.4313108 | W44: -0.21665383 | X44: 1.0746325 | Z44: ROIC | AA44: 0.16115466 | AB44: 0.16228985 | AC44: 0.16808642 | AD44: 0.17283526 | AE44: 0.17735407 | AF44: 0.18151091 | AH44: 0.4313108 | AI44: -0.21665383 | AJ44: 1.0746325
B45: ROE | C45: =Model!BW480 -> 0.27462507 | D45: =Model!BX480 -> 0.28289916 | E45: =Model!BY480 -> 0.33409368 | F45: =Model!BZ480 -> 0.39007873 | G45: =Model!CA480 -> 0.45931668 | H45: =Model!CB480 -> 0.54488411 | J45: =IFERROR(AVERAGE(Model!C480,Model!D480,Model!E480,Model!J480,Model!O480,Model!T480,Model!Y480,Model!AD480,Model!AI480,Model!AN480,Model!AS480,Model!AX480,Model!BC480,Model!BH480,Model!BM480,Model!BR480),"") -> 1.9109924 | K45: =IFERROR(MIN(Model!C480,Model!D480,Model!E480,Model!J480,Model!O480,Model!T480,Model!Y480,Model!AD480,Model!AI480,Model!AN480,Model!AS480,Model!AX480,Model!BC480,Model!BH480,Model!BM480,Model!BR480),"") -> -0.23565574 | L45: =IFERROR(MAX(Model!C480,Model!D480,Model!E480,Model!J480,Model!O480,Model!T480,Model!Y480,Model!AD480,Model!AI480,Model!AN480,Model!AS480,Model!AX480,Model!BC480,Model!BH480,Model!BM480,Model!BR480),"") -> 5.9587629 | N45: ROE | O45: 0.27993964 | P45: 0.35258063 | Q45: 0.44052529 | R45: 0.56228669 | S45: 0.74370032 | T45: 1.0394065 | V45: 1.9109924 | W45: -0.23565574 | X45: 5.9587629 | Z45: ROE | AA45: 0.26943679 | AB45: 0.21219107 | AC45: 0.22991477 | AD45: 0.24163182 | AE45: 0.25378257 | AF45: 0.26581689 | AH45: 1.9109924 | AI45: -0.23565574 | AJ45: 5.9587629
B47: Implied Market Cap (USDm) | F47: =F27*F21 -> 166544.53 | G47: =G27*G21 -> 177766.15 | H47: =H27*H21 -> 189367.87 | N47: Implied Market Cap (USDm) | R47: =R27*R21 -> 212830.37 | S47: =S27*S21 -> 233469.32 | T47: =T27*T21 -> 255582 | Z47: Implied Market Cap (USDm) | AD47: =AD27*AD21 -> 103260.55 | AE47: =AE27*AE21 -> 104448.55 | AF47: =AF27*AF21 -> 105547.16
B48: (+) Net Debt & NCI | F48: =F38+Model!BZ492 -> 19567.219 | G48: =G38+Model!CA492 -> 20576.829 | H48: =H38+Model!CB492 -> 21608.095 | N48: (+) Net Debt & NCI | R48: =R38+Model!BZ492 -> 23966.014 | S48: =S38+Model!CA492 -> 25867.201 | T48: =T38+Model!CB492 -> 27890.463 | Z48: (+) Net Debt & NCI | AD48: =AD38+Model!BZ492 -> 14712.732 | AE48: =AE38+Model!CA492 -> 14820.557 | AF48: =AF38+Model!CB492 -> 14909.064
B49: Implied Enterprise Value (USDm) | F49: =F47+F48 -> 186111.75 | G49: =G47+G48 -> 198342.98 | H49: =H47+H48 -> 210975.97 | N49: Implied Enterprise Value (USDm) | R49: =R47+R48 -> 236796.38 | S49: =S47+S48 -> 259336.52 | T49: =T47+T48 -> 283472.46 | Z49: Implied Enterprise Value (USDm) | AD49: =AD47+AD48 -> 117973.28 | AE49: =AE47+AE48 -> 119269.11 | AF49: =AF47+AF48 -> 120456.22
B50: Implied EV / Adjusted EBITDA (x) | F50: =IFERROR(F49/F35,"") -> 19.348724 | G50: =IFERROR(G49/G35,"") -> 19.271781 | H50: =IFERROR(H49/H35,"") -> 19.215625 | N50: Implied EV / Adjusted EBITDA (x) | R50: =IFERROR(R49/R35,"") -> 22.010589 | S50: =IFERROR(S49/S35,"") -> 21.894756 | T50: =IFERROR(T49/T35,"") -> 21.804172 | Z50: Implied EV / Adjusted EBITDA (x) | AD50: =IFERROR(AD49/AD35,"") -> 15.403252 | AE50: =IFERROR(AE49/AE35,"") -> 15.39901 | AF50: =IFERROR(AF49/AF35,"") -> 15.411391

Sheet DCF
B2: DCF VALUATION — S&P GLOBAL INC. (SPGI)
B4: 1. WACC BUILD
B5: Risk-free rate (US 10Y govt) | C5: 0.0425 | D5: Assumption (~US 10Y Treasury yield, Oct-2026; government rate sources not reachable from the build environment); update to market
B6: Equity risk premium | C6: 0.05 | D6: Assumption: US implied ERP ~4.5–5.5%
B7: Levered beta | C7: 1 | D7: Assumption: information-services / benchmark peers (MCO, MSCI, ICE, CME, VRSK, FDS) ~0.9–1.1; Ratings issuance and Indices asset-linked fees are market-sensitive, subscriptions defensive
B8: Cost of equity | C8: =C5+C7*C6 -> 0.0925
B9: Pre-tax cost of debt | C9: 0.05 | D9: Recent issues: $600m 4.25% 2031 and $400m 4.80% 2035 notes (Dec-2025); A-rated issuer; pre-tax cost of new debt ~5% (assumption)
B10: Tax rate | C10: 0.225 | D10: Model 2027E+ effective tax rate (FY26 guidance 22–23%)
B11: After-tax cost of debt | C11: =C9*(1-C10) -> 0.03875
B12: Target D/V | C12: 0.1 | D12: Net debt ~$12bn at YE2026E (after >$7bn of 2026 buybacks) vs ~$118bn market cap ($415 × ~283m diluted shares); ~1.6x adjusted EBITDA; plus ~$5bn redeemable NCI
B13: WACC | C13: =C8*(1-C12)+C11*C12 -> 0.087125
B15: Valuation date (live) | C15: =TODAY() -> 2026-10-12 00:00:00 | D15: Periods = (31-Dec of the year − today) / 365.25; cash flows assumed at year end; FY2026E (Q4 under way at the valuation date) is the base year — its cash flow is in YE2026E net debt
B16: 2. UNLEVERED FREE CASH FLOW BUILD (USDm)
D17: 2027E | E17: 2028E | F17: 2029E | G17: 2030E | H17: 2031E | I17: 2032E | J17: 2033E | K17: 2034E | L17: 2035E | M17: 2036E | N17: Terminal | P17: CAGR 27–31E | Q17: CAGR 27–36E
