Workbook

Sheet Model
AU1: SCENARIO SWITCH ▼ (Bull / Base / Bear) — drives all scenario-linked forecast drivers
B2: STERIS plc (NYSE: STE) — 3-Statement Financial Model | AU2: Base
B3: US GAAP as reported · USD millions (per-share data in USD; shares in millions) · Fiscal years ended 31 March (2027 = Apr-2026 – Mar-2027) · Source: STERIS Forms 10-K / 10-Q and Form 8-K earnings releases (Ex. 99.1), SEC EDGAR (STERIS Corp CIK 815065 to FY2015; STERIS plc (UK) CIK 1624899 FY2016–19; STERIS plc (Ireland) CIK 1757898 from FY2019); investor-relations releases at steris-ir.com are the same documents as filed on EDGAR
B4: Basis notes: FY2012–FY2022 as originally reported; FY2023 onward continuing operations (Dental, acquired with Cantel Jun-2021, sold Sep-2024, recast in the Q4 FY24 and FY25 releases) — originally reported adjusted EPS rebuilt and checked in memo rows. Segments: Healthcare, Applied Sterilization Technologies (AST), Life Sciences (+ Dental FY2022). Acquisitions: Synergy Health Nov-15, Cantel Jun-21, BD surgical instrumentation Aug-23. Q2/27E–Q4/27E calibrated to FY27 revenue-growth and adjusted-EPS guidance.
AW5: Forecast | AX5: Historical | AY5: Historical | AZ5: Historical
B6: (USDm) | C6: 2012 | D6: 2013 | E6: 2014 | F6: 2015 | G6: 2016 | H6: 2017 | I6: 2018 | J6: 2019 | K6: 2020 | L6: 2021 | M6: Q1/22 | N6: Q2/22 | O6: Q3/22 | P6: Q4/22 | Q6: 2022 | R6: Q1/23 | S6: Q2/23 | T6: Q3/23 | U6: Q4/23 | V6: 2023 | W6: Q1/24 | X6: Q2/24 | Y6: Q3/24 | Z6: Q4/24 | AA6: 2024 | AB6: Q1/25 | AC6: Q2/25 | AD6: Q3/25 | AE6: Q4/25 | AF6: 2025 | AG6: Q1/26 | AH6: Q2/26 | AI6: Q3/26 | AJ6: Q4/26 | AK6: 2026 | AL6: Q1/27 | AM6: Q2/27E | AN6: Q3/27E | AO6: Q4/27E | AP6: 2027E | AQ6: 2028E | AR6: 2029E | AS6: 2030E | AT6: 2031E | AU6: Modelling Notes | AW6: 5Y CAGR | AX6: 5Y CAGR | AY6: 10Y CAGR | AZ6: 14Y CAGR
AW7: 26-'31 | AX7: 21-'26 | AY7: 16-'26 | AZ7: 12-'26
B8: SEGMENT P&L — HEALTHCARE · AST · LIFE SCIENCES (revenue by type × segment operating margin) | AU8: SEGMENT BUILD — modelling logic (capital / consumables / service revenue by segment → segment operating income at the segment margin → + corporate = adjusted operating income → GAAP P&L)
BC9: SCENARIO INPUT TABLE — driver assumptions per Bull / Base / Bear | BD9: Bull | BE9: Base | BF9: Bear | BG9: Bull / Bear = Base + Δ (Δ inputs on each block header). Outlook block = high / mid / low end of the FY27 guidance ranges.
B10: Healthcare (infection prevention consumables, sterilizers & washers, surgical tables / lights / OR integration, endoscopy (Cantel), repair & instrument services) | AU10: HEALTHCARE — modelling logic
B11: Capital equipment revenue | C11: 545.596 | D11: 521.806 | E11: 515.38 | F11: 517.007 | G11: 524.992 | H11: 547.5425 | I11: 527.402 | J11: 568.811 | K11: 592.436 | L11: 588.864 | M11: 150.89 | N11: 202.405 | O11: 217.214 | P11: 211.996 | Q11: 782.505 | R11: 179.134 | S11: 212.484 | T11: 227.226 | U11: 277.746 | V11: 896.59 | W11: 238.099 | X11: 254.905 | Y11: 266.838 | Z11: 331.695 | AA11: 1091.537 | AB11: 214.639 | AC11: 249.732 | AD11: 254.804 | AE11: 318.025 | AF11: 1037.2 | AG11: 227.3 | AH11: 259.4 | AI11: 272.1 | AJ11: 337.1 | AK11: 1095.9 | AL11: 230.5 | AM11: =AH11*(1+AM12) | AN11: =AI11*(1+AN12) | AO11: =AJ11*(1+AO12) | AP11: =SUM(AL11,AM11,AN11,AO11) | AQ11: =AP11*(1+AQ12) | AR11: =AQ11*(1+AR12) | AS11: =AR11*(1+AS12) | AT11: =AS11*(1+AT12) | AU11: Revenue by type as published (release "Unaudited Supplemental Financial Data"). Q2–Q4/27E: prior-year quarter × (1 + growth). 2028E+: prior year × (1 + scenario lever). | AW11: =IFERROR((AT11/AK11)^(1/5)-1,"n/m") | AX11: =IFERROR((AK11/L11)^(1/5)-1,"n/m") | AY11: =IFERROR((AK11/G11)^(1/10)-1,"n/m") | AZ11: =IFERROR((AK11/C11)^(1/14)-1,"n/m") | BC11: FY27 outlook — Q4 FY26 release (11-May-26), reiterated 5-Aug-26 | BD11: High | BE11: Mid | BF11: Low | BG11: As-reported revenue growth 7–8% (incl. Healthcare tuck-ins, slightly favourable FX); constant-currency organic 6–7%; adjusted EPS $11.10–11.30 (+9–11% vs $10.17); ~25% tax rate; capex ~$450m (raised from $375m in Aug-26); free cash flow ~$800m (from $850m).
B12: y/y % | D12: =IF(AND(ISNUMBER(D11),ISNUMBER(C11)),IFERROR(D11/C11-1,""),"") | E12: =IF(AND(ISNUMBER(E11),ISNUMBER(D11)),IFERROR(E11/D11-1,""),"") | F12: =IF(AND(ISNUMBER(F11),ISNUMBER(E11)),IFERROR(F11/E11-1,""),"") | G12: =IF(AND(ISNUMBER(G11),ISNUMBER(F11)),IFERROR(G11/F11-1,""),"") | H12: =IF(AND(ISNUMBER(H11),ISNUMBER(G11)),IFERROR(H11/G11-1,""),"") | I12: =IF(AND(ISNUMBER(I11),ISNUMBER(H11)),IFERROR(I11/H11-1,""),"") | J12: =IF(AND(ISNUMBER(J11),ISNUMBER(I11)),IFERROR(J11/I11-1,""),"") | K12: =IF(AND(ISNUMBER(K11),ISNUMBER(J11)),IFERROR(K11/J11-1,""),"") | L12: =IF(AND(ISNUMBER(L11),ISNUMBER(K11)),IFERROR(L11/K11-1,""),"") | Q12: =IF(AND(ISNUMBER(Q11),ISNUMBER(L11)),IFERROR(Q11/L11-1,""),"") | R12: =IF(AND(ISNUMBER(R11),ISNUMBER(M11)),IFERROR(R11/M11-1,""),"") | S12: =IF(AND(ISNUMBER(S11),ISNUMBER(N11)),IFERROR(S11/N11-1,""),"") | T12: =IF(AND(ISNUMBER(T11),ISNUMBER(O11)),IFERROR(T11/O11-1,""),"") | U12: =IF(AND(ISNUMBER(U11),ISNUMBER(P11)),IFERROR(U11/P11-1,""),"") | V12: =IF(AND(ISNUMBER(V11),ISNUMBER(Q11)),IFERROR(V11/Q11-1,""),"") | W12: =IF(AND(ISNUMBER(W11),ISNUMBER(R11)),IFERROR(W11/R11-1,""),"") | X12: =IF(AND(ISNUMBER(X11),ISNUMBER(S11)),IFERROR(X11/S11-1,""),"") | ... AL12: =IF(AND(ISNUMBER(AL11),ISNUMBER(AG11)),IFERROR(AL11/AG11-1,""),"") | AM12: =AM13+$AM$127 | AN12: =AN13+$AM$127 | AO12: =AO13+$AM$127 | AP12: =IF(AND(ISNUMBER(AP11),ISNUMBER(AK11)),IFERROR(AP11/AK11-1,""),"") | AQ12: =CHOOSE(MATCH($AU$2,{"Bull","Base","Bear"},0),$BD$30,$BE$30,$BF$30) | AR12: =CHOOSE(MATCH($AU$2,{"Bull","Base","Bear"},0),$BD$31,$BE$31,$BF$31) | AS12: =CHOOSE(MATCH($AU$2,{"Bull","Base","Bear"},0),$BD$32,$BE$32,$BF$32) | AT12: =CHOOSE(MATCH($AU$2,{"Bull","Base","Bear"},0),$BD$33,$BE$33,$BF$33) | AU12: Q2–Q4/27E: Q1/27 y/y growth of the line + revenue-outlook calibration Δ (Group block). 2028E–2031E: scenario lever (Bull/Base/Bear table →). | BC12: FY27 revenue growth, as reported | BD12: 0.08 | BE12: 0.075 | BF12: 0.07 | BG12: Guided 7–8%. Drives the Q2–Q4/27E revenue calibration.
B13: Q2–Q4/27E growth before revenue calibration (Q1/27 y/y) | AM13: =IFERROR(AL11/AG11-1,0) | AN13: =IFERROR(AL11/AG11-1,0) | AO13: =IFERROR(AL11/AG11-1,0) | BC13: FY27 constant-currency organic growth — memo | BD13: 0.07 | BE13: 0.065 | BF13: 0.06 | BG13: Guided 6–7% (memo; compare the growth-bridge row).
B14: Consumables revenue | C14: 229.504 | D14: 278.15 | E14: 325.703 | F14: 359.49 | G14: 381.477 | H14: 402.50063 | I14: 412.495 | J14: 414.969 | K14: 454.518 | L14: 510.946 | M14: 206.692 | N14: 270.089 | O14: 273.75 | P14: 254.074 | Q14: 1004.605 | R14: 252.032 | S14: 246.05 | T14: 259.81 | U14: 292.424 | V14: 1050.316 | W14: 280.281 | X14: 306.025 | Y14: 329.435 | Z14: 332.683 | AA14: 1248.424 | AB14: 343.354 | AC14: 341.707 | AD14: 358.233 | AE14: 352.737 | AF14: 1396.031 | AG14: 358.9 | AH14: 374.2 | AI14: 387.1 | AJ14: 376.4 | AK14: 1496.6 | AL14: 391.9 | AM14: =AH14*(1+AM15) | AN14: =AI14*(1+AN15) | AO14: =AJ14*(1+AO15) | AP14: =SUM(AL14,AM14,AN14,AO14) | AQ14: =AP14*(1+AQ15) | AR14: =AQ14*(1+AR15) | AS14: =AR14*(1+AS15) | AT14: =AS14*(1+AT15) | AW14: =IFERROR((AT14/AK14)^(1/5)-1,"n/m") | AX14: =IFERROR((AK14/L14)^(1/5)-1,"n/m") | AY14: =IFERROR((AK14/G14)^(1/10)-1,"n/m") | AZ14: =IFERROR((AK14/C14)^(1/14)-1,"n/m") | BC14: FY27 adjusted EPS ($) | BD14: 11.3 | BE14: 11.2 | BF14: 11.1 | BG14: Guided $11.10–11.30. Drives the Q2–Q4/27E segment-margin calibration.
B15: y/y % | D15: =IF(AND(ISNUMBER(D14),ISNUMBER(C14)),IFERROR(D14/C14-1,""),"") | E15: =IF(AND(ISNUMBER(E14),ISNUMBER(D14)),IFERROR(E14/D14-1,""),"") | F15: =IF(AND(ISNUMBER(F14),ISNUMBER(E14)),IFERROR(F14/E14-1,""),"") | G15: =IF(AND(ISNUMBER(G14),ISNUMBER(F14)),IFERROR(G14/F14-1,""),"") | H15: =IF(AND(ISNUMBER(H14),ISNUMBER(G14)),IFERROR(H14/G14-1,""),"") | I15: =IF(AND(ISNUMBER(I14),ISNUMBER(H14)),IFERROR(I14/H14-1,""),"") | J15: =IF(AND(ISNUMBER(J14),ISNUMBER(I14)),IFERROR(J14/I14-1,""),"") | K15: =IF(AND(ISNUMBER(K14),ISNUMBER(J14)),IFERROR(K14/J14-1,""),"") | L15: =IF(AND(ISNUMBER(L14),ISNUMBER(K14)),IFERROR(L14/K14-1,""),"") | Q15: =IF(AND(ISNUMBER(Q14),ISNUMBER(L14)),IFERROR(Q14/L14-1,""),"") | R15: =IF(AND(ISNUMBER(R14),ISNUMBER(M14)),IFERROR(R14/M14-1,""),"") | S15: =IF(AND(ISNUMBER(S14),ISNUMBER(N14)),IFERROR(S14/N14-1,""),"") | T15: =IF(AND(ISNUMBER(T14),ISNUMBER(O14)),IFERROR(T14/O14-1,""),"") | U15: =IF(AND(ISNUMBER(U14),ISNUMBER(P14)),IFERROR(U14/P14-1,""),"") | V15: =IF(AND(ISNUMBER(V14),ISNUMBER(Q14)),IFERROR(V14/Q14-1,""),"") | W15: =IF(AND(ISNUMBER(W14),ISNUMBER(R14)),IFERROR(W14/R14-1,""),"") | X15: =IF(AND(ISNUMBER(X14),ISNUMBER(S14)),IFERROR(X14/S14-1,""),"") | ... AL15: =IF(AND(ISNUMBER(AL14),ISNUMBER(AG14)),IFERROR(AL14/AG14-1,""),"") | AM15: =AM16+$AM$127 | AN15: =AN16+$AM$127 | AO15: =AO16+$AM$127 | AP15: =IF(AND(ISNUMBER(AP14),ISNUMBER(AK14)),IFERROR(AP14/AK14-1,""),"") | AQ15: =CHOOSE(MATCH($AU$2,{"Bull","Base","Bear"},0),$BD$35,$BE$35,$BF$35) | AR15: =CHOOSE(MATCH($AU$2,{"Bull","Base","Bear"},0),$BD$36,$BE$36,$BF$36) | AS15: =CHOOSE(MATCH($AU$2,{"Bull","Base","Bear"},0),$BD$37,$BE$37,$BF$37) | AT15: =CHOOSE(MATCH($AU$2,{"Bull","Base","Bear"},0),$BD$38,$BE$38,$BF$38) | BC15: FY27 GAAP diluted EPS, continuing ($) — memo | BD15: 9.12 | BE15: 9.02 | BF15: 8.92 | BG15: Guided $8.92–9.12 (amortization $2.08, acquisition $0.01, restructuring $0.07, other $0.02 per share); memo, not forced.
B16: Q2–Q4/27E growth before revenue calibration (Q1/27 y/y) | AM16: =IFERROR(AL14/AG14-1,0) | AN16: =IFERROR(AL14/AG14-1,0) | AO16: =IFERROR(AL14/AG14-1,0) | BC16: Q2–Q4/27E share repurchases ($m) | BD16: 400 | BE16: 300 | BF16: 200 | BG16: Q1/27 $115.5m; $900m left on the $1.0bn May-2026 authorization.
B17: Service revenue | C17: 238.002 | D17: 274.834 | E17: 338.968 | F17: 515.377 | G17: 723.549 | H17: 871.00987 | I17: 805.222 | J17: 864.705 | K17: 939.855 | L17: 854.245 | M17: 245.235 | N17: 271.64 | O17: 268.711 | P17: 272.771 | Q17: 1058.357 | R17: 267.36 | S17: 274.279 | T17: 282.108 | U17: 314.478 | V17: 1138.225 | W17: 300.494 | X17: 309.126 | Y17: 319.954 | Z17: 343.484 | AA17: 1273.058 | AB17: 343.228 | AC17: 352.791 | AD17: 363.007 | AE17: 386.414 | AF17: 1445.44 | AG17: 388.5 | AH17: 400.1 | AI17: 404.7 | AJ17: 422.8 | AK17: 1616 | AL17: 425.9 | AM17: =AH17*(1+AM18) | AN17: =AI17*(1+AN18) | AO17: =AJ17*(1+AO18) | AP17: =SUM(AL17,AM17,AN17,AO17) | AQ17: =AP17*(1+AQ18) | AR17: =AQ17*(1+AR18) | AS17: =AR17*(1+AS18) | AT17: =AS17*(1+AT18) | AW17: =IFERROR((AT17/AK17)^(1/5)-1,"n/m") | AX17: =IFERROR((AK17/L17)^(1/5)-1,"n/m") | AY17: =IFERROR((AK17/G17)^(1/10)-1,"n/m") | AZ17: =IFERROR((AK17/C17)^(1/14)-1,"n/m")
B18: y/y % | D18: =IF(AND(ISNUMBER(D17),ISNUMBER(C17)),IFERROR(D17/C17-1,""),"") | E18: =IF(AND(ISNUMBER(E17),ISNUMBER(D17)),IFERROR(E17/D17-1,""),"") | F18: =IF(AND(ISNUMBER(F17),ISNUMBER(E17)),IFERROR(F17/E17-1,""),"") | G18: =IF(AND(ISNUMBER(G17),ISNUMBER(F17)),IFERROR(G17/F17-1,""),"") | H18: =IF(AND(ISNUMBER(H17),ISNUMBER(G17)),IFERROR(H17/G17-1,""),"") | I18: =IF(AND(ISNUMBER(I17),ISNUMBER(H17)),IFERROR(I17/H17-1,""),"") | J18: =IF(AND(ISNUMBER(J17),ISNUMBER(I17)),IFERROR(J17/I17-1,""),"") | K18: =IF(AND(ISNUMBER(K17),ISNUMBER(J17)),IFERROR(K17/J17-1,""),"") | L18: =IF(AND(ISNUMBER(L17),ISNUMBER(K17)),IFERROR(L17/K17-1,""),"") | Q18: =IF(AND(ISNUMBER(Q17),ISNUMBER(L17)),IFERROR(Q17/L17-1,""),"") | R18: =IF(AND(ISNUMBER(R17),ISNUMBER(M17)),IFERROR(R17/M17-1,""),"") | S18: =IF(AND(ISNUMBER(S17),ISNUMBER(N17)),IFERROR(S17/N17-1,""),"") | T18: =IF(AND(ISNUMBER(T17),ISNUMBER(O17)),IFERROR(T17/O17-1,""),"") | U18: =IF(AND(ISNUMBER(U17),ISNUMBER(P17)),IFERROR(U17/P17-1,""),"") | V18: =IF(AND(ISNUMBER(V17),ISNUMBER(Q17)),IFERROR(V17/Q17-1,""),"") | W18: =IF(AND(ISNUMBER(W17),ISNUMBER(R17)),IFERROR(W17/R17-1,""),"") | X18: =IF(AND(ISNUMBER(X17),ISNUMBER(S17)),IFERROR(X17/S17-1,""),"") | ... AL18: =IF(AND(ISNUMBER(AL17),ISNUMBER(AG17)),IFERROR(AL17/AG17-1,""),"") | AM18: =AM19+$AM$127 | AN18: =AN19+$AM$127 | AO18: =AO19+$AM$127 | AP18: =IF(AND(ISNUMBER(AP17),ISNUMBER(AK17)),IFERROR(AP17/AK17-1,""),"") | AQ18: =CHOOSE(MATCH($AU$2,{"Bull","Base","Bear"},0),$BD$40,$BE$40,$BF$40) | AR18: =CHOOSE(MATCH($AU$2,{"Bull","Base","Bear"},0),$BD$41,$BE$41,$BF$41) | AS18: =CHOOSE(MATCH($AU$2,{"Bull","Base","Bear"},0),$BD$42,$BE$42,$BF$42) | AT18: =CHOOSE(MATCH($AU$2,{"Bull","Base","Bear"},0),$BD$43,$BE$43,$BF$43) | BC18: FY27 point estimates (all cases)
B19: Q2–Q4/27E growth before revenue calibration (Q1/27 y/y) | AM19: =IFERROR(AL17/AG17-1,0) | AN19: =IFERROR(AL17/AG17-1,0) | AO19: =IFERROR(AL17/AG17-1,0) | BC19: Interest expense ($m) | BE19: 63 | BG19: Not guided; FY26 $60.7m, Q1/27 $15.8m; Feb-2027 private-placement maturity refinanced on the revolver.
B20: Healthcare — revenue | C20: =IF(ISNUMBER(C11),C11+C14+C17,"") | D20: =IF(ISNUMBER(D11),D11+D14+D17,"") | E20: =IF(ISNUMBER(E11),E11+E14+E17,"") | F20: =IF(ISNUMBER(F11),F11+F14+F17,"") | G20: =IF(ISNUMBER(G11),G11+G14+G17,"") | H20: =IF(ISNUMBER(H11),H11+H14+H17,"") | I20: =IF(ISNUMBER(I11),I11+I14+I17,"") | J20: =IF(ISNUMBER(J11),J11+J14+J17,"") | ... AT20: =IF(ISNUMBER(AT11),AT11+AT14+AT17,"") | AW20: =IFERROR((AT20/AK20)^(1/5)-1,"n/m") | AX20: =IFERROR((AK20/L20)^(1/5)-1,"n/m") | AY20: =IFERROR((AK20/G20)^(1/10)-1,"n/m") | AZ20: =IFERROR((AK20/C20)^(1/14)-1,"n/m") | BC20: Other non-operating (income) expense, net ($m) | BE20: -10 | BG20: Interest & miscellaneous income (Q1/27 −$3.1m) net of other items.
B21: Revenue y/y % | D21: =IF(AND(ISNUMBER(D20),ISNUMBER(C20)),IFERROR(D20/C20-1,""),"") | E21: =IF(AND(ISNUMBER(E20),ISNUMBER(D20)),IFERROR(E20/D20-1,""),"") | F21: =IF(AND(ISNUMBER(F20),ISNUMBER(E20)),IFERROR(F20/E20-1,""),"") | G21: =IF(AND(ISNUMBER(G20),ISNUMBER(F20)),IFERROR(G20/F20-1,""),"") | H21: =IF(AND(ISNUMBER(H20),ISNUMBER(G20)),IFERROR(H20/G20-1,""),"") | I21: =IF(AND(ISNUMBER(I20),ISNUMBER(H20)),IFERROR(I20/H20-1,""),"") | J21: =IF(AND(ISNUMBER(J20),ISNUMBER(I20)),IFERROR(J20/I20-1,""),"") | K21: =IF(AND(ISNUMBER(K20),ISNUMBER(J20)),IFERROR(K20/J20-1,""),"") | L21: =IF(AND(ISNUMBER(L20),ISNUMBER(K20)),IFERROR(L20/K20-1,""),"") | Q21: =IF(AND(ISNUMBER(Q20),ISNUMBER(L20)),IFERROR(Q20/L20-1,""),"") | R21: =IF(AND(ISNUMBER(R20),ISNUMBER(M20)),IFERROR(R20/M20-1,""),"") | S21: =IF(AND(ISNUMBER(S20),ISNUMBER(N20)),IFERROR(S20/N20-1,""),"") | T21: =IF(AND(ISNUMBER(T20),ISNUMBER(O20)),IFERROR(T20/O20-1,""),"") | U21: =IF(AND(ISNUMBER(U20),ISNUMBER(P20)),IFERROR(U20/P20-1,""),"") | V21: =IF(AND(ISNUMBER(V20),ISNUMBER(Q20)),IFERROR(V20/Q20-1,""),"") | W21: =IF(AND(ISNUMBER(W20),ISNUMBER(R20)),IFERROR(W20/R20-1,""),"") | X21: =IF(AND(ISNUMBER(X20),ISNUMBER(S20)),IFERROR(X20/S20-1,""),"") | ... AP21: =IF(AND(ISNUMBER(AP20),ISNUMBER(AK20)),IFERROR(AP20/AK20-1,""),"") | AQ21: =IF(AND(ISNUMBER(AQ20),ISNUMBER(AP20)),IFERROR(AQ20/AP20-1,""),"") | AR21: =IF(AND(ISNUMBER(AR20),ISNUMBER(AQ20)),IFERROR(AR20/AQ20-1,""),"") | AS21: =IF(AND(ISNUMBER(AS20),ISNUMBER(AR20)),IFERROR(AS20/AR20-1,""),"") | AT21: =IF(AND(ISNUMBER(AT20),ISNUMBER(AS20)),IFERROR(AT20/AS20-1,""),"") | BC21: Amortization of acquired intangibles ($m) | BE21: 262 | BG21: Q1/27 $65.3m; 10-K schedule $253.1m + FY27 tuck-ins; FY27 outlook $2.08 per share after tax.
B22: % of total revenue | C22: =IF(AND(ISNUMBER(C20),ISNUMBER(C117)),IFERROR(C20/C117,""),"") | D22: =IF(AND(ISNUMBER(D20),ISNUMBER(D117)),IFERROR(D20/D117,""),"") | E22: =IF(AND(ISNUMBER(E20),ISNUMBER(E117)),IFERROR(E20/E117,""),"") | F22: =IF(AND(ISNUMBER(F20),ISNUMBER(F117)),IFERROR(F20/F117,""),"") | G22: =IF(AND(ISNUMBER(G20),ISNUMBER(G117)),IFERROR(G20/G117,""),"") | H22: =IF(AND(ISNUMBER(H20),ISNUMBER(H117)),IFERROR(H20/H117,""),"") | I22: =IF(AND(ISNUMBER(I20),ISNUMBER(I117)),IFERROR(I20/I117,""),"") | J22: =IF(AND(ISNUMBER(J20),ISNUMBER(J117)),IFERROR(J20/J117,""),"") | ... AT22: =IF(AND(ISNUMBER(AT20),ISNUMBER(AT117)),IFERROR(AT20/AT117,""),"") | BC22: Depreciation & other amortization ($m) | BE22: 238 | BG22: Q1/27 $58.5m (D&A $123.8m − amortization $65.3m); rising with capex.
B23: Recurring (consumables + service) % of segment revenue | C23: =IF(ISNUMBER(C14),IFERROR((C14+C17)/C20,""),"") | D23: =IF(ISNUMBER(D14),IFERROR((D14+D17)/D20,""),"") | E23: =IF(ISNUMBER(E14),IFERROR((E14+E17)/E20,""),"") | F23: =IF(ISNUMBER(F14),IFERROR((F14+F17)/F20,""),"") | G23: =IF(ISNUMBER(G14),IFERROR((G14+G17)/G20,""),"") | H23: =IF(ISNUMBER(H14),IFERROR((H14+H17)/H20,""),"") | I23: =IF(ISNUMBER(I14),IFERROR((I14+I17)/I20,""),"") | J23: =IF(ISNUMBER(J14),IFERROR((J14+J17)/J20,""),"") | ... AT23: =IF(ISNUMBER(AT14),IFERROR((AT14+AT17)/AT20,""),"") | BC23: Tax rate (GAAP & adjusted) | BE23: 0.25 | BG23: FY27 outlook ~25% (Q1/27 GAAP 26.5%, adjusted 25.9%).
B24: Memo: Healthcare revenue as published (segment data) | C24: 1013.102 | D24: 1074.79 | E24: 1180.051 | F24: 1391.874 | G24: 1630.018 | H24: 1821.053 | I24: 1745.119 | J24: 1848.485 | K24: 1986.809 | L24: 1954.055 | M24: 602.817 | N24: 744.134 | O24: 759.675 | P24: 738.841 | Q24: 2845.467 | R24: 698.526 | S24: 732.813 | T24: 769.144 | U24: 884.648 | V24: 3085.131 | W24: 818.874 | X24: 870.056 | Y24: 916.227 | Z24: 1007.862 | AA24: 3613.019 | AB24: 901.221 | AC24: 944.23 | AD24: 976.044 | AE24: 1057.176 | AF24: 3878.671 | AG24: 974.7 | AH24: 1033.8 | AI24: 1063.8 | AJ24: 1136.3 | AK24: 4208.6 | AL24: 1048.3 | BC24: Capital expenditures ($m) | BE24: 450 | BG24: FY27 outlook ~$450m (Q1/27 release), incl. the North Carolina chemistries and Mentor, OH plants.
B25: Check: revenue by type vs segment revenue (should be 0) | C25: =IF(AND(ISNUMBER(C20),ISNUMBER(C24)),IF(ABS(C20-C24)<=0.15,0,ROUND(C20-C24,1)),"") | D25: =IF(AND(ISNUMBER(D20),ISNUMBER(D24)),IF(ABS(D20-D24)<=0.15,0,ROUND(D20-D24,1)),"") | E25: =IF(AND(ISNUMBER(E20),ISNUMBER(E24)),IF(ABS(E20-E24)<=0.15,0,ROUND(E20-E24,1)),"") | F25: =IF(AND(ISNUMBER(F20),ISNUMBER(F24)),IF(ABS(F20-F24)<=0.15,0,ROUND(F20-F24,1)),"") | G25: =IF(AND(ISNUMBER(G20),ISNUMBER(G24)),IF(ABS(G20-G24)<=0.15,0,ROUND(G20-G24,1)),"") | H25: =IF(AND(ISNUMBER(H20),ISNUMBER(H24)),IF(ABS(H20-H24)<=0.15,0,ROUND(H20-H24,1)),"") | I25: =IF(AND(ISNUMBER(I20),ISNUMBER(I24)),IF(ABS(I20-I24)<=0.15,0,ROUND(I20-I24,1)),"") | J25: =IF(AND(ISNUMBER(J20),ISNUMBER(J24)),IF(ABS(J20-J24)<=0.15,0,ROUND(J20-J24,1)),"") | ... AL25: =IF(AND(ISNUMBER(AL20),ISNUMBER(AL24)),IF(ABS(AL20-AL24)<=0.15,0,ROUND(AL20-AL24,1)),"") | BC25: Free cash flow outlook ($m) — memo | BE25: 800 | BG25: FY27 outlook ~$800m (CFO ~$1,250m − capex ~$450m).
B26: Segment operating income (adjusted basis) | C26: 127.849 | D26: 128.767 | E26: 149.842 | F26: 185.108 | G26: 205.46 | H26: 237.972 | I26: 250.705 | J26: 387.906 | K26: 420.636 | L26: 427.089 | M26: 136.16 | N26: 160.39 | O26: 169.267 | P26: 160.281 | Q26: 626.098 | R26: 156.497 | S26: 165.337 | T26: 175.399 | U26: 208.787 | V26: 706.02 | W26: 198.182 | X26: 204.054 | Y26: 223.898 | Z26: 245.224 | AA26: 871.358 | AB26: 216.887 | AC26: 228.006 | AD26: 246.917 | AE26: 279.711 | AF26: 971.521 | AG26: 235.5 | AH26: 259.5 | AI26: 258.1 | AJ26: 283.2 | AK26: 1036.4 | AL26: 260.2 | AM26: =AM20*AM27 | AN26: =AN20*AN27 | AO26: =AO20*AO27 | AP26: =SUM(AL26,AM26,AN26,AO26) | AQ26: =AQ20*AQ27 | AR26: =AR20*AR27 | AS26: =AS20*AS27 | AT26: =AT20*AT27 | AU26: Segment income before adjustments (company measure; FY2012–15: adjusted segment operating income from the release reconciliations). Forecast = revenue × segment margin. | AW26: =IFERROR((AT26/AK26)^(1/5)-1,"n/m") | AX26: =IFERROR((AK26/L26)^(1/5)-1,"n/m") | AY26: =IFERROR((AK26/G26)^(1/10)-1,"n/m") | AZ26: =IFERROR((AK26/C26)^(1/14)-1,"n/m")
B27: Segment operating margin % | C27: =IF(AND(ISNUMBER(C26),ISNUMBER(C20)),IFERROR(C26/C20,""),"") | D27: =IF(AND(ISNUMBER(D26),ISNUMBER(D20)),IFERROR(D26/D20,""),"") | E27: =IF(AND(ISNUMBER(E26),ISNUMBER(E20)),IFERROR(E26/E20,""),"") | F27: =IF(AND(ISNUMBER(F26),ISNUMBER(F20)),IFERROR(F26/F20,""),"") | G27: =IF(AND(ISNUMBER(G26),ISNUMBER(G20)),IFERROR(G26/G20,""),"") | H27: =IF(AND(ISNUMBER(H26),ISNUMBER(H20)),IFERROR(H26/H20,""),"") | I27: =IF(AND(ISNUMBER(I26),ISNUMBER(I20)),IFERROR(I26/I20,""),"") | J27: =IF(AND(ISNUMBER(J26),ISNUMBER(J20)),IFERROR(J26/J20,""),"") | ... AL27: =IF(AND(ISNUMBER(AL26),ISNUMBER(AL20)),IFERROR(AL26/AL20,""),"") | AM27: =AM28+$AM$134 | AN27: =AN28+$AM$134 | AO27: =AO28+$AM$134 | AP27: =IF(AND(ISNUMBER(AP26),ISNUMBER(AP20)),IFERROR(AP26/AP20,""),"") | AQ27: =CHOOSE(MATCH($AU$2,{"Bull","Base","Bear"},0),$BD$70,$BE$70,$BF$70) | AR27: =CHOOSE(MATCH($AU$2,{"Bull","Base","Bear"},0),$BD$71,$BE$71,$BF$71) | AS27: =CHOOSE(MATCH($AU$2,{"Bull","Base","Bear"},0),$BD$72,$BE$72,$BF$72) | AT27: =CHOOSE(MATCH($AU$2,{"Bull","Base","Bear"},0),$BD$73,$BE$73,$BF$73) | AU27: Q2–Q4/27E: margin before calibration + adjusted-EPS-outlook calibration Δ (Group block). 2028E+: scenario lever. | AW27: =IFERROR(AVERAGE(AP27,AQ27,AR27,AS27,AT27),"n/m") | AX27: =IFERROR(AVERAGE(Q27,V27,AA27,AF27,AK27),"n/m") | AY27: =IFERROR(AVERAGE(H27,I27,J27,K27,L27,Q27,V27,AA27,AF27,AK27),"n/m") | AZ27: =IFERROR(AVERAGE(C27,D27,E27,F27,G27,H27,I27,J27,K27,L27,Q27,V27,AA27,AF27,AK27),"n/m") | BC27: Maximum net debt / adjusted EBITDA before buybacks (x) — buyback floor 2028E+ | BD27: 1 | BE27: 0.75 | BF27: 0.5 | BG27: Net debt $1.41bn at 30-Jun-26 ≈ 0.9x adjusted EBITDA (model definition). Target = leverage up to which surplus cash is returned via buybacks; below it free cash flow is held / repays the revolver. Bull = more buybacks (higher target).
B28: Q2–Q4/27E margin before EPS-outlook calibration (prior-year quarter + Q1/27 y/y drift) | AM28: =AH27+IFERROR(AL26/AL20-AG26/AG20,0) | AN28: =AI27+IFERROR(AL26/AL20-AG26/AG20,0) | AO28: =AJ27+IFERROR(AL26/AL20-AG26/AG20,0)
B29: Incremental segment margin (Δ operating income / Δ revenue) | D29: =IFERROR((D26-C26)/(D20-C20),"") | E29: =IFERROR((E26-D26)/(E20-D20),"") | F29: =IFERROR((F26-E26)/(F20-E20),"") | G29: =IFERROR((G26-F26)/(G20-F20),"") | H29: =IFERROR((H26-G26)/(H20-G20),"") | I29: =IFERROR((I26-H26)/(I20-H20),"") | J29: =IFERROR((J26-I26)/(J20-I20),"") | K29: =IFERROR((K26-J26)/(K20-J20),"") | L29: =IFERROR((L26-K26)/(L20-K20),"") | Q29: =IFERROR((Q26-L26)/(Q20-L20),"") | R29: =IFERROR((R26-M26)/(R20-M20),"") | S29: =IFERROR((S26-N26)/(S20-N20),"") | T29: =IFERROR((T26-O26)/(T20-O20),"") | U29: =IFERROR((U26-P26)/(U20-P20),"") | V29: =IFERROR((V26-Q26)/(V20-Q20),"") | W29: =IFERROR((W26-R26)/(W20-R20),"") | X29: =IFERROR((X26-S26)/(X20-S20),"") | ... AP29: =IFERROR((AP26-AK26)/(AP20-AK20),"") | AQ29: =IFERROR((AQ26-AP26)/(AQ20-AP20),"") | AR29: =IFERROR((AR26-AQ26)/(AR20-AQ20),"") | AS29: =IFERROR((AS26-AR26)/(AS20-AR20),"") | AT29: =IFERROR((AT26-AS26)/(AT20-AS20),"") | BC29: HC_CAP (Healthcare capital equipment y/y) | BD29: 0.02 | BE29: Δ → | BF29: -0.04 | BG29: Hospital capex cycle (sterilizers, washers, OR tables / lights, integration); backlog $444m at 30-Jun-26 (+10% y/y).
BC30: 2028E | BD30: =BE30+$BD$29 | BE30: 0.045 | BF30: =BE30+$BF$29
B31: Applied Sterilization Technologies (contract EO / gamma / E-beam / X-ray sterilization and lab testing; "Isomedix" to FY2015) | AU31: APPLIED STERILIZATION TECHNOLOGIES (AST) — modelling logic | BC31: 2029E | BD31: =BE31+$BD$29 | BE31: 0.04 | BF31: =BE31+$BF$29
B32: Service (contract sterilization & lab testing) revenue | C32: 164.257 | D32: 179.55 | E32: 194.183 | F32: 205.675 | G32: 310.12 | H32: 458.231 | I32: 513.287 | J32: 555.127 | K32: 627.147 | L32: 685.912 | M32: 208.902 | N32: 204.892 | O32: 216.298 | P32: 222.88 | Q32: 852.972 | R32: 220.911 | S32: 232.358 | T32: 222.014 | U32: 227.469 | V32: 887.971 | W32: 232.225 | X32: 233.299 | Y32: 229.69 | Z32: 244.247 | AA32: 939.461 | AB32: 248.715 | AC32: 247.932 | AD32: 253.14 | AE32: 257.84 | AF32: 1007.627 | AG32: 279.6 | AH32: 279.4 | AI32: 276.4 | AJ32: 283.1 | AK32: 1118.5 | AL32: 296.3 | AM32: =AH32*(1+AM33) | AN32: =AI32*(1+AN33) | AO32: =AJ32*(1+AO33) | AP32: =SUM(AL32,AM32,AN32,AO32) | AQ32: =AP32*(1+AQ33) | AR32: =AQ32*(1+AR33) | AS32: =AR32*(1+AS33) | AT32: =AS32*(1+AT33) | AU32: Revenue by type as published (release "Unaudited Supplemental Financial Data"). Q2–Q4/27E: prior-year quarter × (1 + growth). 2028E+: prior year × (1 + scenario lever). | AW32: =IFERROR((AT32/AK32)^(1/5)-1,"n/m") | AX32: =IFERROR((AK32/L32)^(1/5)-1,"n/m") | AY32: =IFERROR((AK32/G32)^(1/10)-1,"n/m") | AZ32: =IFERROR((AK32/C32)^(1/14)-1,"n/m") | BC32: 2030E | BD32: =BE32+$BD$29 | BE32: 0.04 | BF32: =BE32+$BF$29
B33: y/y % | D33: =IF(AND(ISNUMBER(D32),ISNUMBER(C32)),IFERROR(D32/C32-1,""),"") | E33: =IF(AND(ISNUMBER(E32),ISNUMBER(D32)),IFERROR(E32/D32-1,""),"") | F33: =IF(AND(ISNUMBER(F32),ISNUMBER(E32)),IFERROR(F32/E32-1,""),"") | G33: =IF(AND(ISNUMBER(G32),ISNUMBER(F32)),IFERROR(G32/F32-1,""),"") | H33: =IF(AND(ISNUMBER(H32),ISNUMBER(G32)),IFERROR(H32/G32-1,""),"") | I33: =IF(AND(ISNUMBER(I32),ISNUMBER(H32)),IFERROR(I32/H32-1,""),"") | J33: =IF(AND(ISNUMBER(J32),ISNUMBER(I32)),IFERROR(J32/I32-1,""),"") | K33: =IF(AND(ISNUMBER(K32),ISNUMBER(J32)),IFERROR(K32/J32-1,""),"") | L33: =IF(AND(ISNUMBER(L32),ISNUMBER(K32)),IFERROR(L32/K32-1,""),"") | Q33: =IF(AND(ISNUMBER(Q32),ISNUMBER(L32)),IFERROR(Q32/L32-1,""),"") | R33: =IF(AND(ISNUMBER(R32),ISNUMBER(M32)),IFERROR(R32/M32-1,""),"") | S33: =IF(AND(ISNUMBER(S32),ISNUMBER(N32)),IFERROR(S32/N32-1,""),"") | T33: =IF(AND(ISNUMBER(T32),ISNUMBER(O32)),IFERROR(T32/O32-1,""),"") | U33: =IF(AND(ISNUMBER(U32),ISNUMBER(P32)),IFERROR(U32/P32-1,""),"") | V33: =IF(AND(ISNUMBER(V32),ISNUMBER(Q32)),IFERROR(V32/Q32-1,""),"") | W33: =IF(AND(ISNUMBER(W32),ISNUMBER(R32)),IFERROR(W32/R32-1,""),"") | X33: =IF(AND(ISNUMBER(X32),ISNUMBER(S32)),IFERROR(X32/S32-1,""),"") | ... AL33: =IF(AND(ISNUMBER(AL32),ISNUMBER(AG32)),IFERROR(AL32/AG32-1,""),"") | AM33: =AM34+$AM$127 | AN33: =AN34+$AM$127 | AO33: =AO34+$AM$127 | AP33: =IF(AND(ISNUMBER(AP32),ISNUMBER(AK32)),IFERROR(AP32/AK32-1,""),"") | AQ33: =CHOOSE(MATCH($AU$2,{"Bull","Base","Bear"},0),$BD$45,$BE$45,$BF$45) | AR33: =CHOOSE(MATCH($AU$2,{"Bull","Base","Bear"},0),$BD$46,$BE$46,$BF$46) | AS33: =CHOOSE(MATCH($AU$2,{"Bull","Base","Bear"},0),$BD$47,$BE$47,$BF$47) | AT33: =CHOOSE(MATCH($AU$2,{"Bull","Base","Bear"},0),$BD$48,$BE$48,$BF$48) | AU33: Q2–Q4/27E: Q1/27 y/y growth of the line + revenue-outlook calibration Δ (Group block). 2028E–2031E: scenario lever (Bull/Base/Bear table →). | BC33: 2031E | BD33: =BE33+$BD$29 | BE33: 0.04 | BF33: =BE33+$BF$29
B34: Q2–Q4/27E growth before revenue calibration (Q1/27 y/y) | AM34: =IFERROR(AL32/AG32-1,0) | AN34: =IFERROR(AL32/AG32-1,0) | AO34: =IFERROR(AL32/AG32-1,0) | BC34: HC_CONS (Healthcare consumables y/y) | BD34: 0.015 | BE34: Δ → | BF34: -0.03 | BG34: Procedure volumes (US surgical procedures +MSD), endoscopy consumables (Cantel), share gains, price.
B35: Capital equipment revenue | C35: 0 | D35: 0 | E35: 0 | F35: 0 | G35: 0 | H35: 0 | I35: 0 | J35: 0 | K35: 0 | L35: 0 | M35: 0 | N35: 0 | O35: 0 | P35: 0 | Q35: 0 | R35: 0 | S35: 0 | T35: 0 | U35: 11.679 | V35: 26.46 | W35: 0.874 | X35: 1.754 | Y35: 5.241 | Z35: 6.65 | AA35: 14.519 | AB35: 1.088 | AC35: 8.805 | AD35: 5.004 | AE35: 16.049 | AF35: 30.946 | AG35: 1.6 | AH35: 2.1 | AI35: 10.2 | AJ35: 6.1 | AK35: 20 | AL35: 1.4 | AM35: =AH35*(1+AM36) | AN35: =AI35*(1+AN36) | AO35: =AJ35*(1+AO36) | AP35: =SUM(AL35,AM35,AN35,AO35) | AQ35: =AP35*(1+AQ36) | AR35: =AQ35*(1+AR36) | AS35: =AR35*(1+AS36) | AT35: =AS35*(1+AT36) | BC35: 2028E | BD35: =BE35+$BD$34 | BE35: 0.065 | BF35: =BE35+$BF$34
B36: y/y % | D36: =IF(AND(ISNUMBER(D35),ISNUMBER(C35)),IFERROR(D35/C35-1,""),"") | E36: =IF(AND(ISNUMBER(E35),ISNUMBER(D35)),IFERROR(E35/D35-1,""),"") | F36: =IF(AND(ISNUMBER(F35),ISNUMBER(E35)),IFERROR(F35/E35-1,""),"") | G36: =IF(AND(ISNUMBER(G35),ISNUMBER(F35)),IFERROR(G35/F35-1,""),"") | H36: =IF(AND(ISNUMBER(H35),ISNUMBER(G35)),IFERROR(H35/G35-1,""),"") | I36: =IF(AND(ISNUMBER(I35),ISNUMBER(H35)),IFERROR(I35/H35-1,""),"") | J36: =IF(AND(ISNUMBER(J35),ISNUMBER(I35)),IFERROR(J35/I35-1,""),"") | K36: =IF(AND(ISNUMBER(K35),ISNUMBER(J35)),IFERROR(K35/J35-1,""),"") | L36: =IF(AND(ISNUMBER(L35),ISNUMBER(K35)),IFERROR(L35/K35-1,""),"") | Q36: =IF(AND(ISNUMBER(Q35),ISNUMBER(L35)),IFERROR(Q35/L35-1,""),"") | R36: =IF(AND(ISNUMBER(R35),ISNUMBER(M35)),IFERROR(R35/M35-1,""),"") | S36: =IF(AND(ISNUMBER(S35),ISNUMBER(N35)),IFERROR(S35/N35-1,""),"") | T36: =IF(AND(ISNUMBER(T35),ISNUMBER(O35)),IFERROR(T35/O35-1,""),"") | U36: =IF(AND(ISNUMBER(U35),ISNUMBER(P35)),IFERROR(U35/P35-1,""),"") | V36: =IF(AND(ISNUMBER(V35),ISNUMBER(Q35)),IFERROR(V35/Q35-1,""),"") | W36: =IF(AND(ISNUMBER(W35),ISNUMBER(R35)),IFERROR(W35/R35-1,""),"") | X36: =IF(AND(ISNUMBER(X35),ISNUMBER(S35)),IFERROR(X35/S35-1,""),"") | ... AL36: =IF(AND(ISNUMBER(AL35),ISNUMBER(AG35)),IFERROR(AL35/AG35-1,""),"") | AM36: =AM37+$AM$127 | AN36: =AN37+$AM$127 | AO36: =AO37+$AM$127 | AP36: =IF(AND(ISNUMBER(AP35),ISNUMBER(AK35)),IFERROR(AP35/AK35-1,""),"") | AQ36: =CHOOSE(MATCH($AU$2,{"Bull","Base","Bear"},0),$BD$50,$BE$50,$BF$50) | AR36: =CHOOSE(MATCH($AU$2,{"Bull","Base","Bear"},0),$BD$51,$BE$51,$BF$51) | AS36: =CHOOSE(MATCH($AU$2,{"Bull","Base","Bear"},0),$BD$52,$BE$52,$BF$52) | AT36: =CHOOSE(MATCH($AU$2,{"Bull","Base","Bear"},0),$BD$53,$BE$53,$BF$53) | BC36: 2029E | BD36: =BE36+$BD$34 | BE36: 0.065 | BF36: =BE36+$BF$34
B37: Q2–Q4/27E growth before revenue calibration (Q1/27 y/y) | AM37: =IFERROR(AL35/AG35-1,0) | AN37: =IFERROR(AL35/AG35-1,0) | AO37: =IFERROR(AL35/AG35-1,0) | BC37: 2030E | BD37: =BE37+$BD$34 | BE37: 0.06 | BF37: =BE37+$BF$34
B38: Applied Sterilization Technologies (AST) — revenue | C38: =IF(ISNUMBER(C32),C32+C35,"") | D38: =IF(ISNUMBER(D32),D32+D35,"") | E38: =IF(ISNUMBER(E32),E32+E35,"") | F38: =IF(ISNUMBER(F32),F32+F35,"") | G38: =IF(ISNUMBER(G32),G32+G35,"") | H38: =IF(ISNUMBER(H32),H32+H35,"") | I38: =IF(ISNUMBER(I32),I32+I35,"") | J38: =IF(ISNUMBER(J32),J32+J35,"") | ... AT38: =IF(ISNUMBER(AT32),AT32+AT35,"") | AW38: =IFERROR((AT38/AK38)^(1/5)-1,"n/m") | AX38: =IFERROR((AK38/L38)^(1/5)-1,"n/m") | AY38: =IFERROR((AK38/G38)^(1/10)-1,"n/m") | AZ38: =IFERROR((AK38/C38)^(1/14)-1,"n/m") | BC38: 2031E | BD38: =BE38+$BD$34 | BE38: 0.06 | BF38: =BE38+$BF$34
B39: Revenue y/y % | D39: =IF(AND(ISNUMBER(D38),ISNUMBER(C38)),IFERROR(D38/C38-1,""),"") | E39: =IF(AND(ISNUMBER(E38),ISNUMBER(D38)),IFERROR(E38/D38-1,""),"") | F39: =IF(AND(ISNUMBER(F38),ISNUMBER(E38)),IFERROR(F38/E38-1,""),"") | G39: =IF(AND(ISNUMBER(G38),ISNUMBER(F38)),IFERROR(G38/F38-1,""),"") | H39: =IF(AND(ISNUMBER(H38),ISNUMBER(G38)),IFERROR(H38/G38-1,""),"") | I39: =IF(AND(ISNUMBER(I38),ISNUMBER(H38)),IFERROR(I38/H38-1,""),"") | J39: =IF(AND(ISNUMBER(J38),ISNUMBER(I38)),IFERROR(J38/I38-1,""),"") | K39: =IF(AND(ISNUMBER(K38),ISNUMBER(J38)),IFERROR(K38/J38-1,""),"") | L39: =IF(AND(ISNUMBER(L38),ISNUMBER(K38)),IFERROR(L38/K38-1,""),"") | Q39: =IF(AND(ISNUMBER(Q38),ISNUMBER(L38)),IFERROR(Q38/L38-1,""),"") | R39: =IF(AND(ISNUMBER(R38),ISNUMBER(M38)),IFERROR(R38/M38-1,""),"") | S39: =IF(AND(ISNUMBER(S38),ISNUMBER(N38)),IFERROR(S38/N38-1,""),"") | T39: =IF(AND(ISNUMBER(T38),ISNUMBER(O38)),IFERROR(T38/O38-1,""),"") | U39: =IF(AND(ISNUMBER(U38),ISNUMBER(P38)),IFERROR(U38/P38-1,""),"") | V39: =IF(AND(ISNUMBER(V38),ISNUMBER(Q38)),IFERROR(V38/Q38-1,""),"") | W39: =IF(AND(ISNUMBER(W38),ISNUMBER(R38)),IFERROR(W38/R38-1,""),"") | X39: =IF(AND(ISNUMBER(X38),ISNUMBER(S38)),IFERROR(X38/S38-1,""),"") | ... AP39: =IF(AND(ISNUMBER(AP38),ISNUMBER(AK38)),IFERROR(AP38/AK38-1,""),"") | AQ39: =IF(AND(ISNUMBER(AQ38),ISNUMBER(AP38)),IFERROR(AQ38/AP38-1,""),"") | AR39: =IF(AND(ISNUMBER(AR38),ISNUMBER(AQ38)),IFERROR(AR38/AQ38-1,""),"") | AS39: =IF(AND(ISNUMBER(AS38),ISNUMBER(AR38)),IFERROR(AS38/AR38-1,""),"") | AT39: =IF(AND(ISNUMBER(AT38),ISNUMBER(AS38)),IFERROR(AT38/AS38-1,""),"") | BC39: HC_SERV (Healthcare service y/y) | BD39: 0.015 | BE39: Δ → | BF39: -0.03 | BG39: Equipment service contracts, instrument repair (BD instruments, Aug-23), outsourced reprocessing; FY26 +12%.
B40: % of total revenue | C40: =IF(AND(ISNUMBER(C38),ISNUMBER(C117)),IFERROR(C38/C117,""),"") | D40: =IF(AND(ISNUMBER(D38),ISNUMBER(D117)),IFERROR(D38/D117,""),"") | E40: =IF(AND(ISNUMBER(E38),ISNUMBER(E117)),IFERROR(E38/E117,""),"") | F40: =IF(AND(ISNUMBER(F38),ISNUMBER(F117)),IFERROR(F38/F117,""),"") | G40: =IF(AND(ISNUMBER(G38),ISNUMBER(G117)),IFERROR(G38/G117,""),"") | H40: =IF(AND(ISNUMBER(H38),ISNUMBER(H117)),IFERROR(H38/H117,""),"") | I40: =IF(AND(ISNUMBER(I38),ISNUMBER(I117)),IFERROR(I38/I117,""),"") | J40: =IF(AND(ISNUMBER(J38),ISNUMBER(J117)),IFERROR(J38/J117,""),"") | ... AT40: =IF(AND(ISNUMBER(AT38),ISNUMBER(AT117)),IFERROR(AT38/AT117,""),"") | BC40: 2028E | BD40: =BE40+$BD$39 | BE40: 0.085 | BF40: =BE40+$BF$39
...

Sheet Bull-Base-Bear
B2: STERIS plc (STE) — Bull / Base / Bear Case P&L Summary | J2: Share price ($): | K2: =Model!$AP$446
B3: Adjusted figures (company definitions: adjusted income from operations, adjusted EPS from continuing operations; adjusted EBITDA = model definition) · USD millions · fiscal years ended 31 March · Live panel linked to Model — toggle scenario via Model!AU2. Bull and Bear panels are value snapshots generated from the Model with the switch set to each case. FY2027E calibrated to the FY27 outlook (revenue growth 7–8%, adjusted EPS $11.10–11.30). | J3: As of: | K3: =TODAY()
B5: Scenario: | C5: =Model!$AU$2 | N5: Scenario: | O5: Bull | P5: Snapshot (values) — Model run with switch = Bull | Z5: Scenario: | AA5: Bear | AB5: Snapshot (values) — Model run with switch = Bear
B7: (USDm, except EPS and shares) | C7: 2026A | D7: 2027E | E7: 2028E | F7: 2029E | G7: 2030E | H7: 2031E | I7: 26-'31 CAGR | J7: LT Hist Avg | K7: LT Hist Min | L7: LT Hist Max | N7: (USDm, except EPS and shares) | O7: 2026A | P7: 2027E | Q7: 2028E | R7: 2029E | S7: 2030E | T7: 2031E | U7: 26-'31 CAGR | V7: LT Hist Avg | W7: LT Hist Min | X7: LT Hist Max | Z7: (USDm, except EPS and shares) | AA7: 2026A | AB7: 2027E | AC7: 2028E | AD7: 2029E | AE7: 2030E | AF7: 2031E | AG7: 26-'31 CAGR | AH7: LT Hist Avg | AI7: LT Hist Min | AJ7: LT Hist Max
B9: Revenues | C9: =Model!AK159 | D9: =Model!AP159 | E9: =Model!AQ159 | F9: =Model!AR159 | G9: =Model!AS159 | H9: =Model!AT159 | I9: =IFERROR((H9/C9)^(1/5)-1,"n/m") | N9: Revenues | O9: 5935.9 | P9: 6410.672 | Q9: 6994.7344 | R9: 7652.2817 | S9: 8335.993 | T9: 9061.4375 | U9: 0.088283649 | Z9: Revenues | AA9: 5935.9 | AB9: 6351.313 | AC9: 6566.8389 | AD9: 6777.1349 | AE9: 6971.6932 | AF9: 7163.6121 | AG9: 0.038314926
B10: Revenues y/y % | D10: =IFERROR(D9/C9-1,"") | E10: =IFERROR(E9/D9-1,"") | F10: =IFERROR(F9/E9-1,"") | G10: =IFERROR(G9/F9-1,"") | H10: =IFERROR(H9/G9-1,"") | N10: Revenues y/y % | P10: 0.079983153 | Q10: 0.091107832 | R10: 0.094006043 | S10: 0.089347376 | T10: 0.087025557 | Z10: Revenues y/y % | AB10: 0.069983153 | AC10: 0.033934071 | AD10: 0.03202393 | AE10: 0.028708043 | AF10: 0.027528309
B11: Constant-currency organic growth % | C11: =Model!AK267 | D11: =Model!AP267 | E11: =Model!AQ267 | F11: =Model!AR267 | G11: =Model!AS267 | H11: =Model!AT267 | N11: Constant-currency organic growth % | O11: 0.073 | P11: 0.070480458 | Q11: 0.085258211 | R11: 0.077386398 | S11: 0.063350228 | T11: 0.052745373 | Z11: Constant-currency organic growth % | AA11: 0.073 | AB11: 0.060480627 | AC11: 0.033934071 | AD11: 0.03202393 | AE11: 0.028708043 | AF11: 0.027528309
B12: Adjusted EBITDA (model) | C12: =Model!AK233 | D12: =Model!AP233 | E12: =Model!AQ233 | F12: =Model!AR233 | G12: =Model!AS233 | H12: =Model!AT233 | I12: =IFERROR((H12/C12)^(1/5)-1,"n/m") | N12: Adjusted EBITDA (model) | O12: 1603.4 | P12: 1760.7702 | Q12: 1974.0376 | R12: 2185.1419 | S12: 2408.7475 | T12: 2641.276 | U12: 0.10497991 | Z12: Adjusted EBITDA (model) | AA12: 1603.4 | AB12: 1740.1169 | AC12: 1657.3536 | AD12: 1737.3821 | AE12: 1815.0427 | AF12: 1886.9437 | AG12: 0.033102497
B13: Adjusted EBITDA margin % | C13: =IFERROR(C12/C9,"") | D13: =IFERROR(D12/D9,"") | E13: =IFERROR(E12/E9,"") | F13: =IFERROR(F12/F9,"") | G13: =IFERROR(G12/G9,"") | H13: =IFERROR(H12/H9,"") | J13: =IFERROR(AVERAGE(Model!C234,Model!D234,Model!E234,Model!F234,Model!G234,Model!H234,Model!I234,Model!J234,Model!K234,Model!L234,Model!Q234,Model!V234,Model!AA234,Model!AF234,Model!AK234),"") | K13: =IFERROR(MIN(Model!C234,Model!D234,Model!E234,Model!F234,Model!G234,Model!H234,Model!I234,Model!J234,Model!K234,Model!L234,Model!Q234,Model!V234,Model!AA234,Model!AF234,Model!AK234),"") | L13: =IFERROR(MAX(Model!C234,Model!D234,Model!E234,Model!F234,Model!G234,Model!H234,Model!I234,Model!J234,Model!K234,Model!L234,Model!Q234,Model!V234,Model!AA234,Model!AF234,Model!AK234),"") | N13: Adjusted EBITDA margin % | O13: 0.27011911 | P13: 0.27466234 | Q13: 0.28221767 | R13: 0.2855543 | S13: 0.28895747 | T13: 0.29148532 | V13: 0.24082676 | W13: 0.1839674 | X13: 0.30351681 | Z13: Adjusted EBITDA margin % | AA13: 0.27011911 | AB13: 0.27397751 | AC13: 0.25238225 | AD13: 0.25635938 | AE13: 0.2603446 | AF13: 0.26340673 | AH13: 0.24082676 | AI13: 0.1839674 | AJ13: 0.30351681
B15: Income from Operations (GAAP) | C15: =Model!AK167 | D15: =Model!AP167 | E15: =Model!AQ167 | F15: =Model!AR167 | G15: =Model!AS167 | H15: =Model!AT167 | I15: =IFERROR((H15/C15)^(1/5)-1,"n/m") | N15: Income from Operations (GAAP) | O15: 1101.8 | P15: 1241.2702 | Q15: 1415.2877 | R15: 1579.153 | S15: 1764.2578 | T15: 1995.4685 | U15: 0.12612973 | Z15: Income from Operations (GAAP) | AA15: 1101.8 | AB15: 1220.6169 | AC15: 1129.1137 | AD15: 1196.2738 | AE15: 1272.3749 | AF15: 1380.7992 | AG15: 0.046177923
B16: Income from operations y/y % | D16: =IFERROR(D15/C15-1,"") | E16: =IFERROR(E15/D15-1,"") | F16: =IFERROR(F15/E15-1,"") | G16: =IFERROR(G15/F15-1,"") | H16: =IFERROR(H15/G15-1,"") | N16: Income from operations y/y % | P16: 0.12658391 | Q16: 0.14019315 | R16: 0.11578227 | S16: 0.11721778 | T16: 0.13105272 | Z16: Income from operations y/y % | AB16: 0.10783891 | AC16: -0.074964713 | AD16: 0.059480378 | AE16: 0.06361513 | AF16: 0.085214066
B17: Operating margin (GAAP) % | C17: =IFERROR(C15/C9,"") | D17: =IFERROR(D15/D9,"") | E17: =IFERROR(E15/E9,"") | F17: =IFERROR(F15/F9,"") | G17: =IFERROR(G15/G9,"") | H17: =IFERROR(H15/H9,"") | J17: =IFERROR(AVERAGE(Model!C280,Model!D280,Model!E280,Model!F280,Model!G280,Model!H280,Model!I280,Model!J280,Model!K280,Model!L280,Model!Q280,Model!V280,Model!AA280,Model!AF280,Model!AK280),"") | K17: =IFERROR(MIN(Model!C280,Model!D280,Model!E280,Model!F280,Model!G280,Model!H280,Model!I280,Model!J280,Model!K280,Model!L280,Model!Q280,Model!V280,Model!AA280,Model!AF280,Model!AK280),"") | L17: =IFERROR(MAX(Model!C280,Model!D280,Model!E280,Model!F280,Model!G280,Model!H280,Model!I280,Model!J280,Model!K280,Model!L280,Model!Q280,Model!V280,Model!AA280,Model!AF280,Model!AK280),"") | N17: Operating margin (GAAP) % | O17: 0.18561633 | P17: 0.19362559 | Q17: 0.20233616 | R17: 0.20636367 | S17: 0.21164338 | T17: 0.22021545 | V17: 0.14546743 | W17: 0.087109167 | X17: 0.18561633 | Z17: Operating margin (GAAP) % | AA17: 0.18561633 | AB17: 0.1921834 | AC17: 0.17194174 | AD17: 0.17651616 | AE17: 0.18250587 | AF17: 0.19275181 | AH17: 0.14546743 | AI17: 0.087109167 | AJ17: 0.18561633
B19: Adjusted Net Income (continuing operations) | C19: =Model!AK247 | D19: =Model!AP247 | E19: =Model!AQ247 | F19: =Model!AR247 | G19: =Model!AS247 | H19: =Model!AT247 | I19: =IFERROR((H19/C19)^(1/5)-1,"n/m") | N19: Adjusted Net Income (continuing operations) | O19: 1003.4 | P19: 1098.0276 | Q19: 1239.0793 | R19: 1347.2467 | S19: 1478.9598 | T19: 1621.8764 | U19: 0.10080079 | Z19: Adjusted Net Income (continuing operations) | AA19: 1003.4 | AB19: 1082.5377 | AC19: 1017.3202 | AD19: 1072.5505 | AE19: 1119.6926 | AF19: 1165.8014 | AG19: 0.030457533
B21: FDSO (m) | C21: =Model!AK186 | D21: =Model!AP186 | E21: =Model!AQ186 | F21: =Model!AR186 | G21: =Model!AS186 | H21: =Model!AT186 | I21: =IFERROR((H21/C21)^(1/5)-1,"n/m") | N21: FDSO (m) | O21: 98.7 | P21: 97.170585 | Q21: 93.664059 | R21: 89.662347 | S21: 86.378991 | T21: 82.823099 | U21: -0.034467571 | Z21: FDSO (m) | AA21: 98.7 | AB21: 97.525918 | AC21: 96.461294 | AD21: 94.503358 | AE21: 91.775088 | AF21: 89.099853 | AG21: -0.020257456
B23: Adjusted EPS — Diluted ($) | C23: =Model!AK251 | D23: =Model!AP251 | E23: =Model!AQ251 | F23: =Model!AR251 | G23: =Model!AS251 | H23: =Model!AT251 | I23: =IFERROR((H23/C23)^(1/5)-1,"n/m") | N23: Adjusted EPS — Diluted ($) | O23: 10.16616 | P23: 11.3 | Q23: 13.228972 | R23: 15.02578 | S23: 17.121754 | T23: 19.582417 | U23: 0.14009717 | Z23: Adjusted EPS — Diluted ($) | AA23: 10.16616 | AB23: 11.1 | AC23: 10.546409 | AD23: 11.349337 | AE23: 12.200398 | AF23: 13.084213 | AG23: 0.051763588
B24: EPS y/y % | D24: =IFERROR(D23/C23-1,"") | E24: =IFERROR(E23/D23-1,"") | F24: =IFERROR(F23/E23-1,"") | G24: =IFERROR(G23/F23-1,"") | H24: =IFERROR(H23/G23-1,"") | N24: EPS y/y % | P24: 0.1115308 | Q24: 0.17070553 | R24: 0.13582369 | S24: 0.13949185 | T24: 0.14371557 | Z24: EPS y/y % | AB24: 0.091857684 | AC24: -0.049873069 | AD24: 0.076132861 | AE24: 0.074987713 | AF24: 0.072441473
B26: P / E (x) — assumed (adjusted EPS) | G26: 22 | H26: 22 | N26: P / E (x) — assumed (adjusted EPS) | S26: 25 | T26: 25 | Z26: P / E (x) — assumed (adjusted EPS) | AD26: 17 | AE26: 17 | AF26: 17
B27: Price Target ($) | G27: =G26*G23 | H27: =H26*H23 | N27: Price Target ($) | S27: =S26*S23 | T27: =T26*T23 | Z27: Price Target ($) | AD27: =AD26*AD23 | AE27: =AE26*AE23 | AF27: =AF26*AF23
B28: Upside / (Downside) vs current | G28: =IFERROR(G27/$K$2-1,"") | H28: =IFERROR(H27/$K$2-1,"") | N28: Upside / (Downside) vs current | S28: =IFERROR(S27/$K$2-1,"") | T28: =IFERROR(T27/$K$2-1,"") | Z28: Upside / (Downside) vs current | AD28: =IFERROR(AD27/$K$2-1,"") | AE28: =IFERROR(AE27/$K$2-1,"") | AF28: =IFERROR(AF27/$K$2-1,"")
B29: IRR (to 31-Mar of Y-1) | G29: =IFERROR((G27/$K$2)^(1/((DATE(2030-1,3,31)-$K$3)/365.25))-1,"") | H29: =IFERROR((H27/$K$2)^(1/((DATE(2031-1,3,31)-$K$3)/365.25))-1,"") | N29: IRR (to 31-Mar of Y-1) | S29: =IFERROR((S27/$K$2)^(1/((DATE(2030-1,3,31)-$K$3)/365.25))-1,"") | T29: =IFERROR((T27/$K$2)^(1/((DATE(2031-1,3,31)-$K$3)/365.25))-1,"") | Z29: IRR (to 31-Mar of Y-1) | AD29: =IFERROR((AD27/$K$2)^(1/((DATE(2029-1,3,31)-$K$3)/365.25))-1,"") | AE29: =IFERROR((AE27/$K$2)^(1/((DATE(2030-1,3,31)-$K$3)/365.25))-1,"") | AF29: =IFERROR((AF27/$K$2)^(1/((DATE(2031-1,3,31)-$K$3)/365.25))-1,"")
B31: Free Cash Flow | C31: =Model!AK313 | D31: =Model!AP313 | E31: =Model!AQ313 | F31: =Model!AR313 | G31: =Model!AS313 | H31: =Model!AT313 | I31: =IFERROR((H31/C31)^(1/5)-1,"n/m") | N31: Free Cash Flow | O31: 982.9 | P31: 951.34806 | Q31: 1072.3173 | R31: 1187.3799 | S31: 1339.8636 | T31: 1484.994 | U31: 0.086033131 | Z31: Free Cash Flow | AA31: 982.9 | AB31: 942.05652 | AC31: 887.15355 | AD31: 976.55899 | AE31: 1048.6575 | AF31: 1102.8561 | AG31: 0.023297469
B32: FCF % | C32: =IFERROR(C31/C9,"") | D32: =IFERROR(D31/D9,"") | E32: =IFERROR(E31/E9,"") | F32: =IFERROR(F31/F9,"") | G32: =IFERROR(G31/G9,"") | H32: =IFERROR(H31/H9,"") | J32: =IFERROR(AVERAGE(Model!C317,Model!D317,Model!E317,Model!F317,Model!G317,Model!H317,Model!I317,Model!J317,Model!K317,Model!L317,Model!Q317,Model!V317,Model!AA317,Model!AF317,Model!AK317),"") | K32: =IFERROR(MIN(Model!C317,Model!D317,Model!E317,Model!F317,Model!G317,Model!H317,Model!I317,Model!J317,Model!K317,Model!L317,Model!Q317,Model!V317,Model!AA317,Model!AF317,Model!AK317),"") | L32: =IFERROR(MAX(Model!C317,Model!D317,Model!E317,Model!F317,Model!G317,Model!H317,Model!I317,Model!J317,Model!K317,Model!L317,Model!Q317,Model!V317,Model!AA317,Model!AF317,Model!AK317),"") | N32: FCF % | O32: 0.16558567 | P32: 0.14840068 | Q32: 0.1533035 | R32: 0.15516678 | S32: 0.16073233 | T32: 0.16388062 | V32: 0.10617638 | W32: 0.057671108 | X32: 0.16558567 | Z32: FCF % | AA32: 0.16558567 | AB32: 0.14832469 | AC32: 0.13509598 | AD32: 0.14409614 | AE32: 0.15041648 | AF32: 0.15395251 | AH32: 0.10617638 | AI32: 0.057671108 | AJ32: 0.16558567
B33: FCF / share ($) | C33: =IFERROR(C31/C21,"") | D33: =IFERROR(D31/D21,"") | E33: =IFERROR(E31/E21,"") | F33: =IFERROR(F31/F21,"") | G33: =IFERROR(G31/G21,"") | H33: =IFERROR(H31/H21,"") | N33: FCF / share ($) | O33: 9.95846 | P33: 9.7904943 | Q33: 11.448546 | R33: 13.242793 | S33: 15.511452 | T33: 17.929709 | Z33: FCF / share ($) | AA33: 9.95846 | AB33: 9.6595504 | AC33: 9.19699 | AD33: 10.33359 | AE33: 11.426385 | AF33: 12.377754
B34: FCF Yield (on PT) | F34: =IFERROR(F33/F$27,"") | G34: =IFERROR(G33/G$27,"") | H34: =IFERROR(H33/H$27,"") | N34: FCF Yield (on PT) | R34: =IFERROR(R33/R$27,"") | S34: =IFERROR(S33/S$27,"") | T34: =IFERROR(T33/T$27,"") | Z34: FCF Yield (on PT) | AD34: =IFERROR(AD33/AD$27,"") | AE34: =IFERROR(AE33/AE$27,"") | AF34: =IFERROR(AF33/AF$27,"")
B35: Adjusted EBITDA (leverage basis) | C35: =Model!AK233 | D35: =Model!AP233 | E35: =Model!AQ233 | F35: =Model!AR233 | G35: =Model!AS233 | H35: =Model!AT233 | I35: =IFERROR((H35/C35)^(1/5)-1,"n/m") | N35: Adjusted EBITDA (leverage basis) | O35: 1603.4 | P35: 1760.7702 | Q35: 1974.0376 | R35: 2185.1419 | S35: 2408.7475 | T35: 2641.276 | U35: 0.10497991 | Z35: Adjusted EBITDA (leverage basis) | AA35: 1603.4 | AB35: 1740.1169 | AC35: 1657.3536 | AD35: 1737.3821 | AE35: 1815.0427 | AF35: 1886.9437 | AG35: 0.033102497
B36: Adjusted EBITDA % of revenues | C36: =IFERROR(C35/C9,"") | D36: =IFERROR(D35/D9,"") | E36: =IFERROR(E35/E9,"") | F36: =IFERROR(F35/F9,"") | G36: =IFERROR(G35/G9,"") | H36: =IFERROR(H35/H9,"") | J36: =IFERROR(AVERAGE(Model!C279,Model!D279,Model!E279,Model!F279,Model!G279,Model!H279,Model!I279,Model!J279,Model!K279,Model!L279,Model!Q279,Model!V279,Model!AA279,Model!AF279,Model!AK279),"") | K36: =IFERROR(MIN(Model!C279,Model!D279,Model!E279,Model!F279,Model!G279,Model!H279,Model!I279,Model!J279,Model!K279,Model!L279,Model!Q279,Model!V279,Model!AA279,Model!AF279,Model!AK279),"") | L36: =IFERROR(MAX(Model!C279,Model!D279,Model!E279,Model!F279,Model!G279,Model!H279,Model!I279,Model!J279,Model!K279,Model!L279,Model!Q279,Model!V279,Model!AA279,Model!AF279,Model!AK279),"") | N36: Adjusted EBITDA % of revenues | O36: 0.27011911 | P36: 0.27466234 | Q36: 0.28221767 | R36: 0.2855543 | S36: 0.28895747 | T36: 0.29148532 | V36: 0.24082676 | W36: 0.1839674 | X36: 0.30351681 | Z36: Adjusted EBITDA % of revenues | AA36: 0.27011911 | AB36: 0.27397751 | AC36: 0.25238225 | AD36: 0.25635938 | AE36: 0.2603446 | AF36: 0.26340673 | AH36: 0.24082676 | AI36: 0.1839674 | AJ36: 0.30351681
B38: Net Debt | C38: =Model!AK441 | D38: =Model!AP441 | E38: =Model!AQ441 | F38: =Model!AR441 | G38: =Model!AS441 | H38: =Model!AT441 | N38: Net Debt | O38: 1492.1 | P38: 1315.7778 | Q38: 1974.0376 | R38: 2185.1419 | S38: 2408.7475 | T38: 2641.276 | Z38: Net Debt | AA38: 1492.1 | AB38: 1125.9648 | AC38: 828.6768 | AD38: 868.69105 | AE38: 907.52134 | AF38: 943.47184
B39: Net Debt / Adjusted EBITDA (x) | C39: =IFERROR(C38/C35,"") | D39: =IFERROR(D38/D35,"") | E39: =IFERROR(E38/E35,"") | F39: =IFERROR(F38/F35,"") | G39: =IFERROR(G38/G35,"") | H39: =IFERROR(H38/H35,"") | N39: Net Debt / Adjusted EBITDA (x) | O39: 0.93058501 | P39: 0.74727403 | Q39: 1 | R39: 1 | S39: 1 | T39: 1 | Z39: Net Debt / Adjusted EBITDA (x) | AA39: 0.93058501 | AB39: 0.64706273 | AC39: 0.5 | AD39: 0.5 | AE39: 0.5 | AF39: 0.5
B40: Share repurchases ($m; FY2027E = Q2–Q4) | D40: =Model!AP327 | E40: =Model!AQ327 | F40: =Model!AR327 | G40: =Model!AS327 | H40: =Model!AT327 | N40: Share repurchases ($m; FY2027E = Q2–Q4) | P40: 400 | Q40: 1181.1906 | R40: 842.40897 | S40: 995.73688 | T40: 1139.1076 | AB40: 200 | AC40: 337.90017 | AD40: 746.83922 | AE40: 803.77176 | AF40: 840.6538
B41: Implied avg buyback price ($) | D41: =Model!AP326 | E41: =Model!AQ326 | F41: =Model!AR326 | G41: =Model!AS326 | H41: =Model!AT326 | N41: Implied avg buyback price ($) | P41: 211.07 | Q41: 227.9556 | R41: 246.19205 | S41: 265.88741 | T41: 287.1584 | AB41: 211.07 | AC41: 227.9556 | AD41: 246.19205 | AE41: 265.88741 | AF41: 287.1584
B42: Shares repurchased (m) | D42: =Model!AP328 | E42: =Model!AQ328 | F42: =Model!AR328 | G42: =Model!AS328 | H42: =Model!AT328 | N42: Shares repurchased (m) | P42: 1.8951059 | Q42: 5.1816695 | R42: 3.4217554 | S42: 3.7449568 | T42: 3.9668266 | AB42: 0.94755294 | AC42: 1.482307 | AD42: 3.0335635 | AE42: 3.0229779 | AF42: 2.9274915
B44: ROIC | C44: =Model!AK424 | D44: =Model!AP424 | E44: =Model!AQ424 | F44: =Model!AR424 | G44: =Model!AS424 | H44: =Model!AT424 | J44: =IFERROR(AVERAGE(Model!C424,Model!D424,Model!E424,Model!F424,Model!G424,Model!H424,Model!I424,Model!J424,Model!K424,Model!L424,Model!Q424,Model!V424,Model!AA424,Model!AF424,Model!AK424),"") | K44: =IFERROR(MIN(Model!C424,Model!D424,Model!E424,Model!F424,Model!G424,Model!H424,Model!I424,Model!J424,Model!K424,Model!L424,Model!Q424,Model!V424,Model!AA424,Model!AF424,Model!AK424),"") | L44: =IFERROR(MAX(Model!C424,Model!D424,Model!E424,Model!F424,Model!G424,Model!H424,Model!I424,Model!J424,Model!K424,Model!L424,Model!Q424,Model!V424,Model!AA424,Model!AF424,Model!AK424),"") | N44: ROIC | O44: 0.097170795 | P44: 0.10837716 | Q44: 0.12001866 | R44: 0.12918558 | S44: 0.13902153 | T44: 0.1510531 | V44: 0.091989474 | W44: 0.054499159 | X44: 0.15241455 | Z44: ROIC | AA44: 0.097170795 | AB44: 0.10667352 | AC44: 0.099440824 | AD44: 0.10571324 | AE44: 0.11229345 | AF44: 0.1210534 | AH44: 0.091989474 | AI44: 0.054499159 | AJ44: 0.15241455
B45: RONTA | C45: =Model!AK435 | D45: =Model!AP435 | E45: =Model!AQ435 | F45: =Model!AR435 | G45: =Model!AS435 | H45: =Model!AT435 | J45: =IFERROR(AVERAGE(Model!C435,Model!D435,Model!E435,Model!F435,Model!G435,Model!H435,Model!I435,Model!J435,Model!K435,Model!L435,Model!Q435,Model!V435,Model!AA435,Model!AF435,Model!AK435),"") | K45: =IFERROR(MIN(Model!C435,Model!D435,Model!E435,Model!F435,Model!G435,Model!H435,Model!I435,Model!J435,Model!K435,Model!L435,Model!Q435,Model!V435,Model!AA435,Model!AF435,Model!AK435),"") | L45: =IFERROR(MAX(Model!C435,Model!D435,Model!E435,Model!F435,Model!G435,Model!H435,Model!I435,Model!J435,Model!K435,Model!L435,Model!Q435,Model!V435,Model!AA435,Model!AF435,Model!AK435),"") | N45: RONTA | O45: 0.21670461 | P45: 0.22597362 | Q45: 0.24609346 | R45: 0.25707133 | S45: 0.26900777 | T45: 0.28507103 | V45: 0.19710919 | W45: 0.14256772 | X45: 0.23560522 | Z45: RONTA | AA45: 0.21670461 | AB45: 0.21289481 | AC45: 0.18235993 | AD45: 0.19166323 | AE45: 0.19645644 | AF45: 0.20940405 | AH45: 0.19710919 | AI45: 0.14256772 | AJ45: 0.23560522
B47: Implied Market Cap (USDm) | F47: =F27*F21 | G47: =G27*G21 | H47: =H27*H21 | N47: Implied Market Cap (USDm) | R47: =R27*R21 | S47: =S27*S21 | T47: =T27*T21 | Z47: Implied Market Cap (USDm) | AD47: =AD27*AD21 | AE47: =AE27*AE21 | AF47: =AF27*AF21
B48: (+) Net Debt & NCI | F48: =F38+Model!AR357 | G48: =G38+Model!AS357 | H48: =H38+Model!AT357 | N48: (+) Net Debt & NCI | R48: =R38+Model!AR357 | S48: =S38+Model!AS357 | T48: =T38+Model!AT357 | Z48: (+) Net Debt & NCI | AD48: =AD38+Model!AR357 | AE48: =AE38+Model!AS357 | AF48: =AF38+Model!AT357
B49: Implied Enterprise Value (USDm) | F49: =F47+F48 | G49: =G47+G48 | H49: =H47+H48 | N49: Implied Enterprise Value (USDm) | R49: =R47+R48 | S49: =S47+S48 | T49: =T47+T48 | Z49: Implied Enterprise Value (USDm) | AD49: =AD47+AD48 | AE49: =AE47+AE48 | AF49: =AF47+AF48
B50: Implied EV / Adjusted EBITDA (x) | F50: =IFERROR(F49/F35,"") | G50: =IFERROR(G49/G35,"") | H50: =IFERROR(H49/H35,"") | N50: Implied EV / Adjusted EBITDA (x) | R50: =IFERROR(R49/R35,"") | S50: =IFERROR(S49/S35,"") | T50: =IFERROR(T49/T35,"") | Z50: Implied EV / Adjusted EBITDA (x) | AD50: =IFERROR(AD49/AD35,"") | AE50: =IFERROR(AE49/AE35,"") | AF50: =IFERROR(AF49/AF35,"")

Sheet DCF
B2: DCF VALUATION — STERIS PLC (STE)
B4: 1. WACC BUILD
B5: Risk-free rate (US 10Y govt) | C5: 0.045 | D5: Assumption (~US 10Y Treasury yield, Oct-2026); update to market
B6: Equity risk premium | C6: 0.05 | D6: US implied ERP ~4.5–5.5% (Damodaran)
B7: Levered beta | C7: 0.85 | D7: Medtech / infection-prevention peers (Ecolab, Getinge, Cantel pre-deal, Sotera Health) ~0.7–1.0; ~75% recurring consumables & service revenue dampens cyclicality
B8: Cost of equity | C8: =C5+C7*C6
B9: Pre-tax cost of debt | C9: 0.05 | D9: Investment grade (BBB+ / Baa1); 2.70% 2031 and 3.75% 2051 public notes; marginal cost ~5%
B10: Tax rate | C10: 0.25 | D10: Model FY2027E+ effective tax rate (FY27 outlook ~25%)
B11: After-tax cost of debt | C11: =C9*(1-C10)
B12: Target D/V | C12: 0.08 | D12: Net debt ~$1.4bn at 30-Jun-2026 vs ~$20.6bn market cap ($211.07 × ~98m diluted shares); ~0.9x adjusted EBITDA
B13: WACC | C13: =C8*(1-C12)+C11*C12
B15: Valuation date (live) | C15: =TODAY() | D15: Periods = (31-Mar of fiscal year − today) / 365.25; cash flows assumed at fiscal year-end (31 March)
B16: 2. UNLEVERED FREE CASH FLOW BUILD (USDm)
D17: 2027E | E17: 2028E | F17: 2029E | G17: 2030E | H17: 2031E | I17: 2032E | J17: 2033E | K17: 2034E | L17: 2035E | M17: 2036E | N17: Terminal | P17: CAGR 26–30E | Q17: CAGR 26–35E
B18: Adj. EBIT less acquisition, integration & restructuring costs | D18: =Model!AP238-Model!AP240 | E18: =Model!AQ238-Model!AQ240 | F18: =Model!AR238-Model!AR240 | G18: =Model!AS238-Model!AS240 | H18: =Model!AT238-Model!AT240 | I18: =H18*(1+I$26) | J18: =I18*(1+J$26) | K18: =J18*(1+K$26) | L18: =K18*(1+L$26) | M18: =L18*(1+M$26) | P18: =(H18/D18)^(1/(COLUMNS(D18:H18)-1))-1 | Q18: =(M18/D18)^(1/(COLUMNS(D18:M18)-1))-1
B19: × (1 − tax rate) | D19: =1-$C$10 | E19: =1-$C$10 | F19: =1-$C$10 | G19: =1-$C$10 | H19: =1-$C$10 | I19: =1-$C$10 | J19: =1-$C$10 | K19: =1-$C$10 | ... M19: =1-$C$10
B20: NOPAT | D20: =D18*D19 | E20: =E18*E19 | F20: =F18*F19 | G20: =G18*G19 | H20: =H18*H19 | I20: =I18*I19 | J20: =J18*J19 | K20: =K18*K19 | ... M20: =M18*M19
B21: plus DD&A (total, incl. acquired-intangible amortization) | D21: =Model!AP182 | E21: =Model!AQ182 | F21: =Model!AR182 | G21: =Model!AS182 | H21: =Model!AT182 | I21: =H21*(1+I$26) | J21: =I21*(1+J$26) | K21: =J21*(1+K$26) | L21: =K21*(1+L$26) | M21: =L21*(1+M$26)
B22: − Capex (PP&E & intangibles) and acquisitions (tuck-ins; M&A lever 2028E–31E) | D22: =Model!AP294+Model!AP296 | E22: =Model!AQ294+Model!AQ296 | F22: =Model!AR294+Model!AR296 | G22: =Model!AS294+Model!AS296 | H22: =Model!AT294+Model!AT296 | I22: =Model!AT294*(1+I$26) | J22: =I22*(1+J$26) | K22: =J22*(1+K$26) | L22: =K22*(1+L$26) | M22: =L22*(1+M$26)
B23: − Δ Working capital (CF statement) | D23: =Model!AP292 | E23: =Model!AQ292 | F23: =Model!AR292 | G23: =Model!AS292 | H23: =Model!AT292 | I23: =H23*(1+I$26) | J23: =I23*(1+J$26) | K23: =J23*(1+K$26) | L23: =K23*(1+L$26) | M23: =L23*(1+M$26)
B24: Unlevered FCF | D24: =D20+D21+D22+D23 | E24: =E20+E21+E22+E23 | F24: =F20+F21+F22+F23 | G24: =G20+G21+G22+G23 | H24: =H20+H21+H22+H23 | I24: =I20+I21+I22+I23 | J24: =J20+J21+J22+J23 | K24: =K20+K21+K22+K23 | ... M24: =M20+M21+M22+M23 | N24: =M24*(1+$C$27) | P24: =(H24/D24)^(1/(COLUMNS(D24:H24)-1))-1 | Q24: =(M24/D24)^(1/(COLUMNS(D24:M24)-1))-1
B25: Terminal Value (Gordon Growth) | N25: =N24/($C$13-$C$27)
B26: Fade-period growth (2032E–36E; 6.0% → 4.5% linear) | I26: 0.06 | J26: =I26+($M$26-$I$26)/4 | K26: =J26+($M$26-$I$26)/4 | L26: =K26+($M$26-$I$26)/4 | M26: 0.045
B27: Terminal growth rate | C27: 0.035
B29: Discount period (years) | D29: =(DATE(2027,3,31)-$C$15)/365.25 | E29: =(DATE(2028,3,31)-$C$15)/365.25 | F29: =(DATE(2029,3,31)-$C$15)/365.25 | G29: =(DATE(2030,3,31)-$C$15)/365.25 | H29: =(DATE(2031,3,31)-$C$15)/365.25 | I29: =(DATE(2032,3,31)-$C$15)/365.25 | J29: =(DATE(2033,3,31)-$C$15)/365.25 | K29: =(DATE(2034,3,31)-$C$15)/365.25 | L29: =(DATE(2035,3,31)-$C$15)/365.25 | M29: =(DATE(2036,3,31)-$C$15)/365.25 | N29: =M29
B30: Discount factor | D30: =1/(1+$C$13)^D29 | E30: =1/(1+$C$13)^E29 | F30: =1/(1+$C$13)^F29 | G30: =1/(1+$C$13)^G29 | H30: =1/(1+$C$13)^H29 | I30: =1/(1+$C$13)^I29 | J30: =1/(1+$C$13)^J29 | K30: =1/(1+$C$13)^K29 | ... N30: =1/(1+$C$13)^N29
B31: PV of UFCF | D31: =D24*D30 | E31: =E24*E30 | F31: =F24*F30 | G31: =G24*G30 | H31: =H24*H30 | I31: =I24*I30 | J31: =J24*J30 | K31: =K24*K30 | ... M31: =M24*M30 | N31: =N25*N30
D32: STERIS's adjusted operating income excludes acquired-intangible amortization (~$262m in FY27E) but expenses share-based compensation; Adjusted EBIT here deducts all D&A (non-cash, added back in row 21). Acquisition & integration and restructuring charges (cash; adjusted out by the company, incl. the FY27–30 North Carolina Center-of-Excellence plan) are deducted inside row 18. Row 22 includes tuck-in acquisitions in FY2027E–31E; the fade period and terminal value assume no new acquisitions. Dental (sold Sep-2024) is excluded throughout (continuing operations).
B33: IMPLIED ROIC — invested capital roll-forward (USDm)
B34: Opening invested capital | D34: =Model!AK421 | E34: =D38 | F34: =E38 | G34: =F38 | H34: =G38 | I34: =H38 | J34: =I38 | K34: =J38 | L34: =K38 | M34: =L38
B35: plus Capex and acquisitions | D35: =-D22 | E35: =-E22 | F35: =-F22 | G35: =-G22 | H35: =-H22 | I35: =-I22 | J35: =-J22 | K35: =-K22 | ... M35: =-M22
B36: less DD&A | D36: =-D21 | E36: =-E21 | F36: =-F21 | G36: =-G21 | H36: =-H21 | I36: =-I21 | J36: =-J21 | K36: =-K21 | ... M36: =-M21
B37: plus Δ Working capital investment | D37: =-D23 | E37: =-E23 | F37: =-F23 | G37: =-G23 | H37: =-H23 | I37: =-I23 | J37: =-J23 | K37: =-K23 | ... M37: =-M23
B38: Closing invested capital | D38: =SUM(D34:D37) | E38: =SUM(E34:E37) | F38: =SUM(F34:F37) | G38: =SUM(G34:G37) | H38: =SUM(H34:H37) | I38: =SUM(I34:I37) | J38: =SUM(J34:J37) | K38: =SUM(K34:K37) | ... M38: =SUM(M34:M37)
B39: NOPAT (row 20) | D39: =D20 | E39: =E20 | F39: =F20 | G39: =G20 | H39: =H20 | I39: =I20 | J39: =J20 | K39: =K20 | ... M39: =M20
B40: Implied ROIC (NOPAT / avg. invested capital) | D40: =IFERROR(D39/AVERAGE(D34,D38),"") | E40: =IFERROR(E39/AVERAGE(E34,E38),"") | F40: =IFERROR(F39/AVERAGE(F34,F38),"") | G40: =IFERROR(G39/AVERAGE(G34,G38),"") | H40: =IFERROR(H39/AVERAGE(H34,H38),"") | I40: =IFERROR(I39/AVERAGE(I34,I38),"") | J40: =IFERROR(J39/AVERAGE(J34,J38),"") | K40: =IFERROR(K39/AVERAGE(K34,K38),"") | ... M40: =IFERROR(M39/AVERAGE(M34,M38),"")
B41: Reinvestment rate (net investment / NOPAT) | D41: =IFERROR(SUM(D35:D37)/D39,"") | E41: =IFERROR(SUM(E35:E37)/E39,"") | F41: =IFERROR(SUM(F35:F37)/F39,"") | G41: =IFERROR(SUM(G35:G37)/G39,"") | H41: =IFERROR(SUM(H35:H37)/H39,"") | I41: =IFERROR(SUM(I35:I37)/I39,"") | J41: =IFERROR(SUM(J35:J37)/J39,"") | K41: =IFERROR(SUM(K35:K37)/K39,"") | ... M41: =IFERROR(SUM(M35:M37)/M39,"")
B42: Implied terminal RONIC (g / reinvestment rate) | N42: =IFERROR($C$27/M41,"")
D43: Opening IC = Model FY2026A book IC (total equity incl. NCI + net debt), rolled forward with capex + M&A − DD&A + ΔWC.
B44: 3. VALUATION SUMMARY
...

Sheet Charts
B2: STERIS plc — Operating Performance (FY2012–FY2026) and Model Forecast (FY2027E–FY2031E)
B3: USDm · fiscal years ended 31 March · Linked to Model. Bars = constant-currency organic growth vs acquisitions, divestitures & FX (published bridge from FY2017; earlier years: total growth shown as organic). Adjusted EBITDA = model definition (adjusted operating income + depreciation & other amortization). ROIC / RONTA on adjusted EBIT (full-cost).
C7: 2012 | D7: 2013 | E7: 2014 | F7: 2015 | G7: 2016 | H7: 2017 | I7: 2018 | J7: 2019 | K7: 2020 | L7: 2021 | M7: 2022 | N7: 2023 | O7: 2024 | P7: 2025 | Q7: 2026 | R7: 2027E | S7: 2028E | T7: 2029E | U7: 2030E | V7: 2031E
