Workbook

Sheet Model
CE1: SCENARIO SWITCH ▼ (Bull / Base / Bear) — drives all scenario-linked forecast drivers
B2: Visa Inc. (NYSE: V) — 3-Statement Financial Model | CE2: Base
B3: US GAAP as reported · USD millions (per-share data in USD; shares in millions, as-converted class A) · Fiscal years ended 30 September (2026 = Oct-2025 – Sep-2026) · Source: Visa Forms 10-K / 10-Q and Form 8-K earnings releases (Item 2.02, Ex. 99.1), SEC EDGAR (CIK 0001403161); XBRL company facts (cross-checks, dividends); releases on investor.visa.com are the same documents as filed on EDGAR · Q4 FY26 outlook: earnings call only (not on EDGAR) — UNVERIFIED
B4: Basis notes: as originally reported. IPO 19-Mar-2008 (reorganization Oct-2007; FY2008 first Visa Inc. 10-K year). 4-for-1 split Mar-2015 (per-share ÷4, shares ×4 before). One reportable segment; revenue by category; client incentives deducted from gross revenue. ASC 606 from FY2019; ASU 2016-18 restricted cash in the cash flow from FY2019. Visa Europe acquired 21-Jun-2016. Non-GAAP definitions per period (flag rows). Q4/26E calibrated to the Q4 FY26 call outlook (UNVERIFIED).
CG5: Forecast | CH5: Historical | CI5: Historical | CJ5: Historical
B6: (USDm) | C6: 2008 | D6: 2009 | E6: 2010 | F6: 2011 | G6: 2012 | H6: Q1/13 | I6: Q2/13 | J6: Q3/13 | K6: Q4/13 | L6: 2013 | M6: Q1/14 | N6: Q2/14 | O6: Q3/14 | P6: Q4/14 | Q6: 2014 | R6: Q1/15 | S6: Q2/15 | T6: Q3/15 | U6: Q4/15 | V6: 2015 | W6: Q1/16 | X6: Q2/16 | Y6: Q3/16 | Z6: Q4/16 | AA6: 2016 | AB6: Q1/17 | AC6: Q2/17 | AD6: Q3/17 | AE6: Q4/17 | AF6: 2017 | AG6: Q1/18 | AH6: Q2/18 | AI6: Q3/18 | AJ6: Q4/18 | AK6: 2018 | AL6: Q1/19 | AM6: Q2/19 | AN6: Q3/19 | AO6: Q4/19 | AP6: 2019 | AQ6: Q1/20 | AR6: Q2/20 | AS6: Q3/20 | AT6: Q4/20 | AU6: 2020 | AV6: Q1/21 | AW6: Q2/21 | AX6: Q3/21 | AY6: Q4/21 | AZ6: 2021 | BA6: Q1/22 | BB6: Q2/22 | BC6: Q3/22 | BD6: Q4/22 | BE6: 2022 | BF6: Q1/23 | BG6: Q2/23 | BH6: Q3/23 | BI6: Q4/23 | BJ6: 2023 | BK6: Q1/24 | BL6: Q2/24 | BM6: Q3/24 | BN6: Q4/24 | BO6: 2024 | BP6: Q1/25 | BQ6: Q2/25 | BR6: Q3/25 | BS6: Q4/25 | BT6: 2025 | BU6: Q1/26 | BV6: Q2/26 | BW6: Q3/26 | BX6: Q4/26E | BY6: 2026E | BZ6: 2027E | CA6: 2028E | CB6: 2029E | CC6: 2030E | CD6: 2031E | CE6: Modelling Notes | CG6: 5Y CAGR | CH6: 5Y CAGR | CI6: 10Y CAGR | CJ6: 17Y CAGR
CG7: 26-'31 | CH7: 20-'25 | CI7: 15-'25 | CJ7: 08-'25
B8: NET REVENUE BUILD — PAYMENTS VOLUME × YIELD · PROCESSED TRANSACTIONS × YIELD · CROSS-BORDER · CLIENT INCENTIVES | CE8: REVENUE BUILD — modelling logic (operating drivers → gross revenue by category → client incentives → net revenue; Visa reports one segment)
CM9: SCENARIO INPUT TABLE — driver assumptions per Bull / Base / Bear | CN9: Bull | CO9: Base | CP9: Bear | CQ9: Bull / Bear = Base + Δ (Δ inputs on each block header). Outlook block = high / mid / low end of the Q4 FY26 outlook (UNVERIFIED — call only).
B10: Operating drivers — Visa-branded payments volume and processed transactions (10-Q / 10-K MD&A) | CE10: KPIs — service revenue in a quarter is assessed on the PRIOR quarter's nominal payments volume; data processing revenue on processed transactions
B11: Nominal payments volume ($bn; the calendar quarter driving the period's service revenue) | D11: 2679 | E11: 3037 | F11: 3530 | G11: 3899 | H11: 1008 | I11: 1074 | J11: 1025 | K11: 1091 | L11: 4197 | M11: 1104 | N11: 1164 | O11: 1108 | P11: 1191 | Q11: 4567 | R11: 1217 | S11: 1245 | T11: 1168 | U11: 1254 | V11: 4884 | W11: 1265 | X11: 1305 | Y11: 1253 | Z11: 1828 | AA11: 5651 | AB11: 1858 | AC11: 1802 | AD11: 1734 | AE11: 1867 | AF11: 7265 | AG11: 1930 | AH11: 2033 | AI11: 1998 | AJ11: 2101 | AK11: 8063 | AL11: 2112 | AM11: 2197 | AN11: 2085 | AO11: 2228 | AP11: 8619 | AQ11: 2270 | AR11: 2361 | AS11: 2130 | AT11: 1955 | AU11: 8713 | AV11: 2349 | AW11: 2475 | AX11: 2423 | AY11: 2720 | AZ11: 9968 | BA11: 2784 | BB11: 2963 | BC11: 2775 | BD11: 2942 | BE11: 11464 | BF11: 2929 | BG11: 3018 | BH11: 2957 | BI11: 3166 | BJ11: 12074 | BK11: 3198 | BL11: 3280 | BM11: 3172 | BN11: 3328 | BO11: 12984 | BP11: 3410 | BQ11: 3524 | BR11: 3344 | BS11: 3617 | BT11: 13894 | BU11: 3732 | BV11: 3868 | BW11: 3728 | BX11: =BS11*(1+BX12) -> 4014.87 | BY11: =SUM(BU11:BX11) -> 15342.87 | BZ11: =BY11*(1+BZ12) -> 16647.014 | CA11: =BZ11*(1+CA12) -> 17978.775 | CB11: =CA11*(1+CB12) -> 19417.077 | CC11: =CB11*(1+CC12) -> 20873.358 | CD11: =CC11*(1+CD12) -> 22438.86 | CE11: 10-Q / 10-K "Total nominal payments volume" (three / twelve months ended one quarter before the fiscal period; Q4 = twelve months − nine months). Forecast = prior year × (1 + growth). | CG11: =IFERROR((CD11/BY11)^(1/5)-1,"n/m") -> 0.078993518 | CH11: =IFERROR((BT11/AU11)^(1/5)-1,"n/m") -> 0.097821966 | CI11: =IFERROR((BT11/V11)^(1/10)-1,"n/m") -> 0.11021007 | CJ11: =IFERROR((BT11/C11)^(1/17)-1,"n/m") -> n/m | CM11: Q4 FY26 outlook — Q3 FY26 earnings call (28-Jul-2026) — UNVERIFIED | CN11: High | CO11: Mid | CP11: Low | CQ11: UNVERIFIED (earnings call, not on EDGAR): Visa has given its outlook only on the call since FY2020 (the 8-K release has none); figures from secondary summaries found by web search. Q4 FY26: adjusted net revenue growth similar to Q3 (+14% nominal); non-GAAP EPS growth at the low end of mid-teens; adjusted opex growth low double digits; FY26 tax rate 18.0–18.25%, non-GAAP non-operating expense ~$165m.
B12: y/y % | D12: =IF(AND(ISNUMBER(D11),ISNUMBER(C11)),IFERROR(D11/C11-1,""),"") | E12: =IF(AND(ISNUMBER(E11),ISNUMBER(D11)),IFERROR(E11/D11-1,""),"") -> 0.13363195 | F12: =IF(AND(ISNUMBER(F11),ISNUMBER(E11)),IFERROR(F11/E11-1,""),"") -> 0.16233125 | G12: =IF(AND(ISNUMBER(G11),ISNUMBER(F11)),IFERROR(G11/F11-1,""),"") -> 0.10453258 | L12: =IF(AND(ISNUMBER(L11),ISNUMBER(G11)),IFERROR(L11/G11-1,""),"") -> 0.076429854 | M12: =IF(AND(ISNUMBER(M11),ISNUMBER(H11)),IFERROR(M11/H11-1,""),"") -> 0.095238095 | N12: =IF(AND(ISNUMBER(N11),ISNUMBER(I11)),IFERROR(N11/I11-1,""),"") -> 0.083798883 | O12: =IF(AND(ISNUMBER(O11),ISNUMBER(J11)),IFERROR(O11/J11-1,""),"") -> 0.08097561 | P12: =IF(AND(ISNUMBER(P11),ISNUMBER(K11)),IFERROR(P11/K11-1,""),"") -> 0.091659028 | Q12: =IF(AND(ISNUMBER(Q11),ISNUMBER(L11)),IFERROR(Q11/L11-1,""),"") -> 0.088158208 | R12: =IF(AND(ISNUMBER(R11),ISNUMBER(M11)),IFERROR(R11/M11-1,""),"") -> 0.10235507 | S12: =IF(AND(ISNUMBER(S11),ISNUMBER(N11)),IFERROR(S11/N11-1,""),"") -> 0.069587629 | ... BW12: =IF(AND(ISNUMBER(BW11),ISNUMBER(BR11)),IFERROR(BW11/BR11-1,""),"") -> 0.11483254 | BX12: =$CO$17 -> 0.11 | BY12: =IF(AND(ISNUMBER(BY11),ISNUMBER(BT11)),IFERROR(BY11/BT11-1,""),"") -> 0.10428026 | BZ12: =CHOOSE(MATCH($CE$2,{"Bull","Base","Bear"},0),$CN$29,$CO$29,$CP$29) -> 0.085 | CA12: =CHOOSE(MATCH($CE$2,{"Bull","Base","Bear"},0),$CN$30,$CO$30,$CP$30) -> 0.08 | CB12: =CHOOSE(MATCH($CE$2,{"Bull","Base","Bear"},0),$CN$31,$CO$31,$CP$31) -> 0.08 | CC12: =CHOOSE(MATCH($CE$2,{"Bull","Base","Bear"},0),$CN$32,$CO$32,$CP$32) -> 0.075 | CD12: =CHOOSE(MATCH($CE$2,{"Bull","Base","Bear"},0),$CN$33,$CO$33,$CP$33) -> 0.075 | CE12: Q4/26E: published — Q3 FY26 release: payments volume for the quarter ended 30-Jun-2026 +11% nominal (drives Q4 service revenue). 2027E+: scenario lever. | CM12: Q4/26E net revenue growth y/y (UNVERIFIED) | CN12: 0.14 | CO12: 0.13 | CP12: 0.12 | CQ12: Q4 FY26 adjusted net revenue growth 'similar to Q3' (Q3: +14% nominal, +13% constant dollar) - UNVERIFIED. Model end-points high / mid / low = 14% / 13% / 12% on Q4 FY25 net revenue $10,724m.
B13: of which U.S. ($bn) | D13: 1621 | E13: 1752 | F13: 1961 | G13: 2066 | H13: 521 | I13: 545 | J13: 530 | K13: 571 | L13: 2166 | M13: 575 | N13: 591 | O13: 575 | P13: 628 | Q13: 2369 | R13: 632 | S13: 651 | T13: 628 | U13: 683 | V13: 2594 | W13: 693 | X13: 714 | Y13: 695 | Z13: 749 | AA13: 2851 | AB13: 768 | AC13: 804 | AD13: 776 | AE13: 839 | AF13: 3187 | AG13: 836 | AH13: 881 | AI13: 854 | AJ13: 927 | AK13: 3499 | AL13: 945 | AM13: 979 | AN13: 930 | AO13: 1020 | AP13: 3875 | AQ13: 1023 | AR13: 1057 | AS13: 983 | AT13: 950 | AU13: 4009 | AV13: 1097 | AW13: 1140 | AX13: 1157 | AY13: 1332 | AZ13: 4725 | BA13: 1325 | BB13: 1394 | BC13: 1337 | BD13: 1489 | BE13: 5546 | BF13: 1480 | BG13: 1522 | BH13: 1470 | BI13: 1572 | BJ13: 6045 | BK13: 1569 | BL13: 1603 | BM13: 1561 | BN13: 1653 | BO13: 6387 | BP13: 1649 | BQ13: 1720 | BR13: 1654 | BS13: 1764 | BT13: 6788 | BU13: 1775 | BV13: 1835 | BW13: 1788 | CM13: Q4/26E non-GAAP EPS growth y/y (UNVERIFIED) | CN13: 0.15 | CO13: 0.14 | CP13: 0.13 | CQ13: Q4 FY26 non-GAAP EPS growth 'low end of mid-teens' - UNVERIFIED. End-points 15% / 14% / 13% on Q4 FY25 non-GAAP EPS $2.98.
B14: of which international ($bn) | D14: 1058 | E14: 1285 | F14: 1569 | G14: 1833 | H14: 487 | I14: 529 | J14: 495 | K14: 519 | L14: 2030 | M14: 529 | N14: 573 | O14: 533 | P14: 563 | Q14: 2198 | R14: 585 | S14: 594 | T14: 540 | U14: 571 | V14: 2290 | W14: 572 | X14: 591 | Y14: 558 | Z14: 1079 | AA14: 2800 | AB14: 1091 | AC14: 999 | AD14: 958 | AE14: 1028 | AF14: 4078 | AG14: 1094 | AH14: 1152 | AI14: 1143 | AJ14: 1172 | AK14: 4562 | AL14: 1167 | AM14: 1218 | AN14: 1155 | AO14: 1208 | AP14: 4744 | AQ14: 1247 | AR14: 1304 | AS14: 1147 | AT14: 1005 | AU14: 4704 | AV14: 1252 | AW14: 1335 | AX14: 1266 | AY14: 1388 | AZ14: 5243 | BA14: 1458 | BB14: 1568 | BC14: 1438 | BD14: 1453 | BE14: 5918 | BF14: 1449 | BG14: 1495 | BH14: 1487 | BI14: 1594 | BJ14: 6029 | BK14: 1629 | BL14: 1677 | BM14: 1611 | BN14: 1674 | BO14: 6597 | BP14: 1760 | BQ14: 1803 | BR14: 1690 | BS14: 1853 | BT14: 7106 | BU14: 1957 | BV14: 2033 | BW14: 1940 | CM14: Q4/26E share repurchases ($m) | CN14: 6000 | CO14: 5000 | CP14: 4000 | CQ14: Q3 FY26 $4.8bn (14.5m shares at $330.71); 9M FY26 $16.5bn; $28.4bn authorization remaining at 30-Jun-2026 (10-Q). Scenario input.
B15: International % of payments volume | C15: =IF(ISNUMBER(C14),IFERROR(C14/C11,""),"") | D15: =IF(ISNUMBER(D14),IFERROR(D14/D11,""),"") -> 0.39492348 | E15: =IF(ISNUMBER(E14),IFERROR(E14/E11,""),"") -> 0.42311492 | F15: =IF(ISNUMBER(F14),IFERROR(F14/F11,""),"") -> 0.44447592 | G15: =IF(ISNUMBER(G14),IFERROR(G14/G11,""),"") -> 0.47012054 | H15: =IF(ISNUMBER(H14),IFERROR(H14/H11,""),"") -> 0.48313492 | I15: =IF(ISNUMBER(I14),IFERROR(I14/I11,""),"") -> 0.49255121 | J15: =IF(ISNUMBER(J14),IFERROR(J14/J11,""),"") -> 0.48292683 | ... CD15: =IF(ISNUMBER(CD14),IFERROR(CD14/CD11,""),"") | CG15: =IFERROR(AVERAGE(BZ15,CA15,CB15,CC15,CD15),"n/m") -> n/m | CH15: =IFERROR(AVERAGE(AZ15,BE15,BJ15,BO15,BT15),"n/m") -> 0.51221519 | CI15: =IFERROR(AVERAGE(AA15,AF15,AK15,AP15,AU15,AZ15,BE15,BJ15,BO15,BT15),"n/m") -> 0.5273974 | CJ15: =IFERROR(AVERAGE(C15,D15,E15,F15,G15,L15,Q15,V15,AA15,AF15,AK15,AP15,AU15,AZ15,BE15,BJ15,BO15,BT15),"n/m") -> 0.49649673
B16: Processed transactions (millions) | E16: 45411 | G16: 53324 | H16: 14159 | I16: 13850 | J16: 14972 | K16: 15491 | L16: 58472 | M16: 15985 | N16: 15354 | O16: 16662 | P16: 16943 | Q16: 64944 | R16: 17599 | S16: 16980 | T16: 18024 | U16: 18364 | V16: 70968 | W16: 18986 | X16: 18475 | Y16: 19778 | Z16: 25921 | AA16: 83159 | AB16: 27329 | AC16: 26256 | AD16: 28450 | AE16: 29180 | AF16: 111215 | AG16: 30508 | AH16: 29321 | AI16: 31728 | AJ16: 32763 | AK16: 124320 | AL16: 33931 | AM16: 32544 | AN16: 35428 | AO16: 36425 | AP16: 138329 | AQ16: 37775 | AR16: 34941 | AS16: 30676 | AT16: 37448 | AU16: 140839 | AV16: 39213 | AW16: 37644 | AX16: 42561 | AY16: 45315 | AZ16: 164733 | BA16: 47558 | BB16: 44807 | BC16: 49279 | BD16: 50885 | BE16: 192530 | BF16: 52512 | BG16: 50069 | BH16: 54034 | BI16: 55964 | BJ16: 212579 | BK16: 57472 | BL16: 55456 | BM16: 59318 | BN16: 61511 | BO16: 233758 | BP16: 63797 | BQ16: 60651 | BR16: 65443 | BS16: 67654 | BT16: 257545 | BU16: 69400 | BV16: 66086 | BW16: 71662 | BX16: =BS16*(1+BX17) -> 73802.291 | BY16: =SUM(BU16:BX16) -> 280950.29 | BZ16: =BY16*(1+BZ17) -> 306235.82 | CA16: =BZ16*(1+CA17) -> 333797.04 | CB16: =CA16*(1+CB17) -> 362169.79 | CC16: =CB16*(1+CC17) -> 391143.37 | CD16: =CC16*(1+CD17) -> 422434.84 | CE16: 10-Q / 10-K "Visa processed transactions" (current period; Q4 = fiscal year − nine months). Forecast = prior year × (1 + growth). | CG16: =IFERROR((CD16/BY16)^(1/5)-1,"n/m") -> 0.084990783 | CH16: =IFERROR((BT16/AU16)^(1/5)-1,"n/m") -> 0.12830377 | CI16: =IFERROR((BT16/V16)^(1/10)-1,"n/m") -> 0.13757242 | CJ16: =IFERROR((BT16/C16)^(1/17)-1,"n/m") -> n/m | CM16: Q4/26E and FY26 point estimates (all cases)
B17: y/y % | D17: =IF(AND(ISNUMBER(D16),ISNUMBER(C16)),IFERROR(D16/C16-1,""),"") | E17: =IF(AND(ISNUMBER(E16),ISNUMBER(D16)),IFERROR(E16/D16-1,""),"") | F17: =IF(AND(ISNUMBER(F16),ISNUMBER(E16)),IFERROR(F16/E16-1,""),"") | G17: =IF(AND(ISNUMBER(G16),ISNUMBER(F16)),IFERROR(G16/F16-1,""),"") | L17: =IF(AND(ISNUMBER(L16),ISNUMBER(G16)),IFERROR(L16/G16-1,""),"") -> 0.096541895 | M17: =IF(AND(ISNUMBER(M16),ISNUMBER(H16)),IFERROR(M16/H16-1,""),"") -> 0.12896391 | N17: =IF(AND(ISNUMBER(N16),ISNUMBER(I16)),IFERROR(N16/I16-1,""),"") -> 0.10859206 | O17: =IF(AND(ISNUMBER(O16),ISNUMBER(J16)),IFERROR(O16/J16-1,""),"") -> 0.11287737 | P17: =IF(AND(ISNUMBER(P16),ISNUMBER(K16)),IFERROR(P16/K16-1,""),"") -> 0.093731844 | Q17: =IF(AND(ISNUMBER(Q16),ISNUMBER(L16)),IFERROR(Q16/L16-1,""),"") -> 0.11068546 | R17: =IF(AND(ISNUMBER(R16),ISNUMBER(M16)),IFERROR(R16/M16-1,""),"") -> 0.10096966 | S17: =IF(AND(ISNUMBER(S16),ISNUMBER(N16)),IFERROR(S16/N16-1,""),"") -> 0.10590074 | ... BW17: =IF(AND(ISNUMBER(BW16),ISNUMBER(BR16)),IFERROR(BW16/BR16-1,""),"") -> 0.095029262 | BX17: =IFERROR(SUM(BU16:BW16)/SUM(BP16:BR16)-1,0) -> 0.090878451 | BY17: =IF(AND(ISNUMBER(BY16),ISNUMBER(BT16)),IFERROR(BY16/BT16-1,""),"") -> 0.090878451 | BZ17: =CHOOSE(MATCH($CE$2,{"Bull","Base","Bear"},0),$CN$35,$CO$35,$CP$35) -> 0.09 | CA17: =CHOOSE(MATCH($CE$2,{"Bull","Base","Bear"},0),$CN$36,$CO$36,$CP$36) -> 0.09 | CB17: =CHOOSE(MATCH($CE$2,{"Bull","Base","Bear"},0),$CN$37,$CO$37,$CP$37) -> 0.085 | CC17: =CHOOSE(MATCH($CE$2,{"Bull","Base","Bear"},0),$CN$38,$CO$38,$CP$38) -> 0.08 | CD17: =CHOOSE(MATCH($CE$2,{"Bull","Base","Bear"},0),$CN$39,$CO$39,$CP$39) -> 0.08 | CE17: Q4/26E: 9M FY26 y/y (+9%). 2027E+: scenario lever. | CM17: Q4/26E nominal payments volume growth (quarter ended 30-Jun-2026; published) | CO17: 0.11 | CQ17: Q3 FY26 release (8-K 28-Jul-2026, Ex. 99.1) 'Key business drivers': payments volume growth for the quarter ended 30-Jun-2026 +11% nominal (+10% constant). Service revenue in Q4 FY26 is based on this quarter's volume (company: service revenue is assessed on prior-quarter payments volume).
CM18: Q4/26E interest expense ($m) | CO18: 195 | CQ18: Q3 FY26 $194m; $24.1bn debt incl. $1.5bn commercial paper; no notes mature in Q4.
B19: Gross revenue by category → client incentives → net revenue | CE19: REVENUE CATEGORIES — company presentation (service, data processing, international transaction, other; less client incentives) | CM19: Q4/26E investment income & other ($m) | CO19: 114 | CQ19: UNVERIFIED (earnings call, not on EDGAR): FY26 non-GAAP non-operating expense ~$165m; 9M $84m → Q4 −$81m = interest $195m − $114m investment income. Q3 FY26 non-GAAP $159m.
B20: Service revenue | C20: 3061 | D20: 3174 | E20: 3497 | F20: 4261 | G20: 4872 | H20: 1300 | I20: 1369 | J20: 1298 | K20: 1385 | L20: 5352 | M20: 1419 | N20: 1462 | O20: 1417 | P20: 1499 | Q20: 5797 | R20: 1538 | S20: 1577 | T20: 1550 | U20: 1637 | V20: 6302 | W20: 1645 | X20: 1699 | Y20: 1635 | Z20: 1768 | AA20: 6747 | AB20: 1918 | AC20: 1993 | AD20: 1948 | AE20: 2116 | AF20: 7975 | AG20: 2146 | AH20: 2253 | AI20: 2196 | AJ20: 2323 | AK20: 8918 | AL20: 2342 | AM20: 2417 | AN20: 2405 | AO20: 2536 | AP20: 9700 | AQ20: 2555 | AR20: 2623 | AS20: 2409 | AT20: 2217 | AU20: 9804 | AV20: 2677 | AW20: 2845 | AX20: 2828 | AY20: 3125 | AZ20: 11475 | BA20: 3193 | BB20: 3521 | BC20: 3189 | BD20: 3458 | BE20: 13361 | BF20: 3511 | BG20: 3771 | BH20: 3668 | BI20: 3876 | BJ20: 14826 | BK20: 3915 | BL20: 4033 | BM20: 3967 | BN20: 4199 | BO20: 16114 | BP20: 4208 | BQ20: 4399 | BR20: 4330 | BS20: 4602 | BT20: 17539 | BU20: 4760 | BV20: 4981 | BW20: 4922 | BX20: =BX11*1000*BX21 -> 5118.9905 | BY20: =SUM(BU20:BX20) -> 19781.99 | BZ20: =BZ11*1000*BZ21 -> 21678.094 | CA20: =CA11*1000*CA21 -> 23646.465 | CB20: =CB11*1000*CB21 -> 25665.873 | CC20: =CC11*1000*CC21 -> 27728.768 | CD20: =CD11*1000*CD21 -> 29957.468 | CE20: Forecast = nominal payments volume ($bn × 1,000) × service yield. | CG20: =IFERROR((CD20/BY20)^(1/5)-1,"n/m") -> 0.08654326 | CH20: =IFERROR((BT20/AU20)^(1/5)-1,"n/m") -> 0.12336349 | CI20: =IFERROR((BT20/V20)^(1/10)-1,"n/m") -> 0.10777776 | CJ20: =IFERROR((BT20/C20)^(1/17)-1,"n/m") -> 0.10814492 | CM20: Q4/26E non-GAAP tax rate | CO20: 0.19 | CQ20: UNVERIFIED (earnings call, not on EDGAR): FY26 18.0–18.25% with 9M FY26 non-GAAP 17.8% implies ~19% in Q4 (Q3 18.4%).
B21: Service yield (% of nominal payments volume) | C21: =IF(AND(ISNUMBER(C20),ISNUMBER(C11)),IFERROR(C20/(C11*1000),""),"") | D21: =IF(AND(ISNUMBER(D20),ISNUMBER(D11)),IFERROR(D20/(D11*1000),""),"") -> 0.0011847704 | E21: =IF(AND(ISNUMBER(E20),ISNUMBER(E11)),IFERROR(E20/(E11*1000),""),"") -> 0.0011514653 | F21: =IF(AND(ISNUMBER(F20),ISNUMBER(F11)),IFERROR(F20/(F11*1000),""),"") -> 0.0012070822 | G21: =IF(AND(ISNUMBER(G20),ISNUMBER(G11)),IFERROR(G20/(G11*1000),""),"") -> 0.0012495512 | H21: =IF(AND(ISNUMBER(H20),ISNUMBER(H11)),IFERROR(H20/(H11*1000),""),"") -> 0.0012896825 | I21: =IF(AND(ISNUMBER(I20),ISNUMBER(I11)),IFERROR(I20/(I11*1000),""),"") -> 0.0012746741 | J21: =IF(AND(ISNUMBER(J20),ISNUMBER(J11)),IFERROR(J20/(J11*1000),""),"") -> 0.0012663415 | ... BW21: =IF(AND(ISNUMBER(BW20),ISNUMBER(BW11)),IFERROR(BW20/(BW11*1000),""),"") -> 0.001320279 | BX21: =BS21*(1+BX22+$BX$50) -> 0.0012750078 | BY21: =IF(AND(ISNUMBER(BY20),ISNUMBER(BY11)),IFERROR(BY20/(BY11*1000),""),"") -> 0.0012893279 | BZ21: =BY21*(1+CHOOSE(MATCH($CE$2,{"Bull","Base","Bear"},0),$CN$41,$CO$41,$CP$41)) -> 0.0013022212 | CA21: =BZ21*(1+CHOOSE(MATCH($CE$2,{"Bull","Base","Bear"},0),$CN$42,$CO$42,$CP$42)) -> 0.0013152434 | CB21: =CA21*(1+CHOOSE(MATCH($CE$2,{"Bull","Base","Bear"},0),$CN$43,$CO$43,$CP$43)) -> 0.0013218196 | CC21: =CB21*(1+CHOOSE(MATCH($CE$2,{"Bull","Base","Bear"},0),$CN$44,$CO$44,$CP$44)) -> 0.0013284287 | CD21: =CC21*(1+CHOOSE(MATCH($CE$2,{"Bull","Base","Bear"},0),$CN$45,$CO$45,$CP$45)) -> 0.0013350709 | CE21: Q4/26E: prior-year quarter × (1 + 9M FY26 y/y yield change + revenue calibration Δ). 2027E+: prior year × (1 + scenario yield change: pricing, mix, card benefits). | CG21: =IFERROR(AVERAGE(BZ21,CA21,CB21,CC21,CD21),"n/m") -> 0.0013205568 | CH21: =IFERROR(AVERAGE(AZ21,BE21,BJ21,BO21,BT21),"n/m") -> 0.0012095991 | CI21: =IFERROR(AVERAGE(AA21,AF21,AK21,AP21,AU21,AZ21,BE21,BJ21,BO21,BT21),"n/m") -> 0.0011696348 | CJ21: =IFERROR(AVERAGE(C21,D21,E21,F21,G21,L21,Q21,V21,AA21,AF21,AK21,AP21,AU21,AZ21,BE21,BJ21,BO21,BT21),"n/m") -> 0.0011955337 | CM21: Q4/26E litigation provision ($m; adjusted out) | CO21: 0 | CQ21: Not forecast (assumption): covered-litigation provisions are funded through the escrow / class B conversion-rate mechanism.
B22: Q4/26E yield change before calibration (9M FY26 y/y) | BX22: =IFERROR((SUM(BU20:BW20)/SUM(BU11:BW11))/(SUM(BP20:BR20)/SUM(BP11:BR11))-1,0) -> 0.028358707 | CE22: Trend input: 9M FY26 service yield ÷ 9M FY25 service yield − 1 (formula on actuals). | CM22: Q4/26E amortization of acquired intangibles ($m; adjusted out) | CO22: 64 | CQ22: Q3 FY26 $64m (Featurespace, Pismo, Tink).
B23: Service revenue y/y % | D23: =IF(AND(ISNUMBER(D20),ISNUMBER(C20)),IFERROR(D20/C20-1,""),"") -> 0.036916041 | E23: =IF(AND(ISNUMBER(E20),ISNUMBER(D20)),IFERROR(E20/D20-1,""),"") -> 0.10176434 | F23: =IF(AND(ISNUMBER(F20),ISNUMBER(E20)),IFERROR(F20/E20-1,""),"") -> 0.21847298 | G23: =IF(AND(ISNUMBER(G20),ISNUMBER(F20)),IFERROR(G20/F20-1,""),"") -> 0.14339357 | L23: =IF(AND(ISNUMBER(L20),ISNUMBER(G20)),IFERROR(L20/G20-1,""),"") -> 0.098522167 | M23: =IF(AND(ISNUMBER(M20),ISNUMBER(H20)),IFERROR(M20/H20-1,""),"") -> 0.091538462 | N23: =IF(AND(ISNUMBER(N20),ISNUMBER(I20)),IFERROR(N20/I20-1,""),"") -> 0.067932798 | O23: =IF(AND(ISNUMBER(O20),ISNUMBER(J20)),IFERROR(O20/J20-1,""),"") -> 0.091679507 | P23: =IF(AND(ISNUMBER(P20),ISNUMBER(K20)),IFERROR(P20/K20-1,""),"") -> 0.082310469 | Q23: =IF(AND(ISNUMBER(Q20),ISNUMBER(L20)),IFERROR(Q20/L20-1,""),"") -> 0.083146487 | R23: =IF(AND(ISNUMBER(R20),ISNUMBER(M20)),IFERROR(R20/M20-1,""),"") -> 0.083861875 | S23: =IF(AND(ISNUMBER(S20),ISNUMBER(N20)),IFERROR(S20/N20-1,""),"") -> 0.078659371 | ... BY23: =IF(AND(ISNUMBER(BY20),ISNUMBER(BT20)),IFERROR(BY20/BT20-1,""),"") -> 0.12788588 | BZ23: =IF(AND(ISNUMBER(BZ20),ISNUMBER(BY20)),IFERROR(BZ20/BY20-1,""),"") -> 0.09585 | CA23: =IF(AND(ISNUMBER(CA20),ISNUMBER(BZ20)),IFERROR(CA20/BZ20-1,""),"") -> 0.0908 | CB23: =IF(AND(ISNUMBER(CB20),ISNUMBER(CA20)),IFERROR(CB20/CA20-1,""),"") -> 0.0854 | CC23: =IF(AND(ISNUMBER(CC20),ISNUMBER(CB20)),IFERROR(CC20/CB20-1,""),"") -> 0.080375 | CD23: =IF(AND(ISNUMBER(CD20),ISNUMBER(CC20)),IFERROR(CD20/CC20-1,""),"") -> 0.080375 | CM23: Q4/26E acquisition-related costs ($m; adjusted out) | CO23: 15 | CQ23: Q3 FY26 $14m.
B24: Data processing revenue | C24: 2073 | D24: 2430 | E24: 3125 | F24: 3478 | G24: 3975 | H24: 1115 | I24: 1150 | J24: 1191 | K24: 1186 | L24: 4642 | M24: 1264 | N24: 1234 | O24: 1321 | P24: 1348 | Q24: 5167 | R24: 1383 | S24: 1340 | T24: 1400 | U24: 1429 | V24: 5552 | W24: 1479 | X24: 1473 | Y24: 1541 | Z24: 1779 | AA24: 6272 | AB24: 1892 | AC24: 1843 | AD24: 1984 | AE24: 2067 | AF24: 7786 | AG24: 2147 | AH24: 2127 | AI24: 2359 | AJ24: 2394 | AK24: 9027 | AL24: 2470 | AM24: 2432 | AN24: 2662 | AO24: 2769 | AP24: 10333 | AQ24: 2864 | AR24: 2711 | AS24: 2525 | AT24: 2875 | AU24: 10975 | AV24: 3033 | AW24: 2996 | AX24: 3327 | AY24: 3436 | AZ24: 12792 | BA24: 3614 | BB24: 3480 | BC24: 3579 | BD24: 3765 | BE24: 14438 | BF24: 3827 | BG24: 3819 | BH24: 4105 | BI24: 4256 | BJ24: 16007 | BK24: 4356 | BL24: 4259 | BM24: 4489 | BN24: 4610 | BO24: 17714 | BP24: 4745 | BQ24: 4701 | BR24: 5153 | BS24: 5394 | BT24: 19993 | BU24: 5544 | BV24: 5543 | BW24: 6042 | BX24: =BX16*BX25 -> 6174.316 | BY24: =SUM(BU24:BX24) -> 23303.316 | BZ24: =BZ16*BZ25 -> 26035.63 | CA24: =CA16*CA25 -> 28946.413 | CB24: =CB16*CB25 -> 32034.996 | CC24: =CC16*CC25 -> 35116.762 | CD24: =CD16*CD25 -> 38494.995 | CE24: Forecast = processed transactions (m) × data processing revenue per transaction ($). | CG24: =IFERROR((CD24/BY24)^(1/5)-1,"n/m") -> 0.10559816 | CH24: =IFERROR((BT24/AU24)^(1/5)-1,"n/m") -> 0.12744324 | CI24: =IFERROR((BT24/V24)^(1/10)-1,"n/m") -> 0.13669212 | CJ24: =IFERROR((BT24/C24)^(1/17)-1,"n/m") -> 0.14261191 | CM24: FY26 purchases of property, equipment & technology ($m) | CO24: 1600 | CQ24: 9M FY26 $1,178m; FY25 $1,482m (3.7% of net revenue). Not guided (assumption).
B25: Data processing revenue per processed transaction ($) | C25: =IF(AND(ISNUMBER(C24),ISNUMBER(C16)),IFERROR(C24/C16,""),"") | D25: =IF(AND(ISNUMBER(D24),ISNUMBER(D16)),IFERROR(D24/D16,""),"") | E25: =IF(AND(ISNUMBER(E24),ISNUMBER(E16)),IFERROR(E24/E16,""),"") -> 0.068815926 | F25: =IF(AND(ISNUMBER(F24),ISNUMBER(F16)),IFERROR(F24/F16,""),"") | G25: =IF(AND(ISNUMBER(G24),ISNUMBER(G16)),IFERROR(G24/G16,""),"") -> 0.074544295 | H25: =IF(AND(ISNUMBER(H24),ISNUMBER(H16)),IFERROR(H24/H16,""),"") -> 0.078748499 | I25: =IF(AND(ISNUMBER(I24),ISNUMBER(I16)),IFERROR(I24/I16,""),"") -> 0.083032491 | J25: =IF(AND(ISNUMBER(J24),ISNUMBER(J16)),IFERROR(J24/J16,""),"") -> 0.079548491 | ... BW25: =IF(AND(ISNUMBER(BW24),ISNUMBER(BW16)),IFERROR(BW24/BW16,""),"") -> 0.084312467 | BX25: =BS25*(1+BX26+$BX$50) -> 0.083660222 | BY25: =IF(AND(ISNUMBER(BY24),ISNUMBER(BY16)),IFERROR(BY24/BY16,""),"") -> 0.082944623 | BZ25: =BY25*(1+CHOOSE(MATCH($CE$2,{"Bull","Base","Bear"},0),$CN$47,$CO$47,$CP$47)) -> 0.085018239 | CA25: =BZ25*(1+CHOOSE(MATCH($CE$2,{"Bull","Base","Bear"},0),$CN$48,$CO$48,$CP$48)) -> 0.086718604 | CB25: =CA25*(1+CHOOSE(MATCH($CE$2,{"Bull","Base","Bear"},0),$CN$49,$CO$49,$CP$49)) -> 0.088452976 | CC25: =CB25*(1+CHOOSE(MATCH($CE$2,{"Bull","Base","Bear"},0),$CN$50,$CO$50,$CP$50)) -> 0.08977977 | CD25: =CC25*(1+CHOOSE(MATCH($CE$2,{"Bull","Base","Bear"},0),$CN$51,$CO$51,$CP$51)) -> 0.091126467 | CE25: Q4/26E: prior-year quarter × (1 + 9M FY26 y/y change + calibration Δ). 2027E+: scenario (pricing, value-added services, cross-border mix).
B26: Q4/26E change before calibration (9M FY26 y/y) | BX26: =IFERROR((SUM(BU24:BW24)/SUM(BU16:BW16))/(SUM(BP24:BR24)/SUM(BP16:BR16))-1,0) -> 0.075554788 | CE26: Trend input: 9M FY26 ÷ 9M FY25 data processing revenue per transaction − 1 (formula on actuals). | CM26: Maximum net debt / adjusted EBITDA before buybacks (x) — buyback floor 2027E+ | CN26: 0.5 | CO26: 0.35 | CP26: 0.25 | CQ26: Net debt (debt − cash − investment securities) $9.9bn at 30-Jun-2026 ≈ 0.3x adjusted EBITDA (model definition). Visa returns most free cash flow via buybacks and dividends; target = leverage up to which surplus cash is returned (assumption; Visa states no leverage target). Bull = more buybacks.
B27: Data processing revenue y/y % | D27: =IF(AND(ISNUMBER(D24),ISNUMBER(C24)),IFERROR(D24/C24-1,""),"") -> 0.17221418 | E27: =IF(AND(ISNUMBER(E24),ISNUMBER(D24)),IFERROR(E24/D24-1,""),"") -> 0.28600823 | F27: =IF(AND(ISNUMBER(F24),ISNUMBER(E24)),IFERROR(F24/E24-1,""),"") -> 0.11296 | G27: =IF(AND(ISNUMBER(G24),ISNUMBER(F24)),IFERROR(G24/F24-1,""),"") -> 0.14289822 | L27: =IF(AND(ISNUMBER(L24),ISNUMBER(G24)),IFERROR(L24/G24-1,""),"") -> 0.16779874 | M27: =IF(AND(ISNUMBER(M24),ISNUMBER(H24)),IFERROR(M24/H24-1,""),"") -> 0.13363229 | N27: =IF(AND(ISNUMBER(N24),ISNUMBER(I24)),IFERROR(N24/I24-1,""),"") -> 0.073043478 | O27: =IF(AND(ISNUMBER(O24),ISNUMBER(J24)),IFERROR(O24/J24-1,""),"") -> 0.10915197 | P27: =IF(AND(ISNUMBER(P24),ISNUMBER(K24)),IFERROR(P24/K24-1,""),"") -> 0.13659359 | Q27: =IF(AND(ISNUMBER(Q24),ISNUMBER(L24)),IFERROR(Q24/L24-1,""),"") -> 0.1130978 | R27: =IF(AND(ISNUMBER(R24),ISNUMBER(M24)),IFERROR(R24/M24-1,""),"") -> 0.09414557 | S27: =IF(AND(ISNUMBER(S24),ISNUMBER(N24)),IFERROR(S24/N24-1,""),"") -> 0.085899514 | ... BY27: =IF(AND(ISNUMBER(BY24),ISNUMBER(BT24)),IFERROR(BY24/BT24-1,""),"") -> 0.16557375 | BZ27: =IF(AND(ISNUMBER(BZ24),ISNUMBER(BY24)),IFERROR(BZ24/BY24-1,""),"") -> 0.11725 | CA27: =IF(AND(ISNUMBER(CA24),ISNUMBER(BZ24)),IFERROR(CA24/BZ24-1,""),"") -> 0.1118 | CB27: =IF(AND(ISNUMBER(CB24),ISNUMBER(CA24)),IFERROR(CB24/CA24-1,""),"") -> 0.1067 | CC27: =IF(AND(ISNUMBER(CC24),ISNUMBER(CB24)),IFERROR(CC24/CB24-1,""),"") -> 0.0962 | CD27: =IF(AND(ISNUMBER(CD24),ISNUMBER(CC24)),IFERROR(CD24/CC24-1,""),"") -> 0.0962
B28: International transaction revenue | C28: 1721 | D28: 1916 | E28: 2290 | F28: 2674 | G28: 3025 | H28: 805 | I28: 831 | J28: 854 | K28: 899 | L28: 3389 | M28: 891 | N28: 871 | O28: 860 | P28: 938 | Q28: 3560 | R28: 970 | S28: 964 | T28: 1039 | U28: 1091 | V28: 4064 | W28: 1031 | X28: 1045 | Y28: 1084 | Z28: 1489 | AA28: 4649 | AB28: 1489 | AC28: 1469 | AD28: 1571 | AE28: 1792 | AF28: 6321 | AG28: 1666 | AH28: 1752 | AI28: 1830 | AJ28: 1963 | AK28: 7211 | AL28: 1851 | AM28: 1796 | AN28: 1977 | AO28: 2180 | AP28: 7804 | AQ28: 2018 | AR28: 1833 | AS28: 1102 | AT28: 1346 | AU28: 6299 | AV28: 1451 | AW28: 1488 | AX28: 1696 | AY28: 1895 | AZ28: 6530 | BA28: 2174 | BB28: 2208 | BC28: 2560 | BD28: 2873 | BE28: 9815 | BF28: 2797 | BG28: 2749 | BH28: 2920 | BI28: 3172 | BJ28: 11638 | BK28: 3019 | BL28: 2984 | BM28: 3194 | BN28: 3468 | BO28: 12665 | BP28: 3442 | BQ28: 3291 | BR28: 3633 | BS28: 3800 | BT28: 14166 | BU28: 3652 | BV28: 3631 | BW28: 3853 | BX28: =BS28*(1+BX29) -> 3982.518 | BY28: =SUM(BU28:BX28) -> 15118.518 | BZ28: =BY28*(1+BZ29) -> 16630.37 | CA28: =BZ28*(1+CA29) -> 18293.407 | CB28: =CA28*(1+CB29) -> 19939.813 | CC28: =CB28*(1+CC29) -> 21734.397 | CD28: =CC28*(1+CD29) -> 23473.148 | CE28: Driven by cross-border volume (excl. intra-Europe) and currency volatility. Q4/26E: prior-year quarter × (1 + 9M FY26 y/y + calibration Δ). 2027E+: scenario growth. | CG28: =IFERROR((CD28/BY28)^(1/5)-1,"n/m") -> 0.091974318 | CH28: =IFERROR((BT28/AU28)^(1/5)-1,"n/m") -> 0.17596698 | CI28: =IFERROR((BT28/V28)^(1/10)-1,"n/m") -> 0.13299855 | CJ28: =IFERROR((BT28/C28)^(1/17)-1,"n/m") -> 0.13201182 | CM28: PV (nominal payments volume y/y) | CN28: 0.02 | CO28: Δ → | CP28: -0.03 | CQ28: FY2023–25 +5–7.5% (FY2025 +7.0%); 9M FY26 +10.2% nominal (FX tailwind ~1pt). Consumer spending + cash digitisation; U.S. ~48% of volume.
B29: y/y % | D29: =IF(AND(ISNUMBER(D28),ISNUMBER(C28)),IFERROR(D28/C28-1,""),"") -> 0.11330622 | E29: =IF(AND(ISNUMBER(E28),ISNUMBER(D28)),IFERROR(E28/D28-1,""),"") -> 0.19519833 | F29: =IF(AND(ISNUMBER(F28),ISNUMBER(E28)),IFERROR(F28/E28-1,""),"") -> 0.16768559 | G29: =IF(AND(ISNUMBER(G28),ISNUMBER(F28)),IFERROR(G28/F28-1,""),"") -> 0.13126402 | L29: =IF(AND(ISNUMBER(L28),ISNUMBER(G28)),IFERROR(L28/G28-1,""),"") -> 0.12033058 | M29: =IF(AND(ISNUMBER(M28),ISNUMBER(H28)),IFERROR(M28/H28-1,""),"") -> 0.1068323 | N29: =IF(AND(ISNUMBER(N28),ISNUMBER(I28)),IFERROR(N28/I28-1,""),"") -> 0.048134777 | O29: =IF(AND(ISNUMBER(O28),ISNUMBER(J28)),IFERROR(O28/J28-1,""),"") -> 0.0070257611 | P29: =IF(AND(ISNUMBER(P28),ISNUMBER(K28)),IFERROR(P28/K28-1,""),"") -> 0.043381535 | Q29: =IF(AND(ISNUMBER(Q28),ISNUMBER(L28)),IFERROR(Q28/L28-1,""),"") -> 0.050457362 | R29: =IF(AND(ISNUMBER(R28),ISNUMBER(M28)),IFERROR(R28/M28-1,""),"") -> 0.088664422 | S29: =IF(AND(ISNUMBER(S28),ISNUMBER(N28)),IFERROR(S28/N28-1,""),"") -> 0.10677382 | ... BW29: =IF(AND(ISNUMBER(BW28),ISNUMBER(BR28)),IFERROR(BW28/BR28-1,""),"") -> 0.060556014 | BX29: =BX30+$BX$50 -> 0.048031055 | BY29: =IF(AND(ISNUMBER(BY28),ISNUMBER(BT28)),IFERROR(BY28/BT28-1,""),"") -> 0.06723973 | BZ29: =CHOOSE(MATCH($CE$2,{"Bull","Base","Bear"},0),$CN$53,$CO$53,$CP$53) -> 0.1 | CA29: =CHOOSE(MATCH($CE$2,{"Bull","Base","Bear"},0),$CN$54,$CO$54,$CP$54) -> 0.1 | CB29: =CHOOSE(MATCH($CE$2,{"Bull","Base","Bear"},0),$CN$55,$CO$55,$CP$55) -> 0.09 | CC29: =CHOOSE(MATCH($CE$2,{"Bull","Base","Bear"},0),$CN$56,$CO$56,$CP$56) -> 0.09 | CD29: =CHOOSE(MATCH($CE$2,{"Bull","Base","Bear"},0),$CN$57,$CO$57,$CP$57) -> 0.08 | CM29: 2027E | CN29: =CO29+$CN$28 -> 0.105 | CO29: 0.085 | CP29: =CO29+$CP$28 -> 0.055
B30: Q4/26E growth before calibration (9M FY26 y/y) | BX30: =IFERROR(SUM(BU28:BW28)/SUM(BP28:BR28)-1,0) -> 0.074281304 | CE30: Trend input: 9M FY26 ÷ 9M FY25 international transaction revenue − 1. | CM30: 2028E | CN30: =CO30+$CN$28 -> 0.1 | CO30: 0.08 | CP30: =CO30+$CP$28 -> 0.05
B31: Other revenue (value-added services, licensing, marketing services) | C31: 569 | D31: 625 | E31: 713 | F31: 655 | G31: 704 | H31: 179 | I31: 175 | J31: 179 | K31: 183 | L31: 716 | M31: 180 | N31: 183 | O31: 195 | P31: 212 | Q31: 770 | R31: 204 | S31: 204 | T31: 199 | U31: 216 | V31: 823 | W31: 198 | X31: 198 | Y31: 209 | Z31: 218 | AA31: 823 | AB31: 203 | AC31: 203 | AD31: 209 | AE31: 226 | AF31: 841 | AG31: 229 | AH31: 230 | AI31: 229 | AJ31: 256 | AK31: 944 | AL31: 299 | AM31: 327 | AN31: 342 | AO31: 345 | AP31: 1313 | AQ31: 365 | AR31: 392 | AS31: 314 | AT31: 361 | AU31: 1432 | AV31: 384 | AW31: 392 | AX31: 409 | AY31: 490 | AZ31: 1675 | BA31: 449 | BB31: 474 | BC31: 517 | BD31: 551 | BE31: 1991 | BF31: 587 | BG31: 551 | BH31: 597 | BI31: 744 | BJ31: 2479 | BK31: 692 | BL31: 756 | BM31: 780 | BN31: 969 | BO31: 3197 | BP31: 912 | BQ31: 937 | BR31: 1028 | BS31: 1176 | BT31: 4053 | BU31: 1214 | BV31: 1320 | BW31: 1496 | BX31: =BS31*(1+BX32) -> 1616.429 | BY31: =SUM(BU31:BX31) -> 5646.429 | BZ31: =BY31*(1+BZ32) -> 6888.6434 | CA31: =BZ31*(1+CA32) -> 8128.5992 | CB31: =CA31*(1+CB32) -> 9429.175 | CC31: =CB31*(1+CC32) -> 10749.26 | CD31: =CC31*(1+CD32) -> 12146.663 | CE31: Value-added services, consulting, marketing services, licensing. Q4/26E: prior-year quarter × (1 + 9M FY26 y/y + calibration Δ). 2027E+: scenario growth. | CG31: =IFERROR((CD31/BY31)^(1/5)-1,"n/m") -> 0.16556534 | CH31: =IFERROR((BT31/AU31)^(1/5)-1,"n/m") -> 0.23130805 | CI31: =IFERROR((BT31/V31)^(1/10)-1,"n/m") -> 0.17283705 | CJ31: =IFERROR((BT31/C31)^(1/17)-1,"n/m") -> 0.12242344 | CM31: 2029E | CN31: =CO31+$CN$28 -> 0.1 | CO31: 0.08 | CP31: =CO31+$CP$28 -> 0.05
B32: y/y % | D32: =IF(AND(ISNUMBER(D31),ISNUMBER(C31)),IFERROR(D31/C31-1,""),"") -> 0.098418278 | E32: =IF(AND(ISNUMBER(E31),ISNUMBER(D31)),IFERROR(E31/D31-1,""),"") -> 0.1408 | F32: =IF(AND(ISNUMBER(F31),ISNUMBER(E31)),IFERROR(F31/E31-1,""),"") -> -0.081346424 | G32: =IF(AND(ISNUMBER(G31),ISNUMBER(F31)),IFERROR(G31/F31-1,""),"") -> 0.07480916 | L32: =IF(AND(ISNUMBER(L31),ISNUMBER(G31)),IFERROR(L31/G31-1,""),"") -> 0.017045455 | M32: =IF(AND(ISNUMBER(M31),ISNUMBER(H31)),IFERROR(M31/H31-1,""),"") -> 0.0055865922 | N32: =IF(AND(ISNUMBER(N31),ISNUMBER(I31)),IFERROR(N31/I31-1,""),"") -> 0.045714286 | O32: =IF(AND(ISNUMBER(O31),ISNUMBER(J31)),IFERROR(O31/J31-1,""),"") -> 0.089385475 | P32: =IF(AND(ISNUMBER(P31),ISNUMBER(K31)),IFERROR(P31/K31-1,""),"") -> 0.15846995 | Q32: =IF(AND(ISNUMBER(Q31),ISNUMBER(L31)),IFERROR(Q31/L31-1,""),"") -> 0.075418994 | R32: =IF(AND(ISNUMBER(R31),ISNUMBER(M31)),IFERROR(R31/M31-1,""),"") -> 0.13333333 | S32: =IF(AND(ISNUMBER(S31),ISNUMBER(N31)),IFERROR(S31/N31-1,""),"") -> 0.1147541 | ... BW32: =IF(AND(ISNUMBER(BW31),ISNUMBER(BR31)),IFERROR(BW31/BR31-1,""),"") -> 0.45525292 | BX32: =BX33+$BX$50 -> 0.37451444 | BY32: =IF(AND(ISNUMBER(BY31),ISNUMBER(BT31)),IFERROR(BY31/BT31-1,""),"") -> 0.39314803 | BZ32: =CHOOSE(MATCH($CE$2,{"Bull","Base","Bear"},0),$CN$59,$CO$59,$CP$59) -> 0.22 | CA32: =CHOOSE(MATCH($CE$2,{"Bull","Base","Bear"},0),$CN$60,$CO$60,$CP$60) -> 0.18 | CB32: =CHOOSE(MATCH($CE$2,{"Bull","Base","Bear"},0),$CN$61,$CO$61,$CP$61) -> 0.16 | CC32: =CHOOSE(MATCH($CE$2,{"Bull","Base","Bear"},0),$CN$62,$CO$62,$CP$62) -> 0.14 | CD32: =CHOOSE(MATCH($CE$2,{"Bull","Base","Bear"},0),$CN$63,$CO$63,$CP$63) -> 0.13 | CM32: 2030E | CN32: =CO32+$CN$28 -> 0.095 | CO32: 0.075 | CP32: =CO32+$CP$28 -> 0.045
B33: Q4/26E growth before calibration (9M FY26 y/y) | BX33: =IFERROR(SUM(BU31:BW31)/SUM(BP31:BR31)-1,0) -> 0.40076469 | CE33: Trend input: 9M FY26 ÷ 9M FY25 other revenue − 1. | CM33: 2031E | CN33: =CO33+$CN$28 -> 0.095 | CO33: 0.075 | CP33: =CO33+$CP$28 -> 0.045
B34: Gross revenue | C34: =IF(ISNUMBER(C20),C20+C24+C28+C31,"") -> 7424 | D34: =IF(ISNUMBER(D20),D20+D24+D28+D31,"") -> 8145 | E34: =IF(ISNUMBER(E20),E20+E24+E28+E31,"") -> 9625 | F34: =IF(ISNUMBER(F20),F20+F24+F28+F31,"") -> 11068 | G34: =IF(ISNUMBER(G20),G20+G24+G28+G31,"") -> 12576 | H34: =IF(ISNUMBER(H20),H20+H24+H28+H31,"") -> 3399 | I34: =IF(ISNUMBER(I20),I20+I24+I28+I31,"") -> 3525 | J34: =IF(ISNUMBER(J20),J20+J24+J28+J31,"") -> 3522 | ... CD34: =IF(ISNUMBER(CD20),CD20+CD24+CD28+CD31,"") -> 104072.27 | CG34: =IFERROR((CD34/BY34)^(1/5)-1,"n/m") -> 0.10264188 | CH34: =IFERROR((BT34/AU34)^(1/5)-1,"n/m") -> 0.14353928 | CI34: =IFERROR((BT34/V34)^(1/10)-1,"n/m") -> 0.12783905 | CJ34: =IFERROR((BT34/C34)^(1/17)-1,"n/m") -> 0.12591796 | CM34: PTX (processed transactions y/y) | CN34: 0.02 | CO34: Δ → | CP34: -0.03 | CQ34: FY2023–25 +10–10.4%; 9M FY26 +9.1%. Tap-to-pay, e-commerce, new flows.
B35: Gross revenue y/y % | D35: =IF(AND(ISNUMBER(D34),ISNUMBER(C34)),IFERROR(D34/C34-1,""),"") -> 0.097117457 | E35: =IF(AND(ISNUMBER(E34),ISNUMBER(D34)),IFERROR(E34/D34-1,""),"") -> 0.18170657 | F35: =IF(AND(ISNUMBER(F34),ISNUMBER(E34)),IFERROR(F34/E34-1,""),"") -> 0.14992208 | G35: =IF(AND(ISNUMBER(G34),ISNUMBER(F34)),IFERROR(G34/F34-1,""),"") -> 0.13624864 | L35: =IF(AND(ISNUMBER(L34),ISNUMBER(G34)),IFERROR(L34/G34-1,""),"") -> 0.12110369 | M35: =IF(AND(ISNUMBER(M34),ISNUMBER(H34)),IFERROR(M34/H34-1,""),"") -> 0.10444248 | N35: =IF(AND(ISNUMBER(N34),ISNUMBER(I34)),IFERROR(N34/I34-1,""),"") -> 0.063829787 | O35: =IF(AND(ISNUMBER(O34),ISNUMBER(J34)),IFERROR(O34/J34-1,""),"") -> 0.076944918 | P35: =IF(AND(ISNUMBER(P34),ISNUMBER(K34)),IFERROR(P34/K34-1,""),"") -> 0.094169176 | Q35: =IF(AND(ISNUMBER(Q34),ISNUMBER(L34)),IFERROR(Q34/L34-1,""),"") -> 0.084757784 | R35: =IF(AND(ISNUMBER(R34),ISNUMBER(M34)),IFERROR(R34/M34-1,""),"") -> 0.090836441 | S35: =IF(AND(ISNUMBER(S34),ISNUMBER(N34)),IFERROR(S34/N34-1,""),"") -> 0.089333333 | ... BY35: =IF(AND(ISNUMBER(BY34),ISNUMBER(BT34)),IFERROR(BY34/BT34-1,""),"") -> 0.14527548 | BZ35: =IF(AND(ISNUMBER(BZ34),ISNUMBER(BY34)),IFERROR(BZ34/BY34-1,""),"") -> 0.11562184 | CA35: =IF(AND(ISNUMBER(CA34),ISNUMBER(BZ34)),IFERROR(CA34/BZ34-1,""),"") -> 0.10924959 | CB35: =IF(AND(ISNUMBER(CB34),ISNUMBER(CA34)),IFERROR(CB34/CA34-1,""),"") -> 0.10194248 | CC35: =IF(AND(ISNUMBER(CC34),ISNUMBER(CB34)),IFERROR(CC34/CB34-1,""),"") -> 0.094858647 | CD35: =IF(AND(ISNUMBER(CD34),ISNUMBER(CC34)),IFERROR(CD34/CC34-1,""),"") -> 0.0917147 | CM35: 2027E | CN35: =CO35+$CN$34 -> 0.11 | CO35: 0.09 | CP35: =CO35+$CP$34 -> 0.06
B36: Client incentives (deducted from gross revenue) | C36: 1161 | D36: 1234 | E36: 1560 | F36: 1880 | G36: 2155 | H36: 553 | I36: 567 | J36: 521 | K36: 680 | L36: 2321 | M36: 599 | N36: 587 | O36: 638 | P36: 768 | Q36: 2592 | R36: 713 | S36: 676 | T36: 670 | U36: 802 | V36: 2861 | W36: 788 | X36: 789 | Y36: 839 | Z36: 993 | AA36: 3409 | AB36: 1041 | AC36: 1031 | AD36: 1147 | AE36: 1346 | AF36: 4565 | AG36: 1326 | AH36: 1289 | AI36: 1374 | AJ36: 1502 | AK36: 5491 | AL36: 1456 | AM36: 1478 | AN36: 1546 | AO36: 1693 | AP36: 6173 | AQ36: 1748 | AR36: 1705 | AS36: 1513 | AT36: 1698 | AU36: 6664 | AV36: 1858 | AW36: 1992 | AX36: 2130 | AY36: 2387 | AZ36: 8367 | BA36: 2371 | BB36: 2494 | BC36: 2570 | BD36: 2860 | BE36: 10295 | BF36: 2786 | BG36: 2905 | BH36: 3167 | BI36: 3439 | BJ36: 12297 | BK36: 3348 | BL36: 3257 | BM36: 3530 | BN36: 3629 | BO36: 13764 | BP36: 3797 | BQ36: 3734 | BR36: 3972 | BS36: 4248 | BT36: 15751 | BU36: 4269 | BV36: 4245 | BW36: 4680 | BX36: =BX34*BX37 -> 4774.1335 | BY36: =SUM(BU36:BX36) -> 17968.133 | BZ36: =BZ34*BZ37 -> 20586.261 | CA36: =CA34*CA37 -> 22993.331 | CB36: =CB34*CB37 -> 25511.468 | CC36: =CC34*CC37 -> 28122.11 | CD36: =CD34*CD37 -> 30909.465 | CE36: Contra-revenue: incentives to financial-institution clients and merchants ("volume and support incentives" to FY2012). | CG36: =IFERROR((CD36/BY36)^(1/5)-1,"n/m") -> 0.11459658 | CH36: =IFERROR((BT36/AU36)^(1/5)-1,"n/m") -> 0.18772153 | CI36: =IFERROR((BT36/V36)^(1/10)-1,"n/m") -> 0.18598454 | CJ36: =IFERROR((BT36/C36)^(1/17)-1,"n/m") -> 0.16577901 | CM36: 2028E | CN36: =CO36+$CN$34 -> 0.11 | CO36: 0.09 | CP36: =CO36+$CP$34 -> 0.06
B37: Client incentives % of gross revenue | C37: =IF(AND(ISNUMBER(C36),ISNUMBER(C34)),IFERROR(C36/C34,""),"") -> 0.1563847 | D37: =IF(AND(ISNUMBER(D36),ISNUMBER(D34)),IFERROR(D36/D34,""),"") -> 0.15150399 | E37: =IF(AND(ISNUMBER(E36),ISNUMBER(E34)),IFERROR(E36/E34,""),"") -> 0.16207792 | F37: =IF(AND(ISNUMBER(F36),ISNUMBER(F34)),IFERROR(F36/F34,""),"") -> 0.16985905 | G37: =IF(AND(ISNUMBER(G36),ISNUMBER(G34)),IFERROR(G36/G34,""),"") -> 0.17135814 | H37: =IF(AND(ISNUMBER(H36),ISNUMBER(H34)),IFERROR(H36/H34,""),"") -> 0.16269491 | I37: =IF(AND(ISNUMBER(I36),ISNUMBER(I34)),IFERROR(I36/I34,""),"") -> 0.16085106 | J37: =IF(AND(ISNUMBER(J36),ISNUMBER(J34)),IFERROR(J36/J34,""),"") -> 0.14792731 | ... BW37: =IF(AND(ISNUMBER(BW36),ISNUMBER(BW34)),IFERROR(BW36/BW34,""),"") -> 0.28688776 | BX37: =BS37+IFERROR(SUM(BU36:BW36)/SUM(BU34:BW34)-SUM(BP36:BR36)/SUM(BP34:BR34),0) -> 0.28262265 | BY37: =IF(AND(ISNUMBER(BY36),ISNUMBER(BY34)),IFERROR(BY36/BY34,""),"") -> 0.28141053 | BZ37: =CHOOSE(MATCH($CE$2,{"Bull","Base","Bear"},0),$CN$65,$CO$65,$CP$65) -> 0.289 | CA37: =CHOOSE(MATCH($CE$2,{"Bull","Base","Bear"},0),$CN$66,$CO$66,$CP$66) -> 0.291 | CB37: =CHOOSE(MATCH($CE$2,{"Bull","Base","Bear"},0),$CN$67,$CO$67,$CP$67) -> 0.293 | CC37: =CHOOSE(MATCH($CE$2,{"Bull","Base","Bear"},0),$CN$68,$CO$68,$CP$68) -> 0.295 | CD37: =CHOOSE(MATCH($CE$2,{"Bull","Base","Bear"},0),$CN$69,$CO$69,$CP$69) -> 0.297 | CE37: Q4/26E: prior-year quarter + 9M FY26 y/y drift. 2027E+: scenario lever (renewals; FY2025 28.0%). | CG37: =IFERROR(AVERAGE(BZ37,CA37,CB37,CC37,CD37),"n/m") -> 0.293 | CH37: =IFERROR(AVERAGE(AZ37,BE37,BJ37,BO37,BT37),"n/m") -> 0.27014043 | CI37: =IFERROR(AVERAGE(AA37,AF37,AK37,AP37,AU37,AZ37,BE37,BJ37,BO37,BT37),"n/m") -> 0.23900995 | CJ37: =IFERROR(AVERAGE(C37,D37,E37,F37,G37,L37,Q37,V37,AA37,AF37,AK37,AP37,AU37,AZ37,BE37,BJ37,BO37,BT37),"n/m") -> 0.2059045 | CM37: 2029E | CN37: =CO37+$CN$34 -> 0.105 | CO37: 0.085 | CP37: =CO37+$CP$34 -> 0.055
B38: Revenue from future acquisitions (M&A lever) | BX38: =N(BX78) -> 0 | BY38: =N(BY78) -> 0 | BZ38: =N(BZ78) -> 62.5 | CA38: =N(CA78) -> 206.25 | CB38: =N(CB78) -> 371.5625 | CC38: =N(CC78) -> 561.67188 | CD38: =N(CD78) -> 780.29766 | CM38: 2030E | CN38: =CO38+$CN$34 -> 0.1 | CO38: 0.08 | CP38: =CO38+$CP$34 -> 0.05
B39: Net revenue (build) | C39: =IF(ISNUMBER(C34),C34-C36,C113) -> 6263 | D39: =IF(ISNUMBER(D34),D34-D36,D113) -> 6911 | E39: =IF(ISNUMBER(E34),E34-E36,E113) -> 8065 | F39: =IF(ISNUMBER(F34),F34-F36,F113) -> 9188 | G39: =IF(ISNUMBER(G34),G34-G36,G113) -> 10421 | H39: =IF(ISNUMBER(H34),H34-H36,H113) -> 2846 | I39: =IF(ISNUMBER(I34),I34-I36,I113) -> 2958 | J39: =IF(ISNUMBER(J34),J34-J36,J113) -> 3001 | ... BW39: =IF(ISNUMBER(BW34),BW34-BW36,BW113) -> 11633 | BX39: =BX34-BX36+BX38 -> 12118.12 | BY39: =SUM(BU39:BX39) -> 45882.12 | BZ39: =BZ34-BZ36+BZ38 -> 50708.976 | CA39: =CA34-CA36+CA38 -> 56227.803 | CB39: =CB34-CB36+CB38 -> 61929.952 | CC39: =CC34-CC36+CC38 -> 67768.748 | CD39: =CD34-CD36+CD38 -> 73943.106 | CE39: Gross revenue − client incentives (+ future acquisitions from 2027E). Drives the income statement. | CG39: =IFERROR((CD39/BY39)^(1/5)-1,"n/m") -> 0.10014731 | CH39: =IFERROR((BT39/AU39)^(1/5)-1,"n/m") -> 0.12859368 | CI39: =IFERROR((BT39/V39)^(1/10)-1,"n/m") -> 0.11164739 | CJ39: =IFERROR((BT39/C39)^(1/17)-1,"n/m") -> 0.11524239 | CM39: 2031E | CN39: =CO39+$CN$34 -> 0.1 | CO39: 0.08 | CP39: =CO39+$CP$34 -> 0.05
B40: Net revenue y/y % | D40: =IF(AND(ISNUMBER(D39),ISNUMBER(C39)),IFERROR(D39/C39-1,""),"") -> 0.10346479 | E40: =IF(AND(ISNUMBER(E39),ISNUMBER(D39)),IFERROR(E39/D39-1,""),"") -> 0.16698018 | F40: =IF(AND(ISNUMBER(F39),ISNUMBER(E39)),IFERROR(F39/E39-1,""),"") -> 0.13924365 | G40: =IF(AND(ISNUMBER(G39),ISNUMBER(F39)),IFERROR(G39/F39-1,""),"") -> 0.13419678 | L40: =IF(AND(ISNUMBER(L39),ISNUMBER(G39)),IFERROR(L39/G39-1,""),"") -> 0.13021783 | M40: =IF(AND(ISNUMBER(M39),ISNUMBER(H39)),IFERROR(M39/H39-1,""),"") -> 0.10857344 | N40: =IF(AND(ISNUMBER(N39),ISNUMBER(I39)),IFERROR(N39/I39-1,""),"") -> 0.069303584 | O40: =IF(AND(ISNUMBER(O39),ISNUMBER(J39)),IFERROR(O39/J39-1,""),"") -> 0.051316228 | P40: =IF(AND(ISNUMBER(P39),ISNUMBER(K39)),IFERROR(P39/K39-1,""),"") -> 0.086108308 | Q40: =IF(AND(ISNUMBER(Q39),ISNUMBER(L39)),IFERROR(Q39/L39-1,""),"") -> 0.07845135 | R40: =IF(AND(ISNUMBER(R39),ISNUMBER(M39)),IFERROR(R39/M39-1,""),"") -> 0.071949287 | S40: =IF(AND(ISNUMBER(S39),ISNUMBER(N39)),IFERROR(S39/N39-1,""),"") -> 0.077774265 | ... BY40: =IF(AND(ISNUMBER(BY39),ISNUMBER(BT39)),IFERROR(BY39/BT39-1,""),"") -> 0.147053 | BZ40: =IF(AND(ISNUMBER(BZ39),ISNUMBER(BY39)),IFERROR(BZ39/BY39-1,""),"") -> 0.10520125 | CA40: =IF(AND(ISNUMBER(CA39),ISNUMBER(BZ39)),IFERROR(CA39/BZ39-1,""),"") -> 0.10883333 | CB40: =IF(AND(ISNUMBER(CB39),ISNUMBER(CA39)),IFERROR(CB39/CA39-1,""),"") -> 0.10141155 | CC40: =IF(AND(ISNUMBER(CC39),ISNUMBER(CB39)),IFERROR(CC39/CB39-1,""),"") -> 0.094280657 | CD40: =IF(AND(ISNUMBER(CD39),ISNUMBER(CC39)),IFERROR(CD39/CC39-1,""),"") -> 0.091109224 | CM40: SVC_YLD (service yield change y/y) | CN40: 0.01 | CO40: Δ → | CP40: -0.015 | CQ40: Service revenue ÷ prior-quarter payments volume: FY2021–25 +1.1% to +5.4% a year (pricing, card benefits); 9M FY26 +2.8%.
...

Sheet Bull-Base-Bear
B2: Visa Inc. (V) — Bull / Base / Bear Case P&L Summary | J2: Share price ($): | K2: =Model!$BZ$375 -> 389
B3: Non-GAAP figures (company definitions: non-GAAP operating expenses, net income and EPS; adjusted EBITDA is a model definition) · USD millions · fiscal years ended 30 September · Live panel linked to Model — toggle scenario via Model!CE2. Bull and Bear panels are value snapshots generated from the Model with the switch set to each case. FY2026E = Q1–Q3 actual + Q4 calibrated to the Q4 FY26 call outlook (UNVERIFIED: net revenue growth ~13%, non-GAAP EPS growth ~14%). | J3: As of: | K3: =TODAY() -> 2026-10-12 00:00:00
B5: Scenario: | C5: =Model!$CE$2 -> Base | N5: Scenario: | O5: Bull | P5: Snapshot (values) — Model run with switch = Bull | Z5: Scenario: | AA5: Bear | AB5: Snapshot (values) — Model run with switch = Bear
B7: (USDm, except EPS and shares) | C7: 2026E | D7: 2027E | E7: 2028E | F7: 2029E | G7: 2030E | H7: 2031E | I7: 26-'31 CAGR | J7: LT Hist Avg | K7: LT Hist Min | L7: LT Hist Max | N7: (USDm, except EPS and shares) | O7: 2026E | P7: 2027E | Q7: 2028E | R7: 2029E | S7: 2030E | T7: 2031E | U7: 26-'31 CAGR | V7: LT Hist Avg | W7: LT Hist Min | X7: LT Hist Max | Z7: (USDm, except EPS and shares) | AA7: 2026E | AB7: 2027E | AC7: 2028E | AD7: 2029E | AE7: 2030E | AF7: 2031E | AG7: 26-'31 CAGR | AH7: LT Hist Avg | AI7: LT Hist Min | AJ7: LT Hist Max
B9: Net revenue | C9: =Model!BY113 -> 45882.12 | D9: =Model!BZ113 -> 50708.976 | E9: =Model!CA113 -> 56227.803 | F9: =Model!CB113 -> 61929.952 | G9: =Model!CC113 -> 67768.748 | H9: =Model!CD113 -> 73943.106 | I9: =IFERROR((H9/C9)^(1/5)-1,"n/m") -> 0.10014731 | N9: Net revenue | O9: 45989.36 | P9: 52839.919 | Q9: 60562.227 | R9: 68948.124 | S9: 77986.378 | T9: 87953.949 | U9: 0.13846477 | Z9: Net revenue | AA9: 45774.88 | AB9: 47382.295 | AC9: 49821.447 | AD9: 52016.294 | AE9: 53937.241 | AF9: 55756.837 | AG9: 0.040241517
B10: Net revenue y/y % | D10: =IFERROR(D9/C9-1,"") -> 0.10520125 | E10: =IFERROR(E9/D9-1,"") -> 0.10883333 | F10: =IFERROR(F9/E9-1,"") -> 0.10141155 | G10: =IFERROR(G9/F9-1,"") -> 0.094280657 | H10: =IFERROR(H9/G9-1,"") -> 0.091109224 | N10: Net revenue y/y % | P10: 0.14895966 | Q10: 0.14614534 | R10: 0.13846744 | S10: 0.13108775 | T10: 0.12781169 | Z10: Net revenue y/y % | AB10: 0.035115656 | AC10: 0.051478129 | AD10: 0.044054262 | AE10: 0.036929715 | AF10: 0.033735434
B11: Nominal payments volume y/y % | C11: =Model!BY202 -> 0.10428026 | D11: =Model!BZ202 -> 0.085 | E11: =Model!CA202 -> 0.08 | F11: =Model!CB202 -> 0.08 | G11: =Model!CC202 -> 0.075 | H11: =Model!CD202 -> 0.075 | N11: Nominal payments volume y/y % | O11: 0.10428026 | P11: 0.105 | Q11: 0.1 | R11: 0.1 | S11: 0.095 | T11: 0.095 | Z11: Nominal payments volume y/y % | AA11: 0.10428026 | AB11: 0.055 | AC11: 0.05 | AD11: 0.05 | AE11: 0.045 | AF11: 0.045
B12: Adjusted EBITDA (model) | C12: =Model!BY174 -> 32066.301 | D12: =Model!BZ174 -> 35529.645 | E12: =Model!CA174 -> 39500.032 | F12: =Model!CB174 -> 43676.913 | G12: =Model!CC174 -> 47794.801 | H12: =Model!CD174 -> 52285.56 | I12: =IFERROR((H12/C12)^(1/5)-1,"n/m") -> 0.10272337 | N12: Adjusted EBITDA (model) | O12: 32133.627 | P12: 37509.39 | Q12: 43102.775 | R12: 49261.62 | S12: 55719.215 | T12: 63002.802 | U12: 0.14414225 | Z12: Adjusted EBITDA (model) | AA12: 31998.888 | AB12: 32325.947 | AC12: 34081.803 | AD12: 35726.981 | AE12: 37046.368 | AF12: 38398.853 | AG12: 0.037138301
B13: Adjusted EBITDA margin % | C13: =IFERROR(C12/C9,"") -> 0.69888448 | D13: =IFERROR(D12/D9,"") -> 0.70065789 | E13: =IFERROR(E12/E9,"") -> 0.7025 | F13: =IFERROR(F12/F9,"") -> 0.70526316 | G13: =IFERROR(G12/G9,"") -> 0.70526316 | H13: =IFERROR(H12/H9,"") -> 0.70710526 | J13: =IFERROR(AVERAGE(Model!C175,Model!D175,Model!E175,Model!F175,Model!G175,Model!L175,Model!Q175,Model!V175,Model!AA175,Model!AF175,Model!AK175,Model!AP175,Model!AU175,Model!AZ175,Model!BE175,Model!BJ175,Model!BO175,Model!BT175),"") -> 0.66087513 | K13: =IFERROR(MIN(Model!C175,Model!D175,Model!E175,Model!F175,Model!G175,Model!L175,Model!Q175,Model!V175,Model!AA175,Model!AF175,Model!AK175,Model!AP175,Model!AU175,Model!AZ175,Model!BE175,Model!BJ175,Model!BO175,Model!BT175),"") -> 0.48954175 | L13: =IFERROR(MAX(Model!C175,Model!D175,Model!E175,Model!F175,Model!G175,Model!L175,Model!Q175,Model!V175,Model!AA175,Model!AF175,Model!AK175,Model!AP175,Model!AU175,Model!AZ175,Model!BE175,Model!BJ175,Model!BO175,Model!BT175),"") -> 0.70501535 | N13: Adjusted EBITDA margin % | O13: 0.69871873 | P13: 0.70986842 | Q13: 0.71171053 | R13: 0.71447368 | S13: 0.71447368 | T13: 0.71631579 | V13: 0.66087513 | W13: 0.48954175 | X13: 0.70501535 | Z13: Adjusted EBITDA margin % | AA13: 0.69904909 | AB13: 0.68223684 | AC13: 0.68407895 | AD13: 0.68684211 | AE13: 0.68684211 | AF13: 0.68868421 | AH13: 0.66087513 | AI13: 0.48954175 | AJ13: 0.70501535
B15: Operating income (GAAP) | C15: =Model!BY125 -> 28755.088 | D15: =Model!BZ125 -> 33890.702 | E15: =Model!CA125 -> 37732.651 | F15: =Model!CB125 -> 41783.081 | G15: =Model!CC125 -> 45757.749 | H15: =Model!CD125 -> 50098.484 | I15: =IFERROR((H15/C15)^(1/5)-1,"n/m") -> 0.11743424 | N15: Operating income (GAAP) | O15: 28818.993 | P15: 35809.63 | Q15: 41189.107 | R15: 47125.634 | S15: 53330.601 | T15: 60342.704 | U15: 0.15928227 | Z15: Operating income (GAAP) | AA15: 28691.089 | AB15: 30745.403 | AC15: 32482.691 | AD15: 34120.754 | AE15: 35428.579 | AF15: 36771.026 | AG15: 0.050876652
B16: Operating income y/y % | D16: =IFERROR(D15/C15-1,"") -> 0.17859842 | E16: =IFERROR(E15/D15-1,"") -> 0.11336294 | F16: =IFERROR(F15/E15-1,"") -> 0.1073455 | G16: =IFERROR(G15/F15-1,"") -> 0.095126238 | H16: =IFERROR(H15/G15-1,"") -> 0.094863395 | N16: Operating income y/y % | P16: 0.24257049 | Q16: 0.15022431 | R16: 0.14412856 | S16: 0.13166862 | T16: 0.13148367 | Z16: Operating income y/y % | AB16: 0.07160112 | AC16: 0.056505598 | AD16: 0.05042881 | AE16: 0.03832931 | AF16: 0.037891647
B17: Operating margin (GAAP) % | C17: =IFERROR(C15/C9,"") -> 0.62671665 | D17: =IFERROR(D15/D9,"") -> 0.66833733 | E17: =IFERROR(E15/E9,"") -> 0.6710675 | F17: =IFERROR(F15/F9,"") -> 0.67468293 | G17: =IFERROR(G15/G9,"") -> 0.67520428 | H17: =IFERROR(H15/H9,"") -> 0.67752745 | J17: =IFERROR(AVERAGE(Model!C213,Model!D213,Model!E213,Model!F213,Model!G213,Model!L213,Model!Q213,Model!V213,Model!AA213,Model!AF213,Model!AK213,Model!AP213,Model!AU213,Model!AZ213,Model!BE213,Model!BJ213,Model!BO213,Model!BT213),"") -> 0.56987512 | K17: =IFERROR(MIN(Model!C213,Model!D213,Model!E213,Model!F213,Model!G213,Model!L213,Model!Q213,Model!V213,Model!AA213,Model!AF213,Model!AK213,Model!AP213,Model!AU213,Model!AZ213,Model!BE213,Model!BJ213,Model!BO213,Model!BT213),"") -> 0.19671084 | L17: =IFERROR(MAX(Model!C213,Model!D213,Model!E213,Model!F213,Model!G213,Model!L213,Model!Q213,Model!V213,Model!AA213,Model!AF213,Model!AK213,Model!AP213,Model!AU213,Model!AZ213,Model!BE213,Model!BJ213,Model!BO213,Model!BT213),"") -> 0.66150997 | N17: Operating margin (GAAP) % | O17: 0.6266448 | P17: 0.67770032 | Q17: 0.68011216 | R17: 0.68349407 | S17: 0.68384508 | T17: 0.68607157 | V17: 0.56987512 | W17: 0.19671084 | X17: 0.66150997 | Z17: Operating margin (GAAP) % | AA17: 0.62678677 | AB17: 0.64887957 | AC17: 0.65198208 | AD17: 0.6559628 | AE17: 0.65684819 | AF17: 0.6594891 | AH17: 0.56987512 | AI17: 0.19671084 | AJ17: 0.66150997
B19: Non-GAAP Net Income | C19: =Model!BY188 -> 25165.122 | D19: =Model!BZ188 -> 27790.377 | E19: =Model!CA188 -> 30765.502 | F19: =Model!CB188 -> 33985.558 | G19: =Model!CC188 -> 37157.922 | H19: =Model!CD188 -> 40637.42 | I19: =IFERROR((H19/C19)^(1/5)-1,"n/m") -> 0.10058964 | N19: Non-GAAP Net Income | O19: 25216.884 | P19: 29365.451 | Q19: 33454.915 | R19: 38197.67 | S19: 43166.741 | T19: 48797.152 | U19: 0.14114441 | Z19: Non-GAAP Net Income | AA19: 25113.282 | AB19: 25210.934 | AC19: 26548.426 | AD19: 27805.751 | AE19: 28810.143 | AF19: 29851.35 | AG19: 0.03517101
B21: FDSO (m) | C21: =Model!BY143 -> 1907.9558 | D21: =Model!BZ143 -> 1850.3694 | E21: =Model!CA143 -> 1795.395 | F21: =Model!CB143 -> 1741.6677 | G21: =Model!CC143 -> 1686.7594 | H21: =Model!CD143 -> 1630.9967 | I21: =IFERROR((H21/C21)^(1/5)-1,"n/m") -> -0.030881348 | N21: FDSO (m) | O21: 1907.6345 | P21: 1840.6566 | Q21: 1774.982 | R21: 1712.5414 | S21: 1645.7367 | T21: 1574.7309 | U21: -0.037629642 | Z21: FDSO (m) | AA21: 1908.2772 | AB21: 1858.9698 | AC21: 1814.7865 | AD21: 1772.449 | AE21: 1732.5423 | AF21: 1695.2973 | AG21: -0.023390638
B23: Adjusted EPS — Diluted ($) | C23: =Model!BY191 -> 13.189573 | D23: =Model!BZ191 -> 15.018827 | E23: =Model!CA191 -> 17.135785 | F23: =Model!CB191 -> 19.513227 | G23: =Model!CC191 -> 22.029177 | H23: =Model!CD191 -> 24.915698 | I23: =IFERROR((H23/C23)^(1/5)-1,"n/m") -> 0.13566036 | N23: Adjusted EPS — Diluted ($) | O23: 13.218929 | P23: 15.953792 | Q23: 18.84803 | R23: 22.304669 | S23: 26.229433 | T23: 30.987613 | U23: 0.1857643 | Z23: Adjusted EPS — Diluted ($) | AA23: 13.160186 | AB23: 13.561777 | AC23: 14.628953 | AD23: 15.687758 | AE23: 16.628825 | AF23: 17.608328 | AG23: 0.05996425
B24: EPS y/y % | D24: =IFERROR(D23/C23-1,"") -> 0.13868943 | E24: =IFERROR(E23/D23-1,"") -> 0.14095364 | F24: =IFERROR(F23/E23-1,"") -> 0.13874136 | G24: =IFERROR(G23/F23-1,"") -> 0.12893558 | H24: =IFERROR(H23/G23-1,"") -> 0.13103174 | N24: EPS y/y % | P24: 0.2068899 | Q24: 0.18141384 | R24: 0.18339523 | S24: 0.17596153 | T24: 0.18140613 | Z24: EPS y/y % | AB24: 0.030515611 | AC24: 0.078689973 | AD24: 0.07237736 | AE24: 0.059987383 | AF24: 0.05890388
B26: P / E (x) — assumed (adjusted EPS) | G26: 30 | H26: 30 | N26: P / E (x) — assumed (adjusted EPS) | S26: 33 | T26: 33 | Z26: P / E (x) — assumed (adjusted EPS) | AD26: 25 | AE26: 25 | AF26: 25
B27: Price Target ($) | G27: =G26*G23 -> 660.8753 | H27: =H26*H23 -> 747.47094 | N27: Price Target ($) | S27: =S26*S23 -> 865.57129 | T27: =T26*T23 -> 1022.5912 | Z27: Price Target ($) | AD27: =AD26*AD23 -> 392.19395 | AE27: =AE26*AE23 -> 415.72064 | AF27: =AF26*AF23 -> 440.20819
B28: Upside / (Downside) vs current | G28: =IFERROR(G27/$K$2-1,"") -> 0.69890822 | H28: =IFERROR(H27/$K$2-1,"") -> 0.92151912 | N28: Upside / (Downside) vs current | S28: =IFERROR(S27/$K$2-1,"") -> 1.225119 | T28: =IFERROR(T27/$K$2-1,"") -> 1.6287692 | Z28: Upside / (Downside) vs current | AD28: =IFERROR(AD27/$K$2-1,"") -> 0.0082106622 | AE28: =IFERROR(AE27/$K$2-1,"") -> 0.068690581 | AF28: =IFERROR(AF27/$K$2-1,"") -> 0.1316406
B29: IRR (to 30-Sep of Y-1) | G29: =IFERROR((G27/$K$2)^(1/((DATE(2030-1,9,30)-$K$3)/365.25))-1,"") -> 0.19551477 | H29: =IFERROR((H27/$K$2)^(1/((DATE(2031-1,9,30)-$K$3)/365.25))-1,"") -> 0.17895827 | N29: IRR (to 30-Sep of Y-1) | S29: =IFERROR((S27/$K$2)^(1/((DATE(2030-1,9,30)-$K$3)/365.25))-1,"") -> 0.30930087 | T29: =IFERROR((T27/$K$2)^(1/((DATE(2031-1,9,30)-$K$3)/365.25))-1,"") -> 0.27587218 | Z29: IRR (to 30-Sep of Y-1) | AD29: =IFERROR((AD27/$K$2)^(1/((DATE(2029-1,9,30)-$K$3)/365.25))-1,"") -> 0.0041626031 | AE29: =IFERROR((AE27/$K$2)^(1/((DATE(2030-1,9,30)-$K$3)/365.25))-1,"") -> 0.02263717 | AF29: =IFERROR((AF27/$K$2)^(1/((DATE(2031-1,9,30)-$K$3)/365.25))-1,"") -> 0.031664124
B31: Free Cash Flow | C31: =Model!BY242 -> 22759.817 | D31: =Model!BZ242 -> 28437.461 | E31: =Model!CA242 -> 31549.776 | F31: =Model!CB242 -> 34894.544 | G31: =Model!CC242 -> 38148.748 | H31: =Model!CD242 -> 41712.272 | I31: =IFERROR((H31/C31)^(1/5)-1,"n/m") -> 0.12880524 | N31: Free Cash Flow | O31: 22819.076 | P31: 30051.416 | Q31: 34314.75 | R31: 39239.357 | S31: 44351.772 | T31: 50135.606 | U31: 0.17049521 | Z31: Free Cash Flow | AA31: 22700.489 | AB31: 25792.857 | AC31: 27228.798 | AD31: 28540.036 | AE31: 29555.131 | AF31: 30605.14 | AG31: 0.061577812
B32: FCF % | C32: =IFERROR(C31/C9,"") -> 0.49604981 | D32: =IFERROR(D31/D9,"") -> 0.56079739 | E32: =IFERROR(E31/E9,"") -> 0.56110632 | F32: =IFERROR(F31/F9,"") -> 0.56345182 | G32: =IFERROR(G31/G9,"") -> 0.56292538 | H32: =IFERROR(H31/H9,"") -> 0.56411306 | J32: =IFERROR(AVERAGE(Model!C244,Model!D244,Model!E244,Model!F244,Model!G244,Model!L244,Model!Q244,Model!V244,Model!AA244,Model!AF244,Model!AK244,Model!AP244,Model!AU244,Model!AZ244,Model!BE244,Model!BJ244,Model!BO244,Model!BT244),"") -> 0.42190106 | K32: =IFERROR(MIN(Model!C244,Model!D244,Model!E244,Model!F244,Model!G244,Model!L244,Model!Q244,Model!V244,Model!AA244,Model!AF244,Model!AK244,Model!AP244,Model!AU244,Model!AZ244,Model!BE244,Model!BJ244,Model!BO244,Model!BT244),"") -> 0.018521475 | L32: =IFERROR(MAX(Model!C244,Model!D244,Model!E244,Model!F244,Model!G244,Model!L244,Model!Q244,Model!V244,Model!AA244,Model!AF244,Model!AK244,Model!AP244,Model!AU244,Model!AZ244,Model!BE244,Model!BJ244,Model!BO244,Model!BT244),"") -> 0.60999659 | N32: FCF % | O32: 0.49618164 | P32: 0.56872563 | Q32: 0.56660317 | R32: 0.56911421 | S32: 0.56871178 | T32: 0.57002109 | V32: 0.42190106 | W32: 0.018521475 | X32: 0.60999659 | Z32: FCF % | AA32: 0.49591585 | AB32: 0.54435644 | AC32: 0.54652764 | AD32: 0.54867492 | AE32: 0.54795408 | AF32: 0.54890381 | AH32: 0.42190106 | AI32: 0.018521475 | AJ32: 0.60999659
B33: FCF / share ($) | C33: =IFERROR(C31/C21,"") -> 11.928902 | D33: =IFERROR(D31/D21,"") -> 15.368532 | E33: =IFERROR(E31/E21,"") -> 17.57261 | F33: =IFERROR(F31/F21,"") -> 20.035133 | G33: =IFERROR(G31/G21,"") -> 22.616591 | H33: =IFERROR(H31/H21,"") -> 25.574713 | N33: FCF / share ($) | O33: 11.961975 | P33: 16.326466 | Q33: 19.332449 | R33: 22.912939 | S33: 26.949494 | T33: 31.83757 | Z33: FCF / share ($) | AA33: 11.895803 | AB33: 13.874813 | AC33: 15.003857 | AD33: 16.102035 | AE33: 17.058823 | AF33: 18.052964
B34: FCF Yield (on PT) | F34: =IFERROR(F33/F$27,"") | G34: =IFERROR(G33/G$27,"") -> 0.034222176 | H34: =IFERROR(H33/H$27,"") -> 0.034214993 | N34: FCF Yield (on PT) | R34: =IFERROR(R33/R$27,"") | S34: =IFERROR(S33/S$27,"") -> 0.031134922 | T34: =IFERROR(T33/T$27,"") -> 0.03113421 | Z34: FCF Yield (on PT) | AD34: =IFERROR(AD33/AD$27,"") -> 0.041056307 | AE34: =IFERROR(AE33/AE$27,"") -> 0.041034342 | AF34: =IFERROR(AF33/AF$27,"") -> 0.041010058
B35: Adjusted EBITDA (leverage basis) | C35: =Model!BY174 -> 32066.301 | D35: =Model!BZ174 -> 35529.645 | E35: =Model!CA174 -> 39500.032 | F35: =Model!CB174 -> 43676.913 | G35: =Model!CC174 -> 47794.801 | H35: =Model!CD174 -> 52285.56 | I35: =IFERROR((H35/C35)^(1/5)-1,"n/m") -> 0.10272337 | N35: Adjusted EBITDA (leverage basis) | O35: 32133.627 | P35: 37509.39 | Q35: 43102.775 | R35: 49261.62 | S35: 55719.215 | T35: 63002.802 | U35: 0.14414225 | Z35: Adjusted EBITDA (leverage basis) | AA35: 31998.888 | AB35: 32325.947 | AC35: 34081.803 | AD35: 35726.981 | AE35: 37046.368 | AF35: 38398.853 | AG35: 0.037138301
B36: Adjusted EBITDA % of net revenue | C36: =IFERROR(C35/C9,"") -> 0.69888448 | D36: =IFERROR(D35/D9,"") -> 0.70065789 | E36: =IFERROR(E35/E9,"") -> 0.7025 | F36: =IFERROR(F35/F9,"") -> 0.70526316 | G36: =IFERROR(G35/G9,"") -> 0.70526316 | H36: =IFERROR(H35/H9,"") -> 0.70710526 | J36: =IFERROR(AVERAGE(Model!C212,Model!D212,Model!E212,Model!F212,Model!G212,Model!L212,Model!Q212,Model!V212,Model!AA212,Model!AF212,Model!AK212,Model!AP212,Model!AU212,Model!AZ212,Model!BE212,Model!BJ212,Model!BO212,Model!BT212),"") -> 0.66087513 | K36: =IFERROR(MIN(Model!C212,Model!D212,Model!E212,Model!F212,Model!G212,Model!L212,Model!Q212,Model!V212,Model!AA212,Model!AF212,Model!AK212,Model!AP212,Model!AU212,Model!AZ212,Model!BE212,Model!BJ212,Model!BO212,Model!BT212),"") -> 0.48954175 | L36: =IFERROR(MAX(Model!C212,Model!D212,Model!E212,Model!F212,Model!G212,Model!L212,Model!Q212,Model!V212,Model!AA212,Model!AF212,Model!AK212,Model!AP212,Model!AU212,Model!AZ212,Model!BE212,Model!BJ212,Model!BO212,Model!BT212),"") -> 0.70501535 | N36: Adjusted EBITDA % of net revenue | O36: 0.69871873 | P36: 0.70986842 | Q36: 0.71171053 | R36: 0.71447368 | S36: 0.71447368 | T36: 0.71631579 | V36: 0.66087513 | W36: 0.48954175 | X36: 0.70501535 | Z36: Adjusted EBITDA % of net revenue | AA36: 0.69904909 | AB36: 0.68223684 | AC36: 0.68407895 | AD36: 0.68684211 | AE36: 0.68684211 | AF36: 0.68868421 | AH36: 0.66087513 | AI36: 0.48954175 | AJ36: 0.70501535
B38: Net Debt | C38: =Model!BY369 -> 8583.0146 | D38: =Model!BZ369 -> 12435.376 | E38: =Model!CA369 -> 13825.011 | F38: =Model!CB369 -> 15286.92 | G38: =Model!CC369 -> 16728.18 | H38: =Model!CD369 -> 18299.946 | N38: Net Debt | O38: 9522.8942 | P38: 18754.695 | Q38: 21551.387 | R38: 24630.81 | S38: 27859.608 | T38: 31501.401 | Z38: Net Debt | AA38: 7643.2041 | AB38: 8081.4868 | AC38: 8520.4507 | AD38: 8931.7452 | AE38: 9261.592 | AF38: 9599.7133
