Workbook

Sheet Model
CF1: SCENARIO SWITCH ▼ (Bull / Base / Bear) — drives all scenario-linked forecast drivers
B2: Westinghouse Air Brake Technologies Corporation (Wabtec, NYSE: WAB) — 3-Statement Financial Model | CF2: Base
B3: US GAAP as reported · USD millions (per-share data in USD; shares in millions, split-adjusted) · Source: Wabtec Forms 10-K / 10-Q and Form 8-K earnings releases (Ex. 99.1) and earnings decks, deal 8-Ks, SEC EDGAR CIK 0000943452 (investor-relations releases are the same documents as filed on EDGAR)
B4: Basis notes: calendar fiscal year; all periods as originally reported. 2-for-1 stock split Jun-2013 (earlier shares / per-share data restated). Faiveley Transport from 30-Nov-2016; GE Transportation merger 25-Feb-2019 (segments recast Q4-19; product-line sales from 2019); adjusted results add back non-cash amortization from Q1-20 (2019 merger basis as reported). Inspection Technologies 1-Jul-2025; Frauscher 1-Dec-2025; Dellner Couplers 10-Feb-2026. Cash flow incl. restricted cash from 2018 (ASU 2016-18). Q3/26E–Q4/26E calibrated to FY26 sales and adjusted-EPS guidance.
CH5: Forecast | CI5: Historical | CJ5: Historical | CK5: Historical
B6: (USDm) | C6: 2006 | D6: 2007 | E6: 2008 | F6: 2009 | G6: 2010 | H6: 2011 | I6: 2012 | J6: Q1/13 | K6: Q2/13 | L6: Q3/13 | M6: Q4/13 | N6: 2013 | O6: Q1/14 | P6: Q2/14 | Q6: Q3/14 | R6: Q4/14 | S6: 2014 | T6: Q1/15 | U6: Q2/15 | V6: Q3/15 | W6: Q4/15 | X6: 2015 | Y6: Q1/16 | Z6: Q2/16 | AA6: Q3/16 | AB6: Q4/16 | AC6: 2016 | AD6: Q1/17 | AE6: Q2/17 | AF6: Q3/17 | AG6: Q4/17 | AH6: 2017 | AI6: Q1/18 | AJ6: Q2/18 | AK6: Q3/18 | AL6: Q4/18 | AM6: 2018 | AN6: Q1/19 | AO6: Q2/19 | AP6: Q3/19 | AQ6: Q4/19 | AR6: 2019 | AS6: Q1/20 | AT6: Q2/20 | AU6: Q3/20 | AV6: Q4/20 | AW6: 2020 | AX6: Q1/21 | AY6: Q2/21 | AZ6: Q3/21 | BA6: Q4/21 | BB6: 2021 | BC6: Q1/22 | BD6: Q2/22 | BE6: Q3/22 | BF6: Q4/22 | BG6: 2022 | BH6: Q1/23 | BI6: Q2/23 | BJ6: Q3/23 | BK6: Q4/23 | BL6: 2023 | BM6: Q1/24 | BN6: Q2/24 | BO6: Q3/24 | BP6: Q4/24 | BQ6: 2024 | BR6: Q1/25 | BS6: Q2/25 | BT6: Q3/25 | BU6: Q4/25 | BV6: 2025 | BW6: Q1/26 | BX6: Q2/26 | BY6: Q3/26E | BZ6: Q4/26E | CA6: 2026E | CB6: 2027E | CC6: 2028E | CD6: 2029E | CE6: 2030E | CF6: Modelling Notes | CH6: 5Y CAGR | CI6: 5Y CAGR | CJ6: 10Y CAGR | CK6: 19Y CAGR
CH7: 25-'30 | CI7: 20-'25 | CJ7: 15-'25 | CK7: 06-'25
B8: PRODUCT-LINE P&L — FREIGHT (SERVICES · EQUIPMENT · COMPONENTS · DIGITAL INTELLIGENCE) · TRANSIT (OE · AFTERMARKET) · BACKLOG | CF8: PRODUCT-LINE BUILD — modelling logic (product-line sales → segment sales × adjusted operating margin → adjusted operating income → Adjusted EBITDA / adjusted EPS)
CN9: SCENARIO INPUT TABLE — driver assumptions per Bull / Base / Bear | CO9: Bull | CP9: Base | CQ9: Bear | CR9: Bull / Bear = Base + Δ (Δ inputs on each block header). Outlook block = high / mid / low end of FY26 guidance ranges.
B10: Freight segment (locomotives & modernizations, services, components, digital intelligence; ~70% of sales) | CF10: FREIGHT — modelling logic
B11: 12-month backlog — Freight (period end) | C11: 192.8 | D11: 153.7 | E11: 148.6 | F11: 126.2 | G11: 297.2 | H11: 591.4 | I11: 413.8 | M11: 447.4 | N11: 447.4 | R11: 843.7 | S11: 843.7 | W11: 586 | X11: 586 | AB11: 396.2 | AC11: 396.2 | AE11: 413.2 | AF11: 419.7 | AG11: 423.8 | AH11: 423.8 | AI11: 501.4 | AJ11: 464.3 | AK11: 408.5 | AL11: 503.5 | AM11: 503.5 | AN11: 4061.3 | AO11: 3793.9 | AP11: 3914.2 | AQ11: 3911 | AR11: 3911 | AS11: 3819 | AT11: 3681.8 | AU11: 3626.7 | AV11: 3586.3 | AW11: 3586.3 | AX11: 3910.2 | AY11: 4098.1 | AZ11: 4060.2 | BA11: 4520 | BB11: 4520 | BC11: 4812 | BD11: 4821 | BE11: 4567 | BF11: 4901 | BG11: 4901 | BH11: 4978 | BI11: 5318 | BJ11: 5282 | BK11: 5450 | BL11: 5450 | BM11: 5667 | BN11: 5504 | BO11: 5589 | BP11: 5577 | BQ11: 5577 | BR11: 6069 | BS11: 6024 | BT11: 6085 | BU11: 6022 | BV11: 6022 | BW11: 6679 | BX11: 6638 | CF11: Company-reported 12-month backlog (subset of total backlog). Historical only; context for the Q3/Q4-26E growth inputs. | CN11: FY26 outlook — Q2-26 release (22-Jul-26) | CO11: High | CP11: Mid | CQ11: Low | CR11: Raised in the Q2-26 release (from $12.19–12.49bn / $10.25–10.65 in Q1-26; $10.05–10.45 in Feb-26). Includes Dellner (closed 10-Feb-26).
B12: Total (multi-year) backlog — Freight (period end) | C12: 261.8 | D12: 224.9 | E12: 195.7 | F12: 211.3 | G12: 383.6 | H12: 712.9 | I12: 491.8 | M12: 511.7 | N12: 511.7 | R12: 977.8 | S12: 977.8 | W12: 671.9 | X12: 671.9 | AB12: 575.9 | AC12: 575.9 | AE12: 611.2 | AF12: 610.7 | AG12: 549.2 | AH12: 549.2 | AI12: 631.6 | AJ12: 649.3 | AK12: 607.9 | AL12: 664.7 | AM12: 664.7 | AN12: 19466.1 | AO12: 18765.5 | AP12: 18257.6 | AQ12: 18945.3 | AR12: 18945.3 | AS12: 18099.6 | AT12: 17969.8 | AU12: 17840.5 | AV12: 17887.1 | AW12: 17887.1 | AX12: 18005.5 | AY12: 17836.3 | AZ12: 18211 | BA12: 18502 | BB12: 18502 | BC12: 19024 | BD12: 19679 | BE12: 19173 | BF12: 18641 | BG12: 18641 | BH12: 18362 | BI12: 18336 | BJ12: 17614 | BK12: 17831 | BL12: 17831 | BM12: 17898 | BN12: 17929 | BO12: 17756 | BP12: 17986 | BQ12: 17986 | BR12: 17851 | BS12: 17136 | BT12: 20907 | BU12: 22493 | BV12: 22493 | BW12: 25175 | BX12: 25332 | CN12: FY26 net sales ($m) | CO12: 12600 | CP12: 12450 | CQ12: 12300 | CR12: Guided $12.30–12.60bn (raised $110m at mid-point in Q2-26; +11.5% y/y).
B13: 12-month backlog ÷ annualised sales (x) | C13: =IF(AND(ISNUMBER(C11),ISNUMBER(C27)),IFERROR(C11/(C27*1),""),"") | D13: =IF(AND(ISNUMBER(D11),ISNUMBER(D27)),IFERROR(D11/(D27*1),""),"") | E13: =IF(AND(ISNUMBER(E11),ISNUMBER(E27)),IFERROR(E11/(E27*1),""),"") | F13: =IF(AND(ISNUMBER(F11),ISNUMBER(F27)),IFERROR(F11/(F27*1),""),"") | G13: =IF(AND(ISNUMBER(G11),ISNUMBER(G27)),IFERROR(G11/(G27*1),""),"") | H13: =IF(AND(ISNUMBER(H11),ISNUMBER(H27)),IFERROR(H11/(H27*1),""),"") | I13: =IF(AND(ISNUMBER(I11),ISNUMBER(I27)),IFERROR(I11/(I27*1),""),"") | J13: =IF(AND(ISNUMBER(J11),ISNUMBER(J27)),IFERROR(J11/(J27*4),""),"") | K13: =IF(AND(ISNUMBER(K11),ISNUMBER(K27)),IFERROR(K11/(K27*4),""),"") | L13: =IF(AND(ISNUMBER(L11),ISNUMBER(L27)),IFERROR(L11/(L27*4),""),"") | M13: =IF(AND(ISNUMBER(M11),ISNUMBER(M27)),IFERROR(M11/(M27*4),""),"") | N13: =IF(AND(ISNUMBER(N11),ISNUMBER(N27)),IFERROR(N11/(N27*1),""),"") | O13: =IF(AND(ISNUMBER(O11),ISNUMBER(O27)),IFERROR(O11/(O27*4),""),"") | P13: =IF(AND(ISNUMBER(P11),ISNUMBER(P27)),IFERROR(P11/(P27*4),""),"") | Q13: =IF(AND(ISNUMBER(Q11),ISNUMBER(Q27)),IFERROR(Q11/(Q27*4),""),"") | R13: =IF(AND(ISNUMBER(R11),ISNUMBER(R27)),IFERROR(R11/(R27*4),""),"") | S13: =IF(AND(ISNUMBER(S11),ISNUMBER(S27)),IFERROR(S11/(S27*1),""),"") | T13: =IF(AND(ISNUMBER(T11),ISNUMBER(T27)),IFERROR(T11/(T27*4),""),"") | U13: =IF(AND(ISNUMBER(U11),ISNUMBER(U27)),IFERROR(U11/(U27*4),""),"") | V13: =IF(AND(ISNUMBER(V11),ISNUMBER(V27)),IFERROR(V11/(V27*4),""),"") | W13: =IF(AND(ISNUMBER(W11),ISNUMBER(W27)),IFERROR(W11/(W27*4),""),"") | X13: =IF(AND(ISNUMBER(X11),ISNUMBER(X27)),IFERROR(X11/(X27*1),""),"") | Y13: =IF(AND(ISNUMBER(Y11),ISNUMBER(Y27)),IFERROR(Y11/(Y27*4),""),"") | Z13: =IF(AND(ISNUMBER(Z11),ISNUMBER(Z27)),IFERROR(Z11/(Z27*4),""),"") | AA13: =IF(AND(ISNUMBER(AA11),ISNUMBER(AA27)),IFERROR(AA11/(AA27*4),""),"") | AB13: =IF(AND(ISNUMBER(AB11),ISNUMBER(AB27)),IFERROR(AB11/(AB27*4),""),"") | AC13: =IF(AND(ISNUMBER(AC11),ISNUMBER(AC27)),IFERROR(AC11/(AC27*1),""),"") | AD13: =IF(AND(ISNUMBER(AD11),ISNUMBER(AD27)),IFERROR(AD11/(AD27*4),""),"") | AE13: =IF(AND(ISNUMBER(AE11),ISNUMBER(AE27)),IFERROR(AE11/(AE27*4),""),"") | AF13: =IF(AND(ISNUMBER(AF11),ISNUMBER(AF27)),IFERROR(AF11/(AF27*4),""),"") | AG13: =IF(AND(ISNUMBER(AG11),ISNUMBER(AG27)),IFERROR(AG11/(AG27*4),""),"") | AH13: =IF(AND(ISNUMBER(AH11),ISNUMBER(AH27)),IFERROR(AH11/(AH27*1),""),"") | AI13: =IF(AND(ISNUMBER(AI11),ISNUMBER(AI27)),IFERROR(AI11/(AI27*4),""),"") | AJ13: =IF(AND(ISNUMBER(AJ11),ISNUMBER(AJ27)),IFERROR(AJ11/(AJ27*4),""),"") | AK13: =IF(AND(ISNUMBER(AK11),ISNUMBER(AK27)),IFERROR(AK11/(AK27*4),""),"") | AL13: =IF(AND(ISNUMBER(AL11),ISNUMBER(AL27)),IFERROR(AL11/(AL27*4),""),"") | AM13: =IF(AND(ISNUMBER(AM11),ISNUMBER(AM27)),IFERROR(AM11/(AM27*1),""),"") | AN13: =IF(AND(ISNUMBER(AN11),ISNUMBER(AN27)),IFERROR(AN11/(AN27*4),""),"") | AO13: =IF(AND(ISNUMBER(AO11),ISNUMBER(AO27)),IFERROR(AO11/(AO27*4),""),"") | AP13: =IF(AND(ISNUMBER(AP11),ISNUMBER(AP27)),IFERROR(AP11/(AP27*4),""),"") | AQ13: =IF(AND(ISNUMBER(AQ11),ISNUMBER(AQ27)),IFERROR(AQ11/(AQ27*4),""),"") | AR13: =IF(AND(ISNUMBER(AR11),ISNUMBER(AR27)),IFERROR(AR11/(AR27*1),""),"") | AS13: =IF(AND(ISNUMBER(AS11),ISNUMBER(AS27)),IFERROR(AS11/(AS27*4),""),"") | AT13: =IF(AND(ISNUMBER(AT11),ISNUMBER(AT27)),IFERROR(AT11/(AT27*4),""),"") | AU13: =IF(AND(ISNUMBER(AU11),ISNUMBER(AU27)),IFERROR(AU11/(AU27*4),""),"") | AV13: =IF(AND(ISNUMBER(AV11),ISNUMBER(AV27)),IFERROR(AV11/(AV27*4),""),"") | AW13: =IF(AND(ISNUMBER(AW11),ISNUMBER(AW27)),IFERROR(AW11/(AW27*1),""),"") | AX13: =IF(AND(ISNUMBER(AX11),ISNUMBER(AX27)),IFERROR(AX11/(AX27*4),""),"") | AY13: =IF(AND(ISNUMBER(AY11),ISNUMBER(AY27)),IFERROR(AY11/(AY27*4),""),"") | AZ13: =IF(AND(ISNUMBER(AZ11),ISNUMBER(AZ27)),IFERROR(AZ11/(AZ27*4),""),"") | BA13: =IF(AND(ISNUMBER(BA11),ISNUMBER(BA27)),IFERROR(BA11/(BA27*4),""),"") | BB13: =IF(AND(ISNUMBER(BB11),ISNUMBER(BB27)),IFERROR(BB11/(BB27*1),""),"") | BC13: =IF(AND(ISNUMBER(BC11),ISNUMBER(BC27)),IFERROR(BC11/(BC27*4),""),"") | BD13: =IF(AND(ISNUMBER(BD11),ISNUMBER(BD27)),IFERROR(BD11/(BD27*4),""),"") | BE13: =IF(AND(ISNUMBER(BE11),ISNUMBER(BE27)),IFERROR(BE11/(BE27*4),""),"") | BF13: =IF(AND(ISNUMBER(BF11),ISNUMBER(BF27)),IFERROR(BF11/(BF27*4),""),"") | BG13: =IF(AND(ISNUMBER(BG11),ISNUMBER(BG27)),IFERROR(BG11/(BG27*1),""),"") | BH13: =IF(AND(ISNUMBER(BH11),ISNUMBER(BH27)),IFERROR(BH11/(BH27*4),""),"") | BI13: =IF(AND(ISNUMBER(BI11),ISNUMBER(BI27)),IFERROR(BI11/(BI27*4),""),"") | BJ13: =IF(AND(ISNUMBER(BJ11),ISNUMBER(BJ27)),IFERROR(BJ11/(BJ27*4),""),"") | BK13: =IF(AND(ISNUMBER(BK11),ISNUMBER(BK27)),IFERROR(BK11/(BK27*4),""),"") | BL13: =IF(AND(ISNUMBER(BL11),ISNUMBER(BL27)),IFERROR(BL11/(BL27*1),""),"") | BM13: =IF(AND(ISNUMBER(BM11),ISNUMBER(BM27)),IFERROR(BM11/(BM27*4),""),"") | BN13: =IF(AND(ISNUMBER(BN11),ISNUMBER(BN27)),IFERROR(BN11/(BN27*4),""),"") | BO13: =IF(AND(ISNUMBER(BO11),ISNUMBER(BO27)),IFERROR(BO11/(BO27*4),""),"") | BP13: =IF(AND(ISNUMBER(BP11),ISNUMBER(BP27)),IFERROR(BP11/(BP27*4),""),"") | BQ13: =IF(AND(ISNUMBER(BQ11),ISNUMBER(BQ27)),IFERROR(BQ11/(BQ27*1),""),"") | BR13: =IF(AND(ISNUMBER(BR11),ISNUMBER(BR27)),IFERROR(BR11/(BR27*4),""),"") | BS13: =IF(AND(ISNUMBER(BS11),ISNUMBER(BS27)),IFERROR(BS11/(BS27*4),""),"") | BT13: =IF(AND(ISNUMBER(BT11),ISNUMBER(BT27)),IFERROR(BT11/(BT27*4),""),"") | BU13: =IF(AND(ISNUMBER(BU11),ISNUMBER(BU27)),IFERROR(BU11/(BU27*4),""),"") | BV13: =IF(AND(ISNUMBER(BV11),ISNUMBER(BV27)),IFERROR(BV11/(BV27*1),""),"") | BW13: =IF(AND(ISNUMBER(BW11),ISNUMBER(BW27)),IFERROR(BW11/(BW27*4),""),"") | BX13: =IF(AND(ISNUMBER(BX11),ISNUMBER(BX27)),IFERROR(BX11/(BX27*4),""),"") | CF13: 12-month backlog over quarterly sales × 4 (annual columns: full-year sales). >1.0x = next-twelve-month sales largely covered. | CN13: FY26 adjusted diluted EPS ($) | CO13: 10.9 | CP13: 10.75 | CQ13: 10.6 | CR13: Guided $10.60–10.90 (+19.9% y/y at mid). Drives the Q3/Q4-26E adjusted-margin calibration.
B14: Services — sales | AN14: 231.4 | AO14: 556.5 | AP14: 635 | AQ14: 568.2 | AR14: 1991.1 | AS14: 499 | AT14: 508.8 | AU14: 512.8 | AV14: 547.5 | AW14: 2068.1 | AX14: 562.5 | AY14: 622 | AZ14: 582.5 | BA14: 663 | BB14: 2430 | BC14: 666 | BD14: 711 | BE14: 669 | BF14: 773 | BG14: 2819 | BH14: 707 | BI14: 810 | BJ14: 787 | BK14: 958 | BL14: 3262 | BM14: 829 | BN14: 829 | BO14: 917 | BP14: 806 | BQ14: 3381 | BR14: 863 | BS14: 781 | BT14: 744 | BU14: 667 | BV14: 3055 | BW14: 714 | BX14: 748 | BY14: =BT14*(1+BY15) | BZ14: =BU14*(1+BZ15) | CA14: =SUM(BW14,BX14,BY14,BZ14) | CB14: =CA14*(1+CB15) | CC14: =CB14*(1+CC15) | CD14: =CC14*(1+CD15) | CE14: =CD14*(1+CE15) | CF14: Product-line sales as published (from 2019, GE Transportation merger). Q3/Q4-26E: prior-year quarter × (1 + growth). 2027E+: prior year × (1 + scenario lever). | CH14: =IFERROR((CE14/BV14)^(1/5)-1,"n/m") | CI14: =IFERROR((BV14/AW14)^(1/5)-1,"n/m") | CJ14: =IFERROR((BV14/X14)^(1/10)-1,"n/m") | CK14: =IFERROR((BV14/C14)^(1/19)-1,"n/m") | CN14: 2H/26 share repurchases ($m) | CO14: 500 | CP14: 350 | CQ14: 200 | CR14: Authorization $760m remaining at 30-Jun-26 (1H/26: $457m, 1.80m shares).
B15: y/y % | D15: =IF(AND(ISNUMBER(D14),ISNUMBER(C14)),IFERROR(D14/C14-1,""),"") | E15: =IF(AND(ISNUMBER(E14),ISNUMBER(D14)),IFERROR(E14/D14-1,""),"") | F15: =IF(AND(ISNUMBER(F14),ISNUMBER(E14)),IFERROR(F14/E14-1,""),"") | G15: =IF(AND(ISNUMBER(G14),ISNUMBER(F14)),IFERROR(G14/F14-1,""),"") | H15: =IF(AND(ISNUMBER(H14),ISNUMBER(G14)),IFERROR(H14/G14-1,""),"") | I15: =IF(AND(ISNUMBER(I14),ISNUMBER(H14)),IFERROR(I14/H14-1,""),"") | N15: =IF(AND(ISNUMBER(N14),ISNUMBER(I14)),IFERROR(N14/I14-1,""),"") | O15: =IF(AND(ISNUMBER(O14),ISNUMBER(J14)),IFERROR(O14/J14-1,""),"") | P15: =IF(AND(ISNUMBER(P14),ISNUMBER(K14)),IFERROR(P14/K14-1,""),"") | Q15: =IF(AND(ISNUMBER(Q14),ISNUMBER(L14)),IFERROR(Q14/L14-1,""),"") | R15: =IF(AND(ISNUMBER(R14),ISNUMBER(M14)),IFERROR(R14/M14-1,""),"") | S15: =IF(AND(ISNUMBER(S14),ISNUMBER(N14)),IFERROR(S14/N14-1,""),"") | T15: =IF(AND(ISNUMBER(T14),ISNUMBER(O14)),IFERROR(T14/O14-1,""),"") | U15: =IF(AND(ISNUMBER(U14),ISNUMBER(P14)),IFERROR(U14/P14-1,""),"") | ... BX15: =IF(AND(ISNUMBER(BX14),ISNUMBER(BS14)),IFERROR(BX14/BS14-1,""),"") | BY15: =BY16+$BY$109 | BZ15: =BZ16+$BY$109 | CA15: =IF(AND(ISNUMBER(CA14),ISNUMBER(BV14)),IFERROR(CA14/BV14-1,""),"") | CB15: =CHOOSE(MATCH($CF$2,{"Bull","Base","Bear"},0),$CO$31,$CP$31,$CQ$31) | CC15: =CHOOSE(MATCH($CF$2,{"Bull","Base","Bear"},0),$CO$32,$CP$32,$CQ$32) | CD15: =CHOOSE(MATCH($CF$2,{"Bull","Base","Bear"},0),$CO$33,$CP$33,$CQ$33) | CE15: =CHOOSE(MATCH($CF$2,{"Bull","Base","Bear"},0),$CO$34,$CP$34,$CQ$34) | CF15: Q3/Q4-26E: growth input (row below) + revenue-outlook calibration Δ (Group block). 2027E–2030E: scenario lever (Bull/Base/Bear table →). | CN15: FY26 point estimates (all cases)
B16: Q3/Q4-26E growth input before revenue calibration | BY16: -0.04 | BZ16: -0.04 | CF16: Input −4%: 1H/26 −11% y/y (lower N.A. modernization deliveries, as guided), Q2/26 −4%. | CN16: Interest expense, net ($m) | CP16: 311 | CR16: 1H/26 $151m + Q2/26 run-rate ($80m) × 2 — Dellner financing on the revolver / receivables program; not guided.
B17: Equipment — sales | AN17: 267.1 | AO17: 531.3 | AP17: 263.3 | AQ17: 638 | AR17: 1699.7 | AS17: 408 | AT17: 334.9 | AU17: 355.3 | AV17: 433.3 | AW17: 1531.5 | AX17: 261.8 | AY17: 327.8 | AZ17: 335.2 | BA17: 377 | BB17: 1302 | BC17: 274 | BD17: 381 | BE17: 443 | BF17: 430 | BG17: 1528 | BH17: 393 | BI17: 415 | BJ17: 615 | BK17: 347 | BL17: 1770 | BM17: 526 | BN17: 570 | BO17: 513 | BP17: 499 | BQ17: 2108 | BR17: 476 | BS17: 546 | BT17: 677 | BU17: 666 | BV17: 2365 | BW17: 726 | BX17: 737 | BY17: =BT17*(1+BY18) | BZ17: =BU17*(1+BZ18) | CA17: =SUM(BW17,BX17,BY17,BZ17) | CB17: =CA17*(1+CB18) | CC17: =CB17*(1+CC18) | CD17: =CC17*(1+CD18) | CE17: =CD17*(1+CE18) | CF17: Product-line sales as published (from 2019, GE Transportation merger). Q3/Q4-26E: prior-year quarter × (1 + growth). 2027E+: prior year × (1 + scenario lever). | CH17: =IFERROR((CE17/BV17)^(1/5)-1,"n/m") | CI17: =IFERROR((BV17/AW17)^(1/5)-1,"n/m") | CJ17: =IFERROR((BV17/X17)^(1/10)-1,"n/m") | CK17: =IFERROR((BV17/C17)^(1/19)-1,"n/m") | CN17: Other income (expense), net ($m) | CP17: 21 | CR17: 1H/26 actual $21m; 2H/26 assumed nil (Q2/26 −$2m).
B18: y/y % | D18: =IF(AND(ISNUMBER(D17),ISNUMBER(C17)),IFERROR(D17/C17-1,""),"") | E18: =IF(AND(ISNUMBER(E17),ISNUMBER(D17)),IFERROR(E17/D17-1,""),"") | F18: =IF(AND(ISNUMBER(F17),ISNUMBER(E17)),IFERROR(F17/E17-1,""),"") | G18: =IF(AND(ISNUMBER(G17),ISNUMBER(F17)),IFERROR(G17/F17-1,""),"") | H18: =IF(AND(ISNUMBER(H17),ISNUMBER(G17)),IFERROR(H17/G17-1,""),"") | I18: =IF(AND(ISNUMBER(I17),ISNUMBER(H17)),IFERROR(I17/H17-1,""),"") | N18: =IF(AND(ISNUMBER(N17),ISNUMBER(I17)),IFERROR(N17/I17-1,""),"") | O18: =IF(AND(ISNUMBER(O17),ISNUMBER(J17)),IFERROR(O17/J17-1,""),"") | P18: =IF(AND(ISNUMBER(P17),ISNUMBER(K17)),IFERROR(P17/K17-1,""),"") | Q18: =IF(AND(ISNUMBER(Q17),ISNUMBER(L17)),IFERROR(Q17/L17-1,""),"") | R18: =IF(AND(ISNUMBER(R17),ISNUMBER(M17)),IFERROR(R17/M17-1,""),"") | S18: =IF(AND(ISNUMBER(S17),ISNUMBER(N17)),IFERROR(S17/N17-1,""),"") | T18: =IF(AND(ISNUMBER(T17),ISNUMBER(O17)),IFERROR(T17/O17-1,""),"") | U18: =IF(AND(ISNUMBER(U17),ISNUMBER(P17)),IFERROR(U17/P17-1,""),"") | ... BX18: =IF(AND(ISNUMBER(BX17),ISNUMBER(BS17)),IFERROR(BX17/BS17-1,""),"") | BY18: =BY19+$BY$109 | BZ18: =BZ19+$BY$109 | CA18: =IF(AND(ISNUMBER(CA17),ISNUMBER(BV17)),IFERROR(CA17/BV17-1,""),"") | CB18: =CHOOSE(MATCH($CF$2,{"Bull","Base","Bear"},0),$CO$36,$CP$36,$CQ$36) | CC18: =CHOOSE(MATCH($CF$2,{"Bull","Base","Bear"},0),$CO$37,$CP$37,$CQ$37) | CD18: =CHOOSE(MATCH($CF$2,{"Bull","Base","Bear"},0),$CO$38,$CP$38,$CQ$38) | CE18: =CHOOSE(MATCH($CF$2,{"Bull","Base","Bear"},0),$CO$39,$CP$39,$CQ$39) | CF18: Q3/Q4-26E: growth input (row below) + revenue-outlook calibration Δ (Group block). 2027E–2030E: scenario lever (Bull/Base/Bear table →). | CN18: Tax rate (GAAP & adjusted) | CP18: 0.245 | CR18: FY26 guidance slide: tax rate ~24.5%.
B19: Q3/Q4-26E growth input before revenue calibration | BY19: 0.12 | BZ19: 0.12 | CF19: Input +12%: 1H/26 +43% (international locomotive deliveries); tougher comparisons in 2H (Q3-25 $677m, Q4-25 $666m). | CN19: Capital expenditures ($m) | CP19: 250 | CR19: Guidance: capex ~2% of sales (≈$250m on the mid-point); 1H/26 $108m.
B20: Components — sales | AN20: 295.2 | AO20: 279.5 | AP20: 248.7 | AQ20: 250.1 | AR20: 1073.5 | AS20: 220.4 | AT20: 195.5 | AU20: 208.2 | AV20: 194.6 | AW20: 818.7 | AX20: 202.5 | AY20: 224.3 | AZ20: 222.1 | BA20: 218 | BB20: 867 | BC20: 229 | BD20: 234 | BE20: 232 | BF20: 241 | BG20: 936 | BH20: 279 | BI20: 288 | BJ20: 307 | BK20: 283 | BL20: 1157 | BM20: 293 | BN20: 322 | BO20: 296 | BP20: 282 | BQ20: 1193 | BR20: 381 | BS20: 401 | BT20: 375 | BU20: 429 | BV20: 1586 | BW20: 357 | BX20: 398 | BY20: =BT20*(1+BY21) | BZ20: =BU20*(1+BZ21) | CA20: =SUM(BW20,BX20,BY20,BZ20) | CB20: =CA20*(1+CB21) | CC20: =CB20*(1+CC21) | CD20: =CC20*(1+CD21) | CE20: =CD20*(1+CE21) | CF20: Product-line sales as published (from 2019, GE Transportation merger). Q3/Q4-26E: prior-year quarter × (1 + growth). 2027E+: prior year × (1 + scenario lever). | CH20: =IFERROR((CE20/BV20)^(1/5)-1,"n/m") | CI20: =IFERROR((BV20/AW20)^(1/5)-1,"n/m") | CJ20: =IFERROR((BV20/X20)^(1/10)-1,"n/m") | CK20: =IFERROR((BV20/C20)^(1/19)-1,"n/m") | CN20: Restructuring & portfolio optimization costs ($m) | CP20: 15 | CR20: 1H/26 $5m; Integration 3.0 / Portfolio Optimization; analyst point estimate.
B21: y/y % | D21: =IF(AND(ISNUMBER(D20),ISNUMBER(C20)),IFERROR(D20/C20-1,""),"") | E21: =IF(AND(ISNUMBER(E20),ISNUMBER(D20)),IFERROR(E20/D20-1,""),"") | F21: =IF(AND(ISNUMBER(F20),ISNUMBER(E20)),IFERROR(F20/E20-1,""),"") | G21: =IF(AND(ISNUMBER(G20),ISNUMBER(F20)),IFERROR(G20/F20-1,""),"") | H21: =IF(AND(ISNUMBER(H20),ISNUMBER(G20)),IFERROR(H20/G20-1,""),"") | I21: =IF(AND(ISNUMBER(I20),ISNUMBER(H20)),IFERROR(I20/H20-1,""),"") | N21: =IF(AND(ISNUMBER(N20),ISNUMBER(I20)),IFERROR(N20/I20-1,""),"") | O21: =IF(AND(ISNUMBER(O20),ISNUMBER(J20)),IFERROR(O20/J20-1,""),"") | P21: =IF(AND(ISNUMBER(P20),ISNUMBER(K20)),IFERROR(P20/K20-1,""),"") | Q21: =IF(AND(ISNUMBER(Q20),ISNUMBER(L20)),IFERROR(Q20/L20-1,""),"") | R21: =IF(AND(ISNUMBER(R20),ISNUMBER(M20)),IFERROR(R20/M20-1,""),"") | S21: =IF(AND(ISNUMBER(S20),ISNUMBER(N20)),IFERROR(S20/N20-1,""),"") | T21: =IF(AND(ISNUMBER(T20),ISNUMBER(O20)),IFERROR(T20/O20-1,""),"") | U21: =IF(AND(ISNUMBER(U20),ISNUMBER(P20)),IFERROR(U20/P20-1,""),"") | ... BX21: =IF(AND(ISNUMBER(BX20),ISNUMBER(BS20)),IFERROR(BX20/BS20-1,""),"") | BY21: =BY22+$BY$109 | BZ21: =BZ22+$BY$109 | CA21: =IF(AND(ISNUMBER(CA20),ISNUMBER(BV20)),IFERROR(CA20/BV20-1,""),"") | CB21: =CHOOSE(MATCH($CF$2,{"Bull","Base","Bear"},0),$CO$41,$CP$41,$CQ$41) | CC21: =CHOOSE(MATCH($CF$2,{"Bull","Base","Bear"},0),$CO$42,$CP$42,$CQ$42) | CD21: =CHOOSE(MATCH($CF$2,{"Bull","Base","Bear"},0),$CO$43,$CP$43,$CQ$43) | CE21: =CHOOSE(MATCH($CF$2,{"Bull","Base","Bear"},0),$CO$44,$CP$44,$CQ$44) | CF21: Q3/Q4-26E: growth input (row below) + revenue-outlook calibration Δ (Group block). 2027E–2030E: scenario lever (Bull/Base/Bear table →).
B22: Q3/Q4-26E growth input before revenue calibration | BY22: 0 | BZ22: 0 | CF22: Input 0%: 1H/26 −3% (N.A. railcar build down; industrial up).
B23: Digital Intelligence (Digital Electronics to 2023) — sales | AN23: 121.8 | AO23: 159 | AP23: 185.5 | AQ23: 210.8 | AR23: 677.1 | AS23: 173.6 | AT23: 165.5 | AU23: 161 | AV23: 163.9 | AW23: 664 | AX23: 156.5 | AY23: 161.8 | AZ23: 155.2 | BA23: 167 | BB23: 640 | BC23: 153 | BD23: 164 | BE23: 187 | BF23: 225 | BG23: 729 | BH23: 187 | BI23: 195 | BJ23: 181 | BK23: 210 | BL23: 773 | BM23: 176 | BN23: 199 | BO23: 204 | BP23: 207 | BQ23: 786 | BR23: 181 | BS23: 191 | BT23: 297 | BU23: 361 | BV23: 1030 | BW23: 318 | BX23: 360 | BY23: =BT23*(1+BY24) | BZ23: =BU23*(1+BZ24) | CA23: =SUM(BW23,BX23,BY23,BZ23) | CB23: =CA23*(1+CB24) | CC23: =CB23*(1+CC24) | CD23: =CC23*(1+CD24) | CE23: =CD23*(1+CE24) | CF23: Product-line sales as published (from 2019, GE Transportation merger). Q3/Q4-26E: prior-year quarter × (1 + growth). 2027E+: prior year × (1 + scenario lever). | CH23: =IFERROR((CE23/BV23)^(1/5)-1,"n/m") | CI23: =IFERROR((BV23/AW23)^(1/5)-1,"n/m") | CJ23: =IFERROR((BV23/X23)^(1/10)-1,"n/m") | CK23: =IFERROR((BV23/C23)^(1/19)-1,"n/m")
B24: y/y % | D24: =IF(AND(ISNUMBER(D23),ISNUMBER(C23)),IFERROR(D23/C23-1,""),"") | E24: =IF(AND(ISNUMBER(E23),ISNUMBER(D23)),IFERROR(E23/D23-1,""),"") | F24: =IF(AND(ISNUMBER(F23),ISNUMBER(E23)),IFERROR(F23/E23-1,""),"") | G24: =IF(AND(ISNUMBER(G23),ISNUMBER(F23)),IFERROR(G23/F23-1,""),"") | H24: =IF(AND(ISNUMBER(H23),ISNUMBER(G23)),IFERROR(H23/G23-1,""),"") | I24: =IF(AND(ISNUMBER(I23),ISNUMBER(H23)),IFERROR(I23/H23-1,""),"") | N24: =IF(AND(ISNUMBER(N23),ISNUMBER(I23)),IFERROR(N23/I23-1,""),"") | O24: =IF(AND(ISNUMBER(O23),ISNUMBER(J23)),IFERROR(O23/J23-1,""),"") | P24: =IF(AND(ISNUMBER(P23),ISNUMBER(K23)),IFERROR(P23/K23-1,""),"") | Q24: =IF(AND(ISNUMBER(Q23),ISNUMBER(L23)),IFERROR(Q23/L23-1,""),"") | R24: =IF(AND(ISNUMBER(R23),ISNUMBER(M23)),IFERROR(R23/M23-1,""),"") | S24: =IF(AND(ISNUMBER(S23),ISNUMBER(N23)),IFERROR(S23/N23-1,""),"") | T24: =IF(AND(ISNUMBER(T23),ISNUMBER(O23)),IFERROR(T23/O23-1,""),"") | U24: =IF(AND(ISNUMBER(U23),ISNUMBER(P23)),IFERROR(U23/P23-1,""),"") | ... BX24: =IF(AND(ISNUMBER(BX23),ISNUMBER(BS23)),IFERROR(BX23/BS23-1,""),"") | BY24: =BY25+$BY$109 | BZ24: =BZ25+$BY$109 | CA24: =IF(AND(ISNUMBER(CA23),ISNUMBER(BV23)),IFERROR(CA23/BV23-1,""),"") | CB24: =CHOOSE(MATCH($CF$2,{"Bull","Base","Bear"},0),$CO$46,$CP$46,$CQ$46) | CC24: =CHOOSE(MATCH($CF$2,{"Bull","Base","Bear"},0),$CO$47,$CP$47,$CQ$47) | CD24: =CHOOSE(MATCH($CF$2,{"Bull","Base","Bear"},0),$CO$48,$CP$48,$CQ$48) | CE24: =CHOOSE(MATCH($CF$2,{"Bull","Base","Bear"},0),$CO$49,$CP$49,$CQ$49) | CF24: Q3/Q4-26E: growth input (row below) + revenue-outlook calibration Δ (Group block). 2027E–2030E: scenario lever (Bull/Base/Bear table →).
B25: Q3/Q4-26E growth input before revenue calibration | BY25: 0.262 | BZ25: 0.171 | CF25: Input = 6% organic + Frauscher (closed 1-Dec-25) not yet in the prior-year quarter (~$60m in Q3, ~$40m in Q4; analyst estimate). Inspection Technologies anniversaries 1-Jul-26.
B26: Freight sales not split by product line (pre-2019 disclosure) | C26: =IF(ISNUMBER(C27),C27-(N(C14)+N(C17)+N(C20)+N(C23)),"") | D26: =IF(ISNUMBER(D27),D27-(N(D14)+N(D17)+N(D20)+N(D23)),"") | E26: =IF(ISNUMBER(E27),E27-(N(E14)+N(E17)+N(E20)+N(E23)),"") | F26: =IF(ISNUMBER(F27),F27-(N(F14)+N(F17)+N(F20)+N(F23)),"") | G26: =IF(ISNUMBER(G27),G27-(N(G14)+N(G17)+N(G20)+N(G23)),"") | H26: =IF(ISNUMBER(H27),H27-(N(H14)+N(H17)+N(H20)+N(H23)),"") | I26: =IF(ISNUMBER(I27),I27-(N(I14)+N(I17)+N(I20)+N(I23)),"") | J26: =IF(ISNUMBER(J27),J27-(N(J14)+N(J17)+N(J20)+N(J23)),"") | ... BX26: =IF(ISNUMBER(BX27),BX27-(N(BX14)+N(BX17)+N(BX20)+N(BX23)),"") | CF26: Historical segment sales less the product-line split (product lines are published from 2019; earlier years show the segment total here).
B27: Freight segment net sales | C27: 709.4 | D27: 734.2 | E27: 773.5 | F27: 588.4 | G27: 784.5 | H27: 1210.1 | I27: 1501.9 | J27: 305.9 | K27: 354.9 | L27: 340.5 | M27: 389 | N27: 1398.1 | O27: 385.5 | P27: 411.5 | Q27: 453.3 | R27: 481.1 | S27: 1731.5 | T27: 511.9 | U27: 534.7 | V27: 507.2 | W27: 501 | X27: 2054.7 | Y27: 442.7 | Z27: 397.1 | AA27: 362 | AB27: 341.4 | AC27: 1543.1 | AD27: 347.9 | AE27: 344.8 | AF27: 340.2 | AG27: 363.6 | AH27: 1396.6 | AI27: 379.6 | AJ27: 412.3 | AK27: 391.6 | AL27: 380.9 | AM27: 1564.3 | AN27: 876.4 | AO27: 1493.9 | AP27: 1295.7 | AQ27: 1667.1 | AR27: 5441.4 | AS27: 1301 | AT27: 1204.7 | AU27: 1237.3 | AV27: 1339.3 | AW27: 5082.3 | AX27: 1183.3 | AY27: 1335.9 | AZ27: 1295 | BA27: 1425 | BB27: 5239 | BC27: 1322 | BD27: 1490 | BE27: 1531 | BF27: 1669 | BG27: 6012 | BH27: 1566 | BI27: 1708 | BJ27: 1890 | BK27: 1798 | BL27: 6962 | BM27: 1824 | BN27: 1920 | BO27: 1930 | BP27: 1794 | BQ27: 7468 | BR27: 1901 | BS27: 1919 | BT27: 2093 | BU27: 2123 | BV27: 8036 | BW27: 2115 | BX27: 2243 | BY27: =N(BY14)+N(BY17)+N(BY20)+N(BY23) | BZ27: =N(BZ14)+N(BZ17)+N(BZ20)+N(BZ23) | CA27: =SUM(BW27,BX27,BY27,BZ27) | CB27: =N(CB14)+N(CB17)+N(CB20)+N(CB23) | CC27: =N(CC14)+N(CC17)+N(CC20)+N(CC23) | CD27: =N(CD14)+N(CD17)+N(CD20)+N(CD23) | CE27: =N(CE14)+N(CE17)+N(CE20)+N(CE23) | CF27: Historical = segment net sales as originally reported. Forecast = Σ product lines. | CH27: =IFERROR((CE27/BV27)^(1/5)-1,"n/m") | CI27: =IFERROR((BV27/AW27)^(1/5)-1,"n/m") | CJ27: =IFERROR((BV27/X27)^(1/10)-1,"n/m") | CK27: =IFERROR((BV27/C27)^(1/19)-1,"n/m")
B28: Segment net sales y/y % | D28: =IF(AND(ISNUMBER(D27),ISNUMBER(C27)),IFERROR(D27/C27-1,""),"") | E28: =IF(AND(ISNUMBER(E27),ISNUMBER(D27)),IFERROR(E27/D27-1,""),"") | F28: =IF(AND(ISNUMBER(F27),ISNUMBER(E27)),IFERROR(F27/E27-1,""),"") | G28: =IF(AND(ISNUMBER(G27),ISNUMBER(F27)),IFERROR(G27/F27-1,""),"") | H28: =IF(AND(ISNUMBER(H27),ISNUMBER(G27)),IFERROR(H27/G27-1,""),"") | I28: =IF(AND(ISNUMBER(I27),ISNUMBER(H27)),IFERROR(I27/H27-1,""),"") | N28: =IF(AND(ISNUMBER(N27),ISNUMBER(I27)),IFERROR(N27/I27-1,""),"") | O28: =IF(AND(ISNUMBER(O27),ISNUMBER(J27)),IFERROR(O27/J27-1,""),"") | P28: =IF(AND(ISNUMBER(P27),ISNUMBER(K27)),IFERROR(P27/K27-1,""),"") | Q28: =IF(AND(ISNUMBER(Q27),ISNUMBER(L27)),IFERROR(Q27/L27-1,""),"") | R28: =IF(AND(ISNUMBER(R27),ISNUMBER(M27)),IFERROR(R27/M27-1,""),"") | S28: =IF(AND(ISNUMBER(S27),ISNUMBER(N27)),IFERROR(S27/N27-1,""),"") | T28: =IF(AND(ISNUMBER(T27),ISNUMBER(O27)),IFERROR(T27/O27-1,""),"") | U28: =IF(AND(ISNUMBER(U27),ISNUMBER(P27)),IFERROR(U27/P27-1,""),"") | ... CA28: =IF(AND(ISNUMBER(CA27),ISNUMBER(BV27)),IFERROR(CA27/BV27-1,""),"") | CB28: =IF(AND(ISNUMBER(CB27),ISNUMBER(CA27)),IFERROR(CB27/CA27-1,""),"") | CC28: =IF(AND(ISNUMBER(CC27),ISNUMBER(CB27)),IFERROR(CC27/CB27-1,""),"") | CD28: =IF(AND(ISNUMBER(CD27),ISNUMBER(CC27)),IFERROR(CD27/CC27-1,""),"") | CE28: =IF(AND(ISNUMBER(CE27),ISNUMBER(CD27)),IFERROR(CE27/CD27-1,""),"") | CN28: Minimum net debt / Adjusted EBITDA (x) — buyback floor 2027E+ | CO28: 1.75 | CP28: 1.5 | CQ28: 1.25 | CR28: Wabtec targets net leverage of ~2.0–2.5x through the cycle; ~1.7x Adjusted EBITDA expected at YE26 (2.0x at 30-Jun-26 after Dellner). Floors leave headroom for bolt-on M&A; buybacks absorb free cash flow once leverage reaches the scenario floor.
B29: Segment gross profit (GAAP; published from 2019) | AQ29: 514.2 | AR29: 1581.4 | AX29: 356 | AY29: 414 | AZ29: 444 | BA29: 454 | BB29: 1667 | BC29: 424 | BD29: 493 | BE29: 497 | BF29: 482 | BG29: 1896 | BH29: 480 | BI29: 541 | BJ29: 611 | BK29: 558 | BL29: 2190 | BM29: 625 | BN29: 669 | BO29: 673 | BP29: 556 | BQ29: 2523 | BR29: 685 | BS29: 697 | BT29: 750 | BU29: 703 | BV29: 2835 | BW29: 788 | BX29: 854
B30: Segment gross margin % | C30: =IF(AND(ISNUMBER(C29),ISNUMBER(C27)),IFERROR(C29/C27,""),"") | D30: =IF(AND(ISNUMBER(D29),ISNUMBER(D27)),IFERROR(D29/D27,""),"") | E30: =IF(AND(ISNUMBER(E29),ISNUMBER(E27)),IFERROR(E29/E27,""),"") | F30: =IF(AND(ISNUMBER(F29),ISNUMBER(F27)),IFERROR(F29/F27,""),"") | G30: =IF(AND(ISNUMBER(G29),ISNUMBER(G27)),IFERROR(G29/G27,""),"") | H30: =IF(AND(ISNUMBER(H29),ISNUMBER(H27)),IFERROR(H29/H27,""),"") | I30: =IF(AND(ISNUMBER(I29),ISNUMBER(I27)),IFERROR(I29/I27,""),"") | J30: =IF(AND(ISNUMBER(J29),ISNUMBER(J27)),IFERROR(J29/J27,""),"") | ... BX30: =IF(AND(ISNUMBER(BX29),ISNUMBER(BX27)),IFERROR(BX29/BX27,""),"") | CH30: =IFERROR(AVERAGE(CA30,CB30,CC30,CD30,CE30),"n/m") | CI30: =IFERROR(AVERAGE(BB30,BG30,BL30,BQ30,BV30),"n/m") | CJ30: =IFERROR(AVERAGE(AC30,AH30,AM30,AR30,AW30,BB30,BG30,BL30,BQ30,BV30),"n/m") | CK30: =IFERROR(AVERAGE(C30,D30,E30,F30,G30,H30,I30,N30,S30,X30,AC30,AH30,AM30,AR30,AW30,BB30,BG30,BL30,BQ30,BV30),"n/m") | CN30: FRT_SVC (Freight Services sales y/y) | CO30: 0.02 | CP30: Δ → | CQ30: -0.02 | CR30: Modernizations (lumpy; N.A. mods down in 2026), overhauls, parts & long-term service agreements on the ~25,000 GE-built fleet.
B31: Freight adjusted income from operations (company definition) | AM31: 308 | AS31: 240.6 | AT31: 228.9 | AU31: 234.2 | AV31: 218.4 | AW31: 922.1 | AX31: 214.1 | AY31: 246.7 | AZ31: 266.2 | BA31: 267 | BB31: 993 | BC31: 259 | BD31: 301 | BE31: 307 | BF31: 284 | BG31: 1151 | BH31: 297 | BI31: 346 | BJ31: 399 | BK31: 347 | BL31: 1389 | BM31: 439 | BN31: 462 | BO31: 467 | BP31: 348 | BQ31: 1716 | BR31: 488 | BS31: 480 | BT31: 513 | BU31: 470 | BV31: 1951 | BW31: 550 | BX31: 579 | BY31: =BY27*BY32 | BZ31: =BZ27*BZ32 | CA31: =SUM(BW31,BX31,BY31,BZ31) | CB31: =CB27*CB32 | CC31: =CC27*CC32 | CD31: =CD27*CD32 | CE31: =CE27*CE32 | CF31: Segment adjusted operating income as published (segment Reported→Adjusted tables). Forecast = segment sales × adjusted operating margin. | CH31: =IFERROR((CE31/BV31)^(1/5)-1,"n/m") | CI31: =IFERROR((BV31/AW31)^(1/5)-1,"n/m") | CJ31: =IFERROR((BV31/X31)^(1/10)-1,"n/m") | CK31: =IFERROR((BV31/C31)^(1/19)-1,"n/m") | CN31: 2027E | CO31: =CP31+$CO$30 | CP31: 0.04 | CQ31: =CP31+$CQ$30
B32: Adjusted operating margin % | C32: =IF(AND(ISNUMBER(C31),ISNUMBER(C27)),IFERROR(C31/C27,""),"") | D32: =IF(AND(ISNUMBER(D31),ISNUMBER(D27)),IFERROR(D31/D27,""),"") | E32: =IF(AND(ISNUMBER(E31),ISNUMBER(E27)),IFERROR(E31/E27,""),"") | F32: =IF(AND(ISNUMBER(F31),ISNUMBER(F27)),IFERROR(F31/F27,""),"") | G32: =IF(AND(ISNUMBER(G31),ISNUMBER(G27)),IFERROR(G31/G27,""),"") | H32: =IF(AND(ISNUMBER(H31),ISNUMBER(H27)),IFERROR(H31/H27,""),"") | I32: =IF(AND(ISNUMBER(I31),ISNUMBER(I27)),IFERROR(I31/I27,""),"") | J32: =IF(AND(ISNUMBER(J31),ISNUMBER(J27)),IFERROR(J31/J27,""),"") | ... BX32: =IF(AND(ISNUMBER(BX31),ISNUMBER(BX27)),IFERROR(BX31/BX27,""),"") | BY32: =BY33+$BY$115 | BZ32: =BZ33+$BY$115 | CA32: =IF(AND(ISNUMBER(CA31),ISNUMBER(CA27)),IFERROR(CA31/CA27,""),"") | CB32: =CHOOSE(MATCH($CF$2,{"Bull","Base","Bear"},0),$CO$61,$CP$61,$CQ$61) | CC32: =CHOOSE(MATCH($CF$2,{"Bull","Base","Bear"},0),$CO$62,$CP$62,$CQ$62) | CD32: =CHOOSE(MATCH($CF$2,{"Bull","Base","Bear"},0),$CO$63,$CP$63,$CQ$63) | CE32: =CHOOSE(MATCH($CF$2,{"Bull","Base","Bear"},0),$CO$64,$CP$64,$CQ$64) | CF32: Q3/Q4-26E: margin before calibration + adjusted-EPS-outlook calibration Δ (Group block). 2027E–2030E: scenario lever. | CH32: =IFERROR(AVERAGE(CA32,CB32,CC32,CD32,CE32),"n/m") | CI32: =IFERROR(AVERAGE(BB32,BG32,BL32,BQ32,BV32),"n/m") | CJ32: =IFERROR(AVERAGE(AC32,AH32,AM32,AR32,AW32,BB32,BG32,BL32,BQ32,BV32),"n/m") | CK32: =IFERROR(AVERAGE(C32,D32,E32,F32,G32,H32,I32,N32,S32,X32,AC32,AH32,AM32,AR32,AW32,BB32,BG32,BL32,BQ32,BV32),"n/m") | CN32: 2028E | CO32: =CP32+$CO$30 | CP32: 0.05 | CQ32: =CP32+$CQ$30
B33: Adjusted operating margin before outlook calibration % (Q3/Q4-26E helper) | BY33: =BT32+((BW31+BX31)/(BW27+BX27)-(BR31+BS31)/(BR27+BS27)) | BZ33: =BU32+((BW31+BX31)/(BW27+BX27)-(BR31+BS31)/(BR27+BS27)) | CF33: Prior-year quarter margin + (1H/26 − 1H/25 adjusted margin drift). | CN33: 2029E | CO33: =CP33+$CO$30 | CP33: 0.05 | CQ33: =CP33+$CQ$30
B34: Incremental adjusted operating margin (Δ adj. op. income / Δ sales) | D34: =IFERROR((D31-C31)/(D27-C27),"") | E34: =IFERROR((E31-D31)/(E27-D27),"") | F34: =IFERROR((F31-E31)/(F27-E27),"") | G34: =IFERROR((G31-F31)/(G27-F27),"") | H34: =IFERROR((H31-G31)/(H27-G27),"") | I34: =IFERROR((I31-H31)/(I27-H27),"") | N34: =IFERROR((N31-I31)/(N27-I27),"") | O34: =IFERROR((O31-J31)/(O27-J27),"") | P34: =IFERROR((P31-K31)/(P27-K27),"") | Q34: =IFERROR((Q31-L31)/(Q27-L27),"") | R34: =IFERROR((R31-M31)/(R27-M27),"") | S34: =IFERROR((S31-N31)/(S27-N27),"") | T34: =IFERROR((T31-O31)/(T27-O27),"") | U34: =IFERROR((U31-P31)/(U27-P27),"") | ... CA34: =IFERROR((CA31-BV31)/(CA27-BV27),"") | CB34: =IFERROR((CB31-CA31)/(CB27-CA27),"") | CC34: =IFERROR((CC31-CB31)/(CC27-CB27),"") | CD34: =IFERROR((CD31-CC31)/(CD27-CC27),"") | CE34: =IFERROR((CE31-CD31)/(CE27-CD27),"") | CN34: 2030E | CO34: =CP34+$CO$30 | CP34: 0.05 | CQ34: =CP34+$CQ$30
B35: Adjusting items in segment (amortization, restructuring, purchase accounting, transaction) | C35: =IF(AND(ISNUMBER(C31),ISNUMBER(C37)),C31-C37,"") | D35: =IF(AND(ISNUMBER(D31),ISNUMBER(D37)),D31-D37,"") | E35: =IF(AND(ISNUMBER(E31),ISNUMBER(E37)),E31-E37,"") | F35: =IF(AND(ISNUMBER(F31),ISNUMBER(F37)),F31-F37,"") | G35: =IF(AND(ISNUMBER(G31),ISNUMBER(G37)),G31-G37,"") | H35: =IF(AND(ISNUMBER(H31),ISNUMBER(H37)),H31-H37,"") | I35: =IF(AND(ISNUMBER(I31),ISNUMBER(I37)),I31-I37,"") | J35: =IF(AND(ISNUMBER(J31),ISNUMBER(J37)),J31-J37,"") | ... BX35: =IF(AND(ISNUMBER(BX31),ISNUMBER(BX37)),BX31-BX37,"") | BY35: =BY213*BY36 | BZ35: =BZ213*BZ36 | CA35: =SUM(BW35,BX35,BY35,BZ35) | CB35: =CB213*CB36 | CC35: =CC213*CC36 | CD35: =CD213*CD36 | CE35: =CE213*CE36 | CF35: Historical = adjusted − GAAP segment operating income. Forecast = consolidated operating-level adjusting items × segment share. | CN35: FRT_EQ (Freight Equipment sales y/y) | CO35: 0.03 | CP35: Δ → | CQ35: -0.04 | CR35: New locomotives (international orders: Kazakhstan, India, Brazil, Africa) & mining; $25.3bn Freight backlog at 30-Jun-26.
B36: Segment share of consolidated operating-level adjusting items % | C36: =IF(ISNUMBER(C35),IFERROR(C35/C213,""),"") | D36: =IF(ISNUMBER(D35),IFERROR(D35/D213,""),"") | E36: =IF(ISNUMBER(E35),IFERROR(E35/E213,""),"") | F36: =IF(ISNUMBER(F35),IFERROR(F35/F213,""),"") | G36: =IF(ISNUMBER(G35),IFERROR(G35/G213,""),"") | H36: =IF(ISNUMBER(H35),IFERROR(H35/H213,""),"") | I36: =IF(ISNUMBER(I35),IFERROR(I35/I213,""),"") | J36: =IF(ISNUMBER(J35),IFERROR(J35/J213,""),"") | ... BX36: =IF(ISNUMBER(BX35),IFERROR(BX35/BX213,""),"") | BY36: =IFERROR((BW35+BX35)/(BW213+BX213),0) | BZ36: =IFERROR((BW35+BX35)/(BW213+BX213),0) | CA36: =IFERROR(CA35/CA213,"") | CB36: =$BZ$36 | CC36: =$BZ$36 | CD36: =$BZ$36 | CE36: =$BZ$36 | CF36: Forecast at the 1H/26 share (Freight carries most acquired-intangible amortization). | CN36: 2027E | CO36: =CP36+$CO$35 | CP36: 0.06 | CQ36: =CP36+$CQ$35
B37: Freight income from operations (GAAP) | C37: 109.8 | D37: 126.5 | E37: 133.5 | F37: 74.1 | G37: 122.1 | H37: 225.3 | I37: 316.1 | J37: 75.4 | K37: 78.6 | L37: 77.3 | M37: 83.4 | N37: 309.1 | O37: 91.9 | P37: 100.3 | Q37: 102.2 | R37: 108.1 | S37: 402.5 | T37: 111.6 | U37: 125.2 | V37: 119.9 | W37: 125.9 | X37: 482.6 | Y37: 106.7 | Z37: 92.3 | AA37: 78 | AB37: 67.5 | AC37: 344.5 | AD37: 71.4 | AE37: 63.3 | AF37: 61.6 | AG37: 68.3 | AH37: 264.6 | AI37: 69.6 | AJ37: 84.3 | AK37: 79.4 | AL37: 71.4 | AM37: 304.8 | AN37: 75.2 | AO37: 152 | AP37: 148.1 | AQ37: 239.2 | AR37: 642.9 | AS37: 161.7 | AT37: 141.5 | AU37: 160.2 | AV37: 120.5 | AW37: 583.9 | AX37: 141.8 | AY37: 173.2 | AZ37: 195.2 | BA37: 207 | BB37: 717 | BC37: 189 | BD37: 233 | BE37: 233 | BF37: 209 | BG37: 864 | BH37: 227 | BI37: 271 | BJ37: 327 | BK37: 246 | BL37: 1071 | BM37: 368 | BN37: 391 | BO37: 390 | BP37: 273 | BQ37: 1422 | BR37: 420 | BS37: 415 | BT37: 414 | BU37: 318 | BV37: 1567 | BW37: 450 | BX37: 504 | BY37: =BY31-BY35 | BZ37: =BZ31-BZ35 | CA37: =SUM(BW37,BX37,BY37,BZ37) | CB37: =CB31-CB35 | CC37: =CC31-CC35 | CD37: =CD31-CD35 | CE37: =CE31-CE35 | CN37: 2028E | CO37: =CP37+$CO$35 | CP37: 0.05 | CQ37: =CP37+$CQ$35
B38: GAAP operating margin % | C38: =IF(AND(ISNUMBER(C37),ISNUMBER(C27)),IFERROR(C37/C27,""),"") | D38: =IF(AND(ISNUMBER(D37),ISNUMBER(D27)),IFERROR(D37/D27,""),"") | E38: =IF(AND(ISNUMBER(E37),ISNUMBER(E27)),IFERROR(E37/E27,""),"") | F38: =IF(AND(ISNUMBER(F37),ISNUMBER(F27)),IFERROR(F37/F27,""),"") | G38: =IF(AND(ISNUMBER(G37),ISNUMBER(G27)),IFERROR(G37/G27,""),"") | H38: =IF(AND(ISNUMBER(H37),ISNUMBER(H27)),IFERROR(H37/H27,""),"") | I38: =IF(AND(ISNUMBER(I37),ISNUMBER(I27)),IFERROR(I37/I27,""),"") | J38: =IF(AND(ISNUMBER(J37),ISNUMBER(J27)),IFERROR(J37/J27,""),"") | ... CE38: =IF(AND(ISNUMBER(CE37),ISNUMBER(CE27)),IFERROR(CE37/CE27,""),"") | CN38: 2029E | CO38: =CP38+$CO$35 | CP38: 0.04 | CQ38: =CP38+$CQ$35
CN39: 2030E | CO39: =CP39+$CO$35 | CP39: 0.04 | CQ39: =CP39+$CQ$35
B40: Transit segment (passenger-rail original equipment & aftermarket: brakes, doors, HVAC, couplers, pantographs) | CF40: TRANSIT — modelling logic | CN40: FRT_COMP (Freight Components sales y/y) | CO40: 0.02 | CP40: Δ → | CQ40: -0.03 | CR40: N.A. railcar build (soft 2025–26) and industrial (L&M, cooling); North American freight car cycle recovery from 2027.
...

Sheet Bull-Base-Bear
B2: Westinghouse Air Brake Technologies (WAB) — Bull / Base / Bear Case P&L Summary | J2: Share price ($): | K2: =Model!$CA$431
B3: Adjusted figures (company definitions: Adjusted EBITDA; adjusted EPS incl. add-back of non-cash amortization) · USD millions · Live panel linked to Model — toggle scenario via Model!CF2. Bull and Bear panels are value snapshots generated from the Model with the switch set to each case. 2026E includes Dellner Couplers from 10-Feb-2026. | J3: As of: | K3: =TODAY()
B5: Scenario: | C5: =Model!$CF$2 | N5: Scenario: | O5: Bull | P5: Snapshot (values) — Model run with switch = Bull | Z5: Scenario: | AA5: Bear | AB5: Snapshot (values) — Model run with switch = Bear
B7: (USDm, except EPS and shares) | C7: 2025A | D7: 2026E | E7: 2027E | F7: 2028E | G7: 2029E | H7: 2030E | I7: 25-'30 CAGR | J7: LT Hist Avg | K7: LT Hist Min | L7: LT Hist Max | N7: (USDm, except EPS and shares) | O7: 2025A | P7: 2026E | Q7: 2027E | R7: 2028E | S7: 2029E | T7: 2030E | U7: 25-'30 CAGR | V7: LT Hist Avg | W7: LT Hist Min | X7: LT Hist Max | Z7: (USDm, except EPS and shares) | AA7: 2025A | AB7: 2026E | AC7: 2027E | AD7: 2028E | AE7: 2029E | AF7: 2030E | AG7: 25-'30 CAGR | AH7: LT Hist Avg | AI7: LT Hist Min | AJ7: LT Hist Max
B9: Net Sales | C9: =Model!BV142 | D9: =Model!CA142 | E9: =Model!CB142 | F9: =Model!CC142 | G9: =Model!CD142 | H9: =Model!CE142 | I9: =IFERROR((H9/C9)^(1/5)-1,"n/m") | N9: Net Sales | O9: 11167 | P9: 12600 | Q9: 13748.765 | R9: 15168.395 | S9: 16620.599 | T9: 18174.291 | U9: 0.10231113 | Z9: Net Sales | AA9: 11167 | AB9: 12300 | AC9: 12634.634 | AD9: 13012.09 | AE9: 13340.55 | AF9: 13681.272 | AG9: 0.041448956
B10: Net sales y/y % | D10: =IFERROR(D9/C9-1,"") | E10: =IFERROR(E9/D9-1,"") | F10: =IFERROR(F9/E9-1,"") | G10: =IFERROR(G9/F9-1,"") | H10: =IFERROR(H9/G9-1,"") | N10: Net sales y/y % | P10: 0.12832453 | Q10: 0.091171793 | R10: 0.10325514 | S10: 0.095738795 | T10: 0.093479884 | Z10: Net sales y/y % | AB10: 0.10145966 | AC10: 0.027206041 | AD10: 0.029874692 | AE10: 0.025242668 | AF10: 0.025540291
B11: Organic sales growth % | C11: =Model!BV241 | D11: =Model!CA241 | E11: =Model!CB241 | F11: =Model!CC241 | G11: =Model!CD241 | H11: =Model!CE241 | N11: Organic sales growth % | O11: 0.044671224 | P11: 0.059908659 | Q11: 0.076999457 | R11: 0.075720195 | S11: 0.069283412 | T11: 0.067887373 | Z11: Organic sales growth % | AA11: 0.044671224 | AB11: 0.03304379 | AC11: 0.02430244 | AD11: 0.023882093 | AE11: 0.019074778 | AF11: 0.019163299
B12: Adjusted EBITDA | C12: =Model!BV194 | D12: =Model!CA194 | E12: =Model!CB194 | F12: =Model!CC194 | G12: =Model!CD194 | H12: =Model!CE194 | I12: =IFERROR((H12/C12)^(1/5)-1,"n/m") | N12: Adjusted EBITDA | O12: 2464 | P12: 2944.2271 | Q12: 3437.3406 | R12: 3854.9365 | S12: 4290.5795 | T12: 4762.7654 | U12: 0.1408898 | Z12: Adjusted EBITDA | AA12: 2464 | AB12: 2875.7214 | AC12: 2846.3296 | AD12: 2994.673 | AE12: 3134.3355 | AF12: 3279.3289 | AG12: 0.05883638
B13: Adjusted EBITDA margin % | C13: =IFERROR(C12/C9,"") | D13: =IFERROR(D12/D9,"") | E13: =IFERROR(E12/E9,"") | F13: =IFERROR(F12/F9,"") | G13: =IFERROR(G12/G9,"") | H13: =IFERROR(H12/H9,"") | J13: =IFERROR(AVERAGE(Model!C195,Model!D195,Model!E195,Model!F195,Model!G195,Model!H195,Model!I195,Model!N195,Model!S195,Model!X195,Model!AC195,Model!AH195,Model!AM195,Model!AR195,Model!AW195,Model!BB195,Model!BG195,Model!BL195,Model!BQ195,Model!BV195),"") | K13: =IFERROR(MIN(Model!C195,Model!D195,Model!E195,Model!F195,Model!G195,Model!H195,Model!I195,Model!N195,Model!S195,Model!X195,Model!AC195,Model!AH195,Model!AM195,Model!AR195,Model!AW195,Model!BB195,Model!BG195,Model!BL195,Model!BQ195,Model!BV195),"") | L13: =IFERROR(MAX(Model!C195,Model!D195,Model!E195,Model!F195,Model!G195,Model!H195,Model!I195,Model!N195,Model!S195,Model!X195,Model!AC195,Model!AH195,Model!AM195,Model!AR195,Model!AW195,Model!BB195,Model!BG195,Model!BL195,Model!BQ195,Model!BV195),"") | N13: Adjusted EBITDA margin % | O13: 0.22065013 | P13: 0.23366882 | Q13: 0.25001087 | R13: 0.25414267 | S13: 0.25814831 | T13: 0.26206059 | V13: 0.19446972 | W13: 0.1769299 | X13: 0.22065013 | Z13: Adjusted EBITDA margin % | AA13: 0.22065013 | AB13: 0.23379849 | AC13: 0.22527994 | AD13: 0.23014542 | AE13: 0.234948 | AF13: 0.23969475 | AH13: 0.19446972 | AI13: 0.1769299 | AJ13: 0.22065013
B15: Income from Operations (GAAP) | C15: =Model!BV150 | D15: =Model!CA150 | E15: =Model!CB150 | F15: =Model!CC150 | G15: =Model!CD150 | H15: =Model!CE150 | I15: =IFERROR((H15/C15)^(1/5)-1,"n/m") | N15: Income from Operations (GAAP) | O15: 1793 | P15: 2296.5913 | Q15: 2809.9027 | R15: 3176.908 | S15: 3561.4229 | T15: 3991.8062 | U15: 0.17359387 | Z15: Income from Operations (GAAP) | AA15: 1793 | AB15: 2233.0293 | AC15: 2248.9415 | AD15: 2387.2235 | AE15: 2517.6331 | AF15: 2664.1713 | AG15: 0.0824214
B16: Income from operations y/y % | D16: =IFERROR(D15/C15-1,"") | E16: =IFERROR(E15/D15-1,"") | F16: =IFERROR(F15/E15-1,"") | G16: =IFERROR(G15/F15-1,"") | H16: =IFERROR(H15/G15-1,"") | N16: Income from operations y/y % | P16: 0.2808652 | Q16: 0.22351012 | R16: 0.13061139 | S16: 0.12103433 | T16: 0.12084589 | Z16: Income from operations y/y % | AB16: 0.24541513 | AC16: 0.0071258142 | AD16: 0.061487599 | AE16: 0.054628165 | AF16: 0.05820472
B17: Operating margin (GAAP) % | C17: =IFERROR(C15/C9,"") | D17: =IFERROR(D15/D9,"") | E17: =IFERROR(E15/E9,"") | F17: =IFERROR(F15/F9,"") | G17: =IFERROR(G15/G9,"") | H17: =IFERROR(H15/H9,"") | J17: =IFERROR(AVERAGE(Model!C253,Model!D253,Model!E253,Model!F253,Model!G253,Model!H253,Model!I253,Model!N253,Model!S253,Model!X253,Model!AC253,Model!AH253,Model!AM253,Model!AR253,Model!AW253,Model!BB253,Model!BG253,Model!BL253,Model!BQ253,Model!BV253),"") | K17: =IFERROR(MIN(Model!C253,Model!D253,Model!E253,Model!F253,Model!G253,Model!H253,Model!I253,Model!N253,Model!S253,Model!X253,Model!AC253,Model!AH253,Model!AM253,Model!AR253,Model!AW253,Model!BB253,Model!BG253,Model!BL253,Model!BQ253,Model!BV253),"") | L17: =IFERROR(MAX(Model!C253,Model!D253,Model!E253,Model!F253,Model!G253,Model!H253,Model!I253,Model!N253,Model!S253,Model!X253,Model!AC253,Model!AH253,Model!AM253,Model!AR253,Model!AW253,Model!BB253,Model!BG253,Model!BL253,Model!BQ253,Model!BV253),"") | N17: Operating margin (GAAP) % | O17: 0.16056237 | P17: 0.18226915 | Q17: 0.20437492 | R17: 0.20944259 | S17: 0.21427765 | T17: 0.21964028 | V17: 0.13551085 | W17: 0.080865854 | X17: 0.18364571 | Z17: Operating margin (GAAP) % | AA17: 0.16056237 | AB17: 0.1815471 | AC17: 0.17799815 | AD17: 0.18346196 | AE17: 0.18872034 | AF17: 0.19473126 | AH17: 0.13551085 | AI17: 0.080865854 | AJ17: 0.18364571
B19: Adjusted Net Income (attributable to Wabtec) | C19: =Model!BV229 | D19: =Model!CA229 | E19: =Model!CB229 | F19: =Model!CC229 | G19: =Model!CD229 | H19: =Model!CE229 | I19: =IFERROR((H19/C19)^(1/5)-1,"n/m") | N19: Adjusted Net Income (attributable to Wabtec) | O19: 1537 | P19: 1846.7714 | Q19: 2226.548 | R19: 2488.2882 | S19: 2765.9242 | T19: 3072.9904 | U19: 0.14862289 | Z19: Adjusted Net Income (attributable to Wabtec) | AA19: 1537 | AB19: 1798.7821 | AC19: 1801.4129 | AD19: 1923.1879 | AE19: 2013.3865 | AF19: 2111.7984 | AG19: 0.065603699
B21: FDSO (m) | C21: =Model!BV168 | D21: =Model!CA168 | E21: =Model!CB168 | F21: =Model!CC168 | G21: =Model!CD168 | H21: =Model!CE168 | I21: =IFERROR((H21/C21)^(1/5)-1,"n/m") | N21: FDSO (m) | O21: 171.1 | P21: 169.42857 | Q21: 165.74154 | R21: 161.1977 | S21: 156.58483 | T21: 151.40998 | U21: -0.024154866 | Z21: FDSO (m) | AA21: 171.1 | AB21: 169.69643 | AC21: 169.38389 | AD21: 167.39055 | AE21: 163.07475 | AF21: 158.8794 | AG21: -0.014711266
B23: Adjusted EPS — Diluted ($) | C23: =Model!BV232 | D23: =Model!CA232 | E23: =Model!CB232 | F23: =Model!CC232 | G23: =Model!CD232 | H23: =Model!CE232 | I23: =IFERROR((H23/C23)^(1/5)-1,"n/m") | N23: Adjusted EPS — Diluted ($) | O23: 8.9830508 | P23: 10.9 | Q23: 13.433856 | R23: 15.436251 | S23: 17.664063 | T23: 20.295824 | U23: 0.17705448 | Z23: Adjusted EPS — Diluted ($) | AA23: 8.9830508 | AB23: 10.6 | AC23: 10.63509 | AD23: 11.489226 | AE23: 12.346403 | AF23: 13.291833 | AG23: 0.081514141
B24: EPS y/y % | D24: =IFERROR(D23/C23-1,"") | E24: =IFERROR(E23/D23-1,"") | F24: =IFERROR(F23/E23-1,"") | G24: =IFERROR(G23/F23-1,"") | H24: =IFERROR(H23/G23-1,"") | N24: EPS y/y % | P24: 0.21339623 | Q24: 0.23246388 | R24: 0.14905587 | S24: 0.14432333 | T24: 0.14898959 | Z24: EPS y/y % | AB24: 0.18 | AC24: 0.0033103417 | AD24: 0.080313053 | AE24: 0.074607014 | AF24: 0.076575325
B26: P / E (x) — assumed (adjusted EPS) | G26: 23 | H26: 23 | N26: P / E (x) — assumed (adjusted EPS) | S26: 27 | T26: 27 | Z26: P / E (x) — assumed (adjusted EPS) | AD26: 18 | AE26: 18 | AF26: 18
B27: Price Target ($) | G27: =G26*G23 | H27: =H26*H23 | N27: Price Target ($) | S27: =S26*S23 | T27: =T26*T23 | Z27: Price Target ($) | AD27: =AD26*AD23 | AE27: =AE26*AE23 | AF27: =AF26*AF23
B28: Upside / (Downside) vs current | G28: =IFERROR(G27/$K$2-1,"") | H28: =IFERROR(H27/$K$2-1,"") | N28: Upside / (Downside) vs current | S28: =IFERROR(S27/$K$2-1,"") | T28: =IFERROR(T27/$K$2-1,"") | Z28: Upside / (Downside) vs current | AD28: =IFERROR(AD27/$K$2-1,"") | AE28: =IFERROR(AE27/$K$2-1,"") | AF28: =IFERROR(AF27/$K$2-1,"")
B29: IRR (to Dec-Y-1) | G29: =IFERROR((G27/$K$2)^(1/((DATE(2029-1,12,31)-$K$3)/365.25))-1,"") | H29: =IFERROR((H27/$K$2)^(1/((DATE(2030-1,12,31)-$K$3)/365.25))-1,"") | N29: IRR (to Dec-Y-1) | S29: =IFERROR((S27/$K$2)^(1/((DATE(2029-1,12,31)-$K$3)/365.25))-1,"") | T29: =IFERROR((T27/$K$2)^(1/((DATE(2030-1,12,31)-$K$3)/365.25))-1,"") | Z29: IRR (to Dec-Y-1) | AD29: =IFERROR((AD27/$K$2)^(1/((DATE(2028-1,12,31)-$K$3)/365.25))-1,"") | AE29: =IFERROR((AE27/$K$2)^(1/((DATE(2029-1,12,31)-$K$3)/365.25))-1,"") | AF29: =IFERROR((AF27/$K$2)^(1/((DATE(2030-1,12,31)-$K$3)/365.25))-1,"")
B31: Free Cash Flow | C31: =Model!BV285 | D31: =Model!CA285 | E31: =Model!CB285 | F31: =Model!CC285 | G31: =Model!CD285 | H31: =Model!CE285 | I31: =IFERROR((H31/C31)^(1/5)-1,"n/m") | N31: Free Cash Flow | O31: 1499 | P31: 1954.4584 | Q31: 2191.6393 | R31: 2396.7116 | S31: 2684.5449 | T31: 2989.6766 | U31: 0.14805982 | Z31: Free Cash Flow | AA31: 1499 | AB31: 1944.2536 | AC31: 1820.5997 | AD31: 1964.8352 | AE31: 2065.2929 | AF31: 2162.0908 | AG31: 0.076005422
B32: FCF % | C32: =IFERROR(C31/C9,"") | D32: =IFERROR(D31/D9,"") | E32: =IFERROR(E31/E9,"") | F32: =IFERROR(F31/F9,"") | G32: =IFERROR(G31/G9,"") | H32: =IFERROR(H31/H9,"") | J32: =IFERROR(AVERAGE(Model!C287,Model!D287,Model!E287,Model!F287,Model!G287,Model!H287,Model!I287,Model!N287,Model!S287,Model!X287,Model!AC287,Model!AH287,Model!AM287,Model!AR287,Model!AW287,Model!BB287,Model!BG287,Model!BL287,Model!BQ287,Model!BV287),"") | K32: =IFERROR(MIN(Model!C287,Model!D287,Model!E287,Model!F287,Model!G287,Model!H287,Model!I287,Model!N287,Model!S287,Model!X287,Model!AC287,Model!AH287,Model!AM287,Model!AR287,Model!AW287,Model!BB287,Model!BG287,Model!BL287,Model!BQ287,Model!BV287),"") | L32: =IFERROR(MAX(Model!C287,Model!D287,Model!E287,Model!F287,Model!G287,Model!H287,Model!I287,Model!N287,Model!S287,Model!X287,Model!AC287,Model!AH287,Model!AM287,Model!AR287,Model!AW287,Model!BB287,Model!BG287,Model!BL287,Model!BQ287,Model!BV287),"") | N32: FCF % | O32: 0.1342348 | P32: 0.15511575 | Q32: 0.15940627 | R32: 0.15800694 | S32: 0.16151914 | T32: 0.16450032 | V32: 0.10258846 | W32: 0.025580916 | X32: 0.15663811 | Z32: FCF % | AA32: 0.1342348 | AB32: 0.1580694 | AC32: 0.14409595 | AD32: 0.15100074 | AE32: 0.15481317 | AF32: 0.15803289 | AH32: 0.10258846 | AI32: 0.025580916 | AJ32: 0.15663811
B33: FCF / share ($) | C33: =IFERROR(C31/C21,"") | D33: =IFERROR(D31/D21,"") | E33: =IFERROR(E31/E21,"") | F33: =IFERROR(F31/F21,"") | G33: =IFERROR(G31/G21,"") | H33: =IFERROR(H31/H21,"") | N33: FCF / share ($) | O33: 8.7609585 | P33: 11.535589 | Q33: 13.223235 | R33: 14.868151 | S33: 17.144348 | T33: 19.745571 | Z33: FCF / share ($) | AA33: 8.7609585 | AB33: 11.457245 | AC33: 10.748364 | AD33: 11.738029 | AE33: 12.664701 | AF33: 13.608377
B34: FCF Yield (on PT) | F34: =IFERROR(F33/F$27,"") | G34: =IFERROR(G33/G$27,"") | H34: =IFERROR(H33/H$27,"") | N34: FCF Yield (on PT) | R34: =IFERROR(R33/R$27,"") | S34: =IFERROR(S33/S$27,"") | T34: =IFERROR(T33/T$27,"") | Z34: FCF Yield (on PT) | AD34: =IFERROR(AD33/AD$27,"") | AE34: =IFERROR(AE33/AE$27,"") | AF34: =IFERROR(AF33/AF$27,"")
B35: Adjusted EBITDA (leverage basis) | C35: =Model!BV194 | D35: =Model!CA194 | E35: =Model!CB194 | F35: =Model!CC194 | G35: =Model!CD194 | H35: =Model!CE194 | I35: =IFERROR((H35/C35)^(1/5)-1,"n/m") | N35: Adjusted EBITDA (leverage basis) | O35: 2464 | P35: 2944.2271 | Q35: 3437.3406 | R35: 3854.9365 | S35: 4290.5795 | T35: 4762.7654 | U35: 0.1408898 | Z35: Adjusted EBITDA (leverage basis) | AA35: 2464 | AB35: 2875.7214 | AC35: 2846.3296 | AD35: 2994.673 | AE35: 3134.3355 | AF35: 3279.3289 | AG35: 0.05883638
B36: Adjusted EBITDA % of net sales | C36: =IFERROR(C35/C9,"") | D36: =IFERROR(D35/D9,"") | E36: =IFERROR(E35/E9,"") | F36: =IFERROR(F35/F9,"") | G36: =IFERROR(G35/G9,"") | H36: =IFERROR(H35/H9,"") | J36: =IFERROR(AVERAGE(Model!C251,Model!D251,Model!E251,Model!F251,Model!G251,Model!H251,Model!I251,Model!N251,Model!S251,Model!X251,Model!AC251,Model!AH251,Model!AM251,Model!AR251,Model!AW251,Model!BB251,Model!BG251,Model!BL251,Model!BQ251,Model!BV251),"") | K36: =IFERROR(MIN(Model!C251,Model!D251,Model!E251,Model!F251,Model!G251,Model!H251,Model!I251,Model!N251,Model!S251,Model!X251,Model!AC251,Model!AH251,Model!AM251,Model!AR251,Model!AW251,Model!BB251,Model!BG251,Model!BL251,Model!BQ251,Model!BV251),"") | L36: =IFERROR(MAX(Model!C251,Model!D251,Model!E251,Model!F251,Model!G251,Model!H251,Model!I251,Model!N251,Model!S251,Model!X251,Model!AC251,Model!AH251,Model!AM251,Model!AR251,Model!AW251,Model!BB251,Model!BG251,Model!BL251,Model!BQ251,Model!BV251),"") | N36: Adjusted EBITDA % of net sales | O36: 0.22065013 | P36: 0.23366882 | Q36: 0.25001087 | R36: 0.25414267 | S36: 0.25814831 | T36: 0.26206059 | V36: 0.19446972 | W36: 0.1769299 | X36: 0.22065013 | Z36: Adjusted EBITDA % of net sales | AA36: 0.22065013 | AB36: 0.23379849 | AC36: 0.22527994 | AD36: 0.23014542 | AE36: 0.234948 | AF36: 0.23969475 | AH36: 0.19446972 | AI36: 0.1769299 | AJ36: 0.22065013
B38: Net Debt | C38: =Model!BV426 | D38: =Model!CA426 | E38: =Model!CB426 | F38: =Model!CC426 | G38: =Model!CD426 | H38: =Model!CE426 | N38: Net Debt | O38: 4752 | P38: 5082.83 | Q38: 6015.3461 | R38: 6746.1389 | S38: 7508.5141 | T38: 8334.8394 | Z38: Net Debt | AA38: 4752 | AB38: 4793.367 | AC38: 3557.912 | AD38: 3743.3412 | AE38: 3917.9194 | AF38: 4099.1611
B39: Net Debt / Adjusted EBITDA (x) | C39: =IFERROR(C38/C35,"") | D39: =IFERROR(D38/D35,"") | E39: =IFERROR(E38/E35,"") | F39: =IFERROR(F38/F35,"") | G39: =IFERROR(G38/G35,"") | H39: =IFERROR(H38/H35,"") | N39: Net Debt / Adjusted EBITDA (x) | O39: 1.9285714 | P39: 1.7263716 | Q39: 1.75 | R39: 1.75 | S39: 1.75 | T39: 1.75 | Z39: Net Debt / Adjusted EBITDA (x) | AA39: 1.9285714 | AB39: 1.6668398 | AC39: 1.25 | AD39: 1.25 | AE39: 1.25 | AF39: 1.25
B41: ROIC | C41: =Model!BV409 | D41: =Model!CA409 | E41: =Model!CB409 | F41: =Model!CC409 | G41: =Model!CD409 | H41: =Model!CE409 | J41: =IFERROR(AVERAGE(Model!C409,Model!D409,Model!E409,Model!F409,Model!G409,Model!H409,Model!I409,Model!N409,Model!S409,Model!X409,Model!AC409,Model!AH409,Model!AM409,Model!AR409,Model!AW409,Model!BB409,Model!BG409,Model!BL409,Model!BQ409,Model!BV409),"") | K41: =IFERROR(MIN(Model!C409,Model!D409,Model!E409,Model!F409,Model!G409,Model!H409,Model!I409,Model!N409,Model!S409,Model!X409,Model!AC409,Model!AH409,Model!AM409,Model!AR409,Model!AW409,Model!BB409,Model!BG409,Model!BL409,Model!BQ409,Model!BV409),"") | L41: =IFERROR(MAX(Model!C409,Model!D409,Model!E409,Model!F409,Model!G409,Model!H409,Model!I409,Model!N409,Model!S409,Model!X409,Model!AC409,Model!AH409,Model!AM409,Model!AR409,Model!AW409,Model!BB409,Model!BG409,Model!BL409,Model!BQ409,Model!BV409),"") | N41: ROIC | O41: 0.091825881 | P41: 0.10943943 | Q41: 0.12147935 | R41: 0.12876988 | S41: 0.13601087 | T41: 0.14410167 | V41: 0.12316765 | W41: 0.04674643 | X41: 0.2098046 | Z41: ROIC | AA41: 0.091825881 | AB41: 0.10680366 | AC41: 0.10392801 | AD41: 0.11004491 | AE41: 0.11585647 | AF41: 0.12231639 | AH41: 0.12316765 | AI41: 0.04674643 | AJ41: 0.2098046
B42: RONTA | C42: =Model!BV420 | D42: =Model!CA420 | E42: =Model!CB420 | F42: =Model!CC420 | G42: =Model!CD420 | H42: =Model!CE420 | J42: =IFERROR(AVERAGE(Model!C420,Model!D420,Model!E420,Model!F420,Model!G420,Model!H420,Model!I420,Model!N420,Model!S420,Model!X420,Model!AC420,Model!AH420,Model!AM420,Model!AR420,Model!AW420,Model!BB420,Model!BG420,Model!BL420,Model!BQ420,Model!BV420),"") | K42: =IFERROR(MIN(Model!C420,Model!D420,Model!E420,Model!F420,Model!G420,Model!H420,Model!I420,Model!N420,Model!S420,Model!X420,Model!AC420,Model!AH420,Model!AM420,Model!AR420,Model!AW420,Model!BB420,Model!BG420,Model!BL420,Model!BQ420,Model!BV420),"") | L42: =IFERROR(MAX(Model!C420,Model!D420,Model!E420,Model!F420,Model!G420,Model!H420,Model!I420,Model!N420,Model!S420,Model!X420,Model!AC420,Model!AH420,Model!AM420,Model!AR420,Model!AW420,Model!BB420,Model!BG420,Model!BL420,Model!BQ420,Model!BV420),"") | N42: RONTA | O42: 0.3557444 | P42: 0.43275229 | Q42: 0.48077661 | R42: 0.50337256 | S42: 0.52464166 | T42: 0.54760299 | V42: 0.23875302 | W42: 0.10751575 | X42: 0.3557444 | Z42: RONTA | AA42: 0.3557444 | AB42: 0.4115263 | AC42: 0.30460099 | AD42: 0.32738441 | AE42: 0.34943777 | AF42: 0.37458158 | AH42: 0.23875302 | AI42: 0.10751575 | AJ42: 0.3557444
B44: Implied Market Cap (USDm) | F44: =F27*F21 | G44: =G27*G21 | H44: =H27*H21 | N44: Implied Market Cap (USDm) | R44: =R27*R21 | S44: =S27*S21 | T44: =T27*T21 | Z44: Implied Market Cap (USDm) | AD44: =AD27*AD21 | AE44: =AE27*AE21 | AF44: =AF27*AF21
B45: (+) Net Debt & NCI | F45: =F38+Model!CC337 | G45: =G38+Model!CD337 | H45: =H38+Model!CE337 | N45: (+) Net Debt & NCI | R45: =R38+Model!CC337 | S45: =S38+Model!CD337 | T45: =T38+Model!CE337 | Z45: (+) Net Debt & NCI | AD45: =AD38+Model!CC337 | AE45: =AE38+Model!CD337 | AF45: =AF38+Model!CE337
B46: Implied Enterprise Value (USDm) | F46: =F44+F45 | G46: =G44+G45 | H46: =H44+H45 | N46: Implied Enterprise Value (USDm) | R46: =R44+R45 | S46: =S44+S45 | T46: =T44+T45 | Z46: Implied Enterprise Value (USDm) | AD46: =AD44+AD45 | AE46: =AE44+AE45 | AF46: =AF44+AF45
B47: Implied EV / Adjusted EBITDA (x) | F47: =IFERROR(F46/F35,"") | G47: =IFERROR(G46/G35,"") | H47: =IFERROR(H46/H35,"") | N47: Implied EV / Adjusted EBITDA (x) | R47: =IFERROR(R46/R35,"") | S47: =IFERROR(S46/S35,"") | T47: =IFERROR(T46/T35,"") | Z47: Implied EV / Adjusted EBITDA (x) | AD47: =IFERROR(AD46/AD35,"") | AE47: =IFERROR(AE46/AE35,"") | AF47: =IFERROR(AF46/AF35,"")

Sheet DCF
B2: DCF VALUATION — WESTINGHOUSE AIR BRAKE TECHNOLOGIES (WAB)
B4: 1. WACC BUILD
B5: Risk-free rate (US 10Y govt) | C5: 0.055 | D5: Assumption (~US 10Y Treasury yield); update to market
B6: Equity risk premium | C6: 0.05 | D6: US implied ERP ~4.5–5.5% (Damodaran)
B7: Levered beta | C7: 1.05 | D7: Rail equipment / transportation-technology peers (Knorr-Bremse, Alstom, Siemens Mobility, Trinity, Greenbrier) ~0.9–1.2; 25,000+ locomotive installed base and multi-year backlog ($30.9bn) dampen cyclicality
B8: Cost of equity | C8: =C5+C7*C6
B9: Pre-tax cost of debt | C9: 0.055 | D9: Investment grade (BBB / Baa2); 5.50% 2035 and 4.90% 2030 notes issued 2025; marginal cost ~5.0–5.5%
B10: Tax rate | C10: 0.245 | D10: Model 2027E+ effective tax rate (FY26 guidance ~24.5%)
B11: After-tax cost of debt | C11: =C9*(1-C10)
B12: Target D/V | C12: 0.15 | D12: Net debt ~$5.9bn at 30-Jun-26 vs ~$47bn market cap ($280 × ~169m shares); ~2.0x Adjusted EBITDA, targeted 2.0–2.5x
B13: WACC | C13: =C8*(1-C12)+C11*C12
B15: Valuation date (live) | C15: =TODAY() | D15: Periods = (Dec-31-Year − today) / 365.25; cash flows assumed at year-end
B16: 2. UNLEVERED FREE CASH FLOW BUILD (USDm)
D17: 2026E | E17: 2027E | F17: 2028E | G17: 2029E | H17: 2030E | I17: 2031E | J17: 2032E | K17: 2033E | L17: 2034E | M17: 2035E | N17: Terminal | P17: CAGR 26–30E | Q17: CAGR 26–35E
B18: Adjusted EBIT (Model; Adjusted EBITDA − DD&A) | D18: =Model!CA201 | E18: =Model!CB201 | F18: =Model!CC201 | G18: =Model!CD201 | H18: =Model!CE201 | I18: =H18*(1+I$31) | J18: =I18*(1+J$31) | K18: =J18*(1+K$31) | L18: =K18*(1+L$31) | M18: =L18*(1+M$31) | P18: =IFERROR(($H18/$D18)^(1/(VALUE(LEFT($H$17,4))-VALUE(LEFT($D$17,4))))-1,"n/m") | Q18: =IFERROR(($M18/$D18)^(1/(VALUE(LEFT($M$17,4))-VALUE(LEFT($D$17,4))))-1,"n/m")
B19: y/y % | E19: =IFERROR(E18/D18-1,"") | F19: =IFERROR(F18/E18-1,"") | G19: =IFERROR(G18/F18-1,"") | H19: =IFERROR(H18/G18-1,"") | I19: =IFERROR(I18/H18-1,"") | J19: =IFERROR(J18/I18-1,"") | K19: =IFERROR(K18/J18-1,"") | L19: =IFERROR(L18/K18-1,"") | M19: =IFERROR(M18/L18-1,"")
B20: (−) Restructuring & transaction costs (cash; added back in Adjusted EBITDA) | D20: =-Model!CA208 | E20: =-Model!CB208 | F20: =-Model!CC208 | G20: =-Model!CD208 | H20: =-Model!CE208 | I20: =H20*(1+I$31) | J20: =I20*(1+J$31) | K20: =J20*(1+K$31) | L20: =K20*(1+L$31) | M20: =L20*(1+M$31)
B21: × (1 − tax rate) | D21: =1-$C$10 | E21: =1-$C$10 | F21: =1-$C$10 | G21: =1-$C$10 | H21: =1-$C$10 | I21: =1-$C$10 | J21: =1-$C$10 | K21: =1-$C$10 | ... M21: =1-$C$10
B22: NOPAT = (Adjusted EBIT − restructuring & transaction costs) × (1 − t) | D22: =(D18+D20)*D21 | E22: =(E18+E20)*E21 | F22: =(F18+F20)*F21 | G22: =(G18+G20)*G21 | H22: =(H18+H20)*H21 | I22: =(I18+I20)*I21 | J22: =(J18+J20)*J21 | K22: =(K18+K20)*K21 | ... M22: =(M18+M20)*M21
B23: plus depreciation & amortization (total, incl. acquired-intangible amortization) | D23: =Model!CA164 | E23: =Model!CB164 | F23: =Model!CC164 | G23: =Model!CD164 | H23: =Model!CE164 | I23: =H23*(1+I$31) | J23: =I23*(1+J$31) | K23: =J23*(1+K$31) | L23: =K23*(1+L$31) | M23: =L23*(1+M$31)
B24: − Capex (PP&E) and acquisitions (M&A lever, 2027E+) | D24: =D29 | E24: =E29+Model!CB268 | F24: =F29+Model!CC268 | G24: =G29+Model!CD268 | H24: =H29+Model!CE268 | I24: =I29 | J24: =J29 | K24: =K29 | L24: =L29 | M24: =M29
B25: − Δ Working capital (CF statement) | D25: =Model!CA265 | E25: =Model!CB265 | F25: =Model!CC265 | G25: =Model!CD265 | H25: =Model!CE265 | I25: =H25*(1+I$31) | J25: =I25*(1+J$31) | K25: =J25*(1+K$31) | L25: =K25*(1+L$31) | M25: =L25*(1+M$31)
