Workbook

Sheet Model
CF1: SCENARIO SWITCH ▼ (Bull / Base / Bear) — drives all scenario-linked forecast drivers
B2: Waste Connections, Inc. (NYSE / TSX: WCN) — 3-Statement Financial Model | CF2: Base
B3: US GAAP as reported · USD millions (per-share data in USD, restated to the current share basis; shares in millions) · Source: Waste Connections Forms 10-K / 10-Q (financial statements, MD&A revenue bridges, segment and debt notes) and Form 8-K earnings releases (Ex. 99.1 non-GAAP reconciliations, revenue breakdown, internal growth, outlook) on SEC EDGAR — legacy Waste Connections, Inc. (Delaware) CIK 0001057058 to Q1/16; Waste Connections, Inc. (Ontario) CIK 0001318220 from Q2/16 (investor-relations releases are the same documents as filed on EDGAR)
B4: Basis notes: calendar fiscal year. Old Waste Connections was the accounting acquirer in the 1-Jun-2016 Progressive Waste merger (WCN re-domiciled to Ontario; Canada segment from Q2/16; net 1:1 share exchange) — pre-merger periods are legacy WCN (US only). 3-for-2 share splits Mar-2007, Nov-2010 and Jun-2017: all share counts / per-share data restated to the current basis (factor row). Service-line revenues are gross of intercompany eliminations; recycling and intermodal / other reported combined to 2011; E&P separate from FY2012 (R360, Oct-2012). Q4 = FY − 9M where only annual figures are disclosed. Adjusted EBITDA / adjusted EPS / adjusted FCF per the company definition in force in each period (definition rows). FY26 outlook per the Q2-26 release (22-Jul-2026); Q3/26E onward are model estimates.
CH5: Forecast | CI5: Historical | CJ5: Historical | CK5: Historical
B6: (USDm) | C6: 2006 | D6: 2007 | E6: 2008 | F6: 2009 | G6: 2010 | H6: 2011 | I6: 2012 | J6: Q1/13 | K6: Q2/13 | L6: Q3/13 | M6: Q4/13 | N6: 2013 | O6: Q1/14 | P6: Q2/14 | Q6: Q3/14 | R6: Q4/14 | S6: 2014 | T6: Q1/15 | U6: Q2/15 | V6: Q3/15 | W6: Q4/15 | X6: 2015 | Y6: Q1/16 | Z6: Q2/16 | AA6: Q3/16 | AB6: Q4/16 | AC6: 2016 | AD6: Q1/17 | AE6: Q2/17 | AF6: Q3/17 | AG6: Q4/17 | AH6: 2017 | AI6: Q1/18 | AJ6: Q2/18 | AK6: Q3/18 | AL6: Q4/18 | AM6: 2018 | AN6: Q1/19 | AO6: Q2/19 | AP6: Q3/19 | AQ6: Q4/19 | AR6: 2019 | AS6: Q1/20 | AT6: Q2/20 | AU6: Q3/20 | AV6: Q4/20 | AW6: 2020 | AX6: Q1/21 | AY6: Q2/21 | AZ6: Q3/21 | BA6: Q4/21 | BB6: 2021 | BC6: Q1/22 | BD6: Q2/22 | BE6: Q3/22 | BF6: Q4/22 | BG6: 2022 | BH6: Q1/23 | BI6: Q2/23 | BJ6: Q3/23 | BK6: Q4/23 | BL6: 2023 | BM6: Q1/24 | BN6: Q2/24 | BO6: Q3/24 | BP6: Q4/24 | BQ6: 2024 | BR6: Q1/25 | BS6: Q2/25 | BT6: Q3/25 | BU6: Q4/25 | BV6: 2025 | BW6: Q1/26 | BX6: Q2/26 | BY6: Q3/26E | BZ6: Q4/26E | CA6: 2026E | CB6: 2027E | CC6: 2028E | CD6: 2029E | CE6: 2030E | CF6: Modelling Notes | CH6: 5Y CAGR | CI6: 5Y CAGR | CJ6: 10Y CAGR | CK6: 19Y CAGR
CH7: 25-'30 | CI7: 20-'25 | CJ7: 15-'25 | CK7: 06-'25
B8: SERVICE-LINE REVENUE BUILD — SOLID WASTE (collection · landfill & transfer · recycling) · E&P WASTE · INTERMODAL & OTHER (price × volume internal-growth build) | CF8: SERVICE-LINE BUILD — modelling logic (prior-year revenues × (1 + price + volume + recycled commodities + acquisitions) → revenues → cost of operations → Adjusted EBITDA)
CN9: SCENARIO INPUT TABLE — driver assumptions per Bull / Base / Bear | CO9: Bull | CP9: Base | CQ9: Bear | CR9: Bull / Bear = Base + Δ (Δ inputs on each block header). Outlook block = high / mid / low end of the FY26 outlook ranges.
B10: Solid waste — collection, disposal & transfer, recycling (gross revenues before intercompany eliminations) | CF10: SOLID WASTE — modelling logic
B11: Collection revenues (commercial + residential + industrial & construction roll-off) | C11: 602.762 | D11: 693.675 | E11: 787.713 | F11: 901.768 | G11: 951.327 | H11: 1069.065 | I11: 1176.333 | J11: 293.144 | K11: 306.472 | L11: 312.872 | M11: 306.603 | N11: 1219.091 | O11: 306.003 | P11: 322.763 | Q11: 333.917 | R11: 327.224 | S11: 1289.906 | T11: 327.005 | U11: 342.583 | V11: 354.49 | W11: 354.601 | X11: 1378.679 | Y11: 356.598 | Z11: 502.948 | AA11: 760.281 | AB11: 739.986 | AC11: 2359.813 | AD11: 768.346 | AE11: 797.131 | AF11: 815.344 | AG11: 800.625 | AH11: 3181.447 | AI11: 809.646 | AJ11: 854.719 | AK11: 871.7 | AL11: 874.601 | AM11: 3410.666 | AN11: 891.353 | AO11: 958.124 | AP11: 990.79 | AQ11: 974.886 | AR11: 3815.153 | AS11: 989.009 | AT11: 948.072 | AU11: 1010.497 | AV11: 1024.099 | AW11: 3971.678 | AX11: 1036.472 | AY11: 1098.319 | AZ11: 1137.206 | BA11: 1169.428 | BB11: 4441.426 | BC11: 1199.452 | BD11: 1297.402 | BE11: 1368.491 | BF11: 1385.682 | BG11: 5251.027 | BH11: 1434.647 | BI11: 1485.705 | BJ11: 1512.745 | BK11: 1501.882 | BL11: 5934.979 | BM11: 1515.06 | BN11: 1583.098 | BO11: 1622.308 | BP11: 1612.307 | BQ11: 6332.773 | BR11: 1621.077 | BS11: 1690.785 | BT11: 1730.339 | BU11: 1705.896 | BV11: 6748.096 | BW11: 1709.628 | BX11: 1789.235 | BY11: =BT11*(1+BY20) -> 1802.8064 | BZ11: =BU11*(1+BZ20) -> 1777.3397 | CA11: =SUM(BW11,BX11,BY11,BZ11) -> 7079.0091 | CB11: =CA11*(1+CB20) -> 7379.8669 | CC11: =CB11*(1+CC20) -> 7711.961 | CD11: =CC11*(1+CD20) -> 8078.2791 | CE11: =CD11*(1+CE20) -> 8441.8017 | CF11: Historical: earnings-release revenue breakdown (quarters; gross of intercompany) and 10-K service-line table (FY). Q3/Q4-26E: prior-year quarter × (1 + solid waste growth below). 2027E+: prior year × (1 + organic internal growth). | CH11: =IFERROR((CE11/BV11)^(1/5)-1,"n/m") -> 0.045805155 | CI11: =IFERROR((BV11/AW11)^(1/5)-1,"n/m") -> 0.11183782 | CJ11: =IFERROR((BV11/X11)^(1/10)-1,"n/m") -> 0.17211928 | CK11: =IFERROR((BV11/C11)^(1/19)-1,"n/m") -> 0.13556602 | CN11: FY26 outlook — Q2-26 release (22-Jul-26, "updated outlook") | CO11: High | CP11: Mid | CQ11: Low | CR11: WCN outlook "assumes no change in the current economic environment" and excludes transaction-related items and acquisitions not yet closed.
B12: Memo: commercial (from Q2/18) | M12: =IF(AND(ISNUMBER(N12),ISNUMBER(J12),ISNUMBER(K12),ISNUMBER(L12)),N12-J12-K12-L12,"") | R12: =IF(AND(ISNUMBER(S12),ISNUMBER(O12),ISNUMBER(P12),ISNUMBER(Q12)),S12-O12-P12-Q12,"") | W12: =IF(AND(ISNUMBER(X12),ISNUMBER(T12),ISNUMBER(U12),ISNUMBER(V12)),X12-T12-U12-V12,"") | AB12: =IF(AND(ISNUMBER(AC12),ISNUMBER(Y12),ISNUMBER(Z12),ISNUMBER(AA12)),AC12-Y12-Z12-AA12,"") | AG12: =IF(AND(ISNUMBER(AH12),ISNUMBER(AD12),ISNUMBER(AE12),ISNUMBER(AF12)),AH12-AD12-AE12-AF12,"") | AJ12: 360.364 | AK12: 369.543 | AL12: =IF(AND(ISNUMBER(AM12),ISNUMBER(AI12),ISNUMBER(AJ12),ISNUMBER(AK12)),AM12-AI12-AJ12-AK12,"") | AM12: 1452.831 | AN12: 381.509 | AO12: 396.641 | AP12: 408.415 | AQ12: =IF(AND(ISNUMBER(AR12),ISNUMBER(AN12),ISNUMBER(AO12),ISNUMBER(AP12)),AR12-AN12-AO12-AP12,"") -> 406.652 | AR12: 1593.217 | AS12: 416.507 | AT12: 375.427 | AU12: 406.037 | AV12: =IF(AND(ISNUMBER(AW12),ISNUMBER(AS12),ISNUMBER(AT12),ISNUMBER(AU12)),AW12-AS12-AT12-AU12,"") -> 412.342 | AW12: 1610.313 | AX12: 426.395 | AY12: 444.044 | AZ12: 465.246 | BA12: =IF(AND(ISNUMBER(BB12),ISNUMBER(AX12),ISNUMBER(AY12),ISNUMBER(AZ12)),BB12-AX12-AY12-AZ12,"") -> 477.741 | BB12: 1813.426 | BC12: 499.676 | BD12: 538.525 | BE12: 564.592 | BF12: =IF(AND(ISNUMBER(BG12),ISNUMBER(BC12),ISNUMBER(BD12),ISNUMBER(BE12)),BG12-BC12-BD12-BE12,"") -> 573.502 | BG12: 2176.295 | BH12: 602.279 | BI12: 615.803 | BJ12: 630.641 | BK12: =IF(AND(ISNUMBER(BL12),ISNUMBER(BH12),ISNUMBER(BI12),ISNUMBER(BJ12)),BL12-BH12-BI12-BJ12,"") -> 628.168 | BL12: 2476.891 | BM12: 642.859 | BN12: 656.926 | BO12: 680.444 | BP12: =IF(AND(ISNUMBER(BQ12),ISNUMBER(BM12),ISNUMBER(BN12),ISNUMBER(BO12)),BQ12-BM12-BN12-BO12,"") -> 690.32 | BQ12: 2670.549 | BR12: 712.46 | BS12: 731.573 | BT12: 750.384 | BU12: =IF(AND(ISNUMBER(BV12),ISNUMBER(BR12),ISNUMBER(BS12),ISNUMBER(BT12)),BV12-BR12-BS12-BT12,"") -> 749.862 | BV12: 2944.279 | BW12: 761.562 | BX12: 784.532 | CF12: 10-Q / 10-K disaggregation note (ASC 606) from Q2/18; Q4 = FY − 9M. | CN12: FY26 revenues ($m) | CO12: 10050 | CP12: 10035 | CQ12: 10020 | CR12: Raised to $10.02–10.05bn in the Q2-26 release (from $9.90–9.95bn, Feb-26). Drives the Q3/Q4-26E revenue calibration.
B13: Memo: residential (from Q2/18) | M13: =IF(AND(ISNUMBER(N13),ISNUMBER(J13),ISNUMBER(K13),ISNUMBER(L13)),N13-J13-K13-L13,"") | R13: =IF(AND(ISNUMBER(S13),ISNUMBER(O13),ISNUMBER(P13),ISNUMBER(Q13)),S13-O13-P13-Q13,"") | W13: =IF(AND(ISNUMBER(X13),ISNUMBER(T13),ISNUMBER(U13),ISNUMBER(V13)),X13-T13-U13-V13,"") | AB13: =IF(AND(ISNUMBER(AC13),ISNUMBER(Y13),ISNUMBER(Z13),ISNUMBER(AA13)),AC13-Y13-Z13-AA13,"") | AG13: =IF(AND(ISNUMBER(AH13),ISNUMBER(AD13),ISNUMBER(AE13),ISNUMBER(AF13)),AH13-AD13-AE13-AF13,"") | AJ13: 297.076 | AK13: 300.026 | AL13: =IF(AND(ISNUMBER(AM13),ISNUMBER(AI13),ISNUMBER(AJ13),ISNUMBER(AK13)),AM13-AI13-AJ13-AK13,"") | AM13: 1189.148 | AN13: 322.404 | AO13: 346.128 | AP13: 355.574 | AQ13: =IF(AND(ISNUMBER(AR13),ISNUMBER(AN13),ISNUMBER(AO13),ISNUMBER(AP13)),AR13-AN13-AO13-AP13,"") -> 356.657 | AR13: 1380.763 | AS13: 365.731 | AT13: 378.188 | AU13: 387.566 | AV13: =IF(AND(ISNUMBER(AW13),ISNUMBER(AS13),ISNUMBER(AT13),ISNUMBER(AU13)),AW13-AS13-AT13-AU13,"") -> 396.732 | AW13: 1528.217 | AX13: 400.819 | AY13: 416.975 | AZ13: 422.543 | BA13: =IF(AND(ISNUMBER(BB13),ISNUMBER(AX13),ISNUMBER(AY13),ISNUMBER(AZ13)),BB13-AX13-AY13-AZ13,"") -> 433.482 | BB13: 1673.819 | BC13: 440.288 | BD13: 463.32 | BE13: 487.995 | BF13: =IF(AND(ISNUMBER(BG13),ISNUMBER(BC13),ISNUMBER(BD13),ISNUMBER(BE13)),BG13-BC13-BD13-BE13,"") -> 499.505 | BG13: 1891.108 | BH13: 514.053 | BI13: 529.872 | BJ13: 538.364 | BK13: =IF(AND(ISNUMBER(BL13),ISNUMBER(BH13),ISNUMBER(BI13),ISNUMBER(BJ13)),BL13-BH13-BI13-BJ13,"") -> 542.779 | BL13: 2125.068 | BM13: 546.211 | BN13: 567.383 | BO13: 574.305 | BP13: =IF(AND(ISNUMBER(BQ13),ISNUMBER(BM13),ISNUMBER(BN13),ISNUMBER(BO13)),BQ13-BM13-BN13-BO13,"") -> 571.012 | BQ13: 2258.911 | BR13: 571.619 | BS13: 592.225 | BT13: 600.832 | BU13: =IF(AND(ISNUMBER(BV13),ISNUMBER(BR13),ISNUMBER(BS13),ISNUMBER(BT13)),BV13-BR13-BS13-BT13,"") -> 599.86 | BV13: 2364.536 | BW13: 600.117 | BX13: 619.691 | CN13: FY26 Adjusted EBITDA ($m) | CO13: 3340 | CP13: 3335 | CQ13: 3330 | CR13: Raised to $3.330–3.340bn (from $3.300–3.325bn). Drives the Q3/Q4-26E cost-of-operations calibration.
B14: Memo: industrial & construction roll-off (from Q2/18) | M14: =IF(AND(ISNUMBER(N14),ISNUMBER(J14),ISNUMBER(K14),ISNUMBER(L14)),N14-J14-K14-L14,"") | R14: =IF(AND(ISNUMBER(S14),ISNUMBER(O14),ISNUMBER(P14),ISNUMBER(Q14)),S14-O14-P14-Q14,"") | W14: =IF(AND(ISNUMBER(X14),ISNUMBER(T14),ISNUMBER(U14),ISNUMBER(V14)),X14-T14-U14-V14,"") | AB14: =IF(AND(ISNUMBER(AC14),ISNUMBER(Y14),ISNUMBER(Z14),ISNUMBER(AA14)),AC14-Y14-Z14-AA14,"") | AG14: =IF(AND(ISNUMBER(AH14),ISNUMBER(AD14),ISNUMBER(AE14),ISNUMBER(AF14)),AH14-AD14-AE14-AF14,"") | AJ14: 197.279 | AK14: 202.13 | AL14: =IF(AND(ISNUMBER(AM14),ISNUMBER(AI14),ISNUMBER(AJ14),ISNUMBER(AK14)),AM14-AI14-AJ14-AK14,"") | AM14: 768.687 | AN14: 187.44 | AO14: 215.355 | AP14: 226.801 | AQ14: =IF(AND(ISNUMBER(AR14),ISNUMBER(AN14),ISNUMBER(AO14),ISNUMBER(AP14)),AR14-AN14-AO14-AP14,"") -> 211.577 | AR14: 841.173 | AS14: 206.771 | AT14: 194.457 | AU14: 216.894 | AV14: =IF(AND(ISNUMBER(AW14),ISNUMBER(AS14),ISNUMBER(AT14),ISNUMBER(AU14)),AW14-AS14-AT14-AU14,"") -> 215.026 | AW14: 833.148 | AX14: 209.258 | AY14: 237.3 | AZ14: 249.417 | BA14: =IF(AND(ISNUMBER(BB14),ISNUMBER(AX14),ISNUMBER(AY14),ISNUMBER(AZ14)),BB14-AX14-AY14-AZ14,"") -> 258.206 | BB14: 954.181 | BC14: 259.488 | BD14: 295.557 | BE14: 315.904 | BF14: =IF(AND(ISNUMBER(BG14),ISNUMBER(BC14),ISNUMBER(BD14),ISNUMBER(BE14)),BG14-BC14-BD14-BE14,"") -> 312.675 | BG14: 1183.624 | BH14: 318.315 | BI14: 340.03 | BJ14: 343.74 | BK14: =IF(AND(ISNUMBER(BL14),ISNUMBER(BH14),ISNUMBER(BI14),ISNUMBER(BJ14)),BL14-BH14-BI14-BJ14,"") -> 330.935 | BL14: 1333.02 | BM14: 325.99 | BN14: 358.789 | BO14: 367.559 | BP14: =IF(AND(ISNUMBER(BQ14),ISNUMBER(BM14),ISNUMBER(BN14),ISNUMBER(BO14)),BQ14-BM14-BN14-BO14,"") -> 350.975 | BQ14: 1403.313 | BR14: 336.998 | BS14: 366.987 | BT14: 379.123 | BU14: =IF(AND(ISNUMBER(BV14),ISNUMBER(BR14),ISNUMBER(BS14),ISNUMBER(BT14)),BV14-BR14-BS14-BT14,"") -> 356.173 | BV14: 1439.281 | BW14: 347.949 | BX14: 385.012 | CN14: FY26 net income attributable ($m; outlook reconciliation) | CO14: 1173 | CP14: 1171 | CQ14: 1169 | CR14: Q2-26 outlook reconciliation (memo only; includes 1H/26 impairments & other items).
B15: Disposal & transfer revenues (landfill + transfer stations) | C15: 259.19 | D15: 298.954 | E15: 308.811 | F15: 392.497 | G15: 458.241 | H15: 510.33 | I15: 524.861 | J15: 122.772 | K15: 153.6 | L15: 158.142 | M15: 144.866 | N15: 579.379 | O15: 135.563 | P15: 158.913 | Q15: 167.129 | R15: 155.557 | S15: 617.161 | T15: 142.43 | U15: 171.932 | V15: 180.442 | W15: 175.565 | X15: 670.369 | Y15: 170.083 | Z15: 256.847 | AA15: 377.998 | AB15: 350.482 | AC15: 1155.41 | AD15: 357.025 | AE15: 416.176 | AF15: 416.764 | AG15: 388.01 | AH15: 1577.975 | AI15: 370.929 | AJ15: 440.537 | AK15: 473.906 | AL15: 447.998 | AM15: 1733.371 | AN15: 405.791 | AO15: 501.401 | AP15: 520.218 | AQ15: 476.84 | AR15: 1904.251 | AS15: 446.983 | AT15: 469.704 | AU15: 514.705 | AV15: 493.093 | AW15: 1924.486 | AX15: 461.259 | AY15: 544.257 | AZ15: 553.974 | BA15: 533.122 | BB15: 2092.612 | BC15: 517.722 | BD15: 601.194 | BE15: 616.9 | BF15: 619.176 | BG15: 2354.992 | BH15: 616.954 | BI15: 688.965 | BJ15: 703.544 | BK15: 672.318 | BL15: 2681.782 | BM15: 655.36 | BN15: 756.139 | BO15: 776.928 | BP15: 718.525 | BQ15: 2906.952 | BR15: 658.023 | BS15: 784.015 | BT15: 804.442 | BU15: 757.06 | BV15: 3003.54 | BW15: 714.624 | BX15: 829.536 | BY15: =BT15*(1+BY20) -> 838.13239 | BZ15: =BU15*(1+BZ20) -> 788.76601 | CA15: =SUM(BW15,BX15,BY15,BZ15) -> 3171.0584 | CB15: =CA15*(1+CB20) -> 3305.8284 | CC15: =CB15*(1+CC20) -> 3454.5907 | CD15: =CC15*(1+CD20) -> 3618.6837 | CE15: =CD15*(1+CE20) -> 3781.5245 | CF15: Gross of intercompany (~45–50% of landfill & transfer revenue is internalized volume from WCN collection, eliminated below). | CH15: =IFERROR((CE15/BV15)^(1/5)-1,"n/m") -> 0.047144701 | CI15: =IFERROR((BV15/AW15)^(1/5)-1,"n/m") -> 0.093109661 | CJ15: =IFERROR((BV15/X15)^(1/10)-1,"n/m") -> 0.16180155 | CK15: =IFERROR((BV15/C15)^(1/19)-1,"n/m") -> 0.13762938 | CN15: FY26 adjusted free cash flow ($m) | CO15: 1450 | CP15: 1425 | CQ15: 1400 | CR15: Reaffirmed $1.40–1.45bn (memo; compare with model Adjusted FCF).
B16: Memo: landfill (from Q2/18) | M16: =IF(AND(ISNUMBER(N16),ISNUMBER(J16),ISNUMBER(K16),ISNUMBER(L16)),N16-J16-K16-L16,"") | R16: =IF(AND(ISNUMBER(S16),ISNUMBER(O16),ISNUMBER(P16),ISNUMBER(Q16)),S16-O16-P16-Q16,"") | W16: =IF(AND(ISNUMBER(X16),ISNUMBER(T16),ISNUMBER(U16),ISNUMBER(V16)),X16-T16-U16-V16,"") | AB16: =IF(AND(ISNUMBER(AC16),ISNUMBER(Y16),ISNUMBER(Z16),ISNUMBER(AA16)),AC16-Y16-Z16-AA16,"") | AG16: =IF(AND(ISNUMBER(AH16),ISNUMBER(AD16),ISNUMBER(AE16),ISNUMBER(AF16)),AH16-AD16-AE16-AF16,"") | AJ16: 271.674 | AK16: 285.945 | AL16: =IF(AND(ISNUMBER(AM16),ISNUMBER(AI16),ISNUMBER(AJ16),ISNUMBER(AK16)),AM16-AI16-AJ16-AK16,"") | AM16: 1063.242 | AN16: 244.601 | AO16: 296.84 | AP16: 310.633 | AQ16: =IF(AND(ISNUMBER(AR16),ISNUMBER(AN16),ISNUMBER(AO16),ISNUMBER(AP16)),AR16-AN16-AO16-AP16,"") -> 280.861 | AR16: 1132.935 | AS16: 266.218 | AT16: 280.619 | AU16: 308.795 | AV16: =IF(AND(ISNUMBER(AW16),ISNUMBER(AS16),ISNUMBER(AT16),ISNUMBER(AU16)),AW16-AS16-AT16-AU16,"") -> 291.1 | AW16: 1146.732 | AX16: 271.936 | AY16: 327.124 | AZ16: 328.147 | BA16: =IF(AND(ISNUMBER(BB16),ISNUMBER(AX16),ISNUMBER(AY16),ISNUMBER(AZ16)),BB16-AX16-AY16-AZ16,"") -> 306.292 | BB16: 1233.499 | BC16: 299.765 | BD16: 339.719 | BE16: 345.215 | BF16: =IF(AND(ISNUMBER(BG16),ISNUMBER(BC16),ISNUMBER(BD16),ISNUMBER(BE16)),BG16-BC16-BD16-BE16,"") -> 344.243 | BG16: 1328.942 | BH16: 343.433 | BI16: 382.944 | BJ16: 390.33 | BK16: =IF(AND(ISNUMBER(BL16),ISNUMBER(BH16),ISNUMBER(BI16),ISNUMBER(BJ16)),BL16-BH16-BI16-BJ16,"") -> 366.69 | BL16: 1483.397 | BM16: 353.478 | BN16: 405.912 | BO16: 418.508 | BP16: =IF(AND(ISNUMBER(BQ16),ISNUMBER(BM16),ISNUMBER(BN16),ISNUMBER(BO16)),BQ16-BM16-BN16-BO16,"") -> 379.974 | BQ16: 1557.872 | BR16: 338.754 | BS16: 402.08 | BT16: 414.614 | BU16: =IF(AND(ISNUMBER(BV16),ISNUMBER(BR16),ISNUMBER(BS16),ISNUMBER(BT16)),BV16-BR16-BS16-BT16,"") -> 386.456 | BV16: 1541.904 | BW16: 360.448 | BX16: 417.541 | CN16: FY26 net cash provided by operating activities ($m) | CO16: 2680 | CP16: 2655 | CQ16: 2630 | CR16: Trimmed to $2.63–2.68bn (from $2.65–2.70bn) — memo.
B17: Memo: transfer (from Q2/18) | M17: =IF(AND(ISNUMBER(N17),ISNUMBER(J17),ISNUMBER(K17),ISNUMBER(L17)),N17-J17-K17-L17,"") | R17: =IF(AND(ISNUMBER(S17),ISNUMBER(O17),ISNUMBER(P17),ISNUMBER(Q17)),S17-O17-P17-Q17,"") | W17: =IF(AND(ISNUMBER(X17),ISNUMBER(T17),ISNUMBER(U17),ISNUMBER(V17)),X17-T17-U17-V17,"") | AB17: =IF(AND(ISNUMBER(AC17),ISNUMBER(Y17),ISNUMBER(Z17),ISNUMBER(AA17)),AC17-Y17-Z17-AA17,"") | AG17: =IF(AND(ISNUMBER(AH17),ISNUMBER(AD17),ISNUMBER(AE17),ISNUMBER(AF17)),AH17-AD17-AE17-AF17,"") | AJ17: 168.863 | AK17: 187.961 | AL17: =IF(AND(ISNUMBER(AM17),ISNUMBER(AI17),ISNUMBER(AJ17),ISNUMBER(AK17)),AM17-AI17-AJ17-AK17,"") | AM17: 670.129 | AN17: 161.191 | AO17: 204.561 | AP17: 209.585 | AQ17: =IF(AND(ISNUMBER(AR17),ISNUMBER(AN17),ISNUMBER(AO17),ISNUMBER(AP17)),AR17-AN17-AO17-AP17,"") -> 195.979 | AR17: 771.316 | AS17: 180.765 | AT17: 189.085 | AU17: 205.91 | AV17: =IF(AND(ISNUMBER(AW17),ISNUMBER(AS17),ISNUMBER(AT17),ISNUMBER(AU17)),AW17-AS17-AT17-AU17,"") -> 201.994 | AW17: 777.754 | AX17: 189.323 | AY17: 217.133 | AZ17: 225.827 | BA17: =IF(AND(ISNUMBER(BB17),ISNUMBER(AX17),ISNUMBER(AY17),ISNUMBER(AZ17)),BB17-AX17-AY17-AZ17,"") -> 226.83 | BB17: 859.113 | BC17: 217.957 | BD17: 261.475 | BE17: 271.685 | BF17: =IF(AND(ISNUMBER(BG17),ISNUMBER(BC17),ISNUMBER(BD17),ISNUMBER(BE17)),BG17-BC17-BD17-BE17,"") -> 274.933 | BG17: 1026.05 | BH17: 273.521 | BI17: 306.021 | BJ17: 313.214 | BK17: =IF(AND(ISNUMBER(BL17),ISNUMBER(BH17),ISNUMBER(BI17),ISNUMBER(BJ17)),BL17-BH17-BI17-BJ17,"") -> 305.629 | BL17: 1198.385 | BM17: 301.882 | BN17: 350.227 | BO17: 358.42 | BP17: =IF(AND(ISNUMBER(BQ17),ISNUMBER(BM17),ISNUMBER(BN17),ISNUMBER(BO17)),BQ17-BM17-BN17-BO17,"") -> 338.551 | BQ17: 1349.08 | BR17: 319.269 | BS17: 381.935 | BT17: 389.828 | BU17: =IF(AND(ISNUMBER(BV17),ISNUMBER(BR17),ISNUMBER(BS17),ISNUMBER(BT17)),BV17-BR17-BS17-BT17,"") -> 370.604 | BV17: 1461.636 | BW17: 354.176 | BX17: 411.995 | CN17: FY26 point estimates (all cases)
B18: Recycling revenues (recycled commodities; within "recycling & other" to 2011) | I18: 81.512 | J18: 18.794 | K18: 18.61 | L18: 18.402 | M18: 16.025 | N18: 71.831 | O18: 14.904 | P18: 14.836 | Q18: 14.973 | R18: 13.513 | S18: 58.226 | T18: 11.069 | U18: 12.332 | V18: 12.213 | W18: 11.678 | X18: 47.292 | Y18: 10.619 | Z18: 18.119 | AA18: 32.138 | AB18: 31.58 | AC18: 92.456 | AD18: 43.889 | AE18: 43.693 | AF18: 43.864 | AG18: 30.285 | AH18: 161.73 | AI18: 23.485 | AJ18: 22.703 | AK18: 23.37 | AL18: 23.075 | AM18: 92.634 | AN18: 19.804 | AO18: 16.73 | AP18: 14.142 | AQ18: 13.569 | AR18: 64.245 | AS18: 18.108 | AT18: 20.217 | AU18: 21.377 | AV18: 26.688 | AW18: 86.389 | AX18: 32.448 | AY18: 41.539 | AZ18: 55.772 | BA18: 75.317 | BB18: 205.076 | BC18: 63.094 | BD18: 67.504 | BE18: 48.246 | BF18: 26.031 | BG18: 204.876 | BH18: 31.301 | BI18: 38.319 | BJ18: 36.103 | BK18: 41.316 | BL18: 147.039 | BM18: 49.025 | BN18: 63.298 | BO18: 69.748 | BP18: 59.802 | BQ18: 241.873 | BR18: 61.341 | BS18: 69.163 | BT18: 58.351 | BU18: 51.202 | BV18: 240.057 | BW18: 53.649 | BX18: 63.946 | BY18: =BT18*(1+BY20) -> 60.794766 | BZ18: =BU18*(1+BZ20) -> 53.346363 | CA18: =SUM(BW18,BX18,BY18,BZ18) -> 231.73613 | CB18: =CA18*(1+CB20) -> 241.58491 | CC18: =CB18*(1+CC20) -> 252.45624 | CD18: =CC18*(1+CD20) -> 264.44791 | CE18: =CD18*(1+CE20) -> 276.34806 | CF18: Recycled-commodity price exposure (OCC, fibre, plastics); RINs / landfill gas sit in intermodal & other. Forecast grows with solid waste (recycled-commodity contribution input below). | CH18: =IFERROR((CE18/BV18)^(1/5)-1,"n/m") -> 0.028557108 | CI18: =IFERROR((BV18/AW18)^(1/5)-1,"n/m") -> 0.22679271 | CJ18: =IFERROR((BV18/X18)^(1/10)-1,"n/m") -> 0.17639364 | CK18: =IFERROR((BV18/C18)^(1/19)-1,"n/m") -> n/m | CN18: Interest expense, net of interest income ($m) | CP18: 358 | CR18: Q2-26 outlook reconciliation: "interest expense, net" $358m (was $330m in Feb).
B19: Solid waste revenues before intercompany eliminations | C19: =N(C11)+N(C15)+N(C18) -> 861.952 | D19: =N(D11)+N(D15)+N(D18) -> 992.629 | E19: =N(E11)+N(E15)+N(E18) -> 1096.524 | F19: =N(F11)+N(F15)+N(F18) -> 1294.265 | G19: =N(G11)+N(G15)+N(G18) -> 1409.568 | H19: =N(H11)+N(H15)+N(H18) -> 1579.395 | I19: =N(I11)+N(I15)+N(I18) -> 1782.706 | J19: =N(J11)+N(J15)+N(J18) -> 434.71 | ... CE19: =N(CE11)+N(CE15)+N(CE18) -> 12499.674 | CF19: 2006–11 excludes recycling (reported combined with intermodal & other — memo line below), so 2012 y/y is overstated by the reclassification. | CH19: =IFERROR((CE19/BV19)^(1/5)-1,"n/m") -> 0.04580791 | CI19: =IFERROR((BV19/AW19)^(1/5)-1,"n/m") -> 0.10802741 | CJ19: =IFERROR((BV19/X19)^(1/10)-1,"n/m") -> 0.16900868 | CK19: =IFERROR((BV19/C19)^(1/19)-1,"n/m") -> 0.13764879 | CN19: Tax rate (GAAP effective) | CP19: 0.231 | CR19: Q2-26 release footnote: FY26 effective tax rate ~23.1% (24.5% in Feb outlook).
B20: Solid waste revenues y/y % (gross) — forecast growth driver | D20: =IF(AND(ISNUMBER(D19),ISNUMBER(C19)),IFERROR(D19/C19-1,""),"") -> 0.15160589 | E20: =IF(AND(ISNUMBER(E19),ISNUMBER(D19)),IFERROR(E19/D19-1,""),"") -> 0.1046665 | F20: =IF(AND(ISNUMBER(F19),ISNUMBER(E19)),IFERROR(F19/E19-1,""),"") -> 0.1803344 | G20: =IF(AND(ISNUMBER(G19),ISNUMBER(F19)),IFERROR(G19/F19-1,""),"") -> 0.089087629 | H20: =IF(AND(ISNUMBER(H19),ISNUMBER(G19)),IFERROR(H19/G19-1,""),"") -> 0.12048159 | I20: =IF(AND(ISNUMBER(I19),ISNUMBER(H19)),IFERROR(I19/H19-1,""),"") -> 0.12872714 | N20: =IF(AND(ISNUMBER(N19),ISNUMBER(I19)),IFERROR(N19/I19-1,""),"") -> 0.049135976 | O20: =IF(AND(ISNUMBER(O19),ISNUMBER(J19)),IFERROR(O19/J19-1,""),"") -> 0.050056359 | P20: =IF(AND(ISNUMBER(P19),ISNUMBER(K19)),IFERROR(P19/K19-1,""),"") -> 0.03724811 | Q20: =IF(AND(ISNUMBER(Q19),ISNUMBER(L19)),IFERROR(Q19/L19-1,""),"") -> 0.054356621 | R20: =IF(AND(ISNUMBER(R19),ISNUMBER(M19)),IFERROR(R19/M19-1,""),"") -> 0.061605069 | S20: =IF(AND(ISNUMBER(S19),ISNUMBER(N19)),IFERROR(S19/N19-1,""),"") -> 0.050789686 | T20: =IF(AND(ISNUMBER(T19),ISNUMBER(O19)),IFERROR(T19/O19-1,""),"") -> 0.052651872 | U20: =IF(AND(ISNUMBER(U19),ISNUMBER(P19)),IFERROR(U19/P19-1,""),"") -> 0.061096207 | ... BX20: =IF(AND(ISNUMBER(BX19),ISNUMBER(BS19)),IFERROR(BX19/BS19-1,""),"") -> 0.05454246 | BY20: =$BX$21+BY87 -> 0.041880446 | BZ20: =$BX$21+BZ87 -> 0.041880446 | CA20: =IFERROR(CA19/BV19-1,"") -> 0.049051806 | CB20: =CB31 -> 0.0425 | CC20: =CC31 -> 0.045 | CD20: =CD31 -> 0.0475 | CE20: =CE31 -> 0.045 | CF20: Q3/Q4-26E: Q2/26 y/y (+price, −volume, + acquisition roll-over) + revenue-outlook calibration Δ (Group block). 2027E+: organic internal growth (price + volume + recycling + FX); bolt-ons in the future-acquisitions block. | CN20: Depreciation & depletion ($m) | CP20: 1112 | CR20: Q2-26 outlook reconciliation $1,110–1,114m (mid-point).
B21: Memo: Q2/26 y/y growth basis (trend input to Q3/Q4-26E) | BX21: =IFERROR(BX19/BS19-1,"") -> 0.05454246 | CN21: Amortization of intangibles ($m) | CP21: 192 | CR21: Q2-26 outlook reconciliation $192m.
CN22: Capital expenditures for property & equipment ($m) | CP22: 1250 | CR22: "Approximately $1.25 billion" (unchanged since Feb-26).
B23: Solid waste internal growth — company-reported % of prior-year solid waste revenues (price × volume) | CN23: Closure & post-closure accretion ($m) | CP23: 40.608 | CR23: Q2-26 outlook reconciliation line ($50m in Feb).
B24: Core price % (yield basis in the forecast) | C24: 0.051 | D24: 0.047 | E24: 0.056 | F24: 0.048 | G24: 0.027 | H24: 0.036 | I24: 0.032 | J24: 0.028 | K24: 0.026 | L24: 0.024 | M24: 0.026 | N24: 0.026 | O24: 0.029 | P24: 0.026 | Q24: 0.028 | R24: 0.029 | S24: 0.028 | T24: 0.028 | U24: 0.029 | V24: 0.027 | W24: 0.029 | X24: 0.028 | Y24: 0.031 | Z24: 0.029 | AA24: 0.026 | AB24: 0.027 | AC24: 0.028 | AD24: 0.026 | AE24: 0.031 | AF24: 0.033 | AG24: 0.035 | AH24: 0.031 | AI24: 0.041 | AJ24: 0.039 | AK24: 0.04 | AL24: 0.044 | AM24: 0.041 | AN24: 0.05 | AO24: 0.05 | AP24: 0.051 | AQ24: 0.054 | AR24: 0.051 | AS24: 0.055 | AT24: 0.045 | AU24: 0.041 | AV24: 0.043 | AW24: 0.045 | AX24: 0.045 | AY24: 0.047 | AZ24: 0.047 | BA24: 0.05 | BB24: 0.047 | BC24: 0.063 | BD24: 0.072 | BE24: 0.083 | BF24: 0.09 | BG24: 0.077 | BH24: 0.11 | BI24: 0.098 | BJ24: 0.088 | BK24: 0.087 | BL24: 0.095 | BM24: 0.078 | BN24: 0.07 | BO24: 0.068 | BP24: 0.067 | BQ24: 0.071 | BR24: 0.069 | BS24: 0.066 | BT24: 0.063 | BU24: 0.064 | BV24: 0.065 | BW24: 0.06 | BX24: 0.056 | CB24: =CHOOSE(MATCH($CF$2,{"Bull","Base","Bear"},0),$CO$29,$CP$29,$CQ$29) -> 0.0475 | CC24: =CHOOSE(MATCH($CF$2,{"Bull","Base","Bear"},0),$CO$30,$CP$30,$CQ$30) -> 0.045 | CD24: =CHOOSE(MATCH($CF$2,{"Bull","Base","Bear"},0),$CO$31,$CP$31,$CQ$31) -> 0.0425 | CE24: =CHOOSE(MATCH($CF$2,{"Bull","Base","Bear"},0),$CO$32,$CP$32,$CQ$32) -> 0.04 | CF24: Core price = price increases net of rollbacks on solid waste (company). 2006–08 = total price incl. surcharges. From Q1/26 the company total uses "yield"; core price is shown as memo. 2027E+: scenario lever SW_price (yield incl. surcharges). | CH24: =IFERROR(AVERAGE(CA24,CB24,CC24,CD24,CE24),"n/m") -> 0.04375 | CI24: =IFERROR(AVERAGE(BB24,BG24,BL24,BQ24,BV24),"n/m") -> 0.071 | CJ24: =IFERROR(AVERAGE(AC24,AH24,AM24,AR24,AW24,BB24,BG24,BL24,BQ24,BV24),"n/m") -> 0.0551 | CK24: =IFERROR(AVERAGE(C24,D24,E24,F24,G24,H24,I24,N24,S24,X24,AC24,AH24,AM24,AR24,AW24,BB24,BG24,BL24,BQ24,BV24),"n/m") -> 0.0465 | CN24: 2H/26 share repurchases ($m) | CO24: 600 | CP24: 400 | CQ24: 200 | CR24: 1H/26: 3.76m shares for $614.5m under the NCIB. 2H/26 is a scenario input (not guided).
B25: Surcharges % (fuel / materials / environmental) | F25: -0.021 | G25: 0.002 | J25: 0.004 | K25: 0.002 | L25: 0.003 | M25: 0.003 | N25: 0.003 | O25: 0.001 | P25: 0 | Q25: 0 | R25: 0 | S25: 0 | U25: -0.001 | V25: -0.002 | W25: -0.005 | X25: -0.002 | Y25: -0.004 | Z25: -0.003 | AA25: -0.003 | AB25: -0.001 | AC25: -0.003 | AD25: 0 | AE25: 0 | AF25: 0 | AG25: 0.001 | AH25: 0.001 | AI25: 0.002 | AJ25: 0.003 | AK25: 0.005 | AL25: 0.004 | AM25: 0.004 | AN25: 0.002 | AO25: 0.002 | AP25: 0.001 | AQ25: 0 | AR25: 0.001 | AS25: 0.001 | AT25: -0.002 | AU25: -0.004 | AV25: -0.005 | AW25: -0.002 | AX25: -0.003 | AY25: 0.002 | AZ25: 0.004 | BA25: 0.007 | BB25: 0.003 | BC25: 0.008 | BD25: 0.016 | BE25: 0.018 | BF25: 0.016 | BG25: 0.015 | BH25: 0.008 | BI25: -0.007 | BJ25: -0.011 | BK25: -0.008 | BL25: -0.005 | BM25: -0.007 | BN25: -0.002 | BO25: -0.003 | BP25: -0.005 | BQ25: -0.005 | BR25: -0.002 | BS25: -0.002 | BT25: -0.001 | BU25: 0 | BV25: -0.001 | BW25: -0.001 | BX25: 0.011 | CB25: 0 | CC25: 0 | CD25: 0 | CE25: 0 | CF25: Input 0% 2027E+ (surcharges captured in the yield lever). | CH25: =IFERROR(AVERAGE(CA25,CB25,CC25,CD25,CE25),"n/m") -> 0 | CI25: =IFERROR(AVERAGE(BB25,BG25,BL25,BQ25,BV25),"n/m") -> 0.0014 | CJ25: =IFERROR(AVERAGE(AC25,AH25,AM25,AR25,AW25,BB25,BG25,BL25,BQ25,BV25),"n/m") -> 0.0008 | CK25: =IFERROR(AVERAGE(C25,D25,E25,F25,G25,H25,I25,N25,S25,X25,AC25,AH25,AM25,AR25,AW25,BB25,BG25,BL25,BQ25,BV25),"n/m") -> -0.00066666667
B26: Volume % (unit volume from Q1/26) | C26: 0.028 | D26: 0.04 | E26: -0.019 | F26: -0.062 | G26: 0 | H26: -0.003 | I26: -0.021 | J26: -0.019 | K26: 0.009 | L26: 0.022 | M26: 0.014 | N26: 0.007 | O26: 0.025 | P26: 0.015 | Q26: 0.021 | R26: 0.023 | S26: 0.021 | T26: 0.016 | U26: 0.024 | V26: 0.026 | W26: 0.024 | X26: 0.022 | Y26: 0.032 | Z26: 0.024 | AA26: 0.011 | AB26: 0.01 | AC26: 0.019 | AD26: 0.021 | AE26: 0.02 | AF26: 0.005 | AG26: 0.007 | AH26: 0.012 | AI26: -0.011 | AJ26: -0.015 | AK26: -0.001 | AL26: 0.001 | AM26: -0.007 | AN26: -0.012 | AO26: 0.008 | AP26: 0.009 | AQ26: -0.014 | AR26: -0.002 | AS26: -0.004 | AT26: -0.096 | AU26: -0.057 | AV26: -0.031 | AW26: -0.048 | AX26: -0.032 | AY26: 0.065 | AZ26: 0.022 | BA26: 0.012 | BB26: 0.016 | BC26: 0.005 | BD26: -0.007 | BE26: -0.015 | BF26: -0.025 | BG26: -0.011 | BH26: -0.013 | BI26: -0.019 | BJ26: -0.024 | BK26: -0.023 | BL26: -0.02 | BM26: -0.038 | BN26: -0.028 | BO26: -0.019 | BP26: -0.032 | BQ26: -0.029 | BR26: -0.028 | BS26: -0.026 | BT26: -0.027 | BU26: -0.027 | BV26: -0.028 | BW26: -0.015 | BX26: -0.019 | CB26: =CHOOSE(MATCH($CF$2,{"Bull","Base","Bear"},0),$CO$34,$CP$34,$CQ$34) -> -0.005 | CC26: =CHOOSE(MATCH($CF$2,{"Bull","Base","Bear"},0),$CO$35,$CP$35,$CQ$35) -> 0 | CD26: =CHOOSE(MATCH($CF$2,{"Bull","Base","Bear"},0),$CO$36,$CP$36,$CQ$36) -> 0.005 | CE26: =CHOOSE(MATCH($CF$2,{"Bull","Base","Bear"},0),$CO$37,$CP$37,$CQ$37) -> 0.005 | CF26: 2027E+: scenario lever SW_vol. | CH26: =IFERROR(AVERAGE(CA26,CB26,CC26,CD26,CE26),"n/m") -> 0.00125 | CI26: =IFERROR(AVERAGE(BB26,BG26,BL26,BQ26,BV26),"n/m") -> -0.0144 | CJ26: =IFERROR(AVERAGE(AC26,AH26,AM26,AR26,AW26,BB26,BG26,BL26,BQ26,BV26),"n/m") -> -0.0098 | CK26: =IFERROR(AVERAGE(C26,D26,E26,F26,G26,H26,I26,N26,S26,X26,AC26,AH26,AM26,AR26,AW26,BB26,BG26,BL26,BQ26,BV26),"n/m") -> -0.00425 | CN26: Minimum net debt / Adjusted EBITDA (x) — buyback floor 2027E+ | CO26: 3 | CP26: 2.75 | CQ26: 2.5 | CR26: WCN targets leverage ~2.5–3.0x (2.75x at YE2025 per the Q4-25 release); surplus cash returned via buybacks once at the floor.
B27: Recycled commodities % | I27: -0.013 | J27: -0.006 | K27: -0.008 | L27: 0 | M27: -0.005 | N27: -0.005 | O27: -0.007 | P27: -0.006 | Q27: -0.005 | R27: -0.006 | S27: -0.006 | T27: -0.008 | U27: -0.005 | V27: -0.005 | W27: -0.004 | X27: -0.006 | Y27: -0.002 | Z27: -0.001 | AA27: 0.004 | AB27: 0.004 | AC27: 0.001 | AD27: 0.015 | AE27: 0.011 | AF27: 0.008 | AG27: -0.003 | AH27: 0.007 | AI27: -0.019 | AJ27: -0.018 | AK27: -0.018 | AL27: -0.008 | AM27: -0.016 | AN27: -0.005 | AO27: -0.007 | AP27: -0.008 | AQ27: -0.008 | AR27: -0.007 | AS27: -0.004 | AT27: 0 | AU27: 0.002 | AV27: 0.005 | AW27: 0.001 | AX27: 0.009 | AY27: 0.015 | AZ27: 0.021 | BA27: 0.026 | BB27: 0.018 | BC27: 0.011 | BD27: 0.004 | BE27: -0.013 | BF27: -0.029 | BG27: -0.007 | BH27: -0.019 | BI27: -0.015 | BJ27: -0.005 | BK27: 0.008 | BL27: -0.008 | BM27: 0.008 | BN27: 0.008 | BO27: 0.01 | BP27: 0.002 | BQ27: 0.007 | BR27: -0.001 | BS27: -0.003 | BT27: -0.008 | BU27: -0.006 | BV27: -0.005 | BW27: -0.005 | BX27: -0.002 | CB27: 0 | CC27: 0 | CD27: 0 | CE27: 0 | CF27: Input 0% (commodity prices assumed flat from 2H/26 levels). | CH27: =IFERROR(AVERAGE(CA27,CB27,CC27,CD27,CE27),"n/m") -> 0 | CI27: =IFERROR(AVERAGE(BB27,BG27,BL27,BQ27,BV27),"n/m") -> 0.001 | CJ27: =IFERROR(AVERAGE(AC27,AH27,AM27,AR27,AW27,BB27,BG27,BL27,BQ27,BV27),"n/m") -> -0.0009 | CK27: =IFERROR(AVERAGE(C27,D27,E27,F27,G27,H27,I27,N27,S27,X27,AC27,AH27,AM27,AR27,AW27,BB27,BG27,BL27,BQ27,BV27),"n/m") -> -0.0027857143
B28: Foreign exchange impact % (Canada; from Q2/17) | AE28: -0.002 | AF28: 0.007 | AG28: 0.008 | AI28: 0.007 | AJ28: 0.007 | AK28: -0.007 | AL28: -0.006 | AN28: -0.007 | AO28: -0.005 | AP28: -0.002 | AQ28: 0 | AS28: -0.001 | AT28: -0.005 | AU28: -0.001 | AV28: 0.002 | AX28: 0.007 | AY28: 0.015 | AZ28: 0.007 | BA28: 0.005 | BB28: 0.009 | BC28: 0 | BD28: -0.005 | BE28: -0.005 | BF28: -0.009 | BG28: -0.005 | BH28: -0.009 | BI28: -0.007 | BJ28: -0.004 | BK28: -0.001 | BL28: -0.005 | BM28: 0 | BN28: -0.002 | BO28: -0.002 | BP28: -0.003 | BQ28: -0.002 | BR28: -0.007 | BS28: -0.002 | BT28: -0.001 | BU28: 0 | BV28: -0.003 | BW28: 0.005 | BX28: 0 | CB28: 0 | CC28: 0 | CD28: 0 | CE28: 0 | CF28: Input 0% (flat CAD/USD). | CN28: SW_price (solid waste price / yield, % of prior-year solid waste revenue) | CO28: 0.0075 | CP28: Δ → | CQ28: -0.0075 | CR28: 1H/26 yield +4.6–4.7% (core price +5.6–6.0%); pricing decelerating with CPI and a lower cost-inflation backdrop.
B29: Closed operation % (Chiquita Canyon landfill, 2025) | BR29: -0.009 | BS29: -0.009 | BT29: -0.008 | BU29: -0.005 | BV29: -0.008 | CN29: 2027E | CO29: =CP29+$CO$28 -> 0.055 | CP29: 0.0475 | CQ29: =CP29+$CQ$28 -> 0.04
B30: Memo: yield % (company basis from Q1/26; replaces core price + surcharges) | BW30: 0.047 | BX30: 0.046 | CN30: 2028E | CO30: =CP30+$CO$28 -> 0.0525 | CP30: 0.045 | CQ30: =CP30+$CQ$28 -> 0.0375
B31: Solid waste internal growth % (company total) | C31: 0.076 | D31: 0.104 | E31: 0.03 | F31: -0.06 | G31: 0.055 | H31: 0.047 | I31: -0.001 | J31: 0.007 | K31: 0.029 | L31: 0.049 | M31: 0.038 | N31: 0.031 | O31: 0.048 | P31: 0.035 | Q31: 0.044 | R31: 0.046 | S31: 0.043 | T31: 0.036 | U31: 0.047 | V31: 0.046 | W31: 0.044 | X31: 0.042 | Y31: 0.057 | Z31: 0.049 | AA31: 0.038 | AB31: 0.04 | AC31: 0.045 | AD31: 0.062 | AE31: 0.06 | AF31: 0.053 | AG31: 0.048 | AH31: 0.051 | AI31: 0.02 | AJ31: 0.016 | AK31: 0.019 | AL31: 0.035 | AM31: 0.022 | AN31: 0.028 | AO31: 0.048 | AP31: 0.051 | AQ31: 0.032 | AR31: 0.043 | AS31: 0.047 | AT31: -0.058 | AU31: -0.019 | AV31: 0.014 | AW31: -0.004 | AX31: 0.026 | AY31: 0.144 | AZ31: 0.101 | BA31: 0.1 | BB31: 0.093 | BC31: 0.087 | BD31: 0.08 | BE31: 0.068 | BF31: 0.043 | BG31: 0.069 | BH31: 0.077 | BI31: 0.05 | BJ31: 0.044 | BK31: 0.063 | BL31: 0.057 | BM31: 0.041 | BN31: 0.046 | BO31: 0.054 | BP31: 0.029 | BQ31: 0.042 | BR31: 0.022 | BS31: 0.024 | BT31: 0.018 | BU31: 0.026 | BV31: 0.02 | BW31: 0.031 | BX31: 0.036 | CB31: =N(CB24)+N(CB25)+N(CB26)+N(CB27)+N(CB28) -> 0.0425 | CC31: =N(CC24)+N(CC25)+N(CC26)+N(CC27)+N(CC28) -> 0.045 | CD31: =N(CD24)+N(CD25)+N(CD26)+N(CD27)+N(CD28) -> 0.0475 | CE31: =N(CE24)+N(CE25)+N(CE26)+N(CE27)+N(CE28) -> 0.045 | CF31: Company-reported (releases; FY from 10-K MD&A). 2006–12 = company-wide internal growth incl. intermodal / recycling / other; 2013+ solid waste basis. Forecast = Σ components above. | CH31: =IFERROR(AVERAGE(CA31,CB31,CC31,CD31,CE31),"n/m") -> 0.045 | CI31: =IFERROR(AVERAGE(BB31,BG31,BL31,BQ31,BV31),"n/m") -> 0.0562 | CJ31: =IFERROR(AVERAGE(AC31,AH31,AM31,AR31,AW31,BB31,BG31,BL31,BQ31,BV31),"n/m") -> 0.0438 | CK31: =IFERROR(AVERAGE(C31,D31,E31,F31,G31,H31,I31,N31,S31,X31,AC31,AH31,AM31,AR31,AW31,BB31,BG31,BL31,BQ31,BV31),"n/m") -> 0.04025 | CN31: 2029E | CO31: =CP31+$CO$28 -> 0.05 | CP31: 0.0425 | CQ31: =CP31+$CQ$28 -> 0.035
B32: Acquisitions, net of divestitures — contribution to solid waste growth % (derived) | D32: =IF(AND(ISNUMBER(D20),ISNUMBER(D31)),D20-D31,"") -> 0.04760589 | E32: =IF(AND(ISNUMBER(E20),ISNUMBER(E31)),E20-E31,"") -> 0.074666497 | F32: =IF(AND(ISNUMBER(F20),ISNUMBER(F31)),F20-F31,"") -> 0.2403344 | G32: =IF(AND(ISNUMBER(G20),ISNUMBER(G31)),G20-G31,"") -> 0.034087629 | H32: =IF(AND(ISNUMBER(H20),ISNUMBER(H31)),H20-H31,"") -> 0.073481594 | I32: =IF(AND(ISNUMBER(I20),ISNUMBER(I31)),I20-I31,"") -> 0.12972714 | N32: =IF(AND(ISNUMBER(N20),ISNUMBER(N31)),N20-N31,"") -> 0.018135976 | O32: =IF(AND(ISNUMBER(O20),ISNUMBER(O31)),O20-O31,"") -> 0.0020563594 | P32: =IF(AND(ISNUMBER(P20),ISNUMBER(P31)),P20-P31,"") -> 0.0022481104 | Q32: =IF(AND(ISNUMBER(Q20),ISNUMBER(Q31)),Q20-Q31,"") -> 0.010356621 | R32: =IF(AND(ISNUMBER(R20),ISNUMBER(R31)),R20-R31,"") -> 0.015605069 | S32: =IF(AND(ISNUMBER(S20),ISNUMBER(S31)),S20-S31,"") -> 0.0077896857 | T32: =IF(AND(ISNUMBER(T20),ISNUMBER(T31)),T20-T31,"") -> 0.016651872 | U32: =IF(AND(ISNUMBER(U20),ISNUMBER(U31)),U20-U31,"") -> 0.014096207 | ... BX32: =IF(AND(ISNUMBER(BX20),ISNUMBER(BX31)),BX20-BX31,"") -> 0.01854246 | CF32: Derived: gross solid waste y/y − company internal growth (approximation; internal growth is measured on reported revenues). Forecast M&A sits in the future-acquisitions block. | CN32: 2030E | CO32: =CP32+$CO$28 -> 0.0475 | CP32: 0.04 | CQ32: =CP32+$CQ$28 -> 0.0325
CN33: SW_vol (solid waste unit volume y/y) | CO33: 0.01 | CP33: Δ → | CQ33: -0.01 | CR33: Unit volume −1.5% / −1.9% in Q1/Q2-26 (purposeful shedding, Chiquita Canyon closure, soft C&D / roll-off). Recovery assumed as shedding laps.
B34: Revenue change bridge y/y ($m) — company MD&A (10-Q quarters; Q4 = FY − Q1 − Q2 − Q3) | CN34: 2027E | CO34: =CP34+$CO$33 -> 0.005 | CP34: -0.005 | CQ34: =CP34+$CQ$33 -> -0.015
B35: Δ Total revenues y/y (company MD&A) | C35: 102.5 | D35: 134.1 | E35: 91.1 | F35: 141.8 | G35: 128.4 | H35: 185.6 | I35: 156.2 | J35: 73.5 | K35: 78.7 | L35: 77.9 | M35: =IF(AND(ISNUMBER(N35),ISNUMBER(J35),ISNUMBER(K35),ISNUMBER(L35)),N35-J35-K35-L35,"") -> 37.1 | N35: 267.2 | O35: 31.8 | P35: 35.3 | Q35: 43 | R35: =IF(AND(ISNUMBER(S35),ISNUMBER(O35),ISNUMBER(P35),ISNUMBER(Q35)),S35-O35-P35-Q35,"") -> 40.3 | S35: 150.4 | T35: 24.4 | U35: 6.6 | V35: 1.3 | W35: =IF(AND(ISNUMBER(X35),ISNUMBER(T35),ISNUMBER(U35),ISNUMBER(V35)),X35-T35-U35-V35,"") -> 5.8 | X35: 38.1 | Y35: 8.6 | Z35: 196.3 | AA35: 537 | AB35: =IF(AND(ISNUMBER(AC35),ISNUMBER(Y35),ISNUMBER(Z35),ISNUMBER(AA35)),AC35-Y35-Z35-AA35,"") -> 517.1 | AC35: 1259 | AD35: 576.6 | AE35: 448 | AF35: 121.6 | AG35: =IF(AND(ISNUMBER(AH35),ISNUMBER(AD35),ISNUMBER(AE35),ISNUMBER(AF35)),AH35-AD35-AE35-AF35,"") -> 108.8 | AH35: 1255 | AI35: 48.8 | AJ35: 64.4 | AK35: 74.6 | AL35: =IF(AND(ISNUMBER(AM35),ISNUMBER(AI35),ISNUMBER(AJ35),ISNUMBER(AK35)),AM35-AI35-AJ35-AK35,"") -> 104.6 | AM35: 292.4 | AN35: 104.5 | AO35: 129.6 | AP35: 131.3 | AQ35: =IF(AND(ISNUMBER(AR35),ISNUMBER(AN35),ISNUMBER(AO35),ISNUMBER(AP35)),AR35-AN35-AO35-AP35,"") -> 100.4 | AR35: 465.8 | AS35: 107.8 | AT35: -63.8 | AU35: -22.8 | AV35: =IF(AND(ISNUMBER(AW35),ISNUMBER(AS35),ISNUMBER(AT35),ISNUMBER(AU35)),AW35-AS35-AT35-AU35,"") -> 36.1 | AW35: 57.3 | AX35: 43.5 | AY35: 228.1 | AZ35: 207.6 | BA35: =IF(AND(ISNUMBER(BB35),ISNUMBER(AX35),ISNUMBER(AY35),ISNUMBER(AZ35)),BB35-AX35-AY35-AZ35,"") -> 226.2 | BB35: 705.4 | BC35: 250.3 | BD35: 282.5 | BE35: 282.7 | BF35: =IF(AND(ISNUMBER(BG35),ISNUMBER(BC35),ISNUMBER(BD35),ISNUMBER(BE35)),BG35-BC35-BD35-BE35,"") -> 244.5 | BG35: 1060 | BH35: 254.2 | BI35: 204.7 | BJ35: 184.9 | BK35: =IF(AND(ISNUMBER(BL35),ISNUMBER(BH35),ISNUMBER(BI35),ISNUMBER(BJ35)),BL35-BH35-BI35-BJ35,"") -> 166.3 | BL35: 810.1 | BM35: 172.2 | BN35: 227.1 | BO35: 273.7 | BP35: =IF(AND(ISNUMBER(BQ35),ISNUMBER(BM35),ISNUMBER(BN35),ISNUMBER(BO35)),BQ35-BM35-BN35-BO35,"") -> 224.6 | BQ35: 897.6 | BR35: 155.5 | BS35: 158.9 | BT35: 119.9 | BU35: =IF(AND(ISNUMBER(BV35),ISNUMBER(BR35),ISNUMBER(BS35),ISNUMBER(BT35)),BV35-BR35-BS35-BT35,"") -> 113 | BV35: 547.3 | BW35: 142.5 | BX35: 154.6 | CN35: 2028E | CO35: =CP35+$CO$33 -> 0.01 | CP35: 0 | CQ35: =CP35+$CQ$33 -> -0.01
B36: of which: acquisitions, net of divestitures & closed operations | C36: 47.7 | D36: 48.3 | E36: 62.1 | F36: 203.6 | G36: 62.9 | H36: 124.7 | I36: 158.8 | J36: 70.6 | K36: 68.9 | L36: 60.8 | M36: =IF(AND(ISNUMBER(N36),COUNT(J36,K36,L36)>0),N36-N(J36)-N(K36)-N(L36),"") -> 18.5 | N36: 218.8 | O36: 2.8 | P36: 3.7 | Q36: 6.6 | R36: =IF(AND(ISNUMBER(S36),COUNT(O36,P36,Q36)>0),S36-N(O36)-N(P36)-N(Q36),"") -> 8.7 | S36: 21.8 | T36: 13.9 | U36: 11.3 | V36: 11.6 | W36: =IF(AND(ISNUMBER(X36),COUNT(T36,U36,V36)>0),X36-N(T36)-N(U36)-N(V36),"") -> 20.8 | X36: 57.6 | Y36: 21.5 | Z36: 199.4 | AA36: 538.5 | AB36: =IF(AND(ISNUMBER(AC36),COUNT(Y36,Z36,AA36)>0),AC36-N(Y36)-N(Z36)-N(AA36),"") -> 507.3 | AC36: 1266.7 | AD36: 539 | AE36: 386.3 | AF36: 40.2 | AG36: =IF(AND(ISNUMBER(AH36),COUNT(AD36,AE36,AF36)>0),AH36-N(AD36)-N(AE36)-N(AF36),"") -> 37.5 | AH36: 1003 | AI36: 10.8 | AJ36: 32.7 | AK36: 48.1 | AL36: =IF(AND(ISNUMBER(AM36),COUNT(AI36,AJ36,AK36)>0),AM36-N(AI36)-N(AJ36)-N(AK36),"") -> 61.5 | AM36: 153.1 | AN36: 69 | AO36: 77.4 | AP36: 77 | AQ36: =IF(AND(ISNUMBER(AR36),COUNT(AN36,AO36,AP36)>0),AR36-N(AN36)-N(AO36)-N(AP36),"") -> 68.6 | AR36: 292 | AS36: 59.6 | AT36: 40.7 | AU36: 44.3 | AV36: =IF(AND(ISNUMBER(AW36),COUNT(AS36,AT36,AU36)>0),AW36-N(AS36)-N(AT36)-N(AU36),"") -> 52.6 | AW36: 197.2 | AX36: 40.5 | AY36: 44.1 | AZ36: 51.3 | BA36: =IF(AND(ISNUMBER(BB36),COUNT(AX36,AY36,AZ36)>0),BB36-N(AX36)-N(AY36)-N(AZ36),"") -> 79.5 | BB36: 215.4 | BC36: 110 | BD36: 141.4 | BE36: 150.7 | BF36: =IF(AND(ISNUMBER(BG36),COUNT(BC36,BD36,BE36)>0),BG36-N(BC36)-N(BD36)-N(BE36),"") -> 149.9 | BG36: 552 | BH36: 132.1 | BI36: 121.3 | BJ36: 102.9 | BK36: =IF(AND(ISNUMBER(BL36),COUNT(BH36,BI36,BJ36)>0),BL36-N(BH36)-N(BI36)-N(BJ36),"") -> 51 | BL36: 407.3 | BM36: 78 | BN36: 120.8 | BO36: 161 | BP36: =IF(AND(ISNUMBER(BQ36),COUNT(BM36,BN36,BO36)>0),BQ36-N(BM36)-N(BN36)-N(BO36),"") -> 169.2 | BQ36: 529 | BR36: 112.1 | BS36: 95.3 | BT36: 62.2 | BU36: =IF(AND(ISNUMBER(BV36),COUNT(BR36,BS36,BT36)>0),BV36-N(BR36)-N(BS36)-N(BT36),"") -> 48.2 | BV36: 317.8 | BW36: 55.2 | BX36: 45.8 | CN36: 2029E | CO36: =CP36+$CO$33 -> 0.015 | CP36: 0.005 | CQ36: =CP36+$CQ$33 -> -0.005
B37: of which: solid waste core price (total price incl. surcharges 2006–08) | C37: 37.2 | D37: 38.2 | E37: 53.6 | F37: 49.6 | G37: 31.8 | H37: 36.7 | I37: 45.1 | J37: 10.5 | K37: 10.8 | L37: 10.2 | M37: =IF(AND(ISNUMBER(N37),COUNT(J37,K37,L37)>0),N37-N(J37)-N(K37)-N(L37),"") -> 10.7 | N37: 42.2 | O37: 11.3 | P37: 11 | Q37: 12.1 | R37: =IF(AND(ISNUMBER(S37),COUNT(O37,P37,Q37)>0),S37-N(O37)-N(P37)-N(Q37),"") -> 12.2 | S37: 46.6 | T37: 11.7 | U37: 12.7 | V37: 12.7 | W37: =IF(AND(ISNUMBER(X37),COUNT(T37,U37,V37)>0),X37-N(T37)-N(U37)-N(V37),"") -> 12.9 | X37: 50 | Y37: 13.4 | Z37: 13.7 | AA37: 12.6 | AB37: =IF(AND(ISNUMBER(AC37),COUNT(Y37,Z37,AA37)>0),AC37-N(Y37)-N(Z37)-N(AA37),"") -> 12.9 | AC37: 52.6 | AD37: 12.4 | AE37: 20.5 | AF37: 32.6 | AG37: =IF(AND(ISNUMBER(AH37),COUNT(AD37,AE37,AF37)>0),AH37-N(AD37)-N(AE37)-N(AF37),"") -> 32.7 | AH37: 98.2 | AI37: 40.2 | AJ37: 42.1 | AK37: 43.4 | AL37: =IF(AND(ISNUMBER(AM37),COUNT(AI37,AJ37,AK37)>0),AM37-N(AI37)-N(AJ37)-N(AK37),"") -> 46.5 | AM37: 172.2 | AN37: 52 | AO37: 56.3 | AP37: 60.1 | AQ37: =IF(AND(ISNUMBER(AR37),COUNT(AN37,AO37,AP37)>0),AR37-N(AN37)-N(AO37)-N(AP37),"") -> 62.1 | AR37: 230.5 | AS37: 63 | AT37: 57.1 | AU37: 53.8 | AV37: =IF(AND(ISNUMBER(AW37),COUNT(AS37,AT37,AU37)>0),AW37-N(AS37)-N(AT37)-N(AU37),"") -> 53.8 | AW37: 227.7 | AX37: 55.9 | AY37: 58.3 | AZ37: 62 | BA37: =IF(AND(ISNUMBER(BB37),COUNT(AX37,AY37,AZ37)>0),BB37-N(AX37)-N(AY37)-N(AZ37),"") -> 67.3 | BB37: 243.5 | BC37: 83.5 | BD37: 105.6 | BE37: 126.3 | BF37: =IF(AND(ISNUMBER(BG37),COUNT(BC37,BD37,BE37)>0),BG37-N(BC37)-N(BD37)-N(BE37),"") -> 140.4 | BG37: 455.8 | BH37: 171.2 | BI37: 168.5 | BJ37: 156.6 | BK37: =IF(AND(ISNUMBER(BL37),COUNT(BH37,BI37,BJ37)>0),BL37-N(BH37)-N(BI37)-N(BJ37),"") -> 154.8 | BL37: 651.1 | BM37: 140.6 | BN37: 135.7 | BO37: 132.9 | BP37: =IF(AND(ISNUMBER(BQ37),COUNT(BM37,BN37,BO37)>0),BQ37-N(BM37)-N(BN37)-N(BO37),"") -> 129.8 | BQ37: 539 | BR37: 133.2 | BS37: 136.9 | BT37: 134.3 | BU37: =IF(AND(ISNUMBER(BV37),COUNT(BR37,BS37,BT37)>0),BV37-N(BR37)-N(BS37)-N(BT37),"") -> 132.6 | BV37: 537 | BW37: 121.3 | BX37: 121.8 | CN37: 2030E | CO37: =CP37+$CO$33 -> 0.015 | CP37: 0.005 | CQ37: =CP37+$CQ$33 -> -0.005
B38: of which: surcharges | F38: -21.9 | G38: 2.6 | H38: 10.3 | I38: 2.4 | J38: 1.5 | K38: 0.9 | L38: 1.2 | M38: =IF(AND(ISNUMBER(N38),COUNT(J38,K38,L38)>0),N38-N(J38)-N(K38)-N(L38),"") -> 0.9 | N38: 4.5 | O38: 0.3 | Q38: 0.3 | R38: =IF(AND(ISNUMBER(S38),COUNT(O38,P38,Q38)>0),S38-N(O38)-N(P38)-N(Q38),"") -> 0.1 | S38: 0.7 | U38: -0.4 | V38: -1 | W38: =IF(AND(ISNUMBER(X38),COUNT(T38,U38,V38)>0),X38-N(T38)-N(U38)-N(V38),"") -> -2.2 | X38: -3.6 | Y38: -1.7 | Z38: -1.5 | AA38: -1.3 | AB38: =IF(AND(ISNUMBER(AC38),COUNT(Y38,Z38,AA38)>0),AC38-N(Y38)-N(Z38)-N(AA38),"") -> -0.2 | AC38: -4.7 | AD38: 0.2 | AE38: 0.4 | AF38: 0.2 | AG38: =IF(AND(ISNUMBER(AH38),COUNT(AD38,AE38,AF38)>0),AH38-N(AD38)-N(AE38)-N(AF38),"") -> 1 | AH38: 1.8 | AI38: 2.1 | AJ38: 3.5 | AK38: 6.1 | AL38: =IF(AND(ISNUMBER(AM38),COUNT(AI38,AJ38,AK38)>0),AM38-N(AI38)-N(AJ38)-N(AK38),"") -> 4.7 | AM38: 16.4 | AN38: 2.8 | AO38: 2.2 | AP38: 1 | AQ38: =IF(AND(ISNUMBER(AR38),COUNT(AN38,AO38,AP38)>0),AR38-N(AN38)-N(AO38)-N(AP38),"") -> 0.5 | AR38: 6.5 | AS38: 1.5 | AT38: -2.7 | AU38: -4.7 | AV38: =IF(AND(ISNUMBER(AW38),COUNT(AS38,AT38,AU38)>0),AW38-N(AS38)-N(AT38)-N(AU38),"") -> -5.8 | AW38: -11.7 | AX38: -3.7 | AY38: 2.6 | AZ38: 5.7 | BA38: =IF(AND(ISNUMBER(BB38),COUNT(AX38,AY38,AZ38)>0),BB38-N(AX38)-N(AY38)-N(AZ38),"") -> 9.1 | BB38: 13.7 | BC38: 10.5 | BD38: 23 | BE38: 27.9 | BF38: =IF(AND(ISNUMBER(BG38),COUNT(BC38,BD38,BE38)>0),BG38-N(BC38)-N(BD38)-N(BE38),"") -> 24.5 | BG38: 85.9 | BH38: 12.3 | BI38: -12.7 | BJ38: -19.2 | BK38: =IF(AND(ISNUMBER(BL38),COUNT(BH38,BI38,BJ38)>0),BL38-N(BH38)-N(BI38)-N(BJ38),"") -> -14.9 | BL38: -34.5 | BM38: -12.1 | BN38: -4.5 | BO38: -5.2 | BP38: =IF(AND(ISNUMBER(BQ38),COUNT(BM38,BN38,BO38)>0),BQ38-N(BM38)-N(BN38)-N(BO38),"") -> -10.8 | BQ38: -32.6 | BR38: -3.7 | BS38: -4.1 | BT38: -2.2 | BU38: =IF(AND(ISNUMBER(BV38),COUNT(BR38,BS38,BT38)>0),BV38-N(BR38)-N(BS38)-N(BT38),"") -> -0.4 | BV38: -10.4 | BW38: -1.3 | BX38: 24.5 | CN38: EP_g (E&P waste revenues y/y) | CO38: 0.06 | CP38: Δ → | CQ38: -0.06 | CR38: E&P gross revenues +18% y/y in Q2/26 (Permian / Bakken activity, acquired E&P facilities); oil-price sensitive.
B39: of which: solid waste volume | C39: 20 | D39: 12.6 | E39: -22.2 | F39: -64.2 | G39: 0.5 | H39: -3.9 | I39: -31.4 | J39: -7.1 | K39: 3.3 | L39: 8.1 | M39: =IF(AND(ISNUMBER(N39),COUNT(J39,K39,L39)>0),N39-N(J39)-N(K39)-N(L39),"") -> 9.4 | N39: 13.7 | O39: 9.7 | P39: 6.3 | Q39: 9.1 | R39: =IF(AND(ISNUMBER(S39),COUNT(O39,P39,Q39)>0),S39-N(O39)-N(P39)-N(Q39),"") -> 10 | S39: 35.1 | T39: 6.5 | U39: 10.5 | V39: 11.8 | W39: =IF(AND(ISNUMBER(X39),COUNT(T39,U39,V39)>0),X39-N(T39)-N(U39)-N(V39),"") -> 10.7 | X39: 39.5 | Y39: 14.1 | Z39: 11.7 | AA39: 5.5 | AB39: =IF(AND(ISNUMBER(AC39),COUNT(Y39,Z39,AA39)>0),AC39-N(Y39)-N(Z39)-N(AA39),"") -> 5.2 | AC39: 36.5 | AD39: 10 | AE39: 13.6 | AF39: 5 | AG39: =IF(AND(ISNUMBER(AH39),COUNT(AD39,AE39,AF39)>0),AH39-N(AD39)-N(AE39)-N(AF39),"") -> 7.1 | AH39: 35.7 | AI39: -11.2 | AJ39: -15.6 | AK39: -1.4 | AL39: =IF(AND(ISNUMBER(AM39),COUNT(AI39,AJ39,AK39)>0),AM39-N(AI39)-N(AJ39)-N(AK39),"") -> 1.5 | AM39: -26.7 | AN39: -12.6 | AO39: 9.3 | AP39: 10.3 | AQ39: =IF(AND(ISNUMBER(AR39),COUNT(AN39,AO39,AP39)>0),AR39-N(AN39)-N(AO39)-N(AP39),"") -> -15.9 | AR39: -8.9 | AS39: -4 | AT39: -121.2 | AU39: -74.6 | AV39: =IF(AND(ISNUMBER(AW39),COUNT(AS39,AT39,AU39)>0),AW39-N(AS39)-N(AT39)-N(AU39),"") -> -39 | AW39: -238.8 | AX39: -40.5 | AY39: 80.2 | AZ39: 28.9 | BA39: =IF(AND(ISNUMBER(BB39),COUNT(AX39,AY39,AZ39)>0),BB39-N(AX39)-N(AY39)-N(AZ39),"") -> 16.4 | BB39: 85 | BC39: 7 | BD39: -10.4 | BE39: -22.3 | BF39: =IF(AND(ISNUMBER(BG39),COUNT(BC39,BD39,BE39)>0),BG39-N(BC39)-N(BD39)-N(BE39),"") -> -37.5 | BG39: -63.2 | BH39: -20.5 | BI39: -32.9 | BJ39: -42 | BK39: =IF(AND(ISNUMBER(BL39),COUNT(BH39,BI39,BJ39)>0),BL39-N(BH39)-N(BI39)-N(BJ39),"") -> -41.6 | BL39: -137 | BM39: -69.6 | BN39: -54.2 | BO39: -37.7 | BP39: =IF(AND(ISNUMBER(BQ39),COUNT(BM39,BN39,BO39)>0),BQ39-N(BM39)-N(BN39)-N(BO39),"") -> -61 | BQ39: -222.5 | BR39: -65.9 | BS39: -56.2 | BT39: -59.4 | BU39: =IF(AND(ISNUMBER(BV39),COUNT(BR39,BS39,BT39)>0),BV39-N(BR39)-N(BS39)-N(BT39),"") -> -56.5 | BV39: -238 | BW39: -57.9 | BX39: -64.1 | CN39: 2027E | CO39: =CP39+$CO$38 -> 0.12 | CP39: 0.06 | CQ39: =CP39+$CQ$38 -> 0
B40: of which: recycled commodities (incl. recycling-facility closures) | D40: 13 | E40: -3.3 | F40: -15.5 | G40: 24.6 | H40: 14 | I40: -20 | J40: -2.4 | K40: -3.3 | L40: -0.2 | M40: =IF(AND(ISNUMBER(N40),COUNT(J40,K40,L40)>0),N40-N(J40)-N(K40)-N(L40),"") -> -2 | N40: -7.9 | O40: -2.7 | P40: -2.5 | Q40: -2.3 | R40: =IF(AND(ISNUMBER(S40),COUNT(O40,P40,Q40)>0),S40-N(O40)-N(P40)-N(Q40),"") -> -2.3 | S40: -9.8 | T40: -3.5 | U40: -2.3 | V40: -2.4 | W40: =IF(AND(ISNUMBER(X40),COUNT(T40,U40,V40)>0),X40-N(T40)-N(U40)-N(V40),"") -> -1.7 | X40: -9.9 | Y40: -0.9 | Z40: -0.6 | AA40: 1.8 | AB40: =IF(AND(ISNUMBER(AC40),COUNT(Y40,Z40,AA40)>0),AC40-N(Y40)-N(Z40)-N(AA40),"") -> 1.9 | AC40: 2.2 | AD40: 7.1 | AE40: 7.6 | AF40: 7.9 | AG40: =IF(AND(ISNUMBER(AH40),COUNT(AD40,AE40,AF40)>0),AH40-N(AD40)-N(AE40)-N(AF40),"") -> -3.1 | AH40: 19.5 | AI40: -18.8 | AJ40: -19.7 | AK40: -19.5 | AL40: =IF(AND(ISNUMBER(AM40),COUNT(AI40,AJ40,AK40)>0),AM40-N(AI40)-N(AJ40)-N(AK40),"") -> -8.3 | AM40: -66.3 | AN40: -5.3 | AO40: -7.1 | AP40: -9.5 | AQ40: =IF(AND(ISNUMBER(AR40),COUNT(AN40,AO40,AP40)>0),AR40-N(AN40)-N(AO40)-N(AP40),"") -> -10 | AR40: -31.9 | AS40: -4.4 | AT40: -0.5 | AU40: 2.4 | AV40: =IF(AND(ISNUMBER(AW40),COUNT(AS40,AT40,AU40)>0),AW40-N(AS40)-N(AT40)-N(AU40),"") -> 6.8 | AW40: 4.3 | AX40: 11.3 | AY40: 18 | AZ40: 28.3 | BA40: =IF(AND(ISNUMBER(BB40),COUNT(AX40,AY40,AZ40)>0),BB40-N(AX40)-N(AY40)-N(AZ40),"") -> 35.1 | BB40: 92.7 | BC40: 15 | BD40: 5.7 | BE40: -19.5 | BF40: =IF(AND(ISNUMBER(BG40),COUNT(BC40,BD40,BE40)>0),BG40-N(BC40)-N(BD40)-N(BE40),"") -> -46.2 | BG40: -45 | BH40: -29.9 | BI40: -25.8 | BJ40: -9.5 | BK40: =IF(AND(ISNUMBER(BL40),COUNT(BH40,BI40,BJ40)>0),BL40-N(BH40)-N(BI40)-N(BJ40),"") -> 13.9 | BL40: -51.3 | BM40: 15.3 | BN40: 15.2 | BO40: 19.2 | BP40: =IF(AND(ISNUMBER(BQ40),COUNT(BM40,BN40,BO40)>0),BQ40-N(BM40)-N(BN40)-N(BO40),"") -> 4.3 | BQ40: 54 | BR40: -2.1 | BS40: -7 | BT40: -17.1 | BU40: =IF(AND(ISNUMBER(BV40),COUNT(BR40,BS40,BT40)>0),BV40-N(BR40)-N(BS40)-N(BT40),"") -> -11.5 | BV40: -37.7 | BW40: -9.2 | BX40: -4.8 | CN40: 2028E | CO40: =CP40+$CO$38 -> 0.11 | CP40: 0.05 | CQ40: =CP40+$CQ$38 -> -0.01
...

Sheet Bull-Base-Bear
B2: Waste Connections (WCN) — Bull / Base / Bear Case P&L Summary | J2: Share price ($): | K2: =Model!$CA$425 -> 155
B3: Adjusted figures (company definitions: Adjusted EBITDA, adjusted net income / adjusted EPS, adjusted free cash flow) · USD millions · Live panel linked to Model — toggle scenario via Model!CF2. Bull and Bear panels are value snapshots generated from the Model with the switch set to each case. 2026E calibrated to the FY26 outlook (Q2-26 release) end-points. | J3: As of: | K3: =TODAY() -> 46301
B5: Scenario: | C5: =Model!$CF$2 -> Base | N5: Scenario: | O5: Bull | P5: Snapshot (values) — Model run with switch = Bull | Z5: Scenario: | AA5: Bear | AB5: Snapshot (values) — Model run with switch = Bear
B7: (USDm, except EPS and shares) | C7: 2025A | D7: 2026E | E7: 2027E | F7: 2028E | G7: 2029E | H7: 2030E | I7: 25-'30 CAGR | J7: LT Hist Avg | K7: LT Hist Min | L7: LT Hist Max | N7: (USDm, except EPS and shares) | O7: 2025A | P7: 2026E | Q7: 2027E | R7: 2028E | S7: 2029E | T7: 2030E | U7: 25-'30 CAGR | V7: LT Hist Avg | W7: LT Hist Min | X7: LT Hist Max | Z7: (USDm, except EPS and shares) | AA7: 2025A | AB7: 2026E | AC7: 2027E | AD7: 2028E | AE7: 2029E | AF7: 2030E | AG7: 25-'30 CAGR | AH7: LT Hist Avg | AI7: LT Hist Min | AJ7: LT Hist Max
B9: Revenues | C9: =Model!BV128 -> 9466.915 | D9: =Model!CA128 -> 10035 | E9: =Model!CB128 -> 10653.27 | F9: =Model!CC128 -> 11506.962 | G9: =Model!CD128 -> 12417.963 | H9: =Model!CE128 -> 13346.873 | I9: =IFERROR((H9/C9)^(1/5)-1,"n/m") -> 0.071110343 | N9: Revenues | O9: 9466.915 | P9: 10050 | Q9: 10962.545 | R9: 12234.637 | S9: 13599.884 | T9: 15020.35 | U9: 0.096716342 | Z9: Revenues | AA9: 9466.915 | AB9: 10020 | AC9: 10344.596 | AD9: 10791.266 | AE9: 11271.713 | AF9: 11746.596 | AG9: 0.044096667
B10: Revenues y/y % | D10: =IFERROR(D9/C9-1,"") -> 0.060007405 | E10: =IFERROR(E9/D9-1,"") -> 0.061611395 | F10: =IFERROR(F9/E9-1,"") -> 0.080134219 | G10: =IFERROR(G9/F9-1,"") -> 0.079169584 | H10: =IFERROR(H9/G9-1,"") -> 0.074803753 | N10: Revenues y/y % | P10: 0.06159187 | Q10: 0.090800449 | R10: 0.11603993 | S10: 0.1115886 | T10: 0.10444695 | Z10: Revenues y/y % | AB10: 0.058422939 | AC10: 0.032394787 | AD10: 0.043179086 | AE10: 0.04452183 | AF10: 0.042130505
B11: Solid waste revenues y/y % (organic from 2027E) | C11: =Model!BV20 -> 0.053798421 | D11: =Model!CA20 -> 0.049051806 | E11: =Model!CB20 -> 0.0425 | F11: =Model!CC20 -> 0.045 | G11: =Model!CD20 -> 0.0475 | H11: =Model!CE20 -> 0.045 | N11: Solid waste revenues y/y % (organic from 2027E) | O11: 0.053798421 | P11: 0.050638686 | Q11: 0.06 | R11: 0.0625 | S11: 0.065 | T11: 0.0625 | Z11: Solid waste revenues y/y % (organic from 2027E) | AA11: 0.053798421 | AB11: 0.047464926 | AC11: 0.025 | AD11: 0.0275 | AE11: 0.03 | AF11: 0.0275
B12: Adjusted EBITDA | C12: =Model!BV180 -> 3124.555 | D12: =Model!CA180 -> 3335 | E12: =Model!CB180 -> 3573.6807 | F12: =Model!CC180 -> 3870.1895 | G12: =Model!CD180 -> 4187.3839 | H12: =Model!CE180 -> 4511.9817 | I12: =IFERROR((H12/C12)^(1/5)-1,"n/m") -> 0.07625661 | N12: Adjusted EBITDA | O12: 3124.555 | P12: 3340 | Q12: 3754.8613 | R12: 4191.9809 | S12: 4663.023 | T12: 5155.0519 | U12: 0.10532241 | Z12: Adjusted EBITDA | AA12: 3124.555 | AB12: 3330 | AC12: 3395.9724 | AD12: 3559.0452 | AE12: 3734.0998 | AF12: 3908.1074 | AG12: 0.045768759
B13: Adjusted EBITDA margin % | C13: =IFERROR(C12/C9,"") -> 0.33004997 | D13: =IFERROR(D12/D9,"") -> 0.33233682 | E13: =IFERROR(E12/E9,"") -> 0.33545386 | F13: =IFERROR(F12/F9,"") -> 0.33633461 | G13: =IFERROR(G12/G9,"") -> 0.33720376 | H13: =IFERROR(H12/H9,"") -> 0.33805533 | J13: =IFERROR(AVERAGE(Model!C181,Model!D181,Model!E181,Model!F181,Model!G181,Model!H181,Model!I181,Model!N181,Model!S181,Model!X181,Model!AC181,Model!AH181,Model!AM181,Model!AR181,Model!AW181,Model!BB181,Model!BG181,Model!BL181,Model!BQ181,Model!BV181),"") -> 0.31777802 | K13: =IFERROR(MIN(Model!C181,Model!D181,Model!E181,Model!F181,Model!G181,Model!H181,Model!I181,Model!N181,Model!S181,Model!X181,Model!AC181,Model!AH181,Model!AM181,Model!AR181,Model!AW181,Model!BB181,Model!BG181,Model!BL181,Model!BQ181,Model!BV181),"") -> 0.29850715 | L13: =IFERROR(MAX(Model!C181,Model!D181,Model!E181,Model!F181,Model!G181,Model!H181,Model!I181,Model!N181,Model!S181,Model!X181,Model!AC181,Model!AH181,Model!AM181,Model!AR181,Model!AW181,Model!BB181,Model!BG181,Model!BL181,Model!BQ181,Model!BV181),"") -> 0.34488733 | N13: Adjusted EBITDA margin % | O13: 0.33004997 | P13: 0.33233831 | Q13: 0.34251732 | R13: 0.34263221 | S13: 0.34287227 | T13: 0.34320452 | V13: 0.31777802 | W13: 0.29850715 | X13: 0.34488733 | Z13: Adjusted EBITDA margin % | AA13: 0.33004997 | AB13: 0.33233533 | AC13: 0.32828469 | AD13: 0.32980794 | AE13: 0.3312806 | AF13: 0.33270128 | AH13: 0.31777802 | AI13: 0.29850715 | AJ13: 0.34488733
B15: Operating Income (GAAP) | C15: =Model!BV134 -> 1710.174 | D15: =Model!CA134 -> 1843.663 | E15: =Model!CB134 -> 2159.8727 | F15: =Model!CC134 -> 2353.2252 | G15: =Model!CD134 -> 2561.0735 | H15: =Model!CE134 -> 2773.6868 | I15: =IFERROR((H15/C15)^(1/5)-1,"n/m") -> 0.10154799 | N15: Operating Income (GAAP) | O15: 1710.174 | P15: 1848.663 | Q15: 2301.146 | R15: 2578.5021 | S15: 2879.6695 | T15: 3195.1049 | U15: 0.13315408 | Z15: Operating Income (GAAP) | AA15: 1710.174 | AB15: 1838.663 | AC15: 2022.003 | AD15: 2137.2178 | AE15: 2260.7305 | AF15: 2383.0467 | AG15: 0.068608069
B16: Operating income y/y % | D16: =IFERROR(D15/C15-1,"") -> 0.0780558 | E16: =IFERROR(E15/D15-1,"") -> 0.17151168 | F16: =IFERROR(F15/E15-1,"") -> 0.089520307 | G16: =IFERROR(G15/F15-1,"") -> 0.088324876 | H16: =IFERROR(H15/G15-1,"") -> 0.083017232 | N16: Operating income y/y % | P16: 0.080979479 | Q16: 0.24476228 | R16: 0.12052958 | S16: 0.11679936 | T16: 0.10953876 | Z16: Operating income y/y % | AB16: 0.075132121 | AC16: 0.099713767 | AD16: 0.056980528 | AE16: 0.057791343 | AF16: 0.054104704
B17: Operating margin (GAAP) % | C17: =IFERROR(C15/C9,"") -> 0.18064744 | D17: =IFERROR(D15/D9,"") -> 0.18372327 | E17: =IFERROR(E15/E9,"") -> 0.2027427 | F17: =IFERROR(F15/F9,"") -> 0.20450448 | G17: =IFERROR(G15/G9,"") -> 0.20623942 | H17: =IFERROR(H15/H9,"") -> 0.20781547 | J17: =IFERROR(AVERAGE(Model!C227,Model!D227,Model!E227,Model!F227,Model!G227,Model!H227,Model!I227,Model!N227,Model!S227,Model!X227,Model!AC227,Model!AH227,Model!AM227,Model!AR227,Model!AW227,Model!BB227,Model!BG227,Model!BL227,Model!BQ227,Model!BV227),"") -> 0.16420594 | K17: =IFERROR(MIN(Model!C227,Model!D227,Model!E227,Model!F227,Model!G227,Model!H227,Model!I227,Model!N227,Model!S227,Model!X227,Model!AC227,Model!AH227,Model!AM227,Model!AR227,Model!AW227,Model!BB227,Model!BG227,Model!BL227,Model!BQ227,Model!BV227),"") -> -0.029061719 | L17: =IFERROR(MAX(Model!C227,Model!D227,Model!E227,Model!F227,Model!G227,Model!H227,Model!I227,Model!N227,Model!S227,Model!X227,Model!AC227,Model!AH227,Model!AM227,Model!AR227,Model!AW227,Model!BB227,Model!BG227,Model!BL227,Model!BQ227,Model!BV227),"") -> 0.21608135 | N17: Operating margin (GAAP) % | O17: 0.18064744 | P17: 0.18394657 | Q17: 0.20990984 | R17: 0.21075427 | S17: 0.21174222 | T17: 0.21271841 | V17: 0.16420594 | W17: -0.029061719 | X17: 0.21608135 | Z17: Operating margin (GAAP) % | AA17: 0.18064744 | AB17: 0.1834993 | AC17: 0.19546467 | AD17: 0.1980507 | AE17: 0.20056672 | AF17: 0.20287126 | AH17: 0.16420594 | AI17: -0.029061719 | AJ17: 0.21608135
B19: Adjusted Net Income (attributable to WCN) | C19: =Model!BV206 -> 1328.334 | D19: =Model!CA206 -> 1427.4655 | E19: =Model!CB206 -> 1514.3873 | F19: =Model!CC206 -> 1643.7109 | G19: =Model!CD206 -> 1777.359 | H19: =Model!CE206 -> 1913.5626 | I19: =IFERROR((H19/C19)^(1/5)-1,"n/m") -> 0.075739403 | N19: Adjusted Net Income (attributable to WCN) | O19: 1328.334 | P19: 1431.3105 | Q19: 1620.872 | R19: 1783.116 | S19: 1981.2305 | T19: 2187.6904 | U19: 0.10493241 | Z19: Adjusted Net Income (attributable to WCN) | AA19: 1328.334 | AB19: 1423.6205 | AC19: 1410.4893 | AD19: 1508.1818 | AE19: 1581.3742 | AF19: 1653.451 | AG19: 0.044760651
B21: FDSO (m) | C21: =Model!BV153 -> 257.97674 | D21: =Model!CA153 -> 253.7157 | E21: =Model!CB153 -> 247.34321 | F21: =Model!CC153 -> 241.24552 | G21: =Model!CD153 -> 234.73886 | H21: =Model!CE153 -> 228.02568 | I21: =IFERROR((H21/C21)^(1/5)-1,"n/m") -> -0.024380122 | N21: FDSO (m) | O21: 257.97674 | P21: 253.39312 | Q21: 243.38563 | R21: 234.0843 | S21: 226.24249 | T21: 217.69864 | U21: -0.033381655 | Z21: FDSO (m) | AA21: 257.97674 | AB21: 254.03828 | AC21: 250.99409 | AD21: 247.5293 | AE21: 241.7867 | AF21: 236.24446 | AG21: -0.017446481
B23: Adjusted EPS — Diluted ($) | C23: =Model!BV210 -> 5.1490456 | D23: =Model!CA210 -> 5.6262405 | E23: =Model!CB210 -> 6.1226153 | F23: =Model!CC210 -> 6.8134358 | G23: =Model!CD210 -> 7.5716434 | H23: =Model!CE210 -> 8.3918733 | I23: =IFERROR((H23/C23)^(1/5)-1,"n/m") -> 0.10262145 | N23: Adjusted EPS — Diluted ($) | O23: 5.1490456 | P23: 5.648577 | Q23: 6.6596863 | R23: 7.6174097 | S23: 8.7571107 | T23: 10.049169 | U23: 0.14309067 | Z23: Adjusted EPS — Diluted ($) | AA23: 5.1490456 | AB23: 5.6039607 | AC23: 5.6196118 | AD23: 6.0929427 | AE23: 6.5403686 | AF23: 6.9988985 | AG23: 0.063311698
B24: EPS y/y % | D24: =IFERROR(D23/C23-1,"") -> 0.092676381 | E24: =IFERROR(E23/D23-1,"") -> 0.088224955 | F24: =IFERROR(F23/E23-1,"") -> 0.11283094 | G24: =IFERROR(G23/F23-1,"") -> 0.11128124 | H24: =IFERROR(H23/G23-1,"") -> 0.10832917 | N24: EPS y/y % | P24: 0.09701437 | Q24: 0.17900249 | R24: 0.14380908 | S24: 0.14961792 | T24: 0.14754387 | Z24: EPS y/y % | AB24: 0.088349409 | AC24: 0.0027928581 | AD24: 0.084228398 | AE24: 0.073433475 | AF24: 0.07010765
B26: P / E (x) — assumed (adjusted EPS) | F26: 30 | G26: 30 | H26: 30 | N26: P / E (x) — assumed (adjusted EPS) | R26: 34 | S26: 34 | T26: 34 | Z26: P / E (x) — assumed (adjusted EPS) | AD26: 24 | AE26: 24 | AF26: 24
B27: Price Target ($) | F27: =F26*F23 -> 204.40307 | G27: =G26*G23 -> 227.1493 | H27: =H26*H23 -> 251.7562 | N27: Price Target ($) | R27: =R26*R23 -> 258.99193 | S27: =S26*S23 -> 297.74176 | T27: =T26*T23 -> 341.67174 | Z27: Price Target ($) | AD27: =AD26*AD23 -> 146.23062 | AE27: =AE26*AE23 -> 156.96885 | AF27: =AF26*AF23 -> 167.97356
B28: Upside / (Downside) vs current | F28: =IFERROR(F27/$K$2-1,"") -> 0.31872951 | G28: =IFERROR(G27/$K$2-1,"") -> 0.46547937 | H28: =IFERROR(H27/$K$2-1,"") -> 0.62423354 | N28: Upside / (Downside) vs current | R28: =IFERROR(R27/$K$2-1,"") -> 0.67091567 | S28: =IFERROR(S27/$K$2-1,"") -> 0.9209146 | T28: =IFERROR(T27/$K$2-1,"") -> 1.2043338 | Z28: Upside / (Downside) vs current | AD28: =IFERROR(AD27/$K$2-1,"") -> -0.056576616 | AE28: =IFERROR(AE27/$K$2-1,"") -> 0.012702241 | AF28: =IFERROR(AF27/$K$2-1,"") -> 0.083700416
