Workbook

Sheet Model
AV1: SCENARIO SWITCH ▼ (Bull / Base / Bear) — drives all scenario-linked forecast drivers
B2: Woodward, Inc. (NASDAQ: WWD) — 3-Statement Financial Model | AV2: Base
B3: US GAAP as reported · USD millions (per-share data in USD; shares in millions) · Fiscal years ended 30 September (2026 = Oct-2025 – Sep-2026) · Source: Woodward Forms 10-K / 10-Q, Form 8-K earnings releases (Ex. 99.1) and deal / financing 8-Ks, SEC EDGAR (CIK 108312); XBRL company facts; investor-relations releases at woodward.com are the same documents as filed on EDGAR
B4: Basis notes: as originally reported (FY2016 and FY2018 reclassifications not recast; FY2018 restated segment earnings in memo rows). Segments: Aerospace, Industrial (Energy to FY2015). Acquisitions: L'Orange Jun-18, Safran EMA Jul-25, Valve Research Apr-26; divestitures: renewable power systems May-20, product lines FY25, pilot controls (ONTIC, pending FY27). Q4/26E calibrated to FY26 sales-growth and adjusted-EPS guidance (29-Jul-2026).
AX5: Forecast | AY5: Historical | AZ5: Historical | BA5: Historical
B6: (USDm) | C6: 2011 | D6: 2012 | E6: 2013 | F6: 2014 | G6: 2015 | H6: 2016 | I6: 2017 | J6: 2018 | K6: 2019 | L6: 2020 | M6: Q1/21 | N6: Q2/21 | O6: Q3/21 | P6: Q4/21 | Q6: 2021 | R6: Q1/22 | S6: Q2/22 | T6: Q3/22 | U6: Q4/22 | V6: 2022 | W6: Q1/23 | X6: Q2/23 | Y6: Q3/23 | Z6: Q4/23 | AA6: 2023 | AB6: Q1/24 | AC6: Q2/24 | AD6: Q3/24 | AE6: Q4/24 | AF6: 2024 | AG6: Q1/25 | AH6: Q2/25 | AI6: Q3/25 | AJ6: Q4/25 | AK6: 2025 | AL6: Q1/26 | AM6: Q2/26 | AN6: Q3/26 | AO6: Q4/26E | AP6: 2026E | AQ6: 2027E | AR6: 2028E | AS6: 2029E | AT6: 2030E | AU6: 2031E | AV6: Modelling Notes | AX6: 5Y CAGR | AY6: 5Y CAGR | AZ6: 10Y CAGR | BA6: 14Y CAGR
AX7: 26-'31 | AY7: 20-'25 | AZ7: 15-'25 | BA7: 11-'25
B8: SEGMENT P&L — AEROSPACE · INDUSTRIAL (sales by primary market × segment earnings margin) | AV8: SEGMENT BUILD — modelling logic (sales by primary market → segment sales → segment earnings at the segment margin → + adjusted nonsegment expenses = adjusted EBIT → GAAP P&L)
BD9: SCENARIO INPUT TABLE — driver assumptions per Bull / Base / Bear | BE9: Bull | BF9: Base | BG9: Bear | BH9: Bull / Bear = Base + Δ (Δ inputs on each block header). Outlook block = high / mid / low end of the FY26 guidance ranges.
B10: Aerospace (fuel, combustion, actuation, motion & flight-control systems for commercial and defense aircraft, guided weapons; OEM and aftermarket) | AV10: AEROSPACE — modelling logic
B11: Commercial OEM sales | K11: 659.336 | L11: 434.306 | M11: 76.081 | N11: 101.907 | O11: 96.29 | P11: 112.265 | Q11: 386.543 | R11: 104.826 | S11: 122.889 | T11: 131.968 | U11: 139.755 | V11: 499.438 | W11: 138.875 | X11: 159.271 | Y11: 186.173 | Z11: 166.956 | AA11: 651.275 | AB11: 171.354 | AC11: 183.517 | AD11: 189.697 | AE11: 193.826 | AF11: 738.394 | AG11: 154.076 | AH11: 167.461 | AI11: 175.226 | AJ11: 194.199 | AK11: 690.962 | AL11: 187.939 | AM11: 218.015 | AN11: 234.398 | AO11: =AJ11*(1+AO12) -> 230.99782 | AP11: =SUM(AL11:AO11) -> 871.34982 | AQ11: =AP11*(1+AQ12) -> 993.33879 | AR11: =AQ11*(1+AR12) -> 1102.6061 | AS11: =AR11*(1+AS12) -> 1201.8406 | AT11: =AS11*(1+AT12) -> 1285.9695 | AU11: =AT11*(1+AU12) -> 1363.1276 | AV11: Sales by primary market (10-Q / 10-K revenue-disaggregation note, from FY2019; Q4 = fiscal year − nine months). Q4/26E: prior-year quarter × (1 + growth). 2027E+: prior year × (1 + scenario lever). | AX11: =IFERROR((AU11/AP11)^(1/5)-1,"n/m") -> 0.093625918 | AY11: =IFERROR((AK11/L11)^(1/5)-1,"n/m") -> 0.097315887 | AZ11: =IFERROR((AK11/G11)^(1/10)-1,"n/m") -> n/m | BA11: =IFERROR((AK11/C11)^(1/14)-1,"n/m") -> n/m | BD11: FY26 guidance — Q3 FY26 release (29-Jul-2026) | BE11: High | BF11: Mid | BG11: Low | BH11: Sales growth +20–23% (unchanged), adjusted EPS $9.30–9.50 (raised from $9.15–9.45), FCF $300–350m, capex ~$290m, ~61.5m shares, adjusted tax rate ~22.5%; Aerospace sales +21–23% at ~23.5% segment margin; Industrial sales +19–21% at ~19%.
B12: y/y % | D12: =IF(AND(ISNUMBER(D11),ISNUMBER(C11)),IFERROR(D11/C11-1,""),"") | E12: =IF(AND(ISNUMBER(E11),ISNUMBER(D11)),IFERROR(E11/D11-1,""),"") | F12: =IF(AND(ISNUMBER(F11),ISNUMBER(E11)),IFERROR(F11/E11-1,""),"") | G12: =IF(AND(ISNUMBER(G11),ISNUMBER(F11)),IFERROR(G11/F11-1,""),"") | H12: =IF(AND(ISNUMBER(H11),ISNUMBER(G11)),IFERROR(H11/G11-1,""),"") | I12: =IF(AND(ISNUMBER(I11),ISNUMBER(H11)),IFERROR(I11/H11-1,""),"") | J12: =IF(AND(ISNUMBER(J11),ISNUMBER(I11)),IFERROR(J11/I11-1,""),"") | K12: =IF(AND(ISNUMBER(K11),ISNUMBER(J11)),IFERROR(K11/J11-1,""),"") | L12: =IF(AND(ISNUMBER(L11),ISNUMBER(K11)),IFERROR(L11/K11-1,""),"") -> -0.34129791 | Q12: =IF(AND(ISNUMBER(Q11),ISNUMBER(L11)),IFERROR(Q11/L11-1,""),"") -> -0.10997546 | R12: =IF(AND(ISNUMBER(R11),ISNUMBER(M11)),IFERROR(R11/M11-1,""),"") -> 0.37782101 | S12: =IF(AND(ISNUMBER(S11),ISNUMBER(N11)),IFERROR(S11/N11-1,""),"") -> 0.20589361 | T12: =IF(AND(ISNUMBER(T11),ISNUMBER(O11)),IFERROR(T11/O11-1,""),"") -> 0.37052653 | U12: =IF(AND(ISNUMBER(U11),ISNUMBER(P11)),IFERROR(U11/P11-1,""),"") -> 0.24486706 | V12: =IF(AND(ISNUMBER(V11),ISNUMBER(Q11)),IFERROR(V11/Q11-1,""),"") -> 0.29206324 | W12: =IF(AND(ISNUMBER(W11),ISNUMBER(R11)),IFERROR(W11/R11-1,""),"") -> 0.32481445 | X12: =IF(AND(ISNUMBER(X11),ISNUMBER(S11)),IFERROR(X11/S11-1,""),"") -> 0.29605579 | ... AN12: =IF(AND(ISNUMBER(AN11),ISNUMBER(AI11)),IFERROR(AN11/AI11-1,""),"") -> 0.33768961 | AO12: =AO13+$AO$109 -> 0.18949026 | AP12: =IF(AND(ISNUMBER(AP11),ISNUMBER(AK11)),IFERROR(AP11/AK11-1,""),"") -> 0.26106764 | AQ12: =CHOOSE(MATCH($AV$2,{"Bull","Base","Bear"},0),$BE$34,$BF$34,$BG$34) -> 0.14 | AR12: =CHOOSE(MATCH($AV$2,{"Bull","Base","Bear"},0),$BE$35,$BF$35,$BG$35) -> 0.11 | AS12: =CHOOSE(MATCH($AV$2,{"Bull","Base","Bear"},0),$BE$36,$BF$36,$BG$36) -> 0.09 | AT12: =CHOOSE(MATCH($AV$2,{"Bull","Base","Bear"},0),$BE$37,$BF$37,$BG$37) -> 0.07 | AU12: =CHOOSE(MATCH($AV$2,{"Bull","Base","Bear"},0),$BE$38,$BF$38,$BG$38) -> 0.06 | AV12: Q4/26E: 9M FY26 y/y growth of the market + sales-guidance calibration Δ (Group block). 2027E–2031E: scenario lever (Bull/Base/Bear table →). | BD12: FY26 net sales growth | BE12: 0.23 | BF12: 0.215 | BG12: 0.2 | BH12: Guided +20–23%. Drives the Q4/26E sales calibration.
B13: Q4/26E growth before sales calibration (9M FY26 y/y) | AO13: =IFERROR(SUM(AL11:AN11)/SUM(AG11:AI11)-1,0) -> 0.28904931 | BD13: FY26 adjusted EPS ($) | BE13: 9.5 | BF13: 9.4 | BG13: 9.3 | BH13: Guided $9.30–9.50. Drives the Q4/26E segment-margin calibration.
B14: Commercial services (aftermarket) sales | K14: 497.795 | L14: 399.843 | M14: 65.515 | N14: 77.579 | O14: 75.508 | P14: 87.945 | Q14: 306.547 | R14: 86.086 | S14: 108.554 | T14: 108.695 | U14: 117.546 | V14: 420.881 | W14: 126.643 | X14: 139.445 | Y14: 139.518 | Z14: 142.019 | AA14: 547.625 | AB14: 137.544 | AC14: 163.886 | AD14: 165.718 | AE14: 173.675 | AF14: 640.823 | AG14: 163.85 | AH14: 201.861 | AI14: 215.451 | AJ14: 242.385 | AK14: 823.547 | AL14: 244.906 | AM14: 275.374 | AN14: 267.849 | AO14: =AJ14*(1+AO15) -> 304.57302 | AP14: =SUM(AL14:AO14) -> 1092.702 | AQ14: =AP14*(1+AQ15) -> 1191.0452 | AR14: =AQ14*(1+AR15) -> 1286.3288 | AS14: =AR14*(1+AS15) -> 1376.3718 | AT14: =AS14*(1+AT15) -> 1458.9542 | AU14: =AT14*(1+AU15) -> 1546.4914 | AX14: =IFERROR((AU14/AP14)^(1/5)-1,"n/m") -> 0.07193673 | AY14: =IFERROR((AK14/L14)^(1/5)-1,"n/m") -> 0.15547294 | AZ14: =IFERROR((AK14/G14)^(1/10)-1,"n/m") -> n/m | BA14: =IFERROR((AK14/C14)^(1/14)-1,"n/m") -> n/m | BD14: FY26 Aerospace sales growth — memo | BE14: 0.23 | BF14: 0.22 | BG14: 0.21 | BH14: Guided +21–23% (information row; compare the model).
B15: y/y % | D15: =IF(AND(ISNUMBER(D14),ISNUMBER(C14)),IFERROR(D14/C14-1,""),"") | E15: =IF(AND(ISNUMBER(E14),ISNUMBER(D14)),IFERROR(E14/D14-1,""),"") | F15: =IF(AND(ISNUMBER(F14),ISNUMBER(E14)),IFERROR(F14/E14-1,""),"") | G15: =IF(AND(ISNUMBER(G14),ISNUMBER(F14)),IFERROR(G14/F14-1,""),"") | H15: =IF(AND(ISNUMBER(H14),ISNUMBER(G14)),IFERROR(H14/G14-1,""),"") | I15: =IF(AND(ISNUMBER(I14),ISNUMBER(H14)),IFERROR(I14/H14-1,""),"") | J15: =IF(AND(ISNUMBER(J14),ISNUMBER(I14)),IFERROR(J14/I14-1,""),"") | K15: =IF(AND(ISNUMBER(K14),ISNUMBER(J14)),IFERROR(K14/J14-1,""),"") | L15: =IF(AND(ISNUMBER(L14),ISNUMBER(K14)),IFERROR(L14/K14-1,""),"") -> -0.19677176 | Q15: =IF(AND(ISNUMBER(Q14),ISNUMBER(L14)),IFERROR(Q14/L14-1,""),"") -> -0.23333158 | R15: =IF(AND(ISNUMBER(R14),ISNUMBER(M14)),IFERROR(R14/M14-1,""),"") -> 0.31398916 | S15: =IF(AND(ISNUMBER(S14),ISNUMBER(N14)),IFERROR(S14/N14-1,""),"") -> 0.39927042 | T15: =IF(AND(ISNUMBER(T14),ISNUMBER(O14)),IFERROR(T14/O14-1,""),"") -> 0.43951634 | U15: =IF(AND(ISNUMBER(U14),ISNUMBER(P14)),IFERROR(U14/P14-1,""),"") -> 0.33658537 | V15: =IF(AND(ISNUMBER(V14),ISNUMBER(Q14)),IFERROR(V14/Q14-1,""),"") -> 0.3729738 | W15: =IF(AND(ISNUMBER(W14),ISNUMBER(R14)),IFERROR(W14/R14-1,""),"") -> 0.4711219 | X15: =IF(AND(ISNUMBER(X14),ISNUMBER(S14)),IFERROR(X14/S14-1,""),"") -> 0.28456805 | ... AN15: =IF(AND(ISNUMBER(AN14),ISNUMBER(AI14)),IFERROR(AN14/AI14-1,""),"") -> 0.24320147 | AO15: =AO16+$AO$109 -> 0.25656713 | AP15: =IF(AND(ISNUMBER(AP14),ISNUMBER(AK14)),IFERROR(AP14/AK14-1,""),"") -> 0.32682412 | AQ15: =CHOOSE(MATCH($AV$2,{"Bull","Base","Bear"},0),$BE$40,$BF$40,$BG$40) -> 0.09 | AR15: =CHOOSE(MATCH($AV$2,{"Bull","Base","Bear"},0),$BE$41,$BF$41,$BG$41) -> 0.08 | AS15: =CHOOSE(MATCH($AV$2,{"Bull","Base","Bear"},0),$BE$42,$BF$42,$BG$42) -> 0.07 | AT15: =CHOOSE(MATCH($AV$2,{"Bull","Base","Bear"},0),$BE$43,$BF$43,$BG$43) -> 0.06 | AU15: =CHOOSE(MATCH($AV$2,{"Bull","Base","Bear"},0),$BE$44,$BF$44,$BG$44) -> 0.06 | BD15: FY26 Industrial sales growth — memo | BE15: 0.21 | BF15: 0.2 | BG15: 0.19 | BH15: Guided +19–21% (information row).
B16: Q4/26E growth before sales calibration (9M FY26 y/y) | AO16: =IFERROR(SUM(AL14:AN14)/SUM(AG14:AI14)-1,0) -> 0.35612617 | BD16: FY26 free cash flow ($m) — memo | BE16: 350 | BF16: 325 | BG16: 300 | BH16: Guided $300–350m (information row).
B17: Defense OEM sales | K17: 529.94 | L17: 526.264 | M17: 131.263 | N17: 135.63 | O17: 117.204 | P17: 125.718 | Q17: 509.815 | R17: 105.375 | S17: 97.812 | T17: 115.205 | U17: 103.624 | V17: 422.016 | W17: 89.762 | X17: 87.807 | Y17: 101.008 | Z17: 90.076 | AA17: 368.653 | AB17: 93.425 | AC17: 91.017 | AD17: 96.557 | AE17: 125.811 | AF17: 406.81 | AG17: 112.782 | AH17: 137.928 | AI17: 150.358 | AJ17: 160.22 | AK17: 561.288 | AL17: 138.233 | AM17: 150.932 | AN17: 140.725 | AO17: =AJ17*(1+AO18) -> 155.78256 | AP17: =SUM(AL17:AO17) -> 585.67256 | AQ17: =AP17*(1+AQ18) -> 626.66964 | AR17: =AQ17*(1+AR18) -> 664.26982 | AS17: =AR17*(1+AS18) -> 697.48331 | AT17: =AS17*(1+AT18) -> 732.35747 | AU17: =AT17*(1+AU18) -> 768.97535 | AX17: =IFERROR((AU17/AP17)^(1/5)-1,"n/m") -> 0.055969825 | AY17: =IFERROR((AK17/L17)^(1/5)-1,"n/m") -> 0.012969616 | AZ17: =IFERROR((AK17/G17)^(1/10)-1,"n/m") -> n/m | BA17: =IFERROR((AK17/C17)^(1/14)-1,"n/m") -> n/m | BD17: Q4/26E share repurchases ($m) | BE17: 300 | BF17: 200 | BG17: 100 | BH17: 9M FY26 $553.4m ($198m in Q3); $1,286m left on the $1.8bn 2026 Authorization at 30-Jun-2026.
B18: y/y % | D18: =IF(AND(ISNUMBER(D17),ISNUMBER(C17)),IFERROR(D17/C17-1,""),"") | E18: =IF(AND(ISNUMBER(E17),ISNUMBER(D17)),IFERROR(E17/D17-1,""),"") | F18: =IF(AND(ISNUMBER(F17),ISNUMBER(E17)),IFERROR(F17/E17-1,""),"") | G18: =IF(AND(ISNUMBER(G17),ISNUMBER(F17)),IFERROR(G17/F17-1,""),"") | H18: =IF(AND(ISNUMBER(H17),ISNUMBER(G17)),IFERROR(H17/G17-1,""),"") | I18: =IF(AND(ISNUMBER(I17),ISNUMBER(H17)),IFERROR(I17/H17-1,""),"") | J18: =IF(AND(ISNUMBER(J17),ISNUMBER(I17)),IFERROR(J17/I17-1,""),"") | K18: =IF(AND(ISNUMBER(K17),ISNUMBER(J17)),IFERROR(K17/J17-1,""),"") | L18: =IF(AND(ISNUMBER(L17),ISNUMBER(K17)),IFERROR(L17/K17-1,""),"") -> -0.0069366343 | Q18: =IF(AND(ISNUMBER(Q17),ISNUMBER(L17)),IFERROR(Q17/L17-1,""),"") -> -0.031256176 | R18: =IF(AND(ISNUMBER(R17),ISNUMBER(M17)),IFERROR(R17/M17-1,""),"") -> -0.19722237 | S18: =IF(AND(ISNUMBER(S17),ISNUMBER(N17)),IFERROR(S17/N17-1,""),"") -> -0.27883212 | T18: =IF(AND(ISNUMBER(T17),ISNUMBER(O17)),IFERROR(T17/O17-1,""),"") -> -0.017055732 | U18: =IF(AND(ISNUMBER(U17),ISNUMBER(P17)),IFERROR(U17/P17-1,""),"") -> -0.17574253 | V18: =IF(AND(ISNUMBER(V17),ISNUMBER(Q17)),IFERROR(V17/Q17-1,""),"") -> -0.17221737 | W18: =IF(AND(ISNUMBER(W17),ISNUMBER(R17)),IFERROR(W17/R17-1,""),"") -> -0.14816607 | X18: =IF(AND(ISNUMBER(X17),ISNUMBER(S17)),IFERROR(X17/S17-1,""),"") -> -0.10228806 | ... AN18: =IF(AND(ISNUMBER(AN17),ISNUMBER(AI17)),IFERROR(AN17/AI17-1,""),"") -> -0.064067093 | AO18: =AO19+$AO$109 -> -0.027695915 | AP18: =IF(AND(ISNUMBER(AP17),ISNUMBER(AK17)),IFERROR(AP17/AK17-1,""),"") -> 0.043443937 | AQ18: =CHOOSE(MATCH($AV$2,{"Bull","Base","Bear"},0),$BE$46,$BF$46,$BG$46) -> 0.07 | AR18: =CHOOSE(MATCH($AV$2,{"Bull","Base","Bear"},0),$BE$47,$BF$47,$BG$47) -> 0.06 | AS18: =CHOOSE(MATCH($AV$2,{"Bull","Base","Bear"},0),$BE$48,$BF$48,$BG$48) -> 0.05 | AT18: =CHOOSE(MATCH($AV$2,{"Bull","Base","Bear"},0),$BE$49,$BF$49,$BG$49) -> 0.05 | AU18: =CHOOSE(MATCH($AV$2,{"Bull","Base","Bear"},0),$BE$50,$BF$50,$BG$50) -> 0.05
B19: Q4/26E growth before sales calibration (9M FY26 y/y) | AO19: =IFERROR(SUM(AL17:AN17)/SUM(AG17:AI17)-1,0) -> 0.071863125 | BD19: Q4/26E and FY26 point estimates (all cases)
B20: Defense services (aftermarket) sales | K20: 193.449 | L20: 230.55 | M20: 48.808 | N20: 49.59 | O20: 51.91 | P20: 50.904 | Q20: 201.212 | R20: 40.148 | S20: 43.502 | T20: 45.844 | U20: 47.493 | V20: 176.987 | W20: 40.405 | X20: 50.494 | Y20: 53.832 | Z20: 55.819 | AA20: 200.55 | AB20: 58.433 | AC20: 59.092 | AD20: 65.588 | AE20: 59.478 | AF20: 242.591 | AG20: 63.174 | AH20: 54.479 | AI20: 54.955 | AJ20: 64.401 | AK20: 237.009 | AL20: 63.819 | AM20: 59 | AN20: 65.701 | AO20: =AJ20*(1+AO21) -> 63.926153 | AP20: =SUM(AL20:AO20) -> 252.44615 | AQ20: =AP20*(1+AQ21) -> 265.06846 | AR20: =AQ20*(1+AR21) -> 278.32188 | AS20: =AR20*(1+AS21) -> 289.45476 | AT20: =AS20*(1+AT21) -> 301.03295 | AU20: =AT20*(1+AU21) -> 313.07427 | AX20: =IFERROR((AU20/AP20)^(1/5)-1,"n/m") -> 0.04398852 | AY20: =IFERROR((AK20/L20)^(1/5)-1,"n/m") -> 0.0055413682 | AZ20: =IFERROR((AK20/G20)^(1/10)-1,"n/m") -> n/m | BA20: =IFERROR((AK20/C20)^(1/14)-1,"n/m") -> n/m | BD20: Q4/26E interest expense ($m) | BF20: 15.5 | BH20: Not guided; Q3 $14.8m; full quarter of the $250m term loan and the revolver (~$1.35bn debt at ~4.6%).
B21: y/y % | D21: =IF(AND(ISNUMBER(D20),ISNUMBER(C20)),IFERROR(D20/C20-1,""),"") | E21: =IF(AND(ISNUMBER(E20),ISNUMBER(D20)),IFERROR(E20/D20-1,""),"") | F21: =IF(AND(ISNUMBER(F20),ISNUMBER(E20)),IFERROR(F20/E20-1,""),"") | G21: =IF(AND(ISNUMBER(G20),ISNUMBER(F20)),IFERROR(G20/F20-1,""),"") | H21: =IF(AND(ISNUMBER(H20),ISNUMBER(G20)),IFERROR(H20/G20-1,""),"") | I21: =IF(AND(ISNUMBER(I20),ISNUMBER(H20)),IFERROR(I20/H20-1,""),"") | J21: =IF(AND(ISNUMBER(J20),ISNUMBER(I20)),IFERROR(J20/I20-1,""),"") | K21: =IF(AND(ISNUMBER(K20),ISNUMBER(J20)),IFERROR(K20/J20-1,""),"") | L21: =IF(AND(ISNUMBER(L20),ISNUMBER(K20)),IFERROR(L20/K20-1,""),"") -> 0.19178698 | Q21: =IF(AND(ISNUMBER(Q20),ISNUMBER(L20)),IFERROR(Q20/L20-1,""),"") -> -0.12725222 | R21: =IF(AND(ISNUMBER(R20),ISNUMBER(M20)),IFERROR(R20/M20-1,""),"") -> -0.17742993 | S21: =IF(AND(ISNUMBER(S20),ISNUMBER(N20)),IFERROR(S20/N20-1,""),"") -> -0.12276669 | T21: =IF(AND(ISNUMBER(T20),ISNUMBER(O20)),IFERROR(T20/O20-1,""),"") -> -0.1168561 | U21: =IF(AND(ISNUMBER(U20),ISNUMBER(P20)),IFERROR(U20/P20-1,""),"") -> -0.067008487 | V21: =IF(AND(ISNUMBER(V20),ISNUMBER(Q20)),IFERROR(V20/Q20-1,""),"") -> -0.1203954 | W21: =IF(AND(ISNUMBER(W20),ISNUMBER(R20)),IFERROR(W20/R20-1,""),"") -> 0.0064013151 | X21: =IF(AND(ISNUMBER(X20),ISNUMBER(S20)),IFERROR(X20/S20-1,""),"") -> 0.16072824 | ... AN21: =IF(AND(ISNUMBER(AN20),ISNUMBER(AI20)),IFERROR(AN20/AI20-1,""),"") -> 0.19554181 | AO21: =AO22+$AO$109 -> -0.0073732784 | AP21: =IF(AND(ISNUMBER(AP20),ISNUMBER(AK20)),IFERROR(AP20/AK20-1,""),"") -> 0.065133195 | AQ21: =CHOOSE(MATCH($AV$2,{"Bull","Base","Bear"},0),$BE$52,$BF$52,$BG$52) -> 0.05 | AR21: =CHOOSE(MATCH($AV$2,{"Bull","Base","Bear"},0),$BE$53,$BF$53,$BG$53) -> 0.05 | AS21: =CHOOSE(MATCH($AV$2,{"Bull","Base","Bear"},0),$BE$54,$BF$54,$BG$54) -> 0.04 | AT21: =CHOOSE(MATCH($AV$2,{"Bull","Base","Bear"},0),$BE$55,$BF$55,$BG$55) -> 0.04 | AU21: =CHOOSE(MATCH($AV$2,{"Bull","Base","Bear"},0),$BE$56,$BF$56,$BG$56) -> 0.04 | BD21: Q4/26E interest income ($m) | BF21: 0.6 | BH21: Q3 $0.6m.
B22: Q4/26E growth before sales calibration (9M FY26 y/y) | AO22: =IFERROR(SUM(AL20:AN20)/SUM(AG20:AI20)-1,0) -> 0.092185762 | BD22: Q4/26E other income, net ($m) | BF22: 20 | BH22: 9M FY26 $60.3m (~$20m a quarter; no divestiture gains).
B23: Aerospace — segment net sales | C23: =IF(ISNUMBER(C11),C11+C14+C17+C20,C27) -> 843.032 | D23: =IF(ISNUMBER(D11),D11+D14+D17+D20,D27) -> 896.083 | E23: =IF(ISNUMBER(E11),E11+E14+E17+E20,E27) -> 1061.477 | F23: =IF(ISNUMBER(F11),F11+F14+F17+F20,F27) -> 1084.025 | G23: =IF(ISNUMBER(G11),G11+G14+G17+G20,G27) -> 1160.883 | H23: =IF(ISNUMBER(H11),H11+H14+H17+H20,H27) -> 1233.176 | I23: =IF(ISNUMBER(I11),I11+I14+I17+I20,I27) -> 1342.339 | J23: =IF(ISNUMBER(J11),J11+J14+J17+J20,J27) -> 1557.988 | ... AN23: =IF(ISNUMBER(AN11),AN11+AN14+AN17+AN20,AN27) -> 708.673 | AO23: =AO11+AO14+AO17+AO20 -> 755.27956 | AP23: =AP11+AP14+AP17+AP20 -> 2802.1706 | AQ23: =AQ11+AQ14+AQ17+AQ20 -> 3076.1221 | AR23: =AR11+AR14+AR17+AR20 -> 3331.5266 | AS23: =AS11+AS14+AS17+AS20 -> 3565.1505 | AT23: =AT11+AT14+AT17+AT20 -> 3778.314 | AU23: =AU11+AU14+AU17+AU20 -> 3991.6686 | AV23: History: Σ primary markets where published, otherwise segment net sales as reported. | AX23: =IFERROR((AU23/AP23)^(1/5)-1,"n/m") -> 0.073326824 | AY23: =IFERROR((AK23/L23)^(1/5)-1,"n/m") -> 0.077694894 | AZ23: =IFERROR((AK23/G23)^(1/10)-1,"n/m") -> 0.071359131 | BA23: =IFERROR((AK23/C23)^(1/14)-1,"n/m") -> 0.074748372 | BD23: Q4/26E amortization of intangibles ($m) | BF23: 8.448 | BH23: Q3 FY26 10-Q schedule: $8.4m remaining in FY26.
B24: Segment sales y/y % | D24: =IF(AND(ISNUMBER(D23),ISNUMBER(C23)),IFERROR(D23/C23-1,""),"") -> 0.062928809 | E24: =IF(AND(ISNUMBER(E23),ISNUMBER(D23)),IFERROR(E23/D23-1,""),"") -> 0.18457442 | F24: =IF(AND(ISNUMBER(F23),ISNUMBER(E23)),IFERROR(F23/E23-1,""),"") -> 0.021242099 | G24: =IF(AND(ISNUMBER(G23),ISNUMBER(F23)),IFERROR(G23/F23-1,""),"") -> 0.070900579 | H24: =IF(AND(ISNUMBER(H23),ISNUMBER(G23)),IFERROR(H23/G23-1,""),"") -> 0.062274148 | I24: =IF(AND(ISNUMBER(I23),ISNUMBER(H23)),IFERROR(I23/H23-1,""),"") -> 0.088521833 | J24: =IF(AND(ISNUMBER(J23),ISNUMBER(I23)),IFERROR(J23/I23-1,""),"") -> 0.16065167 | K24: =IF(AND(ISNUMBER(K23),ISNUMBER(J23)),IFERROR(K23/J23-1,""),"") -> 0.20701828 | L24: =IF(AND(ISNUMBER(L23),ISNUMBER(K23)),IFERROR(L23/K23-1,""),"") -> -0.15397709 | Q24: =IF(AND(ISNUMBER(Q23),ISNUMBER(L23)),IFERROR(Q23/L23-1,""),"") -> -0.11744208 | R24: =IF(AND(ISNUMBER(R23),ISNUMBER(M23)),IFERROR(R23/M23-1,""),"") -> 0.045910833 | S24: =IF(AND(ISNUMBER(S23),ISNUMBER(N23)),IFERROR(S23/N23-1,""),"") -> 0.022075315 | T24: =IF(AND(ISNUMBER(T23),ISNUMBER(O23)),IFERROR(T23/O23-1,""),"") -> 0.17834514 | U24: =IF(AND(ISNUMBER(U23),ISNUMBER(P23)),IFERROR(U23/P23-1,""),"") -> 0.083819845 | V24: =IF(AND(ISNUMBER(V23),ISNUMBER(Q23)),IFERROR(V23/Q23-1,""),"") -> 0.082048006 | W24: =IF(AND(ISNUMBER(W23),ISNUMBER(R23)),IFERROR(W23/R23-1,""),"") -> 0.17611128 | X24: =IF(AND(ISNUMBER(X23),ISNUMBER(S23)),IFERROR(X23/S23-1,""),"") -> 0.17239113 | ... AP24: =IF(AND(ISNUMBER(AP23),ISNUMBER(AK23)),IFERROR(AP23/AK23-1,""),"") -> 0.21158911 | AQ24: =IF(AND(ISNUMBER(AQ23),ISNUMBER(AP23)),IFERROR(AQ23/AP23-1,""),"") -> 0.09776405 | AR24: =IF(AND(ISNUMBER(AR23),ISNUMBER(AQ23)),IFERROR(AR23/AQ23-1,""),"") -> 0.083028071 | AS24: =IF(AND(ISNUMBER(AS23),ISNUMBER(AR23)),IFERROR(AS23/AR23-1,""),"") -> 0.070125188 | AT24: =IF(AND(ISNUMBER(AT23),ISNUMBER(AS23)),IFERROR(AT23/AS23-1,""),"") -> 0.059790886 | AU24: =IF(AND(ISNUMBER(AU23),ISNUMBER(AT23)),IFERROR(AU23/AT23-1,""),"") -> 0.056468204 | BD24: Q4/26E depreciation ($m) | BF24: 23 | BH24: Q3 $22.5m; rising with capex.
B25: % of total net sales | C25: =IF(AND(ISNUMBER(C23),ISNUMBER(C99)),IFERROR(C23/C99,""),"") -> 0.49251096 | D25: =IF(AND(ISNUMBER(D23),ISNUMBER(D99)),IFERROR(D23/D99,""),"") -> 0.48031198 | E25: =IF(AND(ISNUMBER(E23),ISNUMBER(E99)),IFERROR(E23/E99,""),"") -> 0.54829037 | F25: =IF(AND(ISNUMBER(F23),ISNUMBER(F99)),IFERROR(F23/F99,""),"") -> 0.54167666 | G25: =IF(AND(ISNUMBER(G23),ISNUMBER(G99)),IFERROR(G23/G99,""),"") -> 0.56953407 | H25: =IF(AND(ISNUMBER(H23),ISNUMBER(H99)),IFERROR(H23/H99,""),"") -> 0.60955435 | I25: =IF(AND(ISNUMBER(I23),ISNUMBER(I99)),IFERROR(I23/I99,""),"") -> 0.63960957 | J25: =IF(AND(ISNUMBER(J23),ISNUMBER(J99)),IFERROR(J23/J99,""),"") -> 0.66985085 | ... AU25: =IF(AND(ISNUMBER(AU23),ISNUMBER(AU99)),IFERROR(AU23/AU99,""),"") -> 0.65185919 | BD25: Q4/26E tax rate (GAAP & adjusted) | BF25: 0.24 | BH25: FY26 adjusted rate guided ~22.5%; 9M FY26 adjusted 21.9% → Q4 ~24% (Q3 24.2%).
B26: Aftermarket (commercial + defense services) % of Aerospace sales | C26: =IF(ISNUMBER(C14),IFERROR((C14+C20)/C23,""),"") | D26: =IF(ISNUMBER(D14),IFERROR((D14+D20)/D23,""),"") | E26: =IF(ISNUMBER(E14),IFERROR((E14+E20)/E23,""),"") | F26: =IF(ISNUMBER(F14),IFERROR((F14+F20)/F23,""),"") | G26: =IF(ISNUMBER(G14),IFERROR((G14+G20)/G23,""),"") | H26: =IF(ISNUMBER(H14),IFERROR((H14+H20)/H23,""),"") | I26: =IF(ISNUMBER(I14),IFERROR((I14+I20)/I23,""),"") | J26: =IF(ISNUMBER(J14),IFERROR((J14+J20)/J23,""),"") | ... AU26: =IF(ISNUMBER(AU14),IFERROR((AU14+AU20)/AU23,""),"") -> 0.46586173 | AX26: =IFERROR(AVERAGE(AQ26,AR26,AS26,AT26,AU26),"n/m") -> 0.46838746 | AY26: =IFERROR(AVERAGE(Q26,V26,AA26,AF26,AK26),"n/m") -> 0.41446329 | AZ26: =IFERROR(AVERAGE(H26,I26,J26,K26,L26,Q26,V26,AA26,AF26,AK26),"n/m") -> 0.40516163 | BA26: =IFERROR(AVERAGE(C26,D26,E26,F26,G26,H26,I26,J26,K26,L26,Q26,V26,AA26,AF26,AK26),"n/m") -> 0.40516163 | BD26: FY26 capital expenditures ($m) | BF26: 290 | BH26: Guided ~$290m (9M $156.3m); Spartanburg, SC campus.
B27: Memo: Aerospace segment net sales as reported (segment schedule) | C27: 843.032 | D27: 896.083 | E27: 1061.477 | F27: 1084.025 | G27: 1160.883 | H27: 1233.176 | I27: 1342.339 | J27: 1557.988 | K27: 1880.52 | L27: 1590.963 | M27: 321.667 | N27: 364.706 | O27: 340.912 | P27: 376.832 | Q27: 1404.117 | R27: 336.435 | S27: 372.757 | T27: 401.712 | U27: 408.418 | V27: 1519.322 | W27: 395.685 | X27: 437.017 | Y27: 480.531 | Z27: 454.87 | AA27: 1768.103 | AB27: 460.756 | AC27: 497.512 | AD27: 517.56 | AE27: 552.79 | AF27: 2028.618 | AG27: 493.882 | AH27: 561.729 | AI27: 595.99 | AJ27: 661.205 | AK27: 2312.806 | AL27: 634.897 | AM27: 703.321 | AN27: 708.673 | BD27: Q4/26E restructuring charges ($m) | BF27: 6 | BH27: China OH wind-down complete; servo-valve transition (~$15m total) and the start of the Santa Clarita plan (8-K 21-Sep-2026).
B28: Check: primary markets vs segment net sales (should be 0) | C28: =IF(AND(ISNUMBER(C11),ISNUMBER(C27)),IF(ABS(C23-C27)<=0.15,0,ROUND(C23-C27,1)),"") | D28: =IF(AND(ISNUMBER(D11),ISNUMBER(D27)),IF(ABS(D23-D27)<=0.15,0,ROUND(D23-D27,1)),"") | E28: =IF(AND(ISNUMBER(E11),ISNUMBER(E27)),IF(ABS(E23-E27)<=0.15,0,ROUND(E23-E27,1)),"") | F28: =IF(AND(ISNUMBER(F11),ISNUMBER(F27)),IF(ABS(F23-F27)<=0.15,0,ROUND(F23-F27,1)),"") | G28: =IF(AND(ISNUMBER(G11),ISNUMBER(G27)),IF(ABS(G23-G27)<=0.15,0,ROUND(G23-G27,1)),"") | H28: =IF(AND(ISNUMBER(H11),ISNUMBER(H27)),IF(ABS(H23-H27)<=0.15,0,ROUND(H23-H27,1)),"") | I28: =IF(AND(ISNUMBER(I11),ISNUMBER(I27)),IF(ABS(I23-I27)<=0.15,0,ROUND(I23-I27,1)),"") | J28: =IF(AND(ISNUMBER(J11),ISNUMBER(J27)),IF(ABS(J23-J27)<=0.15,0,ROUND(J23-J27,1)),"") | ... AN28: =IF(AND(ISNUMBER(AN11),ISNUMBER(AN27)),IF(ABS(AN23-AN27)<=0.15,0,ROUND(AN23-AN27,1)),"") -> 0 | BD28: FY26 Aerospace segment margin guidance | BF28: 0.235 | BH28: Guided ~23.5% (information row).
B29: Aerospace segment earnings | C29: 129.502 | D29: 130.192 | E29: 166.122 | F29: 159.2 | G29: 187.747 | H29: 232.166 | I29: 257.813 | J29: 301.803 | K29: 389.126 | L29: 310.137 | M29: 46.466 | N29: 69.008 | O29: 53.167 | P29: 65.715 | Q29: 234.356 | R29: 51.083 | S29: 59.809 | T29: 56.566 | U29: 63.475 | V29: 230.933 | W29: 55.434 | X29: 73.314 | Y29: 83.075 | Z29: 78.281 | AA29: 290.104 | AB29: 79.002 | AC29: 98.451 | AD29: 101.842 | AE29: 106.065 | AF29: 385.36 | AG29: 94.725 | AH29: 124.616 | AI29: 125.74 | AJ29: 161.532 | AK29: 506.613 | AL29: 148.395 | AM29: 158.075 | AN29: 170.02 | AO29: =AO23*AO30 -> 185.66086 | AP29: =SUM(AL29:AO29) -> 662.15086 | AQ29: =AQ23*AQ30 -> 738.2693 | AR29: =AR23*AR30 -> 816.22401 | AS29: =AS23*AS30 -> 891.28763 | AT29: =AT23*AT30 -> 955.91345 | AU29: =AU23*AU30 -> 1017.8755 | AV29: Segment earnings as reported (company measure: after amortization of intangibles; excludes nonsegment expenses). Forecast = segment sales × segment margin. | AX29: =IFERROR((AU29/AP29)^(1/5)-1,"n/m") -> 0.089801857 | AY29: =IFERROR((AK29/L29)^(1/5)-1,"n/m") -> 0.10312455 | AZ29: =IFERROR((AK29/G29)^(1/10)-1,"n/m") -> 0.10435915 | BA29: =IFERROR((AK29/C29)^(1/14)-1,"n/m") -> 0.10233672 | BD29: FY26 Industrial segment margin guidance | BF29: 0.19 | BH29: Guided ~19% (information row).
B30: Segment margin % | C30: =IF(AND(ISNUMBER(C29),ISNUMBER(C23)),IFERROR(C29/C23,""),"") -> 0.15361457 | D30: =IF(AND(ISNUMBER(D29),ISNUMBER(D23)),IFERROR(D29/D23,""),"") -> 0.14529011 | E30: =IF(AND(ISNUMBER(E29),ISNUMBER(E23)),IFERROR(E29/E23,""),"") -> 0.1565008 | F30: =IF(AND(ISNUMBER(F29),ISNUMBER(F23)),IFERROR(F29/F23,""),"") -> 0.14686008 | G30: =IF(AND(ISNUMBER(G29),ISNUMBER(G23)),IFERROR(G29/G23,""),"") -> 0.16172775 | H30: =IF(AND(ISNUMBER(H29),ISNUMBER(H23)),IFERROR(H29/H23,""),"") -> 0.18826672 | I30: =IF(AND(ISNUMBER(I29),ISNUMBER(I23)),IFERROR(I29/I23,""),"") -> 0.19206251 | J30: =IF(AND(ISNUMBER(J29),ISNUMBER(J23)),IFERROR(J29/J23,""),"") -> 0.1937133 | ... AN30: =IF(AND(ISNUMBER(AN29),ISNUMBER(AN23)),IFERROR(AN29/AN23,""),"") -> 0.23991319 | AO30: =AO31+$AO$116 -> 0.2458174 | AP30: =IF(AND(ISNUMBER(AP29),ISNUMBER(AP23)),IFERROR(AP29/AP23,""),"") -> 0.23629927 | AQ30: =CHOOSE(MATCH($AV$2,{"Bull","Base","Bear"},0),$BE$76,$BF$76,$BG$76) -> 0.24 | AR30: =CHOOSE(MATCH($AV$2,{"Bull","Base","Bear"},0),$BE$77,$BF$77,$BG$77) -> 0.245 | AS30: =CHOOSE(MATCH($AV$2,{"Bull","Base","Bear"},0),$BE$78,$BF$78,$BG$78) -> 0.25 | AT30: =CHOOSE(MATCH($AV$2,{"Bull","Base","Bear"},0),$BE$79,$BF$79,$BG$79) -> 0.253 | AU30: =CHOOSE(MATCH($AV$2,{"Bull","Base","Bear"},0),$BE$80,$BF$80,$BG$80) -> 0.255 | AV30: Q4/26E: margin before calibration + adjusted-EPS-guidance calibration Δ (Group block). 2027E+: scenario lever. | AX30: =IFERROR(AVERAGE(AQ30,AR30,AS30,AT30,AU30),"n/m") -> 0.2486 | AY30: =IFERROR(AVERAGE(Q30,V30,AA30,AF30,AK30),"n/m") -> 0.17839778 | AZ30: =IFERROR(AVERAGE(H30,I30,J30,K30,L30,Q30,V30,AA30,AF30,AK30),"n/m") -> 0.18678927 | BA30: =IFERROR(AVERAGE(C30,D30,E30,F30,G30,H30,I30,J30,K30,L30,Q30,V30,AA30,AF30,AK30),"n/m") -> 0.17545907
B31: Q4/26E margin before EPS calibration (prior-year quarter + 9M FY26 y/y drift) | AO31: =AJ30+IFERROR(SUM(AL29:AN29)/SUM(AL23:AN23)-SUM(AG29:AI29)/SUM(AG23:AI23),0) -> 0.26814934 | BD31: Maximum net debt / adjusted EBITDA before buybacks (x) — buyback floor 2027E+ | BE31: 1.75 | BF31: 1.25 | BG31: 0.75 | BH31: Net debt $867m at 30-Jun-26 ≈ 1.0x adjusted EBITDA (FY2021–25 0.5–1.1x); company "EBITDA leverage" (total debt / TTM EBITDA) 1.6x. Target = leverage up to which surplus cash is returned via buybacks ($1.8bn three-year authorization to Nov-2028); below it free cash flow repays the revolver. Bull = more buybacks (higher target).
B32: Incremental segment margin (Δ earnings / Δ sales) | D32: =IFERROR((D29-C29)/(D23-C23),"") -> 0.013006352 | E32: =IFERROR((E29-D29)/(E23-D23),"") -> 0.21723884 | F32: =IFERROR((F29-E29)/(F23-E23),"") -> -0.30698953 | G32: =IFERROR((G29-F29)/(G23-F23),"") -> 0.37142523 | H32: =IFERROR((H29-G29)/(H23-G23),"") -> 0.61443017 | I32: =IFERROR((I29-H29)/(I23-H23),"") -> 0.23494224 | J32: =IFERROR((J29-I29)/(J23-I23),"") -> 0.20398889 | K32: =IFERROR((K29-J29)/(K23-J23),"") -> 0.27074213 | L32: =IFERROR((L29-K29)/(L23-K23),"") -> 0.27279258 | Q32: =IFERROR((Q29-L29)/(Q23-L23),"") -> 0.40558 | R32: =IFERROR((R29-M29)/(R23-M23),"") -> 0.31263543 | S32: =IFERROR((S29-N29)/(S23-N23),"") -> -1.142591 | T32: =IFERROR((T29-O29)/(T23-O23),"") -> 0.055904605 | U32: =IFERROR((U29-P29)/(U23-P23),"") -> -0.070917495 | V32: =IFERROR((V29-Q29)/(V23-Q23),"") -> -0.029712252 | W32: =IFERROR((W29-R29)/(W23-R23),"") -> 0.073434599 | X32: =IFERROR((X29-S29)/(X23-S23),"") -> 0.21016184 | ... AP32: =IFERROR((AP29-AK29)/(AP23-AK23),"") -> 0.31783637 | AQ32: =IFERROR((AQ29-AP29)/(AQ23-AP23),"") -> 0.2778537 | AR32: =IFERROR((AR29-AQ29)/(AR23-AQ23),"") -> 0.3052206 | AS32: =IFERROR((AS29-AR29)/(AS23-AR23),"") -> 0.32130106 | AT32: =IFERROR((AT29-AS29)/(AT23-AS23),"") -> 0.30317487 | AU32: =IFERROR((AU29-AT29)/(AU23-AT23),"") -> 0.29041816
B33: Memo: Aerospace segment earnings as restated in the following year's release (where different) | J33: 308.553 | AV33: FY2018 restated in the FY2019 release (pension-cost reclassification, ASU 2017-07); the model keeps the originally reported figure. | BD33: AERO_COEM (Commercial OEM y/y) | BE33: 0.04 | BF33: Δ → | BG33: -0.06 | BH33: 9M FY26 +29% (airframer rate increases after the FY25 Boeing work stoppage / inventory normalisation); 737 / A320 / 787 / A350 ramps, A350 spoiler actuation from Spartanburg (2027).
BD34: 2027E | BE34: =BF34+$BE$33 -> 0.18 | BF34: 0.14 | BG34: =BF34+$BG$33 -> 0.08
B35: Industrial ("Energy" to FY2015; fuel, combustion, ignition & control systems for gas turbines, reciprocating engines and compressors; L'Orange fuel injection from Jun-2018) | AV35: INDUSTRIAL — modelling logic | BD35: 2028E | BE35: =BF35+$BE$33 -> 0.15 | BF35: 0.11 | BG35: =BF35+$BG$33 -> 0.05
B36: Power generation sales | Q36: 292.47 | V36: 317.026 | W36: 81.577 | X36: 94.013 | Y36: 101.387 | Z36: 105.559 | AA36: 382.536 | AB36: 98.106 | AC36: 106.811 | AD36: 109.583 | AE36: 109.372 | AF36: 423.872 | AG36: 105.219 | AH36: 111.047 | AI36: 109.341 | AJ36: 163.333 | AK36: 488.94 | AL36: 122.84 | AM36: 135.87 | AN36: 144.675 | AO36: =AJ36*(1+AO37) -> 186.08721 | AP36: =SUM(AL36:AO36) -> 589.47221 | AQ36: =AP36*(1+AQ37) -> 660.20887 | AR36: =AQ36*(1+AR37) -> 726.22976 | AS36: =AR36*(1+AS37) -> 784.32814 | AT36: =AS36*(1+AT37) -> 831.38783 | AU36: =AT36*(1+AU37) -> 872.95722 | AV36: Sales by primary market (10-Q / 10-K revenue-disaggregation note, from FY2019; Q4 = fiscal year − nine months). Q4/26E: prior-year quarter × (1 + growth). 2027E+: prior year × (1 + scenario lever). | AX36: =IFERROR((AU36/AP36)^(1/5)-1,"n/m") -> 0.081697748 | AY36: =IFERROR((AK36/L36)^(1/5)-1,"n/m") -> n/m | AZ36: =IFERROR((AK36/G36)^(1/10)-1,"n/m") -> n/m | BA36: =IFERROR((AK36/C36)^(1/14)-1,"n/m") -> n/m | BD36: 2029E | BE36: =BF36+$BE$33 -> 0.13 | BF36: 0.09 | BG36: =BF36+$BG$33 -> 0.03
B37: y/y % | D37: =IF(AND(ISNUMBER(D36),ISNUMBER(C36)),IFERROR(D36/C36-1,""),"") | E37: =IF(AND(ISNUMBER(E36),ISNUMBER(D36)),IFERROR(E36/D36-1,""),"") | F37: =IF(AND(ISNUMBER(F36),ISNUMBER(E36)),IFERROR(F36/E36-1,""),"") | G37: =IF(AND(ISNUMBER(G36),ISNUMBER(F36)),IFERROR(G36/F36-1,""),"") | H37: =IF(AND(ISNUMBER(H36),ISNUMBER(G36)),IFERROR(H36/G36-1,""),"") | I37: =IF(AND(ISNUMBER(I36),ISNUMBER(H36)),IFERROR(I36/H36-1,""),"") | J37: =IF(AND(ISNUMBER(J36),ISNUMBER(I36)),IFERROR(J36/I36-1,""),"") | K37: =IF(AND(ISNUMBER(K36),ISNUMBER(J36)),IFERROR(K36/J36-1,""),"") | L37: =IF(AND(ISNUMBER(L36),ISNUMBER(K36)),IFERROR(L36/K36-1,""),"") | Q37: =IF(AND(ISNUMBER(Q36),ISNUMBER(L36)),IFERROR(Q36/L36-1,""),"") | R37: =IF(AND(ISNUMBER(R36),ISNUMBER(M36)),IFERROR(R36/M36-1,""),"") | S37: =IF(AND(ISNUMBER(S36),ISNUMBER(N36)),IFERROR(S36/N36-1,""),"") | T37: =IF(AND(ISNUMBER(T36),ISNUMBER(O36)),IFERROR(T36/O36-1,""),"") | U37: =IF(AND(ISNUMBER(U36),ISNUMBER(P36)),IFERROR(U36/P36-1,""),"") | V37: =IF(AND(ISNUMBER(V36),ISNUMBER(Q36)),IFERROR(V36/Q36-1,""),"") -> 0.083960748 | W37: =IF(AND(ISNUMBER(W36),ISNUMBER(R36)),IFERROR(W36/R36-1,""),"") | X37: =IF(AND(ISNUMBER(X36),ISNUMBER(S36)),IFERROR(X36/S36-1,""),"") | ... AN37: =IF(AND(ISNUMBER(AN36),ISNUMBER(AI36)),IFERROR(AN36/AI36-1,""),"") -> 0.32315417 | AO37: =AO38+$AO$109 -> 0.13931175 | AP37: =IF(AND(ISNUMBER(AP36),ISNUMBER(AK36)),IFERROR(AP36/AK36-1,""),"") -> 0.20561256 | AQ37: =CHOOSE(MATCH($AV$2,{"Bull","Base","Bear"},0),$BE$58,$BF$58,$BG$58) -> 0.12 | AR37: =CHOOSE(MATCH($AV$2,{"Bull","Base","Bear"},0),$BE$59,$BF$59,$BG$59) -> 0.1 | AS37: =CHOOSE(MATCH($AV$2,{"Bull","Base","Bear"},0),$BE$60,$BF$60,$BG$60) -> 0.08 | AT37: =CHOOSE(MATCH($AV$2,{"Bull","Base","Bear"},0),$BE$61,$BF$61,$BG$61) -> 0.06 | AU37: =CHOOSE(MATCH($AV$2,{"Bull","Base","Bear"},0),$BE$62,$BF$62,$BG$62) -> 0.05 | AV37: Q4/26E: 9M FY26 y/y growth of the market + sales-guidance calibration Δ (Group block). 2027E–2031E: scenario lever (Bull/Base/Bear table →). | BD37: 2030E | BE37: =BF37+$BE$33 -> 0.11 | BF37: 0.07 | BG37: =BF37+$BG$33 -> 0.01
B38: Q4/26E growth before sales calibration (9M FY26 y/y) | AO38: =IFERROR(SUM(AL36:AN36)/SUM(AG36:AI36)-1,0) -> 0.23887079 | BD38: 2031E | BE38: =BF38+$BE$33 -> 0.1 | BF38: 0.06 | BG38: =BF38+$BG$33 -> 0
B39: Transportation sales | Q39: 399.002 | V39: 354.682 | W39: 88.915 | X39: 118.777 | Y39: 158.039 | Z39: 161.767 | AA39: 527.498 | AB39: 174.469 | AC39: 173.786 | AD39: 163.31 | AE39: 130.609 | AF39: 642.174 | AG39: 116.606 | AH39: 141.734 | AI39: 143.652 | AJ39: 105.384 | AK39: 507.376 | AL39: 166.308 | AM39: 176.914 | AN39: 180.155 | AO39: =AJ39*(1+AO40) -> 126.71369 | AP39: =SUM(AL39:AO39) -> 650.09069 | AQ39: =AP39*(1+AQ40) -> 650.09069 | AR39: =AQ39*(1+AR40) -> 676.09432 | AS39: =AR39*(1+AS40) -> 703.13809 | AT39: =AS39*(1+AT40) -> 724.23223 | AU39: =AT39*(1+AU40) -> 745.9592 | AX39: =IFERROR((AU39/AP39)^(1/5)-1,"n/m") -> 0.027893751 | AY39: =IFERROR((AK39/L39)^(1/5)-1,"n/m") -> n/m | AZ39: =IFERROR((AK39/G39)^(1/10)-1,"n/m") -> n/m | BA39: =IFERROR((AK39/C39)^(1/14)-1,"n/m") -> n/m | BD39: AERO_CSERV (Commercial services y/y) | BE39: 0.03 | BF39: Δ → | BG39: -0.06 | BH39: 9M FY26 +36% (FY25 +29%, partly advance purchases); high utilisation of legacy fleets, price; normalising toward high-single digits.
B40: y/y % | D40: =IF(AND(ISNUMBER(D39),ISNUMBER(C39)),IFERROR(D39/C39-1,""),"") | E40: =IF(AND(ISNUMBER(E39),ISNUMBER(D39)),IFERROR(E39/D39-1,""),"") | F40: =IF(AND(ISNUMBER(F39),ISNUMBER(E39)),IFERROR(F39/E39-1,""),"") | G40: =IF(AND(ISNUMBER(G39),ISNUMBER(F39)),IFERROR(G39/F39-1,""),"") | H40: =IF(AND(ISNUMBER(H39),ISNUMBER(G39)),IFERROR(H39/G39-1,""),"") | I40: =IF(AND(ISNUMBER(I39),ISNUMBER(H39)),IFERROR(I39/H39-1,""),"") | J40: =IF(AND(ISNUMBER(J39),ISNUMBER(I39)),IFERROR(J39/I39-1,""),"") | K40: =IF(AND(ISNUMBER(K39),ISNUMBER(J39)),IFERROR(K39/J39-1,""),"") | L40: =IF(AND(ISNUMBER(L39),ISNUMBER(K39)),IFERROR(L39/K39-1,""),"") | Q40: =IF(AND(ISNUMBER(Q39),ISNUMBER(L39)),IFERROR(Q39/L39-1,""),"") | R40: =IF(AND(ISNUMBER(R39),ISNUMBER(M39)),IFERROR(R39/M39-1,""),"") | S40: =IF(AND(ISNUMBER(S39),ISNUMBER(N39)),IFERROR(S39/N39-1,""),"") | T40: =IF(AND(ISNUMBER(T39),ISNUMBER(O39)),IFERROR(T39/O39-1,""),"") | U40: =IF(AND(ISNUMBER(U39),ISNUMBER(P39)),IFERROR(U39/P39-1,""),"") | V40: =IF(AND(ISNUMBER(V39),ISNUMBER(Q39)),IFERROR(V39/Q39-1,""),"") -> -0.11107714 | W40: =IF(AND(ISNUMBER(W39),ISNUMBER(R39)),IFERROR(W39/R39-1,""),"") | X40: =IF(AND(ISNUMBER(X39),ISNUMBER(S39)),IFERROR(X39/S39-1,""),"") | ... AN40: =IF(AND(ISNUMBER(AN39),ISNUMBER(AI39)),IFERROR(AN39/AI39-1,""),"") -> 0.25410715 | AO40: =AO41+$AO$109 -> 0.20239971 | AP40: =IF(AND(ISNUMBER(AP39),ISNUMBER(AK39)),IFERROR(AP39/AK39-1,""),"") -> 0.28127994 | AQ40: =CHOOSE(MATCH($AV$2,{"Bull","Base","Bear"},0),$BE$64,$BF$64,$BG$64) -> 0 | AR40: =CHOOSE(MATCH($AV$2,{"Bull","Base","Bear"},0),$BE$65,$BF$65,$BG$65) -> 0.04 | AS40: =CHOOSE(MATCH($AV$2,{"Bull","Base","Bear"},0),$BE$66,$BF$66,$BG$66) -> 0.04 | AT40: =CHOOSE(MATCH($AV$2,{"Bull","Base","Bear"},0),$BE$67,$BF$67,$BG$67) -> 0.03 | AU40: =CHOOSE(MATCH($AV$2,{"Bull","Base","Bear"},0),$BE$68,$BF$68,$BG$68) -> 0.03 | BD40: 2027E | BE40: =BF40+$BE$39 -> 0.12 | BF40: 0.09 | BG40: =BF40+$BG$39 -> 0.03
...

Sheet Bull-Base-Bear
B2: Woodward, Inc. (WWD) — Bull / Base / Bear Case P&L Summary | J2: Share price ($): | K2: =Model!$AQ$420 -> 382.17
B3: Adjusted figures (company definitions: adjusted EBIT, adjusted EBITDA, adjusted EPS) · USD millions · fiscal years ended 30 September · Live panel linked to Model — toggle scenario via Model!AV2. Bull and Bear panels are value snapshots generated from the Model with the switch set to each case. FY2026E = Q1–Q3 actual + Q4 calibrated to the FY26 guidance (sales +20–23%, adjusted EPS $9.30–9.50). | J3: As of: | K3: =TODAY() -> 2026-10-07 00:00:00
B5: Scenario: | C5: =Model!$AV$2 -> Base | N5: Scenario: | O5: Bull | P5: Snapshot (values) — Model run with switch = Bull | Z5: Scenario: | AA5: Bear | AB5: Snapshot (values) — Model run with switch = Bear
B7: (USDm, except EPS and shares) | C7: 2026E | D7: 2027E | E7: 2028E | F7: 2029E | G7: 2030E | H7: 2031E | I7: 26-'31 CAGR | J7: LT Hist Avg | K7: LT Hist Min | L7: LT Hist Max | N7: (USDm, except EPS and shares) | O7: 2026E | P7: 2027E | Q7: 2028E | R7: 2029E | S7: 2030E | T7: 2031E | U7: 26-'31 CAGR | V7: LT Hist Avg | W7: LT Hist Min | X7: LT Hist Max | Z7: (USDm, except EPS and shares) | AA7: 2026E | AB7: 2027E | AC7: 2028E | AD7: 2029E | AE7: 2030E | AF7: 2031E | AG7: 26-'31 CAGR | AH7: LT Hist Avg | AI7: LT Hist Min | AJ7: LT Hist Max
B9: Net sales | C9: =Model!AP150 -> 4333.9828 | D9: =Model!AQ150 -> 4707.0276 | E9: =Model!AR150 -> 5101.6142 | F9: =Model!AS150 -> 5466.6132 | G9: =Model!AT150 -> 5796.2854 | H9: =Model!AU150 -> 6123.5137 | I9: =IFERROR((H9/C9)^(1/5)-1,"n/m") -> 0.071575319 | N9: Net sales | O9: 4387.4887 | P9: 4932.2285 | Q9: 5546.4013 | R9: 6161.6821 | S9: 6769.7071 | T9: 7405.5381 | U9: 0.11037103 | Z9: Net sales | AA9: 4280.4768 | AB9: 4379.054 | AC9: 4457.4338 | AD9: 4485.8453 | AE9: 4466.6351 | AF9: 4432.509 | AG9: 0.0070046959
B10: Net sales y/y % | D10: =IFERROR(D9/C9-1,"") -> 0.086074373 | E10: =IFERROR(E9/D9-1,"") -> 0.083829245 | F10: =IFERROR(F9/E9-1,"") -> 0.071545784 | G10: =IFERROR(G9/F9-1,"") -> 0.060306486 | H10: =IFERROR(H9/G9-1,"") -> 0.056454821 | N10: Net sales y/y % | P10: 0.12415753 | Q10: 0.12452237 | R10: 0.11093335 | S10: 0.098678399 | T10: 0.093922973 | Z10: Net sales y/y % | AB10: 0.023029502 | AC10: 0.017898781 | AD10: 0.0063739604 | AE10: -0.0042824042 | AF10: -0.0076402208
B11: Aerospace segment sales y/y % | C11: =Model!AP242 -> 0.21158911 | D11: =Model!AQ242 -> 0.09776405 | E11: =Model!AR242 -> 0.083028071 | F11: =Model!AS242 -> 0.070125188 | G11: =Model!AT242 -> 0.059790886 | H11: =Model!AU242 -> 0.056468204 | N11: Aerospace segment sales y/y % | O11: 0.22695865 | P11: 0.12994682 | Q11: 0.11548682 | R11: 0.10277544 | S11: 0.09254294 | T11: 0.08926244 | Z11: Aerospace segment sales y/y % | AA11: 0.19621957 | AB11: 0.043758936 | AC11: 0.028788598 | AD11: 0.015717458 | AE11: 0.0053616325 | AF11: 0.0020385845
B12: Adjusted EBITDA | C12: =Model!AP214 -> 913.5007 | D12: =Model!AQ214 -> 1024.7817 | E12: =Model!AR214 -> 1139.0037 | F12: =Model!AS214 -> 1246.7652 | G12: =Model!AT214 -> 1335.8274 | H12: =Model!AU214 -> 1422.7568 | I12: =IFERROR((H12/C12)^(1/5)-1,"n/m") -> 0.092658275 | N12: Adjusted EBITDA | O12: 921.13377 | P12: 1121.0404 | Q12: 1289.2138 | R12: 1459.4421 | S12: 1617.0928 | T12: 1780.5846 | U12: 0.14090105 | Z12: Adjusted EBITDA | AA12: 905.85902 | AB12: 853.8193 | AC12: 896.80065 | AD12: 927.13431 | AE12: 937.12811 | AF12: 941.22601 | AG12: 0.0076893323
B13: Adjusted EBITDA margin % | C13: =IFERROR(C12/C9,"") -> 0.21077626 | D13: =IFERROR(D12/D9,"") -> 0.21771312 | E13: =IFERROR(E12/E9,"") -> 0.22326339 | F13: =IFERROR(F12/F9,"") -> 0.22806904 | G13: =IFERROR(G12/G9,"") -> 0.23046266 | H13: =IFERROR(H12/H9,"") -> 0.23234321 | J13: =IFERROR(AVERAGE(Model!C215,Model!D215,Model!E215,Model!F215,Model!G215,Model!H215,Model!I215,Model!J215,Model!K215,Model!L215,Model!Q215,Model!V215,Model!AA215,Model!AF215,Model!AK215),"") -> 0.17136239 | K13: =IFERROR(MIN(Model!C215,Model!D215,Model!E215,Model!F215,Model!G215,Model!H215,Model!I215,Model!J215,Model!K215,Model!L215,Model!Q215,Model!V215,Model!AA215,Model!AF215,Model!AK215),"") -> 0.14944288 | L13: =IFERROR(MAX(Model!C215,Model!D215,Model!E215,Model!F215,Model!G215,Model!H215,Model!I215,Model!J215,Model!K215,Model!L215,Model!Q215,Model!V215,Model!AA215,Model!AF215,Model!AK215),"") -> 0.19005596 | N13: Adjusted EBITDA margin % | O13: 0.20994556 | P13: 0.22728883 | Q13: 0.23244149 | R13: 0.23685773 | S13: 0.2388719 | T13: 0.24043959 | V13: 0.17136239 | W13: 0.14944288 | X13: 0.19005596 | Z13: Adjusted EBITDA margin % | AA13: 0.21162573 | AB13: 0.19497802 | AC13: 0.20119214 | AD13: 0.20667996 | AE13: 0.20980628 | AF13: 0.2123461 | AH13: 0.17136239 | AI13: 0.14944288 | AJ13: 0.19005596
B15: EBIT (GAAP) | C15: =Model!AP160 -> 768.9607 | D15: =Model!AQ160 -> 1014.3647 | E15: =Model!AR160 -> 958.35434 | F15: =Model!AS160 -> 1064.7626 | G15: =Model!AT160 -> 1142.6146 | H15: =Model!AU160 -> 1219.5455 | I15: =IFERROR((H15/C15)^(1/5)-1,"n/m") -> 0.096626588 | N15: EBIT (GAAP) | O15: 776.59377 | P15: 1102.1105 | Q15: 1091.4447 | R15: 1250.701 | S15: 1387.2377 | T15: 1530.0406 | U15: 0.14525398 | Z15: EBIT (GAAP) | AA15: 761.31902 | AB15: 854.27906 | AC15: 738.2558 | AD15: 779.29833 | AE15: 789.81959 | AF15: 795.98077 | AG15: 0.0089442727
B16: EBIT y/y % | D16: =IFERROR(D15/C15-1,"") -> 0.31913727 | E16: =IFERROR(E15/D15-1,"") -> -0.055217203 | F16: =IFERROR(F15/E15-1,"") -> 0.11103231 | G16: =IFERROR(G15/F15-1,"") -> 0.073116755 | H16: =IFERROR(H15/G15-1,"") -> 0.067328782 | N16: EBIT y/y % | P16: 0.41915962 | Q16: -0.009677598 | R16: 0.14591325 | S16: 0.10916819 | T16: 0.10294042 | Z16: EBIT y/y % | AB16: 0.12210392 | AC16: -0.13581423 | AD16: 0.055593918 | AE16: 0.013500939 | AF16: 0.0078007433
B17: EBIT margin (GAAP) % | C17: =IFERROR(C15/C9,"") -> 0.17742588 | D17: =IFERROR(D15/D9,"") -> 0.21550006 | E17: =IFERROR(E15/E9,"") -> 0.18785316 | F17: =IFERROR(F15/F9,"") -> 0.19477556 | G17: =IFERROR(G15/G9,"") -> 0.19712877 | H17: =IFERROR(H15/H9,"") -> 0.19915779 | J17: =IFERROR(AVERAGE(Model!C253,Model!D253,Model!E253,Model!F253,Model!G253,Model!H253,Model!I253,Model!J253,Model!K253,Model!L253,Model!Q253,Model!V253,Model!AA253,Model!AF253,Model!AK253),"") -> 0.12466827 | K17: =IFERROR(MIN(Model!C253,Model!D253,Model!E253,Model!F253,Model!G253,Model!H253,Model!I253,Model!J253,Model!K253,Model!L253,Model!Q253,Model!V253,Model!AA253,Model!AF253,Model!AK253),"") -> 0.09762883 | L17: =IFERROR(MAX(Model!C253,Model!D253,Model!E253,Model!F253,Model!G253,Model!H253,Model!I253,Model!J253,Model!K253,Model!L253,Model!Q253,Model!V253,Model!AA253,Model!AF253,Model!AK253),"") -> 0.15780793 | N17: EBIT margin (GAAP) % | O17: 0.17700188 | P17: 0.22345082 | Q17: 0.19678431 | R17: 0.20298045 | S17: 0.20491843 | T17: 0.20660762 | V17: 0.12466827 | W17: 0.09762883 | X17: 0.15780793 | Z17: EBIT margin (GAAP) % | AA17: 0.17785846 | AB17: 0.19508301 | AC17: 0.1656235 | AD17: 0.17372385 | AE17: 0.17682653 | AF17: 0.17957793 | AH17: 0.12466827 | AI17: 0.09762883 | AJ17: 0.15780793
B19: Adjusted Net Earnings | C19: =Model!AP228 -> 574.51469 | D19: =Model!AQ228 -> 637.49725 | E19: =Model!AR228 -> 698.27579 | F19: =Model!AS228 -> 763.02328 | G19: =Model!AT228 -> 817.55878 | H19: =Model!AU228 -> 872.23181 | I19: =IFERROR((H19/C19)^(1/5)-1,"n/m") -> 0.087091643 | N19: Adjusted Net Earnings | O19: 580.31582 | P19: 703.16758 | Q19: 778.17112 | R19: 878.35644 | S19: 972.42817 | T19: 1072.1578 | U19: 0.13062573 | Z19: Adjusted Net Earnings | AA19: 568.70702 | AB19: 515.76324 | AC19: 542.73977 | AD19: 561.87956 | AE19: 569.03448 | AF19: 572.88127 | AG19: 0.0014636894
B21: FDSO (m) | C21: =Model!AP175 -> 61.118584 | D21: =Model!AQ175 -> 59.757613 | E21: =Model!AR175 -> 58.510436 | F21: =Model!AS175 -> 57.46884 | G21: =Model!AT175 -> 56.394854 | H21: =Model!AU175 -> 55.342988 | I21: =IFERROR((H21/C21)^(1/5)-1,"n/m") -> -0.019657425 | N21: FDSO (m) | O21: 61.085876 | P21: 58.885371 | Q21: 56.930665 | R21: 55.654596 | S21: 54.27666 | T21: 52.853958 | U21: -0.028534592 | Z21: FDSO (m) | AA21: 61.151292 | AB21: 60.627819 | AC21: 60.099639 | AD21: 59.321887 | AE21: 58.585025 | AF21: 57.936397 | AG21: -0.010742916
B23: Adjusted EPS — Diluted ($) | C23: =Model!AP231 -> 9.4 | D23: =Model!AQ231 -> 10.668051 | E23: =Model!AR231 -> 11.934209 | F23: =Model!AS231 -> 13.277165 | G23: =Model!AT231 -> 14.497046 | H23: =Model!AU231 -> 15.760476 | I23: =IFERROR((H23/C23)^(1/5)-1,"n/m") -> 0.10888956 | N23: Adjusted EPS — Diluted ($) | O23: 9.5 | P23: 11.941295 | Q23: 13.668752 | R23: 15.78228 | S23: 17.916139 | T23: 20.28529 | U23: 0.16383529 | Z23: Adjusted EPS — Diluted ($) | AA23: 9.3 | AB23: 8.5070393 | AC23: 9.030666 | AD23: 9.4717075 | AE23: 9.7129682 | AF23: 9.8881066 | AG23: 0.012339164
B24: EPS y/y % | D24: =IFERROR(D23/C23-1,"") -> 0.13489902 | E24: =IFERROR(E23/D23-1,"") -> 0.11868697 | F24: =IFERROR(F23/E23-1,"") -> 0.11252994 | G24: =IFERROR(G23/F23-1,"") -> 0.091878101 | H24: =IFERROR(H23/G23-1,"") -> 0.087150839 | N24: EPS y/y % | P24: 0.2569784 | Q24: 0.14466243 | R24: 0.15462486 | S24: 0.13520597 | T24: 0.13223557 | Z24: EPS y/y % | AB24: -0.085264588 | AC24: 0.061552158 | AD24: 0.048838212 | AE24: 0.025471713 | AF24: 0.018031407
B26: P / E (x) — assumed (adjusted EPS) | G26: 32 | H26: 32 | N26: P / E (x) — assumed (adjusted EPS) | S26: 36 | T26: 36 | Z26: P / E (x) — assumed (adjusted EPS) | AD26: 25 | AE26: 25 | AF26: 25
B27: Price Target ($) | G27: =G26*G23 -> 463.90547 | H27: =H26*H23 -> 504.33522 | N27: Price Target ($) | S27: =S26*S23 -> 644.981 | T27: =T26*T23 -> 730.27043 | Z27: Price Target ($) | AD27: =AD26*AD23 -> 236.79269 | AE27: =AE26*AE23 -> 242.8242 | AF27: =AF26*AF23 -> 247.20267
B28: Upside / (Downside) vs current | G28: =IFERROR(G27/$K$2-1,"") -> 0.21387202 | H28: =IFERROR(H27/$K$2-1,"") -> 0.31966198 | N28: Upside / (Downside) vs current | S28: =IFERROR(S27/$K$2-1,"") -> 0.68768088 | T28: =IFERROR(T27/$K$2-1,"") -> 0.91085233 | Z28: Upside / (Downside) vs current | AD28: =IFERROR(AD27/$K$2-1,"") -> -0.38039959 | AE28: =IFERROR(AE27/$K$2-1,"") -> -0.36461731 | AF28: =IFERROR(AF27/$K$2-1,"") -> -0.35316046
B29: IRR (to 30-Sep of Y-1) | G29: =IFERROR((G27/$K$2)^(1/((DATE(2030-1,9,30)-$K$3)/365.25))-1,"") -> 0.067164929 | H29: =IFERROR((H27/$K$2)^(1/((DATE(2031-1,9,30)-$K$3)/365.25))-1,"") -> 0.072162621 | N29: IRR (to 30-Sep of Y-1) | S29: =IFERROR((S27/$K$2)^(1/((DATE(2030-1,9,30)-$K$3)/365.25))-1,"") -> 0.19188142 | T29: =IFERROR((T27/$K$2)^(1/((DATE(2031-1,9,30)-$K$3)/365.25))-1,"") -> 0.17664447 | Z29: IRR (to 30-Sep of Y-1) | AD29: =IFERROR((AD27/$K$2)^(1/((DATE(2029-1,9,30)-$K$3)/365.25))-1,"") -> -0.21454258 | AE29: =IFERROR((AE27/$K$2)^(1/((DATE(2030-1,9,30)-$K$3)/365.25))-1,"") -> -0.14110876 | AF29: =IFERROR((AF27/$K$2)^(1/((DATE(2031-1,9,30)-$K$3)/365.25))-1,"") -> -0.1036628
B31: Free Cash Flow | C31: =Model!AP285 -> 292.75614 | D31: =Model!AQ285 -> 420.65842 | E31: =Model!AR285 -> 606.49127 | F31: =Model!AS285 -> 713.13048 | G31: =Model!AT285 -> 789.61244 | H31: =Model!AU285 -> 848.51378 | I31: =IFERROR((H31/C31)^(1/5)-1,"n/m") -> 0.23717341 | N31: Free Cash Flow | O31: 286.12095 | P31: 450.07557 | Q31: 639.17503 | R31: 779.57821 | S31: 894.5731 | T31: 996.06585 | U31: 0.28335757 | Z31: Free Cash Flow | AA31: 299.38356 | AB31: 352.69877 | AC31: 520.77733 | AD31: 580.19836 | AE31: 606.0242 | AF31: 612.32828 | AG31: 0.1538551
B32: FCF % | C32: =IFERROR(C31/C9,"") -> 0.067548985 | D32: =IFERROR(D31/D9,"") -> 0.089368164 | E32: =IFERROR(E31/E9,"") -> 0.11888223 | F32: =IFERROR(F31/F9,"") -> 0.13045197 | G32: =IFERROR(G31/G9,"") -> 0.13622732 | H32: =IFERROR(H31/H9,"") -> 0.13856649 | J32: =IFERROR(AVERAGE(Model!C289,Model!D289,Model!E289,Model!F289,Model!G289,Model!H289,Model!I289,Model!J289,Model!K289,Model!L289,Model!Q289,Model!V289,Model!AA289,Model!AF289,Model!AK289),"") -> 0.080527366 | K32: =IFERROR(MIN(Model!C289,Model!D289,Model!E289,Model!F289,Model!G289,Model!H289,Model!I289,Model!J289,Model!K289,Model!L289,Model!Q289,Model!V289,Model!AA289,Model!AF289,Model!AK289),"") -> 0.00040082363 | L32: =IFERROR(MAX(Model!C289,Model!D289,Model!E289,Model!F289,Model!G289,Model!H289,Model!I289,Model!J289,Model!K289,Model!L289,Model!Q289,Model!V289,Model!AA289,Model!AF289,Model!AK289),"") -> 0.19012108 | N32: FCF % | O32: 0.06521292 | P32: 0.091251971 | Q32: 0.1152414 | R32: 0.12652035 | S32: 0.13214355 | T32: 0.13450283 | V32: 0.080527366 | W32: 0.00040082363 | X32: 0.19012108 | Z32: FCF % | AA32: 0.069941637 | AB32: 0.080542228 | AC32: 0.11683344 | AD32: 0.12933981 | AE32: 0.13567802 | AF32: 0.13814485 | AH32: 0.080527366 | AI32: 0.00040082363 | AJ32: 0.19012108
B33: FCF / share ($) | C33: =IFERROR(C31/C21,"") -> 4.7899692 | D33: =IFERROR(D31/D21,"") -> 7.0394113 | E33: =IFERROR(E31/E21,"") -> 10.365523 | F33: =IFERROR(F31/F21,"") -> 12.408994 | G33: =IFERROR(G31/G21,"") -> 14.001498 | H33: =IFERROR(H31/H21,"") -> 15.331911 | N33: FCF / share ($) | O33: 4.6839134 | P33: 7.6432493 | Q33: 11.227254 | R33: 14.007436 | S33: 16.481727 | T33: 18.845625 | Z33: FCF / share ($) | AA33: 4.8957846 | AB33: 5.8174412 | AC33: 8.6652323 | AD33: 9.7805108 | AE33: 10.344353 | AF33: 10.568974
B34: FCF Yield (on PT) | F34: =IFERROR(F33/F$27,"") | G34: =IFERROR(G33/G$27,"") -> 0.030181791 | H34: =IFERROR(H33/H$27,"") -> 0.030400239 | N34: FCF Yield (on PT) | R34: =IFERROR(R33/R$27,"") | S34: =IFERROR(S33/S$27,"") -> 0.025553818 | T34: =IFERROR(T33/T$27,"") -> 0.025806364 | Z34: FCF Yield (on PT) | AD34: =IFERROR(AD33/AD$27,"") -> 0.041304108 | AE34: =IFERROR(AE33/AE$27,"") -> 0.042600174 | AF34: =IFERROR(AF33/AF$27,"") -> 0.042754288
B35: Adjusted EBITDA (leverage basis) | C35: =Model!AP214 -> 913.5007 | D35: =Model!AQ214 -> 1024.7817 | E35: =Model!AR214 -> 1139.0037 | F35: =Model!AS214 -> 1246.7652 | G35: =Model!AT214 -> 1335.8274 | H35: =Model!AU214 -> 1422.7568 | I35: =IFERROR((H35/C35)^(1/5)-1,"n/m") -> 0.092658275 | N35: Adjusted EBITDA (leverage basis) | O35: 921.13377 | P35: 1121.0404 | Q35: 1289.2138 | R35: 1459.4421 | S35: 1617.0928 | T35: 1780.5846 | U35: 0.14090105 | Z35: Adjusted EBITDA (leverage basis) | AA35: 905.85902 | AB35: 853.8193 | AC35: 896.80065 | AD35: 927.13431 | AE35: 937.12811 | AF35: 941.22601 | AG35: 0.0076893323
B36: Adjusted EBITDA % of net sales | C36: =IFERROR(C35/C9,"") -> 0.21077626 | D36: =IFERROR(D35/D9,"") -> 0.21771312 | E36: =IFERROR(E35/E9,"") -> 0.22326339 | F36: =IFERROR(F35/F9,"") -> 0.22806904 | G36: =IFERROR(G35/G9,"") -> 0.23046266 | H36: =IFERROR(H35/H9,"") -> 0.23234321 | J36: =IFERROR(AVERAGE(Model!C252,Model!D252,Model!E252,Model!F252,Model!G252,Model!H252,Model!I252,Model!J252,Model!K252,Model!L252,Model!Q252,Model!V252,Model!AA252,Model!AF252,Model!AK252),"") -> 0.17136239 | K36: =IFERROR(MIN(Model!C252,Model!D252,Model!E252,Model!F252,Model!G252,Model!H252,Model!I252,Model!J252,Model!K252,Model!L252,Model!Q252,Model!V252,Model!AA252,Model!AF252,Model!AK252),"") -> 0.14944288 | L36: =IFERROR(MAX(Model!C252,Model!D252,Model!E252,Model!F252,Model!G252,Model!H252,Model!I252,Model!J252,Model!K252,Model!L252,Model!Q252,Model!V252,Model!AA252,Model!AF252,Model!AK252),"") -> 0.19005596 | N36: Adjusted EBITDA % of net sales | O36: 0.20994556 | P36: 0.22728883 | Q36: 0.23244149 | R36: 0.23685773 | S36: 0.2388719 | T36: 0.24043959 | V36: 0.17136239 | W36: 0.14944288 | X36: 0.19005596 | Z36: Adjusted EBITDA % of net sales | AA36: 0.21162573 | AB36: 0.19497802 | AC36: 0.20119214 | AD36: 0.20667996 | AE36: 0.20980628 | AF36: 0.2123461 | AH36: 0.17136239 | AI36: 0.14944288 | AJ36: 0.19005596
B38: Net Debt | C38: =Model!AP414 -> 978.81341 | D38: =Model!AQ414 -> 1280.9771 | E38: =Model!AR414 -> 1423.7546 | F38: =Model!AS414 -> 1558.4566 | G38: =Model!AT414 -> 1669.7842 | H38: =Model!AU414 -> 1778.446 | N38: Net Debt | O38: 1085.4067 | P38: 1961.8208 | Q38: 2256.1241 | R38: 2554.0236 | S38: 2829.9124 | T38: 3116.023 | Z38: Net Debt | AA38: 872.22786 | AB38: 640.36447 | AC38: 672.60048 | AD38: 695.35073 | AE38: 702.84608 | AF38: 705.91951
B39: Net Debt / Adjusted EBITDA (x) | C39: =IFERROR(C38/C35,"") -> 1.0714972 | D39: =IFERROR(D38/D35,"") -> 1.25 | E39: =IFERROR(E38/E35,"") -> 1.25 | F39: =IFERROR(F38/F35,"") -> 1.25 | G39: =IFERROR(G38/G35,"") -> 1.25 | H39: =IFERROR(H38/H35,"") -> 1.25 | N39: Net Debt / Adjusted EBITDA (x) | O39: 1.1783378 | P39: 1.75 | Q39: 1.75 | R39: 1.75 | S39: 1.75 | T39: 1.75 | Z39: Net Debt / Adjusted EBITDA (x) | AA39: 0.96287373 | AB39: 0.75 | AC39: 0.75 | AD39: 0.75 | AE39: 0.75 | AF39: 0.75
B40: Share repurchases ($m; FY2026E = Q4) | D40: =Model!AQ299 -> 782.61118 | E40: =Model!AR299 -> 623.28152 | F40: =Model!AS299 -> 714.89397 | G40: =Model!AT299 -> 760.67753 | H40: =Model!AU299 -> 809.00964 | N40: Share repurchases ($m; FY2026E = Q4) | P40: 1286.6356 | Q40: 709.71592 | R40: 847.3066 | S40: 933.74272 | T40: 1038.573 | AB40: 280.26754 | AC40: 524.80738 | AD40: 567.20497 | AE40: 569.61432 | AF40: 562.49498
B41: Implied avg buyback price ($) | D41: =Model!AQ298 -> 412.7436 | E41: =Model!AR298 -> 445.76309 | F41: =Model!AS298 -> 481.42414 | G41: =Model!AT298 -> 519.93807 | H41: =Model!AU298 -> 561.53311 | N41: Implied avg buyback price ($) | P41: 412.7436 | Q41: 445.76309 | R41: 481.42414 | S41: 519.93807 | T41: 561.53311 | AB41: 412.7436 | AC41: 445.76309 | AD41: 481.42414 | AE41: 519.93807 | AF41: 561.53311
B42: Shares repurchased (m) | D42: =Model!AQ300 -> 1.8961195 | E42: =Model!AR300 -> 1.3982349 | F42: =Model!AS300 -> 1.4849567 | G42: =Model!AT300 -> 1.4630157 | H42: =Model!AU300 -> 1.4407158 | N42: Shares repurchased (m) | P42: 3.1172757 | Q42: 1.592137 | R42: 1.7600002 | S42: 1.795873 | T42: 1.8495311 | AB42: 0.67903546 | AC42: 1.1773235 | AD42: 1.1781814 | AE42: 1.0955426 | AF42: 1.0017129
B44: ROIC | C44: =Model!AP397 -> 0.180706 | D44: =Model!AQ397 -> 0.18625395 | E44: =Model!AR397 -> 0.19406949 | F44: =Model!AS397 -> 0.20214688 | G44: =Model!AT397 -> 0.20796692 | H44: =Model!AU397 -> 0.21323528 | J44: =IFERROR(AVERAGE(Model!C397,Model!D397,Model!E397,Model!F397,Model!G397,Model!H397,Model!I397,Model!J397,Model!K397,Model!L397,Model!Q397,Model!V397,Model!AA397,Model!AF397,Model!AK397),"") -> 0.11381492 | K44: =IFERROR(MIN(Model!C397,Model!D397,Model!E397,Model!F397,Model!G397,Model!H397,Model!I397,Model!J397,Model!K397,Model!L397,Model!Q397,Model!V397,Model!AA397,Model!AF397,Model!AK397),"") -> 0.080656647 | L44: =IFERROR(MAX(Model!C397,Model!D397,Model!E397,Model!F397,Model!G397,Model!H397,Model!I397,Model!J397,Model!K397,Model!L397,Model!Q397,Model!V397,Model!AA397,Model!AF397,Model!AK397),"") -> 0.16769573 | N44: ROIC | O44: 0.18174692 | P44: 0.19718811 | Q44: 0.20522156 | R44: 0.21411076 | S44: 0.22122374 | T44: 0.22820186 | V44: 0.11381492 | W44: 0.080656647 | X44: 0.16769573 | Z44: ROIC | AA44: 0.17965549 | AB44: 0.15931723 | AC44: 0.16426734 | AD44: 0.16900448 | AE44: 0.1712394 | AF44: 0.17266072 | AH44: 0.11381492 | AI44: 0.080656647 | AJ44: 0.16769573
B45: RONTA | C45: =Model!AP408 -> 0.20142276 | D45: =Model!AQ408 -> 0.21064484 | E45: =Model!AR408 -> 0.22259846 | F45: =Model!AS408 -> 0.23497117 | G45: =Model!AT408 -> 0.24473416 | H45: =Model!AU408 -> 0.25374714 | J45: =IFERROR(AVERAGE(Model!C408,Model!D408,Model!E408,Model!F408,Model!G408,Model!H408,Model!I408,Model!J408,Model!K408,Model!L408,Model!Q408,Model!V408,Model!AA408,Model!AF408,Model!AK408),"") -> 0.14677544 | K45: =IFERROR(MIN(Model!C408,Model!D408,Model!E408,Model!F408,Model!G408,Model!H408,Model!I408,Model!J408,Model!K408,Model!L408,Model!Q408,Model!V408,Model!AA408,Model!AF408,Model!AK408),"") -> 0.099246509 | L45: =IFERROR(MAX(Model!C408,Model!D408,Model!E408,Model!F408,Model!G408,Model!H408,Model!I408,Model!J408,Model!K408,Model!L408,Model!Q408,Model!V408,Model!AA408,Model!AF408,Model!AK408),"") -> 0.19011194 | N45: RONTA | O45: 0.20249826 | P45: 0.2278247 | Q45: 0.24451295 | R45: 0.261944 | S45: 0.27686442 | T45: 0.29108591 | V45: 0.14677544 | W45: 0.099246509 | X45: 0.19011194 | Z45: RONTA | AA45: 0.20033626 | AB45: 0.16517865 | AC45: 0.17123084 | AD45: 0.17672245 | AE45: 0.17886462 | AF45: 0.17998872 | AH45: 0.14677544 | AI45: 0.099246509 | AJ45: 0.19011194
B47: Implied Market Cap (USDm) | F47: =F27*F21 -> 0 | G47: =G27*G21 -> 26161.881 | H47: =H27*H21 -> 27911.418 | N47: Implied Market Cap (USDm) | R47: =R27*R21 -> 0 | S47: =S27*S21 -> 35007.414 | T47: =T27*T21 -> 38597.683 | Z47: Implied Market Cap (USDm) | AD47: =AD27*AD21 -> 14046.989 | AE47: =AE27*AE21 -> 14225.862 | AF47: =AF27*AF21 -> 14322.032
B48: (+) Net Debt & NCI | F48: =F38+Model!AS328 -> 1558.4566 | G48: =G38+Model!AT328 -> 1669.7842 | H48: =H38+Model!AU328 -> 1778.446 | N48: (+) Net Debt & NCI | R48: =R38+Model!AS328 -> 2554.0236 | S48: =S38+Model!AT328 -> 2829.9124 | T48: =T38+Model!AU328 -> 3116.023 | Z48: (+) Net Debt & NCI | AD48: =AD38+Model!AS328 -> 695.35073 | AE48: =AE38+Model!AT328 -> 702.84608 | AF48: =AF38+Model!AU328 -> 705.91951
B49: Implied Enterprise Value (USDm) | F49: =F47+F48 -> 1558.4566 | G49: =G47+G48 -> 27831.665 | H49: =H47+H48 -> 29689.864 | N49: Implied Enterprise Value (USDm) | R49: =R47+R48 -> 2554.0236 | S49: =S47+S48 -> 37837.327 | T49: =T47+T48 -> 41713.706 | Z49: Implied Enterprise Value (USDm) | AD49: =AD47+AD48 -> 14742.34 | AE49: =AE47+AE48 -> 14928.708 | AF49: =AF47+AF48 -> 15027.951
B50: Implied EV / Adjusted EBITDA (x) | F50: =IFERROR(F49/F35,"") -> 1.25 | G50: =IFERROR(G49/G35,"") -> 20.834777 | H50: =IFERROR(H49/H35,"") -> 20.867842 | N50: Implied EV / Adjusted EBITDA (x) | R50: =IFERROR(R49/R35,"") -> 1.75 | S50: =IFERROR(S49/S35,"") -> 23.398364 | T50: =IFERROR(T49/T35,"") -> 23.426972 | Z50: Implied EV / Adjusted EBITDA (x) | AD50: =IFERROR(AD49/AD35,"") -> 15.900975 | AE50: =IFERROR(AE49/AE35,"") -> 15.930275 | AF50: =IFERROR(AF49/AF35,"") -> 15.966358

Sheet DCF
B2: DCF VALUATION — WOODWARD, INC. (WWD)
B4: 1. WACC BUILD
B5: Risk-free rate (US 10Y govt) | C5: 0.0425 | D5: Assumption (~US 10Y Treasury yield, Oct-2026; government rate sources not reachable from the build environment); update to market
B6: Equity risk premium | C6: 0.05 | D6: Assumption: US implied ERP ~4.5–5.5%
B7: Levered beta | C7: 1.05 | D7: Assumption: aerospace & defense components peers (HEI, TDG, CW, MOG, PH aerospace) ~0.9–1.2; ~30% of sales Industrial (cyclical power generation / transportation / oil & gas)
B8: Cost of equity | C8: =C5+C7*C6 -> 0.095
B9: Pre-tax cost of debt | C9: 0.055 | D9: Aug-2026 Series U / V / W private-placement notes at 5.34% / 5.39% / 5.64% (8-K 21-Aug-2026); revolver at SOFR + 0.875–1.75% (4.73% at 30-Jun-2026)
B10: Tax rate | C10: 0.225 | D10: Model FY2027E+ effective tax rate (FY26 adjusted-rate guidance ~22.5%)
B11: After-tax cost of debt | C11: =C9*(1-C10) -> 0.042625
B12: Target D/V | C12: 0.06 | D12: Net debt ~$0.9bn at 30-Jun-2026 vs ~$23bn market cap ($382.17 × ~61m diluted shares); ~1.0x adjusted EBITDA
B13: WACC | C13: =C8*(1-C12)+C11*C12 -> 0.0918575
B15: Valuation date (live) | C15: =TODAY() -> 2026-10-07 00:00:00 | D15: Periods = (30-Sep of fiscal year − today) / 365.25; cash flows assumed at fiscal year-end (30 September); FY2026E (ended 30-Sep-2026) is the base year
B16: 2. UNLEVERED FREE CASH FLOW BUILD (USDm)
D17: 2027E | E17: 2028E | F17: 2029E | G17: 2030E | H17: 2031E | I17: 2032E | J17: 2033E | K17: 2034E | L17: 2035E | M17: 2036E | N17: Terminal | P17: CAGR 27–31E | Q17: CAGR 27–36E
