Workbook

Sheet Model
AF1: SCENARIO SWITCH ▼ (Bull / Base / Bear) — drives all scenario-linked forecast drivers
B2: XPO, Inc. (NYSE: XPO) — 3-Statement Financial Model | AF2: Base
B3: US GAAP as reported · USD millions (per-share data in USD; LTL pounds per day in thousands) · Source: XPO Forms 10-K / 10-Q, Form 8-K earnings releases (Ex. 99.1), investor presentations and monthly LTL operating-data releases (Item 7.01, Ex. 99.1), SEC EDGAR CIK 0001166003 (investor-relations releases are the same documents as filed on EDGAR)
B4: Basis notes: calendar fiscal year. History starts in FY2022, the year XPO became a standalone North American LTL + European Transportation company (GXO spun off Aug-2021; North American intermodal sold Mar-2022; RXO spun off 1-Nov-2022). 2022 P&L, segment, non-GAAP and cash-flow data on the continuing-operations basis recast in the 2023 releases (natural-expense income statement adopted Q1/23, 2022 recast); balance sheet from 31-Dec-2022 (Q1–Q3/22 balance sheets included RXO). Real-estate gains are included in adjusted EBITDA but excluded from LTL adjusted operating income (current company definitions). Valuation share price $180.00 = user-provided input.
AH5: Forecast | AI5: Historical
B6: (USDm) | C6: Q1/22 | D6: Q2/22 | E6: Q3/22 | F6: Q4/22 | G6: 2022 | H6: Q1/23 | I6: Q2/23 | J6: Q3/23 | K6: Q4/23 | L6: 2023 | M6: Q1/24 | N6: Q2/24 | O6: Q3/24 | P6: Q4/24 | Q6: 2024 | R6: Q1/25 | S6: Q2/25 | T6: Q3/25 | U6: Q4/25 | V6: 2025 | W6: Q1/26 | X6: Q2/26 | Y6: Q3/26E | Z6: Q4/26E | AA6: 2026E | AB6: 2027E | AC6: 2028E | AD6: 2029E | AE6: 2030E | AF6: Modelling Notes | AH6: 5Y CAGR | AI6: 3Y CAGR
AH7: 25-'30 | AI7: 22-'25
B8: SEGMENT P&L — NORTH AMERICAN LTL · EUROPEAN TRANSPORTATION · CORPORATE (tonnage × yield build) | AF8: SEGMENT BUILD — modelling logic (pounds/day × days × yield → revenue → adjusted operating ratio → adjusted EBITDA)
AL9: SCENARIO INPUT TABLE — driver assumptions per Bull / Base / Bear | AM9: Bull | AN9: Base | AO9: Bear | AP9: Bull / Bear = Base + Δ (Δ inputs on each block header). Outlook block = high / mid / low end of the company planning assumptions.
B10: North American LTL (asset-based less-than-truckload; ~300 service centers, 4th-largest US LTL carrier) — segment | AF10: NORTH AMERICAN LTL — modelling logic
B11: Working days | C11: 64 | D11: 64 | E11: 64 | F11: 61 | G11: 252.5 | H11: 64 | I11: 63.5 | J11: 62.5 | K11: 61 | L11: 251 | M11: 63.5 | N11: 64 | O11: 63.5 | P11: 61.5 | Q11: 252.5 | R11: 63 | S11: 63.5 | T11: 64 | U11: 61 | V11: 251.5 | W11: 62.5 | X11: 63.5 | Y11: =T11 -> 64 | Z11: =U11 -> 61 | AA11: =SUM(W11,X11,Y11,Z11) -> 251 | AB11: 252 | AC11: 252 | AD11: 252 | AE11: 252 | AF11: Q3/Q4-26E: prior-year quarter working days. 2027E+: 252 (input). | AL11: FY26 outlook — Q2-26 investor deck (30-Jul-26); company planning assumptions | AM11: High | AN11: Mid | AO11: Low | AP11: XPO gives planning assumptions (not revenue / EBITDA / EPS guidance). Bull/Base/Bear pick the high / mid / low end where a range is given.
B12: Pounds per day (thousands) — tonnage | C12: 70176 | D12: 72333 | E12: 70063 | F12: 67996 | G12: 70163 | H12: 68889 | I12: 70290 | J12: 72257 | K12: 69357 | L12: 70196 | M12: 70709 | N12: 72658 | O12: 69470 | P12: 65433 | Q12: 69606 | R12: 65427 | S12: 67813 | T12: 65236 | U12: 62486 | V12: 65268 | W12: 65510 | X12: 68463 | Y12: =T12*(1+Y13) -> 67519.26 | Z12: =U12*(1+Z13) -> 64985.44 | AA12: =IFERROR((W11*W12+X11*X12+Y11*Y12+Z11*Z12)/AA11,"") -> 66641.912 | AB12: =AA12*(1+AB13) -> 68641.17 | AC12: =AB12*(1+AC13) -> 70700.405 | AD12: =AC12*(1+AD13) -> 72467.915 | AE12: =AD12*(1+AE13) -> 74279.613 | AF12: Q3/Q4-26E: prior-year quarter × (1 + tonnage/day y/y input). 2026E = working-day-weighted average of the quarters. 2027E+: × (1 + scenario lever LTL_vol). | AH12: =IFERROR((AE12/V12)^(1/5)-1,"n/m") -> 0.026204383 | AI12: =IFERROR((V12/G12)^(1/3)-1,"n/m") -> -0.023818173 | AL12: Total company gross capex ($m) | AM12: 600 | AN12: 550 | AO12: 500 | AP12: Planning assumption $500–600m (unchanged Feb-26 → Jul-26).
B13: Tonnage (pounds) per day y/y % | H13: =IF(AND(ISNUMBER(H12),ISNUMBER(C12)),IFERROR(H12/C12-1,""),"") -> -0.018339603 | I13: =IF(AND(ISNUMBER(I12),ISNUMBER(D12)),IFERROR(I12/D12-1,""),"") -> -0.02824437 | J13: =IF(AND(ISNUMBER(J12),ISNUMBER(E12)),IFERROR(J12/E12-1,""),"") -> 0.031314674 | K13: =IF(AND(ISNUMBER(K12),ISNUMBER(F12)),IFERROR(K12/F12-1,""),"") -> 0.020015883 | L13: =IF(AND(ISNUMBER(L12),ISNUMBER(G12)),IFERROR(L12/G12-1,""),"") -> 0.00047033337 | M13: =IF(AND(ISNUMBER(M12),ISNUMBER(H12)),IFERROR(M12/H12-1,""),"") -> 0.026419312 | N13: =IF(AND(ISNUMBER(N12),ISNUMBER(I12)),IFERROR(N12/I12-1,""),"") -> 0.033689003 | O13: =IF(AND(ISNUMBER(O12),ISNUMBER(J12)),IFERROR(O12/J12-1,""),"") -> -0.038570658 | ... X13: =IF(AND(ISNUMBER(X12),ISNUMBER(S12)),IFERROR(X12/S12-1,""),"") -> 0.0095851828 | Y13: 0.035 | Z13: 0.04 | AA13: =IFERROR(AA12/V12-1,"") -> 0.02105032 | AB13: =CHOOSE(MATCH($AF$2,{"Bull","Base","Bear"},0),$AM$30,$AN$30,$AO$30) -> 0.03 | AC13: =CHOOSE(MATCH($AF$2,{"Bull","Base","Bear"},0),$AM$31,$AN$31,$AO$31) -> 0.03 | AD13: =CHOOSE(MATCH($AF$2,{"Bull","Base","Bear"},0),$AM$32,$AN$32,$AO$32) -> 0.025 | AE13: =CHOOSE(MATCH($AF$2,{"Bull","Base","Bear"},0),$AM$33,$AN$33,$AO$33) -> 0.025 | AF13: Q3/26E +3.5% input: Aug-26 tonnage/day +3.7% y/y (shipments/day +5.7%, weight/shipment −1.8%; 8-K 3-Sep-26), Q2/26 +1.0%, easy comp (Q3/25 −6.1%). Q4/26E +4.0% (Q4/25 comp −4.5%). 2027E+: scenario lever LTL_vol. | AL13: Interest expense ($m) | AN13: 210 | AP13: $205–215m (mid-point).
B14: Memo: reported tonnage per day y/y % (company; 2022 vs 2021) | C14: -0.008 | D14: -0.055 | E14: -0.029 | F14: 0.009 | G14: -0.022 | AL14: Pension income ($m) | AN14: 14 | AP14: Approximately $14m.
B15: Shipments per day | C15: 48366 | D15: 50274 | E15: 49744 | F15: 48622 | G15: 49257 | H15: 49107 | I15: 51220 | J15: 53637 | K15: 51382 | L15: 51322 | M15: 51392 | N15: 53519 | O15: 51921 | P15: 49109 | Q15: 51508 | R15: 48400 | S15: 50782 | T15: 50094 | U15: 48348 | V15: 49420 | W15: 49834 | X15: 52229 | AL15: Adjusted effective tax rate | AM15: 0.23 | AN15: 0.235 | AO15: 0.24 | AP15: Lowered to 23–24% in Jul-26 (from 24–25% in Feb-26).
B16: Shipments per day y/y % | H16: =IF(AND(ISNUMBER(H15),ISNUMBER(C15)),IFERROR(H15/C15-1,""),"") -> 0.01532068 | I16: =IF(AND(ISNUMBER(I15),ISNUMBER(D15)),IFERROR(I15/D15-1,""),"") -> 0.018816883 | J16: =IF(AND(ISNUMBER(J15),ISNUMBER(E15)),IFERROR(J15/E15-1,""),"") -> 0.078260695 | K16: =IF(AND(ISNUMBER(K15),ISNUMBER(F15)),IFERROR(K15/F15-1,""),"") -> 0.056764428 | L16: =IF(AND(ISNUMBER(L15),ISNUMBER(G15)),IFERROR(L15/G15-1,""),"") -> 0.041922975 | M16: =IF(AND(ISNUMBER(M15),ISNUMBER(H15)),IFERROR(M15/H15-1,""),"") -> 0.046531044 | N16: =IF(AND(ISNUMBER(N15),ISNUMBER(I15)),IFERROR(N15/I15-1,""),"") -> 0.044884811 | O16: =IF(AND(ISNUMBER(O15),ISNUMBER(J15)),IFERROR(O15/J15-1,""),"") -> -0.031992841 | ... X16: =IF(AND(ISNUMBER(X15),ISNUMBER(S15)),IFERROR(X15/S15-1,""),"") -> 0.028494348 | AL16: Diluted share count (m) | AN16: 118 | AP16: Approximately 118m.
B17: Average weight per shipment (lbs) | C17: 1451 | D17: 1439 | E17: 1408 | F17: 1398 | G17: 1424 | H17: 1403 | I17: 1372 | J17: 1347 | K17: 1350 | L17: 1368 | M17: 1376 | N17: 1358 | O17: 1338 | P17: 1332 | Q17: 1351 | R17: 1352 | S17: 1335 | T17: 1302 | U17: 1292 | V17: 1321 | W17: 1315 | X17: 1311 | AL17: 2H/26 share repurchases ($m) | AM17: 150 | AN17: 100 | AO17: 50 | AP17: Model assumption: 1H/26 $100m ($70m in Q2 at $205.22); $525m authorization remaining.
B18: Hundredweight shipped (millions) = pounds per day × working days ÷ 100,000 | C18: =IFERROR(C12*C11/100000,"") -> 44.91264 | D18: =IFERROR(D12*D11/100000,"") -> 46.29312 | E18: =IFERROR(E12*E11/100000,"") -> 44.84032 | F18: =IFERROR(F12*F11/100000,"") -> 41.47756 | G18: =IFERROR(G12*G11/100000,"") -> 177.16157 | H18: =IFERROR(H12*H11/100000,"") -> 44.08896 | I18: =IFERROR(I12*I11/100000,"") -> 44.63415 | J18: =IFERROR(J12*J11/100000,"") -> 45.160625 | ... Z18: =IFERROR(Z12*Z11/100000,"") -> 39.641118 | AA18: =SUM(W18,X18,Y18,Z18) -> 167.2712 | AB18: =IFERROR(AB12*AB11/100000,"") -> 172.97575 | AC18: =IFERROR(AC12*AC11/100000,"") -> 178.16502 | AD18: =IFERROR(AD12*AD11/100000,"") -> 182.61915 | AE18: =IFERROR(AE12*AE11/100000,"") -> 187.18462 | AL18: Minimum net debt / Adjusted EBITDA (x) — buyback floor 2027E+ | AM18: 1.5 | AN18: 1.25 | AO18: 1 | AP18: Model assumption (no published target): Base 1.25x; Bull re-levers to 1.5x (more buybacks), Bear 1.0x. FY25 2.4x; term loans prepayable.
B19: Gross revenue per hundredweight excl. fuel surcharges — yield ($) | C19: 20.76 | D19: 21.34 | E19: 21.43 | F19: 21.19 | G19: 21.18 | H19: 21.06 | I19: 21.63 | J19: 22.81 | K19: 23.37 | L19: 22.21 | M19: 23.13 | N19: 23.56 | O19: 24.34 | P19: 24.84 | Q19: 23.94 | R19: 24.73 | S19: 24.99 | T19: 25.77 | U19: 26.12 | V19: 25.39 | W19: 25.71 | X19: 26.09 | Y19: =T19*(1+Y20) -> 26.904334 | Z19: =U19*(1+Z20) -> 27.26974 | AA19: =IFERROR((W18*W19+X18*X19+Y18*Y19+Z18*Z19)/AA18,"") -> 26.486941 | AB19: =AA19*(1+AB20) -> 27.811288 | AC19: =AB19*(1+AC20) -> 29.062796 | AD19: =AC19*(1+AD20) -> 30.370622 | AE19: =AD19*(1+AE20) -> 31.585447 | AF19: Q3/Q4-26E: prior-year quarter × (1 + Q2/26 y/y yield change). 2027E+: × (1 + scenario lever LTL_yield). | AH19: =IFERROR((AE19/V19)^(1/5)-1,"n/m") -> 0.044635704 | AI19: =IFERROR((V19/G19)^(1/3)-1,"n/m") -> 0.062296087
B20: Yield (excl. fuel) y/y % | H20: =IF(AND(ISNUMBER(H19),ISNUMBER(C19)),IFERROR(H19/C19-1,""),"") -> 0.014450867 | I20: =IF(AND(ISNUMBER(I19),ISNUMBER(D19)),IFERROR(I19/D19-1,""),"") -> 0.013589503 | J20: =IF(AND(ISNUMBER(J19),ISNUMBER(E19)),IFERROR(J19/E19-1,""),"") -> 0.064395707 | K20: =IF(AND(ISNUMBER(K19),ISNUMBER(F19)),IFERROR(K19/F19-1,""),"") -> 0.10287872 | L20: =IF(AND(ISNUMBER(L19),ISNUMBER(G19)),IFERROR(L19/G19-1,""),"") -> 0.048630784 | M20: =IF(AND(ISNUMBER(M19),ISNUMBER(H19)),IFERROR(M19/H19-1,""),"") -> 0.098290598 | N20: =IF(AND(ISNUMBER(N19),ISNUMBER(I19)),IFERROR(N19/I19-1,""),"") -> 0.089227924 | O20: =IF(AND(ISNUMBER(O19),ISNUMBER(J19)),IFERROR(O19/J19-1,""),"") -> 0.067075844 | ... X20: =IF(AND(ISNUMBER(X19),ISNUMBER(S19)),IFERROR(X19/S19-1,""),"") -> 0.044017607 | Y20: =$X$20 -> 0.044017607 | Z20: =$X$20 -> 0.044017607 | AA20: =IFERROR(AA19/V19-1,"") -> 0.043203673 | AB20: =CHOOSE(MATCH($AF$2,{"Bull","Base","Bear"},0),$AM$35,$AN$35,$AO$35) -> 0.05 | AC20: =CHOOSE(MATCH($AF$2,{"Bull","Base","Bear"},0),$AM$36,$AN$36,$AO$36) -> 0.045 | AD20: =CHOOSE(MATCH($AF$2,{"Bull","Base","Bear"},0),$AM$37,$AN$37,$AO$37) -> 0.045 | AE20: =CHOOSE(MATCH($AF$2,{"Bull","Base","Bear"},0),$AM$38,$AN$38,$AO$38) -> 0.04 | AL20: LTL targets 2021–2027 (investor deck; memo — compared with the model in the Group Total block) | AM20: High | AN20: Mid | AO20: Low
B21: Memo: reported yield (excl. fuel) y/y % (company; 2022 vs 2021) | C21: 0.087 | D21: 0.106 | E21: 0.07 | F21: 0.014 | G21: 0.07 | AL21: LTL revenue CAGR 2021–27 | AM21: 0.08 | AN21: 0.07 | AO21: 0.06 | AP21: Target range 6–8%.
B22: Revenue ex fuel ÷ (hundredweight × yield) — revenue recognition & other (x) | C22: =IFERROR(C23/(C18*C19),"") -> 0.96526504 | D22: =IFERROR(D23/(D18*D19),"") -> 0.96062823 | E22: =IFERROR(E23/(E18*E19),"") -> 0.96885505 | F22: =IFERROR(F23/(F18*F19),"") -> 0.96824531 | G22: =IFERROR(G23/(G18*G19),"") -> 0.96767776 | H22: =IFERROR(H23/(H18*H19),"") -> 0.97252221 | I22: =IFERROR(I23/(I18*I19),"") -> 0.97365268 | J22: =IFERROR(J23/(J18*J19),"") -> 0.97562031 | ... X22: =IFERROR(X23/(X18*X19),"") -> 0.98215823 | Y22: =T22 -> 0.98519942 | Z22: =U22 -> 0.99437332 | AA22: =IFERROR(AA23/(AA18*AA19),"") -> 0.98460892 | AB22: =AA22 -> 0.98460892 | AC22: =AB22 -> 0.98460892 | AD22: =AC22 -> 0.98460892 | AE22: =AD22 -> 0.98460892 | AF22: Bridges the operating statistics to reported revenue (in-transit revenue deferral, accessorials/other). Forecast: prior-year quarter; 2027E+ held at 2026E. | AL22: LTL adjusted EBITDA CAGR 2021–27 | AM22: 0.13 | AN22: 0.12 | AO22: 0.11 | AP22: Target range 11–13%.
B23: Revenue (excluding fuel surcharge revenue) | C23: 900 | D23: 949 | E23: 931 | F23: 851 | G23: 3631 | H23: 903 | I23: 940 | J23: 1005 | K23: 966 | L23: 3814 | M23: 1011 | N23: 1064 | O23: 1055 | P23: 985 | Q23: 4115 | R23: 994 | S23: 1057 | T23: 1060 | U23: 990 | V23: 4101 | W23: 1028 | X23: 1114 | Y23: =Y18*Y19*Y22 -> 1145.3917 | Z23: =Z18*Z19*Z22 -> 1074.9205 | AA23: =SUM(W23,X23,Y23,Z23) -> 4362.3122 | AB23: =AB18*AB19*AB22 -> 4736.6369 | AC23: =AC18*AC19*AC22 -> 5098.2791 | AD23: =AD18*AD19*AD22 -> 5460.8942 | AE23: =AE18*AE19*AE22 -> 5821.3132 | AH23: =IFERROR((AE23/V23)^(1/5)-1,"n/m") -> 0.072571467 | AI23: =IFERROR((V23/G23)^(1/3)-1,"n/m") -> 0.041408633 | AL23: LTL adjusted operating ratio improvement 2021–27 (bp, at least) | AN23: 600 | AP23: At least 600 bp.
B24: Revenue ex fuel y/y % | H24: =IF(AND(ISNUMBER(H23),ISNUMBER(C23)),IFERROR(H23/C23-1,""),"") -> 0.0033333333 | I24: =IF(AND(ISNUMBER(I23),ISNUMBER(D23)),IFERROR(I23/D23-1,""),"") -> -0.009483667 | J24: =IF(AND(ISNUMBER(J23),ISNUMBER(E23)),IFERROR(J23/E23-1,""),"") -> 0.079484425 | K24: =IF(AND(ISNUMBER(K23),ISNUMBER(F23)),IFERROR(K23/F23-1,""),"") -> 0.13513514 | L24: =IF(AND(ISNUMBER(L23),ISNUMBER(G23)),IFERROR(L23/G23-1,""),"") -> 0.050399339 | M24: =IF(AND(ISNUMBER(M23),ISNUMBER(H23)),IFERROR(M23/H23-1,""),"") -> 0.11960133 | N24: =IF(AND(ISNUMBER(N23),ISNUMBER(I23)),IFERROR(N23/I23-1,""),"") -> 0.13191489 | O24: =IF(AND(ISNUMBER(O23),ISNUMBER(J23)),IFERROR(O23/J23-1,""),"") -> 0.049751244 | ... X24: =IF(AND(ISNUMBER(X23),ISNUMBER(S23)),IFERROR(X23/S23-1,""),"") -> 0.053926206 | Y24: =IFERROR(Y23/T23-1,"") -> 0.080558223 | Z24: =IFERROR(Z23/U23-1,"") -> 0.085778311 | AA24: =IFERROR(AA23/V23-1,"") -> 0.063719153 | AB24: =IFERROR(AB23/AA23-1,"") -> 0.085808765 | AC24: =IFERROR(AC23/AB23-1,"") -> 0.07635 | AD24: =IFERROR(AD23/AC23-1,"") -> 0.071125 | AE24: =IFERROR(AE23/AD23-1,"") -> 0.066 | AL24: Capex % of LTL revenue (average through 2027) | AM24: 0.12 | AN24: 0.1 | AO24: 0.08 | AP24: Target range 8–12%.
B25: Fuel surcharge revenue % of revenue ex fuel | C25: =IF(AND(ISNUMBER(C26),ISNUMBER(C23)),IFERROR(C26/C23,""),"") -> 0.23 | D25: =IF(AND(ISNUMBER(D26),ISNUMBER(D23)),IFERROR(D26/D23,""),"") -> 0.30663857 | E25: =IF(AND(ISNUMBER(E26),ISNUMBER(E23)),IFERROR(E26/E23,""),"") -> 0.2943072 | F25: =IF(AND(ISNUMBER(F26),ISNUMBER(F23)),IFERROR(F26/F23,""),"") -> 0.28437133 | G25: =IF(AND(ISNUMBER(G26),ISNUMBER(G23)),IFERROR(G26/G23,""),"") -> 0.27926191 | H25: =IF(AND(ISNUMBER(H26),ISNUMBER(H23)),IFERROR(H26/H23,""),"") -> 0.24031008 | I25: =IF(AND(ISNUMBER(I26),ISNUMBER(I23)),IFERROR(I26/I23,""),"") -> 0.20851064 | J25: =IF(AND(ISNUMBER(J26),ISNUMBER(J23)),IFERROR(J26/J23,""),"") -> 0.22189055 | ... X25: =IF(AND(ISNUMBER(X26),ISNUMBER(X23)),IFERROR(X26/X23,""),"") -> 0.28186715 | Y25: =$X$25 -> 0.28186715 | Z25: =$X$25 -> 0.28186715 | AA25: =IFERROR(AA26/AA23,"") -> 0.26152027 | AB25: =AVERAGE($L$25,$Q$25,$V$25) -> 0.19790439 | AC25: =AVERAGE($L$25,$Q$25,$V$25) -> 0.19790439 | AD25: =AVERAGE($L$25,$Q$25,$V$25) -> 0.19790439 | AE25: =AVERAGE($L$25,$Q$25,$V$25) -> 0.19790439 | AF25: Q3/Q4-26E: held at the Q2/26 ratio (28.2%; diesel spike — update with EIA diesel). 2027E+: 2023–25 average (diesel normalisation). Fuel is a pass-through: it moves revenue and the operating ratio, not cents per cwt. | AL25: FY2021 base: LTL revenue ($m) | AN25: 4125 | AP25: Q4-22 release (8-K 8-Feb-23), FY2021 column.
B26: Fuel surcharge revenue | C26: 207 | D26: 291 | E26: 274 | F26: 242 | G26: 1014 | H26: 217 | I26: 196 | J26: 223 | K26: 221 | L26: 857 | M26: 210 | N26: 208 | O26: 195 | P26: 171 | Q26: 785 | R26: 178 | S26: 183 | T26: 194 | U26: 175 | V26: 731 | W26: 201 | X26: 314 | Y26: =Y23*Y25 -> 322.84829 | Z26: =Z23*Z25 -> 302.98478 | AA26: =SUM(W26,X26,Y26,Z26) -> 1140.8331 | AB26: =AB23*AB25 -> 937.40124 | AC26: =AC23*AC25 -> 1008.9718 | AD26: =AD23*AD25 -> 1080.735 | AE26: =AE23*AE25 -> 1152.0635 | AL26: FY2021 base: LTL adjusted EBITDA ($m) | AN26: 906 | AP26: As first published (incl. $62m real-estate gains and pension income).
B27: North American LTL revenue | C27: 1107 | D27: 1240 | E27: 1205 | F27: 1093 | G27: 4645 | H27: 1120 | I27: 1136 | J27: 1228 | K27: 1187 | L27: 4671 | M27: 1221 | N27: 1272 | O27: 1251 | P27: 1156 | Q27: 4899 | R27: 1172 | S27: 1240 | T27: 1255 | U27: 1165 | V27: 4832 | W27: 1229 | X27: 1428 | Y27: =Y23+Y26 -> 1468.24 | Z27: =Z23+Z26 -> 1377.9053 | AA27: =SUM(W27,X27,Y27,Z27) -> 5503.1453 | AB27: =AB23+AB26 -> 5674.0381 | AC27: =AC23+AC26 -> 6107.2509 | AD27: =AD23+AD26 -> 6541.6291 | AE27: =AE23+AE26 -> 6973.3767 | AH27: =IFERROR((AE27/V27)^(1/5)-1,"n/m") -> 0.076126286 | AI27: =IFERROR((V27/G27)^(1/3)-1,"n/m") -> 0.013243289 | AL27: FY2021 base: LTL adjusted operating ratio | AN27: 0.827 | AP27: As first published (definition then in force).
B28: LTL revenue y/y % | H28: =IF(AND(ISNUMBER(H27),ISNUMBER(C27)),IFERROR(H27/C27-1,""),"") -> 0.011743451 | I28: =IF(AND(ISNUMBER(I27),ISNUMBER(D27)),IFERROR(I27/D27-1,""),"") -> -0.083870968 | J28: =IF(AND(ISNUMBER(J27),ISNUMBER(E27)),IFERROR(J27/E27-1,""),"") -> 0.019087137 | K28: =IF(AND(ISNUMBER(K27),ISNUMBER(F27)),IFERROR(K27/F27-1,""),"") -> 0.08600183 | L28: =IF(AND(ISNUMBER(L27),ISNUMBER(G27)),IFERROR(L27/G27-1,""),"") -> 0.0055974166 | M28: =IF(AND(ISNUMBER(M27),ISNUMBER(H27)),IFERROR(M27/H27-1,""),"") -> 0.090178571 | N28: =IF(AND(ISNUMBER(N27),ISNUMBER(I27)),IFERROR(N27/I27-1,""),"") -> 0.11971831 | O28: =IF(AND(ISNUMBER(O27),ISNUMBER(J27)),IFERROR(O27/J27-1,""),"") -> 0.018729642 | ... X28: =IF(AND(ISNUMBER(X27),ISNUMBER(S27)),IFERROR(X27/S27-1,""),"") -> 0.1516129 | Y28: =IFERROR(Y27/T27-1,"") -> 0.16991236 | Z28: =IFERROR(Z27/U27-1,"") -> 0.18275134 | AA28: =IFERROR(AA27/V27-1,"") -> 0.13889597 | AB28: =IFERROR(AB27/AA27-1,"") -> 0.031053659 | AC28: =IFERROR(AC27/AB27-1,"") -> 0.07635 | AD28: =IFERROR(AD27/AC27-1,"") -> 0.071125 | AE28: =IFERROR(AE27/AD27-1,"") -> 0.066
B29: Adjusted operating ratio % (1 − adjusted operating income ÷ revenue) | C29: =IF(AND(ISNUMBER(C30),ISNUMBER(C27)),IFERROR(1-C30/C27,""),"") -> 0.88888889 | D29: =IF(AND(ISNUMBER(D30),ISNUMBER(D27)),IFERROR(1-D30/D27,""),"") -> 0.83225806 | E29: =IF(AND(ISNUMBER(E30),ISNUMBER(E27)),IFERROR(1-E30/E27,""),"") -> 0.85560166 | F29: =IF(AND(ISNUMBER(F30),ISNUMBER(F27)),IFERROR(1-F30/F27,""),"") -> 0.90301921 | G29: =IF(AND(ISNUMBER(G30),ISNUMBER(G27)),IFERROR(1-G30/G27,""),"") -> 0.86846071 | H29: =IF(AND(ISNUMBER(H30),ISNUMBER(H27)),IFERROR(1-H30/H27,""),"") -> 0.89553571 | I29: =IF(AND(ISNUMBER(I30),ISNUMBER(I27)),IFERROR(1-I30/I27,""),"") -> 0.875 | J29: =IF(AND(ISNUMBER(J30),ISNUMBER(J27)),IFERROR(1-J30/J27,""),"") -> 0.86156352 | ... X29: =IF(AND(ISNUMBER(X30),ISNUMBER(X27)),IFERROR(1-X30/X27,""),"") -> 0.79901961 | Y29: =T29+($X$29-$S$29) -> 0.79627253 | Z29: =U29+($X$29-$S$29) -> 0.81381609 | AA29: =IFERROR(1-AA30/AA27,"") -> 0.8108964 | AB29: =CHOOSE(MATCH($AF$2,{"Bull","Base","Bear"},0),$AM$40,$AN$40,$AO$40) -> 0.795 | AC29: =CHOOSE(MATCH($AF$2,{"Bull","Base","Bear"},0),$AM$41,$AN$41,$AO$41) -> 0.785 | AD29: =CHOOSE(MATCH($AF$2,{"Bull","Base","Bear"},0),$AM$42,$AN$42,$AO$42) -> 0.775 | AE29: =CHOOSE(MATCH($AF$2,{"Bull","Base","Bear"},0),$AM$43,$AN$43,$AO$43) -> 0.77 | AF29: Q3/Q4-26E: prior-year quarter adjusted OR + Q2/26 y/y improvement (−300 bp). 2027E+: scenario lever LTL_OR. Company definition: adjusted OR excludes amortization, restructuring/transaction costs and real-estate gains. | AH29: =IFERROR(AVERAGE(AA29,AB29,AC29,AD29,AE29),"n/m") -> 0.78717928 | AI29: =IFERROR(AVERAGE(G29,L29,Q29,V29),"n/m") -> 0.85742462 | AL29: LTL_vol (LTL tonnage per day y/y) | AM29: 0.02 | AN29: Δ → | AO29: -0.02 | AP29: Freight recovery from the 2025 trough (FY25 tonnage/day −6.2%) plus share gains on service; Aug-26 tonnage/day +3.7% y/y (8-K 3-Sep-26).
B30: Adjusted operating income (company definition) | C30: 123 | D30: 208 | E30: 174 | F30: 106 | G30: 611 | H30: 117 | I30: 142 | J30: 170 | K30: 160 | L30: 589 | M30: 175 | N30: 214 | O30: 198 | P30: 159 | Q30: 746 | R30: 165 | S30: 211 | T30: 217 | U30: 181 | V30: 775 | W30: 198 | X30: 287 | Y30: =Y27*(1-Y29) -> 299.12082 | Z30: =Z27*(1-Z29) -> 256.5438 | AA30: =SUM(W30,X30,Y30,Z30) -> 1040.6646 | AB30: =AB27*(1-AB29) -> 1163.1778 | AC30: =AC27*(1-AC29) -> 1313.0589 | AD30: =AD27*(1-AD29) -> 1471.8666 | AE30: =AE27*(1-AE29) -> 1603.8766 | AH30: =IFERROR((AE30/V30)^(1/5)-1,"n/m") -> 0.15657514 | AI30: =IFERROR((V30/G30)^(1/3)-1,"n/m") -> 0.082480706 | AL30: 2027E | AM30: =AN30+$AM$29 -> 0.05 | AN30: 0.03 | AO30: =AN30+$AO$29 -> 0.01
B31: Adjusted operating income y/y % | H31: =IF(AND(ISNUMBER(H30),ISNUMBER(C30)),IFERROR(H30/C30-1,""),"") -> -0.048780488 | I31: =IF(AND(ISNUMBER(I30),ISNUMBER(D30)),IFERROR(I30/D30-1,""),"") -> -0.31730769 | J31: =IF(AND(ISNUMBER(J30),ISNUMBER(E30)),IFERROR(J30/E30-1,""),"") -> -0.022988506 | K31: =IF(AND(ISNUMBER(K30),ISNUMBER(F30)),IFERROR(K30/F30-1,""),"") -> 0.50943396 | L31: =IF(AND(ISNUMBER(L30),ISNUMBER(G30)),IFERROR(L30/G30-1,""),"") -> -0.036006547 | M31: =IF(AND(ISNUMBER(M30),ISNUMBER(H30)),IFERROR(M30/H30-1,""),"") -> 0.4957265 | N31: =IF(AND(ISNUMBER(N30),ISNUMBER(I30)),IFERROR(N30/I30-1,""),"") -> 0.50704225 | O31: =IF(AND(ISNUMBER(O30),ISNUMBER(J30)),IFERROR(O30/J30-1,""),"") -> 0.16470588 | ... X31: =IF(AND(ISNUMBER(X30),ISNUMBER(S30)),IFERROR(X30/S30-1,""),"") -> 0.36018957 | Y31: =IFERROR(Y30/T30-1,"") -> 0.37843696 | Z31: =IFERROR(Z30/U30-1,"") -> 0.41736904 | AA31: =IFERROR(AA30/V30-1,"") -> 0.34279305 | AB31: =IFERROR(AB30/AA30-1,"") -> 0.11772592 | AC31: =IFERROR(AC30/AB30-1,"") -> 0.12885488 | AD31: =IFERROR(AD30/AC30-1,"") -> 0.12094477 | AE31: =IFERROR(AE30/AD30-1,"") -> 0.089688889 | AL31: 2028E | AM31: =AN31+$AM$29 -> 0.05 | AN31: 0.03 | AO31: =AN31+$AO$29 -> 0.01
B32: Incremental adjusted operating margin (Δ adj. operating income ÷ Δ revenue) | H32: =IFERROR((H30-C30)/(H27-C27),"") -> -0.46153846 | I32: =IFERROR((I30-D30)/(I27-D27),"") -> 0.63461538 | J32: =IFERROR((J30-E30)/(J27-E27),"") -> -0.17391304 | K32: =IFERROR((K30-F30)/(K27-F27),"") -> 0.57446809 | L32: =IFERROR((L30-G30)/(L27-G27),"") -> -0.84615385 | M32: =IFERROR((M30-H30)/(M27-H27),"") -> 0.57425743 | N32: =IFERROR((N30-I30)/(N27-I27),"") -> 0.52941176 | O32: =IFERROR((O30-J30)/(O27-J27),"") -> 1.2173913 | ... AA32: =IFERROR((AA30-V30)/(AA27-V27),"") -> 0.3958377 | AB32: =IFERROR((AB30-AA30)/(AB27-AA27),"") -> 0.71690089 | AC32: =IFERROR((AC30-AB30)/(AC27-AB27),"") -> 0.34597577 | AD32: =IFERROR((AD30-AC30)/(AD27-AC27),"") -> 0.36559754 | AE32: =IFERROR((AE30-AD30)/(AE27-AD27),"") -> 0.30575758 | AL32: 2029E | AM32: =AN32+$AM$29 -> 0.045 | AN32: 0.025 | AO32: =AN32+$AO$29 -> 0.005
B33: Δ Revenue ex fuel — volume effect (prior-year revenue ex fuel × Δ hundredweight %) | L33: =G23*(L18/G18-1) -> -19.872662 | Q33: =L23*(Q18/L18-1) -> -9.4555582 | V33: =Q23*(V18/Q18-1) -> -271.73727 | AA33: =V23*(AA18/V18-1) -> 78.002655 | AB33: =AA23*(AB18/AA18-1) -> 148.77049 | AC33: =AB23*(AC18/AB18-1) -> 142.09911 | AD33: =AC23*(AD18/AC18-1) -> 127.45698 | AE33: =AD23*(AE18/AD18-1) -> 136.52235 | AF33: Volume effect = prior-year revenue ex fuel × hundredweight growth; yield & other = residual, so the two sum to the change in revenue ex fuel. | AL33: 2030E | AM33: =AN33+$AM$29 -> 0.045 | AN33: 0.025 | AO33: =AN33+$AO$29 -> 0.005
B34: Δ Revenue ex fuel — yield & other effect (residual) | L34: =L23-G23-L33 -> 202.87266 | Q34: =Q23-L23-Q33 -> 310.45556 | V34: =V23-Q23-V33 -> 257.73727 | AA34: =AA23-V23-AA33 -> 183.30959 | AB34: =AB23-AA23-AB33 -> 225.55414 | AC34: =AC23-AB23-AC33 -> 219.54312 | AD34: =AD23-AC23-AD33 -> 235.15812 | AE34: =AE23-AD23-AE33 -> 223.89666 | AL34: LTL_yield (yield ex fuel y/y) | AM34: 0.01 | AN34: Δ → | AO34: -0.015 | AP34: Gross revenue/cwt ex fuel +7.0% (FY24), +6.1% (FY25), +4.2% (1H/26); above-inflation pricing + accessorials + local-channel mix (investor deck).
B35: Δ Fuel surcharge revenue | L35: =L26-G26 -> -157 | Q35: =Q26-L26 -> -72 | V35: =V26-Q26 -> -54 | AA35: =AA26-V26 -> 409.83307 | AB35: =AB26-AA26 -> -203.43183 | AC35: =AC26-AB26 -> 71.570585 | AD35: =AD26-AC26 -> 71.763121 | AE35: =AE26-AD26 -> 71.328507 | AL35: 2027E | AM35: =AN35+$AM$34 -> 0.06 | AN35: 0.05 | AO35: =AN35+$AO$34 -> 0.035
B36: Depreciation expense (excl. amortization of intangibles) | C36: 48 | D36: 50 | E36: 51 | F36: 56 | G36: 205 | H36: 60 | I36: 62 | J36: 66 | K36: 69 | L36: 257 | M36: 73 | N36: 77 | O36: 80 | P36: 80 | Q36: 310 | R36: 80 | S36: 87 | T36: 89 | U36: 89 | V36: 345 | W36: 88 | X36: 91 | Y36: =T36*($W$36+$X$36)/($R$36+$S$36) -> 95.39521 | Z36: =U36*($W$36+$X$36)/($R$36+$S$36) -> 95.39521 | AA36: =SUM(W36,X36,Y36,Z36) -> 369.79042 | AB36: =AB27*AB37 -> 397.18267 | AC36: =AC27*AC37 -> 427.50756 | AD36: =AD27*AD37 -> 457.91404 | AE36: =AE27*AE37 -> 488.13637 | AF36: Q3/Q4-26E: prior-year quarter × 1H/26 y/y growth (+7.2%). 2027E+: revenue × depreciation % input. | AL36: 2028E | AM36: =AN36+$AM$34 -> 0.055 | AN36: 0.045 | AO36: =AN36+$AO$34 -> 0.03
B37: Depreciation % of revenue | C37: =IF(AND(ISNUMBER(C36),ISNUMBER(C27)),IFERROR(C36/C27,""),"") -> 0.043360434 | D37: =IF(AND(ISNUMBER(D36),ISNUMBER(D27)),IFERROR(D36/D27,""),"") -> 0.040322581 | E37: =IF(AND(ISNUMBER(E36),ISNUMBER(E27)),IFERROR(E36/E27,""),"") -> 0.042323651 | F37: =IF(AND(ISNUMBER(F36),ISNUMBER(F27)),IFERROR(F36/F27,""),"") -> 0.051235133 | G37: =IF(AND(ISNUMBER(G36),ISNUMBER(G27)),IFERROR(G36/G27,""),"") -> 0.044133477 | H37: =IF(AND(ISNUMBER(H36),ISNUMBER(H27)),IFERROR(H36/H27,""),"") -> 0.053571429 | I37: =IF(AND(ISNUMBER(I36),ISNUMBER(I27)),IFERROR(I36/I27,""),"") -> 0.054577465 | J37: =IF(AND(ISNUMBER(J36),ISNUMBER(J27)),IFERROR(J36/J27,""),"") -> 0.053745928 | ... X37: =IF(AND(ISNUMBER(X36),ISNUMBER(X27)),IFERROR(X36/X27,""),"") -> 0.06372549 | Y37: =IFERROR(Y36/Y27,"") -> 0.06497249 | Z37: =IFERROR(Z36/Z27,"") -> 0.06923205 | AA37: =IFERROR(AA36/AA27,"") -> 0.067196194 | AB37: 0.07 | AC37: 0.07 | AD37: 0.07 | AE37: 0.07 | AF37: 2027E+: 7.0% input (FY25 7.1%; 1H/26 6.7% on fuel-inflated revenue; capex 8–12% of revenue through 2027). | AL37: 2029E | AM37: =AN37+$AM$34 -> 0.055 | AN37: 0.045 | AO37: =AN37+$AO$34 -> 0.03
B38: Pension income (in LTL adjusted EBITDA; below adjusted operating income) | C38: 15 | D38: 15 | E38: 14 | F38: 15 | G38: 59 | H38: 4 | I38: 4 | J38: 5 | K38: 4 | L38: 17 | M38: 6 | N38: 6 | O38: 6 | P38: 6 | Q38: 25 | R38: 2 | S38: 2 | T38: 2 | U38: 2 | V38: 6 | W38: 4 | X38: 4 | Y38: =($AN$14-($W$38+$X$38))/2 -> 3 | Z38: =($AN$14-($W$38+$X$38))/2 -> 3 | AA38: =SUM(W38,X38,Y38,Z38) -> 14 | AB38: 12 | AC38: 12 | AD38: 12 | AE38: 12 | AF38: Q3/Q4-26E: (FY26 planning assumption ~$14m − 1H/26 actual) ÷ 2. 2027E+: $12m input. Recorded in other income (non-operating). | AL38: 2030E | AM38: =AN38+$AM$34 -> 0.05 | AN38: 0.04 | AO38: =AN38+$AO$34 -> 0.025
B39: Gains on real-estate transactions (in adjusted EBITDA; excluded from adjusted operating income) | C39: 0 | D39: 0 | E39: 0 | F39: 55 | G39: 55 | H39: 0 | I39: 0 | J39: 0 | K39: 0 | L39: 0 | M39: 0 | N39: 0 | O39: 0 | P39: 34 | Q39: 34 | R39: 2 | S39: 0 | T39: 0 | U39: 13 | V39: 15 | W39: 0 | X39: 9 | Y39: 0 | Z39: 0 | AA39: =SUM(W39,X39,Y39,Z39) -> 9 | AB39: 0 | AC39: 0 | AD39: 0 | AE39: 0 | AF39: Non-recurring service-center sales; not forecast. | AL39: LTL_OR (LTL adjusted operating ratio) | AM39: -0.01 | AN39: Δ → | AO39: 0.015 | AP39: Adj. OR 84.0% (FY25), 81.8% (1H/26), record 79.9% (Q2/26). Target: ≥600 bp improvement 2021–27 (AI-led productivity, linehaul insourcing).
B40: Other (company reconciling item) | C40: 0 | D40: 1 | E40: 1 | F40: 0 | G40: 2 | H40: 1 | I40: 0 | J40: 0 | K40: 0 | L40: 1 | M40: 0 | N40: 0 | O40: 0 | P40: 0 | Q40: 0 | R40: 0 | S40: 0 | T40: 0 | U40: 0 | V40: 0 | W40: 0 | X40: 0 | Y40: 0 | Z40: 0 | AA40: =SUM(W40,X40,Y40,Z40) -> 0 | AB40: 0 | AC40: 0 | AD40: 0 | AE40: 0 | AL40: 2027E | AM40: =AN40+$AM$39 -> 0.785 | AN40: 0.795 | AO40: =AN40+$AO$39 -> 0.81
...

Sheet Bull-Base-Bear
B2: XPO, Inc. (XPO) — Bull / Base / Bear Case P&L Summary | J2: Share price ($): | K2: =Model!$AA$365 -> 180
B3: Adjusted figures (company current definitions: Adjusted EBITDA / adjusted diluted EPS) · USDm except per-share · 2025A actual; 2026E = 1H/26 actual + 2H/26E · LT hist = 2022–2025 (standalone XPO since the RXO spin-off) | J3: As of: | K3: =TODAY() -> 46300
B5: Scenario: | C5: =Model!$AF$2 -> Base | N5: Scenario: | O5: Bull | P5: Snapshot (values) — Model run with switch = Bull | Z5: Scenario: | AA5: Bear | AB5: Snapshot (values) — Model run with switch = Bear
B7: (USDm, except EPS and shares) | C7: 2025A | D7: 2026E | E7: 2027E | F7: 2028E | G7: 2029E | H7: 2030E | I7: 25-'30 CAGR | J7: LT Hist Avg | K7: LT Hist Min | L7: LT Hist Max | N7: (USDm, except EPS and shares) | O7: 2025A | P7: 2026E | Q7: 2027E | R7: 2028E | S7: 2029E | T7: 2030E | U7: 25-'30 CAGR | V7: LT Hist Avg | W7: LT Hist Min | X7: LT Hist Max | Z7: (USDm, except EPS and shares) | AA7: 2025A | AB7: 2026E | AC7: 2027E | AD7: 2028E | AE7: 2029E | AF7: 2030E | AG7: 25-'30 CAGR | AH7: LT Hist Avg | AI7: LT Hist Min | AJ7: LT Hist Max
B9: Revenues | C9: =Model!V106 -> 8157 | D9: =Model!AA106 -> 9180.6234 | E9: =Model!AB106 -> 9462.8706 | F9: =Model!AC106 -> 10009.748 | G9: =Model!AD106 -> 10561.202 | H9: =Model!AE106 -> 11113.536 | I9: =IFERROR((H9/C9)^(1/5)-1,"n/m") -> 0.063810717 | N9: Revenues | O9: 8157 | P9: 9180.6234 | Q9: 9701.7034 | R9: 10524.008 | S9: 11389.642 | T9: 12296.081 | U9: 0.085543541 | Z9: Revenues | AA9: 8157 | AB9: 9180.6234 | AC9: 9199.6418 | AD9: 9457.8149 | AE9: 9695.8838 | AF9: 9911.6998 | AG9: 0.039737087
B10: Revenues y/y % | D10: =IFERROR(D9/C9-1,"") -> 0.12549019 | E10: =IFERROR(E9/D9-1,"") -> 0.030743788 | F10: =IFERROR(F9/E9-1,"") -> 0.057791954 | G10: =IFERROR(G9/F9-1,"") -> 0.055091609 | H10: =IFERROR(H9/G9-1,"") -> 0.052298471 | N10: Revenues y/y % | P10: 0.12549019 | Q10: 0.056758667 | R10: 0.084758809 | S10: 0.082253282 | T10: 0.079584424 | Z10: Revenues y/y % | AB10: 0.12549019 | AC10: 0.0020715726 | AD10: 0.028063386 | AE10: 0.025171664 | AF10: 0.022258514
B11: LTL tonnage per day y/y % | C11: =Model!V195 -> -0.062322214 | D11: =Model!AA195 -> 0.02105032 | E11: =Model!AB195 -> 0.03 | F11: =Model!AC195 -> 0.03 | G11: =Model!AD195 -> 0.025 | H11: =Model!AE195 -> 0.025 | N11: LTL tonnage per day y/y % | O11: -0.062322214 | P11: 0.02105032 | Q11: 0.05 | R11: 0.05 | S11: 0.045 | T11: 0.045 | Z11: LTL tonnage per day y/y % | AA11: -0.062322214 | AB11: 0.02105032 | AC11: 0.01 | AD11: 0.01 | AE11: 0.005 | AF11: 0.005
B12: Adjusted EBITDA | C12: =Model!V158 -> 1272 | D12: =Model!AA158 -> 1571.6686 | E12: =Model!AB158 -> 1745.8021 | F12: =Model!AC158 -> 1941.4476 | G12: =Model!AD158 -> 2146.8571 | H12: =Model!AE158 -> 2315.7218 | I12: =IFERROR((H12/C12)^(1/5)-1,"n/m") -> 0.1273009 | N12: Adjusted EBITDA | O12: 1272 | P12: 1571.6686 | Q12: 1882.289 | R12: 2147.5347 | S12: 2437.2036 | T12: 2701.1597 | U12: 0.16255265 | Z12: Adjusted EBITDA | AA12: 1272 | AB12: 1571.6686 | AC12: 1579.8372 | AD12: 1705.3165 | AE12: 1829.6865 | AF12: 1911.7227 | AG12: 0.084894619
B13: Adjusted EBITDA margin % | C13: =IFERROR(C12/C9,"") -> 0.15593968 | D13: =IFERROR(D12/D9,"") -> 0.17119411 | E13: =IFERROR(E12/E9,"") -> 0.18448969 | F13: =IFERROR(F12/F9,"") -> 0.19395569 | G13: =IFERROR(G12/G9,"") -> 0.20327773 | H13: =IFERROR(H12/H9,"") -> 0.20836948 | J13: =IFERROR(AVERAGE(Model!G159,Model!L159,Model!Q159,Model!V159),"") -> 0.1426431 | K13: =IFERROR(MIN(Model!G159,Model!L159,Model!Q159,Model!V159),"") -> 0.1286157 | L13: =IFERROR(MAX(Model!G159,Model!L159,Model!Q159,Model!V159),"") -> 0.15683845 | N13: Adjusted EBITDA margin % | O13: 0.15593968 | P13: 0.17119411 | Q13: 0.19401634 | R13: 0.20406053 | S13: 0.21398421 | T13: 0.21967648 | V13: 0.1426431 | W13: 0.1286157 | X13: 0.15683845 | Z13: Adjusted EBITDA margin % | AA13: 0.15593968 | AB13: 0.17119411 | AC13: 0.17172812 | AD13: 0.18030767 | AE13: 0.18870755 | AF13: 0.19287536 | AH13: 0.1426431 | AI13: 0.1286157 | AJ13: 0.15683845
B15: Operating Income (GAAP) | C15: =Model!V121 -> 656 | D15: =Model!AA121 -> 957.21647 | E15: =Model!AB121 -> 1124.7991 | F15: =Model!AC121 -> 1299.2552 | G15: =Model!AD121 -> 1480.2776 | H15: =Model!AE121 -> 1614.82 | I15: =IFERROR((H15/C15)^(1/5)-1,"n/m") -> 0.19741324 | N15: Operating Income (GAAP) | O15: 656 | P15: 957.21647 | Q15: 1247.2162 | R15: 1474.8529 | S15: 1721.2274 | T15: 1929.3978 | U15: 0.24080515 | Z15: Operating Income (GAAP) | AA15: 656 | AB15: 957.21647 | AC15: 974.61172 | AD15: 1096.3564 | AE15: 1215.4125 | AF15: 1283.7059 | AG15: 0.14370057
B16: Operating income y/y % | D16: =IFERROR(D15/C15-1,"") -> 0.45917145 | E16: =IFERROR(E15/D15-1,"") -> 0.1750729 | F16: =IFERROR(F15/E15-1,"") -> 0.15509971 | G16: =IFERROR(G15/F15-1,"") -> 0.13932785 | H16: =IFERROR(H15/G15-1,"") -> 0.090889985 | N16: Operating income y/y % | P16: 0.45917145 | Q16: 0.30296153 | R16: 0.18251583 | S16: 0.16705017 | T16: 0.12094298 | Z16: Operating income y/y % | AB16: 0.45917145 | AC16: 0.018172741 | AD16: 0.12491612 | AE16: 0.10859243 | AF16: 0.056189505
B17: Operating margin (GAAP) % | C17: =IFERROR(C15/C9,"") -> 0.080421724 | D17: =IFERROR(D15/D9,"") -> 0.10426487 | E17: =IFERROR(E15/E9,"") -> 0.11886447 | F17: =IFERROR(F15/F9,"") -> 0.12979898 | G17: =IFERROR(G15/G9,"") -> 0.14016185 | H17: =IFERROR(H15/H9,"") -> 0.14530209 | J17: =IFERROR(AVERAGE(Model!G204,Model!L204,Model!Q204,Model!V204),"") -> 0.066898154 | K17: =IFERROR(MIN(Model!G204,Model!L204,Model!Q204,Model!V204),"") -> 0.048846852 | L17: =IFERROR(MAX(Model!G204,Model!L204,Model!Q204,Model!V204),"") -> 0.081764123 | N17: Operating margin (GAAP) % | O17: 0.080421724 | P17: 0.10426487 | Q17: 0.12855642 | R17: 0.14014175 | S17: 0.15112216 | T17: 0.15691161 | V17: 0.066898154 | W17: 0.048846852 | X17: 0.081764123 | Z17: Operating margin (GAAP) % | AA17: 0.080421724 | AB17: 0.10426487 | AC17: 0.10594018 | AD17: 0.11592069 | AE17: 0.12535345 | AF17: 0.1295142 | AH17: 0.066898154 | AI17: 0.048846852 | AJ17: 0.081764123
B19: Adjusted Net Income | C19: =Model!V184 -> 445 | D19: =Model!AA184 -> 676.1056 | E19: =Model!AB184 -> 773.0366 | F19: =Model!AC184 -> 908.01329 | G19: =Model!AD184 -> 1028.4715 | H19: =Model!AE184 -> 1120.9842 | I19: =IFERROR((H19/C19)^(1/5)-1,"n/m") -> 0.20295088 | N19: Adjusted Net Income | O19: 445 | P19: 676.1056 | Q19: 861.68652 | R19: 1016.385 | S19: 1180.3966 | T19: 1321.7886 | U19: 0.24325552 | Z19: Adjusted Net Income | AA19: 445 | AB19: 676.1056 | AC19: 663.4201 | AD19: 759.62855 | AE19: 842.15668 | AF19: 893.96661 | AG19: 0.14972045
B21: FDSO (m) | C21: =Model!V135 -> 119 | D21: =Model!AA135 -> 118.16111 | E21: =Model!AB135 -> 117.24477 | F21: =Model!AC135 -> 114.27337 | G21: =Model!AD135 -> 109.59717 | H21: =Model!AE135 -> 104.91024 | I21: =IFERROR((H21/C21)^(1/5)-1,"n/m") -> -0.024888709 | N21: FDSO (m) | O21: 119 | P21: 118.09167 | Q21: 115.33517 | R21: 110.08413 | S21: 104.00578 | T21: 97.746184 | U21: -0.038585717 | Z21: FDSO (m) | AA21: 119 | AB21: 118.23056 | AC21: 118.60869 | AD21: 117.8588 | AE21: 115.05573 | AF21: 111.87026 | AG21: -0.012280699
B23: Adjusted EPS — Diluted ($) | C23: =Model!V188 -> 3.7394958 | D23: =Model!AA188 -> 5.7218961 | E23: =Model!AB188 -> 6.5933571 | F23: =Model!AC188 -> 7.9459747 | G23: =Model!AD188 -> 9.384107 | H23: =Model!AE188 -> 10.685174 | I23: =IFERROR((H23/C23)^(1/5)-1,"n/m") -> 0.23365496 | N23: Adjusted EPS — Diluted ($) | O23: 3.7394958 | P23: 5.7252609 | Q23: 7.4711515 | R23: 9.2328029 | S23: 11.349336 | T23: 13.522662 | U23: 0.29315275 | Z23: Adjusted EPS — Diluted ($) | AA23: 3.7394958 | AB23: 5.7185353 | AC23: 5.5933517 | AD23: 6.4452428 | AE23: 7.3195543 | AF23: 7.9911013 | AG23: 0.16401538
B24: EPS y/y % | D24: =IFERROR(D23/C23-1,"") -> 0.53012503 | E24: =IFERROR(E23/D23-1,"") -> 0.15230283 | F24: =IFERROR(F23/E23-1,"") -> 0.20514854 | G24: =IFERROR(G23/F23-1,"") -> 0.18098879 | H24: =IFERROR(H23/G23-1,"") -> 0.1386458 | N24: EPS y/y % | P24: 0.53102482 | Q24: 0.30494517 | R24: 0.23579382 | S24: 0.22924063 | T24: 0.19149359 | Z24: EPS y/y % | AB24: 0.52922628 | AC24: -0.021890842 | AD24: 0.15230421 | AE24: 0.13565222 | AF24: 0.091746983
B26: P / E (x) — assumed (adjusted EPS) | G26: 24 | H26: 24 | N26: P / E (x) — assumed (adjusted EPS) | S26: 28 | T26: 28 | Z26: P / E (x) — assumed (adjusted EPS) | AD26: 18 | AE26: 18 | AF26: 18
B27: Price Target ($) | G27: =G26*G23 -> 225.21857 | H27: =H26*H23 -> 256.44418 | N27: Price Target ($) | S27: =S26*S23 -> 317.78142 | T27: =T26*T23 -> 378.63453 | Z27: Price Target ($) | AD27: =AD26*AD23 -> 116.01437 | AE27: =AE26*AE23 -> 131.75198 | AF27: =AF26*AF23 -> 143.83982
B28: Upside / (Downside) vs current | G28: =IFERROR(G27/$K$2-1,"") -> 0.25121427 | H28: =IFERROR(H27/$K$2-1,"") -> 0.42468987 | N28: Upside / (Downside) vs current | S28: =IFERROR(S27/$K$2-1,"") -> 0.76545234 | T28: =IFERROR(T27/$K$2-1,"") -> 1.1035252 | Z28: Upside / (Downside) vs current | AD28: =IFERROR(AD27/$K$2-1,"") -> -0.35547572 | AE28: =IFERROR(AE27/$K$2-1,"") -> -0.26804457 | AF28: =IFERROR(AF27/$K$2-1,"") -> -0.20088987
B29: IRR (to Dec-Y-1) | G29: =IFERROR((G27/$K$2)^(1/((DATE(2029-1,12,31)-$K$3)/365.25))-1,"") -> 0.10524904 | H29: =IFERROR((H27/$K$2)^(1/((DATE(2030-1,12,31)-$K$3)/365.25))-1,"") -> 0.11547796 | N29: IRR (to Dec-Y-1) | S29: =IFERROR((S27/$K$2)^(1/((DATE(2029-1,12,31)-$K$3)/365.25))-1,"") -> 0.28891752 | T29: =IFERROR((T27/$K$2)^(1/((DATE(2030-1,12,31)-$K$3)/365.25))-1,"") -> 0.25808436 | Z29: IRR (to Dec-Y-1) | AD29: =IFERROR((AD27/$K$2)^(1/((DATE(2028-1,12,31)-$K$3)/365.25))-1,"") -> -0.29878534 | AE29: =IFERROR((AE27/$K$2)^(1/((DATE(2029-1,12,31)-$K$3)/365.25))-1,"") -> -0.13005813 | AF29: =IFERROR((AF27/$K$2)^(1/((DATE(2030-1,12,31)-$K$3)/365.25))-1,"") -> -0.066896322
B31: Free Cash Flow (company definition) | C31: =Model!V236 -> 370 | D31: =Model!AA236 -> 805.66452 | E31: =Model!AB236 -> 783.37571 | F31: =Model!AC236 -> 932.99149 | G31: =Model!AD236 -> 1058.9232 | H31: =Model!AE236 -> 1159.3435 | I31: =IFERROR((H31/C31)^(1/5)-1,"n/m") -> 0.25661455 | N31: Free Cash Flow (company definition) | O31: 370 | P31: 755.66452 | Q31: 876.64622 | R31: 1051.7042 | S31: 1223.2644 | T31: 1375.296 | U31: 0.30028602 | Z31: Free Cash Flow (company definition) | AA31: 370 | AB31: 855.66452 | AC31: 668.49393 | AD31: 770.3309 | AE31: 856.73513 | AF31: 914.35743 | AG31: 0.19834772
B32: FCF % | C32: =IFERROR(C31/C9,"") -> 0.045359814 | D32: =IFERROR(D31/D9,"") -> 0.08775706 | E32: =IFERROR(E31/E9,"") -> 0.082784151 | F32: =IFERROR(F31/F9,"") -> 0.093208286 | G32: =IFERROR(G31/G9,"") -> 0.10026541 | H32: =IFERROR(H31/H9,"") -> 0.10431815 | J32: =IFERROR(AVERAGE(Model!G240,Model!L240,Model!Q240,Model!V240),"") -> 0.00076717311 | K32: =IFERROR(MIN(Model!G240,Model!L240,Model!Q240,Model!V240),"") -> -0.10459711 | L32: =IFERROR(MAX(Model!G240,Model!L240,Model!Q240,Model!V240),"") -> 0.050660793 | N32: FCF % | O32: 0.045359814 | P32: 0.082310807 | Q32: 0.090360031 | R32: 0.099933809 | S32: 0.10740147 | T32: 0.11184833 | V32: 0.00076717311 | W32: -0.10459711 | X32: 0.050660793 | Z32: FCF % | AA32: 0.045359814 | AB32: 0.093203313 | AC32: 0.072665213 | AD32: 0.081449141 | AE32: 0.088360705 | AF32: 0.092250315 | AH32: 0.00076717311 | AI32: -0.10459711 | AJ32: 0.050660793
B33: FCF / share ($) | C33: =IFERROR(C31/C21,"") -> 3.1092437 | D33: =IFERROR(D31/D21,"") -> 6.818356 | E33: =IFERROR(E31/E21,"") -> 6.681541 | F33: =IFERROR(F31/F21,"") -> 8.1645575 | G33: =IFERROR(G31/G21,"") -> 9.6619577 | H33: =IFERROR(H31/H21,"") -> 11.050814 | N33: FCF / share ($) | O33: 3.1092437 | P33: 6.3989657 | Q33: 7.6008579 | R33: 9.5536411 | S33: 11.761504 | T33: 14.070074 | Z33: FCF / share ($) | AA33: 3.1092437 | AB33: 7.2372537 | AC33: 5.6361295 | AD33: 6.5360493 | AE33: 7.446262 | AF33: 8.1733733
B34: FCF Yield (on PT) | G34: =IFERROR(G33/G$27,"") -> 0.04290036 | H34: =IFERROR(H33/H$27,"") -> 0.043092473 | N34: FCF Yield (on PT) | S34: =IFERROR(S33/S$27,"") -> 0.037011301 | T34: =IFERROR(T33/T$27,"") -> 0.037160039 | Z34: FCF Yield (on PT) | AD34: =IFERROR(AD33/AD$27,"") -> 0.056338274 | AE34: =IFERROR(AE33/AE$27,"") -> 0.05651727 | AF34: =IFERROR(AF33/AF$27,"") -> 0.056822743
B35: North American LTL Adjusted EBITDA | C35: =Model!V41 -> 1142 | D35: =Model!AA41 -> 1432.455 | E35: =Model!AB41 -> 1572.3605 | F35: =Model!AC41 -> 1752.5665 | G35: =Model!AD41 -> 1941.7806 | H35: =Model!AE41 -> 2104.013 | I35: =IFERROR((H35/C35)^(1/5)-1,"n/m") -> 0.12999485 | N35: North American LTL Adjusted EBITDA | O35: 1142 | P35: 1432.455 | Q35: 1676.2009 | R35: 1920.2034 | S35: 2187.06 | T35: 2437.7089 | U35: 0.16375925 | Z35: North American LTL Adjusted EBITDA | AA35: 1142 | AB35: 1432.455 | AC35: 1437.9385 | AD35: 1552.4578 | AE35: 1665.6644 | AF35: 1745.9003 | AG35: 0.088605858
B36: LTL adjusted operating ratio % | C36: =Model!V29 -> 0.83961093 | D36: =Model!AA29 -> 0.8108964 | E36: =Model!AB29 -> 0.795 | F36: =Model!AC29 -> 0.785 | G36: =Model!AD29 -> 0.775 | H36: =Model!AE29 -> 0.77 | J36: =IFERROR(AVERAGE(Model!G29,Model!L29,Model!Q29,Model!V29),"") -> 0.85742462 | K36: =IFERROR(MIN(Model!G29,Model!L29,Model!Q29,Model!V29),"") -> 0.83961093 | L36: =IFERROR(MAX(Model!G29,Model!L29,Model!Q29,Model!V29),"") -> 0.8739028 | N36: LTL adjusted operating ratio % | O36: 0.83961093 | P36: 0.8108964 | Q36: 0.785 | R36: 0.775 | S36: 0.765 | T36: 0.76 | V36: 0.85742462 | W36: 0.83961093 | X36: 0.8739028 | Z36: LTL adjusted operating ratio % | AA36: 0.83961093 | AB36: 0.8108964 | AC36: 0.81 | AD36: 0.8 | AE36: 0.79 | AF36: 0.785 | AH36: 0.85742462 | AI36: 0.83961093 | AJ36: 0.8739028
B38: Net Debt | C38: =Model!V360 -> 3003 | D38: =Model!AA360 -> 2493.3355 | E38: =Model!AB360 -> 2182.2526 | F38: =Model!AC360 -> 2426.8095 | G38: =Model!AD360 -> 2683.5713 | H38: =Model!AE360 -> 2894.6522 | N38: Net Debt | O38: 3003 | P38: 2593.3355 | Q38: 2823.4335 | R38: 3221.3021 | S38: 3655.8054 | T38: 4051.7396 | Z38: Net Debt | AA38: 3003 | AB38: 2393.3355 | AC38: 1774.8416 | AD38: 1705.3165 | AE38: 1829.6865 | AF38: 1911.7227
B39: Net Debt / Adjusted EBITDA (x) | C39: =IFERROR(C38/C12,"") -> 2.3608491 | D39: =IFERROR(D38/D12,"") -> 1.5864257 | E39: =IFERROR(E38/E12,"") -> 1.25 | F39: =IFERROR(F38/F12,"") -> 1.25 | G39: =IFERROR(G38/G12,"") -> 1.25 | H39: =IFERROR(H38/H12,"") -> 1.25 | N39: Net Debt / Adjusted EBITDA (x) | O39: 2.3608491 | P39: 1.6500523 | Q39: 1.5 | R39: 1.5 | S39: 1.5 | T39: 1.5 | Z39: Net Debt / Adjusted EBITDA (x) | AA39: 2.3608491 | AB39: 1.522799 | AC39: 1.1234332 | AD39: 1 | AE39: 1 | AF39: 1
B41: ROIC | C41: =Model!V343 -> 0.11164827 | D41: =Model!AA343 -> 0.16766473 | E41: =Model!AB343 -> 0.18475132 | F41: =Model!AC343 -> 0.2114973 | G41: =Model!AD343 -> 0.23864752 | H41: =Model!AE343 -> 0.25830796 | J41: =IFERROR(AVERAGE(Model!G343,Model!L343,Model!Q343,Model!V343),"") -> 0.12082201 | K41: =IFERROR(MIN(Model!G343,Model!L343,Model!Q343,Model!V343),"") -> 0.097814069 | L41: =IFERROR(MAX(Model!G343,Model!L343,Model!Q343,Model!V343),"") -> 0.1399069 | N41: ROIC | O41: 0.11164827 | P41: 0.16590079 | Q41: 0.20226882 | R41: 0.23730653 | S41: 0.27455598 | T41: 0.3055964 | V41: 0.12082201 | W41: 0.097814069 | X41: 0.1399069 | Z41: ROIC | AA41: 0.11164827 | AB41: 0.16946659 | AC41: 0.16238302 | AD41: 0.18069978 | AE41: 0.19808008 | AF41: 0.20734357 | AH41: 0.12082201 | AI41: 0.097814069 | AJ41: 0.1399069
B42: RONTA | C42: =Model!V354 -> 0.11217873 | D42: =Model!AA354 -> 0.16557965 | E42: =Model!AB354 -> 0.17811769 | F42: =Model!AC354 -> 0.19926798 | G42: =Model!AD354 -> 0.2199106 | H42: =Model!AE354 -> 0.23263816 | J42: =IFERROR(AVERAGE(Model!G354,Model!L354,Model!Q354,Model!V354),"") -> 0.12543633 | K42: =IFERROR(MIN(Model!G354,Model!L354,Model!Q354,Model!V354),"") -> 0.10281222 | L42: =IFERROR(MAX(Model!G354,Model!L354,Model!Q354,Model!V354),"") -> 0.14665971 | N42: RONTA | O42: 0.11217873 | P42: 0.16385908 | Q42: 0.19479298 | R42: 0.22299684 | S42: 0.25178854 | T42: 0.27314434 | V42: 0.12543633 | W42: 0.10281222 | X42: 0.14665971 | Z42: RONTA | AA42: 0.11217873 | AB42: 0.16733673 | AC42: 0.14821683 | AD42: 0.15938708 | AE42: 0.17533114 | AF42: 0.18257508 | AH42: 0.12543633 | AI42: 0.10281222 | AJ42: 0.14665971
B44: Implied Market Cap (USDm) | G44: =G27*G21 -> 24683.317 | H44: =H27*H21 -> 26903.621 | N44: Implied Market Cap (USDm) | S44: =S27*S21 -> 33051.103 | T44: =T27*T21 -> 37010.08 | Z44: Implied Market Cap (USDm) | AD44: =AD27*AD21 -> 13673.314 | AE44: =AE27*AE21 -> 15158.82 | AF44: =AF27*AF21 -> 16091.399
B45: (+) Net Debt | G45: =G38 -> 2683.5713 | H45: =H38 -> 2894.6522 | N45: (+) Net Debt | S45: =S38 -> 3655.8054 | T45: =T38 -> 4051.7396 | Z45: (+) Net Debt | AD45: =AD38 -> 1705.3165 | AE45: =AE38 -> 1829.6865 | AF45: =AF38 -> 1911.7227
B46: Implied Enterprise Value (USDm) | G46: =G44+G45 -> 27366.888 | H46: =H44+H45 -> 29798.273 | N46: Implied Enterprise Value (USDm) | S46: =S44+S45 -> 36706.909 | T46: =T44+T45 -> 41061.82 | Z46: Implied Enterprise Value (USDm) | AD46: =AD44+AD45 -> 15378.63 | AE46: =AE44+AE45 -> 16988.507 | AF46: =AF44+AF45 -> 18003.122
B47: Implied EV / Adjusted EBITDA (x) | G47: =IFERROR(G46/G12,"") -> 12.74742 | H47: =IFERROR(H46/H12,"") -> 12.867812 | N47: Implied EV / Adjusted EBITDA (x) | S47: =IFERROR(S46/S12,"") -> 15.061076 | T47: =IFERROR(T46/T12,"") -> 15.201552 | Z47: Implied EV / Adjusted EBITDA (x) | AD47: =IFERROR(AD46/AD12,"") -> 9.0180504 | AE47: =IFERROR(AE46/AE12,"") -> 9.2849277 | AF47: =IFERROR(AF46/AF12,"") -> 9.4172246
B49: P/E inputs: Base 24x / Bull 28x / Bear 18x adjusted EPS (LTL peers ODFL ~30x, SAIA ~25x through-cycle; XPO 5-yr post-spin range ~20–40x). Bull and Bear blocks are value snapshots of the Model run with the scenario switch set accordingly (re-run to refresh).

Sheet DCF
B2: DCF VALUATION — XPO, INC. (XPO)
B4: 1. WACC BUILD
B5: Risk-free rate (US 10Y govt) | C5: 0.055 | D5: Assumption (~US 10Y Treasury yield); same as prior models — update to market
B6: Equity risk premium | C6: 0.05 | D6: US implied ERP ~4.5–5.5% (Damodaran)
B7: Levered beta | C7: 1.3 | D7: LTL peers: ODFL ~1.1–1.2, SAIA ~1.5, ArcBest ~1.6; XPO pure-play LTL since Nov-22 (pre-spin history ~1.8–2.0 as a conglomerate); freight-cycle exposure
B8: Cost of equity | C8: =C5+C7*C6 -> 0.12
B9: Pre-tax cost of debt | C9: 0.065 | D9: BB+/Ba1: 6.25% sr. secured 2028, 7.125% notes 2031/2032; term loans SOFR+125–150 bp (~5%); marginal cost ~6.5%
B10: Tax rate | C10: 0.245 | D10: Model 2027E+ effective tax rate
B11: After-tax cost of debt | C11: =C9*(1-C10) -> 0.049075
B12: Target D/V | C12: 0.12 | D12: Net debt ~$2.5bn at YE2026E vs ~$21bn market cap ($180 × ~118m shares); 1.25x leverage floor in the Base case
B13: WACC | C13: =C8*(1-C12)+C11*C12 -> 0.111489
B15: Valuation date (live) | C15: =TODAY() -> 46300 | D15: Periods = (Dec-31-Year − today) / 365.25; cash flows assumed at year-end
B16: 2. UNLEVERED FREE CASH FLOW BUILD (USDm)
D17: 2026E | E17: 2027E | F17: 2028E | G17: 2029E | H17: 2030E | I17: 2031E | J17: 2032E | K17: 2033E | L17: 2034E | M17: 2035E | N17: Terminal | P17: CAGR 26–30E | Q17: CAGR 26–35E
B18: Adjusted EBIT (Model; Adjusted EBITDA − D&A) | D18: =Model!AA167 -> 1028.2165 | E18: =Model!AB167 -> 1156.7991 | F18: =Model!AC167 -> 1331.2552 | G18: =Model!AD167 -> 1512.2776 | H18: =Model!AE167 -> 1646.82 | I18: =H18*(1+I$31) -> 1762.0974 | J18: =I18*(1+J$31) -> 1874.4311 | K18: =J18*(1+K$31) -> 1982.2109 | L18: =K18*(1+L$31) -> 2083.7992 | M18: =L18*(1+M$31) -> 2177.5702 | P18: =IFERROR(($H18/$D18)^(1/(VALUE(LEFT($H$17,4))-VALUE(LEFT($D$17,4))))-1,"n/m") -> 0.12496858 | Q18: =IFERROR(($M18/$D18)^(1/(VALUE(LEFT($M$17,4))-VALUE(LEFT($D$17,4))))-1,"n/m") -> 0.086950416
B19: y/y % | E19: =IFERROR(E18/D18-1,"") -> 0.12505408 | F19: =IFERROR(F18/E18-1,"") -> 0.15080926 | G19: =IFERROR(G18/F18-1,"") -> 0.13597876 | H19: =IFERROR(H18/G18-1,"") -> 0.08896674 | I19: =IFERROR(I18/H18-1,"") -> 0.07 | J19: =IFERROR(J18/I18-1,"") -> 0.06375 | K19: =IFERROR(K18/J18-1,"") -> 0.0575 | L19: =IFERROR(L18/K18-1,"") -> 0.05125 | M19: =IFERROR(M18/L18-1,"") -> 0.045
B20: (−) Restructuring, transaction, legal & environmental costs (cash; added back in Adjusted EBITDA) | D20: =-(Model!AA120+Model!AA119+Model!AA117+Model!AA118) -> -58 | E20: =-(Model!AB120+Model!AB119+Model!AB117+Model!AB118) -> -20 | F20: =-(Model!AC120+Model!AC119+Model!AC117+Model!AC118) -> -20 | G20: =-(Model!AD120+Model!AD119+Model!AD117+Model!AD118) -> -20 | H20: =-(Model!AE120+Model!AE119+Model!AE117+Model!AE118) -> -20 | I20: =H20*(1+I$31) -> -21.4 | J20: =I20*(1+J$31) -> -22.76425 | K20: =J20*(1+K$31) -> -24.073194 | L20: =K20*(1+L$31) -> -25.306946 | M20: =L20*(1+M$31) -> -26.445758
B21: × (1 − tax rate) | D21: =1-$C$10 -> 0.755 | E21: =1-$C$10 -> 0.755 | F21: =1-$C$10 -> 0.755 | G21: =1-$C$10 -> 0.755 | H21: =1-$C$10 -> 0.755 | I21: =1-$C$10 -> 0.755 | J21: =1-$C$10 -> 0.755 | K21: =1-$C$10 -> 0.755 | ... M21: =1-$C$10 -> 0.755
B22: NOPAT = (Adjusted EBIT − adjusting costs) × (1 − t) | D22: =(D18+D20)*D21 -> 732.51344 | E22: =(E18+E20)*E21 -> 858.28335 | F22: =(F18+F20)*F21 -> 989.99764 | G22: =(G18+G20)*G21 -> 1126.6696 | H22: =(H18+H20)*H21 -> 1228.2491 | I22: =(I18+I20)*I21 -> 1314.2265 | J22: =(J18+J20)*J21 -> 1398.0085 | K22: =(K18+K20)*K21 -> 1478.394 | ... M22: =(M18+M20)*M21 -> 1624.0989
B23: plus depreciation & amortization (total, incl. amortization of acquired intangibles) | D23: =Model!AA115 -> 543.45216 | E23: =Model!AB115 -> 589.00297 | F23: =Model!AC115 -> 610.19248 | G23: =Model!AD115 -> 634.5795 | H23: =Model!AE115 -> 668.90179 | I23: =H23*(1+I$31) -> 715.72492 | J23: =I23*(1+J$31) -> 761.35238 | K23: =J23*(1+K$31) -> 805.13014 | L23: =K23*(1+L$31) -> 846.39306 | M23: =L23*(1+M$31) -> 884.48075
B24: − Net capex (gross capex less proceeds from PP&E sales) | D24: =D29 -> -517 | E24: =E29 -> -669.71529 | F24: =F29 -> -710.73113 | G24: =G29 -> -752.09011 | H24: =H29 -> -793.51522 | I24: =I29 -> -849.06128 | J24: =J29 -> -903.18894 | K24: =K29 -> -955.1223 | ... M24: =M29 -> -1049.2556
B25: − Δ Working capital (CF statement) | D25: =Model!AA216 -> 72.771109 | E25: =Model!AB216 -> -1.9168429 | F25: =Model!AC216 -> 5.9950543 | G25: =Model!AD216 -> 5.4885609 | H25: =Model!AE216 -> 8.0228909 | I25: =H25*(1+I$31) -> 8.5844933 | J25: =I25*(1+J$31) -> 9.1317548 | K25: =J25*(1+K$31) -> 9.6568306 | L25: =K25*(1+L$31) -> 10.151743 | M25: =L25*(1+M$31) -> 10.608572
B26: Unlevered FCF | D26: =D22+D23+D24+D25 -> 831.7367 | E26: =E22+E23+E24+E25 -> 775.65418 | F26: =F22+F23+F24+F25 -> 895.45404 | G26: =G22+G23+G24+G25 -> 1014.6475 | H26: =H22+H23+H24+H25 -> 1111.6586 | I26: =I22+I23+I24+I25 -> 1189.4747 | J26: =J22+J23+J24+J25 -> 1265.3037 | K26: =K22+K23+K24+K25 -> 1338.0586 | ... M26: =M22+M23+M24+M25 -> 1469.9327 | N26: =M26*(1+$C$32) -> 1521.3803 | P26: =IFERROR(($H26/$D26)^(1/(VALUE(LEFT($H$17,4))-VALUE(LEFT($D$17,4))))-1,"n/m") -> 0.075217656 | Q26: =IFERROR(($M26/$D26)^(1/(VALUE(LEFT($M$17,4))-VALUE(LEFT($D$17,4))))-1,"n/m") -> 0.065317506
B27: y/y % | E27: =IFERROR(E26/D26-1,"") -> -0.067428216 | F27: =IFERROR(F26/E26-1,"") -> 0.1544501 | G27: =IFERROR(G26/F26-1,"") -> 0.13310954 | H27: =IFERROR(H26/G26-1,"") -> 0.095610578 | I27: =IFERROR(I26/H26-1,"") -> 0.07 | J27: =IFERROR(J26/I26-1,"") -> 0.06375 | K27: =IFERROR(K26/J26-1,"") -> 0.0575 | L27: =IFERROR(L26/K26-1,"") -> 0.05125 | M27: =IFERROR(M26/L26-1,"") -> 0.045
B28: Terminal Value (Gordon Growth) | N28: =N26/($C$13-$C$32) -> 19890.184
B29: memo: net capex (fade years grow with the fade rate) | D29: =Model!AA218+Model!AA219 -> -517 | E29: =Model!AB218+Model!AB219 -> -669.71529 | F29: =Model!AC218+Model!AC219 -> -710.73113 | G29: =Model!AD218+Model!AD219 -> -752.09011 | H29: =Model!AE218+Model!AE219 -> -793.51522 | I29: =H29*(1+I$31) -> -849.06128 | J29: =I29*(1+J$31) -> -903.18894 | K29: =J29*(1+K$31) -> -955.1223 | L29: =K29*(1+L$31) -> -1004.0723 | M29: =L29*(1+M$31) -> -1049.2556
B31: Fade-period growth (2031E–35E) | I31: 0.07 | J31: =I31+($M$31-$I$31)/(COLUMNS($I$31:$M$31)-1) -> 0.06375 | K31: =J31+($M$31-$I$31)/(COLUMNS($I$31:$M$31)-1) -> 0.0575 | L31: =K31+($M$31-$I$31)/(COLUMNS($I$31:$M$31)-1) -> 0.05125 | M31: 0.045
B32: Terminal growth rate | C32: 0.035 | D32: Nominal GDP-plus: North American LTL industry revenue CAGR ~5% (2009–25, investor deck) with pricing discipline; below the 7.0% → 4.5% fade.
B34: Discount period (years) | D34: =(DATE(2026,12,31)-$C$15)/365.25 -> 0.23819302 | E34: =(DATE(2027,12,31)-$C$15)/365.25 -> 1.2375086 | F34: =(DATE(2028,12,31)-$C$15)/365.25 -> 2.2395619 | G34: =(DATE(2029,12,31)-$C$15)/365.25 -> 3.2388775 | H34: =(DATE(2030,12,31)-$C$15)/365.25 -> 4.238193 | I34: =(DATE(2031,12,31)-$C$15)/365.25 -> 5.2375086 | J34: =(DATE(2032,12,31)-$C$15)/365.25 -> 6.2395619 | K34: =(DATE(2033,12,31)-$C$15)/365.25 -> 7.2388775 | L34: =(DATE(2034,12,31)-$C$15)/365.25 -> 8.238193 | M34: =(DATE(2035,12,31)-$C$15)/365.25 -> 9.2375086 | N34: =M34 -> 9.2375086
B35: Discount factor | D35: =1/(1+$C$13)^D34 -> 0.97513717 | E35: =1/(1+$C$13)^E34 -> 0.87738855 | F35: =1/(1+$C$13)^F34 -> 0.78920991 | G35: =1/(1+$C$13)^G34 -> 0.71009881 | H35: =1/(1+$C$13)^H34 -> 0.63891787 | I35: =1/(1+$C$13)^I34 -> 0.57487217 | J35: =1/(1+$C$13)^J34 -> 0.51709681 | K35: =1/(1+$C$13)^K34 -> 0.46526256 | ... N35: =1/(1+$C$13)^N34 -> 0.37666096
B36: PV of UFCF | D36: =D26*D35 -> 811.05737 | E36: =E26*E35 -> 680.55009 | F36: =F26*F35 -> 706.70121 | G36: =G26*G35 -> 720.49999 | H36: =H26*H35 -> 710.25851 | I36: =I26*I35 -> 683.79588 | J36: =J26*J35 -> 654.28448 | K36: =K26*K35 -> 622.54858 | ... M36: =M26*M35 -> 553.66625 | N36: =N28*N35 -> 7491.8559
D37: XPO's Adjusted EBITDA expenses stock-based compensation; Adjusted EBIT deducts all D&A incl. $59m→$36m p.a. amortization of acquired intangibles. Operating leases are treated as operating costs (lease liabilities not deducted from EV). Cash restructuring costs deducted from NOPAT.
B39: Implied ROIC & incremental ROIC (USDm) | D39: =D17 -> 2026E | E39: =E17 -> 2027E | F39: =F17 -> 2028E | G39: =G17 -> 2029E | H39: =H17 -> 2030E | I39: =I17 -> 2031E | J39: =J17 -> 2032E | K39: =K17 -> 2033E | ... M39: =M17 -> 2035E | N39: Terminal
B40: NOPAT (row 22) | D40: =D22 -> 732.51344 | E40: =E22 -> 858.28335 | F40: =F22 -> 989.99764 | G40: =G22 -> 1126.6696 | H40: =H22 -> 1228.2491 | I40: =I22 -> 1314.2265 | J40: =J22 -> 1398.0085 | K40: =K22 -> 1478.394 | ... M40: =M22 -> 1624.0989 | N40: =M40*(1+$C$32) -> 1680.9424
B41: Net investment = NOPAT − UFCF | D41: =D40-D26 -> -99.223266 | E41: =E40-E26 -> 82.629165 | F41: =F40-F26 -> 94.543596 | G41: =G40-G26 -> 112.02205 | H41: =H40-H26 -> 116.59053 | I41: =I40-I26 -> 124.75187 | J41: =J40-J26 -> 132.7048 | K41: =K40-K26 -> 140.33533 | ... N41: =N40-N26 -> 159.56207
B42: Opening invested capital | D42: =Model!V340 -> 4864 | E42: =D43 -> 4764.7767 | F42: =E43 -> 4847.4059 | G42: =F43 -> 4941.9495 | H42: =G43 -> 5053.9715 | I42: =H43 -> 5170.5621 | J42: =I43 -> 5295.314 | K42: =J43 -> 5428.0188 | L42: =K43 -> 5568.3541 | ... N42: =M43 -> 5870.0478
B43: Closing invested capital | D43: =D42+D41 -> 4764.7767 | E43: =E42+E41 -> 4847.4059 | F43: =F42+F41 -> 4941.9495 | G43: =G42+G41 -> 5053.9715 | H43: =H42+H41 -> 5170.5621 | I43: =I42+I41 -> 5295.314 | J43: =J42+J41 -> 5428.0188 | K43: =K42+K41 -> 5568.3541 | ... M43: =M42+M41 -> 5870.0478
B44: Implied ROIC = NOPAT / opening IC | D44: =IFERROR(D40/D42,"") -> 0.15059898 | E44: =IFERROR(E40/E42,"") -> 0.18013086 | F44: =IFERROR(F40/F42,"") -> 0.20423246 | G44: =IFERROR(G40/G42,"") -> 0.22798079 | H44: =IFERROR(H40/H42,"") -> 0.24302651 | I44: =IFERROR(I40/I42,"") -> 0.25417479 | J44: =IFERROR(J40/J42,"") -> 0.26400861 | K44: =IFERROR(K40/K42,"") -> 0.27236346 | ... N44: =IFERROR(N40/N42,"") -> 0.28635923
B45: Reinvestment rate = net inv. / NOPAT | D45: =IFERROR(D41/D40,"") -> -0.1354559 | E45: =IFERROR(E41/E40,"") -> 0.096272595 | F45: =IFERROR(F41/F40,"") -> 0.095498809 | G45: =IFERROR(G41/G40,"") -> 0.0994276 | H45: =IFERROR(H41/H40,"") -> 0.094924177 | I45: =IFERROR(I41/I40,"") -> 0.094924177 | J45: =IFERROR(J41/J40,"") -> 0.094924177 | K45: =IFERROR(K41/K40,"") -> 0.094924177 | ... N45: =IFERROR(N41/N40,"") -> 0.094924177
B46: Incremental ROIC = Δ NOPAT / prior-yr net inv. | E46: =IFERROR((E40-D40)/D41,"") -> -1.2675445 | F46: =IFERROR((F40-E40)/E41,"") -> 1.5940412 | G46: =IFERROR((G40-F40)/F41,"") -> 1.4455969 | H46: =IFERROR((H40-G40)/G41,"") -> 0.90678144 | I46: =IFERROR((I40-H40)/H41,"") -> 0.73743068 | J46: =IFERROR((J40-I40)/I41,"") -> 0.67158865 | K46: =IFERROR((K40-J40)/J41,"") -> 0.60574663 | L46: =IFERROR((L40-K40)/K41,"") -> 0.5399046 | M46: =IFERROR((M40-L40)/L41,"") -> 0.47406258 | N46: =IFERROR($C$32/N45,"") -> 0.36871534
...

Sheet Charts
B2: XPO, Inc. — Historical Operating Performance (standalone, 2022–1H/26)
B3: All historicals · USDm · Linked to Model. Quarterly series Q1/22–Q2/26; returns annual 2022–2025. Volume / price = LTL tonnage per day and yield (gross revenue per cwt excl. fuel) y/y — 2022 quarters as reported by the company vs 2021.
C7: Q1/22 | D7: Q2/22 | E7: Q3/22 | F7: Q4/22 | G7: Q1/23 | H7: Q2/23 | I7: Q3/23 | J7: Q4/23 | K7: Q1/24 | L7: Q2/24 | M7: Q3/24 | N7: Q4/24 | O7: Q1/25 | P7: Q2/25 | Q7: Q3/25 | R7: Q4/25 | S7: Q1/26 | T7: Q2/26
B8: LTL tonnage per day y/y % | C8: =IF(ISNUMBER(Model!C13),Model!C13,IF(ISNUMBER(Model!C14),Model!C14,0)) -> -0.008 | D8: =IF(ISNUMBER(Model!D13),Model!D13,IF(ISNUMBER(Model!D14),Model!D14,0)) -> -0.055 | E8: =IF(ISNUMBER(Model!E13),Model!E13,IF(ISNUMBER(Model!E14),Model!E14,0)) -> -0.029 | F8: =IF(ISNUMBER(Model!F13),Model!F13,IF(ISNUMBER(Model!F14),Model!F14,0)) -> 0.009 | G8: =IF(ISNUMBER(Model!H13),Model!H13,IF(ISNUMBER(Model!H14),Model!H14,0)) -> -0.018339603 | H8: =IF(ISNUMBER(Model!I13),Model!I13,IF(ISNUMBER(Model!I14),Model!I14,0)) -> -0.02824437 | I8: =IF(ISNUMBER(Model!J13),Model!J13,IF(ISNUMBER(Model!J14),Model!J14,0)) -> 0.031314674 | J8: =IF(ISNUMBER(Model!K13),Model!K13,IF(ISNUMBER(Model!K14),Model!K14,0)) -> 0.020015883 | K8: =IF(ISNUMBER(Model!M13),Model!M13,IF(ISNUMBER(Model!M14),Model!M14,0)) -> 0.026419312 | L8: =IF(ISNUMBER(Model!N13),Model!N13,IF(ISNUMBER(Model!N14),Model!N14,0)) -> 0.033689003 | M8: =IF(ISNUMBER(Model!O13),Model!O13,IF(ISNUMBER(Model!O14),Model!O14,0)) -> -0.038570658 | N8: =IF(ISNUMBER(Model!P13),Model!P13,IF(ISNUMBER(Model!P14),Model!P14,0)) -> -0.056576842 | O8: =IF(ISNUMBER(Model!R13),Model!R13,IF(ISNUMBER(Model!R14),Model!R14,0)) -> -0.074700533 | P8: =IF(ISNUMBER(Model!S13),Model!S13,IF(ISNUMBER(Model!S14),Model!S14,0)) -> -0.066682265 | Q8: =IF(ISNUMBER(Model!T13),Model!T13,IF(ISNUMBER(Model!T14),Model!T14,0)) -> -0.060947171 | R8: =IF(ISNUMBER(Model!U13),Model!U13,IF(ISNUMBER(Model!U14),Model!U14,0)) -> -0.045038436 | S8: =IF(ISNUMBER(Model!W13),Model!W13,IF(ISNUMBER(Model!W14),Model!W14,0)) -> 0.0012685894 | T8: =IF(ISNUMBER(Model!X13),Model!X13,IF(ISNUMBER(Model!X14),Model!X14,0)) -> 0.0095851828
